{"local_ts": 1773485240124, "server_ts": 1773485239328, "data": {"e": "depthUpdate", "E": 1773485239331, "T": 1773485239328, "s": "BTCUSDT", "U": 10109438297744, "u": 10109438302445, "pu": 10109438297710, "b": [["5000.00", "101.398"], ["7049.20", "0.028"], ["19991.80", "1.510"], ["20091.80", "1.490"], ["66967.00", "0.150"], ["69417.40", "1.581"], ["69520.00", "0.465"], ["69786.90", "11.668"], ["70360.10", "0.671"], ["70398.10", "0.020"], ["70401.00", "0.005"], ["70402.30", "0.002"], ["70405.20", "2.266"], ["70407.90", "0.000"], ["70409.20", "0.929"], ["70409.60", "1.000"], ["70409.90", "0.516"], ["70410.30", "0.113"], ["70410.60", "0.021"], ["70411.00", "1.228"], ["70412.20", "0.585"], ["70428.30", "0.097"], ["70429.10", "0.002"], ["70432.90", "0.002"], ["70433.70", "0.028"], ["70434.10", "0.293"], ["70434.40", "0.840"], ["70434.80", "0.105"], ["70435.10", "0.004"], ["70435.50", "0.004"], ["70462.50", "0.003"], ["70482.70", "0.004"], ["70482.80", "0.008"], ["70483.10", "0.001"], ["70483.40", "0.025"], ["70483.80", "0.001"], ["70484.20", "0.343"], ["70484.50", "0.003"], ["70489.10", "0.069"], ["70490.00", "0.009"], ["70491.80", "7.829"]], "a": [["70493.60", "0.000"], ["70493.80", "0.005"], ["70494.10", "0.000"], ["70494.20", "0.000"], ["70494.30", "0.037"], ["70494.40", "0.016"], ["70498.60", "0.060"], ["70498.70", "0.002"], ["70498.80", "0.534"], ["70498.90", "0.575"], ["70499.40", "0.255"], ["70499.50", "0.514"], ["70501.30", "0.006"], ["70501.70", "0.011"], ["70502.00", "0.002"], ["70502.40", "0.073"], ["70502.70", "0.085"], ["70502.80", "0.009"], ["70503.10", "0.000"], ["70503.40", "0.078"], ["70526.20", "0.073"], ["70526.50", "0.007"], ["70526.90", "0.000"], ["70527.10", "0.172"], ["70527.20", "0.001"], ["70527.30", "0.036"], ["70527.60", "0.006"], ["70527.90", "0.002"], ["70528.00", "0.009"], ["70528.20", "0.000"], ["70530.20", "0.013"], ["70530.50", "0.002"], ["70548.30", "0.163"], ["70549.80", "0.311"], ["70550.70", "0.119"], ["70551.10", "0.000"], ["70551.40", "0.002"], ["70551.70", "0.000"], ["70551.80", "0.040"], ["70552.10", "4.389"], ["70552.50", "0.000"], ["70553.30", "1.112"], ["70557.00", "0.070"], ["70557.80", "0.003"], ["70574.50", "0.073"], ["70574.80", "0.003"], ["70581.50", "0.589"], ["70581.80", "0.002"], ["70588.60", "0.071"], ["70588.90", "0.002"], ["70624.10", "0.544"], ["70840.30", "0.007"], ["71196.70", "0.000"], ["71196.80", "10.383"], ["74031.90", "0.003"]]}}
{"local_ts": 1773485241148, "server_ts": 1773485240352, "data": {"e": "depthUpdate", "E": 1773485240355, "T": 1773485240352, "s": "BTCUSDT", "U": 10109438345997, "u": 10109438349930, "pu": 10109438345953, "b": [["1000.00", "28.692"], ["5000.00", "101.418"], ["7049.20", "0.000"], ["19991.80", "1.930"], ["20391.80", "1.070"], ["33000.00", "3.789"], ["66954.40", "0.002"], ["69082.00", "0.081"], ["69258.20", "7.715"], ["69302.70", "0.000"], ["69540.20", "3.382"], ["69786.90", "11.668"], ["70139.30", "5.652"], ["70360.10", "0.681"], ["70398.00", "0.035"], ["70398.10", "0.002"], ["70405.10", "0.071"], ["70405.20", "2.195"], ["70412.10", "0.114"], ["70412.20", "0.514"], ["70439.20", "0.000"], ["70439.70", "4.219"], ["70441.20", "0.001"], ["70449.40", "0.021"], ["70453.60", "1.204"], ["70461.00", "0.271"], ["70461.80", "0.155"], ["70470.90", "0.071"], ["70471.40", "0.028"], ["70471.60", "0.007"], ["70472.00", "0.002"], ["70472.30", "0.008"], ["70472.50", "0.082"], ["70472.70", "0.146"], ["70472.80", "0.001"], ["70472.90", "0.000"], ["70473.00", "0.510"], ["70473.40", "0.007"], ["70473.60", "0.002"], ["70475.00", "0.023"], ["70476.00", "1.220"], ["70476.10", "0.004"], ["70476.20", "0.007"], ["70476.90", "0.004"], ["70477.00", "0.007"], ["70478.60", "0.007"], ["70479.00", "0.528"], ["70479.50", "0.153"], ["70479.70", "0.224"], ["70479.80", "0.074"], ["70480.50", "0.004"], ["70482.00", "0.012"], ["70482.90", "0.001"], ["70483.20", "0.002"], ["70483.40", "0.245"], ["70484.80", "0.222"], ["70486.30", "0.017"], ["70486.60", "0.072"], ["70487.90", "0.000"], ["70488.70", "0.370"], ["70488.80", "0.007"], ["70489.10", "0.000"], ["70489.20", "0.000"], ["70489.50", "0.000"], ["70489.60", "0.003"], ["70489.80", "0.000"], ["70490.80", "0.000"]], "a": [["70491.90", "1.742"], ["70492.00", "0.005"], ["70494.60", "0.000"], ["70495.20", "0.026"], ["70497.20", "0.132"], ["70498.20", "0.002"], ["70498.30", "0.006"], ["70498.50", "0.005"], ["70498.70", "0.014"], ["70498.80", "0.521"], ["70498.90", "0.575"], ["70499.50", "0.265"], ["70499.80", "1.298"], ["70504.10", "0.222"], ["70504.50", "0.000"], ["70507.50", "0.025"], ["70507.70", "0.756"], ["70507.80", "1.282"], ["70508.20", "0.004"], ["70509.10", "0.002"], ["70511.30", "0.010"], ["70512.30", "0.005"], ["70513.00", "0.003"], ["70514.90", "0.145"], ["70515.70", "0.003"], ["70516.00", "0.007"], ["70516.50", "0.350"], ["70517.10", "0.001"], ["70517.40", "1.711"], ["70517.70", "0.000"], ["70517.80", "1.212"], ["70518.90", "0.003"], ["70519.60", "0.000"], ["70521.40", "0.835"], ["70523.00", "0.033"], ["70527.10", "0.033"], ["70528.30", "0.220"], ["70536.20", "0.040"], ["70549.80", "0.127"], ["70574.40", "0.161"], ["70574.50", "0.002"], ["70581.40", "0.602"], ["70581.50", "0.518"], ["70587.10", "0.211"], ["70588.50", "0.073"], ["70588.60", "0.000"], ["70624.00", "0.688"], ["70840.20", "0.000"], ["70841.60", "0.007"], ["71196.70", "0.000"], ["71196.80", "10.383"], ["71901.70", "0.012"], ["74049.80", "0.000"]]}}
{"local_ts": 1773485242167, "server_ts": 1773485241374, "data": {"e": "depthUpdate", "E": 1773485241375, "T": 1773485241374, "s": "BTCUSDT", "U": 10109438383514, "u": 10109438387663, "pu": 10109438383465, "b": [["5000.00", "101.418"], ["7049.20", "0.000"], ["19991.80", "0.000"], ["20291.80", "0.620"], ["20391.80", "2.380"], ["66935.80", "0.004"], ["69670.60", "0.000"], ["69786.90", "11.668"], ["69927.90", "1.356"], ["70453.60", "1.204"], ["70461.00", "0.186"], ["70461.80", "0.155"], ["70470.90", "0.001"], ["70471.50", "0.085"], ["70472.10", "0.000"], ["70472.20", "0.080"], ["70472.70", "0.005"], ["70473.00", "0.000"], ["70473.40", "0.077"], ["70473.60", "0.143"], ["70474.30", "0.534"], ["70476.20", "0.000"], ["70476.90", "1.209"], ["70477.10", "0.007"], ["70477.50", "0.074"], ["70478.60", "0.000"], ["70479.50", "0.012"], ["70479.80", "0.081"], ["70480.50", "0.145"], ["70481.30", "0.011"], ["70482.30", "0.638"], ["70482.90", "0.008"], ["70483.10", "0.001"], ["70484.80", "0.224"], ["70491.80", "7.985"]], "a": [["70493.20", "0.000"], ["70493.50", "0.004"], ["70495.00", "0.072"], ["70495.60", "0.011"], ["70497.10", "0.008"], ["70497.60", "0.022"], ["70498.20", "0.000"], ["70498.90", "0.211"], ["70499.40", "0.000"], ["70499.50", "0.514"], ["70504.20", "0.004"], ["70507.30", "0.000"], ["70507.80", "1.143"], ["70516.00", "0.141"], ["70516.40", "0.012"], ["70517.00", "0.000"], ["70517.50", "0.685"], ["70517.60", "0.006"], ["70518.10", "0.570"], ["70518.20", "0.260"], ["70519.10", "0.073"], ["70528.30", "0.036"], ["70587.10", "0.000"], ["70675.20", "0.163"], ["70854.60", "0.018"], ["71196.70", "0.000"], ["71196.80", "10.383"], ["74024.20", "0.445"]]}}
{"local_ts": 1773485243192, "server_ts": 1773485242394, "data": {"e": "depthUpdate", "E": 1773485242397, "T": 1773485242394, "s": "BTCUSDT", "U": 10109438426002, "u": 10109438429264, "pu": 10109438425941, "b": [["1000.00", "28.692"], ["5000.00", "101.418"], ["7049.20", "0.000"], ["20191.80", "0.300"], ["20291.80", "2.570"], ["20391.80", "0.130"], ["66941.40", "0.002"], ["66967.30", "0.006"], ["69781.40", "0.000"], ["69786.90", "11.668"], ["69787.00", "0.033"], ["69941.40", "0.000"], ["70139.30", "5.794"], ["70245.80", "22.882"], ["70461.00", "0.271"], ["70471.50", "0.000"], ["70482.10", "0.000"], ["70482.30", "0.003"], ["70491.80", "7.978"]], "a": [["70491.90", "1.714"], ["70494.50", "0.005"], ["70495.10", "0.003"], ["70495.40", "0.037"], ["70495.70", "0.002"], ["70495.80", "0.006"], ["70497.10", "0.021"], ["70497.50", "0.007"], ["70497.90", "0.003"], ["70498.70", "0.002"], ["70498.80", "0.586"], ["70498.90", "0.370"], ["70499.50", "0.510"], ["70499.70", "0.281"], ["70500.40", "0.227"], ["70500.70", "0.009"], ["70500.80", "0.007"], ["70504.20", "0.004"], ["70504.80", "0.025"], ["70506.10", "0.015"], ["70517.30", "0.583"], ["70518.10", "0.130"], ["70527.10", "0.427"], ["70816.10", "0.002"], ["71050.30", "0.003"], ["71196.80", "10.383"]]}}
{"local_ts": 1773485244215, "server_ts": 1773485243417, "data": {"e": "depthUpdate", "E": 1773485243419, "T": 1773485243417, "s": "BTCUSDT", "U": 10109438461136, "u": 10109438465595, "pu": 10109438461061, "b": [["1000.00", "28.692"], ["5000.00", "101.418"], ["7049.20", "0.056"], ["20091.80", "0.150"], ["20191.80", "2.430"], ["20291.80", "0.420"], ["66933.00", "0.450"], ["68491.80", "0.002"], ["69239.70", "0.021"], ["69572.60", "64.707"], ["69782.00", "55.444"], ["69786.90", "11.668"], ["69928.00", "0.069"], ["70245.10", "0.008"], ["70360.10", "0.688"], ["70439.20", "0.004"], ["70466.10", "0.367"], ["70467.00", "0.065"], ["70472.00", "0.072"], ["70472.10", "0.141"], ["70472.30", "0.008"], ["70472.50", "0.027"], ["70472.60", "0.376"], ["70472.70", "0.005"], ["70472.90", "0.000"], ["70473.80", "0.527"], ["70475.00", "0.023"], ["70477.80", "0.011"], ["70479.20", "0.026"], ["70479.30", "0.142"], ["70479.80", "0.074"], ["70480.90", "0.638"], ["70481.50", "0.021"], ["70481.60", "0.010"], ["70482.00", "0.005"], ["70483.10", "0.284"], ["70483.60", "0.004"], ["70484.00", "0.007"], ["70484.20", "0.347"], ["70484.90", "0.412"], ["70485.50", "0.050"], ["70486.30", "0.002"], ["70488.30", "0.063"], ["70488.40", "0.001"], ["70489.60", "0.003"], ["70490.10", "0.006"], ["70490.20", "0.003"], ["70490.50", "0.000"], ["70491.70", "0.010"], ["70491.80", "7.858"]], "a": [["70491.90", "2.930"], ["70492.00", "0.011"], ["70492.40", "0.021"], ["70493.40", "0.010"], ["70494.40", "0.001"], ["70494.50", "0.026"], ["70495.40", "0.035"], ["70496.40", "0.062"], ["70496.60", "0.021"], ["70497.20", "0.000"], ["70498.80", "0.005"], ["70498.90", "0.531"], ["70499.00", "0.032"], ["70499.90", "0.020"], ["70500.10", "0.061"], ["70500.50", "0.006"], ["70502.20", "0.000"], ["70503.70", "0.171"], ["70503.80", "0.037"], ["70504.00", "0.095"], ["70506.60", "0.001"], ["70507.60", "0.489"], ["70508.30", "0.518"], ["70509.10", "0.002"], ["70511.10", "0.157"], ["70511.50", "0.040"], ["70512.50", "0.020"], ["70513.40", "0.024"], ["70514.60", "0.153"], ["70515.30", "0.019"], ["70516.00", "0.000"], ["70516.20", "0.009"], ["70516.30", "0.640"], ["70516.40", "0.005"], ["70517.00", "0.510"], ["70517.10", "0.001"], ["70517.50", "0.117"], ["70517.90", "0.002"], ["70518.70", "0.005"], ["70518.90", "0.073"], ["70520.20", "0.000"], ["70521.30", "0.250"], ["70523.00", "0.033"], ["70524.80", "0.008"], ["70527.10", "0.137"], ["70532.70", "0.118"], ["70534.40", "0.000"], ["70548.30", "0.163"], ["70549.80", "0.226"], ["70552.10", "4.428"], ["70552.70", "0.025"], ["70623.90", "0.506"], ["70675.20", "0.163"], ["71049.40", "46.189"], ["71196.80", "10.383"], ["71212.80", "53.946"], ["71426.40", "65.468"], ["71471.70", "7.471"], ["71676.20", "0.558"], ["71725.50", "5.988"], ["74030.00", "0.080"]]}}
{"local_ts": 1773485245232, "server_ts": 1773485244438, "data": {"e": "depthUpdate", "E": 1773485244439, "T": 1773485244438, "s": "BTCUSDT", "U": 10109438498898, "u": 10109438502173, "pu": 10109438498859, "b": [["5000.00", "101.418"], ["7049.20", "0.056"], ["20091.80", "2.280"], ["20191.80", "0.720"], ["66932.40", "0.002"], ["66947.10", "0.000"], ["67672.20", "0.058"], ["69279.10", "0.287"], ["69300.50", "2.005"], ["69399.20", "12.876"], ["69469.70", "24.864"], ["69786.90", "11.672"], ["70000.00", "126.831"], ["70308.50", "0.511"], ["70312.00", "0.178"], ["70332.70", "0.714"], ["70345.10", "0.135"], ["70346.40", "3.402"], ["70401.20", "0.425"], ["70402.60", "0.094"], ["70405.20", "2.237"], ["70408.10", "0.002"], ["70409.50", "1.500"], ["70409.80", "0.002"], ["70409.90", "0.516"], ["70410.20", "0.000"], ["70410.50", "0.000"], ["70410.60", "0.021"], ["70410.90", "0.000"], ["70411.30", "0.000"], ["70428.60", "0.002"], ["70429.40", "0.092"], ["70431.90", "0.030"], ["70433.20", "0.000"], ["70434.00", "0.010"], ["70434.30", "0.002"], ["70434.40", "0.840"], ["70434.70", "0.569"], ["70435.10", "0.000"], ["70435.40", "0.081"], ["70435.80", "0.000"], ["70440.60", "0.990"], ["70443.80", "0.062"], ["70444.00", "1.602"], ["70456.60", "1.198"], ["70483.00", "0.010"], ["70483.30", "0.000"], ["70483.40", "0.011"], ["70483.70", "0.003"], ["70484.10", "0.010"], ["70484.40", "0.011"], ["70484.80", "0.118"], ["70488.70", "0.370"], ["70489.60", "0.024"], ["70491.80", "7.690"]], "a": [["70498.80", "0.529"], ["70498.90", "0.559"], ["70499.50", "0.514"], ["70499.70", "0.536"], ["70499.90", "0.530"], ["70500.00", "7.353"], ["70500.10", "0.063"], ["70500.50", "0.004"], ["70500.60", "0.120"], ["70501.00", "0.003"], ["70502.30", "0.017"], ["70502.70", "0.097"], ["70503.00", "0.004"], ["70503.40", "0.078"], ["70503.50", "0.006"], ["70503.70", "0.038"], ["70504.10", "0.004"], ["70508.30", "0.516"], ["70518.20", "0.330"], ["70519.20", "0.205"], ["70526.80", "0.002"], ["70527.10", "0.109"], ["70527.20", "0.001"], ["70527.50", "0.000"], ["70527.60", "0.006"], ["70527.90", "0.002"], ["70528.20", "0.000"], ["70528.30", "0.184"], ["70528.60", "0.202"], ["70528.80", "0.364"], ["70530.90", "0.008"], ["70531.10", "0.990"], ["70548.30", "0.163"], ["70549.80", "0.127"], ["70551.30", "0.003"], ["70551.70", "0.000"], ["70552.00", "0.227"], ["70552.10", "0.858"], ["70552.40", "0.000"], ["70552.70", "0.000"], ["70552.80", "0.002"], ["70553.10", "0.003"], ["70553.90", "0.004"], ["70557.70", "0.006"], ["70558.50", "0.002"], ["70584.50", "1.487"], ["70644.00", "2.756"], ["70675.20", "0.163"], ["70678.70", "0.015"], ["71196.80", "10.383"]]}}
{"local_ts": 1773485246250, "server_ts": 1773485245456, "data": {"e": "depthUpdate", "E": 1773485245459, "T": 1773485245456, "s": "BTCUSDT", "U": 10109438532826, "u": 10109438536465, "pu": 10109438532795, "b": [["1000.00", "28.692"], ["5000.00", "101.418"], ["7049.20", "0.056"], ["19991.80", "1.830"], ["20091.80", "1.170"], ["33000.00", "3.789"], ["66947.70", "0.002"], ["69540.20", "3.669"], ["69786.90", "11.668"], ["70139.30", "5.794"], ["70308.50", "0.670"], ["70403.20", "0.511"], ["70443.50", "0.361"], ["70443.60", "0.005"], ["70456.60", "1.198"], ["70470.00", "4.898"], ["70471.30", "1.107"], ["70471.50", "0.007"], ["70472.30", "0.008"], ["70472.50", "0.027"], ["70473.30", "0.361"], ["70475.60", "0.002"], ["70475.80", "0.538"], ["70481.10", "0.000"], ["70481.40", "0.007"], ["70482.40", "0.400"], ["70483.00", "0.010"], ["70483.10", "0.284"], ["70483.80", "0.001"], ["70487.50", "0.000"], ["70489.60", "0.003"], ["70490.20", "0.008"], ["70490.40", "0.008"], ["70491.70", "0.005"]], "a": [["70492.20", "0.063"], ["70497.50", "0.009"], ["70499.50", "0.514"], ["70500.10", "0.004"], ["70511.10", "0.150"], ["70511.50", "0.047"], ["70515.40", "0.042"], ["70516.00", "0.000"], ["70516.40", "0.515"], ["70528.30", "0.180"], ["70529.20", "0.047"], ["70621.80", "0.237"], ["71196.80", "10.383"], ["71901.70", "0.015"], ["74049.70", "0.000"]]}}
{"local_ts": 1773485247273, "server_ts": 1773485246480, "data": {"e": "depthUpdate", "E": 1773485246481, "T": 1773485246480, "s": "BTCUSDT", "U": 10109438567615, "u": 10109438570728, "pu": 10109438567512, "b": [["5000.00", "101.418"], ["7049.20", "0.028"], ["19991.80", "1.610"], ["20391.80", "1.390"], ["66952.10", "0.002"], ["69786.90", "11.668"], ["69927.90", "1.356"], ["70308.50", "0.670"], ["70312.00", "0.079"], ["70321.30", "3.027"], ["70360.10", "0.519"], ["70397.80", "0.132"], ["70404.90", "0.071"], ["70411.90", "0.073"], ["70470.50", "0.070"], ["70471.30", "1.071"], ["70471.50", "0.000"], ["70472.40", "0.013"], ["70482.50", "0.002"], ["70483.20", "0.004"], ["70484.70", "0.062"], ["70484.80", "0.182"], ["70484.90", "0.412"], ["70488.90", "0.015"], ["70489.20", "0.015"], ["70489.40", "0.015"], ["70489.50", "0.021"], ["70489.60", "0.003"], ["70489.70", "0.001"], ["70489.80", "0.000"], ["70489.90", "0.002"], ["70490.00", "0.007"], ["70490.40", "0.008"], ["70490.50", "0.070"], ["70490.60", "0.000"], ["70490.70", "0.000"], ["70490.80", "0.000"], ["70490.90", "0.000"], ["70491.00", "0.000"], ["70491.10", "0.000"], ["70491.20", "0.000"], ["70491.30", "0.000"], ["70491.40", "0.005"], ["70491.50", "0.002"], ["70491.70", "0.026"], ["70491.80", "7.179"]], "a": [["70491.90", "5.426"], ["70492.00", "0.020"], ["70493.20", "0.015"], ["70493.30", "0.001"], ["70495.40", "0.035"], ["70496.80", "0.006"], ["70497.40", "0.009"], ["70498.80", "0.005"], ["70498.90", "0.087"], ["70499.00", "0.034"], ["70499.60", "0.675"], ["70499.70", "0.026"], ["70500.40", "0.227"], ["70511.50", "0.068"], ["70513.40", "0.045"], ["70515.40", "0.056"], ["70515.60", "0.202"], ["70516.20", "0.640"], ["70516.30", "0.009"], ["70516.40", "0.005"], ["70517.00", "0.510"], ["70517.50", "0.047"], ["70518.50", "0.073"], ["70519.20", "0.205"], ["70522.20", "0.060"], ["70523.40", "0.054"], ["70529.20", "0.140"], ["70534.50", "0.008"], ["70574.10", "0.113"], ["70575.90", "0.091"], ["70581.10", "0.384"], ["70581.40", "0.574"], ["70585.90", "0.005"], ["70586.00", "0.053"], ["70588.20", "0.071"], ["70590.80", "0.225"], ["70593.50", "0.165"], ["70597.80", "0.000"], ["70623.80", "10.068"], ["70662.60", "2.146"], ["70675.20", "0.163"], ["70715.50", "0.000"], ["71196.80", "10.383"], ["71778.50", "2.088"], ["72499.90", "0.000"]]}}
{"local_ts": 1773485248298, "server_ts": 1773485247504, "data": {"e": "depthUpdate", "E": 1773485247505, "T": 1773485247504, "s": "BTCUSDT", "U": 10109438601698, "u": 10109438604913, "pu": 10109438601657, "b": [["1000.00", "28.692"], ["5000.00", "101.418"], ["7049.20", "0.028"], ["20291.80", "0.950"], ["20391.80", "2.050"], ["66937.50", "0.005"], ["66941.70", "0.002"], ["67672.20", "0.064"], ["69540.20", "3.955"], ["69786.90", "11.668"], ["70139.30", "5.794"], ["70443.60", "0.005"], ["70443.70", "0.036"], ["70484.50", "0.018"], ["70484.60", "0.001"]], "a": [["70716.00", "0.009"], ["70844.40", "4.814"], ["71196.80", "10.523"], ["71566.70", "0.704"]]}}
{"local_ts": 1773485249323, "server_ts": 1773485248524, "data": {"e": "depthUpdate", "E": 1773485248527, "T": 1773485248524, "s": "BTCUSDT", "U": 10109438636434, "u": 10109438639681, "pu": 10109438636402, "b": [["1000.00", "28.692"], ["5000.00", "101.418"], ["7049.20", "0.028"], ["20191.80", "0.500"], ["20291.80", "2.500"], ["20391.80", "0.000"], ["56393.00", "0.000"], ["69786.90", "11.668"], ["69788.00", "0.491"], ["70067.90", "39.619"], ["70069.10", "5.944"], ["70167.40", "11.076"], ["70173.10", "32.908"], ["70173.20", "0.648"], ["70174.90", "7.188"], ["70250.40", "26.943"], ["70251.30", "4.944"], ["70414.30", "0.064"], ["70428.30", "0.003"], ["70446.90", "0.006"], ["70454.40", "0.401"], ["70460.90", "0.288"], ["70461.00", "0.087"], ["70479.20", "0.041"], ["70483.10", "0.284"], ["70483.20", "0.017"], ["70484.50", "0.003"], ["70491.80", "6.972"]], "a": [["70492.00", "0.005"], ["70492.10", "0.277"], ["70499.30", "0.008"], ["70528.10", "0.087"], ["70555.40", "0.297"], ["70569.50", "0.003"], ["70597.70", "0.060"], ["70675.20", "0.163"], ["70735.90", "4.270"], ["70737.20", "27.459"], ["70812.60", "5.361"], ["70814.90", "0.648"], ["70815.00", "33.921"], ["70833.80", "0.211"], ["70844.40", "4.603"], ["70921.10", "3.240"], ["70921.20", "40.708"], ["70999.90", "0.000"], ["71059.80", "1.207"], ["71196.80", "10.523"], ["71465.60", "0.000"], ["71725.50", "7.102"], ["74020.90", "0.006"], ["74050.70", "0.000"], ["89523.20", "0.000"]]}}
{"local_ts": 1773485250343, "server_ts": 1773485249548, "data": {"e": "depthUpdate", "E": 1773485249549, "T": 1773485249548, "s": "BTCUSDT", "U": 10109438672714, "u": 10109438675842, "pu": 10109438672671, "b": [["5000.00", "101.418"], ["7049.20", "0.000"], ["20091.80", "0.260"], ["20191.80", "2.540"], ["20291.80", "0.200"], ["56393.00", "0.004"], ["66967.00", "0.150"], ["67672.20", "0.066"], ["69066.80", "1.736"], ["69786.90", "10.237"], ["70333.20", "0.219"], ["70401.50", "0.000"], ["70402.90", "3.806"], ["70408.40", "0.284"], ["70409.80", "0.002"], ["70410.10", "0.000"], ["70410.50", "0.000"], ["70410.80", "0.192"], ["70411.20", "0.092"], ["70411.50", "0.000"], ["70428.90", "0.004"], ["70429.70", "0.113"], ["70433.50", "0.506"], ["70434.30", "0.002"], ["70434.60", "0.048"], ["70434.70", "0.569"], ["70435.00", "0.000"], ["70435.30", "0.097"], ["70435.40", "0.000"], ["70435.70", "0.000"], ["70436.10", "1.066"], ["70460.90", "0.203"], ["70466.10", "0.367"], ["70467.00", "0.065"], ["70472.10", "0.211"], ["70472.70", "0.515"], ["70472.80", "0.001"], ["70473.50", "0.020"], ["70482.20", "0.003"], ["70483.00", "0.008"], ["70483.10", "0.016"], ["70483.30", "0.000"], ["70483.70", "0.003"], ["70484.00", "0.007"], ["70484.20", "0.630"], ["70484.40", "0.011"], ["70484.70", "0.009"], ["70485.10", "0.017"], ["70485.30", "0.001"], ["70491.80", "6.904"]], "a": [["70491.90", "5.144"], ["70496.90", "0.007"], ["70498.90", "0.307"], ["70502.10", "0.005"], ["70502.40", "0.073"], ["70502.80", "0.045"], ["70503.10", "0.000"], ["70503.20", "0.002"], ["70503.50", "0.076"], ["70503.80", "0.037"], ["70508.20", "0.004"], ["70509.30", "0.141"], ["70510.40", "0.009"], ["70510.50", "0.132"], ["70521.30", "0.250"], ["70522.90", "0.000"], ["70524.70", "0.004"], ["70526.60", "0.000"], ["70526.90", "0.000"], ["70527.30", "0.036"], ["70527.60", "0.006"], ["70527.70", "0.006"], ["70528.00", "0.009"], ["70528.10", "0.002"], ["70528.30", "0.184"], ["70528.60", "0.202"], ["70530.60", "0.036"], ["70530.90", "0.008"], ["70533.70", "0.001"], ["70548.30", "0.163"], ["70551.10", "0.000"], ["70551.40", "0.002"], ["70551.80", "0.040"], ["70552.10", "0.858"], ["70552.20", "0.002"], ["70552.50", "0.000"], ["70552.80", "0.002"], ["70553.60", "0.000"], ["70557.40", "0.130"], ["70558.20", "0.092"], ["70833.80", "0.000"], ["71196.80", "10.523"], ["71477.00", "0.238"], ["72268.80", "2.486"], ["74029.00", "0.591"], ["89523.20", "0.000"]]}}
{"local_ts": 1773485251371, "server_ts": 1773485250572, "data": {"e": "depthUpdate", "E": 1773485250573, "T": 1773485250572, "s": "BTCUSDT", "U": 10109438707828, "u": 10109438711164, "pu": 10109438707668, "b": [["1000.00", "28.692"], ["5000.00", "101.438"], ["7049.20", "0.000"], ["19991.80", "0.110"], ["20091.80", "2.400"], ["20191.80", "0.490"], ["56393.00", "0.000"], ["66935.00", "0.015"], ["69000.00", "159.380"], ["69258.20", "10.382"], ["69458.10", "3.672"], ["69645.90", "9.169"], ["69786.90", "9.593"], ["70139.30", "5.794"], ["70296.50", "0.004"], ["70297.10", "0.231"], ["70333.20", "0.219"], ["70402.20", "0.002"], ["70407.20", "0.350"], ["70439.70", "0.784"], ["70440.10", "8.520"], ["70459.90", "0.214"], ["70460.10", "0.431"], ["70470.50", "0.000"], ["70471.60", "0.070"], ["70474.10", "0.010"], ["70475.30", "0.028"], ["70478.80", "0.003"], ["70478.90", "0.003"], ["70479.50", "0.650"], ["70480.10", "0.000"], ["70482.30", "0.000"], ["70484.90", "0.412"], ["70490.20", "0.003"], ["70490.30", "0.017"], ["70490.40", "0.008"], ["70490.50", "0.000"], ["70490.60", "0.029"], ["70490.70", "0.000"], ["70490.80", "0.000"], ["70490.90", "0.000"], ["70491.00", "0.000"], ["70491.10", "0.000"], ["70491.20", "0.000"], ["70491.30", "0.000"], ["70491.70", "0.020"]], "a": [["70491.90", "4.831"], ["70492.40", "0.000"], ["70492.50", "0.000"], ["70493.20", "0.000"], ["70494.30", "0.047"], ["70494.50", "0.005"], ["70494.60", "0.002"], ["70494.80", "0.000"], ["70495.20", "0.005"], ["70495.40", "0.022"], ["70495.60", "0.003"], ["70495.80", "0.006"], ["70495.90", "0.002"], ["70497.60", "0.001"], ["70498.80", "0.095"], ["70499.00", "0.032"], ["70499.40", "0.021"], ["70499.60", "0.654"], ["70500.10", "0.004"], ["70500.20", "0.000"], ["70500.30", "0.000"], ["70500.90", "0.015"], ["70503.70", "0.048"], ["70504.80", "0.025"], ["70506.10", "0.015"], ["70507.70", "0.499"], ["70507.80", "1.141"], ["70508.20", "0.145"], ["70511.50", "0.068"], ["70513.40", "0.045"], ["70515.00", "0.147"], ["70515.40", "0.076"], ["70515.50", "0.697"], ["70516.00", "0.510"], ["70524.70", "0.004"], ["70528.20", "0.184"], ["70528.30", "0.180"], ["70534.30", "0.003"], ["70549.80", "0.226"], ["70580.40", "0.244"], ["70583.50", "0.000"], ["70593.60", "0.043"], ["70715.30", "0.007"], ["71196.80", "9.822"], ["74025.80", "0.035"], ["89523.20", "0.000"]]}}
{"local_ts": 1773485252388, "server_ts": 1773485251592, "data": {"e": "depthUpdate", "E": 1773485251593, "T": 1773485251592, "s": "BTCUSDT", "U": 10109438749146, "u": 10109438752087, "pu": 10109438749094, "b": [["5000.00", "101.418"], ["7049.20", "0.000"], ["19991.80", "2.170"], ["20091.80", "0.830"], ["56393.00", "0.000"], ["69786.90", "11.024"], ["70312.00", "0.019"], ["70332.70", "0.732"], ["70344.00", "0.046"], ["70344.10", "0.005"], ["70346.40", "1.777"], ["70360.00", "0.569"], ["70388.50", "0.343"], ["70403.40", "0.014"], ["70405.20", "1.339"], ["70438.60", "0.154"], ["70456.60", "1.001"], ["70459.60", "0.840"], ["70481.40", "0.067"], ["70482.90", "0.003"], ["70483.00", "0.291"], ["70483.40", "0.011"], ["70483.60", "0.396"], ["70484.70", "0.105"], ["70484.80", "0.182"]], "a": [["70524.70", "0.004"], ["70528.20", "0.184"], ["70529.60", "0.002"], ["70533.70", "0.001"], ["70549.80", "0.127"], ["70550.90", "2.247"], ["70558.90", "0.126"], ["70584.50", "0.731"], ["70586.20", "0.000"], ["70623.70", "0.033"], ["70644.00", "0.973"], ["70645.80", "0.002"], ["70715.60", "0.000"], ["71003.80", "0.007"], ["71055.70", "0.000"], ["71196.80", "9.824"], ["71564.10", "1.257"], ["74029.70", "0.000"], ["74037.60", "0.002"], ["89523.20", "0.000"]]}}
{"local_ts": 1773485253405, "server_ts": 1773485252612, "data": {"e": "depthUpdate", "E": 1773485252613, "T": 1773485252612, "s": "BTCUSDT", "U": 10109438793565, "u": 10109438797057, "pu": 10109438793483, "b": [["1000.00", "28.692"], ["5000.00", "101.418"], ["7049.20", "0.056"], ["19991.80", "1.280"], ["20391.80", "1.720"], ["33000.00", "3.785"], ["56394.00", "0.000"], ["66935.90", "0.002"], ["66947.60", "0.000"], ["69469.70", "30.757"], ["69786.90", "11.024"], ["70100.00", "48.214"], ["70139.30", "5.794"], ["70245.90", "0.004"], ["70453.10", "1.066"], ["70470.40", "0.006"], ["70471.60", "0.070"], ["70477.70", "0.084"], ["70484.80", "0.118"], ["70489.40", "0.000"], ["70489.50", "0.015"], ["70490.10", "0.008"], ["70490.60", "0.000"], ["70491.70", "0.005"], ["70491.80", "6.974"]], "a": [["70491.90", "4.246"], ["70510.90", "0.095"], ["70512.00", "0.208"], ["70514.50", "0.211"], ["70515.50", "0.059"], ["70524.70", "0.004"], ["70524.90", "0.516"], ["70528.20", "0.000"], ["70533.70", "0.001"], ["70650.80", "0.004"], ["70715.30", "0.000"], ["70715.50", "0.007"], ["70840.70", "0.000"], ["70840.80", "0.005"], ["71196.70", "0.000"], ["71196.80", "9.824"], ["71514.00", "29.324"], ["71912.80", "0.000"], ["72200.00", "15.757"], ["72254.20", "0.276"], ["89523.20", "0.000"]]}}
{"local_ts": 1773485254427, "server_ts": 1773485253632, "data": {"e": "depthUpdate", "E": 1773485253633, "T": 1773485253632, "s": "BTCUSDT", "U": 10109438837288, "u": 10109438841086, "pu": 10109438837221, "b": [["1000.00", "28.692"], ["5000.00", "101.418"], ["7049.20", "0.056"], ["20291.80", "1.270"], ["20391.80", "1.730"], ["56394.00", "0.000"], ["66937.50", "0.007"], ["69205.10", "0.721"], ["69628.10", "2.151"], ["69645.90", "9.169"], ["69786.90", "11.024"], ["70333.20", "0.219"], ["70360.00", "0.569"], ["70431.60", "0.005"], ["70443.00", "0.004"], ["70443.10", "0.005"], ["70467.40", "0.002"], ["70481.70", "0.021"], ["70482.00", "0.005"]], "a": [["70491.90", "4.231"], ["70493.20", "0.000"], ["70493.40", "0.017"], ["70494.20", "0.000"], ["70494.60", "0.017"], ["70495.60", "0.011"], ["70497.30", "0.000"], ["70498.80", "0.015"], ["70500.00", "7.407"], ["70500.10", "0.004"], ["70506.10", "0.015"], ["70507.50", "0.166"], ["70508.20", "0.004"], ["70510.90", "0.003"], ["70511.00", "0.067"], ["70511.10", "0.235"], ["70511.50", "0.068"], ["70517.80", "1.142"], ["70518.40", "0.070"], ["70528.30", "0.364"], ["70549.80", "0.085"], ["70564.40", "0.000"], ["70623.60", "0.000"], ["71196.80", "10.523"], ["71408.30", "19.577"], ["71796.00", "2.097"], ["74021.30", "0.000"], ["89523.20", "0.000"]]}}
{"local_ts": 1773485255447, "server_ts": 1773485254652, "data": {"e": "depthUpdate", "E": 1773485254655, "T": 1773485254652, "s": "BTCUSDT", "U": 10109438878457, "u": 10109438882528, "pu": 10109438878378, "b": [["5000.00", "101.418"], ["7049.20", "0.056"], ["20191.80", "0.820"], ["20291.80", "2.180"], ["33000.00", "3.789"], ["56394.00", "0.000"], ["66943.10", "0.000"], ["66951.90", "0.000"], ["69786.90", "11.740"], ["70439.30", "0.516"], ["70456.60", "1.001"], ["70472.00", "0.009"], ["70472.70", "0.005"], ["70473.00", "0.007"], ["70473.60", "0.002"], ["70479.90", "0.141"], ["70480.30", "0.007"], ["70481.90", "0.514"], ["70482.50", "0.004"], ["70484.10", "0.291"], ["70484.50", "0.046"], ["70484.80", "0.189"]], "a": [["70499.40", "0.000"], ["70499.50", "0.514"], ["70499.70", "0.011"], ["70501.20", "0.002"], ["70502.00", "0.002"], ["70503.80", "0.039"], ["70508.50", "0.143"], ["70509.30", "0.000"], ["70516.00", "0.007"], ["70517.00", "0.000"], ["70520.00", "0.099"], ["70521.20", "0.000"], ["70524.70", "0.048"], ["70535.00", "0.003"], ["70678.70", "0.174"], ["71055.80", "1.475"], ["71196.80", "10.523"], ["71337.80", "7.835"], ["71584.50", "13.803"], ["72606.60", "0.018"], ["73311.50", "0.650"], ["74044.40", "0.004"], ["89523.20", "0.000"]]}}
{"local_ts": 1773485256467, "server_ts": 1773485255672, "data": {"e": "depthUpdate", "E": 1773485255675, "T": 1773485255672, "s": "BTCUSDT", "U": 10109438935422, "u": 10109438940683, "pu": 10109438935387, "b": [["1000.00", "28.692"], ["5000.00", "101.418"], ["7049.20", "0.028"], ["20091.80", "0.400"], ["20191.80", "2.570"], ["20291.80", "0.030"], ["66935.90", "0.000"], ["69254.90", "0.720"], ["69490.80", "2.002"], ["69786.90", "8.878"], ["70139.30", "5.758"], ["70139.40", "0.939"], ["70245.60", "0.000"], ["70245.70", "0.006"], ["70315.60", "0.185"], ["70319.10", "0.000"], ["70321.30", "0.020"], ["70445.20", "0.840"], ["70449.60", "0.206"], ["70460.90", "0.104"], ["70469.30", "0.000"], ["70472.00", "0.030"], ["70472.40", "0.076"], ["70473.30", "0.368"], ["70475.70", "0.143"], ["70476.60", "0.000"], ["70476.80", "0.272"], ["70479.00", "0.007"], ["70479.10", "1.216"], ["70479.20", "0.648"], ["70479.80", "0.078"], ["70479.90", "0.000"], ["70481.40", "0.667"], ["70481.90", "0.521"], ["70482.70", "0.004"], ["70483.00", "0.149"], ["70483.80", "0.001"], ["70484.10", "0.006"], ["70484.80", "0.361"], ["70485.10", "0.009"], ["70485.90", "0.024"], ["70486.40", "0.000"], ["70486.60", "0.355"], ["70487.30", "0.002"], ["70491.80", "6.907"]], "a": [["70495.20", "0.053"], ["70495.40", "0.007"], ["70498.90", "0.087"], ["70499.90", "0.020"], ["70504.00", "0.228"], ["70507.50", "0.658"], ["70507.60", "0.350"], ["70511.90", "0.143"], ["70512.80", "0.043"], ["70512.90", "0.087"], ["70514.50", "0.004"], ["70517.10", "0.008"], ["70518.70", "0.003"], ["70518.80", "0.788"], ["70518.90", "0.003"], ["70519.00", "1.115"], ["70519.30", "0.414"], ["70521.00", "0.005"], ["70521.20", "0.000"], ["70521.30", "0.583"], ["70523.20", "0.004"], ["70592.60", "0.342"], ["70593.20", "0.060"], ["70662.40", "0.003"], ["70715.50", "0.000"], ["71196.70", "0.007"], ["71196.80", "10.523"], ["71514.00", "30.302"], ["71693.70", "1.381"], ["89523.20", "0.000"]]}}
{"local_ts": 1773485257490, "server_ts": 1773485256696, "data": {"e": "depthUpdate", "E": 1773485256697, "T": 1773485256696, "s": "BTCUSDT", "U": 10109438982182, "u": 10109438985306, "pu": 10109438982101, "b": [["5000.00", "101.418"], ["7049.20", "0.028"], ["19991.80", "0.220"], ["20091.80", "2.490"], ["20191.80", "0.290"], ["68377.00", "1.444"], ["69786.90", "8.878"], ["69956.90", "0.000"], ["70359.90", "0.708"], ["70388.50", "0.341"], ["70443.70", "0.034"], ["70443.80", "0.064"], ["70460.90", "0.203"], ["70471.50", "0.085"], ["70474.80", "0.653"], ["70475.70", "0.002"], ["70478.30", "0.007"], ["70479.20", "0.641"], ["70481.70", "0.155"], ["70482.40", "0.400"], ["70484.80", "0.163"], ["70485.70", "0.297"], ["70486.60", "0.072"], ["70491.00", "0.002"], ["70491.80", "6.940"]], "a": [["70494.40", "0.001"], ["70498.80", "0.005"], ["70498.90", "0.168"], ["70499.70", "0.003"], ["70517.20", "0.156"], ["70518.80", "0.009"], ["70630.20", "0.561"], ["70630.30", "0.092"], ["70678.70", "0.015"], ["71196.80", "7.719"], ["72606.60", "0.018"], ["74040.40", "0.002"], ["89523.20", "0.000"]]}}
{"local_ts": 1773485258509, "server_ts": 1773485257716, "data": {"e": "depthUpdate", "E": 1773485257717, "T": 1773485257716, "s": "BTCUSDT", "U": 10109439023413, "u": 10109439028390, "pu": 10109439023315, "b": [["1000.00", "28.692"], ["5000.00", "101.418"], ["7049.20", "0.028"], ["19991.80", "2.350"], ["20091.80", "0.590"], ["20391.80", "0.060"], ["66965.10", "0.002"], ["68711.10", "0.000"], ["69328.70", "5.328"], ["69464.00", "0.011"], ["69733.90", "1.002"], ["69786.90", "10.309"], ["70139.30", "5.794"], ["70283.70", "4.878"], ["70284.20", "0.004"], ["70320.70", "3.724"], ["70323.00", "0.599"], ["70359.50", "0.691"], ["70414.30", "0.064"], ["70428.30", "0.003"], ["70449.60", "0.206"], ["70458.70", "0.000"], ["70460.90", "0.288"], ["70471.50", "0.000"], ["70471.70", "0.075"], ["70472.10", "0.007"], ["70472.60", "0.348"], ["70473.00", "0.000"], ["70477.50", "1.264"], ["70477.70", "0.084"], ["70478.60", "0.000"], ["70483.10", "0.001"], ["70484.00", "0.011"], ["70484.30", "0.623"], ["70484.70", "0.011"], ["70491.60", "0.002"], ["70491.70", "0.020"], ["70491.80", "6.909"]], "a": [["70497.50", "0.010"], ["70498.00", "0.057"], ["70498.60", "0.021"], ["70499.70", "0.517"], ["70501.70", "0.005"], ["70503.90", "0.002"], ["70505.90", "0.000"], ["70509.70", "0.005"], ["70510.40", "0.150"], ["70518.90", "0.849"], ["70519.80", "0.070"], ["70524.30", "0.004"], ["70526.20", "0.073"], ["70536.90", "0.007"], ["70555.40", "0.297"], ["70558.80", "0.031"], ["70569.50", "0.003"], ["70627.50", "0.598"], ["70666.30", "3.289"], ["70669.30", "0.526"], ["70675.20", "0.064"], ["70678.70", "0.174"], ["70703.30", "0.091"], ["70706.60", "0.085"], ["71196.80", "9.121"], ["89523.20", "0.000"]]}}
{"local_ts": 1773485259532, "server_ts": 1773485258738, "data": {"e": "depthUpdate", "E": 1773485258739, "T": 1773485258738, "s": "BTCUSDT", "U": 10109439078557, "u": 10109439082654, "pu": 10109439078532, "b": [["1000.00", "28.692"], ["5000.00", "101.418"], ["7049.20", "0.000"], ["19991.80", "0.970"], ["20391.80", "2.030"], ["69455.60", "8.608"], ["69504.90", "7.036"], ["69553.30", "0.000"], ["69786.90", "10.309"], ["70323.00", "0.597"], ["70323.90", "0.004"], ["70414.90", "0.014"], ["70443.70", "0.036"], ["70443.80", "0.062"], ["70444.20", "0.006"], ["70444.30", "1.749"], ["70447.40", "1.579"], ["70458.70", "0.004"], ["70460.90", "0.019"], ["70463.00", "0.163"], ["70466.10", "0.090"], ["70467.40", "0.000"], ["70469.10", "0.248"], ["70470.70", "0.870"], ["70471.50", "0.085"], ["70471.70", "0.005"], ["70472.90", "0.000"], ["70473.50", "0.000"], ["70474.10", "0.226"], ["70474.70", "0.075"], ["70475.40", "0.801"], ["70477.50", "0.059"], ["70477.70", "0.031"], ["70478.60", "1.205"], ["70480.50", "0.011"], ["70481.50", "0.021"], ["70482.00", "0.146"], ["70483.50", "1.706"], ["70484.00", "0.004"], ["70484.70", "0.064"], ["70484.80", "0.367"], ["70490.50", "0.010"], ["70490.60", "0.002"], ["70491.80", "7.080"]], "a": [["70491.90", "1.914"], ["70494.30", "0.267"], ["70494.60", "0.000"], ["70497.50", "0.007"], ["70497.60", "0.001"], ["70499.80", "0.000"], ["70501.50", "0.002"], ["70502.00", "0.002"], ["70504.00", "0.215"], ["70504.90", "0.002"], ["70505.80", "0.002"], ["70507.40", "0.039"], ["70507.50", "0.658"], ["70507.80", "1.143"], ["70509.70", "0.013"], ["70513.70", "0.005"], ["70513.80", "0.087"], ["70516.40", "0.005"], ["70517.10", "0.001"], ["70517.30", "0.078"], ["70517.70", "0.000"], ["70518.20", "0.267"], ["70518.40", "0.000"], ["70518.50", "0.003"], ["70519.30", "0.344"], ["70519.70", "0.000"], ["70519.80", "0.000"], ["70520.20", "0.637"], ["70520.60", "0.516"], ["70520.90", "0.096"], ["70522.00", "0.739"], ["70522.90", "0.072"], ["70524.20", "0.003"], ["70524.30", "0.025"], ["70524.50", "0.000"], ["70524.90", "0.520"], ["70525.30", "0.248"], ["70525.90", "0.006"], ["70527.20", "0.116"], ["70530.80", "1.852"], ["70532.50", "0.137"], ["70536.20", "0.117"], ["70538.70", "0.514"], ["70553.20", "0.000"], ["70553.30", "1.112"], ["70555.70", "0.000"], ["70557.90", "8.502"], ["70564.50", "0.004"], ["70582.60", "0.261"], ["70812.40", "0.007"], ["71196.70", "0.000"], ["71196.80", "9.123"], ["71487.60", "0.000"], ["74051.20", "0.000"], ["74051.50", "0.052"], ["89523.20", "0.000"]]}}
{"local_ts": 1773485260553, "server_ts": 1773485259760, "data": {"e": "depthUpdate", "E": 1773485259761, "T": 1773485259760, "s": "BTCUSDT", "U": 10109439122804, "u": 10109439126598, "pu": 10109439122653, "b": [["1000.00", "28.842"], ["5000.00", "101.398"], ["7049.20", "0.000"], ["20291.80", "1.590"], ["20391.80", "1.410"], ["33000.00", "3.785"], ["66952.00", "0.002"], ["69258.20", "16.150"], ["69786.90", "10.309"], ["69787.00", "0.029"], ["70139.40", "0.943"], ["70323.90", "0.002"], ["70324.00", "0.008"], ["70443.70", "0.036"], ["70443.80", "0.062"], ["70453.50", "0.001"], ["70473.50", "0.000"], ["70475.60", "0.143"], ["70475.80", "0.427"], ["70476.60", "0.000"], ["70484.10", "0.006"], ["70484.50", "0.007"], ["70484.60", "0.003"], ["70485.00", "0.025"], ["70488.40", "0.044"], ["70491.60", "0.679"], ["70491.70", "0.024"], ["70491.80", "7.031"]], "a": [["70491.90", "1.879"], ["70499.90", "1.152"], ["70501.50", "0.005"], ["70508.90", "0.155"], ["70520.80", "1.002"], ["70522.60", "0.074"], ["70524.50", "0.000"], ["70675.90", "0.767"], ["70686.20", "17.013"], ["70715.30", "0.000"], ["71172.30", "0.560"], ["71196.70", "0.007"], ["71196.80", "9.121"], ["71316.70", "4.478"], ["71496.20", "1.404"], ["74021.50", "0.030"]]}}
{"local_ts": 1773485261574, "server_ts": 1773485260780, "data": {"e": "depthUpdate", "E": 1773485260783, "T": 1773485260780, "s": "BTCUSDT", "U": 10109439161831, "u": 10109439164764, "pu": 10109439161788, "b": [["1000.00", "28.692"], ["5000.00", "101.418"], ["7049.20", "0.000"], ["20191.80", "1.140"], ["20291.80", "1.860"], ["66947.50", "0.010"], ["66967.00", "0.150"], ["69200.00", "38.313"], ["69571.40", "0.616"], ["69780.70", "0.000"], ["69786.90", "10.309"], ["70139.30", "5.794"], ["70139.40", "0.939"], ["70251.40", "0.011"], ["70308.50", "0.670"], ["70312.00", "0.178"], ["70319.10", "0.000"], ["70322.40", "0.002"], ["70324.00", "0.006"], ["70333.20", "0.219"], ["70344.40", "0.181"], ["70405.20", "1.339"], ["70476.00", "0.015"]], "a": [["70491.90", "1.829"], ["70499.80", "0.000"], ["70508.90", "0.063"], ["70525.70", "0.059"], ["70533.30", "0.054"], ["70536.50", "0.357"], ["70538.80", "0.006"], ["70560.00", "0.075"], ["70562.40", "0.081"], ["70592.00", "0.154"], ["70594.80", "0.002"], ["70651.50", "1.220"], ["70652.70", "0.000"], ["70715.20", "0.000"], ["70999.80", "0.007"], ["71048.30", "0.000"], ["71059.80", "4.447"], ["71196.80", "10.523"], ["71447.00", "0.909"], ["71707.90", "0.709"], ["71901.70", "0.012"]]}}
{"local_ts": 1773485262596, "server_ts": 1773485261802, "data": {"e": "depthUpdate", "E": 1773485261803, "T": 1773485261802, "s": "BTCUSDT", "U": 10109439195673, "u": 10109439198835, "pu": 10109439195604, "b": [["5000.00", "101.418"], ["7049.20", "0.056"], ["20091.80", "0.690"], ["20191.80", "2.310"], ["20291.80", "0.000"], ["33000.00", "3.785"], ["56394.00", "0.000"], ["69252.50", "0.000"], ["69570.80", "66.874"], ["69786.90", "10.309"], ["69787.00", "0.029"], ["69941.80", "0.004"], ["70200.00", "23.888"], ["70245.60", "0.000"], ["70321.80", "0.004"], ["70322.40", "0.000"], ["70485.30", "0.008"], ["70485.80", "0.009"], ["70486.70", "0.713"], ["70487.20", "0.003"]], "a": [["70491.90", "1.923"], ["70525.70", "0.057"], ["70715.60", "0.007"], ["71196.70", "0.000"], ["71196.80", "10.523"], ["74016.40", "0.005"], ["74031.30", "0.000"]]}}
{"local_ts": 1773485263619, "server_ts": 1773485262824, "data": {"e": "depthUpdate", "E": 1773485262825, "T": 1773485262824, "s": "BTCUSDT", "U": 10109439232452, "u": 10109439235378, "pu": 10109439232386, "b": [["1000.00", "28.692"], ["5000.00", "101.418"], ["7049.20", "0.056"], ["19991.80", "0.320"], ["20091.80", "2.610"], ["20191.80", "0.070"], ["69786.90", "10.309"], ["70139.30", "4.662"], ["70139.40", "0.939"], ["70200.10", "0.007"], ["70245.60", "0.004"]], "a": [["70491.90", "1.922"], ["71196.80", "10.523"], ["71478.70", "0.233"], ["74036.40", "0.000"], ["74038.60", "0.002"]]}}
{"local_ts": 1773485264640, "server_ts": 1773485263846, "data": {"e": "depthUpdate", "E": 1773485263847, "T": 1773485263846, "s": "BTCUSDT", "U": 10109439265157, "u": 10109439268274, "pu": 10109439265140, "b": [["5000.00", "101.418"], ["7049.20", "0.056"], ["19991.80", "2.460"], ["20091.80", "0.370"], ["20391.80", "0.170"], ["33000.00", "3.789"], ["63442.60", "0.020"], ["66967.30", "0.004"], ["69419.10", "2.014"], ["69466.00", "0.000"], ["69786.90", "10.309"], ["70445.50", "0.010"], ["70458.70", "0.000"], ["70461.80", "0.151"], ["70478.60", "1.205"], ["70479.40", "0.647"], ["70479.70", "0.224"], ["70491.60", "0.682"]], "a": [["70491.90", "1.774"], ["70499.30", "0.073"], ["70499.80", "0.514"], ["70508.80", "0.002"], ["70509.40", "0.026"], ["70526.20", "0.094"], ["71196.80", "10.523"], ["71337.80", "8.955"], ["71512.20", "2.657"], ["74033.70", "0.000"], ["77541.10", "0.018"]]}}
{"local_ts": 1773485265662, "server_ts": 1773485264868, "data": {"e": "depthUpdate", "E": 1773485264869, "T": 1773485264868, "s": "BTCUSDT", "U": 10109439305046, "u": 10109439309517, "pu": 10109439304972, "b": [["1000.00", "28.692"], ["5000.00", "101.418"], ["7049.20", "0.028"], ["19991.80", "0.670"], ["20291.80", "0.030"], ["20391.80", "2.300"], ["63442.60", "0.020"], ["66964.80", "0.002"], ["69786.90", "10.309"], ["70352.60", "0.042"], ["70352.70", "0.352"], ["70438.00", "1.325"], ["70443.80", "0.062"], ["70444.00", "0.004"], ["70475.10", "0.003"], ["70476.90", "0.514"], ["70482.60", "0.460"], ["70483.10", "0.001"], ["70483.30", "0.003"], ["70484.90", "0.411"]], "a": [["70491.90", "1.562"], ["70497.10", "0.003"], ["70497.60", "0.004"], ["70498.80", "0.005"], ["70499.00", "0.033"], ["70499.30", "0.073"], ["70499.70", "0.517"], ["70499.80", "0.514"], ["70499.90", "1.407"], ["70501.30", "0.003"], ["70518.90", "0.847"], ["70519.80", "0.638"], ["70519.90", "0.003"], ["70520.70", "1.587"], ["70521.50", "0.916"], ["70522.30", "0.025"], ["70523.10", "0.070"], ["70554.60", "0.285"], ["70715.70", "0.309"], ["70715.80", "0.000"], ["70840.70", "0.000"], ["71196.70", "0.000"], ["71196.80", "9.822"], ["71512.20", "1.819"], ["74038.80", "0.009"], ["77541.10", "0.018"]]}}
{"local_ts": 1773485266685, "server_ts": 1773485265892, "data": {"e": "depthUpdate", "E": 1773485265893, "T": 1773485265892, "s": "BTCUSDT", "U": 10109439356954, "u": 10109439362102, "pu": 10109439356830, "b": [["1000.00", "28.692"], ["5000.00", "101.418"], ["7049.20", "0.028"], ["20291.80", "1.920"], ["20391.80", "1.080"], ["63442.60", "0.020"], ["67672.20", "0.086"], ["69786.90", "9.594"], ["70139.30", "4.662"], ["70443.80", "0.064"], ["70444.00", "0.002"], ["70456.60", "1.001"], ["70484.90", "0.409"], ["70491.80", "6.859"]], "a": [["70491.90", "1.433"], ["70499.00", "0.031"], ["70499.70", "0.517"], ["70499.80", "0.514"], ["70504.10", "0.006"], ["70510.40", "0.009"], ["71050.40", "0.000"], ["71196.80", "9.822"], ["71212.00", "0.000"], ["71336.70", "0.000"], ["71563.90", "0.419"], ["73290.20", "0.028"], ["74046.90", "0.009"], ["77541.10", "0.018"]]}}
{"local_ts": 1773485267713, "server_ts": 1773485266916, "data": {"e": "depthUpdate", "E": 1773485266917, "T": 1773485266916, "s": "BTCUSDT", "U": 10109439407555, "u": 10109439412625, "pu": 10109439407456, "b": [["5000.00", "101.438"], ["7049.20", "0.028"], ["20191.80", "1.480"], ["20291.80", "1.520"], ["56394.00", "0.000"], ["63442.60", "0.020"], ["66942.10", "0.002"], ["69310.90", "0.581"], ["69571.30", "64.355"], ["69780.60", "53.624"], ["69786.90", "9.594"], ["69940.80", "47.397"], ["70281.00", "0.093"], ["70412.10", "0.043"], ["70414.30", "0.078"], ["70443.70", "0.034"], ["70443.80", "0.064"], ["70484.90", "0.409"], ["70491.80", "6.861"]], "a": [["70491.90", "1.363"], ["70492.00", "0.028"], ["70494.30", "0.273"], ["70499.00", "0.031"], ["70500.00", "7.278"], ["70504.10", "0.004"], ["70509.10", "0.004"], ["70593.20", "0.046"], ["70593.70", "0.017"], ["70715.40", "0.011"], ["71050.00", "55.465"], ["71196.70", "0.000"], ["71196.80", "8.420"], ["71408.30", "22.094"], ["71478.70", "0.256"], ["71600.80", "2.392"], ["77541.10", "0.018"]]}}
{"local_ts": 1773485268733, "server_ts": 1773485267936, "data": {"e": "depthUpdate", "E": 1773485267939, "T": 1773485267936, "s": "BTCUSDT", "U": 10109439455202, "u": 10109439460432, "pu": 10109439455064, "b": [["1000.00", "28.692"], ["5000.00", "101.418"], ["7049.20", "0.000"], ["20091.80", "1.030"], ["20191.80", "1.970"], ["63442.60", "0.018"], ["66952.20", "0.000"], ["68360.70", "1.878"], ["69786.90", "10.309"], ["70139.30", "4.662"], ["70320.80", "0.528"], ["70359.20", "6.836"], ["70359.50", "0.000"], ["70359.80", "0.003"], ["70462.10", "0.000"], ["70484.90", "0.409"], ["70491.80", "6.856"]], "a": [["70491.90", "1.291"], ["70494.70", "0.061"], ["70498.90", "0.087"], ["70499.00", "0.058"], ["70499.80", "0.514"], ["70499.90", "1.407"], ["70504.30", "0.002"], ["70509.10", "0.002"], ["70520.10", "0.253"], ["70548.30", "0.007"], ["70623.40", "0.296"], ["70623.80", "0.093"], ["70625.20", "0.016"], ["70626.60", "2.507"], ["70626.70", "11.838"], ["70626.90", "0.000"], ["70664.00", "0.000"], ["70678.70", "0.174"], ["70840.80", "0.216"], ["71196.80", "10.523"], ["71719.50", "0.000"], ["77541.10", "0.016"]]}}
{"local_ts": 1773485269752, "server_ts": 1773485268956, "data": {"e": "depthUpdate", "E": 1773485268959, "T": 1773485268956, "s": "BTCUSDT", "U": 10109439512798, "u": 10109439517905, "pu": 10109439512675, "b": [["5000.00", "101.418"], ["7049.20", "0.000"], ["19991.80", "0.580"], ["20091.80", "2.420"], ["20191.80", "0.000"], ["33000.00", "3.785"], ["63442.60", "0.018"], ["69557.70", "1.436"], ["69610.70", "0.675"], ["69786.90", "10.309"], ["70283.70", "4.572"], ["70320.70", "0.003"], ["70443.70", "0.036"], ["70443.80", "0.062"], ["70462.50", "0.003"], ["70484.90", "0.409"]], "a": [["70491.90", "1.217"], ["70494.70", "0.001"], ["70499.00", "0.050"], ["70499.30", "0.065"], ["70499.70", "0.003"], ["70499.80", "0.000"], ["70499.90", "1.152"], ["70501.30", "0.005"], ["70504.30", "0.000"], ["70505.70", "0.065"], ["70506.00", "0.007"], ["70508.50", "0.135"], ["70663.90", "0.003"], ["70700.90", "0.002"], ["70715.40", "0.004"], ["70819.70", "0.211"], ["70840.70", "0.000"], ["70840.80", "0.005"], ["71176.60", "0.000"], ["71196.70", "0.007"], ["71196.80", "10.523"], ["71508.00", "0.055"], ["74016.40", "0.000"], ["74051.10", "0.018"], ["77541.10", "0.016"]]}}
{"local_ts": 1773485270780, "server_ts": 1773485269980, "data": {"e": "depthUpdate", "E": 1773485269981, "T": 1773485269980, "s": "BTCUSDT", "U": 10109439560163, "u": 10109439565151, "pu": 10109439559995, "b": [["1000.00", "28.692"], ["5000.00", "101.418"], ["7049.20", "0.000"], ["19991.80", "2.560"], ["20091.80", "0.150"], ["20391.80", "0.290"], ["56393.50", "0.009"], ["56394.00", "0.000"], ["63442.60", "0.018"], ["66948.80", "0.002"], ["66961.10", "0.002"], ["66967.20", "2.242"], ["69501.20", "1.824"], ["69786.90", "10.309"], ["70308.50", "0.511"], ["70319.10", "0.159"], ["70333.20", "0.180"], ["70346.60", "12.270"], ["70405.50", "6.869"], ["70440.70", "3.581"], ["70462.00", "1.849"], ["70464.50", "0.733"], ["70484.90", "0.409"], ["70491.80", "6.819"]], "a": [["70491.90", "1.184"], ["70499.00", "0.050"], ["70499.70", "0.517"], ["70499.90", "1.152"], ["70501.30", "0.003"], ["70501.60", "0.009"], ["70508.70", "0.001"], ["70509.50", "0.001"], ["70509.80", "0.063"], ["70532.10", "0.963"], ["70532.70", "2.064"], ["70549.80", "0.269"], ["70553.90", "3.350"], ["70558.50", "0.002"], ["70558.60", "0.092"], ["70562.40", "0.000"], ["70568.70", "1.376"], ["70569.60", "0.018"], ["70588.90", "6.303"], ["70644.00", "2.790"], ["70647.10", "12.009"], ["70678.70", "0.174"], ["70715.40", "0.011"], ["70840.80", "0.216"], ["71050.60", "1.284"], ["71196.70", "0.000"], ["71196.80", "10.523"], ["77541.10", "0.016"], ["89523.20", "0.000"]]}}
{"local_ts": 1773485271796, "server_ts": 1773485271001, "data": {"e": "depthUpdate", "E": 1773485271003, "T": 1773485271001, "s": "BTCUSDT", "U": 10109439604814, "u": 10109439608518, "pu": 10109439604770, "b": [["1000.00", "28.692"], ["5000.00", "101.418"], ["7049.20", "0.056"], ["19991.80", "0.450"], ["20291.80", "0.140"], ["20391.80", "2.410"], ["63442.60", "0.018"], ["66967.20", "2.242"], ["68377.10", "0.003"], ["68714.40", "5.230"], ["69786.90", "10.309"], ["70139.30", "4.662"], ["70139.40", "0.939"], ["70245.90", "0.004"], ["70491.80", "6.820"]], "a": [["70491.90", "1.177"], ["70495.00", "0.002"], ["70501.60", "0.007"], ["70569.60", "0.016"], ["70571.10", "0.048"], ["70840.70", "0.000"], ["71050.60", "0.441"], ["71196.80", "10.523"], ["71332.50", "0.000"], ["71719.40", "2.845"], ["77541.10", "0.016"], ["89523.20", "0.000"]]}}
{"local_ts": 1773485272821, "server_ts": 1773485272024, "data": {"e": "depthUpdate", "E": 1773485272027, "T": 1773485272024, "s": "BTCUSDT", "U": 10109439636103, "u": 10109439639586, "pu": 10109439636059, "b": [["5000.00", "101.418"], ["7049.20", "0.056"], ["20291.80", "2.250"], ["20391.80", "0.750"], ["63442.60", "0.018"], ["66967.00", "0.150"], ["68783.60", "0.622"], ["69082.00", "0.470"], ["69223.50", "0.310"], ["69786.90", "11.404"], ["70445.50", "0.010"], ["70456.70", "0.000"], ["70461.80", "0.197"], ["70461.90", "0.279"], ["70470.20", "0.302"], ["70471.40", "0.205"], ["70471.50", "0.000"], ["70475.80", "0.427"], ["70476.80", "0.782"]], "a": [["70491.90", "1.168"], ["70499.00", "0.058"], ["70499.40", "0.000"], ["70499.70", "0.517"], ["70499.90", "1.152"], ["70508.10", "0.108"], ["70508.30", "0.005"], ["70509.80", "0.027"], ["70511.00", "0.008"], ["70511.40", "0.004"], ["70511.80", "0.023"], ["70511.90", "0.143"], ["70513.20", "0.059"], ["70513.40", "0.002"], ["70514.00", "0.024"], ["70514.20", "0.060"], ["70514.30", "0.088"], ["70515.40", "0.055"], ["70516.00", "0.021"], ["70522.30", "0.025"], ["70523.20", "0.074"], ["70524.00", "0.007"], ["70528.20", "0.021"], ["70530.10", "0.025"], ["70532.10", "0.963"], ["70543.20", "0.237"], ["70570.50", "0.591"], ["70571.10", "0.046"], ["70715.30", "0.007"], ["70842.10", "0.000"], ["71196.80", "10.523"], ["71486.80", "0.004"], ["71616.40", "0.696"], ["71689.90", "0.000"], ["71725.50", "14.900"], ["74032.50", "0.002"], ["77541.10", "0.016"], ["89523.20", "0.000"]]}}
{"local_ts": 1773485273842, "server_ts": 1773485273048, "data": {"e": "depthUpdate", "E": 1773485273049, "T": 1773485273048, "s": "BTCUSDT", "U": 10109439682705, "u": 10109439693123, "pu": 10109439682573, "b": [["1000.00", "28.842"], ["5000.00", "101.418"], ["7049.20", "0.056"], ["20191.80", "1.800"], ["20291.80", "1.200"], ["33000.00", "3.789"], ["56394.00", "0.000"], ["66939.30", "0.000"], ["66967.20", "2.242"], ["66967.30", "0.008"], ["68377.10", "0.003"], ["69786.90", "11.404"], ["70066.90", "0.000"], ["70069.10", "0.035"], ["70139.30", "4.662"], ["70172.20", "0.013"], ["70174.90", "1.228"], ["70249.40", "0.002"], ["70251.30", "1.058"], ["70281.40", "0.006"], ["70443.60", "0.002"], ["70443.70", "0.036"], ["70471.40", "0.106"], ["70479.10", "0.015"], ["70483.10", "0.008"], ["70483.50", "1.068"], ["70484.70", "0.294"], ["70485.30", "0.001"]], "a": [["70491.90", "2.203"], ["70498.90", "0.087"], ["70504.60", "0.008"], ["70513.70", "0.085"], ["70513.90", "0.004"], ["70518.70", "0.641"], ["70520.50", "0.057"], ["70570.00", "0.053"], ["70570.50", "0.589"], ["70678.70", "0.174"], ["70735.90", "0.197"], ["70738.30", "0.004"], ["70800.00", "12.351"], ["70815.90", "0.111"], ["70816.00", "0.698"], ["70816.10", "0.002"], ["70844.40", "4.849"], ["70922.40", "0.000"], ["71196.80", "10.525"], ["71719.40", "2.218"], ["72267.80", "2.487"], ["72606.60", "0.012"], ["89523.20", "0.000"]]}}
{"local_ts": 1773485274867, "server_ts": 1773485274072, "data": {"e": "depthUpdate", "E": 1773485274075, "T": 1773485274072, "s": "BTCUSDT", "U": 10109439741777, "u": 10109439745592, "pu": 10109439741712, "b": [["5000.00", "101.418"], ["7049.20", "0.028"], ["20091.80", "1.370"], ["20191.80", "1.630"], ["56394.00", "0.004"], ["66941.40", "0.002"], ["66954.60", "0.019"], ["68377.10", "0.006"], ["68714.30", "2.618"], ["69082.00", "0.464"], ["69100.90", "3.111"], ["69716.60", "0.000"], ["69786.90", "11.404"], ["70300.00", "20.010"], ["70434.10", "0.301"], ["70443.70", "0.036"], ["70443.80", "0.062"], ["70455.00", "0.021"], ["70471.40", "0.205"], ["70479.10", "0.011"]], "a": [["70504.60", "0.005"], ["70530.90", "0.006"], ["70536.10", "0.013"], ["70537.30", "0.016"], ["71196.80", "10.523"], ["72606.60", "0.018"], ["89523.20", "0.000"]]}}
{"local_ts": 1773485275888, "server_ts": 1773485275093, "data": {"e": "depthUpdate", "E": 1773485275095, "T": 1773485275093, "s": "BTCUSDT", "U": 10109439787456, "u": 10109439792764, "pu": 10109439787120, "b": [["1000.00", "28.692"], ["5000.00", "101.418"], ["7049.20", "0.028"], ["19991.80", "0.920"], ["20091.80", "2.080"], ["69399.20", "19.063"], ["69469.70", "31.332"], ["69723.40", "10.800"], ["69786.90", "11.404"], ["69899.60", "0.184"], ["70446.30", "0.274"], ["70456.60", "1.198"], ["70458.70", "0.004"], ["70479.10", "0.011"], ["70491.80", "6.635"]], "a": [["70496.70", "0.008"], ["70496.90", "0.005"], ["70497.70", "0.002"], ["70498.90", "0.226"], ["70499.60", "0.514"], ["70499.80", "0.510"], ["70499.90", "1.662"], ["70500.80", "0.007"], ["70501.10", "0.065"], ["70501.20", "0.002"], ["70501.30", "0.060"], ["70504.60", "0.005"], ["70506.80", "0.002"], ["70507.70", "0.499"], ["70512.60", "0.037"], ["70512.70", "0.083"], ["70537.70", "0.029"], ["70678.70", "0.174"], ["70715.30", "0.007"], ["71196.70", "0.380"], ["71196.80", "10.523"], ["72254.20", "0.622"], ["74036.50", "0.002"], ["74050.30", "0.000"], ["89523.20", "0.000"]]}}
{"local_ts": 1773485276909, "server_ts": 1773485276112, "data": {"e": "depthUpdate", "E": 1773485276117, "T": 1773485276112, "s": "BTCUSDT", "U": 10109439833805, "u": 10109439837888, "pu": 10109439833746, "b": [["1000.00", "28.692"], ["5000.00", "101.418"], ["7049.20", "0.028"], ["19991.80", "2.530"], ["20091.80", "0.000"], ["20391.80", "0.470"], ["56394.00", "0.000"], ["66936.40", "0.002"], ["69431.30", "0.000"], ["69646.10", "0.008"], ["69786.90", "11.404"], ["70443.40", "0.014"], ["70443.60", "0.002"], ["70479.10", "0.079"]], "a": [["70499.60", "0.514"], ["70504.00", "0.168"], ["70504.60", "0.005"], ["70507.10", "0.109"], ["70513.70", "0.000"], ["70513.80", "0.041"], ["70513.90", "0.089"], ["70715.30", "0.000"], ["71196.70", "0.387"], ["71196.80", "10.523"], ["71507.90", "0.978"], ["71778.40", "2.089"], ["71813.30", "0.500"], ["89523.20", "0.000"]]}}
{"local_ts": 1773485277936, "server_ts": 1773485277136, "data": {"e": "depthUpdate", "E": 1773485277141, "T": 1773485277136, "s": "BTCUSDT", "U": 10109439876279, "u": 10109439880917, "pu": 10109439876094, "b": [["5000.00", "101.418"], ["7049.20", "0.000"], ["19991.80", "0.220"], ["20291.80", "0.250"], ["20391.80", "2.530"], ["56394.00", "0.000"], ["66942.60", "0.002"], ["69080.90", "0.098"], ["69360.90", "0.003"], ["69399.20", "21.077"], ["69786.90", "11.404"], ["69800.60", "0.000"], ["70308.50", "0.670"], ["70333.20", "0.219"], ["70346.30", "0.516"], ["70346.40", "1.773"], ["70404.50", "0.063"], ["70415.80", "0.000"], ["70416.00", "0.053"], ["70423.80", "0.781"], ["70423.90", "0.005"], ["70427.90", "0.187"], ["70431.70", "0.205"], ["70431.90", "0.035"], ["70439.40", "0.000"], ["70439.80", "0.005"], ["70439.90", "0.005"], ["70447.70", "0.003"], ["70447.80", "0.007"], ["70449.70", "0.523"], ["70456.70", "0.000"], ["70460.60", "0.002"], ["70460.90", "0.104"], ["70479.10", "0.079"], ["70483.70", "0.003"], ["70491.80", "6.518"]], "a": [["70492.20", "0.068"], ["70494.20", "0.000"], ["70494.30", "0.216"], ["70496.60", "0.008"], ["70498.90", "0.505"], ["70499.50", "0.514"], ["70499.60", "0.000"], ["70499.90", "1.152"], ["70500.10", "0.006"], ["70502.00", "0.005"], ["70502.50", "0.004"], ["70504.60", "0.005"], ["70504.90", "0.002"], ["70507.50", "0.029"], ["70512.60", "0.017"], ["70513.10", "0.026"], ["70513.80", "0.036"], ["70514.00", "0.029"], ["70516.60", "0.004"], ["70521.80", "0.006"], ["70521.90", "0.018"], ["70527.10", "0.182"], ["70529.80", "0.040"], ["70530.00", "0.117"], ["70530.70", "0.002"], ["70531.70", "0.004"], ["70532.40", "0.005"], ["70537.70", "0.029"], ["70537.80", "0.005"], ["70538.00", "0.077"], ["70545.80", "0.000"], ["70546.00", "0.009"], ["70553.00", "0.119"], ["70555.30", "0.521"], ["70588.30", "1.441"], ["70644.00", "0.973"], ["70647.40", "0.003"], ["70678.70", "0.174"], ["71196.80", "10.523"], ["71337.60", "0.000"], ["71719.40", "1.104"], ["89523.20", "0.000"]]}}
{"local_ts": 1773485278952, "server_ts": 1773485278156, "data": {"e": "depthUpdate", "E": 1773485278161, "T": 1773485278156, "s": "BTCUSDT", "U": 10109439920289, "u": 10109439923235, "pu": 10109439920177, "b": [["1000.00", "28.692"], ["5000.00", "101.418"], ["7049.20", "0.000"], ["20191.80", "0.100"], ["20291.80", "2.380"], ["20391.80", "0.520"], ["33000.00", "3.785"], ["66942.60", "0.000"], ["66955.70", "0.002"], ["69111.10", "1.341"], ["69685.00", "0.572"], ["69786.90", "11.404"], ["70139.30", "4.662"], ["70336.70", "0.041"], ["70439.10", "0.092"], ["70446.20", "0.006"], ["70453.30", "0.068"], ["70456.60", "1.001"], ["70460.40", "0.512"], ["70467.50", "0.008"], ["70474.60", "0.009"], ["70479.10", "0.011"], ["70484.50", "0.194"], ["70484.80", "0.148"]], "a": [["70491.90", "1.656"], ["70498.90", "0.106"], ["70499.50", "0.000"], ["70499.60", "0.000"], ["70499.80", "0.000"], ["70499.90", "1.152"], ["70501.30", "0.003"], ["70501.40", "0.007"], ["70502.50", "0.004"], ["70502.80", "0.009"], ["70507.10", "0.109"], ["70507.50", "0.029"], ["70512.80", "0.008"], ["70517.20", "0.015"], ["70524.30", "0.047"], ["70531.40", "0.007"], ["70538.50", "0.078"], ["70545.60", "0.010"], ["70609.50", "0.260"], ["70612.40", "0.082"], ["70614.30", "0.078"], ["71196.80", "10.523"], ["72604.10", "0.000"], ["89523.20", "0.000"]]}}
{"local_ts": 1773485279980, "server_ts": 1773485279186, "data": {"e": "depthUpdate", "E": 1773485279187, "T": 1773485279186, "s": "BTCUSDT", "U": 10109439952713, "u": 10109439955411, "pu": 10109439952676, "b": [["5000.00", "101.418"], ["7049.20", "0.000"], ["20191.80", "2.150"], ["20291.80", "0.850"], ["66959.30", "0.002"], ["66967.20", "2.242"], ["66967.30", "0.008"], ["68714.80", "2.628"], ["69231.20", "0.000"], ["69258.20", "21.917"], ["69406.20", "0.000"], ["69786.90", "12.842"], ["70339.80", "0.195"], ["70341.80", "2.318"], ["70345.20", "0.078"], ["70350.60", "0.170"], ["70354.90", "0.172"], ["70357.30", "0.078"], ["70362.50", "0.334"], ["70365.30", "0.080"], ["70368.80", "0.420"], ["70371.00", "0.080"], ["70401.40", "0.445"], ["70403.20", "0.511"], ["70408.50", "0.142"], ["70410.30", "0.023"], ["70415.50", "0.186"], ["70417.30", "0.014"], ["70439.10", "0.000"], ["70446.20", "0.006"], ["70453.30", "0.068"], ["70456.60", "1.037"], ["70460.40", "0.512"], ["70467.50", "0.008"], ["70473.40", "0.007"], ["70474.60", "0.009"], ["70475.20", "0.070"], ["70490.30", "0.007"]], "a": [["70491.90", "1.979"], ["70499.50", "0.514"], ["70499.90", "1.152"], ["70501.90", "0.006"], ["70504.90", "0.002"], ["70507.10", "0.109"], ["70507.90", "0.004"], ["70508.30", "0.005"], ["70509.10", "0.143"], ["70517.20", "0.015"], ["70524.30", "0.004"], ["70531.40", "0.007"], ["70538.50", "0.078"], ["70545.60", "0.010"], ["70555.30", "0.528"], ["70562.30", "0.010"], ["70564.10", "0.000"], ["70569.30", "0.011"], ["70570.70", "0.505"], ["70571.10", "0.046"], ["70572.50", "0.001"], ["70576.30", "2.018"], ["70577.70", "1.382"], ["70578.10", "0.000"], ["70579.50", "0.022"], ["70583.30", "0.026"], ["70584.80", "0.144"], ["70585.10", "0.000"], ["70586.60", "0.000"], ["70590.30", "0.060"], ["70592.10", "0.094"], ["70597.30", "0.007"], ["70599.10", "0.000"], ["70604.30", "0.078"], ["70606.10", "0.000"], ["70609.50", "0.233"], ["70612.40", "0.160"], ["70613.10", "0.108"], ["70614.30", "0.156"], ["70815.90", "0.000"], ["71196.70", "0.387"], ["71196.80", "10.523"], ["71625.50", "0.004"], ["89523.20", "0.000"]]}}
{"local_ts": 1773485281001, "server_ts": 1773485280206, "data": {"e": "depthUpdate", "E": 1773485280207, "T": 1773485280206, "s": "BTCUSDT", "U": 10109440061296, "u": 10109440081491, "pu": 10109440061101, "b": [["1000.00", "28.692"], ["5000.00", "101.398"], ["7049.20", "0.000"], ["7050.00", "0.481"], ["20098.20", "0.170"], ["20099.90", "0.180"], ["20191.80", "1.300"], ["33000.00", "3.789"], ["40000.00", "41.356"], ["56394.00", "0.000"], ["66955.70", "0.002"], ["69090.00", "3.695"], ["69463.80", "1.875"], ["69490.30", "0.002"], ["69491.40", "0.000"], ["69494.50", "0.004"], ["69494.60", "0.071"], ["69498.20", "0.014"], ["69499.90", "0.035"], ["69787.00", "0.029"], ["69793.20", "0.000"], ["69794.90", "0.042"], ["70191.40", "0.270"], ["70195.00", "0.426"], ["70215.10", "0.000"], ["70245.70", "0.006"], ["70246.00", "0.000"], ["70295.30", "0.000"], ["70320.10", "3.829"], ["70322.00", "1.053"], ["70323.70", "0.364"], ["70339.60", "0.441"], ["70341.30", "0.309"], ["70342.80", "1.840"], ["70344.80", "6.566"], ["70346.40", "3.317"], ["70356.80", "1.187"], ["70362.10", "0.448"], ["70362.40", "0.000"], ["70364.80", "0.002"], ["70366.60", "0.013"], ["70368.30", "0.000"], ["70370.10", "0.735"], ["70370.20", "0.543"], ["70371.50", "0.001"], ["70377.20", "0.000"], ["70381.10", "0.002"], ["70383.10", "0.271"], ["70387.20", "0.002"], ["70390.60", "0.096"], ["70390.70", "0.568"], ["70391.80", "0.320"], ["70392.20", "1.617"], ["70392.30", "0.000"], ["70397.10", "3.894"], ["70403.40", "0.156"], ["70404.80", "0.000"], ["70411.60", "0.024"], ["70414.30", "0.061"], ["70418.10", "0.266"], ["70426.80", "0.528"], ["70428.30", "0.120"], ["70431.20", "0.064"], ["70431.40", "0.302"], ["70431.90", "0.016"], ["70434.50", "0.024"], ["70435.20", "0.787"], ["70440.10", "0.000"], ["70440.20", "0.783"], ["70443.30", "0.096"], ["70443.60", "0.002"], ["70445.30", "0.011"], ["70445.40", "0.030"], ["70445.80", "0.101"], ["70446.00", "0.002"], ["70446.30", "0.130"], ["70446.60", "0.013"], ["70446.70", "0.000"], ["70447.30", "0.004"], ["70447.50", "0.735"], ["70449.20", "0.005"], ["70450.20", "0.006"], ["70450.30", "0.204"], ["70450.60", "0.085"], ["70452.00", "0.006"], ["70452.20", "0.005"], ["70452.50", "0.000"], ["70453.60", "1.210"], ["70455.40", "0.121"], ["70455.70", "0.005"], ["70455.90", "0.734"], ["70456.50", "0.005"], ["70457.30", "0.000"], ["70457.60", "0.091"], ["70458.10", "0.002"], ["70458.60", "0.051"], ["70459.10", "0.016"], ["70460.70", "0.003"], ["70461.00", "0.087"], ["70461.10", "0.748"], ["70461.20", "0.361"], ["70461.30", "0.284"], ["70461.50", "0.369"], ["70461.80", "0.000"], ["70462.40", "0.286"], ["70462.60", "0.000"], ["70462.70", "0.516"], ["70462.90", "0.020"], ["70463.00", "0.510"], ["70463.20", "0.868"], ["70463.30", "0.011"], ["70463.40", "0.014"], ["70463.70", "0.014"], ["70463.90", "0.073"], ["70464.30", "0.056"], ["70464.70", "0.008"], ["70464.80", "0.001"], ["70465.40", "0.002"], ["70465.50", "0.011"], ["70466.10", "0.158"], ["70466.30", "0.029"], ["70466.80", "0.840"], ["70466.90", "0.347"], ["70467.10", "0.809"], ["70467.50", "0.008"], ["70467.60", "0.273"], ["70468.00", "0.005"], ["70468.80", "1.347"], ["70469.30", "0.040"], ["70469.90", "0.198"], ["70470.70", "0.312"], ["70471.40", "0.318"], ["70471.80", "0.116"], ["70474.20", "0.015"], ["70475.30", "0.011"], ["70476.00", "0.067"], ["70476.50", "0.252"], ["70476.70", "0.003"], ["70477.00", "0.005"], ["70477.20", "0.002"], ["70477.50", "0.059"], ["70477.60", "0.017"], ["70477.80", "0.000"], ["70478.20", "0.002"], ["70478.60", "0.070"], ["70478.70", "0.002"], ["70478.80", "0.003"], ["70479.00", "0.004"], ["70479.20", "0.048"], ["70479.70", "0.224"], ["70479.80", "0.001"], ["70480.60", "0.000"], ["70481.80", "0.329"], ["70481.90", "0.622"], ["70482.00", "0.515"], ["70482.10", "0.094"], ["70482.30", "0.009"], ["70482.70", "1.209"], ["70483.40", "0.013"], ["70483.60", "0.025"], ["70483.80", "0.307"], ["70483.90", "0.115"], ["70484.00", "0.269"], ["70484.20", "0.373"], ["70484.70", "0.057"], ["70485.60", "0.058"], ["70485.80", "0.088"], ["70485.90", "0.000"], ["70486.00", "0.012"], ["70486.10", "0.462"], ["70486.20", "0.401"], ["70486.40", "0.000"], ["70486.60", "0.058"], ["70486.70", "0.037"], ["70486.80", "0.514"], ["70487.20", "0.057"], ["70487.30", "0.047"], ["70487.60", "0.309"], ["70487.70", "0.007"], ["70487.80", "0.008"], ["70488.30", "0.057"], ["70488.70", "0.452"], ["70488.90", "0.007"], ["70489.30", "0.003"], ["70489.70", "0.001"], ["70490.00", "0.044"], ["70490.20", "0.007"], ["70490.30", "0.004"], ["70490.40", "0.004"], ["70490.60", "0.642"], ["70490.70", "0.295"], ["70490.80", "0.001"], ["70490.90", "0.005"], ["70491.00", "0.000"], ["70491.10", "0.002"], ["70491.30", "0.003"], ["70491.40", "0.006"], ["70491.70", "0.027"], ["70491.80", "0.999"], ["70492.10", "0.009"], ["70492.20", "0.000"], ["70492.30", "0.003"], ["70492.60", "0.005"], ["70493.20", "0.339"], ["70493.30", "0.061"], ["70493.40", "0.934"], ["70493.50", "0.003"], ["70493.60", "0.000"], ["70494.00", "0.004"], ["70494.10", "0.001"], ["70494.40", "0.003"], ["70494.50", "0.087"], ["70494.60", "0.002"], ["70494.70", "0.001"], ["70494.80", "0.001"], ["70495.00", "0.084"], ["70495.10", "1.106"], ["70495.20", "0.301"], ["70495.40", "0.000"], ["70495.70", "0.001"], ["70496.10", "0.001"], ["70496.20", "0.190"], ["70497.00", "0.126"], ["70497.20", "0.000"], ["70497.30", "0.121"], ["70497.40", "0.000"], ["70497.50", "0.003"], ["70497.90", "0.055"], ["70498.00", "0.125"], ["70498.10", "0.005"], ["70498.20", "0.042"], ["70498.30", "0.007"], ["70498.40", "0.002"], ["70498.50", "0.000"], ["70498.60", "0.002"], ["70498.70", "0.000"], ["70498.80", "0.000"], ["70498.90", "0.000"], ["70499.00", "0.000"], ["70499.10", "0.021"], ["70499.20", "0.000"], ["70499.60", "0.000"], ["70499.70", "0.000"], ["70499.80", "0.044"], ["70499.90", "11.831"]], "a": [["70498.30", "0.000"], ["70498.40", "0.000"], ["70498.50", "0.000"], ["70498.60", "0.000"], ["70498.70", "0.000"], ["70498.80", "0.000"], ["70498.90", "0.000"], ["70499.00", "0.000"], ["70499.10", "0.000"], ["70499.30", "0.000"], ["70499.70", "0.000"], ["70499.80", "0.000"], ["70499.90", "0.000"], ["70500.00", "9.511"], ["70500.10", "0.004"], ["70500.20", "0.002"], ["70500.30", "0.001"], ["70500.60", "0.006"], ["70500.70", "0.003"], ["70500.80", "0.067"], ["70501.00", "0.003"], ["70501.10", "0.001"], ["70501.70", "0.001"], ["70502.00", "0.000"], ["70502.70", "0.001"], ["70502.80", "0.002"], ["70503.20", "0.000"], ["70503.30", "0.071"], ["70504.90", "0.003"], ["70505.00", "0.026"], ["70506.40", "0.000"], ["70506.60", "0.004"], ["70507.00", "0.056"], ["70507.20", "0.005"], ["70507.30", "0.002"], ["70507.40", "0.157"], ["70508.10", "0.097"], ["70508.30", "0.659"], ["70508.40", "1.078"], ["70508.50", "0.019"], ["70508.70", "0.050"], ["70508.90", "0.002"], ["70509.00", "0.005"], ["70509.40", "0.000"], ["70509.90", "0.000"], ["70510.00", "0.060"], ["70510.10", "0.015"], ["70510.30", "0.007"], ["70510.40", "0.014"], ["70510.60", "0.000"], ["70511.00", "0.010"], ["70511.40", "0.019"], ["70511.70", "0.003"], ["70511.80", "0.014"], ["70512.00", "0.206"], ["70512.10", "0.023"], ["70512.40", "0.005"], ["70512.50", "0.000"], ["70512.70", "0.003"], ["70512.80", "0.059"], ["70513.00", "0.038"], ["70513.40", "0.344"], ["70513.50", "0.003"], ["70514.10", "0.023"], ["70514.40", "0.017"], ["70514.80", "0.002"], ["70515.00", "0.063"], ["70515.20", "0.006"], ["70515.30", "0.012"], ["70515.80", "0.020"], ["70515.90", "0.006"], ["70516.20", "0.002"], ["70516.60", "0.004"], ["70516.70", "0.029"], ["70516.80", "0.654"], ["70516.90", "0.045"], ["70517.20", "0.088"], ["70517.30", "0.015"], ["70517.50", "0.002"], ["70517.70", "0.000"], ["70517.90", "0.004"], ["70518.00", "0.010"], ["70518.30", "0.115"], ["70518.40", "0.080"], ["70519.00", "0.098"], ["70519.10", "0.549"], ["70519.30", "0.344"], ["70519.40", "0.004"], ["70519.80", "0.005"], ["70520.10", "0.117"], ["70520.20", "0.000"], ["70520.40", "0.021"], ["70520.80", "1.011"], ["70520.90", "0.065"], ["70521.50", "0.038"], ["70522.00", "0.739"], ["70522.20", "0.003"], ["70522.30", "0.004"], ["70522.80", "0.204"], ["70522.90", "0.002"], ["70523.00", "0.378"], ["70523.30", "0.045"], ["70523.60", "0.004"], ["70523.80", "0.066"], ["70524.10", "0.146"], ["70524.30", "0.004"], ["70524.40", "0.000"], ["70524.70", "0.000"], ["70524.80", "0.009"], ["70525.00", "1.023"], ["70525.10", "0.878"], ["70525.70", "0.022"], ["70526.10", "0.663"], ["70526.40", "0.000"], ["70526.90", "0.637"], ["70527.70", "0.006"], ["70527.80", "0.000"], ["70528.10", "0.009"], ["70528.20", "0.139"], ["70528.30", "0.342"], ["70528.90", "0.008"], ["70529.00", "0.201"], ["70529.10", "0.000"], ["70529.60", "0.002"], ["70530.20", "0.004"], ["70530.70", "0.030"], ["70531.10", "0.992"], ["70531.40", "0.007"], ["70531.60", "0.137"], ["70531.80", "0.012"], ["70532.50", "0.124"], ["70533.00", "0.253"], ["70533.50", "0.002"], ["70534.90", "0.036"], ["70535.00", "0.039"], ["70535.60", "0.000"], ["70536.20", "0.117"], ["70536.40", "0.009"], ["70536.60", "0.080"], ["70537.50", "0.477"], ["70539.10", "0.002"], ["70539.30", "0.002"], ["70539.40", "0.321"], ["70540.40", "0.073"], ["70542.30", "0.575"], ["70544.10", "0.003"], ["70544.80", "0.021"], ["70545.10", "0.006"], ["70545.80", "0.005"], ["70547.00", "0.062"], ["70549.30", "0.031"], ["70550.30", "0.109"], ["70551.00", "0.786"], ["70553.10", "0.005"], ["70553.80", "0.047"], ["70554.80", "0.000"], ["70555.30", "0.546"], ["70555.40", "0.294"], ["70556.00", "0.821"], ["70557.00", "0.014"], ["70558.50", "0.083"], ["70561.10", "0.016"], ["70562.20", "0.008"], ["70562.30", "0.003"], ["70565.40", "0.002"], ["70565.90", "0.534"], ["70566.10", "0.151"], ["70568.60", "0.056"], ["70569.30", "0.004"], ["70569.50", "0.000"], ["70572.10", "0.000"], ["70573.90", "0.096"], ["70574.10", "10.181"], ["70576.30", "2.011"], ["70583.30", "0.019"], ["70590.30", "0.053"], ["70597.30", "0.000"], ["70598.30", "0.082"], ["70604.30", "0.071"], ["70605.30", "0.011"], ["70607.40", "0.002"], ["70612.30", "0.135"], ["70616.20", "0.080"], ["70617.80", "0.110"], ["70619.30", "0.007"], ["70619.70", "0.078"], ["70620.90", "0.080"], ["70624.60", "0.179"], ["70626.30", "0.008"], ["70633.30", "6.508"], ["70637.40", "0.000"], ["70640.30", "0.007"], ["70647.30", "0.100"], ["70647.60", "3.721"], ["70885.50", "0.002"], ["70920.70", "9.267"], ["70921.90", "0.016"], ["71157.50", "0.002"], ["71192.80", "0.017"], ["71196.80", "10.523"], ["71203.30", "0.000"], ["71205.00", "0.002"], ["71909.90", "0.006"], ["76778.20", "0.003"], ["76954.30", "0.000"], ["89523.20", "0.000"]]}}
{"local_ts": 1773485282021, "server_ts": 1773485281226, "data": {"e": "depthUpdate", "E": 1773485281227, "T": 1773485281226, "s": "BTCUSDT", "U": 10109440147075, "u": 10109440152225, "pu": 10109440146959, "b": [["1000.00", "28.692"], ["5000.00", "101.418"], ["7050.00", "0.481"], ["19999.90", "1.250"], ["20091.80", "0.910"], ["20099.90", "0.640"], ["66953.30", "0.002"], ["68239.50", "1.000"], ["68943.00", "0.300"], ["69275.70", "4.324"], ["69794.90", "0.042"], ["70316.60", "0.099"], ["70400.20", "0.022"], ["70407.30", "0.074"], ["70414.30", "0.132"], ["70424.80", "0.002"], ["70449.90", "8.515"], ["70450.40", "0.003"], ["70453.10", "1.066"], ["70453.50", "0.008"], ["70461.10", "0.665"], ["70461.90", "0.003"], ["70463.00", "0.364"], ["70467.90", "0.000"], ["70468.30", "0.000"], ["70471.10", "0.000"], ["70471.40", "0.134"], ["70473.90", "0.279"], ["70474.60", "0.054"], ["70475.50", "0.082"], ["70475.60", "0.000"], ["70479.10", "0.081"], ["70479.90", "0.254"], ["70480.10", "0.070"], ["70480.70", "0.511"], ["70481.10", "0.002"], ["70481.60", "0.003"], ["70488.70", "0.650"], ["70489.10", "0.008"], ["70489.30", "0.003"], ["70489.40", "0.000"], ["70492.60", "0.005"], ["70498.50", "0.046"]], "a": [["70502.60", "0.000"], ["70502.70", "0.016"], ["70506.70", "0.118"], ["70508.40", "1.080"], ["70508.50", "0.002"], ["70510.60", "0.060"], ["70513.80", "0.003"], ["70524.10", "0.783"], ["70524.50", "0.510"], ["70525.10", "0.885"], ["70525.80", "0.005"], ["70526.80", "0.072"], ["70527.80", "0.007"], ["70529.20", "0.320"], ["70529.40", "0.334"], ["70530.90", "0.006"], ["70531.10", "1.044"], ["70532.40", "0.005"], ["70558.40", "0.018"], ["70565.40", "0.009"], ["70572.40", "0.304"], ["70576.50", "0.000"], ["70576.60", "0.086"], ["70579.40", "0.007"], ["70583.50", "0.000"], ["70583.60", "0.076"], ["70586.40", "0.009"], ["70590.60", "0.077"], ["70590.70", "0.307"], ["70593.40", "0.055"], ["70598.30", "0.075"], ["70600.40", "0.007"], ["70605.30", "0.004"], ["70607.40", "0.009"], ["70612.30", "0.128"], ["70619.30", "0.000"], ["70626.30", "0.001"], ["70633.30", "6.501"], ["70640.30", "0.000"], ["70647.30", "0.093"], ["70676.20", "0.175"], ["71205.00", "0.002"], ["71676.00", "0.093"]]}}
{"local_ts": 1773485283039, "server_ts": 1773485282246, "data": {"e": "depthUpdate", "E": 1773485282247, "T": 1773485282246, "s": "BTCUSDT", "U": 10109440191942, "u": 10109440195445, "pu": 10109440191932, "b": [["5000.00", "101.418"], ["7050.00", "0.481"], ["19999.90", "2.200"], ["20399.90", "0.800"], ["33000.00", "3.789"], ["65508.10", "0.002"], ["67680.00", "0.051"], ["69794.90", "0.042"], ["70341.50", "0.078"], ["70352.90", "0.082"], ["70363.20", "0.046"], ["70416.00", "0.011"], ["70417.50", "0.000"], ["70453.20", "0.004"], ["70453.30", "0.040"], ["70471.70", "0.399"], ["70478.20", "0.004"], ["70487.20", "0.003"], ["70489.30", "0.003"], ["70489.40", "0.638"], ["70489.60", "0.005"], ["70492.30", "0.014"], ["70492.60", "0.005"], ["70492.90", "0.008"], ["70497.20", "0.003"], ["70498.50", "0.012"], ["70499.90", "7.562"]], "a": [["70500.00", "9.831"], ["70502.20", "0.001"], ["70503.10", "0.080"], ["70503.60", "0.001"], ["70504.40", "0.013"], ["70504.80", "0.027"], ["70506.70", "0.118"], ["70510.60", "0.060"], ["70558.40", "0.011"], ["70563.00", "0.007"], ["70564.50", "0.000"], ["70565.40", "0.002"], ["70566.90", "0.166"], ["70570.00", "0.058"], ["70572.40", "0.297"], ["70577.00", "0.349"], ["70579.40", "0.000"], ["70584.00", "0.086"], ["70586.40", "0.002"], ["70591.00", "0.009"], ["70593.40", "0.048"], ["70598.00", "0.017"], ["70600.40", "0.000"], ["70605.00", "0.007"], ["70607.40", "0.002"], ["70612.00", "0.032"], ["70628.70", "0.082"], ["70630.60", "10.002"], ["70634.30", "0.043"], ["70641.60", "0.000"], ["70645.30", "0.041"], ["70645.60", "0.189"], ["70676.20", "0.175"], ["71205.00", "0.004"], ["71514.00", "34.423"], ["71522.20", "4.329"], ["71655.00", "6.526"], ["74053.20", "0.069"]]}}
{"local_ts": 1773485284062, "server_ts": 1773485283268, "data": {"e": "depthUpdate", "E": 1773485283269, "T": 1773485283268, "s": "BTCUSDT", "U": 10109440244508, "u": 10109440249740, "pu": 10109440244379, "b": [["1000.00", "28.692"], ["5000.00", "101.438"], ["7050.00", "0.453"], ["19999.90", "0.040"], ["20299.90", "0.400"], ["20399.90", "2.560"], ["66974.00", "0.020"], ["68764.90", "0.002"], ["69794.90", "1.473"], ["70147.40", "0.036"], ["70147.50", "0.000"], ["70253.70", "0.004"], ["70413.30", "0.002"], ["70413.70", "0.344"], ["70453.20", "0.002"], ["70453.30", "0.042"], ["70461.60", "0.003"], ["70466.90", "0.481"], ["70473.00", "0.000"], ["70474.50", "0.060"], ["70486.80", "0.514"], ["70487.40", "0.008"], ["70490.70", "0.015"], ["70491.00", "0.000"]], "a": [["70500.00", "10.749"], ["70505.30", "0.068"], ["70518.80", "0.271"], ["70523.50", "0.063"], ["70524.00", "0.654"], ["70528.60", "0.200"], ["70529.10", "0.248"], ["70530.40", "0.087"], ["70531.00", "0.636"], ["70549.80", "0.000"], ["70563.00", "0.000"], ["70570.00", "0.051"], ["70570.60", "0.007"], ["70577.00", "0.342"], ["70577.60", "0.010"], ["70584.00", "0.079"], ["70584.60", "1.076"], ["70591.00", "0.002"], ["70591.60", "0.092"], ["70598.00", "0.010"], ["70598.60", "0.082"], ["70605.00", "0.000"], ["70605.60", "0.084"], ["70612.00", "0.025"], ["70612.60", "0.087"], ["70619.60", "0.010"], ["71205.00", "0.002"], ["71909.90", "0.012"], ["74040.70", "0.166"]]}}
{"local_ts": 1773485285082, "server_ts": 1773485284288, "data": {"e": "depthUpdate", "E": 1773485284289, "T": 1773485284288, "s": "BTCUSDT", "U": 10109440289777, "u": 10109440294375, "pu": 10109440289654, "b": [["5000.00", "101.418"], ["7050.00", "0.453"], ["20199.90", "0.210"], ["20299.90", "2.490"], ["20399.90", "0.300"], ["66967.20", "2.236"], ["66967.30", "0.008"], ["69399.20", "20.070"], ["69469.70", "34.206"], ["69794.90", "1.473"], ["70281.40", "0.002"], ["70316.60", "0.099"], ["70360.30", "0.014"], ["70360.60", "0.727"], ["70399.20", "0.090"], ["70406.30", "0.272"], ["70413.30", "0.073"], ["70422.30", "0.316"], ["70436.40", "0.101"], ["70442.70", "0.004"], ["70452.10", "0.322"], ["70453.00", "0.009"], ["70453.20", "0.002"], ["70472.70", "0.002"], ["70473.40", "0.251"], ["70473.90", "0.031"], ["70478.90", "0.143"], ["70479.30", "0.001"], ["70479.60", "1.024"], ["70479.90", "0.000"], ["70480.10", "0.002"], ["70487.00", "0.008"], ["70487.20", "0.003"], ["70487.30", "0.112"], ["70487.70", "0.645"], ["70488.20", "0.496"], ["70493.70", "0.034"]], "a": [["70500.00", "11.212"], ["70502.90", "0.004"], ["70507.30", "0.012"], ["70513.30", "0.226"], ["70513.50", "0.003"], ["70513.70", "0.000"], ["70521.40", "0.023"], ["70521.50", "0.038"], ["70523.10", "0.000"], ["70523.60", "0.643"], ["70529.30", "0.014"], ["70563.50", "0.003"], ["70575.60", "0.125"], ["70577.60", "0.003"], ["70582.60", "0.332"], ["70589.70", "0.321"], ["70631.30", "0.544"], ["70723.50", "0.007"], ["70841.70", "0.010"], ["71205.00", "0.002"], ["71514.00", "32.467"], ["71569.70", "0.837"], ["74054.50", "0.052"]]}}
{"local_ts": 1773485286103, "server_ts": 1773485285308, "data": {"e": "depthUpdate", "E": 1773485285309, "T": 1773485285308, "s": "BTCUSDT", "U": 10109440336074, "u": 10109440339423, "pu": 10109440336002, "b": [["1000.00", "28.692"], ["5000.00", "101.418"], ["7050.00", "0.453"], ["20099.90", "0.060"], ["20199.90", "2.340"], ["20299.90", "0.600"], ["66945.50", "0.002"], ["69794.90", "1.473"], ["70147.50", "0.000"], ["70253.20", "0.009"], ["70254.00", "0.073"], ["70399.40", "0.021"], ["70406.50", "0.079"], ["70413.50", "0.071"], ["70417.90", "0.002"], ["70442.70", "0.004"], ["70452.10", "0.326"], ["70453.20", "0.002"], ["70453.30", "0.042"], ["70473.40", "0.251"], ["70473.90", "0.031"], ["70477.20", "0.002"], ["70479.20", "0.005"], ["70488.30", "0.000"], ["70488.50", "0.089"], ["70496.20", "0.016"], ["70496.70", "0.000"], ["70497.30", "0.000"], ["70497.50", "0.003"], ["70497.60", "0.070"], ["70499.00", "0.000"], ["70499.20", "0.002"], ["70499.80", "0.041"]], "a": [["70500.00", "11.236"], ["70500.40", "0.515"], ["70500.60", "0.006"], ["70501.90", "0.008"], ["70502.70", "0.086"], ["70503.10", "0.000"], ["70537.50", "0.477"], ["70575.70", "0.000"], ["70575.80", "0.114"], ["70582.70", "0.000"], ["70582.80", "0.073"], ["70589.80", "0.306"], ["70589.90", "2.459"], ["71055.80", "5.900"], ["71205.00", "0.430"], ["71337.80", "14.216"], ["71592.70", "2.929"], ["71909.90", "0.012"], ["74058.40", "0.000"]]}}
{"local_ts": 1773485287121, "server_ts": 1773485286328, "data": {"e": "depthUpdate", "E": 1773485286329, "T": 1773485286328, "s": "BTCUSDT", "U": 10109440376617, "u": 10109440381239, "pu": 10109440376486, "b": [["1000.00", "29.092"], ["5000.00", "101.418"], ["7050.00", "0.453"], ["20099.90", "2.010"], ["20199.90", "0.990"], ["66954.10", "0.002"], ["69287.60", "0.000"], ["69565.60", "0.718"], ["69699.00", "0.032"], ["69794.90", "2.189"], ["70341.30", "0.309"], ["70351.30", "0.161"], ["70361.50", "0.593"], ["70432.80", "0.000"], ["70453.00", "0.007"], ["70453.10", "1.068"], ["70489.90", "0.064"], ["70490.10", "0.009"], ["70492.20", "0.018"], ["70492.90", "0.077"], ["70496.30", "0.000"], ["70497.10", "0.002"], ["70498.00", "0.059"], ["70499.00", "0.000"], ["70499.30", "0.000"]], "a": [["70500.00", "11.403"], ["70500.20", "0.002"], ["70500.30", "0.075"], ["70500.40", "0.440"], ["70501.30", "0.011"], ["70502.70", "0.107"], ["70507.00", "0.008"], ["70514.60", "0.147"], ["70549.40", "0.232"], ["70549.80", "0.184"], ["71052.50", "0.705"], ["71205.00", "0.703"], ["71334.50", "2.801"], ["71369.70", "1.944"], ["71698.50", "0.279"], ["71698.60", "0.002"], ["72000.00", "230.349"]]}}
{"local_ts": 1773485288142, "server_ts": 1773485287348, "data": {"e": "depthUpdate", "E": 1773485287349, "T": 1773485287348, "s": "BTCUSDT", "U": 10109440416446, "u": 10109440420111, "pu": 10109440416357, "b": [["5000.00", "101.418"], ["7050.00", "0.425"], ["19999.90", "1.560"], ["20099.90", "1.440"], ["33000.00", "3.785"], ["66941.40", "0.000"], ["66955.70", "0.004"], ["69082.00", "1.262"], ["69255.80", "0.002"], ["69794.90", "2.189"]], "a": [["70500.00", "11.454"], ["70501.90", "0.008"], ["70530.50", "0.057"], ["70546.20", "0.222"], ["70549.40", "0.147"], ["71205.00", "0.703"]]}}
{"local_ts": 1773485289174, "server_ts": 1773485288368, "data": {"e": "depthUpdate", "E": 1773485288369, "T": 1773485288368, "s": "BTCUSDT", "U": 10109440457032, "u": 10109440460403, "pu": 10109440457000, "b": [["1000.00", "29.092"], ["5000.00", "101.398"], ["7050.00", "0.425"], ["19999.90", "1.890"], ["20399.90", "1.110"], ["67122.40", "0.000"], ["70147.40", "0.072"], ["70330.50", "0.004"], ["70335.00", "0.095"], ["70339.80", "0.080"], ["70362.20", "0.000"], ["70362.30", "0.610"], ["70399.80", "0.047"], ["70399.90", "0.018"], ["70406.90", "0.511"], ["70407.00", "1.788"], ["70413.90", "0.084"], ["70414.00", "0.073"], ["70453.20", "0.002"], ["70453.30", "0.042"], ["70464.70", "0.002"], ["70471.70", "0.535"], ["70479.00", "0.004"], ["70480.30", "0.077"], ["70488.50", "0.087"], ["70492.70", "0.213"], ["70492.90", "0.174"], ["70499.50", "0.002"], ["70499.60", "0.015"], ["70499.70", "0.000"], ["70499.80", "0.005"]], "a": [["70500.00", "9.930"], ["70500.40", "0.572"], ["70507.00", "0.010"], ["70526.20", "0.328"], ["70526.80", "0.072"], ["70576.20", "0.009"], ["70576.30", "2.082"], ["70583.20", "0.002"], ["70583.30", "0.090"], ["70590.30", "0.053"], ["70590.40", "2.074"], ["70610.60", "0.000"], ["70612.90", "0.000"], ["70615.30", "0.079"], ["70616.90", "0.000"], ["70631.30", "0.539"], ["71205.00", "0.703"], ["71698.60", "0.006"], ["71733.70", "3.346"], ["72275.20", "2.486"], ["74049.80", "0.000"], ["89523.20", "0.000"]]}}
{"local_ts": 1773485290184, "server_ts": 1773485289390, "data": {"e": "depthUpdate", "E": 1773485289391, "T": 1773485289390, "s": "BTCUSDT", "U": 10109440496885, "u": 10109440500483, "pu": 10109440496846, "b": [["5000.00", "101.418"], ["7050.00", "0.425"], ["19999.90", "0.000"], ["20299.90", "0.660"], ["20399.90", "2.340"], ["33000.00", "3.789"], ["61193.90", "0.749"], ["66974.00", "0.000"], ["69459.10", "0.005"], ["69477.70", "18.864"], ["69548.20", "1.504"], ["69794.90", "3.620"], ["70453.10", "1.068"], ["70453.20", "0.002"], ["70455.80", "0.162"], ["70473.30", "0.000"], ["70474.30", "0.054"], ["70475.20", "0.000"], ["70483.80", "0.539"], ["70488.50", "0.087"], ["70488.90", "0.000"], ["70489.10", "0.004"], ["70489.70", "0.101"], ["70492.90", "0.077"], ["70494.30", "0.005"], ["70496.60", "0.001"], ["70497.00", "0.055"], ["70497.10", "0.002"], ["70497.20", "0.060"], ["70497.30", "0.000"], ["70497.40", "0.000"], ["70497.50", "0.003"], ["70497.60", "0.049"], ["70497.70", "0.212"], ["70498.90", "0.000"], ["70499.10", "0.036"], ["70499.30", "0.008"], ["70499.90", "6.091"]], "a": [["70500.00", "9.850"], ["70500.80", "0.047"], ["70501.90", "0.008"], ["70502.50", "0.003"], ["70503.10", "0.000"], ["70507.00", "0.008"], ["70515.70", "0.005"], ["70518.80", "0.186"], ["70520.40", "0.008"], ["70525.60", "0.003"], ["70526.60", "0.070"], ["70527.40", "0.000"], ["70549.80", "0.269"], ["70618.40", "0.085"], ["70623.20", "0.094"], ["71205.00", "0.703"], ["74025.40", "0.002"], ["74031.60", "0.000"], ["89523.20", "0.000"]]}}
{"local_ts": 1773485291204, "server_ts": 1773485290412, "data": {"e": "depthUpdate", "E": 1773485290413, "T": 1773485290412, "s": "BTCUSDT", "U": 10109440541405, "u": 10109440545862, "pu": 10109440541333, "b": [["1000.00", "28.692"], ["5000.00", "101.418"], ["7050.00", "0.481"], ["20199.90", "0.310"], ["20299.90", "2.600"], ["20399.90", "0.090"], ["68500.00", "85.773"], ["69794.90", "3.620"], ["70343.00", "3.804"], ["70349.40", "0.264"], ["70353.70", "12.514"], ["70411.80", "6.414"], ["70446.80", "3.393"], ["70453.60", "1.210"], ["70453.70", "0.268"], ["70468.00", "1.787"], ["70471.40", "0.318"], ["70471.50", "0.233"], ["70471.80", "0.201"], ["70471.90", "0.011"], ["70476.70", "0.055"], ["70477.80", "0.000"], ["70482.90", "1.206"], ["70483.20", "0.000"], ["70492.90", "0.274"], ["70493.50", "0.003"], ["70498.60", "0.002"], ["70499.80", "0.020"], ["70499.90", "7.091"]], "a": [["70500.00", "7.962"], ["70500.70", "0.002"], ["70502.10", "0.005"], ["70503.30", "0.004"], ["70503.50", "0.002"], ["70503.60", "0.016"], ["70504.80", "0.012"], ["70505.10", "0.035"], ["70505.20", "0.016"], ["70506.20", "0.003"], ["70507.00", "0.033"], ["70510.00", "0.075"], ["70510.50", "0.004"], ["70511.50", "0.004"], ["70515.70", "0.020"], ["70516.90", "0.060"], ["70518.70", "0.088"], ["70520.40", "0.006"], ["70522.80", "0.225"], ["70531.00", "0.832"], ["70533.00", "0.005"], ["70535.80", "1.834"], ["70537.90", "0.002"], ["70538.00", "0.070"], ["70549.80", "0.000"], ["70557.10", "3.451"], ["70563.70", "6.303"], ["70563.90", "0.000"], ["70592.30", "6.420"], ["70649.70", "0.004"], ["70651.00", "14.546"], ["70669.80", "0.018"], ["70676.20", "0.016"], ["70683.30", "0.159"], ["70723.70", "2.002"], ["70723.90", "0.007"], ["71204.90", "0.000"], ["71205.00", "2.105"], ["74050.40", "0.002"], ["89523.20", "0.000"]]}}
{"local_ts": 1773485292224, "server_ts": 1773485291432, "data": {"e": "depthUpdate", "E": 1773485291433, "T": 1773485291432, "s": "BTCUSDT", "U": 10109440587021, "u": 10109440590440, "pu": 10109440586917, "b": [["1000.00", "28.692"], ["5000.00", "101.418"], ["7050.00", "0.481"], ["20099.90", "0.160"], ["20199.90", "2.450"], ["20299.90", "0.390"], ["66950.10", "0.000"], ["69477.70", "20.876"], ["69784.80", "0.000"], ["69794.90", "3.620"], ["69795.00", "0.103"], ["69947.60", "0.016"], ["70253.60", "0.000"], ["70366.80", "0.649"], ["70407.50", "0.144"], ["70414.60", "0.222"], ["70421.60", "0.144"], ["70471.50", "0.216"], ["70493.00", "0.392"], ["70495.60", "0.015"], ["70496.20", "0.001"], ["70499.20", "0.004"]], "a": [["70500.00", "8.014"], ["70501.80", "0.080"], ["70503.20", "0.058"], ["70507.10", "0.046"], ["70511.50", "0.002"], ["70529.40", "0.086"], ["70530.90", "0.254"], ["70576.80", "0.151"], ["70583.80", "0.367"], ["70590.90", "0.142"], ["70632.70", "0.467"], ["70723.70", "2.009"], ["70744.20", "1.006"], ["70834.90", "0.000"], ["71056.10", "0.000"], ["71205.00", "2.105"], ["71219.50", "0.000"], ["71795.80", "0.000"], ["72615.00", "0.005"], ["89523.20", "0.000"]]}}
{"local_ts": 1773485293244, "server_ts": 1773485292452, "data": {"e": "depthUpdate", "E": 1773485292453, "T": 1773485292452, "s": "BTCUSDT", "U": 10109440622030, "u": 10109440625680, "pu": 10109440622022, "b": [["5000.00", "101.418"], ["7050.00", "0.481"], ["19999.90", "0.010"], ["20099.90", "2.300"], ["20199.90", "0.690"], ["66944.70", "0.000"], ["66974.90", "0.004"], ["66975.00", "0.086"], ["69554.10", "0.000"], ["69581.50", "64.755"], ["69790.80", "53.936"], ["69794.90", "3.620"], ["69795.00", "0.099"], ["69951.70", "44.528"], ["70254.10", "0.000"], ["70260.50", "0.006"], ["70493.00", "0.392"]], "a": [["70500.00", "8.788"], ["70504.00", "0.198"], ["70507.10", "0.046"], ["70516.00", "0.000"], ["70516.10", "0.097"], ["70723.40", "0.000"], ["70744.00", "0.095"], ["71056.00", "41.268"], ["71205.00", "2.105"], ["71219.40", "47.688"], ["71433.10", "59.356"], ["71574.90", "0.697"], ["74042.10", "0.000"], ["89523.20", "0.000"]]}}
{"local_ts": 1773485294266, "server_ts": 1773485293473, "data": {"e": "depthUpdate", "E": 1773485293475, "T": 1773485293473, "s": "BTCUSDT", "U": 10109440657762, "u": 10109440661123, "pu": 10109440657734, "b": [["1000.00", "28.692"], ["5000.00", "101.418"], ["7050.00", "0.453"], ["19999.90", "1.870"], ["20099.90", "1.130"], ["66948.90", "0.002"], ["66974.90", "0.006"], ["69328.70", "2.592"], ["69469.70", "24.146"], ["69498.80", "1.430"], ["69794.90", "3.620"], ["70147.40", "0.108"], ["70495.80", "0.031"], ["70495.90", "0.002"], ["70499.90", "7.140"]], "a": [["70500.00", "8.828"], ["70504.00", "0.196"], ["70513.10", "0.005"], ["70529.40", "0.086"], ["70530.90", "0.254"], ["71205.00", "3.507"], ["74040.20", "0.000"], ["89523.20", "0.000"]]}}
{"local_ts": 1773485295289, "server_ts": 1773485294493, "data": {"e": "depthUpdate", "E": 1773485294495, "T": 1773485294493, "s": "BTCUSDT", "U": 10109440691753, "u": 10109440695245, "pu": 10109440691734, "b": [["5000.00", "101.438"], ["7050.00", "0.453"], ["19999.90", "1.580"], ["20399.90", "1.420"], ["33000.00", "3.785"], ["66948.70", "0.002"], ["66974.90", "0.008"], ["68373.20", "3.504"], ["69090.00", "3.707"], ["69791.70", "0.801"], ["69794.90", "3.620"], ["69795.10", "0.002"], ["70147.40", "0.108"], ["70253.60", "0.004"], ["70406.60", "0.081"], ["70408.80", "0.003"], ["70425.20", "0.004"], ["70453.00", "0.064"], ["70456.50", "0.062"], ["70456.90", "0.000"], ["70473.90", "0.031"], ["70474.00", "0.332"], ["70475.00", "0.008"], ["70475.50", "0.082"], ["70478.70", "0.004"], ["70479.40", "0.444"], ["70479.50", "0.105"], ["70479.60", "0.521"], ["70479.70", "0.226"], ["70479.80", "0.001"], ["70480.10", "0.519"], ["70480.30", "0.007"], ["70480.50", "0.004"], ["70480.70", "0.071"], ["70484.80", "0.141"], ["70485.30", "0.126"], ["70485.90", "0.000"], ["70486.00", "0.024"], ["70487.70", "0.014"], ["70488.10", "0.070"], ["70488.20", "0.198"], ["70488.50", "0.077"], ["70488.60", "1.311"], ["70488.80", "0.001"], ["70489.00", "0.008"], ["70489.10", "1.034"], ["70489.90", "0.022"], ["70491.80", "0.284"], ["70492.30", "0.029"], ["70492.70", "0.213"], ["70493.00", "0.000"], ["70493.30", "0.066"], ["70494.60", "0.000"], ["70495.00", "0.014"], ["70495.80", "0.013"], ["70496.10", "0.001"], ["70496.30", "0.000"], ["70496.40", "0.017"], ["70496.80", "0.000"], ["70497.80", "0.002"], ["70498.20", "0.007"], ["70498.50", "0.002"], ["70498.60", "0.000"], ["70499.20", "0.002"], ["70499.90", "4.865"]], "a": [["70500.00", "9.885"], ["70502.80", "0.004"], ["70508.10", "0.040"], ["70510.00", "0.077"], ["70513.10", "0.003"], ["70513.60", "0.006"], ["70517.80", "0.004"], ["70519.40", "0.011"], ["70521.10", "0.019"], ["70521.50", "0.188"], ["70523.40", "0.029"], ["70523.50", "0.063"], ["70523.90", "0.004"], ["70524.40", "0.637"], ["70524.50", "0.000"], ["70524.70", "0.517"], ["70524.80", "0.002"], ["70526.00", "0.286"], ["70526.10", "0.733"], ["70526.60", "0.000"], ["70527.30", "0.070"], ["70527.40", "0.000"], ["70531.10", "1.254"], ["70533.60", "0.155"], ["70545.80", "0.003"], ["70554.80", "0.000"], ["70571.00", "0.005"], ["70844.40", "4.428"], ["71205.00", "3.507"], ["71575.30", "0.699"], ["71676.00", "0.111"], ["71909.90", "0.009"], ["89523.20", "0.000"]]}}
{"local_ts": 1773485296307, "server_ts": 1773485295512, "data": {"e": "depthUpdate", "E": 1773485295515, "T": 1773485295512, "s": "BTCUSDT", "U": 10109440789423, "u": 10109440798819, "pu": 10109440789208, "b": [["1000.00", "28.692"], ["5000.00", "101.418"], ["7049.60", "0.028"], ["20295.50", "0.850"], ["20399.90", "1.510"], ["66940.90", "0.384"], ["68499.90", "0.013"], ["69511.80", "0.011"], ["69790.50", "0.003"], ["70416.30", "0.042"], ["70416.70", "1.167"], ["70458.40", "0.079"], ["70462.70", "0.516"], ["70468.90", "1.009"], ["70473.70", "0.003"], ["70474.60", "0.072"], ["70474.90", "0.355"], ["70481.50", "0.000"], ["70482.50", "0.008"], ["70483.90", "0.113"], ["70484.90", "0.009"], ["70495.40", "0.000"], ["70495.50", "0.262"]], "a": [["70495.60", "9.440"], ["70495.70", "0.403"], ["70495.80", "0.000"], ["70496.10", "0.002"], ["70502.80", "0.009"], ["70506.20", "0.006"], ["70519.10", "0.514"], ["70519.70", "0.077"], ["70520.60", "0.008"], ["70521.30", "0.583"], ["70524.60", "0.015"], ["70524.90", "0.794"], ["70528.60", "0.206"], ["70531.00", "0.584"], ["70533.10", "1.090"], ["70534.50", "0.007"], ["70554.40", "0.034"], ["70557.10", "0.061"], ["70557.50", "0.089"], ["70724.30", "0.000"], ["71200.50", "0.013"], ["71200.60", "0.073"], ["71917.10", "0.003"], ["73315.40", "0.002"], ["74045.70", "0.000"], ["89523.20", "0.000"]]}}
{"local_ts": 1773485297337, "server_ts": 1773485296536, "data": {"e": "depthUpdate", "E": 1773485296537, "T": 1773485296536, "s": "BTCUSDT", "U": 10109440855794, "u": 10109440861158, "pu": 10109440855703, "b": [["1000.00", "28.692"], ["5000.00", "101.418"], ["7049.60", "0.000"], ["20195.50", "0.530"], ["20295.50", "2.470"], ["20395.50", "0.000"], ["33000.00", "3.785"], ["56396.00", "0.002"], ["66946.10", "0.004"], ["69163.90", "0.000"], ["69790.50", "0.003"], ["69931.50", "0.000"], ["70319.30", "0.161"], ["70442.30", "0.049"], ["70447.40", "1.583"], ["70448.90", "0.004"], ["70449.20", "0.007"], ["70450.30", "0.202"], ["70455.40", "0.108"], ["70457.80", "0.004"], ["70460.70", "0.000"], ["70464.80", "0.007"], ["70464.90", "7.815"], ["70469.40", "0.001"], ["70472.60", "0.404"], ["70473.30", "0.070"], ["70474.00", "0.549"], ["70475.30", "0.026"], ["70486.00", "0.008"], ["70487.20", "0.018"], ["70488.50", "0.098"], ["70488.60", "1.311"], ["70488.70", "0.005"], ["70488.80", "0.004"], ["70488.90", "0.000"], ["70489.00", "0.005"], ["70489.10", "0.001"], ["70489.20", "0.000"], ["70489.30", "0.024"], ["70489.40", "0.057"], ["70489.50", "0.358"], ["70489.60", "0.330"], ["70489.70", "0.001"], ["70489.80", "0.002"], ["70489.90", "0.225"], ["70490.00", "0.014"], ["70490.20", "0.051"], ["70495.40", "0.001"], ["70495.50", "1.501"]], "a": [["70495.70", "0.407"], ["70496.80", "0.020"], ["70500.00", "6.839"], ["70502.60", "0.041"], ["70504.90", "0.003"], ["70510.50", "0.002"], ["70515.10", "0.009"], ["70518.90", "0.633"], ["70519.60", "0.007"], ["70519.70", "0.007"], ["70520.60", "0.083"], ["70520.90", "0.035"], ["70521.90", "0.075"], ["70522.30", "0.006"], ["70525.20", "0.436"], ["70531.00", "0.584"], ["71200.60", "0.000"], ["71478.70", "0.122"], ["71770.90", "4.173"], ["74401.40", "0.013"], ["89523.20", "0.000"]]}}
{"local_ts": 1773485298350, "server_ts": 1773485297557, "data": {"e": "depthUpdate", "E": 1773485297559, "T": 1773485297557, "s": "BTCUSDT", "U": 10109440988498, "u": 10109441007692, "pu": 10109440988445, "b": [["5000.00", "101.418"], ["7049.20", "0.000"], ["20088.60", "0.120"], ["20188.60", "0.220"], ["20195.50", "1.180"], ["20295.50", "0.190"], ["56396.00", "0.002"], ["69783.70", "0.004"], ["69896.60", "0.045"], ["70168.80", "24.078"], ["70191.50", "0.527"], ["70246.10", "20.153"], ["70285.70", "1.277"], ["70339.90", "0.238"], ["70342.10", "0.087"], ["70374.20", "0.004"], ["70376.60", "0.000"], ["70381.20", "0.096"], ["70382.30", "0.092"], ["70385.90", "0.005"], ["70392.50", "0.043"], ["70394.20", "0.029"], ["70409.50", "1.500"], ["70429.90", "0.005"], ["70430.50", "8.520"], ["70431.70", "0.224"], ["70431.90", "0.792"], ["70432.60", "0.005"], ["70434.20", "0.012"], ["70435.40", "0.000"], ["70438.50", "0.080"], ["70440.70", "0.347"], ["70441.20", "0.103"], ["70441.30", "0.079"], ["70441.40", "0.207"], ["70443.30", "0.000"], ["70444.80", "0.126"], ["70454.70", "0.032"], ["70456.70", "0.080"], ["70457.50", "0.539"], ["70457.90", "0.007"], ["70458.40", "0.040"], ["70458.50", "0.004"], ["70459.80", "0.008"], ["70459.90", "0.213"], ["70460.40", "0.519"], ["70460.50", "0.003"], ["70460.60", "0.005"], ["70461.00", "0.059"], ["70461.10", "0.071"], ["70461.20", "0.111"], ["70461.40", "0.512"], ["70461.80", "0.002"], ["70461.90", "0.005"], ["70462.00", "0.012"], ["70462.40", "0.286"], ["70462.60", "0.000"], ["70462.70", "0.516"], ["70462.90", "0.020"], ["70463.10", "0.404"], ["70463.20", "0.840"], ["70464.40", "0.000"], ["70465.10", "0.070"], ["70466.50", "0.000"], ["70467.00", "0.009"], ["70467.70", "0.018"], ["70467.80", "1.208"], ["70468.30", "0.000"], ["70469.50", "0.000"], ["70469.70", "0.406"], ["70470.50", "0.000"], ["70471.40", "0.659"], ["70471.70", "1.783"], ["70471.90", "0.320"], ["70472.00", "0.057"], ["70472.50", "0.010"], ["70472.60", "0.348"], ["70472.70", "0.768"], ["70473.20", "0.008"], ["70474.00", "0.026"], ["70474.30", "0.054"], ["70474.50", "0.090"], ["70474.80", "0.029"], ["70475.20", "0.000"], ["70475.30", "0.009"], ["70475.40", "0.206"], ["70476.00", "0.325"], ["70476.80", "0.047"], ["70477.00", "0.007"], ["70477.20", "0.059"], ["70478.70", "0.043"], ["70478.80", "0.183"], ["70479.10", "0.114"], ["70479.30", "0.001"], ["70479.40", "0.487"], ["70479.60", "0.003"], ["70479.80", "0.209"], ["70480.00", "0.022"], ["70480.20", "0.153"], ["70481.00", "0.004"], ["70481.30", "0.011"], ["70481.40", "0.007"], ["70482.40", "0.003"], ["70482.60", "0.013"], ["70483.00", "0.008"], ["70483.10", "0.041"], ["70483.20", "0.021"], ["70483.80", "0.347"], ["70484.00", "0.001"], ["70484.30", "0.059"], ["70484.60", "0.151"], ["70485.40", "0.008"], ["70486.30", "0.002"], ["70486.40", "0.021"], ["70487.00", "0.000"], ["70487.10", "0.024"], ["70488.00", "0.004"], ["70488.10", "0.048"], ["70488.50", "0.071"], ["70488.60", "2.708"]], "a": [["70488.70", "16.446"], ["70488.80", "0.401"], ["70488.90", "0.008"], ["70489.30", "0.003"], ["70489.50", "0.002"], ["70489.60", "0.046"], ["70489.70", "0.000"], ["70489.90", "0.000"], ["70490.00", "0.007"], ["70490.10", "0.060"], ["70490.30", "0.000"], ["70491.10", "0.031"], ["70491.40", "0.000"], ["70491.50", "0.003"], ["70491.60", "0.141"], ["70491.70", "0.003"], ["70491.90", "0.003"], ["70492.00", "0.001"], ["70492.40", "0.003"], ["70492.50", "0.004"], ["70492.80", "0.000"], ["70493.40", "0.005"], ["70493.70", "0.003"], ["70493.80", "0.027"], ["70494.20", "0.024"], ["70494.60", "0.062"], ["70495.80", "0.019"], ["70496.20", "0.062"], ["70496.30", "0.052"], ["70496.80", "0.024"], ["70497.00", "0.012"], ["70497.70", "0.023"], ["70497.80", "0.001"], ["70498.10", "0.002"], ["70498.60", "0.003"], ["70498.70", "0.010"], ["70498.90", "0.002"], ["70499.30", "0.002"], ["70499.50", "0.012"], ["70499.60", "0.018"], ["70499.70", "0.001"], ["70499.90", "1.060"], ["70500.50", "0.006"], ["70501.00", "0.146"], ["70501.20", "0.004"], ["70501.80", "0.000"], ["70502.80", "0.052"], ["70502.90", "0.003"], ["70503.00", "0.004"], ["70503.20", "0.072"], ["70503.30", "0.004"], ["70503.60", "0.199"], ["70503.90", "0.002"], ["70504.60", "0.004"], ["70504.70", "0.003"], ["70504.80", "0.003"], ["70505.60", "0.129"], ["70505.70", "0.000"], ["70506.10", "0.113"], ["70506.20", "0.003"], ["70506.40", "0.004"], ["70506.70", "0.080"], ["70506.80", "0.001"], ["70506.90", "0.007"], ["70507.00", "0.088"], ["70507.20", "0.024"], ["70507.50", "0.004"], ["70507.70", "0.630"], ["70507.90", "0.661"], ["70508.30", "1.071"], ["70508.70", "0.510"], ["70509.50", "0.001"], ["70509.90", "0.023"], ["70510.30", "0.003"], ["70511.30", "0.073"], ["70511.80", "0.023"], ["70513.00", "0.003"], ["70513.10", "0.005"], ["70513.30", "0.050"], ["70513.40", "0.248"], ["70513.80", "0.021"], ["70514.50", "1.674"], ["70514.60", "0.111"], ["70514.90", "0.056"], ["70515.20", "0.006"], ["70515.30", "0.012"], ["70518.70", "0.005"], ["70518.80", "0.004"], ["70519.20", "0.262"], ["70519.40", "0.004"], ["70519.50", "0.000"], ["70519.80", "0.532"], ["70520.20", "0.000"], ["70520.60", "0.190"], ["70521.00", "0.005"], ["70521.20", "0.544"], ["70524.00", "0.015"], ["70524.90", "0.794"], ["70525.20", "0.379"], ["70525.50", "0.002"], ["70525.60", "0.023"], ["70525.70", "0.004"], ["70526.00", "0.288"], ["70527.50", "1.852"], ["70532.00", "0.006"], ["70534.90", "0.121"], ["70537.50", "0.338"], ["70539.50", "0.001"], ["70540.20", "0.021"], ["70540.50", "0.032"], ["70541.30", "0.002"], ["70548.60", "0.083"], ["70550.50", "0.045"], ["70550.80", "2.685"], ["70555.00", "0.199"], ["70555.10", "0.049"], ["70561.00", "0.004"], ["70561.80", "0.477"], ["70564.30", "0.039"], ["70566.10", "0.000"], ["70577.40", "0.092"], ["70587.40", "0.213"], ["70600.20", "0.120"], ["70603.10", "0.119"], ["70631.00", "0.221"], ["70637.40", "0.000"], ["70640.20", "0.003"], ["70650.30", "0.000"], ["70679.00", "0.159"], ["70694.60", "0.000"], ["70730.60", "26.309"], ["70795.90", "0.002"], ["70801.30", "6.492"], ["70808.40", "31.537"], ["70812.00", "0.010"], ["70841.00", "0.064"], ["70841.70", "0.010"], ["71193.60", "0.000"], ["71478.30", "0.000"], ["71488.70", "0.017"], ["71898.40", "0.006"], ["73308.20", "0.002"], ["74025.20", "0.002"], ["89523.20", "0.000"], ["100000.00", "23.659"]]}}
{"local_ts": 1773485299370, "server_ts": 1773485298576, "data": {"e": "depthUpdate", "E": 1773485298579, "T": 1773485298576, "s": "BTCUSDT", "U": 10109441089521, "u": 10109441093927, "pu": 10109441089435, "b": [["1000.00", "28.692"], ["5000.00", "101.418"], ["7048.90", "0.000"], ["19988.60", "0.120"], ["20088.60", "2.360"], ["20091.50", "0.020"], ["20191.50", "0.060"], ["33000.00", "3.789"], ["40000.00", "41.356"], ["56396.00", "0.002"], ["66948.00", "0.004"], ["69168.50", "1.299"], ["69783.70", "0.004"], ["70136.10", "0.003"], ["70136.20", "0.071"], ["70171.30", "0.010"], ["70347.10", "0.000"], ["70441.40", "0.209"], ["70441.60", "0.965"], ["70453.40", "0.030"], ["70460.50", "0.005"], ["70468.80", "0.003"], ["70469.10", "0.000"], ["70471.70", "1.786"], ["70471.80", "1.893"], ["70473.20", "0.268"], ["70475.40", "0.206"], ["70475.80", "0.535"], ["70476.50", "0.003"], ["70477.00", "0.007"], ["70477.50", "0.004"], ["70477.70", "0.004"], ["70478.00", "0.202"], ["70478.90", "0.005"], ["70479.10", "0.114"], ["70479.20", "0.005"], ["70479.50", "0.577"], ["70479.80", "0.323"], ["70479.90", "0.000"], ["70480.00", "0.022"], ["70480.20", "0.156"], ["70480.50", "0.012"], ["70480.80", "0.008"], ["70481.40", "0.265"], ["70486.80", "0.000"], ["70487.10", "0.032"], ["70488.60", "4.974"]], "a": [["70488.70", "11.590"], ["70489.70", "0.000"], ["70491.40", "0.049"], ["70492.80", "0.021"], ["70493.70", "0.004"], ["70495.20", "0.002"], ["70496.30", "0.003"], ["70496.80", "0.007"], ["70497.70", "0.002"], ["70498.20", "0.001"], ["70498.80", "0.422"], ["70500.10", "0.018"], ["70500.40", "0.232"], ["70502.50", "0.003"], ["70503.10", "0.009"], ["70504.60", "0.004"], ["70505.00", "0.370"], ["70505.20", "0.015"], ["70506.00", "0.008"], ["70506.90", "0.007"], ["70507.30", "0.513"], ["70507.50", "1.070"], ["70507.60", "0.006"], ["70507.70", "0.630"], ["70508.30", "0.005"], ["70511.40", "0.057"], ["70515.70", "0.094"], ["70517.70", "0.021"], ["70523.90", "0.067"], ["70548.90", "0.020"], ["70549.30", "0.116"], ["70550.80", "2.685"], ["70614.40", "0.080"], ["70910.50", "0.182"], ["70912.20", "0.000"], ["71193.50", "0.000"], ["71193.60", "0.000"], ["71373.00", "0.407"], ["71475.40", "3.642"], ["73308.20", "0.004"], ["74026.60", "0.000"], ["100000.00", "23.659"]]}}
{"local_ts": 1773485300393, "server_ts": 1773485299600, "data": {"e": "depthUpdate", "E": 1773485299601, "T": 1773485299600, "s": "BTCUSDT", "U": 10109441133713, "u": 10109441137266, "pu": 10109441133611, "b": [["5000.00", "101.438"], ["7048.90", "0.000"], ["19988.60", "2.190"], ["20088.60", "0.810"], ["56396.00", "0.002"], ["66948.00", "0.002"], ["66974.90", "0.000"], ["66975.00", "0.090"], ["69588.50", "0.000"], ["70136.10", "0.003"], ["70136.30", "0.002"], ["70242.80", "0.033"], ["70308.90", "0.002"], ["70315.90", "0.004"], ["70319.40", "0.415"], ["70323.00", "0.507"], ["70343.60", "0.018"], ["70346.40", "3.421"], ["70401.80", "2.024"], ["70441.90", "0.042"], ["70442.00", "0.312"], ["70486.70", "0.040"], ["70487.60", "0.005"], ["70487.70", "0.002"]], "a": [["70489.60", "0.152"], ["70490.70", "0.059"], ["70499.70", "0.022"], ["70501.80", "0.000"], ["70505.40", "0.031"], ["70517.70", "0.021"], ["70552.10", "0.855"], ["70581.40", "1.379"], ["70587.40", "0.002"], ["70714.90", "0.009"], ["70834.10", "0.213"], ["71193.60", "0.000"], ["71475.40", "3.642"], ["71716.20", "0.831"]]}}
{"local_ts": 1773485301414, "server_ts": 1773485300620, "data": {"e": "depthUpdate", "E": 1773485300623, "T": 1773485300620, "s": "BTCUSDT", "U": 10109441192195, "u": 10109441198495, "pu": 10109441192114, "b": [["1000.00", "28.692"], ["5000.00", "101.418"], ["7048.90", "0.056"], ["19988.60", "1.260"], ["20388.60", "1.740"], ["56391.00", "0.076"], ["66964.00", "0.000"], ["69783.70", "0.004"], ["70319.40", "0.415"], ["70405.10", "0.148"], ["70405.50", "0.404"], ["70435.70", "0.085"], ["70435.80", "8.523"], ["70436.20", "0.350"], ["70441.70", "0.513"], ["70441.80", "0.004"], ["70442.30", "0.005"], ["70446.20", "0.002"], ["70452.90", "0.020"], ["70457.00", "0.064"], ["70464.80", "0.001"], ["70464.90", "0.019"], ["70468.70", "0.000"], ["70470.40", "0.002"], ["70471.70", "1.790"], ["70478.00", "0.005"], ["70481.60", "0.029"], ["70481.70", "0.000"]], "a": [["70488.70", "11.408"], ["70488.80", "0.403"], ["70495.70", "0.110"], ["70496.40", "0.007"], ["70496.80", "0.026"], ["70499.30", "0.005"], ["70500.00", "7.080"], ["70505.40", "0.033"], ["70512.00", "0.208"], ["70521.60", "0.469"], ["70535.90", "0.003"], ["70546.50", "0.007"], ["70548.20", "0.092"], ["71193.60", "1.403"], ["71685.90", "0.000"], ["74018.80", "0.004"], ["74039.60", "0.005"]]}}
{"local_ts": 1773485302437, "server_ts": 1773485301640, "data": {"e": "depthUpdate", "E": 1773485301645, "T": 1773485301640, "s": "BTCUSDT", "U": 10109441267409, "u": 10109441280041, "pu": 10109441267124, "b": [["1000.00", "28.692"], ["5000.00", "101.418"], ["7048.90", "0.056"], ["20288.50", "0.280"], ["20388.60", "1.710"], ["56391.00", "0.076"], ["69783.60", "0.000"], ["69783.70", "0.719"], ["70136.30", "0.002"], ["70190.50", "0.268"], ["70242.80", "0.033"], ["70319.40", "0.355"], ["70416.80", "0.003"], ["70418.30", "0.002"], ["70434.50", "0.137"], ["70435.80", "0.004"], ["70436.30", "2.318"], ["70437.40", "0.146"], ["70438.00", "0.845"], ["70440.70", "0.344"], ["70441.30", "0.081"], ["70441.40", "0.207"], ["70443.30", "0.003"], ["70448.40", "0.264"], ["70458.10", "0.252"], ["70458.90", "0.008"], ["70460.30", "0.029"], ["70461.70", "0.016"], ["70462.40", "0.328"], ["70464.10", "0.512"], ["70464.40", "0.000"], ["70465.00", "0.520"], ["70466.50", "0.070"], ["70467.40", "0.006"], ["70472.30", "0.259"], ["70472.50", "0.010"], ["70472.60", "0.986"], ["70473.10", "0.006"], ["70474.50", "0.072"], ["70475.80", "0.625"], ["70476.00", "0.274"], ["70477.90", "0.008"], ["70480.20", "0.153"], ["70481.10", "0.005"], ["70484.70", "0.023"], ["70488.50", "0.469"]], "a": [["70488.60", "15.545"], ["70488.70", "0.975"], ["70488.80", "0.263"], ["70488.90", "0.196"], ["70495.70", "0.110"], ["70498.60", "0.657"], ["70498.70", "0.000"], ["70499.20", "0.004"], ["70500.10", "0.018"], ["70500.30", "0.141"], ["70501.70", "0.000"], ["70501.80", "0.028"], ["70503.90", "0.038"], ["70504.30", "0.024"], ["70504.50", "0.007"], ["70504.90", "0.215"], ["70505.20", "0.022"], ["70505.30", "0.256"], ["70505.40", "0.011"], ["70505.90", "0.014"], ["70506.20", "0.102"], ["70506.70", "0.007"], ["70507.00", "0.067"], ["70507.60", "0.006"], ["70507.80", "1.143"], ["70508.20", "0.009"], ["70508.30", "1.153"], ["70508.90", "0.002"], ["70509.30", "0.000"], ["70509.80", "0.002"], ["70511.30", "0.003"], ["70511.40", "0.066"], ["70511.90", "0.070"], ["70518.50", "0.006"], ["70518.80", "0.061"], ["70519.20", "0.205"], ["70548.50", "0.081"], ["70900.00", "13.890"], ["71193.50", "0.000"], ["71898.30", "0.005"], ["73240.80", "1.093"], ["73308.10", "1.786"], ["74019.60", "0.000"], ["74043.00", "0.002"], ["100000.00", "23.620"]]}}
{"local_ts": 1773485303456, "server_ts": 1773485302662, "data": {"e": "depthUpdate", "E": 1773485302665, "T": 1773485302662, "s": "BTCUSDT", "U": 10109441332633, "u": 10109441336984, "pu": 10109441332513, "b": [["5000.00", "101.418"], ["7048.90", "0.056"], ["20188.50", "0.840"], ["20288.60", "0.170"], ["20388.70", "0.000"], ["66945.30", "0.000"], ["69078.90", "0.012"], ["69783.60", "0.000"], ["70136.00", "0.024"], ["70242.60", "0.014"], ["70353.30", "1.003"], ["70418.20", "1.239"], ["70434.50", "0.052"], ["70436.40", "0.342"], ["70440.40", "0.004"], ["70448.40", "0.260"]], "a": [["70555.40", "0.298"], ["70619.80", "0.017"], ["71193.50", "0.000"], ["71471.60", "0.000"], ["71558.60", "0.418"], ["71879.50", "0.595"], ["74018.40", "0.002"]]}}
{"local_ts": 1773485304637, "server_ts": 1773485303688, "data": {"e": "depthUpdate", "E": 1773485303689, "T": 1773485303688, "s": "BTCUSDT", "U": 10109441381811, "u": 10109441387574, "pu": 10109441381663, "b": [["1000.00", "28.692"], ["5000.00", "101.418"], ["7048.90", "0.028"], ["20088.50", "0.430"], ["20188.50", "2.550"], ["20288.50", "0.020"], ["33000.00", "3.785"], ["66930.20", "0.002"], ["66960.10", "0.000"], ["68600.00", "28.513"], ["69395.90", "7.127"], ["69452.30", "2.572"], ["69783.60", "0.000"], ["70136.10", "0.003"], ["70242.70", "0.211"], ["70353.60", "0.000"], ["70436.40", "0.257"], ["70440.40", "0.000"], ["70441.10", "0.131"], ["70441.40", "0.209"], ["70448.50", "0.007"], ["70449.70", "0.519"], ["70473.10", "0.006"], ["70473.20", "0.005"], ["70473.80", "0.639"], ["70474.00", "0.013"], ["70474.40", "0.057"], ["70476.70", "0.111"], ["70477.90", "0.008"], ["70479.10", "0.028"], ["70479.20", "0.005"], ["70479.60", "0.019"], ["70479.80", "0.001"], ["70479.90", "0.000"], ["70480.00", "0.022"], ["70480.10", "0.040"], ["70480.20", "0.210"], ["70480.30", "0.143"], ["70480.40", "0.002"], ["70480.50", "0.012"], ["70480.60", "0.000"], ["70480.80", "0.006"], ["70480.90", "0.000"], ["70481.00", "0.007"], ["70481.20", "0.003"], ["70481.40", "0.265"], ["70481.50", "0.028"], ["70481.70", "0.000"], ["70481.80", "0.004"], ["70481.90", "0.002"], ["70482.00", "0.005"], ["70482.20", "0.001"], ["70482.30", "0.000"], ["70482.40", "0.022"], ["70482.50", "0.516"], ["70482.70", "0.014"], ["70482.90", "0.001"], ["70483.10", "0.001"], ["70483.20", "0.000"], ["70483.30", "0.000"], ["70483.40", "0.008"], ["70483.50", "0.005"], ["70486.70", "0.048"], ["70487.30", "0.012"], ["70488.50", "0.763"]], "a": [["70489.60", "0.000"], ["70491.60", "0.125"], ["70492.70", "0.023"], ["70495.60", "0.232"], ["70495.90", "0.000"], ["70498.50", "0.005"], ["70499.20", "0.004"], ["70509.20", "0.000"], ["70509.70", "0.641"], ["70509.90", "0.021"], ["70619.70", "0.078"], ["70711.90", "0.007"], ["70807.20", "0.003"]]}}
{"local_ts": 1773485305705, "server_ts": 1773485304912, "data": {"e": "depthUpdate", "E": 1773485304913, "T": 1773485304912, "s": "BTCUSDT", "U": 10109441451318, "u": 10109441455108, "pu": 10109441451172, "b": [["1000.00", "28.692"], ["5000.00", "101.398"], ["7048.90", "0.028"], ["19988.50", "0.460"], ["20088.50", "2.540"], ["20188.50", "0.000"], ["63439.60", "0.026"], ["66941.30", "0.002"], ["66943.10", "0.000"], ["66975.10", "0.004"], ["69783.60", "0.000"], ["70136.10", "0.003"], ["70162.70", "0.000"], ["70242.20", "0.000"], ["70390.40", "0.187"], ["70441.70", "0.513"], ["70441.80", "0.004"], ["70469.60", "0.266"], ["70469.90", "0.034"], ["70473.10", "0.006"], ["70473.50", "0.000"], ["70474.00", "0.011"], ["70474.50", "0.067"], ["70474.80", "0.008"], ["70475.20", "0.290"], ["70478.30", "0.431"], ["70478.50", "0.015"], ["70478.90", "0.033"], ["70479.40", "0.757"], ["70479.70", "0.373"], ["70480.90", "0.012"], ["70484.40", "0.517"], ["70484.50", "1.071"], ["70484.90", "0.195"], ["70485.30", "0.008"], ["70485.60", "0.003"], ["70488.50", "2.526"]], "a": [["70488.70", "0.165"], ["70488.80", "0.258"], ["70489.60", "0.008"], ["70489.90", "0.001"], ["70491.40", "0.049"], ["70492.50", "0.007"], ["70492.80", "0.021"], ["70493.90", "0.070"], ["70495.10", "0.000"], ["70495.60", "0.213"], ["70495.80", "0.020"], ["70496.30", "0.018"], ["70497.70", "0.002"], ["70499.80", "0.002"], ["70500.10", "0.021"], ["70501.40", "0.024"], ["70506.10", "0.003"], ["70507.00", "0.063"], ["70508.80", "0.006"], ["70511.40", "0.057"], ["70512.50", "0.638"], ["70513.80", "1.087"], ["70514.10", "0.061"], ["70515.70", "0.094"], ["70516.10", "0.081"], ["70678.90", "0.003"], ["70712.40", "0.000"], ["70805.60", "0.007"], ["71052.50", "0.634"], ["71193.50", "0.000"], ["71898.30", "0.008"], ["73308.10", "1.808"], ["77537.50", "0.026"]]}}
{"local_ts": 1773485306727, "server_ts": 1773485305934, "data": {"e": "depthUpdate", "E": 1773485305935, "T": 1773485305934, "s": "BTCUSDT", "U": 10109441511903, "u": 10109441517072, "pu": 10109441511858, "b": [["5000.00", "101.418"], ["7048.90", "0.000"], ["19988.50", "2.520"], ["20088.50", "0.230"], ["20388.50", "0.250"], ["56391.00", "0.076"], ["63439.60", "0.024"], ["66949.70", "0.044"], ["66970.80", "0.000"], ["69078.80", "0.018"], ["69466.40", "13.009"], ["69783.60", "0.000"], ["69818.90", "7.680"], ["70314.90", "0.000"], ["70315.00", "0.216"], ["70355.30", "0.015"], ["70442.30", "0.005"], ["70442.40", "0.150"], ["70472.60", "0.348"], ["70477.90", "0.205"], ["70481.50", "0.596"], ["70488.10", "0.109"]], "a": [["70488.60", "5.632"], ["70495.60", "0.205"], ["70496.00", "0.001"], ["70497.90", "0.002"], ["70499.20", "0.061"], ["70499.70", "0.001"], ["70501.40", "0.003"], ["70516.50", "0.005"], ["70518.70", "0.187"], ["70525.80", "0.005"], ["70623.80", "0.093"], ["70658.00", "0.606"], ["70658.50", "0.273"], ["71193.50", "0.000"], ["71898.30", "0.014"]]}}
{"local_ts": 1773485307746, "server_ts": 1773485306954, "data": {"e": "depthUpdate", "E": 1773485306955, "T": 1773485306954, "s": "BTCUSDT", "U": 10109441562316, "u": 10109441564873, "pu": 10109441562294, "b": [["1000.00", "28.692"], ["5000.00", "101.418"], ["7048.90", "0.000"], ["19988.50", "0.530"], ["20288.50", "0.100"], ["20388.50", "2.370"], ["20388.60", "0.000"], ["63439.60", "0.024"], ["66975.00", "0.082"], ["69487.60", "0.290"], ["69642.60", "6.162"], ["69783.60", "0.000"], ["69924.60", "5.428"], ["70136.10", "0.003"], ["70200.00", "24.138"], ["70242.20", "0.000"], ["70242.60", "0.014"], ["70488.50", "4.205"]], "a": [["70488.60", "6.674"], ["70512.80", "0.004"], ["70525.80", "0.005"], ["71193.50", "0.000"], ["74044.80", "0.098"], ["77537.50", "0.024"]]}}
{"local_ts": 1773485308769, "server_ts": 1773485307972, "data": {"e": "depthUpdate", "E": 1773485307977, "T": 1773485307972, "s": "BTCUSDT", "U": 10109441597547, "u": 10109441600801, "pu": 10109441597385, "b": [["1000.00", "28.692"], ["5000.00", "101.418"], ["7048.90", "0.000"], ["20288.50", "2.120"], ["20388.50", "0.880"], ["33000.00", "3.785"], ["63439.60", "0.024"], ["66952.00", "0.000"], ["69783.60", "0.000"], ["70080.00", "0.767"], ["70080.80", "0.142"], ["70315.80", "0.003"], ["70355.30", "0.545"], ["70456.20", "0.019"], ["70476.70", "0.003"], ["70477.30", "0.073"]], "a": [["70488.60", "6.670"], ["70502.10", "0.149"], ["70507.20", "0.002"], ["70507.30", "0.023"], ["70507.40", "0.088"], ["70623.10", "0.397"], ["70623.20", "0.094"], ["70711.90", "0.000"], ["70712.10", "2.103"], ["70833.80", "0.000"], ["71193.50", "0.000"], ["74029.30", "0.002"], ["77537.50", "0.024"]]}}
{"local_ts": 1773485309788, "server_ts": 1773485308994, "data": {"e": "depthUpdate", "E": 1773485308997, "T": 1773485308994, "s": "BTCUSDT", "U": 10109441671105, "u": 10109441677717, "pu": 10109441671096, "b": [["5000.00", "101.418"], ["7048.90", "0.000"], ["20188.50", "1.670"], ["20288.50", "1.330"], ["56391.00", "0.076"], ["63439.60", "0.024"], ["66947.90", "0.000"], ["66952.00", "0.002"], ["67669.00", "1.321"], ["69255.00", "7.692"], ["69642.60", "7.308"], ["69783.60", "0.000"], ["70441.90", "0.002"], ["70442.00", "0.314"], ["70487.70", "0.002"]], "a": [["70488.60", "1.406"], ["70511.30", "0.003"], ["70512.30", "0.227"], ["70524.00", "0.015"], ["70524.20", "0.003"], ["71193.50", "0.000"], ["71492.90", "2.780"], ["71898.30", "0.014"], ["71910.60", "1.665"], ["74021.70", "0.000"], ["77537.50", "0.024"], ["89523.20", "0.000"]]}}
{"local_ts": 1773485310811, "server_ts": 1773485310016, "data": {"e": "depthUpdate", "E": 1773485310017, "T": 1773485310016, "s": "BTCUSDT", "U": 10109441796619, "u": 10109441806436, "pu": 10109441796375, "b": [["1000.00", "28.692"], ["5000.00", "101.418"], ["7049.20", "0.056"], ["20091.50", "1.210"], ["20188.50", "1.640"], ["20191.00", "0.000"], ["20191.50", "0.140"], ["33000.00", "3.789"], ["56393.00", "0.000"], ["63442.30", "0.000"], ["66965.40", "0.002"], ["68374.00", "0.006"], ["69786.60", "2.148"], ["70139.00", "0.023"], ["70318.80", "0.166"], ["70322.30", "0.130"], ["70325.30", "0.002"], ["70325.80", "0.000"], ["70442.70", "0.004"], ["70442.80", "0.086"], ["70446.20", "0.843"], ["70453.30", "0.938"], ["70460.40", "2.691"], ["70467.50", "0.847"], ["70474.60", "1.354"], ["70491.00", "0.442"], ["70491.20", "1.066"], ["70491.40", "0.352"], ["70491.50", "11.613"]], "a": [["70491.60", "0.521"], ["70495.10", "0.000"], ["70498.80", "0.164"], ["70499.00", "0.002"], ["70499.80", "0.540"], ["70503.60", "0.018"], ["70504.20", "0.002"], ["70506.90", "0.025"], ["70507.80", "1.156"], ["70508.20", "0.002"], ["70508.70", "0.003"], ["70509.30", "0.000"], ["70509.50", "0.143"], ["70509.60", "0.009"], ["70510.10", "0.015"], ["70517.20", "0.844"], ["70517.90", "0.141"], ["70518.80", "0.520"], ["70520.00", "0.027"], ["70521.00", "0.642"], ["70524.30", "0.855"], ["70524.80", "0.002"], ["70526.00", "0.534"], ["70526.10", "0.571"], ["70528.30", "0.107"], ["70531.00", "0.511"], ["70531.40", "0.869"], ["70532.10", "0.628"], ["70538.50", "0.919"], ["70545.60", "0.851"], ["70570.90", "0.000"], ["70584.90", "0.156"], ["70587.00", "0.040"], ["70608.80", "0.101"], ["70619.10", "0.004"], ["70647.00", "0.133"], ["70676.50", "0.000"], ["70676.70", "0.003"], ["70677.70", "0.016"], ["70678.40", "0.159"], ["71196.50", "0.000"], ["71419.00", "1.960"], ["71492.90", "2.502"], ["71898.30", "0.011"], ["72268.80", "0.000"], ["77540.80", "0.000"], ["89523.20", "0.000"]]}}
{"local_ts": 1773485311832, "server_ts": 1773485311036, "data": {"e": "depthUpdate", "E": 1773485311041, "T": 1773485311036, "s": "BTCUSDT", "U": 10109441887187, "u": 10109441895098, "pu": 10109441886996, "b": [["5000.00", "101.418"], ["7049.20", "0.056"], ["19991.50", "0.780"], ["20091.50", "2.210"], ["66932.60", "0.002"], ["66963.10", "0.000"], ["68374.00", "0.003"], ["68376.80", "0.005"], ["68715.10", "2.615"], ["69786.60", "2.148"], ["70323.30", "0.002"], ["70397.30", "0.000"], ["70443.50", "0.878"], ["70443.70", "0.034"], ["70461.10", "0.092"], ["70462.10", "0.028"], ["70476.00", "0.087"], ["70477.00", "0.007"], ["70478.80", "0.007"], ["70487.80", "0.056"], ["70491.50", "11.354"]], "a": [["70491.60", "0.519"], ["70494.60", "0.002"], ["70494.70", "0.213"], ["70504.00", "0.139"], ["70504.30", "0.039"], ["70505.80", "0.063"], ["70505.90", "0.000"], ["70506.10", "0.133"], ["70506.20", "0.003"], ["70506.30", "0.002"], ["70506.40", "0.000"], ["70506.60", "0.003"], ["70506.70", "0.000"], ["70506.80", "0.009"], ["70525.90", "0.009"], ["70528.30", "0.357"], ["70619.10", "0.002"], ["70633.40", "0.002"], ["70800.00", "11.768"], ["70855.60", "0.009"], ["71052.50", "0.072"], ["71196.50", "0.000"], ["71337.50", "0.470"], ["71446.70", "0.841"], ["71760.40", "0.111"], ["71901.40", "0.012"], ["72603.30", "0.004"], ["89523.20", "0.000"]]}}
{"local_ts": 1773485312853, "server_ts": 1773485312060, "data": {"e": "depthUpdate", "E": 1773485312061, "T": 1773485312060, "s": "BTCUSDT", "U": 10109441956612, "u": 10109441961701, "pu": 10109441956409, "b": [["1000.00", "28.692"], ["5000.00", "101.398"], ["7049.20", "0.056"], ["19991.50", "2.570"], ["20091.50", "0.050"], ["20391.50", "0.380"], ["66939.60", "0.002"], ["66966.00", "0.006"], ["66966.90", "0.006"], ["68376.80", "0.008"], ["69642.60", "5.445"], ["69786.60", "2.150"], ["69786.70", "0.147"], ["70139.00", "0.023"], ["70245.30", "0.000"], ["70318.80", "0.007"], ["70322.30", "0.289"], ["70323.30", "0.000"], ["70339.90", "0.198"], ["70358.10", "0.612"], ["70395.60", "0.000"], ["70402.70", "0.449"], ["70403.00", "0.796"], ["70409.70", "0.065"], ["70410.10", "0.220"], ["70417.10", "0.218"], ["70446.20", "0.843"], ["70453.30", "0.938"], ["70460.40", "2.691"], ["70461.00", "0.144"], ["70461.10", "0.001"], ["70467.50", "0.847"], ["70474.60", "1.354"], ["70478.80", "0.003"], ["70484.50", "0.065"], ["70489.80", "0.668"], ["70490.60", "0.002"], ["70491.50", "11.709"]], "a": [["70491.60", "0.525"], ["70498.60", "0.068"], ["70501.60", "0.009"], ["70504.30", "0.036"], ["70512.50", "0.057"], ["70514.60", "0.357"], ["70517.20", "0.844"], ["70518.00", "0.340"], ["70524.30", "0.855"], ["70531.40", "0.848"], ["70538.50", "0.846"], ["70545.60", "0.851"], ["70562.10", "0.263"], ["70564.80", "0.002"], ["70571.80", "0.000"], ["70573.30", "0.142"], ["70578.90", "1.527"], ["70580.30", "0.161"], ["70587.40", "0.144"], ["70619.10", "0.004"], ["70628.70", "0.585"], ["70628.80", "0.000"], ["70633.40", "0.000"], ["70678.40", "0.060"], ["70715.30", "0.000"], ["71196.50", "0.000"], ["71564.10", "0.002"], ["71666.70", "0.011"], ["72606.30", "0.006"], ["89523.20", "0.000"]]}}
{"local_ts": 1773485313879, "server_ts": 1773485313084, "data": {"e": "depthUpdate", "E": 1773485313085, "T": 1773485313084, "s": "BTCUSDT", "U": 10109442002419, "u": 10109442008196, "pu": 10109442002330, "b": [["1000.00", "28.692"], ["5000.00", "101.418"], ["7049.20", "0.028"], ["19991.50", "0.310"], ["20291.50", "0.210"], ["20391.50", "2.480"], ["56393.00", "0.000"], ["66962.40", "0.000"], ["69786.60", "2.148"], ["69794.90", "2.189"], ["70318.80", "0.007"], ["70348.50", "0.668"], ["70478.80", "0.003"]], "a": [["70498.60", "0.068"], ["70499.90", "1.114"], ["70504.30", "0.036"], ["70619.10", "0.002"], ["70619.90", "0.002"], ["70715.30", "0.000"], ["70844.10", "0.258"], ["71775.20", "0.699"], ["77540.70", "0.007"], ["89523.20", "0.000"]]}}
{"local_ts": 1773485314901, "server_ts": 1773485314108, "data": {"e": "depthUpdate", "E": 1773485314109, "T": 1773485314108, "s": "BTCUSDT", "U": 10109442058404, "u": 10109442063577, "pu": 10109442058299, "b": [["5000.00", "101.418"], ["7049.20", "0.028"], ["20191.50", "0.060"], ["20291.50", "2.340"], ["20391.50", "0.600"], ["66961.40", "0.000"], ["66963.30", "0.000"], ["66967.00", "0.150"], ["68957.30", "0.000"], ["69786.60", "2.148"], ["70442.40", "0.005"], ["70444.20", "0.496"], ["70444.30", "0.291"], ["70446.20", "0.002"], ["70453.30", "0.097"], ["70454.70", "0.013"], ["70460.40", "1.850"], ["70467.50", "0.009"], ["70474.60", "0.513"], ["70478.80", "0.003"], ["70489.80", "0.668"], ["70490.00", "0.021"], ["70491.50", "11.719"]], "a": [["70494.90", "0.000"], ["70504.30", "0.036"], ["70517.20", "0.003"], ["70524.30", "0.014"], ["70531.40", "0.007"], ["70538.50", "0.005"], ["70541.60", "0.006"], ["70545.60", "0.010"], ["70562.10", "0.344"], ["70619.90", "0.000"], ["70620.30", "0.002"], ["70678.40", "0.159"], ["70844.10", "0.258"], ["71196.50", "0.000"], ["71898.30", "0.002"], ["89523.20", "0.000"]]}}
{"local_ts": 1773485315927, "server_ts": 1773485315128, "data": {"e": "depthUpdate", "E": 1773485315129, "T": 1773485315128, "s": "BTCUSDT", "U": 10109442105807, "u": 10109442110818, "pu": 10109442105770, "b": [["1000.00", "28.692"], ["5000.00", "101.418"], ["7049.20", "0.028"], ["20191.50", "2.010"], ["20291.50", "0.990"], ["33000.00", "3.785"], ["66955.80", "0.012"], ["66966.90", "0.010"], ["66967.00", "0.152"], ["69222.70", "0.577"], ["69398.90", "1.009"], ["69469.40", "2.659"], ["69490.80", "2.580"], ["69786.60", "3.579"], ["69821.80", "0.714"], ["70139.00", "0.059"], ["70177.40", "0.000"], ["70245.50", "0.004"], ["70423.80", "0.000"], ["70447.40", "1.587"], ["70456.70", "0.000"], ["70477.40", "0.028"], ["70478.00", "0.005"], ["70478.80", "0.003"], ["70482.20", "0.000"], ["70484.40", "0.596"], ["70484.50", "0.065"], ["70490.00", "0.019"], ["70490.90", "0.004"], ["70491.50", "12.018"]], "a": [["70498.60", "0.087"], ["70504.30", "0.036"], ["70513.50", "0.003"], ["70526.00", "0.286"], ["70528.20", "0.000"], ["70528.30", "0.355"], ["70529.90", "0.145"], ["70537.20", "0.205"], ["70561.10", "0.016"], ["71053.30", "0.002"], ["71059.80", "4.447"], ["71064.00", "0.354"], ["71196.50", "0.000"], ["71522.20", "22.411"], ["72269.10", "0.000"], ["74019.30", "0.000"], ["74038.60", "0.000"], ["89523.20", "0.000"]]}}
{"local_ts": 1773485316947, "server_ts": 1773485316152, "data": {"e": "depthUpdate", "E": 1773485316153, "T": 1773485316152, "s": "BTCUSDT", "U": 10109442156914, "u": 10109442161240, "pu": 10109442156891, "b": [["5000.00", "101.438"], ["7049.20", "0.000"], ["20091.50", "1.570"], ["20191.50", "1.430"], ["69081.70", "0.012"], ["69486.90", "2.890"], ["69653.90", "0.717"], ["69786.60", "3.579"], ["70308.20", "0.000"], ["70315.30", "0.159"], ["70406.00", "6.556"], ["70409.40", "1.904"], ["70415.90", "0.000"], ["70416.10", "0.005"], ["70423.90", "0.000"], ["70424.10", "0.005"], ["70431.90", "0.792"], ["70432.00", "0.019"], ["70439.90", "0.000"], ["70440.10", "0.005"], ["70441.40", "3.590"], ["70444.10", "0.362"], ["70444.20", "0.496"], ["70447.40", "1.587"], ["70447.80", "0.005"], ["70447.90", "0.389"], ["70456.70", "0.000"], ["70463.00", "1.804"], ["70465.10", "0.927"], ["70474.70", "0.070"], ["70475.60", "0.057"], ["70476.30", "0.070"], ["70476.70", "0.513"], ["70477.10", "0.000"], ["70477.80", "0.000"], ["70478.80", "0.003"], ["70489.80", "0.670"], ["70490.00", "0.019"], ["70490.70", "0.038"], ["70490.90", "0.002"], ["70491.50", "10.815"]], "a": [["70495.40", "0.010"], ["70495.50", "0.099"], ["70498.60", "0.196"], ["70498.70", "0.008"], ["70501.30", "0.006"], ["70501.70", "0.000"], ["70504.30", "0.036"], ["70510.50", "0.059"], ["70511.90", "0.000"], ["70513.40", "0.023"], ["70513.90", "0.004"], ["70514.10", "0.009"], ["70520.50", "0.517"], ["70521.00", "0.005"], ["70521.40", "0.003"], ["70521.70", "0.637"], ["70521.90", "0.000"], ["70522.10", "0.010"], ["70522.50", "0.070"], ["70523.20", "0.004"], ["70526.00", "0.534"], ["70528.30", "0.107"], ["70530.00", "0.189"], ["70530.10", "0.030"], ["70534.80", "1.870"], ["70537.40", "0.000"], ["70538.00", "0.051"], ["70538.10", "7.809"], ["70545.90", "0.003"], ["70546.10", "0.314"], ["70548.10", "0.063"], ["70553.20", "1.168"], ["70556.40", "0.159"], ["70556.50", "3.581"], ["70592.30", "2.613"], ["70592.40", "6.894"], ["70592.90", "0.003"], ["70678.40", "0.159"], ["71196.50", "0.000"], ["71513.70", "6.423"], ["71522.20", "19.479"], ["71654.70", "0.979"], ["74016.50", "0.002"], ["74026.70", "0.000"], ["89523.20", "0.000"]]}}
{"local_ts": 1773485317967, "server_ts": 1773485317172, "data": {"e": "depthUpdate", "E": 1773485317175, "T": 1773485317172, "s": "BTCUSDT", "U": 10109442209024, "u": 10109442216816, "pu": 10109442208716, "b": [["1000.00", "28.692"], ["5000.00", "101.418"], ["7049.50", "0.000"], ["19994.70", "1.120"], ["20091.50", "1.320"], ["20094.70", "0.540"], ["33000.00", "3.785"], ["69268.60", "0.004"], ["69469.40", "7.545"], ["69789.80", "0.000"], ["70142.20", "0.000"], ["70438.70", "0.287"], ["70446.20", "0.002"], ["70453.30", "0.068"], ["70460.40", "1.853"], ["70461.20", "0.444"], ["70464.00", "0.217"], ["70467.50", "0.009"], ["70470.80", "0.000"], ["70473.30", "0.248"], ["70474.60", "0.513"], ["70477.60", "1.080"], ["70482.50", "0.000"], ["70484.10", "0.005"], ["70485.90", "0.283"], ["70487.00", "0.003"], ["70487.80", "0.658"], ["70490.60", "0.003"], ["70492.60", "1.620"], ["70494.50", "0.069"], ["70494.70", "13.349"]], "a": [["70498.50", "0.031"], ["70498.80", "0.076"], ["70505.40", "0.003"], ["70517.20", "0.003"], ["70522.30", "0.019"], ["70523.10", "0.637"], ["70524.30", "0.014"], ["70531.40", "0.007"], ["70538.50", "0.005"], ["70545.60", "0.010"], ["70556.30", "0.085"], ["70556.40", "0.258"], ["70558.60", "0.321"], ["70561.80", "0.255"], ["71199.70", "0.016"], ["71522.20", "15.570"], ["74034.30", "0.002"], ["89523.20", "0.000"]]}}
{"local_ts": 1773485318987, "server_ts": 1773485318194, "data": {"e": "depthUpdate", "E": 1773485318195, "T": 1773485318194, "s": "BTCUSDT", "U": 10109442263541, "u": 10109442276733, "pu": 10109442263479, "b": [["5000.00", "101.418"], ["7049.50", "0.000"], ["19994.70", "2.330"], ["19994.90", "0.000"], ["19995.50", "0.000"], ["20091.50", "0.000"], ["20394.70", "0.440"], ["20395.10", "0.010"], ["20395.30", "0.010"], ["20395.50", "0.010"], ["20395.60", "0.010"], ["20395.90", "0.190"], ["66939.60", "0.000"], ["66947.20", "0.000"], ["66950.20", "0.002"], ["67676.10", "0.002"], ["69081.70", "0.006"], ["69085.10", "0.003"], ["69488.70", "0.000"], ["69490.30", "0.000"], ["69490.80", "2.574"], ["69491.00", "0.000"], ["69491.50", "0.000"], ["69492.60", "0.002"], ["69494.60", "0.071"], ["69494.70", "0.004"], ["69494.90", "0.000"], ["69495.10", "0.039"], ["69495.50", "0.734"], ["69495.60", "0.002"], ["69495.90", "0.020"], ["69499.90", "0.021"], ["69500.70", "0.431"], ["69789.80", "0.000"], ["69790.00", "0.113"], ["69790.10", "3.405"], ["69790.30", "0.638"], ["69790.50", "0.003"], ["69790.60", "0.000"], ["69790.90", "0.000"], ["70116.40", "0.000"], ["70294.40", "0.004"], ["70295.80", "1.867"], ["70296.40", "0.003"], ["70297.10", "0.389"], ["70322.00", "1.051"], ["70322.20", "3.609"], ["70323.20", "0.159"], ["70325.90", "0.003"], ["70333.20", "0.000"], ["70336.70", "0.870"], ["70336.90", "0.000"], ["70340.40", "0.096"], ["70340.50", "0.511"], ["70343.10", "0.002"], ["70343.30", "0.182"], ["70344.00", "0.005"], ["70346.90", "0.002"], ["70347.90", "0.198"], ["70350.60", "0.170"], ["70360.70", "0.005"], ["70360.80", "0.015"], ["70361.40", "0.096"], ["70361.60", "0.106"], ["70365.10", "0.046"], ["70365.20", "0.000"], ["70365.50", "0.211"], ["70369.00", "0.742"], ["70386.30", "0.206"], ["70396.20", "0.000"], ["70399.40", "0.017"], ["70402.50", "0.210"], ["70407.40", "0.480"], ["70407.50", "0.273"], ["70407.80", "0.164"], ["70410.10", "0.220"], ["70422.20", "0.133"], ["70423.20", "0.088"], ["70423.60", "1.921"], ["70423.70", "0.003"], ["70424.50", "0.006"], ["70428.50", "0.163"], ["70437.30", "0.007"], ["70438.00", "0.842"], ["70439.10", "0.000"], ["70439.50", "0.014"], ["70441.30", "3.500"], ["70441.40", "0.204"], ["70442.00", "0.001"], ["70445.40", "8.518"], ["70445.50", "0.000"], ["70445.60", "0.000"], ["70446.40", "0.000"], ["70446.60", "0.097"], ["70447.00", "0.113"], ["70447.10", "0.003"], ["70447.30", "0.008"], ["70447.50", "1.745"], ["70447.60", "0.003"], ["70447.70", "0.003"], ["70447.80", "0.005"], ["70447.90", "0.387"], ["70449.10", "0.000"], ["70452.40", "1.153"], ["70452.60", "0.002"], ["70453.60", "1.399"], ["70454.20", "0.016"], ["70454.90", "0.003"], ["70456.10", "0.122"], ["70456.20", "0.017"], ["70456.30", "0.075"], ["70456.40", "0.145"], ["70457.10", "0.035"], ["70457.20", "0.011"], ["70458.50", "0.114"], ["70458.90", "0.000"], ["70459.00", "0.100"], ["70459.80", "0.006"], ["70460.40", "1.314"], ["70461.20", "0.032"], ["70461.70", "0.014"], ["70462.80", "0.342"], ["70463.00", "1.858"], ["70463.30", "0.132"], ["70464.00", "0.214"], ["70464.40", "0.550"], ["70464.60", "0.090"], ["70464.70", "0.002"], ["70464.80", "0.821"], ["70466.50", "0.042"], ["70467.70", "0.622"], ["70467.90", "0.068"], ["70468.00", "0.005"], ["70469.10", "0.002"], ["70470.20", "0.188"], ["70470.30", "0.005"], ["70470.60", "0.022"], ["70470.80", "0.000"], ["70471.80", "1.334"], ["70471.90", "0.057"], ["70472.00", "0.197"], ["70472.50", "0.012"], ["70472.70", "0.250"], ["70473.00", "0.111"], ["70473.50", "0.002"], ["70473.60", "0.039"], ["70473.70", "0.003"], ["70473.80", "0.001"], ["70473.90", "0.015"], ["70474.10", "0.000"], ["70474.30", "0.052"], ["70474.40", "0.145"], ["70474.70", "0.002"], ["70475.30", "0.009"], ["70476.40", "0.000"], ["70476.60", "0.142"], ["70476.90", "0.019"], ["70477.10", "0.000"], ["70477.40", "0.028"], ["70477.80", "0.000"], ["70477.90", "0.019"], ["70478.40", "0.415"], ["70478.80", "0.520"], ["70479.60", "0.004"], ["70479.80", "0.002"], ["70479.90", "0.000"], ["70480.50", "1.208"], ["70480.60", "0.007"], ["70481.40", "0.667"], ["70481.60", "0.007"], ["70481.80", "0.083"], ["70482.20", "0.009"], ["70482.60", "0.492"], ["70483.40", "0.007"], ["70484.00", "0.269"], ["70484.10", "0.002"], ["70484.20", "0.000"], ["70484.30", "0.345"], ["70484.70", "0.294"], ["70484.90", "0.697"], ["70485.00", "0.008"], ["70485.30", "0.007"], ["70485.50", "0.012"], ["70485.60", "0.006"], ["70485.80", "0.011"], ["70485.90", "0.000"], ["70486.00", "0.012"], ["70486.10", "0.009"], ["70486.20", "0.656"], ["70486.60", "0.014"], ["70486.70", "0.048"], ["70487.10", "0.003"], ["70487.20", "0.220"], ["70487.30", "0.012"], ["70487.40", "0.287"], ["70487.50", "0.044"], ["70487.60", "0.060"], ["70487.70", "0.003"], ["70487.80", "0.006"], ["70488.00", "0.032"], ["70488.10", "0.053"], ["70488.30", "0.003"], ["70488.40", "0.008"], ["70488.50", "0.104"], ["70489.00", "0.007"], ["70489.10", "0.011"], ["70489.50", "0.004"], ["70489.80", "0.640"], ["70489.90", "0.009"], ["70490.40", "0.003"], ["70491.50", "0.097"], ["70491.60", "0.006"], ["70491.70", "0.003"], ["70492.00", "0.001"], ["70492.20", "0.001"], ["70492.50", "0.022"], ["70492.60", "0.520"], ["70492.80", "0.726"], ["70493.40", "0.001"], ["70493.50", "0.007"], ["70493.60", "0.014"], ["70493.80", "0.027"], ["70494.10", "0.003"], ["70494.50", "0.065"], ["70494.60", "0.221"], ["70494.70", "1.134"], ["70494.80", "0.043"], ["70494.90", "0.000"], ["70495.00", "0.003"], ["70495.10", "0.000"], ["70495.20", "0.000"], ["70495.30", "0.003"], ["70495.40", "0.000"], ["70495.50", "0.002"], ["70495.60", "0.134"], ["70495.70", "1.653"], ["70495.80", "0.000"], ["70495.90", "8.082"]], "a": [["70494.80", "0.000"], ["70495.00", "0.000"], ["70495.10", "0.000"], ["70495.20", "0.000"], ["70495.40", "0.000"], ["70495.60", "0.000"], ["70495.70", "0.000"], ["70495.90", "0.000"], ["70496.00", "1.053"], ["70496.20", "0.002"], ["70496.30", "0.001"], ["70496.80", "0.000"], ["70497.40", "0.002"], ["70497.70", "0.004"], ["70497.80", "0.216"], ["70498.00", "0.000"], ["70498.30", "0.000"], ["70498.50", "0.029"], ["70498.60", "0.002"], ["70498.80", "0.006"], ["70499.60", "0.153"], ["70499.90", "0.131"], ["70500.00", "7.080"], ["70500.20", "0.009"], ["70500.50", "0.006"], ["70500.90", "0.103"], ["70501.20", "0.025"], ["70501.60", "0.029"], ["70501.80", "0.000"], ["70502.30", "0.002"], ["70502.50", "0.004"], ["70502.70", "0.001"], ["70502.80", "0.014"], ["70503.20", "0.001"], ["70503.80", "0.036"], ["70503.90", "0.003"], ["70505.40", "0.000"], ["70505.60", "0.004"], ["70505.80", "0.135"], ["70506.00", "0.008"], ["70506.20", "0.190"], ["70506.60", "0.006"], ["70506.80", "0.009"], ["70506.90", "0.019"], ["70507.40", "0.000"], ["70507.70", "0.367"], ["70508.70", "0.000"], ["70508.80", "0.056"], ["70509.10", "0.023"], ["70509.20", "0.000"], ["70509.80", "0.003"], ["70509.90", "0.000"], ["70510.00", "0.037"], ["70510.10", "0.032"], ["70510.20", "0.000"], ["70510.30", "0.003"], ["70510.50", "0.059"], ["70510.80", "0.000"], ["70510.90", "0.023"], ["70511.00", "0.037"], ["70511.10", "0.345"], ["70511.20", "0.089"], ["70511.30", "0.003"], ["70511.50", "0.009"], ["70511.70", "0.000"], ["70511.90", "0.003"], ["70512.30", "0.006"], ["70512.60", "0.031"], ["70512.70", "0.032"], ["70513.00", "0.347"], ["70513.10", "0.005"], ["70513.30", "0.000"], ["70513.60", "0.515"], ["70513.70", "1.068"], ["70514.30", "0.060"], ["70514.80", "0.002"], ["70515.20", "0.006"], ["70515.30", "0.033"], ["70515.40", "0.035"], ["70515.50", "0.208"], ["70515.70", "0.008"], ["70515.80", "0.003"], ["70517.30", "0.021"], ["70518.00", "0.166"], ["70518.90", "0.975"], ["70519.10", "0.003"], ["70520.20", "0.141"], ["70520.50", "0.000"], ["70521.40", "0.003"], ["70521.50", "0.937"], ["70521.80", "0.013"], ["70521.90", "0.040"], ["70522.70", "0.271"], ["70523.20", "0.004"], ["70523.40", "0.639"], ["70523.80", "0.515"], ["70523.90", "0.002"], ["70524.80", "0.072"], ["70525.00", "1.023"], ["70525.50", "0.024"], ["70526.10", "0.641"], ["70526.60", "0.000"], ["70528.20", "0.000"], ["70529.40", "0.261"], ["70529.90", "0.084"], ["70530.10", "0.030"], ["70530.70", "0.224"], ["70531.40", "0.007"], ["70534.00", "0.085"], ["70534.50", "0.004"], ["70538.00", "0.023"], ["70538.30", "0.002"], ["70539.80", "0.149"], ["70540.00", "0.022"], ["70540.50", "0.032"], ["70541.00", "0.059"], ["70541.50", "0.002"], ["70541.60", "0.000"], ["70542.10", "0.063"], ["70543.20", "0.005"], ["70545.40", "0.019"], ["70549.80", "0.085"], ["70551.90", "0.004"], ["70553.00", "0.031"], ["70556.20", "0.033"], ["70556.30", "0.000"], ["70556.50", "0.000"], ["70556.80", "0.307"], ["70557.10", "3.402"], ["70558.20", "0.534"], ["70562.00", "0.081"], ["70562.20", "0.160"], ["70562.40", "0.000"], ["70562.60", "0.000"], ["70562.70", "0.000"], ["70563.00", "0.081"], ["70563.20", "0.002"], ["70564.30", "0.070"], ["70564.70", "0.009"], ["70565.40", "0.005"], ["70568.60", "0.059"], ["70570.20", "0.002"], ["70571.70", "0.356"], ["70577.20", "0.071"], ["70578.70", "0.027"], ["70581.10", "0.131"], ["70582.20", "0.009"], ["70583.50", "0.003"], ["70584.20", "0.114"], ["70585.70", "0.395"], ["70587.40", "0.009"], ["70591.20", "1.066"], ["70592.70", "0.012"], ["70597.00", "0.552"], ["70597.10", "2.004"], ["70598.20", "0.123"], ["70599.70", "0.053"], ["70605.20", "0.000"], ["70606.70", "0.489"], ["70608.70", "0.207"], ["70613.70", "0.085"], ["70678.30", "0.159"], ["70678.50", "0.171"], ["70678.70", "0.123"], ["70702.40", "0.003"], ["70705.90", "0.000"], ["70815.60", "0.000"], ["70815.80", "0.213"], ["71199.70", "0.039"], ["71199.90", "0.140"], ["71200.20", "0.002"], ["71200.40", "0.019"], ["71200.60", "0.000"], ["71200.70", "0.002"], ["71201.00", "0.014"], ["71905.50", "0.003"], ["89523.20", "0.000"]]}}
{"local_ts": 1773485320013, "server_ts": 1773485319218, "data": {"e": "depthUpdate", "E": 1773485319219, "T": 1773485319218, "s": "BTCUSDT", "U": 10109442308212, "u": 10109442312206, "pu": 10109442308197, "b": [["1000.00", "28.692"], ["5000.00", "101.418"], ["7049.60", "0.056"], ["19994.70", "0.090"], ["20295.90", "0.320"], ["20395.90", "2.110"], ["33000.00", "3.789"], ["56397.00", "0.000"], ["69424.90", "1.857"], ["69789.80", "0.716"], ["69790.90", "0.000"], ["70142.20", "0.036"], ["70400.80", "0.550"], ["70407.90", "0.000"], ["70414.90", "0.014"], ["70424.30", "0.049"], ["70425.10", "0.010"], ["70427.10", "1.231"], ["70449.30", "0.005"], ["70449.40", "0.009"], ["70456.10", "0.207"], ["70470.20", "0.004"], ["70471.90", "0.326"], ["70472.00", "0.013"]], "a": [["70529.70", "0.002"], ["70537.60", "0.004"], ["70539.60", "0.010"], ["70546.60", "0.022"], ["70549.80", "0.000"], ["70553.60", "0.007"], ["70556.70", "0.172"], ["70556.80", "0.222"], ["70560.60", "0.045"], ["70564.70", "0.002"], ["70567.60", "0.007"], ["70571.70", "0.349"], ["70574.60", "0.007"], ["70577.20", "0.000"], ["70578.70", "0.020"], ["70581.60", "0.023"], ["70584.20", "0.043"], ["70585.70", "0.388"], ["70588.60", "0.007"], ["70591.30", "0.511"], ["70592.70", "0.005"], ["70594.20", "0.000"], ["70595.80", "0.045"], ["70599.60", "0.803"], ["70599.70", "0.046"], ["70603.40", "0.000"], ["70606.70", "0.482"], ["70607.50", "0.160"], ["70610.20", "0.159"], ["70612.20", "0.554"], ["70613.70", "0.078"], ["70614.00", "0.094"], ["70679.30", "0.159"], ["70815.80", "0.002"], ["71201.00", "0.715"], ["71610.00", "0.288"], ["71694.50", "0.002"], ["72623.20", "3.299"], ["74023.60", "0.000"], ["74034.90", "0.002"]]}}
{"local_ts": 1773485321032, "server_ts": 1773485320240, "data": {"e": "depthUpdate", "E": 1773485320241, "T": 1773485320240, "s": "BTCUSDT", "U": 10109442349959, "u": 10109442354216, "pu": 10109442349831, "b": [["1000.00", "28.692"], ["5000.00", "101.418"], ["7049.60", "0.056"], ["20195.90", "0.170"], ["20295.90", "2.450"], ["20395.90", "0.300"], ["66937.40", "0.002"], ["69649.90", "0.143"], ["69790.90", "0.000"], ["69928.50", "0.144"], ["70143.40", "0.000"], ["70249.80", "0.004"], ["70405.10", "0.000"], ["70406.40", "0.314"], ["70411.90", "0.297"], ["70413.30", "0.002"], ["70413.70", "0.004"], ["70414.00", "0.005"], ["70414.40", "0.530"], ["70414.70", "0.000"], ["70415.10", "0.000"], ["70432.40", "0.079"], ["70433.20", "0.000"], ["70437.00", "0.001"], ["70437.80", "0.005"], ["70438.20", "0.000"], ["70438.50", "0.079"], ["70438.90", "0.002"], ["70439.20", "0.003"], ["70439.60", "0.010"], ["70461.60", "0.217"], ["70461.90", "0.005"], ["70462.60", "0.000"], ["70467.00", "0.116"], ["70473.00", "0.467"], ["70474.40", "0.031"], ["70474.80", "0.140"], ["70485.30", "0.007"], ["70486.80", "0.524"], ["70486.90", "0.001"], ["70487.20", "0.000"], ["70487.50", "0.001"], ["70487.60", "0.002"], ["70487.90", "0.001"], ["70488.20", "0.000"], ["70488.60", "0.064"], ["70491.80", "0.003"]], "a": [["70498.20", "0.057"], ["70504.00", "0.011"], ["70504.30", "0.095"], ["70504.40", "0.049"], ["70504.70", "0.068"], ["70505.10", "0.003"], ["70505.50", "0.007"], ["70505.80", "0.002"], ["70506.10", "0.000"], ["70506.20", "0.010"], ["70506.60", "0.003"], ["70528.90", "0.010"], ["70529.20", "0.317"], ["70529.60", "0.002"], ["70530.00", "0.132"], ["70530.30", "0.004"], ["70530.70", "0.044"], ["70530.90", "0.006"], ["70533.00", "0.021"], ["70533.20", "0.002"], ["70539.60", "0.003"], ["70546.60", "0.015"], ["70547.50", "0.008"], ["70553.40", "0.005"], ["70553.60", "0.000"], ["70553.80", "0.050"], ["70554.10", "0.002"], ["70554.50", "0.009"], ["70554.80", "0.000"], ["70555.20", "0.086"], ["70556.00", "0.043"], ["70556.70", "0.271"], ["70559.80", "0.031"], ["70560.60", "0.002"], ["70561.50", "0.007"], ["70563.00", "0.081"], ["70567.60", "0.000"], ["70568.50", "0.349"], ["70574.60", "0.000"], ["70575.50", "0.099"], ["70581.60", "0.016"], ["70582.50", "0.007"], ["70588.60", "0.000"], ["70589.50", "0.009"], ["70596.50", "0.007"], ["71201.00", "0.715"], ["71492.90", "2.224"], ["74034.10", "0.000"]]}}
{"local_ts": 1773485322054, "server_ts": 1773485321256, "data": {"e": "depthUpdate", "E": 1773485321261, "T": 1773485321256, "s": "BTCUSDT", "U": 10109442387723, "u": 10109442390811, "pu": 10109442387656, "b": [["5000.00", "101.418"], ["7049.60", "0.056"], ["20095.90", "0.020"], ["20195.90", "2.290"], ["20295.90", "0.690"], ["66965.80", "0.000"], ["66971.00", "0.003"], ["69790.90", "0.000"], ["69966.10", "1.430"], ["70340.80", "0.041"], ["70400.80", "0.568"], ["70407.90", "0.071"], ["70414.90", "0.125"], ["70448.80", "0.843"], ["70448.90", "0.274"], ["70473.10", "0.190"], ["70485.30", "0.010"], ["70488.20", "0.003"]], "a": [["70496.00", "2.259"], ["70506.40", "0.021"], ["70506.60", "0.006"], ["70508.40", "1.080"], ["70509.50", "0.001"], ["70515.50", "0.158"], ["70530.00", "0.153"], ["70537.60", "0.004"], ["70547.50", "0.001"], ["70553.70", "0.013"], ["70554.50", "0.027"], ["70554.80", "0.065"], ["70560.70", "0.007"], ["70561.50", "0.000"], ["70567.70", "0.007"], ["70568.50", "0.342"], ["70574.70", "1.073"], ["70575.50", "0.092"], ["70577.20", "0.071"], ["70581.70", "0.007"], ["70582.50", "0.000"], ["70584.20", "0.114"], ["70588.70", "0.007"], ["70589.50", "0.002"], ["70591.30", "0.582"], ["70595.70", "0.007"], ["70596.50", "0.000"], ["70602.60", "0.000"], ["70602.70", "0.283"], ["70614.00", "0.175"], ["71201.00", "2.117"], ["71412.40", "0.839"], ["71813.30", "0.013"]]}}
{"local_ts": 1773485323074, "server_ts": 1773485322282, "data": {"e": "depthUpdate", "E": 1773485322283, "T": 1773485322282, "s": "BTCUSDT", "U": 10109442425956, "u": 10109442430013, "pu": 10109442425887, "b": [["1000.00", "28.692"], ["5000.00", "101.418"], ["7049.60", "0.028"], ["20095.90", "1.890"], ["20195.90", "1.110"], ["66971.10", "0.004"], ["69558.40", "0.718"], ["69786.20", "0.002"], ["69790.90", "0.000"], ["69946.30", "0.000"], ["70143.40", "0.036"], ["70447.00", "0.002"], ["70448.90", "0.274"], ["70449.20", "0.005"], ["70472.70", "0.186"], ["70480.00", "0.131"], ["70494.80", "0.046"], ["70495.00", "0.003"], ["70495.80", "0.225"]], "a": [["70496.00", "2.213"], ["70498.20", "0.000"], ["70501.20", "0.028"], ["70539.20", "0.007"], ["70546.20", "0.225"], ["70553.20", "0.749"], ["70553.70", "0.006"], ["70560.20", "0.013"], ["70560.70", "0.000"], ["70567.20", "0.244"], ["70567.70", "0.000"], ["70574.20", "0.011"], ["70574.70", "1.066"], ["70581.20", "0.025"], ["70581.70", "0.000"], ["70588.20", "0.007"], ["70588.70", "0.000"], ["70595.70", "0.000"], ["70602.70", "0.276"], ["71053.40", "0.000"], ["71053.50", "0.077"], ["71059.80", "4.447"], ["71201.00", "2.117"], ["71217.00", "0.000"], ["71481.70", "0.145"], ["71588.70", "1.953"], ["74025.80", "0.031"], ["74032.50", "0.002"]]}}
{"local_ts": 1773485324099, "server_ts": 1773485323305, "data": {"e": "depthUpdate", "E": 1773485323307, "T": 1773485323305, "s": "BTCUSDT", "U": 10109442468883, "u": 10109442471824, "pu": 10109442468833, "b": [["5000.00", "101.418"], ["7049.60", "0.028"], ["19995.90", "1.450"], ["20095.90", "1.550"], ["66955.70", "0.000"], ["67675.50", "0.060"], ["69490.90", "0.000"], ["69726.80", "0.715"], ["69790.90", "0.000"], ["69903.70", "0.068"], ["70167.40", "11.076"], ["70179.30", "0.662"], ["70242.10", "0.034"], ["70249.80", "0.004"], ["70316.10", "0.162"], ["70333.80", "0.043"], ["70347.00", "0.092"], ["70349.60", "0.366"], ["70400.80", "0.568"], ["70405.80", "0.047"], ["70405.90", "1.591"], ["70407.90", "0.071"], ["70414.90", "0.125"], ["70430.70", "0.734"], ["70441.30", "0.082"], ["70444.20", "0.494"], ["70456.20", "0.201"], ["70463.00", "0.024"], ["70471.90", "0.057"], ["70474.80", "0.004"], ["70488.90", "0.071"]], "a": [["70496.00", "2.220"], ["70503.00", "0.039"], ["70527.80", "0.710"], ["70535.30", "0.087"], ["70545.80", "0.001"], ["70556.80", "0.123"], ["70557.00", "0.856"], ["70559.80", "0.215"], ["70563.00", "0.081"], ["70577.20", "0.071"], ["70584.20", "0.114"], ["70591.30", "0.582"], ["70592.50", "1.584"], ["70606.90", "0.360"], ["70651.50", "1.220"], ["70742.40", "5.918"], ["70820.20", "0.648"], ["70844.90", "3.255"], ["70926.50", "3.240"], ["70999.90", "0.000"], ["71059.80", "1.207"], ["71201.00", "2.117"], ["74056.00", "0.072"]]}}
{"local_ts": 1773485325123, "server_ts": 1773485324328, "data": {"e": "depthUpdate", "E": 1773485324331, "T": 1773485324328, "s": "BTCUSDT", "U": 10109442535394, "u": 10109442552292, "pu": 10109442535302, "b": [["1000.00", "28.692"], ["5000.00", "101.418"], ["7049.60", "0.028"], ["19995.90", "1.990"], ["20395.90", "1.010"], ["33000.00", "3.785"], ["66951.00", "0.004"], ["69084.90", "0.004"], ["69086.00", "0.303"], ["69262.20", "1.154"], ["69790.90", "0.000"], ["70284.50", "4.903"], ["70400.80", "0.550"], ["70400.90", "0.018"], ["70407.90", "0.000"], ["70408.00", "0.235"], ["70414.90", "0.054"], ["70415.00", "0.073"], ["70418.30", "0.002"], ["70432.40", "0.079"], ["70449.30", "0.005"], ["70449.50", "0.099"], ["70451.20", "0.000"], ["70470.20", "0.072"], ["70473.00", "0.606"], ["70474.70", "0.054"], ["70476.60", "0.001"], ["70485.30", "0.227"], ["70486.70", "0.442"], ["70487.60", "0.016"], ["70488.10", "0.090"], ["70488.80", "0.003"], ["70488.90", "0.071"], ["70489.00", "1.030"], ["70489.80", "0.636"], ["70491.50", "0.026"], ["70493.80", "0.004"], ["70494.20", "0.003"], ["70495.50", "0.012"], ["70495.80", "0.061"], ["70495.90", "6.890"]], "a": [["70496.00", "0.119"], ["70500.30", "0.214"], ["70500.60", "0.111"], ["70501.20", "0.023"], ["70501.40", "0.003"], ["70503.00", "0.032"], ["70506.60", "0.006"], ["70509.40", "0.000"], ["70514.90", "0.004"], ["70516.60", "0.595"], ["70518.50", "0.108"], ["70518.60", "0.347"], ["70518.70", "0.003"], ["70519.40", "0.005"], ["70524.30", "0.653"], ["70526.20", "0.046"], ["70529.40", "0.261"], ["70531.10", "0.990"], ["70531.20", "0.063"], ["70532.00", "0.006"], ["70556.40", "0.074"], ["70559.50", "0.041"], ["70560.30", "0.000"], ["70563.50", "0.225"], ["70573.60", "0.000"], ["70577.20", "0.000"], ["70577.30", "0.178"], ["70584.20", "0.043"], ["70584.30", "0.075"], ["70587.00", "0.042"], ["70591.30", "0.511"], ["70591.40", "0.148"], ["70719.50", "0.000"], ["70719.70", "0.000"], ["70807.50", "0.000"], ["70808.40", "10.007"], ["70815.80", "0.009"], ["70840.80", "0.005"], ["71201.00", "2.117"], ["71905.90", "0.086"]]}}
{"local_ts": 1773485326147, "server_ts": 1773485325353, "data": {"e": "depthUpdate", "E": 1773485325355, "T": 1773485325353, "s": "BTCUSDT", "U": 10109442663477, "u": 10109442671643, "pu": 10109442663324, "b": [["1000.00", "28.692"], ["5000.00", "101.418"], ["7049.60", "0.000"], ["19995.90", "0.000"], ["20295.90", "0.570"], ["20395.90", "2.430"], ["66966.40", "0.000"], ["69790.90", "1.431"], ["70135.10", "0.010"], ["70136.30", "19.394"], ["70136.40", "3.053"], ["70143.40", "0.036"], ["70400.90", "0.018"], ["70404.90", "0.000"], ["70406.30", "0.201"], ["70408.00", "0.235"], ["70411.80", "0.087"], ["70413.20", "0.094"], ["70413.50", "0.000"], ["70413.80", "0.269"], ["70413.90", "0.084"], ["70414.20", "0.042"], ["70414.60", "0.080"], ["70414.90", "0.014"], ["70415.00", "0.073"], ["70432.30", "0.009"], ["70433.10", "0.000"], ["70436.90", "0.000"], ["70437.70", "0.000"], ["70438.00", "0.842"], ["70438.30", "0.053"], ["70438.40", "0.002"], ["70438.70", "0.004"], ["70439.10", "0.000"], ["70439.40", "0.000"], ["70472.70", "0.186"], ["70473.00", "0.467"], ["70473.60", "0.124"], ["70486.00", "0.016"], ["70486.70", "0.048"], ["70487.00", "0.000"], ["70487.10", "0.008"], ["70487.40", "0.004"], ["70487.70", "0.004"], ["70487.80", "0.006"], ["70488.10", "0.049"], ["70488.50", "0.104"], ["70489.00", "0.392"], ["70489.30", "0.650"], ["70490.20", "0.002"], ["70491.10", "0.022"], ["70495.40", "0.010"]], "a": [["70496.00", "0.119"], ["70498.00", "0.004"], ["70499.50", "0.141"], ["70500.30", "0.214"], ["70503.10", "0.002"], ["70505.10", "0.000"], ["70505.50", "0.007"], ["70505.80", "0.002"], ["70506.20", "0.010"], ["70506.50", "0.003"], ["70506.90", "0.007"], ["70513.10", "0.159"], ["70515.70", "0.010"], ["70517.10", "0.141"], ["70524.20", "0.003"], ["70525.30", "0.510"], ["70525.50", "0.024"], ["70526.50", "0.070"], ["70529.40", "0.034"], ["70529.60", "0.002"], ["70530.00", "0.132"], ["70530.30", "0.004"], ["70530.70", "0.002"], ["70530.90", "0.254"], ["70531.00", "0.511"], ["70531.40", "0.007"], ["70531.60", "0.096"], ["70533.70", "0.001"], ["70533.90", "0.002"], ["70554.10", "0.002"], ["70554.50", "0.002"], ["70554.80", "0.004"], ["70555.20", "0.086"], ["70555.50", "0.195"], ["70555.60", "0.024"], ["70555.90", "0.498"], ["70556.70", "0.087"], ["70560.50", "0.550"], ["70561.30", "0.048"], ["70563.00", "0.000"], ["70577.30", "0.178"], ["70584.30", "0.075"], ["70587.60", "0.000"], ["70591.40", "0.148"], ["71201.00", "3.519"], ["71740.70", "0.002"], ["72270.20", "2.486"], ["73315.80", "0.006"], ["74051.10", "0.018"]]}}
{"local_ts": 1773485327168, "server_ts": 1773485326374, "data": {"e": "depthUpdate", "E": 1773485326375, "T": 1773485326374, "s": "BTCUSDT", "U": 10109442751676, "u": 10109442757645, "pu": 10109442751538, "b": [["5000.00", "101.418"], ["7050.00", "0.425"], ["20199.90", "0.280"], ["20295.90", "1.470"], ["20298.40", "0.000"], ["20299.00", "0.050"], ["20299.90", "1.020"], ["20395.90", "0.160"], ["33000.00", "3.789"], ["66946.30", "0.002"], ["66974.00", "0.020"], ["67680.00", "0.065"], ["69794.90", "0.042"], ["70452.50", "0.269"], ["70452.80", "0.042"], ["70467.00", "0.002"], ["70481.60", "0.510"], ["70482.50", "0.027"], ["70482.80", "0.017"], ["70499.90", "8.269"]], "a": [["70506.00", "0.010"], ["70577.30", "0.178"], ["70596.30", "0.011"], ["70816.80", "0.000"], ["71205.00", "0.004"], ["74054.90", "0.024"]]}}
{"local_ts": 1773485328190, "server_ts": 1773485327398, "data": {"e": "depthUpdate", "E": 1773485327399, "T": 1773485327398, "s": "BTCUSDT", "U": 10109442798096, "u": 10109442800821, "pu": 10109442798016, "b": [["1000.00", "28.842"], ["5000.00", "101.418"], ["7050.00", "0.425"], ["20099.90", "0.130"], ["20199.90", "2.420"], ["20295.90", "0.450"], ["20296.60", "0.000"], ["66960.50", "0.002"], ["69794.90", "0.042"], ["70147.40", "0.000"], ["70200.00", "24.194"], ["70401.10", "0.092"], ["70408.20", "0.016"], ["70415.20", "0.016"], ["70453.00", "0.010"], ["70454.80", "0.960"], ["70464.70", "1.917"], ["70465.10", "0.000"], ["70465.20", "8.071"], ["70465.30", "2.139"]], "a": [["70506.00", "0.008"], ["70535.20", "1.544"], ["70577.40", "0.092"], ["70584.40", "0.511"], ["70591.50", "0.000"], ["70700.00", "22.170"], ["70850.90", "0.097"], ["70852.50", "0.284"], ["71014.50", "0.004"], ["71227.50", "0.004"], ["71440.60", "0.008"], ["71529.10", "0.000"], ["71653.60", "0.004"], ["71866.70", "0.004"], ["74040.00", "1.065"]]}}
{"local_ts": 1773485329215, "server_ts": 1773485328420, "data": {"e": "depthUpdate", "E": 1773485328423, "T": 1773485328420, "s": "BTCUSDT", "U": 10109442857098, "u": 10109442860635, "pu": 10109442856971, "b": [["5000.00", "101.398"], ["7050.00", "0.481"], ["20099.90", "2.240"], ["20199.90", "0.760"], ["33000.00", "3.789"], ["66956.90", "0.000"], ["69645.90", "5.676"], ["69794.90", "0.042"], ["69903.70", "0.000"], ["70075.80", "40.370"], ["70075.90", "6.081"], ["70180.80", "0.007"], ["70181.10", "31.980"], ["70181.20", "5.008"], ["70258.30", "27.456"], ["70259.00", "6.197"], ["70320.10", "0.159"], ["70489.50", "0.004"], ["70489.90", "0.011"]], "a": [["70504.20", "0.004"], ["70518.60", "0.009"], ["70745.10", "21.311"], ["70822.50", "4.315"], ["70822.90", "26.234"], ["70841.90", "0.211"], ["70852.50", "0.073"], ["70929.10", "31.608"], ["71205.00", "0.002"], ["71692.90", "0.557"]]}}
{"local_ts": 1773485330237, "server_ts": 1773485329444, "data": {"e": "depthUpdate", "E": 1773485329445, "T": 1773485329444, "s": "BTCUSDT", "U": 10109442888563, "u": 10109442892976, "pu": 10109442888533, "b": [["1000.00", "28.692"], ["5000.00", "101.398"], ["7050.00", "0.481"], ["19999.90", "1.800"], ["20099.90", "1.200"], ["69794.90", "0.042"], ["70354.00", "0.000"], ["70357.20", "0.000"], ["70425.30", "0.002"], ["70430.90", "0.038"], ["70441.30", "0.000"], ["70453.20", "0.002"], ["70453.30", "0.042"]], "a": [["70535.10", "0.520"], ["70543.50", "0.006"], ["70588.10", "0.212"], ["70723.60", "0.007"], ["70744.90", "0.002"], ["70840.90", "0.035"], ["70841.90", "0.000"], ["71204.90", "0.000"], ["71205.00", "0.002"], ["74034.00", "0.113"]]}}
{"local_ts": 1773485331262, "server_ts": 1773485330468, "data": {"e": "depthUpdate", "E": 1773485330469, "T": 1773485330468, "s": "BTCUSDT", "U": 10109442926638, "u": 10109442931549, "pu": 10109442926168, "b": [["1000.00", "28.692"], ["5000.00", "101.418"], ["7050.00", "0.453"], ["19999.90", "1.640"], ["20399.90", "1.360"], ["66952.70", "0.002"], ["69495.10", "0.744"], ["69515.30", "0.000"], ["69794.90", "0.042"], ["70147.40", "0.000"], ["70433.30", "0.168"], ["70453.10", "1.068"], ["70453.20", "0.002"], ["70464.00", "0.215"], ["70464.70", "1.846"], ["70480.10", "0.010"], ["70481.60", "0.082"], ["70486.90", "0.090"], ["70494.80", "0.026"], ["70496.50", "0.126"], ["70498.70", "0.009"], ["70498.90", "0.004"], ["70499.70", "0.021"], ["70499.80", "0.098"]], "a": [["70509.70", "0.039"], ["70512.70", "0.003"], ["70514.10", "0.004"], ["70535.20", "1.574"], ["70536.60", "0.041"], ["70563.40", "0.168"], ["70569.80", "0.002"], ["70576.50", "0.002"], ["70676.20", "0.076"], ["71014.50", "0.000"], ["71205.00", "0.002"], ["71227.50", "0.000"], ["71440.60", "0.004"], ["71653.60", "0.000"], ["71866.70", "0.000"], ["73319.90", "0.032"], ["89523.20", "0.000"]]}}
{"local_ts": 1773485332283, "server_ts": 1773485331490, "data": {"e": "depthUpdate", "E": 1773485331491, "T": 1773485331490, "s": "BTCUSDT", "U": 10109442973947, "u": 10109442977449, "pu": 10109442973943, "b": [["5000.00", "101.418"], ["7050.00", "0.453"], ["20299.90", "0.910"], ["20399.90", "2.090"], ["56400.00", "6.994"], ["65204.90", "0.000"], ["66958.50", "0.010"], ["69794.90", "0.042"], ["70422.30", "0.003"], ["70457.90", "0.007"], ["70463.10", "0.404"], ["70476.10", "0.084"], ["70476.20", "0.000"], ["70484.80", "0.004"], ["70489.00", "1.123"], ["70499.90", "5.029"]], "a": [["70508.50", "0.009"], ["70508.60", "0.025"], ["70509.80", "0.005"], ["70514.60", "0.010"], ["70518.30", "0.004"], ["70518.50", "0.115"], ["70531.70", "0.006"], ["70558.50", "0.002"], ["70571.80", "0.002"], ["70576.50", "0.000"], ["70599.30", "0.245"], ["70603.50", "0.010"], ["70606.40", "0.004"], ["71205.00", "0.002"], ["89523.20", "0.000"]]}}
{"local_ts": 1773485333307, "server_ts": 1773485332511, "data": {"e": "depthUpdate", "E": 1773485332513, "T": 1773485332511, "s": "BTCUSDT", "U": 10109443028821, "u": 10109443033964, "pu": 10109443028730, "b": [["1000.00", "28.692"], ["5000.00", "101.438"], ["7050.00", "0.453"], ["20199.90", "0.460"], ["20299.90", "2.540"], ["20399.90", "0.000"], ["66969.80", "0.000"], ["66974.00", "0.000"], ["69794.90", "0.042"], ["70147.40", "0.000"], ["70472.70", "0.186"], ["70472.90", "0.002"], ["70491.10", "0.069"]], "a": [["70511.10", "0.161"], ["70513.60", "0.004"], ["70514.80", "0.143"], ["70520.50", "0.170"], ["70520.90", "0.035"], ["70571.80", "0.000"], ["70571.90", "0.002"], ["71169.70", "1.403"], ["71536.40", "4.676"], ["71568.50", "0.863"], ["72975.30", "0.000"], ["89523.20", "0.000"]]}}
{"local_ts": 1773485334326, "server_ts": 1773485333532, "data": {"e": "depthUpdate", "E": 1773485333533, "T": 1773485333532, "s": "BTCUSDT", "U": 10109443067104, "u": 10109443070347, "pu": 10109443067071, "b": [["5000.00", "101.418"], ["7050.00", "0.453"], ["20099.90", "0.250"], ["20199.90", "2.520"], ["20299.90", "0.230"], ["33000.00", "3.785"], ["56400.00", "6.994"], ["66942.20", "0.000"], ["66952.80", "0.002"], ["69681.00", "0.000"], ["69794.90", "0.042"], ["70365.30", "0.869"], ["70452.90", "0.006"], ["70453.00", "0.010"], ["70471.70", "1.628"], ["70472.50", "0.359"], ["70485.80", "0.069"]], "a": [["70519.40", "0.004"], ["70519.50", "0.085"], ["70526.20", "0.078"], ["70571.90", "0.000"], ["70630.90", "0.472"], ["71205.00", "1.404"], ["71652.70", "4.180"], ["72267.80", "0.000"], ["72273.00", "2.489"], ["89523.20", "0.000"]]}}
{"local_ts": 1773485335351, "server_ts": 1773485334552, "data": {"e": "depthUpdate", "E": 1773485334555, "T": 1773485334552, "s": "BTCUSDT", "U": 10109443098092, "u": 10109443100896, "pu": 10109443098051, "b": [["1000.00", "28.692"], ["5000.00", "101.398"], ["7050.00", "0.425"], ["19999.90", "0.100"], ["20099.90", "2.370"], ["20199.90", "0.530"], ["56400.00", "6.998"], ["66956.50", "0.006"], ["68499.90", "0.013"], ["68796.30", "0.000"], ["69108.80", "1.240"], ["69218.70", "0.015"], ["69578.80", "3.731"], ["69794.90", "0.757"], ["70326.60", "3.112"], ["70365.40", "0.767"], ["70437.60", "0.010"], ["70491.10", "0.125"]], "a": [["70520.60", "0.009"], ["70524.80", "0.004"], ["70526.20", "0.076"], ["70539.50", "0.009"], ["70542.90", "0.140"], ["70630.00", "1.095"], ["70630.90", "0.475"], ["70669.70", "2.000"], ["71205.00", "2.105"], ["71818.40", "1.041"], ["89523.20", "0.000"]]}}
{"local_ts": 1773485336366, "server_ts": 1773485335572, "data": {"e": "depthUpdate", "E": 1773485335575, "T": 1773485335572, "s": "BTCUSDT", "U": 10109443130978, "u": 10109443133961, "pu": 10109443130964, "b": [["1000.00", "28.692"], ["5000.00", "101.418"], ["7050.00", "0.425"], ["19999.90", "2.120"], ["20099.90", "0.880"], ["33000.00", "3.789"], ["56400.00", "6.994"], ["69794.90", "0.757"], ["70147.40", "0.000"], ["70290.00", "0.194"], ["70316.60", "0.159"], ["70438.70", "0.105"], ["70452.90", "0.006"], ["70453.00", "0.010"], ["70467.40", "0.000"], ["70471.70", "1.431"], ["70484.80", "0.006"], ["70485.80", "0.095"], ["70487.70", "0.104"], ["70488.40", "0.005"], ["70491.10", "0.069"], ["70499.80", "0.090"]], "a": [["70500.00", "8.630"], ["70500.80", "0.089"], ["70502.30", "0.005"], ["70502.70", "0.009"], ["70503.10", "0.057"], ["70503.40", "0.006"], ["70504.80", "0.026"], ["70505.80", "0.003"], ["70506.30", "0.002"], ["70506.80", "0.030"], ["70506.90", "0.061"], ["70507.00", "0.055"], ["70509.00", "0.041"], ["70516.10", "0.005"], ["70523.50", "0.664"], ["70533.50", "0.094"], ["70558.00", "0.129"], ["70559.10", "0.087"], ["70676.20", "0.175"], ["71205.00", "2.105"], ["74034.10", "0.000"], ["89523.20", "0.000"]]}}
{"local_ts": 1773485337394, "server_ts": 1773485336596, "data": {"e": "depthUpdate", "E": 1773485336599, "T": 1773485336596, "s": "BTCUSDT", "U": 10109443171052, "u": 10109443175056, "pu": 10109443171044, "b": [["5000.00", "101.418"], ["7050.00", "0.425"], ["19999.90", "1.320"], ["20399.90", "1.680"], ["56400.00", "6.994"], ["66963.30", "0.000"], ["66974.90", "0.006"], ["66975.00", "0.088"], ["68726.50", "2.615"], ["69794.90", "0.757"], ["70100.00", "48.251"], ["70180.50", "0.000"], ["70251.60", "0.007"], ["70283.10", "0.002"], ["70316.60", "0.000"], ["70334.20", "0.000"], ["70337.80", "0.000"], ["70351.70", "12.007"], ["70353.30", "2.795"], ["70410.20", "6.525"], ["70413.00", "2.020"], ["70435.70", "0.094"], ["70445.20", "4.233"], ["70446.60", "0.000"], ["70453.90", "0.317"], ["70466.30", "1.767"], ["70471.40", "0.053"], ["70471.70", "1.431"], ["70475.20", "0.510"], ["70480.40", "0.290"], ["70485.80", "0.095"], ["70487.00", "0.840"], ["70488.70", "0.005"], ["70490.20", "0.006"], ["70492.90", "0.469"], ["70493.00", "0.011"], ["70493.20", "0.000"], ["70499.30", "0.021"], ["70499.80", "0.098"]], "a": [["70500.00", "8.400"], ["70500.80", "0.079"], ["70501.80", "0.080"], ["70502.60", "0.002"], ["70503.10", "0.000"], ["70504.80", "0.005"], ["70505.40", "0.028"], ["70506.90", "0.004"], ["70507.00", "0.036"], ["70509.60", "0.171"], ["70510.80", "0.041"], ["70514.90", "0.006"], ["70516.20", "0.022"], ["70518.50", "0.012"], ["70518.80", "0.091"], ["70519.10", "0.594"], ["70520.80", "1.017"], ["70520.90", "0.035"], ["70521.00", "0.005"], ["70521.10", "0.107"], ["70521.50", "0.059"], ["70522.90", "0.000"], ["70523.90", "0.512"], ["70532.10", "0.881"], ["70532.80", "0.006"], ["70535.30", "0.123"], ["70535.50", "1.770"], ["70545.40", "0.016"], ["70552.80", "0.005"], ["70556.60", "1.423"], ["70556.70", "3.488"], ["70557.00", "0.108"], ["70561.00", "0.068"], ["70591.70", "2.514"], ["70591.80", "6.385"], ["70592.50", "0.000"], ["70647.60", "3.787"], ["70650.30", "12.172"], ["70679.80", "2.587"], ["70723.40", "0.007"], ["71205.00", "2.105"], ["71465.90", "1.363"], ["71909.90", "0.009"], ["73950.00", "10.220"], ["74055.80", "0.010"], ["89523.20", "0.000"]]}}
{"local_ts": 1773485338418, "server_ts": 1773485337624, "data": {"e": "depthUpdate", "E": 1773485337627, "T": 1773485337624, "s": "BTCUSDT", "U": 10109443207567, "u": 10109443210764, "pu": 10109443207560, "b": [["1000.00", "28.842"], ["5000.00", "101.418"], ["7050.00", "0.481"], ["20299.90", "1.250"], ["20399.90", "1.750"], ["33000.00", "3.789"], ["56400.00", "6.994"], ["66967.00", "0.150"], ["66971.20", "0.002"], ["68368.90", "0.628"], ["69463.50", "3.089"], ["69794.90", "2.194"], ["69795.00", "0.103"], ["70147.40", "0.000"], ["70254.30", "0.008"], ["70354.10", "0.007"], ["70365.40", "0.783"], ["70404.60", "0.092"], ["70405.00", "0.063"], ["70407.00", "1.708"], ["70411.60", "0.024"], ["70412.10", "0.002"], ["70414.00", "0.202"], ["70419.10", "0.000"], ["70425.70", "0.569"], ["70428.10", "0.600"], ["70452.90", "0.006"], ["70453.00", "0.010"], ["70464.70", "0.006"], ["70490.50", "0.073"], ["70490.70", "0.033"], ["70492.90", "0.204"]], "a": [["70500.00", "8.349"], ["70503.40", "0.006"], ["70507.00", "0.067"], ["70509.20", "0.000"], ["70520.60", "0.094"], ["70534.90", "0.080"], ["70535.20", "1.514"], ["70581.40", "0.574"], ["70588.40", "0.005"], ["70595.50", "0.010"], ["70630.90", "0.448"], ["71000.00", "82.623"], ["71205.00", "2.105"], ["74059.30", "0.002"], ["74100.00", "56.060"], ["89523.20", "0.000"]]}}
{"local_ts": 1773485339442, "server_ts": 1773485338650, "data": {"e": "depthUpdate", "E": 1773485338651, "T": 1773485338650, "s": "BTCUSDT", "U": 10109443245142, "u": 10109443247820, "pu": 10109443245109, "b": [["5000.00", "101.418"], ["7050.00", "0.481"], ["20199.90", "0.810"], ["20299.90", "2.190"], ["20400.00", "0.007"], ["56400.00", "6.994"], ["66975.10", "0.000"], ["69512.90", "4.385"], ["69794.90", "2.194"], ["70254.20", "0.239"], ["70490.20", "0.006"], ["70491.10", "0.069"], ["70498.30", "0.000"], ["70498.50", "0.029"]], "a": [["70501.60", "0.025"], ["70501.90", "0.008"], ["70520.30", "0.087"], ["70520.50", "0.000"], ["70520.60", "0.096"], ["70534.90", "0.080"], ["71205.00", "2.105"], ["71275.50", "2.006"], ["71408.10", "3.398"], ["71522.20", "15.431"], ["71909.90", "0.009"], ["74035.80", "0.003"], ["74047.30", "0.002"], ["89523.20", "0.000"]]}}
{"local_ts": 1773485340465, "server_ts": 1773485339672, "data": {"e": "depthUpdate", "E": 1773485339673, "T": 1773485339672, "s": "BTCUSDT", "U": 10109443316740, "u": 10109443321326, "pu": 10109443316559, "b": [["1000.00", "28.842"], ["5000.00", "101.398"], ["7050.00", "0.453"], ["20099.90", "0.400"], ["20199.90", "2.570"], ["20299.90", "0.030"], ["66974.90", "0.004"], ["66975.00", "0.088"], ["69794.90", "2.194"], ["70147.40", "0.284"], ["70180.10", "0.004"], ["70253.40", "0.000"], ["70450.60", "0.116"], ["70464.00", "0.215"], ["70464.10", "0.046"], ["70464.70", "0.006"], ["70464.80", "0.001"], ["70472.90", "0.037"], ["70475.60", "0.109"], ["70477.30", "0.071"], ["70485.90", "0.001"], ["70487.70", "0.111"], ["70488.30", "0.000"]], "a": [["70507.50", "0.014"], ["70513.40", "0.005"], ["70518.60", "0.153"], ["70521.20", "0.672"], ["70535.10", "0.562"], ["70600.60", "0.127"], ["70723.90", "0.000"], ["71204.90", "0.007"], ["71205.00", "2.105"], ["71408.10", "2.559"], ["71513.80", "3.352"], ["71536.40", "6.057"], ["74027.80", "0.005"], ["89523.20", "0.000"]]}}
{"local_ts": 1773485341486, "server_ts": 1773485340694, "data": {"e": "depthUpdate", "E": 1773485340695, "T": 1773485340694, "s": "BTCUSDT", "U": 10109443408950, "u": 10109443418466, "pu": 10109443408780, "b": [["1000.00", "28.842"], ["5000.00", "101.418"], ["7050.00", "0.453"], ["19999.90", "0.210"], ["20099.90", "2.500"], ["20199.90", "0.290"], ["56400.00", "6.994"], ["66974.00", "0.000"], ["69548.10", "0.586"], ["69794.90", "2.194"], ["69830.10", "0.714"], ["70147.40", "1.138"], ["70405.00", "0.081"], ["70412.10", "0.073"], ["70419.10", "0.071"], ["70453.10", "1.068"], ["70453.20", "0.002"], ["70471.70", "1.601"], ["70471.90", "0.241"], ["70475.20", "0.707"], ["70491.50", "0.033"], ["70491.60", "0.007"], ["70491.70", "0.129"], ["70491.80", "0.024"], ["70491.90", "0.011"]], "a": [["70500.10", "0.021"], ["70514.10", "0.148"], ["70514.20", "0.019"], ["70514.30", "0.015"], ["70515.20", "0.006"], ["70523.90", "0.002"], ["70524.20", "0.005"], ["70524.50", "0.510"], ["70525.00", "1.028"], ["70526.20", "0.006"], ["70526.80", "0.070"], ["70528.50", "0.744"], ["70529.10", "0.248"], ["70542.40", "0.009"], ["70544.10", "0.050"], ["70581.40", "0.645"], ["70588.40", "0.076"], ["70595.50", "0.081"], ["70676.20", "0.175"], ["71205.00", "2.105"], ["71536.40", "6.615"], ["74031.10", "0.000"], ["89523.20", "0.000"]]}}
{"local_ts": 1773485342512, "server_ts": 1773485341716, "data": {"e": "depthUpdate", "E": 1773485341717, "T": 1773485341716, "s": "BTCUSDT", "U": 10109443476001, "u": 10109443481146, "pu": 10109443475833, "b": [["5000.00", "101.418"], ["7050.00", "0.453"], ["19999.90", "2.340"], ["20099.90", "0.590"], ["20399.90", "0.070"], ["66958.20", "0.000"], ["69090.00", "3.701"], ["69469.60", "1.868"], ["69794.90", "2.194"], ["69935.90", "1.506"], ["70041.60", "0.060"], ["70147.50", "1.136"], ["70253.50", "0.356"], ["70453.10", "1.068"], ["70453.30", "0.040"], ["70488.10", "0.687"], ["70488.50", "0.101"], ["70491.10", "0.148"], ["70492.90", "0.401"], ["70497.60", "0.080"], ["70498.20", "0.003"]], "a": [["70500.00", "7.958"], ["70504.00", "0.071"], ["70507.00", "0.010"], ["70507.80", "0.217"], ["70518.50", "0.194"], ["70523.40", "0.639"], ["70524.30", "0.006"], ["70558.00", "0.129"], ["70723.80", "0.210"], ["71205.00", "2.105"], ["71733.70", "12.258"], ["74029.20", "0.002"]]}}
{"local_ts": 1773485343530, "server_ts": 1773485342736, "data": {"e": "depthUpdate", "E": 1773485342739, "T": 1773485342736, "s": "BTCUSDT", "U": 10109443530423, "u": 10109443536497, "pu": 10109443530039, "b": [["1000.00", "28.842"], ["5000.00", "101.418"], ["7050.00", "0.425"], ["19999.90", "0.970"], ["20399.90", "2.030"], ["33000.00", "3.785"], ["66963.50", "0.004"], ["69520.00", "4.700"], ["69794.90", "2.194"], ["69795.00", "0.099"], ["70147.40", "3.699"], ["70147.50", "1.136"], ["70407.10", "0.005"], ["70408.30", "0.308"], ["70414.10", "0.368"], ["70415.30", "0.239"], ["70428.20", "0.014"], ["70429.40", "0.729"], ["70447.50", "1.099"], ["70453.10", "1.068"], ["70453.30", "0.040"], ["70473.00", "0.034"], ["70487.70", "0.104"], ["70487.80", "0.009"], ["70490.80", "0.040"], ["70491.00", "0.011"], ["70491.10", "0.148"], ["70492.90", "0.466"], ["70493.90", "0.016"], ["70494.00", "0.002"], ["70494.10", "0.003"]], "a": [["70500.00", "7.954"], ["70500.40", "0.440"], ["70502.90", "0.009"], ["70507.00", "0.036"], ["70509.50", "0.134"], ["70518.50", "0.003"], ["70528.30", "0.071"], ["70529.10", "0.248"], ["70561.50", "1.532"], ["70840.90", "0.057"], ["71205.00", "2.105"], ["73319.90", "0.040"], ["74051.70", "0.006"]]}}
{"local_ts": 1773485344551, "server_ts": 1773485343756, "data": {"e": "depthUpdate", "E": 1773485343759, "T": 1773485343756, "s": "BTCUSDT", "U": 10109443578272, "u": 10109443583160, "pu": 10109443578249, "b": [["5000.00", "101.418"], ["7050.00", "0.425"], ["20299.90", "1.580"], ["20399.90", "1.420"], ["66763.40", "0.036"], ["66974.90", "0.008"], ["66975.00", "0.088"], ["66975.10", "0.000"], ["69794.90", "2.194"], ["70147.50", "1.136"], ["70313.10", "0.159"], ["70316.60", "0.060"], ["70330.70", "0.039"], ["70350.60", "0.170"], ["70353.30", "1.003"], ["70353.80", "0.513"], ["70409.50", "1.503"], ["70413.00", "0.926"], ["70444.80", "0.129"], ["70447.50", "0.581"], ["70452.80", "0.044"], ["70452.90", "0.004"], ["70466.00", "0.286"], ["70471.70", "1.627"], ["70481.60", "0.002"], ["70481.70", "1.205"], ["70482.90", "0.001"], ["70485.80", "0.069"], ["70492.90", "0.468"], ["70493.20", "0.022"], ["70498.80", "0.057"], ["70499.80", "0.183"], ["70499.90", "4.084"]], "a": [["70500.00", "6.912"], ["70501.20", "0.004"], ["70501.60", "0.007"], ["70502.50", "0.018"], ["70502.60", "0.002"], ["70503.80", "0.000"], ["70504.80", "0.005"], ["70505.10", "0.000"], ["70506.80", "0.012"], ["70507.00", "0.036"], ["70507.60", "0.689"], ["70507.70", "0.361"], ["70508.80", "0.132"], ["70509.90", "0.219"], ["70510.10", "0.015"], ["70510.30", "0.003"], ["70511.10", "0.081"], ["70511.30", "0.003"], ["70523.50", "0.027"], ["70524.20", "0.003"], ["70525.30", "0.510"], ["70537.40", "0.000"], ["70537.50", "0.349"], ["70541.00", "0.075"], ["70557.00", "0.016"], ["70558.20", "0.301"], ["70558.30", "0.025"], ["70558.50", "0.002"], ["70558.70", "0.958"], ["70567.00", "0.195"], ["70592.90", "1.233"], ["70594.20", "0.000"], ["70623.00", "0.207"], ["70651.50", "1.220"], ["70653.30", "0.460"], ["70676.20", "0.175"], ["70679.80", "2.746"], ["71205.00", "2.105"], ["73319.90", "0.046"], ["74031.00", "0.045"], ["74057.30", "0.002"]]}}
{"local_ts": 1773485345583, "server_ts": 1773485344780, "data": {"e": "depthUpdate", "E": 1773485344781, "T": 1773485344780, "s": "BTCUSDT", "U": 10109443651517, "u": 10109443655703, "pu": 10109443651457, "b": [["1000.00", "28.842"], ["5000.00", "101.418"], ["7050.00", "0.425"], ["20199.90", "1.140"], ["20299.90", "1.860"], ["33000.00", "3.789"], ["69166.80", "0.000"], ["69288.30", "0.514"], ["69512.90", "5.247"], ["69794.90", "2.194"], ["70201.50", "0.088"], ["70222.90", "0.012"], ["70253.60", "0.004"], ["70473.80", "0.052"], ["70474.70", "0.013"], ["70499.10", "0.002"]], "a": [["70522.70", "0.349"], ["70522.90", "0.000"], ["70549.30", "0.031"], ["70624.50", "0.000"], ["70645.90", "0.104"], ["71569.70", "0.000"], ["74025.60", "0.000"], ["74059.70", "0.002"]]}}
{"local_ts": 1773485346593, "server_ts": 1773485345802, "data": {"e": "depthUpdate", "E": 1773485345803, "T": 1773485345802, "s": "BTCUSDT", "U": 10109443698663, "u": 10109443703525, "pu": 10109443698654, "b": [["1000.00", "28.842"], ["5000.00", "101.418"], ["7050.00", "0.481"], ["20099.90", "0.690"], ["20199.90", "2.310"], ["20299.90", "0.000"], ["56400.10", "0.008"], ["69548.10", "0.873"], ["69577.60", "0.000"], ["69794.90", "2.194"], ["70253.70", "0.000"], ["70341.30", "0.549"], ["70447.50", "0.997"], ["70453.20", "0.002"], ["70453.30", "0.042"], ["70465.90", "0.004"], ["70471.70", "1.601"], ["70474.90", "0.343"], ["70475.30", "0.026"], ["70485.80", "0.095"], ["70491.50", "0.018"], ["70499.90", "4.601"]], "a": [["70500.00", "6.611"], ["70522.80", "0.204"], ["70522.90", "0.085"], ["70533.80", "0.000"], ["70546.50", "0.014"], ["70676.20", "0.175"], ["70700.00", "24.170"], ["70900.00", "11.890"], ["71058.40", "1.441"], ["71059.80", "4.447"], ["71205.00", "2.105"], ["71435.60", "0.708"], ["71592.70", "4.743"], ["74054.10", "0.002"]]}}
{"local_ts": 1773485347616, "server_ts": 1773485346820, "data": {"e": "depthUpdate", "E": 1773485346823, "T": 1773485346820, "s": "BTCUSDT", "U": 10109443753739, "u": 10109443765143, "pu": 10109443753720, "b": [["5000.00", "101.418"], ["7050.00", "0.481"], ["19999.90", "0.320"], ["20099.90", "2.600"], ["20199.90", "0.080"], ["66974.90", "0.008"], ["66975.00", "0.090"], ["69794.90", "2.194"], ["69795.00", "0.099"], ["70191.30", "0.415"], ["70258.70", "0.000"], ["70302.50", "0.121"], ["70337.80", "0.000"], ["70430.40", "0.387"], ["70445.40", "8.515"], ["70447.70", "0.006"], ["70452.60", "0.004"], ["70453.20", "0.002"], ["70457.40", "0.340"], ["70463.10", "0.404"], ["70469.10", "0.248"], ["70469.50", "0.054"], ["70469.70", "0.000"], ["70470.20", "0.072"], ["70471.40", "0.001"], ["70471.50", "0.000"], ["70471.80", "1.334"], ["70472.50", "0.076"], ["70472.80", "0.224"], ["70472.90", "0.186"], ["70475.20", "0.818"], ["70475.30", "0.140"], ["70475.80", "0.070"], ["70476.00", "0.093"], ["70476.50", "0.513"], ["70477.30", "0.071"], ["70477.80", "1.066"], ["70477.90", "0.012"], ["70478.30", "0.000"], ["70478.50", "0.148"], ["70478.60", "0.002"], ["70478.70", "0.009"], ["70478.80", "0.003"], ["70478.90", "0.010"], ["70479.20", "0.005"], ["70479.30", "0.001"], ["70479.70", "0.226"], ["70479.90", "0.000"], ["70480.10", "0.006"], ["70480.90", "0.000"], ["70481.30", "0.211"], ["70481.40", "0.667"], ["70481.70", "1.205"], ["70482.90", "0.001"], ["70483.10", "0.053"], ["70483.70", "1.707"], ["70483.80", "0.003"], ["70484.50", "0.000"], ["70484.80", "0.004"], ["70485.40", "0.154"], ["70485.70", "0.000"], ["70485.90", "0.343"], ["70486.00", "0.418"], ["70486.30", "0.002"], ["70486.70", "0.048"], ["70486.80", "0.517"], ["70487.80", "0.009"], ["70488.60", "0.060"], ["70488.70", "0.015"], ["70489.30", "0.005"], ["70489.50", "1.070"], ["70489.60", "0.002"], ["70490.20", "0.517"], ["70490.40", "0.115"], ["70490.60", "0.060"], ["70491.10", "0.241"], ["70491.20", "0.012"], ["70491.30", "0.027"], ["70491.70", "0.148"], ["70491.80", "0.005"], ["70491.90", "0.006"], ["70492.30", "0.007"], ["70492.60", "0.021"], ["70492.90", "0.468"], ["70493.00", "0.032"], ["70493.10", "0.338"], ["70493.20", "0.364"], ["70493.30", "0.010"], ["70493.40", "0.003"], ["70493.70", "0.000"], ["70494.50", "0.000"], ["70494.90", "0.003"], ["70495.00", "0.008"], ["70495.10", "0.091"], ["70496.00", "0.054"], ["70496.10", "0.019"], ["70496.30", "0.003"], ["70496.50", "0.000"], ["70497.60", "0.008"], ["70497.70", "0.015"], ["70497.80", "0.003"], ["70497.90", "0.000"], ["70498.00", "0.000"], ["70498.10", "0.003"], ["70498.20", "0.003"], ["70498.30", "0.000"], ["70498.50", "0.008"], ["70498.60", "0.000"], ["70498.70", "0.009"], ["70498.80", "0.094"], ["70499.00", "0.001"], ["70499.10", "0.000"], ["70499.20", "0.002"], ["70499.30", "0.000"], ["70499.50", "0.002"], ["70499.60", "0.000"], ["70499.80", "0.119"], ["70499.90", "3.612"]], "a": [["70500.00", "7.517"], ["70500.30", "0.000"], ["70500.50", "0.021"], ["70501.20", "0.084"], ["70502.10", "0.003"], ["70502.90", "0.016"], ["70503.20", "0.001"], ["70505.20", "0.024"], ["70506.50", "0.016"], ["70507.00", "0.039"], ["70507.70", "0.658"], ["70508.30", "0.005"], ["70508.60", "0.027"], ["70509.90", "0.000"], ["70511.90", "0.184"], ["70512.00", "0.209"], ["70513.10", "0.369"], ["70513.80", "0.022"], ["70515.80", "0.009"], ["70517.60", "0.131"], ["70518.90", "0.734"], ["70519.10", "0.404"], ["70519.50", "0.531"], ["70519.80", "0.652"], ["70521.10", "0.022"], ["70521.80", "0.006"], ["70522.00", "0.739"], ["70522.60", "0.061"], ["70522.70", "0.334"], ["70523.00", "0.082"], ["70523.60", "1.096"], ["70524.80", "0.072"], ["70524.90", "0.253"], ["70525.00", "1.023"], ["70525.30", "0.000"], ["70526.00", "0.286"], ["70526.40", "0.002"], ["70526.50", "0.004"], ["70526.90", "0.064"], ["70527.10", "0.000"], ["70527.20", "0.001"], ["70528.20", "0.000"], ["70528.40", "0.771"], ["70530.10", "0.032"], ["70534.60", "0.048"], ["70549.30", "0.433"], ["70556.50", "0.000"], ["70557.80", "8.568"], ["70560.80", "0.041"], ["70560.90", "0.003"], ["70567.70", "0.004"], ["70834.90", "0.211"], ["71205.00", "2.105"], ["71909.90", "0.015"], ["73319.90", "0.052"], ["74053.20", "0.069"], ["74056.40", "0.000"]]}}
{"local_ts": 1773485348636, "server_ts": 1773485347844, "data": {"e": "depthUpdate", "E": 1773485347845, "T": 1773485347844, "s": "BTCUSDT", "U": 10109443820077, "u": 10109443825279, "pu": 10109443820011, "b": [["1000.00", "28.842"], ["5000.00", "101.418"], ["7050.00", "0.481"], ["19999.90", "2.460"], ["20099.90", "0.370"], ["20399.90", "0.170"], ["63449.90", "0.010"], ["66974.90", "0.004"], ["66975.00", "0.092"], ["69407.20", "12.446"], ["69645.90", "2.953"], ["69794.90", "3.625"], ["70147.40", "3.735"], ["70191.60", "3.275"], ["70330.00", "0.156"], ["70452.90", "0.004"], ["70453.00", "0.012"], ["70453.30", "0.044"], ["70492.80", "0.005"], ["70493.30", "0.519"], ["70493.40", "0.005"], ["70497.10", "0.021"], ["70497.30", "0.216"], ["70497.40", "0.000"], ["70499.50", "0.000"]], "a": [["70500.00", "7.464"], ["70506.90", "0.006"], ["70508.00", "0.003"], ["70511.80", "0.019"], ["70517.50", "0.186"], ["70517.70", "0.085"], ["70517.80", "0.281"], ["70558.60", "2.191"], ["70841.90", "0.000"], ["71205.00", "2.105"], ["71480.00", "5.840"], ["71574.90", "1.395"], ["74038.40", "0.000"], ["77550.00", "0.089"]]}}
{"local_ts": 1773485349664, "server_ts": 1773485348872, "data": {"e": "depthUpdate", "E": 1773485348873, "T": 1773485348872, "s": "BTCUSDT", "U": 10109443888907, "u": 10109443893110, "pu": 10109443888808, "b": [["5000.00", "101.438"], ["7050.00", "0.453"], ["19999.90", "0.660"], ["20299.90", "0.030"], ["20399.90", "2.310"], ["56400.00", "6.994"], ["63449.90", "0.010"], ["66955.50", "0.010"], ["69433.70", "0.432"], ["69494.80", "0.000"], ["69794.90", "3.625"], ["69935.90", "1.642"], ["70330.00", "0.154"], ["70332.10", "0.017"], ["70341.30", "0.549"], ["70452.80", "0.044"], ["70453.10", "1.066"], ["70471.10", "0.000"], ["70473.20", "0.320"], ["70478.90", "0.073"], ["70480.90", "0.000"], ["70482.20", "0.000"], ["70483.40", "0.007"], ["70491.10", "0.392"], ["70492.90", "0.469"], ["70493.30", "0.534"], ["70496.70", "0.016"], ["70496.80", "0.002"], ["70497.00", "0.009"], ["70497.10", "0.000"], ["70497.30", "0.216"], ["70497.40", "0.000"], ["70497.50", "0.000"], ["70497.60", "0.008"], ["70497.70", "0.000"], ["70497.80", "0.003"], ["70498.60", "0.021"], ["70498.90", "0.016"], ["70499.10", "0.000"], ["70499.20", "0.002"], ["70499.30", "0.000"], ["70499.80", "0.090"], ["70499.90", "3.636"]], "a": [["70500.00", "7.414"], ["70502.20", "0.001"], ["70503.20", "0.001"], ["70511.80", "0.017"], ["70517.50", "0.002"], ["70517.70", "0.085"], ["70517.80", "0.012"], ["70520.70", "0.195"], ["70527.60", "0.010"], ["70528.30", "0.319"], ["70528.40", "0.773"], ["70528.80", "0.344"], ["70529.70", "0.054"], ["70834.90", "0.211"], ["70840.90", "0.057"], ["71064.00", "1.337"], ["71205.00", "2.105"], ["71592.70", "8.649"], ["72000.00", "231.350"], ["73319.90", "0.058"], ["74037.00", "0.116"], ["74043.30", "0.000"], ["77550.00", "0.089"]]}}
{"local_ts": 1773485350694, "server_ts": 1773485349892, "data": {"e": "depthUpdate", "E": 1773485349895, "T": 1773485349892, "s": "BTCUSDT", "U": 10109443928673, "u": 10109443932329, "pu": 10109443928631, "b": [["1000.00", "28.842"], ["5000.00", "101.418"], ["7050.00", "0.453"], ["20299.90", "1.920"], ["20399.90", "1.080"], ["63449.90", "0.010"], ["66945.70", "0.000"], ["66955.10", "0.002"], ["66974.00", "0.000"], ["67680.00", "0.101"], ["69653.90", "2.865"], ["70147.40", "3.735"], ["70331.90", "0.013"], ["70332.10", "0.015"], ["70448.50", "0.004"], ["70452.40", "1.153"], ["70452.50", "0.269"], ["70463.60", "0.004"], ["70492.90", "0.399"], ["70499.30", "0.015"], ["70499.40", "0.002"], ["70499.60", "0.008"]], "a": [["70507.00", "0.011"], ["70519.70", "0.005"], ["70519.90", "0.088"], ["70520.10", "0.003"], ["70528.40", "0.771"], ["70528.70", "0.844"], ["70676.20", "0.175"], ["70723.70", "2.009"], ["70834.90", "0.211"], ["70840.90", "0.035"], ["70841.90", "0.000"], ["71204.90", "0.000"], ["71205.00", "2.105"], ["77550.00", "0.089"]]}}
{"local_ts": 1773485351711, "server_ts": 1773485350916, "data": {"e": "depthUpdate", "E": 1773485350919, "T": 1773485350916, "s": "BTCUSDT", "U": 10109443968333, "u": 10109443972953, "pu": 10109443968219, "b": [["1000.00", "28.842"], ["5000.00", "101.418"], ["7050.00", "0.453"], ["20199.90", "1.480"], ["20299.90", "1.520"], ["56400.00", "6.994"], ["63449.90", "0.010"], ["66955.10", "0.000"], ["69575.20", "0.000"], ["69794.90", "3.625"], ["70400.00", "4.983"], ["70464.70", "0.015"], ["70471.70", "1.680"], ["70485.80", "0.016"]], "a": [["70503.20", "0.016"], ["70503.40", "0.006"], ["70506.60", "0.008"], ["70513.60", "0.006"], ["70528.70", "1.090"], ["70533.80", "0.000"], ["70535.20", "1.516"], ["70544.10", "0.006"], ["70723.60", "0.007"], ["71204.90", "0.000"], ["71205.00", "2.806"], ["77550.00", "0.089"]]}}
{"local_ts": 1773485352732, "server_ts": 1773485351940, "data": {"e": "depthUpdate", "E": 1773485351941, "T": 1773485351940, "s": "BTCUSDT", "U": 10109444012602, "u": 10109444018800, "pu": 10109444012401, "b": [["5000.00", "101.418"], ["7050.00", "0.425"], ["20099.90", "1.040"], ["20199.90", "1.960"], ["33000.00", "3.785"], ["63449.90", "0.008"], ["66968.50", "0.000"], ["69283.60", "1.441"], ["69794.90", "4.341"], ["69966.10", "0.716"], ["70346.40", "1.601"], ["70347.90", "1.832"], ["70349.60", "0.753"], ["70472.70", "0.002"], ["70473.20", "0.268"], ["70473.30", "0.248"], ["70475.20", "0.680"], ["70484.20", "0.012"], ["70484.80", "0.004"], ["70491.10", "0.201"], ["70492.90", "0.471"], ["70499.90", "3.738"]], "a": [["70500.00", "6.392"], ["70500.80", "0.063"], ["70502.00", "0.000"], ["70502.10", "0.003"], ["70502.30", "0.002"], ["70503.90", "0.003"], ["70505.10", "0.000"], ["70505.40", "0.003"], ["70505.70", "0.000"], ["70513.60", "0.004"], ["70520.00", "0.061"], ["70520.80", "1.226"], ["70522.30", "0.061"], ["70522.80", "0.841"], ["70723.30", "0.226"], ["70820.80", "0.211"], ["71204.90", "0.000"], ["71205.00", "3.186"], ["71515.90", "0.000"], ["71567.40", "0.418"], ["77550.00", "0.087"]]}}
{"local_ts": 1773485353756, "server_ts": 1773485352964, "data": {"e": "depthUpdate", "E": 1773485352965, "T": 1773485352964, "s": "BTCUSDT", "U": 10109444061841, "u": 10109444065533, "pu": 10109444061800, "b": [["1000.00", "28.842"], ["5000.00", "101.418"], ["7050.00", "0.425"], ["19999.90", "0.600"], ["20099.90", "2.400"], ["20199.90", "0.000"], ["56400.00", "6.994"], ["63449.90", "0.008"], ["69266.20", "10.381"], ["69794.90", "4.341"], ["70147.40", "3.807"], ["70452.60", "0.004"], ["70452.80", "0.042"], ["70464.70", "0.086"], ["70471.70", "1.680"], ["70473.20", "0.303"], ["70473.80", "0.052"], ["70474.70", "0.013"], ["70487.50", "0.642"], ["70488.60", "0.075"], ["70491.10", "0.097"]], "a": [["70502.50", "0.010"], ["70502.60", "0.002"], ["70502.70", "0.001"], ["70502.80", "0.002"], ["70502.90", "0.034"], ["70503.00", "0.004"], ["70503.10", "0.000"], ["70503.20", "0.001"], ["70503.30", "0.004"], ["70503.40", "0.006"], ["70503.50", "0.002"], ["70503.60", "0.001"], ["70503.70", "0.002"], ["70503.80", "0.000"], ["70503.90", "0.003"], ["70504.00", "0.142"], ["70504.90", "0.022"], ["70535.20", "1.544"], ["70537.30", "0.026"], ["70549.80", "0.184"], ["70676.20", "0.175"], ["70723.30", "0.226"], ["70900.00", "11.820"], ["71204.90", "0.000"], ["71205.00", "3.188"], ["71501.10", "1.946"], ["72482.00", "0.133"], ["74030.50", "0.002"], ["74044.30", "0.000"], ["77550.00", "0.087"]]}}
{"local_ts": 1773485354777, "server_ts": 1773485353984, "data": {"e": "depthUpdate", "E": 1773485353987, "T": 1773485353984, "s": "BTCUSDT", "U": 10109444102868, "u": 10109444105957, "pu": 10109444102851, "b": [["5000.00", "101.418"], ["7050.00", "0.425"], ["19999.90", "2.570"], ["20099.90", "0.140"], ["20399.90", "0.290"], ["33000.00", "3.789"], ["63449.90", "0.008"], ["66971.60", "0.002"], ["68499.90", "0.016"], ["69090.00", "4.084"], ["69407.20", "12.446"], ["69543.20", "0.572"], ["69794.90", "4.341"], ["70283.80", "0.004"], ["70337.80", "0.000"], ["70491.10", "0.257"], ["70494.00", "0.029"], ["70495.40", "0.011"]], "a": [["70500.00", "5.069"], ["70500.30", "0.133"], ["70505.80", "0.018"], ["70505.90", "0.003"], ["70517.80", "0.014"], ["70520.70", "0.011"], ["70534.70", "0.002"], ["70535.30", "0.125"], ["70537.30", "0.024"], ["70539.30", "0.084"], ["70545.00", "0.001"], ["70547.80", "0.004"], ["70549.80", "0.269"], ["70820.80", "0.211"], ["71205.00", "3.186"], ["71433.90", "2.096"], ["74057.20", "0.000"], ["77550.00", "0.087"], ["89523.20", "0.000"]]}}
{"local_ts": 1773485355798, "server_ts": 1773485355006, "data": {"e": "depthUpdate", "E": 1773485355007, "T": 1773485355006, "s": "BTCUSDT", "U": 10109444136460, "u": 10109444140774, "pu": 10109444136372, "b": [["1000.00", "28.842"], ["5000.00", "101.418"], ["7050.00", "0.481"], ["19999.90", "0.440"], ["20299.90", "0.140"], ["20399.90", "2.420"], ["56400.00", "6.994"], ["63449.90", "0.008"], ["66960.00", "0.643"], ["68384.90", "0.000"], ["69534.10", "0.860"], ["69794.90", "5.772"], ["69795.00", "0.483"], ["70147.40", "3.807"], ["70253.40", "0.000"], ["70452.90", "0.004"], ["70453.00", "0.012"], ["70485.50", "0.005"], ["70486.60", "0.017"], ["70486.70", "0.048"], ["70487.90", "0.639"], ["70489.00", "0.000"]], "a": [["70500.00", "6.213"], ["70510.30", "0.003"], ["70513.90", "0.004"], ["70520.70", "0.011"], ["70535.30", "0.125"], ["70539.30", "0.082"], ["70540.50", "0.004"], ["70560.80", "0.041"], ["70562.00", "8.502"], ["70676.20", "0.175"], ["71205.00", "3.186"], ["74059.80", "0.000"], ["77550.00", "0.087"], ["89523.20", "0.000"]]}}
{"local_ts": 1773485356818, "server_ts": 1773485356024, "data": {"e": "depthUpdate", "E": 1773485356027, "T": 1773485356024, "s": "BTCUSDT", "U": 10109444181951, "u": 10109444188556, "pu": 10109444181948, "b": [["1000.00", "28.842"], ["5000.00", "101.418"], ["7050.00", "0.481"], ["20299.90", "2.250"], ["20399.90", "0.750"], ["63449.90", "0.008"], ["69498.80", "2.289"], ["69794.90", "5.772"], ["70472.80", "0.224"], ["70478.80", "0.214"], ["70479.90", "0.000"], ["70481.80", "0.596"], ["70482.30", "0.310"]], "a": [["70500.00", "6.242"], ["70500.80", "0.073"], ["70501.70", "0.003"], ["70502.40", "0.013"], ["70502.50", "0.010"], ["70502.70", "0.016"], ["70503.80", "0.080"], ["70504.00", "0.142"], ["70504.30", "0.057"], ["70505.30", "0.041"], ["70505.60", "0.006"], ["70506.10", "0.021"], ["70506.60", "0.033"], ["70508.10", "0.002"], ["70508.60", "0.046"], ["70510.10", "0.003"], ["70510.50", "0.023"], ["70517.00", "0.000"], ["70517.80", "0.014"], ["70518.20", "0.012"], ["70523.60", "1.082"], ["70524.00", "0.772"], ["70525.40", "0.291"], ["70526.60", "0.070"], ["70527.30", "0.000"], ["70528.70", "0.842"], ["70528.80", "0.346"], ["70529.10", "0.248"], ["70531.40", "0.009"], ["70535.30", "0.123"], ["70540.50", "0.002"], ["70591.70", "0.002"], ["70599.60", "0.837"], ["70627.50", "0.041"], ["70638.80", "0.002"], ["71205.00", "4.588"], ["71492.90", "0.278"], ["71891.10", "1.789"], ["74048.40", "0.000"], ["77550.00", "0.087"], ["89523.20", "0.000"]]}}
{"local_ts": 1773485357839, "server_ts": 1773485357044, "data": {"e": "depthUpdate", "E": 1773485357047, "T": 1773485357044, "s": "BTCUSDT", "U": 10109444231382, "u": 10109444236413, "pu": 10109444231308, "b": [["5000.00", "101.418"], ["7050.00", "0.481"], ["20199.90", "1.800"], ["20299.90", "1.200"], ["65000.00", "98.032"], ["65220.00", "0.010"], ["65440.00", "0.010"], ["65660.00", "0.193"], ["65880.00", "0.489"], ["66100.00", "3.668"], ["66320.00", "0.292"], ["66540.00", "0.079"], ["66760.00", "0.073"], ["66972.60", "0.002"], ["66980.00", "0.018"], ["67200.00", "4.917"], ["67420.00", "0.138"], ["67640.00", "0.035"], ["67860.00", "0.056"], ["68080.00", "5.275"], ["68300.00", "16.475"], ["68520.00", "0.027"], ["68740.00", "0.037"], ["68960.00", "0.805"], ["69180.00", "2.616"], ["69400.00", "27.698"], ["69620.00", "0.025"], ["69794.90", "5.772"], ["69840.00", "0.084"], ["70060.00", "0.245"], ["70280.00", "5.221"], ["70323.00", "0.525"], ["70351.30", "0.161"], ["70453.00", "0.012"], ["70453.10", "1.066"], ["70473.00", "0.000"], ["70481.80", "0.525"], ["70482.30", "0.310"], ["70487.20", "0.060"]], "a": [["70500.00", "6.359"], ["70512.70", "0.006"], ["70517.50", "0.271"], ["70517.80", "0.014"], ["70527.90", "0.047"], ["70528.80", "0.344"], ["70530.80", "0.002"], ["70531.40", "0.007"], ["70549.30", "0.195"], ["70649.40", "0.185"], ["70665.80", "0.018"], ["70720.00", "0.562"], ["70838.40", "0.213"], ["70840.90", "0.057"], ["70900.00", "12.396"], ["70940.00", "0.024"], ["71160.00", "0.090"], ["71204.90", "0.000"], ["71205.00", "5.990"], ["71380.00", "1.417"], ["71380.90", "0.700"], ["71600.00", "113.832"], ["71820.00", "0.111"], ["72040.00", "0.279"], ["72260.00", "0.050"], ["72480.00", "0.999"], ["72700.00", "45.353"], ["72920.00", "0.050"], ["73140.00", "0.011"], ["73360.00", "0.083"], ["73580.00", "2.198"], ["73800.00", "35.234"], ["74020.00", "0.234"], ["74240.00", "1.484"], ["74460.00", "0.136"], ["74680.00", "0.327"], ["74900.00", "13.186"], ["75120.00", "0.056"], ["75340.00", "0.110"], ["75560.00", "0.216"], ["75780.00", "0.083"], ["76000.00", "109.972"], ["89523.20", "0.000"]]}}
{"local_ts": 1773485358867, "server_ts": 1773485358066, "data": {"e": "depthUpdate", "E": 1773485358067, "T": 1773485358066, "s": "BTCUSDT", "U": 10109444274542, "u": 10109444279022, "pu": 10109444274511, "b": [["1000.00", "28.842"], ["5000.00", "101.418"], ["7050.00", "0.453"], ["20099.90", "1.350"], ["20199.90", "1.650"], ["56400.00", "6.994"], ["66962.40", "0.002"], ["69794.90", "7.203"], ["69795.00", "0.479"], ["70074.00", "0.005"], ["70147.40", "4.377"], ["70179.30", "0.014"], ["70254.00", "0.073"], ["70256.60", "0.000"], ["70337.80", "0.039"], ["70366.90", "8.285"], ["70454.30", "0.004"], ["70463.60", "0.004"], ["70464.70", "0.082"], ["70473.00", "0.000"], ["70487.20", "0.056"]], "a": [["70500.00", "5.848"], ["70500.20", "0.023"], ["70512.70", "0.003"], ["70514.10", "0.002"], ["70514.20", "0.005"], ["70517.50", "0.002"], ["70517.80", "0.198"], ["70522.10", "0.007"], ["70522.20", "0.017"], ["70527.90", "0.045"], ["70530.20", "0.009"], ["70530.80", "0.000"], ["70533.30", "0.014"], ["70535.20", "1.544"], ["70538.20", "0.007"], ["70546.10", "0.301"], ["70546.20", "0.223"], ["70604.50", "0.045"], ["70611.90", "0.048"], ["70630.80", "1.577"], ["70630.90", "9.251"], ["70676.20", "0.175"], ["70743.30", "0.000"], ["70820.80", "0.211"], ["70821.10", "0.000"], ["70834.90", "0.211"], ["70840.90", "0.035"], ["70927.30", "0.002"], ["71205.00", "5.990"], ["89523.20", "0.000"]]}}
{"local_ts": 1773485359881, "server_ts": 1773485359088, "data": {"e": "depthUpdate", "E": 1773485359089, "T": 1773485359088, "s": "BTCUSDT", "U": 10109444315561, "u": 10109444319945, "pu": 10109444315483, "b": [["5000.00", "101.418"], ["7050.00", "0.453"], ["19999.90", "0.910"], ["20099.90", "2.090"], ["33000.00", "3.785"], ["66969.90", "0.002"], ["68384.90", "0.000"], ["68385.00", "0.300"], ["69090.00", "4.090"], ["69794.90", "7.203"], ["69795.00", "0.479"], ["70147.50", "1.132"], ["70253.90", "0.147"], ["70430.20", "1.337"], ["70472.80", "0.179"], ["70475.90", "0.562"], ["70487.20", "0.056"], ["70491.10", "0.194"]], "a": [["70500.00", "5.845"], ["70500.30", "0.002"], ["70512.70", "0.003"], ["70557.90", "0.337"], ["70567.50", "0.041"], ["70583.40", "0.000"], ["70584.90", "0.158"], ["70834.90", "0.000"], ["71205.00", "6.033"], ["71609.10", "1.205"], ["72614.90", "0.000"], ["89523.20", "0.000"]]}}
{"local_ts": 1773485360904, "server_ts": 1773485360112, "data": {"e": "depthUpdate", "E": 1773485360113, "T": 1773485360112, "s": "BTCUSDT", "U": 10109444359160, "u": 10109444364432, "pu": 10109444359057, "b": [["1000.00", "28.842"], ["5000.00", "101.418"], ["7050.00", "0.453"], ["19999.90", "2.530"], ["20099.90", "0.000"], ["20399.90", "0.470"], ["56400.00", "6.994"], ["66954.30", "0.000"], ["66974.00", "0.000"], ["69371.90", "8.308"], ["69794.90", "7.203"], ["69795.00", "0.483"], ["70147.40", "4.377"], ["70253.90", "0.143"], ["70283.80", "0.008"], ["70453.10", "1.068"], ["70453.20", "0.002"], ["70472.80", "0.144"], ["70487.20", "0.056"], ["70491.10", "0.090"]], "a": [["70500.00", "5.689"], ["70500.40", "0.440"], ["70500.50", "0.141"], ["70502.30", "0.017"], ["70502.50", "0.018"], ["70502.80", "0.030"], ["70504.10", "0.040"], ["70504.90", "0.058"], ["70506.60", "0.044"], ["70512.70", "0.003"], ["70515.70", "0.025"], ["70517.00", "0.000"], ["70520.70", "0.011"], ["70520.90", "0.035"], ["70521.00", "0.090"], ["70523.40", "0.002"], ["70525.40", "0.291"], ["70549.80", "0.269"], ["70557.90", "0.153"], ["70584.90", "0.156"], ["70595.40", "0.127"], ["70630.80", "2.770"], ["70676.20", "0.175"], ["71169.80", "2.812"], ["71205.00", "6.033"], ["71597.70", "0.000"], ["89523.20", "0.000"]]}}
{"local_ts": 1773485361930, "server_ts": 1773485361136, "data": {"e": "depthUpdate", "E": 1773485361139, "T": 1773485361136, "s": "BTCUSDT", "U": 10109444400365, "u": 10109444404005, "pu": 10109444400288, "b": [["5000.00", "101.398"], ["7050.00", "0.425"], ["19999.90", "0.220"], ["20299.90", "0.250"], ["20399.90", "2.530"], ["33000.00", "3.785"], ["69726.50", "1.430"], ["69794.90", "7.203"], ["70326.10", "0.000"], ["70326.20", "3.552"], ["70365.00", "0.928"], ["70453.20", "0.002"], ["70453.30", "0.042"], ["70464.70", "0.082"], ["70473.20", "0.268"], ["70487.20", "0.056"]], "a": [["70508.40", "1.080"], ["70512.70", "0.003"], ["70535.20", "1.544"], ["70537.50", "0.322"], ["70594.40", "0.251"], ["70595.40", "0.125"], ["70630.70", "0.547"], ["70669.50", "2.039"], ["70834.90", "0.211"], ["74049.60", "0.002"], ["74050.50", "0.054"], ["89523.20", "0.000"]]}}
{"local_ts": 1773485362950, "server_ts": 1773485362156, "data": {"e": "depthUpdate", "E": 1773485362159, "T": 1773485362156, "s": "BTCUSDT", "U": 10109444440853, "u": 10109444444822, "pu": 10109444440847, "b": [["1000.00", "28.842"], ["5000.00", "101.398"], ["7050.00", "0.425"], ["20199.90", "0.100"], ["20299.90", "2.380"], ["20399.90", "0.520"], ["66959.10", "0.002"], ["68801.40", "0.000"], ["69090.00", "4.090"], ["69548.20", "3.082"], ["69583.40", "10.332"], ["69618.60", "0.135"], ["69794.90", "7.203"], ["70139.30", "0.000"], ["70302.50", "0.121"], ["70453.00", "0.010"], ["70453.30", "0.042"], ["70457.40", "0.283"], ["70472.80", "0.179"], ["70483.00", "0.010"], ["70486.10", "0.426"]], "a": [["70502.50", "0.010"], ["70506.50", "0.004"], ["70508.30", "0.005"], ["70509.10", "0.023"], ["70509.80", "0.005"], ["70509.90", "0.184"], ["70520.70", "0.011"], ["70594.40", "0.249"], ["70596.00", "0.011"], ["70723.40", "0.000"], ["70840.80", "0.012"], ["70844.40", "0.024"], ["71205.00", "4.631"], ["71416.40", "0.000"], ["74033.30", "0.003"], ["89523.20", "0.000"]]}}
{"local_ts": 1773485363973, "server_ts": 1773485363177, "data": {"e": "depthUpdate", "E": 1773485363179, "T": 1773485363177, "s": "BTCUSDT", "U": 10109444481091, "u": 10109444484212, "pu": 10109444481059, "b": [["1000.00", "28.842"], ["5000.00", "101.418"], ["7050.00", "0.425"], ["20199.90", "2.130"], ["20299.90", "0.870"], ["33000.00", "3.789"], ["69794.90", "7.203"], ["70147.40", "4.377"], ["70453.40", "0.004"], ["70453.50", "0.001"], ["70472.80", "0.144"], ["70487.70", "0.744"], ["70488.70", "0.015"], ["70488.80", "0.010"], ["70489.30", "0.005"], ["70491.70", "0.190"], ["70499.90", "3.777"]], "a": [["70505.20", "0.058"], ["70508.00", "0.003"], ["70509.30", "0.015"], ["70517.60", "0.441"], ["70524.40", "0.000"], ["70525.70", "0.003"], ["70549.30", "0.031"], ["70596.00", "0.009"], ["70598.60", "0.002"], ["70676.20", "0.175"], ["71205.00", "4.631"], ["71319.80", "0.576"], ["71416.50", "10.068"], ["71494.10", "0.949"], ["71558.60", "0.418"], ["74025.70", "0.181"], ["89523.20", "0.000"]]}}
{"local_ts": 1773485364994, "server_ts": 1773485364200, "data": {"e": "depthUpdate", "E": 1773485364201, "T": 1773485364200, "s": "BTCUSDT", "U": 10109444526392, "u": 10109444529879, "pu": 10109444526317, "b": [["5000.00", "101.418"], ["7050.00", "0.425"], ["20099.90", "1.690"], ["20199.90", "1.310"], ["56400.00", "6.994"], ["66956.60", "0.002"], ["66971.00", "0.003"], ["67675.40", "0.654"], ["69794.90", "7.203"], ["70406.10", "0.624"], ["70414.30", "0.180"], ["70464.70", "0.002"], ["70473.40", "0.003"], ["70488.10", "0.045"], ["70488.40", "0.007"], ["70492.90", "0.272"]], "a": [["70507.00", "0.036"], ["70514.70", "0.004"], ["70534.90", "0.080"], ["70535.20", "1.516"], ["70543.00", "0.782"], ["70717.40", "0.293"], ["70724.40", "0.007"], ["70731.40", "0.009"], ["70738.40", "0.009"], ["70745.40", "0.211"], ["70748.70", "0.000"], ["70752.40", "0.007"], ["70755.70", "0.000"], ["70759.40", "0.015"], ["70762.70", "0.000"], ["70766.40", "4.791"], ["70769.70", "0.000"], ["70776.70", "0.000"], ["70783.70", "0.000"], ["70790.70", "0.009"], ["70797.70", "0.000"], ["71205.00", "5.332"], ["71219.30", "0.000"], ["71249.90", "3.243"]]}}
{"local_ts": 1773485366014, "server_ts": 1773485365220, "data": {"e": "depthUpdate", "E": 1773485365223, "T": 1773485365220, "s": "BTCUSDT", "U": 10109444562788, "u": 10109444565889, "pu": 10109444562396, "b": [["1000.00", "28.842"], ["5000.00", "101.418"], ["7050.00", "0.481"], ["19999.90", "1.240"], ["20099.90", "1.760"], ["67832.80", "0.000"], ["69794.90", "6.488"], ["70076.40", "36.776"], ["70076.50", "5.551"], ["70147.40", "4.519"], ["70181.70", "5.723"], ["70254.10", "0.004"], ["70472.90", "0.037"]], "a": [["70566.20", "0.749"], ["70717.40", "0.286"], ["70723.30", "0.226"], ["70724.40", "0.000"], ["70731.40", "0.002"], ["70738.40", "0.002"], ["70745.40", "0.204"], ["70752.40", "0.000"], ["70759.40", "0.008"], ["70766.40", "4.784"], ["71204.90", "0.000"], ["71205.00", "5.332"], ["71909.90", "0.006"], ["72043.30", "0.000"], ["74047.70", "0.002"]]}}
{"local_ts": 1773485367034, "server_ts": 1773485366240, "data": {"e": "depthUpdate", "E": 1773485366243, "T": 1773485366240, "s": "BTCUSDT", "U": 10109444597436, "u": 10109444600880, "pu": 10109444597423, "b": [["5000.00", "101.438"], ["7050.00", "0.481"], ["19999.90", "2.210"], ["20399.90", "0.790"], ["66962.10", "0.000"], ["69477.70", "34.673"], ["69794.90", "6.488"], ["70313.10", "0.000"], ["70316.60", "0.159"], ["70330.70", "0.000"], ["70353.30", "2.895"], ["70413.00", "2.030"], ["70447.50", "1.074"], ["70479.40", "0.655"], ["70479.60", "0.011"], ["70479.90", "0.000"], ["70480.60", "0.007"], ["70487.90", "0.643"], ["70488.40", "0.005"], ["70488.50", "0.079"]], "a": [["70501.40", "0.060"], ["70501.80", "0.008"], ["70503.00", "0.019"], ["70507.00", "0.057"], ["70517.60", "0.337"], ["70521.80", "0.091"], ["70522.00", "0.739"], ["70523.20", "0.661"], ["70523.50", "0.013"], ["70524.30", "0.004"], ["70524.40", "0.000"], ["70525.40", "0.291"], ["70526.80", "0.000"], ["70527.30", "0.000"], ["70527.60", "0.080"], ["70530.30", "0.056"], ["70532.30", "0.005"], ["70535.20", "1.612"], ["70549.30", "0.031"], ["70558.00", "1.167"], ["70592.90", "2.037"], ["70651.50", "2.940"], ["70679.80", "2.587"], ["70716.00", "0.009"], ["70840.90", "0.057"], ["71028.70", "1.406"], ["71205.00", "5.332"], ["71786.40", "2.793"], ["72248.90", "0.005"]]}}
