{"local_ts": 1773485123765, "server_ts": 1773485122968, "data": {"e": "depthUpdate", "E": 1773485122971, "T": 1773485122968, "s": "BTCUSDT", "U": 10109432979693, "u": 10109432984710, "pu": 10109432979680, "b": [["1000.00", "28.692"], ["5000.00", "101.418"], ["7050.90", "0.000"], ["20208.30", "1.610"], ["20306.70", "0.220"], ["20307.70", "0.410"], ["20308.30", "0.740"], ["56407.00", "0.000"], ["63457.50", "0.000"], ["64627.60", "0.002"], ["68376.20", "0.626"], ["69449.60", "3.422"], ["69485.40", "4.415"], ["69542.30", "0.286"], ["69803.20", "0.000"], ["69873.20", "0.708"], ["70346.10", "0.159"], ["70367.30", "0.667"], ["70384.30", "0.002"], ["70386.80", "2.139"], ["70395.60", "0.092"], ["70398.00", "0.017"], ["70398.40", "0.967"], ["70398.70", "0.018"], ["70399.10", "0.114"], ["70399.40", "2.673"], ["70399.80", "0.052"], ["70417.90", "0.000"], ["70419.40", "0.000"], ["70425.40", "0.041"], ["70426.90", "0.022"], ["70427.20", "0.841"], ["70427.50", "0.516"], ["70427.60", "0.049"], ["70427.90", "0.003"], ["70428.30", "0.000"], ["70428.60", "0.002"], ["70431.20", "0.063"], ["70437.20", "0.363"], ["70438.70", "0.731"], ["70439.10", "0.157"], ["70439.40", "0.058"], ["70439.80", "0.059"], ["70440.10", "0.039"], ["70444.60", "0.539"], ["70473.10", "1.863"], ["70493.90", "0.115"], ["70495.80", "0.003"], ["70496.10", "0.005"], ["70496.30", "0.002"], ["70496.40", "0.393"], ["70496.50", "0.060"], ["70496.70", "0.023"], ["70496.80", "0.191"], ["70497.00", "0.008"], ["70497.10", "0.061"], ["70497.20", "0.016"], ["70497.40", "0.008"], ["70497.50", "0.059"], ["70497.70", "0.000"], ["70497.80", "0.043"], ["70499.30", "0.403"], ["70501.00", "0.084"], ["70501.10", "0.016"], ["70503.30", "0.005"], ["70504.00", "0.185"], ["70504.10", "0.130"], ["70505.00", "0.068"], ["70507.30", "0.005"], ["70507.80", "0.019"], ["70508.30", "111.702"]], "a": [["70508.40", "2.300"], ["70509.00", "0.002"], ["70510.20", "0.000"], ["70510.50", "0.000"], ["70511.30", "0.022"], ["70513.00", "0.003"], ["70514.00", "0.003"], ["70515.10", "0.072"], ["70515.60", "0.000"], ["70517.60", "0.005"], ["70517.70", "0.003"], ["70518.80", "0.021"], ["70518.90", "1.953"], ["70519.00", "0.300"], ["70519.20", "0.005"], ["70519.50", "0.000"], ["70519.90", "0.041"], ["70520.20", "0.008"], ["70520.30", "0.002"], ["70520.60", "0.046"], ["70520.90", "0.021"], ["70521.60", "0.391"], ["70522.00", "0.776"], ["70522.30", "0.038"], ["70522.70", "0.040"], ["70523.00", "0.112"], ["70523.40", "0.272"], ["70523.50", "0.098"], ["70526.00", "0.059"], ["70529.30", "0.072"], ["70530.10", "0.105"], ["70530.50", "0.311"], ["70531.60", "0.024"], ["70532.70", "0.003"], ["70533.30", "0.082"], ["70534.00", "0.007"], ["70534.60", "0.637"], ["70537.20", "0.495"], ["70541.30", "0.002"], ["70545.20", "0.016"], ["70550.30", "0.149"], ["70550.70", "0.191"], ["70550.80", "0.124"], ["70551.20", "0.359"], ["70551.50", "0.072"], ["70551.90", "0.095"], ["70552.20", "7.980"], ["70552.80", "0.038"], ["70556.00", "0.397"], ["70562.70", "0.090"], ["70563.10", "0.051"], ["70563.40", "1.273"], ["70563.80", "0.780"], ["70564.10", "0.000"], ["70564.50", "0.002"], ["70566.00", "0.145"], ["70572.00", "0.045"], ["70573.50", "0.000"], ["70582.60", "0.297"], ["70588.60", "0.120"], ["70591.60", "0.142"], ["70591.90", "0.000"], ["70592.30", "0.000"], ["70592.60", "0.342"], ["70592.70", "0.005"], ["70593.00", "1.519"], ["70593.30", "0.007"], ["70595.80", "0.006"], ["70602.40", "0.017"], ["70604.60", "0.000"], ["70607.00", "0.044"], ["71213.50", "0.000"], ["71499.80", "0.071"], ["71530.80", "0.846"], ["71721.00", "0.348"], ["74048.60", "0.004"], ["77559.20", "0.000"], ["89523.20", "0.000"]]}}
{"local_ts": 1773485124792, "server_ts": 1773485123992, "data": {"e": "depthUpdate", "E": 1773485123997, "T": 1773485123992, "s": "BTCUSDT", "U": 10109433026901, "u": 10109433032841, "pu": 10109433026748, "b": [["5000.00", "101.418"], ["7050.90", "0.000"], ["20108.30", "1.170"], ["20208.30", "1.830"], ["33000.00", "3.789"], ["63457.50", "0.000"], ["64275.40", "0.002"], ["69508.30", "3.385"], ["69732.70", "0.154"], ["69803.20", "0.000"], ["70262.50", "0.014"], ["70458.50", "0.004"], ["70458.70", "0.090"], ["70493.90", "0.194"], ["70497.70", "0.000"], ["70501.10", "0.019"], ["70508.30", "116.570"]], "a": [["70508.40", "1.634"], ["70519.00", "0.300"], ["70519.90", "0.041"], ["70520.20", "0.008"], ["70520.30", "0.049"], ["70520.70", "0.119"], ["70526.50", "0.002"], ["70547.10", "0.201"], ["70565.70", "0.041"], ["70568.70", "1.109"], ["70591.10", "0.161"], ["70594.90", "0.552"], ["70600.20", "2.285"], ["70605.20", "0.149"], ["70616.70", "1.776"], ["70625.90", "0.041"], ["70637.80", "0.135"], ["70643.40", "0.131"], ["70654.40", "1.140"], ["70731.70", "0.003"], ["70731.80", "0.016"], ["71213.50", "0.000"], ["71528.30", "0.000"], ["74056.50", "0.052"], ["74056.60", "0.000"], ["75578.90", "0.033"], ["77559.20", "0.000"], ["89523.20", "0.000"], ["115844.00", "0.170"]]}}
{"local_ts": 1773485125814, "server_ts": 1773485125016, "data": {"e": "depthUpdate", "E": 1773485125017, "T": 1773485125016, "s": "BTCUSDT", "U": 10109433129786, "u": 10109433135072, "pu": 10109433129699, "b": [["1000.00", "28.692"], ["5000.00", "101.418"], ["7050.90", "0.056"], ["20008.30", "0.730"], ["20108.30", "2.270"], ["56407.00", "0.000"], ["63457.50", "0.000"], ["66966.80", "0.002"], ["68393.10", "0.006"], ["69490.10", "0.005"], ["69662.20", "0.854"], ["69944.20", "0.071"], ["70155.80", "0.000"], ["70262.50", "0.014"], ["70322.60", "0.090"], ["70335.60", "0.000"], ["70342.60", "0.577"], ["70345.80", "0.006"], ["70346.40", "3.358"], ["70406.10", "0.755"], ["70406.40", "0.206"], ["70413.20", "0.002"], ["70451.90", "0.655"], ["70453.30", "0.839"], ["70457.60", "0.034"], ["70457.70", "0.050"], ["70458.70", "0.090"], ["70459.80", "0.043"], ["70460.40", "1.352"], ["70460.50", "0.000"], ["70461.80", "0.022"], ["70463.90", "0.005"], ["70467.50", "1.350"], ["70473.10", "0.049"], ["70473.20", "0.655"], ["70474.40", "0.018"], ["70474.50", "0.012"], ["70474.60", "0.884"], ["70474.70", "0.000"], ["70474.90", "0.040"], ["70475.10", "0.125"], ["70475.70", "0.002"], ["70476.60", "1.489"], ["70477.30", "0.002"], ["70478.60", "0.513"], ["70480.00", "0.059"], ["70480.50", "0.052"], ["70481.70", "0.839"], ["70483.20", "0.000"], ["70487.50", "0.514"], ["70487.80", "1.118"], ["70489.80", "0.076"], ["70490.80", "0.339"], ["70491.10", "0.013"], ["70491.50", "0.009"], ["70492.40", "0.002"], ["70493.80", "0.025"], ["70494.10", "0.029"], ["70494.30", "0.638"], ["70494.40", "0.005"], ["70501.10", "0.201"], ["70501.40", "0.392"], ["70502.50", "0.011"], ["70502.80", "0.113"], ["70505.60", "0.033"]], "a": [["70515.00", "0.039"], ["70515.80", "0.083"], ["70516.00", "0.162"], ["70524.30", "0.845"], ["70525.00", "0.088"], ["70528.40", "0.004"], ["70529.50", "1.718"], ["70531.40", "0.846"], ["70533.70", "0.001"], ["70534.70", "0.250"], ["70536.00", "0.104"], ["70537.10", "0.105"], ["70538.50", "0.844"], ["70545.60", "0.890"], ["70547.10", "0.286"], ["70552.70", "0.839"], ["70559.80", "0.843"], ["70595.80", "0.183"], ["71072.50", "0.070"], ["71213.50", "0.000"], ["72623.60", "0.008"], ["77559.20", "0.000"], ["89523.20", "0.000"]]}}
{"local_ts": 1773485126831, "server_ts": 1773485126038, "data": {"e": "depthUpdate", "E": 1773485126039, "T": 1773485126038, "s": "BTCUSDT", "U": 10109433169099, "u": 10109433173980, "pu": 10109433169083, "b": [["5000.00", "101.418"], ["7050.90", "0.056"], ["20008.30", "2.600"], ["20108.30", "0.060"], ["20408.30", "0.340"], ["66958.60", "0.000"], ["66973.80", "0.002"], ["68722.60", "0.000"], ["68735.10", "5.230"], ["69803.20", "0.002"], ["69811.00", "0.004"], ["69944.20", "0.071"], ["70100.00", "48.797"], ["70368.60", "0.859"], ["70453.30", "0.839"], ["70460.40", "1.352"], ["70461.20", "0.002"], ["70464.00", "0.024"], ["70465.00", "0.004"], ["70466.70", "0.000"], ["70467.50", "1.350"], ["70468.10", "0.006"], ["70473.20", "0.635"], ["70474.60", "0.884"], ["70476.90", "0.104"], ["70481.30", "0.195"], ["70481.70", "0.839"], ["70482.00", "0.634"], ["70482.20", "0.001"], ["70486.50", "0.072"], ["70488.00", "0.053"], ["70488.20", "0.073"], ["70488.70", "0.510"], ["70488.80", "0.085"], ["70491.60", "0.005"], ["70493.40", "0.003"], ["70493.50", "0.006"], ["70494.10", "0.084"], ["70495.70", "0.004"], ["70495.90", "0.638"], ["70497.70", "0.141"], ["70500.40", "0.029"], ["70501.60", "0.057"], ["70504.70", "0.011"]], "a": [["70508.40", "8.453"], ["70521.10", "0.022"], ["70521.40", "0.009"], ["70524.30", "0.845"], ["70530.90", "0.006"], ["70531.10", "0.982"], ["70531.40", "0.846"], ["70531.60", "0.024"], ["70531.80", "0.647"], ["70532.30", "0.515"], ["70532.80", "0.011"], ["70533.30", "0.012"], ["70534.60", "0.070"], ["70537.30", "0.021"], ["70538.20", "0.000"], ["70538.50", "0.844"], ["70539.40", "0.072"], ["70543.70", "0.449"], ["70545.60", "0.890"], ["70547.00", "0.162"], ["70547.10", "0.017"], ["70547.20", "0.246"], ["70552.70", "0.839"], ["70559.80", "0.843"], ["70569.00", "0.003"], ["70570.80", "8.547"], ["70640.40", "0.523"], ["70677.60", "0.159"], ["70857.40", "0.215"], ["71213.50", "0.004"], ["89523.20", "0.000"]]}}
{"local_ts": 1773485127851, "server_ts": 1773485127058, "data": {"e": "depthUpdate", "E": 1773485127059, "T": 1773485127058, "s": "BTCUSDT", "U": 10109433205244, "u": 10109433217650, "pu": 10109433205127, "b": [["1000.00", "28.692"], ["5000.00", "101.418"], ["7050.90", "0.056"], ["20008.30", "0.350"], ["20308.30", "0.180"], ["20408.30", "2.470"], ["56407.00", "0.000"], ["68497.30", "0.000"], ["69097.60", "0.000"], ["69098.20", "0.018"], ["69153.80", "0.021"], ["69467.00", "0.718"], ["69803.20", "0.000"], ["70078.50", "38.929"], ["70080.50", "6.367"], ["70155.80", "0.036"], ["70183.80", "32.675"], ["70261.10", "27.676"], ["70413.80", "0.005"], ["70415.30", "0.000"], ["70415.90", "0.005"], ["70423.30", "4.701"], ["70423.70", "0.454"], ["70423.90", "0.229"], ["70429.10", "0.002"], ["70429.50", "0.365"], ["70429.80", "0.000"], ["70431.30", "0.022"], ["70431.90", "0.012"], ["70436.70", "0.512"], ["70439.30", "0.511"], ["70439.90", "0.005"], ["70444.40", "2.267"], ["70447.20", "0.068"], ["70447.80", "0.007"], ["70452.60", "0.002"], ["70453.30", "0.000"], ["70457.40", "0.041"], ["70457.60", "1.727"], ["70457.70", "0.048"], ["70460.40", "0.513"], ["70460.50", "0.085"], ["70461.00", "0.006"], ["70462.00", "0.133"], ["70467.50", "0.511"], ["70468.50", "0.582"], ["70470.70", "0.000"], ["70471.70", "0.003"], ["70471.80", "0.038"], ["70472.10", "0.692"], ["70472.40", "0.009"], ["70472.50", "1.697"], ["70473.80", "0.005"], ["70474.60", "0.045"], ["70475.50", "0.003"], ["70475.90", "0.746"], ["70476.00", "1.082"], ["70476.60", "1.468"], ["70476.70", "0.011"], ["70476.90", "0.004"], ["70481.70", "0.000"], ["70483.10", "0.512"], ["70485.40", "0.250"], ["70488.80", "0.000"], ["70489.00", "0.010"], ["70489.50", "0.004"], ["70489.70", "0.544"], ["70489.90", "0.004"], ["70490.30", "1.205"], ["70490.50", "0.013"], ["70491.20", "0.003"], ["70491.40", "0.008"], ["70491.60", "0.012"], ["70491.80", "0.048"], ["70492.00", "0.007"], ["70492.10", "0.004"], ["70493.50", "0.006"], ["70493.70", "1.367"], ["70493.90", "0.108"], ["70494.10", "0.084"], ["70494.30", "0.000"], ["70495.40", "0.018"], ["70495.60", "0.004"], ["70496.20", "0.003"], ["70497.00", "0.029"], ["70497.70", "0.057"], ["70497.80", "0.040"], ["70499.80", "0.004"], ["70500.50", "0.003"], ["70501.20", "0.084"], ["70501.40", "0.407"], ["70504.60", "0.011"], ["70504.80", "0.007"], ["70504.90", "0.021"], ["70505.60", "0.090"], ["70506.60", "0.016"], ["70506.90", "0.007"], ["70507.00", "0.023"], ["70508.30", "109.541"]], "a": [["70508.40", "6.671"], ["70508.50", "0.003"], ["70509.10", "0.000"], ["70509.40", "0.000"], ["70509.70", "0.002"], ["70509.80", "0.005"], ["70510.00", "0.006"], ["70511.30", "0.003"], ["70511.80", "0.003"], ["70511.90", "0.245"], ["70512.00", "0.167"], ["70512.10", "0.002"], ["70512.20", "0.003"], ["70512.70", "0.004"], ["70512.90", "0.000"], ["70513.30", "0.000"], ["70513.90", "0.057"], ["70514.50", "0.004"], ["70514.60", "0.005"], ["70514.70", "0.001"], ["70514.90", "1.423"], ["70515.00", "0.039"], ["70515.70", "0.005"], ["70515.90", "0.014"], ["70516.10", "0.037"], ["70516.20", "0.093"], ["70516.50", "0.025"], ["70517.00", "0.057"], ["70517.40", "0.002"], ["70518.20", "0.018"], ["70518.50", "0.021"], ["70518.90", "0.004"], ["70519.00", "0.303"], ["70519.30", "0.025"], ["70521.10", "0.019"], ["70521.40", "0.004"], ["70521.60", "0.436"], ["70521.90", "0.005"], ["70522.10", "0.007"], ["70523.10", "0.002"], ["70523.70", "0.004"], ["70523.80", "0.023"], ["70523.90", "0.000"], ["70524.30", "0.006"], ["70529.30", "0.078"], ["70530.00", "0.154"], ["70530.70", "0.078"], ["70531.40", "0.007"], ["70531.80", "0.640"], ["70532.70", "0.007"], ["70533.40", "0.206"], ["70533.50", "0.004"], ["70534.10", "0.017"], ["70534.20", "0.118"], ["70537.30", "0.016"], ["70538.00", "0.028"], ["70538.50", "0.005"], ["70545.30", "0.310"], ["70545.60", "0.053"], ["70545.90", "0.008"], ["70547.00", "0.162"], ["70547.10", "0.286"], ["70549.20", "0.024"], ["70549.30", "0.135"], ["70552.70", "0.000"], ["70558.20", "0.095"], ["70558.60", "0.049"], ["70559.80", "0.019"], ["70560.50", "0.762"], ["70560.70", "0.000"], ["70573.90", "0.046"], ["70576.70", "0.000"], ["70677.60", "0.159"], ["70746.40", "27.763"], ["70822.20", "0.211"], ["70824.20", "32.257"], ["70857.40", "0.004"], ["70928.70", "6.514"], ["70930.40", "38.494"], ["71213.50", "0.000"], ["71916.90", "0.000"], ["71917.90", "0.033"], ["74039.10", "0.064"], ["74065.50", "0.050"]]}}
{"local_ts": 1773485128871, "server_ts": 1773485128078, "data": {"e": "depthUpdate", "E": 1773485128079, "T": 1773485128078, "s": "BTCUSDT", "U": 10109433270996, "u": 10109433275472, "pu": 10109433270942, "b": [["1000.00", "28.692"], ["5000.00", "101.418"], ["7050.90", "0.028"], ["20208.30", "0.030"], ["20308.30", "2.320"], ["20408.30", "0.650"], ["56407.00", "0.000"], ["69088.90", "1.734"], ["69803.20", "0.000"], ["70283.70", "4.572"], ["70346.10", "0.159"], ["70367.30", "0.628"], ["70423.70", "0.270"], ["70435.00", "0.061"], ["70440.30", "0.054"], ["70441.60", "1.199"], ["70442.00", "0.066"], ["70442.30", "0.842"], ["70442.70", "0.122"], ["70443.00", "0.339"], ["70453.30", "0.839"], ["70457.80", "8.518"], ["70458.40", "0.116"], ["70458.50", "0.002"], ["70460.00", "0.017"], ["70460.40", "1.352"], ["70463.90", "0.005"], ["70464.80", "0.001"], ["70467.50", "1.350"], ["70473.10", "0.011"], ["70474.60", "0.882"], ["70476.70", "0.193"], ["70481.70", "0.839"], ["70495.60", "0.001"], ["70496.90", "0.393"], ["70497.20", "0.128"], ["70497.60", "0.059"], ["70497.90", "0.058"], ["70498.30", "0.046"], ["70501.30", "0.060"], ["70505.10", "0.000"], ["70505.20", "0.058"], ["70508.30", "109.530"]], "a": [["70509.90", "0.000"], ["70510.10", "0.057"], ["70516.40", "0.030"], ["70516.70", "0.037"], ["70517.10", "0.037"], ["70517.40", "0.074"], ["70517.80", "0.219"], ["70521.10", "0.019"], ["70524.30", "0.845"], ["70531.40", "0.846"], ["70533.20", "0.030"], ["70535.10", "0.009"], ["70538.50", "0.844"], ["70544.00", "0.041"], ["70544.30", "0.036"], ["70544.70", "0.039"], ["70545.10", "0.328"], ["70545.40", "0.202"], ["70545.60", "0.890"], ["70545.90", "0.044"], ["70547.00", "0.077"], ["70547.10", "0.017"], ["70548.70", "0.039"], ["70549.20", "0.109"], ["70552.00", "0.190"], ["70552.70", "0.839"], ["70555.10", "0.003"], ["70558.40", "0.011"], ["70559.80", "0.858"], ["70570.80", "8.547"], ["70571.90", "0.000"], ["70574.60", "0.508"], ["70575.40", "0.000"], ["70576.50", "0.000"], ["70579.70", "0.043"], ["70664.30", "0.016"], ["71213.50", "0.000"], ["74044.20", "0.002"]]}}
{"local_ts": 1773485129890, "server_ts": 1773485129096, "data": {"e": "depthUpdate", "E": 1773485129099, "T": 1773485129096, "s": "BTCUSDT", "U": 10109433309178, "u": 10109433312740, "pu": 10109433309125, "b": [["5000.00", "101.418"], ["7050.90", "0.028"], ["20208.30", "1.930"], ["20308.30", "1.070"], ["33000.00", "3.785"], ["56407.00", "0.000"], ["67722.90", "0.002"], ["69803.20", "1.430"], ["69810.90", "0.000"], ["69838.50", "2.357"], ["70346.10", "0.000"], ["70349.70", "0.201"], ["70453.30", "0.000"], ["70458.00", "0.369"], ["70458.10", "0.004"], ["70460.40", "0.513"], ["70465.30", "0.014"], ["70466.20", "0.003"], ["70467.50", "0.511"], ["70474.60", "0.043"], ["70481.70", "0.000"], ["70484.30", "0.005"], ["70486.40", "0.000"], ["70487.70", "0.292"], ["70491.40", "0.173"], ["70493.10", "0.010"], ["70493.50", "0.006"], ["70494.50", "0.108"], ["70495.30", "0.009"], ["70495.40", "0.010"], ["70495.60", "0.001"]], "a": [["70521.10", "0.019"], ["70524.30", "0.006"], ["70531.40", "0.007"], ["70538.50", "0.005"], ["70545.60", "0.051"], ["70549.20", "0.060"], ["70550.70", "0.129"], ["70552.00", "0.006"], ["70552.70", "0.000"], ["70558.40", "0.009"], ["70559.80", "0.019"], ["70562.10", "0.265"], ["70677.60", "0.159"], ["71213.50", "2.804"], ["71530.80", "2.800"], ["74055.80", "0.008"], ["74061.10", "0.002"], ["77343.60", "0.064"]]}}
{"local_ts": 1773485130912, "server_ts": 1773485130118, "data": {"e": "depthUpdate", "E": 1773485130119, "T": 1773485130118, "s": "BTCUSDT", "U": 10109433457435, "u": 10109433466683, "pu": 10109433457161, "b": [["1000.00", "28.692"], ["5000.00", "101.418"], ["7049.80", "0.028"], ["20097.40", "0.900"], ["20208.30", "1.520"], ["56398.00", "0.004"], ["65151.80", "0.000"], ["69792.40", "0.000"], ["70152.40", "0.009"], ["70155.80", "0.072"], ["70241.30", "0.021"], ["70310.60", "0.189"], ["70314.10", "0.163"], ["70334.80", "0.104"], ["70370.10", "0.735"], ["70383.70", "0.612"], ["70386.40", "0.702"], ["70386.70", "0.044"], ["70387.00", "0.004"], ["70387.40", "0.005"], ["70407.30", "2.003"], ["70411.90", "0.056"], ["70414.00", "0.425"], ["70418.30", "0.002"], ["70423.70", "0.003"], ["70425.10", "0.105"], ["70429.40", "0.090"], ["70430.40", "0.629"], ["70432.20", "0.102"], ["70432.70", "0.000"], ["70434.00", "0.091"], ["70441.70", "0.584"], ["70444.50", "0.485"], ["70445.20", "1.500"], ["70446.20", "0.002"], ["70447.50", "0.697"], ["70448.00", "1.175"], ["70449.50", "0.376"], ["70450.20", "0.004"], ["70450.90", "0.005"], ["70451.30", "0.309"], ["70451.60", "0.532"], ["70453.30", "0.000"], ["70460.40", "0.511"], ["70460.90", "0.019"], ["70461.30", "0.124"], ["70461.90", "0.034"], ["70462.60", "0.015"], ["70463.10", "0.143"], ["70463.50", "0.000"], ["70464.50", "0.072"], ["70465.40", "0.317"], ["70465.50", "0.005"], ["70465.60", "1.072"], ["70467.50", "0.000"], ["70467.80", "0.251"], ["70468.00", "0.002"], ["70471.40", "0.016"], ["70471.50", "0.000"], ["70472.50", "1.172"], ["70472.60", "0.347"], ["70472.70", "0.722"], ["70472.80", "0.087"], ["70474.40", "0.110"], ["70474.60", "0.009"], ["70475.70", "0.520"], ["70475.90", "0.010"], ["70476.20", "0.285"], ["70477.20", "0.115"], ["70477.30", "0.002"], ["70477.60", "0.000"], ["70478.00", "0.005"], ["70478.80", "0.001"], ["70479.50", "0.008"], ["70479.90", "0.007"], ["70481.90", "0.640"], ["70483.60", "0.515"], ["70484.70", "0.241"], ["70486.80", "0.001"], ["70487.30", "0.003"], ["70488.80", "0.022"], ["70489.60", "0.000"], ["70490.40", "0.031"], ["70490.50", "0.010"], ["70494.90", "0.058"], ["70497.40", "3.612"]], "a": [["70497.50", "6.653"], ["70498.70", "0.001"], ["70499.30", "0.016"], ["70500.10", "0.003"], ["70500.30", "0.106"], ["70500.50", "0.143"], ["70501.50", "0.013"], ["70502.10", "0.003"], ["70503.20", "0.078"], ["70504.60", "0.002"], ["70505.50", "0.040"], ["70506.20", "0.147"], ["70507.00", "0.251"], ["70508.10", "0.000"], ["70508.40", "3.351"], ["70510.20", "0.000"], ["70511.90", "0.402"], ["70515.40", "0.007"], ["70515.50", "0.400"], ["70515.70", "0.005"], ["70516.00", "0.121"], ["70516.50", "0.004"], ["70516.70", "0.036"], ["70517.20", "0.066"], ["70517.30", "0.638"], ["70520.70", "0.083"], ["70521.90", "0.005"], ["70522.30", "0.009"], ["70523.10", "0.000"], ["70523.30", "0.263"], ["70524.30", "0.004"], ["70524.50", "0.052"], ["70531.40", "0.009"], ["70538.50", "0.078"], ["70545.60", "0.051"], ["70546.80", "0.044"], ["70548.30", "0.163"], ["70549.40", "0.438"], ["70549.70", "0.002"], ["70550.20", "0.030"], ["70551.10", "0.213"], ["70561.30", "0.002"], ["70562.10", "0.263"], ["70562.40", "0.017"], ["70566.70", "0.109"], ["70572.00", "0.081"], ["70582.10", "0.919"], ["70650.60", "0.000"], ["71202.50", "0.000"], ["71319.20", "0.002"], ["74025.40", "0.002"], ["74044.20", "0.000"]]}}
{"local_ts": 1773485131955, "server_ts": 1773485131138, "data": {"e": "depthUpdate", "E": 1773485131139, "T": 1773485131138, "s": "BTCUSDT", "U": 10109433528886, "u": 10109433599139, "pu": 10109433528633, "b": [["5000.00", "101.438"], ["7049.80", "0.028"], ["19994.80", "0.010"], ["19994.90", "0.100"], ["19997.00", "0.050"], ["19997.40", "0.860"], ["20097.40", "1.980"], ["33000.00", "3.789"], ["66036.40", "0.000"], ["66212.50", "0.000"], ["66388.60", "0.000"], ["66564.70", "0.000"], ["66838.20", "0.000"], ["66958.80", "0.062"], ["66962.70", "0.007"], ["67014.10", "0.000"], ["67190.00", "0.004"], ["69786.70", "0.532"], ["69788.60", "0.019"], ["69789.10", "0.000"], ["69789.90", "0.022"], ["69790.00", "0.828"], ["69792.00", "0.004"], ["69792.20", "0.000"], ["69792.40", "1.431"], ["69792.50", "0.004"], ["69812.50", "0.005"], ["70073.10", "0.530"], ["70112.00", "3.966"], ["70116.40", "0.002"], ["70155.10", "1.049"], ["70196.70", "0.288"], ["70198.80", "0.286"], ["70206.50", "0.006"], ["70223.70", "0.293"], ["70241.70", "0.000"], ["70244.30", "1.177"], ["70251.10", "0.096"], ["70277.00", "0.302"], ["70279.50", "0.000"], ["70300.00", "20.181"], ["70301.00", "3.470"], ["70303.10", "0.159"], ["70303.30", "0.159"], ["70311.20", "0.089"], ["70312.20", "0.000"], ["70324.90", "0.691"], ["70325.60", "0.144"], ["70325.70", "0.039"], ["70326.10", "0.090"], ["70327.50", "0.143"], ["70327.80", "0.055"], ["70328.00", "0.058"], ["70328.20", "0.041"], ["70328.60", "0.090"], ["70331.70", "0.039"], ["70333.40", "2.067"], ["70333.50", "0.002"], ["70335.40", "0.172"], ["70346.20", "0.084"], ["70349.00", "0.002"], ["70366.00", "0.847"], ["70367.30", "0.320"], ["70369.40", "0.012"], ["70375.80", "0.000"], ["70375.90", "0.041"], ["70377.10", "0.085"], ["70378.00", "0.218"], ["70378.20", "0.042"], ["70383.70", "0.308"], ["70384.70", "0.627"], ["70385.70", "0.389"], ["70386.10", "0.079"], ["70387.20", "0.008"], ["70390.90", "0.014"], ["70391.10", "0.000"], ["70391.50", "3.091"], ["70394.00", "0.285"], ["70394.40", "0.002"], ["70395.50", "0.156"], ["70397.60", "0.301"], ["70399.30", "0.699"], ["70401.20", "0.283"], ["70401.40", "0.303"], ["70402.20", "0.004"], ["70402.80", "0.000"], ["70402.90", "3.806"], ["70404.80", "0.283"], ["70405.90", "0.072"], ["70407.50", "0.002"], ["70407.70", "0.000"], ["70408.00", "0.461"], ["70408.20", "0.016"], ["70409.70", "0.024"], ["70412.10", "0.046"], ["70413.20", "0.002"], ["70413.60", "0.000"], ["70415.30", "0.048"], ["70416.70", "1.066"], ["70417.50", "0.000"], ["70418.50", "0.004"], ["70419.10", "0.000"], ["70419.30", "0.051"], ["70420.20", "0.064"], ["70420.50", "0.002"], ["70420.70", "0.059"], ["70422.10", "0.388"], ["70423.70", "0.272"], ["70423.80", "0.085"], ["70424.30", "0.081"], ["70425.00", "0.867"], ["70425.10", "0.102"], ["70425.60", "0.003"], ["70426.30", "0.015"], ["70426.60", "0.207"], ["70426.70", "0.286"], ["70427.20", "0.898"], ["70427.60", "0.000"], ["70427.90", "0.003"], ["70428.00", "0.291"], ["70428.40", "0.004"], ["70428.50", "0.400"], ["70430.70", "0.570"], ["70433.70", "0.092"], ["70434.00", "0.010"], ["70434.20", "0.167"], ["70434.50", "0.000"], ["70434.70", "1.350"], ["70435.10", "0.000"], ["70435.40", "0.000"], ["70435.60", "0.000"], ["70435.70", "0.000"], ["70435.80", "0.135"], ["70435.90", "0.068"], ["70436.10", "9.582"], ["70436.20", "0.348"], ["70436.40", "0.041"], ["70436.50", "0.002"], ["70437.00", "0.002"], ["70437.30", "0.000"], ["70437.40", "0.007"], ["70437.50", "0.251"], ["70437.70", "0.127"], ["70437.80", "0.005"], ["70437.90", "0.000"], ["70438.00", "0.936"], ["70438.40", "0.002"], ["70438.60", "0.205"], ["70438.70", "0.400"], ["70439.20", "0.003"], ["70439.30", "0.511"], ["70439.40", "0.068"], ["70439.50", "0.014"], ["70439.60", "0.299"], ["70439.70", "0.422"], ["70440.00", "0.034"], ["70440.10", "0.001"], ["70440.20", "0.020"], ["70440.30", "0.069"], ["70440.50", "0.009"], ["70440.60", "0.004"], ["70440.70", "0.000"], ["70440.80", "0.310"], ["70440.90", "0.013"], ["70441.00", "0.002"], ["70441.10", "0.128"], ["70441.20", "0.000"], ["70441.30", "0.000"], ["70441.40", "0.204"], ["70441.50", "0.003"], ["70441.60", "1.256"], ["70441.70", "0.581"], ["70441.90", "0.002"], ["70442.00", "0.106"], ["70442.20", "0.002"], ["70442.50", "0.000"], ["70442.60", "0.007"], ["70442.70", "0.165"], ["70443.10", "0.003"], ["70443.30", "0.020"], ["70443.60", "0.004"], ["70444.00", "0.002"], ["70444.20", "0.006"], ["70444.50", "0.427"], ["70444.60", "0.539"], ["70444.70", "0.068"], ["70444.80", "0.231"], ["70445.00", "0.000"], ["70445.20", "0.843"], ["70445.30", "0.011"], ["70445.50", "0.139"], ["70445.60", "0.197"], ["70445.70", "0.242"], ["70445.80", "0.105"], ["70446.00", "0.002"], ["70446.10", "0.000"], ["70446.20", "0.002"], ["70446.30", "0.227"], ["70446.50", "0.002"], ["70446.60", "0.021"], ["70446.80", "0.001"], ["70446.90", "0.002"], ["70447.00", "0.002"], ["70447.30", "0.004"], ["70447.50", "0.851"], ["70447.60", "0.003"], ["70447.70", "0.003"], ["70447.90", "0.384"], ["70448.00", "1.176"], ["70448.10", "0.430"], ["70448.20", "0.034"], ["70448.30", "0.016"], ["70448.40", "0.260"], ["70448.50", "0.000"], ["70448.70", "0.047"], ["70448.90", "0.100"], ["70449.10", "0.010"], ["70449.20", "0.002"], ["70449.30", "0.091"], ["70449.40", "0.005"], ["70449.50", "0.376"], ["70449.80", "0.000"], ["70450.00", "0.061"], ["70450.10", "0.000"], ["70450.30", "0.230"], ["70451.00", "0.004"], ["70451.20", "0.059"], ["70451.40", "0.691"], ["70451.60", "0.529"], ["70451.70", "0.031"], ["70451.80", "0.171"], ["70451.90", "0.648"], ["70452.10", "0.000"], ["70452.60", "0.037"], ["70453.10", "1.066"], ["70453.30", "0.000"], ["70453.60", "1.200"], ["70453.70", "0.012"], ["70453.80", "0.002"], ["70453.90", "0.335"], ["70454.30", "0.403"], ["70454.80", "0.960"], ["70455.20", "0.348"], ["70455.30", "0.515"], ["70455.40", "0.164"], ["70455.50", "0.004"], ["70455.70", "0.000"], ["70455.80", "0.006"], ["70455.90", "0.000"], ["70456.00", "1.729"], ["70456.10", "0.122"], ["70456.40", "0.002"], ["70456.70", "0.000"], ["70456.80", "0.080"], ["70456.90", "0.021"], ["70457.00", "0.000"], ["70457.40", "0.017"], ["70457.70", "0.033"], ["70457.80", "0.013"], ["70458.20", "0.000"], ["70458.30", "0.002"], ["70458.40", "0.114"], ["70458.50", "0.002"], ["70458.60", "0.023"], ["70458.80", "1.375"], ["70459.20", "0.004"], ["70459.40", "0.061"], ["70459.60", "0.840"], ["70459.70", "0.252"], ["70459.80", "0.025"], ["70459.90", "0.211"], ["70460.00", "0.025"], ["70460.30", "0.003"], ["70460.40", "0.511"], ["70460.50", "0.605"], ["70460.60", "0.000"], ["70460.70", "0.000"], ["70461.10", "0.001"], ["70461.20", "0.005"], ["70461.30", "0.381"], ["70461.40", "0.059"], ["70461.50", "0.295"], ["70461.60", "0.003"], ["70461.70", "0.000"], ["70461.80", "0.024"], ["70461.90", "0.036"], ["70462.00", "0.091"], ["70462.10", "0.004"], ["70462.20", "0.001"], ["70462.30", "0.002"], ["70462.40", "0.294"], ["70462.50", "0.000"], ["70462.60", "0.000"], ["70462.70", "0.795"], ["70462.80", "0.005"], ["70463.00", "0.000"], ["70463.10", "0.143"], ["70463.20", "0.930"], ["70463.30", "0.012"], ["70463.40", "0.003"], ["70463.60", "0.585"], ["70463.70", "0.408"], ["70463.80", "0.026"], ["70463.90", "0.005"], ["70464.00", "0.049"], ["70464.10", "0.002"], ["70464.40", "0.000"], ["70464.50", "0.002"], ["70464.70", "0.000"], ["70464.90", "0.011"], ["70465.00", "0.161"], ["70465.20", "0.024"], ["70465.30", "0.000"], ["70465.40", "0.313"], ["70465.50", "0.003"], ["70465.60", "1.072"], ["70465.70", "0.004"], ["70465.80", "0.056"], ["70465.90", "0.101"], ["70466.00", "0.295"], ["70466.10", "0.197"], ["70466.20", "0.143"], ["70466.30", "1.167"], ["70466.40", "0.512"], ["70466.50", "0.002"], ["70466.60", "0.007"], ["70466.80", "0.000"], ["70466.90", "0.347"], ["70467.00", "0.511"], ["70467.10", "0.000"], ["70467.50", "0.000"], ["70467.60", "1.066"], ["70467.70", "0.004"], ["70467.80", "0.024"], ["70468.10", "0.068"], ["70468.20", "0.004"], ["70468.30", "0.000"], ["70468.40", "0.006"], ["70468.50", "0.582"], ["70468.60", "0.076"], ["70468.70", "0.000"], ["70468.80", "0.067"], ["70468.90", "0.011"], ["70469.00", "0.559"], ["70469.10", "0.054"], ["70469.20", "0.143"], ["70469.40", "0.000"], ["70469.50", "0.000"], ["70469.60", "0.060"], ["70469.80", "0.025"], ["70470.00", "4.905"], ["70470.10", "0.359"], ["70470.20", "0.649"], ["70470.30", "0.005"], ["70470.40", "0.008"], ["70470.50", "0.511"], ["70470.60", "1.150"], ["70470.80", "0.073"], ["70471.00", "0.155"], ["70471.10", "0.007"], ["70471.20", "0.208"], ["70471.40", "0.001"], ["70471.50", "0.000"], ["70471.60", "0.000"], ["70471.70", "0.005"], ["70471.90", "0.000"], ["70472.10", "0.000"], ["70472.20", "0.031"], ["70472.30", "0.007"], ["70472.40", "0.006"], ["70472.50", "0.010"], ["70472.60", "0.006"], ["70472.70", "0.516"], ["70472.80", "1.074"], ["70472.90", "0.412"], ["70473.00", "0.050"], ["70473.10", "0.002"], ["70473.20", "0.058"], ["70473.30", "0.340"], ["70473.40", "1.215"], ["70473.50", "0.000"], ["70473.60", "0.030"], ["70473.70", "0.003"], ["70474.00", "0.006"], ["70474.10", "0.349"], ["70474.20", "0.001"], ["70474.40", "0.011"], ["70474.50", "0.010"], ["70474.60", "0.002"], ["70474.70", "0.641"], ["70474.80", "0.634"], ["70474.90", "0.340"], ["70475.00", "0.008"], ["70475.10", "0.003"], ["70475.20", "0.013"], ["70475.50", "0.010"], ["70475.60", "0.000"], ["70475.80", "0.004"], ["70475.90", "0.002"], ["70476.00", "0.017"], ["70476.10", "0.003"], ["70476.30", "0.111"], ["70476.40", "0.008"], ["70476.50", "0.001"], ["70476.60", "0.012"], ["70476.70", "0.518"], ["70476.80", "0.002"], ["70476.90", "0.430"], ["70477.00", "0.005"], ["70477.10", "0.000"], ["70477.30", "0.004"], ["70477.60", "0.000"], ["70477.70", "0.002"], ["70478.00", "0.005"], ["70478.20", "0.004"], ["70478.30", "0.426"], ["70478.40", "0.011"], ["70478.50", "0.010"], ["70478.60", "0.002"], ["70478.90", "0.000"], ["70479.10", "0.011"], ["70479.20", "0.032"], ["70479.40", "0.428"], ["70479.50", "0.006"], ["70479.60", "0.003"], ["70479.80", "0.342"], ["70480.30", "0.221"], ["70480.40", "0.291"], ["70480.50", "1.083"], ["70480.70", "0.001"], ["70480.80", "0.009"], ["70480.90", "0.000"], ["70481.20", "0.001"], ["70481.30", "0.007"], ["70481.50", "0.000"], ["70481.90", "0.938"], ["70482.10", "0.008"], ["70482.40", "0.000"], ["70482.50", "0.010"], ["70482.60", "0.003"], ["70482.70", "0.003"], ["70482.80", "0.004"], ["70482.90", "0.000"], ["70483.00", "0.012"], ["70483.10", "0.001"], ["70483.20", "0.000"], ["70483.30", "0.003"], ["70483.50", "0.003"], ["70483.60", "0.004"], ["70483.80", "0.004"], ["70483.90", "0.095"], ["70484.00", "0.219"], ["70484.10", "0.000"], ["70484.20", "0.001"], ["70484.30", "0.006"], ["70484.40", "0.002"], ["70484.50", "0.000"], ["70484.60", "0.003"], ["70484.80", "0.000"], ["70485.60", "0.007"], ["70485.80", "0.049"], ["70486.00", "0.004"], ["70486.10", "0.007"], ["70486.40", "0.259"], ["70486.50", "0.106"], ["70486.60", "0.217"], ["70486.70", "0.255"], ["70486.80", "0.115"], ["70486.90", "0.000"], ["70487.00", "0.005"], ["70487.10", "0.029"], ["70487.50", "0.000"], ["70487.60", "0.021"], ["70487.70", "0.000"], ["70487.80", "0.041"], ["70488.10", "0.001"], ["70488.20", "0.002"], ["70488.40", "0.008"], ["70488.60", "0.000"], ["70488.70", "0.000"], ["70488.90", "0.002"], ["70489.00", "0.004"], ["70489.10", "0.000"], ["70489.20", "0.002"], ["70489.30", "0.001"], ["70489.50", "0.003"], ["70489.90", "0.002"], ["70490.00", "0.012"], ["70490.20", "0.002"], ["70490.40", "0.004"], ["70490.90", "0.001"], ["70491.10", "0.004"], ["70491.20", "0.003"], ["70491.40", "0.003"], ["70491.50", "0.000"], ["70491.60", "0.177"], ["70491.70", "0.000"], ["70491.80", "0.000"], ["70492.10", "0.000"], ["70492.30", "0.000"], ["70492.40", "0.000"], ["70492.50", "0.000"], ["70492.60", "0.000"], ["70492.70", "0.000"], ["70492.80", "0.000"], ["70492.90", "0.000"], ["70493.00", "0.000"], ["70493.10", "0.000"], ["70493.30", "0.000"], ["70493.40", "0.000"], ["70493.50", "0.000"], ["70493.60", "0.000"], ["70493.70", "0.000"], ["70493.80", "0.000"], ["70493.90", "0.000"], ["70494.00", "0.000"], ["70494.10", "0.000"], ["70494.20", "0.000"], ["70494.40", "0.000"], ["70494.50", "0.000"], ["70494.80", "0.000"], ["70494.90", "0.000"], ["70495.00", "0.000"], ["70495.10", "0.000"], ["70495.20", "0.000"], ["70495.30", "0.000"], ["70495.50", "0.000"], ["70495.60", "0.000"], ["70495.70", "0.000"], ["70495.80", "0.000"], ["70496.00", "0.000"], ["70496.10", "0.000"], ["70496.30", "0.000"], ["70496.40", "0.000"], ["70496.60", "0.000"], ["70497.00", "0.000"], ["70497.10", "0.000"], ["70497.20", "0.000"], ["70497.30", "0.000"], ["70497.40", "0.000"]], "a": [["70491.70", "27.466"], ["70491.80", "1.053"], ["70491.90", "0.014"], ["70492.20", "0.014"], ["70492.40", "0.683"], ["70492.60", "0.014"], ["70492.70", "0.014"], ["70492.80", "0.147"], ["70492.90", "0.145"], ["70493.10", "0.145"], ["70493.40", "0.153"], ["70493.50", "3.191"], ["70493.60", "0.728"], ["70493.70", "0.000"], ["70493.80", "0.145"], ["70493.90", "0.145"], ["70494.00", "0.147"], ["70494.10", "0.145"], ["70494.20", "0.000"], ["70494.30", "0.145"], ["70494.50", "0.145"], ["70494.60", "0.016"], ["70494.70", "0.000"], ["70494.80", "0.002"], ["70494.90", "0.673"], ["70495.00", "0.137"], ["70495.10", "0.015"], ["70495.20", "0.080"], ["70495.30", "0.014"], ["70495.40", "0.000"], ["70495.50", "0.000"], ["70495.60", "0.000"], ["70495.70", "0.000"], ["70495.80", "0.000"], ["70495.90", "0.085"], ["70496.00", "0.080"], ["70496.10", "0.000"], ["70496.20", "0.002"], ["70496.40", "0.000"], ["70496.50", "0.002"], ["70496.70", "0.058"], ["70496.80", "0.014"], ["70496.90", "1.418"], ["70497.00", "2.061"], ["70497.10", "0.548"], ["70497.20", "0.003"], ["70497.30", "0.318"], ["70497.40", "0.004"], ["70497.50", "0.983"], ["70497.60", "0.045"], ["70497.80", "0.000"], ["70497.90", "0.001"], ["70498.00", "0.000"], ["70498.10", "0.002"], ["70498.30", "0.001"], ["70498.40", "0.000"], ["70498.50", "0.002"], ["70498.60", "0.000"], ["70498.70", "0.001"], ["70498.80", "0.002"], ["70499.00", "0.005"], ["70499.20", "0.002"], ["70499.30", "0.005"], ["70499.40", "0.009"], ["70499.70", "0.001"], ["70499.90", "0.003"], ["70500.00", "0.003"], ["70500.10", "0.000"], ["70500.30", "0.000"], ["70500.40", "0.235"], ["70500.50", "0.145"], ["70500.70", "0.019"], ["70501.00", "0.035"], ["70501.60", "0.106"], ["70501.90", "0.070"], ["70502.00", "0.006"], ["70502.10", "0.003"], ["70502.20", "0.206"], ["70502.30", "0.002"], ["70502.40", "0.002"], ["70502.80", "0.004"], ["70502.90", "0.348"], ["70503.00", "0.008"], ["70503.30", "0.003"], ["70503.90", "0.009"], ["70504.00", "0.252"], ["70504.10", "0.023"], ["70504.20", "0.002"], ["70504.30", "0.000"], ["70504.40", "0.012"], ["70504.50", "0.078"], ["70504.60", "0.005"], ["70505.00", "0.008"], ["70505.30", "0.088"], ["70505.50", "0.050"], ["70505.70", "0.007"], ["70505.80", "0.067"], ["70505.90", "1.067"], ["70506.00", "0.529"], ["70506.10", "0.136"], ["70506.20", "0.154"], ["70506.40", "0.000"], ["70506.60", "0.008"], ["70506.70", "0.004"], ["70506.90", "0.237"], ["70507.00", "0.205"], ["70507.30", "0.000"], ["70507.40", "0.014"], ["70507.50", "0.004"], ["70507.60", "0.004"], ["70507.70", "0.753"], ["70508.00", "0.003"], ["70508.10", "0.000"], ["70508.20", "0.002"], ["70508.30", "0.586"], ["70508.40", "3.093"], ["70508.50", "0.005"], ["70508.60", "0.007"], ["70508.70", "0.000"], ["70508.90", "0.002"], ["70509.00", "0.005"], ["70509.10", "0.068"], ["70509.20", "0.002"], ["70509.40", "0.000"], ["70510.20", "0.000"], ["70510.40", "0.011"], ["70510.50", "0.000"], ["70510.60", "0.511"], ["70510.70", "0.731"], ["70511.40", "0.644"], ["70511.50", "0.452"], ["70511.60", "1.069"], ["70511.70", "0.029"], ["70511.80", "0.049"], ["70512.10", "0.002"], ["70512.20", "0.002"], ["70512.90", "0.521"], ["70513.40", "0.023"], ["70514.10", "0.002"], ["70514.20", "0.003"], ["70514.40", "0.002"], ["70514.70", "0.249"], ["70514.80", "0.557"], ["70515.30", "0.082"], ["70515.50", "0.000"], ["70515.60", "0.202"], ["70515.70", "0.057"], ["70516.00", "0.075"], ["70516.10", "0.012"], ["70516.20", "0.021"], ["70516.50", "0.003"], ["70516.90", "0.007"], ["70517.10", "0.008"], ["70517.20", "0.078"], ["70517.50", "0.260"], ["70518.00", "0.006"], ["70518.30", "0.004"], ["70518.40", "0.000"], ["70518.50", "0.003"], ["70518.60", "0.004"], ["70518.70", "0.003"], ["70518.90", "0.004"], ["70519.30", "0.072"], ["70519.70", "0.000"], ["70520.30", "0.054"], ["70520.50", "0.000"], ["70520.60", "0.013"], ["70520.90", "0.073"], ["70521.20", "0.003"], ["70521.40", "0.003"], ["70521.50", "0.547"], ["70521.90", "0.005"], ["70522.30", "0.002"], ["70522.60", "0.006"], ["70522.70", "0.002"], ["70522.90", "0.002"], ["70523.00", "0.035"], ["70523.50", "0.006"], ["70523.60", "0.004"], ["70523.70", "0.004"], ["70524.20", "0.016"], ["70524.30", "0.004"], ["70524.60", "0.052"], ["70524.80", "0.012"], ["70525.00", "0.119"], ["70525.10", "0.874"], ["70525.20", "0.600"], ["70525.50", "0.009"], ["70525.60", "0.009"], ["70526.00", "0.343"], ["70526.10", "0.575"], ["70526.40", "0.012"], ["70526.70", "0.023"], ["70526.90", "0.346"], ["70527.00", "0.009"], ["70527.20", "0.005"], ["70527.30", "0.000"], ["70528.70", "0.842"], ["70528.80", "0.344"], ["70529.20", "0.047"], ["70529.30", "0.024"], ["70529.40", "0.086"], ["70529.60", "0.059"], ["70529.90", "0.041"], ["70530.10", "0.071"], ["70530.20", "0.013"], ["70530.40", "0.099"], ["70530.50", "0.377"], ["70530.60", "0.002"], ["70530.70", "0.006"], ["70531.40", "0.007"], ["70532.00", "0.012"], ["70533.60", "0.075"], ["70535.50", "0.006"], ["70535.90", "0.084"], ["70536.30", "0.073"], ["70537.90", "0.000"], ["70538.00", "0.028"], ["70538.50", "0.078"], ["70538.80", "0.003"], ["70539.20", "0.000"], ["70539.40", "0.097"], ["70539.50", "0.006"], ["70539.80", "0.500"], ["70540.10", "0.003"], ["70540.50", "0.325"], ["70541.40", "0.015"], ["70541.50", "0.003"], ["70541.90", "0.008"], ["70542.00", "0.004"], ["70542.10", "0.133"], ["70542.30", "0.554"], ["70542.40", "0.088"], ["70542.90", "0.003"], ["70543.30", "0.027"], ["70543.70", "0.636"], ["70543.90", "0.006"], ["70544.30", "0.138"], ["70545.60", "0.051"], ["70545.90", "0.093"], ["70546.80", "0.035"], ["70547.20", "0.089"], ["70547.80", "0.006"], ["70547.90", "0.047"], ["70548.60", "0.002"], ["70549.30", "0.031"], ["70549.50", "0.518"], ["70549.60", "1.817"], ["70550.00", "0.563"], ["70550.40", "0.036"], ["70550.50", "0.045"], ["70550.80", "0.098"], ["70551.20", "1.103"], ["70551.30", "0.003"], ["70551.40", "0.075"], ["70551.50", "8.503"], ["70552.10", "0.853"], ["70553.30", "1.102"], ["70553.40", "0.004"], ["70553.50", "0.259"], ["70555.60", "0.027"], ["70555.80", "0.225"], ["70556.80", "1.183"], ["70557.00", "0.014"], ["70557.10", "2.587"], ["70557.40", "0.092"], ["70558.30", "0.000"], ["70558.40", "0.011"], ["70558.70", "0.956"], ["70560.60", "0.002"], ["70560.90", "0.028"], ["70564.50", "0.000"], ["70565.10", "0.225"], ["70565.40", "0.005"], ["70566.80", "0.000"], ["70568.60", "0.003"], ["70570.60", "0.000"], ["70571.70", "0.176"], ["70577.60", "0.000"], ["70580.40", "0.242"], ["70580.90", "0.071"], ["70582.60", "0.259"], ["70584.80", "0.002"], ["70590.20", "6.535"], ["70593.80", "0.438"], ["70594.00", "0.006"], ["70597.10", "1.918"], ["70597.20", "0.673"], ["70599.70", "0.119"], ["70602.70", "0.127"], ["70603.20", "0.000"], ["70604.60", "0.000"], ["70605.30", "0.002"], ["70608.90", "0.023"], ["70609.70", "0.022"], ["70616.10", "0.178"], ["70616.30", "0.000"], ["70617.80", "0.110"], ["70624.20", "0.061"], ["70628.50", "0.418"], ["70632.20", "0.210"], ["70632.50", "0.110"], ["70635.00", "0.000"], ["70641.60", "0.119"], ["70658.20", "0.511"], ["70664.40", "1.047"], ["70666.10", "0.000"], ["70671.50", "0.060"], ["70673.40", "0.183"], ["70674.80", "0.003"], ["70676.90", "0.000"], ["70677.10", "4.567"], ["70677.30", "0.000"], ["70678.20", "0.000"], ["70678.30", "0.000"], ["70693.00", "0.221"], ["70700.00", "22.668"], ["70702.90", "0.000"], ["70752.00", "0.008"], ["70762.10", "0.000"], ["70772.00", "1.715"], ["70788.60", "0.002"], ["70792.20", "0.004"], ["70812.20", "0.211"], ["70815.90", "0.000"], ["70817.40", "0.000"], ["70819.30", "0.211"], ["70821.80", "0.000"], ["70868.70", "0.547"], ["71196.60", "0.565"], ["71198.50", "0.002"], ["71199.80", "0.000"], ["71199.90", "2.243"], ["71202.10", "2.103"], ["71202.50", "0.000"], ["71470.10", "0.000"], ["71471.30", "0.000"], ["71471.40", "0.008"], ["71474.00", "0.000"], ["71493.60", "0.500"], ["71494.10", "0.534"], ["71494.90", "0.004"], ["71495.00", "0.019"], ["71497.10", "0.046"], ["71497.50", "0.715"], ["71500.10", "0.000"], ["71904.80", "0.013"], ["71913.90", "0.004"], ["100000.00", "23.620"]]}}
{"local_ts": 1773485133100, "server_ts": 1773485132157, "data": {"e": "depthUpdate", "E": 1773485132159, "T": 1773485132157, "s": "BTCUSDT", "U": 10109433664027, "u": 10109433669747, "pu": 10109433663967, "b": [["1000.00", "28.692"], ["5000.00", "101.418"], ["7049.20", "0.000"], ["19991.60", "1.950"], ["19997.40", "0.280"], ["20097.40", "0.000"], ["20391.60", "0.580"], ["69786.70", "0.150"], ["70139.10", "0.116"], ["70304.80", "0.222"], ["70356.80", "0.435"], ["70367.30", "0.009"], ["70370.10", "0.735"], ["70386.40", "0.774"], ["70386.70", "0.004"], ["70387.00", "0.047"], ["70387.10", "6.523"], ["70387.80", "0.048"], ["70390.40", "1.159"], ["70394.00", "0.285"], ["70441.40", "0.204"], ["70441.60", "1.258"], ["70447.70", "0.060"], ["70456.50", "0.041"], ["70465.60", "1.074"], ["70466.00", "0.004"], ["70466.10", "0.199"], ["70469.60", "0.060"], ["70472.60", "0.013"], ["70473.20", "0.058"], ["70473.90", "0.000"], ["70474.00", "0.210"], ["70477.50", "0.225"], ["70479.20", "0.062"], ["70479.30", "0.221"], ["70479.40", "0.002"], ["70479.60", "0.104"], ["70480.90", "0.000"], ["70481.00", "0.794"], ["70482.60", "0.021"], ["70486.80", "0.285"], ["70489.50", "0.005"], ["70491.50", "0.008"], ["70491.60", "1.287"]], "a": [["70491.70", "8.681"], ["70496.80", "0.015"], ["70498.10", "0.000"], ["70498.80", "0.002"], ["70502.20", "0.206"], ["70502.30", "0.002"], ["70504.00", "0.405"], ["70505.90", "1.067"], ["70509.20", "0.002"], ["70511.90", "0.002"], ["70512.70", "0.004"], ["70513.30", "0.510"], ["70516.20", "0.021"], ["70517.00", "0.385"], ["70517.40", "0.002"], ["70517.50", "0.515"], ["70520.70", "0.011"], ["70523.20", "0.004"], ["70530.20", "0.013"], ["70537.20", "0.495"], ["70544.20", "0.007"], ["70549.30", "0.865"], ["70551.20", "0.323"], ["70558.70", "0.956"], ["70583.30", "0.019"], ["70591.70", "0.015"], ["70598.70", "0.206"], ["70605.70", "0.009"], ["70612.70", "0.009"], ["70619.70", "0.007"], ["70626.70", "0.518"], ["70633.70", "0.009"], ["70640.70", "2.307"], ["70678.50", "6.864"], ["70722.00", "2.416"], ["70844.20", "0.211"], ["70930.20", "0.013"], ["71196.60", "0.563"], ["71519.70", "0.986"], ["73311.30", "0.015"], ["74018.30", "0.000"], ["74044.00", "0.009"], ["74054.50", "0.050"], ["74066.10", "0.000"]]}}
{"local_ts": 1773485134319, "server_ts": 1773485133384, "data": {"e": "depthUpdate", "E": 1773485133385, "T": 1773485133384, "s": "BTCUSDT", "U": 10109433761047, "u": 10109433765581, "pu": 10109433760972, "b": [["1000.00", "28.692"], ["5000.00", "101.418"], ["7048.70", "0.000"], ["19991.60", "0.000"], ["20286.60", "0.650"], ["20386.60", "2.100"], ["20391.60", "0.230"], ["33000.00", "3.785"], ["66960.20", "0.004"], ["66962.00", "0.020"], ["67667.20", "0.004"], ["69394.10", "1.008"], ["69605.50", "0.717"], ["69781.70", "0.002"], ["70069.10", "0.035"], ["70134.20", "0.002"], ["70138.10", "0.252"], ["70174.90", "2.479"], ["70205.80", "1.161"], ["70226.40", "0.439"], ["70248.50", "7.110"], ["70279.90", "3.583"], ["70330.50", "3.374"], ["70364.10", "0.311"], ["70389.90", "0.005"], ["70394.90", "1.141"], ["70416.50", "0.522"], ["70424.00", "0.830"], ["70436.30", "0.658"], ["70438.00", "0.944"], ["70438.40", "0.004"], ["70445.40", "0.407"], ["70445.50", "0.000"], ["70446.10", "0.377"], ["70447.80", "0.143"], ["70448.20", "0.218"], ["70456.40", "0.006"], ["70464.40", "0.510"], ["70464.50", "0.568"], ["70472.50", "0.445"], ["70474.30", "0.239"], ["70476.00", "0.174"], ["70479.20", "0.045"], ["70479.60", "0.039"], ["70482.20", "0.285"], ["70483.30", "0.129"], ["70483.50", "0.024"], ["70484.20", "0.009"], ["70484.30", "0.030"]], "a": [["70486.70", "5.661"], ["70490.30", "0.017"], ["70491.20", "0.058"], ["70491.70", "0.032"], ["70493.70", "0.001"], ["70493.80", "0.005"], ["70495.10", "0.001"], ["70497.30", "0.230"], ["70501.90", "0.033"], ["70503.20", "0.003"], ["70508.30", "1.053"], ["70511.70", "0.009"], ["70511.80", "0.056"], ["70527.80", "0.000"], ["70527.90", "0.006"], ["70529.50", "1.094"], ["70532.30", "0.007"], ["70536.60", "0.466"], ["70543.00", "0.341"], ["70543.30", "0.111"], ["70544.40", "0.002"], ["70550.00", "0.563"], ["70553.20", "0.737"], ["70568.00", "0.524"], ["70587.10", "0.002"], ["70593.90", "0.003"], ["70602.70", "2.522"], ["70658.00", "0.550"], ["70658.10", "1.631"], ["70710.40", "0.007"], ["70809.90", "4.990"], ["70899.90", "1.939"], ["71191.60", "0.000"], ["71508.80", "1.002"], ["71579.20", "0.977"], ["74040.50", "0.004"], ["89523.20", "0.000"]]}}
{"local_ts": 1773485135516, "server_ts": 1773485134610, "data": {"e": "depthUpdate", "E": 1773485134611, "T": 1773485134610, "s": "BTCUSDT", "U": 10109433822479, "u": 10109433826813, "pu": 10109433822435, "b": [["1000.00", "28.692"], ["5000.00", "101.438"], ["7048.70", "0.056"], ["20186.60", "0.710"], ["20286.60", "2.290"], ["56389.00", "0.000"], ["66954.20", "0.002"], ["69076.90", "0.026"], ["69464.50", "4.024"], ["69781.70", "0.002"], ["70134.20", "0.002"], ["70134.30", "0.000"], ["70240.60", "0.004"], ["70332.50", "0.096"], ["70334.30", "0.063"], ["70346.80", "0.028"], ["70354.00", "0.000"], ["70354.90", "0.094"], ["70360.50", "2.548"], ["70360.60", "0.006"], ["70375.90", "0.002"], ["70376.00", "0.214"], ["70386.10", "0.001"], ["70392.40", "0.003"], ["70399.40", "2.587"], ["70405.50", "0.303"], ["70410.40", "0.000"], ["70415.80", "0.000"], ["70419.60", "0.002"], ["70422.50", "0.205"], ["70425.40", "0.042"], ["70427.30", "0.000"], ["70438.00", "0.944"], ["70438.30", "0.345"], ["70444.30", "7.910"], ["70445.40", "0.268"], ["70449.60", "0.090"], ["70464.60", "0.005"], ["70464.70", "0.069"], ["70472.50", "0.710"], ["70474.30", "0.060"], ["70476.00", "0.177"], ["70478.80", "0.400"], ["70482.50", "0.023"], ["70483.80", "0.008"]], "a": [["70486.70", "5.743"], ["70486.80", "0.043"], ["70488.60", "0.002"], ["70493.40", "0.041"], ["70495.50", "0.006"], ["70500.40", "0.232"], ["70504.10", "0.021"], ["70511.70", "0.002"], ["70516.00", "0.000"], ["70516.70", "0.073"], ["70517.70", "0.002"], ["70520.00", "0.027"], ["70520.20", "0.179"], ["70525.20", "0.297"], ["70526.10", "0.577"], ["70527.20", "0.286"], ["70528.00", "0.029"], ["70528.50", "2.115"], ["70529.00", "0.292"], ["70529.30", "0.024"], ["70529.50", "8.927"], ["70532.50", "0.370"], ["70539.00", "0.004"], ["70539.40", "0.015"], ["70543.10", "0.339"], ["70548.40", "0.089"], ["70551.50", "0.000"], ["70552.20", "0.003"], ["70552.30", "0.340"], ["70553.10", "0.003"], ["70553.60", "0.000"], ["70555.50", "0.285"], ["70556.10", "0.046"], ["70556.90", "0.384"], ["70677.00", "0.378"], ["70710.20", "0.007"], ["70878.00", "0.212"], ["71191.60", "0.000"], ["71513.70", "0.000"], ["71513.80", "10.054"], ["71654.80", "1.952"], ["71918.50", "0.000"], ["72642.50", "0.017"], ["74037.40", "0.000"], ["89523.20", "0.000"]]}}
{"local_ts": 1773485136677, "server_ts": 1773485135632, "data": {"e": "depthUpdate", "E": 1773485135633, "T": 1773485135632, "s": "BTCUSDT", "U": 10109433886323, "u": 10109433904426, "pu": 10109433886214, "b": [["5000.00", "101.418"], ["7048.70", "0.056"], ["20086.60", "0.330"], ["20186.60", "2.600"], ["20286.60", "0.070"], ["56389.00", "0.000"], ["69781.70", "0.002"], ["70134.10", "0.000"], ["70240.50", "0.004"], ["70309.20", "0.002"], ["70311.20", "0.089"], ["70324.80", "0.090"], ["70325.50", "0.293"], ["70344.50", "0.078"], ["70351.70", "0.078"], ["70358.30", "0.170"], ["70373.60", "0.193"], ["70383.70", "0.386"], ["70390.00", "0.053"], ["70392.20", "1.568"], ["70394.50", "0.312"], ["70401.00", "0.044"], ["70404.70", "0.041"], ["70407.60", "0.089"], ["70409.00", "0.221"], ["70409.20", "0.929"], ["70412.80", "0.973"], ["70415.70", "0.118"], ["70418.60", "0.709"], ["70420.50", "0.041"], ["70428.10", "0.000"], ["70437.00", "0.003"], ["70438.00", "0.944"], ["70438.40", "0.004"], ["70444.40", "1.984"], ["70448.20", "0.218"], ["70448.60", "0.051"], ["70451.40", "0.691"], ["70454.90", "0.166"], ["70456.30", "0.004"], ["70456.40", "0.006"], ["70456.50", "0.010"], ["70457.00", "0.000"], ["70457.10", "0.019"], ["70458.40", "0.055"], ["70458.50", "0.115"], ["70459.10", "0.001"], ["70459.20", "0.002"], ["70469.20", "0.127"], ["70471.10", "0.000"], ["70472.50", "0.374"], ["70474.40", "0.092"], ["70474.60", "0.293"], ["70476.00", "0.022"], ["70479.30", "0.001"], ["70479.80", "0.085"], ["70480.00", "0.008"], ["70481.10", "0.002"], ["70482.40", "0.002"], ["70483.10", "0.001"], ["70483.40", "0.016"], ["70485.00", "0.049"], ["70486.60", "5.442"]], "a": [["70486.70", "1.377"], ["70487.20", "0.082"], ["70491.00", "0.045"], ["70491.50", "0.000"], ["70492.90", "0.048"], ["70493.80", "0.005"], ["70493.90", "0.000"], ["70494.30", "0.085"], ["70494.50", "0.000"], ["70494.60", "0.006"], ["70494.80", "0.005"], ["70496.60", "0.514"], ["70496.70", "0.320"], ["70496.80", "0.071"], ["70497.30", "0.233"], ["70499.60", "0.094"], ["70503.80", "0.022"], ["70504.30", "0.030"], ["70505.10", "0.511"], ["70505.20", "0.343"], ["70505.50", "0.064"], ["70506.10", "0.154"], ["70507.80", "0.271"], ["70508.20", "0.584"], ["70511.40", "0.085"], ["70511.90", "1.068"], ["70513.80", "0.002"], ["70513.90", "0.053"], ["70514.50", "0.002"], ["70514.60", "0.005"], ["70515.40", "0.035"], ["70515.90", "0.075"], ["70516.00", "0.002"], ["70516.60", "0.002"], ["70516.70", "0.101"], ["70520.50", "0.140"], ["70523.00", "0.045"], ["70525.60", "0.010"], ["70529.00", "0.022"], ["70533.20", "0.036"], ["70539.80", "0.360"], ["70543.50", "0.002"], ["70545.50", "0.017"], ["70553.50", "0.542"], ["70553.80", "0.134"], ["70563.50", "0.002"], ["70564.60", "0.026"], ["70583.30", "0.230"], ["70654.10", "0.178"], ["70700.00", "22.068"], ["70710.30", "0.009"], ["70766.00", "0.000"], ["71191.50", "0.010"], ["71191.60", "0.701"], ["74043.40", "0.002"], ["89523.20", "0.000"]]}}
{"local_ts": 1773485137756, "server_ts": 1773485136960, "data": {"e": "depthUpdate", "E": 1773485136961, "T": 1773485136960, "s": "BTCUSDT", "U": 10109433985240, "u": 10109433989778, "pu": 10109433985101, "b": [["1000.00", "28.692"], ["5000.00", "101.418"], ["7048.70", "0.000"], ["19986.60", "0.590"], ["20086.60", "2.410"], ["20186.60", "0.000"], ["63437.90", "0.000"], ["66940.30", "0.002"], ["69649.00", "4.872"], ["69781.70", "0.717"], ["69855.80", "0.016"], ["69860.70", "0.035"], ["69894.50", "0.034"], ["69932.50", "0.008"], ["70134.20", "0.012"], ["70168.00", "1.375"], ["70351.50", "1.541"], ["70430.40", "0.629"], ["70437.70", "0.074"]], "a": [["70486.70", "1.357"], ["70494.00", "0.014"], ["70494.10", "0.003"], ["70499.80", "0.057"], ["70511.10", "0.013"], ["70619.00", "7.007"], ["70677.00", "0.279"], ["71045.90", "0.006"], ["71123.10", "0.016"], ["71128.10", "0.000"], ["71191.60", "0.701"], ["71473.50", "0.004"], ["72271.00", "0.000"], ["74039.70", "0.000"], ["77535.40", "0.000"]]}}
{"local_ts": 1773485138827, "server_ts": 1773485137880, "data": {"e": "depthUpdate", "E": 1773485137883, "T": 1773485137880, "s": "BTCUSDT", "U": 10109434033696, "u": 10109434038343, "pu": 10109434033628, "b": [["1000.00", "28.692"], ["5000.00", "101.398"], ["7048.70", "0.028"], ["19986.60", "2.490"], ["20086.60", "0.310"], ["20386.60", "0.200"], ["63437.90", "0.002"], ["66983.00", "0.010"], ["69781.70", "0.717"], ["70134.20", "0.002"], ["70351.80", "0.713"], ["70438.60", "0.158"], ["70438.70", "0.109"], ["70444.60", "0.512"], ["70476.00", "0.022"], ["70479.70", "0.616"], ["70486.60", "5.158"]], "a": [["70486.70", "1.694"], ["70493.80", "0.002"], ["70494.30", "0.003"], ["70496.20", "0.069"], ["70496.30", "0.003"], ["70496.50", "0.088"], ["70505.70", "0.002"], ["70513.40", "0.092"], ["70521.90", "0.111"], ["70545.20", "0.004"], ["70619.10", "0.485"], ["70699.70", "6.513"], ["70809.40", "0.648"], ["70915.70", "3.240"], ["71059.80", "1.207"], ["71191.60", "0.701"], ["71199.90", "0.140"], ["71249.90", "0.003"], ["71896.40", "0.456"], ["72618.40", "0.007"], ["73873.70", "0.002"], ["74022.20", "0.200"], ["77535.40", "0.002"], ["89523.20", "0.000"]]}}
{"local_ts": 1773485139952, "server_ts": 1773485139008, "data": {"e": "depthUpdate", "E": 1773485139009, "T": 1773485139008, "s": "BTCUSDT", "U": 10109434082893, "u": 10109434086939, "pu": 10109434082781, "b": [["5000.00", "101.398"], ["7048.70", "0.056"], ["19986.60", "0.430"], ["20286.60", "0.140"], ["20386.60", "2.430"], ["33000.00", "3.785"], ["63437.90", "0.000"], ["66935.40", "0.000"], ["66967.00", "0.150"], ["66967.10", "0.002"], ["69781.70", "0.717"], ["69781.80", "0.113"], ["70240.70", "0.263"], ["70310.40", "0.159"], ["70352.00", "0.002"], ["70352.10", "0.730"], ["70395.60", "0.110"], ["70395.70", "0.000"], ["70402.70", "0.520"], ["70402.80", "0.000"], ["70409.70", "0.095"], ["70409.80", "0.002"], ["70423.40", "2.939"], ["70424.80", "0.002"], ["70445.30", "0.195"], ["70456.20", "0.165"], ["70470.30", "0.005"], ["70471.80", "0.014"], ["70472.30", "0.001"], ["70473.20", "0.289"], ["70473.80", "0.003"], ["70473.90", "0.018"], ["70474.30", "0.004"], ["70474.60", "0.010"], ["70476.00", "0.222"], ["70485.40", "0.000"], ["70486.60", "3.967"]], "a": [["70486.70", "3.767"], ["70488.70", "0.010"], ["70491.80", "0.004"], ["70493.60", "0.100"], ["70493.80", "0.002"], ["70493.90", "0.000"], ["70496.70", "0.527"], ["70497.30", "0.032"], ["70497.60", "0.007"], ["70499.30", "0.006"], ["70502.90", "0.004"], ["70507.90", "0.007"], ["70509.90", "0.510"], ["70510.30", "0.011"], ["70511.10", "0.018"], ["70511.80", "0.047"], ["70512.30", "0.005"], ["70512.70", "0.003"], ["70572.00", "0.116"], ["70572.10", "0.003"], ["70579.00", "0.214"], ["70579.10", "0.232"], ["70586.10", "0.364"], ["70586.20", "0.000"], ["70619.10", "0.505"], ["70624.50", "0.189"], ["70624.80", "0.000"], ["70677.00", "0.378"], ["71191.60", "0.701"], ["71315.90", "0.000"], ["71487.60", "0.556"], ["71896.40", "0.453"], ["71901.50", "0.000"], ["74011.00", "0.270"], ["74225.50", "0.052"], ["77535.40", "0.000"]]}}
{"local_ts": 1773485141079, "server_ts": 1773485140236, "data": {"e": "depthUpdate", "E": 1773485140237, "T": 1773485140236, "s": "BTCUSDT", "U": 10109434130377, "u": 10109434134386, "pu": 10109434130294, "b": [["5000.00", "101.418"], ["7048.70", "0.056"], ["20186.60", "0.170"], ["20286.60", "2.440"], ["20386.60", "0.390"], ["66934.20", "0.000"], ["68642.80", "0.010"], ["69781.70", "0.717"], ["70444.10", "0.435"], ["70446.60", "0.025"], ["70449.60", "0.090"], ["70456.30", "0.004"], ["70474.50", "0.012"], ["70477.80", "0.104"]], "a": [["70486.70", "3.078"], ["70496.20", "0.087"], ["70496.70", "0.003"], ["70546.10", "0.307"], ["70546.80", "0.030"], ["70560.70", "0.000"], ["70566.90", "0.132"], ["70652.80", "0.000"], ["70658.00", "0.557"], ["70659.80", "0.000"], ["70665.00", "3.180"], ["70666.80", "0.725"], ["70672.00", "1.375"], ["70673.80", "0.010"], ["70679.00", "0.007"], ["70680.80", "0.000"], ["70686.00", "1.214"], ["70687.80", "0.505"], ["70693.00", "0.228"], ["70694.80", "0.000"], ["70700.00", "22.075"], ["70701.80", "0.029"], ["70707.00", "0.178"], ["71191.60", "2.104"], ["74039.80", "0.002"]]}}
{"local_ts": 1773485142153, "server_ts": 1773485141356, "data": {"e": "depthUpdate", "E": 1773485141361, "T": 1773485141356, "s": "BTCUSDT", "U": 10109434177656, "u": 10109434181251, "pu": 10109434177533, "b": [["5000.00", "101.418"], ["7048.70", "0.000"], ["20086.60", "0.100"], ["20186.60", "2.380"], ["20286.60", "0.520"], ["66927.90", "0.002"], ["69481.70", "0.728"], ["69781.70", "0.717"], ["70471.50", "0.106"], ["70474.30", "0.108"]], "a": [["70495.80", "0.023"], ["70637.90", "0.090"], ["70638.70", "0.288"], ["70646.40", "0.095"], ["70647.80", "1.898"], ["71191.60", "2.104"], ["71750.20", "1.104"], ["72261.40", "2.487"], ["74011.00", "0.265"], ["74036.30", "0.000"], ["89523.20", "0.000"]]}}
{"local_ts": 1773485143188, "server_ts": 1773485142386, "data": {"e": "depthUpdate", "E": 1773485142387, "T": 1773485142386, "s": "BTCUSDT", "U": 10109434222335, "u": 10109434228317, "pu": 10109434222070, "b": [["1000.00", "28.692"], ["5000.00", "101.418"], ["7048.70", "0.000"], ["20086.60", "2.150"], ["20186.60", "0.850"], ["66958.40", "0.002"], ["67667.20", "0.008"], ["69781.70", "0.719"], ["70134.20", "0.002"], ["70438.10", "0.091"], ["70438.40", "0.002"], ["70446.10", "0.329"], ["70456.20", "0.349"], ["70471.40", "0.001"], ["70472.30", "0.008"], ["70472.90", "0.002"], ["70479.70", "0.618"], ["70483.00", "0.015"], ["70483.40", "0.006"], ["70483.50", "0.003"]], "a": [["70486.70", "3.359"], ["70491.70", "0.005"], ["70493.80", "0.004"], ["70500.20", "0.000"], ["70710.20", "0.007"], ["71191.50", "0.010"], ["71191.60", "2.104"], ["89523.20", "0.000"]]}}
{"local_ts": 1773485144203, "server_ts": 1773485143408, "data": {"e": "depthUpdate", "E": 1773485143411, "T": 1773485143408, "s": "BTCUSDT", "U": 10109434280071, "u": 10109434285514, "pu": 10109434280020, "b": [["1000.00", "28.692"], ["5000.00", "101.418"], ["7048.70", "0.056"], ["19986.60", "1.710"], ["20086.60", "1.290"], ["66958.40", "0.000"], ["66962.30", "0.008"], ["69781.70", "0.717"], ["69990.50", "0.004"], ["70207.70", "0.591"], ["70240.50", "26.826"], ["70306.90", "0.502"], ["70310.40", "0.159"], ["70420.90", "0.061"], ["70425.60", "0.057"], ["70426.60", "0.338"], ["70426.70", "0.488"], ["70427.00", "0.092"], ["70427.30", "0.101"], ["70427.80", "0.054"], ["70428.10", "0.038"], ["70437.70", "0.070"], ["70437.80", "0.007"], ["70471.40", "0.185"], ["70476.00", "0.215"], ["70479.50", "0.399"], ["70479.70", "0.618"], ["70479.80", "0.159"], ["70480.20", "0.060"], ["70480.50", "0.100"], ["70480.90", "0.038"], ["70483.40", "0.006"]], "a": [["70486.70", "2.900"], ["70493.80", "0.007"], ["70497.30", "0.014"], ["70500.20", "0.025"], ["70500.50", "0.065"], ["70500.90", "0.061"], ["70501.20", "0.158"], ["70501.60", "0.220"], ["70511.40", "0.004"], ["70512.70", "0.010"], ["70526.60", "0.025"], ["70526.90", "0.378"], ["70527.30", "0.061"], ["70527.60", "0.067"], ["70528.00", "0.263"], ["70528.30", "0.039"], ["70530.90", "0.042"], ["70552.90", "0.025"], ["70553.30", "1.138"], ["70553.70", "0.121"], ["70554.10", "0.734"], ["70554.30", "0.075"], ["70554.40", "0.108"], ["70555.50", "0.321"], ["70560.20", "0.042"], ["70566.80", "0.278"], ["71191.60", "2.104"], ["72151.90", "0.595"], ["72261.40", "4.974"], ["89523.20", "0.000"]]}}
{"local_ts": 1773485145225, "server_ts": 1773485144432, "data": {"e": "depthUpdate", "E": 1773485144433, "T": 1773485144432, "s": "BTCUSDT", "U": 10109434320256, "u": 10109434324190, "pu": 10109434320180, "b": [["5000.00", "101.418"], ["7048.70", "0.056"], ["19986.60", "1.730"], ["20386.60", "1.270"], ["66951.00", "0.004"], ["69781.70", "0.717"], ["69931.90", "0.010"], ["70430.40", "0.633"], ["70438.10", "0.032"], ["70438.30", "0.345"], ["70440.90", "0.010"], ["70474.30", "0.060"], ["70479.70", "0.618"]], "a": [["70486.70", "2.892"], ["70490.00", "0.016"], ["70492.80", "0.024"], ["70493.50", "0.007"], ["70493.60", "0.125"], ["70493.80", "0.061"], ["70495.50", "0.006"], ["70495.60", "0.085"], ["70495.70", "0.003"], ["70496.30", "0.003"], ["70496.40", "0.005"], ["70499.70", "0.068"], ["70710.50", "1.529"], ["70710.60", "0.017"], ["71043.30", "0.000"], ["71043.40", "0.000"], ["71059.80", "1.855"], ["71191.50", "0.010"], ["71191.60", "2.104"], ["71206.70", "3.240"], ["71596.40", "1.611"], ["74035.60", "0.008"]]}}
{"local_ts": 1773485146247, "server_ts": 1773485145454, "data": {"e": "depthUpdate", "E": 1773485145455, "T": 1773485145454, "s": "BTCUSDT", "U": 10109434355893, "u": 10109434359204, "pu": 10109434355855, "b": [["1000.00", "28.692"], ["5000.00", "101.418"], ["7048.70", "0.056"], ["20286.60", "0.820"], ["20386.60", "2.180"], ["33000.00", "3.785"], ["66956.30", "0.023"], ["66960.90", "0.002"], ["69440.30", "0.000"], ["69552.20", "0.861"], ["69561.70", "66.061"], ["69771.00", "56.938"], ["69781.70", "0.717"], ["70134.20", "0.002"], ["70134.30", "0.000"], ["70240.70", "0.263"], ["70306.90", "0.661"], ["70310.40", "0.099"], ["70445.60", "0.000"], ["70446.10", "0.516"], ["70452.70", "0.020"], ["70456.60", "0.293"], ["70483.50", "0.003"]], "a": [["70486.70", "4.097"], ["70491.20", "0.135"], ["70493.50", "0.007"], ["70493.60", "0.241"], ["70496.60", "0.187"], ["70496.70", "0.667"], ["70497.90", "0.451"], ["70499.80", "0.025"], ["70504.70", "0.184"], ["70506.80", "0.002"], ["70508.00", "1.219"], ["70721.40", "0.007"], ["70750.00", "2.304"], ["71039.80", "48.454"], ["71191.60", "2.104"], ["71203.20", "57.825"], ["71416.80", "69.191"], ["72151.90", "0.002"]]}}
{"local_ts": 1773485147269, "server_ts": 1773485146476, "data": {"e": "depthUpdate", "E": 1773485146477, "T": 1773485146476, "s": "BTCUSDT", "U": 10109434398093, "u": 10109434401629, "pu": 10109434397973, "b": [["5000.00", "101.418"], ["7048.70", "0.028"], ["20186.60", "0.410"], ["20286.60", "2.560"], ["20386.60", "0.030"], ["66959.60", "0.002"], ["69363.80", "0.000"], ["69492.70", "1.005"], ["70432.30", "0.009"], ["70436.20", "0.346"], ["70438.40", "0.002"], ["70438.50", "0.017"], ["70471.40", "0.086"], ["70477.90", "0.514"], ["70480.30", "0.518"]], "a": [["70493.10", "0.654"], ["70493.20", "0.002"], ["70493.30", "0.002"], ["70496.90", "0.007"], ["70504.00", "0.013"], ["70521.40", "0.003"], ["70710.10", "0.000"], ["70828.50", "0.044"], ["71191.60", "2.176"], ["71320.20", "0.560"], ["72194.70", "1.779"], ["74041.70", "0.002"]]}}
{"local_ts": 1773485148295, "server_ts": 1773485147496, "data": {"e": "depthUpdate", "E": 1773485147497, "T": 1773485147496, "s": "BTCUSDT", "U": 10109434446720, "u": 10109434451914, "pu": 10109434446593, "b": [["1000.00", "28.692"], ["5000.00", "101.418"], ["7048.70", "0.028"], ["20086.60", "0.220"], ["20186.60", "2.490"], ["20286.60", "0.290"], ["33000.00", "3.785"], ["66962.40", "0.008"], ["69781.70", "0.717"], ["70134.20", "0.002"], ["70467.00", "0.576"], ["70467.10", "0.062"]], "a": [["70508.30", "0.075"], ["70509.30", "0.638"], ["70677.00", "0.378"], ["71191.60", "2.174"], ["71577.60", "0.003"], ["72601.30", "0.000"], ["74023.00", "0.158"]]}}
{"local_ts": 1773485149320, "server_ts": 1773485148520, "data": {"e": "depthUpdate", "E": 1773485148521, "T": 1773485148520, "s": "BTCUSDT", "U": 10109434495157, "u": 10109434498796, "pu": 10109434495055, "b": [["1000.00", "28.692"], ["5000.00", "101.418"], ["7048.70", "0.028"], ["19986.60", "0.070"], ["20086.60", "2.350"], ["20186.60", "0.580"], ["56389.00", "0.004"], ["66937.20", "0.000"], ["70419.80", "0.063"], ["70424.30", "0.054"], ["70425.30", "0.333"], ["70425.60", "0.108"], ["70426.00", "0.058"], ["70426.30", "0.112"], ["70426.70", "0.324"], ["70467.20", "0.488"], ["70467.30", "0.071"], ["70470.60", "1.077"], ["70471.20", "0.215"], ["70472.50", "0.367"], ["70474.30", "0.181"], ["70477.00", "0.418"], ["70477.40", "0.224"], ["70477.70", "0.104"], ["70478.10", "0.098"], ["70478.40", "0.041"], ["70486.40", "0.000"], ["70486.50", "0.064"]], "a": [["70486.70", "4.275"], ["70491.30", "0.140"], ["70496.00", "0.026"], ["70496.40", "0.066"], ["70496.70", "0.049"], ["70497.10", "0.215"], ["70497.40", "0.221"], ["70521.90", "0.037"], ["70522.20", "0.123"], ["70522.60", "0.065"], ["70522.90", "0.061"], ["70523.30", "0.180"], ["70523.60", "0.040"], ["70526.00", "0.320"], ["70554.70", "0.036"], ["70710.00", "0.005"], ["71050.60", "3.322"], ["71191.50", "0.017"], ["71191.60", "2.174"], ["71431.70", "0.280"], ["74036.80", "0.002"]]}}
{"local_ts": 1773485150335, "server_ts": 1773485149540, "data": {"e": "depthUpdate", "E": 1773485149543, "T": 1773485149540, "s": "BTCUSDT", "U": 10109434528308, "u": 10109434535236, "pu": 10109434528293, "b": [["5000.00", "101.418"], ["7048.70", "0.000"], ["19986.60", "2.040"], ["20086.60", "0.960"], ["33000.00", "3.789"], ["56389.00", "0.000"], ["66940.80", "0.217"], ["69781.70", "0.717"], ["69781.80", "0.113"], ["70134.30", "0.004"], ["70240.80", "0.000"], ["70306.90", "0.661"], ["70378.50", "0.014"], ["70378.60", "0.004"], ["70438.50", "0.000"], ["70472.70", "0.012"], ["70474.20", "0.016"], ["70479.70", "0.609"], ["70486.60", "2.089"]], "a": [["70486.70", "4.236"], ["70489.80", "0.000"], ["70492.20", "0.002"], ["70493.00", "0.004"], ["70495.00", "0.081"], ["70495.10", "0.086"], ["70495.20", "0.002"], ["70499.90", "0.024"], ["70794.80", "0.000"], ["70795.10", "0.007"], ["70806.60", "0.000"], ["71050.60", "4.164"], ["71191.60", "2.174"], ["71431.70", "0.000"], ["74038.90", "0.000"]]}}
{"local_ts": 1773485151357, "server_ts": 1773485150562, "data": {"e": "depthUpdate", "E": 1773485150563, "T": 1773485150562, "s": "BTCUSDT", "U": 10109434572588, "u": 10109434577258, "pu": 10109434572509, "b": [["1000.00", "28.692"], ["5000.00", "101.418"], ["7048.70", "0.000"], ["19986.60", "1.410"], ["20386.60", "1.590"], ["56389.00", "0.000"], ["66936.30", "0.000"], ["66962.30", "0.006"], ["69076.90", "0.041"], ["69506.80", "3.595"], ["69781.70", "0.717"], ["70057.00", "38.947"], ["70059.50", "8.664"], ["70134.20", "0.002"], ["70162.30", "32.163"], ["70164.40", "4.989"], ["70239.60", "27.044"], ["70240.60", "5.000"], ["70306.90", "0.661"], ["70418.40", "0.090"], ["70437.80", "0.005"], ["70438.00", "0.946"], ["70454.90", "0.302"], ["70468.30", "0.070"], ["70469.40", "0.001"], ["70469.50", "0.007"], ["70470.40", "0.006"], ["70474.60", "0.092"], ["70476.00", "0.015"], ["70482.40", "0.087"], ["70482.60", "0.008"], ["70485.00", "0.072"], ["70486.60", "4.107"]], "a": [["70486.70", "2.445"], ["70490.50", "0.003"], ["70492.20", "0.000"], ["70492.40", "0.000"], ["70495.00", "0.145"], ["70495.20", "0.002"], ["70497.10", "0.251"], ["70497.90", "0.003"], ["70499.30", "0.016"], ["70502.60", "0.059"], ["70505.50", "0.007"], ["70506.10", "0.168"], ["70507.80", "0.482"], ["70514.30", "0.024"], ["70521.90", "0.030"], ["70524.00", "0.014"], ["70525.20", "0.333"], ["70536.20", "0.097"], ["70541.50", "0.002"], ["70544.10", "0.000"], ["70547.20", "0.000"], ["70580.40", "0.244"], ["70584.00", "0.079"], ["70588.30", "1.441"], ["70591.60", "0.077"], ["70593.00", "1.596"], ["70595.90", "0.077"], ["70600.10", "2.591"], ["70604.50", "0.000"], ["70607.30", "0.073"], ["70612.30", "10.126"], ["70658.80", "10.003"], ["70665.00", "0.010"], ["70665.50", "0.000"], ["70680.70", "0.000"], ["70689.90", "10.715"], ["70710.50", "1.529"], ["70712.10", "2.096"], ["70720.90", "10.003"], ["70731.00", "27.474"], ["70743.10", "0.000"], ["70743.20", "0.000"], ["70767.50", "10.000"], ["70773.90", "0.672"], ["70774.30", "0.000"], ["70808.80", "31.837"], ["70820.90", "0.129"], ["70915.00", "39.824"], ["71191.60", "2.174"], ["74014.80", "0.002"]]}}
{"local_ts": 1773485152380, "server_ts": 1773485151583, "data": {"e": "depthUpdate", "E": 1773485151585, "T": 1773485151583, "s": "BTCUSDT", "U": 10109434608296, "u": 10109434611806, "pu": 10109434608217, "b": [["5000.00", "101.418"], ["7048.70", "0.000"], ["20286.60", "1.140"], ["20386.60", "1.860"], ["56389.00", "0.000"], ["69253.10", "1.153"], ["69416.00", "1.734"], ["69640.80", "1.434"], ["69781.70", "2.155"], ["70355.10", "0.618"], ["70479.60", "0.258"], ["70485.00", "0.049"]], "a": [["70490.90", "0.008"], ["70626.90", "2.340"], ["71191.60", "2.174"], ["71375.70", "0.000"], ["74018.30", "0.002"]]}}
{"local_ts": 1773485153397, "server_ts": 1773485152604, "data": {"e": "depthUpdate", "E": 1773485152605, "T": 1773485152604, "s": "BTCUSDT", "U": 10109434651031, "u": 10109434653943, "pu": 10109434650893, "b": [["1000.00", "28.692"], ["5000.00", "101.418"], ["7048.70", "0.056"], ["20186.60", "0.700"], ["20286.60", "2.300"], ["20386.60", "0.000"], ["56389.00", "0.000"], ["66956.10", "0.000"], ["69415.40", "1.996"], ["69485.90", "7.700"], ["69781.70", "2.155"], ["70134.20", "0.002"], ["70331.50", "0.002"], ["70355.10", "0.643"], ["70409.10", "0.017"], ["70423.20", "0.290"], ["70446.10", "0.304"], ["70447.80", "0.002"], ["70470.70", "1.247"], ["70471.40", "0.185"], ["70476.00", "0.351"], ["70477.80", "0.167"], ["70486.60", "3.286"]], "a": [["70486.70", "2.888"], ["70507.80", "0.401"], ["70550.20", "0.067"], ["70564.30", "0.003"], ["70626.30", "0.496"], ["70626.60", "0.204"], ["71191.60", "2.174"]]}}
{"local_ts": 1773485154419, "server_ts": 1773485153626, "data": {"e": "depthUpdate", "E": 1773485153627, "T": 1773485153626, "s": "BTCUSDT", "U": 10109434688014, "u": 10109434691057, "pu": 10109434687918, "b": [["1000.00", "28.692"], ["5000.00", "101.418"], ["7048.70", "0.056"], ["20086.60", "0.320"], ["20186.60", "2.610"], ["20286.60", "0.070"], ["56389.00", "0.000"], ["66948.30", "0.000"], ["66962.30", "0.010"], ["66962.40", "0.004"], ["69464.50", "14.519"], ["69781.70", "2.157"], ["70303.30", "0.159"], ["70307.40", "0.002"], ["70310.30", "0.000"], ["70316.40", "6.530"], ["70355.10", "0.000"], ["70395.30", "0.063"], ["70403.20", "0.871"], ["70404.20", "0.068"], ["70404.60", "0.038"], ["70446.10", "0.443"], ["70447.20", "0.000"], ["70456.60", "0.394"], ["70472.50", "0.171"], ["70474.30", "0.032"], ["70476.00", "0.015"], ["70476.10", "0.011"], ["70477.80", "0.000"], ["70485.40", "0.000"]], "a": [["70486.70", "4.006"], ["70555.60", "0.060"], ["70626.10", "0.100"], ["70628.80", "0.000"], ["70664.90", "0.000"], ["70677.00", "0.378"], ["71191.60", "2.174"], ["74026.20", "0.002"]]}}
{"local_ts": 1773485155440, "server_ts": 1773485154644, "data": {"e": "depthUpdate", "E": 1773485154647, "T": 1773485154644, "s": "BTCUSDT", "U": 10109434725099, "u": 10109434727487, "pu": 10109434725009, "b": [["5000.00", "101.418"], ["7048.70", "0.056"], ["19986.60", "0.170"], ["20086.60", "2.460"], ["20186.60", "0.370"], ["33000.00", "3.785"], ["56389.00", "0.000"], ["66956.40", "0.002"], ["66962.00", "0.020"], ["69535.00", "1.147"], ["69781.70", "4.302"], ["70057.00", "0.008"], ["70162.30", "0.000"], ["70239.60", "0.000"], ["70307.40", "0.000"], ["70310.30", "0.002"], ["70437.30", "0.201"], ["70438.30", "0.055"], ["70438.40", "0.002"], ["70447.80", "0.335"], ["70472.50", "0.352"], ["70472.70", "0.012"], ["70473.00", "0.000"], ["70473.30", "0.340"], ["70476.00", "0.015"]], "a": [["70486.70", "3.277"], ["70491.20", "0.045"], ["70493.50", "0.009"], ["70493.60", "0.299"], ["70494.10", "0.003"], ["70494.30", "0.087"], ["70494.90", "0.662"], ["70599.90", "0.021"], ["70604.60", "0.006"], ["70710.20", "0.007"], ["70731.00", "0.205"], ["70808.80", "0.003"], ["70915.00", "0.000"], ["71191.60", "2.875"], ["71496.30", "0.834"], ["706600.00", "0.070"]]}}
{"local_ts": 1773485156462, "server_ts": 1773485155668, "data": {"e": "depthUpdate", "E": 1773485155669, "T": 1773485155668, "s": "BTCUSDT", "U": 10109434759483, "u": 10109434763089, "pu": 10109434759456, "b": [["1000.00", "28.692"], ["5000.00", "101.418"], ["7048.70", "0.028"], ["19986.60", "2.300"], ["20086.60", "0.670"], ["20386.60", "0.030"], ["66957.60", "0.000"], ["66962.30", "0.012"], ["69281.80", "0.002"], ["69352.20", "0.000"], ["69781.70", "4.302"], ["69900.00", "67.096"], ["70134.20", "0.002"], ["70310.30", "0.000"], ["70311.40", "1.052"], ["70331.50", "0.002"], ["70401.50", "0.105"], ["70403.50", "0.000"], ["70438.10", "0.032"], ["70448.40", "0.264"], ["70451.40", "0.692"], ["70456.60", "0.187"], ["70476.00", "0.638"], ["70481.30", "0.063"], ["70483.30", "0.150"], ["70486.60", "2.584"]], "a": [["70486.70", "2.852"], ["70489.30", "0.002"], ["70491.80", "0.061"], ["70707.30", "0.172"], ["71191.60", "2.875"], ["71332.50", "4.897"], ["89523.20", "0.000"]]}}
{"local_ts": 1773485157534, "server_ts": 1773485156588, "data": {"e": "depthUpdate", "E": 1773485156589, "T": 1773485156588, "s": "BTCUSDT", "U": 10109434790238, "u": 10109434793218, "pu": 10109434790021, "b": [["1000.00", "28.692"], ["5000.00", "101.418"], ["7048.70", "0.000"], ["19986.60", "1.340"], ["20386.60", "1.660"], ["56389.00", "0.000"], ["66927.10", "0.000"], ["69156.00", "0.031"], ["69781.70", "4.302"], ["70331.50", "0.041"], ["70437.30", "0.201"], ["70438.70", "0.109"], ["70438.90", "0.002"], ["70468.70", "0.000"], ["70486.60", "2.282"]], "a": [["70486.70", "3.162"], ["70488.30", "0.057"], ["70507.70", "0.087"], ["70543.60", "0.186"], ["70607.70", "0.000"], ["70677.00", "0.378"], ["71191.60", "2.875"], ["74040.70", "0.168"]]}}
{"local_ts": 1773485158549, "server_ts": 1773485157610, "data": {"e": "depthUpdate", "E": 1773485157611, "T": 1773485157610, "s": "BTCUSDT", "U": 10109434824536, "u": 10109434827396, "pu": 10109434824509, "b": [["5000.00", "101.398"], ["7048.70", "0.056"], ["20286.60", "1.210"], ["20386.60", "1.790"], ["56389.00", "0.000"], ["66943.40", "0.002"], ["69191.10", "0.000"], ["69281.80", "0.002"], ["69352.20", "0.000"], ["69459.00", "0.002"], ["69781.70", "4.304"], ["70355.10", "0.000"], ["70437.30", "0.004"], ["70438.30", "0.053"], ["70438.40", "0.008"], ["70472.50", "0.350"], ["70473.00", "0.006"], ["70480.40", "0.087"], ["70483.40", "0.009"]], "a": [["70486.70", "3.623"], ["70488.80", "0.000"], ["70500.00", "0.762"], ["70507.70", "0.186"], ["70663.00", "0.037"], ["70701.50", "0.000"], ["70710.00", "0.012"], ["70828.40", "0.006"], ["71191.40", "0.000"], ["71191.60", "2.875"], ["72601.30", "0.000"], ["74045.50", "0.000"]]}}
{"local_ts": 1773485159554, "server_ts": 1773485158733, "data": {"e": "depthUpdate", "E": 1773485158735, "T": 1773485158733, "s": "BTCUSDT", "U": 10109434861211, "u": 10109434863358, "pu": 10109434861172, "b": [["1000.00", "28.692"], ["5000.00", "101.418"], ["7048.70", "0.000"], ["20186.60", "1.020"], ["20286.60", "1.980"], ["66935.10", "0.124"], ["66962.30", "0.008"], ["66962.40", "0.008"], ["69281.80", "0.002"], ["69781.70", "4.302"], ["70331.50", "0.041"], ["70396.50", "0.063"], ["70404.10", "0.072"], ["70404.30", "0.198"], ["70405.40", "0.195"], ["70405.70", "0.059"], ["70428.50", "0.012"], ["70469.10", "0.007"], ["70469.20", "0.189"]], "a": [["70486.70", "2.866"], ["70503.80", "0.107"], ["70511.30", "0.345"], ["70677.00", "0.378"], ["70839.10", "0.546"], ["71191.60", "2.875"], ["71332.50", "7.135"], ["71678.40", "0.000"], ["74045.70", "0.002"], ["89523.20", "0.000"]]}}
{"local_ts": 1773485160601, "server_ts": 1773485159656, "data": {"e": "depthUpdate", "E": 1773485159657, "T": 1773485159656, "s": "BTCUSDT", "U": 10109434885082, "u": 10109434889086, "pu": 10109434885027, "b": [["5000.00", "101.398"], ["7048.70", "0.056"], ["20086.60", "0.380"], ["20186.60", "2.570"], ["20286.60", "0.050"], ["33000.00", "3.785"], ["56389.00", "0.000"], ["66943.80", "0.002"], ["69076.90", "0.044"], ["69781.70", "4.302"], ["70311.50", "0.003"], ["70311.80", "0.005"]], "a": [["70486.70", "2.881"], ["70495.80", "0.005"], ["70510.70", "0.005"], ["70543.60", "0.271"], ["71191.60", "2.875"], ["71626.70", "0.003"], ["74026.90", "0.000"]]}}
{"local_ts": 1773485161619, "server_ts": 1773485160677, "data": {"e": "depthUpdate", "E": 1773485160679, "T": 1773485160677, "s": "BTCUSDT", "U": 10109434940048, "u": 10109434947245, "pu": 10109434939643, "b": [["1000.00", "28.692"], ["5000.00", "101.418"], ["7048.70", "0.028"], ["19986.60", "0.200"], ["20086.60", "2.480"], ["20186.60", "0.320"], ["56389.00", "0.000"], ["66962.00", "0.000"], ["69494.20", "0.000"], ["69781.70", "5.733"], ["70311.70", "0.007"], ["70311.80", "0.003"], ["70339.20", "12.543"], ["70378.30", "0.000"], ["70380.30", "0.122"], ["70397.30", "6.398"], ["70425.00", "0.852"], ["70432.10", "3.310"], ["70453.30", "1.786"], ["70464.70", "0.077"], ["70465.80", "0.056"], ["70472.60", "0.145"], ["70472.80", "0.020"], ["70473.10", "0.855"], ["70473.20", "0.280"], ["70474.30", "0.155"], ["70475.10", "0.018"], ["70475.20", "0.000"], ["70475.30", "0.412"], ["70475.40", "0.751"], ["70475.50", "0.514"], ["70476.00", "0.212"], ["70477.80", "0.015"], ["70477.90", "0.622"], ["70478.00", "0.007"], ["70478.10", "0.140"], ["70478.20", "0.002"], ["70478.30", "0.000"], ["70478.40", "0.003"], ["70478.50", "0.008"], ["70478.60", "0.000"], ["70478.80", "0.001"], ["70478.90", "0.003"], ["70485.20", "0.057"], ["70486.10", "0.000"], ["70486.50", "0.083"]], "a": [["70486.70", "3.221"], ["70486.80", "0.045"], ["70487.60", "0.000"], ["70490.10", "0.003"], ["70490.80", "0.002"], ["70494.10", "0.006"], ["70496.10", "0.085"], ["70496.30", "0.003"], ["70497.30", "0.031"], ["70507.80", "0.503"], ["70509.50", "0.001"], ["70509.90", "0.649"], ["70510.30", "0.514"], ["70511.40", "0.004"], ["70511.50", "0.398"], ["70511.90", "1.075"], ["70512.20", "0.072"], ["70516.50", "0.003"], ["70517.30", "0.052"], ["70520.20", "0.104"], ["70523.20", "1.849"], ["70525.70", "0.056"], ["70544.40", "3.356"], ["70579.30", "6.594"], ["70637.70", "12.416"], ["71191.60", "2.875"], ["74018.30", "0.000"], ["74030.00", "0.080"]]}}
{"local_ts": 1773485162700, "server_ts": 1773485161900, "data": {"e": "depthUpdate", "E": 1773485161905, "T": 1773485161900, "s": "BTCUSDT", "U": 10109435006866, "u": 10109435011108, "pu": 10109435006746, "b": [["1000.00", "28.692"], ["5000.00", "101.418"], ["7048.70", "0.028"], ["19986.60", "2.500"], ["20086.60", "0.280"], ["20386.60", "0.220"], ["56389.00", "0.000"], ["63437.90", "0.002"], ["66941.50", "0.002"], ["66946.30", "0.000"], ["66962.00", "0.000"], ["66962.40", "0.010"], ["69076.90", "0.047"], ["69781.70", "5.733"], ["70134.10", "0.000"], ["70134.20", "0.110"], ["70458.90", "0.008"], ["70459.00", "0.305"], ["70459.70", "0.004"], ["70476.00", "0.354"]], "a": [["70486.70", "3.105"], ["70494.20", "0.075"], ["70497.30", "0.028"], ["70507.30", "0.000"], ["70514.40", "0.004"], ["70524.20", "0.183"], ["70541.10", "0.004"], ["71191.60", "5.681"], ["71481.60", "0.000"], ["71769.60", "0.557"], ["77535.40", "0.002"]]}}
{"local_ts": 1773485163742, "server_ts": 1773485162928, "data": {"e": "depthUpdate", "E": 1773485162929, "T": 1773485162928, "s": "BTCUSDT", "U": 10109435055405, "u": 10109435064768, "pu": 10109435055350, "b": [["1000.00", "28.692"], ["5000.00", "101.418"], ["7048.70", "0.028"], ["19986.60", "0.570"], ["20286.60", "0.070"], ["20294.90", "0.010"], ["20386.60", "2.330"], ["20386.80", "0.010"], ["20394.90", "0.010"], ["40000.00", "41.352"], ["56389.00", "0.004"], ["63437.90", "0.002"], ["66959.00", "0.000"], ["66962.30", "0.006"], ["69076.90", "0.041"], ["69168.50", "1.587"], ["69781.70", "5.733"], ["69790.00", "0.119"], ["70000.00", "126.799"], ["70113.50", "0.000"], ["70117.60", "0.584"], ["70276.00", "0.085"], ["70287.20", "0.005"], ["70306.90", "0.502"], ["70311.60", "0.686"], ["70332.50", "0.092"], ["70332.60", "10.971"], ["70336.20", "0.000"], ["70343.80", "0.082"], ["70357.30", "0.000"], ["70363.10", "0.000"], ["70365.20", "0.000"], ["70367.30", "0.007"], ["70367.40", "3.424"], ["70367.60", "0.002"], ["70369.20", "0.000"], ["70369.40", "0.010"], ["70371.80", "0.008"], ["70375.90", "0.006"], ["70385.70", "0.108"], ["70390.40", "0.589"], ["70394.00", "0.000"], ["70394.20", "0.029"], ["70397.30", "6.402"], ["70397.60", "0.000"], ["70402.50", "0.210"], ["70409.10", "0.014"], ["70411.20", "0.092"], ["70412.00", "0.297"], ["70413.70", "0.344"], ["70416.60", "0.218"], ["70417.40", "0.003"], ["70418.30", "0.002"], ["70419.60", "0.000"], ["70420.00", "0.888"], ["70420.10", "0.047"], ["70420.40", "0.049"], ["70423.20", "0.287"], ["70424.50", "0.003"], ["70425.10", "0.105"], ["70431.80", "0.000"], ["70432.00", "0.023"], ["70433.70", "0.028"], ["70434.20", "0.016"], ["70434.30", "0.002"], ["70434.90", "0.000"], ["70435.00", "0.081"], ["70435.30", "0.097"], ["70436.30", "1.857"], ["70437.10", "0.000"], ["70438.00", "0.944"], ["70438.10", "0.036"], ["70438.30", "0.053"], ["70438.60", "0.158"], ["70439.80", "0.007"], ["70440.80", "8.829"], ["70442.60", "0.007"], ["70442.90", "0.000"], ["70443.70", "0.037"], ["70444.30", "7.824"], ["70444.40", "1.916"], ["70444.70", "0.211"], ["70445.40", "0.000"], ["70446.10", "0.443"], ["70447.80", "0.199"], ["70448.40", "0.360"], ["70448.50", "0.000"], ["70449.40", "0.019"], ["70449.60", "0.125"], ["70450.50", "0.000"], ["70450.70", "0.002"], ["70451.30", "0.014"], ["70451.60", "0.308"], ["70452.60", "0.088"], ["70453.50", "0.001"], ["70453.60", "1.228"], ["70453.70", "0.103"], ["70454.00", "0.730"], ["70454.20", "0.025"], ["70454.30", "0.011"], ["70454.60", "0.000"], ["70454.80", "0.960"], ["70454.90", "0.003"], ["70455.00", "0.049"], ["70455.50", "1.154"], ["70455.60", "0.140"], ["70456.10", "0.264"], ["70456.40", "0.011"], ["70456.60", "0.321"], ["70457.70", "0.022"], ["70457.80", "0.032"], ["70458.40", "0.002"], ["70458.50", "0.117"], ["70458.70", "0.000"], ["70458.90", "0.064"], ["70459.70", "0.033"], ["70459.80", "0.002"], ["70459.90", "0.211"], ["70461.40", "0.002"], ["70462.00", "0.046"], ["70462.60", "0.000"], ["70463.50", "0.061"], ["70463.90", "0.005"], ["70464.10", "0.139"], ["70464.20", "0.054"], ["70464.60", "0.005"], ["70465.20", "0.004"], ["70465.30", "0.000"], ["70465.40", "0.000"], ["70465.50", "0.005"], ["70465.60", "1.074"], ["70465.70", "0.049"], ["70465.80", "0.056"], ["70466.40", "0.014"], ["70466.50", "0.000"], ["70466.60", "0.003"], ["70466.70", "0.000"], ["70466.80", "0.003"], ["70466.90", "0.347"], ["70467.20", "0.264"], ["70467.30", "0.002"], ["70467.60", "0.271"], ["70467.70", "0.004"], ["70468.10", "0.008"], ["70468.50", "0.005"], ["70468.90", "0.011"], ["70469.00", "0.555"], ["70469.10", "0.000"], ["70469.20", "0.129"], ["70469.30", "0.000"], ["70469.40", "0.001"], ["70469.90", "0.087"], ["70470.00", "4.967"], ["70470.20", "0.002"], ["70470.60", "1.077"], ["70471.20", "0.213"], ["70471.40", "0.285"], ["70471.60", "0.000"], ["70471.70", "0.015"], ["70472.30", "0.015"], ["70472.60", "0.004"], ["70472.70", "0.020"], ["70472.90", "0.000"], ["70473.00", "0.074"], ["70473.10", "0.853"], ["70473.40", "0.003"], ["70473.60", "0.002"], ["70473.70", "0.005"], ["70473.80", "0.235"], ["70473.90", "0.002"], ["70474.10", "0.000"], ["70474.20", "0.018"], ["70474.30", "0.655"], ["70474.70", "0.033"], ["70475.00", "0.011"], ["70475.20", "0.004"], ["70475.30", "0.403"], ["70475.40", "0.744"], ["70475.50", "0.534"], ["70475.60", "0.378"], ["70475.80", "0.062"], ["70476.00", "0.015"], ["70476.10", "0.004"], ["70476.20", "0.000"], ["70476.40", "0.000"], ["70476.50", "0.004"], ["70476.60", "0.000"], ["70476.70", "0.003"], ["70476.80", "0.270"], ["70476.90", "0.004"], ["70477.00", "0.026"], ["70477.10", "0.002"], ["70477.20", "0.204"], ["70477.40", "0.004"], ["70477.70", "0.011"], ["70477.80", "0.000"], ["70477.90", "0.617"], ["70478.00", "1.212"], ["70478.10", "0.001"], ["70478.30", "0.007"], ["70478.50", "0.011"], ["70478.60", "0.000"], ["70479.10", "0.033"], ["70479.40", "0.002"], ["70479.60", "0.961"], ["70479.70", "0.689"], ["70479.80", "0.000"], ["70479.90", "0.000"], ["70480.00", "0.226"], ["70480.40", "0.611"], ["70480.50", "0.280"], ["70480.60", "0.000"], ["70480.70", "0.098"], ["70480.80", "0.011"], ["70481.10", "0.062"], ["70481.20", "0.142"], ["70481.30", "0.010"], ["70481.40", "0.107"], ["70481.60", "0.005"], ["70481.70", "0.010"], ["70481.80", "0.212"], ["70481.90", "0.520"], ["70482.30", "0.405"], ["70482.40", "0.512"], ["70482.50", "0.010"], ["70482.90", "0.000"], ["70483.00", "0.008"], ["70483.30", "0.003"], ["70483.40", "0.290"], ["70483.60", "0.053"], ["70483.90", "0.028"], ["70484.30", "0.012"], ["70484.40", "0.004"], ["70484.60", "0.005"], ["70484.70", "0.002"], ["70484.80", "0.283"], ["70485.00", "0.014"], ["70485.10", "0.017"], ["70485.20", "0.003"], ["70485.30", "0.015"], ["70485.50", "0.002"], ["70485.60", "0.005"], ["70485.80", "0.025"], ["70486.10", "0.062"], ["70486.40", "0.030"], ["70486.50", "0.067"], ["70486.60", "0.175"], ["70486.70", "0.002"], ["70486.80", "0.126"], ["70486.90", "0.698"], ["70487.00", "0.007"], ["70487.10", "0.002"], ["70487.20", "1.278"], ["70487.30", "0.000"], ["70487.60", "0.523"], ["70487.70", "0.658"], ["70487.80", "0.002"], ["70487.90", "0.000"], ["70488.00", "0.003"], ["70488.10", "0.000"], ["70488.20", "0.342"], ["70488.30", "0.000"], ["70488.40", "0.002"], ["70488.50", "0.021"], ["70488.60", "0.000"], ["70488.80", "0.000"], ["70489.00", "0.015"], ["70489.10", "0.002"], ["70489.20", "0.002"], ["70489.40", "0.000"], ["70489.50", "0.000"], ["70489.80", "0.004"], ["70489.90", "0.000"], ["70490.00", "0.069"], ["70490.10", "0.003"], ["70490.20", "0.002"], ["70490.30", "0.000"], ["70490.40", "0.015"], ["70490.50", "0.000"], ["70490.70", "0.057"], ["70490.80", "0.000"], ["70491.00", "0.021"], ["70491.10", "0.000"], ["70491.20", "0.000"], ["70491.30", "0.002"], ["70491.40", "0.000"], ["70491.50", "0.003"], ["70491.60", "0.002"], ["70491.70", "0.003"], ["70491.80", "0.015"], ["70491.90", "0.000"], ["70492.00", "0.000"], ["70492.10", "0.000"], ["70492.30", "0.000"], ["70492.40", "0.000"], ["70492.70", "0.002"], ["70492.80", "0.000"], ["70492.90", "0.713"], ["70493.20", "0.021"], ["70493.30", "0.015"], ["70493.40", "0.002"], ["70493.50", "0.002"], ["70493.70", "0.000"], ["70493.80", "0.002"], ["70493.90", "0.000"], ["70494.00", "0.000"], ["70494.10", "0.000"], ["70494.20", "0.000"], ["70494.30", "0.000"], ["70494.50", "0.000"], ["70494.70", "0.000"], ["70494.80", "0.057"], ["70494.90", "4.128"]], "a": [["70486.70", "0.000"], ["70486.80", "0.000"], ["70486.90", "0.000"], ["70487.10", "0.000"], ["70487.20", "0.000"], ["70487.30", "0.000"], ["70487.80", "0.000"], ["70487.90", "0.000"], ["70488.00", "0.000"], ["70488.10", "0.000"], ["70488.20", "0.000"], ["70488.40", "0.000"], ["70488.50", "0.000"], ["70488.60", "0.000"], ["70488.70", "0.000"], ["70488.90", "0.000"], ["70489.10", "0.000"], ["70489.30", "0.000"], ["70489.60", "0.000"], ["70489.90", "0.000"], ["70490.00", "0.000"], ["70490.10", "0.000"], ["70490.20", "0.000"], ["70490.30", "0.000"], ["70490.50", "0.000"], ["70490.70", "0.000"], ["70490.80", "0.000"], ["70490.90", "0.000"], ["70491.10", "0.000"], ["70491.20", "0.000"], ["70491.30", "0.000"], ["70491.40", "0.000"], ["70491.50", "0.000"], ["70491.60", "0.000"], ["70491.70", "0.000"], ["70491.80", "0.000"], ["70491.90", "0.000"], ["70492.10", "0.000"], ["70492.20", "0.000"], ["70492.40", "0.000"], ["70492.50", "0.000"], ["70492.80", "0.000"], ["70492.90", "0.000"], ["70493.00", "0.000"], ["70493.20", "0.000"], ["70493.40", "0.000"], ["70493.50", "0.000"], ["70493.60", "0.000"], ["70493.70", "0.000"], ["70493.80", "0.000"], ["70493.90", "0.000"], ["70494.00", "0.000"], ["70494.10", "0.000"], ["70494.20", "0.000"], ["70494.30", "0.000"], ["70494.40", "0.000"], ["70494.60", "0.000"], ["70494.80", "0.000"], ["70494.90", "0.000"], ["70495.00", "4.500"], ["70495.10", "0.002"], ["70495.30", "0.000"], ["70495.40", "0.004"], ["70495.50", "0.000"], ["70495.60", "0.000"], ["70495.70", "0.002"], ["70496.00", "0.001"], ["70496.20", "0.021"], ["70496.40", "0.001"], ["70496.60", "0.000"], ["70496.80", "0.155"], ["70496.90", "0.024"], ["70497.00", "0.011"], ["70497.20", "0.001"], ["70497.30", "0.025"], ["70497.50", "0.004"], ["70497.60", "0.026"], ["70497.90", "0.033"], ["70498.30", "0.067"], ["70498.40", "0.000"], ["70498.80", "0.043"], ["70498.90", "0.002"], ["70499.20", "0.053"], ["70499.30", "0.091"], ["70499.40", "0.015"], ["70499.80", "0.049"], ["70499.90", "0.003"], ["70500.00", "0.049"], ["70500.10", "0.000"], ["70500.20", "0.000"], ["70500.40", "0.236"], ["70500.50", "0.025"], ["70500.80", "0.007"], ["70501.10", "0.277"], ["70501.50", "0.003"], ["70501.60", "0.004"], ["70501.80", "0.072"], ["70501.90", "0.006"], ["70502.00", "0.002"], ["70502.20", "0.206"], ["70502.50", "0.008"], ["70502.60", "0.002"], ["70503.00", "0.004"], ["70503.10", "0.000"], ["70503.40", "0.035"], ["70503.60", "0.000"], ["70503.70", "0.002"], ["70503.80", "0.001"], ["70503.90", "0.005"], ["70504.20", "0.023"], ["70504.60", "0.005"], ["70504.70", "0.449"], ["70504.80", "0.007"], ["70504.90", "0.084"], ["70505.00", "0.008"], ["70505.30", "0.000"], ["70505.50", "0.007"], ["70505.70", "0.000"], ["70505.80", "0.002"], ["70506.10", "0.132"], ["70506.90", "0.004"], ["70507.10", "0.065"], ["70507.60", "0.004"], ["70507.70", "0.344"], ["70507.80", "0.437"], ["70507.90", "0.005"], ["70508.10", "0.023"], ["70508.50", "0.004"], ["70508.70", "0.000"], ["70509.00", "0.054"], ["70509.30", "0.000"], ["70509.50", "0.001"], ["70509.60", "0.006"], ["70510.00", "0.029"], ["70510.40", "0.009"], ["70510.60", "0.000"], ["70510.90", "0.003"], ["70511.00", "0.008"], ["70511.10", "0.002"], ["70511.30", "0.003"], ["70511.40", "0.004"], ["70511.70", "0.011"], ["70511.80", "0.059"], ["70511.90", "0.002"], ["70512.00", "0.375"], ["70512.80", "0.010"], ["70513.10", "0.003"], ["70513.20", "0.099"], ["70513.30", "0.000"], ["70513.50", "0.345"], ["70513.60", "0.023"], ["70513.80", "0.011"], ["70513.90", "0.032"], ["70514.40", "0.002"], ["70514.50", "0.004"], ["70514.60", "0.005"], ["70514.70", "0.001"], ["70514.80", "0.960"], ["70514.90", "0.642"], ["70515.00", "0.004"], ["70515.20", "0.006"], ["70515.30", "0.012"], ["70515.90", "0.029"], ["70516.00", "0.002"], ["70516.20", "0.004"], ["70516.50", "0.011"], ["70516.60", "0.018"], ["70516.70", "0.073"], ["70516.90", "0.004"], ["70517.00", "0.000"], ["70517.10", "0.001"], ["70517.40", "0.513"], ["70517.50", "0.002"], ["70517.60", "0.031"], ["70517.80", "1.161"], ["70518.00", "0.010"], ["70518.20", "0.515"], ["70518.50", "0.011"], ["70519.20", "0.275"], ["70519.30", "0.344"], ["70519.70", "0.007"], ["70519.80", "0.070"], ["70520.10", "0.003"], ["70520.20", "0.104"], ["70520.50", "0.148"], ["70520.70", "0.134"], ["70520.90", "0.022"], ["70521.10", "0.019"], ["70521.40", "0.587"], ["70521.50", "0.876"], ["70521.90", "0.253"], ["70522.50", "0.033"], ["70523.10", "1.066"], ["70523.20", "0.088"], ["70523.30", "0.002"], ["70523.40", "0.002"], ["70523.70", "0.038"], ["70524.10", "0.022"], ["70524.30", "0.004"], ["70524.40", "0.000"], ["70524.90", "0.516"], ["70525.00", "1.021"], ["70525.10", "0.872"], ["70525.30", "0.002"], ["70525.40", "0.306"], ["70525.70", "0.113"], ["70526.90", "0.000"], ["70527.50", "0.000"], ["70527.90", "0.004"], ["70528.00", "0.080"], ["70528.40", "0.771"], ["70529.20", "0.104"], ["70529.80", "0.004"], ["70530.50", "0.002"], ["70531.10", "0.990"], ["70531.30", "0.000"], ["70532.00", "0.010"], ["70532.70", "0.175"], ["70532.90", "0.054"], ["70533.00", "0.005"], ["70533.10", "0.275"], ["70534.40", "0.000"], ["70534.90", "0.000"], ["70535.10", "0.520"], ["70535.20", "1.436"], ["70535.90", "0.003"], ["70536.80", "0.002"], ["70536.90", "0.007"], ["70537.40", "0.000"], ["70538.70", "0.511"], ["70544.30", "0.212"], ["70544.40", "0.005"], ["70545.60", "0.063"], ["70547.20", "0.003"], ["70548.10", "0.002"], ["70548.50", "0.000"], ["70548.90", "0.015"], ["70549.40", "0.327"], ["70549.50", "0.518"], ["70550.20", "0.028"], ["70552.30", "0.048"], ["70553.50", "0.813"], ["70554.10", "0.002"], ["70555.80", "8.727"], ["70557.00", "0.073"], ["70557.20", "2.325"], ["70558.40", "0.092"], ["70558.50", "0.712"], ["70560.00", "0.072"], ["70561.10", "0.016"], ["70563.50", "0.000"], ["70564.30", "0.000"], ["70565.40", "0.005"], ["70569.20", "0.130"], ["70573.60", "0.000"], ["70574.10", "0.042"], ["70578.40", "0.005"], ["70579.10", "0.225"], ["70587.40", "0.009"], ["70599.00", "0.008"], ["70601.10", "0.002"], ["70603.20", "0.002"], ["70605.80", "0.003"], ["70612.30", "0.128"], ["70613.90", "0.044"], ["70614.00", "0.013"], ["70631.50", "0.200"], ["70658.50", "0.273"], ["70658.80", "0.003"], ["70665.50", "0.267"], ["70666.10", "0.275"], ["70666.50", "10.000"], ["70666.70", "0.000"], ["70676.70", "0.003"], ["70677.00", "0.378"], ["70678.30", "0.159"], ["70682.60", "0.000"], ["70684.20", "0.204"], ["70686.50", "0.273"], ["70689.90", "0.000"], ["70692.60", "0.002"], ["70699.90", "0.162"], ["70700.00", "22.070"], ["70701.90", "0.511"], ["70705.50", "0.002"], ["70707.50", "0.457"], ["70713.10", "10.284"], ["70713.30", "0.000"], ["70717.60", "0.002"], ["70719.10", "0.000"], ["70720.90", "0.003"], ["70731.60", "0.588"], ["70733.10", "0.000"], ["70737.10", "0.000"], ["70739.40", "0.000"], ["70744.20", "10.000"], ["70746.40", "0.017"], ["70759.40", "0.008"], ["70760.80", "0.009"], ["70762.40", "0.000"], ["70767.50", "0.000"], ["70772.40", "0.034"], ["70775.10", "0.002"], ["70775.20", "10.000"], ["70780.70", "0.000"], ["70781.00", "0.950"], ["70784.90", "0.940"], ["70807.60", "0.000"], ["70809.90", "0.054"], ["70821.80", "10.000"], ["70842.80", "0.000"], ["70878.00", "0.210"], ["70913.20", "0.142"], ["70948.40", "2.187"], ["70980.00", "0.540"], ["70983.60", "0.004"], ["71087.10", "0.004"], ["71122.30", "0.000"], ["71157.50", "0.002"], ["71191.60", "5.681"], ["71191.80", "0.000"], ["71199.90", "0.144"], ["71485.30", "0.000"], ["71513.80", "8.099"], ["71584.30", "1.816"], ["71904.80", "0.013"], ["73697.80", "0.000"], ["73873.70", "0.000"], ["74028.00", "0.002"], ["74049.60", "0.002"], ["74225.50", "0.050"], ["74401.40", "0.011"], ["74577.30", "0.000"], ["74753.10", "0.000"], ["74929.00", "0.098"], ["75104.90", "0.000"], ["75280.80", "0.000"], ["75456.70", "0.000"], ["76602.10", "0.000"], ["76778.20", "0.003"], ["76954.30", "0.000"], ["77130.40", "0.002"], ["77306.50", "0.000"], ["77482.60", "0.000"], ["77535.40", "0.002"]]}}
{"local_ts": 1773485164743, "server_ts": 1773485163949, "data": {"e": "depthUpdate", "E": 1773485163951, "T": 1773485163949, "s": "BTCUSDT", "U": 10109435113005, "u": 10109435117052, "pu": 10109435112971, "b": [["5000.00", "101.438"], ["7049.50", "0.000"], ["20294.90", "1.990"], ["20386.60", "0.940"], ["63445.40", "0.032"], ["66916.90", "0.002"], ["66960.80", "0.005"], ["66962.40", "0.008"], ["68318.60", "0.009"], ["69464.50", "18.399"], ["69790.00", "0.113"], ["70279.50", "0.002"], ["70398.10", "0.063"], ["70404.40", "0.002"], ["70405.00", "0.077"], ["70406.30", "0.332"], ["70406.70", "0.069"], ["70407.00", "1.637"], ["70407.40", "0.102"], ["70408.10", "0.042"], ["70444.50", "0.230"], ["70444.60", "0.514"], ["70453.70", "0.103"], ["70455.60", "0.002"], ["70456.10", "0.226"], ["70471.40", "0.019"], ["70473.80", "0.461"], ["70475.90", "0.010"], ["70476.00", "0.077"], ["70476.70", "0.003"], ["70476.80", "0.406"], ["70477.20", "0.206"], ["70480.30", "1.158"], ["70481.10", "0.000"], ["70483.80", "0.212"], ["70483.90", "0.013"], ["70484.30", "0.278"], ["70485.40", "0.021"], ["70486.10", "0.505"], ["70487.40", "0.004"], ["70487.60", "0.005"], ["70487.90", "0.067"], ["70492.40", "0.000"], ["70494.90", "3.019"]], "a": [["70495.00", "7.204"], ["70497.60", "0.003"], ["70498.80", "0.043"], ["70502.00", "0.023"], ["70505.60", "0.002"], ["70516.60", "0.006"], ["70517.50", "0.009"], ["70523.00", "0.094"], ["70543.60", "0.005"], ["70546.20", "0.245"], ["70546.90", "0.063"], ["70547.20", "0.036"], ["70547.60", "0.058"], ["70547.90", "0.182"], ["70552.60", "0.315"], ["70555.20", "0.270"], ["70792.00", "0.132"], ["70812.60", "4.205"], ["71199.90", "0.140"], ["71263.40", "0.700"], ["71517.20", "12.726"], ["71622.90", "1.392"], ["71896.40", "0.424"], ["74042.80", "0.005"], ["77544.50", "0.032"]]}}
{"local_ts": 1773485165763, "server_ts": 1773485164969, "data": {"e": "depthUpdate", "E": 1773485164971, "T": 1773485164969, "s": "BTCUSDT", "U": 10109435163021, "u": 10109435168683, "pu": 10109435162965, "b": [["1000.00", "28.692"], ["5000.00", "101.418"], ["7049.50", "0.000"], ["20194.90", "1.610"], ["20294.90", "1.320"], ["56396.00", "0.002"], ["63445.40", "0.032"], ["66564.70", "0.002"], ["67675.20", "0.044"], ["69201.60", "0.619"], ["69394.10", "8.852"], ["69464.50", "14.375"], ["69790.00", "0.113"], ["69790.10", "3.405"], ["70142.40", "0.854"], ["70249.10", "0.779"], ["70379.10", "0.526"], ["70382.40", "0.108"], ["70444.40", "3.093"], ["70445.10", "0.052"], ["70445.50", "0.005"], ["70445.60", "0.197"], ["70455.00", "0.083"], ["70467.70", "0.267"], ["70469.10", "0.015"], ["70470.90", "0.001"], ["70471.30", "1.071"], ["70471.60", "0.000"], ["70473.40", "1.208"], ["70473.50", "0.184"], ["70473.80", "0.301"], ["70475.00", "0.018"], ["70475.40", "0.746"], ["70475.50", "0.845"], ["70485.70", "0.000"], ["70487.90", "0.067"], ["70491.60", "0.014"], ["70494.90", "2.662"]], "a": [["70495.00", "6.538"], ["70498.50", "0.004"], ["70499.00", "0.300"], ["70500.30", "0.002"], ["70500.50", "0.014"], ["70500.90", "0.000"], ["70502.10", "0.028"], ["70505.50", "0.007"], ["70518.90", "0.004"], ["70519.00", "0.806"], ["70519.90", "0.003"], ["70520.60", "0.076"], ["70521.40", "0.587"], ["70524.20", "0.046"], ["70549.60", "0.143"], ["70556.80", "2.638"], ["70562.00", "0.000"], ["70572.10", "0.028"], ["70582.00", "0.005"], ["70593.00", "1.610"], ["70666.80", "1.916"], ["70707.30", "1.722"], ["70735.90", "3.415"], ["70777.70", "1.956"], ["71009.50", "0.004"], ["71164.70", "2.383"], ["71199.90", "0.140"], ["71222.50", "0.412"], ["71435.50", "0.703"], ["71508.80", "9.379"], ["71513.80", "4.190"], ["71579.20", "4.883"], ["71648.50", "0.004"], ["71654.80", "0.000"], ["71861.60", "0.004"], ["71904.80", "0.019"], ["72203.30", "0.941"], ["74031.80", "0.002"], ["77544.50", "0.032"]]}}
{"local_ts": 1773485166784, "server_ts": 1773485165989, "data": {"e": "depthUpdate", "E": 1773485165991, "T": 1773485165989, "s": "BTCUSDT", "U": 10109435213215, "u": 10109435217422, "pu": 10109435213212, "b": [["5000.00", "101.418"], ["7049.50", "0.000"], ["20094.90", "1.160"], ["20194.90", "1.840"], ["33000.00", "3.785"], ["63445.40", "0.032"], ["66662.30", "0.002"], ["66944.20", "0.000"], ["69076.90", "0.008"], ["69781.70", "5.018"], ["69790.00", "0.113"], ["69790.20", "1.449"], ["70142.40", "0.854"], ["70248.80", "0.054"], ["70417.30", "0.302"], ["70431.40", "0.187"], ["70445.30", "0.098"], ["70445.50", "0.003"], ["70454.10", "0.000"], ["70457.90", "0.727"], ["70461.40", "0.017"], ["70467.60", "0.271"], ["70468.20", "0.111"], ["70469.60", "0.306"], ["70472.60", "0.006"], ["70473.30", "0.340"], ["70473.40", "0.003"], ["70473.70", "0.086"], ["70473.80", "0.091"], ["70476.20", "0.004"], ["70478.30", "0.000"], ["70488.00", "0.007"], ["70489.10", "0.060"], ["70490.00", "0.093"]], "a": [["70495.00", "7.244"], ["70495.30", "0.021"], ["70496.40", "0.018"], ["70497.20", "0.003"], ["70501.10", "0.145"], ["70501.30", "0.015"], ["70503.70", "0.005"], ["70503.80", "0.001"], ["70505.90", "1.166"], ["70512.40", "0.005"], ["70512.50", "0.000"], ["70513.10", "0.012"], ["70513.20", "0.068"], ["70523.30", "0.002"], ["70525.40", "0.306"], ["70526.60", "0.052"], ["70552.50", "0.121"], ["70558.50", "0.729"], ["70572.60", "0.005"], ["71199.90", "0.140"], ["74029.80", "0.075"], ["77544.50", "0.032"], ["89523.20", "0.000"]]}}
{"local_ts": 1773485167804, "server_ts": 1773485167012, "data": {"e": "depthUpdate", "E": 1773485167013, "T": 1773485167012, "s": "BTCUSDT", "U": 10109435253944, "u": 10109435257838, "pu": 10109435253822, "b": [["1000.00", "29.092"], ["5000.00", "101.418"], ["7049.50", "0.056"], ["19994.90", "0.720"], ["20094.90", "2.280"], ["63445.40", "0.032"], ["69790.00", "0.113"], ["70065.60", "0.002"], ["70142.40", "0.854"], ["70337.30", "0.792"], ["70342.50", "0.004"], ["70346.30", "0.516"], ["70353.10", "0.003"], ["70356.30", "0.526"], ["70356.50", "1.164"], ["70359.00", "0.010"], ["70386.60", "0.014"], ["70386.90", "0.228"], ["70387.00", "0.008"], ["70397.10", "3.623"], ["70401.40", "0.307"], ["70405.40", "0.145"], ["70421.10", "0.006"], ["70432.00", "0.019"], ["70444.70", "0.072"], ["70445.10", "0.056"], ["70446.00", "0.002"], ["70446.10", "0.202"], ["70449.60", "0.090"], ["70454.10", "0.000"], ["70458.00", "0.564"], ["70475.30", "0.407"], ["70476.10", "0.019"], ["70477.50", "0.002"], ["70480.90", "0.101"], ["70484.00", "0.638"], ["70484.70", "0.513"], ["70486.00", "0.219"], ["70487.90", "0.005"], ["70488.30", "0.005"], ["70488.50", "0.240"], ["70492.90", "0.002"], ["70493.60", "0.082"], ["70494.40", "0.082"], ["70494.50", "0.051"]], "a": [["70495.00", "7.087"], ["70496.20", "0.002"], ["70496.60", "0.000"], ["70497.00", "0.010"], ["70497.40", "0.005"], ["70499.10", "0.004"], ["70504.80", "0.005"], ["70504.90", "0.000"], ["70506.00", "0.920"], ["70507.60", "0.145"], ["70507.80", "1.254"], ["70508.10", "0.021"], ["70509.60", "0.004"], ["70511.70", "1.095"], ["70511.80", "0.563"], ["70519.40", "0.004"], ["70523.30", "0.002"], ["70523.50", "0.006"], ["70524.60", "0.009"], ["70525.10", "0.874"], ["70530.60", "0.000"], ["70531.50", "0.000"], ["70532.50", "0.370"], ["70532.60", "0.042"], ["70556.50", "0.085"], ["70556.60", "0.272"], ["70705.30", "20.487"], ["71199.90", "0.140"], ["71481.90", "0.651"], ["71648.50", "0.008"], ["71861.60", "0.008"], ["74029.80", "0.073"], ["77544.50", "0.032"], ["89523.20", "0.000"]]}}
{"local_ts": 1773485168828, "server_ts": 1773485168032, "data": {"e": "depthUpdate", "E": 1773485168033, "T": 1773485168032, "s": "BTCUSDT", "U": 10109435292409, "u": 10109435296872, "pu": 10109435292233, "b": [["1000.00", "29.092"], ["5000.00", "101.438"], ["7049.50", "0.056"], ["19994.90", "2.590"], ["20094.90", "0.070"], ["20394.90", "0.340"], ["33000.00", "3.789"], ["56396.00", "0.002"], ["63445.40", "0.032"], ["66954.40", "0.000"], ["69790.00", "0.828"], ["70100.00", "48.789"], ["70142.40", "0.854"], ["70308.10", "0.159"], ["70455.00", "0.042"], ["70475.60", "0.605"], ["70476.90", "0.004"], ["70482.20", "0.005"]], "a": [["70495.00", "4.722"], ["70507.30", "0.113"], ["70507.70", "1.045"], ["70511.90", "0.271"], ["70521.40", "0.587"], ["70524.20", "0.046"], ["70678.30", "0.159"], ["71009.50", "0.004"], ["71164.70", "4.065"], ["71199.90", "0.841"], ["71222.50", "0.412"], ["71435.50", "0.703"], ["71517.20", "18.312"], ["71580.00", "2.265"], ["71648.50", "0.004"], ["71861.60", "0.004"], ["74044.80", "0.100"], ["77544.50", "0.032"], ["89523.20", "0.006"]]}}
{"local_ts": 1773485169848, "server_ts": 1773485169052, "data": {"e": "depthUpdate", "E": 1773485169055, "T": 1773485169052, "s": "BTCUSDT", "U": 10109435331302, "u": 10109435334964, "pu": 10109435331292, "b": [["5000.00", "101.438"], ["7049.50", "0.056"], ["19994.90", "0.360"], ["20294.90", "0.180"], ["20394.90", "2.460"], ["69206.60", "0.002"], ["69266.60", "0.007"], ["69790.00", "0.828"], ["70405.60", "0.905"], ["70407.00", "1.839"], ["70407.30", "0.108"], ["70407.70", "0.058"], ["70408.00", "0.558"], ["70446.20", "0.843"], ["70448.90", "0.000"], ["70453.30", "0.842"], ["70455.20", "0.326"], ["70460.40", "1.351"], ["70467.50", "0.841"], ["70481.70", "0.025"], ["70482.20", "0.041"], ["70483.00", "0.023"]], "a": [["70507.70", "1.042"], ["70509.20", "0.002"], ["70510.10", "0.839"], ["70513.70", "0.080"], ["70517.20", "0.911"], ["70524.20", "0.046"], ["70524.30", "0.843"], ["70531.40", "0.846"], ["70532.60", "0.000"], ["70532.80", "0.072"], ["70538.50", "0.991"], ["70545.60", "0.902"], ["70550.40", "3.397"], ["70550.70", "0.155"], ["70551.10", "0.252"], ["70551.40", "0.182"], ["70678.30", "0.159"], ["71199.90", "0.841"], ["74044.50", "0.004"], ["74045.70", "0.000"], ["89523.20", "0.006"]]}}
{"local_ts": 1773485170873, "server_ts": 1773485170078, "data": {"e": "depthUpdate", "E": 1773485170079, "T": 1773485170078, "s": "BTCUSDT", "U": 10109435364482, "u": 10109435368597, "pu": 10109435364320, "b": [["1000.00", "29.092"], ["5000.00", "101.418"], ["7049.50", "0.028"], ["20194.90", "0.030"], ["20294.90", "2.320"], ["20394.90", "0.650"], ["66951.90", "0.000"], ["66970.00", "0.002"], ["69162.50", "0.437"], ["69472.70", "15.249"], ["69790.00", "0.828"], ["70142.40", "0.854"], ["70359.60", "7.992"], ["70437.40", "0.011"], ["70448.20", "0.102"], ["70455.20", "0.326"], ["70475.70", "1.211"], ["70476.00", "0.015"], ["70476.10", "0.018"], ["70476.20", "0.011"], ["70477.20", "0.204"], ["70477.30", "1.439"], ["70477.40", "0.019"], ["70478.30", "0.000"], ["70479.70", "0.234"], ["70482.20", "0.041"]], "a": [["70495.00", "4.598"], ["70501.50", "0.003"], ["70501.70", "0.146"], ["70505.60", "0.111"], ["70507.70", "1.042"], ["70519.50", "0.007"], ["70519.80", "0.638"], ["70524.20", "0.047"], ["70524.80", "0.252"], ["70525.90", "0.067"], ["70527.10", "0.054"], ["70528.00", "0.011"], ["70532.80", "0.072"], ["70558.60", "8.594"], ["70560.40", "0.568"], ["70561.50", "0.003"], ["70627.00", "8.999"], ["70678.30", "0.159"], ["71009.50", "0.000"], ["71191.60", "3.577"], ["71199.90", "0.841"], ["71222.50", "0.408"], ["71435.50", "0.699"], ["71648.50", "0.000"], ["71861.60", "0.000"], ["74027.20", "0.002"], ["89523.20", "0.006"]]}}
{"local_ts": 1773485171895, "server_ts": 1773485171100, "data": {"e": "depthUpdate", "E": 1773485171101, "T": 1773485171100, "s": "BTCUSDT", "U": 10109435405898, "u": 10109435409269, "pu": 10109435405799, "b": [["5000.00", "101.418"], ["7048.90", "0.028"], ["20188.50", "1.580"], ["20294.90", "1.000"], ["66964.00", "0.020"], ["69331.70", "3.033"], ["69396.00", "1.030"], ["69415.50", "0.862"], ["69466.50", "1.006"], ["69783.60", "0.000"], ["70360.60", "0.002"], ["70364.10", "0.293"], ["70367.30", "0.005"], ["70368.20", "0.000"], ["70373.00", "0.121"], ["70374.60", "0.111"], ["70377.60", "0.000"], ["70381.80", "0.212"], ["70384.50", "0.000"], ["70387.10", "6.537"], ["70398.30", "0.004"], ["70399.90", "0.004"], ["70401.40", "0.303"], ["70402.60", "0.004"], ["70409.30", "0.004"], ["70412.70", "0.342"], ["70423.50", "0.006"], ["70428.90", "0.004"], ["70432.70", "0.004"], ["70434.20", "0.012"], ["70438.30", "0.057"], ["70440.10", "0.010"], ["70441.60", "0.872"], ["70444.20", "0.002"], ["70444.30", "0.021"], ["70444.70", "0.000"], ["70449.90", "0.004"], ["70451.10", "0.003"], ["70453.30", "0.043"], ["70458.00", "0.522"], ["70460.30", "0.386"], ["70461.60", "0.003"], ["70463.60", "0.637"], ["70465.50", "0.011"], ["70468.30", "0.000"], ["70471.40", "0.021"], ["70472.60", "0.487"], ["70472.70", "1.295"], ["70473.00", "0.000"], ["70475.80", "0.000"], ["70476.30", "0.000"], ["70477.30", "0.116"], ["70477.40", "1.583"], ["70477.50", "0.697"], ["70479.50", "0.004"], ["70488.10", "0.002"], ["70488.20", "0.002"], ["70488.50", "8.085"]], "a": [["70488.70", "0.003"], ["70491.70", "0.003"], ["70491.90", "0.003"], ["70493.70", "0.001"], ["70495.00", "0.182"], ["70495.30", "0.000"], ["70497.50", "0.218"], ["70498.80", "0.695"], ["70498.90", "0.002"], ["70501.30", "0.064"], ["70501.60", "0.007"], ["70504.50", "0.002"], ["70506.30", "0.000"], ["70507.60", "0.006"], ["70508.90", "0.022"], ["70512.00", "0.375"], ["70515.30", "0.014"], ["70520.80", "1.000"], ["70540.10", "0.540"], ["70551.90", "8.504"], ["70555.70", "0.713"], ["70678.90", "0.162"], ["70712.00", "0.284"], ["70815.70", "0.007"], ["71193.50", "0.000"], ["74031.80", "0.002"], ["76602.10", "0.002"], ["89523.20", "0.006"]]}}
{"local_ts": 1773485172914, "server_ts": 1773485172120, "data": {"e": "depthUpdate", "E": 1773485172123, "T": 1773485172120, "s": "BTCUSDT", "U": 10109435445900, "u": 10109435450355, "pu": 10109435445762, "b": [["1000.00", "28.692"], ["5000.00", "101.418"], ["7048.90", "0.028"], ["20088.50", "1.490"], ["20188.50", "1.510"], ["56396.00", "0.002"], ["66943.80", "0.000"], ["66946.70", "0.002"], ["69783.60", "0.000"], ["70136.10", "0.005"], ["70301.70", "6.690"], ["70332.70", "0.732"], ["70335.60", "0.000"], ["70385.40", "0.137"], ["70387.10", "6.523"], ["70424.60", "0.000"], ["70475.80", "0.000"], ["70477.30", "0.116"], ["70477.70", "0.025"], ["70477.80", "0.638"], ["70478.00", "0.007"], ["70478.10", "0.001"], ["70487.40", "0.018"], ["70487.90", "0.000"], ["70488.50", "8.072"]], "a": [["70488.60", "5.014"], ["70488.70", "0.005"], ["70488.80", "0.002"], ["70488.90", "0.002"], ["70491.60", "0.015"], ["70491.90", "0.001"], ["70492.50", "0.002"], ["70492.90", "0.000"], ["70493.10", "0.018"], ["70495.00", "0.163"], ["70495.40", "0.028"], ["70496.80", "0.028"], ["70498.00", "0.021"], ["70500.00", "0.198"], ["70501.30", "0.064"], ["70504.80", "0.003"], ["70505.70", "0.085"], ["70507.00", "0.205"], ["70508.30", "0.005"], ["70508.90", "0.002"], ["70509.10", "0.082"], ["70509.40", "0.536"], ["70509.50", "0.401"], ["70513.90", "0.011"], ["70515.90", "0.006"], ["70517.70", "0.250"], ["70518.80", "0.004"], ["70518.90", "0.004"], ["70535.00", "0.088"], ["70559.10", "0.083"], ["70561.90", "0.511"], ["70584.50", "0.589"], ["70640.50", "1.885"], ["70678.90", "0.162"], ["70816.40", "0.002"], ["70840.90", "0.056"], ["70841.00", "0.218"], ["70841.70", "0.010"], ["71193.50", "0.000"], ["71479.80", "0.000"], ["71570.20", "1.395"], ["71806.70", "0.347"], ["89523.20", "0.006"]]}}
{"local_ts": 1773485173946, "server_ts": 1773485173144, "data": {"e": "depthUpdate", "E": 1773485173145, "T": 1773485173144, "s": "BTCUSDT", "U": 10109435483594, "u": 10109435487564, "pu": 10109435483386, "b": [["1000.00", "28.692"], ["5000.00", "101.418"], ["7048.90", "0.000"], ["19988.50", "1.050"], ["20088.50", "1.950"], ["33000.00", "3.785"], ["69272.50", "0.721"], ["69498.80", "0.286"], ["69783.60", "0.000"], ["70440.10", "0.006"], ["70440.20", "0.122"], ["70471.20", "0.213"], ["70472.50", "0.171"], ["70475.80", "0.000"], ["70477.90", "0.109"], ["70478.10", "0.001"], ["70478.20", "0.094"], ["70481.40", "0.007"], ["70482.70", "0.006"], ["70485.10", "0.017"], ["70486.70", "0.049"], ["70488.00", "0.156"], ["70488.50", "8.073"]], "a": [["70488.60", "5.118"], ["70489.60", "0.000"], ["70490.90", "0.000"], ["70491.40", "0.000"], ["70491.90", "0.001"], ["70492.20", "0.017"], ["70495.70", "0.006"], ["70496.20", "0.002"], ["70499.20", "0.038"], ["70501.30", "0.064"], ["70506.20", "0.003"], ["70525.80", "0.041"], ["71193.50", "0.000"], ["71703.40", "0.697"], ["74033.70", "0.002"], ["89523.20", "0.006"]]}}
{"local_ts": 1773485174956, "server_ts": 1773485174164, "data": {"e": "depthUpdate", "E": 1773485174165, "T": 1773485174164, "s": "BTCUSDT", "U": 10109435523476, "u": 10109435527408, "pu": 10109435523470, "b": [["5000.00", "101.418"], ["7048.90", "0.000"], ["19988.50", "2.400"], ["20088.50", "0.000"], ["20388.50", "0.600"], ["66942.00", "0.000"], ["66957.40", "0.000"], ["66958.60", "0.000"], ["66962.20", "0.000"], ["69563.60", "0.000"], ["69783.60", "0.000"], ["70400.50", "0.061"], ["70407.40", "0.336"], ["70408.40", "0.922"], ["70408.80", "0.041"], ["70439.10", "0.092"], ["70439.80", "0.007"], ["70440.10", "0.006"], ["70445.20", "1.440"], ["70446.20", "0.088"], ["70453.30", "0.040"], ["70456.10", "0.254"], ["70460.40", "0.512"], ["70461.60", "0.251"], ["70462.50", "0.000"], ["70467.50", "0.004"], ["70473.40", "1.270"], ["70473.90", "0.015"], ["70477.30", "0.116"], ["70477.60", "0.005"], ["70481.40", "0.067"], ["70481.50", "0.079"], ["70485.20", "0.015"], ["70485.50", "0.005"], ["70487.80", "0.138"]], "a": [["70489.40", "0.017"], ["70494.30", "0.127"], ["70494.40", "0.285"], ["70494.50", "0.005"], ["70495.70", "0.004"], ["70495.80", "0.024"], ["70496.60", "0.002"], ["70497.50", "0.166"], ["70499.80", "0.284"], ["70506.20", "0.142"], ["70510.10", "0.000"], ["70517.20", "0.072"], ["70524.30", "0.004"], ["70527.40", "0.000"], ["70531.40", "0.007"], ["70538.50", "0.152"], ["70547.00", "0.010"], ["70549.70", "0.025"], ["70550.10", "0.345"], ["70551.00", "0.004"], ["70551.10", "0.335"], ["70660.10", "0.000"], ["70660.80", "0.010"], ["70667.10", "5.022"], ["70667.80", "0.007"], ["70674.10", "0.000"], ["70674.80", "0.010"], ["70675.40", "0.164"], ["70678.90", "0.162"], ["70681.10", "0.000"], ["70681.80", "0.021"], ["70688.10", "2.537"], ["70688.80", "0.291"], ["70695.10", "0.000"], ["70695.80", "0.007"], ["70702.10", "0.000"], ["70702.80", "0.007"], ["70709.10", "0.000"], ["70709.80", "0.009"], ["70711.80", "0.002"], ["70712.00", "0.291"], ["70816.30", "0.000"], ["71193.50", "0.000"], ["71819.90", "0.000"], ["89523.20", "0.006"]]}}
{"local_ts": 1773485175980, "server_ts": 1773485175188, "data": {"e": "depthUpdate", "E": 1773485175189, "T": 1773485175188, "s": "BTCUSDT", "U": 10109435564189, "u": 10109435570321, "pu": 10109435564054, "b": [["1000.00", "28.692"], ["5000.00", "101.418"], ["7048.90", "0.000"], ["19988.50", "0.140"], ["20288.50", "0.290"], ["20388.50", "2.570"], ["33000.00", "3.785"], ["56391.00", "0.076"], ["69413.40", "0.719"], ["70136.10", "0.005"], ["70439.60", "0.006"], ["70439.80", "0.007"], ["70483.40", "0.282"], ["70486.10", "0.120"]], "a": [["70494.10", "0.189"], ["70494.20", "0.654"], ["70494.30", "0.004"], ["70494.40", "0.003"], ["70495.10", "0.013"], ["70496.60", "0.015"], ["70499.20", "0.038"], ["70499.80", "0.000"], ["70500.70", "0.117"], ["70537.20", "0.208"], ["70546.80", "0.169"], ["70606.80", "0.041"], ["70610.40", "0.012"], ["70621.60", "0.000"], ["70622.30", "0.041"], ["70651.80", "0.007"], ["70658.80", "0.010"], ["70660.80", "0.003"], ["70665.80", "0.007"], ["70667.80", "0.000"], ["70672.80", "0.011"], ["70674.80", "0.003"], ["70678.90", "0.162"], ["70679.80", "0.010"], ["70681.80", "0.014"], ["70686.80", "0.007"], ["70688.80", "0.284"], ["70693.80", "0.007"], ["70695.80", "0.000"], ["70700.80", "0.007"], ["70702.80", "0.000"], ["70709.80", "0.002"], ["70711.90", "0.000"], ["71193.50", "0.250"], ["71468.40", "1.536"], ["72165.60", "0.000"], ["74022.30", "0.000"], ["89523.10", "0.007"], ["89523.20", "0.006"]]}}
{"local_ts": 1773485177001, "server_ts": 1773485176208, "data": {"e": "depthUpdate", "E": 1773485176209, "T": 1773485176208, "s": "BTCUSDT", "U": 10109435611825, "u": 10109435616201, "pu": 10109435611808, "b": [["5000.00", "101.418"], ["7048.90", "0.056"], ["20188.50", "0.140"], ["20288.50", "2.420"], ["20388.50", "0.440"], ["68373.80", "0.007"], ["69078.80", "0.632"], ["69775.80", "0.119"], ["69783.10", "0.050"], ["69783.60", "0.715"], ["69924.60", "0.002"], ["69936.70", "46.797"], ["70308.80", "0.159"], ["70460.30", "0.386"], ["70488.50", "7.803"]], "a": [["70495.00", "0.150"], ["70495.10", "0.011"], ["70495.20", "0.020"], ["70496.40", "0.005"], ["70496.50", "0.018"], ["70506.20", "0.142"], ["70509.40", "0.516"], ["70509.50", "0.421"], ["70524.70", "0.004"], ["70532.30", "0.007"], ["70649.80", "0.596"], ["70651.80", "0.000"], ["70656.80", "0.213"], ["70658.80", "0.003"], ["70663.80", "0.009"], ["70665.80", "0.000"], ["70670.80", "0.007"], ["70672.80", "0.004"], ["70677.80", "0.007"], ["70679.80", "0.003"], ["70684.80", "0.007"], ["70686.80", "0.000"], ["70691.80", "0.009"], ["70693.80", "0.000"], ["70698.80", "0.007"], ["70700.80", "0.000"], ["71193.50", "0.000"], ["71492.00", "0.000"], ["71570.00", "0.929"], ["74033.60", "0.017"], ["89523.20", "0.006"]]}}
{"local_ts": 1773485178030, "server_ts": 1773485177228, "data": {"e": "depthUpdate", "E": 1773485177231, "T": 1773485177228, "s": "BTCUSDT", "U": 10109435651175, "u": 10109435654874, "pu": 10109435651114, "b": [["1000.00", "28.692"], ["5000.00", "101.398"], ["7048.90", "0.056"], ["20188.50", "2.260"], ["20288.50", "0.740"], ["33000.00", "3.789"], ["69290.20", "0.002"], ["69415.40", "1.429"], ["69453.20", "0.718"], ["69498.80", "0.000"], ["69624.90", "0.717"], ["69783.60", "0.715"], ["69801.80", "0.000"], ["69818.90", "2.181"], ["70136.10", "0.005"], ["70308.80", "0.159"], ["70400.90", "0.142"], ["70403.10", "0.355"], ["70438.90", "0.002"], ["70439.80", "0.005"], ["70441.10", "0.341"], ["70449.10", "0.112"], ["70460.30", "0.333"], ["70474.40", "0.031"]], "a": [["70499.20", "0.038"], ["70500.70", "0.701"], ["70501.90", "0.021"], ["70506.20", "0.142"], ["70512.00", "0.390"], ["70523.90", "0.000"], ["70525.00", "1.250"], ["70526.10", "0.729"], ["70558.00", "0.000"], ["70560.20", "0.219"], ["70614.90", "0.000"], ["70617.10", "0.488"], ["70644.50", "0.718"], ["70649.80", "0.589"], ["70651.50", "1.411"], ["70656.80", "0.206"], ["70658.50", "0.280"], ["70663.80", "0.002"], ["70665.50", "0.007"], ["70670.80", "0.000"], ["70672.50", "0.007"], ["70677.80", "0.000"], ["70679.50", "0.518"], ["70684.80", "0.000"], ["70686.50", "0.280"], ["70691.80", "0.002"], ["70693.50", "0.007"], ["70698.80", "0.000"], ["73308.10", "1.176"], ["74020.70", "0.002"]]}}
{"local_ts": 1773485179044, "server_ts": 1773485178250, "data": {"e": "depthUpdate", "E": 1773485178251, "T": 1773485178250, "s": "BTCUSDT", "U": 10109435691571, "u": 10109435695671, "pu": 10109435691503, "b": [["1000.00", "28.692"], ["5000.00", "101.418"], ["7048.90", "0.056"], ["20088.50", "1.810"], ["20188.50", "1.190"], ["66933.90", "0.000"], ["66964.10", "0.007"], ["68345.80", "0.004"], ["69783.60", "0.715"], ["70250.00", "4.619"], ["70440.50", "0.386"], ["70440.60", "0.488"], ["70460.30", "0.333"], ["70474.40", "0.084"], ["70482.70", "0.044"], ["70488.20", "0.015"], ["70488.30", "0.002"]], "a": [["70492.20", "0.002"], ["70494.20", "0.015"], ["70495.50", "0.015"], ["70496.80", "0.031"], ["70497.40", "0.005"], ["70499.40", "0.015"], ["70500.00", "0.198"], ["70506.20", "0.003"], ["70507.00", "0.205"], ["70513.90", "0.032"], ["70515.90", "0.027"], ["70546.80", "0.030"], ["70644.50", "0.711"], ["70646.80", "0.007"], ["70651.50", "1.404"], ["70653.80", "0.007"], ["70658.50", "0.273"], ["70660.80", "0.010"], ["70665.50", "0.000"], ["70667.80", "0.007"], ["70672.50", "0.000"], ["70674.80", "0.010"], ["70679.50", "0.511"], ["70681.80", "0.021"], ["70686.50", "0.273"], ["70688.80", "0.291"], ["70693.50", "0.000"], ["70695.80", "0.007"], ["71193.50", "0.000"], ["71193.90", "0.294"], ["71560.10", "0.435"], ["74032.20", "0.002"]]}}
{"local_ts": 1773485180065, "server_ts": 1773485179272, "data": {"e": "depthUpdate", "E": 1773485179273, "T": 1773485179272, "s": "BTCUSDT", "U": 10109435730635, "u": 10109435735357, "pu": 10109435730582, "b": [["5000.00", "101.418"], ["7048.90", "0.028"], ["19988.50", "1.360"], ["20088.50", "1.640"], ["66948.50", "0.000"], ["66952.80", "0.002"], ["66964.10", "0.007"], ["66964.20", "0.004"], ["67669.00", "0.014"], ["69783.60", "0.715"], ["70440.70", "0.128"], ["70440.80", "0.312"], ["70460.60", "0.002"], ["70460.70", "0.184"], ["70461.60", "0.003"], ["70461.70", "0.264"], ["70467.40", "0.111"], ["70468.50", "0.075"], ["70469.50", "0.000"], ["70475.70", "0.640"], ["70476.20", "0.000"], ["70482.70", "0.004"], ["70486.40", "0.015"], ["70487.10", "0.002"]], "a": [["70488.60", "2.926"], ["70491.50", "0.003"], ["70515.10", "0.006"], ["70516.10", "0.086"], ["70524.70", "0.025"], ["70532.60", "0.004"], ["70548.20", "0.020"], ["71179.40", "0.872"], ["71193.50", "0.000"]]}}
{"local_ts": 1773485181085, "server_ts": 1773485180292, "data": {"e": "depthUpdate", "E": 1773485180293, "T": 1773485180292, "s": "BTCUSDT", "U": 10109435776179, "u": 10109435780645, "pu": 10109435776173, "b": [["1000.00", "28.692"], ["5000.00", "101.418"], ["7048.90", "0.028"], ["19988.50", "2.080"], ["20388.50", "0.920"], ["66329.70", "1.355"], ["66943.50", "0.002"], ["68796.80", "1.163"], ["69393.30", "2.636"], ["69783.60", "0.715"], ["70062.90", "0.114"], ["70136.10", "0.005"], ["70170.50", "0.875"], ["70248.50", "3.520"], ["70440.80", "0.310"], ["70440.90", "0.080"], ["70460.70", "0.000"], ["70470.90", "0.258"], ["70481.60", "0.398"], ["70482.70", "0.004"], ["70483.00", "0.065"], ["70483.20", "0.002"], ["70483.40", "0.010"], ["70483.80", "0.021"], ["70483.90", "0.013"], ["70484.10", "0.003"], ["70484.30", "0.005"], ["70484.80", "0.005"], ["70485.20", "0.015"], ["70485.40", "0.000"], ["70485.50", "0.005"], ["70485.70", "0.000"]], "a": [["70488.60", "3.854"], ["70495.70", "0.006"], ["70495.90", "0.039"], ["70497.00", "0.019"], ["70497.10", "0.520"], ["70497.20", "0.828"], ["70501.90", "0.222"], ["70546.80", "0.169"], ["70548.10", "0.002"], ["70548.20", "0.105"], ["70559.10", "0.083"], ["70560.20", "0.219"], ["70562.20", "0.006"], ["70735.90", "0.197"], ["70812.60", "0.357"], ["71193.50", "0.000"], ["71573.00", "0.610"], ["73237.70", "1.117"]]}}
{"local_ts": 1773485182105, "server_ts": 1773485181308, "data": {"e": "depthUpdate", "E": 1773485181313, "T": 1773485181308, "s": "BTCUSDT", "U": 10109435817740, "u": 10109435821670, "pu": 10109435817706, "b": [["5000.00", "101.418"], ["7048.90", "0.028"], ["19988.50", "0.000"], ["20288.50", "0.460"], ["20388.50", "2.540"], ["66964.10", "0.009"], ["67669.00", "0.649"], ["69395.90", "2.667"], ["69783.60", "0.715"], ["70318.10", "0.024"]], "a": [["70493.50", "0.004"], ["70497.10", "0.016"], ["70506.20", "0.142"], ["70548.20", "0.020"], ["70560.00", "0.076"], ["70562.20", "0.004"], ["70661.90", "0.000"], ["71193.50", "0.000"], ["71247.00", "0.002"], ["73237.70", "2.481"], ["74035.50", "0.005"], ["74037.70", "0.000"]]}}
{"local_ts": 1773485183133, "server_ts": 1773485182336, "data": {"e": "depthUpdate", "E": 1773485182337, "T": 1773485182336, "s": "BTCUSDT", "U": 10109435856851, "u": 10109435860471, "pu": 10109435856778, "b": [["1000.00", "28.692"], ["5000.00", "101.418"], ["7048.90", "0.000"], ["20188.50", "0.250"], ["20288.50", "2.520"], ["20388.50", "0.230"], ["33000.00", "3.785"], ["66930.30", "0.002"], ["69783.60", "0.715"], ["69896.30", "0.068"], ["70136.10", "0.005"], ["70395.10", "0.032"], ["70402.20", "0.075"], ["70409.20", "1.000"], ["70439.80", "0.005"], ["70448.90", "0.004"]], "a": [["70505.70", "0.000"], ["70556.50", "0.002"], ["70560.00", "0.074"], ["70571.40", "0.138"], ["70578.40", "0.073"], ["70585.30", "0.090"], ["70585.50", "0.305"], ["70592.10", "0.005"], ["71000.00", "21.478"], ["71193.50", "0.000"], ["71300.00", "37.763"], ["71574.50", "0.000"], ["74037.20", "0.000"]]}}
{"local_ts": 1773485184150, "server_ts": 1773485183354, "data": {"e": "depthUpdate", "E": 1773485183357, "T": 1773485183354, "s": "BTCUSDT", "U": 10109435894233, "u": 10109435898694, "pu": 10109435894207, "b": [["1000.00", "28.692"], ["5000.00", "101.418"], ["7048.90", "0.000"], ["20088.50", "0.100"], ["20188.50", "2.370"], ["20288.50", "0.530"], ["66940.40", "0.002"], ["68357.50", "1.254"], ["69170.30", "0.000"], ["69202.10", "0.000"], ["69358.80", "4.141"], ["69554.50", "0.720"], ["69571.90", "0.000"], ["69783.60", "0.715"], ["69783.70", "0.004"], ["70242.20", "0.000"], ["70356.90", "0.528"], ["70395.00", "0.018"], ["70402.10", "0.071"], ["70409.10", "0.085"], ["70439.50", "0.022"], ["70459.70", "0.356"], ["70460.60", "0.002"], ["70466.80", "0.514"], ["70467.50", "0.004"], ["70469.70", "0.141"], ["70470.20", "0.002"], ["70484.80", "0.005"], ["70485.00", "0.029"], ["70485.30", "0.001"]], "a": [["70488.60", "3.958"], ["70488.90", "0.002"], ["70489.60", "0.015"], ["70506.20", "0.142"], ["70510.40", "0.012"], ["70511.20", "0.642"], ["70511.40", "0.004"], ["70514.70", "0.003"], ["70516.30", "0.002"], ["70516.40", "0.253"], ["70524.70", "0.031"], ["70533.80", "0.008"], ["70546.80", "0.030"], ["70555.10", "0.084"], ["70556.50", "0.000"], ["70571.30", "0.241"], ["70578.30", "0.073"], ["70585.40", "0.080"], ["70622.80", "0.530"], ["70678.90", "0.003"], ["71193.50", "0.000"], ["71573.00", "0.012"]]}}
{"local_ts": 1773485185168, "server_ts": 1773485184374, "data": {"e": "depthUpdate", "E": 1773485184377, "T": 1773485184374, "s": "BTCUSDT", "U": 10109435935764, "u": 10109435939410, "pu": 10109435935708, "b": [["5000.00", "101.438"], ["7048.90", "0.000"], ["20088.50", "2.120"], ["20188.50", "0.880"], ["33000.00", "3.789"], ["66964.10", "0.003"], ["66964.20", "0.008"], ["69392.50", "1.007"], ["69504.80", "0.002"], ["69783.60", "0.715"], ["70440.90", "0.080"], ["70441.00", "0.002"], ["70475.40", "0.287"], ["70477.90", "0.109"], ["70481.60", "0.396"], ["70484.20", "0.358"], ["70488.50", "7.700"]], "a": [["70488.60", "3.929"], ["70495.70", "0.004"], ["70496.40", "0.005"], ["70499.20", "0.002"], ["70506.20", "0.084"], ["70555.10", "0.082"], ["70556.90", "0.386"], ["71193.50", "0.000"], ["71234.60", "0.017"], ["74018.10", "0.002"], ["74043.00", "0.000"], ["74047.50", "0.050"], ["77442.90", "0.008"], ["77537.50", "0.004"]]}}
{"local_ts": 1773485186190, "server_ts": 1773485185396, "data": {"e": "depthUpdate", "E": 1773485185397, "T": 1773485185396, "s": "BTCUSDT", "U": 10109435974417, "u": 10109435978400, "pu": 10109435974325, "b": [["1000.00", "28.692"], ["5000.00", "101.418"], ["7048.90", "0.000"], ["19988.50", "1.670"], ["20088.50", "1.330"], ["69783.60", "0.715"], ["70136.10", "0.005"], ["70305.20", "0.002"], ["70308.80", "0.159"], ["70322.90", "0.000"], ["70326.40", "0.002"], ["70332.70", "0.714"], ["70339.80", "0.136"], ["70340.70", "2.433"], ["70435.00", "0.085"], ["70440.80", "0.310"], ["70441.00", "0.004"], ["70458.40", "0.000"], ["70459.30", "0.003"], ["70461.30", "0.619"], ["70464.20", "0.002"], ["70464.40", "0.000"], ["70466.50", "0.510"], ["70467.80", "0.144"], ["70469.10", "0.000"], ["70474.10", "0.000"], ["70475.20", "1.006"], ["70475.50", "0.013"], ["70475.60", "0.672"], ["70475.80", "0.002"], ["70477.60", "0.286"], ["70477.80", "0.004"], ["70478.30", "0.000"], ["70478.40", "0.005"], ["70479.70", "0.251"], ["70480.30", "0.008"], ["70480.40", "0.000"], ["70480.60", "0.003"], ["70481.40", "0.007"], ["70481.50", "0.304"], ["70486.50", "0.062"], ["70487.80", "0.051"]], "a": [["70488.60", "4.296"], ["70492.50", "0.002"], ["70493.80", "0.109"], ["70495.60", "0.027"], ["70497.00", "0.260"], ["70499.90", "0.734"], ["70501.40", "0.136"], ["70503.40", "0.147"], ["70505.40", "0.002"], ["70509.30", "0.000"], ["70510.20", "0.141"], ["70510.40", "0.522"], ["70510.80", "0.638"], ["70512.70", "0.003"], ["70514.50", "0.002"], ["70515.80", "0.005"], ["70516.40", "0.253"], ["70516.70", "0.073"], ["70517.70", "0.054"], ["70559.10", "0.002"], ["70581.40", "1.464"], ["70675.40", "0.164"], ["70678.90", "0.003"], ["71193.50", "0.000"], ["71510.70", "3.631"], ["74032.30", "0.000"]]}}
{"local_ts": 1773485187220, "server_ts": 1773485186416, "data": {"e": "depthUpdate", "E": 1773485186417, "T": 1773485186416, "s": "BTCUSDT", "U": 10109436014339, "u": 10109436018226, "pu": 10109436014089, "b": [["5000.00", "101.418"], ["7048.90", "0.056"], ["19988.50", "1.770"], ["20388.50", "1.230"], ["66942.60", "0.000"], ["69783.60", "0.715"], ["70393.80", "0.000"], ["70395.00", "0.014"], ["70395.10", "0.000"], ["70400.90", "0.000"], ["70407.90", "0.000"], ["70464.40", "0.002"], ["70468.80", "0.067"], ["70475.70", "0.781"], ["70475.80", "0.064"], ["70481.50", "0.319"], ["70483.10", "0.001"], ["70488.50", "7.465"]], "a": [["70493.60", "0.002"], ["70493.80", "0.095"], ["70495.60", "0.027"], ["70495.70", "0.004"], ["70495.80", "0.003"], ["70495.90", "0.018"], ["70496.00", "0.004"], ["70497.00", "0.246"], ["70499.80", "0.654"], ["70499.90", "0.023"], ["70570.10", "0.058"], ["70577.10", "0.097"], ["70584.20", "0.043"], ["71193.50", "0.000"], ["72265.60", "2.487"], ["74034.80", "0.002"]]}}
{"local_ts": 1773485188234, "server_ts": 1773485187437, "data": {"e": "depthUpdate", "E": 1773485187439, "T": 1773485187437, "s": "BTCUSDT", "U": 10109436056714, "u": 10109436060259, "pu": 10109436056667, "b": [["1000.00", "28.692"], ["5000.00", "101.418"], ["7048.90", "0.056"], ["20288.50", "0.780"], ["20388.50", "2.220"], ["66961.30", "0.002"], ["66964.00", "0.000"], ["66964.20", "0.004"], ["68373.80", "0.007"], ["69413.50", "0.719"], ["69640.80", "1.148"], ["69783.60", "0.715"], ["69783.70", "0.008"], ["69922.70", "0.085"], ["70136.10", "0.005"], ["70242.50", "0.002"], ["70318.20", "0.000"], ["70356.90", "0.004"], ["70395.10", "0.014"], ["70395.20", "0.002"], ["70396.00", "0.022"], ["70423.10", "0.008"], ["70475.90", "0.259"], ["70476.00", "0.077"], ["70477.20", "0.023"], ["70481.50", "0.304"], ["70488.50", "7.745"]], "a": [["70495.60", "0.027"], ["70497.00", "0.158"], ["70498.70", "0.002"], ["70505.60", "0.299"], ["70525.80", "0.005"], ["70552.90", "0.000"], ["70622.40", "0.000"], ["70658.00", "0.606"], ["70661.40", "0.329"], ["70675.40", "0.005"], ["71050.60", "4.937"], ["71193.50", "0.000"], ["71813.60", "1.254"], ["89523.20", "0.012"]]}}
{"local_ts": 1773485189254, "server_ts": 1773485188460, "data": {"e": "depthUpdate", "E": 1773485188461, "T": 1773485188460, "s": "BTCUSDT", "U": 10109436091134, "u": 10109436094218, "pu": 10109436091012, "b": [["1000.00", "28.692"], ["5000.00", "101.418"], ["7048.90", "0.056"], ["20188.50", "0.380"], ["20288.50", "2.580"], ["20388.50", "0.040"], ["66948.80", "0.002"], ["69783.60", "2.862"], ["70466.20", "0.003"], ["70467.00", "0.135"], ["70467.80", "0.214"], ["70467.90", "0.000"], ["70476.10", "0.008"], ["70476.20", "0.062"], ["70477.90", "0.005"], ["70481.50", "0.302"], ["70483.50", "0.002"], ["70484.40", "0.019"], ["70484.60", "0.001"], ["70484.80", "0.005"], ["70485.00", "0.014"], ["70485.30", "0.001"], ["70485.50", "0.005"], ["70485.70", "0.021"], ["70485.90", "0.008"], ["70486.10", "0.120"]], "a": [["70488.60", "4.201"], ["70488.80", "0.072"], ["70489.00", "0.589"], ["70493.60", "0.002"], ["70494.80", "0.012"], ["70495.60", "0.025"], ["70496.10", "0.021"], ["70496.40", "0.005"], ["70499.20", "0.002"], ["70500.00", "0.334"], ["70505.60", "0.030"], ["70512.00", "0.229"], ["70513.70", "0.000"], ["70514.60", "0.584"], ["70515.80", "0.005"], ["70524.80", "0.273"], ["70532.70", "0.175"], ["71193.50", "0.701"], ["74036.60", "0.000"], ["89523.20", "0.012"]]}}
{"local_ts": 1773485190282, "server_ts": 1773485189480, "data": {"e": "depthUpdate", "E": 1773485189481, "T": 1773485189480, "s": "BTCUSDT", "U": 10109436128227, "u": 10109436132050, "pu": 10109436128103, "b": [["5000.00", "101.418"], ["7048.90", "0.028"], ["20088.50", "0.200"], ["20188.50", "2.490"], ["20288.50", "0.310"], ["33000.00", "3.785"], ["66963.90", "0.000"], ["68711.50", "2.615"], ["69783.60", "2.862"], ["70294.80", "0.000"], ["70296.10", "0.255"], ["70356.50", "0.002"], ["70356.70", "7.354"], ["70356.80", "2.734"], ["70356.90", "0.530"], ["70359.60", "0.050"], ["70360.50", "2.244"], ["70393.80", "0.018"], ["70400.90", "0.071"], ["70407.90", "0.402"], ["70435.00", "0.000"], ["70436.50", "8.518"], ["70436.60", "0.087"], ["70438.20", "0.000"], ["70440.60", "0.488"], ["70441.70", "0.513"], ["70451.40", "0.720"], ["70451.70", "0.035"], ["70458.60", "0.023"], ["70459.10", "0.001"], ["70460.60", "0.292"], ["70461.60", "0.003"], ["70462.50", "0.000"], ["70463.80", "1.117"], ["70465.10", "0.015"], ["70466.50", "0.510"], ["70467.40", "0.132"], ["70468.50", "0.005"], ["70468.90", "0.018"], ["70469.70", "0.000"], ["70472.60", "0.348"], ["70472.80", "0.001"], ["70473.50", "0.035"], ["70473.90", "0.000"], ["70475.50", "0.651"], ["70476.30", "0.000"], ["70476.40", "0.000"], ["70477.00", "0.029"], ["70477.90", "0.008"], ["70478.30", "0.015"], ["70483.50", "0.023"], ["70483.80", "0.000"], ["70485.50", "0.026"], ["70485.70", "0.000"], ["70488.50", "7.010"]], "a": [["70488.60", "4.267"], ["70488.90", "0.017"], ["70491.80", "0.003"], ["70493.50", "0.004"], ["70493.60", "0.115"], ["70495.60", "0.063"], ["70495.70", "0.004"], ["70496.40", "0.008"], ["70496.50", "0.003"], ["70496.60", "0.000"], ["70497.00", "0.245"], ["70499.20", "0.005"], ["70499.90", "0.687"], ["70511.40", "0.004"], ["70512.10", "0.640"], ["70532.70", "0.118"], ["70570.10", "0.129"], ["70577.10", "0.168"], ["70584.20", "0.114"], ["70620.20", "1.777"], ["70620.30", "9.582"], ["70620.60", "0.000"], ["70622.10", "0.260"], ["70626.90", "0.549"], ["70627.00", "0.220"], ["71059.30", "0.000"], ["71193.50", "0.701"], ["71493.20", "0.697"], ["74045.80", "0.002"], ["89523.20", "0.012"]]}}
{"local_ts": 1773485191296, "server_ts": 1773485190499, "data": {"e": "depthUpdate", "E": 1773485190501, "T": 1773485190499, "s": "BTCUSDT", "U": 10109436169591, "u": 10109436173097, "pu": 10109436169529, "b": [["1000.00", "28.692"], ["5000.00", "101.418"], ["7048.90", "0.028"], ["19988.50", "0.050"], ["20088.50", "2.330"], ["20188.50", "0.620"], ["66959.90", "0.009"], ["66964.10", "0.007"], ["66964.20", "0.008"], ["69783.60", "2.862"], ["70136.10", "0.005"], ["70370.30", "0.000"], ["70380.90", "0.003"], ["70436.60", "0.002"], ["70436.90", "0.085"], ["70440.80", "0.378"], ["70451.40", "0.724"], ["70453.30", "0.040"], ["70476.50", "0.004"], ["70480.60", "0.025"], ["70488.00", "0.010"], ["70488.50", "7.265"]], "a": [["70488.60", "3.943"], ["70488.90", "0.017"], ["70489.10", "0.000"], ["70491.80", "0.003"], ["70493.60", "0.105"], ["70495.90", "0.000"], ["70496.00", "0.004"], ["70496.10", "0.021"], ["70497.00", "0.243"], ["70499.80", "0.654"], ["70499.90", "0.023"], ["70500.70", "0.083"], ["70500.80", "0.128"], ["70505.60", "0.214"], ["70520.30", "0.262"], ["70530.70", "0.006"], ["70541.30", "0.072"], ["70576.30", "2.011"], ["70586.90", "0.000"], ["70675.40", "0.164"], ["71193.50", "0.701"], ["74045.80", "0.000"], ["89523.20", "0.012"]]}}
{"local_ts": 1773485192318, "server_ts": 1773485191520, "data": {"e": "depthUpdate", "E": 1773485191521, "T": 1773485191520, "s": "BTCUSDT", "U": 10109436209366, "u": 10109436213057, "pu": 10109436209242, "b": [["5000.00", "101.418"], ["7048.90", "0.028"], ["19988.50", "1.980"], ["20088.50", "1.020"], ["33000.00", "3.789"], ["56391.00", "0.080"], ["66937.90", "0.007"], ["66958.10", "0.000"], ["66964.10", "0.005"], ["66964.20", "0.008"], ["69464.50", "10.349"], ["69502.40", "0.004"], ["69783.60", "2.862"], ["70255.00", "1.999"], ["70441.80", "0.002"], ["70441.90", "0.009"], ["70451.40", "0.720"], ["70460.60", "0.292"], ["70461.60", "0.003"], ["70475.20", "0.356"], ["70475.60", "0.640"], ["70475.80", "0.545"], ["70476.20", "0.000"], ["70476.70", "0.003"], ["70477.00", "0.022"], ["70477.50", "0.066"], ["70477.70", "0.005"], ["70477.90", "0.008"], ["70478.00", "0.007"], ["70478.40", "0.005"], ["70478.50", "0.357"], ["70478.90", "0.488"], ["70479.40", "0.002"], ["70480.20", "0.008"], ["70488.50", "7.275"]], "a": [["70488.80", "0.090"], ["70493.50", "0.006"], ["70493.60", "0.107"], ["70496.40", "0.005"], ["70496.70", "0.003"], ["70496.80", "0.028"], ["70497.00", "0.243"], ["70499.20", "0.002"], ["70499.70", "0.663"], ["70499.80", "0.057"], ["70499.90", "0.023"], ["70500.70", "0.083"], ["70500.90", "0.000"], ["70501.20", "0.087"], ["70504.30", "0.581"], ["70505.10", "0.141"], ["70505.60", "0.030"], ["70507.50", "0.346"], ["70508.30", "0.012"], ["70511.10", "0.660"], ["70511.80", "0.701"], ["70512.60", "0.510"], ["70516.10", "0.016"], ["70522.10", "0.009"], ["70530.70", "0.002"], ["70541.50", "0.099"], ["70559.80", "0.007"], ["70561.40", "0.024"], ["70712.30", "0.016"], ["71193.40", "0.000"], ["71193.50", "0.701"], ["71398.80", "0.000"], ["89523.20", "0.012"]]}}
{"local_ts": 1773485193336, "server_ts": 1773485192542, "data": {"e": "depthUpdate", "E": 1773485192543, "T": 1773485192542, "s": "BTCUSDT", "U": 10109436244059, "u": 10109436246976, "pu": 10109436244009, "b": [["1000.00", "28.692"], ["5000.00", "101.398"], ["7048.90", "0.000"], ["19988.50", "1.460"], ["20388.50", "1.540"], ["56391.00", "0.076"], ["66951.20", "0.000"], ["69470.60", "0.143"], ["69783.60", "2.862"], ["70136.10", "0.077"], ["70301.70", "6.690"], ["70308.80", "0.000"], ["70322.90", "0.039"], ["70332.70", "0.732"], ["70341.20", "0.000"], ["70341.30", "0.664"], ["70356.90", "0.004"], ["70399.40", "0.643"], ["70401.60", "1.753"], ["70427.70", "1.944"], ["70430.20", "0.947"], ["70434.20", "0.055"], ["70440.00", "0.041"], ["70440.10", "0.001"], ["70448.60", "0.035"], ["70455.30", "0.511"], ["70466.40", "0.014"], ["70467.80", "0.513"], ["70481.60", "0.393"]], "a": [["70491.20", "0.008"], ["70504.20", "0.348"], ["70505.10", "0.000"], ["70520.30", "0.181"], ["70524.80", "0.029"], ["70525.30", "0.036"], ["70526.40", "0.043"], ["70527.40", "0.000"], ["70529.30", "0.009"], ["70541.50", "0.000"], ["70546.40", "0.484"], ["70546.50", "0.008"], ["70548.50", "0.463"], ["70550.80", "2.069"], ["70581.40", "0.531"], ["70581.80", "0.047"], ["70621.90", "0.092"], ["70640.50", "1.885"], ["70641.40", "0.299"], ["70809.30", "0.000"], ["70834.00", "0.211"], ["71193.50", "0.701"], ["71684.10", "0.000"], ["71758.10", "0.702"], ["71898.30", "0.011"], ["89523.20", "0.012"]]}}
{"local_ts": 1773485194368, "server_ts": 1773485193564, "data": {"e": "depthUpdate", "E": 1773485193567, "T": 1773485193564, "s": "BTCUSDT", "U": 10109436280961, "u": 10109436284666, "pu": 10109436280622, "b": [["1000.00", "28.692"], ["5000.00", "101.398"], ["7048.90", "0.000"], ["20288.50", "1.100"], ["20388.50", "1.900"], ["33000.00", "3.789"], ["56391.00", "0.076"], ["69473.10", "3.941"], ["69783.60", "5.724"], ["70136.10", "0.113"], ["70393.70", "0.000"], ["70400.80", "0.817"], ["70407.80", "0.005"], ["70448.80", "0.877"], ["70452.40", "0.862"], ["70459.70", "0.108"], ["70477.00", "0.022"], ["70477.60", "0.003"], ["70477.90", "0.005"], ["70485.50", "0.026"]], "a": [["70488.60", "3.926"], ["70493.60", "0.173"], ["70496.30", "0.005"], ["70496.70", "0.657"], ["70496.80", "0.028"], ["70496.90", "0.032"], ["70497.00", "0.158"], ["70499.20", "0.002"], ["70499.90", "0.023"], ["70501.40", "0.172"], ["70501.60", "0.045"], ["70501.70", "0.643"], ["70526.30", "0.046"], ["70570.00", "0.051"], ["70577.00", "0.342"], ["70584.10", "0.004"], ["70834.00", "0.000"], ["70841.00", "0.323"], ["71045.40", "0.005"], ["71059.80", "1.855"], ["71193.50", "2.104"], ["71249.90", "3.243"], ["71340.90", "2.391"], ["71510.70", "9.357"], ["71616.40", "3.064"], ["74017.90", "0.002"], ["74032.90", "0.000"], ["89523.20", "0.012"]]}}
{"local_ts": 1773485195380, "server_ts": 1773485194588, "data": {"e": "depthUpdate", "E": 1773485194589, "T": 1773485194588, "s": "BTCUSDT", "U": 10109436319045, "u": 10109436322843, "pu": 10109436318923, "b": [["5000.00", "101.418"], ["7048.90", "0.000"], ["20188.50", "0.660"], ["20288.50", "2.340"], ["20388.50", "0.000"], ["56391.00", "0.076"], ["66959.30", "0.002"], ["69395.90", "10.150"], ["69396.40", "0.002"], ["69783.60", "5.724"], ["69818.90", "6.966"], ["70318.10", "3.959"], ["70356.90", "0.700"], ["70436.80", "0.252"], ["70442.30", "0.009"], ["70451.40", "0.720"], ["70465.10", "0.000"], ["70470.90", "0.357"], ["70471.40", "0.106"], ["70476.60", "0.015"], ["70476.70", "0.003"], ["70479.60", "0.557"], ["70481.50", "0.074"], ["70486.20", "0.029"], ["70488.50", "5.939"]], "a": [["70488.60", "3.716"], ["70489.00", "0.590"], ["70495.60", "0.003"], ["70496.90", "0.546"], ["70498.40", "0.000"], ["70505.50", "0.092"], ["70512.70", "0.515"], ["70513.80", "0.009"], ["70520.30", "0.262"], ["70541.50", "0.000"], ["70547.70", "0.015"], ["70621.70", "0.458"], ["70621.80", "0.196"], ["70660.50", "2.568"], ["70660.60", "0.000"], ["70712.20", "0.000"], ["70819.90", "1.323"], ["70840.90", "0.035"], ["71052.40", "0.039"], ["71193.50", "3.507"], ["71581.20", "5.232"], ["71631.00", "0.006"], ["71704.60", "1.391"], ["89523.20", "0.012"]]}}
{"local_ts": 1773485196407, "server_ts": 1773485195610, "data": {"e": "depthUpdate", "E": 1773485195611, "T": 1773485195610, "s": "BTCUSDT", "U": 10109436353558, "u": 10109436356371, "pu": 10109436353528, "b": [["1000.00", "28.692"], ["5000.00", "101.418"], ["7048.90", "0.056"], ["20088.50", "0.310"], ["20188.50", "2.590"], ["20288.50", "0.100"], ["56391.00", "0.076"], ["66964.10", "0.007"], ["66964.20", "0.006"], ["69395.90", "12.164"], ["69466.40", "20.554"], ["69501.70", "1.596"], ["69783.60", "5.724"], ["70136.10", "0.113"], ["70212.80", "0.739"], ["70242.70", "0.211"], ["70255.70", "2.610"], ["70308.80", "0.159"], ["70434.10", "0.293"], ["70435.10", "0.004"], ["70436.80", "0.153"], ["70442.70", "0.003"], ["70449.00", "0.034"], ["70450.80", "0.004"], ["70453.30", "0.040"], ["70465.10", "0.000"], ["70465.60", "1.074"], ["70467.40", "0.000"], ["70467.70", "0.445"], ["70470.90", "0.412"], ["70471.40", "0.205"], ["70476.80", "0.273"], ["70477.90", "0.005"], ["70478.00", "0.022"], ["70478.10", "0.001"], ["70478.40", "0.003"], ["70481.50", "0.078"], ["70482.60", "0.494"], ["70488.00", "0.004"], ["70488.10", "0.052"], ["70488.50", "5.827"]], "a": [["70489.30", "0.002"], ["70496.30", "0.008"], ["70504.20", "0.108"], ["70505.50", "0.007"], ["70511.70", "1.066"], ["70512.70", "0.003"], ["70513.00", "0.513"], ["70520.30", "0.262"], ["70526.20", "0.050"], ["70528.50", "2.090"], ["70532.90", "0.056"], ["70722.80", "2.592"], ["71193.50", "3.507"], ["74042.30", "0.000"], ["89523.20", "0.012"]]}}
{"local_ts": 1773485197425, "server_ts": 1773485196632, "data": {"e": "depthUpdate", "E": 1773485196633, "T": 1773485196632, "s": "BTCUSDT", "U": 10109436401658, "u": 10109436405648, "pu": 10109436401628, "b": [["5000.00", "101.418"], ["7048.90", "0.056"], ["19988.50", "0.160"], ["20088.50", "2.450"], ["20188.50", "0.390"], ["56391.00", "0.076"], ["69108.20", "0.002"], ["69298.60", "0.000"], ["69325.40", "4.973"], ["69642.60", "6.879"], ["69783.60", "5.724"], ["70100.00", "48.213"], ["70433.40", "0.007"], ["70440.50", "0.390"], ["70440.60", "0.488"], ["70442.70", "0.007"]], "a": [["70522.70", "0.006"], ["70549.10", "0.000"], ["70559.90", "1.079"], ["70675.40", "0.065"], ["71193.50", "3.507"], ["71866.30", "0.000"], ["74025.00", "0.356"], ["89523.20", "0.012"]]}}
{"local_ts": 1773485198452, "server_ts": 1773485197656, "data": {"e": "depthUpdate", "E": 1773485197657, "T": 1773485197656, "s": "BTCUSDT", "U": 10109436438962, "u": 10109436441775, "pu": 10109436438903, "b": [["1000.00", "28.692"], ["5000.00", "101.418"], ["7048.90", "0.056"], ["19988.50", "2.290"], ["20088.50", "0.690"], ["20388.50", "0.020"], ["68711.60", "5.230"], ["68945.00", "0.000"], ["69078.80", "0.632"], ["69416.00", "2.165"], ["69783.60", "5.724"], ["70136.10", "0.113"], ["70256.10", "6.540"], ["70356.90", "0.004"], ["70462.50", "0.052"], ["70477.70", "0.005"], ["70477.90", "0.067"], ["70479.10", "0.026"], ["70486.60", "0.168"], ["70488.50", "5.585"]], "a": [["70488.60", "3.757"], ["70490.10", "0.004"], ["70494.70", "0.001"], ["70496.30", "0.005"], ["70496.50", "0.060"], ["70499.20", "0.002"], ["70621.60", "0.000"], ["70711.50", "0.007"], ["71052.50", "1.056"], ["71169.80", "0.709"], ["71193.40", "0.000"], ["71193.50", "3.507"], ["74032.60", "0.001"]]}}
{"local_ts": 1773485199474, "server_ts": 1773485198682, "data": {"e": "depthUpdate", "E": 1773485198683, "T": 1773485198682, "s": "BTCUSDT", "U": 10109436473334, "u": 10109436477553, "pu": 10109436473292, "b": [["1000.00", "28.692"], ["5000.00", "101.418"], ["7048.90", "0.028"], ["19988.50", "1.110"], ["20388.50", "1.890"], ["33000.00", "3.785"], ["63439.60", "0.024"], ["66947.40", "0.002"], ["66964.00", "0.000"], ["69783.60", "5.724"], ["70308.80", "0.159"], ["70347.10", "0.153"], ["70356.70", "7.531"], ["70356.80", "0.917"], ["70440.20", "0.104"], ["70440.50", "0.388"], ["70441.70", "0.513"], ["70477.90", "0.005"], ["70480.70", "0.228"], ["70480.90", "0.004"], ["70488.50", "5.931"]], "a": [["70488.60", "3.734"], ["70496.30", "0.008"], ["70499.20", "0.005"], ["70522.70", "0.002"], ["70532.90", "0.056"], ["70620.20", "9.476"], ["70620.30", "0.000"], ["71045.40", "0.005"], ["71193.50", "3.507"], ["71208.80", "0.000"], ["71898.30", "0.008"]]}}
{"local_ts": 1773485200506, "server_ts": 1773485199700, "data": {"e": "depthUpdate", "E": 1773485199703, "T": 1773485199700, "s": "BTCUSDT", "U": 10109436538623, "u": 10109436543964, "pu": 10109436538598, "b": [["5000.00", "101.418"], ["7049.20", "0.028"], ["20291.80", "0.670"], ["20388.50", "1.560"], ["66967.20", "0.005"], ["69281.80", "0.002"], ["69352.20", "0.000"], ["69566.70", "66.526"], ["69776.00", "55.707"], ["69783.60", "6.439"], ["69786.90", "0.000"], ["69936.80", "46.548"], ["70208.70", "0.268"], ["70215.70", "0.547"], ["70222.70", "0.264"], ["70333.20", "0.219"], ["70341.70", "3.178"], ["70403.70", "0.665"], ["70444.20", "0.002"], ["70444.30", "0.023"], ["70444.90", "0.068"], ["70448.20", "0.038"], ["70454.00", "0.734"], ["70461.80", "0.003"], ["70463.30", "0.022"], ["70463.60", "0.664"], ["70464.40", "0.000"], ["70464.60", "0.253"], ["70465.00", "0.011"], ["70465.80", "0.056"], ["70466.10", "0.090"], ["70466.40", "0.066"], ["70467.10", "0.000"], ["70467.80", "0.003"], ["70468.80", "0.067"], ["70469.60", "0.300"], ["70469.70", "0.070"], ["70470.00", "4.897"], ["70470.20", "0.072"], ["70471.50", "0.014"], ["70471.60", "0.510"], ["70471.80", "0.008"], ["70472.30", "0.001"], ["70472.40", "0.008"], ["70472.60", "0.348"], ["70473.40", "0.007"], ["70473.60", "0.009"], ["70473.90", "1.205"], ["70475.20", "0.360"], ["70475.40", "0.221"], ["70475.50", "0.013"], ["70476.00", "0.015"], ["70476.10", "0.027"], ["70476.60", "0.019"], ["70476.80", "0.273"], ["70476.90", "0.004"], ["70477.00", "0.022"], ["70477.10", "0.007"], ["70477.20", "0.023"], ["70477.60", "0.144"], ["70477.90", "0.005"], ["70478.60", "0.105"], ["70478.70", "0.108"], ["70479.00", "1.173"], ["70479.60", "0.516"], ["70479.80", "0.001"], ["70480.00", "0.012"], ["70480.10", "0.007"], ["70480.50", "0.019"], ["70480.60", "0.000"], ["70481.10", "0.000"], ["70481.30", "0.686"], ["70481.40", "0.007"], ["70481.50", "0.021"], ["70481.80", "0.212"], ["70481.90", "0.561"], ["70482.10", "0.002"], ["70482.30", "0.097"], ["70482.50", "0.002"], ["70482.60", "0.460"], ["70483.10", "0.015"], ["70483.20", "0.031"], ["70483.50", "0.011"], ["70483.80", "0.029"], ["70484.00", "0.011"], ["70484.10", "0.003"], ["70484.20", "0.343"], ["70484.40", "0.004"], ["70484.80", "0.009"], ["70484.90", "0.412"], ["70485.30", "0.219"], ["70485.70", "0.000"], ["70486.00", "0.013"], ["70486.10", "0.335"], ["70487.00", "0.001"], ["70487.10", "0.002"], ["70487.90", "0.000"], ["70488.40", "0.005"], ["70489.60", "0.003"], ["70490.10", "0.003"], ["70490.80", "0.008"], ["70491.10", "0.000"], ["70491.30", "0.000"], ["70491.40", "0.005"], ["70491.50", "0.000"], ["70491.60", "0.265"], ["70491.70", "0.008"], ["70491.80", "9.238"]], "a": [["70491.90", "5.170"], ["70492.00", "0.003"], ["70492.20", "0.002"], ["70492.80", "0.000"], ["70493.80", "0.026"], ["70494.10", "0.000"], ["70498.60", "0.001"], ["70499.30", "0.008"], ["70499.40", "0.331"], ["70499.50", "0.025"], ["70499.90", "1.209"], ["70500.00", "0.323"], ["70500.10", "0.012"], ["70500.30", "0.025"], ["70500.50", "0.004"], ["70501.20", "0.059"], ["70501.30", "0.222"], ["70502.20", "0.027"], ["70504.00", "0.011"], ["70504.30", "0.126"], ["70504.90", "0.057"], ["70506.20", "0.003"], ["70506.70", "0.022"], ["70506.90", "0.143"], ["70507.50", "0.025"], ["70507.60", "0.006"], ["70508.00", "0.021"], ["70508.50", "0.002"], ["70509.80", "0.004"], ["70513.90", "0.171"], ["70514.70", "1.152"], ["70515.20", "0.013"], ["70515.90", "0.012"], ["70516.00", "0.512"], ["70516.40", "0.005"], ["70516.70", "0.073"], ["70517.00", "0.070"], ["70517.20", "1.592"], ["70517.50", "0.072"], ["70517.70", "0.059"], ["70518.70", "0.003"], ["70519.70", "0.000"], ["70520.20", "0.104"], ["70520.70", "0.259"], ["70521.20", "0.000"], ["70522.90", "0.052"], ["70523.00", "0.033"], ["70523.80", "0.164"], ["70524.80", "0.136"], ["70526.00", "0.338"], ["70526.60", "0.000"], ["70527.20", "0.045"], ["70528.30", "1.840"], ["70532.90", "0.005"], ["70548.30", "0.244"], ["70549.50", "3.894"], ["70552.60", "0.046"], ["70554.10", "0.006"], ["70556.90", "0.384"], ["70564.40", "0.283"], ["70577.80", "0.000"], ["70579.40", "0.003"], ["70711.90", "0.000"], ["70726.00", "0.784"], ["70740.00", "0.795"], ["70747.00", "0.257"], ["70754.00", "0.527"], ["70761.00", "0.265"], ["70768.00", "0.531"], ["70775.00", "0.571"], ["70789.00", "0.551"], ["71050.50", "48.773"], ["71193.40", "0.000"], ["71193.50", "4.208"], ["71196.80", "0.000"], ["71213.90", "57.290"], ["71427.60", "70.036"], ["74044.80", "0.098"]]}}
{"local_ts": 1773485201519, "server_ts": 1773485200720, "data": {"e": "depthUpdate", "E": 1773485200725, "T": 1773485200720, "s": "BTCUSDT", "U": 10109436588675, "u": 10109436593464, "pu": 10109436588638, "b": [["1000.00", "28.692"], ["5000.00", "101.438"], ["7049.20", "0.028"], ["20191.80", "0.990"], ["20288.50", "0.690"], ["20290.30", "0.010"], ["20291.80", "1.310"], ["33000.00", "3.789"], ["56394.00", "0.000"], ["65454.90", "0.796"], ["65823.60", "0.780"], ["66192.40", "0.780"], ["66561.20", "0.780"], ["66930.00", "0.824"], ["66961.60", "0.000"], ["67298.80", "0.780"], ["67667.60", "0.832"], ["68036.40", "0.855"], ["68111.00", "1.893"], ["68405.10", "1.396"], ["68773.90", "0.780"], ["69142.70", "0.780"], ["69511.50", "0.780"], ["69786.90", "0.000"], ["69880.30", "0.789"], ["70246.20", "0.039"], ["70249.10", "0.781"], ["70444.20", "0.004"], ["70444.30", "0.021"], ["70467.10", "0.052"], ["70468.30", "0.000"], ["70472.60", "0.418"], ["70473.20", "0.785"], ["70481.70", "0.029"], ["70483.00", "0.105"], ["70483.20", "0.044"], ["70485.00", "0.017"], ["70486.20", "0.008"], ["70488.30", "0.063"], ["70490.40", "0.021"]], "a": [["70491.90", "4.508"], ["70493.70", "0.001"], ["70495.10", "0.024"], ["70498.90", "0.375"], ["70499.00", "0.022"], ["70499.10", "0.003"], ["70499.70", "0.019"], ["70499.90", "0.045"], ["70504.20", "0.004"], ["70510.20", "0.007"], ["70511.80", "0.049"], ["70518.20", "0.770"], ["70518.40", "0.017"], ["70520.10", "0.212"], ["70520.20", "0.104"], ["70522.10", "0.005"], ["70522.50", "0.002"], ["70527.10", "0.041"], ["70715.30", "0.007"], ["70986.70", "0.780"], ["71129.80", "0.018"], ["71129.90", "2.105"], ["71196.80", "4.207"], ["71355.40", "0.789"], ["71411.80", "6.573"], ["71443.50", "1.466"], ["71724.20", "0.780"], ["72093.00", "0.780"], ["72461.80", "0.780"], ["72830.60", "1.877"], ["73199.40", "0.780"], ["73568.20", "0.780"], ["73937.00", "0.813"]]}}
{"local_ts": 1773485202538, "server_ts": 1773485201744, "data": {"e": "depthUpdate", "E": 1773485201745, "T": 1773485201744, "s": "BTCUSDT", "U": 10109436626545, "u": 10109436629357, "pu": 10109436626356, "b": [["5000.00", "101.418"], ["7049.20", "0.000"], ["20091.80", "0.550"], ["20191.80", "2.450"], ["20288.50", "0.000"], ["20291.90", "0.000"], ["69363.90", "0.722"], ["69399.30", "0.000"], ["69455.60", "1.309"], ["69786.90", "0.000"], ["70245.50", "0.000"], ["70245.80", "22.886"], ["70305.00", "0.190"], ["70329.70", "0.092"], ["70332.70", "0.714"], ["70343.40", "12.546"], ["70343.50", "0.219"], ["70393.70", "0.000"], ["70393.90", "0.018"], ["70400.80", "0.550"], ["70401.00", "0.076"], ["70401.50", "6.339"], ["70407.80", "0.336"], ["70408.00", "0.235"], ["70436.40", "3.414"], ["70444.10", "0.438"], ["70444.30", "0.023"], ["70457.60", "1.788"], ["70458.90", "0.192"], ["70465.80", "0.056"], ["70482.00", "0.078"], ["70482.20", "0.020"], ["70482.30", "0.112"], ["70482.40", "0.015"], ["70482.60", "0.460"], ["70491.00", "0.021"]], "a": [["70491.90", "4.848"], ["70493.50", "0.004"], ["70495.00", "0.088"], ["70498.90", "0.212"], ["70530.10", "1.806"], ["70551.30", "3.427"], ["70570.20", "0.073"], ["70577.20", "0.071"], ["70584.30", "0.075"], ["70584.50", "1.449"], ["70586.40", "6.398"], ["70644.90", "11.962"], ["71196.80", "4.207"], ["71270.90", "1.406"], ["71443.50", "2.862"], ["71552.80", "1.162"], ["71558.50", "0.000"], ["72118.50", "0.000"], ["72261.40", "2.487"], ["74027.00", "0.500"]]}}
{"local_ts": 1773485203560, "server_ts": 1773485202766, "data": {"e": "depthUpdate", "E": 1773485202767, "T": 1773485202766, "s": "BTCUSDT", "U": 10109436668075, "u": 10109436672516, "pu": 10109436667987, "b": [["1000.00", "28.692"], ["5000.00", "101.418"], ["7049.20", "0.000"], ["19991.80", "0.270"], ["20091.80", "2.560"], ["20191.80", "0.170"], ["66950.80", "0.002"], ["66964.20", "0.004"], ["66966.20", "0.000"], ["66967.20", "0.008"], ["69786.90", "0.000"], ["70139.30", "0.000"], ["70308.50", "0.511"], ["70333.20", "0.219"], ["70360.10", "0.538"], ["70444.10", "0.438"], ["70444.20", "0.004"], ["70458.90", "0.093"], ["70459.00", "0.243"], ["70469.00", "0.559"], ["70470.80", "0.087"], ["70471.20", "0.353"], ["70471.50", "0.007"], ["70472.00", "0.072"], ["70472.30", "0.001"], ["70476.90", "0.011"], ["70477.70", "0.005"], ["70480.10", "0.007"], ["70480.50", "0.008"], ["70481.50", "0.304"], ["70481.60", "0.221"], ["70481.70", "0.076"], ["70481.90", "0.557"], ["70482.00", "0.066"], ["70482.10", "0.002"], ["70482.30", "0.097"], ["70482.40", "0.000"], ["70491.80", "9.471"]], "a": [["70491.90", "4.710"], ["70498.90", "0.210"], ["70499.70", "0.019"], ["70500.10", "0.002"], ["70501.20", "0.002"], ["70504.30", "0.392"], ["70506.60", "0.142"], ["70507.90", "0.002"], ["70515.80", "0.012"], ["70516.60", "0.730"], ["70517.10", "0.058"], ["70517.90", "0.000"], ["70519.80", "0.070"], ["70522.30", "0.004"], ["70625.20", "0.300"], ["70625.30", "0.024"], ["70715.20", "0.000"], ["71196.70", "0.000"], ["71196.80", "4.207"], ["71270.90", "0.006"]]}}
{"local_ts": 1773485204587, "server_ts": 1773485203784, "data": {"e": "depthUpdate", "E": 1773485203787, "T": 1773485203784, "s": "BTCUSDT", "U": 10109436710494, "u": 10109436714523, "pu": 10109436710392, "b": [["1000.00", "28.692"], ["5000.00", "101.418"], ["7049.20", "0.000"], ["19991.80", "2.410"], ["20091.80", "0.470"], ["20391.80", "0.120"], ["69313.50", "0.000"], ["69434.50", "0.000"], ["69539.40", "1.436"], ["69786.90", "0.000"], ["70245.30", "0.000"], ["70245.60", "0.004"], ["70276.90", "0.040"], ["70333.20", "0.180"], ["70360.10", "0.000"], ["70444.40", "0.312"], ["70444.50", "0.232"], ["70459.00", "0.059"], ["70469.10", "0.000"], ["70470.80", "0.087"], ["70481.80", "0.212"], ["70481.90", "0.619"], ["70491.00", "0.000"], ["70491.80", "10.033"]], "a": [["70499.40", "0.514"], ["70500.70", "0.009"], ["70504.30", "0.305"], ["70504.40", "0.097"], ["70517.70", "0.589"], ["70519.70", "0.070"], ["70519.80", "0.000"], ["70521.70", "0.007"], ["70521.90", "0.018"], ["70523.00", "0.281"], ["70527.10", "0.041"], ["70527.20", "0.043"], ["70625.10", "0.184"], ["70675.20", "0.064"], ["71196.80", "5.616"], ["71405.70", "0.000"], ["71409.10", "1.399"], ["71729.10", "3.620"], ["74031.20", "0.006"], ["74051.00", "0.054"]]}}
{"local_ts": 1773485205603, "server_ts": 1773485204808, "data": {"e": "depthUpdate", "E": 1773485204809, "T": 1773485204808, "s": "BTCUSDT", "U": 10109436746997, "u": 10109436751217, "pu": 10109436746914, "b": [["5000.00", "101.418"], ["7049.20", "0.056"], ["19991.80", "0.790"], ["20391.80", "2.210"], ["56394.00", "0.000"], ["66936.70", "0.002"], ["69208.80", "0.577"], ["69502.80", "0.000"], ["69784.80", "0.000"], ["69821.20", "1.269"], ["70458.10", "0.018"], ["70462.30", "0.082"], ["70462.60", "0.042"], ["70462.70", "0.797"], ["70465.80", "0.123"], ["70466.90", "0.347"], ["70467.10", "0.015"], ["70471.40", "0.021"], ["70471.60", "0.510"], ["70472.80", "0.001"], ["70477.90", "0.397"], ["70479.50", "0.107"], ["70479.90", "0.068"], ["70481.40", "0.007"], ["70482.00", "0.005"], ["70482.10", "0.064"], ["70484.90", "0.006"], ["70486.10", "0.135"], ["70491.80", "7.050"]], "a": [["70491.90", "5.933"], ["70495.80", "0.009"], ["70498.90", "0.357"], ["70499.00", "0.022"], ["70499.30", "0.008"], ["70499.40", "0.514"], ["70499.90", "0.627"], ["70501.30", "0.006"], ["70505.60", "0.143"], ["70505.80", "0.344"], ["70506.60", "0.001"], ["70507.10", "0.010"], ["70507.80", "1.159"], ["70515.40", "0.673"], ["70516.10", "0.526"], ["70517.00", "0.000"], ["70517.70", "0.002"], ["70518.00", "0.131"], ["70519.70", "0.000"], ["70527.10", "0.083"], ["70527.20", "0.001"], ["70549.80", "0.262"], ["70731.40", "0.009"], ["71196.70", "0.000"], ["71196.80", "5.616"], ["71376.20", "0.266"], ["71408.30", "11.187"], ["71514.00", "2.513"], ["74034.80", "0.000"]]}}
{"local_ts": 1773485206625, "server_ts": 1773485205830, "data": {"e": "depthUpdate", "E": 1773485205831, "T": 1773485205830, "s": "BTCUSDT", "U": 10109436785176, "u": 10109436788744, "pu": 10109436785155, "b": [["1000.00", "28.692"], ["5000.00", "101.418"], ["7049.20", "0.056"], ["20291.80", "1.760"], ["20391.80", "1.240"], ["63442.60", "0.004"], ["66944.90", "0.002"], ["66953.90", "0.003"], ["69497.90", "0.505"], ["69573.10", "3.016"], ["69786.90", "2.154"], ["69855.10", "2.146"], ["70356.60", "0.000"], ["70357.60", "7.658"], ["70444.30", "0.021"], ["70444.40", "0.314"], ["70484.70", "0.059"], ["70484.90", "0.006"], ["70491.80", "7.073"]], "a": [["70491.90", "5.838"], ["70493.40", "0.002"], ["70499.00", "0.022"], ["70623.50", "0.002"], ["70623.60", "8.937"], ["71196.80", "5.616"], ["71247.80", "0.005"], ["71768.80", "0.000"], ["77541.10", "0.002"]]}}
{"local_ts": 1773485207647, "server_ts": 1773485206850, "data": {"e": "depthUpdate", "E": 1773485206851, "T": 1773485206850, "s": "BTCUSDT", "U": 10109436823889, "u": 10109436826758, "pu": 10109436823863, "b": [["5000.00", "101.418"], ["7049.20", "0.056"], ["20191.80", "1.310"], ["20291.80", "1.690"], ["63442.60", "0.004"], ["66958.00", "0.002"], ["66959.50", "0.000"], ["69419.80", "1.295"], ["69786.90", "4.300"], ["70444.30", "0.023"], ["70444.40", "0.312"], ["70472.60", "0.858"], ["70473.30", "0.361"], ["70484.90", "0.006"]], "a": [["70491.90", "5.838"], ["70493.60", "0.000"], ["70499.00", "0.022"], ["70499.40", "0.000"], ["71052.50", "0.986"], ["71196.80", "6.037"], ["77541.10", "0.002"]]}}
{"local_ts": 1773485208663, "server_ts": 1773485207868, "data": {"e": "depthUpdate", "E": 1773485207871, "T": 1773485207868, "s": "BTCUSDT", "U": 10109436856153, "u": 10109436858855, "pu": 10109436856129, "b": [["1000.00", "28.692"], ["5000.00", "101.418"], ["7049.20", "0.028"], ["20091.80", "0.860"], ["20191.80", "2.140"], ["33000.00", "3.785"], ["56394.00", "0.000"], ["63442.60", "0.004"], ["66964.10", "0.003"], ["66967.00", "0.150"], ["69649.00", "0.000"], ["69786.90", "4.300"], ["70139.30", "0.142"], ["70319.70", "0.000"], ["70320.00", "4.310"], ["70358.70", "0.000"], ["70358.80", "0.453"], ["70444.10", "0.438"], ["70444.20", "0.004"], ["70481.90", "0.734"], ["70482.20", "0.105"], ["70484.90", "0.006"]], "a": [["70491.90", "5.832"], ["70498.80", "0.015"], ["70499.00", "0.022"], ["70499.40", "0.000"], ["70624.20", "0.448"], ["70663.00", "2.239"], ["70675.20", "0.064"], ["71196.80", "6.037"], ["72450.00", "11.354"], ["74046.00", "1.449"], ["77541.10", "0.002"], ["89523.20", "0.024"]]}}
{"local_ts": 1773485209684, "server_ts": 1773485208892, "data": {"e": "depthUpdate", "E": 1773485208893, "T": 1773485208892, "s": "BTCUSDT", "U": 10109436903578, "u": 10109436909684, "pu": 10109436903461, "b": [["1000.00", "28.692"], ["5000.00", "101.418"], ["7049.20", "0.028"], ["19991.80", "0.430"], ["20091.80", "2.550"], ["20191.80", "0.020"], ["63442.60", "0.012"], ["69082.00", "0.017"], ["69786.90", "4.302"], ["70308.50", "0.670"], ["70312.00", "0.178"], ["70333.20", "0.219"], ["70334.80", "0.021"], ["70342.20", "0.000"], ["70346.80", "0.028"], ["70354.00", "0.000"], ["70360.60", "0.002"], ["70375.90", "0.006"], ["70386.10", "0.001"], ["70386.40", "0.511"], ["70393.60", "0.114"], ["70398.30", "0.108"], ["70401.00", "0.005"], ["70405.50", "0.303"], ["70409.40", "0.903"], ["70413.70", "0.344"], ["70417.40", "0.003"], ["70420.30", "0.511"], ["70421.30", "0.096"], ["70423.20", "0.000"], ["70425.10", "0.213"], ["70436.30", "0.007"], ["70444.00", "0.485"], ["70444.10", "0.438"], ["70444.90", "8.583"], ["70447.20", "0.003"], ["70447.50", "1.895"], ["70457.60", "0.009"], ["70460.10", "0.197"], ["70461.40", "0.002"], ["70461.60", "0.117"], ["70467.80", "0.253"], ["70468.90", "0.063"], ["70469.10", "0.000"], ["70469.70", "0.000"], ["70470.20", "0.002"], ["70470.30", "0.005"], ["70470.70", "0.421"], ["70471.50", "0.141"], ["70472.10", "0.015"], ["70472.30", "0.071"], ["70473.30", "0.361"], ["70473.50", "0.090"], ["70474.20", "0.018"], ["70474.40", "0.038"], ["70475.20", "0.353"], ["70475.30", "0.538"], ["70475.50", "1.208"], ["70476.00", "0.015"], ["70476.10", "0.008"], ["70476.90", "0.004"], ["70477.80", "0.011"], ["70478.60", "0.231"], ["70479.10", "0.011"], ["70479.80", "0.006"], ["70480.50", "0.011"], ["70480.90", "0.000"], ["70481.80", "0.212"], ["70482.70", "0.642"], ["70483.60", "0.004"], ["70484.60", "0.003"], ["70484.70", "0.002"], ["70485.40", "0.003"], ["70486.90", "0.066"], ["70487.70", "0.121"], ["70488.20", "0.198"], ["70488.50", "0.108"], ["70488.80", "0.000"], ["70491.40", "0.002"], ["70491.80", "8.166"]], "a": [["70491.90", "3.049"], ["70495.60", "0.011"], ["70496.10", "0.021"], ["70497.00", "0.067"], ["70497.20", "0.000"], ["70497.40", "0.009"], ["70498.10", "0.021"], ["70499.80", "0.237"], ["70499.90", "0.534"], ["70500.00", "0.260"], ["70500.20", "0.675"], ["70500.30", "0.000"], ["70502.90", "0.006"], ["70504.00", "0.257"], ["70504.10", "0.004"], ["70504.20", "0.115"], ["70506.00", "0.229"], ["70506.90", "0.002"], ["70507.00", "0.208"], ["70507.10", "0.095"], ["70507.30", "0.141"], ["70507.50", "0.110"], ["70507.80", "1.147"], ["70507.90", "0.022"], ["70508.30", "0.516"], ["70508.50", "0.004"], ["70511.30", "1.069"], ["70513.70", "0.000"], ["70515.20", "0.008"], ["70515.30", "0.014"], ["70515.40", "0.040"], ["70515.90", "0.024"], ["70516.00", "0.000"], ["70516.30", "0.002"], ["70516.60", "0.004"], ["70517.30", "0.004"], ["70517.40", "0.006"], ["70517.70", "0.007"], ["70518.00", "0.068"], ["70518.10", "0.060"], ["70518.90", "0.011"], ["70519.80", "0.637"], ["70519.90", "0.003"], ["70520.10", "0.142"], ["70520.20", "0.614"], ["70520.50", "0.070"], ["70520.60", "0.006"], ["70521.50", "0.876"], ["70522.30", "0.004"], ["70522.50", "0.070"], ["70523.50", "0.254"], ["70523.80", "0.005"], ["70524.70", "0.000"], ["70525.10", "0.928"], ["70525.90", "0.031"], ["70527.40", "0.042"], ["70528.70", "0.842"], ["70541.50", "0.002"], ["70548.30", "0.262"], ["70549.30", "0.072"], ["70556.70", "0.235"], ["70556.80", "0.038"], ["70556.90", "8.886"], ["70560.40", "1.719"], ["70562.30", "0.006"], ["70562.40", "0.000"], ["70563.30", "0.002"], ["70585.00", "0.009"], ["70590.00", "0.094"], ["70644.00", "2.769"], ["70644.30", "0.089"], ["71196.80", "6.039"], ["71564.90", "0.422"], ["74043.40", "0.002"], ["77541.10", "0.010"], ["89523.20", "0.024"]]}}
{"local_ts": 1773485210708, "server_ts": 1773485209912, "data": {"e": "depthUpdate", "E": 1773485209913, "T": 1773485209912, "s": "BTCUSDT", "U": 10109436943736, "u": 10109436946908, "pu": 10109436943700, "b": [["5000.00", "101.418"], ["7049.20", "0.028"], ["19991.80", "2.510"], ["20091.80", "0.260"], ["20391.80", "0.230"], ["33000.00", "3.789"], ["63442.60", "0.012"], ["66936.80", "0.040"], ["68714.40", "2.615"], ["69192.30", "0.000"], ["69434.40", "7.699"], ["69786.90", "4.300"], ["70308.50", "0.670"], ["70348.30", "0.078"], ["70355.50", "0.079"], ["70362.10", "0.078"], ["70377.60", "0.078"], ["70387.80", "0.126"], ["70394.00", "0.039"], ["70398.70", "2.182"], ["70399.00", "0.020"], ["70405.40", "0.180"], ["70406.10", "0.656"], ["70409.40", "1.001"], ["70413.10", "0.112"], ["70413.70", "0.383"], ["70417.50", "0.041"], ["70420.40", "0.088"], ["70423.30", "1.117"], ["70425.10", "0.249"], ["70444.00", "1.602"], ["70444.10", "0.438"], ["70472.80", "0.008"], ["70473.60", "0.002"], ["70476.90", "0.011"], ["70477.80", "0.163"]], "a": [["70491.90", "3.172"], ["70499.30", "0.010"], ["70499.50", "0.656"], ["70499.60", "0.000"], ["70499.70", "0.009"], ["70499.80", "0.000"], ["70503.90", "0.002"], ["70511.10", "0.387"], ["70511.40", "0.038"], ["70511.50", "0.005"], ["70516.10", "0.012"], ["70517.00", "1.073"], ["70517.70", "0.638"], ["70518.90", "0.004"], ["70550.00", "36.949"], ["70556.80", "2.019"], ["70575.30", "0.171"], ["70575.40", "0.000"], ["70582.30", "0.078"], ["70582.40", "0.000"], ["70589.40", "0.071"], ["70589.50", "0.002"], ["70647.80", "3.416"], ["70715.30", "0.000"], ["70819.70", "0.000"], ["71196.60", "0.149"], ["71196.80", "6.037"], ["71426.10", "69.698"], ["71492.90", "1.252"], ["71514.00", "4.469"], ["71582.20", "0.987"], ["77541.10", "0.010"], ["89523.20", "0.024"]]}}
{"local_ts": 1773485212770, "server_ts": 1773485210424, "data": {"e": "depthUpdate", "E": 1773485210425, "T": 1773485210424, "s": "BTCUSDT", "U": 10109436961268, "u": 10109436964826, "pu": 10109436961222, "b": [["5000.00", "101.418"], ["7049.20", "0.056"], ["19991.80", "1.750"], ["20391.80", "1.250"], ["66967.20", "0.009"], ["66967.30", "0.006"], ["69786.90", "4.300"], ["69787.00", "0.033"], ["69857.40", "10.721"], ["70139.40", "0.000"], ["70398.20", "0.000"], ["70425.00", "0.854"], ["70425.80", "0.094"], ["70469.40", "0.001"], ["70471.30", "1.071"], ["70478.60", "0.000"], ["70479.40", "0.092"], ["70489.20", "0.057"], ["70491.20", "0.021"]], "a": [["70493.90", "0.000"], ["70499.00", "0.109"], ["70500.00", "0.260"], ["70500.10", "0.000"], ["70500.20", "0.021"], ["70500.60", "0.278"], ["70501.60", "0.009"], ["70503.60", "0.169"], ["70503.80", "0.655"], ["70503.90", "0.002"], ["70528.40", "0.771"], ["70530.40", "0.123"], ["70555.20", "0.086"], ["70557.20", "0.129"], ["70675.20", "0.163"], ["70812.60", "5.157"], ["71196.80", "6.037"], ["74046.10", "0.002"]]}}
{"local_ts": 1773485213772, "server_ts": 1773485212980, "data": {"e": "depthUpdate", "E": 1773485212981, "T": 1773485212980, "s": "BTCUSDT", "U": 10109437059415, "u": 10109437062438, "pu": 10109437059357, "b": [["1000.00", "28.692"], ["5000.00", "101.398"], ["7049.20", "0.000"], ["20191.80", "1.640"], ["20291.80", "1.360"], ["56394.00", "0.000"], ["63442.60", "0.010"], ["66941.50", "0.000"], ["66960.50", "0.002"], ["66967.20", "0.006"], ["67672.20", "0.024"], ["69628.20", "2.866"], ["70139.30", "0.142"], ["70333.20", "0.180"], ["70360.10", "0.593"], ["70398.70", "2.200"], ["70398.80", "0.209"], ["70405.80", "0.071"], ["70405.90", "0.072"], ["70412.80", "1.025"], ["70412.90", "0.000"]], "a": [["70493.50", "0.082"], ["70496.20", "0.025"], ["70498.10", "0.033"], ["70498.80", "0.005"], ["70499.20", "0.659"], ["70499.30", "0.008"], ["70499.40", "0.000"], ["70499.50", "0.002"], ["70503.90", "0.002"], ["70525.70", "0.117"], ["70534.00", "0.000"], ["70575.10", "0.073"], ["70582.10", "0.990"], ["70589.20", "0.087"], ["70624.10", "0.552"], ["70675.20", "0.163"], ["71196.80", "6.037"], ["72621.60", "3.299"], ["77541.10", "0.008"], ["89523.20", "0.024"]]}}
{"local_ts": 1773485214792, "server_ts": 1773485214000, "data": {"e": "depthUpdate", "E": 1773485214001, "T": 1773485214000, "s": "BTCUSDT", "U": 10109437121272, "u": 10109437124937, "pu": 10109437121262, "b": [["5000.00", "101.418"], ["7049.20", "0.000"], ["20091.80", "1.190"], ["20191.80", "1.810"], ["63442.60", "0.018"], ["66957.00", "0.023"], ["68377.10", "0.003"], ["69082.00", "0.008"], ["69363.90", "2.449"], ["69399.20", "4.028"], ["69469.70", "5.605"], ["69786.90", "4.300"], ["69787.00", "0.029"], ["70170.20", "0.003"], ["70245.90", "0.004"], ["70333.20", "0.219"], ["70360.10", "0.000"], ["70444.10", "0.438"], ["70444.30", "0.023"], ["70467.30", "0.004"], ["70470.50", "0.070"], ["70471.50", "0.000"], ["70471.60", "0.070"], ["70472.90", "0.000"], ["70480.60", "0.638"], ["70481.40", "0.007"], ["70481.80", "0.606"], ["70482.50", "0.103"], ["70491.80", "6.987"]], "a": [["70491.90", "4.454"], ["70496.20", "0.002"], ["70499.10", "0.013"], ["70499.90", "0.030"], ["70502.50", "0.009"], ["70516.90", "0.510"], ["70517.70", "0.064"], ["70518.80", "0.004"], ["70518.90", "0.074"], ["70521.30", "0.002"], ["70624.10", "0.043"], ["71196.80", "6.037"], ["71810.10", "0.558"], ["71901.70", "0.018"], ["77541.10", "0.016"], ["89523.20", "0.024"]]}}
{"local_ts": 1773485215816, "server_ts": 1773485215022, "data": {"e": "depthUpdate", "E": 1773485215023, "T": 1773485215022, "s": "BTCUSDT", "U": 10109437162413, "u": 10109437166205, "pu": 10109437162343, "b": [["1000.00", "28.692"], ["5000.00", "101.418"], ["7049.20", "0.056"], ["19991.80", "0.740"], ["20091.80", "2.260"], ["33000.00", "3.785"], ["56393.00", "0.000"], ["63442.60", "0.018"], ["66939.20", "0.002"], ["68377.10", "0.003"], ["68714.50", "2.619"], ["68800.00", "41.666"], ["69281.80", "0.002"], ["69352.20", "0.000"], ["69786.90", "4.300"], ["70308.50", "0.670"], ["70321.30", "0.020"], ["70332.70", "0.714"], ["70341.60", "0.112"], ["70360.10", "0.000"], ["70398.60", "0.000"], ["70405.70", "0.021"], ["70412.70", "0.299"], ["70436.50", "1.162"], ["70439.10", "0.932"], ["70442.70", "0.003"], ["70446.20", "0.846"], ["70450.10", "0.004"], ["70453.30", "0.908"], ["70460.40", "1.352"], ["70467.50", "0.928"]], "a": [["70491.90", "1.983"], ["70497.10", "0.009"], ["70498.30", "0.104"], ["70508.80", "0.002"], ["70508.90", "0.087"], ["70510.10", "0.840"], ["70517.20", "0.855"], ["70524.30", "0.844"], ["70525.70", "0.117"], ["70527.60", "0.109"], ["70531.40", "0.847"], ["70534.00", "0.000"], ["70538.50", "0.992"], ["70575.00", "0.256"], ["70582.00", "0.005"], ["70589.10", "0.002"], ["70624.10", "0.043"], ["70662.80", "0.000"], ["70675.20", "0.064"], ["71196.80", "6.037"], ["71473.50", "0.909"], ["72606.60", "0.012"], ["74022.50", "0.027"], ["77541.10", "0.016"], ["89523.20", "0.024"]]}}
{"local_ts": 1773485219697, "server_ts": 1773485218900, "data": {"e": "depthUpdate", "E": 1773485218903, "T": 1773485218900, "s": "BTCUSDT", "U": 10109437303898, "u": 10109437309003, "pu": 10109437303878, "b": [["5000.00", "101.418"], ["7049.20", "0.028"], ["20191.80", "1.440"], ["20291.80", "1.560"], ["56393.00", "0.000"], ["63442.60", "0.020"], ["66938.90", "0.000"], ["66967.20", "0.008"], ["66967.30", "0.004"], ["69507.10", "0.000"], ["69786.90", "4.300"], ["70117.60", "0.300"], ["70473.80", "0.516"], ["70484.80", "0.124"]], "a": [["70491.90", "2.962"], ["70494.20", "0.021"], ["70494.90", "0.066"], ["70498.30", "0.104"], ["70498.90", "0.037"], ["71196.80", "6.037"], ["71469.90", "1.536"], ["74033.70", "0.002"], ["77541.10", "0.018"]]}}
{"local_ts": 1773485220716, "server_ts": 1773485219922, "data": {"e": "depthUpdate", "E": 1773485219923, "T": 1773485219922, "s": "BTCUSDT", "U": 10109437341786, "u": 10109437344556, "pu": 10109437341756, "b": [["1000.00", "28.692"], ["5000.00", "101.398"], ["7049.20", "0.028"], ["20091.80", "0.990"], ["20191.80", "2.010"], ["33000.00", "3.785"], ["56393.00", "0.004"], ["63442.60", "0.020"], ["69786.90", "5.731"], ["69787.00", "0.029"], ["70129.50", "0.435"], ["70139.30", "0.426"], ["70139.40", "0.000"], ["70246.00", "0.004"], ["70312.00", "0.178"], ["70360.10", "0.683"], ["70484.80", "0.124"]], "a": [["70491.90", "3.164"], ["70494.90", "0.030"], ["70498.90", "0.037"], ["70499.10", "0.013"], ["70499.90", "0.030"], ["70506.00", "0.406"], ["70506.90", "0.002"], ["70510.10", "0.002"], ["70513.90", "0.013"], ["70515.90", "0.005"], ["70525.70", "0.117"], ["70534.00", "0.000"], ["70544.80", "0.018"], ["70624.00", "0.709"], ["70799.90", "0.000"], ["71196.70", "0.007"], ["71196.80", "6.037"], ["71337.80", "5.037"], ["71690.30", "4.583"], ["74031.60", "0.002"], ["74033.70", "0.000"], ["77541.10", "0.018"]]}}
{"local_ts": 1773485221742, "server_ts": 1773485220948, "data": {"e": "depthUpdate", "E": 1773485220949, "T": 1773485220948, "s": "BTCUSDT", "U": 10109437395673, "u": 10109437400949, "pu": 10109437395539, "b": [["5000.00", "101.418"], ["7049.20", "0.000"], ["19991.80", "0.560"], ["20091.80", "2.440"], ["20191.80", "0.000"], ["63442.60", "0.018"], ["66951.00", "0.004"], ["69082.00", "0.014"], ["69449.70", "3.091"], ["69786.90", "6.447"], ["70444.00", "1.627"], ["70444.10", "0.440"], ["70456.60", "0.586"], ["70471.60", "0.092"], ["70483.00", "0.010"], ["70483.40", "0.035"], ["70491.00", "0.000"], ["70491.10", "0.000"], ["70491.20", "0.000"], ["70491.80", "7.961"]], "a": [["70491.90", "3.182"], ["70492.40", "0.000"], ["70492.50", "0.000"], ["70492.80", "0.015"], ["70493.60", "0.000"], ["70494.30", "0.019"], ["70497.30", "0.071"], ["70497.50", "0.028"], ["70499.80", "0.514"], ["70510.10", "0.000"], ["70513.70", "0.007"], ["70515.90", "0.005"], ["70517.80", "1.147"], ["70675.20", "0.163"], ["70808.90", "0.000"], ["70832.20", "0.423"], ["70844.40", "3.334"], ["71196.70", "0.007"], ["71196.80", "6.738"], ["71572.00", "0.008"], ["77541.10", "0.016"]]}}
{"local_ts": 1773485222762, "server_ts": 1773485221968, "data": {"e": "depthUpdate", "E": 1773485221969, "T": 1773485221968, "s": "BTCUSDT", "U": 10109437450492, "u": 10109437456081, "pu": 10109437450411, "b": [["1000.00", "28.692"], ["5000.00", "101.418"], ["7049.20", "0.000"], ["19991.80", "2.550"], ["20091.80", "0.170"], ["20391.80", "0.280"], ["33000.00", "3.789"], ["56394.00", "0.000"], ["63442.60", "0.018"], ["69786.90", "6.447"], ["70139.30", "5.010"], ["70443.60", "0.002"], ["70443.70", "0.036"]], "a": [["70491.90", "3.879"], ["70493.00", "0.001"], ["70494.90", "0.066"], ["70500.60", "0.200"], ["70502.00", "0.344"], ["70506.00", "0.088"], ["70511.80", "0.049"], ["70513.70", "0.005"], ["70524.50", "0.004"], ["71146.10", "0.000"], ["71196.80", "6.738"], ["71508.80", "6.447"], ["71649.70", "0.000"], ["74048.10", "0.000"], ["77541.10", "0.016"]]}}
{"local_ts": 1773485223784, "server_ts": 1773485222988, "data": {"e": "depthUpdate", "E": 1773485222991, "T": 1773485222988, "s": "BTCUSDT", "U": 10109437494926, "u": 10109437498597, "pu": 10109437494823, "b": [["1000.00", "28.692"], ["5000.00", "101.418"], ["7049.20", "0.000"], ["19991.80", "0.470"], ["20291.80", "0.130"], ["20391.80", "2.400"], ["56394.00", "0.000"], ["63442.60", "0.018"], ["66933.10", "0.002"], ["68710.50", "0.000"], ["69082.00", "0.017"], ["69392.10", "0.647"], ["69786.90", "6.447"], ["70360.10", "0.000"], ["70443.80", "0.062"], ["70444.00", "1.629"], ["70462.60", "0.114"], ["70463.20", "0.042"], ["70483.00", "0.010"], ["70483.20", "0.002"], ["70484.60", "0.003"], ["70485.70", "0.000"]], "a": [["70495.00", "0.066"], ["70508.90", "0.004"], ["70511.80", "0.047"], ["70527.10", "0.384"], ["70537.20", "0.201"], ["70624.00", "0.186"], ["74045.80", "0.000"], ["77541.10", "0.016"]]}}
{"local_ts": 1773485224806, "server_ts": 1773485224011, "data": {"e": "depthUpdate", "E": 1773485224013, "T": 1773485224011, "s": "BTCUSDT", "U": 10109437547518, "u": 10109437554765, "pu": 10109437547516, "b": [["5000.00", "101.418"], ["7049.20", "0.056"], ["20291.80", "2.210"], ["20391.80", "0.790"], ["63442.60", "0.018"], ["69082.00", "0.011"], ["69382.90", "0.617"], ["69667.00", "1.147"], ["69786.90", "7.520"], ["70100.00", "48.775"], ["70344.70", "0.335"], ["70352.80", "0.131"], ["70360.50", "2.283"], ["70376.10", "0.552"], ["70386.20", "0.400"], ["70441.80", "0.005"], ["70443.50", "0.361"], ["70443.60", "0.002"], ["70444.40", "8.827"], ["70444.90", "0.000"], ["70455.60", "0.002"], ["70455.70", "0.007"], ["70456.30", "0.222"], ["70456.40", "0.195"], ["70458.90", "0.161"], ["70462.20", "0.007"], ["70464.00", "0.008"], ["70467.80", "0.003"], ["70469.10", "0.248"], ["70469.70", "0.114"], ["70470.20", "0.072"], ["70472.80", "0.008"], ["70476.00", "0.015"], ["70476.40", "0.510"], ["70477.50", "1.279"], ["70481.20", "0.060"], ["70481.40", "0.067"], ["70482.20", "0.001"], ["70482.40", "0.220"], ["70482.60", "0.458"], ["70482.80", "0.069"], ["70484.30", "0.515"], ["70485.30", "0.016"], ["70485.50", "0.056"], ["70485.90", "0.015"], ["70486.00", "0.090"], ["70486.60", "0.074"], ["70487.70", "0.133"], ["70488.70", "0.370"], ["70489.80", "0.000"], ["70490.20", "0.010"], ["70490.50", "0.000"], ["70491.70", "0.025"], ["70491.80", "8.349"]], "a": [["70491.90", "1.235"], ["70493.30", "0.001"], ["70494.30", "0.025"], ["70494.60", "0.000"], ["70494.90", "0.005"], ["70496.60", "0.000"], ["70497.60", "0.001"], ["70497.80", "0.018"], ["70497.90", "0.003"], ["70498.20", "0.000"], ["70499.20", "0.002"], ["70499.60", "0.000"], ["70499.80", "0.002"], ["70499.90", "0.534"], ["70500.30", "0.000"], ["70500.40", "0.245"], ["70501.20", "0.014"], ["70502.60", "0.088"], ["70503.60", "0.036"], ["70504.00", "0.204"], ["70504.80", "0.010"], ["70505.40", "0.015"], ["70505.60", "0.004"], ["70506.60", "0.001"], ["70506.70", "0.015"], ["70507.50", "0.750"], ["70507.60", "0.346"], ["70507.90", "0.017"], ["70508.30", "0.005"], ["70508.50", "0.084"], ["70508.90", "0.002"], ["70509.50", "0.110"], ["70509.60", "0.145"], ["70509.70", "0.003"], ["70511.50", "0.026"], ["70511.80", "0.002"], ["70513.40", "0.045"], ["70514.80", "0.591"], ["70514.90", "0.006"], ["70515.10", "0.008"], ["70515.90", "0.003"], ["70516.00", "0.000"], ["70516.40", "0.005"], ["70516.60", "0.006"], ["70516.70", "0.216"], ["70517.00", "0.000"], ["70517.30", "0.009"], ["70517.50", "0.047"], ["70518.00", "0.068"], ["70518.10", "0.060"], ["70518.50", "0.641"], ["70518.70", "0.005"], ["70518.80", "0.517"], ["70518.90", "0.004"], ["70519.50", "0.000"], ["70519.80", "0.000"], ["70520.10", "0.142"], ["70520.50", "0.510"], ["70523.80", "0.005"], ["70526.20", "0.080"], ["70527.10", "0.344"], ["70527.80", "0.108"], ["70528.80", "0.364"], ["70544.80", "0.117"], ["70548.30", "0.461"], ["70844.40", "4.144"], ["71193.50", "0.701"], ["71196.80", "6.738"], ["71510.70", "16.201"], ["71581.20", "7.186"], ["74042.60", "0.002"], ["77541.10", "0.016"]]}}
{"local_ts": 1773485225826, "server_ts": 1773485225033, "data": {"e": "depthUpdate", "E": 1773485225035, "T": 1773485225033, "s": "BTCUSDT", "U": 10109437603609, "u": 10109437609463, "pu": 10109437603588, "b": [["1000.00", "28.692"], ["5000.00", "101.398"], ["7049.20", "0.056"], ["20191.80", "1.770"], ["20291.80", "1.230"], ["56393.00", "0.000"], ["63442.60", "0.018"], ["68377.10", "0.003"], ["69281.80", "0.002"], ["69352.20", "0.000"], ["69473.50", "1.299"], ["69521.20", "1.751"], ["69575.40", "14.131"], ["69786.90", "10.382"], ["70068.70", "38.575"], ["70139.30", "5.046"], ["70173.90", "32.060"], ["70251.20", "27.853"], ["70443.70", "0.034"], ["70443.80", "0.064"], ["70454.40", "0.405"], ["70467.90", "0.000"], ["70469.10", "0.248"], ["70469.70", "0.114"], ["70479.10", "0.015"], ["70482.10", "0.000"], ["70483.60", "0.680"], ["70490.50", "0.002"], ["70491.80", "8.346"]], "a": [["70491.90", "1.222"], ["70494.30", "0.028"], ["70495.20", "0.020"], ["70495.40", "0.007"], ["70497.60", "0.016"], ["70497.80", "0.005"], ["70499.90", "0.020"], ["70501.50", "0.030"], ["70501.80", "0.002"], ["70504.30", "0.000"], ["70504.50", "0.005"], ["70505.50", "0.028"], ["70507.50", "0.750"], ["70518.10", "0.060"], ["70518.20", "0.260"], ["70518.90", "0.642"], ["70519.60", "0.510"], ["70523.00", "0.033"], ["70524.80", "0.252"], ["70738.90", "24.946"], ["70816.70", "30.802"], ["70922.90", "35.575"], ["71196.80", "6.738"], ["71514.00", "16.197"], ["73311.50", "0.610"], ["74030.80", "0.036"], ["77541.10", "0.016"]]}}
{"local_ts": 1773485226849, "server_ts": 1773485226053, "data": {"e": "depthUpdate", "E": 1773485226055, "T": 1773485226053, "s": "BTCUSDT", "U": 10109437661668, "u": 10109437666052, "pu": 10109437661598, "b": [["5000.00", "101.398"], ["7049.20", "0.056"], ["20091.80", "1.320"], ["20191.80", "1.680"], ["66967.10", "0.004"], ["69449.70", "1.726"], ["69786.90", "10.382"], ["70251.40", "0.007"], ["70284.30", "0.002"], ["70284.40", "0.286"], ["70321.40", "3.774"], ["70360.20", "0.695"], ["70444.00", "1.591"], ["70444.10", "0.438"], ["70479.10", "0.011"], ["70486.40", "0.066"], ["70488.40", "0.001"], ["70491.80", "8.337"]], "a": [["70496.80", "0.006"], ["70504.60", "0.005"], ["70523.00", "0.281"], ["70524.70", "0.000"], ["70527.10", "0.165"], ["70548.30", "0.223"], ["70584.80", "0.002"], ["70625.00", "1.168"], ["70662.70", "0.015"], ["70663.80", "3.140"], ["70699.80", "0.694"], ["70700.80", "0.530"], ["71196.80", "9.542"], ["74020.80", "0.002"], ["74042.60", "0.000"]]}}
{"local_ts": 1773485227870, "server_ts": 1773485227076, "data": {"e": "depthUpdate", "E": 1773485227077, "T": 1773485227076, "s": "BTCUSDT", "U": 10109437711191, "u": 10109437716318, "pu": 10109437711189, "b": [["1000.00", "28.692"], ["5000.00", "101.418"], ["7049.20", "0.028"], ["19991.80", "0.870"], ["20091.80", "2.130"], ["33000.00", "3.785"], ["66943.20", "0.002"], ["66967.20", "0.006"], ["66967.30", "0.008"], ["69328.70", "2.016"], ["69419.30", "0.432"], ["69423.30", "0.927"], ["69555.10", "3.301"], ["69786.90", "10.382"], ["70139.30", "5.082"], ["70322.10", "23.059"], ["70398.00", "0.017"], ["70405.10", "0.000"], ["70412.10", "0.043"], ["70422.00", "0.026"], ["70442.80", "0.160"], ["70443.40", "0.014"], ["70443.50", "0.359"], ["70460.90", "0.288"], ["70471.40", "0.113"], ["70479.10", "0.011"], ["70489.80", "0.002"], ["70490.60", "0.015"], ["70491.00", "0.000"], ["70491.20", "0.000"], ["70491.30", "0.000"], ["70491.40", "0.002"], ["70491.50", "0.002"], ["70491.60", "0.002"], ["70491.70", "0.010"], ["70491.80", "8.326"]], "a": [["70493.00", "0.016"], ["70495.10", "0.003"], ["70495.20", "0.020"], ["70496.50", "0.018"], ["70499.20", "0.023"], ["70499.90", "0.674"], ["70501.60", "0.045"], ["70503.60", "0.065"], ["70504.60", "0.007"], ["70505.90", "0.000"], ["70506.70", "0.000"], ["70506.90", "0.059"], ["70507.90", "0.002"], ["70509.20", "0.189"], ["70510.90", "0.060"], ["70517.30", "0.186"], ["70519.30", "0.344"], ["70521.20", "0.000"], ["70523.00", "0.281"], ["70523.20", "0.004"], ["70524.80", "0.004"], ["70543.20", "0.180"], ["70548.30", "0.223"], ["70559.70", "0.000"], ["70574.30", "0.000"], ["70581.30", "0.025"], ["70588.40", "0.005"], ["71196.80", "9.542"], ["74031.70", "0.000"]]}}
{"local_ts": 1773485228891, "server_ts": 1773485228096, "data": {"e": "depthUpdate", "E": 1773485228099, "T": 1773485228096, "s": "BTCUSDT", "U": 10109437762059, "u": 10109437767372, "pu": 10109437761913, "b": [["1000.00", "28.692"], ["5000.00", "101.418"], ["7049.20", "0.028"], ["19991.80", "2.550"], ["20091.80", "0.010"], ["20391.80", "0.440"], ["56393.00", "0.000"], ["66952.20", "0.002"], ["66967.00", "0.150"], ["69082.00", "0.008"], ["69388.00", "152.004"], ["69558.00", "2.974"], ["69786.90", "10.382"], ["69899.60", "0.139"], ["70397.90", "0.000"], ["70405.00", "0.063"], ["70412.00", "0.297"], ["70437.50", "0.244"], ["70438.70", "0.104"], ["70443.20", "0.001"], ["70443.40", "0.014"], ["70447.60", "0.008"], ["70453.70", "0.370"], ["70460.90", "0.203"], ["70461.00", "0.087"], ["70461.40", "0.070"], ["70479.10", "0.011"], ["70491.50", "0.017"]], "a": [["70491.90", "1.155"], ["70492.40", "0.000"], ["70493.60", "0.000"], ["70493.90", "0.000"], ["70501.00", "0.003"], ["70504.60", "0.005"], ["70506.00", "0.239"], ["70527.10", "0.165"], ["70548.30", "0.322"], ["70574.20", "0.004"], ["70581.20", "0.108"], ["70588.30", "1.441"], ["71196.80", "9.542"], ["72204.50", "0.593"], ["72606.60", "0.018"], ["89523.20", "0.000"]]}}
{"local_ts": 1773485229913, "server_ts": 1773485229118, "data": {"e": "depthUpdate", "E": 1773485229119, "T": 1773485229118, "s": "BTCUSDT", "U": 10109437809040, "u": 10109437813656, "pu": 10109437808904, "b": [["5000.00", "101.418"], ["7049.20", "0.028"], ["19991.80", "0.250"], ["20291.80", "0.230"], ["20391.80", "2.520"], ["33000.00", "3.785"], ["56393.00", "0.004"], ["69238.00", "2.542"], ["69275.60", "0.720"], ["69293.40", "2.456"], ["69359.00", "0.002"], ["69786.90", "10.740"], ["70340.20", "0.000"], ["70343.80", "0.080"], ["70360.10", "0.663"], ["70397.90", "0.018"], ["70405.00", "0.134"], ["70412.00", "0.368"], ["70415.70", "0.023"], ["70415.80", "0.000"], ["70423.70", "0.008"], ["70431.60", "0.288"], ["70431.70", "0.205"], ["70439.10", "0.932"], ["70439.70", "0.789"], ["70446.00", "0.083"], ["70446.20", "0.846"], ["70446.90", "0.002"], ["70447.50", "0.737"], ["70447.60", "0.003"], ["70453.30", "0.908"], ["70456.60", "0.877"], ["70460.10", "2.063"], ["70460.40", "1.352"], ["70461.00", "0.087"], ["70463.60", "0.808"], ["70467.50", "0.848"], ["70471.30", "1.092"], ["70472.50", "0.012"], ["70473.80", "0.656"], ["70475.00", "0.023"], ["70477.70", "0.058"], ["70479.10", "0.011"], ["70481.50", "0.659"], ["70481.60", "0.018"], ["70481.80", "0.212"], ["70482.10", "0.000"], ["70482.90", "0.074"], ["70484.00", "0.000"], ["70484.20", "0.358"], ["70485.30", "0.001"], ["70485.50", "0.056"], ["70486.70", "0.038"], ["70486.80", "0.129"], ["70487.50", "0.021"], ["70488.00", "0.004"], ["70489.50", "0.021"], ["70489.90", "0.009"], ["70490.40", "0.010"], ["70490.80", "0.000"], ["70490.90", "0.002"], ["70491.80", "7.950"]], "a": [["70491.90", "1.839"], ["70493.20", "0.000"], ["70494.50", "0.026"], ["70495.30", "0.000"], ["70495.50", "0.008"], ["70497.10", "0.027"], ["70498.10", "0.018"], ["70499.70", "0.066"], ["70499.80", "0.516"], ["70504.60", "0.005"], ["70508.50", "0.006"], ["70510.10", "0.840"], ["70510.60", "0.000"], ["70513.40", "0.024"], ["70514.80", "0.836"], ["70515.40", "0.037"], ["70516.60", "0.272"], ["70517.20", "0.855"], ["70524.30", "0.844"], ["70527.10", "0.225"], ["70531.40", "0.847"], ["70536.20", "0.040"], ["70536.50", "0.468"], ["70538.50", "0.918"], ["70548.30", "0.223"], ["70574.20", "0.075"], ["70581.20", "0.179"], ["70588.30", "1.512"], ["70600.00", "2.924"], ["70624.70", "0.704"], ["70686.60", "0.000"], ["70689.30", "0.036"], ["70773.70", "0.009"], ["70812.60", "0.568"], ["70816.20", "0.211"], ["71196.70", "0.000"], ["71196.80", "9.542"], ["71492.90", "2.920"], ["71882.90", "0.595"], ["74025.80", "0.031"], ["89523.20", "0.000"]]}}
{"local_ts": 1773485230934, "server_ts": 1773485230136, "data": {"e": "depthUpdate", "E": 1773485230139, "T": 1773485230136, "s": "BTCUSDT", "U": 10109437856479, "u": 10109437861200, "pu": 10109437856365, "b": [["1000.00", "28.692"], ["5000.00", "101.418"], ["7049.20", "0.000"], ["20191.80", "0.080"], ["20291.80", "2.370"], ["20391.80", "0.550"], ["66953.10", "0.002"], ["69485.70", "2.287"], ["69786.90", "10.740"], ["69787.00", "0.029"], ["70139.30", "5.082"], ["70139.40", "0.939"], ["70245.80", "22.886"], ["70442.90", "0.000"], ["70444.40", "8.827"], ["70461.00", "0.002"], ["70461.70", "0.283"], ["70461.80", "0.158"], ["70467.80", "0.005"], ["70468.10", "0.006"], ["70469.10", "0.300"], ["70479.10", "0.011"], ["70482.10", "0.000"], ["70483.20", "0.698"]], "a": [["70492.90", "0.017"], ["70499.90", "0.020"], ["70504.60", "0.005"], ["70507.50", "0.679"], ["70517.70", "0.000"], ["70518.50", "0.641"], ["70519.00", "0.605"], ["70519.80", "0.070"], ["70522.90", "0.000"], ["70524.80", "0.252"], ["70524.90", "0.516"], ["70525.60", "0.055"], ["70715.40", "0.011"], ["71050.50", "0.000"], ["71196.80", "9.542"], ["71398.70", "0.000"], ["71707.70", "0.696"], ["71719.10", "1.396"], ["71866.50", "0.833"], ["74041.20", "0.000"], ["89523.20", "0.000"]]}}
{"local_ts": 1773485231957, "server_ts": 1773485231158, "data": {"e": "depthUpdate", "E": 1773485231159, "T": 1773485231158, "s": "BTCUSDT", "U": 10109437906525, "u": 10109437910873, "pu": 10109437906517, "b": [["5000.00", "101.418"], ["7049.20", "0.000"], ["20191.80", "2.080"], ["20291.80", "0.920"], ["33000.00", "3.789"], ["40000.00", "41.356"], ["66958.70", "0.000"], ["69786.80", "0.014"], ["69786.90", "10.740"], ["70332.70", "0.732"], ["70345.90", "0.180"], ["70397.80", "0.132"], ["70404.90", "0.071"], ["70411.90", "0.073"], ["70414.30", "0.064"], ["70428.30", "0.097"], ["70438.70", "0.004"], ["70456.70", "0.184"], ["70463.60", "0.861"], ["70465.30", "0.000"], ["70465.90", "0.131"], ["70466.30", "0.013"], ["70468.70", "0.003"], ["70470.70", "0.521"], ["70471.40", "0.113"], ["70475.20", "0.000"], ["70475.50", "0.003"], ["70475.60", "0.357"], ["70475.70", "1.207"], ["70476.00", "0.015"], ["70477.90", "0.005"], ["70479.50", "0.008"], ["70479.90", "0.638"], ["70480.00", "0.010"], ["70480.40", "0.259"], ["70480.50", "0.004"], ["70482.90", "0.003"], ["70483.00", "0.008"], ["70483.50", "1.190"], ["70483.70", "0.018"], ["70484.80", "0.062"], ["70484.90", "0.398"], ["70485.00", "0.015"], ["70485.10", "0.070"], ["70485.20", "0.004"], ["70485.30", "0.001"], ["70485.40", "0.003"], ["70485.50", "0.056"], ["70485.60", "0.005"], ["70485.70", "0.000"], ["70485.90", "0.008"], ["70486.00", "0.013"], ["70486.10", "0.462"], ["70486.40", "0.000"], ["70486.50", "0.077"], ["70486.90", "0.060"], ["70487.00", "0.001"], ["70487.60", "0.005"], ["70487.70", "0.114"], ["70487.90", "0.000"], ["70488.10", "0.052"], ["70489.20", "0.021"], ["70491.50", "0.000"], ["70491.60", "0.002"]], "a": [["70493.10", "0.000"], ["70494.30", "0.031"], ["70494.90", "0.005"], ["70499.00", "0.037"], ["70499.10", "0.209"], ["70499.80", "0.537"], ["70499.90", "0.684"], ["70502.40", "0.073"], ["70505.10", "0.002"], ["70506.00", "0.378"], ["70508.50", "0.004"], ["70509.60", "0.004"], ["70511.50", "0.061"], ["70512.40", "0.007"], ["70515.20", "0.516"], ["70515.80", "0.643"], ["70520.70", "0.011"], ["70521.30", "0.250"], ["70522.20", "0.060"], ["70522.90", "0.052"], ["70553.70", "0.004"], ["70554.60", "8.504"], ["70555.40", "0.297"], ["70569.50", "0.003"], ["70574.10", "0.042"], ["70574.20", "0.075"], ["70581.10", "0.267"], ["70581.20", "0.179"], ["70588.20", "0.000"], ["70588.30", "1.512"], ["70833.80", "0.211"], ["71196.80", "9.682"], ["71565.10", "0.836"], ["74040.70", "0.166"], ["89523.20", "0.000"]]}}
{"local_ts": 1773485232972, "server_ts": 1773485232178, "data": {"e": "depthUpdate", "E": 1773485232179, "T": 1773485232178, "s": "BTCUSDT", "U": 10109437968250, "u": 10109437978381, "pu": 10109437968238, "b": [["1000.00", "28.692"], ["5000.00", "101.418"], ["7049.20", "0.000"], ["20091.80", "1.630"], ["20191.80", "1.370"], ["66967.00", "0.150"], ["66967.20", "0.006"], ["69395.90", "6.120"], ["69466.40", "10.850"], ["69786.90", "10.754"], ["69787.10", "0.006"], ["70139.30", "5.082"], ["70246.00", "0.000"], ["70319.10", "0.000"], ["70397.80", "0.114"], ["70404.90", "0.000"], ["70411.90", "0.002"], ["70443.00", "0.004"], ["70443.10", "0.005"], ["70456.60", "1.001"], ["70460.90", "0.288"], ["70471.40", "0.297"]], "a": [["70491.90", "0.982"], ["70495.40", "0.007"], ["70495.50", "0.000"], ["70495.60", "0.003"], ["70495.80", "0.006"], ["70495.90", "0.002"], ["70496.00", "0.001"], ["70496.10", "0.000"], ["70496.20", "0.002"], ["70496.30", "0.006"], ["70498.60", "0.003"], ["70498.80", "0.519"], ["70498.90", "0.239"], ["70499.80", "0.531"], ["70499.90", "1.184"], ["70508.50", "0.143"], ["70510.20", "0.002"], ["70527.10", "0.041"], ["70548.30", "0.163"], ["70552.20", "0.004"], ["70559.50", "0.000"], ["70563.70", "6.300"], ["70566.50", "0.245"], ["70573.50", "0.000"], ["70574.20", "0.004"], ["70580.50", "0.185"], ["70581.20", "0.108"], ["70587.10", "0.211"], ["70587.50", "0.008"], ["70588.30", "1.441"], ["70594.50", "0.000"], ["70601.50", "0.108"], ["70608.50", "0.086"], ["70609.70", "0.029"], ["70616.70", "1.781"], ["70623.70", "0.040"], ["70630.70", "0.227"], ["70637.70", "0.011"], ["70644.70", "0.205"], ["70651.70", "0.007"], ["70658.70", "0.007"], ["70705.20", "3.639"], ["70715.50", "0.007"], ["70754.20", "0.258"], ["70799.90", "0.000"], ["71196.80", "9.682"], ["71546.60", "1.331"], ["74027.00", "0.502"], ["89523.20", "0.000"]]}}
{"local_ts": 1773485233995, "server_ts": 1773485233200, "data": {"e": "depthUpdate", "E": 1773485233201, "T": 1773485233200, "s": "BTCUSDT", "U": 10109438022625, "u": 10109438027008, "pu": 10109438022518, "b": [["1000.00", "28.692"], ["5000.00", "101.438"], ["7049.20", "0.000"], ["19991.80", "1.190"], ["20091.80", "1.810"], ["66963.20", "0.000"], ["69399.20", "11.509"], ["69589.40", "0.000"], ["69786.90", "10.789"], ["69787.00", "0.029"], ["69816.20", "0.000"], ["70000.00", "126.835"], ["70245.20", "0.004"], ["70397.70", "0.018"], ["70404.80", "0.354"], ["70411.80", "0.079"], ["70443.50", "0.359"], ["70443.60", "0.007"], ["70456.60", "1.001"], ["70460.90", "0.203"], ["70468.20", "0.083"], ["70468.70", "0.003"], ["70471.40", "0.028"], ["70471.50", "0.184"], ["70481.20", "0.060"], ["70482.30", "0.638"], ["70482.70", "0.004"], ["70483.90", "0.345"], ["70491.80", "7.897"]], "a": [["70491.90", "0.810"], ["70494.30", "0.004"], ["70494.40", "0.001"], ["70494.90", "0.005"], ["70495.50", "0.000"], ["70495.90", "0.017"], ["70496.30", "0.006"], ["70498.80", "0.026"], ["70499.40", "0.856"], ["70499.50", "0.514"], ["70499.70", "0.066"], ["70499.80", "0.021"], ["70499.90", "0.674"], ["70505.00", "0.088"], ["70506.00", "0.009"], ["70506.80", "0.059"], ["70509.30", "0.000"], ["70510.90", "0.003"], ["70511.00", "0.065"], ["70511.10", "0.237"], ["70513.40", "0.045"], ["70525.90", "0.006"], ["70562.40", "0.081"], ["70574.00", "0.073"], ["70574.10", "0.042"], ["70581.00", "0.082"], ["70581.10", "0.267"], ["70587.10", "0.211"], ["70588.10", "0.072"], ["70588.20", "0.000"], ["70604.90", "0.112"], ["70609.70", "0.022"], ["70611.90", "0.010"], ["70616.70", "1.774"], ["70618.90", "0.518"], ["70623.70", "0.033"], ["70624.30", "0.093"], ["70625.90", "0.048"], ["70630.70", "0.220"], ["70631.00", "0.203"], ["70632.90", "0.007"], ["70637.70", "0.004"], ["70639.90", "0.518"], ["70644.70", "0.198"], ["70646.90", "0.101"], ["70651.70", "0.000"], ["70653.90", "0.007"], ["70658.70", "0.000"], ["70716.00", "0.009"], ["70800.00", "11.775"], ["70997.00", "0.221"], ["71196.60", "0.142"], ["71196.80", "9.682"], ["71196.90", "0.042"], ["71398.10", "0.005"], ["71400.00", "11.632"], ["71553.20", "0.562"], ["71796.00", "1.055"], ["71905.70", "0.000"], ["89523.20", "0.000"]]}}
{"local_ts": 1773485235015, "server_ts": 1773485234222, "data": {"e": "depthUpdate", "E": 1773485234223, "T": 1773485234222, "s": "BTCUSDT", "U": 10109438067821, "u": 10109438071816, "pu": 10109438067765, "b": [["5000.00", "101.418"], ["7049.20", "0.056"], ["19991.80", "2.260"], ["20391.80", "0.740"], ["66945.30", "0.000"], ["66953.10", "0.002"], ["67672.20", "0.042"], ["69082.00", "0.056"], ["69085.30", "0.867"], ["69437.80", "0.397"], ["69469.70", "25.008"], ["69592.90", "0.077"], ["69786.90", "10.939"], ["69787.00", "0.029"], ["69790.20", "0.007"], ["70139.40", "0.943"], ["70397.70", "0.018"], ["70404.80", "0.354"], ["70411.80", "0.079"], ["70443.60", "0.007"], ["70443.70", "0.034"], ["70461.40", "0.070"], ["70481.40", "0.007"], ["70487.90", "0.015"], ["70488.00", "0.066"], ["70491.80", "7.846"]], "a": [["70491.90", "1.469"], ["70492.60", "0.350"], ["70498.80", "0.005"], ["70499.10", "0.209"], ["70499.90", "0.929"], ["70521.90", "0.013"], ["70522.90", "0.248"], ["70523.00", "0.033"], ["70574.00", "0.073"], ["70581.00", "0.082"], ["70588.10", "0.072"], ["70604.90", "0.105"], ["70611.90", "0.003"], ["70612.60", "0.009"], ["70618.90", "0.511"], ["70619.60", "0.010"], ["70625.90", "0.041"], ["70626.60", "0.211"], ["70632.90", "0.000"], ["70633.60", "1.584"], ["70639.90", "0.511"], ["70640.60", "1.164"], ["70646.90", "0.094"], ["70647.60", "0.007"], ["70653.90", "0.000"], ["70654.60", "0.007"], ["70661.60", "0.374"], ["70844.30", "0.007"], ["71196.70", "0.000"], ["71196.80", "8.983"], ["71200.30", "0.000"], ["71397.60", "0.000"], ["71552.70", "0.704"], ["71905.20", "0.007"], ["89523.20", "0.000"]]}}
{"local_ts": 1773485236036, "server_ts": 1773485235244, "data": {"e": "depthUpdate", "E": 1773485235245, "T": 1773485235244, "s": "BTCUSDT", "U": 10109438115390, "u": 10109438119057, "pu": 10109438115180, "b": [["1000.00", "28.692"], ["5000.00", "101.418"], ["7049.20", "0.056"], ["19991.80", "0.060"], ["20291.80", "0.360"], ["20391.80", "2.580"], ["66937.30", "0.002"], ["66967.30", "0.004"], ["69281.80", "0.002"], ["69352.20", "0.000"], ["69417.70", "0.718"], ["69786.90", "11.654"], ["70139.30", "5.652"], ["70319.10", "0.159"], ["70340.20", "0.039"], ["70360.10", "0.697"], ["70444.30", "0.025"], ["70459.80", "0.002"], ["70461.90", "0.005"], ["70464.30", "0.000"], ["70483.30", "0.283"], ["70483.50", "1.096"], ["70485.60", "0.020"], ["70485.80", "0.023"], ["70487.20", "0.003"], ["70491.80", "7.919"]], "a": [["70491.90", "2.641"], ["70498.90", "0.352"], ["70499.00", "0.088"], ["70499.10", "0.072"], ["70548.30", "0.163"], ["70597.20", "0.680"], ["70604.20", "0.048"], ["70611.20", "3.220"], ["70612.60", "0.002"], ["70618.20", "0.007"], ["70619.60", "0.003"], ["70624.30", "0.615"], ["70625.20", "0.023"], ["70626.60", "0.204"], ["70632.20", "0.217"], ["70633.60", "1.577"], ["70639.20", "0.007"], ["70640.60", "1.157"], ["70646.20", "0.099"], ["70647.60", "0.000"], ["70654.60", "0.000"], ["70661.60", "0.367"], ["70678.70", "0.174"], ["71196.80", "8.981"], ["71803.90", "0.003"], ["71901.70", "0.015"], ["74040.10", "0.044"], ["89523.20", "0.000"]]}}
{"local_ts": 1773485237060, "server_ts": 1773485236266, "data": {"e": "depthUpdate", "E": 1773485236267, "T": 1773485236266, "s": "BTCUSDT", "U": 10109438160919, "u": 10109438165477, "pu": 10109438160870, "b": [["5000.00", "101.418"], ["7049.20", "0.028"], ["20191.80", "0.190"], ["20291.80", "2.470"], ["20391.80", "0.340"], ["33000.00", "3.785"], ["66952.80", "0.000"], ["69363.90", "9.360"], ["69415.40", "0.431"], ["69449.70", "0.002"], ["69786.90", "11.661"], ["70312.00", "0.178"], ["70315.60", "0.185"], ["70319.10", "0.000"], ["70336.70", "0.041"], ["70397.60", "0.000"], ["70397.90", "0.018"], ["70404.70", "0.529"], ["70405.00", "0.134"], ["70411.70", "0.272"], ["70412.00", "0.368"], ["70443.40", "0.014"], ["70443.50", "0.359"], ["70450.00", "0.064"], ["70451.40", "0.695"], ["70467.00", "0.065"], ["70467.10", "0.000"], ["70467.80", "0.253"], ["70468.30", "0.052"], ["70469.10", "0.000"], ["70476.00", "1.220"], ["70476.90", "0.004"], ["70481.70", "0.014"], ["70482.50", "0.640"], ["70483.10", "0.221"], ["70488.40", "0.001"], ["70489.10", "0.007"], ["70490.10", "0.006"]], "a": [["70491.90", "1.553"], ["70494.30", "0.037"], ["70497.20", "0.015"], ["70498.30", "0.006"], ["70498.90", "0.052"], ["70499.50", "0.000"], ["70499.60", "0.000"], ["70499.70", "0.009"], ["70501.60", "0.028"], ["70510.50", "0.047"], ["70510.60", "0.085"], ["70511.70", "0.003"], ["70512.10", "0.004"], ["70514.90", "0.004"], ["70523.00", "0.281"], ["70524.80", "0.004"], ["70527.10", "0.005"], ["70550.90", "2.246"], ["70574.00", "0.002"], ["70574.30", "0.071"], ["70581.00", "0.011"], ["70581.30", "0.096"], ["70588.10", "0.001"], ["70588.40", "0.076"], ["70597.20", "0.673"], ["70604.20", "0.041"], ["70611.20", "3.213"], ["70618.20", "0.000"], ["70625.20", "0.016"], ["70632.20", "0.210"], ["70639.20", "0.000"], ["70646.20", "0.092"], ["71196.80", "10.383"], ["71213.40", "53.713"], ["71427.10", "67.675"], ["71901.80", "0.065"], ["72621.20", "3.899"], ["74030.10", "0.002"], ["89523.20", "0.000"]]}}
{"local_ts": 1773485238083, "server_ts": 1773485237290, "data": {"e": "depthUpdate", "E": 1773485237291, "T": 1773485237290, "s": "BTCUSDT", "U": 10109438206901, "u": 10109438211136, "pu": 10109438206848, "b": [["1000.00", "28.692"], ["5000.00", "101.398"], ["7049.20", "0.028"], ["20091.80", "0.040"], ["20191.80", "2.330"], ["20291.80", "0.630"], ["66967.20", "2.242"], ["66967.30", "0.008"], ["69379.70", "0.000"], ["69786.90", "11.668"], ["70139.30", "5.652"], ["70360.10", "0.681"], ["70443.60", "0.007"], ["70443.70", "0.034"], ["70444.30", "0.025"], ["70459.70", "0.004"], ["70460.90", "2.071"], ["70482.00", "0.005"], ["70482.80", "0.145"]], "a": [["70491.90", "0.883"], ["70494.50", "0.005"], ["70494.70", "0.034"], ["70497.50", "0.022"], ["70498.90", "0.434"], ["70499.70", "0.009"], ["70499.80", "1.241"], ["70500.00", "7.418"], ["70500.40", "0.227"], ["70504.00", "0.095"], ["70506.10", "0.000"], ["70507.10", "0.012"], ["70507.90", "0.017"], ["70511.30", "0.003"], ["70516.60", "0.008"], ["70516.70", "0.002"], ["70520.20", "0.000"], ["70527.10", "0.295"], ["70550.90", "2.244"], ["70624.20", "0.559"], ["71196.80", "10.383"], ["71514.00", "24.575"], ["74039.60", "0.003"], ["74051.50", "0.052"], ["89523.20", "0.000"]]}}
{"local_ts": 1773485239105, "server_ts": 1773485238308, "data": {"e": "depthUpdate", "E": 1773485238311, "T": 1773485238308, "s": "BTCUSDT", "U": 10109438252279, "u": 10109438257252, "pu": 10109438252181, "b": [["1000.00", "28.692"], ["5000.00", "101.418"], ["7049.20", "0.028"], ["20091.80", "1.960"], ["20191.80", "1.040"], ["33000.00", "3.789"], ["66958.80", "0.064"], ["69786.90", "11.668"], ["70122.80", "0.000"], ["70397.90", "0.000"], ["70398.10", "0.020"], ["70405.00", "0.063"], ["70405.20", "2.233"], ["70412.00", "0.297"], ["70412.20", "0.585"], ["70443.60", "0.005"], ["70443.70", "0.036"], ["70461.80", "0.155"], ["70462.20", "0.007"], ["70463.00", "0.133"], ["70466.70", "0.052"], ["70467.00", "0.313"], ["70467.70", "0.375"], ["70469.10", "0.000"], ["70469.80", "0.004"], ["70470.80", "0.002"], ["70471.40", "0.367"], ["70472.90", "0.070"], ["70473.60", "0.512"], ["70474.10", "0.010"], ["70474.80", "0.002"], ["70475.50", "0.003"], ["70475.80", "0.000"], ["70476.60", "0.000"], ["70481.30", "0.649"], ["70482.00", "0.005"], ["70482.90", "0.008"], ["70483.20", "0.002"], ["70483.40", "0.126"], ["70484.10", "0.010"], ["70491.40", "0.005"]], "a": [["70496.80", "0.004"], ["70498.80", "0.676"], ["70498.90", "0.320"], ["70499.70", "0.009"], ["70500.60", "0.120"], ["70503.30", "0.002"], ["70516.70", "0.640"], ["70517.60", "0.516"], ["70517.80", "1.212"], ["70519.90", "0.073"], ["70520.20", "0.000"], ["70520.60", "0.006"], ["70521.10", "0.019"], ["70521.50", "1.124"], ["70522.90", "0.000"], ["70524.20", "0.055"], ["70524.80", "0.004"], ["70527.50", "0.000"], ["70574.20", "0.004"], ["70574.80", "0.074"], ["70581.20", "0.108"], ["70581.80", "0.073"], ["70584.80", "0.004"], ["70588.30", "1.441"], ["70588.90", "0.073"], ["70715.50", "0.000"], ["70840.50", "0.009"], ["71196.80", "10.383"], ["71482.20", "1.188"], ["73311.50", "0.632"]]}}
