{"local_ts": 1773485483534, "server_ts": 1773485482741, "data": {"e": "depthUpdate", "E": 1773485482743, "T": 1773485482741, "s": "BTCUSDT", "U": 10109450906697, "u": 10109450912778, "pu": 10109450906465, "b": [["1000.00", "28.842"], ["5000.00", "101.398"], ["7050.40", "0.000"], ["20203.60", "1.040"], ["20303.60", "1.960"], ["33000.00", "3.789"], ["40000.00", "41.317"], ["69093.60", "0.027"], ["69439.30", "0.862"], ["69798.60", "2.861"], ["70354.00", "0.081"], ["70414.50", "0.000"], ["70426.00", "0.025"], ["70433.30", "0.154"], ["70433.90", "0.249"], ["70434.90", "0.094"], ["70435.30", "0.043"], ["70440.10", "0.003"], ["70444.20", "1.234"], ["70451.80", "0.042"], ["70451.90", "0.708"], ["70453.30", "0.100"], ["70455.50", "0.002"], ["70471.40", "0.005"], ["70475.30", "0.034"], ["70478.50", "0.007"], ["70479.50", "0.010"], ["70479.80", "0.188"], ["70480.50", "0.248"], ["70481.50", "0.000"], ["70481.80", "0.052"], ["70482.60", "0.002"], ["70482.70", "0.003"], ["70483.00", "0.008"], ["70483.60", "0.004"], ["70484.20", "0.005"], ["70484.30", "0.031"], ["70485.40", "0.000"], ["70485.50", "0.012"], ["70486.10", "0.070"], ["70486.40", "0.007"], ["70486.80", "0.080"], ["70487.20", "0.017"], ["70487.80", "0.006"], ["70488.40", "0.513"], ["70488.90", "0.000"], ["70489.40", "0.059"], ["70489.70", "0.007"], ["70490.30", "0.003"], ["70490.60", "0.003"], ["70490.80", "1.239"], ["70491.80", "0.000"], ["70492.00", "0.026"], ["70492.30", "0.014"], ["70492.50", "0.022"], ["70492.70", "0.002"], ["70493.10", "0.309"], ["70493.40", "0.006"], ["70493.50", "0.009"], ["70493.60", "0.005"], ["70493.70", "0.773"], ["70493.90", "0.005"], ["70494.10", "0.009"], ["70494.20", "0.004"], ["70494.30", "0.028"], ["70494.40", "0.024"], ["70494.70", "0.002"], ["70494.80", "0.053"], ["70494.90", "0.016"], ["70495.10", "1.089"], ["70495.20", "0.661"], ["70495.30", "0.015"], ["70495.80", "0.024"], ["70495.90", "0.008"], ["70496.00", "0.300"], ["70496.40", "0.226"], ["70496.60", "0.024"], ["70497.60", "0.000"], ["70498.30", "0.004"], ["70498.50", "0.003"], ["70499.80", "0.000"], ["70500.50", "0.004"], ["70501.10", "0.052"], ["70501.80", "0.003"], ["70502.40", "0.045"], ["70502.60", "0.029"], ["70503.30", "0.004"], ["70503.40", "0.002"], ["70503.60", "5.421"]], "a": [["70503.70", "1.717"], ["70505.40", "0.005"], ["70506.10", "0.008"], ["70506.70", "0.000"], ["70506.80", "0.000"], ["70507.40", "0.021"], ["70507.50", "0.004"], ["70507.80", "0.002"], ["70508.20", "0.076"], ["70509.60", "0.016"], ["70511.40", "0.007"], ["70512.20", "0.002"], ["70513.80", "0.000"], ["70514.10", "0.002"], ["70514.30", "0.006"], ["70516.20", "0.255"], ["70517.40", "0.347"], ["70517.80", "0.158"], ["70518.30", "0.088"], ["70518.90", "0.209"], ["70519.10", "0.011"], ["70519.20", "0.005"], ["70519.90", "0.217"], ["70521.10", "0.531"], ["70521.20", "0.217"], ["70521.40", "0.010"], ["70521.60", "0.001"], ["70521.70", "0.000"], ["70522.00", "0.739"], ["70522.40", "0.039"], ["70522.70", "0.144"], ["70523.00", "0.033"], ["70525.00", "0.091"], ["70526.10", "0.324"], ["70526.60", "0.020"], ["70528.50", "0.004"], ["70528.70", "0.981"], ["70528.90", "0.012"], ["70529.60", "0.154"], ["70529.80", "0.007"], ["70529.90", "0.007"], ["70530.00", "0.137"], ["70530.20", "0.526"], ["70530.30", "0.004"], ["70530.60", "0.009"], ["70530.70", "0.013"], ["70531.20", "0.075"], ["70531.30", "0.639"], ["70531.50", "0.007"], ["70531.60", "0.003"], ["70532.00", "0.006"], ["70532.70", "0.000"], ["70533.10", "1.948"], ["70533.30", "0.069"], ["70533.80", "0.510"], ["70534.00", "0.070"], ["70534.40", "0.161"], ["70535.70", "0.000"], ["70535.80", "0.275"], ["70536.00", "0.119"], ["70538.00", "0.023"], ["70539.50", "0.715"], ["70544.20", "0.019"], ["70544.40", "0.266"], ["70546.00", "0.803"], ["70547.00", "0.062"], ["70548.50", "0.000"], ["70553.10", "0.003"], ["70554.40", "0.518"], ["70557.00", "0.046"], ["70557.30", "1.206"], ["70557.60", "0.267"], ["70558.70", "0.146"], ["70558.90", "0.040"], ["70567.20", "0.274"], ["70569.20", "0.012"], ["70581.30", "0.003"], ["70595.80", "0.087"], ["71208.70", "0.701"], ["71504.90", "3.326"], ["74039.00", "0.040"], ["89523.20", "0.000"]]}}
{"local_ts": 1773485484554, "server_ts": 1773485483762, "data": {"e": "depthUpdate", "E": 1773485483763, "T": 1773485483762, "s": "BTCUSDT", "U": 10109450962804, "u": 10109450967490, "pu": 10109450962593, "b": [["5000.00", "101.418"], ["7050.40", "0.000"], ["20103.60", "0.590"], ["20203.60", "2.410"], ["20303.60", "0.000"], ["66966.90", "0.000"], ["69270.40", "0.000"], ["69586.80", "1.506"], ["69798.60", "4.507"], ["69798.70", "0.000"], ["70081.10", "0.000"], ["70083.50", "0.699"], ["70151.10", "0.214"], ["70186.40", "0.000"], ["70188.10", "0.963"], ["70263.60", "0.002"], ["70265.50", "0.457"], ["70286.00", "0.024"], ["70294.90", "0.375"], ["70331.90", "5.133"], ["70370.70", "0.869"], ["70451.30", "0.086"], ["70451.50", "0.006"], ["70475.70", "0.100"], ["70502.80", "0.004"]], "a": [["70503.70", "1.718"], ["70527.50", "0.002"], ["70535.30", "0.091"], ["70535.70", "0.000"], ["70539.00", "0.201"], ["70542.50", "0.203"], ["70635.60", "0.772"], ["70674.30", "3.097"], ["70674.40", "0.000"], ["70702.60", "0.002"], ["70711.40", "0.268"], ["70746.50", "0.240"], ["70748.70", "0.000"], ["70826.50", "0.000"], ["70826.60", "0.000"], ["70932.80", "0.000"], ["71208.70", "1.402"], ["71420.30", "0.703"], ["71490.80", "1.257"], ["71561.30", "1.120"], ["71696.50", "0.000"], ["71837.50", "0.000"], ["73323.80", "0.039"], ["89523.20", "0.000"]]}}
{"local_ts": 1773485485574, "server_ts": 1773485484784, "data": {"e": "depthUpdate", "E": 1773485484785, "T": 1773485484784, "s": "BTCUSDT", "U": 10109451014716, "u": 10109451018583, "pu": 10109451014650, "b": [["1000.00", "28.842"], ["5000.00", "101.398"], ["7050.40", "0.000"], ["20003.60", "0.290"], ["20103.60", "2.570"], ["20203.60", "0.140"], ["69516.50", "1.166"], ["69798.60", "5.222"], ["70313.80", "0.002"], ["70328.00", "0.021"], ["70456.60", "0.010"], ["70456.70", "0.043"], ["70475.70", "0.015"], ["70488.20", "0.086"], ["70488.90", "0.000"], ["70503.50", "0.609"], ["70503.60", "5.457"]], "a": [["70522.60", "0.028"], ["70524.40", "0.001"], ["70528.50", "0.011"], ["70528.70", "0.996"], ["70539.00", "0.102"], ["70540.80", "0.052"], ["70542.80", "0.016"], ["70800.00", "111.913"], ["71208.70", "2.804"], ["74038.10", "0.002"], ["74056.30", "0.000"]]}}
{"local_ts": 1773485486595, "server_ts": 1773485485804, "data": {"e": "depthUpdate", "E": 1773485485805, "T": 1773485485804, "s": "BTCUSDT", "U": 10109451069836, "u": 10109451074557, "pu": 10109451069582, "b": [["5000.00", "101.418"], ["7050.40", "0.056"], ["20003.60", "2.420"], ["20103.60", "0.440"], ["20403.60", "0.140"], ["66978.00", "0.000"], ["69440.30", "0.430"], ["69467.00", "0.005"], ["69798.60", "5.222"], ["70257.90", "0.004"], ["70438.10", "0.082"], ["70453.10", "1.067"], ["70453.20", "0.085"], ["70456.60", "0.010"], ["70457.20", "0.037"], ["70475.60", "0.185"], ["70493.00", "0.014"], ["70495.40", "0.008"], ["70495.90", "0.011"], ["70496.10", "0.001"]], "a": [["70508.10", "0.000"], ["70514.30", "0.003"], ["70514.80", "0.002"], ["70515.10", "0.002"], ["70515.40", "0.003"], ["70515.50", "0.059"], ["70515.70", "0.141"], ["70515.80", "0.019"], ["70516.10", "0.005"], ["70516.20", "0.002"], ["70516.50", "0.003"], ["70520.60", "0.051"], ["70520.90", "0.081"], ["70521.00", "0.040"], ["70521.30", "0.110"], ["70522.60", "0.007"], ["70522.90", "0.006"], ["70523.60", "0.144"], ["70524.50", "0.005"], ["70528.20", "0.057"], ["70528.40", "0.142"], ["70529.50", "0.858"], ["70530.40", "0.052"], ["70532.00", "0.516"], ["70532.20", "0.019"], ["70565.10", "0.225"], ["70579.10", "0.261"], ["70579.40", "0.036"], ["70579.80", "0.285"], ["70583.20", "0.036"], ["70583.80", "0.353"], ["70588.20", "0.000"], ["70676.40", "0.000"], ["71208.70", "2.804"], ["74031.90", "0.005"]]}}
{"local_ts": 1773485487616, "server_ts": 1773485486824, "data": {"e": "depthUpdate", "E": 1773485486825, "T": 1773485486824, "s": "BTCUSDT", "U": 10109451117256, "u": 10109451120939, "pu": 10109451117165, "b": [["1000.00", "28.842"], ["5000.00", "101.398"], ["7050.40", "0.056"], ["20003.60", "0.750"], ["20403.60", "2.250"], ["56403.00", "0.000"], ["69798.60", "6.653"], ["70151.10", "0.356"], ["70426.50", "0.676"], ["70452.60", "0.062"], ["70452.70", "0.085"], ["70480.60", "0.052"], ["70485.90", "0.510"], ["70486.80", "0.010"], ["70491.70", "0.010"], ["70492.40", "0.066"], ["70500.00", "0.630"], ["70502.80", "0.004"]], "a": [["70503.70", "1.619"], ["70503.80", "0.031"], ["70504.90", "0.000"], ["70506.30", "0.002"], ["70519.90", "0.242"], ["70527.40", "0.025"], ["70528.50", "0.026"], ["70528.60", "1.144"], ["70536.70", "0.840"], ["70536.80", "0.087"], ["71208.70", "4.206"], ["71451.70", "4.275"], ["71564.70", "0.000"], ["74033.00", "0.021"], ["74061.60", "0.025"], ["75500.00", "30.282"]]}}
{"local_ts": 1773485488635, "server_ts": 1773485487844, "data": {"e": "depthUpdate", "E": 1773485487845, "T": 1773485487844, "s": "BTCUSDT", "U": 10109451191405, "u": 10109451196892, "pu": 10109451191364, "b": [["1000.00", "28.842"], ["5000.00", "101.418"], ["7050.90", "0.056"], ["20308.80", "1.640"], ["20403.60", "1.200"], ["33000.00", "3.785"], ["63457.90", "0.002"], ["66974.60", "0.002"], ["69093.60", "0.006"], ["69803.70", "0.105"], ["69803.80", "0.000"], ["70436.80", "0.050"], ["70437.30", "0.313"], ["70438.40", "0.098"], ["70438.70", "0.042"], ["70492.80", "0.008"], ["70507.10", "0.006"], ["70508.80", "8.801"]], "a": [["70517.60", "0.004"], ["70522.70", "0.031"], ["70530.20", "0.014"], ["70538.60", "0.155"], ["70542.20", "0.051"], ["71214.00", "0.000"], ["71350.50", "0.710"], ["74067.20", "0.000"], ["77559.80", "0.002"]]}}
{"local_ts": 1773485489657, "server_ts": 1773485488866, "data": {"e": "depthUpdate", "E": 1773485488867, "T": 1773485488866, "s": "BTCUSDT", "U": 10109451235040, "u": 10109451238940, "pu": 10109451234969, "b": [["5000.00", "101.418"], ["7050.90", "0.028"], ["20208.80", "1.350"], ["20308.80", "1.490"], ["63457.90", "0.002"], ["66968.70", "0.002"], ["69803.70", "0.105"], ["70033.00", "0.024"], ["70156.30", "0.000"], ["70325.50", "0.362"], ["70353.80", "0.513"], ["70353.90", "0.986"], ["70362.10", "0.264"], ["70362.20", "0.000"], ["70369.40", "0.010"], ["70369.50", "0.008"], ["70384.80", "2.242"], ["70395.00", "0.000"], ["70396.40", "6.303"], ["70404.40", "0.000"], ["70409.00", "0.000"], ["70414.80", "0.003"], ["70418.70", "0.002"], ["70423.10", "0.008"], ["70426.90", "0.000"], ["70429.80", "0.340"], ["70432.70", "0.174"], ["70434.50", "0.139"], ["70499.60", "0.006"], ["70508.80", "8.716"]], "a": [["70512.30", "0.004"], ["70513.30", "0.001"], ["70515.70", "0.064"], ["70517.10", "0.006"], ["70520.70", "0.040"], ["70534.30", "0.457"], ["70535.10", "0.646"], ["70540.60", "0.166"], ["70594.80", "0.002"], ["71214.00", "0.000"], ["71724.30", "0.696"], ["71919.00", "0.015"], ["77559.80", "0.002"]]}}
{"local_ts": 1773485490678, "server_ts": 1773485489888, "data": {"e": "depthUpdate", "E": 1773485489889, "T": 1773485489888, "s": "BTCUSDT", "U": 10109451274360, "u": 10109451277325, "pu": 10109451274338, "b": [["1000.00", "28.842"], ["5000.00", "101.418"], ["7050.90", "0.028"], ["20108.80", "0.910"], ["20208.80", "2.090"], ["63457.90", "0.002"], ["68724.40", "0.218"], ["69803.70", "0.105"], ["69803.80", "0.004"], ["70262.90", "0.004"], ["70455.90", "0.206"], ["70456.20", "3.335"], ["70470.90", "0.000"], ["70471.00", "0.086"], ["70480.30", "0.007"], ["70481.30", "0.204"], ["70491.50", "0.016"], ["70493.00", "0.919"], ["70495.20", "0.002"], ["70504.80", "0.003"]], "a": [["70533.00", "0.007"], ["70534.20", "0.009"], ["70544.20", "0.104"], ["70546.60", "1.841"], ["70547.40", "0.004"], ["71214.00", "0.000"], ["74063.60", "0.000"], ["74064.50", "0.052"], ["77559.80", "0.002"]]}}
{"local_ts": 1773485491698, "server_ts": 1773485490907, "data": {"e": "depthUpdate", "E": 1773485490909, "T": 1773485490907, "s": "BTCUSDT", "U": 10109451312320, "u": 10109451316349, "pu": 10109451312256, "b": [["5000.00", "101.418"], ["7050.90", "0.028"], ["20008.80", "0.460"], ["20108.80", "2.530"], ["20208.80", "0.010"], ["63457.90", "0.002"], ["66961.80", "0.002"], ["69160.40", "5.697"], ["69217.80", "1.444"], ["69380.70", "2.162"], ["69472.30", "1.724"], ["69794.00", "0.000"], ["69803.70", "0.105"], ["70058.40", "0.019"], ["70080.40", "0.000"], ["70185.70", "0.187"], ["70200.10", "0.007"], ["70262.60", "0.006"], ["70263.00", "0.704"], ["70473.60", "0.343"], ["70501.80", "0.073"]], "a": [["70597.10", "1.891"], ["70752.20", "0.211"], ["71192.80", "0.788"], ["71214.00", "0.000"], ["71496.00", "0.113"], ["77559.80", "0.002"]]}}
{"local_ts": 1773485492718, "server_ts": 1773485491927, "data": {"e": "depthUpdate", "E": 1773485491929, "T": 1773485491927, "s": "BTCUSDT", "U": 10109451365882, "u": 10109451369732, "pu": 10109451365819, "b": [["1000.00", "28.842"], ["5000.00", "101.418"], ["7050.90", "0.028"], ["20008.80", "2.520"], ["20108.80", "0.240"], ["20408.80", "0.240"], ["56407.00", "0.000"], ["63457.90", "0.002"], ["66965.00", "0.004"], ["69169.10", "2.890"], ["69239.60", "1.788"], ["69429.00", "1.475"], ["69723.40", "4.291"], ["69803.70", "0.819"], ["70156.30", "0.000"], ["70295.20", "0.000"], ["70333.00", "0.527"], ["70377.20", "0.000"], ["70498.20", "1.045"], ["70501.50", "0.005"]], "a": [["70508.90", "3.875"], ["70519.50", "0.097"], ["70539.50", "0.916"], ["70554.00", "0.008"], ["70597.10", "1.848"], ["70643.30", "0.043"], ["70679.00", "0.000"], ["70716.00", "0.002"], ["70732.40", "0.002"], ["71214.00", "0.000"], ["71596.00", "0.380"], ["71674.30", "0.380"], ["71752.60", "0.380"], ["71831.00", "0.380"], ["71909.30", "0.383"], ["71919.00", "0.036"], ["74058.40", "0.007"], ["77559.80", "0.002"]]}}
{"local_ts": 1773485493740, "server_ts": 1773485492950, "data": {"e": "depthUpdate", "E": 1773485492951, "T": 1773485492950, "s": "BTCUSDT", "U": 10109451406552, "u": 10109451411182, "pu": 10109451406533, "b": [["1000.00", "28.842"], ["5000.00", "101.418"], ["7050.90", "0.000"], ["20008.80", "0.530"], ["20308.80", "0.090"], ["20408.80", "2.380"], ["56407.00", "0.000"], ["63457.90", "0.000"], ["66965.00", "0.002"], ["68393.50", "0.000"], ["69723.40", "2.861"], ["69803.70", "0.819"], ["70325.50", "0.362"], ["70335.20", "0.926"], ["70371.90", "0.000"], ["70372.20", "0.840"], ["70377.70", "2.339"], ["70392.80", "0.255"], ["70461.10", "0.265"], ["70461.20", "0.004"], ["70483.10", "0.052"], ["70484.50", "0.053"], ["70487.40", "0.073"], ["70488.40", "0.003"], ["70488.90", "0.070"], ["70489.70", "0.020"], ["70490.50", "0.725"], ["70491.00", "0.004"], ["70491.90", "0.004"], ["70498.00", "0.647"], ["70498.20", "0.407"], ["70499.50", "0.021"], ["70501.50", "0.005"], ["70501.80", "0.073"]], "a": [["70508.90", "3.515"], ["70514.10", "0.000"], ["70519.50", "0.097"], ["70524.40", "0.056"], ["70526.20", "0.026"], ["70533.30", "0.649"], ["70534.40", "0.601"], ["70535.70", "0.000"], ["70536.30", "0.072"], ["70536.80", "0.002"], ["70538.00", "0.291"], ["70538.50", "0.005"], ["70539.60", "1.758"], ["70540.60", "0.166"], ["70540.80", "0.073"], ["70543.10", "0.000"], ["70639.70", "0.211"], ["70640.20", "0.003"], ["70640.30", "0.535"], ["71214.00", "0.000"], ["71572.90", "0.837"], ["77559.80", "0.000"]]}}
{"local_ts": 1773485494764, "server_ts": 1773485493972, "data": {"e": "depthUpdate", "E": 1773485493973, "T": 1773485493972, "s": "BTCUSDT", "U": 10109451446767, "u": 10109451451515, "pu": 10109451446700, "b": [["5000.00", "101.418"], ["7050.90", "0.000"], ["20308.80", "2.120"], ["20408.80", "0.880"], ["56407.10", "0.000"], ["63457.90", "0.000"], ["66961.90", "0.002"], ["69803.70", "0.819"], ["69880.00", "0.900"], ["70081.10", "0.682"], ["70156.30", "0.000"], ["70189.00", "5.669"], ["70372.50", "0.798"], ["70375.00", "0.263"], ["70375.40", "8.188"], ["70454.90", "0.091"], ["70455.00", "0.023"], ["70487.40", "0.003"], ["70488.90", "0.000"], ["70490.10", "0.070"], ["70491.20", "0.344"], ["70498.20", "0.404"]], "a": [["70508.90", "3.508"], ["70534.10", "0.005"], ["70535.00", "0.663"], ["70535.30", "0.006"], ["70536.10", "0.518"], ["70537.70", "0.004"], ["70539.10", "0.087"], ["70539.30", "0.094"], ["70544.20", "0.164"], ["70585.00", "0.011"], ["70590.00", "0.694"], ["70595.90", "0.043"], ["70597.00", "0.044"], ["70599.10", "0.043"], ["70603.60", "0.043"], ["70610.80", "0.586"], ["70640.30", "0.423"], ["70640.60", "8.575"], ["70749.00", "3.705"], ["70752.20", "0.211"], ["71214.00", "1.402"], ["71703.70", "0.209"], ["77559.80", "0.000"]]}}
{"local_ts": 1773485495786, "server_ts": 1773485494992, "data": {"e": "depthUpdate", "E": 1773485494993, "T": 1773485494992, "s": "BTCUSDT", "U": 10109451569926, "u": 10109451576430, "pu": 10109451569909, "b": [["1000.00", "28.842"], ["5000.00", "101.418"], ["7050.40", "0.000"], ["20203.60", "0.640"], ["20308.80", "1.330"], ["33000.00", "3.785"], ["56403.00", "0.000"], ["56407.00", "0.000"], ["62947.40", "0.000"], ["63453.20", "0.002"], ["66948.90", "0.000"], ["68795.60", "0.624"], ["69093.60", "0.009"], ["69098.70", "0.010"], ["69502.50", "0.286"], ["69551.90", "0.288"], ["69798.60", "6.653"], ["70081.10", "0.000"], ["70083.70", "6.307"], ["70189.00", "11.870"], ["70262.90", "0.008"], ["70306.80", "0.000"], ["70314.20", "0.003"], ["70355.60", "0.001"], ["70377.90", "0.003"], ["70383.10", "0.271"], ["70410.40", "0.540"], ["70411.60", "0.024"], ["70413.20", "0.005"], ["70418.40", "0.262"], ["70426.50", "0.871"], ["70431.30", "0.341"], ["70433.60", "0.316"], ["70448.50", "0.003"], ["70449.40", "0.003"], ["70452.20", "0.024"], ["70453.70", "0.263"], ["70456.10", "0.258"], ["70456.40", "0.005"], ["70456.60", "0.016"], ["70457.10", "0.004"], ["70458.80", "1.456"], ["70467.70", "0.072"], ["70468.40", "0.016"], ["70471.10", "0.005"], ["70471.20", "0.308"], ["70475.90", "0.111"], ["70477.10", "0.080"], ["70480.70", "0.018"], ["70481.60", "0.002"], ["70482.90", "0.861"], ["70483.80", "0.063"], ["70484.00", "0.277"], ["70484.20", "0.009"], ["70484.90", "0.208"], ["70485.30", "0.009"], ["70486.00", "0.324"], ["70486.70", "0.217"], ["70488.80", "0.005"], ["70488.90", "0.195"], ["70489.00", "0.497"], ["70489.20", "0.001"], ["70489.60", "0.096"], ["70490.00", "0.523"], ["70490.50", "0.214"], ["70491.30", "0.206"], ["70493.20", "0.006"], ["70493.50", "0.265"], ["70493.60", "0.514"], ["70495.00", "0.176"], ["70495.10", "0.065"], ["70496.00", "0.000"], ["70498.20", "0.009"], ["70499.20", "0.071"], ["70499.70", "0.000"], ["70500.10", "0.114"], ["70500.30", "0.001"], ["70500.40", "0.029"], ["70500.60", "0.007"], ["70501.00", "0.000"], ["70501.20", "0.000"], ["70501.30", "0.001"], ["70501.40", "0.000"], ["70501.70", "0.002"], ["70501.80", "0.003"], ["70501.90", "0.000"], ["70502.10", "0.000"], ["70502.40", "0.008"], ["70503.00", "0.000"], ["70503.50", "0.006"], ["70503.60", "2.828"]], "a": [["70503.70", "14.859"], ["70503.80", "0.059"], ["70504.20", "0.000"], ["70504.30", "0.105"], ["70504.40", "0.003"], ["70504.50", "0.005"], ["70504.80", "0.003"], ["70505.20", "0.003"], ["70505.60", "0.026"], ["70505.70", "0.003"], ["70505.80", "0.023"], ["70506.60", "0.001"], ["70506.80", "0.010"], ["70507.20", "0.060"], ["70507.60", "0.004"], ["70507.70", "0.001"], ["70508.00", "0.210"], ["70508.10", "0.316"], ["70508.70", "0.321"], ["70508.90", "1.847"], ["70509.40", "0.001"], ["70510.50", "0.000"], ["70510.80", "0.003"], ["70512.20", "0.005"], ["70512.30", "0.004"], ["70512.60", "0.043"], ["70513.30", "0.000"], ["70513.70", "0.003"], ["70513.80", "0.000"], ["70514.20", "0.000"], ["70516.00", "0.697"], ["70516.70", "0.036"], ["70516.80", "0.074"], ["70517.10", "0.005"], ["70518.60", "0.002"], ["70519.80", "0.451"], ["70521.00", "0.044"], ["70525.00", "0.547"], ["70526.10", "0.000"], ["70526.70", "0.012"], ["70527.60", "0.006"], ["70528.70", "0.981"], ["70530.00", "0.394"], ["70533.30", "0.012"], ["70537.30", "0.021"], ["70538.50", "0.005"], ["70541.60", "0.079"], ["70542.50", "0.362"], ["70543.20", "0.994"], ["70554.70", "0.194"], ["70555.40", "0.286"], ["70558.80", "0.034"], ["70560.20", "0.005"], ["70564.00", "0.219"], ["70579.00", "0.143"], ["70594.10", "0.005"], ["70599.30", "0.245"], ["70602.20", "0.965"], ["70627.10", "0.000"], ["70629.40", "0.095"], ["70630.60", "0.002"], ["70633.40", "0.441"], ["70634.60", "10.204"], ["70727.10", "0.009"], ["71058.90", "0.002"], ["71208.70", "4.206"], ["74059.30", "0.002"], ["77554.10", "0.000"], ["89523.20", "0.000"]]}}
{"local_ts": 1773485496808, "server_ts": 1773485496018, "data": {"e": "depthUpdate", "E": 1773485496019, "T": 1773485496018, "s": "BTCUSDT", "U": 10109451682517, "u": 10109451689062, "pu": 10109451682448, "b": [["5000.00", "101.418"], ["7050.40", "0.056"], ["20103.60", "1.230"], ["20203.60", "1.770"], ["20204.20", "0.000"], ["20204.30", "0.000"], ["20207.10", "0.000"], ["20208.10", "0.000"], ["20208.60", "0.000"], ["61186.90", "0.000"], ["63453.20", "0.002"], ["66973.20", "0.007"], ["69482.20", "0.000"], ["69798.60", "6.653"], ["70123.10", "0.265"], ["70151.10", "0.392"], ["70371.00", "0.002"], ["70431.20", "0.412"], ["70445.30", "0.011"], ["70448.60", "0.001"], ["70448.70", "0.182"], ["70456.40", "0.004"], ["70457.50", "0.939"], ["70482.30", "0.596"], ["70483.20", "0.021"], ["70485.10", "1.208"], ["70488.20", "0.001"], ["70489.60", "0.103"]], "a": [["70503.70", "15.586"], ["70505.80", "0.012"], ["70507.40", "0.006"], ["70518.70", "0.445"], ["70519.40", "0.080"], ["70528.60", "0.586"], ["70531.60", "0.003"], ["70533.30", "0.012"], ["70537.30", "0.014"], ["70547.40", "0.083"], ["70549.90", "9.060"], ["70551.90", "0.111"], ["70560.40", "1.810"], ["70572.40", "0.343"], ["70586.50", "0.071"], ["70638.20", "0.202"], ["70638.30", "0.048"], ["71208.70", "4.206"], ["71405.00", "2.097"], ["77554.10", "0.000"], ["89523.20", "0.000"]]}}
{"local_ts": 1773485497831, "server_ts": 1773485497040, "data": {"e": "depthUpdate", "E": 1773485497041, "T": 1773485497040, "s": "BTCUSDT", "U": 10109451746682, "u": 10109451752341, "pu": 10109451746546, "b": [["1000.00", "28.842"], ["5000.00", "101.418"], ["7050.40", "0.056"], ["20003.60", "0.780"], ["20103.60", "2.220"], ["33000.00", "3.789"], ["59364.00", "3.000"], ["68503.60", "0.005"], ["69255.00", "5.385"], ["69466.40", "2.731"], ["69472.70", "0.876"], ["69640.80", "0.719"], ["69798.60", "6.653"], ["69939.60", "0.430"], ["70151.10", "0.392"], ["70151.20", "0.004"], ["70262.90", "0.004"], ["70353.30", "3.184"], ["70448.60", "0.001"], ["70448.70", "0.097"], ["70448.80", "1.026"], ["70454.90", "0.010"], ["70458.10", "0.593"], ["70461.90", "0.086"], ["70481.00", "0.142"], ["70481.70", "0.847"], ["70490.90", "0.010"], ["70496.50", "0.007"]], "a": [["70503.70", "15.624"], ["70506.10", "0.026"], ["70510.60", "0.003"], ["70516.40", "0.228"], ["70531.40", "0.904"], ["70532.80", "0.018"], ["70532.90", "0.004"], ["70533.00", "0.092"], ["70535.80", "0.785"], ["70537.90", "0.042"], ["70574.80", "0.397"], ["70626.50", "1.304"], ["70727.30", "0.000"], ["70900.00", "12.446"], ["71208.70", "4.206"], ["71877.50", "0.000"], ["74037.60", "0.002"], ["74044.40", "0.009"], ["89523.20", "0.000"]]}}
{"local_ts": 1773485498853, "server_ts": 1773485498062, "data": {"e": "depthUpdate", "E": 1773485498063, "T": 1773485498062, "s": "BTCUSDT", "U": 10109451813199, "u": 10109451820793, "pu": 10109451813182, "b": [["1000.00", "28.842"], ["5000.00", "101.438"], ["7050.40", "0.056"], ["20003.60", "2.580"], ["20103.60", "0.040"], ["20403.60", "0.380"], ["56403.00", "0.000"], ["66964.60", "0.002"], ["66973.50", "0.000"], ["66978.40", "0.002"], ["69219.00", "0.577"], ["69498.80", "0.858"], ["70320.30", "0.455"], ["70323.80", "0.162"], ["70400.50", "0.142"], ["70448.00", "2.559"], ["70490.90", "0.006"]], "a": [["70503.70", "14.994"], ["70516.40", "0.009"], ["70532.60", "1.420"], ["70532.70", "0.087"], ["70542.50", "0.203"], ["70547.00", "0.633"], ["70615.10", "0.000"], ["70617.90", "0.002"], ["70620.40", "0.386"], ["71208.70", "4.206"], ["89523.20", "0.000"]]}}
{"local_ts": 1773485499876, "server_ts": 1773485499085, "data": {"e": "depthUpdate", "E": 1773485499087, "T": 1773485499085, "s": "BTCUSDT", "U": 10109451874123, "u": 10109451881328, "pu": 10109451873979, "b": [["1000.00", "28.842"], ["5000.00", "101.418"], ["7050.40", "0.028"], ["20003.60", "0.310"], ["20303.60", "0.210"], ["20403.60", "2.480"], ["66960.30", "0.000"], ["69093.60", "0.024"], ["69375.50", "5.467"], ["69481.30", "24.577"], ["69657.60", "4.241"], ["69798.60", "6.653"], ["69939.60", "0.501"], ["70151.10", "0.392"], ["70433.10", "0.081"], ["70438.80", "0.000"], ["70448.30", "0.101"], ["70448.40", "0.340"], ["70455.30", "0.511"], ["70456.50", "0.004"], ["70457.10", "0.004"], ["70471.90", "0.395"], ["70475.40", "0.212"], ["70477.30", "0.002"], ["70479.20", "0.104"], ["70479.30", "0.022"], ["70484.30", "0.005"], ["70484.80", "0.000"], ["70486.10", "0.000"], ["70487.40", "0.144"], ["70487.90", "0.003"], ["70489.60", "0.096"], ["70489.70", "0.000"], ["70489.80", "0.063"], ["70490.90", "0.006"], ["70493.60", "0.571"], ["70493.80", "0.005"], ["70496.00", "0.021"], ["70496.60", "0.028"], ["70496.90", "0.286"], ["70499.80", "0.042"], ["70501.30", "0.001"], ["70503.60", "0.887"]], "a": [["70503.70", "15.847"], ["70504.60", "0.021"], ["70504.90", "0.000"], ["70507.10", "0.002"], ["70508.00", "0.204"], ["70508.90", "1.765"], ["70510.70", "0.003"], ["70515.10", "0.002"], ["70515.80", "0.362"], ["70516.40", "0.009"], ["70520.70", "0.068"], ["70520.80", "1.005"], ["70521.70", "0.637"], ["70521.80", "0.372"], ["70521.90", "0.002"], ["70522.20", "0.512"], ["70522.70", "0.514"], ["70522.80", "0.345"], ["70523.50", "0.013"], ["70524.40", "0.006"], ["70524.50", "0.007"], ["70532.50", "0.665"], ["70532.60", "1.415"], ["70532.70", "0.002"], ["70540.50", "0.064"], ["70540.60", "0.002"], ["70548.50", "0.005"], ["70548.60", "0.002"], ["70555.30", "0.175"], ["70556.50", "0.036"], ["70556.60", "0.003"], ["70557.20", "1.262"], ["70576.10", "0.002"], ["70619.50", "0.079"], ["70622.50", "0.159"], ["70626.30", "0.171"], ["71208.70", "4.206"], ["71526.00", "19.685"], ["71596.50", "6.222"], ["71667.00", "1.950"], ["89523.20", "0.000"]]}}
{"local_ts": 1773485500898, "server_ts": 1773485500108, "data": {"e": "depthUpdate", "E": 1773485500109, "T": 1773485500108, "s": "BTCUSDT", "U": 10109451925164, "u": 10109451930877, "pu": 10109451924976, "b": [["1000.00", "28.842"], ["5000.00", "101.418"], ["7050.40", "0.028"], ["20203.60", "0.060"], ["20303.60", "2.340"], ["20403.60", "0.600"], ["33000.00", "3.785"], ["66952.60", "0.023"], ["66978.00", "0.000"], ["69093.60", "0.018"], ["69466.40", "1.725"], ["69798.60", "6.653"], ["69939.60", "0.501"], ["70430.90", "0.038"], ["70433.10", "0.081"], ["70447.50", "0.088"], ["70447.60", "0.018"], ["70447.70", "0.002"], ["70447.80", "0.002"], ["70457.10", "0.006"], ["70457.20", "0.004"], ["70468.40", "0.049"], ["70471.80", "1.417"], ["70471.90", "0.259"], ["70472.80", "0.085"], ["70475.30", "0.231"], ["70479.50", "0.149"], ["70481.00", "0.248"], ["70486.00", "0.604"], ["70489.40", "0.059"], ["70490.90", "0.006"], ["70493.00", "0.148"], ["70496.60", "0.000"], ["70502.30", "0.009"], ["70502.70", "0.003"], ["70503.50", "0.085"], ["70503.60", "1.626"]], "a": [["70503.70", "15.693"], ["70504.30", "0.000"], ["70505.50", "0.005"], ["70507.50", "0.004"], ["70508.70", "0.212"], ["70509.40", "0.022"], ["70510.70", "0.003"], ["70515.80", "0.221"], ["70516.40", "0.009"], ["70516.60", "0.150"], ["70521.00", "0.004"], ["70521.80", "0.392"], ["70531.70", "0.148"], ["70531.90", "0.211"], ["70532.30", "0.022"], ["70542.50", "0.362"], ["70563.60", "2.722"], ["71067.70", "0.494"], ["71208.70", "3.505"], ["71349.70", "1.959"], ["71408.30", "21.675"], ["71483.70", "6.422"], ["71822.10", "0.834"], ["71919.00", "0.003"], ["74055.70", "0.005"], ["89523.20", "0.000"]]}}
{"local_ts": 1773485501922, "server_ts": 1773485501130, "data": {"e": "depthUpdate", "E": 1773485501131, "T": 1773485501130, "s": "BTCUSDT", "U": 10109451970877, "u": 10109451975405, "pu": 10109451970853, "b": [["5000.00", "101.418"], ["7050.40", "0.028"], ["20203.60", "2.010"], ["20303.60", "0.990"], ["69093.60", "0.021"], ["69798.60", "5.938"], ["70151.20", "0.000"], ["70257.80", "0.011"], ["70431.00", "0.093"], ["70433.10", "0.081"], ["70457.10", "0.006"], ["70457.40", "0.266"], ["70460.40", "0.511"], ["70464.80", "0.260"], ["70472.70", "0.397"], ["70475.10", "0.038"], ["70486.00", "0.740"], ["70490.90", "0.006"], ["70496.60", "0.032"], ["70498.30", "0.106"], ["70498.60", "0.028"], ["70500.40", "0.024"], ["70503.50", "0.007"], ["70503.60", "1.640"]], "a": [["70503.70", "15.111"], ["70504.90", "0.002"], ["70510.70", "0.003"], ["70516.40", "0.009"], ["70522.20", "0.045"], ["70535.60", "0.110"], ["70542.50", "0.362"], ["70543.00", "0.271"], ["70543.10", "0.000"], ["71138.20", "6.322"], ["71208.70", "7.712"], ["71421.90", "1.217"], ["74037.10", "0.002"], ["89523.20", "0.000"]]}}
{"local_ts": 1773485502945, "server_ts": 1773485502150, "data": {"e": "depthUpdate", "E": 1773485502151, "T": 1773485502150, "s": "BTCUSDT", "U": 10109452012245, "u": 10109452016723, "pu": 10109452012237, "b": [["1000.00", "28.842"], ["5000.00", "101.418"], ["7050.40", "0.000"], ["20103.60", "1.560"], ["20203.60", "1.440"], ["33000.00", "3.785"], ["56403.00", "0.000"], ["66969.60", "0.006"], ["69234.40", "0.147"], ["69340.30", "3.024"], ["69798.60", "5.938"], ["70151.10", "0.392"], ["70426.50", "0.871"], ["70431.00", "0.008"], ["70434.50", "0.139"], ["70442.40", "0.005"], ["70450.50", "0.005"], ["70457.10", "0.004"], ["70457.20", "0.006"], ["70458.30", "0.024"], ["70458.40", "0.019"], ["70468.40", "0.050"], ["70472.70", "0.213"], ["70490.90", "0.006"], ["70491.90", "0.210"], ["70492.40", "0.005"], ["70496.60", "0.000"], ["70502.10", "0.008"], ["70502.20", "0.057"], ["70502.60", "0.035"]], "a": [["70503.70", "15.053"], ["70503.90", "0.000"], ["70504.60", "0.000"], ["70506.60", "0.001"], ["70509.40", "0.001"], ["70510.70", "0.003"], ["70516.40", "0.009"], ["70527.80", "0.043"], ["70535.60", "0.025"], ["70543.00", "0.087"], ["71208.70", "7.712"], ["71267.30", "4.215"], ["71490.70", "0.067"], ["71773.00", "0.163"], ["74051.20", "0.002"], ["89523.20", "0.000"]]}}
{"local_ts": 1773485503964, "server_ts": 1773485503172, "data": {"e": "depthUpdate", "E": 1773485503173, "T": 1773485503172, "s": "BTCUSDT", "U": 10109452061142, "u": 10109452064086, "pu": 10109452061018, "b": [["5000.00", "101.418"], ["7050.40", "0.000"], ["20003.60", "1.120"], ["20103.60", "1.880"], ["69180.70", "0.000"], ["69230.90", "1.660"], ["69572.10", "0.000"], ["69657.60", "5.387"], ["69678.70", "2.908"], ["69798.60", "5.940"], ["70290.50", "0.511"], ["70457.20", "0.006"], ["70457.50", "0.002"], ["70472.70", "0.213"], ["70496.60", "0.032"]], "a": [["70503.70", "10.667"], ["70510.70", "0.003"], ["70543.00", "0.002"], ["70549.50", "1.014"], ["70559.30", "0.205"], ["70568.40", "0.007"], ["71208.70", "7.712"], ["71492.40", "1.216"], ["71504.90", "4.716"], ["71703.90", "1.214"], ["73314.80", "0.000"], ["74056.10", "0.002"], ["89523.20", "0.000"]]}}
{"local_ts": 1773485504984, "server_ts": 1773485504192, "data": {"e": "depthUpdate", "E": 1773485504193, "T": 1773485504192, "s": "BTCUSDT", "U": 10109452103501, "u": 10109452107589, "pu": 10109452103415, "b": [["1000.00", "28.842"], ["5000.00", "101.418"], ["7050.40", "0.000"], ["20003.60", "2.330"], ["20103.60", "0.000"], ["20403.60", "0.670"], ["33000.00", "3.789"], ["66949.30", "0.002"], ["66953.60", "0.000"], ["66958.00", "0.000"], ["69114.70", "0.477"], ["69550.10", "1.456"], ["69786.90", "4.508"], ["69798.60", "5.942"], ["69798.70", "0.004"], ["70151.10", "0.392"], ["70258.10", "0.000"], ["70316.80", "0.159"], ["70323.80", "0.162"], ["70337.90", "0.645"], ["70352.90", "0.000"], ["70353.30", "1.417"], ["70411.40", "0.000"], ["70413.00", "1.278"], ["70413.20", "0.003"], ["70426.00", "0.025"], ["70430.90", "0.123"], ["70440.10", "0.003"], ["70446.40", "0.017"], ["70448.00", "0.815"], ["70453.20", "0.000"], ["70460.40", "0.515"], ["70467.70", "0.072"], ["70468.90", "0.742"], ["70472.20", "0.016"], ["70472.30", "0.555"], ["70480.50", "0.007"], ["70496.60", "0.032"], ["70501.20", "0.002"], ["70503.50", "0.066"]], "a": [["70503.70", "10.714"], ["70510.70", "0.003"], ["70531.90", "0.211"], ["70535.80", "0.464"], ["70537.50", "0.268"], ["70539.00", "0.456"], ["70542.50", "0.443"], ["70557.20", "0.951"], ["70558.80", "0.037"], ["70567.20", "0.281"], ["70581.30", "2.233"], ["70592.40", "1.535"], ["70594.20", "0.152"], ["70651.50", "1.312"], ["70653.80", "0.090"], ["70856.20", "0.922"], ["71208.70", "7.712"], ["71381.30", "0.141"], ["71421.90", "2.615"], ["71465.90", "1.643"], ["71478.80", "0.010"], ["89523.20", "0.000"]]}}
{"local_ts": 1773485506008, "server_ts": 1773485505216, "data": {"e": "depthUpdate", "E": 1773485505217, "T": 1773485505216, "s": "BTCUSDT", "U": 10109452152227, "u": 10109452157671, "pu": 10109452152219, "b": [["1000.00", "28.842"], ["5000.00", "101.418"], ["7050.40", "0.056"], ["20003.60", "0.090"], ["20303.60", "0.320"], ["20403.60", "2.590"], ["56403.00", "0.000"], ["66974.90", "0.000"], ["69288.30", "2.168"], ["69446.00", "0.207"], ["69516.00", "4.368"], ["69601.20", "0.007"], ["69798.60", "8.085"], ["69798.70", "0.004"], ["69832.00", "1.818"], ["69857.40", "4.289"], ["70257.70", "0.000"], ["70320.30", "0.614"], ["70323.80", "0.162"], ["70401.30", "0.014"], ["70403.10", "0.611"], ["70408.30", "0.026"], ["70410.10", "0.000"], ["70415.30", "0.071"], ["70415.40", "0.484"], ["70417.20", "0.002"], ["70422.40", "0.075"], ["70466.30", "0.015"], ["70471.10", "0.000"], ["70471.90", "0.062"], ["70474.50", "0.011"], ["70475.20", "0.263"], ["70476.80", "0.264"], ["70477.30", "0.002"], ["70477.40", "0.004"], ["70478.00", "0.547"], ["70478.10", "0.003"], ["70479.90", "0.085"], ["70480.20", "0.513"], ["70480.70", "0.528"], ["70480.90", "0.007"], ["70481.60", "0.002"], ["70482.60", "0.593"], ["70486.80", "0.006"], ["70487.40", "0.023"], ["70488.60", "0.011"], ["70489.00", "0.750"], ["70489.50", "0.015"], ["70491.30", "0.260"], ["70493.50", "0.009"], ["70494.80", "0.046"], ["70495.10", "0.012"], ["70495.50", "0.005"], ["70503.40", "0.216"], ["70503.60", "3.081"]], "a": [["70503.70", "8.078"], ["70505.60", "0.002"], ["70508.00", "0.204"], ["70511.50", "0.028"], ["70512.40", "0.057"], ["70512.60", "0.043"], ["70513.40", "0.024"], ["70515.00", "0.068"], ["70516.20", "0.028"], ["70518.10", "0.652"], ["70518.50", "0.000"], ["70521.20", "0.002"], ["70522.10", "0.012"], ["70526.90", "0.073"], ["70529.30", "0.079"], ["70534.80", "0.278"], ["70534.90", "0.002"], ["70535.40", "0.322"], ["70535.50", "0.008"], ["70535.60", "0.087"], ["70542.50", "0.443"], ["70544.00", "0.338"], ["70554.40", "0.514"], ["70580.80", "0.002"], ["70586.50", "0.071"], ["70587.90", "0.383"], ["70593.60", "0.116"], ["70594.90", "0.511"], ["70600.60", "0.168"], ["70610.60", "0.014"], ["70727.10", "0.002"], ["71208.50", "0.007"], ["71208.70", "8.413"], ["71208.90", "0.007"], ["71406.40", "0.007"], ["71913.70", "0.083"], ["89523.20", "0.000"]]}}
{"local_ts": 1773485507029, "server_ts": 1773485506232, "data": {"e": "depthUpdate", "E": 1773485506237, "T": 1773485506232, "s": "BTCUSDT", "U": 10109452197763, "u": 10109452201693, "pu": 10109452197738, "b": [["5000.00", "101.418"], ["7050.40", "0.056"], ["20203.60", "0.160"], ["20303.60", "2.450"], ["20403.60", "0.390"], ["69093.60", "0.024"], ["69502.40", "2.860"], ["69551.80", "2.798"], ["69798.60", "7.376"], ["70320.30", "0.614"], ["70370.20", "0.445"], ["70448.10", "0.257"], ["70456.40", "0.002"], ["70456.50", "0.004"], ["70459.90", "0.213"]], "a": [["70503.70", "8.047"], ["70509.40", "0.001"], ["70526.60", "0.000"], ["70527.40", "0.012"], ["70635.30", "0.002"], ["71200.00", "10.945"], ["71208.70", "8.413"], ["71667.00", "3.901"], ["71913.70", "0.107"], ["72212.20", "1.234"], ["74047.20", "0.016"], ["74054.10", "0.000"]]}}
{"local_ts": 1773485508049, "server_ts": 1773485507256, "data": {"e": "depthUpdate", "E": 1773485507259, "T": 1773485507256, "s": "BTCUSDT", "U": 10109452237460, "u": 10109452241691, "pu": 10109452237424, "b": [["1000.00", "28.842"], ["5000.00", "101.418"], ["7050.40", "0.056"], ["20103.60", "0.020"], ["20203.60", "2.290"], ["20303.60", "0.690"], ["66943.30", "0.000"], ["69093.60", "0.027"], ["69434.40", "5.276"], ["69439.80", "0.862"], ["69798.00", "2.156"], ["69798.60", "10.953"], ["69833.90", "0.004"], ["70151.10", "0.392"], ["70257.60", "0.004"], ["70408.30", "0.026"], ["70415.30", "6.386"], ["70422.40", "0.075"], ["70483.80", "0.076"], ["70484.20", "0.016"], ["70485.00", "0.152"], ["70485.10", "0.010"], ["70485.40", "1.021"], ["70486.90", "0.020"], ["70492.90", "0.645"], ["70494.30", "0.003"]], "a": [["70503.70", "6.204"], ["70528.50", "0.521"], ["70530.90", "0.005"], ["70533.80", "0.000"], ["70584.90", "0.071"], ["70585.00", "0.011"], ["70592.00", "0.073"], ["70592.10", "0.005"], ["70599.00", "0.077"], ["70599.10", "0.043"], ["70727.30", "0.000"], ["71208.70", "8.413"], ["74031.80", "0.002"]]}}
{"local_ts": 1773485509074, "server_ts": 1773485508278, "data": {"e": "depthUpdate", "E": 1773485508279, "T": 1773485508278, "s": "BTCUSDT", "U": 10109452279480, "u": 10109452283277, "pu": 10109452279404, "b": [["5000.00", "101.418"], ["7050.40", "0.028"], ["20103.60", "1.880"], ["20203.60", "1.120"], ["66977.80", "0.000"], ["69499.80", "3.594"], ["69554.40", "1.445"], ["69798.60", "10.953"], ["70151.20", "0.004"], ["70257.70", "0.000"], ["70471.90", "0.451"]], "a": [["70503.70", "6.142"], ["70529.90", "0.092"], ["70530.10", "0.535"], ["70547.90", "0.002"], ["71208.70", "8.415"], ["71913.70", "0.107"]]}}
{"local_ts": 1773485510091, "server_ts": 1773485509296, "data": {"e": "depthUpdate", "E": 1773485509299, "T": 1773485509296, "s": "BTCUSDT", "U": 10109452316385, "u": 10109452320889, "pu": 10109452316302, "b": [["1000.00", "28.842"], ["5000.00", "101.418"], ["7050.40", "0.028"], ["20003.60", "1.430"], ["20103.60", "1.570"], ["33000.00", "3.785"], ["69412.20", "4.317"], ["69798.60", "10.953"], ["70151.10", "0.356"], ["70151.20", "0.004"], ["70257.50", "0.243"], ["70290.30", "0.004"], ["70348.30", "0.432"], ["70348.50", "0.593"], ["70350.80", "0.000"], ["70352.10", "0.092"], ["70352.80", "0.080"], ["70353.60", "0.000"], ["70355.40", "0.041"], ["70356.10", "0.173"], ["70357.00", "0.094"], ["70357.10", "0.102"], ["70358.90", "0.646"], ["70360.50", "3.955"], ["70362.80", "0.092"], ["70364.50", "0.092"], ["70411.20", "0.000"], ["70424.10", "0.000"], ["70456.50", "0.002"], ["70456.60", "0.012"], ["70475.30", "0.282"], ["70484.50", "0.858"], ["70485.40", "0.511"], ["70491.80", "0.638"], ["70492.90", "0.007"], ["70501.90", "0.008"]], "a": [["70503.70", "6.110"], ["70504.20", "0.002"], ["70508.20", "0.000"], ["70530.20", "0.007"], ["70530.30", "0.004"], ["70530.50", "0.089"], ["70539.60", "1.670"], ["70547.90", "0.002"], ["70757.40", "0.190"], ["71208.60", "0.009"], ["71208.70", "8.413"], ["74037.60", "0.002"], ["74060.10", "0.000"]]}}
{"local_ts": 1773485511108, "server_ts": 1773485510316, "data": {"e": "depthUpdate", "E": 1773485510319, "T": 1773485510316, "s": "BTCUSDT", "U": 10109452409956, "u": 10109452418333, "pu": 10109452409775, "b": [["1000.00", "28.842"], ["5000.00", "101.418"], ["7050.40", "0.028"], ["20003.60", "2.020"], ["20403.60", "0.980"], ["68388.40", "0.000"], ["69798.60", "10.953"], ["69798.70", "0.000"], ["70257.60", "0.008"], ["70408.30", "0.008"], ["70412.70", "0.018"], ["70415.30", "6.315"], ["70419.70", "0.273"], ["70422.40", "0.004"], ["70426.80", "0.692"], ["70436.50", "0.002"], ["70440.10", "0.003"], ["70446.90", "0.305"], ["70472.80", "0.184"], ["70483.20", "0.162"], ["70484.30", "0.010"], ["70485.70", "0.164"], ["70486.40", "1.205"], ["70486.70", "0.096"], ["70487.70", "0.004"], ["70490.00", "0.532"], ["70501.30", "0.058"], ["70501.40", "0.003"], ["70503.60", "4.321"]], "a": [["70503.70", "2.968"], ["70504.90", "0.000"], ["70505.70", "0.027"], ["70506.30", "0.002"], ["70510.70", "0.003"], ["70539.00", "0.494"], ["70542.50", "0.284"], ["70561.90", "0.000"], ["70563.20", "0.285"], ["70584.70", "0.000"], ["70589.00", "0.086"], ["70591.80", "0.000"], ["70596.10", "0.158"], ["70598.80", "0.000"], ["70603.10", "0.071"], ["71208.70", "8.413"], ["71349.70", "7.976"], ["71420.60", "0.000"], ["71451.70", "0.924"], ["72211.80", "2.372"], ["72338.50", "0.004"], ["74040.20", "0.002"], ["74049.90", "0.000"]]}}
{"local_ts": 1773485512128, "server_ts": 1773485511338, "data": {"e": "depthUpdate", "E": 1773485511339, "T": 1773485511338, "s": "BTCUSDT", "U": 10109452466957, "u": 10109452472922, "pu": 10109452466649, "b": [["5000.00", "101.418"], ["7050.40", "0.000"], ["20003.60", "0.000"], ["20303.60", "0.530"], ["20403.60", "2.470"], ["33000.00", "3.789"], ["66950.20", "0.000"], ["69798.60", "10.953"], ["69869.10", "17.867"], ["70370.50", "0.000"], ["70370.60", "0.844"], ["70426.00", "0.022"], ["70440.10", "0.000"], ["70475.30", "0.229"], ["70489.40", "0.059"], ["70500.90", "0.003"]], "a": [["70503.70", "3.012"], ["70506.20", "0.003"], ["70524.90", "0.515"], ["70544.40", "0.002"], ["70567.20", "0.278"], ["70581.30", "2.230"], ["70635.30", "0.002"], ["70635.40", "0.533"], ["71208.70", "8.413"]]}}
{"local_ts": 1773485513131, "server_ts": 1773485512256, "data": {"e": "depthUpdate", "E": 1773485512257, "T": 1773485512256, "s": "BTCUSDT", "U": 10109452510181, "u": 10109452514993, "pu": 10109452510161, "b": [["5000.00", "101.418"], ["7050.40", "0.056"], ["20203.60", "0.180"], ["20303.60", "2.470"], ["20403.60", "0.350"], ["69798.60", "10.953"], ["69804.00", "0.933"], ["69911.90", "0.000"], ["70151.20", "0.004"], ["70323.00", "0.523"], ["70357.00", "12.783"], ["70357.30", "0.000"], ["70415.90", "6.633"], ["70451.10", "3.468"], ["70457.20", "0.008"], ["70457.50", "0.004"], ["70467.40", "0.000"], ["70472.40", "2.604"], ["70475.30", "0.282"], ["70479.40", "1.097"], ["70484.30", "0.073"], ["70485.30", "0.007"], ["70489.40", "0.006"]], "a": [["70503.70", "2.535"], ["70519.40", "0.271"], ["70524.70", "0.003"], ["70540.10", "2.292"], ["70560.40", "0.989"], ["70561.30", "3.343"], ["70595.00", "1.640"], ["70596.20", "6.287"], ["70651.50", "2.952"], ["70652.40", "0.000"], ["70654.20", "12.006"], ["70669.80", "2.041"], ["71208.70", "8.498"], ["71328.60", "1.679"], ["71567.90", "0.419"], ["71913.70", "0.089"], ["74054.10", "0.000"], ["89523.20", "0.000"]]}}
{"local_ts": 1773485514177, "server_ts": 1773485513376, "data": {"e": "depthUpdate", "E": 1773485513379, "T": 1773485513376, "s": "BTCUSDT", "U": 10109452563174, "u": 10109452566997, "pu": 10109452563142, "b": [["5000.00", "101.418"], ["7050.40", "0.000"], ["20103.60", "0.120"], ["20203.60", "2.390"], ["20303.60", "0.490"], ["33000.00", "3.789"], ["66970.60", "0.000"], ["69093.60", "0.033"], ["69798.60", "10.953"], ["69798.70", "0.000"], ["70151.10", "0.396"], ["70412.20", "0.532"], ["70412.30", "0.002"], ["70419.20", "0.384"], ["70419.30", "0.563"], ["70426.30", "0.071"], ["70426.40", "0.353"], ["70457.20", "0.004"], ["70457.40", "0.306"], ["70459.20", "0.004"], ["70467.40", "0.004"], ["70473.30", "0.000"], ["70473.40", "0.089"], ["70475.30", "0.229"], ["70478.50", "0.255"], ["70480.30", "0.007"], ["70486.00", "0.204"], ["70489.40", "0.059"], ["70490.80", "0.024"], ["70492.50", "0.071"], ["70493.00", "0.012"], ["70493.20", "0.641"], ["70494.40", "0.218"], ["70495.60", "0.000"], ["70496.10", "0.346"], ["70496.60", "0.047"], ["70503.60", "4.761"]], "a": [["70503.70", "1.865"], ["70505.70", "0.030"], ["70510.30", "0.060"], ["70514.30", "0.123"], ["70514.50", "0.061"], ["70514.70", "0.007"], ["70518.80", "0.024"], ["70547.50", "0.058"], ["70588.60", "0.071"], ["70588.70", "0.092"], ["70595.70", "0.071"], ["70595.80", "0.085"], ["70602.70", "0.074"], ["70602.80", "0.126"], ["71161.60", "2.272"], ["71208.70", "8.413"], ["73525.60", "0.000"], ["74055.40", "0.002"]]}}
{"local_ts": 1773485515193, "server_ts": 1773485514400, "data": {"e": "depthUpdate", "E": 1773485514401, "T": 1773485514400, "s": "BTCUSDT", "U": 10109452614501, "u": 10109452625770, "pu": 10109452614048, "b": [["1000.00", "28.842"], ["5000.00", "101.438"], ["7050.40", "0.000"], ["20103.60", "2.180"], ["20203.60", "0.820"], ["66963.90", "0.002"], ["68956.70", "0.623"], ["69509.50", "2.082"], ["69798.60", "9.522"], ["69798.70", "0.000"], ["70151.10", "0.392"], ["70151.20", "0.004"], ["70450.70", "0.808"], ["70454.20", "0.097"], ["70462.80", "0.393"], ["70469.20", "0.129"], ["70497.90", "0.013"], ["70502.50", "0.002"], ["70502.70", "0.005"]], "a": [["70509.30", "0.000"], ["70509.70", "0.016"], ["70510.20", "0.018"], ["70518.70", "0.003"], ["71208.70", "7.712"], ["72971.20", "0.012"]]}}
{"local_ts": 1773485516216, "server_ts": 1773485515420, "data": {"e": "depthUpdate", "E": 1773485515425, "T": 1773485515420, "s": "BTCUSDT", "U": 10109452683305, "u": 10109452688397, "pu": 10109452683165, "b": [["1000.00", "28.842"], ["5000.00", "101.418"], ["7050.40", "0.056"], ["20003.60", "1.740"], ["20103.60", "1.260"], ["66955.00", "0.006"], ["66978.20", "0.002"], ["66978.40", "0.008"], ["66978.50", "0.010"], ["69439.30", "1.725"], ["69448.00", "0.256"], ["69798.60", "8.807"], ["70412.00", "0.285"], ["70419.00", "0.267"], ["70426.10", "0.114"], ["70453.90", "2.286"], ["70473.30", "1.826"], ["70496.10", "0.451"]], "a": [["70506.10", "0.005"], ["70508.90", "1.747"], ["70509.60", "0.013"], ["70513.30", "0.003"], ["70515.80", "0.107"], ["70520.50", "0.049"], ["70536.90", "0.104"], ["70551.10", "0.060"], ["70588.40", "1.440"], ["70595.50", "0.071"], ["70602.50", "0.071"], ["70736.40", "0.000"], ["71208.70", "6.310"], ["71725.50", "12.881"], ["73323.80", "0.059"]]}}
{"local_ts": 1773485517240, "server_ts": 1773485516440, "data": {"e": "depthUpdate", "E": 1773485516445, "T": 1773485516440, "s": "BTCUSDT", "U": 10109452730615, "u": 10109452735410, "pu": 10109452730445, "b": [["5000.00", "101.418"], ["7050.40", "0.056"], ["20003.60", "1.710"], ["20403.60", "1.290"], ["66962.60", "0.000"], ["69798.60", "8.807"], ["69812.70", "0.717"], ["69911.30", "0.075"], ["70177.20", "0.020"], ["70275.80", "0.000"], ["70452.10", "3.629"], ["70458.50", "0.010"], ["70458.60", "0.020"], ["70495.40", "0.195"]], "a": [["70516.40", "0.042"], ["70538.10", "0.320"], ["71208.70", "5.609"], ["74045.00", "0.176"], ["89523.20", "0.000"]]}}
{"local_ts": 1773485518257, "server_ts": 1773485517466, "data": {"e": "depthUpdate", "E": 1773485517467, "T": 1773485517466, "s": "BTCUSDT", "U": 10109452780305, "u": 10109452785286, "pu": 10109452780245, "b": [["1000.00", "28.842"], ["5000.00", "101.418"], ["7050.40", "0.028"], ["20303.60", "0.850"], ["20403.60", "2.150"], ["66944.90", "0.002"], ["66955.50", "0.008"], ["69587.10", "17.075"], ["69798.60", "9.352"], ["70151.10", "0.392"], ["70345.00", "0.045"], ["70371.00", "0.539"], ["70473.80", "0.195"], ["70493.00", "0.012"], ["70496.10", "0.454"]], "a": [["70511.20", "0.023"], ["70514.30", "0.123"], ["70519.00", "0.074"], ["70542.50", "0.284"], ["70583.80", "0.480"], ["70635.40", "0.003"], ["70635.50", "1.009"], ["71208.70", "7.011"], ["71507.50", "2.092"], ["89523.20", "0.000"]]}}
{"local_ts": 1773485519279, "server_ts": 1773485518488, "data": {"e": "depthUpdate", "E": 1773485518489, "T": 1773485518488, "s": "BTCUSDT", "U": 10109452832213, "u": 10109452837483, "pu": 10109452832105, "b": [["5000.00", "101.418"], ["7050.40", "0.028"], ["20203.60", "0.430"], ["20303.60", "2.550"], ["20403.60", "0.020"], ["33000.00", "3.785"], ["66972.50", "0.000"], ["67536.00", "0.002"], ["69502.40", "3.718"], ["70502.90", "0.004"]], "a": [["70517.30", "0.003"], ["70517.40", "0.062"], ["70521.30", "0.083"], ["70539.00", "0.598"], ["70547.50", "0.058"], ["71208.70", "7.011"], ["71288.90", "0.100"], ["71526.00", "24.433"], ["71757.40", "0.000"], ["74035.70", "0.002"], ["89523.20", "0.000"]]}}
{"local_ts": 1773485520298, "server_ts": 1773485519508, "data": {"e": "depthUpdate", "E": 1773485519509, "T": 1773485519508, "s": "BTCUSDT", "U": 10109452878006, "u": 10109452882038, "pu": 10109452877907, "b": [["1000.00", "28.842"], ["5000.00", "101.418"], ["7050.40", "0.028"], ["20103.60", "0.230"], ["20203.60", "2.500"], ["20303.60", "0.270"], ["66973.30", "0.004"], ["66978.40", "0.010"], ["69305.00", "6.747"], ["69798.60", "10.783"], ["69798.70", "0.000"], ["70151.10", "0.392"], ["70151.20", "0.004"], ["70332.00", "0.014"], ["70332.30", "3.322"], ["70371.00", "0.002"], ["70371.10", "0.537"], ["70405.80", "0.000"], ["70452.30", "0.008"], ["70458.30", "0.024"], ["70458.40", "0.016"], ["70462.60", "0.000"], ["70475.70", "0.008"], ["70493.00", "0.012"], ["70496.00", "0.031"], ["70503.60", "4.929"]], "a": [["70514.30", "0.126"], ["70517.60", "0.004"], ["70535.40", "0.057"], ["70539.00", "0.737"], ["70542.50", "0.284"], ["70635.50", "1.024"], ["70672.80", "0.129"], ["70674.20", "0.000"], ["70674.30", "3.315"], ["71173.50", "6.658"], ["71208.70", "8.413"], ["74033.50", "0.002"], ["89523.20", "0.000"]]}}
{"local_ts": 1773485521318, "server_ts": 1773485520528, "data": {"e": "depthUpdate", "E": 1773485520529, "T": 1773485520528, "s": "BTCUSDT", "U": 10109452927905, "u": 10109452935174, "pu": 10109452927796, "b": [["1000.00", "28.842"], ["5000.00", "101.418"], ["7050.40", "0.028"], ["20003.60", "0.070"], ["20103.60", "2.360"], ["20203.60", "0.570"], ["33000.00", "3.789"], ["56403.00", "0.004"], ["66950.10", "0.000"], ["66978.00", "0.020"], ["67683.50", "1.948"], ["69798.60", "10.785"], ["70290.80", "0.002"], ["70371.10", "0.668"], ["70402.90", "3.806"], ["70420.60", "0.253"], ["70458.30", "0.026"], ["70458.40", "0.014"], ["70469.90", "0.126"], ["70482.70", "0.060"], ["70493.00", "0.009"], ["70495.90", "0.008"], ["70496.60", "0.064"], ["70503.00", "0.000"], ["70503.20", "0.000"], ["70503.60", "4.751"]], "a": [["70503.70", "1.215"], ["70514.30", "0.123"], ["70520.10", "0.002"], ["70522.10", "0.005"], ["70522.20", "0.002"], ["70522.40", "0.034"], ["70536.80", "0.002"], ["70539.00", "0.737"], ["70539.40", "0.019"], ["70539.50", "0.988"], ["70546.30", "0.007"], ["70635.50", "1.003"], ["70856.20", "0.957"], ["70898.20", "2.205"], ["71208.70", "8.447"], ["71471.70", "0.907"], ["71483.70", "10.891"], ["71599.80", "0.627"], ["74045.80", "0.002"], ["89523.20", "0.000"]]}}
{"local_ts": 1773485522341, "server_ts": 1773485521550, "data": {"e": "depthUpdate", "E": 1773485521551, "T": 1773485521550, "s": "BTCUSDT", "U": 10109452995033, "u": 10109453000843, "pu": 10109452994916, "b": [["5000.00", "101.418"], ["7050.40", "0.000"], ["20003.60", "2.060"], ["20103.60", "0.940"], ["56403.00", "0.000"], ["66948.80", "0.002"], ["66952.50", "0.000"], ["67683.50", "1.950"], ["69798.60", "10.783"], ["69822.10", "1.000"], ["70448.20", "0.000"], ["70448.30", "0.016"], ["70448.40", "0.340"], ["70448.50", "0.088"], ["70478.50", "0.255"], ["70479.50", "0.010"], ["70493.30", "1.241"], ["70493.90", "0.013"]], "a": [["70503.70", "0.736"], ["70505.70", "0.003"], ["70505.80", "0.037"], ["70507.40", "0.000"], ["70514.30", "0.126"], ["70514.60", "0.000"], ["70515.90", "0.021"], ["70516.50", "0.003"], ["70517.80", "0.086"], ["70517.90", "0.037"], ["70518.00", "0.215"], ["70519.80", "0.002"], ["70519.90", "0.237"], ["70520.00", "0.069"], ["70520.10", "0.002"], ["70520.20", "0.002"], ["70520.30", "0.046"], ["70520.40", "0.548"], ["70520.50", "0.006"], ["70520.60", "0.007"], ["70520.70", "0.013"], ["70520.80", "1.003"], ["70520.90", "0.011"], ["70521.00", "0.019"], ["70521.30", "0.023"], ["70522.50", "0.015"], ["70531.40", "0.028"], ["70532.00", "0.006"], ["70532.10", "0.012"], ["70532.20", "0.159"], ["70532.40", "0.586"], ["70533.40", "0.227"], ["71208.70", "8.413"], ["71597.50", "0.000"], ["71913.70", "0.068"], ["89523.20", "0.000"]]}}
{"local_ts": 1773485523361, "server_ts": 1773485522568, "data": {"e": "depthUpdate", "E": 1773485522571, "T": 1773485522568, "s": "BTCUSDT", "U": 10109453045195, "u": 10109453050444, "pu": 10109453045147, "b": [["1000.00", "28.842"], ["5000.00", "101.418"], ["7050.40", "0.000"], ["20003.60", "1.390"], ["20403.60", "1.610"], ["33000.00", "3.789"], ["56403.00", "0.000"], ["69217.80", "3.608"], ["69798.60", "10.783"], ["70151.10", "1.524"], ["70191.80", "0.171"], ["70371.20", "0.657"], ["70458.10", "0.593"], ["70458.20", "0.021"], ["70474.50", "0.094"]], "a": [["70503.70", "2.419"], ["70513.20", "0.004"], ["70516.70", "0.252"], ["70517.00", "0.015"], ["70517.20", "0.003"], ["70527.90", "0.020"], ["70529.40", "0.035"], ["70531.90", "0.213"], ["70532.00", "0.091"], ["70533.00", "0.007"], ["70534.00", "0.248"], ["70549.50", "0.615"], ["70635.50", "0.975"], ["70750.50", "0.015"], ["71208.70", "8.413"], ["71400.00", "11.688"], ["71913.70", "0.074"], ["72634.80", "2.356"], ["74057.20", "0.002"], ["89523.20", "0.000"]]}}
{"local_ts": 1773485524386, "server_ts": 1773485523596, "data": {"e": "depthUpdate", "E": 1773485523597, "T": 1773485523596, "s": "BTCUSDT", "U": 10109453088669, "u": 10109453092128, "pu": 10109453088626, "b": [["5000.00", "101.398"], ["7050.40", "0.000"], ["20303.60", "1.180"], ["20403.60", "1.820"], ["56403.00", "0.000"], ["69097.70", "0.007"], ["69431.50", "0.000"], ["69499.90", "1.460"], ["69539.90", "0.000"], ["69798.60", "10.785"], ["70416.50", "0.614"], ["70427.00", "0.154"], ["70442.00", "0.080"], ["70451.80", "0.042"], ["70462.50", "0.003"]], "a": [["70503.70", "2.240"], ["70514.50", "0.025"], ["70517.00", "0.015"], ["70531.60", "0.003"], ["70539.80", "0.148"], ["70547.90", "0.006"], ["71208.70", "8.413"], ["74045.70", "0.000"], ["74056.30", "0.002"], ["89523.20", "0.000"]]}}
{"local_ts": 1773485525407, "server_ts": 1773485524616, "data": {"e": "depthUpdate", "E": 1773485524617, "T": 1773485524616, "s": "BTCUSDT", "U": 10109453130701, "u": 10109453134923, "pu": 10109453130596, "b": [["1000.00", "28.842"], ["5000.00", "101.418"], ["7050.40", "0.056"], ["20203.60", "0.730"], ["20303.60", "2.270"], ["56403.00", "0.000"], ["66972.80", "0.005"], ["66978.40", "0.006"], ["69500.00", "165.154"], ["69622.30", "0.270"], ["69798.60", "12.220"], ["69798.70", "0.004"], ["70151.10", "1.524"], ["70257.70", "0.000"], ["70371.20", "0.002"], ["70449.70", "0.521"], ["70449.80", "0.000"], ["70449.90", "0.003"], ["70450.60", "0.089"], ["70457.80", "0.317"], ["70457.90", "0.001"], ["70468.40", "0.018"], ["70487.60", "0.774"], ["70491.30", "0.214"]], "a": [["70503.70", "2.438"], ["70513.10", "0.002"], ["70513.40", "0.018"], ["70517.90", "0.007"], ["70533.40", "0.206"], ["70533.50", "0.006"], ["70533.70", "0.001"], ["70534.30", "0.279"], ["70635.50", "0.436"], ["70826.20", "5.017"], ["70999.90", "3.240"], ["71059.80", "1.207"], ["71208.70", "8.413"], ["71716.40", "0.696"], ["72660.80", "0.495"], ["89523.20", "0.006"]]}}
{"local_ts": 1773485526428, "server_ts": 1773485525637, "data": {"e": "depthUpdate", "E": 1773485525639, "T": 1773485525637, "s": "BTCUSDT", "U": 10109453170509, "u": 10109453173903, "pu": 10109453170413, "b": [["1000.00", "28.842"], ["5000.00", "101.418"], ["7050.40", "0.056"], ["20103.60", "0.340"], ["20203.60", "2.600"], ["20303.60", "0.060"], ["56403.00", "0.000"], ["66950.50", "0.008"], ["66950.90", "0.000"], ["69584.00", "66.974"], ["69798.60", "12.220"], ["70450.30", "0.293"], ["70450.40", "0.045"], ["70452.10", "0.089"], ["70458.10", "0.593"], ["70458.20", "0.021"], ["70465.80", "0.035"], ["70467.00", "0.000"], ["70473.30", "0.007"], ["70487.70", "1.209"], ["70491.20", "0.276"], ["70491.70", "0.144"], ["70492.00", "0.003"], ["70492.10", "0.638"], ["70492.20", "0.000"], ["70494.00", "0.026"], ["70494.10", "0.004"], ["70496.60", "0.000"], ["70502.80", "0.004"]], "a": [["70514.10", "0.008"], ["70539.00", "0.816"], ["70727.10", "0.009"], ["71208.60", "0.002"], ["71208.70", "8.413"], ["71438.50", "64.673"], ["71596.50", "12.848"], ["71631.80", "9.478"], ["74062.00", "0.054"]]}}
{"local_ts": 1773485527450, "server_ts": 1773485526660, "data": {"e": "depthUpdate", "E": 1773485526661, "T": 1773485526660, "s": "BTCUSDT", "U": 10109453207748, "u": 10109453212533, "pu": 10109453207711, "b": [["5000.00", "101.418"], ["7050.40", "0.056"], ["20003.60", "0.180"], ["20103.60", "2.470"], ["20203.60", "0.350"], ["68726.00", "0.000"], ["69798.60", "12.220"], ["70290.80", "0.006"], ["70450.10", "0.320"], ["70450.30", "0.208"], ["70464.90", "0.013"], ["70473.60", "0.363"], ["70474.90", "0.343"], ["70484.30", "0.003"], ["70485.30", "0.524"], ["70496.50", "0.011"], ["70496.60", "0.044"], ["70503.20", "0.002"]], "a": [["70503.70", "1.942"], ["70504.00", "0.004"], ["70510.60", "0.002"], ["70517.40", "0.046"], ["70519.80", "0.471"], ["70521.20", "0.074"], ["70522.40", "0.034"], ["70528.60", "0.912"], ["70529.10", "0.007"], ["70530.40", "0.012"], ["70531.40", "0.092"], ["70532.60", "0.349"], ["70539.00", "0.605"], ["71208.70", "9.815"], ["71504.90", "5.828"], ["71563.70", "0.000"], ["71565.80", "0.005"], ["74055.50", "0.064"], ["74064.00", "0.050"]]}}
{"local_ts": 1773485528473, "server_ts": 1773485527682, "data": {"e": "depthUpdate", "E": 1773485527683, "T": 1773485527682, "s": "BTCUSDT", "U": 10109453249260, "u": 10109453253619, "pu": 10109453249102, "b": [["1000.00", "29.242"], ["5000.00", "101.418"], ["7050.40", "0.028"], ["20003.60", "2.310"], ["20103.60", "0.650"], ["20403.60", "0.040"], ["33000.00", "3.785"], ["66956.80", "0.000"], ["69798.60", "12.935"], ["70151.10", "1.524"], ["70450.40", "0.045"], ["70450.50", "0.085"], ["70458.10", "0.593"], ["70458.20", "0.021"], ["70496.50", "0.206"], ["70496.60", "0.044"], ["70503.60", "4.230"]], "a": [["70503.70", "1.932"], ["70510.70", "0.022"], ["70513.40", "0.006"], ["70514.30", "0.144"], ["70515.00", "0.022"], ["70515.30", "0.077"], ["70516.80", "0.002"], ["70517.10", "0.008"], ["70518.00", "0.230"], ["70524.70", "0.200"], ["70531.40", "0.077"], ["70534.10", "0.346"], ["70534.20", "0.002"], ["70534.30", "0.279"], ["70539.00", "0.605"], ["70549.50", "0.404"], ["70764.60", "0.211"], ["71205.00", "0.954"], ["71208.70", "9.817"], ["71437.00", "4.212"], ["71913.70", "0.065"]]}}
{"local_ts": 1773485529495, "server_ts": 1773485528704, "data": {"e": "depthUpdate", "E": 1773485528705, "T": 1773485528704, "s": "BTCUSDT", "U": 10109453313185, "u": 10109453317447, "pu": 10109453313028, "b": [["5000.00", "101.418"], ["7050.40", "0.028"], ["20003.60", "1.050"], ["20403.70", "1.840"], ["20403.80", "0.007"], ["66966.00", "0.006"], ["69700.00", "14.163"], ["69798.70", "0.000"], ["70257.90", "0.000"], ["70460.60", "0.013"], ["70464.00", "0.225"], ["70468.80", "0.390"], ["70493.10", "0.010"], ["70496.20", "0.018"], ["70503.70", "16.170"]], "a": [["70503.80", "1.381"], ["70506.60", "0.003"], ["70506.70", "0.047"], ["70506.80", "0.010"], ["70511.80", "0.011"], ["70514.40", "0.005"], ["70521.40", "0.044"], ["70525.00", "1.745"], ["70525.90", "0.030"], ["70526.50", "0.017"], ["70527.90", "0.020"], ["70528.50", "0.085"], ["70530.20", "0.007"], ["70534.40", "0.131"], ["71208.70", "9.815"], ["71208.80", "0.000"], ["71531.30", "0.994"], ["74057.00", "0.052"]]}}
{"local_ts": 1773485530518, "server_ts": 1773485529725, "data": {"e": "depthUpdate", "E": 1773485529727, "T": 1773485529725, "s": "BTCUSDT", "U": 10109453356241, "u": 10109453359890, "pu": 10109453356197, "b": [["1000.00", "29.242"], ["5000.00", "101.418"], ["7050.40", "0.028"], ["20303.70", "1.500"], ["20403.70", "1.390"], ["33000.00", "3.789"], ["66766.90", "0.036"], ["69258.20", "16.797"], ["69587.20", "0.002"], ["69798.70", "0.000"], ["70151.20", "0.000"], ["70257.80", "0.011"], ["70433.70", "0.043"], ["70493.10", "0.013"], ["70496.10", "0.440"], ["70496.70", "0.465"]], "a": [["70503.80", "1.370"], ["70506.60", "0.003"], ["70506.80", "0.055"], ["70510.80", "0.003"], ["70514.40", "0.005"], ["70525.00", "1.745"], ["70530.80", "0.058"], ["70571.00", "0.004"], ["71208.80", "0.000"], ["71526.00", "25.417"], ["71788.90", "0.601"], ["72634.90", "0.589"], ["74053.30", "0.000"], ["74061.90", "0.002"]]}}
{"local_ts": 1773485531543, "server_ts": 1773485530748, "data": {"e": "depthUpdate", "E": 1773485530749, "T": 1773485530748, "s": "BTCUSDT", "U": 10109453401495, "u": 10109453405617, "pu": 10109453401364, "b": [["1000.00", "28.842"], ["5000.00", "101.438"], ["7050.40", "0.000"], ["20203.70", "1.060"], ["20303.70", "1.940"], ["66978.00", "0.000"], ["69439.90", "1.739"], ["69481.30", "30.039"], ["69798.70", "0.000"], ["70348.60", "0.004"], ["70352.10", "0.092"], ["70361.10", "12.255"], ["70363.90", "2.384"], ["70458.80", "1.357"], ["70459.20", "0.006"], ["70487.10", "0.003"], ["70493.10", "0.651"], ["70493.40", "0.143"], ["70493.90", "0.009"], ["70494.90", "0.016"], ["70496.10", "0.440"], ["70502.50", "0.009"], ["70502.80", "0.004"]], "a": [["70503.80", "1.917"], ["70505.80", "0.049"], ["70514.40", "0.008"], ["70521.40", "0.044"], ["70527.90", "0.005"], ["70528.10", "0.004"], ["70528.30", "0.239"], ["71208.80", "0.000"], ["71526.00", "20.524"], ["71684.40", "1.114"], ["74038.00", "0.005"], ["74052.70", "0.000"]]}}
{"local_ts": 1773485532559, "server_ts": 1773485531768, "data": {"e": "depthUpdate", "E": 1773485531769, "T": 1773485531768, "s": "BTCUSDT", "U": 10109453446715, "u": 10109453451022, "pu": 10109453446685, "b": [["5000.00", "101.418"], ["7050.40", "0.000"], ["20103.70", "0.600"], ["20203.70", "2.400"], ["20303.70", "0.000"], ["33000.00", "3.789"], ["66958.90", "0.002"], ["69098.80", "0.000"], ["69177.20", "0.000"], ["69250.00", "19.774"], ["69255.50", "0.004"], ["69333.80", "0.000"], ["69412.20", "4.317"], ["69490.50", "0.000"], ["69568.90", "0.000"], ["69584.00", "0.000"], ["69647.20", "0.004"], ["69725.60", "0.002"], ["69798.70", "0.000"], ["69803.90", "0.010"], ["70359.60", "0.000"], ["70475.60", "0.394"], ["70493.10", "0.010"], ["70493.50", "0.009"], ["70494.10", "0.638"], ["70496.00", "0.036"], ["70503.60", "0.256"]], "a": [["70503.80", "1.390"], ["70503.90", "0.000"], ["70505.80", "0.001"], ["70514.40", "0.003"], ["70518.10", "0.434"], ["70521.30", "0.002"], ["70522.40", "0.019"], ["70525.60", "0.003"], ["70528.20", "0.271"], ["70528.80", "0.005"], ["70529.50", "0.660"], ["70529.60", "0.004"], ["70529.70", "0.028"], ["70539.10", "0.512"], ["70764.70", "0.211"], ["71208.80", "0.000"], ["71214.10", "0.000"], ["71292.40", "0.017"], ["71370.80", "0.971"], ["71408.30", "9.229"], ["71438.50", "0.027"], ["71449.10", "0.000"], ["71526.00", "19.546"], ["71527.50", "0.000"], ["71605.80", "0.000"], ["71684.20", "0.279"], ["71762.50", "0.000"], ["71840.80", "0.002"], ["71919.20", "1.666"]]}}
{"local_ts": 1773485533584, "server_ts": 1773485532792, "data": {"e": "depthUpdate", "E": 1773485532793, "T": 1773485532792, "s": "BTCUSDT", "U": 10109453485441, "u": 10109453488591, "pu": 10109453485353, "b": [["1000.00", "28.992"], ["5000.00", "101.418"], ["7050.40", "0.000"], ["20003.70", "0.300"], ["20103.70", "2.570"], ["20203.70", "0.130"], ["66965.50", "9.372"], ["66966.00", "0.008"], ["69399.20", "9.211"], ["69798.70", "0.000"], ["70151.20", "0.000"], ["70316.90", "0.183"], ["70323.90", "0.002"], ["70345.10", "0.039"], ["70361.10", "0.202"], ["70363.90", "0.503"], ["70419.50", "0.090"], ["70419.60", "0.582"], ["70430.80", "0.884"], ["70431.30", "0.200"], ["70434.30", "0.056"], ["70434.80", "0.002"], ["70435.10", "0.120"], ["70435.20", "0.260"], ["70435.50", "0.306"], ["70435.80", "0.000"], ["70435.90", "0.001"], ["70436.20", "0.611"], ["70436.60", "0.081"], ["70452.50", "0.514"], ["70452.60", "0.004"], ["70452.70", "0.085"], ["70453.30", "0.000"], ["70453.60", "1.200"], ["70454.20", "0.016"], ["70455.60", "0.024"], ["70455.90", "0.152"], ["70456.20", "0.002"], ["70456.60", "0.010"], ["70456.90", "0.000"], ["70457.30", "0.000"], ["70457.60", "0.003"], ["70458.20", "0.054"], ["70458.90", "0.038"], ["70471.90", "0.209"], ["70475.30", "0.203"], ["70493.10", "0.013"], ["70496.00", "0.039"], ["70498.10", "0.000"], ["70498.40", "0.003"], ["70498.80", "0.006"], ["70499.10", "0.002"], ["70499.50", "0.000"], ["70499.80", "0.015"], ["70500.40", "0.054"], ["70501.10", "0.050"]], "a": [["70514.40", "0.006"], ["70514.50", "0.004"], ["70514.90", "0.003"], ["70515.20", "0.002"], ["70515.60", "0.003"], ["70515.90", "0.000"], ["70516.00", "0.002"], ["70516.30", "0.002"], ["70516.80", "0.027"], ["70517.50", "0.026"], ["70521.40", "0.125"], ["70525.20", "0.005"], ["70527.20", "0.002"], ["70535.60", "0.002"], ["70536.00", "0.131"], ["70536.30", "0.002"], ["70536.40", "0.088"], ["70536.50", "0.087"], ["70536.70", "0.855"], ["70537.00", "0.053"], ["70537.30", "0.014"], ["70537.40", "0.000"], ["70537.90", "0.025"], ["70538.50", "0.005"], ["70538.60", "0.173"], ["70540.30", "0.846"], ["70542.60", "0.065"], ["70556.70", "0.003"], ["70557.40", "0.002"], ["70557.80", "0.003"], ["70558.10", "0.000"], ["70558.50", "0.005"], ["70559.00", "0.054"], ["70559.40", "0.002"], ["70559.70", "0.031"], ["70560.40", "0.546"], ["70560.80", "0.000"], ["70561.00", "0.096"], ["70561.50", "0.000"], ["70595.00", "0.704"], ["70596.70", "0.000"], ["70655.80", "1.161"], ["70655.90", "2.477"], ["71205.00", "0.533"], ["71790.00", "0.739"]]}}
{"local_ts": 1773485534610, "server_ts": 1773485533815, "data": {"e": "depthUpdate", "E": 1773485533817, "T": 1773485533815, "s": "BTCUSDT", "U": 10109453527912, "u": 10109453532464, "pu": 10109453527836, "b": [["5000.00", "101.418"], ["7050.40", "0.056"], ["20003.70", "2.420"], ["20103.70", "0.430"], ["20403.70", "0.150"], ["69093.70", "0.021"], ["69657.70", "1.431"], ["69798.70", "0.000"], ["70352.10", "0.092"], ["70371.50", "0.769"], ["70475.90", "0.044"], ["70479.00", "0.243"]], "a": [["70507.10", "0.141"], ["70521.40", "0.088"], ["70635.70", "4.079"], ["70727.20", "0.015"], ["71208.70", "9.815"], ["71787.00", "0.586"], ["74050.40", "0.002"]]}}
{"local_ts": 1773485535630, "server_ts": 1773485534836, "data": {"e": "depthUpdate", "E": 1773485534841, "T": 1773485534836, "s": "BTCUSDT", "U": 10109453563042, "u": 10109453566339, "pu": 10109453562918, "b": [["1000.00", "28.842"], ["5000.00", "101.418"], ["7050.40", "0.056"], ["20003.70", "0.720"], ["20403.70", "2.280"], ["63453.30", "0.006"], ["66970.70", "0.004"], ["68175.50", "1.465"], ["69791.70", "0.000"], ["69798.70", "0.000"], ["70151.20", "0.004"], ["70371.50", "0.159"], ["70399.00", "0.002"], ["70399.10", "0.397"], ["70475.90", "0.010"], ["70476.00", "0.099"], ["70493.10", "0.013"], ["70495.90", "0.018"], ["70503.70", "16.200"]], "a": [["70503.80", "2.016"], ["70514.40", "0.003"], ["70523.60", "0.003"], ["70529.10", "0.162"], ["70529.50", "0.660"], ["70530.20", "0.007"], ["70531.50", "0.002"], ["70532.90", "0.019"], ["70539.10", "0.512"], ["70541.90", "0.023"], ["70543.20", "0.895"], ["70635.70", "3.538"], ["71208.70", "9.114"], ["71208.80", "0.421"], ["73164.70", "0.011"], ["74052.20", "0.000"], ["77554.20", "0.002"]]}}
{"local_ts": 1773485536652, "server_ts": 1773485535861, "data": {"e": "depthUpdate", "E": 1773485535863, "T": 1773485535861, "s": "BTCUSDT", "U": 10109453608059, "u": 10109453613381, "pu": 10109453607988, "b": [["1000.00", "28.842"], ["5000.00", "101.418"], ["7050.40", "0.056"], ["20303.70", "1.840"], ["20403.70", "1.160"], ["63453.30", "0.006"], ["66961.90", "0.000"], ["66978.50", "2.242"], ["66978.60", "0.006"], ["69410.80", "9.571"], ["69798.70", "0.000"], ["70452.20", "0.024"], ["70452.30", "0.089"], ["70458.80", "1.359"], ["70458.90", "0.038"], ["70493.10", "0.010"], ["70496.00", "0.036"], ["70503.50", "0.099"], ["70503.70", "16.198"]], "a": [["70503.80", "1.602"], ["70506.50", "0.000"], ["70514.40", "0.003"], ["70524.80", "0.019"], ["70526.20", "0.021"], ["70538.20", "0.027"], ["71208.80", "0.421"], ["71567.50", "0.462"], ["77554.20", "0.002"], ["89523.20", "0.000"]]}}
{"local_ts": 1773485537671, "server_ts": 1773485536880, "data": {"e": "depthUpdate", "E": 1773485536883, "T": 1773485536880, "s": "BTCUSDT", "U": 10109453650565, "u": 10109453653769, "pu": 10109453650521, "b": [["5000.00", "101.418"], ["7050.40", "0.028"], ["20203.70", "1.390"], ["20303.70", "1.610"], ["33000.00", "3.785"], ["63453.30", "0.006"], ["66951.60", "0.000"], ["66966.70", "0.002"], ["67683.60", "0.006"], ["69798.70", "0.000"], ["70257.80", "0.011"], ["70468.50", "0.002"], ["70496.70", "0.465"]], "a": [["70521.00", "0.004"], ["70526.20", "0.006"], ["71208.80", "0.421"], ["77554.20", "0.002"], ["89523.20", "0.000"]]}}
{"local_ts": 1773485538697, "server_ts": 1773485537908, "data": {"e": "depthUpdate", "E": 1773485537909, "T": 1773485537908, "s": "BTCUSDT", "U": 10109453688209, "u": 10109453692149, "pu": 10109453688113, "b": [["1000.00", "28.842"], ["5000.00", "101.398"], ["7050.40", "0.028"], ["20103.70", "0.960"], ["20203.70", "2.040"], ["63453.30", "0.006"], ["66956.40", "0.002"], ["68382.10", "3.504"], ["69185.30", "0.721"], ["69628.20", "5.017"], ["69798.70", "0.000"], ["70151.20", "0.000"], ["70352.10", "0.131"], ["70388.30", "0.003"], ["70401.90", "0.000"], ["70404.40", "0.014"], ["70432.00", "0.014"], ["70432.60", "0.002"], ["70435.50", "0.306"], ["70436.00", "0.000"], ["70436.40", "0.000"], ["70436.70", "0.591"], ["70437.10", "0.000"], ["70437.40", "0.007"], ["70437.80", "0.005"], ["70454.60", "2.754"], ["70454.80", "0.002"], ["70456.90", "0.000"], ["70457.10", "0.004"], ["70457.50", "0.002"], ["70457.80", "0.315"], ["70458.10", "0.656"], ["70458.20", "0.014"], ["70458.50", "0.046"], ["70458.80", "1.397"], ["70458.90", "0.000"], ["70459.20", "0.044"], ["70459.90", "0.247"], ["70475.50", "1.892"], ["70475.90", "0.010"], ["70499.30", "0.004"], ["70499.60", "0.003"], ["70499.70", "0.013"], ["70500.00", "0.628"], ["70500.30", "0.059"], ["70500.40", "0.014"], ["70500.60", "0.045"], ["70500.70", "0.007"], ["70501.00", "0.055"], ["70501.10", "0.012"], ["70501.40", "0.043"], ["70502.10", "0.038"], ["70503.50", "0.133"]], "a": [["70516.70", "0.063"], ["70516.80", "0.002"], ["70517.20", "0.003"], ["70517.40", "0.030"], ["70517.50", "0.001"], ["70517.70", "0.025"], ["70517.80", "0.005"], ["70517.90", "0.081"], ["70518.10", "0.459"], ["70518.20", "0.003"], ["70518.40", "0.039"], ["70518.50", "0.000"], ["70518.60", "0.048"], ["70521.40", "0.125"], ["70537.70", "0.027"], ["70537.90", "0.015"], ["70538.20", "0.002"], ["70538.40", "0.105"], ["70538.60", "0.148"], ["70538.80", "0.299"], ["70538.90", "0.086"], ["70539.00", "0.327"], ["70539.10", "0.512"], ["70539.20", "0.030"], ["70539.30", "0.007"], ["70539.50", "1.020"], ["70539.60", "1.669"], ["70540.70", "0.295"], ["70540.80", "0.010"], ["70558.80", "0.059"], ["70559.00", "0.029"], ["70559.30", "0.003"], ["70559.50", "0.025"], ["70559.70", "0.006"], ["70559.90", "0.025"], ["70560.00", "0.852"], ["70560.10", "0.055"], ["70560.20", "0.030"], ["70560.40", "1.067"], ["70560.60", "0.038"], ["70560.70", "0.000"], ["70560.90", "0.002"], ["70563.00", "0.000"], ["70563.30", "0.002"], ["71208.80", "1.122"], ["71455.60", "0.285"], ["71874.80", "0.013"], ["72227.70", "0.000"], ["74029.70", "0.000"], ["77554.20", "0.002"], ["89523.20", "0.000"]]}}
{"local_ts": 1773485539718, "server_ts": 1773485538928, "data": {"e": "depthUpdate", "E": 1773485538929, "T": 1773485538928, "s": "BTCUSDT", "U": 10109453729031, "u": 10109453733455, "pu": 10109453728937, "b": [["5000.00", "101.398"], ["7050.40", "0.028"], ["20003.70", "0.510"], ["20103.70", "2.490"], ["20203.70", "0.000"], ["33000.00", "3.789"], ["63453.30", "0.006"], ["69798.70", "0.715"], ["69798.80", "0.004"], ["70257.60", "0.004"], ["70405.60", "0.851"], ["70408.10", "0.352"], ["70410.10", "0.018"], ["70414.00", "0.144"], ["70414.40", "0.516"], ["70417.10", "0.087"], ["70421.00", "0.144"], ["70421.40", "0.386"], ["70424.20", "0.073"], ["70428.10", "0.142"], ["70428.50", "0.012"], ["70431.40", "0.000"], ["70452.50", "0.514"], ["70452.60", "0.089"], ["70476.40", "0.000"], ["70479.00", "0.340"], ["70494.20", "0.783"], ["70495.80", "0.010"], ["70500.40", "0.016"]], "a": [["70503.80", "1.417"], ["70506.90", "0.003"], ["70514.40", "0.003"], ["70517.90", "0.081"], ["70521.40", "0.044"], ["70530.10", "0.535"], ["70530.20", "0.644"], ["70531.40", "0.007"], ["70551.50", "0.085"], ["70583.30", "0.161"], ["70583.70", "0.093"], ["70586.40", "0.073"], ["70586.50", "0.000"], ["70590.40", "0.145"], ["70590.80", "0.477"], ["70593.50", "0.071"], ["70593.60", "0.045"], ["70597.40", "0.142"], ["70597.80", "0.128"], ["70600.50", "0.071"], ["70600.60", "0.004"], ["70698.00", "0.000"], ["70900.00", "11.872"], ["71208.80", "1.122"], ["71599.80", "0.279"], ["72618.90", "0.006"], ["74059.30", "0.000"], ["77554.20", "0.002"], ["89523.20", "0.000"]]}}
{"local_ts": 1773485540739, "server_ts": 1773485539948, "data": {"e": "depthUpdate", "E": 1773485539949, "T": 1773485539948, "s": "BTCUSDT", "U": 10109453783624, "u": 10109453794794, "pu": 10109453783297, "b": [["1000.00", "28.842"], ["5000.00", "101.438"], ["7050.40", "0.000"], ["20003.70", "2.540"], ["20103.70", "0.200"], ["20403.70", "0.260"], ["56403.00", "0.000"], ["63453.30", "0.004"], ["66960.40", "0.002"], ["69678.80", "1.145"], ["69798.70", "2.146"], ["70151.20", "0.000"], ["70452.70", "0.000"], ["70452.80", "0.042"], ["70452.90", "0.124"], ["70453.00", "0.089"], ["70458.70", "0.152"], ["70458.80", "1.451"], ["70468.50", "0.070"], ["70493.10", "0.010"], ["70496.10", "0.437"], ["70496.50", "0.011"], ["70496.80", "0.013"], ["70497.10", "0.001"]], "a": [["70514.40", "0.003"], ["70517.90", "0.081"], ["70529.50", "0.660"], ["70530.60", "0.000"], ["70536.40", "0.088"], ["70536.50", "0.059"], ["70536.70", "0.925"], ["70727.40", "0.223"], ["71208.80", "1.166"], ["71408.30", "8.390"], ["73323.90", "2.355"], ["77554.20", "0.000"], ["89523.20", "0.000"]]}}
{"local_ts": 1773485541760, "server_ts": 1773485540969, "data": {"e": "depthUpdate", "E": 1773485540971, "T": 1773485540969, "s": "BTCUSDT", "U": 10109453844423, "u": 10109453850218, "pu": 10109453844370, "b": [["1000.00", "28.842"], ["5000.00", "101.418"], ["7050.40", "0.000"], ["20003.70", "0.500"], ["20303.70", "0.110"], ["20403.70", "2.390"], ["33000.00", "3.789"], ["63453.30", "0.004"], ["66978.50", "2.248"], ["69272.40", "0.000"], ["69798.70", "2.146"], ["69798.80", "0.000"], ["70256.90", "0.006"], ["70316.90", "0.024"], ["70323.90", "0.161"], ["70333.40", "0.000"], ["70345.10", "0.000"], ["70352.10", "0.131"], ["70361.50", "12.863"], ["70361.60", "0.122"], ["70363.90", "2.411"], ["70419.20", "6.490"], ["70419.60", "1.431"], ["70431.00", "0.102"], ["70452.90", "0.124"], ["70453.00", "0.089"], ["70454.10", "3.463"], ["70475.30", "1.959"], ["70493.10", "0.010"], ["70493.20", "0.000"], ["70494.20", "0.011"], ["70496.20", "0.018"], ["70498.50", "0.020"], ["70499.10", "0.285"]], "a": [["70503.80", "0.800"], ["70514.40", "0.003"], ["70517.90", "0.036"], ["70525.00", "1.667"], ["70525.80", "0.005"], ["70530.00", "0.137"], ["70530.60", "0.141"], ["70539.10", "0.337"], ["70539.90", "0.082"], ["70540.40", "1.838"], ["70560.40", "1.073"], ["70561.70", "3.452"], ["70595.00", "1.565"], ["70597.00", "6.778"], ["70605.50", "0.046"], ["70656.30", "0.099"], ["70656.40", "12.951"], ["70677.90", "0.000"], ["71208.80", "1.122"], ["71349.80", "1.399"], ["71505.00", "0.861"], ["74035.40", "0.002"], ["77554.20", "0.000"], ["89523.20", "0.000"]]}}
{"local_ts": 1773485542788, "server_ts": 1773485541996, "data": {"e": "depthUpdate", "E": 1773485541997, "T": 1773485541996, "s": "BTCUSDT", "U": 10109453895712, "u": 10109453900985, "pu": 10109453895628, "b": [["5000.00", "101.398"], ["7050.40", "0.000"], ["20303.70", "2.180"], ["20403.70", "0.820"], ["63453.30", "0.004"], ["66956.20", "0.000"], ["66978.00", "0.000"], ["69798.70", "2.146"], ["69798.80", "0.000"], ["70257.40", "0.004"], ["70403.70", "0.032"], ["70453.00", "0.004"], ["70453.10", "1.067"], ["70453.20", "0.280"], ["70475.90", "0.010"], ["70478.10", "0.205"], ["70486.00", "0.007"], ["70487.10", "0.010"], ["70491.40", "0.002"], ["70493.10", "0.013"], ["70493.50", "0.009"], ["70494.00", "0.650"], ["70494.50", "0.001"], ["70496.10", "0.440"], ["70498.40", "0.003"], ["70499.10", "0.285"], ["70503.70", "16.670"]], "a": [["70503.80", "0.816"], ["70506.50", "0.000"], ["70507.10", "0.060"], ["70511.60", "0.021"], ["70514.40", "0.006"], ["70521.40", "0.005"], ["70523.00", "0.060"], ["70523.40", "0.005"], ["70524.80", "0.145"], ["70525.00", "1.748"], ["70527.20", "0.000"], ["70527.50", "0.514"], ["70528.60", "0.912"], ["70529.20", "0.002"], ["70529.30", "0.066"], ["70529.40", "0.004"], ["70529.90", "0.644"], ["70530.60", "0.141"], ["70531.20", "0.398"], ["70531.70", "0.076"], ["70532.10", "0.014"], ["70532.50", "0.573"], ["70533.20", "0.023"], ["70533.70", "0.001"], ["70534.70", "0.250"], ["70535.10", "0.009"], ["70535.20", "0.046"], ["70535.70", "0.000"], ["70536.40", "0.088"], ["70536.80", "0.002"], ["70536.90", "0.128"], ["70537.70", "0.027"], ["70538.90", "0.283"], ["70539.10", "0.337"], ["70539.30", "0.107"], ["70539.40", "0.239"], ["70540.30", "0.849"], ["70540.60", "0.089"], ["70541.60", "0.079"], ["70541.90", "0.023"], ["70542.80", "0.016"], ["70543.10", "0.015"], ["70544.50", "0.020"], ["70545.00", "0.042"], ["70545.70", "0.019"], ["70547.00", "0.669"], ["70548.30", "0.024"], ["70548.90", "0.485"], ["70549.50", "0.467"], ["70550.80", "2.697"], ["70550.90", "2.276"], ["70552.00", "0.006"], ["70553.30", "0.000"], ["71208.80", "1.122"], ["74040.40", "0.002"], ["77554.20", "0.000"], ["89523.20", "0.000"]]}}
{"local_ts": 1773485543809, "server_ts": 1773485543016, "data": {"e": "depthUpdate", "E": 1773485543019, "T": 1773485543016, "s": "BTCUSDT", "U": 10109453946961, "u": 10109453952813, "pu": 10109453946849, "b": [["1000.00", "28.842"], ["5000.00", "101.418"], ["7050.40", "0.056"], ["20203.70", "1.730"], ["20303.70", "1.270"], ["56403.00", "0.000"], ["63453.30", "0.004"], ["69439.80", "1.292"], ["69534.10", "1.147"], ["69798.70", "2.146"], ["70352.10", "0.131"], ["70453.20", "0.195"], ["70453.30", "0.085"], ["70457.80", "0.441"], ["70458.20", "0.113"], ["70458.30", "0.026"], ["70458.40", "0.232"], ["70458.50", "0.102"], ["70458.90", "0.040"], ["70459.60", "1.132"], ["70475.50", "1.892"], ["70486.50", "0.097"], ["70486.60", "0.011"], ["70500.00", "0.812"], ["70500.40", "0.176"], ["70500.70", "0.097"], ["70501.10", "0.052"], ["70501.80", "0.041"], ["70503.50", "0.131"]], "a": [["70503.80", "0.864"], ["70503.90", "0.028"], ["70504.00", "0.032"], ["70506.60", "0.003"], ["70515.40", "0.175"], ["70516.10", "0.256"], ["70516.80", "0.027"], ["70517.20", "0.064"], ["70517.50", "0.026"], ["70517.60", "0.076"], ["70517.90", "0.364"], ["70521.40", "0.005"], ["70526.40", "0.000"], ["70527.60", "0.079"], ["70528.50", "0.002"], ["70529.00", "0.215"], ["70529.10", "0.000"], ["70529.60", "0.641"], ["70537.20", "0.320"], ["70537.90", "0.025"], ["70538.30", "0.070"], ["70538.60", "0.173"], ["70538.70", "0.069"], ["70539.00", "0.260"], ["70553.90", "0.023"], ["70558.30", "0.226"], ["70559.00", "0.054"], ["70559.40", "0.063"], ["70559.70", "0.031"], ["70559.80", "0.166"], ["70560.10", "0.127"], ["70727.20", "0.015"], ["70727.30", "0.000"], ["70750.60", "26.716"], ["70757.60", "0.211"], ["71208.70", "9.114"], ["71208.80", "1.122"], ["74054.00", "0.050"], ["77554.20", "0.000"], ["89523.20", "0.000"]]}}
{"local_ts": 1773485544830, "server_ts": 1773485544038, "data": {"e": "depthUpdate", "E": 1773485544039, "T": 1773485544038, "s": "BTCUSDT", "U": 10109454004085, "u": 10109454009330, "pu": 10109454004035, "b": [["5000.00", "101.418"], ["7050.90", "0.056"], ["20108.80", "1.280"], ["20203.70", "1.330"], ["20208.80", "0.330"], ["65155.90", "0.002"], ["66978.50", "2.242"], ["66978.60", "0.006"], ["69502.50", "0.858"], ["69803.70", "0.819"], ["69872.60", "0.003"], ["69877.70", "0.018"], ["70047.30", "0.006"], ["70052.40", "0.011"], ["70293.00", "0.250"], ["70405.30", "0.015"], ["70433.60", "0.314"], ["70434.00", "0.055"], ["70435.60", "0.132"], ["70458.00", "0.520"], ["70460.40", "1.354"], ["70461.10", "0.267"], ["70461.20", "0.016"], ["70461.30", "8.513"], ["70467.50", "0.875"], ["70467.70", "0.004"], ["70469.20", "0.127"], ["70472.10", "0.232"], ["70472.80", "0.006"], ["70474.60", "1.358"], ["70475.90", "0.262"], ["70476.00", "0.016"], ["70476.60", "0.000"], ["70476.70", "0.014"], ["70477.30", "0.022"], ["70477.40", "0.013"], ["70478.70", "0.002"], ["70478.80", "0.695"], ["70479.40", "1.077"], ["70479.50", "0.008"], ["70480.10", "0.004"], ["70480.20", "0.535"], ["70480.60", "0.880"], ["70480.70", "0.089"], ["70480.80", "0.010"], ["70480.90", "0.000"], ["70481.70", "0.847"], ["70482.20", "0.342"], ["70482.30", "0.416"], ["70483.70", "0.003"], ["70486.00", "0.059"], ["70486.40", "0.000"], ["70487.10", "0.002"], ["70487.50", "0.000"], ["70488.80", "0.846"], ["70489.20", "0.008"], ["70489.30", "0.000"], ["70489.70", "0.080"], ["70489.90", "0.076"], ["70490.70", "0.920"], ["70490.80", "0.158"], ["70490.90", "0.015"], ["70491.80", "0.026"], ["70492.90", "0.077"], ["70493.40", "0.002"], ["70493.50", "0.009"], ["70494.30", "1.208"], ["70494.40", "0.027"], ["70494.90", "0.009"], ["70496.10", "0.441"], ["70496.30", "1.582"], ["70496.60", "0.000"], ["70497.00", "0.008"], ["70497.80", "0.142"], ["70498.50", "0.531"], ["70498.90", "0.001"], ["70499.00", "0.009"], ["70499.10", "0.002"], ["70499.20", "0.001"], ["70499.80", "0.020"], ["70500.20", "0.661"], ["70500.30", "0.008"], ["70500.90", "0.513"], ["70501.10", "0.097"], ["70501.80", "0.115"], ["70501.90", "0.403"], ["70502.30", "0.018"], ["70504.60", "0.181"], ["70505.40", "1.103"], ["70506.00", "0.000"], ["70506.30", "0.003"], ["70506.70", "0.012"], ["70507.00", "0.002"], ["70507.20", "0.007"], ["70507.40", "0.007"], ["70508.10", "0.057"], ["70508.80", "9.625"]], "a": [["70508.90", "2.204"], ["70511.00", "0.244"], ["70513.10", "0.002"], ["70514.00", "0.003"], ["70514.10", "0.008"], ["70515.80", "0.010"], ["70515.90", "0.003"], ["70516.30", "0.002"], ["70516.40", "0.006"], ["70517.30", "0.003"], ["70517.50", "0.026"], ["70517.60", "0.121"], ["70517.70", "0.000"], ["70518.00", "0.012"], ["70519.00", "0.074"], ["70519.40", "0.036"], ["70519.60", "0.000"], ["70519.80", "0.454"], ["70520.10", "0.046"], ["70520.40", "0.006"], ["70520.60", "0.007"], ["70520.70", "0.068"], ["70520.80", "1.003"], ["70521.20", "0.014"], ["70521.30", "0.002"], ["70521.60", "0.004"], ["70521.80", "0.347"], ["70521.90", "0.002"], ["70522.60", "0.019"], ["70522.90", "0.028"], ["70523.20", "0.005"], ["70523.60", "0.024"], ["70523.70", "0.051"], ["70523.80", "0.021"], ["70523.90", "0.000"], ["70524.30", "0.847"], ["70524.50", "0.000"], ["70524.60", "0.066"], ["70524.70", "0.000"], ["70525.40", "0.003"], ["70525.50", "0.366"], ["70525.60", "0.055"], ["70526.00", "0.004"], ["70526.40", "0.141"], ["70526.50", "0.002"], ["70526.90", "0.046"], ["70527.30", "1.146"], ["70527.70", "0.006"], ["70527.90", "0.004"], ["70528.20", "0.018"], ["70528.50", "0.004"], ["70529.10", "0.000"], ["70530.00", "0.158"], ["70531.40", "0.850"], ["70531.50", "0.179"], ["70531.60", "0.003"], ["70532.90", "0.004"], ["70533.00", "1.073"], ["70533.20", "0.143"], ["70533.40", "0.204"], ["70533.50", "0.004"], ["70534.00", "0.007"], ["70534.10", "0.346"], ["70534.20", "0.023"], ["70534.30", "0.003"], ["70534.70", "0.002"], ["70534.80", "0.272"], ["70534.90", "0.018"], ["70535.10", "0.024"], ["70535.20", "0.067"], ["70535.40", "0.000"], ["70535.80", "0.642"], ["70536.00", "0.131"], ["70536.20", "0.640"], ["70536.30", "0.023"], ["70536.40", "0.103"], ["70536.90", "0.043"], ["70537.00", "0.053"], ["70537.10", "0.669"], ["70537.60", "0.027"], ["70537.70", "0.061"], ["70537.80", "0.085"], ["70538.30", "0.165"], ["70538.40", "0.309"], ["70538.50", "0.848"], ["70538.60", "0.094"], ["70538.90", "0.321"], ["70539.00", "0.334"], ["70539.10", "0.085"], ["70539.50", "1.090"], ["70540.00", "0.074"], ["70540.30", "0.870"], ["70540.60", "0.101"], ["70540.80", "0.258"], ["70541.40", "0.001"], ["70541.90", "0.046"], ["70542.00", "0.004"], ["70542.20", "0.036"], ["70543.00", "0.002"], ["70543.50", "1.853"], ["70543.60", "0.146"], ["70544.20", "0.185"], ["70544.40", "0.009"], ["70544.90", "0.030"], ["70545.60", "0.845"], ["70551.10", "0.060"], ["70552.70", "0.925"], ["70552.90", "0.181"], ["70553.50", "0.218"], ["70553.90", "0.053"], ["70554.00", "0.007"], ["70554.60", "0.059"], ["70557.50", "0.876"], ["70558.10", "0.120"], ["70571.60", "0.004"], ["70572.10", "0.000"], ["70572.20", "0.079"], ["70579.00", "0.143"], ["70579.10", "0.225"], ["70582.30", "0.040"], ["70584.50", "0.593"], ["70588.40", "1.369"], ["70628.50", "0.668"], ["70699.30", "0.211"], ["70750.60", "26.505"], ["70757.60", "0.000"], ["70786.00", "0.009"], ["70791.10", "0.004"], ["70963.00", "0.007"], ["70968.10", "0.008"], ["71140.40", "0.000"], ["71145.50", "0.024"], ["71169.70", "5.607"], ["71214.00", "0.000"], ["74062.90", "0.006"], ["89523.20", "0.000"]]}}
{"local_ts": 1773485545849, "server_ts": 1773485545056, "data": {"e": "depthUpdate", "E": 1773485545059, "T": 1773485545056, "s": "BTCUSDT", "U": 10109454050766, "u": 10109454055871, "pu": 10109454050713, "b": [["1000.00", "28.842"], ["5000.00", "101.418"], ["7050.90", "0.056"], ["20008.80", "0.830"], ["20108.80", "2.170"], ["69416.70", "3.591"], ["69445.20", "0.862"], ["69803.70", "0.819"], ["70156.30", "0.040"], ["70333.00", "0.525"], ["70336.80", "3.600"], ["70375.40", "0.088"], ["70375.60", "0.631"], ["70435.60", "0.084"], ["70461.60", "0.017"], ["70461.80", "0.005"], ["70468.00", "0.094"], ["70480.50", "0.026"], ["70494.60", "0.057"], ["70496.10", "0.437"], ["70507.40", "0.009"]], "a": [["70508.90", "2.203"], ["70509.10", "0.025"], ["70511.10", "0.002"], ["70517.40", "0.005"], ["70521.60", "0.001"], ["70535.20", "0.704"], ["70535.70", "0.000"], ["70537.10", "0.669"], ["70540.20", "0.042"], ["70540.60", "0.002"], ["70541.80", "0.111"], ["70543.60", "0.094"], ["70544.90", "0.026"], ["70546.40", "0.000"], ["70553.50", "0.222"], ["70593.60", "0.002"], ["70600.40", "0.000"], ["70607.80", "0.043"], ["70640.90", "0.564"], ["70672.80", "0.137"], ["70674.60", "0.000"], ["70679.70", "38.262"], ["70699.30", "0.000"], ["70842.80", "0.002"], ["71178.70", "1.405"], ["71214.00", "0.000"], ["74049.20", "0.002"], ["74051.20", "0.000"], ["89523.20", "0.000"]]}}
{"local_ts": 1773485546872, "server_ts": 1773485546080, "data": {"e": "depthUpdate", "E": 1773485546081, "T": 1773485546080, "s": "BTCUSDT", "U": 10109454120301, "u": 10109454126255, "pu": 10109454120261, "b": [["1000.00", "28.842"], ["5000.00", "101.398"], ["7050.90", "0.028"], ["20008.80", "2.550"], ["20108.80", "0.030"], ["20408.80", "0.420"], ["33000.00", "3.785"], ["56407.00", "0.000"], ["69440.30", "0.000"], ["69585.00", "0.003"], ["69768.50", "0.644"], ["69803.70", "0.819"], ["70200.00", "24.824"], ["70411.60", "0.024"], ["70411.70", "0.350"], ["70437.00", "0.172"], ["70447.60", "0.026"], ["70455.80", "0.103"], ["70455.90", "0.148"], ["70456.00", "0.883"], ["70480.70", "0.089"], ["70480.80", "0.279"], ["70490.70", "1.032"], ["70490.80", "0.527"], ["70496.20", "0.004"], ["70498.20", "0.040"], ["70500.80", "0.000"], ["70500.90", "0.005"], ["70501.80", "0.567"], ["70503.80", "0.037"], ["70504.70", "0.057"], ["70506.60", "0.008"]], "a": [["70508.90", "4.538"], ["70511.70", "0.081"], ["70514.70", "0.007"], ["70514.90", "0.018"], ["70515.00", "0.037"], ["70515.10", "0.002"], ["70515.90", "0.022"], ["70516.20", "0.004"], ["70516.30", "0.017"], ["70516.60", "0.013"], ["70517.50", "0.036"], ["70519.50", "0.004"], ["70521.60", "0.001"], ["70527.40", "0.009"], ["70528.80", "0.005"], ["70531.60", "0.003"], ["70531.80", "0.005"], ["70532.50", "0.580"], ["70539.60", "1.794"], ["70539.70", "0.073"], ["70539.80", "0.148"], ["70544.20", "0.225"], ["70549.80", "0.049"], ["71214.00", "0.000"], ["71439.40", "0.002"], ["71919.00", "0.009"], ["73329.20", "0.016"], ["74037.60", "0.002"]]}}
{"local_ts": 1773485547893, "server_ts": 1773485547099, "data": {"e": "depthUpdate", "E": 1773485547101, "T": 1773485547099, "s": "BTCUSDT", "U": 10109454166354, "u": 10109454171663, "pu": 10109454166261, "b": [["5000.00", "101.418"], ["7050.90", "0.028"], ["20008.80", "0.290"], ["20308.80", "0.220"], ["20408.80", "2.490"], ["56407.00", "0.000"], ["66978.60", "0.004"], ["69803.70", "0.819"], ["69944.70", "0.006"], ["69974.80", "0.713"], ["70435.50", "0.306"], ["70437.10", "0.038"], ["70456.00", "0.902"], ["70456.10", "0.343"], ["70461.30", "8.516"], ["70461.40", "0.002"], ["70480.40", "0.348"], ["70495.50", "0.002"], ["70496.10", "0.343"], ["70497.70", "0.000"], ["70500.40", "0.056"], ["70500.70", "0.010"], ["70501.80", "0.802"], ["70504.50", "0.403"], ["70504.90", "0.210"], ["70505.60", "0.096"], ["70505.90", "0.041"]], "a": [["70508.90", "1.832"], ["70511.30", "0.068"], ["70515.90", "0.001"], ["70521.30", "0.027"], ["70521.60", "0.001"], ["70521.70", "0.061"], ["70522.40", "0.155"], ["70522.70", "0.075"], ["70524.20", "0.003"], ["70524.30", "0.012"], ["70526.50", "0.002"], ["70528.80", "0.062"], ["70530.20", "0.048"], ["70530.40", "0.027"], ["70532.30", "0.010"], ["70537.10", "0.225"], ["70538.30", "0.023"], ["70538.70", "0.033"], ["70539.70", "0.005"], ["70539.80", "0.233"], ["70540.10", "0.547"], ["70540.30", "0.849"], ["70541.70", "0.083"], ["70543.00", "0.022"], ["70544.20", "0.243"], ["70548.30", "0.009"], ["70554.70", "0.246"], ["70556.30", "0.005"], ["70559.20", "0.509"], ["70573.30", "0.077"], ["70574.30", "0.000"], ["70575.80", "8.502"], ["70579.80", "0.274"], ["70580.10", "0.070"], ["70580.80", "0.027"], ["70581.20", "0.136"], ["70581.70", "0.074"], ["70678.10", "3.554"], ["71214.00", "0.000"], ["74054.30", "0.002"]]}}
{"local_ts": 1773485548912, "server_ts": 1773485548120, "data": {"e": "depthUpdate", "E": 1773485548121, "T": 1773485548120, "s": "BTCUSDT", "U": 10109454209108, "u": 10109454213552, "pu": 10109454209047, "b": [["1000.00", "28.842"], ["5000.00", "101.418"], ["7050.90", "0.028"], ["20208.80", "0.070"], ["20308.80", "2.350"], ["20408.80", "0.580"], ["33000.00", "3.789"], ["56407.00", "0.000"], ["66956.80", "0.000"], ["69097.50", "0.003"], ["69375.50", "8.057"], ["69481.30", "22.997"], ["69627.50", "0.000"], ["69803.70", "0.819"], ["70376.00", "0.635"], ["70460.00", "0.087"], ["70461.10", "0.267"], ["70461.40", "1.946"], ["70462.30", "0.329"], ["70462.60", "0.004"], ["70462.70", "0.610"], ["70463.00", "0.094"], ["70463.40", "0.111"], ["70464.10", "0.040"], ["70479.00", "0.087"], ["70490.70", "0.520"], ["70491.10", "0.050"], ["70496.10", "0.343"], ["70500.80", "0.003"], ["70501.70", "0.004"], ["70501.80", "0.806"], ["70503.70", "0.050"], ["70504.50", "0.403"], ["70504.90", "0.210"], ["70505.20", "0.095"], ["70505.60", "0.096"], ["70506.30", "0.041"], ["70507.70", "0.199"], ["70508.10", "0.009"], ["70508.80", "8.501"]], "a": [["70508.90", "1.811"], ["70511.10", "0.068"], ["70511.40", "0.002"], ["70511.90", "0.010"], ["70512.60", "0.041"], ["70515.90", "0.001"], ["70517.80", "0.062"], ["70518.20", "0.011"], ["70519.70", "0.002"], ["70520.60", "0.011"], ["70520.90", "0.032"], ["70521.60", "0.062"], ["70521.90", "0.061"], ["70522.30", "0.145"], ["70522.70", "0.219"], ["70527.30", "0.000"], ["70527.40", "0.005"], ["70527.90", "0.004"], ["70528.00", "0.009"], ["70528.40", "0.169"], ["70535.30", "0.006"], ["70535.80", "1.282"], ["70537.10", "0.735"], ["70540.60", "0.002"], ["70541.20", "0.248"], ["70541.70", "0.083"], ["70542.00", "0.031"], ["70542.70", "0.063"], ["70543.00", "0.083"], ["70543.40", "0.063"], ["70543.70", "0.260"], ["70544.20", "0.243"], ["70544.90", "0.062"], ["70558.10", "0.000"], ["70563.10", "0.027"], ["70563.80", "0.061"], ["70564.10", "0.102"], ["70564.50", "0.061"], ["70564.80", "0.275"], ["70567.10", "0.036"], ["70641.00", "0.536"], ["71214.00", "0.000"], ["74047.10", "0.002"]]}}
{"local_ts": 1773485549939, "server_ts": 1773485549141, "data": {"e": "depthUpdate", "E": 1773485549145, "T": 1773485549141, "s": "BTCUSDT", "U": 10109454247460, "u": 10109454251682, "pu": 10109454247235, "b": [["5000.00", "101.418"], ["7050.90", "0.000"], ["20208.80", "2.040"], ["20308.80", "0.960"], ["56407.00", "0.000"], ["67688.50", "0.016"], ["68508.80", "0.030"], ["70496.10", "0.343"], ["70498.20", "0.044"], ["70501.10", "0.063"], ["70501.80", "0.806"]], "a": [["70508.90", "1.809"], ["70510.90", "0.073"], ["70511.80", "0.021"], ["70512.60", "0.053"], ["70515.90", "0.001"], ["70518.70", "0.003"], ["70519.50", "0.001"], ["70521.60", "0.062"], ["70524.20", "0.008"], ["70526.70", "0.003"], ["70528.40", "0.154"], ["70528.50", "0.004"], ["70528.80", "0.005"], ["70529.50", "0.080"], ["70535.30", "0.145"], ["70535.80", "1.282"], ["70536.50", "0.510"], ["70537.10", "0.165"], ["70540.60", "0.101"], ["70540.80", "0.008"], ["70544.20", "0.104"], ["70561.60", "0.127"], ["70575.90", "0.002"], ["70593.50", "0.708"], ["70597.00", "0.044"], ["71214.00", "2.103"], ["71707.60", "0.557"], ["74048.50", "0.050"], ["74062.60", "0.000"], ["74068.80", "0.000"]]}}
{"local_ts": 1773485550956, "server_ts": 1773485550164, "data": {"e": "depthUpdate", "E": 1773485550165, "T": 1773485550164, "s": "BTCUSDT", "U": 10109454289470, "u": 10109454295668, "pu": 10109454289334, "b": [["1000.00", "28.842"], ["5000.00", "101.418"], ["7050.90", "0.000"], ["20108.80", "1.600"], ["20208.80", "1.400"], ["56407.00", "0.000"], ["66983.40", "0.010"], ["68746.10", "0.436"], ["69434.40", "0.000"], ["69481.30", "19.979"], ["69486.40", "6.395"], ["69803.70", "2.964"], ["70156.30", "0.036"], ["70498.20", "0.041"], ["70501.20", "0.009"], ["70501.80", "0.809"], ["70507.30", "0.006"]], "a": [["70508.90", "1.168"], ["70512.30", "0.004"], ["70515.90", "0.001"], ["70519.50", "0.001"], ["70519.60", "0.012"], ["70529.10", "0.000"], ["70529.80", "0.022"], ["70531.30", "0.017"], ["70532.40", "0.038"], ["70540.60", "0.349"], ["70542.00", "0.031"], ["70543.00", "0.083"], ["70597.00", "0.044"], ["71214.00", "2.103"], ["71451.80", "2.725"], ["71514.00", "8.031"], ["72278.10", "4.997"], ["74069.20", "0.002"]]}}
{"local_ts": 1773485551978, "server_ts": 1773485551186, "data": {"e": "depthUpdate", "E": 1773485551187, "T": 1773485551186, "s": "BTCUSDT", "U": 10109454350294, "u": 10109454373804, "pu": 10109454350234, "b": [["1000.00", "28.842"], ["5000.00", "101.418"], ["7050.90", "0.000"], ["20010.90", "0.300"], ["20108.80", "1.850"], ["66310.50", "0.002"], ["66978.10", "0.002"], ["69100.70", "0.003"], ["69274.90", "3.459"], ["69805.80", "0.002"], ["70324.00", "0.165"], ["70327.60", "0.159"], ["70359.30", "0.210"], ["70381.20", "0.000"], ["70399.10", "0.000"], ["70401.30", "0.000"], ["70402.80", "0.252"], ["70412.30", "0.049"], ["70414.60", "0.123"], ["70415.50", "0.016"], ["70418.30", "0.000"], ["70422.00", "0.024"], ["70432.60", "0.026"], ["70436.20", "0.611"], ["70439.30", "0.545"], ["70440.80", "0.950"], ["70450.10", "0.000"], ["70456.50", "0.087"], ["70456.60", "0.104"], ["70456.70", "0.000"], ["70456.80", "0.000"], ["70460.00", "0.074"], ["70460.50", "0.000"], ["70461.30", "0.000"], ["70461.40", "0.007"], ["70461.50", "0.006"], ["70461.80", "0.000"], ["70462.80", "0.619"], ["70463.30", "0.004"], ["70464.90", "8.526"], ["70465.10", "0.085"], ["70465.30", "2.904"], ["70466.60", "0.001"], ["70468.40", "0.090"], ["70469.70", "0.013"], ["70470.40", "1.025"], ["70471.90", "0.008"], ["70472.10", "0.329"], ["70472.30", "0.472"], ["70472.40", "0.511"], ["70473.70", "0.156"], ["70474.40", "0.074"], ["70474.50", "0.011"], ["70475.20", "0.311"], ["70475.90", "0.075"], ["70478.10", "0.259"], ["70478.30", "0.104"], ["70478.70", "0.392"], ["70478.80", "0.000"], ["70479.20", "0.418"], ["70479.40", "1.090"], ["70479.50", "0.017"], ["70479.80", "0.786"], ["70479.90", "0.118"], ["70480.00", "0.117"], ["70480.30", "0.007"], ["70481.00", "0.010"], ["70481.20", "0.010"], ["70481.50", "0.051"], ["70481.60", "0.002"], ["70482.20", "0.342"], ["70482.30", "0.550"], ["70482.90", "0.000"], ["70483.00", "0.012"], ["70483.50", "0.024"], ["70483.60", "0.006"], ["70483.70", "0.276"], ["70484.30", "0.003"], ["70485.10", "0.117"], ["70485.40", "0.549"], ["70486.30", "0.068"], ["70486.60", "0.031"], ["70487.50", "0.000"], ["70487.70", "0.004"], ["70487.80", "0.261"], ["70488.50", "0.016"], ["70489.50", "0.069"], ["70489.90", "0.004"], ["70490.50", "0.000"], ["70491.00", "0.001"], ["70491.30", "0.204"], ["70491.70", "0.083"], ["70492.10", "0.002"], ["70493.20", "0.211"], ["70493.50", "0.007"], ["70493.90", "0.001"], ["70494.20", "0.053"], ["70495.30", "0.002"], ["70496.10", "0.342"], ["70496.20", "0.514"], ["70496.40", "0.281"], ["70497.50", "0.002"], ["70498.30", "0.004"], ["70499.20", "0.060"], ["70499.60", "0.003"], ["70500.30", "0.405"], ["70501.70", "0.013"], ["70502.00", "1.076"], ["70502.70", "0.006"], ["70502.80", "0.101"], ["70503.10", "1.165"], ["70503.30", "0.002"], ["70503.70", "0.050"], ["70504.00", "0.010"], ["70504.90", "0.210"], ["70505.50", "0.009"], ["70505.90", "0.044"], ["70506.80", "0.050"], ["70507.50", "0.056"], ["70507.70", "0.015"], ["70507.80", "0.005"], ["70508.00", "0.001"], ["70508.50", "0.005"], ["70508.80", "0.631"], ["70509.10", "0.009"], ["70509.50", "0.146"], ["70509.60", "1.345"], ["70509.70", "1.102"], ["70509.80", "1.613"], ["70509.90", "0.560"], ["70510.00", "0.002"], ["70510.50", "0.002"], ["70510.60", "0.000"], ["70510.70", "0.029"], ["70510.80", "0.221"], ["70510.90", "21.847"]], "a": [["70511.00", "0.078"], ["70511.50", "0.000"], ["70512.20", "0.000"], ["70512.80", "0.015"], ["70513.70", "0.003"], ["70515.40", "0.003"], ["70515.60", "0.003"], ["70516.10", "0.217"], ["70517.30", "0.001"], ["70517.80", "0.034"], ["70518.00", "0.036"], ["70518.10", "0.008"], ["70519.30", "0.158"], ["70520.70", "0.212"], ["70521.60", "0.067"], ["70521.70", "0.000"], ["70523.30", "0.000"], ["70523.50", "0.006"], ["70524.80", "0.002"], ["70524.90", "0.437"], ["70525.30", "0.000"], ["70525.80", "0.017"], ["70526.90", "0.003"], ["70527.60", "0.077"], ["70527.70", "0.037"], ["70527.90", "0.004"], ["70528.10", "0.005"], ["70528.60", "0.841"], ["70529.00", "0.001"], ["70529.10", "0.000"], ["70529.40", "0.145"], ["70529.50", "0.003"], ["70530.30", "0.024"], ["70530.70", "0.067"], ["70531.50", "0.005"], ["70531.90", "0.205"], ["70532.10", "0.487"], ["70532.50", "0.500"], ["70532.90", "0.024"], ["70533.20", "0.002"], ["70534.20", "0.004"], ["70535.10", "0.012"], ["70535.70", "0.000"], ["70535.80", "0.467"], ["70536.10", "0.005"], ["70536.20", "0.003"], ["70536.30", "0.023"], ["70536.90", "0.016"], ["70537.00", "0.077"], ["70537.10", "0.028"], ["70537.50", "0.009"], ["70538.10", "0.004"], ["70538.40", "0.026"], ["70538.50", "0.005"], ["70539.00", "0.188"], ["70539.10", "0.641"], ["70539.20", "0.005"], ["70539.70", "0.007"], ["70539.80", "0.150"], ["70539.90", "0.088"], ["70540.00", "0.038"], ["70540.10", "0.555"], ["70540.30", "0.934"], ["70540.40", "0.036"], ["70540.50", "0.004"], ["70540.80", "0.011"], ["70541.10", "0.005"], ["70541.20", "0.002"], ["70541.60", "0.174"], ["70541.70", "0.040"], ["70541.90", "0.078"], ["70542.10", "0.915"], ["70543.00", "0.078"], ["70543.90", "0.070"], ["70545.00", "0.001"], ["70545.50", "0.025"], ["70546.00", "0.006"], ["70546.20", "0.469"], ["70547.30", "0.000"], ["70547.90", "0.054"], ["70550.50", "0.033"], ["70550.90", "2.313"], ["70551.50", "0.171"], ["70551.80", "0.007"], ["70551.90", "0.124"], ["70552.40", "0.020"], ["70552.80", "0.005"], ["70553.30", "0.016"], ["70553.90", "0.004"], ["70557.20", "0.544"], ["70557.90", "0.002"], ["70559.20", "0.000"], ["70559.80", "0.097"], ["70560.20", "0.008"], ["70560.90", "0.002"], ["70561.40", "0.007"], ["70561.70", "0.007"], ["70562.20", "0.145"], ["70565.20", "0.003"], ["70566.50", "1.025"], ["70572.70", "0.010"], ["70574.20", "0.007"], ["70575.80", "0.000"], ["70577.20", "0.269"], ["70577.30", "0.015"], ["70577.50", "2.473"], ["70579.10", "0.266"], ["70579.50", "0.089"], ["70579.70", "8.509"], ["70580.00", "0.144"], ["70581.30", "2.233"], ["70581.50", "0.027"], ["70582.00", "0.024"], ["70586.20", "0.539"], ["70590.80", "0.225"], ["70599.60", "0.758"], ["70600.20", "0.118"], ["70603.80", "0.160"], ["70612.60", "0.252"], ["70622.80", "0.002"], ["70624.90", "0.219"], ["70637.40", "0.610"], ["70644.50", "0.803"], ["70645.60", "0.137"], ["70649.80", "0.669"], ["70658.50", "0.185"], ["70661.20", "0.041"], ["70661.80", "0.250"], ["70662.80", "12.369"], ["70664.20", "0.216"], ["70665.80", "0.092"], ["70666.60", "0.186"], ["70671.80", "0.092"], ["70683.00", "0.497"], ["70686.10", "0.050"], ["70711.00", "0.372"], ["70717.90", "0.003"], ["70731.80", "0.261"], ["70745.80", "0.252"], ["70760.00", "0.409"], ["70828.30", "0.974"], ["71216.10", "0.000"], ["71777.10", "1.796"], ["73800.00", "35.452"], ["74062.70", "0.000"]]}}
{"local_ts": 1773485553005, "server_ts": 1773485552210, "data": {"e": "depthUpdate", "E": 1773485552213, "T": 1773485552210, "s": "BTCUSDT", "U": 10109454476087, "u": 10109454484643, "pu": 10109454475861, "b": [["5000.00", "101.418"], ["7051.50", "0.056"], ["20010.90", "0.950"], ["20014.90", "0.460"], ["20414.90", "0.690"], ["69809.80", "0.000"], ["69944.70", "4.783"], ["70324.50", "0.704"], ["70383.10", "0.271"], ["70389.10", "0.451"], ["70416.70", "7.587"], ["70418.40", "0.262"], ["70423.70", "0.002"], ["70424.40", "0.048"], ["70428.90", "0.000"], ["70430.80", "0.954"], ["70438.60", "0.162"], ["70453.70", "1.020"], ["70455.80", "0.021"], ["70458.10", "0.590"], ["70459.70", "0.007"], ["70465.30", "2.047"], ["70466.30", "0.006"], ["70467.60", "0.677"], ["70467.70", "0.004"], ["70471.40", "0.006"], ["70471.80", "2.510"], ["70485.00", "0.149"], ["70485.80", "0.089"], ["70489.10", "0.005"], ["70495.00", "0.186"], ["70497.90", "0.042"], ["70502.00", "1.319"], ["70504.20", "0.012"], ["70504.30", "0.029"], ["70507.80", "0.010"], ["70509.90", "0.003"], ["70510.90", "0.031"], ["70514.90", "15.747"]], "a": [["70515.00", "0.018"], ["70521.00", "0.079"], ["70522.40", "0.016"], ["70523.50", "0.009"], ["70524.80", "0.002"], ["70525.60", "0.006"], ["70527.00", "0.007"], ["70528.10", "0.107"], ["70528.50", "0.352"], ["70534.80", "0.013"], ["70536.20", "0.003"], ["70540.60", "0.020"], ["70540.70", "0.366"], ["70542.00", "0.006"], ["70542.70", "0.038"], ["70543.00", "0.002"], ["70543.10", "0.007"], ["70543.20", "0.727"], ["70543.70", "0.108"], ["70549.90", "1.489"], ["70550.70", "0.379"], ["70557.90", "0.002"], ["70563.60", "1.571"], ["70564.00", "0.219"], ["70570.10", "0.020"], ["70574.50", "0.004"], ["70578.00", "0.006"], ["70580.20", "0.271"], ["70585.30", "0.032"], ["70586.40", "0.040"], ["70587.00", "0.042"], ["70588.60", "0.710"], ["70592.40", "1.542"], ["70593.10", "0.000"], ["70595.40", "0.000"], ["70599.30", "0.245"], ["70599.50", "1.073"], ["70600.20", "0.047"], ["70602.50", "0.000"], ["70605.40", "0.005"], ["70606.60", "0.007"], ["70607.20", "0.000"], ["70607.40", "0.002"], ["70609.60", "3.444"], ["70613.70", "0.009"], ["70616.70", "1.688"], ["70620.80", "0.186"], ["70623.80", "0.000"], ["70627.90", "0.011"], ["70630.90", "0.005"], ["70634.60", "10.204"], ["70635.00", "0.048"], ["70638.00", "1.420"], ["70640.80", "0.003"], ["70645.10", "0.000"], ["70657.90", "0.143"], ["70676.70", "0.025"], ["71220.10", "0.005"], ["71496.50", "2.656"], ["71931.00", "1.670"], ["74037.60", "0.000"], ["74045.50", "0.000"], ["74068.50", "0.052"]]}}
{"local_ts": 1773485554027, "server_ts": 1773485553236, "data": {"e": "depthUpdate", "E": 1773485553237, "T": 1773485553236, "s": "BTCUSDT", "U": 10109454537472, "u": 10109454542097, "pu": 10109454537316, "b": [["1000.00", "28.842"], ["5000.00", "101.418"], ["7051.50", "0.056"], ["20008.80", "0.060"], ["20009.50", "0.000"], ["20009.70", "0.000"], ["20010.90", "0.000"], ["20314.90", "0.340"], ["20414.90", "2.580"], ["33000.00", "3.785"], ["66983.40", "0.002"], ["66983.50", "0.010"], ["66986.20", "0.004"], ["69277.70", "0.000"], ["69351.40", "2.856"], ["69488.50", "1.005"], ["69809.80", "0.000"], ["70401.80", "0.009"], ["70403.40", "0.000"], ["70461.60", "0.075"], ["70464.20", "0.313"], ["70464.50", "0.040"], ["70464.60", "0.063"], ["70464.90", "0.104"], ["70465.20", "7.902"], ["70465.90", "0.038"], ["70481.40", "0.778"], ["70481.50", "0.134"], ["70489.70", "0.035"], ["70504.30", "0.026"], ["70507.40", "0.372"], ["70507.70", "0.232"], ["70508.00", "0.048"], ["70508.10", "0.058"], ["70508.40", "0.095"], ["70509.10", "0.044"], ["70511.00", "0.608"], ["70514.90", "13.317"]], "a": [["70515.30", "0.011"], ["70523.00", "0.066"], ["70525.60", "0.003"], ["70526.20", "0.122"], ["70526.60", "0.025"], ["70527.00", "0.025"], ["70527.30", "0.073"], ["70527.70", "0.067"], ["70528.00", "0.142"], ["70528.40", "0.221"], ["70539.10", "0.004"], ["70539.60", "1.923"], ["70542.20", "0.015"], ["70543.20", "0.706"], ["70543.40", "0.074"], ["70544.80", "0.023"], ["70546.90", "0.005"], ["70547.10", "0.107"], ["70547.60", "0.251"], ["70548.20", "0.049"], ["70548.90", "0.171"], ["70549.30", "0.914"], ["70549.60", "0.063"], ["70550.00", "1.846"], ["70550.20", "0.017"], ["70551.30", "0.075"], ["70552.00", "0.012"], ["70555.50", "0.194"], ["70557.90", "0.000"], ["70569.80", "0.025"], ["70570.50", "0.061"], ["70570.80", "0.061"], ["70571.20", "0.061"], ["70571.60", "0.112"], ["70575.70", "0.014"], ["70579.90", "0.140"], ["70585.30", "0.000"], ["70587.00", "0.049"], ["70592.40", "1.535"], ["70594.10", "0.009"], ["70599.50", "1.066"], ["70601.20", "0.007"], ["70606.60", "0.000"], ["70608.30", "0.007"], ["70613.70", "0.002"], ["70615.40", "0.371"], ["70620.80", "0.179"], ["70622.50", "0.166"], ["70627.90", "0.004"], ["70629.60", "0.048"], ["70635.00", "0.041"], ["71220.10", "1.407"], ["71357.80", "1.119"], ["71572.90", "0.419"]]}}
{"local_ts": 1773485555053, "server_ts": 1773485554261, "data": {"e": "depthUpdate", "E": 1773485554263, "T": 1773485554261, "s": "BTCUSDT", "U": 10109454589190, "u": 10109454594832, "pu": 10109454589017, "b": [["5000.00", "101.418"], ["7051.50", "0.056"], ["20214.90", "0.190"], ["20314.90", "2.460"], ["20414.90", "0.350"], ["66989.10", "0.002"], ["69739.30", "0.006"], ["69809.80", "0.000"], ["70269.00", "0.236"], ["70458.70", "0.250"], ["70458.80", "1.357"], ["70459.00", "0.085"], ["70468.20", "0.004"], ["70468.40", "0.004"], ["70489.70", "0.000"], ["70491.30", "0.204"], ["70493.40", "0.250"], ["70504.30", "0.029"], ["70507.80", "0.010"], ["70514.90", "13.315"]], "a": [["70515.00", "1.016"], ["70517.90", "0.072"], ["70523.00", "0.064"], ["70525.60", "0.003"], ["70529.20", "0.002"], ["70529.50", "0.060"], ["70531.90", "0.070"], ["70532.40", "0.005"], ["70535.60", "0.000"], ["70538.10", "0.019"], ["70542.50", "0.885"], ["70542.60", "0.005"], ["70542.80", "0.101"], ["70543.20", "0.646"], ["70551.60", "0.447"], ["70552.00", "0.010"], ["70554.90", "0.002"], ["70579.90", "0.133"], ["70581.00", "0.008"], ["70587.00", "0.042"], ["70594.10", "0.002"], ["70601.20", "0.000"], ["70608.30", "0.000"], ["70615.40", "0.364"], ["70622.50", "0.159"], ["70629.60", "0.041"], ["70684.20", "0.266"], ["70696.60", "7.950"], ["70722.10", "0.280"], ["70729.20", "0.007"], ["70736.30", "0.007"], ["70743.40", "0.007"], ["70750.50", "0.022"], ["70757.60", "0.007"], ["70764.70", "0.007"], ["70771.80", "0.009"], ["71220.10", "1.617"]]}}
{"local_ts": 1773485556074, "server_ts": 1773485555280, "data": {"e": "depthUpdate", "E": 1773485555283, "T": 1773485555280, "s": "BTCUSDT", "U": 10109454641665, "u": 10109454647713, "pu": 10109454641496, "b": [["1000.00", "28.842"], ["5000.00", "101.418"], ["7051.50", "0.028"], ["20114.90", "0.040"], ["20214.90", "2.310"], ["20314.90", "0.650"], ["33000.00", "3.789"], ["66983.40", "0.000"], ["66983.50", "0.010"], ["67694.40", "0.014"], ["69222.80", "0.725"], ["69809.80", "0.000"], ["70162.30", "0.000"], ["70422.50", "0.915"], ["70422.60", "0.513"], ["70429.50", "0.151"], ["70429.60", "0.081"], ["70436.60", "0.152"], ["70436.70", "0.591"], ["70458.40", "0.014"], ["70458.50", "0.005"], ["70458.60", "0.107"], ["70481.80", "0.083"], ["70504.30", "0.029"], ["70506.70", "0.014"], ["70507.00", "0.002"], ["70507.70", "0.235"], ["70507.90", "0.069"], ["70508.20", "1.353"], ["70508.60", "0.000"], ["70509.20", "0.002"], ["70510.80", "0.114"], ["70514.60", "0.002"], ["70514.70", "0.528"], ["70514.80", "1.121"]], "a": [["70515.00", "0.745"], ["70517.70", "0.075"], ["70522.00", "0.739"], ["70525.60", "0.003"], ["70533.30", "0.153"], ["70534.20", "0.002"], ["70536.20", "0.084"], ["70538.70", "0.118"], ["70542.20", "0.030"], ["70542.30", "0.004"], ["70542.40", "0.090"], ["70543.00", "0.271"], ["70543.50", "2.297"], ["70544.80", "0.023"], ["70545.40", "0.086"], ["70546.80", "0.006"], ["70546.90", "0.005"], ["70548.60", "0.004"], ["70549.20", "0.251"], ["70550.30", "0.109"], ["70563.00", "0.002"], ["70567.30", "0.095"], ["70581.00", "0.006"], ["70598.90", "0.116"], ["70606.00", "0.074"], ["70613.00", "0.071"], ["70617.20", "0.002"], ["70620.10", "0.207"], ["70641.80", "0.083"], ["70684.20", "0.264"], ["70722.10", "0.273"], ["70729.20", "0.000"], ["70736.30", "0.000"], ["70743.40", "0.000"], ["70750.50", "0.015"], ["70757.60", "0.000"], ["70764.70", "0.000"], ["70771.80", "0.002"], ["70773.20", "0.004"], ["70830.70", "0.000"], ["70844.90", "3.417"], ["71158.30", "3.616"], ["71220.10", "1.617"], ["71361.20", "2.796"], ["71378.40", "0.706"], ["71494.10", "0.600"], ["71713.80", "0.279"], ["74066.10", "0.000"]]}}
{"local_ts": 1773485557093, "server_ts": 1773485556301, "data": {"e": "depthUpdate", "E": 1773485556303, "T": 1773485556301, "s": "BTCUSDT", "U": 10109454703787, "u": 10109454709913, "pu": 10109454703476, "b": [["1000.00", "28.842"], ["5000.00", "101.418"], ["7051.50", "0.028"], ["20114.90", "1.940"], ["20214.90", "1.060"], ["66981.00", "0.002"], ["66986.10", "0.002"], ["69100.60", "0.619"], ["69452.30", "1.365"], ["69809.80", "0.000"], ["69969.30", "47.102"], ["70413.40", "0.000"], ["70415.10", "0.350"], ["70419.80", "0.000"], ["70422.40", "0.022"], ["70422.50", "0.915"], ["70424.20", "0.142"], ["70426.80", "0.351"], ["70429.40", "0.071"], ["70429.50", "0.080"], ["70431.20", "0.384"], ["70433.90", "0.002"], ["70436.50", "0.071"], ["70436.60", "0.081"], ["70437.30", "0.086"], ["70438.30", "0.195"], ["70451.40", "0.694"], ["70490.30", "0.008"], ["70491.30", "0.204"], ["70493.40", "0.250"], ["70504.30", "0.029"], ["70505.80", "0.019"], ["70507.60", "0.010"], ["70507.90", "0.069"], ["70514.90", "13.499"]], "a": [["70515.00", "0.767"], ["70517.90", "0.075"], ["70522.00", "0.739"], ["70523.30", "0.003"], ["70525.60", "0.006"], ["70527.40", "0.057"], ["70528.10", "0.002"], ["70528.50", "0.022"], ["70531.20", "0.079"], ["70532.40", "0.005"], ["70537.10", "0.043"], ["70538.30", "0.002"], ["70543.00", "0.186"], ["70543.20", "0.648"], ["70556.80", "0.257"], ["70564.80", "0.095"], ["70568.40", "0.192"], ["70578.50", "0.003"], ["70580.20", "0.271"], ["70580.50", "1.200"], ["70589.20", "2.459"], ["70592.60", "0.021"], ["70593.70", "0.145"], ["70594.80", "0.004"], ["70596.30", "0.019"], ["70598.80", "0.071"], ["70600.80", "0.188"], ["70603.30", "0.003"], ["70605.90", "0.118"], ["70607.80", "0.185"], ["70612.90", "0.151"], ["70620.10", "0.205"], ["70687.80", "0.204"], ["70706.20", "0.002"], ["70715.70", "0.571"], ["70726.00", "0.259"], ["70796.80", "0.007"], ["70803.90", "0.007"], ["70811.00", "0.018"], ["70818.10", "0.018"], ["70825.20", "0.007"], ["70832.30", "0.007"], ["70839.40", "0.009"], ["70846.50", "0.334"], ["71220.10", "1.617"], ["71408.30", "4.195"], ["71524.90", "2.652"], ["71790.60", "4.174"], ["72630.40", "0.027"]]}}
{"local_ts": 1773485558120, "server_ts": 1773485557326, "data": {"e": "depthUpdate", "E": 1773485557327, "T": 1773485557326, "s": "BTCUSDT", "U": 10109454767031, "u": 10109454772093, "pu": 10109454767019, "b": [["5000.00", "101.418"], ["7051.80", "0.028"], ["20017.70", "0.320"], ["20114.90", "1.500"], ["33000.00", "3.789"], ["66963.10", "0.000"], ["66989.20", "0.004"], ["69812.50", "0.005"], ["70007.20", "0.000"], ["70162.30", "0.036"], ["70230.70", "0.412"], ["70268.80", "0.020"], ["70276.30", "0.004"], ["70287.70", "0.005"], ["70330.80", "0.159"], ["70331.80", "0.020"], ["70334.40", "0.159"], ["70359.00", "0.048"], ["70362.60", "0.121"], ["70380.50", "0.158"], ["70428.60", "0.081"], ["70466.90", "0.344"], ["70467.60", "0.672"], ["70468.60", "0.015"], ["70469.60", "0.268"], ["70477.40", "0.003"], ["70478.60", "0.002"], ["70481.20", "0.845"], ["70482.30", "0.616"], ["70482.90", "0.000"], ["70483.00", "0.095"], ["70483.80", "2.007"], ["70487.80", "0.069"], ["70490.10", "0.002"], ["70490.30", "0.122"], ["70491.00", "0.035"], ["70495.70", "0.000"], ["70500.40", "1.208"], ["70501.00", "0.047"], ["70501.90", "0.007"], ["70503.80", "0.153"], ["70504.20", "0.005"], ["70505.00", "0.027"], ["70506.40", "0.084"], ["70507.10", "0.013"], ["70507.40", "0.371"], ["70508.70", "0.106"], ["70508.90", "0.639"], ["70509.50", "0.000"], ["70510.60", "0.005"], ["70510.80", "0.121"], ["70511.10", "0.003"], ["70512.60", "0.068"], ["70513.20", "0.111"], ["70513.60", "0.052"], ["70513.80", "0.001"], ["70513.90", "1.069"], ["70514.00", "0.336"], ["70514.60", "0.006"], ["70514.80", "0.015"], ["70514.90", "0.543"], ["70515.00", "1.105"], ["70515.10", "0.004"], ["70515.30", "0.203"], ["70515.80", "0.009"], ["70516.00", "0.009"], ["70516.20", "0.388"], ["70516.30", "1.100"], ["70516.40", "0.000"], ["70516.60", "0.002"], ["70517.40", "0.001"], ["70517.50", "0.441"], ["70517.60", "0.706"], ["70517.70", "10.904"]], "a": [["70517.80", "1.179"], ["70518.00", "0.033"], ["70518.10", "0.002"], ["70518.30", "0.002"], ["70518.50", "0.000"], ["70519.30", "0.002"], ["70520.00", "0.081"], ["70520.20", "0.002"], ["70520.70", "0.019"], ["70521.00", "0.214"], ["70524.30", "0.007"], ["70524.80", "0.003"], ["70525.80", "0.006"], ["70526.50", "0.001"], ["70528.40", "0.221"], ["70528.50", "0.277"], ["70530.10", "0.011"], ["70532.00", "0.254"], ["70533.10", "0.052"], ["70534.30", "0.514"], ["70534.80", "0.034"], ["70535.00", "0.002"], ["70536.70", "0.000"], ["70537.20", "0.276"], ["70537.60", "0.001"], ["70538.00", "0.038"], ["70539.40", "0.287"], ["70540.60", "0.002"], ["70540.80", "0.104"], ["70542.30", "0.089"], ["70543.20", "0.198"], ["70543.50", "0.592"], ["70544.00", "0.725"], ["70545.20", "0.006"], ["70545.50", "0.003"], ["70551.70", "0.005"], ["70553.70", "0.353"], ["70553.90", "0.004"], ["70554.00", "0.010"], ["70555.00", "0.046"], ["70555.80", "0.228"], ["70556.30", "0.000"], ["70562.90", "0.140"], ["70564.30", "0.003"], ["70565.00", "0.043"], ["70565.10", "0.225"], ["70565.70", "0.044"], ["70566.40", "0.021"], ["70568.50", "0.004"], ["70579.10", "0.300"], ["70623.00", "2.587"], ["70633.20", "0.006"], ["70684.20", "0.204"], ["70694.10", "0.337"], ["70724.30", "0.003"], ["70726.00", "0.257"], ["70727.80", "0.007"], ["70731.90", "0.024"], ["70856.80", "19.420"], ["71223.00", "0.000"], ["74047.80", "0.002"], ["74053.00", "0.050"], ["89523.20", "0.000"]]}}
{"local_ts": 1773485559138, "server_ts": 1773485558348, "data": {"e": "depthUpdate", "E": 1773485558349, "T": 1773485558348, "s": "BTCUSDT", "U": 10109454824048, "u": 10109454829714, "pu": 10109454824041, "b": [["1000.00", "28.842"], ["5000.00", "101.418"], ["7051.80", "0.000"], ["20014.90", "0.940"], ["20017.70", "0.990"], ["20417.70", "1.050"], ["68402.10", "0.000"], ["68960.20", "0.000"], ["69387.60", "0.000"], ["69458.10", "0.000"], ["69459.90", "0.499"], ["69530.50", "0.498"], ["69812.50", "0.005"], ["69812.60", "0.000"], ["70271.80", "0.089"], ["70422.30", "0.149"], ["70429.30", "0.071"], ["70436.40", "0.071"], ["70460.30", "0.585"], ["70463.20", "1.153"], ["70463.60", "0.101"], ["70463.90", "0.096"], ["70464.30", "0.094"], ["70465.00", "0.808"], ["70472.70", "0.230"], ["70486.20", "0.090"], ["70489.20", "0.000"], ["70489.30", "0.000"], ["70489.90", "0.004"], ["70490.00", "0.604"], ["70491.00", "0.000"], ["70507.10", "0.010"], ["70507.20", "0.002"], ["70507.30", "1.013"], ["70507.40", "0.397"], ["70507.60", "0.220"], ["70507.90", "0.040"], ["70508.00", "0.055"], ["70508.30", "0.097"], ["70508.40", "0.008"], ["70509.00", "0.492"], ["70510.50", "0.001"]], "a": [["70517.80", "2.007"], ["70519.00", "0.080"], ["70520.00", "0.081"], ["70524.70", "0.023"], ["70524.80", "0.003"], ["70525.20", "0.008"], ["70526.50", "0.026"], ["70527.20", "0.064"], ["70527.50", "0.037"], ["70527.60", "0.031"], ["70527.90", "0.135"], ["70528.20", "0.253"], ["70528.40", "0.008"], ["70528.50", "0.277"], ["70533.10", "0.008"], ["70534.00", "0.000"], ["70534.40", "0.111"], ["70546.70", "0.005"], ["70546.80", "0.004"], ["70547.40", "0.087"], ["70547.50", "0.900"], ["70548.50", "0.025"], ["70549.20", "0.064"], ["70549.60", "0.063"], ["70549.90", "1.285"], ["70550.30", "0.325"], ["70551.70", "0.077"], ["70560.10", "0.099"], ["70575.20", "0.038"], ["70575.60", "0.044"], ["70598.70", "0.270"], ["70605.80", "0.076"], ["70612.80", "0.071"], ["70668.10", "0.606"], ["70694.10", "0.277"], ["70731.90", "0.022"], ["71223.00", "0.000"], ["71524.90", "1.326"], ["74057.40", "0.002"], ["89523.20", "0.000"]]}}
{"local_ts": 1773485560159, "server_ts": 1773485559368, "data": {"e": "depthUpdate", "E": 1773485559369, "T": 1773485559368, "s": "BTCUSDT", "U": 10109454885556, "u": 10109454891454, "pu": 10109454885555, "b": [["5000.00", "101.418"], ["7051.80", "0.000"], ["20014.90", "0.000"], ["20317.70", "0.610"], ["20417.70", "2.390"], ["63167.90", "0.000"], ["69529.00", "0.000"], ["69565.70", "5.740"], ["69663.90", "1.420"], ["69812.50", "0.714"], ["69883.10", "0.000"], ["69988.80", "0.798"], ["70271.50", "0.208"], ["70323.80", "0.162"], ["70344.90", "0.039"], ["70348.50", "0.550"], ["70472.80", "0.184"], ["70507.10", "0.010"], ["70507.40", "1.035"], ["70508.20", "1.072"], ["70510.60", "0.002"], ["70514.60", "0.008"], ["70514.90", "0.128"], ["70517.70", "10.956"]], "a": [["70517.80", "2.989"], ["70523.90", "0.057"], ["70528.00", "0.011"], ["70528.40", "0.005"], ["70531.60", "0.023"], ["70531.80", "0.153"], ["70532.20", "0.008"], ["70532.90", "0.024"], ["70533.10", "0.052"], ["70533.40", "0.204"], ["70533.50", "0.019"], ["70538.70", "0.217"], ["70539.50", "0.661"], ["70549.80", "0.060"], ["70552.30", "0.004"], ["70562.80", "0.297"], ["70563.20", "0.087"], ["70666.30", "0.096"], ["70668.10", "0.604"], ["70694.10", "0.337"], ["70729.30", "6.492"], ["70835.10", "0.000"], ["70856.30", "0.285"], ["71191.10", "0.002"], ["71223.00", "0.000"], ["71465.90", "0.805"], ["71496.50", "1.958"], ["71514.00", "5.097"], ["71526.10", "14.269"], ["71596.60", "6.840"], ["74058.80", "0.000"], ["89523.20", "0.000"]]}}
{"local_ts": 1773485561180, "server_ts": 1773485560388, "data": {"e": "depthUpdate", "E": 1773485560391, "T": 1773485560388, "s": "BTCUSDT", "U": 10109454940751, "u": 10109454945440, "pu": 10109454940672, "b": [["1000.00", "28.842"], ["5000.00", "101.418"], ["7051.80", "0.000"], ["20217.70", "0.290"], ["20317.70", "2.580"], ["20417.70", "0.130"], ["61209.40", "0.700"], ["66978.60", "0.000"], ["68500.00", "85.971"], ["69258.20", "8.075"], ["69657.60", "6.822"], ["69812.50", "1.069"], ["70165.10", "0.071"], ["70345.90", "0.000"], ["70367.20", "0.001"], ["70367.60", "3.054"], ["70422.30", "0.149"], ["70429.30", "0.071"], ["70436.40", "0.071"], ["70441.20", "0.315"], ["70441.90", "0.096"], ["70469.70", "0.013"], ["70469.90", "0.008"], ["70482.50", "0.073"], ["70483.40", "0.003"], ["70483.50", "0.101"], ["70488.40", "0.122"], ["70489.90", "0.193"], ["70490.20", "1.131"], ["70490.60", "0.063"], ["70502.10", "0.015"], ["70506.20", "0.019"], ["70506.70", "0.283"], ["70507.10", "0.010"], ["70507.20", "0.002"], ["70507.30", "0.065"], ["70507.90", "0.000"], ["70508.30", "0.003"], ["70508.70", "0.106"], ["70510.50", "0.004"], ["70511.90", "0.377"], ["70512.20", "0.159"], ["70513.00", "0.097"], ["70513.30", "0.041"], ["70516.40", "0.002"], ["70517.70", "3.809"]], "a": [["70528.40", "0.005"], ["70538.40", "0.188"], ["70538.70", "0.174"], ["70539.40", "0.202"], ["70560.10", "0.290"], ["70562.80", "0.028"], ["70598.70", "0.270"], ["70605.80", "0.076"], ["70608.10", "0.389"], ["70612.80", "0.071"], ["70652.20", "0.011"], ["70658.10", "0.360"], ["70660.20", "0.355"], ["70663.10", "2.484"], ["70666.30", "0.094"], ["70741.60", "0.092"], ["71223.00", "0.000"], ["72633.30", "0.008"], ["74057.80", "0.005"], ["89523.20", "0.000"]]}}
{"local_ts": 1773485562206, "server_ts": 1773485561412, "data": {"e": "depthUpdate", "E": 1773485561413, "T": 1773485561412, "s": "BTCUSDT", "U": 10109454992788, "u": 10109454997633, "pu": 10109454992743, "b": [["1000.00", "28.842"], ["5000.00", "101.418"], ["7051.00", "0.000"], ["7051.80", "0.056"], ["20117.70", "0.150"], ["20217.70", "2.420"], ["20317.70", "0.430"], ["66968.10", "0.002"], ["68749.40", "2.614"], ["69107.40", "0.018"], ["69424.70", "3.882"], ["69812.50", "1.069"], ["70470.50", "0.001"], ["70470.70", "0.572"], ["70471.90", "0.890"], ["70491.30", "0.490"], ["70491.90", "0.055"], ["70493.00", "0.000"], ["70493.90", "0.003"], ["70496.40", "0.343"], ["70497.60", "0.000"], ["70498.30", "0.074"], ["70500.10", "1.213"], ["70501.00", "0.047"], ["70503.60", "0.194"], ["70504.00", "0.151"], ["70504.90", "0.138"], ["70505.10", "0.022"], ["70505.40", "0.010"], ["70505.80", "0.654"], ["70506.30", "0.005"], ["70506.50", "0.027"], ["70506.60", "0.007"], ["70506.70", "0.283"], ["70506.80", "0.000"], ["70507.10", "0.013"], ["70507.40", "0.276"], ["70507.60", "0.012"], ["70508.40", "0.008"], ["70508.80", "0.043"], ["70509.70", "0.011"], ["70510.50", "0.001"], ["70510.60", "0.009"], ["70510.70", "0.072"], ["70511.70", "0.018"], ["70512.60", "0.169"], ["70513.10", "0.002"], ["70513.70", "0.082"], ["70516.20", "0.236"], ["70516.30", "0.010"], ["70516.50", "0.000"], ["70516.60", "0.006"], ["70516.70", "0.000"], ["70516.80", "0.004"], ["70516.90", "0.000"], ["70517.10", "0.000"], ["70517.40", "0.002"], ["70517.50", "0.006"], ["70517.70", "3.794"]], "a": [["70517.80", "3.315"], ["70518.00", "0.033"], ["70518.10", "0.002"], ["70518.20", "0.000"], ["70519.50", "0.009"], ["70521.10", "0.079"], ["70521.30", "0.003"], ["70522.90", "0.015"], ["70523.50", "0.009"], ["70525.10", "0.005"], ["70525.40", "0.003"], ["70527.40", "0.000"], ["70527.80", "0.015"], ["70528.40", "0.008"], ["70529.00", "0.022"], ["70531.50", "0.143"], ["70531.70", "0.006"], ["70531.80", "0.012"], ["70533.70", "0.003"], ["70535.40", "0.000"], ["70539.00", "0.273"], ["70541.90", "0.031"], ["70546.90", "0.253"], ["70549.20", "0.064"], ["70549.50", "0.185"], ["70558.10", "0.000"], ["70560.10", "0.570"], ["70561.90", "0.000"], ["70580.40", "8.835"], ["70584.50", "0.625"], ["70585.30", "0.003"], ["70590.00", "0.743"], ["70741.60", "0.099"], ["71223.00", "0.144"], ["71925.20", "0.016"], ["71928.10", "0.018"], ["89523.20", "0.000"]]}}
{"local_ts": 1773485563225, "server_ts": 1773485562433, "data": {"e": "depthUpdate", "E": 1773485562435, "T": 1773485562433, "s": "BTCUSDT", "U": 10109455038816, "u": 10109455042527, "pu": 10109455038640, "b": [["5000.00", "101.418"], ["7051.80", "0.056"], ["20117.70", "2.270"], ["20217.70", "0.730"], ["33000.00", "3.785"], ["66960.40", "0.000"], ["68397.30", "3.504"], ["69812.50", "1.069"], ["70165.10", "0.071"], ["70470.10", "0.634"], ["70470.20", "0.004"], ["70489.20", "0.081"], ["70490.80", "0.019"], ["70502.30", "0.000"], ["70503.30", "0.002"], ["70507.10", "0.010"], ["70510.70", "0.029"], ["70515.90", "0.015"], ["70516.30", "0.010"], ["70516.40", "0.002"], ["70517.30", "0.009"], ["70517.40", "0.002"], ["70517.60", "0.183"], ["70517.70", "3.689"]], "a": [["70517.80", "2.376"], ["70518.10", "0.002"], ["70518.40", "0.015"], ["70518.70", "0.000"], ["70518.80", "0.003"], ["70519.10", "0.001"], ["70519.40", "0.000"], ["70519.60", "0.008"], ["70519.70", "0.000"], ["70519.90", "0.019"], ["70523.30", "0.000"], ["70523.40", "0.005"], ["70535.40", "0.154"], ["70741.20", "0.028"], ["71032.40", "0.004"], ["71223.00", "0.000"], ["71349.70", "8.116"], ["71468.30", "0.000"], ["74058.30", "0.002"], ["89523.20", "0.000"]]}}
{"local_ts": 1773485564250, "server_ts": 1773485563456, "data": {"e": "depthUpdate", "E": 1773485563459, "T": 1773485563456, "s": "BTCUSDT", "U": 10109455078030, "u": 10109455082179, "pu": 10109455077996, "b": [["1000.00", "28.842"], ["5000.00", "101.438"], ["7051.80", "0.056"], ["20017.70", "1.830"], ["20117.70", "1.170"], ["66991.80", "0.010"], ["69258.20", "4.614"], ["69283.60", "6.774"], ["69692.60", "1.719"], ["69812.50", "1.069"], ["69812.60", "0.000"], ["70198.60", "4.981"], ["70271.70", "0.027"], ["70275.50", "4.293"], ["70327.30", "0.231"], ["70464.30", "0.000"], ["70464.50", "0.063"], ["70464.90", "0.068"], ["70467.80", "0.352"], ["70468.20", "0.101"], ["70468.50", "0.096"], ["70468.90", "2.129"], ["70469.60", "0.304"], ["70470.10", "0.634"], ["70470.20", "0.004"], ["70482.40", "0.008"], ["70507.10", "0.010"], ["70510.70", "0.072"], ["70511.80", "0.375"], ["70512.10", "0.006"], ["70512.20", "0.220"], ["70512.50", "0.062"], ["70512.60", "0.122"], ["70512.90", "0.097"], ["70513.60", "0.090"], ["70514.00", "0.251"], ["70516.40", "0.059"], ["70516.50", "0.002"], ["70516.60", "0.019"], ["70516.90", "0.000"], ["70517.70", "3.721"]], "a": [["70518.00", "0.033"], ["70519.50", "0.001"], ["70520.00", "0.081"], ["70520.90", "0.008"], ["70521.60", "0.018"], ["70523.40", "0.002"], ["70526.60", "0.000"], ["70528.20", "0.058"], ["70528.50", "0.032"], ["70529.20", "0.063"], ["70529.50", "0.039"], ["70529.60", "0.026"], ["70529.90", "0.140"], ["70530.20", "0.187"], ["70535.40", "0.015"], ["70540.90", "0.258"], ["70549.50", "0.185"], ["70550.50", "0.030"], ["70551.20", "0.436"], ["70551.60", "0.508"], ["70551.90", "0.185"], ["70552.30", "0.218"], ["70553.70", "0.425"], ["70560.10", "0.431"], ["70577.20", "0.214"], ["70577.60", "0.036"], ["70687.00", "0.579"], ["70731.70", "0.010"], ["70741.20", "0.028"], ["70763.30", "0.191"], ["70835.10", "0.211"], ["70840.90", "4.143"], ["70841.10", "0.648"], ["70844.90", "3.255"], ["70856.30", "0.074"], ["70863.20", "0.000"], ["70863.30", "0.004"], ["70999.90", "3.240"], ["71059.80", "1.207"], ["71223.00", "0.000"], ["74060.50", "0.057"], ["74061.60", "0.023"], ["89523.20", "0.000"]]}}
{"local_ts": 1773485565276, "server_ts": 1773485564482, "data": {"e": "depthUpdate", "E": 1773485564483, "T": 1773485564482, "s": "BTCUSDT", "U": 10109455127004, "u": 10109455130242, "pu": 10109455126915, "b": [["5000.00", "101.418"], ["7051.80", "0.028"], ["20017.70", "1.610"], ["20417.70", "1.390"], ["33000.00", "3.785"], ["66984.30", "0.002"], ["67697.00", "0.010"], ["69596.00", "67.179"], ["69812.50", "1.427"], ["70497.40", "0.002"], ["70499.70", "0.059"], ["70507.10", "0.013"], ["70510.50", "0.004"], ["70516.50", "0.000"], ["70516.70", "0.002"], ["70517.70", "3.792"]], "a": [["70517.80", "2.486"], ["70519.90", "0.012"], ["70524.00", "0.007"], ["70528.40", "0.008"], ["70538.60", "0.221"], ["70555.10", "1.926"], ["70563.20", "0.002"], ["70574.80", "0.839"], ["70576.40", "3.488"], ["70609.10", "2.532"], ["70611.70", "6.463"], ["70669.30", "2.315"], ["70670.60", "12.679"], ["70670.90", "0.000"], ["70677.90", "0.018"], ["70694.10", "0.277"], ["70731.60", "0.588"], ["70863.50", "0.007"], ["70864.40", "0.000"], ["70867.90", "0.009"], ["71223.00", "0.000"], ["71450.30", "45.911"], ["71514.00", "4.469"], ["71751.90", "1.114"], ["72226.60", "0.593"], ["74073.70", "0.000"], ["89523.20", "0.000"]]}}
{"local_ts": 1773485566296, "server_ts": 1773485565504, "data": {"e": "depthUpdate", "E": 1773485565505, "T": 1773485565504, "s": "BTCUSDT", "U": 10109455159542, "u": 10109455163455, "pu": 10109455159520, "b": [["1000.00", "28.842"], ["5000.00", "101.418"], ["7051.80", "0.028"], ["20317.70", "0.950"], ["20417.70", "2.050"], ["66976.90", "0.002"], ["66978.80", "0.002"], ["69812.50", "1.427"], ["70165.10", "0.071"], ["70165.20", "0.009"], ["70271.80", "0.089"], ["70330.80", "0.159"], ["70368.80", "3.151"], ["70462.20", "0.087"], ["70462.30", "0.021"], ["70502.10", "0.015"], ["70507.10", "0.010"], ["70508.80", "0.046"], ["70510.50", "0.001"], ["70515.70", "0.002"], ["70517.70", "3.665"]], "a": [["70517.80", "2.516"], ["70519.80", "0.089"], ["70521.40", "0.062"], ["70526.40", "0.021"], ["70528.40", "0.013"], ["70535.40", "0.235"], ["70538.60", "0.037"], ["70539.00", "0.414"], ["70539.40", "0.187"], ["70544.10", "0.015"], ["70545.90", "0.007"], ["70547.90", "0.002"], ["70549.50", "0.185"], ["70554.60", "0.004"], ["70560.10", "0.431"], ["70663.20", "2.512"], ["70741.20", "0.035"], ["70838.60", "0.004"], ["71223.00", "0.000"], ["71259.90", "0.009"], ["71567.80", "5.797"], ["71928.10", "0.018"], ["89523.20", "0.000"]]}}
{"local_ts": 1773485567316, "server_ts": 1773485566524, "data": {"e": "depthUpdate", "E": 1773485566525, "T": 1773485566524, "s": "BTCUSDT", "U": 10109455201154, "u": 10109455205213, "pu": 10109455201056, "b": [["1000.00", "28.842"], ["5000.00", "101.418"], ["7051.80", "0.028"], ["20217.70", "0.500"], ["20317.70", "2.500"], ["20417.70", "0.000"], ["33000.00", "3.789"], ["56414.00", "0.007"], ["66959.40", "0.000"], ["69469.70", "2.731"], ["69812.50", "1.427"], ["69812.60", "0.004"], ["70271.80", "0.085"], ["70327.30", "0.231"], ["70422.40", "0.004"], ["70429.40", "0.000"], ["70436.50", "0.000"], ["70470.50", "0.001"], ["70470.70", "0.572"], ["70472.30", "0.331"], ["70486.00", "1.126"], ["70486.70", "0.602"], ["70504.60", "0.005"], ["70505.50", "0.005"], ["70507.10", "0.015"], ["70508.80", "0.043"], ["70510.40", "0.011"], ["70517.70", "4.273"]], "a": [["70517.80", "1.333"], ["70528.40", "0.013"], ["70532.00", "0.177"], ["70532.30", "0.005"], ["70532.40", "0.007"], ["70533.00", "0.014"], ["70534.00", "0.000"], ["70535.10", "0.020"], ["70539.00", "0.412"], ["70560.10", "0.510"], ["70598.70", "0.199"], ["70605.80", "0.005"], ["70612.80", "0.000"], ["70741.10", "0.005"], ["70775.70", "0.007"], ["71223.00", "0.000"], ["71928.10", "0.018"], ["74075.70", "0.002"], ["89523.20", "0.000"]]}}
{"local_ts": 1773485568338, "server_ts": 1773485567546, "data": {"e": "depthUpdate", "E": 1773485567547, "T": 1773485567546, "s": "BTCUSDT", "U": 10109455243200, "u": 10109455248266, "pu": 10109455243186, "b": [["1000.00", "28.992"], ["5000.00", "101.418"], ["7051.80", "0.000"], ["20117.70", "0.260"], ["20217.70", "2.530"], ["20317.70", "0.210"], ["56414.00", "0.003"], ["66980.50", "0.000"], ["68600.00", "28.408"], ["69107.40", "0.027"], ["69812.50", "1.427"], ["70165.10", "0.071"], ["70344.90", "0.000"], ["70422.40", "0.022"], ["70429.40", "0.071"], ["70430.50", "6.703"], ["70436.50", "0.071"], ["70462.40", "0.283"], ["70462.50", "0.113"], ["70465.80", "3.536"], ["70470.50", "0.003"], ["70470.70", "0.570"], ["70484.60", "0.002"], ["70487.00", "1.819"], ["70487.70", "0.721"], ["70489.50", "0.135"], ["70507.10", "0.015"], ["70510.40", "0.011"], ["70516.20", "0.236"], ["70517.40", "0.000"]], "a": [["70528.40", "0.010"], ["70530.00", "0.147"], ["70539.00", "0.412"], ["70560.10", "0.272"], ["70598.80", "0.071"], ["70605.90", "0.118"], ["70612.90", "1.568"], ["70614.20", "0.124"], ["70900.00", "11.872"], ["71223.00", "0.140"], ["71646.10", "7.664"], ["71751.90", "2.227"], ["74044.50", "0.004"], ["74065.50", "0.052"], ["89523.20", "0.006"]]}}
{"local_ts": 1773485569361, "server_ts": 1773485568570, "data": {"e": "depthUpdate", "E": 1773485568571, "T": 1773485568570, "s": "BTCUSDT", "U": 10109455292374, "u": 10109455296947, "pu": 10109455292352, "b": [["1000.00", "28.842"], ["5000.00", "101.418"], ["7051.80", "0.000"], ["20017.70", "0.110"], ["20117.70", "2.390"], ["20217.70", "0.500"], ["56414.00", "0.003"], ["69107.40", "0.024"], ["69416.70", "2.155"], ["69511.70", "0.005"], ["69516.30", "0.865"], ["69812.50", "1.427"], ["69812.70", "0.717"], ["69836.30", "0.150"], ["70271.80", "0.089"], ["70440.40", "0.061"], ["70441.20", "0.060"], ["70445.60", "0.126"], ["70445.90", "0.138"], ["70446.20", "0.042"], ["70446.30", "0.056"], ["70446.60", "0.040"], ["70447.30", "0.038"], ["70465.30", "0.755"], ["70478.20", "0.128"], ["70502.10", "0.100"], ["70507.10", "0.650"], ["70510.50", "0.001"], ["70517.70", "4.099"]], "a": [["70517.80", "1.148"], ["70524.80", "0.204"], ["70528.00", "0.065"], ["70528.40", "0.010"], ["70528.50", "0.007"], ["70529.00", "0.062"], ["70529.40", "0.122"], ["70530.40", "0.013"], ["70531.60", "0.044"], ["70534.50", "0.058"], ["70539.00", "0.412"], ["70539.40", "0.187"], ["70546.00", "0.230"], ["70546.20", "0.466"], ["70560.10", "0.290"], ["70562.80", "0.028"], ["70565.10", "0.225"], ["70572.30", "0.484"], ["70573.00", "1.028"], ["70573.40", "0.280"], ["70573.70", "0.112"], ["70574.10", "0.086"], ["70598.00", "0.014"], ["70598.90", "0.045"], ["71223.00", "0.140"], ["71355.10", "0.002"], ["71364.00", "2.243"], ["74065.10", "0.042"]]}}
{"local_ts": 1773485570379, "server_ts": 1773485569590, "data": {"e": "depthUpdate", "E": 1773485569591, "T": 1773485569590, "s": "BTCUSDT", "U": 10109455366160, "u": 10109455371082, "pu": 10109455366135, "b": [["5000.00", "101.418"], ["7052.00", "0.000"], ["20020.20", "0.440"], ["20117.70", "0.840"], ["40000.00", "41.356"], ["56414.00", "0.003"], ["66972.10", "0.000"], ["69407.20", "10.647"], ["69424.70", "6.903"], ["69812.60", "0.000"], ["69815.00", "0.017"], ["70217.70", "0.267"], ["70234.80", "0.004"], ["70271.70", "0.002"], ["70428.60", "0.083"], ["70430.80", "0.954"], ["70435.30", "0.383"], ["70435.40", "0.555"], ["70464.10", "8.513"], ["70464.40", "0.018"], ["70464.70", "0.000"], ["70465.00", "0.865"], ["70467.10", "0.002"], ["70467.40", "0.005"], ["70468.10", "0.003"], ["70468.40", "0.004"], ["70470.30", "0.000"], ["70471.00", "0.000"], ["70471.40", "0.004"], ["70471.70", "1.070"], ["70472.60", "0.407"], ["70473.20", "0.269"], ["70481.10", "0.002"], ["70483.80", "0.754"], ["70487.10", "0.263"], ["70487.20", "0.026"], ["70487.80", "0.002"], ["70487.90", "0.129"], ["70488.90", "0.248"], ["70489.10", "1.821"], ["70489.40", "0.003"], ["70489.70", "0.052"], ["70490.20", "1.322"], ["70491.30", "0.204"], ["70491.70", "0.081"], ["70492.00", "0.437"], ["70493.10", "0.045"], ["70494.70", "0.073"], ["70494.90", "0.009"], ["70495.50", "0.512"], ["70496.20", "0.004"], ["70496.80", "0.076"], ["70497.00", "0.010"], ["70497.60", "0.141"], ["70498.30", "0.007"], ["70498.50", "0.513"], ["70499.00", "0.119"], ["70499.10", "0.002"], ["70499.20", "0.001"], ["70499.90", "0.121"], ["70500.30", "0.001"], ["70500.50", "0.004"], ["70501.30", "0.005"], ["70501.40", "0.000"], ["70501.50", "1.205"], ["70501.70", "0.342"], ["70502.00", "1.317"], ["70502.10", "0.017"], ["70502.40", "0.009"], ["70503.00", "0.000"], ["70503.20", "0.001"], ["70503.30", "0.002"], ["70503.80", "0.019"], ["70504.10", "0.004"], ["70504.80", "0.159"], ["70505.80", "0.135"], ["70505.90", "0.007"], ["70506.30", "0.005"], ["70506.60", "0.652"], ["70507.40", "0.309"], ["70507.60", "0.010"], ["70507.70", "0.014"], ["70507.90", "0.000"], ["70508.50", "0.005"], ["70508.80", "0.043"], ["70508.90", "0.286"], ["70509.00", "0.454"], ["70509.20", "0.305"], ["70509.30", "0.000"], ["70509.60", "0.050"], ["70509.70", "0.007"], ["70509.80", "0.518"], ["70509.90", "0.143"], ["70510.10", "0.004"], ["70510.40", "0.007"], ["70510.50", "0.001"], ["70510.70", "0.029"], ["70510.80", "0.114"], ["70511.70", "0.022"], ["70511.90", "0.214"], ["70513.00", "0.250"], ["70513.10", "0.004"], ["70513.30", "0.063"], ["70513.40", "0.004"], ["70514.00", "0.002"], ["70514.10", "1.074"], ["70514.20", "0.547"], ["70514.60", "0.006"], ["70514.80", "0.010"], ["70514.90", "0.146"], ["70515.20", "0.006"], ["70515.40", "0.002"], ["70515.50", "0.001"], ["70515.70", "0.003"], ["70515.80", "0.000"], ["70516.10", "0.141"], ["70516.40", "0.001"], ["70516.60", "0.000"], ["70517.00", "0.003"], ["70517.30", "0.057"], ["70517.60", "0.004"], ["70517.70", "0.417"], ["70517.80", "0.514"], ["70517.90", "0.324"], ["70518.60", "0.021"], ["70518.80", "0.000"], ["70519.20", "0.318"], ["70519.80", "0.003"], ["70519.90", "0.001"], ["70520.10", "0.028"], ["70520.20", "7.897"]], "a": [["70520.30", "3.642"], ["70521.00", "0.002"], ["70522.60", "0.004"], ["70523.10", "0.000"], ["70523.20", "0.005"], ["70523.40", "0.010"], ["70524.30", "0.007"], ["70524.70", "0.044"], ["70524.80", "0.003"], ["70525.40", "0.021"], ["70527.40", "0.000"], ["70527.50", "0.205"], ["70528.60", "0.007"], ["70529.10", "0.059"], ["70529.40", "0.028"], ["70530.90", "0.008"], ["70531.00", "0.012"], ["70532.00", "0.082"], ["70532.20", "0.026"], ["70533.30", "0.153"], ["70533.60", "0.004"], ["70533.70", "0.010"], ["70533.90", "0.002"], ["70534.10", "0.006"], ["70534.40", "0.002"], ["70534.60", "0.027"], ["70535.30", "0.008"], ["70535.50", "0.029"], ["70535.60", "0.002"], ["70535.70", "0.003"], ["70535.90", "0.047"], ["70536.30", "0.006"], ["70536.50", "0.008"], ["70536.60", "0.113"], ["70536.80", "0.009"], ["70537.10", "0.461"], ["70537.20", "0.210"], ["70537.30", "0.025"], ["70537.90", "0.014"], ["70538.20", "0.024"], ["70538.40", "0.012"], ["70538.50", "0.000"], ["70539.40", "0.003"], ["70539.50", "0.230"], ["70540.10", "0.009"], ["70540.80", "0.010"], ["70541.40", "0.001"], ["70541.70", "0.056"], ["70542.00", "0.643"], ["70543.10", "0.510"], ["70543.50", "0.077"], ["70543.60", "0.310"], ["70543.80", "0.007"], ["70544.60", "0.522"], ["70544.70", "0.203"], ["70544.90", "0.081"], ["70545.30", "0.009"], ["70545.40", "0.016"], ["70545.70", "0.223"], ["70546.30", "0.377"], ["70546.40", "0.356"], ["70547.10", "0.002"], ["70547.40", "0.006"], ["70547.60", "0.012"], ["70548.20", "0.026"], ["70548.50", "0.000"], ["70548.80", "0.102"], ["70549.60", "0.004"], ["70550.90", "0.062"], ["70551.40", "0.294"], ["70551.80", "0.007"], ["70552.00", "0.006"], ["70552.70", "0.082"], ["70553.70", "0.355"], ["70556.00", "0.001"], ["70559.90", "0.000"], ["70561.10", "0.281"], ["70563.20", "0.059"], ["70563.50", "0.094"], ["70563.60", "0.006"], ["70566.00", "0.193"], ["70567.00", "0.072"], ["70567.30", "0.095"], ["70570.10", "0.021"], ["70571.00", "0.000"], ["70571.60", "0.004"], ["70579.80", "0.491"], ["70580.00", "0.150"], ["70580.40", "0.244"], ["70580.80", "8.504"], ["70581.00", "0.008"], ["70584.80", "0.083"], ["70588.00", "0.291"], ["70588.60", "0.000"], ["70588.70", "0.003"], ["70590.00", "0.083"], ["70595.00", "0.706"], ["70595.40", "0.003"], ["70595.80", "0.087"], ["70598.00", "0.012"], ["70600.90", "0.049"], ["70605.50", "0.082"], ["70608.50", "0.088"], ["70608.60", "0.044"], ["70609.00", "0.004"], ["70611.20", "3.031"], ["70613.00", "6.643"], ["70613.40", "0.097"], ["70623.00", "2.589"], ["70637.00", "4.606"], ["70650.60", "0.213"], ["70775.30", "0.000"], ["70856.20", "0.782"], ["71225.50", "0.000"], ["71613.20", "0.111"], ["71778.20", "2.782"], ["71930.70", "0.006"], ["100000.00", "23.620"]]}}
{"local_ts": 1773485571401, "server_ts": 1773485570608, "data": {"e": "depthUpdate", "E": 1773485570611, "T": 1773485570608, "s": "BTCUSDT", "U": 10109455418535, "u": 10109455421869, "pu": 10109455418521, "b": [["1000.00", "28.842"], ["5000.00", "101.418"], ["7052.10", "0.056"], ["20017.70", "1.040"], ["20020.20", "0.190"], ["20420.20", "1.710"], ["56414.00", "0.003"], ["66991.80", "0.006"], ["66991.90", "0.010"], ["69283.60", "9.080"], ["69815.00", "0.015"], ["70095.50", "38.399"], ["70095.60", "6.310"], ["70151.10", "0.213"], ["70167.60", "0.014"], ["70200.80", "31.657"], ["70202.70", "8.893"], ["70278.10", "26.199"], ["70279.90", "7.003"], ["70385.40", "0.149"], ["70388.70", "0.471"], ["70425.30", "0.020"], ["70432.30", "0.080"], ["70439.40", "0.071"], ["70450.00", "0.126"], ["70486.00", "0.000"], ["70507.00", "0.002"], ["70513.20", "0.096"], ["70518.40", "0.002"]], "a": [["70520.30", "4.046"], ["70520.60", "0.092"], ["70521.40", "0.062"], ["70527.30", "0.002"], ["70542.20", "0.199"], ["70542.30", "0.344"], ["70542.50", "0.203"], ["70544.80", "0.090"], ["70545.00", "0.082"], ["70546.00", "0.782"], ["70553.60", "0.824"], ["70560.30", "0.570"], ["70561.40", "0.007"], ["70563.30", "7.838"], ["70567.40", "0.278"], ["70576.70", "0.166"], ["70600.90", "0.047"], ["70601.70", "0.086"], ["70608.80", "0.103"], ["70615.80", "0.279"], ["70650.20", "0.000"], ["70656.40", "0.859"], ["70764.40", "0.162"], ["70764.50", "21.011"], ["70841.20", "0.211"], ["70842.30", "24.748"], ["70844.90", "3.255"], ["70856.20", "0.712"], ["70862.10", "0.000"], ["70863.30", "0.004"], ["70948.50", "15.300"], ["70948.60", "30.291"], ["70999.90", "3.240"], ["71059.80", "1.207"], ["71225.50", "0.000"], ["74070.00", "0.066"]]}}
{"local_ts": 1773485572422, "server_ts": 1773485571632, "data": {"e": "depthUpdate", "E": 1773485571633, "T": 1773485571632, "s": "BTCUSDT", "U": 10109455454700, "u": 10109455457992, "pu": 10109455454575, "b": [["5000.00", "101.418"], ["7052.10", "0.056"], ["20320.20", "1.270"], ["20420.20", "1.730"], ["33000.00", "3.785"], ["56414.00", "0.003"], ["66967.50", "0.000"], ["66986.40", "0.002"], ["69743.70", "0.000"], ["69815.00", "0.036"], ["70497.60", "0.000"], ["70499.10", "0.143"], ["70508.30", "0.003"], ["70509.60", "0.050"], ["70509.80", "0.801"], ["70512.70", "0.003"], ["70514.60", "0.006"], ["70515.50", "0.008"]], "a": [["70530.90", "0.005"], ["70540.80", "0.010"], ["70541.50", "0.228"], ["70542.10", "0.063"], ["70542.20", "0.015"], ["70542.30", "0.344"], ["70544.50", "0.000"], ["70545.30", "0.018"], ["70545.90", "0.191"], ["70558.40", "0.011"], ["70567.40", "0.276"], ["70743.80", "0.007"], ["70872.80", "0.000"], ["71225.50", "0.000"], ["71494.10", "0.041"]]}}
{"local_ts": 1773485573446, "server_ts": 1773485572652, "data": {"e": "depthUpdate", "E": 1773485572653, "T": 1773485572652, "s": "BTCUSDT", "U": 10109455497422, "u": 10109455501394, "pu": 10109455497394, "b": [["1000.00", "28.842"], ["5000.00", "101.418"], ["7052.10", "0.056"], ["20220.20", "0.820"], ["20320.20", "2.180"], ["56416.00", "0.000"], ["66986.40", "0.000"], ["69518.80", "0.286"], ["69815.00", "0.036"], ["69826.20", "0.007"], ["70151.10", "0.142"], ["70167.60", "0.085"], ["70198.50", "0.000"], ["70408.20", "0.258"], ["70472.70", "0.002"], ["70472.90", "0.373"], ["70485.00", "0.204"], ["70505.30", "0.446"], ["70509.60", "0.053"], ["70512.80", "0.060"], ["70513.10", "0.006"]], "a": [["70521.70", "0.057"], ["70527.20", "0.005"], ["70530.90", "0.008"], ["70534.80", "0.262"], ["70542.20", "0.284"], ["70542.30", "0.259"], ["70545.90", "0.007"], ["70558.40", "0.009"], ["70576.70", "0.106"], ["70581.30", "0.000"], ["70581.40", "0.105"], ["70590.80", "0.306"], ["70594.60", "0.012"], ["70598.70", "10.332"], ["71778.20", "1.391"], ["74064.40", "0.002"]]}}
{"local_ts": 1773485574467, "server_ts": 1773485573674, "data": {"e": "depthUpdate", "E": 1773485573675, "T": 1773485573674, "s": "BTCUSDT", "U": 10109455543092, "u": 10109455548324, "pu": 10109455543044, "b": [["1000.00", "28.842"], ["5000.00", "101.418"], ["7052.10", "0.028"], ["20120.20", "0.400"], ["20220.20", "2.570"], ["20320.20", "0.030"], ["33000.00", "3.785"], ["65555.00", "4.086"], ["68404.50", "0.003"], ["69427.10", "1.166"], ["69815.00", "1.456"], ["70438.60", "0.063"], ["70439.40", "0.129"], ["70444.20", "0.193"], ["70444.50", "0.099"], ["70444.80", "0.044"], ["70444.90", "0.054"], ["70445.20", "0.880"], ["70445.90", "0.077"], ["70513.10", "0.042"], ["70520.20", "6.636"]], "a": [["70520.30", "3.961"], ["70520.40", "0.102"], ["70521.50", "0.035"], ["70523.80", "0.007"], ["70527.20", "0.003"], ["70541.90", "0.093"], ["70542.00", "0.190"], ["70542.10", "0.063"], ["70542.20", "0.015"], ["70542.30", "0.344"], ["70574.00", "0.071"], ["70574.70", "0.025"], ["70575.10", "0.065"], ["70575.40", "0.064"], ["70575.80", "0.108"], ["70588.90", "0.004"], ["71225.50", "0.002"], ["74079.30", "0.000"]]}}
{"local_ts": 1773485575485, "server_ts": 1773485574692, "data": {"e": "depthUpdate", "E": 1773485574695, "T": 1773485574692, "s": "BTCUSDT", "U": 10109455585237, "u": 10109455588598, "pu": 10109455585216, "b": [["5000.00", "101.418"], ["7052.10", "0.028"], ["20020.20", "0.210"], ["20120.20", "2.500"], ["20220.20", "0.290"], ["66994.00", "0.002"], ["69109.80", "0.011"], ["69129.00", "0.773"], ["69287.30", "0.000"], ["69714.00", "0.000"], ["69815.00", "2.169"], ["70388.70", "0.000"], ["70486.70", "0.401"], ["70486.80", "0.093"], ["70509.60", "0.050"], ["70512.80", "0.057"], ["70512.90", "0.003"], ["70513.10", "0.042"], ["70520.20", "6.669"]], "a": [["70520.30", "3.950"], ["70527.20", "0.003"], ["70530.90", "0.005"], ["70541.90", "0.008"], ["70542.00", "0.006"], ["70542.20", "0.284"], ["70542.30", "0.075"], ["70545.90", "0.233"], ["70563.80", "0.007"], ["70576.70", "0.106"], ["70655.40", "0.039"], ["70693.10", "0.513"], ["71225.50", "0.701"], ["71408.30", "1.678"], ["74079.30", "0.002"]]}}
{"local_ts": 1773485576506, "server_ts": 1773485575716, "data": {"e": "depthUpdate", "E": 1773485575717, "T": 1773485575716, "s": "BTCUSDT", "U": 10109455623219, "u": 10109455626812, "pu": 10109455623128, "b": [["1000.00", "28.842"], ["5000.00", "101.418"], ["7052.10", "0.028"], ["20020.20", "2.340"], ["20120.20", "0.590"], ["20420.20", "0.070"], ["33000.00", "3.789"], ["66970.60", "0.002"], ["66994.00", "0.002"], ["69815.00", "2.169"], ["70167.60", "0.192"], ["70509.60", "0.147"], ["70513.00", "0.240"]], "a": [["70530.90", "0.008"], ["71225.50", "0.701"], ["71437.10", "2.377"]]}}
{"local_ts": 1773485577533, "server_ts": 1773485576736, "data": {"e": "depthUpdate", "E": 1773485576737, "T": 1773485576736, "s": "BTCUSDT", "U": 10109455657628, "u": 10109455660813, "pu": 10109455657589, "b": [["5000.00", "101.418"], ["7052.10", "0.000"], ["20020.20", "0.970"], ["20420.20", "2.030"], ["66994.00", "0.002"], ["66994.20", "0.150"], ["66994.30", "0.002"], ["69439.70", "0.000"], ["69815.00", "2.169"], ["70167.70", "0.000"], ["70274.20", "0.006"], ["70388.70", "0.500"], ["70425.30", "0.020"], ["70426.70", "0.200"], ["70427.10", "1.410"], ["70432.30", "0.080"], ["70433.70", "0.131"], ["70434.10", "6.442"], ["70439.40", "0.129"], ["70440.80", "1.796"], ["70441.20", "0.142"], ["70466.20", "0.101"], ["70466.50", "0.707"], ["70518.00", "0.019"], ["70520.20", "6.681"]], "a": [["70522.70", "0.000"], ["70524.70", "0.081"], ["70548.10", "0.002"], ["70549.10", "0.075"], ["70549.90", "1.131"], ["70550.00", "1.716"], ["70550.10", "0.290"], ["70596.10", "0.085"], ["70596.40", "0.142"], ["70601.70", "0.086"], ["70603.20", "0.004"], ["70603.50", "0.154"], ["70608.80", "0.103"], ["70610.20", "0.000"], ["70610.50", "0.310"], ["70615.80", "0.279"], ["70639.00", "0.006"], ["70641.20", "0.023"], ["70655.30", "0.002"], ["70658.40", "0.580"], ["71075.80", "0.000"], ["71225.50", "0.701"], ["71289.00", "1.401"], ["71357.80", "0.000"], ["71514.00", "0.838"], ["74060.80", "0.002"], ["74069.40", "0.113"]]}}
{"local_ts": 1773485578550, "server_ts": 1773485577757, "data": {"e": "depthUpdate", "E": 1773485577759, "T": 1773485577757, "s": "BTCUSDT", "U": 10109455701228, "u": 10109455705852, "pu": 10109455701193, "b": [["1000.00", "28.842"], ["5000.00", "101.418"], ["7052.10", "0.000"], ["20320.20", "1.580"], ["20420.20", "1.420"], ["66990.80", "0.026"], ["66994.00", "0.002"], ["68052.10", "0.002"], ["69815.00", "2.169"], ["70167.60", "0.228"], ["70167.70", "0.000"], ["70274.30", "0.004"], ["70466.30", "0.006"], ["70466.50", "0.792"], ["70473.60", "0.007"], ["70473.90", "0.004"], ["70485.00", "0.149"], ["70509.60", "0.144"], ["70512.70", "0.041"], ["70516.70", "0.000"], ["70520.10", "0.081"], ["70520.20", "6.859"]], "a": [["70520.30", "1.974"], ["70525.00", "0.104"], ["70528.20", "0.061"], ["70528.90", "0.037"], ["70530.90", "0.005"], ["70534.10", "0.006"], ["70550.10", "0.290"], ["70550.30", "0.194"], ["70638.50", "0.002"], ["70641.20", "0.021"], ["71225.50", "0.701"], ["71930.70", "0.033"], ["74054.30", "0.000"]]}}
{"local_ts": 1773485579572, "server_ts": 1773485578780, "data": {"e": "depthUpdate", "E": 1773485578781, "T": 1773485578780, "s": "BTCUSDT", "U": 10109455758221, "u": 10109455762753, "pu": 10109455758194, "b": [["1000.00", "28.842"], ["5000.00", "101.418"], ["7052.20", "0.000"], ["20221.90", "0.690"], ["20320.20", "1.860"], ["40000.00", "41.356"], ["66994.00", "0.002"], ["66994.20", "0.154"], ["69380.70", "3.602"], ["69486.40", "7.042"], ["69816.70", "0.002"], ["70359.70", "0.131"], ["70430.80", "0.954"], ["70432.90", "4.078"], ["70433.00", "2.425"], ["70434.20", "0.007"], ["70438.30", "0.114"], ["70439.10", "0.058"], ["70440.80", "1.791"], ["70442.10", "0.088"], ["70444.00", "0.315"], ["70444.30", "0.370"], ["70444.70", "0.054"], ["70448.80", "0.900"], ["70450.10", "0.005"], ["70456.80", "0.000"], ["70458.20", "0.019"], ["70464.70", "0.000"], ["70466.00", "0.303"], ["70470.70", "0.570"], ["70472.70", "0.002"], ["70474.30", "0.087"], ["70474.80", "0.004"], ["70484.40", "1.068"], ["70486.60", "0.011"], ["70491.30", "0.204"], ["70492.00", "0.712"], ["70492.10", "0.090"], ["70492.70", "0.186"], ["70492.80", "0.007"], ["70493.40", "0.002"], ["70493.50", "0.084"], ["70494.10", "0.339"], ["70494.20", "0.274"], ["70494.30", "0.120"], ["70494.90", "0.061"], ["70500.10", "0.141"], ["70500.20", "0.387"], ["70500.90", "0.513"], ["70502.00", "1.317"], ["70504.10", "0.006"], ["70505.70", "0.206"], ["70505.90", "0.007"], ["70509.00", "1.399"], ["70509.30", "0.002"], ["70510.10", "0.000"], ["70510.30", "0.019"], ["70510.40", "0.007"], ["70510.80", "0.396"], ["70511.30", "0.007"], ["70511.50", "0.000"], ["70511.80", "0.007"], ["70511.90", "0.002"], ["70512.20", "0.010"], ["70512.30", "0.001"], ["70512.40", "0.104"], ["70513.00", "0.210"], ["70513.30", "0.021"], ["70513.40", "0.045"], ["70514.10", "0.005"], ["70514.20", "0.005"], ["70514.30", "0.001"], ["70514.40", "0.002"], ["70514.80", "0.010"], ["70514.90", "0.076"], ["70515.20", "0.006"], ["70515.70", "0.003"], ["70515.90", "0.000"], ["70517.80", "0.046"], ["70519.20", "0.090"], ["70519.30", "0.000"], ["70519.40", "0.011"], ["70520.00", "0.059"], ["70520.10", "0.035"], ["70520.20", "0.560"], ["70520.30", "0.070"], ["70520.40", "0.002"], ["70520.50", "0.002"], ["70520.60", "0.002"], ["70521.70", "0.008"], ["70521.80", "0.500"], ["70521.90", "13.339"]], "a": [["70522.00", "3.155"], ["70522.10", "0.005"], ["70522.60", "0.004"], ["70524.70", "0.003"], ["70524.80", "0.005"], ["70526.40", "0.043"], ["70527.60", "0.006"], ["70527.90", "0.006"], ["70531.00", "0.000"], ["70531.50", "0.000"], ["70532.20", "0.015"], ["70532.60", "0.003"], ["70533.30", "0.088"], ["70533.80", "0.000"], ["70534.90", "0.076"], ["70535.40", "0.002"], ["70535.50", "0.072"], ["70535.90", "0.005"], ["70536.90", "0.022"], ["70537.00", "0.370"], ["70537.10", "0.458"], ["70537.60", "0.008"], ["70537.90", "0.004"], ["70538.20", "0.009"], ["70538.50", "0.518"], ["70538.80", "0.017"], ["70538.90", "0.014"], ["70539.00", "0.130"], ["70539.10", "0.040"], ["70539.40", "0.136"], ["70539.50", "0.206"], ["70539.60", "0.103"], ["70539.80", "0.223"], ["70539.90", "0.043"], ["70540.10", "0.012"], ["70540.30", "0.009"], ["70540.50", "0.002"], ["70540.80", "0.194"], ["70541.00", "0.009"], ["70541.10", "0.003"], ["70541.70", "0.029"], ["70542.60", "0.005"], ["70542.90", "0.011"], ["70543.30", "0.039"], ["70544.30", "0.661"], ["70545.90", "1.026"], ["70546.90", "0.005"], ["70547.00", "0.318"], ["70547.40", "0.133"], ["70547.50", "0.883"], ["70548.20", "0.029"], ["70551.10", "0.851"], ["70551.60", "0.449"], ["70553.80", "0.041"], ["70554.10", "0.146"], ["70554.80", "0.036"], ["70554.90", "0.002"], ["70555.30", "0.003"], ["70555.70", "0.000"], ["70556.20", "0.007"], ["70559.20", "0.023"], ["70560.40", "1.778"], ["70560.50", "0.470"], ["70561.40", "0.002"], ["70562.40", "0.003"], ["70562.90", "0.140"], ["70563.10", "0.007"], ["70563.40", "1.630"], ["70563.50", "0.096"], ["70564.20", "0.008"], ["70584.30", "0.040"], ["70584.70", "3.407"], ["70585.10", "0.180"], ["70600.00", "2.835"], ["70600.40", "0.036"], ["70604.00", "0.036"], ["70604.80", "0.107"], ["70638.50", "0.000"], ["70675.90", "0.769"], ["70683.90", "0.000"], ["70701.90", "0.556"], ["70732.50", "0.523"], ["70764.40", "0.000"], ["70773.40", "6.488"], ["70844.90", "3.417"], ["71227.20", "0.061"], ["71544.50", "0.837"], ["74062.80", "0.003"], ["89523.20", "0.000"], ["100000.00", "23.620"]]}}
{"local_ts": 1773485580594, "server_ts": 1773485579804, "data": {"e": "depthUpdate", "E": 1773485579805, "T": 1773485579804, "s": "BTCUSDT", "U": 10109455801366, "u": 10109455805099, "pu": 10109455801229, "b": [["5000.00", "101.418"], ["7052.20", "0.056"], ["20121.90", "0.690"], ["20221.90", "1.860"], ["20320.20", "0.000"], ["66975.50", "0.000"], ["66995.00", "0.002"], ["67701.10", "0.064"], ["70390.30", "0.493"], ["70428.10", "0.018"], ["70435.10", "0.191"], ["70442.20", "0.073"], ["70467.40", "0.087"], ["70467.50", "0.004"], ["70467.60", "0.691"], ["70474.80", "0.004"], ["70474.90", "0.004"], ["70500.30", "0.000"], ["70502.40", "0.016"], ["70511.30", "0.004"], ["70514.80", "0.007"], ["70518.10", "0.022"], ["70520.70", "0.000"], ["70521.90", "11.773"]], "a": [["70522.00", "4.487"], ["70522.50", "0.002"], ["70522.60", "0.004"], ["70532.60", "0.031"], ["70542.40", "0.007"], ["70556.50", "0.004"], ["70574.90", "0.479"], ["70604.50", "0.071"], ["70604.60", "0.002"], ["70611.60", "0.152"], ["70611.70", "0.000"], ["70618.60", "0.196"], ["70618.70", "0.000"], ["70633.30", "6.503"], ["70657.00", "0.364"], ["70675.90", "0.767"], ["70698.30", "0.000"], ["71227.20", "0.061"], ["74074.40", "0.002"], ["89523.20", "0.000"]]}}
{"local_ts": 1773485581615, "server_ts": 1773485580820, "data": {"e": "depthUpdate", "E": 1773485580825, "T": 1773485580820, "s": "BTCUSDT", "U": 10109455859338, "u": 10109455864601, "pu": 10109455859243, "b": [["1000.00", "28.842"], ["5000.00", "101.438"], ["7052.20", "0.056"], ["20021.90", "0.320"], ["20121.90", "2.600"], ["20220.20", "0.000"], ["20221.90", "0.080"], ["33000.00", "3.785"], ["68989.60", "0.620"], ["69428.80", "2.014"], ["69469.70", "0.000"], ["69731.50", "8.156"], ["69816.70", "0.717"], ["70169.20", "0.142"], ["70169.30", "0.142"], ["70227.70", "0.006"], ["70275.80", "0.000"], ["70428.10", "0.018"], ["70435.10", "0.191"], ["70442.20", "0.073"], ["70444.30", "0.373"], ["70458.40", "0.017"], ["70474.80", "0.004"], ["70475.10", "0.015"], ["70486.70", "0.424"], ["70490.90", "0.155"], ["70493.50", "0.031"], ["70511.30", "0.007"], ["70514.50", "0.298"], ["70514.60", "1.583"], ["70514.80", "0.010"], ["70521.90", "10.990"]], "a": [["70522.00", "5.333"], ["70527.00", "0.014"], ["70527.20", "0.003"], ["70528.00", "0.009"], ["70532.60", "0.031"], ["70578.40", "0.956"], ["70585.50", "0.672"], ["70592.50", "0.081"], ["70599.60", "0.003"], ["70604.50", "0.071"], ["70611.60", "0.152"], ["70618.60", "0.196"], ["70633.30", "6.501"], ["70635.00", "0.043"], ["70680.40", "0.126"], ["71227.10", "1.605"], ["71227.20", "0.762"], ["71345.90", "0.000"], ["71733.60", "0.023"], ["74069.20", "0.000"], ["74080.90", "0.002"], ["89523.20", "0.000"]]}}
{"local_ts": 1773485582635, "server_ts": 1773485581841, "data": {"e": "depthUpdate", "E": 1773485581845, "T": 1773485581841, "s": "BTCUSDT", "U": 10109455909162, "u": 10109455913555, "pu": 10109455908975, "b": [["5000.00", "101.418"], ["7052.20", "0.056"], ["20021.90", "2.450"], ["20121.90", "0.380"], ["20421.90", "0.170"], ["63469.70", "0.002"], ["66966.40", "0.002"], ["69816.70", "2.147"], ["69993.00", "0.740"], ["70169.20", "0.142"], ["70508.30", "0.000"], ["70511.30", "0.007"], ["70514.60", "1.585"], ["70514.70", "0.459"], ["70516.00", "0.008"], ["70516.30", "0.002"], ["70521.90", "10.893"]], "a": [["70526.60", "0.018"], ["70527.00", "0.029"], ["70532.60", "0.031"], ["70578.40", "0.956"], ["70745.70", "0.007"], ["70874.50", "0.000"], ["71227.20", "2.164"], ["71584.20", "1.395"], ["71817.60", "0.537"], ["71932.40", "0.030"], ["74076.30", "0.000"], ["77574.20", "0.002"], ["89523.20", "0.000"]]}}
{"local_ts": 1773485583657, "server_ts": 1773485582866, "data": {"e": "depthUpdate", "E": 1773485582867, "T": 1773485582866, "s": "BTCUSDT", "U": 10109455953006, "u": 10109455956062, "pu": 10109455952875, "b": [["1000.00", "28.842"], ["5000.00", "101.418"], ["7052.20", "0.028"], ["20021.90", "0.670"], ["20321.90", "0.020"], ["20421.90", "2.310"], ["33000.00", "3.789"], ["56418.00", "0.131"], ["63469.70", "0.002"], ["68382.20", "0.000"], ["69816.70", "2.147"], ["70142.40", "0.000"], ["70169.30", "3.131"], ["70351.50", "5.548"], ["70353.30", "1.105"], ["70390.30", "0.506"], ["70471.30", "0.090"], ["70488.80", "0.262"], ["70488.90", "0.083"], ["70506.40", "0.021"], ["70514.50", "0.298"], ["70514.60", "1.583"], ["70514.80", "0.007"], ["70521.90", "10.665"]], "a": [["70522.40", "0.073"], ["70526.00", "0.029"], ["70527.70", "0.021"], ["70532.30", "0.016"], ["70532.60", "0.031"], ["70533.10", "0.013"], ["70533.40", "0.221"], ["70536.10", "0.009"], ["70536.60", "0.062"], ["70538.20", "0.007"], ["70544.80", "0.088"], ["70556.40", "0.002"], ["70563.10", "0.005"], ["70565.20", "0.005"], ["70567.60", "0.004"], ["70656.30", "0.450"], ["70695.10", "6.565"], ["71050.90", "1.406"], ["71227.20", "2.304"], ["74054.20", "0.022"], ["77574.20", "0.002"], ["89523.20", "0.000"]]}}
{"local_ts": 1773485584680, "server_ts": 1773485583888, "data": {"e": "depthUpdate", "E": 1773485583891, "T": 1773485583888, "s": "BTCUSDT", "U": 10109455989230, "u": 10109455992322, "pu": 10109455989200, "b": [["1000.00", "28.842"], ["5000.00", "101.418"], ["7052.20", "0.028"], ["20321.90", "1.910"], ["20421.90", "1.090"], ["63469.70", "0.002"], ["66968.20", "0.002"], ["69111.50", "0.101"], ["69180.90", "0.003"], ["69816.70", "2.147"], ["70275.90", "0.018"], ["70306.30", "0.004"], ["70351.50", "2.998"], ["70427.90", "0.195"], ["70434.90", "0.071"], ["70437.60", "0.063"], ["70438.50", "0.140"], ["70442.00", "0.172"], ["70443.50", "0.727"], ["70443.80", "0.245"], ["70444.20", "0.056"], ["70478.90", "0.036"], ["70503.60", "0.207"], ["70511.30", "0.004"], ["70514.60", "1.585"], ["70514.70", "0.456"], ["70514.80", "0.007"], ["70514.90", "0.144"], ["70517.80", "0.053"], ["70518.30", "0.002"], ["70521.80", "0.337"], ["70521.90", "10.891"]], "a": [["70522.00", "4.682"], ["70522.50", "0.002"], ["70522.80", "0.196"], ["70525.50", "0.020"], ["70525.80", "0.014"], ["70526.80", "0.000"], ["70529.20", "0.068"], ["70532.60", "0.006"], ["70534.70", "0.002"], ["70536.00", "0.114"], ["70578.40", "1.208"], ["70604.30", "0.100"], ["70611.40", "0.271"], ["70618.40", "0.152"], ["70695.10", "4.566"], ["71227.20", "2.304"], ["77574.20", "0.002"], ["89523.20", "0.000"]]}}
{"local_ts": 1773485585702, "server_ts": 1773485584912, "data": {"e": "depthUpdate", "E": 1773485584913, "T": 1773485584912, "s": "BTCUSDT", "U": 10109456027539, "u": 10109456031536, "pu": 10109456027520, "b": [["5000.00", "101.418"], ["7052.20", "0.028"], ["20221.90", "1.460"], ["20321.90", "1.540"], ["33000.00", "3.789"], ["56418.00", "0.131"], ["63469.70", "0.002"], ["66966.10", "0.002"], ["69439.90", "0.445"], ["69816.70", "2.149"], ["70351.50", "2.998"], ["70390.30", "0.000"], ["70411.30", "0.014"], ["70413.70", "0.004"], ["70474.80", "0.004"], ["70475.00", "0.784"], ["70496.40", "0.450"], ["70497.00", "0.058"], ["70513.00", "0.210"], ["70514.50", "0.286"], ["70514.60", "1.583"], ["70514.70", "0.459"], ["70521.80", "0.337"]], "a": [["70522.00", "4.991"], ["70526.60", "0.000"], ["70527.30", "0.021"], ["70528.40", "0.026"], ["70532.40", "0.030"], ["70532.60", "0.003"], ["70656.10", "0.000"], ["70694.90", "0.003"], ["71227.20", "3.706"], ["72200.00", "13.978"], ["72230.60", "0.595"], ["74000.00", "198.314"], ["77574.20", "0.002"], ["89523.20", "0.000"]]}}
{"local_ts": 1773485586723, "server_ts": 1773485585932, "data": {"e": "depthUpdate", "E": 1773485585933, "T": 1773485585932, "s": "BTCUSDT", "U": 10109456100487, "u": 10109456105210, "pu": 10109456100354, "b": [["1000.00", "28.842"], ["5000.00", "101.418"], ["7052.20", "0.028"], ["20121.90", "1.020"], ["20221.90", "1.980"], ["66969.90", "0.002"], ["69816.70", "2.147"], ["70101.50", "7.324"], ["70169.30", "3.558"], ["70169.40", "0.000"], ["70206.20", "2.569"], ["70276.00", "0.089"], ["70281.70", "0.831"], ["70351.50", "5.904"], ["70359.70", "0.092"], ["70390.30", "0.580"], ["70511.30", "0.007"], ["70514.70", "0.459"], ["70521.90", "10.702"]], "a": [["70523.90", "0.108"], ["70532.60", "0.003"], ["70533.00", "0.042"], ["70533.20", "0.015"], ["70542.20", "0.284"], ["70543.10", "0.000"], ["70543.80", "0.007"], ["70577.30", "0.040"], ["70655.80", "1.657"], ["70694.60", "3.277"], ["70694.70", "0.000"], ["70763.30", "2.939"], ["70766.00", "0.000"], ["70842.20", "0.022"], ["70842.90", "0.002"], ["70843.90", "3.269"], ["70844.90", "0.162"], ["70864.00", "0.233"], ["70874.60", "3.910"], ["70999.90", "0.648"], ["71059.80", "4.447"], ["71227.20", "3.706"], ["71494.00", "0.419"], ["74056.70", "0.000"], ["89523.20", "0.000"]]}}
{"local_ts": 1773485587743, "server_ts": 1773485586952, "data": {"e": "depthUpdate", "E": 1773485586953, "T": 1773485586952, "s": "BTCUSDT", "U": 10109456141629, "u": 10109456146002, "pu": 10109456141601, "b": [["5000.00", "101.418"], ["7052.20", "0.000"], ["20021.90", "0.570"], ["20121.90", "2.430"], ["20221.90", "0.000"], ["63469.70", "0.000"], ["66963.20", "0.002"], ["66964.00", "0.000"], ["69816.70", "2.149"], ["70390.30", "0.000"], ["70504.00", "1.222"], ["70504.40", "0.018"], ["70508.90", "0.098"], ["70514.90", "0.076"]], "a": [["70533.20", "0.025"], ["70542.10", "0.163"], ["70542.20", "0.015"], ["70542.30", "0.280"], ["70556.40", "0.186"], ["70565.70", "0.003"], ["70655.70", "0.513"], ["70731.80", "0.268"], ["70864.00", "0.022"], ["70871.10", "0.211"], ["71227.10", "1.598"], ["71227.20", "3.706"], ["71368.30", "4.897"], ["77574.20", "0.000"], ["89523.20", "0.000"]]}}
{"local_ts": 1773485588763, "server_ts": 1773485587971, "data": {"e": "depthUpdate", "E": 1773485587973, "T": 1773485587971, "s": "BTCUSDT", "U": 10109456186737, "u": 10109456192470, "pu": 10109456186528, "b": [["1000.00", "28.842"], ["5000.00", "101.418"], ["7052.20", "0.000"], ["20021.90", "2.550"], ["20121.90", "0.170"], ["20421.90", "0.280"], ["63469.70", "0.000"], ["66981.20", "0.000"], ["69816.70", "2.147"], ["70169.30", "3.594"], ["70427.80", "2.368"], ["70434.80", "0.198"], ["70441.90", "0.073"], ["70474.50", "0.011"], ["70474.60", "0.513"], ["70511.30", "0.004"], ["70514.60", "1.583"]], "a": [["70522.00", "4.275"], ["70524.80", "0.005"], ["70531.50", "0.015"], ["70532.40", "0.040"], ["70532.60", "0.006"], ["70542.10", "0.078"], ["70578.40", "1.206"], ["70604.20", "0.099"], ["70611.30", "0.071"], ["70618.30", "0.075"], ["70623.10", "0.084"], ["70636.70", "12.567"], ["70698.30", "0.060"], ["71227.20", "3.706"], ["74054.90", "0.026"], ["77574.20", "0.000"]]}}
{"local_ts": 1773485589783, "server_ts": 1773485588992, "data": {"e": "depthUpdate", "E": 1773485588993, "T": 1773485588992, "s": "BTCUSDT", "U": 10109456230640, "u": 10109456233705, "pu": 10109456230544, "b": [["1000.00", "28.842"], ["5000.00", "101.418"], ["7052.20", "0.000"], ["20021.90", "0.460"], ["20321.90", "0.130"], ["20421.90", "2.410"], ["63469.70", "0.000"], ["66984.10", "0.000"], ["69407.20", "9.208"], ["69477.70", "27.056"], ["69520.50", "0.572"], ["69816.70", "2.147"], ["70324.40", "0.000"], ["70335.00", "17.172"], ["70352.60", "0.000"], ["70353.30", "1.416"], ["70356.30", "0.511"], ["70357.80", "0.326"], ["70362.00", "0.000"], ["70364.50", "0.274"], ["70371.50", "12.521"], ["70371.60", "0.020"], ["70390.20", "0.094"], ["70430.90", "6.535"], ["70433.00", "2.398"], ["70437.50", "0.277"], ["70438.40", "0.062"], ["70442.50", "0.050"], ["70443.40", "0.315"], ["70443.80", "0.245"], ["70444.20", "0.056"], ["70466.80", "4.528"], ["70471.30", "0.094"], ["70480.90", "0.000"], ["70488.50", "2.130"], ["70511.30", "0.007"], ["70514.60", "1.586"]], "a": [["70532.60", "0.003"], ["70547.70", "0.305"], ["70558.30", "1.864"], ["70574.90", "0.479"], ["70580.00", "3.768"], ["70612.90", "1.442"], ["70616.00", "7.053"], ["70655.40", "0.039"], ["70675.80", "4.360"], ["70675.90", "13.507"], ["70701.80", "0.029"], ["70842.90", "0.213"], ["71227.20", "3.706"], ["71832.50", "0.097"], ["77574.20", "0.000"]]}}
{"local_ts": 1773485590804, "server_ts": 1773485590010, "data": {"e": "depthUpdate", "E": 1773485590013, "T": 1773485590010, "s": "BTCUSDT", "U": 10109456273570, "u": 10109456277869, "pu": 10109456273339, "b": [["5000.00", "101.418"], ["7052.20", "0.056"], ["20321.90", "2.210"], ["20421.90", "0.790"], ["33000.00", "3.785"], ["63469.70", "0.000"], ["66987.10", "0.002"], ["69628.10", "0.002"], ["69640.40", "0.878"], ["69658.60", "0.716"], ["70169.40", "0.000"], ["70275.60", "0.004"], ["70411.10", "0.220"], ["70411.30", "0.000"], ["70437.90", "0.112"], ["70439.30", "0.512"], ["70444.50", "0.040"], ["70473.30", "8.514"], ["70474.10", "0.000"], ["70474.20", "0.000"], ["70474.30", "0.089"], ["70486.90", "0.000"], ["70489.00", "0.200"], ["70489.50", "0.129"], ["70490.10", "0.060"], ["70490.20", "1.509"], ["70490.80", "0.102"], ["70491.40", "0.157"], ["70493.80", "0.607"], ["70494.20", "0.098"], ["70494.90", "0.049"], ["70497.70", "0.080"], ["70498.10", "0.054"], ["70498.30", "0.248"], ["70498.60", "0.008"], ["70498.90", "0.001"], ["70501.90", "0.144"], ["70503.00", "0.000"], ["70520.20", "0.146"]], "a": [["70532.80", "0.067"], ["70532.90", "0.166"], ["70547.60", "0.642"], ["70548.60", "0.011"], ["70549.20", "0.045"], ["70553.10", "0.285"], ["70553.60", "0.480"], ["70554.60", "0.056"], ["70556.70", "0.003"], ["70559.80", "0.097"], ["70567.80", "0.083"], ["70578.40", "1.206"], ["70586.60", "8.498"], ["70588.60", "0.000"], ["70617.10", "0.055"], ["71227.20", "5.108"], ["71355.00", "0.716"], ["71932.40", "0.030"], ["73342.80", "0.010"], ["74074.50", "0.050"], ["77574.20", "0.000"]]}}
{"local_ts": 1773485591824, "server_ts": 1773485591033, "data": {"e": "depthUpdate", "E": 1773485591035, "T": 1773485591033, "s": "BTCUSDT", "U": 10109456327021, "u": 10109456341107, "pu": 10109456326687, "b": [["1000.00", "28.842"], ["5000.00", "101.418"], ["7052.20", "0.056"], ["20221.90", "1.770"], ["20321.90", "1.230"], ["63469.70", "0.000"], ["66972.50", "0.000"], ["69424.70", "5.896"], ["69816.70", "2.147"], ["70169.30", "3.594"], ["70276.00", "0.089"], ["70390.20", "0.700"], ["70450.70", "0.006"], ["70476.20", "0.047"], ["70486.30", "0.064"], ["70490.80", "0.201"], ["70509.20", "0.329"], ["70511.70", "0.003"], ["70512.30", "0.641"], ["70521.90", "11.126"]], "a": [["70522.00", "3.866"], ["70522.70", "0.000"], ["70523.90", "0.000"], ["70529.40", "0.005"], ["70534.70", "0.005"], ["70547.50", "0.841"], ["70547.70", "0.900"], ["70556.40", "0.002"], ["70588.10", "0.155"], ["70655.20", "0.620"], ["70745.40", "0.211"], ["71027.10", "0.021"], ["71081.80", "0.099"], ["71227.20", "5.108"], ["71540.30", "8.306"], ["71544.60", "13.152"], ["77574.20", "0.000"]]}}
{"local_ts": 1773485592846, "server_ts": 1773485592056, "data": {"e": "depthUpdate", "E": 1773485592057, "T": 1773485592056, "s": "BTCUSDT", "U": 10109456383337, "u": 10109456387970, "pu": 10109456383333, "b": [["5000.00", "101.418"], ["7052.20", "0.056"], ["20121.90", "1.320"], ["20221.90", "1.680"], ["33000.00", "3.789"], ["56418.00", "0.131"], ["66784.20", "0.036"], ["66986.70", "0.002"], ["66990.30", "0.000"], ["66994.30", "0.000"], ["69816.70", "2.147"], ["70434.20", "0.007"], ["70442.10", "0.083"], ["70442.20", "0.007"], ["70450.10", "0.005"], ["70458.20", "0.019"], ["70466.00", "0.298"], ["70466.10", "0.449"], ["70474.60", "1.356"], ["70481.70", "0.847"], ["70488.80", "1.105"], ["70495.90", "0.845"], ["70503.00", "0.843"], ["70504.00", "0.087"], ["70504.80", "0.003"], ["70509.20", "0.325"], ["70511.10", "0.003"], ["70511.30", "0.007"], ["70512.00", "0.524"], ["70512.10", "0.642"], ["70512.30", "0.017"], ["70514.50", "0.398"], ["70514.90", "0.124"], ["70521.90", "11.129"]], "a": [["70522.00", "3.778"], ["70523.90", "0.000"], ["70529.00", "0.121"], ["70532.60", "0.003"], ["70533.80", "0.060"], ["70534.70", "0.002"], ["70535.00", "0.015"], ["70535.10", "0.021"], ["70536.40", "0.103"], ["70536.50", "0.001"], ["70537.10", "0.025"], ["70537.80", "0.020"], ["70537.90", "0.000"], ["70538.00", "0.012"], ["70538.50", "0.984"], ["70539.10", "0.040"], ["70539.30", "0.000"], ["70540.40", "0.046"], ["70541.70", "0.037"], ["70545.60", "0.860"], ["70547.50", "1.478"], ["70548.00", "0.002"], ["70548.10", "0.007"], ["70549.30", "0.042"], ["70550.60", "0.093"], ["70550.90", "0.026"], ["70551.90", "0.000"], ["70552.70", "0.925"], ["70553.50", "0.459"], ["70553.60", "0.480"], ["70555.30", "0.003"], ["70557.50", "0.345"], ["70559.80", "0.940"], ["70566.90", "0.843"], ["70745.40", "0.204"], ["70994.90", "0.009"], ["71227.20", "5.108"], ["72289.30", "2.486"]]}}
{"local_ts": 1773485593867, "server_ts": 1773485593076, "data": {"e": "depthUpdate", "E": 1773485593079, "T": 1773485593076, "s": "BTCUSDT", "U": 10109456416354, "u": 10109456420728, "pu": 10109456416263, "b": [["1000.00", "28.842"], ["5000.00", "101.418"], ["7052.20", "0.028"], ["20021.90", "0.880"], ["20121.90", "2.120"], ["66978.10", "0.000"], ["66980.50", "0.002"], ["69628.50", "0.000"], ["69816.70", "2.147"], ["69851.90", "1.856"], ["69987.80", "0.000"], ["69998.30", "0.000"], ["70096.60", "0.000"], ["70169.30", "3.594"], ["70201.90", "0.194"], ["70274.20", "0.002"], ["70279.20", "0.002"], ["70284.70", "0.193"], ["70390.20", "0.767"], ["70413.00", "1.801"], ["70450.70", "0.002"], ["70460.70", "0.071"], ["70474.60", "1.356"], ["70481.70", "0.847"], ["70488.80", "1.105"], ["70495.90", "0.845"], ["70503.00", "0.843"], ["70509.20", "0.325"], ["70511.30", "0.007"], ["70514.40", "0.032"], ["70514.90", "0.124"], ["70521.90", "11.129"]], "a": [["70522.00", "3.778"], ["70523.90", "0.117"], ["70529.00", "0.121"], ["70532.60", "0.003"], ["70534.70", "0.002"], ["70536.30", "0.364"], ["70538.50", "1.005"], ["70545.60", "0.860"], ["70552.70", "0.925"], ["70559.80", "0.940"], ["70566.90", "0.843"], ["70578.40", "1.107"], ["70588.10", "0.151"], ["70599.90", "0.023"], ["70610.50", "0.168"], ["70655.00", "0.556"], ["70698.30", "0.159"], ["70767.10", "0.000"], ["70845.00", "21.172"], ["70951.20", "0.000"], ["71222.90", "0.702"], ["71227.20", "5.108"], ["71233.60", "0.002"], ["71536.40", "6.895"], ["71733.70", "20.056"], ["71756.10", "5.650"]]}}
{"local_ts": 1773485594892, "server_ts": 1773485594101, "data": {"e": "depthUpdate", "E": 1773485594103, "T": 1773485594101, "s": "BTCUSDT", "U": 10109456456047, "u": 10109456460204, "pu": 10109456455967, "b": [["1000.00", "28.842"], ["5000.00", "101.418"], ["7052.20", "0.028"], ["20021.90", "2.540"], ["20121.90", "0.010"], ["20421.90", "0.450"], ["33000.00", "3.789"], ["66970.80", "0.000"], ["66976.40", "0.002"], ["69816.70", "2.147"], ["70441.60", "0.901"], ["70442.50", "0.058"], ["70446.60", "0.192"], ["70447.50", "0.313"], ["70447.90", "0.099"], ["70448.20", "0.054"], ["70466.60", "0.086"], ["70466.70", "0.004"], ["70486.70", "0.424"], ["70489.20", "0.000"], ["70498.40", "0.317"], ["70509.20", "0.325"], ["70511.30", "0.007"], ["70514.50", "0.398"], ["70514.90", "0.133"], ["70521.90", "11.316"]], "a": [["70522.00", "2.039"], ["70527.90", "0.022"], ["70528.60", "0.007"], ["70529.00", "0.024"], ["70529.60", "0.058"], ["70532.60", "0.042"], ["70534.70", "0.002"], ["70537.60", "0.019"], ["70548.60", "0.648"], ["70549.80", "0.000"], ["70550.20", "0.092"], ["70550.40", "0.013"], ["70555.50", "0.260"], ["70556.80", "0.310"], ["70568.60", "0.000"], ["70626.70", "1.104"], ["70629.50", "0.000"], ["70654.80", "0.095"], ["70864.00", "0.022"], ["71227.20", "5.108"], ["71480.00", "5.421"], ["72637.60", "0.007"]]}}
{"local_ts": 1773485595919, "server_ts": 1773485595128, "data": {"e": "depthUpdate", "E": 1773485595129, "T": 1773485595128, "s": "BTCUSDT", "U": 10109456497101, "u": 10109456501622, "pu": 10109456497024, "b": [["5000.00", "101.418"], ["7052.20", "0.028"], ["20021.90", "0.230"], ["20321.90", "0.240"], ["20421.90", "2.530"], ["56418.00", "0.135"], ["66961.00", "0.000"], ["66984.30", "0.002"], ["69410.90", "4.028"], ["69481.40", "7.329"], ["69671.50", "1.724"], ["69675.60", "3.582"], ["69816.70", "2.147"], ["70306.30", "0.000"], ["70384.90", "1.127"], ["70466.70", "0.004"], ["70466.80", "0.983"], ["70476.20", "0.047"], ["70486.30", "0.064"], ["70498.70", "0.090"], ["70500.10", "0.248"], ["70509.20", "0.325"], ["70511.30", "0.004"], ["70513.00", "0.210"], ["70513.10", "0.642"], ["70513.60", "0.043"], ["70514.40", "0.029"], ["70514.90", "0.133"], ["70521.90", "11.298"]], "a": [["70522.00", "2.463"], ["70529.00", "0.024"], ["70532.20", "0.017"], ["70532.30", "0.069"], ["70532.60", "0.039"], ["70534.70", "0.002"], ["70536.20", "0.338"], ["70536.30", "0.266"], ["70539.40", "0.144"], ["70540.30", "0.004"], ["70540.40", "0.036"], ["70548.20", "0.022"], ["70548.30", "0.009"], ["70548.60", "0.011"], ["70548.90", "0.644"], ["70549.60", "0.011"], ["70550.30", "0.619"], ["70556.20", "0.002"], ["70556.30", "0.007"], ["70564.20", "0.003"], ["70564.30", "0.008"], ["70576.80", "0.002"], ["70622.60", "0.046"], ["70651.50", "2.954"], ["70655.30", "0.000"], ["70677.00", "0.486"], ["70698.30", "0.060"], ["71227.20", "5.108"], ["71584.00", "1.256"], ["71932.40", "0.039"]]}}
{"local_ts": 1773485596939, "server_ts": 1773485596148, "data": {"e": "depthUpdate", "E": 1773485596149, "T": 1773485596148, "s": "BTCUSDT", "U": 10109456549286, "u": 10109456555326, "pu": 10109456549137, "b": [["1000.00", "28.992"], ["5000.00", "101.418"], ["7052.20", "0.000"], ["20221.90", "0.090"], ["20321.90", "2.380"], ["20421.90", "0.530"], ["69794.90", "0.192"], ["69816.70", "2.154"], ["69816.80", "0.004"], ["70169.30", "3.594"], ["70275.90", "0.014"], ["70474.60", "0.517"], ["70474.80", "0.002"], ["70475.00", "0.786"], ["70481.70", "0.004"], ["70486.70", "0.478"], ["70488.80", "0.262"], ["70493.20", "0.004"], ["70493.40", "0.116"], ["70495.90", "0.002"], ["70503.00", "0.007"], ["70509.20", "0.325"], ["70521.90", "11.083"]], "a": [["70523.90", "0.120"], ["70524.60", "0.009"], ["70533.80", "0.003"], ["70534.70", "0.002"], ["70536.30", "0.251"], ["70538.00", "0.012"], ["70538.20", "0.000"], ["70538.30", "0.025"], ["70538.40", "0.020"], ["70538.50", "0.015"], ["70543.20", "0.095"], ["70545.60", "0.017"], ["70546.10", "0.036"], ["70552.70", "0.082"], ["70559.80", "0.097"], ["70566.90", "0.000"], ["70578.40", "1.085"], ["70592.50", "0.018"], ["70621.80", "0.279"], ["70622.60", "0.044"], ["70745.40", "0.204"], ["70899.90", "1.946"], ["71205.00", "0.154"], ["71227.20", "5.108"], ["71557.50", "0.035"], ["74056.40", "0.000"], ["74067.00", "0.052"]]}}
{"local_ts": 1773485597965, "server_ts": 1773485597172, "data": {"e": "depthUpdate", "E": 1773485597173, "T": 1773485597172, "s": "BTCUSDT", "U": 10109456601185, "u": 10109456605750, "pu": 10109456601028, "b": [["5000.00", "101.438"], ["7052.20", "0.000"], ["20221.90", "2.120"], ["20321.90", "0.880"], ["66972.80", "0.005"], ["66982.10", "0.000"], ["66991.30", "0.000"], ["67701.00", "0.661"], ["69111.50", "0.112"], ["69464.10", "0.014"], ["69816.70", "2.196"], ["69957.70", "1.026"], ["70363.20", "0.286"], ["70467.50", "0.000"], ["70474.60", "0.517"], ["70474.90", "0.004"], ["70475.00", "0.786"], ["70481.70", "0.004"], ["70488.80", "0.262"], ["70495.90", "0.002"], ["70503.00", "0.007"], ["70506.60", "1.212"], ["70507.60", "0.089"], ["70511.30", "0.007"], ["70514.60", "1.586"]], "a": [["70532.60", "0.039"], ["70535.90", "0.003"], ["70536.30", "0.194"], ["70538.50", "0.000"], ["70543.40", "0.040"], ["70544.30", "0.003"], ["70545.60", "0.002"], ["70552.70", "0.082"], ["70559.80", "0.097"], ["70566.90", "0.000"], ["70578.40", "1.085"], ["70588.50", "0.186"], ["70592.50", "0.099"], ["70620.70", "0.002"], ["70621.80", "0.277"], ["70698.30", "0.159"], ["71227.20", "5.108"], ["71523.40", "0.834"], ["71526.30", "0.707"], ["71580.30", "0.009"], ["71932.90", "0.292"], ["74067.00", "0.050"]]}}
{"local_ts": 1773485598983, "server_ts": 1773485598192, "data": {"e": "depthUpdate", "E": 1773485598195, "T": 1773485598192, "s": "BTCUSDT", "U": 10109456646826, "u": 10109456651822, "pu": 10109456646816, "b": [["1000.00", "28.842"], ["5000.00", "101.418"], ["7052.20", "0.000"], ["20121.90", "1.670"], ["20221.90", "1.330"], ["66965.20", "0.000"], ["69089.90", "0.867"], ["69111.50", "0.142"], ["69442.40", "0.223"], ["69597.50", "0.000"], ["69794.90", "0.185"], ["69816.70", "2.203"], ["70169.30", "3.594"], ["70375.50", "0.000"], ["70375.60", "3.065"], ["70474.90", "0.004"], ["70475.00", "0.786"], ["70486.70", "0.474"], ["70504.70", "0.057"], ["70512.90", "0.017"], ["70514.60", "1.583"], ["70514.70", "0.458"], ["70520.90", "0.000"], ["70521.80", "0.314"]], "a": [["70522.00", "5.395"], ["70522.20", "0.122"], ["70522.30", "0.017"], ["70523.10", "0.000"], ["70523.20", "0.011"], ["70527.70", "0.006"], ["70528.50", "0.005"], ["70529.00", "0.024"], ["70529.10", "0.017"], ["70529.80", "0.004"], ["70530.10", "0.091"], ["70530.20", "0.028"], ["70532.60", "0.039"], ["70542.30", "0.075"], ["70542.80", "0.474"], ["70543.50", "0.005"], ["70546.10", "0.220"], ["70549.00", "0.034"], ["70549.30", "0.000"], ["70578.40", "1.145"], ["70620.70", "0.000"], ["70623.10", "0.086"], ["70668.30", "2.723"], ["70668.60", "0.537"], ["70698.30", "0.060"], ["71205.00", "0.140"], ["71227.20", "5.108"], ["71402.40", "0.007"], ["71451.80", "2.376"], ["71557.50", "0.007"], ["71631.80", "4.182"], ["71910.00", "1.422"], ["74077.30", "0.002"]]}}
{"local_ts": 1773485600005, "server_ts": 1773485599216, "data": {"e": "depthUpdate", "E": 1773485599217, "T": 1773485599216, "s": "BTCUSDT", "U": 10109456684105, "u": 10109456688283, "pu": 10109456684045, "b": [["1000.00", "28.842"], ["5000.00", "101.418"], ["7052.20", "0.056"], ["20021.90", "1.230"], ["20121.90", "1.770"], ["33000.00", "3.785"], ["69816.70", "2.203"], ["70328.00", "0.161"], ["70335.00", "17.013"], ["70352.60", "0.039"], ["70356.20", "0.260"], ["70364.50", "0.292"], ["70376.20", "0.659"], ["70436.30", "1.673"], ["70441.20", "0.061"], ["70442.10", "0.141"], ["70446.30", "0.052"], ["70447.20", "0.393"], ["70447.50", "0.099"], ["70447.90", "0.054"], ["70467.50", "0.000"], ["70474.50", "0.009"], ["70474.60", "0.513"], ["70474.70", "0.005"], ["70481.70", "0.004"], ["70488.80", "0.262"], ["70490.30", "0.192"], ["70490.50", "0.262"], ["70491.00", "0.085"], ["70492.60", "0.070"], ["70495.90", "0.002"], ["70503.00", "0.000"]], "a": [["70531.80", "0.036"], ["70532.40", "0.020"], ["70538.50", "0.015"], ["70545.60", "0.002"], ["70552.70", "0.082"], ["70559.80", "0.097"], ["70566.90", "0.000"], ["70592.50", "0.099"], ["70612.90", "0.521"], ["70623.50", "0.085"], ["70672.10", "0.168"], ["70701.80", "0.188"], ["70745.90", "0.009"], ["70853.50", "0.000"], ["70864.00", "0.233"], ["71227.20", "5.108"], ["74060.40", "0.002"], ["89523.20", "0.000"]]}}
{"local_ts": 1773485601029, "server_ts": 1773485600236, "data": {"e": "depthUpdate", "E": 1773485600239, "T": 1773485600236, "s": "BTCUSDT", "U": 10109456727048, "u": 10109456730542, "pu": 10109456726997, "b": [["5000.00", "101.418"], ["7052.20", "0.056"], ["20021.90", "2.220"], ["20421.90", "0.780"], ["56418.10", "0.002"], ["69234.50", "0.002"], ["69816.70", "2.210"], ["70169.40", "0.004"], ["70275.40", "0.150"], ["70482.00", "0.028"], ["70486.70", "0.474"], ["70490.50", "0.078"], ["70521.30", "0.000"], ["70521.80", "0.386"]], "a": [["70523.60", "0.000"], ["70528.70", "0.000"], ["70545.90", "0.189"], ["70547.00", "0.318"], ["70549.00", "0.013"], ["70592.50", "0.023"], ["70595.10", "0.000"], ["71227.20", "5.108"], ["71526.10", "3.520"], ["71596.60", "1.957"], ["71932.40", "0.039"], ["74065.10", "0.044"], ["74075.80", "0.000"], ["89523.20", "0.000"]]}}
{"local_ts": 1773485602050, "server_ts": 1773485601260, "data": {"e": "depthUpdate", "E": 1773485601261, "T": 1773485601260, "s": "BTCUSDT", "U": 10109456762792, "u": 10109456765379, "pu": 10109456762691, "b": [["1000.00", "28.842"], ["5000.00", "101.418"], ["7052.20", "0.056"], ["20021.90", "0.040"], ["20321.90", "0.380"], ["20421.90", "2.580"], ["33000.00", "3.789"], ["66973.50", "0.002"], ["69323.00", "1.381"], ["69464.10", "0.070"], ["69619.20", "0.070"], ["69816.70", "2.217"], ["70169.30", "4.163"], ["70309.20", "0.006"], ["70427.40", "0.002"], ["70434.40", "0.840"], ["70436.00", "0.000"], ["70441.50", "0.003"], ["70514.10", "0.382"], ["70514.50", "0.395"]], "a": [["70578.40", "1.145"], ["70603.80", "0.160"], ["70610.90", "0.000"], ["70617.90", "0.004"], ["70645.20", "0.134"], ["70747.90", "0.144"], ["70784.60", "0.010"], ["70791.70", "0.007"], ["70798.80", "0.033"], ["70805.90", "0.128"], ["70813.00", "0.057"], ["70820.10", "0.007"], ["70827.20", "0.009"], ["70834.30", "0.007"], ["71227.20", "5.108"], ["71425.10", "0.042"], ["71455.50", "5.793"], ["71580.30", "0.072"], ["71932.90", "0.348"], ["74077.40", "0.000"], ["89523.20", "0.000"]]}}
{"local_ts": 1773485603077, "server_ts": 1773485602285, "data": {"e": "depthUpdate", "E": 1773485602287, "T": 1773485602285, "s": "BTCUSDT", "U": 10109456804222, "u": 10109456808209, "pu": 10109456804092, "b": [["5000.00", "101.418"], ["7052.20", "0.028"], ["20221.90", "0.210"], ["20321.90", "2.480"], ["20421.90", "0.310"], ["66978.80", "0.002"], ["66984.10", "0.002"], ["68783.60", "0.000"], ["69184.80", "4.334"], ["69301.40", "0.967"], ["69816.70", "2.217"], ["70390.20", "0.094"], ["70427.40", "0.020"], ["70434.40", "0.911"], ["70441.50", "0.074"], ["70508.30", "0.000"], ["70514.50", "0.398"]], "a": [["70522.00", "4.149"], ["70522.60", "0.004"], ["70532.60", "0.064"], ["70533.60", "0.038"], ["70533.70", "0.037"], ["70533.80", "0.000"], ["70533.90", "0.002"], ["70534.00", "0.000"], ["70534.10", "0.014"], ["70547.30", "0.002"], ["70553.30", "0.262"], ["70555.30", "0.028"], ["70603.80", "0.231"], ["70607.10", "0.000"], ["70608.30", "0.002"], ["70610.90", "0.071"], ["70617.90", "0.075"], ["70654.40", "0.000"], ["70747.90", "0.142"], ["70749.30", "0.002"], ["70784.10", "0.336"], ["70784.60", "0.003"], ["70791.20", "0.013"], ["70791.70", "0.000"], ["70798.30", "0.007"], ["70798.80", "0.026"], ["70805.40", "0.007"], ["70805.90", "0.121"], ["70812.50", "0.009"], ["70813.00", "0.050"], ["70819.60", "0.149"], ["70820.10", "0.000"], ["70826.70", "0.007"], ["70827.20", "0.002"], ["70833.80", "0.007"], ["70834.30", "0.000"], ["71227.20", "5.108"], ["89523.20", "0.000"]]}}
{"local_ts": 1773485604103, "server_ts": 1773485603306, "data": {"e": "depthUpdate", "E": 1773485603307, "T": 1773485603306, "s": "BTCUSDT", "U": 10109456844915, "u": 10109456848211, "pu": 10109456844788, "b": [["1000.00", "28.842"], ["5000.00", "101.418"], ["7052.20", "0.028"], ["20121.90", "0.060"], ["20221.90", "2.330"], ["20321.90", "0.610"], ["33000.00", "3.789"], ["69816.70", "2.217"], ["70169.30", "4.163"], ["70492.50", "0.045"], ["70492.60", "0.111"], ["70505.90", "1.212"], ["70506.60", "0.007"], ["70508.90", "0.008"], ["70509.50", "0.004"], ["70511.30", "0.645"], ["70512.30", "0.010"], ["70512.80", "0.396"], ["70514.40", "0.032"]], "a": [["70522.00", "4.473"], ["70527.20", "0.003"], ["70532.60", "0.064"], ["70538.10", "0.147"], ["70539.20", "0.460"], ["70546.70", "0.088"], ["70556.40", "0.002"], ["70564.60", "0.011"], ["70608.30", "0.000"], ["70609.50", "0.085"], ["70745.40", "0.204"], ["70749.30", "0.000"], ["70752.10", "0.002"], ["70784.10", "0.329"], ["70787.50", "0.009"], ["70791.20", "0.006"], ["70794.60", "0.009"], ["70798.30", "0.000"], ["70801.70", "0.007"], ["70805.40", "0.000"], ["70808.80", "2.594"], ["70812.50", "0.002"], ["70815.90", "0.040"], ["70819.60", "0.142"], ["70823.00", "0.021"], ["70826.70", "0.000"], ["70830.10", "0.007"], ["70833.80", "0.000"], ["70837.20", "0.007"], ["71191.90", "0.007"], ["71544.60", "23.620"], ["71804.30", "0.000"], ["74076.80", "0.002"], ["89523.20", "0.000"]]}}
{"local_ts": 1773485605116, "server_ts": 1773485604325, "data": {"e": "depthUpdate", "E": 1773485604327, "T": 1773485604325, "s": "BTCUSDT", "U": 10109456879271, "u": 10109456882001, "pu": 10109456879259, "b": [["1000.00", "28.842"], ["5000.00", "101.418"], ["7052.20", "0.028"], ["20121.90", "2.000"], ["20221.90", "1.000"], ["66985.20", "0.002"], ["69816.70", "3.647"], ["70446.20", "0.052"], ["70447.10", "0.315"], ["70474.40", "0.025"], ["70474.50", "0.011"], ["70492.70", "0.002"], ["70492.80", "0.088"]], "a": [["70522.00", "4.474"], ["70528.00", "0.017"], ["70528.30", "0.226"], ["70528.70", "0.015"], ["70546.00", "0.145"], ["70609.20", "0.002"], ["70609.50", "0.083"], ["70745.50", "0.000"], ["70752.10", "0.000"], ["70752.80", "0.002"], ["71227.10", "1.605"], ["71227.20", "5.108"], ["71536.40", "6.337"], ["89523.20", "0.000"]]}}
{"local_ts": 1773485606137, "server_ts": 1773485605348, "data": {"e": "depthUpdate", "E": 1773485605349, "T": 1773485605348, "s": "BTCUSDT", "U": 10109456916275, "u": 10109456919447, "pu": 10109456916237, "b": [["5000.00", "101.418"], ["7052.20", "0.000"], ["20021.90", "1.560"], ["20121.90", "1.440"], ["69107.60", "1.733"], ["69459.90", "1.360"], ["69816.70", "3.647"], ["70167.60", "0.192"], ["70389.60", "7.606"], ["70433.00", "0.529"], ["70468.00", "0.195"], ["70511.30", "0.007"], ["70513.30", "0.117"], ["70514.40", "0.005"], ["70521.00", "0.002"], ["70521.90", "13.731"]], "a": [["70522.00", "4.429"], ["70523.20", "0.005"], ["70529.90", "0.008"], ["70530.00", "0.094"], ["70530.30", "0.038"], ["70532.20", "0.114"], ["70532.60", "0.003"], ["70546.00", "0.147"], ["70554.80", "0.097"], ["70556.40", "0.006"], ["70564.60", "0.007"], ["70577.50", "2.026"], ["70607.50", "0.002"], ["70609.20", "0.000"], ["70611.20", "3.031"], ["70630.40", "0.002"], ["70632.30", "0.000"], ["70653.30", "9.793"], ["70653.50", "0.043"], ["70745.40", "0.204"], ["70748.90", "0.002"], ["70752.80", "0.000"], ["70842.10", "0.007"], ["71227.20", "5.108"], ["71451.80", "2.096"], ["74059.50", "0.052"], ["74079.30", "0.000"], ["89523.20", "0.000"]]}}
{"local_ts": 1773485607158, "server_ts": 1773485606368, "data": {"e": "depthUpdate", "E": 1773485606369, "T": 1773485606368, "s": "BTCUSDT", "U": 10109456948197, "u": 10109456952258, "pu": 10109456948117, "b": [["1000.00", "28.842"], ["5000.00", "101.398"], ["7052.20", "0.000"], ["20021.90", "1.890"], ["20421.90", "1.110"], ["69816.70", "3.647"], ["70169.30", "4.163"], ["70169.40", "0.000"], ["70276.00", "0.089"], ["70359.70", "0.092"], ["70372.60", "0.000"], ["70460.60", "0.013"], ["70462.50", "0.809"], ["70465.60", "1.229"], ["70486.70", "0.477"], ["70489.90", "0.002"], ["70511.30", "0.004"], ["70512.50", "0.101"], ["70513.40", "0.157"], ["70514.40", "0.285"], ["70517.80", "0.034"], ["70519.90", "0.002"], ["70521.90", "13.513"]], "a": [["70522.00", "4.098"], ["70523.90", "0.129"], ["70525.80", "0.063"], ["70532.60", "0.006"], ["70532.80", "0.202"], ["70532.90", "0.179"], ["70533.60", "0.002"], ["70545.70", "0.032"], ["70553.60", "0.468"], ["70555.30", "0.250"], ["70556.30", "0.043"], ["70560.10", "0.000"], ["70576.90", "0.098"], ["70600.40", "0.000"], ["70609.80", "0.002"], ["70630.40", "0.000"], ["70630.50", "0.086"], ["70745.40", "0.211"], ["71227.20", "5.809"], ["71544.60", "25.085"], ["74067.50", "0.050"], ["74072.80", "0.002"], ["89523.20", "0.000"]]}}
{"local_ts": 1773485608182, "server_ts": 1773485607388, "data": {"e": "depthUpdate", "E": 1773485607389, "T": 1773485607388, "s": "BTCUSDT", "U": 10109456986451, "u": 10109456991102, "pu": 10109456986414, "b": [["5000.00", "101.438"], ["7052.20", "0.000"], ["20021.90", "0.000"], ["20321.90", "0.660"], ["20421.90", "2.340"], ["66964.10", "0.003"], ["66995.80", "0.008"], ["69516.50", "4.739"], ["69520.50", "1.717"], ["69816.70", "4.362"], ["69816.80", "0.000"], ["70275.70", "0.004"], ["70276.10", "0.190"], ["70328.00", "0.002"], ["70335.00", "17.172"], ["70352.60", "0.000"], ["70359.70", "0.131"], ["70390.10", "0.002"], ["70461.80", "0.000"], ["70471.30", "0.090"], ["70485.30", "0.048"], ["70489.50", "0.017"], ["70489.70", "1.824"], ["70490.90", "0.155"], ["70497.00", "0.308"], ["70498.60", "0.008"], ["70502.50", "0.008"], ["70503.00", "0.000"], ["70503.20", "0.008"], ["70503.70", "0.052"], ["70511.30", "0.007"], ["70511.50", "0.645"], ["70512.10", "0.004"], ["70513.40", "0.045"], ["70514.30", "0.004"], ["70521.90", "13.180"]], "a": [["70522.00", "4.532"], ["70525.80", "0.063"], ["70526.40", "0.022"], ["70531.40", "0.007"], ["70532.00", "0.008"], ["70532.10", "0.013"], ["70532.20", "0.114"], ["70532.30", "0.029"], ["70532.50", "0.074"], ["70532.60", "0.006"], ["70532.70", "0.021"], ["70532.80", "0.202"], ["70532.90", "0.179"], ["70533.50", "0.002"], ["70533.60", "0.002"], ["70533.70", "0.001"], ["70533.90", "0.017"], ["70534.00", "0.000"], ["70534.20", "0.002"], ["70535.60", "0.000"], ["70544.50", "0.015"], ["70546.50", "0.012"], ["70546.80", "0.641"], ["70547.40", "0.006"], ["70547.90", "0.002"], ["70558.80", "1.797"], ["70559.40", "0.002"], ["70577.30", "0.284"], ["70578.40", "1.145"], ["70578.60", "0.003"], ["70592.50", "0.023"], ["70602.50", "0.000"], ["70629.60", "0.002"], ["70630.50", "0.084"], ["70654.20", "0.000"], ["70701.80", "0.029"], ["70842.20", "0.051"], ["70842.90", "0.213"], ["71227.20", "5.809"], ["71504.90", "3.048"], ["71808.80", "0.696"], ["71932.40", "0.042"], ["89523.20", "0.000"]]}}
{"local_ts": 1773485609199, "server_ts": 1773485608408, "data": {"e": "depthUpdate", "E": 1773485608409, "T": 1773485608408, "s": "BTCUSDT", "U": 10109457024491, "u": 10109457029025, "pu": 10109457024462, "b": [["1000.00", "28.842"], ["5000.00", "101.418"], ["7052.20", "0.056"], ["20221.90", "0.310"], ["20321.90", "2.590"], ["20421.90", "0.100"], ["33000.00", "3.785"], ["66967.50", "0.002"], ["69111.50", "0.204"], ["69816.70", "4.362"], ["70169.30", "4.341"], ["70467.50", "0.000"], ["70467.60", "0.780"], ["70491.00", "0.085"], ["70511.30", "0.004"], ["70512.60", "0.212"], ["70514.30", "0.001"], ["70516.70", "0.003"], ["70517.80", "0.036"], ["70519.90", "0.000"], ["70520.40", "0.002"], ["70521.80", "0.322"], ["70521.90", "13.163"]], "a": [["70522.00", "4.544"], ["70523.10", "0.000"], ["70525.20", "0.008"], ["70525.30", "0.017"], ["70529.60", "0.022"], ["70531.00", "0.000"], ["70531.10", "0.000"], ["70531.20", "0.034"], ["70532.30", "0.035"], ["70532.60", "0.006"], ["70533.90", "0.002"], ["70535.20", "0.018"], ["70535.30", "0.408"], ["70545.70", "0.032"], ["70546.10", "0.036"], ["70577.30", "0.284"], ["70629.60", "0.000"], ["70632.30", "0.002"], ["70672.00", "3.300"], ["71227.20", "5.809"], ["71583.40", "1.954"], ["71932.40", "0.045"], ["74055.50", "0.062"], ["89523.20", "0.000"]]}}
{"local_ts": 1773485610220, "server_ts": 1773485609428, "data": {"e": "depthUpdate", "E": 1773485609431, "T": 1773485609428, "s": "BTCUSDT", "U": 10109457058047, "u": 10109457060439, "pu": 10109457057979, "b": [["1000.00", "28.842"], ["5000.00", "101.418"], ["7052.20", "0.056"], ["20121.90", "0.160"], ["20221.90", "2.440"], ["20321.90", "0.400"], ["66967.50", "0.000"], ["66993.00", "0.002"], ["69499.30", "28.872"], ["69658.60", "2.149"], ["69816.70", "4.362"], ["70169.40", "0.000"], ["70275.80", "0.004"], ["70474.80", "0.004"], ["70474.90", "0.004"], ["70491.00", "0.000"], ["70511.30", "0.004"], ["70514.30", "0.001"], ["70517.80", "0.036"], ["70519.90", "0.000"], ["70521.90", "13.219"]], "a": [["70532.10", "0.074"], ["70532.60", "0.006"], ["70532.80", "0.335"], ["70533.40", "0.209"], ["70535.50", "0.077"], ["70535.70", "0.003"], ["70535.90", "0.003"], ["70547.00", "0.354"], ["70631.90", "0.518"], ["70632.30", "0.000"], ["71227.20", "5.879"], ["71615.10", "10.525"]]}}
{"local_ts": 1773485611246, "server_ts": 1773485610452, "data": {"e": "depthUpdate", "E": 1773485610453, "T": 1773485610452, "s": "BTCUSDT", "U": 10109457091833, "u": 10109457094814, "pu": 10109457091824, "b": [["5000.00", "101.418"], ["7052.20", "0.056"], ["20021.90", "0.010"], ["20121.90", "2.300"], ["20221.90", "0.690"], ["33000.00", "3.789"], ["66995.80", "0.006"], ["66995.90", "0.008"], ["69111.50", "0.195"], ["69417.00", "0.000"], ["69499.30", "29.734"], ["69816.70", "4.362"], ["70493.80", "0.513"], ["70493.90", "0.152"], ["70497.60", "0.002"], ["70511.30", "0.007"], ["70514.40", "0.005"], ["70517.80", "0.036"], ["70519.90", "0.000"], ["70521.90", "13.215"]], "a": [["70523.40", "0.059"], ["70530.90", "0.020"], ["70532.60", "0.006"], ["70551.30", "0.072"], ["70551.40", "0.343"], ["70553.60", "0.715"], ["70555.20", "0.115"], ["70555.30", "0.003"], ["70556.40", "0.002"], ["70567.60", "0.004"], ["70631.90", "0.516"], ["71050.90", "1.406"], ["71227.20", "5.879"], ["74062.90", "0.006"]]}}
{"local_ts": 1773485612262, "server_ts": 1773485611472, "data": {"e": "depthUpdate", "E": 1773485611473, "T": 1773485611472, "s": "BTCUSDT", "U": 10109457125279, "u": 10109457129528, "pu": 10109457125195, "b": [["1000.00", "28.842"], ["5000.00", "101.418"], ["7052.20", "0.028"], ["20021.90", "1.870"], ["20121.90", "1.130"], ["56418.00", "0.135"], ["66994.80", "0.005"], ["68959.90", "0.621"], ["69499.30", "30.740"], ["69816.70", "3.649"], ["70101.50", "12.626"], ["70169.30", "4.377"], ["70439.70", "0.613"], ["70491.00", "0.085"], ["70497.00", "0.308"], ["70498.30", "0.000"], ["70502.90", "0.095"], ["70503.90", "0.566"], ["70504.00", "0.738"], ["70504.80", "0.003"], ["70511.30", "0.642"], ["70512.20", "0.017"], ["70514.30", "0.001"], ["70517.80", "0.036"], ["70519.90", "0.000"], ["70521.90", "13.569"]], "a": [["70522.00", "3.661"], ["70527.30", "0.011"], ["70531.90", "0.070"], ["70532.60", "0.003"], ["70533.20", "0.216"], ["70533.40", "0.209"], ["70545.70", "0.032"], ["70546.30", "0.327"], ["70546.60", "0.682"], ["70547.90", "0.512"], ["70548.10", "0.000"], ["70549.40", "0.020"], ["70556.40", "0.006"], ["70564.60", "0.007"], ["70578.40", "1.325"], ["70874.60", "4.474"], ["71227.20", "5.178"], ["71355.60", "0.051"], ["71932.40", "0.051"]]}}
{"local_ts": 1773485613284, "server_ts": 1773485612493, "data": {"e": "depthUpdate", "E": 1773485612495, "T": 1773485612493, "s": "BTCUSDT", "U": 10109457167844, "u": 10109457171252, "pu": 10109457167801, "b": [["5000.00", "101.438"], ["7052.20", "0.028"], ["20021.90", "1.580"], ["20421.90", "1.420"], ["66971.70", "0.002"], ["66993.30", "0.000"], ["68390.20", "1.252"], ["69111.50", "0.189"], ["69502.40", "0.286"], ["69816.70", "2.217"], ["70375.70", "0.002"], ["70375.80", "3.242"], ["70442.10", "0.088"], ["70486.70", "0.480"], ["70490.90", "0.240"], ["70491.00", "0.000"], ["70511.30", "0.004"], ["70512.00", "1.228"], ["70512.50", "0.213"], ["70514.30", "0.001"], ["70517.80", "0.034"], ["70519.90", "0.002"], ["70521.90", "13.570"]], "a": [["70522.00", "3.664"], ["70523.00", "0.123"], ["70532.60", "0.003"], ["70532.70", "0.401"], ["70533.00", "0.080"], ["70578.40", "1.265"], ["70667.80", "2.613"], ["70668.10", "0.004"], ["70745.80", "0.259"], ["70842.20", "0.052"], ["71050.80", "0.005"], ["71227.20", "4.477"], ["71408.00", "2.800"], ["71931.00", "0.005"]]}}
{"local_ts": 1773485614309, "server_ts": 1773485613518, "data": {"e": "depthUpdate", "E": 1773485613519, "T": 1773485613518, "s": "BTCUSDT", "U": 10109457204445, "u": 10109457207713, "pu": 10109457204443, "b": [["1000.00", "28.842"], ["5000.00", "101.438"], ["7052.20", "0.028"], ["20321.90", "0.980"], ["20421.90", "2.020"], ["56418.00", "0.135"], ["66972.10", "0.000"], ["69107.60", "3.466"], ["69111.50", "0.186"], ["69181.70", "0.238"], ["69257.90", "2.307"], ["69466.40", "0.000"], ["69816.70", "2.932"], ["69886.90", "0.047"], ["70169.30", "4.377"], ["70390.10", "0.675"], ["70474.40", "0.025"], ["70474.50", "0.011"], ["70486.70", "0.485"], ["70489.20", "1.219"], ["70490.90", "1.926"], ["70511.30", "0.004"], ["70514.40", "0.002"], ["70519.90", "0.000"], ["70520.20", "0.094"], ["70521.90", "13.764"]], "a": [["70523.90", "0.138"], ["70532.60", "0.003"], ["70534.70", "0.002"], ["70578.40", "1.325"], ["70604.90", "0.000"], ["70612.30", "0.082"], ["70654.00", "0.002"], ["70746.20", "0.000"], ["70842.20", "0.051"], ["71227.20", "4.477"], ["71615.10", "11.501"], ["71932.40", "0.051"]]}}
{"local_ts": 1773485615327, "server_ts": 1773485614536, "data": {"e": "depthUpdate", "E": 1773485614539, "T": 1773485614536, "s": "BTCUSDT", "U": 10109457256126, "u": 10109457260091, "pu": 10109457256076, "b": [["1000.00", "28.842"], ["5000.00", "101.418"], ["7052.20", "0.000"], ["20221.90", "0.530"], ["20321.90", "2.470"], ["20421.90", "0.000"], ["56418.00", "0.131"], ["66993.90", "0.002"], ["69111.50", "0.183"], ["69179.70", "0.000"], ["69816.70", "4.362"], ["70390.10", "0.002"], ["70436.30", "2.416"], ["70471.30", "0.090"], ["70474.40", "0.025"], ["70474.50", "0.011"], ["70481.00", "0.003"], ["70511.30", "0.007"], ["70514.40", "0.005"], ["70519.60", "0.000"], ["70520.20", "0.094"], ["70521.90", "13.753"]], "a": [["70522.00", "3.010"], ["70523.90", "0.138"], ["70525.30", "0.010"], ["70532.60", "0.077"], ["70532.90", "0.103"], ["70533.70", "0.022"], ["70537.00", "0.080"], ["70537.20", "0.220"], ["70550.70", "0.131"], ["70556.40", "0.002"], ["70564.60", "0.011"], ["70628.00", "0.092"], ["70636.00", "0.212"], ["70654.00", "0.002"], ["71129.90", "0.000"], ["71227.20", "3.075"], ["71583.20", "0.841"], ["71932.40", "0.048"], ["74071.70", "0.000"]]}}
{"local_ts": 1773485616350, "server_ts": 1773485615560, "data": {"e": "depthUpdate", "E": 1773485615561, "T": 1773485615560, "s": "BTCUSDT", "U": 10109457309729, "u": 10109457314555, "pu": 10109457309682, "b": [["5000.00", "101.418"], ["7052.20", "0.000"], ["20121.90", "0.270"], ["20221.90", "2.550"], ["20321.90", "0.180"], ["33000.00", "3.785"], ["56418.00", "0.135"], ["69111.50", "0.183"], ["69816.70", "4.364"], ["70314.30", "0.000"], ["70351.30", "0.000"], ["70359.70", "0.092"], ["70433.50", "2.208"], ["70471.30", "0.090"], ["70474.90", "0.006"], ["70475.00", "0.784"], ["70481.00", "0.003"], ["70486.70", "0.483"], ["70515.00", "0.416"], ["70517.80", "0.034"], ["70519.90", "0.002"], ["70521.90", "13.545"]], "a": [["70522.00", "3.002"], ["70524.60", "0.024"], ["70525.20", "0.008"], ["70525.90", "0.021"], ["70529.10", "0.002"], ["70531.70", "0.004"], ["70532.50", "0.013"], ["70544.20", "0.217"], ["70547.00", "0.339"], ["70547.50", "1.478"], ["70692.80", "0.000"], ["70729.80", "0.000"], ["71227.20", "4.477"], ["74055.60", "0.000"]]}}
{"local_ts": 1773485617373, "server_ts": 1773485616580, "data": {"e": "depthUpdate", "E": 1773485616585, "T": 1773485616580, "s": "BTCUSDT", "U": 10109457359403, "u": 10109457363048, "pu": 10109457359371, "b": [["1000.00", "28.842"], ["5000.00", "101.418"], ["7052.20", "0.000"], ["20021.90", "0.120"], ["20121.90", "2.400"], ["20221.90", "0.480"], ["56418.00", "0.131"], ["66982.40", "0.000"], ["68813.40", "0.622"], ["69255.00", "0.771"], ["69485.20", "4.586"], ["69520.50", "2.289"], ["69816.70", "4.362"], ["70051.00", "0.200"], ["70061.50", "0.002"], ["70169.30", "4.377"], ["70200.00", "24.225"], ["70367.10", "0.092"], ["70377.70", "0.141"], ["70460.70", "0.072"], ["70471.30", "0.090"], ["70474.50", "0.011"], ["70474.60", "0.513"], ["70486.70", "0.479"], ["70514.90", "0.444"], ["70517.80", "0.034"], ["70519.90", "0.002"]], "a": [["70560.80", "0.003"], ["70566.20", "0.004"], ["70576.80", "0.072"], ["70577.20", "0.263"], ["70578.40", "1.085"], ["70587.80", "8.498"], ["71223.00", "0.140"], ["71227.20", "4.477"], ["71233.60", "0.002"]]}}
{"local_ts": 1773485618393, "server_ts": 1773485617603, "data": {"e": "depthUpdate", "E": 1773485617605, "T": 1773485617603, "s": "BTCUSDT", "U": 10109457400769, "u": 10109457404413, "pu": 10109457400758, "b": [["5000.00", "101.418"], ["7052.20", "0.056"], ["20021.90", "2.190"], ["20121.90", "0.810"], ["33000.00", "3.785"], ["56418.00", "0.131"], ["66967.30", "0.000"], ["69111.50", "0.186"], ["69421.80", "0.317"], ["69816.70", "4.362"], ["70471.30", "0.086"], ["70495.10", "0.003"], ["70515.00", "0.416"]], "a": [["70522.00", "2.924"], ["70525.50", "0.002"], ["70525.60", "0.003"], ["70525.70", "0.213"], ["70525.80", "0.014"], ["70526.20", "0.021"], ["70527.50", "0.020"], ["70529.10", "0.002"], ["70529.40", "0.026"], ["70544.10", "0.015"], ["70548.70", "0.057"], ["70550.70", "0.131"], ["70560.80", "0.003"], ["71227.20", "5.879"], ["71932.40", "0.033"], ["74057.20", "0.002"]]}}
{"local_ts": 1773485619417, "server_ts": 1773485618622, "data": {"e": "depthUpdate", "E": 1773485618625, "T": 1773485618622, "s": "BTCUSDT", "U": 10109457460704, "u": 10109457468005, "pu": 10109457460478, "b": [["1000.00", "28.842"], ["5000.00", "101.398"], ["7052.20", "0.056"], ["20021.90", "1.260"], ["20421.90", "1.740"], ["56418.00", "0.131"], ["66974.10", "0.002"], ["66987.60", "0.002"], ["69816.70", "4.362"], ["70169.30", "4.377"], ["70479.40", "0.547"], ["70486.70", "0.424"], ["70497.40", "0.004"], ["70497.60", "0.006"], ["70501.40", "0.005"], ["70510.80", "0.120"], ["70514.90", "0.507"], ["70515.00", "0.432"], ["70517.30", "0.001"]], "a": [["70526.80", "0.008"], ["70528.90", "0.008"], ["70529.10", "0.004"], ["70529.80", "0.061"], ["70531.80", "0.012"], ["70533.70", "0.004"], ["70535.50", "0.068"], ["70536.70", "0.021"], ["70538.10", "0.046"], ["70539.20", "0.358"], ["70539.60", "0.087"], ["70540.70", "0.022"], ["70543.20", "0.088"], ["70553.50", "0.212"], ["70554.60", "0.089"], ["70554.70", "0.003"], ["70556.50", "0.004"], ["70560.80", "0.045"], ["70585.90", "0.005"], ["70617.50", "0.129"], ["71191.10", "0.000"], ["71227.20", "5.911"], ["72637.60", "0.010"]]}}
