{"local_ts": 1773485027697, "server_ts": 1773485026900, "data": {"e": "depthUpdate", "E": 1773485026903, "T": 1773485026900, "s": "BTCUSDT", "U": 10109427696807, "u": 10109427700167, "pu": 10109427696802, "b": [["1000.00", "28.692"], ["5000.00", "101.418"], ["7051.00", "0.028"], ["20210.00", "1.440"], ["20310.00", "1.560"], ["56408.00", "0.000"], ["63459.00", "0.002"], ["69099.80", "0.087"], ["69104.30", "0.000"], ["69651.00", "0.024"], ["69804.90", "2.854"], ["69933.00", "0.011"], ["70340.10", "0.000"], ["70342.60", "0.694"], ["70358.10", "0.000"], ["70371.70", "0.041"], ["70374.90", "0.000"], ["70378.50", "0.000"], ["70378.90", "0.000"], ["70390.70", "0.001"], ["70394.30", "0.000"], ["70394.60", "0.000"], ["70394.70", "0.066"], ["70395.00", "0.000"], ["70395.40", "0.000"], ["70395.70", "0.000"], ["70396.10", "0.000"], ["70414.90", "0.014"], ["70417.20", "0.091"], ["70425.50", "0.256"], ["70427.70", "0.041"], ["70427.80", "0.000"], ["70428.10", "0.088"], ["70428.40", "0.004"], ["70428.80", "0.019"], ["70429.20", "0.109"], ["70429.50", "0.629"], ["70450.50", "0.062"], ["70494.60", "0.005"], ["70495.00", "0.005"], ["70495.30", "0.201"], ["70496.90", "0.005"], ["70497.60", "0.010"], ["70498.20", "0.342"], ["70498.50", "0.008"], ["70498.60", "0.007"], ["70498.80", "0.005"], ["70498.90", "0.000"], ["70499.20", "0.002"], ["70499.30", "0.007"], ["70499.40", "0.008"], ["70499.50", "0.226"], ["70499.60", "0.002"], ["70500.00", "0.312"], ["70501.70", "0.060"], ["70502.80", "0.006"], ["70502.90", "0.010"], ["70506.00", "0.011"]], "a": [["70510.10", "2.632"], ["70511.40", "0.000"], ["70518.80", "0.299"], ["70519.30", "0.005"], ["70519.60", "0.002"], ["70520.00", "0.046"], ["70520.30", "0.005"], ["70520.40", "0.006"], ["70520.70", "0.086"], ["70521.00", "0.005"], ["70524.10", "0.004"], ["70538.70", "0.004"], ["70548.00", "0.002"], ["70552.70", "0.002"], ["70553.10", "0.551"], ["70553.40", "0.002"], ["70553.50", "0.258"], ["70553.80", "0.017"], ["70553.90", "0.004"], ["70554.10", "0.038"], ["70554.20", "0.038"], ["70554.50", "0.002"], ["70555.50", "0.195"], ["70559.80", "0.004"], ["70560.70", "0.001"], ["70586.20", "0.000"], ["70586.50", "0.000"], ["70586.90", "0.085"], ["70587.20", "0.443"], ["70587.30", "0.046"], ["70587.60", "0.028"], ["70587.90", "0.323"], ["70590.20", "0.013"], ["70598.50", "2.260"], ["70600.80", "0.004"], ["70643.70", "0.181"], ["70663.90", "0.003"], ["70682.50", "2.612"], ["70900.00", "14.569"], ["71070.90", "0.070"], ["71215.20", "0.000"], ["71546.60", "1.457"], ["74044.30", "0.002"], ["77561.10", "0.115"]]}}
{"local_ts": 1773485028718, "server_ts": 1773485027922, "data": {"e": "depthUpdate", "E": 1773485027923, "T": 1773485027922, "s": "BTCUSDT", "U": 10109427790632, "u": 10109427807958, "pu": 10109427790603, "b": [["5000.00", "101.418"], ["7050.20", "0.028"], ["20101.00", "0.190"], ["20101.90", "0.010"], ["20102.00", "0.220"], ["20210.00", "1.600"], ["63451.80", "0.002"], ["65431.10", "0.000"], ["66982.80", "0.000"], ["69565.10", "2.562"], ["69796.00", "0.004"], ["69796.90", "0.000"], ["69797.00", "0.000"], ["69962.60", "0.000"], ["70260.90", "0.025"], ["70261.00", "0.224"], ["70308.60", "0.000"], ["70309.20", "0.118"], ["70343.30", "0.153"], ["70357.40", "0.087"], ["70359.50", "0.054"], ["70364.40", "0.412"], ["70364.80", "0.184"], ["70365.10", "0.099"], ["70365.50", "0.094"], ["70365.90", "0.035"], ["70373.10", "6.530"], ["70375.10", "0.090"], ["70387.00", "0.019"], ["70387.80", "1.659"], ["70396.40", "0.002"], ["70399.00", "0.042"], ["70401.90", "0.160"], ["70405.30", "0.198"], ["70408.80", "0.003"], ["70410.70", "0.634"], ["70410.90", "0.000"], ["70412.30", "0.142"], ["70412.60", "0.009"], ["70416.20", "0.173"], ["70416.40", "0.955"], ["70419.40", "0.142"], ["70422.20", "0.002"], ["70423.20", "0.000"], ["70426.40", "6.615"], ["70427.00", "0.027"], ["70428.10", "0.371"], ["70428.30", "0.000"], ["70430.30", "0.000"], ["70430.50", "0.000"], ["70431.50", "0.025"], ["70433.40", "0.086"], ["70435.60", "0.000"], ["70438.70", "0.441"], ["70439.60", "0.066"], ["70440.30", "0.781"], ["70443.50", "2.007"], ["70443.60", "0.379"], ["70443.70", "0.225"], ["70444.60", "0.477"], ["70445.40", "0.184"], ["70446.30", "0.086"], ["70447.10", "0.045"], ["70448.50", "0.062"], ["70448.70", "0.000"], ["70450.00", "0.724"], ["70450.20", "0.015"], ["70451.20", "0.002"], ["70451.70", "0.122"], ["70452.60", "0.768"], ["70452.80", "0.230"], ["70452.90", "0.006"], ["70454.90", "0.036"], ["70455.20", "0.320"], ["70455.80", "0.052"], ["70455.90", "0.003"], ["70457.00", "0.750"], ["70458.10", "0.002"], ["70458.40", "0.004"], ["70459.50", "0.090"], ["70460.60", "0.034"], ["70461.20", "0.002"], ["70461.40", "0.002"], ["70462.30", "0.003"], ["70462.50", "0.000"], ["70464.30", "0.000"], ["70464.90", "0.005"], ["70465.00", "0.007"], ["70465.40", "0.020"], ["70465.70", "0.403"], ["70467.50", "0.000"], ["70469.10", "0.012"], ["70469.20", "0.370"], ["70469.30", "0.004"], ["70470.30", "0.007"], ["70470.40", "0.856"], ["70471.00", "0.011"], ["70471.10", "0.007"], ["70471.80", "0.017"], ["70472.40", "0.002"], ["70472.70", "0.081"], ["70473.70", "0.071"], ["70474.10", "0.002"], ["70474.70", "0.002"], ["70475.30", "0.003"], ["70475.40", "0.390"], ["70476.60", "0.006"], ["70477.00", "0.518"], ["70477.60", "0.003"], ["70478.00", "0.163"], ["70479.20", "0.387"], ["70479.40", "0.063"], ["70479.80", "0.000"], ["70479.90", "0.011"], ["70480.10", "0.518"], ["70480.20", "0.350"], ["70480.30", "0.088"], ["70480.70", "0.003"], ["70481.10", "0.004"], ["70481.30", "0.667"], ["70481.40", "0.096"], ["70481.60", "0.064"], ["70481.70", "1.293"], ["70481.80", "0.241"], ["70481.90", "0.002"], ["70482.00", "0.060"], ["70482.10", "0.011"], ["70482.30", "0.022"], ["70482.40", "0.514"], ["70482.60", "0.004"], ["70483.30", "0.149"], ["70483.40", "0.002"], ["70484.20", "1.130"], ["70484.30", "0.028"], ["70484.40", "0.170"], ["70484.70", "0.000"], ["70484.80", "0.004"], ["70485.10", "0.002"], ["70485.30", "0.018"], ["70485.60", "0.474"], ["70485.80", "0.525"], ["70485.90", "0.026"], ["70486.10", "0.107"], ["70486.30", "0.003"], ["70486.50", "0.215"], ["70486.70", "0.270"], ["70486.90", "0.084"], ["70487.00", "0.003"], ["70487.10", "0.342"], ["70487.20", "0.003"], ["70487.50", "0.045"], ["70487.60", "0.009"], ["70487.80", "0.005"], ["70487.90", "0.008"], ["70488.20", "0.260"], ["70488.30", "0.133"], ["70488.40", "0.003"], ["70488.60", "0.123"], ["70488.70", "0.000"], ["70489.00", "0.065"], ["70489.20", "0.006"], ["70489.30", "0.054"], ["70489.50", "0.004"], ["70489.70", "0.038"], ["70489.80", "0.015"], ["70489.90", "1.088"], ["70490.00", "0.901"], ["70490.10", "0.010"], ["70490.30", "0.000"], ["70490.40", "0.091"], ["70490.50", "0.003"], ["70490.70", "0.001"], ["70491.00", "0.000"], ["70491.30", "0.004"], ["70491.40", "0.001"], ["70491.50", "0.009"], ["70492.50", "0.008"], ["70492.60", "0.006"], ["70493.10", "0.015"], ["70493.20", "0.178"], ["70493.30", "0.009"], ["70493.60", "0.006"], ["70494.00", "0.008"], ["70494.70", "0.000"], ["70495.40", "0.036"], ["70495.50", "0.003"], ["70495.80", "0.019"], ["70496.30", "0.000"], ["70496.50", "0.003"], ["70496.80", "0.000"], ["70497.10", "0.173"], ["70498.00", "0.003"], ["70498.50", "0.004"], ["70500.00", "0.303"], ["70500.30", "0.000"], ["70500.50", "0.002"], ["70500.70", "0.001"], ["70500.90", "0.002"], ["70501.00", "0.109"], ["70501.10", "0.000"], ["70501.20", "0.000"], ["70501.30", "0.000"], ["70501.40", "0.000"], ["70501.50", "0.000"], ["70501.70", "0.000"], ["70501.80", "0.000"], ["70501.90", "0.000"], ["70502.00", "0.000"]], "a": [["70501.10", "8.880"], ["70501.20", "0.147"], ["70501.30", "0.000"], ["70501.40", "0.000"], ["70501.50", "0.000"], ["70501.60", "0.000"], ["70501.80", "0.002"], ["70501.90", "0.002"], ["70502.00", "0.119"], ["70502.10", "0.950"], ["70502.20", "0.037"], ["70502.30", "0.000"], ["70502.40", "0.193"], ["70502.60", "0.002"], ["70502.80", "1.418"], ["70502.90", "0.553"], ["70503.00", "0.004"], ["70503.50", "0.000"], ["70503.60", "0.000"], ["70503.70", "0.112"], ["70503.80", "0.001"], ["70503.90", "0.005"], ["70504.00", "0.002"], ["70504.50", "0.004"], ["70504.80", "0.050"], ["70504.90", "0.010"], ["70505.00", "0.011"], ["70505.10", "0.152"], ["70505.20", "0.005"], ["70505.80", "0.022"], ["70506.00", "0.003"], ["70506.30", "0.000"], ["70508.10", "0.002"], ["70508.70", "0.201"], ["70508.80", "0.001"], ["70509.40", "0.003"], ["70509.50", "0.003"], ["70509.60", "0.003"], ["70509.70", "0.008"], ["70509.80", "0.005"], ["70510.10", "0.151"], ["70510.20", "0.005"], ["70511.00", "0.388"], ["70511.40", "0.007"], ["70511.60", "0.059"], ["70511.70", "0.005"], ["70512.40", "0.161"], ["70512.70", "0.000"], ["70512.80", "0.007"], ["70513.40", "0.001"], ["70513.80", "0.012"], ["70514.10", "0.029"], ["70514.50", "0.043"], ["70514.80", "0.699"], ["70515.20", "0.041"], ["70515.30", "0.073"], ["70515.50", "0.248"], ["70517.80", "0.075"], ["70518.70", "0.006"], ["70518.80", "0.663"], ["70518.90", "0.040"], ["70519.80", "0.057"], ["70519.90", "0.003"], ["70520.30", "0.004"], ["70520.60", "0.518"], ["70520.70", "0.013"], ["70520.90", "0.059"], ["70521.00", "0.111"], ["70521.30", "0.187"], ["70522.30", "0.004"], ["70522.50", "0.075"], ["70523.20", "0.012"], ["70523.30", "0.002"], ["70524.10", "0.248"], ["70524.40", "0.001"], ["70525.00", "0.307"], ["70525.10", "0.011"], ["70525.70", "0.292"], ["70525.80", "1.582"], ["70527.60", "0.091"], ["70527.90", "0.006"], ["70528.10", "0.005"], ["70528.20", "0.055"], ["70529.20", "0.029"], ["70529.30", "0.014"], ["70529.80", "0.010"], ["70529.90", "0.009"], ["70530.00", "0.103"], ["70530.50", "0.036"], ["70530.90", "0.080"], ["70531.40", "0.200"], ["70532.20", "0.321"], ["70532.40", "0.901"], ["70533.00", "0.018"], ["70533.80", "0.006"], ["70537.30", "0.061"], ["70537.80", "0.003"], ["70538.80", "0.002"], ["70544.90", "0.336"], ["70545.00", "0.412"], ["70547.90", "0.043"], ["70548.80", "0.020"], ["70552.60", "0.043"], ["70552.70", "0.017"], ["70553.30", "1.070"], ["70554.00", "0.448"], ["70554.70", "0.000"], ["70557.00", "2.306"], ["70557.50", "0.202"], ["70560.40", "0.518"], ["70561.00", "0.074"], ["70561.70", "0.044"], ["70562.10", "0.263"], ["70565.50", "0.043"], ["70565.60", "0.000"], ["70567.20", "0.922"], ["70569.10", "0.445"], ["70574.80", "0.145"], ["70575.50", "0.051"], ["70581.90", "0.185"], ["70583.80", "0.268"], ["70585.50", "0.326"], ["70588.90", "0.144"], ["70589.20", "0.016"], ["70590.50", "0.036"], ["70592.60", "0.344"], ["70596.30", "0.025"], ["70599.60", "0.000"], ["70603.20", "0.712"], ["70607.00", "0.006"], ["70609.50", "1.364"], ["70610.00", "0.015"], ["70618.90", "0.511"], ["70624.50", "0.372"], ["70636.00", "0.124"], ["70647.80", "2.077"], ["70658.40", "3.881"], ["70679.60", "6.390"], ["70692.00", "0.018"], ["70717.90", "0.003"], ["70728.50", "0.011"], ["70742.40", "0.734"], ["70854.10", "0.023"], ["71206.10", "0.000"], ["71207.00", "0.000"], ["71207.10", "0.002"], ["71502.00", "0.022"], ["71502.10", "0.006"], ["71505.90", "0.000"], ["71506.60", "0.008"], ["71506.70", "0.018"], ["71512.40", "0.000"], ["71911.10", "0.027"], ["71912.10", "0.021"], ["77552.30", "0.005"]]}}
{"local_ts": 1773485029742, "server_ts": 1773485028942, "data": {"e": "depthUpdate", "E": 1773485028943, "T": 1773485028942, "s": "BTCUSDT", "U": 10109427885979, "u": 10109427892633, "pu": 10109427885960, "b": [["1000.00", "28.692"], ["5000.00", "101.418"], ["7050.10", "0.000"], ["20000.00", "3.324"], ["20100.00", "0.091"], ["20103.60", "0.020"], ["20105.00", "0.000"], ["20205.00", "0.000"], ["33000.00", "3.785"], ["63450.00", "0.074"], ["66966.00", "0.008"], ["66969.20", "0.002"], ["69090.00", "3.695"], ["69484.10", "1.580"], ["69584.80", "0.000"], ["69795.00", "0.099"], ["70148.50", "0.000"], ["70188.50", "0.986"], ["70303.90", "0.203"], ["70394.20", "0.029"], ["70443.60", "0.110"], ["70450.40", "0.010"], ["70450.80", "0.151"], ["70453.30", "0.305"], ["70454.00", "0.345"], ["70454.10", "0.003"], ["70464.80", "0.029"], ["70468.30", "0.000"], ["70470.40", "0.898"], ["70471.40", "0.759"], ["70474.70", "0.009"], ["70476.60", "0.013"], ["70477.10", "0.005"], ["70477.60", "0.003"], ["70480.20", "0.348"], ["70486.50", "0.225"], ["70488.20", "0.260"], ["70489.40", "0.003"], ["70493.10", "0.013"], ["70496.70", "0.005"], ["70500.00", "1.011"]], "a": [["70500.10", "9.435"], ["70500.20", "0.064"], ["70500.80", "0.280"], ["70500.90", "0.500"], ["70501.00", "0.231"], ["70501.10", "0.375"], ["70501.20", "0.005"], ["70501.40", "0.002"], ["70503.10", "0.000"], ["70503.50", "0.002"], ["70503.60", "0.000"], ["70503.70", "0.112"], ["70504.40", "0.269"], ["70504.50", "1.422"], ["70504.60", "0.000"], ["70505.20", "0.009"], ["70505.50", "0.006"], ["70507.20", "0.002"], ["70507.70", "0.004"], ["70508.80", "0.001"], ["70510.70", "0.003"], ["70513.50", "0.513"], ["70514.40", "0.026"], ["70515.00", "1.349"], ["70516.80", "0.150"], ["70517.70", "0.000"], ["70520.20", "0.000"], ["70528.10", "0.007"], ["70531.40", "0.119"], ["70534.90", "1.876"], ["70535.40", "0.516"], ["70536.00", "0.108"], ["70545.90", "0.170"], ["70549.80", "0.000"], ["70550.50", "0.048"], ["70554.00", "0.364"], ["70567.10", "0.231"], ["70715.10", "0.000"], ["70748.40", "0.303"], ["70801.80", "0.619"], ["70859.30", "0.321"], ["71074.20", "3.722"], ["71205.10", "0.002"], ["71356.20", "4.057"], ["77550.10", "0.002"]]}}
{"local_ts": 1773485030761, "server_ts": 1773485029964, "data": {"e": "depthUpdate", "E": 1773485029965, "T": 1773485029964, "s": "BTCUSDT", "U": 10109427947976, "u": 10109427956411, "pu": 10109427947764, "b": [["5000.00", "101.418"], ["7050.00", "0.425"], ["20000.00", "5.604"], ["20001.00", "0.055"], ["20101.00", "0.090"], ["20400.00", "0.270"], ["56400.00", "6.994"], ["63450.00", "0.074"], ["66947.00", "0.000"], ["66969.40", "0.002"], ["66975.00", "0.084"], ["69548.20", "0.287"], ["69795.00", "0.099"], ["70316.70", "0.491"], ["70323.70", "0.364"], ["70346.30", "4.023"], ["70405.90", "2.339"], ["70429.10", "0.001"], ["70438.90", "0.002"], ["70440.10", "8.562"], ["70443.00", "0.011"], ["70443.70", "0.310"], ["70450.20", "0.015"], ["70450.40", "0.010"], ["70450.90", "0.004"], ["70458.40", "0.000"], ["70460.30", "0.003"], ["70461.00", "1.864"], ["70462.00", "0.024"], ["70463.30", "0.248"], ["70465.60", "0.006"], ["70467.80", "0.003"], ["70468.20", "0.004"], ["70469.30", "0.074"], ["70470.20", "0.000"], ["70474.00", "0.849"], ["70474.80", "0.009"], ["70475.10", "0.003"], ["70475.70", "0.004"], ["70476.40", "0.010"], ["70476.90", "0.006"], ["70480.20", "0.350"], ["70481.30", "0.029"], ["70481.40", "0.096"], ["70481.70", "1.284"], ["70484.10", "0.162"], ["70485.30", "0.005"], ["70485.90", "0.426"], ["70486.20", "0.004"], ["70486.70", "0.286"], ["70486.90", "0.005"], ["70488.40", "0.003"], ["70489.40", "0.000"], ["70489.90", "0.022"], ["70491.60", "0.025"], ["70493.10", "0.009"], ["70495.00", "0.006"], ["70495.40", "0.004"], ["70496.20", "0.014"], ["70496.30", "0.049"], ["70496.80", "0.000"], ["70497.10", "0.005"], ["70497.60", "0.005"], ["70499.00", "0.000"], ["70499.20", "0.000"], ["70499.40", "0.000"], ["70499.50", "0.000"], ["70499.80", "0.000"], ["70499.90", "0.000"], ["70500.00", "0.000"]], "a": [["70498.90", "1.091"], ["70499.30", "1.493"], ["70499.60", "3.304"], ["70499.90", "2.991"], ["70500.00", "2.818"], ["70500.10", "10.261"], ["70501.00", "0.005"], ["70501.10", "0.242"], ["70501.30", "0.007"], ["70502.10", "0.121"], ["70505.10", "0.002"], ["70507.20", "0.002"], ["70510.00", "0.011"], ["70511.80", "0.020"], ["70515.00", "1.346"], ["70516.20", "0.073"], ["70517.80", "0.053"], ["70518.60", "0.002"], ["70519.90", "0.012"], ["70526.50", "0.089"], ["70526.70", "0.000"], ["70527.40", "0.000"], ["70529.20", "0.029"], ["70531.80", "0.235"], ["70531.90", "0.159"], ["70532.00", "0.275"], ["70539.30", "0.004"], ["70546.40", "0.005"], ["70574.50", "0.009"], ["70592.00", "2.702"], ["70592.10", "6.488"], ["70651.30", "3.123"], ["70651.50", "0.002"], ["70679.90", "0.002"], ["70770.00", "0.547"], ["71205.10", "0.000"], ["71346.10", "1.283"], ["71920.30", "0.005"], ["72260.20", "0.000"], ["77550.10", "0.002"]]}}
{"local_ts": 1773485031779, "server_ts": 1773485030984, "data": {"e": "depthUpdate", "E": 1773485030987, "T": 1773485030984, "s": "BTCUSDT", "U": 10109428073091, "u": 10109428086183, "pu": 10109428073082, "b": [["1000.00", "28.692"], ["5000.00", "101.418"], ["7049.60", "0.000"], ["20000.00", "3.404"], ["20295.20", "0.120"], ["20395.20", "0.350"], ["20400.00", "0.150"], ["33000.00", "3.789"], ["63445.70", "0.000"], ["66940.20", "0.004"], ["69206.00", "0.722"], ["69508.30", "1.722"], ["69790.20", "0.000"], ["70142.80", "0.640"], ["70301.90", "0.000"], ["70308.40", "0.208"], ["70357.40", "0.087"], ["70369.50", "0.004"], ["70376.20", "0.001"], ["70404.80", "0.300"], ["70411.50", "0.000"], ["70438.80", "0.197"], ["70440.10", "0.049"], ["70445.70", "0.223"], ["70445.90", "0.197"], ["70446.30", "0.088"], ["70446.80", "0.001"], ["70447.10", "0.102"], ["70460.00", "0.108"], ["70464.00", "0.013"], ["70464.10", "0.124"], ["70464.70", "0.000"], ["70464.80", "0.064"], ["70465.80", "0.009"], ["70466.40", "0.072"], ["70467.20", "0.022"], ["70467.60", "0.072"], ["70468.20", "0.004"], ["70468.60", "0.027"], ["70470.20", "0.070"], ["70471.30", "0.176"], ["70473.80", "0.005"], ["70475.40", "0.007"], ["70476.80", "0.213"], ["70478.60", "0.000"], ["70479.10", "0.063"], ["70481.10", "0.108"], ["70481.90", "0.004"], ["70482.10", "0.101"], ["70482.90", "0.361"], ["70483.40", "0.030"], ["70483.80", "0.132"], ["70484.60", "0.215"], ["70486.00", "0.003"], ["70486.40", "0.059"], ["70487.20", "0.424"], ["70488.20", "0.223"], ["70488.70", "0.001"], ["70491.60", "0.010"], ["70491.90", "0.000"], ["70495.20", "0.108"]], "a": [["70495.30", "4.778"], ["70495.40", "1.549"], ["70496.20", "0.008"], ["70496.50", "0.002"], ["70496.60", "0.442"], ["70500.30", "0.057"], ["70501.00", "0.005"], ["70502.70", "0.000"], ["70503.30", "0.005"], ["70504.60", "0.007"], ["70505.90", "0.063"], ["70506.10", "0.028"], ["70507.50", "1.073"], ["70510.10", "0.151"], ["70510.80", "0.004"], ["70511.50", "0.512"], ["70513.10", "0.000"], ["70514.20", "0.070"], ["70514.30", "0.002"], ["70515.10", "0.002"], ["70515.60", "0.110"], ["70524.20", "0.430"], ["70524.70", "0.000"], ["70550.40", "0.312"], ["70557.20", "2.283"], ["70585.70", "0.388"], ["70592.50", "0.000"], ["70621.00", "0.003"], ["70627.80", "0.089"], ["70724.10", "0.000"], ["71200.30", "0.007"], ["71905.20", "0.006"], ["72550.10", "0.738"], ["74035.30", "0.002"], ["77544.80", "0.000"]]}}
{"local_ts": 1773485032801, "server_ts": 1773485032004, "data": {"e": "depthUpdate", "E": 1773485032007, "T": 1773485032004, "s": "BTCUSDT", "U": 10109428139408, "u": 10109428143141, "pu": 10109428139356, "b": [["1000.00", "28.692"], ["5000.00", "101.418"], ["7049.60", "0.056"], ["20295.20", "2.200"], ["20395.20", "0.800"], ["20395.30", "0.000"], ["63445.70", "0.000"], ["66945.20", "0.002"], ["69155.80", "0.144"], ["69498.20", "0.866"], ["69790.20", "1.431"], ["70325.00", "4.493"], ["70330.20", "0.000"], ["70363.80", "1.384"], ["70417.40", "0.043"], ["70417.70", "0.410"], ["70437.30", "0.000"], ["70437.50", "0.216"], ["70437.60", "0.070"], ["70438.80", "0.000"], ["70440.80", "0.908"], ["70446.60", "0.047"], ["70446.80", "0.001"], ["70463.10", "1.877"], ["70467.10", "0.057"], ["70469.30", "0.094"], ["70471.60", "0.510"], ["70480.40", "0.905"], ["70481.10", "0.578"], ["70481.90", "0.089"], ["70482.90", "0.373"], ["70483.10", "0.088"], ["70484.30", "0.040"], ["70484.50", "0.040"], ["70486.40", "0.653"], ["70488.10", "0.000"], ["70493.30", "0.024"], ["70495.20", "2.158"]], "a": [["70495.30", "2.991"], ["70496.90", "0.002"], ["70497.00", "0.002"], ["70498.20", "0.002"], ["70498.90", "0.010"], ["70499.10", "0.023"], ["70499.20", "0.000"], ["70499.80", "0.003"], ["70502.20", "0.242"], ["70503.10", "0.005"], ["70506.90", "0.039"], ["70507.20", "0.063"], ["70515.10", "0.643"], ["70520.00", "0.029"], ["70520.30", "0.048"], ["70540.40", "0.025"], ["70540.60", "0.027"], ["70541.60", "0.027"], ["70556.80", "0.002"], ["70628.40", "0.381"], ["70667.10", "7.425"], ["70673.00", "0.156"], ["70673.10", "0.000"], ["71200.30", "0.000"], ["71200.40", "3.664"], ["74050.30", "0.000"], ["77544.80", "0.000"], ["89523.20", "0.000"]]}}
{"local_ts": 1773485033822, "server_ts": 1773485033028, "data": {"e": "depthUpdate", "E": 1773485033029, "T": 1773485033028, "s": "BTCUSDT", "U": 10109428181701, "u": 10109428185810, "pu": 10109428181627, "b": [["5000.00", "101.398"], ["7049.60", "0.056"], ["20195.20", "1.760"], ["20295.20", "1.240"], ["33000.00", "3.789"], ["56396.00", "0.002"], ["63445.70", "0.000"], ["66759.00", "0.036"], ["66940.00", "0.050"], ["66979.80", "0.000"], ["66979.90", "0.002"], ["69093.60", "0.006"], ["69790.20", "1.431"], ["70319.00", "0.005"], ["70322.50", "0.163"], ["70363.80", "1.383"], ["70447.00", "0.002"], ["70447.10", "0.047"], ["70460.00", "0.080"], ["70484.60", "0.336"], ["70488.20", "0.284"], ["70488.30", "0.427"], ["70490.50", "0.005"], ["70493.10", "0.008"]], "a": [["70495.30", "2.975"], ["70495.40", "1.581"], ["70498.30", "1.422"], ["70498.60", "0.075"], ["70499.10", "0.021"], ["70509.60", "0.014"], ["70530.90", "0.002"], ["70544.60", "0.138"], ["70628.40", "0.406"], ["71200.30", "0.000"], ["74038.20", "0.002"], ["77544.80", "0.000"], ["89523.20", "0.000"]]}}
{"local_ts": 1773485034845, "server_ts": 1773485034050, "data": {"e": "depthUpdate", "E": 1773485034051, "T": 1773485034050, "s": "BTCUSDT", "U": 10109428220103, "u": 10109428223641, "pu": 10109428220089, "b": [["1000.00", "28.692"], ["5000.00", "101.418"], ["7049.60", "0.056"], ["20095.20", "1.310"], ["20195.20", "1.690"], ["66949.20", "0.002"], ["66968.80", "0.003"], ["69565.10", "0.854"], ["69790.20", "1.431"], ["70142.70", "0.307"], ["70437.50", "0.216"], ["70437.70", "0.070"], ["70440.40", "0.000"], ["70448.30", "0.513"], ["70448.40", "0.363"], ["70451.40", "0.091"], ["70454.80", "0.005"], ["70481.80", "0.269"], ["70482.50", "0.004"], ["70488.20", "0.312"], ["70491.70", "0.000"], ["70493.20", "0.075"], ["70495.20", "1.796"]], "a": [["70495.30", "3.076"], ["70498.60", "0.018"], ["70502.30", "0.000"], ["70508.00", "0.004"], ["70512.40", "0.023"], ["70517.90", "0.511"], ["70533.90", "0.004"], ["71200.30", "0.000"], ["89523.20", "0.000"]]}}
{"local_ts": 1773485035867, "server_ts": 1773485035073, "data": {"e": "depthUpdate", "E": 1773485035075, "T": 1773485035073, "s": "BTCUSDT", "U": 10109428256785, "u": 10109428260552, "pu": 10109428256733, "b": [["5000.00", "101.438"], ["7049.60", "0.028"], ["19995.20", "0.870"], ["20095.20", "2.130"], ["66949.20", "0.000"], ["66966.40", "0.002"], ["68394.70", "0.000"], ["69341.80", "0.015"], ["69790.20", "1.431"], ["70435.30", "0.005"], ["70460.00", "0.080"], ["70481.90", "0.004"], ["70482.50", "0.000"], ["70486.60", "0.086"], ["70488.20", "0.284"]], "a": [["70495.30", "2.845"], ["70495.40", "1.446"], ["70498.40", "0.076"], ["70501.00", "0.001"], ["70501.50", "0.000"], ["70501.60", "0.001"], ["70504.10", "0.513"], ["70505.50", "0.003"], ["70508.00", "0.001"], ["70527.50", "0.004"], ["70533.90", "0.002"], ["70900.00", "15.145"], ["71047.70", "3.325"], ["71059.80", "1.207"], ["71200.30", "0.000"], ["71520.20", "4.431"], ["72625.40", "0.000"], ["89523.20", "0.000"]]}}
{"local_ts": 1773485036892, "server_ts": 1773485036096, "data": {"e": "depthUpdate", "E": 1773485036099, "T": 1773485036096, "s": "BTCUSDT", "U": 10109428300804, "u": 10109428304472, "pu": 10109428300741, "b": [["1000.00", "28.692"], ["5000.00", "101.418"], ["7049.20", "0.028"], ["19991.60", "0.380"], ["19995.20", "2.170"], ["20095.20", "0.010"], ["20391.60", "0.280"], ["56393.00", "0.000"], ["66956.80", "0.000"], ["68365.80", "3.505"], ["68376.90", "0.008"], ["68718.70", "2.615"], ["69431.30", "1.252"], ["69459.50", "0.000"], ["69490.60", "2.799"], ["69786.70", "0.000"], ["70142.70", "0.307"], ["70194.50", "0.004"], ["70255.60", "0.000"], ["70305.50", "0.131"], ["70336.90", "0.087"], ["70353.20", "3.892"], ["70426.80", "0.258"], ["70435.20", "0.518"], ["70437.40", "3.927"], ["70444.20", "0.002"], ["70444.50", "0.154"], ["70445.70", "0.267"], ["70449.20", "0.042"], ["70450.60", "0.005"], ["70450.70", "0.074"], ["70455.60", "0.002"], ["70458.90", "1.782"], ["70470.50", "0.004"], ["70474.40", "0.400"], ["70477.20", "0.217"], ["70479.00", "0.002"], ["70479.80", "0.002"], ["70481.00", "0.385"], ["70481.10", "0.164"], ["70482.80", "0.495"], ["70482.90", "0.625"], ["70484.60", "0.246"], ["70489.00", "0.018"], ["70491.10", "0.059"], ["70491.60", "3.127"]], "a": [["70491.70", "3.547"], ["70495.30", "0.364"], ["70498.80", "0.002"], ["70504.40", "0.002"], ["70510.70", "0.020"], ["70511.30", "0.081"], ["70512.40", "0.512"], ["70514.30", "0.002"], ["70520.70", "0.023"], ["70521.90", "0.017"], ["70530.40", "0.014"], ["70542.00", "0.038"], ["70564.50", "0.000"], ["70794.40", "0.000"], ["71196.60", "0.002"], ["72606.40", "0.006"], ["74017.70", "0.012"], ["89523.20", "0.000"]]}}
{"local_ts": 1773485037919, "server_ts": 1773485037120, "data": {"e": "depthUpdate", "E": 1773485037123, "T": 1773485037120, "s": "BTCUSDT", "U": 10109428339288, "u": 10109428342670, "pu": 10109428339241, "b": [["1000.00", "28.692"], ["5000.00", "101.418"], ["7049.20", "0.028"], ["19991.60", "0.250"], ["19995.20", "0.000"], ["20291.60", "0.240"], ["20391.60", "2.510"], ["20395.20", "0.000"], ["56396.00", "0.002"], ["66964.40", "0.002"], ["68376.90", "0.012"], ["69149.60", "0.809"], ["69786.70", "0.000"], ["70200.00", "25.733"], ["70245.90", "0.000"], ["70360.60", "0.716"], ["70420.20", "0.113"], ["70444.40", "0.315"], ["70444.70", "0.685"], ["70478.90", "0.001"], ["70484.70", "0.040"]], "a": [["70504.40", "0.002"], ["70507.10", "0.035"], ["70530.40", "0.012"], ["70537.60", "0.019"], ["70539.40", "0.373"], ["70571.60", "0.029"], ["70627.00", "0.869"], ["71196.60", "0.002"], ["71482.20", "1.467"], ["74036.90", "0.000"], ["89523.20", "0.000"]]}}
{"local_ts": 1773485038941, "server_ts": 1773485038144, "data": {"e": "depthUpdate", "E": 1773485038145, "T": 1773485038144, "s": "BTCUSDT", "U": 10109428376170, "u": 10109428379803, "pu": 10109428376055, "b": [["5000.00", "101.418"], ["7049.20", "0.000"], ["20191.60", "0.090"], ["20291.60", "2.370"], ["20391.60", "0.540"], ["33000.00", "3.785"], ["66129.00", "0.005"], ["66954.60", "0.021"], ["66979.90", "0.000"], ["69414.00", "0.000"], ["69540.00", "0.360"], ["69592.60", "0.000"], ["69786.70", "0.715"], ["70360.70", "0.000"], ["70397.80", "0.018"], ["70397.90", "0.000"], ["70404.90", "0.071"], ["70405.00", "0.000"], ["70411.90", "0.115"], ["70412.00", "0.310"], ["70437.30", "0.184"], ["70437.50", "0.485"], ["70437.60", "0.070"], ["70438.70", "0.522"], ["70469.70", "0.726"], ["70470.20", "0.000"], ["70470.50", "0.259"], ["70470.70", "0.090"], ["70471.60", "0.000"], ["70473.30", "0.460"], ["70473.40", "1.205"], ["70475.60", "0.670"], ["70476.00", "0.035"], ["70477.00", "0.077"], ["70477.70", "0.012"], ["70478.90", "0.001"], ["70479.10", "0.307"], ["70480.40", "0.391"], ["70481.00", "0.301"], ["70481.80", "0.085"], ["70484.70", "0.220"], ["70486.00", "1.073"], ["70486.30", "0.418"], ["70488.10", "0.000"], ["70490.20", "0.007"], ["70490.50", "0.008"], ["70491.10", "0.023"], ["70491.50", "0.058"], ["70491.60", "3.005"]], "a": [["70491.70", "3.782"], ["70491.80", "0.270"], ["70491.90", "0.023"], ["70492.70", "0.000"], ["70493.90", "0.000"], ["70494.30", "0.000"], ["70494.80", "0.000"], ["70495.00", "0.001"], ["70495.30", "0.189"], ["70496.00", "0.007"], ["70497.10", "0.004"], ["70497.50", "0.264"], ["70497.60", "0.000"], ["70497.70", "0.002"], ["70498.30", "1.419"], ["70498.50", "0.007"], ["70498.90", "0.002"], ["70499.60", "0.000"], ["70501.70", "0.000"], ["70504.30", "0.021"], ["70504.40", "0.002"], ["70504.60", "0.002"], ["70505.70", "0.027"], ["70506.30", "0.004"], ["70506.40", "0.576"], ["70506.90", "0.004"], ["70507.20", "0.114"], ["70507.50", "0.223"], ["70507.60", "0.241"], ["70507.90", "0.367"], ["70508.00", "0.005"], ["70508.10", "0.009"], ["70508.20", "0.011"], ["70508.30", "0.006"], ["70508.40", "0.030"], ["70508.50", "0.000"], ["70508.60", "0.525"], ["70508.70", "0.207"], ["70508.80", "0.009"], ["70508.90", "0.003"], ["70509.00", "0.015"], ["70509.20", "0.002"], ["70509.30", "0.116"], ["70509.40", "0.011"], ["70509.60", "0.021"], ["70509.90", "0.000"], ["70510.50", "0.002"], ["70511.10", "0.518"], ["70511.40", "0.075"], ["70511.60", "0.076"], ["70512.10", "0.024"], ["70514.10", "0.025"], ["70515.00", "1.343"], ["70515.90", "0.014"], ["70516.00", "0.093"], ["70518.00", "0.083"], ["70526.90", "0.156"], ["70530.40", "0.069"], ["70537.60", "0.017"], ["70544.10", "0.087"], ["70556.90", "0.519"], ["70574.20", "0.231"], ["70574.30", "0.000"], ["70581.20", "0.075"], ["70581.30", "0.042"], ["70588.30", "0.071"], ["70588.40", "0.005"], ["70592.80", "1.410"], ["70678.50", "10.950"], ["70754.00", "0.000"], ["70758.00", "0.525"], ["70761.00", "0.002"], ["70765.00", "0.007"], ["70768.00", "0.010"], ["70772.00", "1.722"], ["70775.00", "0.308"], ["70779.00", "0.007"], ["70782.00", "0.000"], ["70786.00", "0.016"], ["70789.00", "0.031"], ["70793.00", "0.021"], ["70796.00", "0.061"], ["70800.00", "11.706"], ["70803.00", "0.005"], ["70807.00", "0.007"], ["71196.60", "0.002"], ["71414.50", "22.733"], ["71905.20", "0.000"], ["74043.80", "0.000"], ["89523.20", "0.000"], ["100000.00", "23.620"]]}}
{"local_ts": 1773485039964, "server_ts": 1773485039170, "data": {"e": "depthUpdate", "E": 1773485039171, "T": 1773485039170, "s": "BTCUSDT", "U": 10109428411985, "u": 10109428415613, "pu": 10109428411978, "b": [["1000.00", "28.692"], ["5000.00", "101.418"], ["7049.20", "0.000"], ["20191.60", "2.110"], ["20291.60", "0.890"], ["66934.40", "0.002"], ["69412.60", "0.000"], ["69469.50", "2.873"], ["69568.80", "0.718"], ["69778.20", "0.000"], ["69786.70", "0.715"], ["69939.00", "0.000"], ["70318.90", "0.099"], ["70435.20", "0.599"], ["70437.30", "0.184"], ["70444.70", "0.370"], ["70445.10", "0.009"], ["70445.30", "0.522"], ["70446.20", "0.005"], ["70453.30", "0.305"], ["70460.40", "1.200"], ["70461.30", "0.014"], ["70467.50", "0.054"], ["70470.00", "5.092"], ["70470.50", "0.004"], ["70471.60", "0.070"], ["70472.60", "0.041"], ["70473.00", "0.512"], ["70473.50", "0.119"], ["70474.60", "1.610"], ["70479.90", "0.006"], ["70480.20", "0.350"], ["70484.00", "0.001"], ["70486.90", "0.015"]], "a": [["70491.70", "2.774"], ["70497.40", "0.000"], ["70498.80", "0.060"], ["70507.90", "0.363"], ["70508.00", "0.001"], ["70508.10", "0.002"], ["70508.20", "0.004"], ["70508.60", "0.518"], ["70508.70", "0.200"], ["70508.80", "0.002"], ["70509.00", "0.004"], ["70509.40", "0.007"], ["70509.60", "0.007"], ["70511.10", "0.511"], ["70511.20", "0.128"], ["70511.60", "0.062"], ["70514.30", "0.002"], ["70514.90", "0.009"], ["70515.30", "0.004"], ["70515.90", "0.638"], ["70516.80", "0.519"], ["70517.20", "0.004"], ["70518.10", "0.009"], ["70518.50", "0.070"], ["70519.20", "0.079"], ["70520.00", "0.029"], ["70521.30", "0.254"], ["70521.40", "0.203"], ["70524.10", "0.052"], ["70524.30", "0.007"], ["70531.40", "0.119"], ["70531.70", "0.052"], ["70538.50", "0.139"], ["70542.40", "0.113"], ["70544.10", "0.085"], ["70569.60", "0.020"], ["70578.70", "0.020"], ["70581.40", "0.016"], ["70758.00", "0.518"], ["70765.00", "0.000"], ["70772.00", "1.715"], ["70779.00", "0.000"], ["70786.00", "0.009"], ["70793.00", "0.014"], ["70800.00", "11.699"], ["70807.00", "0.000"], ["71196.60", "0.002"], ["71211.20", "0.000"], ["71424.80", "0.000"], ["71473.20", "1.886"], ["71632.10", "0.004"], ["74031.40", "0.000"], ["89523.20", "0.000"], ["100000.00", "23.659"]]}}
{"local_ts": 1773485040988, "server_ts": 1773485040194, "data": {"e": "depthUpdate", "E": 1773485040195, "T": 1773485040194, "s": "BTCUSDT", "U": 10109428454542, "u": 10109428469166, "pu": 10109428454526, "b": [["5000.00", "101.418"], ["7049.20", "0.000"], ["20091.60", "1.670"], ["20191.60", "1.330"], ["33000.00", "3.789"], ["56393.00", "0.000"], ["68719.50", "2.615"], ["69786.70", "0.715"], ["70139.20", "0.000"], ["70198.90", "0.007"], ["70205.90", "0.007"], ["70212.90", "0.007"], ["70219.90", "0.067"], ["70226.90", "0.007"], ["70233.90", "0.007"], ["70240.90", "0.007"], ["70247.80", "7.228"], ["70247.90", "0.007"], ["70318.90", "0.159"], ["70444.60", "0.148"], ["70445.30", "0.522"], ["70446.20", "0.005"], ["70453.30", "0.305"], ["70460.40", "1.200"], ["70464.70", "0.002"], ["70465.60", "0.256"], ["70467.50", "0.002"], ["70474.60", "1.610"], ["70477.20", "0.002"], ["70486.60", "0.001"]], "a": [["70491.70", "0.638"], ["70494.40", "0.006"], ["70494.50", "0.003"], ["70495.30", "0.187"], ["70495.90", "0.003"], ["70497.40", "0.000"], ["70498.00", "0.007"], ["70501.80", "0.000"], ["70502.50", "0.011"], ["70503.40", "0.003"], ["70503.70", "0.089"], ["70503.80", "0.003"], ["70504.00", "0.347"], ["70504.40", "0.017"], ["70506.30", "0.002"], ["70508.10", "0.004"], ["70511.40", "0.011"], ["70512.30", "0.015"], ["70513.10", "0.269"], ["70517.20", "0.004"], ["70517.70", "0.070"], ["70519.90", "0.111"], ["70520.50", "0.248"], ["70524.30", "0.007"], ["70526.90", "0.117"], ["70530.90", "0.002"], ["70531.40", "0.119"], ["70538.50", "0.139"], ["70581.10", "0.155"], ["70581.40", "0.002"], ["70583.30", "0.021"], ["70714.90", "0.865"], ["70744.10", "0.805"], ["70744.20", "0.000"], ["70777.00", "4.953"], ["70813.10", "0.000"], ["71045.80", "45.430"], ["71196.60", "0.002"], ["71209.20", "53.581"], ["71422.80", "66.387"], ["74033.10", "0.000"], ["89523.20", "0.000"]]}}
{"local_ts": 1773485042010, "server_ts": 1773485041216, "data": {"e": "depthUpdate", "E": 1773485041217, "T": 1773485041216, "s": "BTCUSDT", "U": 10109428559679, "u": 10109428565893, "pu": 10109428559396, "b": [["1000.00", "28.692"], ["5000.00", "101.418"], ["7049.20", "0.056"], ["19991.60", "1.230"], ["20091.60", "1.770"], ["40000.00", "41.317"], ["68729.30", "0.291"], ["68943.00", "0.300"], ["69081.80", "0.162"], ["69786.70", "0.715"], ["70022.20", "0.005"], ["70139.10", "0.152"], ["70198.90", "0.000"], ["70205.90", "0.000"], ["70212.90", "0.000"], ["70219.90", "0.060"], ["70226.90", "0.000"], ["70233.90", "0.000"], ["70240.90", "0.000"], ["70247.90", "0.000"], ["70305.50", "0.013"], ["70308.30", "0.000"], ["70398.20", "0.000"], ["70398.30", "0.014"], ["70436.20", "0.344"], ["70436.30", "0.089"], ["70443.60", "0.254"], ["70445.80", "0.214"], ["70461.60", "0.243"], ["70468.30", "0.007"], ["70469.10", "0.070"], ["70470.50", "0.357"], ["70472.90", "0.151"], ["70473.80", "0.005"], ["70474.20", "0.000"], ["70474.70", "0.000"], ["70474.90", "0.030"], ["70475.60", "0.020"], ["70475.70", "1.209"], ["70475.80", "0.668"], ["70476.30", "0.004"], ["70476.70", "0.009"], ["70478.80", "0.014"], ["70479.80", "0.009"], ["70480.50", "0.005"], ["70480.90", "0.001"], ["70481.00", "0.243"], ["70481.10", "0.159"], ["70481.60", "0.009"], ["70481.70", "1.269"], ["70481.90", "0.206"], ["70482.20", "0.262"], ["70482.40", "0.003"], ["70483.00", "0.016"], ["70483.20", "0.167"], ["70483.30", "0.068"], ["70483.60", "0.018"], ["70483.70", "0.003"], ["70483.80", "0.023"], ["70484.00", "0.020"], ["70484.10", "0.169"], ["70484.30", "0.395"], ["70484.60", "0.009"], ["70484.90", "0.049"], ["70485.20", "0.003"], ["70485.30", "0.234"], ["70485.40", "0.100"], ["70485.60", "0.024"], ["70486.10", "0.566"], ["70486.30", "0.421"], ["70487.30", "0.085"], ["70487.60", "0.021"], ["70490.90", "0.004"], ["70491.60", "3.883"]], "a": [["70494.60", "0.005"], ["70494.70", "0.006"], ["70497.60", "0.000"], ["70498.00", "0.007"], ["70498.70", "0.004"], ["70499.90", "0.003"], ["70500.20", "1.421"], ["70507.20", "0.110"], ["70509.10", "0.009"], ["70509.90", "0.000"], ["70510.60", "0.010"], ["70513.10", "0.000"], ["70519.90", "0.165"], ["70521.30", "0.002"], ["70521.80", "0.005"], ["70526.90", "0.096"], ["70581.10", "0.141"], ["70586.80", "0.014"], ["70593.10", "0.043"], ["70714.70", "0.000"], ["70716.00", "0.009"], ["70744.40", "1.309"], ["71196.60", "0.002"], ["71473.10", "0.000"], ["71512.20", "3.286"], ["71513.80", "7.678"], ["71582.70", "1.954"], ["71584.30", "2.930"], ["71619.60", "1.952"], ["74049.20", "0.002"], ["89523.20", "0.000"]]}}
{"local_ts": 1773485043029, "server_ts": 1773485042236, "data": {"e": "depthUpdate", "E": 1773485042237, "T": 1773485042236, "s": "BTCUSDT", "U": 10109428623594, "u": 10109428630152, "pu": 10109428623551, "b": [["1000.00", "28.692"], ["5000.00", "101.418"], ["7049.20", "0.056"], ["19991.60", "2.230"], ["20391.60", "0.770"], ["66956.50", "0.006"], ["69363.70", "3.024"], ["69469.50", "9.915"], ["69786.70", "0.717"], ["70285.60", "0.000"], ["70296.00", "0.207"], ["70420.20", "0.113"], ["70445.10", "0.007"], ["70445.30", "0.524"], ["70461.60", "0.276"], ["70465.60", "0.048"], ["70469.80", "0.002"], ["70470.50", "0.496"], ["70476.00", "1.240"], ["70477.00", "0.009"], ["70480.40", "0.309"], ["70480.90", "0.001"], ["70481.20", "0.776"], ["70481.50", "0.108"], ["70481.90", "0.489"], ["70482.30", "0.001"], ["70482.80", "0.017"], ["70484.60", "0.189"], ["70485.30", "0.274"], ["70486.80", "0.003"], ["70487.10", "0.000"], ["70487.20", "0.434"], ["70487.50", "0.000"]], "a": [["70491.70", "0.440"], ["70498.60", "0.015"], ["70499.60", "0.000"], ["70500.90", "0.242"], ["70501.00", "0.003"], ["70501.10", "0.008"], ["70502.80", "1.421"], ["70503.20", "0.017"], ["70506.30", "0.027"], ["70507.00", "0.097"], ["70510.50", "0.002"], ["70511.20", "0.148"], ["70512.00", "0.007"], ["70539.30", "0.114"], ["70571.50", "0.033"], ["70594.30", "0.084"], ["70628.40", "0.003"], ["70638.90", "0.003"], ["70678.50", "10.890"], ["70715.50", "0.007"], ["70744.30", "0.008"], ["71196.50", "0.000"], ["71196.60", "0.004"], ["71357.90", "0.032"], ["71513.80", "12.566"], ["71619.60", "3.904"], ["71654.80", "2.927"], ["71901.50", "0.015"], ["74026.50", "0.040"]]}}
{"local_ts": 1773485044052, "server_ts": 1773485043252, "data": {"e": "depthUpdate", "E": 1773485043257, "T": 1773485043252, "s": "BTCUSDT", "U": 10109428675788, "u": 10109428679713, "pu": 10109428675646, "b": [["5000.00", "101.418"], ["7049.20", "0.056"], ["19991.60", "0.050"], ["20291.60", "0.370"], ["20391.60", "2.580"], ["66943.40", "0.002"], ["69786.70", "0.715"], ["70397.60", "0.139"], ["70397.70", "0.000"], ["70404.70", "0.073"], ["70404.80", "0.003"], ["70411.70", "0.071"], ["70411.80", "0.097"], ["70435.90", "0.085"], ["70436.00", "1.066"], ["70445.20", "1.458"], ["70445.30", "0.524"], ["70482.80", "0.177"], ["70484.60", "0.250"]], "a": [["70491.70", "0.437"], ["70494.80", "0.000"], ["70498.70", "0.004"], ["70538.20", "0.110"], ["70574.00", "0.073"], ["70581.00", "0.075"], ["70588.10", "0.224"], ["70593.70", "6.303"], ["71196.60", "1.544"], ["71513.80", "15.498"], ["71522.40", "1.956"], ["71527.90", "4.541"]]}}
{"local_ts": 1773485045075, "server_ts": 1773485044272, "data": {"e": "depthUpdate", "E": 1773485044277, "T": 1773485044272, "s": "BTCUSDT", "U": 10109428720544, "u": 10109428724611, "pu": 10109428720391, "b": [["1000.00", "28.692"], ["5000.00", "101.418"], ["7049.20", "0.028"], ["20191.60", "0.200"], ["20291.60", "2.470"], ["20391.60", "0.330"], ["69424.60", "0.434"], ["69786.70", "0.715"], ["69962.90", "0.716"], ["70449.40", "0.003"], ["70461.50", "0.006"]], "a": [["70496.30", "0.005"], ["70500.80", "0.003"], ["70501.40", "0.018"], ["70501.70", "0.000"], ["70501.80", "0.000"], ["70501.90", "0.003"], ["70502.00", "0.001"], ["70502.80", "1.421"], ["70557.00", "1.308"], ["70715.20", "0.000"], ["70819.90", "1.119"], ["71196.60", "1.965"], ["74044.60", "0.002"]]}}
{"local_ts": 1773485046094, "server_ts": 1773485045300, "data": {"e": "depthUpdate", "E": 1773485045301, "T": 1773485045300, "s": "BTCUSDT", "U": 10109428771503, "u": 10109428776076, "pu": 10109428771435, "b": [["1000.00", "28.892"], ["5000.00", "101.398"], ["7049.20", "0.028"], ["20091.60", "0.050"], ["20191.60", "2.340"], ["20291.60", "0.610"], ["66936.50", "0.002"], ["66957.00", "0.023"], ["66967.00", "0.156"], ["69391.90", "0.308"], ["69422.80", "0.431"], ["69786.70", "1.012"], ["70401.90", "0.142"], ["70402.00", "0.840"], ["70409.00", "0.496"], ["70409.10", "0.331"], ["70416.00", "0.148"], ["70416.10", "0.089"], ["70435.50", "0.004"], ["70435.70", "0.000"], ["70435.80", "0.085"], ["70444.20", "0.006"], ["70449.60", "0.000"], ["70449.70", "0.062"], ["70463.30", "0.002"], ["70463.40", "0.084"], ["70464.00", "0.058"], ["70464.10", "0.124"], ["70477.70", "0.005"], ["70479.20", "0.013"], ["70481.60", "0.006"], ["70484.70", "0.392"], ["70486.80", "0.013"], ["70487.70", "0.000"], ["70488.40", "0.530"], ["70491.60", "3.630"]], "a": [["70493.80", "0.000"], ["70494.20", "0.017"], ["70494.40", "0.000"], ["70495.70", "0.182"], ["70496.40", "0.001"], ["70498.80", "0.002"], ["70499.90", "0.003"], ["70500.20", "0.020"], ["70500.30", "0.027"], ["70501.40", "0.024"], ["70503.10", "0.002"], ["70504.30", "0.001"], ["70504.90", "0.011"], ["70506.10", "0.003"], ["70516.40", "0.126"], ["70516.70", "0.638"], ["70517.10", "0.030"], ["70519.90", "0.328"], ["70521.10", "0.107"], ["70521.30", "0.002"], ["70522.20", "0.005"], ["70522.30", "0.002"], ["70522.90", "1.197"], ["70523.00", "0.064"], ["70573.40", "0.361"], ["70573.70", "0.097"], ["70579.80", "0.251"], ["70580.40", "0.386"], ["70580.70", "0.184"], ["70586.40", "0.016"], ["70587.10", "6.226"], ["70587.50", "0.150"], ["70587.80", "0.511"], ["70696.90", "0.041"], ["70706.80", "0.000"], ["71196.60", "1.965"], ["71584.30", "7.675"], ["71779.90", "0.700"], ["72263.50", "2.486"], ["72274.20", "0.000"], ["74036.10", "0.083"]]}}
{"local_ts": 1773485047116, "server_ts": 1773485046320, "data": {"e": "depthUpdate", "E": 1773485046323, "T": 1773485046320, "s": "BTCUSDT", "U": 10109428820943, "u": 10109428827421, "pu": 10109428820843, "b": [["1000.00", "29.092"], ["5000.00", "101.418"], ["7049.20", "0.028"], ["20091.60", "1.900"], ["20091.70", "0.090"], ["20191.60", "1.010"], ["40000.00", "41.356"], ["66965.30", "0.006"], ["69081.80", "0.162"], ["69487.10", "0.002"], ["69489.70", "0.006"], ["69490.00", "3.005"], ["69490.10", "1.159"], ["69491.70", "0.012"], ["69786.70", "0.858"], ["69786.80", "0.000"], ["70139.10", "1.284"], ["70167.40", "11.562"], ["70170.50", "0.875"], ["70245.90", "0.166"], ["70247.80", "3.504"], ["70315.40", "0.040"], ["70315.50", "0.002"], ["70319.00", "0.164"], ["70327.40", "5.360"], ["70411.10", "1.973"], ["70419.80", "10.468"], ["70420.50", "0.060"], ["70435.30", "0.005"], ["70435.40", "0.000"], ["70435.50", "0.004"], ["70435.80", "0.085"], ["70438.70", "0.441"], ["70440.90", "0.010"], ["70442.30", "0.005"], ["70442.40", "0.081"], ["70442.90", "0.068"], ["70443.60", "0.186"], ["70444.10", "0.356"], ["70445.40", "0.153"], ["70445.80", "0.146"], ["70445.90", "0.543"], ["70446.00", "0.006"], ["70449.80", "0.007"], ["70449.90", "1.256"], ["70461.60", "0.297"], ["70463.50", "0.111"], ["70466.10", "0.007"], ["70466.90", "0.251"], ["70467.80", "0.003"], ["70470.40", "0.016"], ["70470.50", "0.006"], ["70471.00", "0.016"], ["70471.30", "0.164"], ["70472.90", "0.000"], ["70474.50", "0.044"], ["70474.90", "0.002"], ["70475.50", "0.018"], ["70476.30", "0.000"], ["70476.70", "0.002"], ["70480.60", "0.511"], ["70480.70", "0.056"], ["70481.00", "0.005"], ["70481.10", "0.041"], ["70481.20", "0.002"], ["70481.70", "1.260"], ["70481.80", "0.000"], ["70482.00", "0.002"], ["70482.60", "0.101"], ["70482.80", "0.015"], ["70482.90", "0.514"], ["70483.00", "0.009"], ["70483.10", "0.121"], ["70483.20", "0.290"], ["70483.30", "0.064"], ["70483.40", "0.001"], ["70483.60", "0.011"], ["70483.70", "0.003"], ["70483.80", "0.023"], ["70483.90", "0.010"], ["70484.00", "0.016"], ["70484.10", "0.003"], ["70484.20", "0.016"], ["70484.30", "0.388"], ["70484.60", "0.215"], ["70484.70", "0.591"], ["70484.90", "0.042"], ["70485.40", "0.002"], ["70485.60", "0.010"], ["70485.90", "0.394"], ["70486.10", "0.514"], ["70486.30", "0.585"], ["70486.40", "0.009"], ["70486.60", "0.001"], ["70486.80", "0.003"], ["70486.90", "0.007"], ["70487.30", "0.001"], ["70487.60", "0.007"], ["70488.10", "0.002"], ["70488.20", "0.004"], ["70488.30", "0.004"], ["70488.40", "0.019"], ["70488.60", "0.002"], ["70490.10", "0.011"], ["70490.80", "0.002"], ["70490.90", "0.002"], ["70491.00", "0.057"], ["70491.10", "0.006"], ["70491.20", "0.000"], ["70491.40", "0.002"], ["70491.50", "0.022"], ["70491.60", "0.274"], ["70491.70", "12.725"]], "a": [["70491.70", "0.000"], ["70491.80", "0.252"], ["70492.10", "0.002"], ["70495.30", "0.194"], ["70495.40", "0.114"], ["70495.80", "0.001"], ["70496.80", "0.002"], ["70499.60", "0.000"], ["70499.80", "0.060"], ["70500.10", "0.093"], ["70500.30", "0.010"], ["70500.40", "0.006"], ["70500.60", "0.003"], ["70500.80", "0.003"], ["70501.40", "0.003"], ["70502.00", "0.000"], ["70502.20", "0.007"], ["70502.30", "0.000"], ["70502.40", "0.005"], ["70504.00", "0.476"], ["70504.10", "0.000"], ["70505.70", "0.010"], ["70506.90", "0.004"], ["70507.90", "0.396"], ["70508.20", "0.004"], ["70508.40", "0.001"], ["70508.50", "0.029"], ["70509.40", "0.007"], ["70510.10", "0.130"], ["70510.60", "0.003"], ["70510.70", "0.020"], ["70511.20", "0.128"], ["70511.50", "0.017"], ["70512.00", "0.007"], ["70512.30", "0.020"], ["70512.60", "0.002"], ["70512.80", "0.003"], ["70513.00", "0.016"], ["70513.20", "0.073"], ["70514.90", "0.009"], ["70515.70", "0.529"], ["70515.80", "0.004"], ["70515.90", "0.057"], ["70516.10", "0.000"], ["70516.70", "0.007"], ["70516.80", "0.004"], ["70517.00", "0.022"], ["70517.30", "0.838"], ["70518.00", "0.584"], ["70518.20", "0.060"], ["70518.80", "0.672"], ["70519.50", "0.085"], ["70520.70", "0.038"], ["70520.90", "0.059"], ["70521.30", "0.087"], ["70521.50", "0.036"], ["70521.90", "0.038"], ["70522.00", "0.751"], ["70522.70", "0.248"], ["70523.30", "0.015"], ["70523.70", "0.002"], ["70523.80", "0.024"], ["70525.00", "0.340"], ["70525.80", "1.603"], ["70530.90", "0.002"], ["70536.50", "0.089"], ["70554.80", "0.358"], ["70558.20", "0.002"], ["70558.40", "0.011"], ["70565.80", "0.102"], ["70678.60", "0.271"], ["70809.90", "0.000"], ["70811.80", "0.000"], ["70844.30", "0.211"], ["70918.00", "0.317"], ["71045.70", "0.651"], ["71059.80", "4.447"], ["71196.60", "1.965"], ["71196.70", "0.000"], ["71434.10", "0.000"], ["71498.70", "0.704"], ["71527.90", "5.100"], ["74041.30", "0.000"]]}}
{"local_ts": 1773485048147, "server_ts": 1773485047344, "data": {"e": "depthUpdate", "E": 1773485047347, "T": 1773485047344, "s": "BTCUSDT", "U": 10109428874692, "u": 10109428879498, "pu": 10109428874527, "b": [["5000.00", "101.418"], ["7049.20", "0.000"], ["19991.70", "1.550"], ["20091.60", "1.270"], ["20091.70", "0.180"], ["33000.00", "3.785"], ["66942.50", "0.004"], ["66967.00", "0.158"], ["69786.80", "0.000"], ["70069.10", "37.023"], ["70069.20", "5.564"], ["70174.40", "32.060"], ["70174.90", "7.035"], ["70245.30", "0.000"], ["70250.80", "0.004"], ["70251.60", "26.460"], ["70251.70", "6.938"], ["70322.00", "2.272"], ["70360.70", "0.000"], ["70420.30", "0.655"], ["70420.60", "0.101"], ["70446.00", "0.006"], ["70446.10", "0.162"], ["70470.10", "0.549"], ["70470.80", "0.410"], ["70471.60", "0.077"], ["70472.00", "0.000"], ["70472.20", "0.013"], ["70472.60", "0.048"], ["70472.80", "0.000"], ["70477.70", "1.217"], ["70478.30", "0.002"], ["70481.80", "0.000"], ["70484.70", "0.471"], ["70485.00", "0.049"], ["70486.80", "0.003"], ["70487.60", "0.007"], ["70488.10", "0.000"]], "a": [["70499.30", "0.008"], ["70500.40", "0.013"], ["70500.70", "0.003"], ["70501.40", "0.010"], ["70502.30", "0.000"], ["70502.40", "0.059"], ["70502.50", "1.422"], ["70502.60", "0.002"], ["70502.80", "0.003"], ["70506.60", "0.084"], ["70506.90", "0.137"], ["70512.90", "0.085"], ["70513.10", "0.007"], ["70513.70", "0.211"], ["70515.60", "0.007"], ["70516.30", "0.512"], ["70516.70", "0.000"], ["70516.80", "0.011"], ["70517.40", "0.072"], ["70518.00", "0.074"], ["70518.10", "0.000"], ["70518.30", "0.119"], ["70538.80", "0.063"], ["70539.10", "0.359"], ["70554.80", "0.089"], ["70571.10", "0.025"], ["70571.30", "0.025"], ["70625.70", "8.944"], ["70664.50", "0.015"], ["70735.10", "4.226"], ["70738.10", "27.083"], ["70812.50", "0.213"], ["70815.90", "32.978"], ["70844.20", "0.000"], ["70844.30", "0.000"], ["70922.20", "38.831"], ["74031.00", "0.045"], ["74047.40", "0.007"]]}}
{"local_ts": 1773485049171, "server_ts": 1773485048368, "data": {"e": "depthUpdate", "E": 1773485048369, "T": 1773485048368, "s": "BTCUSDT", "U": 10109428919839, "u": 10109428924234, "pu": 10109428919798, "b": [["1000.00", "29.092"], ["5000.00", "101.418"], ["7049.20", "0.000"], ["19991.70", "1.890"], ["20391.70", "1.110"], ["66946.40", "0.000"], ["66967.10", "0.000"], ["67650.00", "0.316"], ["68491.60", "0.000"], ["69206.40", "0.622"], ["69786.80", "0.000"], ["70139.20", "0.000"], ["70397.50", "0.018"], ["70404.60", "0.113"], ["70411.60", "0.408"], ["70435.60", "0.000"], ["70435.70", "0.085"], ["70462.10", "0.179"], ["70481.10", "0.269"], ["70481.80", "0.638"], ["70482.30", "0.093"], ["70483.90", "0.020"], ["70484.80", "0.177"]], "a": [["70491.80", "0.350"], ["70494.80", "0.000"], ["70495.70", "0.176"], ["70496.50", "0.000"], ["70498.90", "0.002"], ["70502.40", "0.059"], ["70506.60", "0.063"], ["70506.90", "0.137"], ["70507.20", "0.146"], ["70508.90", "0.003"], ["70509.30", "0.054"], ["70512.90", "0.085"], ["70518.80", "0.663"], ["70523.80", "0.024"], ["70573.80", "0.174"], ["70580.80", "0.073"], ["70587.90", "0.314"], ["71196.70", "0.000"], ["74027.60", "0.002"], ["74044.20", "0.000"]]}}
{"local_ts": 1773485050182, "server_ts": 1773485049388, "data": {"e": "depthUpdate", "E": 1773485049389, "T": 1773485049388, "s": "BTCUSDT", "U": 10109428963504, "u": 10109428968084, "pu": 10109428963409, "b": [["1000.00", "28.692"], ["5000.00", "101.418"], ["7049.20", "0.000"], ["19991.70", "0.000"], ["20291.70", "0.660"], ["20391.70", "2.340"], ["33000.00", "3.789"], ["69274.00", "1.441"], ["69467.00", "1.716"], ["69634.30", "3.154"], ["69786.80", "0.000"], ["70284.90", "0.000"], ["70285.00", "0.662"], ["70322.00", "6.231"], ["70360.80", "0.614"], ["70364.00", "1.444"], ["70397.40", "0.062"], ["70398.30", "0.000"], ["70398.40", "1.065"], ["70404.50", "0.115"], ["70411.50", "0.071"], ["70442.80", "2.324"], ["70454.20", "0.014"], ["70473.80", "0.013"], ["70482.30", "0.001"], ["70484.80", "0.177"], ["70486.40", "0.092"], ["70491.70", "10.030"]], "a": [["70491.80", "0.339"], ["70495.30", "0.091"], ["70497.90", "0.005"], ["70498.90", "0.004"], ["70500.70", "0.003"], ["70502.70", "1.476"], ["70502.80", "0.003"], ["70503.90", "0.005"], ["70505.90", "0.087"], ["70573.80", "0.174"], ["70580.80", "0.073"], ["70587.90", "0.314"], ["70623.50", "1.770"], ["70625.60", "0.598"], ["70664.30", "3.346"], ["70701.30", "0.521"], ["70701.90", "0.516"], ["71196.70", "0.000"], ["71357.20", "0.700"], ["71527.30", "0.028"], ["72535.60", "0.000"], ["74030.90", "0.000"]]}}
{"local_ts": 1773485051205, "server_ts": 1773485050408, "data": {"e": "depthUpdate", "E": 1773485050409, "T": 1773485050408, "s": "BTCUSDT", "U": 10109429010032, "u": 10109429014407, "pu": 10109429009928, "b": [["5000.00", "101.398"], ["7049.20", "0.056"], ["20191.70", "0.310"], ["20291.70", "2.590"], ["20391.70", "0.100"], ["66967.20", "0.004"], ["69786.80", "0.007"], ["69786.90", "0.000"], ["69800.90", "0.715"], ["70245.30", "0.000"], ["70397.40", "0.062"], ["70404.50", "0.115"], ["70411.50", "0.071"], ["70444.90", "0.405"], ["70454.20", "0.010"]], "a": [["70491.80", "0.350"], ["70494.90", "0.012"], ["70497.10", "0.006"], ["70501.70", "0.000"], ["70503.00", "0.004"], ["70505.90", "0.006"], ["70515.10", "0.002"], ["70515.80", "0.004"], ["70520.00", "0.717"], ["70552.10", "0.184"], ["70554.80", "0.174"], ["70573.70", "0.168"], ["70580.70", "0.255"], ["70587.80", "0.582"], ["70715.80", "0.007"], ["71174.80", "0.000"], ["71196.70", "0.000"], ["74026.60", "0.002"]]}}
{"local_ts": 1773485052223, "server_ts": 1773485051428, "data": {"e": "depthUpdate", "E": 1773485051431, "T": 1773485051428, "s": "BTCUSDT", "U": 10109429053892, "u": 10109429058212, "pu": 10109429053836, "b": [["1000.00", "28.692"], ["5000.00", "101.418"], ["7049.20", "0.056"], ["20091.70", "0.160"], ["20191.70", "2.440"], ["20291.70", "0.400"], ["66952.80", "0.004"], ["66960.50", "0.002"], ["66967.10", "0.016"], ["69495.60", "0.431"], ["69645.80", "1.291"], ["69786.80", "0.042"], ["70069.10", "0.000"], ["70139.20", "0.000"], ["70174.40", "0.403"], ["70245.50", "0.000"], ["70251.60", "0.000"], ["70462.00", "0.068"], ["70467.10", "0.056"], ["70468.00", "0.018"], ["70470.60", "0.792"], ["70471.90", "0.077"], ["70472.50", "0.157"], ["70481.00", "0.643"], ["70481.50", "0.123"], ["70484.20", "0.294"], ["70484.50", "0.007"], ["70487.60", "0.007"]], "a": [["70497.40", "0.057"], ["70503.80", "0.058"], ["70505.90", "0.006"], ["70516.40", "0.762"], ["70517.20", "0.004"], ["70518.20", "0.001"], ["70519.30", "0.048"], ["70520.00", "0.777"], ["70520.70", "0.023"], ["70521.50", "0.371"], ["70521.90", "0.038"], ["70530.60", "0.249"], ["70554.80", "0.089"], ["70738.10", "0.000"], ["70815.90", "0.000"], ["70922.20", "0.000"], ["71196.70", "0.000"]]}}
{"local_ts": 1773485053244, "server_ts": 1773485052449, "data": {"e": "depthUpdate", "E": 1773485052451, "T": 1773485052449, "s": "BTCUSDT", "U": 10109429102850, "u": 10109429107070, "pu": 10109429102838, "b": [["5000.00", "101.458"], ["7049.60", "0.056"], ["19995.20", "0.010"], ["20095.20", "1.090"], ["20191.70", "0.700"], ["63923.20", "0.002"], ["66946.60", "0.000"], ["66967.10", "0.014"], ["66967.20", "0.002"], ["66970.40", "0.006"], ["69118.60", "1.432"], ["69258.10", "1.164"], ["69272.10", "0.360"], ["69700.00", "11.532"], ["69790.20", "1.431"], ["70138.70", "0.010"], ["70411.60", "0.378"], ["70420.40", "0.100"], ["70421.00", "0.103"], ["70421.30", "0.040"], ["70422.00", "0.180"], ["70448.50", "0.005"], ["70448.60", "0.001"], ["70457.10", "0.004"], ["70458.50", "0.021"], ["70470.50", "0.340"], ["70478.20", "0.404"], ["70478.30", "0.002"], ["70479.40", "0.196"], ["70479.50", "1.216"], ["70482.90", "0.514"], ["70484.60", "0.005"], ["70484.70", "0.496"], ["70485.00", "0.683"], ["70485.10", "0.569"], ["70486.30", "0.623"], ["70487.70", "0.007"], ["70491.70", "0.749"], ["70495.20", "11.156"]], "a": [["70499.60", "0.000"], ["70500.90", "0.050"], ["70503.70", "0.009"], ["70504.00", "0.404"], ["70504.10", "1.419"], ["70505.90", "0.011"], ["70506.20", "0.028"], ["70506.30", "0.000"], ["70506.50", "0.171"], ["70507.70", "0.013"], ["70509.10", "0.003"], ["70517.20", "0.004"], ["70517.90", "0.518"], ["70518.90", "0.008"], ["70519.10", "0.000"], ["70520.50", "0.510"], ["70521.90", "0.017"], ["70522.10", "0.110"], ["70530.50", "0.286"], ["70533.80", "0.000"], ["70538.00", "0.167"], ["70538.30", "0.066"], ["70560.60", "0.077"], ["70563.50", "0.217"], ["70566.70", "0.145"], ["70571.70", "0.096"], ["70580.00", "3.166"], ["70580.10", "0.002"], ["70585.50", "0.309"], ["70593.00", "0.000"], ["71200.30", "0.701"], ["71517.40", "0.838"], ["71626.80", "2.091"], ["73315.10", "0.008"], ["89523.20", "0.000"]]}}
{"local_ts": 1773485054267, "server_ts": 1773485053472, "data": {"e": "depthUpdate", "E": 1773485053473, "T": 1773485053472, "s": "BTCUSDT", "U": 10109429139928, "u": 10109429143150, "pu": 10109429139849, "b": [["1000.00", "28.692"], ["5000.00", "101.398"], ["7049.60", "0.028"], ["19995.20", "1.870"], ["20091.70", "0.690"], ["20095.20", "0.430"], ["66953.40", "0.002"], ["69281.80", "0.002"], ["69352.20", "0.000"], ["69790.20", "1.431"], ["69790.30", "3.507"], ["70142.70", "0.307"], ["70249.30", "0.000"], ["70249.40", "0.006"], ["70364.30", "0.629"], ["70401.90", "0.000"], ["70404.70", "0.144"], ["70409.00", "0.039"], ["70411.80", "0.239"], ["70416.00", "0.006"], ["70418.80", "0.142"], ["70444.00", "0.002"], ["70444.10", "0.000"], ["70445.80", "0.487"], ["70445.90", "0.336"], ["70448.00", "0.325"], ["70448.10", "0.258"], ["70458.30", "0.532"], ["70462.30", "0.103"], ["70477.00", "0.009"], ["70479.40", "0.369"], ["70479.50", "1.216"], ["70481.10", "0.402"], ["70481.50", "0.108"], ["70485.90", "0.397"], ["70486.40", "0.148"], ["70486.80", "0.005"], ["70487.70", "0.004"], ["70488.10", "0.011"], ["70488.20", "0.048"], ["70493.50", "0.020"], ["70495.20", "11.160"]], "a": [["70495.30", "1.467"], ["70499.60", "0.000"], ["70500.90", "0.235"], ["70501.40", "0.005"], ["70501.60", "0.001"], ["70502.30", "0.000"], ["70503.10", "0.002"], ["70503.90", "1.423"], ["70504.00", "0.197"], ["70504.60", "0.002"], ["70505.90", "0.009"], ["70512.90", "0.098"], ["70515.10", "0.005"], ["70515.80", "0.007"], ["70520.00", "0.699"], ["70530.50", "0.226"], ["70573.40", "0.219"], ["70574.00", "0.144"], ["70580.40", "0.244"], ["70581.00", "0.146"], ["70587.50", "6.340"], ["70588.10", "0.143"], ["70609.30", "0.151"], ["70616.90", "0.085"], ["70633.10", "0.668"], ["70633.40", "0.000"], ["70705.20", "3.213"], ["70718.60", "0.000"], ["71200.20", "0.009"], ["71200.30", "0.701"], ["73315.10", "0.010"], ["89523.20", "0.000"]]}}
{"local_ts": 1773485055288, "server_ts": 1773485054493, "data": {"e": "depthUpdate", "E": 1773485054495, "T": 1773485054493, "s": "BTCUSDT", "U": 10109429174301, "u": 10109429178203, "pu": 10109429174273, "b": [["1000.00", "28.692"], ["5000.00", "101.438"], ["7049.60", "0.028"], ["19995.20", "1.580"], ["20395.20", "1.420"], ["33000.00", "3.785"], ["68873.30", "0.000"], ["69177.00", "0.292"], ["69437.80", "0.404"], ["69660.60", "0.002"], ["69790.20", "1.438"], ["69790.30", "3.511"], ["70248.90", "0.000"], ["70364.30", "0.000"], ["70434.50", "0.382"], ["70444.90", "0.401"], ["70469.00", "0.072"], ["70470.10", "0.797"], ["70470.50", "0.546"], ["70481.10", "0.205"], ["70487.70", "0.004"], ["70495.20", "11.181"]], "a": [["70495.30", "1.478"], ["70497.80", "0.022"], ["70498.40", "0.073"], ["70498.70", "0.019"], ["70501.60", "0.016"], ["70503.00", "0.025"], ["70505.90", "0.006"], ["70508.90", "0.003"], ["70519.40", "0.096"], ["70565.80", "0.021"], ["70633.00", "0.089"], ["71200.30", "0.708"], ["74020.80", "0.000"], ["89523.20", "0.000"]]}}
{"local_ts": 1773485056310, "server_ts": 1773485055516, "data": {"e": "depthUpdate", "E": 1773485055517, "T": 1773485055516, "s": "BTCUSDT", "U": 10109429209050, "u": 10109429213342, "pu": 10109429208938, "b": [["5000.00", "101.418"], ["7049.60", "0.028"], ["20295.20", "0.980"], ["20395.20", "2.020"], ["66967.20", "0.002"], ["69629.20", "0.720"], ["69790.20", "2.161"], ["70142.80", "0.680"], ["70249.30", "0.000"], ["70322.00", "2.274"], ["70397.60", "0.139"], ["70404.70", "0.215"], ["70411.70", "0.071"], ["70420.90", "0.010"], ["70441.30", "0.000"], ["70452.90", "0.092"], ["70470.50", "0.546"], ["70473.20", "0.516"], ["70475.00", "0.078"], ["70487.00", "0.061"], ["70488.10", "0.013"]], "a": [["70499.40", "0.000"], ["70501.50", "0.002"], ["70502.00", "0.008"], ["70502.20", "0.006"], ["70503.30", "0.007"], ["70503.50", "0.000"], ["70506.30", "0.000"], ["70514.90", "0.029"], ["70520.80", "1.000"], ["70521.40", "0.205"], ["70521.70", "0.072"], ["70522.10", "0.025"], ["70522.20", "0.010"], ["70522.30", "0.004"], ["70522.40", "0.103"], ["70522.50", "0.189"], ["70523.80", "0.024"], ["70560.80", "1.087"], ["70574.00", "0.215"], ["70581.00", "0.217"], ["70588.10", "0.214"], ["70611.30", "0.007"], ["70627.30", "0.000"], ["70719.20", "0.000"], ["71200.20", "0.009"], ["71200.30", "1.409"], ["71360.50", "1.116"], ["74041.10", "0.000"], ["89523.20", "0.000"]]}}
{"local_ts": 1773485057342, "server_ts": 1773485056540, "data": {"e": "depthUpdate", "E": 1773485056541, "T": 1773485056540, "s": "BTCUSDT", "U": 10109429249804, "u": 10109429253192, "pu": 10109429249690, "b": [["1000.00", "28.692"], ["5000.00", "101.418"], ["7049.60", "0.000"], ["20195.20", "0.540"], ["20295.20", "2.460"], ["20395.20", "0.000"], ["33000.00", "3.789"], ["56396.00", "0.002"], ["66963.70", "0.000"], ["69189.00", "1.916"], ["69790.20", "2.161"], ["70142.70", "0.307"], ["70320.50", "0.091"], ["70322.00", "2.272"], ["70427.30", "0.184"], ["70447.80", "0.070"], ["70447.90", "0.003"], ["70460.00", "0.066"], ["70462.10", "0.003"], ["70471.10", "0.007"], ["70475.20", "0.041"], ["70480.70", "0.010"], ["70489.70", "0.018"], ["70494.70", "0.000"], ["70494.90", "0.057"], ["70495.00", "0.002"]], "a": [["70495.30", "1.451"], ["70495.80", "0.050"], ["70521.40", "0.203"], ["70521.70", "0.074"], ["70522.70", "0.000"], ["70522.90", "1.337"], ["70549.60", "1.140"], ["70673.30", "0.106"], ["70700.00", "22.670"], ["71200.30", "1.409"], ["71457.20", "0.000"], ["73315.10", "0.020"], ["74031.20", "0.008"], ["89523.20", "0.000"]]}}
{"local_ts": 1773485058355, "server_ts": 1773485057560, "data": {"e": "depthUpdate", "E": 1773485057563, "T": 1773485057560, "s": "BTCUSDT", "U": 10109429287436, "u": 10109429291784, "pu": 10109429287328, "b": [["5000.00", "101.418"], ["7049.60", "0.000"], ["20095.20", "0.270"], ["20195.20", "2.550"], ["20295.20", "0.180"], ["56396.00", "0.002"], ["66967.10", "0.004"], ["66967.20", "0.004"], ["69438.10", "0.000"], ["69790.20", "2.161"], ["70319.80", "0.002"], ["70320.50", "0.089"], ["70322.50", "0.163"], ["70325.50", "3.924"], ["70364.20", "0.745"], ["70389.30", "0.042"], ["70389.60", "0.131"], ["70428.20", "0.267"], ["70444.60", "8.661"], ["70446.10", "0.019"], ["70447.60", "0.465"], ["70460.00", "0.026"], ["70462.10", "0.000"], ["70469.00", "0.320"], ["70469.60", "0.367"], ["70469.80", "0.002"], ["70470.50", "0.693"], ["70472.70", "0.017"], ["70473.80", "0.005"], ["70474.00", "0.035"], ["70474.40", "0.140"], ["70474.70", "0.007"], ["70475.10", "0.511"], ["70475.20", "0.056"], ["70475.30", "0.003"], ["70475.40", "0.004"], ["70475.70", "0.011"], ["70476.10", "0.028"], ["70476.20", "0.001"], ["70481.10", "0.293"], ["70482.80", "0.015"], ["70483.40", "0.639"], ["70484.00", "0.295"], ["70484.20", "0.003"], ["70484.60", "0.116"], ["70484.80", "0.004"], ["70485.50", "0.002"], ["70485.60", "0.115"], ["70485.90", "0.398"], ["70487.20", "0.001"], ["70487.60", "0.009"], ["70488.20", "0.004"], ["70493.10", "0.000"], ["70493.50", "0.005"], ["70494.00", "0.000"], ["70495.20", "10.052"]], "a": [["70495.70", "0.199"], ["70496.30", "0.010"], ["70497.70", "0.023"], ["70501.50", "0.009"], ["70502.00", "0.001"], ["70503.50", "1.418"], ["70503.70", "0.066"], ["70503.80", "0.000"], ["70503.90", "0.005"], ["70505.90", "0.009"], ["70507.10", "0.067"], ["70507.60", "0.230"], ["70510.40", "0.007"], ["70510.80", "0.004"], ["70510.90", "0.057"], ["70512.90", "0.083"], ["70514.20", "0.007"], ["70514.90", "0.007"], ["70515.10", "0.007"], ["70516.50", "0.003"], ["70518.70", "0.644"], ["70518.90", "0.511"], ["70519.50", "0.016"], ["70520.30", "0.004"], ["70520.40", "0.036"], ["70520.50", "0.000"], ["70521.00", "0.005"], ["70521.50", "0.106"], ["70521.70", "0.002"], ["70521.80", "0.075"], ["70522.30", "0.004"], ["70522.40", "0.103"], ["70522.50", "0.189"], ["70526.00", "0.056"], ["70527.90", "1.197"], ["70562.30", "0.013"], ["70569.90", "0.225"], ["70570.10", "0.042"], ["70631.60", "0.584"], ["70631.70", "0.018"], ["70668.50", "0.619"], ["70670.40", "4.234"], ["70671.40", "0.008"], ["71200.30", "1.409"], ["71658.50", "0.627"], ["72028.10", "0.596"], ["74031.20", "0.006"], ["89523.20", "0.000"]]}}
{"local_ts": 1773485059382, "server_ts": 1773485058584, "data": {"e": "depthUpdate", "E": 1773485058585, "T": 1773485058584, "s": "BTCUSDT", "U": 10109429325770, "u": 10109429330224, "pu": 10109429325684, "b": [["1000.00", "28.692"], ["5000.00", "101.418"], ["7049.60", "0.000"], ["19995.20", "0.120"], ["20095.20", "2.410"], ["20195.20", "0.470"], ["33000.00", "3.789"], ["56396.00", "0.002"], ["66970.40", "0.012"], ["68721.90", "5.230"], ["69085.30", "0.897"], ["69296.80", "1.341"], ["69790.20", "3.592"], ["70142.70", "0.307"], ["70319.80", "0.000"], ["70320.10", "0.002"], ["70364.20", "0.780"], ["70397.90", "0.018"], ["70405.00", "0.071"], ["70412.00", "0.381"], ["70445.40", "0.252"], ["70445.90", "0.438"], ["70447.40", "0.006"], ["70469.00", "0.320"], ["70469.70", "0.656"], ["70470.50", "0.548"], ["70474.90", "0.072"], ["70475.70", "0.004"], ["70476.90", "1.272"], ["70479.30", "0.111"], ["70481.10", "0.293"], ["70483.70", "0.010"], ["70483.90", "0.010"], ["70484.00", "0.933"], ["70484.60", "0.113"], ["70484.80", "0.004"], ["70487.00", "0.063"], ["70487.60", "0.012"], ["70495.20", "10.031"]], "a": [["70495.30", "1.262"], ["70497.50", "0.011"], ["70499.70", "0.066"], ["70501.40", "0.012"], ["70501.80", "0.000"], ["70503.50", "1.533"], ["70503.90", "0.005"], ["70505.90", "0.009"], ["70508.90", "0.006"], ["70513.20", "0.162"], ["70514.90", "0.007"], ["70518.60", "0.002"], ["70519.30", "0.005"], ["70519.50", "0.193"], ["70520.00", "0.620"], ["70520.40", "0.034"], ["70560.00", "0.072"], ["70574.20", "0.231"], ["70581.20", "0.075"], ["70588.30", "0.071"], ["70631.30", "0.582"], ["70631.50", "0.291"], ["71200.30", "1.409"], ["71479.60", "0.035"], ["74044.20", "0.002"], ["89523.20", "0.000"]]}}
{"local_ts": 1773485060401, "server_ts": 1773485059605, "data": {"e": "depthUpdate", "E": 1773485059607, "T": 1773485059605, "s": "BTCUSDT", "U": 10109429370424, "u": 10109429374344, "pu": 10109429370370, "b": [["1000.00", "28.692"], ["5000.00", "101.418"], ["7049.60", "0.056"], ["19995.20", "2.200"], ["20095.20", "0.800"], ["56396.00", "0.002"], ["66967.30", "0.002"], ["69407.20", "1.998"], ["69473.00", "0.863"], ["69477.70", "5.067"], ["69790.20", "3.592"], ["70242.70", "0.211"], ["70246.10", "2.160"], ["70281.70", "0.004"], ["70288.40", "0.266"], ["70320.10", "0.000"], ["70322.50", "0.004"], ["70325.40", "3.800"], ["70326.00", "2.722"], ["70332.70", "0.714"], ["70336.60", "0.002"], ["70345.80", "4.010"], ["70349.90", "0.133"], ["70364.20", "0.744"], ["70444.90", "0.405"], ["70484.60", "0.116"], ["70487.60", "0.012"], ["70493.50", "0.026"], ["70494.80", "0.000"], ["70494.90", "0.000"], ["70495.00", "0.002"], ["70495.20", "10.025"]], "a": [["70495.30", "1.364"], ["70498.10", "0.000"], ["70498.30", "0.001"], ["70499.30", "0.023"], ["70500.00", "0.108"], ["70503.50", "0.115"], ["70503.90", "1.423"], ["70505.90", "0.006"], ["70513.20", "0.077"], ["70513.60", "0.345"], ["70520.00", "1.128"], ["70524.20", "0.007"], ["70631.00", "0.877"], ["70668.50", "1.207"], ["70669.80", "4.273"], ["70678.60", "0.271"], ["70706.80", "0.058"], ["70718.70", "0.007"], ["70735.00", "0.006"], ["70745.80", "0.247"], ["70746.40", "0.617"], ["70749.10", "1.391"], ["71200.20", "0.002"], ["71200.30", "1.409"], ["71240.40", "0.840"], ["89523.20", "0.000"]]}}
{"local_ts": 1773485061420, "server_ts": 1773485060626, "data": {"e": "depthUpdate", "E": 1773485060627, "T": 1773485060626, "s": "BTCUSDT", "U": 10109429425999, "u": 10109429430813, "pu": 10109429425992, "b": [["5000.00", "101.418"], ["7049.60", "0.056"], ["19995.20", "1.250"], ["20395.20", "1.750"], ["56396.00", "0.002"], ["69790.20", "3.592"], ["70398.00", "0.124"], ["70405.10", "0.153"], ["70408.90", "0.090"], ["70412.10", "0.002"], ["70454.00", "0.342"], ["70479.30", "0.111"], ["70482.10", "0.094"], ["70486.20", "0.007"], ["70486.40", "0.111"], ["70487.60", "0.016"]], "a": [["70495.30", "1.280"], ["70505.90", "0.006"], ["70506.60", "0.038"], ["70508.80", "0.002"], ["70512.90", "0.083"], ["70543.10", "0.072"], ["70574.30", "0.000"], ["70579.70", "0.043"], ["70581.30", "0.042"], ["70581.40", "0.073"], ["70588.40", "0.080"], ["70678.60", "0.271"], ["70718.60", "0.000"], ["71049.60", "0.007"], ["71200.30", "1.409"], ["71572.70", "1.396"], ["71738.10", "0.347"], ["72610.10", "0.006"], ["74021.30", "0.000"], ["74040.40", "0.002"], ["89523.20", "0.000"]]}}
{"local_ts": 1773485062444, "server_ts": 1773485061648, "data": {"e": "depthUpdate", "E": 1773485061649, "T": 1773485061648, "s": "BTCUSDT", "U": 10109429474228, "u": 10109429478323, "pu": 10109429474141, "b": [["1000.00", "28.692"], ["5000.00", "101.398"], ["7049.60", "0.056"], ["20295.20", "1.310"], ["20395.20", "1.690"], ["56396.00", "0.002"], ["66970.00", "0.002"], ["69578.80", "5.453"], ["69790.20", "3.592"], ["70142.70", "0.307"], ["70336.60", "0.002"], ["70341.80", "0.000"], ["70454.20", "0.010"], ["70454.30", "0.062"], ["70461.50", "0.006"], ["70461.70", "0.951"]], "a": [["70498.90", "0.002"], ["70499.40", "0.008"], ["70505.90", "0.006"], ["70514.90", "0.007"], ["70668.50", "1.208"], ["70678.60", "0.271"], ["70735.10", "4.172"], ["70833.70", "0.000"], ["71200.30", "1.409"], ["71561.60", "0.418"], ["71744.40", "0.010"], ["74031.40", "0.000"], ["89523.20", "0.000"]]}}
{"local_ts": 1773485063468, "server_ts": 1773485062670, "data": {"e": "depthUpdate", "E": 1773485062671, "T": 1773485062670, "s": "BTCUSDT", "U": 10109429520409, "u": 10109429524900, "pu": 10109429520393, "b": [["5000.00", "101.418"], ["7049.60", "0.028"], ["20195.20", "0.860"], ["20295.20", "2.140"], ["66941.90", "0.002"], ["66950.10", "0.000"], ["68786.10", "0.622"], ["69790.20", "2.161"], ["70249.40", "0.002"], ["70249.50", "0.006"], ["70336.60", "0.002"], ["70389.50", "0.040"], ["70389.70", "0.040"], ["70466.70", "0.041"], ["70479.30", "0.000"], ["70480.80", "0.002"], ["70485.20", "0.641"], ["70485.80", "0.044"], ["70495.20", "10.082"]], "a": [["70495.80", "0.050"], ["70496.00", "0.080"], ["70496.20", "0.000"], ["70496.50", "0.000"], ["70496.70", "0.000"], ["70497.00", "0.021"], ["70498.50", "0.015"], ["70503.30", "0.064"], ["70505.90", "0.030"], ["70512.40", "0.002"], ["70513.60", "0.345"], ["70513.70", "0.211"], ["70515.80", "0.007"], ["70517.00", "0.000"], ["70520.20", "0.977"], ["70521.20", "0.000"], ["70569.90", "0.225"], ["70570.20", "0.025"], ["70591.60", "0.002"], ["70592.00", "1.970"], ["70623.30", "0.000"], ["70678.60", "0.220"], ["70704.50", "0.004"], ["70705.10", "0.000"], ["70718.60", "0.000"], ["70728.80", "0.012"], ["70779.30", "0.007"], ["71200.30", "1.409"], ["71430.90", "0.698"], ["71779.70", "0.557"], ["89523.20", "0.000"]]}}
{"local_ts": 1773485064484, "server_ts": 1773485063690, "data": {"e": "depthUpdate", "E": 1773485063691, "T": 1773485063690, "s": "BTCUSDT", "U": 10109429561003, "u": 10109429568470, "pu": 10109429560904, "b": [["1000.00", "28.692"], ["5000.00", "101.418"], ["7049.60", "0.028"], ["20095.20", "0.430"], ["20195.20", "2.550"], ["20295.20", "0.020"], ["33000.00", "3.789"], ["66955.80", "0.003"], ["69085.30", "0.900"], ["69790.20", "4.665"], ["70055.80", "0.000"], ["70142.70", "0.343"], ["70143.00", "0.000"], ["70249.20", "0.007"], ["70249.40", "0.002"], ["70387.00", "0.005"], ["70397.80", "0.014"], ["70437.60", "0.002"], ["70442.70", "0.000"], ["70444.60", "0.146"], ["70445.40", "0.068"], ["70447.40", "0.004"], ["70448.50", "8.518"], ["70450.20", "0.003"], ["70450.40", "0.107"], ["70452.70", "0.108"], ["70459.20", "0.006"], ["70469.80", "0.002"], ["70470.10", "0.569"], ["70470.50", "0.635"], ["70471.50", "0.000"], ["70472.40", "0.248"], ["70472.80", "0.052"], ["70473.30", "0.399"], ["70473.90", "0.015"], ["70474.00", "0.020"], ["70474.70", "0.000"], ["70475.20", "0.041"], ["70475.60", "0.020"], ["70475.90", "0.476"], ["70476.10", "0.000"], ["70476.30", "0.070"], ["70476.40", "0.000"], ["70476.60", "0.013"], ["70477.10", "0.005"], ["70477.40", "0.000"], ["70477.80", "0.000"], ["70477.90", "0.070"], ["70478.50", "0.008"], ["70478.80", "0.582"], ["70479.60", "0.000"], ["70479.80", "0.002"], ["70480.00", "5.450"], ["70480.30", "1.161"], ["70480.40", "0.300"], ["70480.80", "0.002"], ["70481.00", "0.004"], ["70481.20", "1.207"], ["70481.40", "0.072"], ["70481.50", "0.019"], ["70481.80", "0.000"], ["70482.00", "0.002"], ["70482.30", "0.008"], ["70484.40", "0.005"], ["70484.60", "0.504"], ["70484.70", "0.000"], ["70485.40", "0.002"], ["70486.10", "0.032"], ["70486.20", "0.007"], ["70486.30", "0.627"], ["70486.40", "0.203"], ["70486.60", "0.270"], ["70486.70", "0.006"], ["70486.80", "0.000"], ["70487.30", "0.008"], ["70487.50", "0.293"], ["70487.60", "0.026"], ["70487.70", "0.638"], ["70488.20", "0.312"], ["70488.40", "0.015"], ["70488.90", "0.006"], ["70489.10", "0.146"], ["70491.10", "0.007"], ["70491.60", "0.179"], ["70491.80", "1.208"], ["70491.90", "0.029"], ["70492.30", "0.000"], ["70493.10", "0.000"], ["70493.90", "0.024"], ["70495.00", "0.027"]], "a": [["70495.30", "0.514"], ["70497.30", "0.000"], ["70497.50", "0.001"], ["70497.60", "0.000"], ["70497.70", "0.002"], ["70497.90", "0.005"], ["70498.90", "0.002"], ["70499.00", "0.008"], ["70499.70", "0.001"], ["70500.50", "0.007"], ["70500.60", "0.003"], ["70500.80", "0.071"], ["70500.90", "0.034"], ["70501.00", "0.003"], ["70501.20", "0.002"], ["70502.40", "0.002"], ["70502.50", "0.005"], ["70502.70", "0.000"], ["70502.80", "0.001"], ["70502.90", "0.004"], ["70503.00", "0.004"], ["70503.30", "0.007"], ["70504.00", "0.400"], ["70504.10", "0.023"], ["70504.60", "0.002"], ["70504.80", "0.007"], ["70505.00", "0.006"], ["70505.70", "0.010"], ["70505.90", "0.009"], ["70506.20", "0.025"], ["70506.50", "1.625"], ["70506.70", "0.000"], ["70507.20", "0.132"], ["70507.30", "0.002"], ["70507.40", "0.041"], ["70508.50", "0.000"], ["70508.60", "0.212"], ["70508.80", "0.002"], ["70509.30", "0.003"], ["70510.90", "0.000"], ["70511.20", "0.128"], ["70512.00", "0.081"], ["70512.40", "0.020"], ["70512.60", "0.014"], ["70513.10", "0.002"], ["70513.30", "0.003"], ["70513.70", "0.268"], ["70514.10", "0.025"], ["70514.70", "0.005"], ["70514.90", "0.022"], ["70515.20", "0.002"], ["70515.60", "0.000"], ["70516.50", "0.003"], ["70516.80", "0.011"], ["70517.00", "0.002"], ["70517.30", "0.200"], ["70517.60", "0.010"], ["70518.40", "0.040"], ["70519.70", "0.001"], ["70519.80", "0.000"], ["70520.10", "1.070"], ["70520.20", "0.340"], ["70520.80", "1.002"], ["70520.90", "0.057"], ["70521.00", "0.005"], ["70521.40", "0.210"], ["70521.70", "0.002"], ["70521.80", "0.005"], ["70522.00", "0.736"], ["70522.30", "0.011"], ["70523.00", "0.062"], ["70523.30", "0.637"], ["70524.10", "0.000"], ["70524.20", "0.515"], ["70524.50", "0.070"], ["70525.10", "0.844"], ["70525.40", "0.679"], ["70526.70", "0.070"], ["70527.30", "0.020"], ["70527.80", "0.251"], ["70528.40", "0.000"], ["70529.40", "0.013"], ["70530.80", "0.054"], ["70531.70", "0.010"], ["70538.90", "2.183"], ["70539.70", "0.055"], ["70541.00", "0.087"], ["70544.50", "0.088"], ["70550.10", "0.290"], ["70554.80", "0.174"], ["70560.40", "0.301"], ["70560.60", "0.002"], ["70560.80", "0.384"], ["70561.40", "0.082"], ["70563.30", "8.593"], ["70586.90", "0.000"], ["70589.20", "0.018"], ["70591.60", "0.000"], ["70592.20", "0.002"], ["70597.70", "0.000"], ["70607.10", "4.025"], ["70704.50", "0.002"], ["70706.80", "0.002"], ["70800.00", "11.699"], ["70812.50", "0.213"], ["71200.30", "1.409"], ["71263.70", "2.100"], ["71713.80", "0.696"], ["71783.40", "0.699"], ["74046.00", "1.451"], ["89523.20", "0.000"]]}}
{"local_ts": 1773485065503, "server_ts": 1773485064710, "data": {"e": "depthUpdate", "E": 1773485064711, "T": 1773485064710, "s": "BTCUSDT", "U": 10109429652423, "u": 10109429659024, "pu": 10109429652342, "b": [["1000.00", "28.692"], ["5000.00", "101.418"], ["7049.60", "0.028"], ["19995.20", "0.230"], ["20095.20", "2.500"], ["20195.20", "0.270"], ["66968.70", "0.002"], ["69405.60", "1.366"], ["69790.20", "5.023"], ["70355.20", "0.086"], ["70357.60", "0.125"], ["70359.50", "0.086"], ["70361.30", "0.101"], ["70365.60", "23.298"], ["70370.40", "0.334"], ["70373.20", "0.928"], ["70375.10", "0.086"], ["70440.60", "0.182"], ["70440.80", "1.408"], ["70447.40", "0.006"], ["70447.60", "0.222"], ["70486.40", "0.314"], ["70487.50", "0.290"], ["70488.20", "0.166"]], "a": [["70495.30", "0.256"], ["70498.60", "0.014"], ["70500.00", "0.110"], ["70500.20", "0.003"], ["70502.30", "0.002"], ["70503.00", "0.021"], ["70505.90", "0.009"], ["70526.10", "0.001"], ["70526.30", "0.345"], ["70589.80", "0.258"], ["70592.20", "0.000"], ["70621.30", "0.193"], ["70625.80", "0.092"], ["70628.80", "0.127"], ["70678.60", "0.271"], ["70697.80", "0.002"], ["70706.80", "0.000"], ["70812.50", "0.002"], ["71049.70", "0.009"], ["71059.80", "1.855"], ["71200.30", "2.811"], ["71249.90", "3.243"], ["71461.10", "0.280"], ["71588.00", "6.849"], ["74020.50", "0.035"]]}}
{"local_ts": 1773485066528, "server_ts": 1773485065733, "data": {"e": "depthUpdate", "E": 1773485065735, "T": 1773485065733, "s": "BTCUSDT", "U": 10109429704417, "u": 10109429709045, "pu": 10109429704412, "b": [["5000.00", "101.418"], ["7049.60", "0.000"], ["19995.20", "2.360"], ["20095.20", "0.560"], ["20395.20", "0.080"], ["33000.00", "3.789"], ["66945.90", "0.000"], ["66967.20", "0.000"], ["69085.30", "0.906"], ["69630.00", "0.760"], ["69790.20", "6.454"], ["69931.20", "0.071"], ["70142.80", "0.644"], ["70249.00", "0.030"], ["70322.50", "0.004"], ["70350.70", "0.085"], ["70351.10", "0.287"], ["70355.30", "0.101"], ["70358.10", "0.200"], ["70372.20", "0.200"], ["70389.80", "0.157"], ["70428.20", "0.014"], ["70447.30", "1.830"], ["70447.40", "0.006"], ["70469.00", "0.072"], ["70470.20", "0.248"], ["70470.50", "0.557"], ["70479.30", "0.000"], ["70481.10", "0.627"], ["70484.60", "0.390"], ["70485.80", "0.041"], ["70487.50", "0.290"], ["70487.60", "0.026"], ["70488.20", "0.055"], ["70491.90", "0.031"]], "a": [["70495.30", "0.650"], ["70496.20", "0.000"], ["70497.50", "0.001"], ["70497.60", "0.012"], ["70499.00", "0.010"], ["70499.60", "0.015"], ["70500.70", "0.003"], ["70501.20", "0.017"], ["70502.30", "0.000"], ["70502.60", "0.017"], ["70502.90", "0.004"], ["70504.40", "0.000"], ["70505.80", "0.110"], ["70505.90", "0.009"], ["70506.10", "0.096"], ["70513.60", "0.360"], ["70514.90", "0.007"], ["70519.80", "0.184"], ["70520.00", "0.757"], ["70520.90", "0.694"], ["70522.20", "0.008"], ["70523.10", "0.073"], ["70524.90", "0.012"], ["70525.40", "0.927"], ["70526.70", "0.000"], ["70527.50", "0.002"], ["70528.40", "0.052"], ["70530.50", "0.246"], ["70572.00", "0.040"], ["70589.80", "0.256"], ["70590.20", "0.015"], ["70697.80", "0.000"], ["70699.60", "0.518"], ["71200.30", "4.353"], ["71905.20", "0.024"]]}}
{"local_ts": 1773485067550, "server_ts": 1773485066752, "data": {"e": "depthUpdate", "E": 1773485066755, "T": 1773485066752, "s": "BTCUSDT", "U": 10109429752023, "u": 10109429756654, "pu": 10109429751951, "b": [["1000.00", "28.692"], ["5000.00", "101.398"], ["7049.60", "0.000"], ["19995.20", "0.930"], ["20395.20", "2.070"], ["66954.40", "0.002"], ["69508.30", "4.521"], ["69790.20", "6.454"], ["70142.70", "0.343"], ["70142.80", "0.644"], ["70249.50", "0.002"], ["70315.40", "0.040"], ["70319.00", "0.005"], ["70322.50", "0.163"], ["70333.10", "0.000"], ["70349.20", "0.000"], ["70349.30", "12.349"], ["70349.40", "2.243"], ["70360.70", "0.000"], ["70402.80", "0.446"], ["70407.60", "6.552"], ["70409.30", "1.724"], ["70409.90", "0.516"], ["70416.90", "0.513"], ["70442.50", "3.322"], ["70455.30", "0.004"], ["70455.40", "0.487"], ["70461.70", "0.685"], ["70463.70", "1.786"], ["70484.60", "0.393"], ["70486.60", "0.086"], ["70487.60", "0.019"], ["70488.40", "0.013"]], "a": [["70495.30", "0.465"], ["70505.90", "0.009"], ["70512.90", "0.083"], ["70533.70", "1.812"], ["70553.00", "1.191"], ["70555.00", "3.930"], ["70579.10", "0.225"], ["70586.10", "0.250"], ["70590.20", "6.524"], ["70591.00", "0.004"], ["70593.20", "0.087"], ["70624.60", "0.009"], ["70647.80", "3.600"], ["70649.10", "12.454"], ["70675.90", "6.148"], ["70699.60", "0.516"], ["70702.50", "0.002"], ["70718.60", "0.007"], ["70815.90", "0.015"], ["70816.10", "0.213"], ["71200.20", "0.002"], ["71200.30", "4.353"], ["71905.20", "0.027"], ["72610.10", "0.011"]]}}
{"local_ts": 1773485068581, "server_ts": 1773485067780, "data": {"e": "depthUpdate", "E": 1773485067781, "T": 1773485067780, "s": "BTCUSDT", "U": 10109429796270, "u": 10109429800687, "pu": 10109429796156, "b": [["5000.00", "101.418"], ["7049.60", "0.000"], ["20295.20", "1.640"], ["20395.20", "1.360"], ["69790.20", "6.454"], ["70142.80", "0.640"], ["70249.40", "0.006"], ["70322.50", "0.103"], ["70364.00", "1.140"], ["70391.90", "0.103"], ["70392.20", "0.040"], ["70402.70", "0.003"], ["70409.80", "0.184"], ["70416.80", "0.077"], ["70447.70", "0.228"], ["70447.80", "0.070"], ["70467.00", "0.028"], ["70481.10", "0.523"], ["70484.60", "0.005"], ["70487.60", "0.019"], ["70494.80", "0.000"], ["70494.90", "0.002"], ["70495.00", "0.027"]], "a": [["70495.30", "0.445"], ["70496.30", "0.002"], ["70496.50", "0.015"], ["70501.80", "0.021"], ["70505.90", "0.009"], ["70519.80", "0.184"], ["70554.80", "0.358"], ["70554.90", "0.174"], ["70572.40", "0.322"], ["70572.60", "0.063"], ["70579.00", "0.592"], ["70586.00", "0.010"], ["70586.90", "0.211"], ["70593.10", "0.043"], ["70623.50", "0.828"], ["70627.20", "0.055"], ["70628.90", "0.000"], ["70629.80", "0.092"], ["70631.40", "0.263"], ["70631.80", "0.565"], ["70632.00", "0.097"], ["70632.50", "0.202"], ["70718.60", "0.007"], ["70816.00", "0.050"], ["71200.30", "3.652"], ["74029.10", "0.000"]]}}
{"local_ts": 1773485069599, "server_ts": 1773485068804, "data": {"e": "depthUpdate", "E": 1773485068807, "T": 1773485068804, "s": "BTCUSDT", "U": 10109429836541, "u": 10109429839825, "pu": 10109429836438, "b": [["1000.00", "28.692"], ["5000.00", "101.418"], ["7049.60", "0.056"], ["20195.20", "1.200"], ["20295.20", "1.800"], ["66953.90", "0.005"], ["69085.30", "0.900"], ["69462.00", "0.934"], ["69790.20", "6.454"], ["70142.70", "0.343"], ["70325.30", "5.849"], ["70364.00", "0.537"], ["70409.90", "0.608"], ["70416.10", "0.000"], ["70447.80", "0.070"], ["70447.90", "0.003"], ["70464.10", "0.159"], ["70484.60", "0.002"], ["70487.60", "0.016"], ["70488.10", "0.026"], ["70492.20", "0.001"], ["70494.40", "0.002"], ["70495.20", "10.437"]], "a": [["70495.30", "0.422"], ["70502.80", "0.058"], ["70505.90", "0.009"], ["70518.50", "0.043"], ["70520.00", "0.916"], ["70541.00", "0.030"], ["70552.50", "0.062"], ["70554.80", "0.089"], ["70586.90", "0.211"], ["70622.60", "0.090"], ["70624.70", "0.196"], ["70627.80", "0.000"], ["70629.80", "0.184"], ["70631.40", "0.355"], ["70631.70", "0.018"], ["70632.50", "0.294"], ["70670.80", "0.000"], ["71059.30", "0.351"], ["71200.30", "3.652"], ["71570.90", "0.000"], ["71905.20", "0.030"], ["74024.50", "0.002"]]}}
{"local_ts": 1773485070620, "server_ts": 1773485069826, "data": {"e": "depthUpdate", "E": 1773485069827, "T": 1773485069826, "s": "BTCUSDT", "U": 10109429878108, "u": 10109429882609, "pu": 10109429878048, "b": [["1000.00", "28.692"], ["5000.00", "101.418"], ["7049.60", "0.056"], ["20095.20", "0.750"], ["20195.20", "2.250"], ["56396.00", "0.002"], ["66943.00", "0.004"], ["66970.50", "0.008"], ["69399.00", "5.045"], ["69726.80", "2.289"], ["69790.20", "6.454"], ["69946.90", "0.000"], ["70142.80", "0.640"], ["70259.10", "0.007"], ["70363.90", "0.739"], ["70402.50", "0.221"], ["70409.60", "1.071"], ["70416.60", "0.289"], ["70438.20", "0.004"], ["70440.80", "0.908"], ["70440.90", "0.095"], ["70442.70", "0.004"], ["70461.50", "0.002"], ["70468.90", "2.013"], ["70484.60", "0.113"], ["70487.60", "0.016"]], "a": [["70495.30", "0.405"], ["70495.40", "0.219"], ["70505.90", "0.009"], ["70507.30", "0.000"], ["70511.10", "0.597"], ["70514.20", "0.002"], ["70519.90", "0.163"], ["70521.40", "0.205"], ["70554.90", "0.358"], ["70578.80", "0.159"], ["70585.80", "0.071"], ["70592.90", "0.074"], ["70631.20", "0.551"], ["70631.30", "0.000"], ["70678.60", "0.271"], ["70718.90", "0.002"], ["71200.20", "0.009"], ["71200.30", "3.652"], ["74053.70", "0.000"]]}}
{"local_ts": 1773485071642, "server_ts": 1773485070848, "data": {"e": "depthUpdate", "E": 1773485070849, "T": 1773485070848, "s": "BTCUSDT", "U": 10109429920815, "u": 10109429924203, "pu": 10109429920741, "b": [["5000.00", "101.398"], ["7049.60", "0.056"], ["19995.20", "0.360"], ["20095.20", "2.590"], ["20195.20", "0.050"], ["33000.00", "3.785"], ["63445.70", "0.002"], ["66957.40", "0.000"], ["69724.00", "1.181"], ["69787.00", "54.076"], ["69790.20", "6.454"], ["69931.20", "5.426"], ["69946.60", "46.795"], ["70100.00", "48.221"], ["70142.80", "0.644"], ["70249.00", "0.030"], ["70421.80", "0.067"], ["70447.40", "0.006"], ["70447.60", "0.326"], ["70459.60", "0.843"], ["70460.30", "0.045"], ["70465.70", "0.330"], ["70484.60", "0.113"], ["70484.90", "0.640"], ["70485.40", "0.114"], ["70487.50", "0.330"]], "a": [["70495.30", "0.392"], ["70498.10", "0.018"], ["70505.90", "0.009"], ["70530.50", "0.087"], ["70559.00", "0.033"], ["70719.00", "0.107"], ["71055.40", "0.000"], ["71200.30", "4.353"], ["71430.30", "66.465"], ["71501.40", "0.699"], ["71517.50", "9.081"], ["71905.20", "0.036"], ["74026.00", "0.007"], ["77544.80", "0.002"]]}}
{"local_ts": 1773485072661, "server_ts": 1773485071868, "data": {"e": "depthUpdate", "E": 1773485071869, "T": 1773485071868, "s": "BTCUSDT", "U": 10109429980250, "u": 10109429984631, "pu": 10109429980199, "b": [["1000.00", "28.692"], ["5000.00", "101.418"], ["7050.00", "0.453"], ["19995.20", "1.860"], ["19999.90", "0.580"], ["20095.20", "0.330"], ["20399.90", "0.190"], ["63449.90", "0.002"], ["63571.00", "0.002"], ["66310.50", "0.002"], ["69473.10", "6.951"], ["69794.90", "0.042"], ["70142.70", "0.379"], ["70147.40", "0.000"], ["70330.80", "0.089"], ["70358.90", "0.829"], ["70362.40", "0.002"], ["70448.50", "0.000"], ["70449.30", "8.523"], ["70451.60", "0.313"], ["70451.90", "0.118"], ["70478.00", "0.014"], ["70481.50", "0.004"], ["70482.30", "0.315"], ["70489.30", "0.000"], ["70490.40", "0.004"], ["70490.70", "0.003"], ["70492.20", "0.284"], ["70492.60", "0.004"], ["70492.80", "0.057"], ["70492.90", "0.061"], ["70493.70", "0.003"], ["70494.50", "0.017"], ["70494.60", "0.004"], ["70495.20", "0.670"], ["70496.90", "0.003"], ["70497.00", "1.435"], ["70497.70", "0.020"], ["70498.20", "0.000"], ["70499.20", "0.005"], ["70499.30", "0.074"], ["70499.80", "0.014"], ["70499.90", "12.223"]], "a": [["70500.00", "0.772"], ["70500.20", "0.002"], ["70500.60", "0.002"], ["70503.20", "0.001"], ["70503.90", "0.005"], ["70505.60", "0.002"], ["70507.60", "0.399"], ["70508.70", "0.025"], ["70510.10", "1.548"], ["70510.60", "0.003"], ["70510.90", "0.058"], ["70511.00", "0.161"], ["70511.30", "0.081"], ["70511.40", "0.026"], ["70513.60", "0.345"], ["70514.20", "0.002"], ["70521.20", "0.004"], ["70522.10", "0.030"], ["70524.70", "0.139"], ["70526.50", "0.087"], ["70526.70", "0.000"], ["70536.50", "0.002"], ["70543.20", "0.167"], ["70546.80", "0.005"], ["70549.80", "0.042"], ["70553.50", "0.300"], ["70554.60", "0.170"], ["70557.30", "0.160"], ["70559.70", "0.000"], ["70561.60", "0.042"], ["70566.50", "8.790"], ["70567.20", "2.238"], ["70568.60", "0.003"], ["70571.50", "0.050"], ["70599.00", "0.088"], ["70605.20", "0.000"], ["70610.30", "0.086"], ["70611.30", "0.000"], ["70615.40", "0.571"], ["70619.30", "0.092"], ["70620.30", "0.000"], ["70628.80", "0.086"], ["70648.70", "0.001"], ["70652.00", "0.049"], ["70662.70", "0.017"], ["70750.70", "0.000"], ["71205.00", "0.002"], ["71818.40", "0.556"], ["71905.20", "0.033"], ["74029.90", "0.004"], ["74034.10", "0.000"], ["77550.00", "0.081"]]}}
{"local_ts": 1773485073685, "server_ts": 1773485072892, "data": {"e": "depthUpdate", "E": 1773485072893, "T": 1773485072892, "s": "BTCUSDT", "U": 10109430019190, "u": 10109430022847, "pu": 10109430019048, "b": [["5000.00", "101.418"], ["7050.00", "0.453"], ["19995.20", "0.630"], ["20299.90", "0.050"], ["20399.90", "2.320"], ["33000.00", "3.789"], ["63449.90", "0.002"], ["66955.30", "0.002"], ["66959.00", "0.002"], ["68728.90", "0.004"], ["69418.70", "1.439"], ["69473.00", "12.647"], ["69794.90", "0.042"], ["70033.00", "0.024"], ["70147.40", "0.000"], ["70394.60", "0.101"], ["70394.90", "0.761"], ["70447.00", "0.002"], ["70452.00", "0.382"], ["70452.20", "0.008"], ["70465.90", "0.000"], ["70497.80", "0.002"]], "a": [["70517.60", "0.149"], ["70520.70", "0.025"], ["70587.40", "0.019"], ["70587.80", "0.511"], ["70676.20", "0.175"], ["71205.00", "0.002"], ["71353.00", "0.000"], ["71513.80", "8.378"], ["71522.20", "7.527"], ["71619.60", "0.976"], ["71663.20", "2.956"], ["72615.00", "0.005"], ["77550.00", "0.081"]]}}
{"local_ts": 1773485074709, "server_ts": 1773485073912, "data": {"e": "depthUpdate", "E": 1773485073915, "T": 1773485073912, "s": "BTCUSDT", "U": 10109430061352, "u": 10109430065979, "pu": 10109430061202, "b": [["1000.00", "28.692"], ["5000.00", "101.418"], ["7050.00", "0.453"], ["20299.90", "1.970"], ["20399.90", "1.030"], ["20400.00", "0.007"], ["63449.90", "0.002"], ["68384.90", "0.000"], ["69794.90", "0.042"], ["70147.40", "0.000"], ["70254.10", "0.000"], ["70288.20", "0.519"], ["70325.10", "0.015"], ["70341.30", "0.000"], ["70404.20", "0.014"], ["70404.30", "0.018"], ["70411.30", "0.000"], ["70411.40", "0.071"], ["70418.30", "0.002"], ["70418.40", "0.071"], ["70444.40", "0.314"], ["70449.20", "0.046"], ["70463.10", "1.843"], ["70465.40", "0.004"], ["70487.60", "0.304"], ["70489.30", "0.000"], ["70491.70", "1.251"], ["70492.50", "0.000"], ["70499.80", "0.067"]], "a": [["70500.00", "0.703"], ["70503.00", "0.004"], ["70505.80", "0.001"], ["70510.20", "0.076"], ["70510.60", "0.103"], ["70511.40", "0.024"], ["70513.80", "0.005"], ["70516.80", "0.002"], ["70517.60", "0.010"], ["70518.70", "0.079"], ["70520.30", "0.009"], ["70520.90", "0.006"], ["70521.40", "0.203"], ["70525.00", "2.110"], ["70525.10", "1.356"], ["70525.60", "0.067"], ["70527.90", "1.201"], ["70531.00", "0.047"], ["70538.30", "0.007"], ["70550.00", "0.462"], ["70556.40", "0.145"], ["70580.60", "0.259"], ["70587.60", "0.071"], ["70594.70", "0.071"], ["70668.50", "0.619"], ["70669.70", "0.000"], ["70707.20", "0.000"], ["71205.00", "0.002"], ["74050.60", "0.003"], ["77550.00", "0.081"]]}}
{"local_ts": 1773485075739, "server_ts": 1773485074938, "data": {"e": "depthUpdate", "E": 1773485074939, "T": 1773485074938, "s": "BTCUSDT", "U": 10109430139971, "u": 10109430144982, "pu": 10109430139948, "b": [["1000.00", "28.692"], ["5000.00", "101.418"], ["7050.00", "0.425"], ["20199.90", "1.530"], ["20299.90", "1.470"], ["33000.00", "3.789"], ["56400.00", "6.998"], ["63449.90", "0.000"], ["69794.90", "0.042"], ["69795.10", "0.002"], ["70253.80", "0.004"], ["70341.30", "0.000"], ["70452.10", "0.005"], ["70452.20", "0.006"], ["70487.40", "0.002"], ["70489.00", "0.660"], ["70489.50", "0.515"], ["70489.60", "0.518"], ["70490.80", "0.063"], ["70493.70", "0.005"], ["70495.80", "0.003"], ["70499.90", "11.666"]], "a": [["70500.70", "0.000"], ["70507.50", "0.065"], ["70513.50", "0.855"], ["70513.60", "0.003"], ["70514.70", "0.000"], ["70518.50", "1.066"], ["70518.60", "0.002"], ["70525.00", "1.473"], ["70526.10", "0.078"], ["70566.30", "0.010"], ["70676.20", "0.175"], ["70723.90", "0.000"], ["71204.90", "2.111"], ["71205.00", "0.004"], ["71493.90", "0.559"], ["74027.20", "0.002"], ["74039.10", "0.062"], ["77550.00", "0.079"], ["89523.20", "0.000"]]}}
{"local_ts": 1773485076756, "server_ts": 1773485075960, "data": {"e": "depthUpdate", "E": 1773485075961, "T": 1773485075960, "s": "BTCUSDT", "U": 10109430187994, "u": 10109430193978, "pu": 10109430187890, "b": [["5000.00", "101.418"], ["7050.00", "0.425"], ["20099.90", "1.090"], ["20199.90", "1.910"], ["63449.90", "0.000"], ["69794.90", "0.042"], ["70147.40", "0.000"], ["70322.20", "0.000"], ["70325.00", "0.044"], ["70336.10", "0.179"], ["70341.00", "0.392"], ["70341.30", "0.039"], ["70404.30", "0.000"], ["70410.10", "0.200"], ["70411.40", "0.000"], ["70417.20", "0.162"], ["70418.40", "0.000"], ["70424.20", "0.092"], ["70430.00", "10.565"], ["70431.20", "0.139"], ["70431.50", "0.022"], ["70444.00", "0.030"], ["70450.70", "0.004"], ["70452.50", "0.513"], ["70452.60", "0.681"], ["70455.50", "0.000"], ["70458.50", "0.009"], ["70459.20", "0.006"], ["70459.30", "0.062"], ["70462.20", "0.069"], ["70465.70", "0.322"], ["70468.80", "1.075"], ["70474.70", "0.248"], ["70476.30", "0.052"], ["70476.90", "0.063"], ["70477.20", "0.010"], ["70477.80", "0.000"], ["70481.40", "0.735"], ["70482.00", "0.512"], ["70482.70", "0.001"], ["70483.40", "0.001"], ["70490.80", "0.060"], ["70490.90", "0.640"], ["70491.40", "0.020"], ["70492.20", "0.005"], ["70493.70", "0.005"], ["70494.00", "0.015"], ["70494.80", "0.017"], ["70495.70", "0.236"], ["70496.40", "0.001"], ["70498.50", "0.069"], ["70499.90", "11.486"]], "a": [["70500.70", "0.002"], ["70506.00", "0.010"], ["70508.50", "0.103"], ["70508.80", "0.002"], ["70509.10", "0.003"], ["70509.20", "0.002"], ["70509.40", "0.006"], ["70509.90", "0.000"], ["70510.40", "0.010"], ["70510.60", "0.091"], ["70510.90", "0.129"], ["70513.40", "0.001"], ["70513.70", "0.255"], ["70514.40", "0.149"], ["70517.60", "0.010"], ["70518.00", "0.010"], ["70518.80", "0.488"], ["70521.70", "0.002"], ["70522.60", "0.011"], ["70523.00", "0.035"], ["70524.10", "0.035"], ["70525.60", "0.000"], ["70526.20", "0.516"], ["70526.70", "0.722"], ["70527.40", "0.000"], ["70527.50", "0.002"], ["70528.80", "0.070"], ["70529.10", "0.002"], ["70529.20", "0.002"], ["70529.30", "0.080"], ["70529.50", "0.340"], ["70530.00", "0.154"], ["70530.40", "0.014"], ["70531.30", "0.005"], ["70532.20", "0.038"], ["70533.20", "0.027"], ["70534.40", "0.255"], ["70545.10", "0.858"], ["70553.10", "0.577"], ["70566.50", "0.287"], ["70566.90", "8.503"], ["70567.00", "0.073"], ["70567.20", "2.314"], ["70580.60", "0.188"], ["70587.20", "0.312"], ["70587.60", "0.000"], ["70594.20", "0.071"], ["70594.70", "0.000"], ["70601.30", "0.290"], ["70602.40", "0.053"], ["70610.00", "0.101"], ["70612.90", "0.000"], ["70613.00", "0.086"], ["70613.40", "0.133"], ["70614.40", "0.678"], ["70626.00", "0.063"], ["71205.00", "1.404"], ["71786.20", "0.600"], ["72632.80", "0.000"], ["74051.60", "0.000"], ["77550.00", "0.079"], ["89523.20", "0.000"]]}}
{"local_ts": 1773485077785, "server_ts": 1773485076988, "data": {"e": "depthUpdate", "E": 1773485076989, "T": 1773485076988, "s": "BTCUSDT", "U": 10109430246537, "u": 10109430250337, "pu": 10109430246455, "b": [["1000.00", "28.692"], ["5000.00", "101.418"], ["7050.00", "0.425"], ["19999.90", "0.650"], ["20099.90", "2.350"], ["20199.90", "0.000"], ["63449.90", "0.000"], ["66958.50", "0.012"], ["67680.00", "0.045"], ["69482.30", "0.719"], ["70072.80", "0.000"], ["70147.40", "0.000"], ["70178.00", "0.000"], ["70255.30", "0.002"], ["70285.30", "0.006"], ["70341.30", "0.000"], ["70409.90", "0.626"], ["70410.00", "0.016"], ["70417.00", "0.071"], ["70417.10", "0.063"], ["70424.00", "0.078"], ["70424.10", "0.000"], ["70465.00", "0.042"], ["70472.70", "0.072"], ["70474.70", "0.248"], ["70478.60", "0.000"], ["70479.30", "0.002"], ["70480.80", "0.072"], ["70481.50", "0.514"], ["70487.80", "0.006"], ["70489.80", "0.642"], ["70492.20", "0.012"], ["70492.60", "0.007"]], "a": [["70510.60", "0.091"], ["70514.10", "0.004"], ["70519.60", "0.046"], ["70523.60", "0.003"], ["70523.90", "0.003"], ["70525.20", "1.155"], ["70525.50", "0.087"], ["70525.80", "0.035"], ["70528.50", "0.009"], ["70529.70", "0.250"], ["70586.50", "0.071"], ["70586.90", "0.000"], ["70593.50", "0.073"], ["70593.90", "0.003"], ["70600.60", "0.075"], ["70601.00", "0.009"], ["70723.60", "0.007"], ["70739.10", "4.202"], ["70741.20", "0.028"], ["70815.90", "1.109"], ["70817.20", "0.000"], ["70819.00", "0.000"], ["70841.90", "0.211"], ["70925.20", "0.009"], ["71205.00", "1.404"], ["71414.50", "17.741"], ["71416.50", "3.767"], ["74028.40", "0.002"], ["77550.00", "0.079"], ["89523.20", "0.000"]]}}
{"local_ts": 1773485078802, "server_ts": 1773485078008, "data": {"e": "depthUpdate", "E": 1773485078009, "T": 1773485078008, "s": "BTCUSDT", "U": 10109430291239, "u": 10109430295594, "pu": 10109430291213, "b": [["5000.00", "101.418"], ["7050.00", "0.481"], ["19999.90", "2.590"], ["20099.90", "0.100"], ["20399.90", "0.310"], ["56400.00", "7.122"], ["63449.90", "0.000"], ["69407.20", "2.007"], ["69413.60", "0.002"], ["69794.90", "0.042"], ["69830.20", "2.137"], ["70397.20", "0.115"], ["70397.50", "0.098"], ["70398.60", "0.667"], ["70444.40", "0.310"], ["70445.20", "1.137"], ["70488.80", "0.032"], ["70490.40", "0.000"], ["70492.90", "0.009"]], "a": [["70503.40", "0.001"], ["70508.60", "0.057"], ["70510.60", "0.094"], ["70517.40", "0.006"], ["70517.60", "0.164"], ["70518.70", "1.072"], ["70518.80", "0.505"], ["70522.40", "0.018"], ["70523.40", "0.005"], ["70723.70", "2.002"], ["74042.80", "0.003"], ["77550.00", "0.079"], ["89523.20", "0.000"]]}}
{"local_ts": 1773485079824, "server_ts": 1773485079028, "data": {"e": "depthUpdate", "E": 1773485079031, "T": 1773485079028, "s": "BTCUSDT", "U": 10109430342673, "u": 10109430349616, "pu": 10109430342557, "b": [["1000.00", "28.692"], ["5000.00", "101.418"], ["7050.00", "0.481"], ["19999.90", "0.400"], ["20299.90", "0.160"], ["20399.90", "2.440"], ["63381.10", "0.000"], ["63449.90", "0.000"], ["66953.70", "0.002"], ["69494.00", "0.719"], ["69794.90", "0.042"], ["69795.00", "0.099"], ["70147.40", "0.000"], ["70253.80", "0.000"], ["70254.00", "0.077"], ["70409.50", "0.018"], ["70409.70", "0.000"], ["70416.60", "0.289"], ["70416.80", "0.202"], ["70423.60", "0.911"], ["70423.80", "0.089"], ["70446.70", "0.014"], ["70452.40", "0.846"], ["70452.50", "0.513"], ["70455.90", "0.007"], ["70459.90", "0.209"]], "a": [["70505.60", "0.017"], ["70510.60", "0.094"], ["70511.90", "0.049"], ["70512.00", "0.002"], ["70513.40", "0.075"], ["70513.50", "1.420"], ["70514.70", "0.025"], ["70521.50", "0.058"], ["70522.10", "0.029"], ["70523.40", "0.003"], ["70524.70", "0.080"], ["70524.80", "0.002"], ["70531.50", "0.006"], ["70540.00", "0.019"], ["70542.30", "0.101"], ["70585.90", "0.214"], ["70586.10", "0.250"], ["70592.90", "0.074"], ["70593.10", "0.234"], ["70600.00", "8.018"], ["70600.20", "2.242"], ["70826.60", "5.160"], ["70849.30", "0.000"], ["70849.70", "0.009"], ["71028.70", "0.703"], ["71055.70", "0.000"], ["71197.30", "0.011"], ["71205.00", "1.544"], ["71480.00", "1.512"], ["77550.00", "0.079"], ["89523.20", "0.000"]]}}
{"local_ts": 1773485080851, "server_ts": 1773485080050, "data": {"e": "depthUpdate", "E": 1773485080051, "T": 1773485080050, "s": "BTCUSDT", "U": 10109430404001, "u": 10109430409588, "pu": 10109430403953, "b": [["1000.00", "28.692"], ["5000.00", "101.418"], ["7050.00", "0.481"], ["20199.90", "0.010"], ["20299.90", "2.290"], ["20399.90", "0.700"], ["33000.00", "3.785"], ["66974.00", "0.000"], ["68790.70", "1.244"], ["69266.20", "3.442"], ["69336.70", "5.100"], ["69530.60", "0.291"], ["69552.70", "0.000"], ["69794.90", "0.042"], ["69795.00", "0.099"], ["70253.80", "0.004"], ["70409.40", "0.018"], ["70416.50", "0.103"], ["70423.50", "0.200"], ["70482.10", "0.057"], ["70487.20", "0.004"], ["70490.30", "0.004"], ["70499.90", "10.656"]], "a": [["70503.00", "0.027"], ["70510.60", "0.094"], ["70512.70", "0.006"], ["70520.00", "0.029"], ["70529.20", "0.004"], ["70531.50", "0.004"], ["70532.20", "0.686"], ["70567.40", "0.720"], ["70585.80", "0.107"], ["70592.80", "1.481"], ["70599.90", "0.092"], ["70676.20", "0.016"], ["71205.00", "1.544"], ["71522.20", "8.658"], ["71628.00", "3.906"], ["71717.40", "0.696"], ["74032.00", "0.007"], ["74043.20", "0.000"], ["89523.20", "0.000"]]}}
{"local_ts": 1773485081865, "server_ts": 1773485081069, "data": {"e": "depthUpdate", "E": 1773485081073, "T": 1773485081069, "s": "BTCUSDT", "U": 10109430458386, "u": 10109430464053, "pu": 10109430458198, "b": [["5000.00", "101.418"], ["7050.00", "0.453"], ["20199.90", "1.860"], ["20299.90", "1.140"], ["66967.10", "0.002"], ["69794.90", "0.042"], ["69927.80", "0.000"], ["70353.30", "0.000"], ["70353.50", "2.988"], ["70368.40", "0.628"], ["70447.30", "0.926"], ["70452.40", "0.846"], ["70452.50", "0.513"], ["70487.20", "0.000"], ["70489.30", "0.197"], ["70492.10", "0.521"], ["70495.20", "0.646"], ["70499.90", "10.817"]], "a": [["70505.50", "0.004"], ["70506.20", "0.001"], ["70506.30", "0.000"], ["70507.40", "0.056"], ["70510.60", "0.013"], ["70512.70", "0.003"], ["70514.10", "0.097"], ["70522.60", "0.009"], ["70522.80", "0.518"], ["70522.90", "1.259"], ["70527.00", "0.004"], ["70529.20", "0.002"], ["70538.80", "1.167"], ["70544.10", "0.085"], ["70545.00", "1.577"], ["70633.80", "0.569"], ["70723.70", "2.009"], ["70824.20", "0.000"], ["71205.00", "1.544"], ["74029.30", "0.000"], ["89523.20", "0.000"]]}}
{"local_ts": 1773485082887, "server_ts": 1773485082092, "data": {"e": "depthUpdate", "E": 1773485082093, "T": 1773485082092, "s": "BTCUSDT", "U": 10109430551053, "u": 10109430555864, "pu": 10109430550901, "b": [["1000.00", "28.692"], ["5000.00", "101.418"], ["7050.60", "0.028"], ["20105.90", "1.420"], ["20199.90", "1.310"], ["20205.90", "0.240"], ["33000.00", "3.789"], ["56400.00", "6.994"], ["66953.80", "0.002"], ["66974.90", "0.004"], ["66975.00", "0.092"], ["69800.80", "0.000"], ["70153.40", "0.000"], ["70333.20", "0.000"], ["70336.70", "0.159"], ["70356.50", "3.051"], ["70374.40", "0.003"], ["70380.10", "0.319"], ["70403.10", "0.007"], ["70404.80", "0.000"], ["70409.20", "0.885"], ["70409.30", "0.718"], ["70415.40", "0.435"], ["70416.20", "0.176"], ["70416.30", "0.635"], ["70423.30", "1.066"], ["70423.40", "0.158"], ["70426.50", "2.066"], ["70431.90", "0.248"], ["70436.80", "0.505"], ["70440.10", "0.781"], ["70450.70", "0.007"], ["70455.80", "0.005"], ["70456.20", "1.106"], ["70457.00", "1.855"], ["70457.10", "0.085"], ["70460.40", "0.002"], ["70463.20", "0.842"], ["70463.30", "0.130"], ["70467.50", "0.000"], ["70474.60", "1.582"], ["70480.10", "0.074"], ["70480.20", "0.345"], ["70481.70", "1.251"], ["70493.20", "0.010"], ["70495.90", "0.003"], ["70498.80", "0.009"], ["70500.60", "0.598"], ["70500.90", "0.497"], ["70502.50", "0.003"], ["70502.90", "0.010"], ["70503.30", "0.000"]], "a": [["70506.00", "2.822"], ["70507.80", "0.007"], ["70512.90", "0.002"], ["70513.00", "0.001"], ["70514.70", "0.627"], ["70518.70", "0.006"], ["70519.80", "0.003"], ["70523.70", "0.010"], ["70524.30", "0.009"], ["70525.40", "0.025"], ["70525.80", "0.032"], ["70526.70", "0.320"], ["70526.90", "0.000"], ["70527.00", "0.002"], ["70530.30", "0.028"], ["70530.70", "0.288"], ["70531.40", "0.119"], ["70535.80", "0.056"], ["70538.50", "0.139"], ["70539.00", "0.007"], ["70544.60", "0.274"], ["70544.80", "1.986"], ["70545.60", "0.051"], ["70546.10", "0.671"], ["70550.40", "0.307"], ["70552.70", "0.000"], ["70556.50", "0.005"], ["70559.80", "0.002"], ["70561.10", "0.005"], ["70563.70", "0.042"], ["70563.80", "0.000"], ["70570.80", "1.854"], ["70585.60", "0.163"], ["70585.70", "0.434"], ["70587.70", "0.008"], ["70592.70", "0.076"], ["70595.80", "0.140"], ["70596.40", "0.003"], ["70599.70", "0.089"], ["70621.00", "0.085"], ["70631.70", "0.021"], ["70686.00", "2.705"], ["71211.10", "0.000"], ["71598.70", "0.349"], ["71705.10", "0.003"], ["73255.60", "1.077"], ["74043.50", "0.000"], ["89523.20", "0.000"]]}}
{"local_ts": 1773485083915, "server_ts": 1773485083120, "data": {"e": "depthUpdate", "E": 1773485083121, "T": 1773485083120, "s": "BTCUSDT", "U": 10109430598258, "u": 10109430601316, "pu": 10109430598215, "b": [["5000.00", "101.418"], ["7050.60", "0.028"], ["20005.90", "0.990"], ["20105.90", "2.010"], ["70260.10", "0.256"], ["70262.30", "2.723"], ["70333.20", "0.000"], ["70336.70", "0.159"], ["70353.30", "1.113"], ["70381.50", "0.695"], ["70406.00", "0.042"], ["70406.30", "0.041"], ["70407.50", "0.132"], ["70416.30", "1.674"], ["70450.00", "0.105"], ["70450.50", "1.282"], ["70457.10", "0.085"], ["70460.40", "0.840"], ["70467.50", "0.838"], ["70474.60", "2.420"], ["70475.90", "0.975"], ["70481.70", "2.089"], ["70493.20", "0.002"], ["70498.80", "0.007"], ["70499.90", "0.014"], ["70500.70", "0.034"], ["70501.10", "0.206"], ["70503.20", "0.002"]], "a": [["70512.90", "0.000"], ["70514.70", "0.079"], ["70518.70", "0.348"], ["70524.30", "0.847"], ["70525.10", "0.570"], ["70526.70", "0.000"], ["70530.70", "0.203"], ["70531.40", "0.957"], ["70538.50", "0.977"], ["70544.60", "0.090"], ["70544.80", "1.926"], ["70545.60", "0.889"], ["70552.70", "0.838"], ["70559.80", "0.840"], ["70561.10", "0.546"], ["71211.10", "0.002"], ["71416.50", "3.774"], ["71616.00", "0.742"], ["71751.80", "2.208"], ["74043.40", "0.002"], ["89523.20", "0.000"]]}}
{"local_ts": 1773485084937, "server_ts": 1773485084144, "data": {"e": "depthUpdate", "E": 1773485084145, "T": 1773485084144, "s": "BTCUSDT", "U": 10109430634616, "u": 10109430637483, "pu": 10109430634511, "b": [["1000.00", "28.692"], ["5000.00", "101.418"], ["7050.60", "0.000"], ["20005.90", "2.450"], ["20105.90", "0.000"], ["20405.90", "0.550"], ["66948.00", "0.002"], ["66973.50", "0.000"], ["66980.20", "0.004"], ["70153.40", "0.000"], ["70264.70", "4.254"], ["70409.30", "0.700"], ["70409.40", "0.018"], ["70416.30", "1.603"], ["70416.40", "1.026"], ["70423.40", "0.087"], ["70423.50", "0.200"], ["70433.80", "0.957"], ["70457.50", "0.002"], ["70457.60", "0.019"], ["70463.70", "0.000"], ["70463.80", "0.066"], ["70470.70", "0.139"], ["70479.30", "0.250"], ["70484.80", "0.286"], ["70485.70", "0.000"], ["70493.20", "0.002"], ["70498.30", "0.051"], ["70499.60", "0.015"]], "a": [["70510.10", "0.130"], ["70514.70", "0.079"], ["70518.70", "0.348"], ["70539.40", "0.503"], ["70544.50", "0.142"], ["70544.60", "0.274"], ["70563.90", "1.191"], ["70585.70", "0.505"], ["70592.80", "1.481"], ["70599.80", "0.610"], ["70829.70", "5.570"], ["71211.10", "0.000"], ["89523.20", "0.000"]]}}
{"local_ts": 1773485085960, "server_ts": 1773485085164, "data": {"e": "depthUpdate", "E": 1773485085167, "T": 1773485085164, "s": "BTCUSDT", "U": 10109430671210, "u": 10109430674693, "pu": 10109430670973, "b": [["1000.00", "28.692"], ["5000.00", "101.438"], ["7050.60", "0.000"], ["20005.90", "0.170"], ["20305.90", "0.270"], ["20405.90", "2.560"], ["56405.00", "0.000"], ["66965.80", "0.000"], ["69800.80", "0.000"], ["70260.20", "0.004"], ["70332.90", "0.469"], ["70374.30", "1.983"], ["70409.40", "0.018"], ["70416.40", "1.026"], ["70423.50", "0.200"], ["70457.50", "0.002"], ["70457.70", "0.026"], ["70476.90", "0.057"], ["70479.30", "0.002"], ["70479.80", "0.250"], ["70482.10", "0.052"], ["70483.40", "0.001"], ["70484.10", "0.003"], ["70484.90", "0.142"], ["70485.70", "0.007"], ["70485.90", "0.344"], ["70486.60", "0.008"], ["70487.50", "0.000"], ["70497.30", "0.021"], ["70498.60", "0.056"], ["70499.80", "0.041"], ["70500.30", "0.000"], ["70501.30", "0.343"]], "a": [["70510.80", "0.000"], ["70512.30", "0.021"], ["70512.90", "0.057"], ["70514.70", "0.602"], ["70544.60", "0.189"], ["70549.60", "0.624"], ["70578.10", "0.678"], ["70579.00", "0.323"], ["70585.70", "0.434"], ["70585.80", "0.071"], ["70592.80", "1.410"], ["70592.90", "0.074"], ["70599.80", "0.539"], ["70599.90", "0.092"], ["70638.50", "0.628"], ["70678.70", "0.499"], ["70826.70", "0.044"], ["71211.10", "0.000"], ["71810.40", "1.059"], ["89523.20", "0.000"]]}}
{"local_ts": 1773485086982, "server_ts": 1773485086188, "data": {"e": "depthUpdate", "E": 1773485086189, "T": 1773485086188, "s": "BTCUSDT", "U": 10109430707033, "u": 10109430710898, "pu": 10109430706984, "b": [["5000.00", "101.418"], ["7050.60", "0.000"], ["20205.90", "0.120"], ["20305.90", "2.410"], ["20405.90", "0.470"], ["69525.90", "2.512"], ["69800.80", "0.000"], ["70220.20", "0.000"], ["70304.90", "1.745"], ["70409.40", "0.000"], ["70409.50", "0.018"], ["70416.40", "0.955"], ["70416.50", "0.103"], ["70423.50", "0.129"], ["70423.60", "0.911"], ["70431.90", "0.200"], ["70446.90", "0.008"], ["70457.10", "0.085"], ["70457.80", "0.009"], ["70457.90", "0.013"], ["70464.30", "0.062"], ["70464.90", "0.009"], ["70466.90", "0.008"], ["70474.00", "0.858"], ["70481.00", "0.017"], ["70482.20", "0.335"], ["70492.10", "0.533"], ["70492.30", "0.002"], ["70495.10", "0.012"], ["70495.70", "0.010"], ["70496.70", "0.004"], ["70498.40", "0.000"], ["70498.80", "0.007"], ["70499.80", "0.041"], ["70500.00", "59.653"], ["70500.20", "1.067"], ["70500.30", "0.000"], ["70500.50", "0.122"], ["70500.60", "0.702"], ["70500.90", "0.497"], ["70501.30", "0.343"], ["70501.60", "0.000"], ["70501.80", "0.000"], ["70502.40", "0.608"], ["70503.20", "0.012"], ["70504.20", "0.000"], ["70505.80", "0.104"], ["70505.90", "8.665"]], "a": [["70506.00", "2.527"], ["70506.20", "0.002"], ["70506.40", "0.000"], ["70507.00", "0.008"], ["70509.50", "0.002"], ["70512.90", "0.000"], ["70513.50", "0.002"], ["70516.60", "0.005"], ["70544.80", "1.986"], ["70545.40", "0.369"], ["70546.40", "0.002"], ["70547.00", "0.014"], ["70570.50", "0.005"], ["70574.60", "0.518"], ["70585.80", "0.071"], ["70592.90", "0.074"], ["70599.90", "0.092"], ["71211.10", "0.000"], ["71542.40", "0.807"], ["71913.90", "1.670"], ["74046.00", "1.451"], ["89523.20", "0.000"]]}}
{"local_ts": 1773485088008, "server_ts": 1773485087212, "data": {"e": "depthUpdate", "E": 1773485087213, "T": 1773485087212, "s": "BTCUSDT", "U": 10109430787868, "u": 10109430790444, "pu": 10109430787831, "b": [["1000.00", "28.692"], ["5000.00", "101.418"], ["7050.80", "0.056"], ["20207.70", "1.280"], ["20305.90", "0.780"], ["20306.00", "0.007"], ["66960.10", "0.000"], ["69570.40", "0.718"], ["69802.60", "0.000"], ["70262.00", "0.002"], ["70409.50", "0.000"], ["70414.40", "0.536"], ["70416.50", "0.032"], ["70421.40", "0.585"], ["70423.60", "0.982"], ["70428.50", "0.473"], ["70458.70", "0.150"], ["70458.80", "0.324"], ["70474.50", "0.018"], ["70474.60", "1.582"], ["70475.20", "0.009"], ["70475.30", "0.012"], ["70475.60", "0.035"], ["70495.30", "0.018"], ["70499.80", "0.015"], ["70503.50", "0.141"], ["70506.50", "0.000"], ["70507.10", "0.002"]], "a": [["70507.80", "3.126"], ["70511.10", "0.057"], ["70515.50", "0.002"], ["70526.80", "0.014"], ["70528.00", "0.217"], ["70542.50", "0.206"], ["70543.10", "1.069"], ["70545.40", "0.367"], ["70585.80", "0.000"], ["70590.80", "0.342"], ["70592.90", "0.003"], ["70597.90", "0.073"], ["70599.90", "0.021"], ["70605.00", "0.197"], ["70642.20", "0.006"], ["70679.00", "0.000"], ["70809.90", "0.054"], ["70810.50", "0.005"], ["70847.80", "0.075"], ["71212.90", "0.000"], ["71473.80", "0.279"], ["71642.00", "0.000"], ["74049.70", "0.002"], ["89523.20", "0.000"]]}}
{"local_ts": 1773485089029, "server_ts": 1773485088236, "data": {"e": "depthUpdate", "E": 1773485088237, "T": 1773485088236, "s": "BTCUSDT", "U": 10109430813460, "u": 10109430816293, "pu": 10109430813403, "b": [["5000.00", "101.418"], ["7050.80", "0.056"], ["20107.70", "1.780"], ["20205.90", "0.200"], ["20207.70", "1.020"], ["66973.60", "0.007"], ["67687.40", "0.004"], ["68741.80", "0.005"], ["69802.60", "0.000"], ["70261.90", "0.029"], ["70338.50", "0.099"], ["70414.10", "0.115"], ["70414.40", "0.518"], ["70421.10", "0.201"], ["70421.40", "0.514"], ["70428.20", "0.146"], ["70428.50", "0.402"], ["70458.60", "0.020"], ["70458.80", "0.326"], ["70474.50", "0.027"], ["70474.60", "1.591"], ["70475.20", "0.000"], ["70475.30", "0.003"], ["70477.90", "0.015"], ["70483.60", "0.006"], ["70489.50", "0.515"], ["70491.20", "0.312"], ["70494.60", "0.009"], ["70495.50", "0.014"], ["70500.30", "0.284"], ["70500.60", "0.893"], ["70503.40", "0.008"], ["70507.70", "3.848"]], "a": [["70507.80", "4.092"], ["70508.30", "0.002"], ["70508.40", "0.000"], ["70508.50", "0.000"], ["70508.60", "0.000"], ["70511.10", "0.254"], ["70514.40", "1.420"], ["70514.50", "0.101"], ["70515.00", "0.002"], ["70522.60", "0.102"], ["70528.50", "0.004"], ["70535.80", "0.006"], ["70542.50", "0.204"], ["70546.10", "0.929"], ["70546.80", "1.788"], ["70590.80", "0.342"], ["70597.90", "0.073"], ["70604.90", "0.154"], ["70605.00", "0.126"], ["71063.60", "0.112"], ["71212.90", "0.000"], ["71249.90", "3.243"], ["71659.70", "0.025"], ["71872.80", "0.011"]]}}
{"local_ts": 1773485090050, "server_ts": 1773485089256, "data": {"e": "depthUpdate", "E": 1773485089259, "T": 1773485089256, "s": "BTCUSDT", "U": 10109430844100, "u": 10109430846947, "pu": 10109430844011, "b": [["1000.00", "28.692"], ["5000.00", "101.418"], ["7050.80", "0.056"], ["20007.70", "1.330"], ["20107.70", "1.670"], ["33000.00", "3.785"], ["69802.60", "0.000"], ["70155.20", "0.000"], ["70261.60", "0.003"], ["70411.20", "0.002"], ["70445.10", "0.011"], ["70458.30", "0.527"], ["70459.60", "0.846"], ["70459.70", "0.346"], ["70459.80", "0.156"], ["70465.80", "0.000"], ["70465.90", "0.062"], ["70469.70", "0.004"], ["70485.00", "0.005"], ["70495.50", "0.017"], ["70497.10", "0.005"], ["70503.20", "0.512"], ["70503.30", "0.002"], ["70505.90", "1.024"], ["70507.70", "1.546"]], "a": [["70518.70", "0.003"], ["70518.80", "0.518"], ["70518.90", "0.441"], ["70535.80", "0.006"], ["70536.40", "0.012"], ["70537.30", "0.103"], ["70540.40", "0.006"], ["70542.00", "0.006"], ["70608.40", "0.043"], ["71212.90", "0.000"], ["74036.20", "0.000"]]}}
{"local_ts": 1773485091071, "server_ts": 1773485090277, "data": {"e": "depthUpdate", "E": 1773485090279, "T": 1773485090277, "s": "BTCUSDT", "U": 10109430917604, "u": 10109430921744, "pu": 10109430917586, "b": [["1000.00", "28.692"], ["5000.00", "101.418"], ["7050.60", "0.028"], ["20007.70", "1.010"], ["20405.60", "0.410"], ["68390.70", "0.000"], ["69483.30", "1.007"], ["69640.00", "0.061"], ["69800.50", "0.000"], ["70305.20", "0.002"], ["70431.60", "0.000"], ["70457.20", "0.002"], ["70457.40", "0.017"], ["70458.20", "0.013"], ["70465.10", "0.000"], ["70465.20", "0.068"], ["70469.10", "0.000"], ["70470.40", "0.975"], ["70476.00", "0.015"], ["70477.90", "0.000"], ["70479.10", "0.003"], ["70482.00", "0.016"], ["70482.70", "0.070"], ["70485.40", "0.078"], ["70487.50", "0.015"], ["70488.00", "0.008"], ["70488.40", "0.417"], ["70488.70", "0.003"], ["70489.00", "0.037"], ["70491.40", "0.020"], ["70494.20", "0.006"], ["70495.00", "0.029"], ["70496.30", "0.264"], ["70497.60", "0.022"], ["70499.90", "0.072"], ["70501.50", "0.013"], ["70502.20", "0.116"], ["70502.40", "0.014"], ["70505.50", "0.002"], ["70505.60", "1.397"]], "a": [["70505.70", "9.061"], ["70505.80", "0.523"], ["70505.90", "0.002"], ["70506.00", "0.048"], ["70506.10", "0.065"], ["70507.70", "0.000"], ["70507.90", "0.002"], ["70508.30", "0.007"], ["70509.80", "0.006"], ["70511.50", "0.000"], ["70513.00", "0.008"], ["70513.60", "0.018"], ["70514.60", "0.004"], ["70515.50", "0.006"], ["70515.80", "0.006"], ["70516.30", "0.005"], ["70518.00", "0.046"], ["70524.00", "0.018"], ["70527.40", "0.000"], ["70527.90", "0.120"], ["70528.80", "0.070"], ["70530.60", "0.000"], ["70531.00", "0.045"], ["70532.10", "0.329"], ["70544.50", "1.793"], ["70555.10", "0.000"], ["70556.40", "0.004"], ["70569.20", "0.091"], ["70572.70", "0.081"], ["70577.60", "0.000"], ["70715.90", "0.008"], ["71210.80", "0.000"], ["71872.80", "0.011"], ["71884.70", "0.000"], ["71915.80", "0.008"], ["74045.30", "0.002"], ["74059.10", "0.000"]]}}
{"local_ts": 1773485092093, "server_ts": 1773485091298, "data": {"e": "depthUpdate", "E": 1773485091299, "T": 1773485091298, "s": "BTCUSDT", "U": 10109430953502, "u": 10109430957286, "pu": 10109430953300, "b": [["5000.00", "101.418"], ["7050.40", "0.028"], ["20005.90", "0.010"], ["20303.50", "0.440"], ["20403.50", "1.360"], ["20405.90", "0.020"], ["33000.00", "3.789"], ["66980.40", "0.004"], ["66980.70", "0.002"], ["69649.30", "10.387"], ["69798.50", "0.000"], ["69931.20", "5.426"], ["70257.30", "0.000"], ["70336.00", "2.324"], ["70408.60", "0.018"], ["70415.60", "0.450"], ["70422.70", "0.252"], ["70425.90", "0.616"], ["70430.10", "1.070"], ["70440.00", "0.037"], ["70444.20", "0.002"], ["70464.40", "0.000"], ["70468.90", "2.013"], ["70475.20", "0.054"], ["70487.70", "0.511"], ["70489.30", "0.096"], ["70492.90", "0.554"], ["70495.00", "0.217"], ["70496.60", "0.392"], ["70497.20", "0.008"], ["70498.10", "0.004"], ["70498.40", "0.007"], ["70498.80", "0.017"]], "a": [["70503.60", "5.603"], ["70505.10", "0.028"], ["70505.80", "0.001"], ["70507.10", "0.001"], ["70507.70", "0.412"], ["70508.70", "0.000"], ["70510.30", "0.003"], ["70510.60", "0.000"], ["70511.30", "0.003"], ["70512.30", "0.021"], ["70513.20", "0.207"], ["70514.20", "0.000"], ["70515.20", "0.002"], ["70518.90", "0.384"], ["70527.10", "0.024"], ["70529.10", "0.029"], ["70534.60", "0.000"], ["70534.70", "0.186"], ["70535.90", "0.844"], ["70537.30", "0.070"], ["70537.40", "0.000"], ["70538.60", "0.002"], ["70542.40", "0.243"], ["70544.40", "0.073"], ["70549.90", "0.370"], ["70551.50", "0.061"], ["70567.10", "0.234"], ["70571.30", "0.000"], ["70581.20", "0.021"], ["70585.00", "0.077"], ["70585.40", "0.009"], ["70592.10", "0.078"], ["70599.10", "0.071"], ["70676.30", "0.062"], ["70727.60", "0.000"], ["70899.90", "1.946"], ["71059.30", "0.562"], ["71208.50", "0.000"], ["71208.60", "0.002"], ["71492.90", "0.418"], ["71775.10", "0.382"], ["72629.60", "3.305"], ["72994.20", "0.054"], ["74052.70", "0.002"]]}}
{"local_ts": 1773485093114, "server_ts": 1773485092320, "data": {"e": "depthUpdate", "E": 1773485092323, "T": 1773485092320, "s": "BTCUSDT", "U": 10109430989619, "u": 10109430993214, "pu": 10109430989494, "b": [["1000.00", "28.692"], ["5000.00", "101.418"], ["7050.40", "0.028"], ["20203.50", "0.240"], ["20303.50", "2.510"], ["20403.50", "0.250"], ["69798.50", "0.000"], ["70431.20", "0.202"], ["70460.10", "0.041"], ["70469.50", "0.296"], ["70482.50", "0.002"], ["70498.50", "0.045"], ["70501.70", "0.614"]], "a": [["70503.60", "3.175"], ["70512.10", "0.000"], ["70517.40", "0.040"], ["70517.70", "0.083"], ["70519.20", "0.007"], ["70520.90", "0.103"], ["70521.30", "0.097"], ["70542.40", "0.303"], ["70544.30", "0.269"], ["70727.10", "0.004"], ["71208.50", "0.000"], ["71208.60", "0.002"], ["74029.70", "0.000"], ["74052.70", "0.002"], ["77554.00", "0.008"]]}}
{"local_ts": 1773485094142, "server_ts": 1773485093347, "data": {"e": "depthUpdate", "E": 1773485093349, "T": 1773485093347, "s": "BTCUSDT", "U": 10109431026073, "u": 10109431028489, "pu": 10109431026013, "b": [["5000.00", "101.398"], ["7050.40", "0.000"], ["20103.50", "0.090"], ["20203.50", "2.370"], ["20303.50", "0.540"], ["68732.60", "2.614"], ["69407.30", "0.000"], ["69502.40", "0.286"], ["70351.40", "0.085"], ["70371.60", "0.002"], ["70408.60", "0.018"], ["70415.60", "0.450"], ["70422.70", "0.252"], ["70430.30", "0.187"], ["70456.70", "0.010"], ["70456.90", "0.301"], ["70464.70", "0.000"], ["70495.10", "0.012"], ["70496.50", "0.046"], ["70501.70", "0.614"]], "a": [["70503.60", "3.264"], ["70507.90", "0.002"], ["70508.90", "0.026"], ["70528.00", "0.215"], ["70542.40", "0.303"], ["70544.40", "0.257"], ["70585.00", "0.077"], ["70592.10", "0.078"], ["70599.10", "0.071"], ["70635.90", "0.001"], ["70650.00", "1.323"], ["71208.60", "0.002"], ["74037.00", "0.116"], ["74059.50", "0.052"]]}}
{"local_ts": 1773485095163, "server_ts": 1773485094370, "data": {"e": "depthUpdate", "E": 1773485094371, "T": 1773485094370, "s": "BTCUSDT", "U": 10109431057749, "u": 10109431061061, "pu": 10109431057732, "b": [["1000.00", "28.692"], ["5000.00", "101.418"], ["7050.40", "0.000"], ["20103.50", "2.110"], ["20203.50", "0.890"], ["40000.10", "0.007"], ["63453.10", "0.012"], ["66950.70", "0.008"], ["66969.80", "0.000"], ["66978.30", "0.002"], ["67683.40", "0.012"], ["69798.50", "0.000"], ["70151.00", "0.042"], ["70257.30", "0.000"], ["70430.30", "0.003"], ["70430.90", "0.187"], ["70465.20", "0.068"], ["70483.90", "0.009"], ["70484.80", "0.003"], ["70503.50", "3.072"]], "a": [["70542.40", "0.303"], ["70727.10", "0.004"], ["70827.70", "0.007"], ["71208.60", "0.002"]]}}
{"local_ts": 1773485096193, "server_ts": 1773485095390, "data": {"e": "depthUpdate", "E": 1773485095391, "T": 1773485095390, "s": "BTCUSDT", "U": 10109431094935, "u": 10109431099171, "pu": 10109431094917, "b": [["5000.00", "101.418"], ["7050.40", "0.000"], ["20003.50", "1.660"], ["20103.50", "1.340"], ["69791.80", "0.000"], ["69798.50", "0.000"], ["69952.70", "0.000"], ["70430.90", "0.003"]], "a": [["70524.60", "0.017"], ["70528.50", "0.011"], ["70528.60", "0.922"], ["70539.90", "0.083"], ["70571.00", "0.042"], ["71064.10", "0.562"], ["71208.60", "0.002"], ["71688.10", "0.278"], ["71915.80", "0.005"], ["71916.10", "0.008"], ["74045.60", "0.004"]]}}
{"local_ts": 1773485097207, "server_ts": 1773485096412, "data": {"e": "depthUpdate", "E": 1773485096413, "T": 1773485096412, "s": "BTCUSDT", "U": 10109431170670, "u": 10109431197163, "pu": 10109431170615, "b": [["1000.00", "28.692"], ["5000.00", "101.398"], ["7050.00", "0.481"], ["7050.40", "0.000"], ["20003.50", "1.790"], ["20400.00", "0.330"], ["33000.00", "3.785"], ["66953.00", "0.000"], ["66975.00", "0.084"], ["69090.00", "3.695"], ["69133.80", "0.000"], ["69537.60", "0.003"], ["69795.00", "0.099"], ["69971.20", "1.432"], ["70151.00", "0.078"], ["70151.10", "0.004"], ["70178.50", "1.799"], ["70180.70", "30.527"], ["70202.80", "0.875"], ["70238.70", "0.747"], ["70241.20", "0.277"], ["70251.00", "0.100"], ["70251.10", "0.096"], ["70300.60", "0.089"], ["70304.10", "0.039"], ["70307.00", "0.340"], ["70311.40", "0.090"], ["70315.40", "0.130"], ["70320.60", "1.738"], ["70321.80", "0.092"], ["70323.20", "0.090"], ["70323.70", "0.364"], ["70328.50", "0.090"], ["70329.80", "0.093"], ["70330.20", "0.092"], ["70331.60", "0.041"], ["70331.70", "0.134"], ["70331.90", "0.050"], ["70334.30", "0.155"], ["70338.20", "0.112"], ["70338.90", "0.092"], ["70339.70", "0.184"], ["70341.70", "0.092"], ["70344.40", "0.229"], ["70346.40", "0.107"], ["70346.90", "0.217"], ["70351.30", "0.181"], ["70353.40", "1.135"], ["70357.20", "0.285"], ["70357.60", "0.303"], ["70358.90", "0.728"], ["70361.50", "0.615"], ["70364.40", "0.124"], ["70377.70", "1.311"], ["70379.00", "2.205"], ["70382.20", "0.020"], ["70387.60", "1.090"], ["70388.10", "0.000"], ["70388.60", "0.000"], ["70394.00", "0.090"], ["70396.00", "0.022"], ["70397.00", "0.987"], ["70399.70", "0.095"], ["70400.90", "0.000"], ["70403.30", "0.000"], ["70403.60", "0.192"], ["70404.00", "0.071"], ["70407.90", "0.112"], ["70408.00", "0.441"], ["70408.10", "0.002"], ["70408.50", "0.327"], ["70409.80", "0.002"], ["70409.90", "0.551"], ["70410.10", "0.090"], ["70410.40", "0.017"], ["70410.50", "0.000"], ["70410.70", "0.279"], ["70411.10", "1.969"], ["70411.50", "0.041"], ["70411.60", "0.378"], ["70412.90", "0.091"], ["70414.00", "0.002"], ["70414.10", "0.008"], ["70414.20", "0.088"], ["70414.70", "0.022"], ["70415.00", "0.229"], ["70415.20", "0.016"], ["70415.50", "0.088"], ["70416.60", "0.220"], ["70418.10", "0.004"], ["70418.50", "0.408"], ["70418.70", "0.000"], ["70422.00", "0.549"], ["70422.10", "0.610"], ["70422.20", "0.002"], ["70422.40", "0.002"], ["70422.60", "0.600"], ["70423.80", "0.002"], ["70424.40", "0.495"], ["70424.60", "0.000"], ["70425.60", "0.084"], ["70425.70", "0.009"], ["70426.60", "0.205"], ["70426.70", "0.000"], ["70426.90", "0.130"], ["70427.90", "0.003"], ["70428.50", "0.402"], ["70429.10", "0.001"], ["70429.20", "0.109"], ["70429.50", "1.315"], ["70429.60", "0.318"], ["70429.90", "0.009"], ["70430.30", "0.184"], ["70430.90", "0.190"], ["70431.00", "0.070"], ["70431.60", "0.005"], ["70431.80", "0.180"], ["70431.90", "0.573"], ["70432.40", "0.368"], ["70432.60", "0.002"], ["70432.70", "0.000"], ["70433.00", "0.371"], ["70433.80", "0.846"], ["70434.90", "0.000"], ["70435.10", "0.000"], ["70435.30", "0.854"], ["70435.60", "0.063"], ["70435.70", "0.000"], ["70436.40", "0.057"], ["70436.50", "0.012"], ["70436.90", "0.069"], ["70437.20", "0.314"], ["70437.70", "0.397"], ["70437.80", "0.073"], ["70438.40", "0.100"], ["70438.80", "8.640"], ["70439.60", "0.295"], ["70439.70", "0.781"], ["70440.00", "0.105"], ["70440.20", "0.085"], ["70440.30", "0.003"], ["70440.70", "0.511"], ["70443.60", "0.070"], ["70443.90", "0.007"], ["70444.00", "0.087"], ["70444.20", "0.113"], ["70444.30", "0.000"], ["70444.60", "0.008"], ["70445.00", "0.000"], ["70445.30", "0.551"], ["70445.80", "0.001"], ["70447.00", "0.002"], ["70447.10", "0.051"], ["70447.30", "0.437"], ["70447.40", "0.006"], ["70447.70", "0.002"], ["70447.80", "0.002"], ["70448.10", "0.483"], ["70448.30", "0.570"], ["70448.60", "0.001"], ["70449.00", "0.000"], ["70449.40", "0.005"], ["70449.90", "1.194"], ["70450.40", "0.633"], ["70450.50", "0.152"], ["70450.60", "0.086"], ["70450.70", "0.007"], ["70451.30", "0.000"], ["70451.60", "0.313"], ["70451.90", "0.173"], ["70452.10", "0.000"], ["70452.60", "0.310"], ["70452.90", "0.016"], ["70453.80", "0.023"], ["70453.90", "0.267"], ["70454.80", "0.002"], ["70454.90", "0.017"], ["70455.50", "0.002"], ["70455.60", "0.060"], ["70455.80", "0.035"], ["70456.30", "0.535"], ["70456.40", "0.049"], ["70456.50", "0.004"], ["70456.60", "0.010"], ["70457.00", "0.003"], ["70457.20", "0.002"], ["70457.30", "0.102"], ["70457.40", "0.015"], ["70457.70", "0.029"], ["70458.30", "0.016"], ["70458.80", "0.403"], ["70459.10", "0.057"], ["70459.20", "0.004"], ["70459.30", "0.000"], ["70459.70", "0.348"], ["70460.00", "0.018"], ["70460.10", "0.096"], ["70460.20", "0.000"], ["70461.20", "0.005"], ["70461.30", "0.000"], ["70461.50", "0.002"], ["70461.70", "0.993"], ["70461.80", "0.000"], ["70461.90", "0.012"], ["70462.00", "0.030"], ["70462.50", "0.000"], ["70462.60", "0.057"], ["70462.70", "0.005"], ["70462.90", "0.003"], ["70463.30", "0.532"], ["70464.00", "0.071"], ["70464.10", "0.124"], ["70464.20", "0.052"], ["70464.50", "0.036"], ["70464.70", "0.000"], ["70464.80", "0.001"], ["70464.90", "0.003"], ["70465.10", "0.525"], ["70465.20", "0.252"], ["70465.30", "0.000"], ["70465.40", "0.049"], ["70465.50", "0.005"], ["70466.10", "0.007"], ["70466.20", "0.009"], ["70466.40", "0.059"], ["70466.80", "0.840"], ["70466.90", "0.514"], ["70467.20", "0.004"], ["70467.40", "0.035"], ["70467.50", "0.000"], ["70467.60", "0.070"], ["70468.00", "0.002"], ["70468.10", "0.003"], ["70468.20", "0.005"], ["70468.30", "0.000"], ["70468.40", "0.016"], ["70468.70", "0.706"], ["70468.80", "1.171"], ["70468.90", "2.017"], ["70469.00", "0.008"], ["70469.10", "0.511"], ["70469.20", "0.513"], ["70469.40", "0.074"], ["70469.60", "0.290"], ["70469.70", "0.000"], ["70469.90", "0.011"], ["70470.10", "0.266"], ["70470.40", "0.150"], ["70470.70", "0.090"], ["70470.80", "0.000"], ["70471.40", "0.582"], ["70471.60", "0.000"], ["70472.00", "0.077"], ["70472.10", "0.000"], ["70472.30", "0.972"], ["70472.40", "0.002"], ["70472.50", "0.005"], ["70472.60", "0.020"], ["70473.00", "0.002"], ["70473.10", "0.004"], ["70473.20", "0.498"], ["70473.50", "0.005"], ["70473.60", "0.023"], ["70473.70", "0.511"], ["70474.00", "0.590"], ["70474.10", "0.004"], ["70474.20", "0.070"], ["70474.40", "0.000"], ["70475.00", "0.008"], ["70475.20", "0.006"], ["70475.40", "0.078"], ["70475.60", "0.370"], ["70475.70", "0.011"], ["70475.90", "1.200"], ["70476.20", "0.035"], ["70476.60", "0.006"], ["70476.70", "0.002"], ["70476.80", "0.229"], ["70476.90", "0.000"], ["70477.10", "0.005"], ["70477.40", "0.041"], ["70477.60", "0.639"], ["70477.70", "0.033"], ["70478.30", "0.523"], ["70478.50", "0.001"], ["70478.60", "0.045"], ["70478.80", "0.005"], ["70478.90", "0.212"], ["70479.10", "0.388"], ["70479.30", "0.002"], ["70479.40", "0.129"], ["70479.50", "1.216"], ["70479.70", "0.006"], ["70479.80", "0.015"], ["70479.90", "0.006"], ["70480.00", "5.012"], ["70480.10", "0.092"], ["70480.40", "0.008"], ["70480.60", "1.134"], ["70480.90", "0.000"], ["70481.00", "0.023"], ["70481.10", "0.024"], ["70481.30", "0.346"], ["70481.40", "0.011"], ["70481.50", "0.056"], ["70481.60", "0.047"], ["70481.70", "0.800"], ["70481.80", "0.007"], ["70481.90", "0.004"], ["70482.40", "0.204"], ["70482.50", "0.002"], ["70482.80", "0.012"], ["70483.00", "0.010"], ["70483.20", "0.003"], ["70483.70", "0.200"], ["70483.80", "0.106"], ["70484.10", "0.003"], ["70484.40", "0.102"], ["70484.70", "0.000"], ["70484.80", "0.021"], ["70484.90", "0.009"], ["70485.00", "0.007"], ["70485.20", "0.012"], ["70485.40", "0.002"], ["70485.60", "0.007"], ["70486.10", "0.003"], ["70486.20", "0.077"], ["70486.30", "0.286"], ["70486.70", "0.004"], ["70487.10", "0.002"], ["70487.30", "0.000"], ["70487.60", "0.013"], ["70487.70", "0.000"], ["70487.80", "0.001"], ["70487.90", "0.000"], ["70488.00", "0.008"], ["70488.10", "0.004"], ["70488.20", "0.000"], ["70488.40", "0.068"], ["70488.70", "0.212"], ["70488.90", "0.005"], ["70489.40", "0.001"], ["70489.50", "0.004"], ["70489.70", "0.002"], ["70489.90", "0.019"], ["70490.60", "0.030"], ["70490.90", "0.003"], ["70491.20", "0.001"], ["70491.60", "0.149"], ["70491.80", "0.001"], ["70492.00", "0.007"], ["70492.10", "0.011"], ["70492.90", "0.002"], ["70493.90", "0.003"], ["70494.10", "0.008"], ["70494.30", "0.000"], ["70494.70", "0.006"], ["70494.90", "0.000"], ["70495.00", "0.005"], ["70495.50", "0.020"], ["70496.30", "0.009"], ["70497.60", "0.000"], ["70498.00", "0.002"], ["70498.80", "0.005"], ["70499.20", "0.003"], ["70499.50", "0.004"], ["70499.80", "0.004"], ["70499.90", "0.020"], ["70500.00", "44.519"]], "a": [["70500.10", "7.123"], ["70500.20", "0.345"], ["70500.30", "0.202"], ["70500.40", "0.003"], ["70500.70", "0.001"], ["70500.80", "0.213"], ["70500.90", "0.001"], ["70501.00", "0.021"], ["70501.10", "0.000"], ["70501.20", "0.002"], ["70501.30", "0.002"], ["70501.40", "0.000"], ["70501.50", "0.000"], ["70501.60", "0.002"], ["70501.70", "0.000"], ["70501.80", "0.003"], ["70501.90", "0.003"], ["70502.00", "0.001"], ["70502.40", "0.007"], ["70502.50", "0.076"], ["70502.70", "0.007"], ["70503.00", "0.013"], ["70503.30", "0.003"], ["70503.40", "0.007"], ["70503.50", "0.011"], ["70503.60", "0.375"], ["70503.90", "0.003"], ["70504.10", "0.001"], ["70504.50", "0.001"], ["70504.70", "0.000"], ["70504.80", "0.377"], ["70504.90", "1.425"], ["70505.20", "0.001"], ["70505.50", "0.002"], ["70505.60", "0.002"], ["70505.90", "0.067"], ["70506.20", "0.001"], ["70506.40", "0.004"], ["70506.60", "0.000"], ["70506.70", "0.009"], ["70506.90", "0.005"], ["70507.10", "0.006"], ["70507.20", "0.003"], ["70507.30", "0.214"], ["70507.40", "0.017"], ["70507.50", "0.021"], ["70507.60", "0.345"], ["70507.70", "1.165"], ["70507.80", "1.230"], ["70507.90", "0.002"], ["70508.00", "0.004"], ["70508.10", "0.008"], ["70508.30", "0.047"], ["70508.40", "0.004"], ["70508.50", "0.014"], ["70508.70", "0.000"], ["70508.90", "0.007"], ["70509.20", "0.006"], ["70509.30", "0.001"], ["70509.40", "0.000"], ["70509.50", "0.003"], ["70509.80", "0.008"], ["70510.00", "0.049"], ["70510.10", "0.002"], ["70510.20", "0.000"], ["70510.30", "0.050"], ["70510.40", "1.079"], ["70510.50", "0.014"], ["70510.60", "0.000"], ["70510.70", "0.001"], ["70510.90", "0.718"], ["70511.10", "0.309"], ["70511.60", "0.003"], ["70511.70", "0.002"], ["70511.80", "0.000"], ["70512.00", "0.002"], ["70512.50", "0.023"], ["70512.60", "0.001"], ["70512.70", "0.023"], ["70512.90", "0.001"], ["70513.10", "0.002"], ["70514.00", "0.013"], ["70514.20", "0.638"], ["70514.50", "0.620"], ["70514.60", "0.003"], ["70515.60", "0.002"], ["70515.80", "0.514"], ["70516.00", "0.078"], ["70516.10", "1.072"], ["70516.20", "0.131"], ["70516.70", "0.057"], ["70516.80", "0.230"], ["70517.40", "0.042"], ["70517.50", "0.372"], ["70517.70", "0.373"], ["70517.80", "0.041"], ["70517.90", "0.036"], ["70518.40", "0.001"], ["70518.60", "0.002"], ["70518.70", "0.420"], ["70518.80", "0.867"], ["70519.20", "0.007"], ["70519.40", "0.007"], ["70519.50", "0.087"], ["70519.80", "0.003"], ["70520.00", "0.031"], ["70520.10", "0.003"], ["70520.20", "0.000"], ["70520.30", "0.002"], ["70520.40", "0.063"], ["70520.70", "0.318"], ["70521.20", "0.052"], ["70521.30", "0.032"], ["70521.50", "0.040"], ["70521.60", "0.633"], ["70521.80", "1.075"], ["70521.90", "0.516"], ["70522.20", "0.005"], ["70522.30", "0.004"], ["70522.80", "0.004"], ["70522.90", "0.002"], ["70523.00", "0.035"], ["70523.20", "0.047"], ["70523.40", "0.023"], ["70523.50", "0.011"], ["70523.60", "0.003"], ["70523.70", "0.004"], ["70524.30", "0.064"], ["70524.40", "0.000"], ["70524.60", "0.009"], ["70525.00", "0.802"], ["70525.10", "0.129"], ["70525.70", "0.005"], ["70525.80", "0.005"], ["70526.20", "0.080"], ["70526.40", "0.018"], ["70526.50", "0.002"], ["70526.70", "0.000"], ["70527.60", "0.006"], ["70527.80", "0.003"], ["70527.90", "0.065"], ["70528.00", "0.002"], ["70528.70", "0.015"], ["70528.80", "0.000"], ["70529.30", "0.024"], ["70529.40", "0.354"], ["70530.10", "0.668"], ["70530.90", "0.008"], ["70531.00", "0.000"], ["70531.30", "0.878"], ["70531.50", "0.003"], ["70532.00", "0.013"], ["70532.40", "0.009"], ["70532.70", "0.012"], ["70532.90", "0.002"], ["70533.30", "0.029"], ["70533.40", "0.201"], ["70533.70", "0.001"], ["70534.10", "0.010"], ["70534.30", "0.006"], ["70534.70", "0.186"], ["70535.10", "0.094"], ["70535.20", "1.952"], ["70535.90", "0.844"], ["70536.80", "0.498"], ["70537.50", "0.002"], ["70537.60", "0.097"], ["70537.80", "0.107"], ["70538.40", "0.044"], ["70538.90", "0.057"], ["70539.80", "1.815"], ["70539.90", "0.000"], ["70540.60", "0.055"], ["70542.20", "0.015"], ["70542.40", "0.805"], ["70544.40", "0.073"], ["70545.00", "1.577"], ["70545.30", "8.100"], ["70546.00", "0.014"], ["70546.50", "0.065"], ["70547.70", "0.068"], ["70548.10", "0.000"], ["70548.50", "0.000"], ["70549.60", "2.100"], ["70550.30", "0.116"], ["70550.60", "0.234"], ["70551.10", "9.299"], ["70552.00", "0.386"], ["70552.50", "0.041"], ["70552.80", "0.002"], ["70553.50", "0.259"], ["70553.60", "0.000"], ["70554.60", "0.010"], ["70555.50", "1.186"], ["70555.70", "0.388"], ["70555.80", "0.230"], ["70556.40", "0.096"], ["70556.50", "0.002"], ["70556.80", "1.183"], ["70556.90", "0.008"], ["70557.00", "0.014"], ["70557.10", "2.589"], ["70557.40", "0.094"], ["70558.50", "0.004"], ["70558.60", "0.004"], ["70560.90", "0.585"], ["70561.70", "3.372"], ["70561.90", "0.513"], ["70563.30", "0.181"], ["70563.50", "0.006"], ["70563.60", "0.083"], ["70565.60", "0.019"], ["70567.10", "0.153"], ["70568.30", "0.077"], ["70570.30", "0.031"], ["70570.50", "0.716"], ["70570.60", "1.042"], ["70570.80", "0.088"], ["70572.20", "0.511"], ["70573.30", "0.158"], ["70574.60", "0.511"], ["70575.10", "0.002"], ["70577.60", "0.178"], ["70578.40", "0.092"], ["70579.30", "0.236"], ["70580.40", "0.315"], ["70581.00", "0.004"], ["70581.10", "0.245"], ["70581.20", "0.021"], ["70582.50", "0.090"], ["70583.80", "0.261"], ["70584.30", "0.002"], ["70584.70", "0.142"], ["70584.90", "0.000"], ["70585.30", "0.180"], ["70585.50", "0.234"], ["70586.40", "0.002"], ["70587.40", "0.073"], ["70588.10", "0.003"], ["70588.20", "0.211"], ["70591.00", "0.002"], ["70591.50", "0.024"], ["70591.70", "0.320"], ["70592.00", "1.970"], ["70595.10", "0.000"], ["70596.30", "0.019"], ["70599.00", "0.088"], ["70605.30", "0.004"], ["70607.00", "0.050"], ["70609.50", "0.254"], ["70610.80", "0.083"], ["70618.90", "0.511"], ["70623.40", "0.002"], ["70635.30", "0.002"], ["70636.60", "0.000"], ["70637.00", "4.606"], ["70638.30", "0.016"], ["70639.30", "0.000"], ["70639.40", "0.197"], ["70639.50", "0.152"], ["70639.90", "0.511"], ["70640.90", "0.000"], ["70641.70", "0.002"], ["70642.00", "0.000"], ["70643.10", "2.584"], ["70643.30", "0.089"], ["70643.40", "0.000"], ["70643.80", "0.000"], ["70646.80", "0.041"], ["70655.80", "2.311"], ["70656.50", "12.065"], ["70662.80", "0.000"], ["70662.90", "0.039"], ["70663.10", "0.000"], ["70676.40", "0.099"], ["70678.40", "0.018"], ["70679.90", "0.002"], ["70683.40", "0.009"], ["70712.40", "0.000"], ["70726.90", "0.308"], ["70750.40", "0.833"], ["70752.60", "4.205"], ["70753.90", "0.000"], ["70803.10", "0.408"], ["70854.70", "0.028"], ["70931.20", "38.277"], ["71058.90", "46.266"], ["71205.10", "0.000"], ["71284.10", "0.701"], ["71910.10", "0.006"], ["74055.70", "0.003"], ["74665.00", "0.052"], ["140720.10", "0.000"], ["140776.50", "0.000"], ["140884.10", "0.012"], ["141000.10", "0.012"]]}}
{"local_ts": 1773485098233, "server_ts": 1773485097432, "data": {"e": "depthUpdate", "E": 1773485097433, "T": 1773485097432, "s": "BTCUSDT", "U": 10109431330687, "u": 10109431342223, "pu": 10109431330667, "b": [["1000.00", "28.692"], ["5000.00", "101.418"], ["7047.60", "0.056"], ["7048.00", "0.000"], ["20275.10", "0.280"], ["20403.50", "0.100"], ["66926.20", "0.002"], ["69382.70", "1.616"], ["69419.40", "0.000"], ["69453.30", "4.167"], ["69770.30", "0.000"], ["70034.40", "0.481"], ["70173.90", "0.002"], ["70177.90", "0.582"], ["70199.40", "0.459"], ["70242.40", "0.007"], ["70247.80", "0.000"], ["70248.00", "18.091"], ["70248.10", "6.206"], ["70258.00", "0.070"], ["70259.00", "1.610"], ["70281.00", "0.093"], ["70281.90", "3.550"], ["70288.30", "0.000"], ["70289.70", "0.003"], ["70290.10", "0.000"], ["70290.30", "23.336"], ["70290.40", "4.852"], ["70300.00", "20.612"], ["70302.50", "0.093"], ["70304.60", "0.093"], ["70306.90", "0.592"], ["70309.60", "2.504"], ["70309.80", "0.279"], ["70310.90", "0.092"], ["70311.90", "0.090"], ["70312.10", "0.090"], ["70313.70", "2.486"], ["70313.80", "0.094"], ["70314.20", "0.003"], ["70315.80", "0.183"], ["70317.90", "0.115"], ["70318.00", "0.093"], ["70318.10", "0.114"], ["70318.40", "0.000"], ["70319.00", "0.185"], ["70321.10", "0.090"], ["70322.00", "4.732"], ["70322.30", "0.102"], ["70323.30", "0.000"], ["70324.30", "0.037"], ["70324.40", "0.090"], ["70324.50", "0.002"], ["70325.20", "0.090"], ["70325.30", "0.731"], ["70326.50", "0.112"], ["70327.60", "0.007"], ["70329.00", "1.150"], ["70330.80", "0.182"], ["70332.60", "34.194"], ["70333.20", "0.129"], ["70336.00", "6.064"], ["70344.00", "0.051"], ["70346.80", "0.002"], ["70350.40", "0.003"], ["70357.60", "0.002"], ["70359.50", "0.002"], ["70365.60", "0.000"], ["70367.40", "1.472"], ["70367.50", "0.008"], ["70371.00", "0.004"], ["70373.20", "0.842"], ["70375.80", "0.000"], ["70378.50", "0.000"], ["70379.00", "0.313"], ["70379.60", "0.004"], ["70379.70", "0.230"], ["70380.20", "0.041"], ["70380.40", "1.095"], ["70381.10", "0.037"], ["70381.80", "0.320"], ["70381.90", "0.364"], ["70382.40", "0.000"], ["70383.20", "0.046"], ["70384.00", "0.948"], ["70386.70", "0.147"], ["70388.30", "0.110"], ["70388.80", "0.511"], ["70390.00", "0.122"], ["70390.70", "0.181"], ["70391.20", "0.950"], ["70392.10", "1.174"], ["70393.30", "0.150"], ["70393.40", "0.110"], ["70393.80", "0.000"], ["70394.20", "0.031"], ["70394.40", "0.168"], ["70395.50", "0.094"], ["70395.60", "0.110"], ["70395.80", "0.003"], ["70395.90", "0.055"], ["70396.70", "0.108"], ["70396.80", "0.030"], ["70397.70", "0.108"], ["70398.50", "0.637"], ["70398.90", "0.108"], ["70399.40", "2.584"], ["70399.60", "2.247"], ["70399.70", "0.006"], ["70399.80", "0.198"], ["70400.90", "0.108"], ["70401.50", "0.108"], ["70402.40", "0.108"], ["70403.10", "0.108"], ["70403.20", "0.632"], ["70403.80", "0.063"], ["70404.60", "0.132"], ["70404.70", "0.004"], ["70405.80", "0.000"], ["70406.60", "0.169"], ["70408.60", "0.007"], ["70409.00", "0.056"], ["70409.10", "0.014"], ["70411.70", "0.000"], ["70412.90", "0.011"], ["70413.30", "0.002"], ["70413.90", "0.000"], ["70415.50", "0.002"], ["70416.00", "0.006"], ["70416.10", "0.149"], ["70416.30", "0.006"], ["70416.50", "0.522"], ["70416.80", "0.000"], ["70417.00", "8.522"], ["70418.60", "2.150"], ["70418.70", "0.158"], ["70419.30", "0.104"], ["70420.10", "0.100"], ["70421.10", "0.000"], ["70421.20", "0.085"], ["70421.80", "0.101"], ["70422.20", "0.002"], ["70422.60", "0.516"], ["70422.80", "0.520"], ["70423.40", "0.831"], ["70423.50", "0.011"], ["70424.20", "0.004"], ["70424.40", "0.495"], ["70424.80", "0.002"], ["70425.40", "1.204"], ["70425.80", "0.006"], ["70427.10", "0.000"], ["70427.20", "0.847"], ["70427.60", "0.104"], ["70427.90", "0.006"], ["70428.30", "0.001"], ["70428.60", "0.005"], ["70429.30", "0.008"], ["70429.40", "0.072"], ["70430.00", "10.630"], ["70430.20", "2.288"], ["70430.30", "0.035"], ["70431.00", "0.002"], ["70432.50", "0.143"], ["70432.80", "0.005"], ["70432.90", "0.544"], ["70433.20", "0.089"], ["70434.20", "0.033"], ["70434.60", "0.021"], ["70435.60", "0.023"], ["70435.80", "0.100"], ["70436.60", "0.005"], ["70436.80", "0.508"], ["70437.40", "0.524"], ["70437.50", "0.219"], ["70437.70", "0.358"], ["70437.80", "0.005"], ["70437.90", "0.000"], ["70439.00", "0.002"], ["70439.90", "0.001"], ["70440.00", "0.042"], ["70440.20", "0.024"], ["70440.30", "0.068"], ["70440.50", "0.012"], ["70440.70", "0.539"], ["70440.80", "0.911"], ["70440.90", "0.010"], ["70441.10", "0.128"], ["70441.70", "0.070"], ["70443.10", "0.003"], ["70443.30", "0.008"], ["70443.40", "1.129"], ["70443.80", "0.063"], ["70443.90", "0.885"], ["70444.00", "0.582"], ["70444.40", "2.531"], ["70444.80", "0.675"], ["70444.90", "0.007"], ["70445.10", "0.182"], ["70445.30", "0.503"], ["70445.50", "0.523"], ["70445.60", "0.298"], ["70445.70", "0.233"], ["70446.60", "0.004"], ["70446.90", "0.238"], ["70447.00", "0.083"], ["70447.20", "0.021"], ["70447.30", "0.623"], ["70447.40", "0.082"], ["70447.50", "0.012"], ["70447.60", "0.004"], ["70448.20", "0.104"], ["70448.30", "0.009"], ["70448.60", "0.000"], ["70449.00", "0.284"], ["70449.10", "0.056"], ["70449.20", "0.002"], ["70449.60", "0.111"], ["70450.10", "0.248"], ["70450.20", "0.187"], ["70450.60", "0.325"], ["70450.90", "0.005"], ["70451.10", "0.000"], ["70451.30", "0.058"], ["70451.50", "0.696"], ["70451.70", "0.277"], ["70451.90", "0.126"], ["70452.00", "0.325"], ["70452.10", "0.003"], ["70452.20", "0.064"], ["70452.60", "0.029"], ["70452.90", "0.010"], ["70453.10", "1.264"], ["70453.30", "0.007"], ["70453.60", "0.164"], ["70453.70", "0.000"], ["70453.80", "0.002"], ["70454.00", "0.003"], ["70454.20", "0.009"], ["70454.30", "0.000"], ["70454.50", "0.000"], ["70454.70", "1.108"], ["70454.80", "0.675"], ["70454.90", "0.050"], ["70455.00", "0.027"], ["70455.10", "0.235"], ["70455.20", "0.292"], ["70455.30", "0.096"], ["70455.50", "0.011"], ["70455.70", "0.020"], ["70455.90", "0.138"], ["70457.10", "0.004"], ["70457.40", "0.017"], ["70458.10", "0.021"], ["70458.20", "0.000"], ["70458.30", "0.343"], ["70458.50", "0.007"], ["70458.60", "0.065"], ["70458.80", "0.290"], ["70459.00", "0.000"], ["70459.10", "0.003"], ["70459.20", "0.023"], ["70459.70", "0.004"], ["70459.90", "0.206"], ["70460.20", "0.000"], ["70460.30", "0.003"], ["70460.40", "0.004"], ["70460.60", "1.351"], ["70461.00", "0.011"], ["70461.30", "0.027"], ["70461.90", "0.798"], ["70462.00", "0.008"], ["70462.10", "0.131"], ["70462.20", "0.638"], ["70462.40", "0.293"], ["70462.50", "0.112"], ["70462.60", "0.003"], ["70463.00", "0.130"], ["70463.20", "0.055"], ["70463.30", "0.035"], ["70463.60", "0.003"], ["70464.00", "0.025"], ["70464.10", "0.124"], ["70464.50", "0.005"], ["70464.60", "0.012"], ["70465.10", "0.308"], ["70465.20", "0.006"], ["70465.50", "0.004"], ["70465.60", "0.016"], ["70465.80", "0.012"], ["70465.90", "0.000"], ["70466.00", "0.018"], ["70466.10", "0.000"], ["70466.30", "0.219"], ["70466.40", "1.068"], ["70466.80", "0.000"], ["70467.00", "0.275"], ["70467.10", "0.007"], ["70467.30", "0.021"], ["70467.50", "0.002"], ["70467.70", "0.006"], ["70468.00", "0.005"], ["70468.10", "0.003"], ["70468.20", "0.396"], ["70468.80", "0.009"], ["70469.00", "0.012"], ["70469.70", "0.004"], ["70469.90", "0.009"], ["70470.00", "5.047"], ["70470.10", "0.820"], ["70470.20", "0.129"], ["70470.30", "0.917"], ["70470.40", "0.012"], ["70470.70", "0.003"], ["70472.30", "0.062"], ["70472.60", "0.016"], ["70472.70", "0.000"], ["70472.90", "0.021"], ["70473.40", "0.003"], ["70475.00", "0.031"], ["70475.10", "6.782"]], "a": [["70475.20", "1.951"], ["70475.30", "0.000"], ["70475.40", "0.002"], ["70475.60", "0.212"], ["70475.90", "0.000"], ["70476.10", "0.002"], ["70476.20", "0.000"], ["70476.30", "0.000"], ["70476.40", "0.000"], ["70476.60", "0.007"], ["70476.70", "0.000"], ["70476.80", "0.000"], ["70477.00", "0.007"], ["70477.20", "0.000"], ["70477.30", "0.000"], ["70477.60", "0.003"], ["70478.40", "0.003"], ["70478.90", "0.007"], ["70479.00", "0.003"], ["70479.30", "0.000"], ["70479.50", "0.004"], ["70479.60", "0.000"], ["70479.70", "0.074"], ["70479.80", "0.252"], ["70480.00", "0.067"], ["70480.10", "0.250"], ["70480.30", "0.000"], ["70480.50", "0.000"], ["70480.60", "0.000"], ["70480.70", "0.030"], ["70481.30", "0.029"], ["70481.40", "0.002"], ["70482.00", "0.000"], ["70482.10", "0.002"], ["70482.30", "0.000"], ["70482.80", "0.005"], ["70482.90", "0.000"], ["70483.00", "0.016"], ["70483.10", "0.024"], ["70483.30", "0.003"], ["70484.00", "0.000"], ["70484.10", "0.001"], ["70484.30", "0.044"], ["70484.40", "0.011"], ["70484.70", "0.008"], ["70485.10", "0.000"], ["70485.20", "0.124"], ["70485.60", "0.013"], ["70485.70", "0.000"], ["70485.80", "0.032"], ["70485.90", "0.021"], ["70486.10", "0.003"], ["70486.40", "0.006"], ["70486.50", "0.009"], ["70486.70", "0.003"], ["70486.90", "0.004"], ["70487.00", "0.044"], ["70487.10", "0.684"], ["70487.20", "0.344"], ["70487.50", "0.000"], ["70487.60", "0.001"], ["70487.70", "0.000"], ["70487.90", "0.002"], ["70488.10", "0.039"], ["70489.20", "0.001"], ["70489.30", "0.003"], ["70490.30", "0.005"], ["70490.40", "0.293"], ["70490.80", "0.005"], ["70491.20", "0.014"], ["70491.60", "0.077"], ["70491.70", "0.512"], ["70491.90", "0.031"], ["70492.40", "1.080"], ["70492.50", "0.022"], ["70492.60", "0.000"], ["70492.70", "0.007"], ["70492.90", "0.026"], ["70493.30", "0.017"], ["70493.50", "0.050"], ["70493.80", "0.361"], ["70494.20", "0.085"], ["70494.30", "0.347"], ["70494.90", "0.002"], ["70495.20", "0.003"], ["70495.50", "0.000"], ["70495.60", "0.115"], ["70495.80", "0.036"], ["70496.00", "0.000"], ["70496.30", "0.068"], ["70496.50", "0.003"], ["70497.20", "0.006"], ["70497.40", "0.000"], ["70497.50", "0.000"], ["70497.60", "0.515"], ["70497.70", "0.004"], ["70498.50", "0.005"], ["70498.60", "0.070"], ["70498.90", "0.004"], ["70499.10", "0.000"], ["70499.20", "0.206"], ["70499.80", "0.002"], ["70500.10", "0.176"], ["70500.40", "0.510"], ["70500.70", "0.944"], ["70501.80", "0.344"], ["70501.90", "0.017"], ["70502.70", "0.000"], ["70502.80", "0.075"], ["70503.00", "0.052"], ["70503.10", "0.000"], ["70503.40", "0.002"], ["70503.60", "0.116"], ["70503.80", "0.012"], ["70504.50", "0.518"], ["70504.90", "0.051"], ["70505.30", "0.000"], ["70505.90", "0.010"], ["70506.30", "0.291"], ["70506.40", "0.891"], ["70506.50", "0.054"], ["70506.60", "0.085"], ["70506.70", "0.002"], ["70507.00", "0.250"], ["70507.30", "0.204"], ["70507.40", "0.054"], ["70507.70", "0.012"], ["70507.80", "0.916"], ["70508.80", "0.002"], ["70509.00", "0.012"], ["70510.20", "0.000"], ["70511.20", "0.002"], ["70511.40", "0.836"], ["70511.90", "0.000"], ["70512.60", "0.004"], ["70512.80", "0.005"], ["70514.70", "0.040"], ["70514.80", "0.000"], ["70515.50", "0.002"], ["70516.00", "0.762"], ["70516.10", "1.199"], ["70516.20", "0.000"], ["70516.50", "0.535"], ["70516.80", "0.254"], ["70517.50", "0.367"], ["70518.20", "0.004"], ["70519.20", "0.116"], ["70519.80", "0.047"], ["70520.30", "0.087"], ["70520.60", "0.016"], ["70521.60", "0.663"], ["70522.20", "0.005"], ["70523.00", "0.036"], ["70523.80", "0.060"], ["70524.50", "0.001"], ["70526.20", "0.114"], ["70526.90", "0.000"], ["70527.60", "0.114"], ["70528.10", "0.030"], ["70528.60", "0.832"], ["70529.30", "0.035"], ["70529.50", "1.079"], ["70530.00", "0.094"], ["70531.60", "0.108"], ["70532.60", "0.030"], ["70534.40", "0.487"], ["70535.00", "0.346"], ["70535.20", "1.946"], ["70535.80", "0.004"], ["70535.90", "0.105"], ["70536.10", "0.114"], ["70536.50", "0.077"], ["70537.90", "0.110"], ["70539.50", "1.911"], ["70539.60", "8.509"], ["70539.70", "0.003"], ["70540.10", "0.175"], ["70541.70", "0.302"], ["70542.20", "0.015"], ["70543.10", "0.354"], ["70544.20", "0.371"], ["70549.20", "0.081"], ["70551.60", "0.447"], ["70552.70", "0.081"], ["70552.80", "0.002"], ["70556.20", "0.083"], ["70557.00", "0.084"], ["70557.70", "0.000"], ["70558.80", "0.013"], ["70564.80", "0.000"], ["70571.60", "0.027"], ["70574.30", "0.050"], ["70575.70", "0.169"], ["70577.20", "0.028"], ["70579.50", "0.206"], ["70579.80", "0.341"], ["70582.00", "0.019"], ["70582.30", "0.184"], ["70584.40", "0.933"], ["70584.50", "3.111"], ["70586.60", "0.092"], ["70592.00", "0.331"], ["70595.20", "0.123"], ["70599.40", "0.151"], ["70599.80", "0.511"], ["70600.30", "10.000"], ["70601.50", "0.108"], ["70605.20", "0.108"], ["70611.90", "2.003"], ["70633.90", "2.289"], ["70636.40", "0.166"], ["70644.00", "0.856"], ["70644.40", "0.000"], ["70646.60", "1.685"], ["70646.90", "10.092"], ["70658.30", "1.222"], ["70668.50", "0.619"], ["70672.50", "0.159"], ["70676.10", "0.108"], ["70677.90", "10.000"], ["70682.50", "2.891"], ["70683.00", "0.000"], ["70690.70", "0.000"], ["70693.60", "0.000"], ["70707.30", "0.528"], ["70707.40", "0.002"], ["70709.00", "10.000"], ["70714.00", "1.721"], ["70714.10", "0.586"], ["70745.00", "2.497"], ["70745.10", "0.000"], ["70777.30", "0.000"], ["70794.30", "0.002"], ["70797.90", "0.000"], ["71180.00", "0.566"], ["71201.20", "58.434"], ["71369.10", "0.700"], ["71411.20", "0.002"], ["71415.40", "67.801"], ["71884.70", "0.006"], ["73298.90", "0.025"], ["89523.20", "0.000"]]}}
{"local_ts": 1773485099250, "server_ts": 1773485098454, "data": {"e": "depthUpdate", "E": 1773485098455, "T": 1773485098454, "s": "BTCUSDT", "U": 10109431422671, "u": 10109431430389, "pu": 10109431422668, "b": [["5000.00", "101.418"], ["7047.00", "0.056"], ["20170.00", "0.110"], ["20270.00", "0.150"], ["20279.70", "0.110"], ["20279.90", "0.000"], ["20379.70", "0.050"], ["20379.90", "0.000"], ["33000.00", "3.789"], ["66922.30", "0.002"], ["69252.70", "2.165"], ["69448.30", "5.718"], ["69464.90", "0.719"], ["69484.40", "1.140"], ["69484.50", "0.719"], ["69730.10", "0.781"], ["69765.30", "0.000"], ["69766.50", "0.000"], ["69786.40", "0.780"], ["69822.90", "0.000"], ["70186.90", "0.582"], ["70225.40", "0.007"], ["70265.00", "0.259"], ["70287.80", "0.000"], ["70293.80", "0.006"], ["70295.40", "2.516"], ["70297.10", "0.521"], ["70306.10", "0.122"], ["70310.70", "0.266"], ["70319.20", "0.039"], ["70323.80", "0.003"], ["70329.10", "2.221"], ["70331.90", "0.084"], ["70332.40", "0.008"], ["70332.90", "0.294"], ["70344.50", "2.040"], ["70344.80", "6.609"], ["70345.00", "0.318"], ["70345.20", "0.040"], ["70345.90", "0.180"], ["70350.10", "0.284"], ["70357.20", "2.246"], ["70358.00", "0.005"], ["70363.10", "0.002"], ["70363.60", "0.620"], ["70367.00", "0.000"], ["70369.20", "0.002"], ["70371.40", "0.087"], ["70376.00", "0.002"], ["70379.10", "0.623"], ["70379.60", "0.004"], ["70381.40", "0.000"], ["70381.90", "0.475"], ["70382.20", "1.182"], ["70384.10", "0.638"], ["70385.40", "0.125"], ["70386.20", "0.208"], ["70386.80", "0.516"], ["70386.90", "0.000"], ["70387.80", "1.237"], ["70388.50", "0.111"], ["70390.10", "0.111"], ["70390.20", "0.278"], ["70391.30", "0.152"], ["70392.20", "0.111"], ["70392.80", "0.214"], ["70396.20", "0.064"], ["70396.40", "6.303"], ["70398.30", "0.000"], ["70399.50", "0.006"], ["70400.20", "0.004"], ["70401.70", "1.068"], ["70401.80", "0.166"], ["70402.20", "0.105"], ["70403.70", "0.000"], ["70403.80", "0.005"], ["70404.20", "0.044"], ["70405.20", "0.260"], ["70405.30", "0.017"], ["70406.90", "0.511"], ["70409.60", "1.000"], ["70412.00", "0.671"], ["70413.70", "0.338"], ["70413.90", "0.059"], ["70414.20", "0.100"], ["70414.40", "0.516"], ["70414.90", "0.016"], ["70415.90", "0.000"], ["70416.60", "0.221"], ["70416.80", "0.002"], ["70417.10", "0.017"], ["70418.60", "0.980"], ["70418.90", "0.014"], ["70419.30", "0.459"], ["70419.70", "0.011"], ["70419.90", "0.057"], ["70420.00", "0.891"], ["70421.00", "0.070"], ["70421.40", "0.355"], ["70422.40", "0.026"], ["70422.80", "0.520"], ["70423.40", "0.910"], ["70423.70", "0.006"], ["70423.90", "0.020"], ["70424.50", "0.000"], ["70424.70", "0.000"], ["70425.40", "1.204"], ["70426.70", "0.000"], ["70427.60", "0.034"], ["70427.70", "0.004"], ["70428.50", "0.435"], ["70428.60", "0.005"], ["70428.90", "0.000"], ["70429.50", "0.345"], ["70430.60", "0.079"], ["70431.80", "0.019"], ["70432.20", "0.002"], ["70432.40", "0.000"], ["70432.50", "0.064"], ["70432.60", "0.085"], ["70433.30", "0.080"], ["70434.60", "0.015"], ["70434.90", "0.024"], ["70435.00", "0.057"], ["70435.70", "0.016"], ["70436.50", "0.002"], ["70436.70", "0.512"], ["70437.10", "0.007"], ["70437.40", "0.034"], ["70437.50", "0.219"], ["70438.10", "0.005"], ["70439.10", "0.102"], ["70439.80", "0.008"], ["70440.00", "0.042"], ["70440.10", "0.070"], ["70440.20", "0.223"], ["70441.20", "0.009"], ["70441.70", "0.262"], ["70441.80", "0.097"], ["70441.90", "0.072"], ["70442.30", "0.003"], ["70442.90", "0.197"], ["70443.10", "0.214"], ["70443.40", "0.090"], ["70443.50", "0.347"], ["70443.60", "0.101"], ["70443.70", "0.358"], ["70444.10", "0.052"], ["70444.20", "0.044"], ["70444.40", "2.569"], ["70444.50", "0.037"], ["70444.60", "0.557"], ["70445.30", "0.236"], ["70445.40", "1.343"], ["70445.80", "0.007"], ["70445.90", "0.000"], ["70446.10", "0.430"], ["70446.20", "0.023"], ["70446.30", "0.097"], ["70446.50", "0.003"], ["70446.60", "0.010"], ["70446.70", "0.003"], ["70446.90", "0.277"], ["70447.10", "0.028"], ["70447.20", "0.000"], ["70447.40", "1.839"], ["70447.60", "0.004"], ["70447.70", "0.939"], ["70447.80", "0.000"], ["70448.30", "0.027"], ["70448.40", "0.328"], ["70448.70", "0.026"], ["70448.80", "0.080"], ["70448.90", "0.738"], ["70449.20", "0.047"], ["70449.50", "0.095"], ["70449.60", "0.264"], ["70449.70", "0.587"], ["70449.90", "0.065"], ["70450.00", "0.109"], ["70450.10", "0.012"], ["70450.30", "0.208"], ["70450.40", "0.007"], ["70450.50", "0.008"], ["70450.60", "0.546"], ["70450.70", "0.023"], ["70451.10", "0.301"], ["70451.50", "0.084"], ["70451.60", "0.297"], ["70451.80", "0.041"], ["70451.90", "0.627"], ["70452.00", "0.006"], ["70452.20", "0.413"], ["70452.40", "0.117"], ["70452.50", "0.042"], ["70452.60", "0.002"], ["70452.70", "0.021"], ["70452.80", "0.042"], ["70453.00", "0.003"], ["70453.10", "1.068"], ["70453.20", "0.007"], ["70453.60", "0.002"], ["70453.90", "0.245"], ["70454.30", "0.000"], ["70454.40", "0.342"], ["70454.60", "0.003"], ["70454.70", "0.038"], ["70454.80", "0.682"], ["70454.90", "0.039"], ["70455.00", "0.018"], ["70455.20", "0.293"], ["70455.30", "0.511"], ["70455.50", "0.286"], ["70455.90", "0.003"], ["70456.00", "0.016"], ["70456.10", "0.007"], ["70456.20", "0.680"], ["70456.50", "0.015"], ["70456.70", "0.033"], ["70456.80", "0.000"], ["70457.10", "0.017"], ["70457.20", "0.002"], ["70457.50", "0.002"], ["70457.70", "0.029"], ["70457.80", "0.160"], ["70458.40", "0.243"], ["70458.50", "0.005"], ["70458.80", "0.291"], ["70459.10", "0.000"], ["70459.20", "0.003"], ["70459.40", "0.011"], ["70459.50", "0.000"], ["70459.60", "0.003"], ["70459.90", "0.209"], ["70460.00", "0.022"], ["70460.10", "0.343"], ["70460.20", "0.399"], ["70460.30", "1.074"], ["70461.00", "0.372"], ["70461.10", "0.285"], ["70461.60", "0.216"], ["70461.80", "0.001"], ["70462.10", "0.005"], ["70462.50", "0.009"], ["70463.10", "0.509"], ["70463.20", "0.087"], ["70463.50", "0.000"], ["70464.70", "0.000"], ["70464.90", "0.004"], ["70465.90", "0.001"], ["70466.40", "0.108"], ["70466.70", "0.285"], ["70466.80", "0.002"], ["70467.70", "0.074"], ["70468.50", "0.002"], ["70469.30", "0.000"], ["70469.40", "0.000"], ["70469.50", "0.002"], ["70469.60", "0.000"], ["70470.00", "8.285"]], "a": [["70470.10", "9.269"], ["70470.20", "0.859"], ["70470.30", "0.002"], ["70470.40", "0.002"], ["70471.20", "0.000"], ["70471.30", "0.024"], ["70471.40", "0.050"], ["70471.50", "0.003"], ["70471.90", "0.003"], ["70472.00", "0.000"], ["70472.50", "0.008"], ["70473.40", "0.001"], ["70473.90", "0.005"], ["70474.10", "0.001"], ["70474.70", "0.001"], ["70475.00", "0.200"], ["70475.20", "1.158"], ["70475.30", "0.006"], ["70475.50", "0.005"], ["70475.70", "0.021"], ["70476.30", "0.005"], ["70476.40", "0.008"], ["70476.60", "0.000"], ["70476.70", "0.004"], ["70476.80", "0.002"], ["70477.00", "0.007"], ["70477.10", "0.005"], ["70477.20", "0.001"], ["70477.30", "0.002"], ["70477.40", "0.009"], ["70477.60", "0.024"], ["70477.90", "0.004"], ["70478.10", "0.022"], ["70478.20", "0.109"], ["70478.30", "0.001"], ["70478.40", "0.003"], ["70478.70", "0.003"], ["70478.80", "0.008"], ["70479.10", "0.000"], ["70479.30", "0.004"], ["70479.40", "0.344"], ["70479.50", "0.262"], ["70479.60", "0.002"], ["70479.80", "0.080"], ["70479.90", "0.512"], ["70480.00", "0.006"], ["70480.10", "0.234"], ["70480.20", "0.003"], ["70480.30", "0.001"], ["70480.40", "0.005"], ["70480.70", "0.000"], ["70480.90", "0.002"], ["70481.10", "0.060"], ["70481.50", "0.000"], ["70481.70", "0.021"], ["70481.90", "0.003"], ["70482.00", "0.000"], ["70482.10", "0.002"], ["70482.40", "0.213"], ["70482.50", "0.007"], ["70482.60", "0.025"], ["70482.70", "0.001"], ["70482.90", "0.000"], ["70483.00", "0.007"], ["70483.10", "0.000"], ["70483.30", "0.064"], ["70483.50", "0.000"], ["70483.60", "0.011"], ["70483.70", "0.029"], ["70483.80", "0.001"], ["70484.10", "0.040"], ["70484.30", "0.299"], ["70484.50", "0.002"], ["70484.60", "0.517"], ["70484.70", "0.009"], ["70485.10", "0.057"], ["70485.20", "0.012"], ["70485.60", "0.006"], ["70485.90", "0.020"], ["70486.10", "0.077"], ["70486.80", "0.542"], ["70487.00", "0.000"], ["70487.50", "0.000"], ["70488.00", "0.054"], ["70488.10", "0.003"], ["70488.20", "0.000"], ["70488.40", "0.079"], ["70488.90", "0.053"], ["70490.10", "0.007"], ["70490.50", "0.003"], ["70491.00", "0.037"], ["70491.70", "0.511"], ["70491.90", "0.004"], ["70492.10", "0.057"], ["70492.30", "0.060"], ["70492.60", "0.640"], ["70492.90", "0.003"], ["70493.00", "0.002"], ["70493.30", "0.020"], ["70493.80", "0.412"], ["70493.90", "0.769"], ["70494.20", "0.092"], ["70494.80", "0.000"], ["70495.60", "0.115"], ["70496.20", "0.510"], ["70497.30", "0.071"], ["70497.40", "0.248"], ["70497.50", "0.739"], ["70498.20", "0.013"], ["70498.70", "1.068"], ["70500.10", "0.133"], ["70500.40", "0.000"], ["70500.60", "0.012"], ["70501.10", "0.002"], ["70501.70", "0.003"], ["70503.20", "0.052"], ["70504.90", "0.017"], ["70505.80", "0.000"], ["70507.60", "0.546"], ["70509.50", "0.003"], ["70509.60", "0.193"], ["70509.80", "0.091"], ["70509.90", "0.185"], ["70510.20", "0.002"], ["70511.00", "0.051"], ["70513.10", "0.009"], ["70513.80", "0.000"], ["70513.90", "0.027"], ["70515.10", "0.603"], ["70515.20", "0.956"], ["70515.60", "0.000"], ["70515.90", "0.042"], ["70516.00", "0.368"], ["70518.70", "0.584"], ["70518.80", "0.887"], ["70520.60", "0.006"], ["70521.10", "0.019"], ["70521.50", "0.038"], ["70521.60", "0.703"], ["70521.80", "1.072"], ["70522.10", "0.010"], ["70522.50", "0.191"], ["70526.10", "0.000"], ["70526.50", "0.000"], ["70528.50", "1.092"], ["70528.60", "0.201"], ["70528.80", "0.000"], ["70532.00", "2.052"], ["70532.10", "8.511"], ["70532.20", "0.002"], ["70534.10", "0.010"], ["70534.20", "0.137"], ["70534.40", "0.156"], ["70537.00", "0.133"], ["70537.30", "0.111"], ["70538.20", "0.111"], ["70540.60", "0.087"], ["70541.20", "0.000"], ["70544.10", "0.265"], ["70544.50", "1.686"], ["70545.80", "0.102"], ["70554.70", "0.051"], ["70558.40", "0.007"], ["70569.60", "0.016"], ["70572.30", "0.211"], ["70575.50", "0.152"], ["70582.90", "2.000"], ["70583.70", "0.000"], ["70599.60", "0.032"], ["70610.40", "0.053"], ["70611.00", "2.063"], ["70611.90", "0.003"], ["70638.20", "0.243"], ["70640.10", "0.089"], ["70663.90", "0.162"], ["70667.40", "0.181"], ["70670.90", "0.159"], ["70674.50", "0.408"], ["70675.10", "0.000"], ["70681.40", "0.258"], ["70684.80", "0.000"], ["70694.90", "0.007"], ["70704.10", "0.004"], ["70748.80", "10.000"], ["70767.20", "0.294"], ["70771.20", "0.295"], ["70780.40", "0.000"], ["70784.60", "0.003"], ["70791.40", "0.000"], ["71174.80", "0.000"], ["71176.00", "0.002"], ["71283.80", "0.014"], ["71451.80", "0.000"], ["71493.20", "0.969"], ["71538.40", "0.037"], ["71640.90", "1.394"], ["71763.00", "0.029"], ["71879.50", "0.009"], ["89523.20", "0.000"], ["100000.00", "23.659"]]}}
{"local_ts": 1773485100271, "server_ts": 1773485099474, "data": {"e": "depthUpdate", "E": 1773485099475, "T": 1773485099474, "s": "BTCUSDT", "U": 10109431510166, "u": 10109431515378, "pu": 10109431510092, "b": [["1000.00", "28.692"], ["5000.00", "101.418"], ["7048.00", "0.028"], ["20079.70", "0.200"], ["20179.70", "0.940"], ["20271.30", "0.130"], ["33000.10", "0.007"], ["66939.80", "0.002"], ["66980.70", "0.002"], ["69774.90", "1.581"], ["69859.40", "0.000"], ["69869.10", "0.160"], ["70117.60", "0.301"], ["70137.50", "0.000"], ["70178.00", "0.000"], ["70321.10", "0.090"], ["70324.60", "0.043"], ["70359.20", "0.288"], ["70361.80", "0.069"], ["70379.20", "0.116"], ["70380.80", "0.000"], ["70381.50", "0.548"], ["70382.00", "0.223"], ["70384.20", "0.114"], ["70386.90", "0.114"], ["70388.50", "0.225"], ["70390.20", "0.344"], ["70391.40", "0.114"], ["70392.30", "0.114"], ["70393.60", "0.114"], ["70394.60", "0.218"], ["70395.80", "0.117"], ["70396.80", "0.144"], ["70397.80", "0.116"], ["70399.10", "0.114"], ["70399.40", "2.635"], ["70399.90", "0.000"], ["70400.00", "3.646"], ["70401.10", "0.114"], ["70430.10", "1.211"], ["70430.20", "0.828"], ["70437.60", "0.037"], ["70438.70", "0.400"], ["70441.70", "0.002"], ["70445.70", "0.213"], ["70449.60", "0.090"], ["70451.00", "0.148"], ["70459.00", "1.206"], ["70460.30", "1.069"], ["70460.50", "0.003"], ["70462.90", "0.291"], ["70463.80", "0.005"], ["70465.60", "0.008"], ["70470.00", "4.988"], ["70479.10", "0.135"], ["70479.20", "0.057"], ["70479.30", "0.128"], ["70479.40", "0.058"], ["70479.50", "0.004"], ["70479.70", "10.449"]], "a": [["70479.80", "1.645"], ["70479.90", "0.001"], ["70490.90", "0.026"], ["70492.50", "0.005"], ["70493.40", "0.059"], ["70497.50", "0.025"], ["70497.80", "0.002"], ["70498.20", "0.010"], ["70500.00", "0.552"], ["70500.10", "0.080"], ["70500.90", "0.000"], ["70502.10", "0.071"], ["70504.50", "0.083"], ["70509.70", "0.000"], ["70510.00", "0.047"], ["70516.50", "0.535"], ["70528.40", "0.052"], ["70549.90", "0.461"], ["70557.10", "2.651"], ["70578.90", "0.605"], ["70599.30", "0.245"], ["70613.80", "0.041"], ["70714.00", "0.262"], ["70735.10", "0.211"], ["70744.90", "0.712"], ["70805.30", "0.002"], ["70842.60", "2.821"], ["71184.50", "0.007"], ["71184.60", "0.030"], ["71515.90", "1.256"], ["72029.60", "0.000"], ["73237.10", "0.020"], ["74024.30", "0.000"], ["89523.20", "0.000"]]}}
{"local_ts": 1773485101295, "server_ts": 1773485100495, "data": {"e": "depthUpdate", "E": 1773485100497, "T": 1773485100495, "s": "BTCUSDT", "U": 10109431586908, "u": 10109431591366, "pu": 10109431586655, "b": [["5000.00", "101.418"], ["7048.00", "0.028"], ["19979.70", "0.050"], ["20079.70", "2.320"], ["20170.00", "0.540"], ["20174.60", "0.000"], ["20175.20", "0.000"], ["20177.80", "0.000"], ["20179.70", "0.000"], ["69162.10", "0.000"], ["69377.70", "1.008"], ["69457.70", "1.150"], ["69656.40", "3.731"], ["69774.90", "1.581"], ["69938.40", "0.143"], ["70300.00", "20.681"], ["70403.80", "0.076"], ["70403.90", "0.000"], ["70409.20", "0.866"], ["70430.70", "0.517"], ["70430.90", "0.000"], ["70438.80", "0.031"], ["70444.00", "0.002"], ["70444.50", "0.091"], ["70445.60", "0.041"], ["70450.50", "0.000"], ["70454.90", "0.041"], ["70459.70", "0.008"], ["70459.90", "0.209"], ["70460.10", "0.354"], ["70460.30", "1.076"], ["70461.90", "0.150"], ["70469.20", "0.001"], ["70470.60", "0.297"], ["70472.30", "0.000"], ["70472.70", "0.042"], ["70478.20", "0.004"], ["70478.60", "0.015"], ["70478.90", "0.059"]], "a": [["70479.80", "3.395"], ["70479.90", "0.001"], ["70481.30", "0.001"], ["70483.40", "0.016"], ["70484.40", "0.003"], ["70484.50", "0.000"], ["70484.90", "1.421"], ["70491.50", "0.006"], ["70493.20", "0.000"], ["70493.30", "0.020"], ["70493.60", "0.018"], ["70493.80", "0.004"], ["70493.90", "0.048"], ["70494.10", "0.003"], ["70494.20", "0.005"], ["70494.60", "0.002"], ["70494.90", "0.002"], ["70495.30", "0.005"], ["70496.80", "0.002"], ["70500.80", "0.000"], ["70501.20", "0.056"], ["70507.80", "0.029"], ["70511.90", "0.000"], ["70514.00", "0.010"], ["70517.40", "0.053"], ["70525.50", "0.007"], ["70530.10", "0.025"], ["70545.50", "0.042"], ["70577.80", "0.000"], ["70578.40", "0.107"], ["70618.60", "0.003"], ["70644.80", "0.000"], ["70703.20", "0.000"], ["70744.80", "0.007"], ["70822.50", "0.508"], ["71184.60", "0.154"], ["74026.30", "0.000"], ["89523.20", "0.000"], ["100000.00", "23.659"]]}}
{"local_ts": 1773485102319, "server_ts": 1773485101517, "data": {"e": "depthUpdate", "E": 1773485101519, "T": 1773485101517, "s": "BTCUSDT", "U": 10109431648614, "u": 10109431653614, "pu": 10109431648583, "b": [["1000.00", "28.692"], ["5000.00", "101.438"], ["7048.00", "0.028"], ["19979.70", "1.980"], ["20079.70", "1.020"], ["56384.00", "0.004"], ["66943.50", "0.000"], ["68239.50", "1.000"], ["69090.00", "3.692"], ["69361.40", "0.617"], ["69604.90", "1.433"], ["69774.90", "1.581"], ["70127.30", "3.313"], ["70234.10", "0.004"], ["70430.80", "0.844"], ["70430.90", "0.085"], ["70445.60", "0.003"], ["70448.30", "0.003"], ["70476.00", "0.023"]], "a": [["70481.20", "0.015"], ["70482.20", "0.001"], ["70483.00", "0.013"], ["70483.50", "0.000"], ["70484.80", "0.000"], ["70485.10", "0.121"], ["70485.80", "0.012"], ["70485.90", "0.021"], ["70504.90", "1.030"], ["70505.90", "0.010"], ["70506.10", "0.154"], ["70508.00", "0.000"], ["70522.20", "0.003"], ["70600.10", "2.674"], ["70614.50", "0.000"], ["71184.60", "0.030"], ["71465.90", "0.247"], ["71800.00", "146.207"], ["71910.10", "0.006"], ["72554.80", "0.000"], ["74005.20", "0.039"], ["76249.90", "0.002"], ["89523.20", "0.000"]]}}
{"local_ts": 1773485103333, "server_ts": 1773485102536, "data": {"e": "depthUpdate", "E": 1773485102539, "T": 1773485102536, "s": "BTCUSDT", "U": 10109431797571, "u": 10109431802911, "pu": 10109431797542, "b": [["1000.00", "28.692"], ["5000.00", "101.418"], ["7049.50", "0.000"], ["19979.70", "1.370"], ["19981.80", "0.000"], ["19986.40", "0.000"], ["19988.40", "0.010"], ["19990.20", "0.050"], ["19993.80", "0.000"], ["19994.80", "0.000"], ["19994.90", "0.000"], ["20394.90", "1.420"], ["56384.00", "0.000"], ["69790.00", "0.113"], ["69931.20", "5.355"], ["70187.50", "0.010"], ["70248.60", "0.006"], ["70367.10", "0.000"], ["70388.40", "4.784"], ["70388.50", "0.345"], ["70409.60", "1.004"], ["70442.00", "0.001"], ["70442.30", "0.329"], ["70487.80", "0.008"], ["70492.50", "0.084"], ["70492.60", "0.007"], ["70494.70", "0.007"], ["70494.90", "112.462"]], "a": [["70495.00", "5.672"], ["70495.10", "0.003"], ["70504.10", "0.058"], ["70504.20", "0.013"], ["70505.10", "0.197"], ["70505.60", "0.005"], ["70507.10", "0.009"], ["70508.60", "0.000"], ["70508.70", "0.000"], ["70508.90", "0.021"], ["70509.80", "0.011"], ["70511.80", "0.024"], ["70512.40", "0.000"], ["70514.20", "0.210"], ["70515.20", "0.114"], ["70515.70", "0.002"], ["70516.60", "0.002"], ["70516.90", "0.067"], ["70518.00", "0.078"], ["70527.00", "0.026"], ["70529.00", "0.024"], ["70535.70", "0.000"], ["70546.90", "0.006"], ["70913.20", "0.144"], ["71064.00", "0.564"], ["71199.90", "0.701"], ["71663.20", "1.981"], ["71904.80", "0.016"], ["74034.60", "0.096"], ["74051.90", "0.013"], ["89523.20", "0.000"]]}}
{"local_ts": 1773485104360, "server_ts": 1773485103561, "data": {"e": "depthUpdate", "E": 1773485103563, "T": 1773485103561, "s": "BTCUSDT", "U": 10109431845776, "u": 10109431849093, "pu": 10109431845729, "b": [["5000.00", "101.398"], ["7049.50", "0.000"], ["20294.90", "1.090"], ["20394.90", "1.800"], ["33000.00", "3.785"], ["56384.00", "0.000"], ["66947.30", "0.000"], ["66959.50", "0.002"], ["68245.30", "0.002"], ["69790.00", "0.113"], ["69790.10", "3.409"], ["69930.90", "0.218"], ["70222.20", "0.012"], ["70342.20", "0.000"], ["70365.90", "0.002"], ["70410.50", "0.000"], ["70423.40", "0.841"], ["70443.00", "0.303"], ["70443.30", "0.004"], ["70459.70", "0.016"], ["70469.70", "0.259"], ["70470.20", "0.002"], ["70484.10", "0.638"], ["70484.80", "0.015"]], "a": [["70718.60", "0.009"], ["71199.90", "0.701"], ["71693.40", "0.279"], ["71712.00", "2.587"], ["89523.20", "0.000"]]}}
{"local_ts": 1773485105375, "server_ts": 1773485104581, "data": {"e": "depthUpdate", "E": 1773485104583, "T": 1773485104581, "s": "BTCUSDT", "U": 10109431886694, "u": 10109431890818, "pu": 10109431886658, "b": [["1000.00", "28.692"], ["5000.00", "101.418"], ["7049.50", "0.000"], ["20194.90", "0.640"], ["20294.90", "2.360"], ["20394.90", "0.000"], ["56396.00", "0.002"], ["66937.10", "0.002"], ["69194.70", "0.620"], ["69424.60", "0.002"], ["69472.70", "3.032"], ["69649.00", "1.291"], ["69790.00", "0.113"], ["69790.10", "3.409"], ["69839.30", "0.000"], ["69864.00", "0.036"], ["70013.90", "2.388"], ["70038.70", "0.008"], ["70142.40", "0.000"], ["70188.90", "0.000"], ["70213.80", "1.564"], ["70248.60", "0.002"], ["70343.70", "0.004"], ["70345.90", "0.180"], ["70362.30", "0.639"], ["70409.60", "1.000"], ["70443.10", "0.121"], ["70443.40", "0.007"], ["70460.00", "0.024"], ["70466.60", "0.000"], ["70480.70", "0.083"], ["70494.90", "111.863"]], "a": [["70500.50", "0.007"], ["70501.60", "1.420"], ["70501.70", "0.011"], ["70501.80", "0.003"], ["70501.90", "0.003"], ["70503.10", "0.001"], ["70503.20", "0.215"], ["70504.70", "0.005"], ["70506.00", "0.049"], ["70509.60", "0.515"], ["70510.40", "0.026"], ["70514.00", "0.105"], ["70515.30", "0.085"], ["70516.50", "0.533"], ["70521.50", "0.880"], ["70527.80", "0.052"], ["70546.90", "0.002"], ["70627.10", "0.639"], ["70752.10", "0.000"], ["70777.10", "0.004"], ["70929.00", "0.004"], ["70954.00", "0.008"], ["71106.30", "0.000"], ["71131.40", "0.016"], ["71199.90", "0.701"], ["71592.70", "0.000"], ["77544.50", "0.016"], ["89523.20", "0.000"]]}}
{"local_ts": 1773485106406, "server_ts": 1773485105606, "data": {"e": "depthUpdate", "E": 1773485105607, "T": 1773485105606, "s": "BTCUSDT", "U": 10109431949436, "u": 10109431957955, "pu": 10109431949199, "b": [["5000.00", "101.418"], ["7049.50", "0.056"], ["20094.90", "0.310"], ["20194.90", "2.580"], ["20294.90", "0.110"], ["33000.00", "3.789"], ["56396.00", "0.002"], ["66948.50", "0.000"], ["66980.70", "0.000"], ["69422.80", "0.000"], ["69790.00", "7.288"], ["70328.40", "13.381"], ["70329.00", "3.017"], ["70329.20", "0.000"], ["70332.80", "0.159"], ["70343.70", "0.002"], ["70349.70", "0.044"], ["70357.40", "0.002"], ["70363.60", "0.300"], ["70368.40", "0.004"], ["70392.80", "7.038"], ["70401.80", "0.157"], ["70417.30", "0.019"], ["70431.40", "0.095"], ["70432.90", "3.773"], ["70443.10", "0.123"], ["70443.40", "0.005"], ["70448.90", "0.002"], ["70454.70", "0.000"], ["70458.50", "2.004"], ["70479.40", "0.222"], ["70484.20", "0.094"], ["70490.10", "0.003"], ["70494.90", "112.473"]], "a": [["70495.70", "0.002"], ["70500.60", "0.003"], ["70501.20", "0.063"], ["70503.50", "0.001"], ["70504.70", "0.375"], ["70504.90", "0.003"], ["70508.10", "0.025"], ["70508.80", "0.063"], ["70509.20", "0.025"], ["70509.50", "1.216"], ["70513.90", "0.017"], ["70521.50", "0.880"], ["70525.80", "0.253"], ["70528.40", "0.003"], ["70535.70", "0.002"], ["70541.00", "2.006"], ["70558.50", "0.005"], ["70566.70", "3.995"], ["70572.60", "0.045"], ["70590.40", "0.025"], ["70590.70", "0.236"], ["70591.10", "0.181"], ["70591.50", "0.025"], ["70591.80", "0.000"], ["70592.10", "0.149"], ["70594.30", "0.084"], ["70594.50", "0.014"], ["70594.60", "0.071"], ["70599.30", "0.281"], ["70605.80", "0.003"], ["70607.30", "7.392"], ["70673.10", "14.055"], ["70900.00", "14.569"], ["71059.00", "0.358"], ["71199.90", "0.841"], ["71340.90", "1.273"], ["71411.40", "0.939"], ["89523.20", "0.000"]]}}
{"local_ts": 1773485107420, "server_ts": 1773485106624, "data": {"e": "depthUpdate", "E": 1773485106627, "T": 1773485106624, "s": "BTCUSDT", "U": 10109432006201, "u": 10109432011586, "pu": 10109432006114, "b": [["1000.00", "28.692"], ["5000.00", "101.418"], ["7049.50", "0.056"], ["19994.90", "0.160"], ["20094.90", "2.430"], ["20194.90", "0.410"], ["56396.00", "0.002"], ["69790.00", "0.113"], ["70142.40", "0.000"], ["70349.70", "0.042"], ["70355.10", "0.002"], ["70405.00", "0.023"], ["70408.70", "0.043"], ["70411.90", "0.002"], ["70416.20", "0.077"]], "a": [["70495.00", "1.275"], ["70505.50", "0.002"], ["70512.30", "0.060"], ["70535.70", "0.000"], ["70536.80", "0.004"], ["70546.00", "1.260"], ["70550.20", "0.028"], ["70561.40", "0.701"], ["70583.10", "0.511"], ["70625.50", "0.215"], ["74036.30", "0.002"], ["89523.20", "0.000"]]}}
{"local_ts": 1773485108445, "server_ts": 1773485107648, "data": {"e": "depthUpdate", "E": 1773485107649, "T": 1773485107648, "s": "BTCUSDT", "U": 10109432064265, "u": 10109432070256, "pu": 10109432064089, "b": [["1000.00", "28.692"], ["5000.00", "101.418"], ["7049.50", "0.056"], ["19994.90", "2.290"], ["20094.90", "0.700"], ["20394.90", "0.010"], ["33000.00", "3.789"], ["66970.20", "40.010"], ["69515.00", "1.032"], ["69790.00", "0.113"], ["69790.10", "3.405"], ["69790.20", "1.449"], ["70248.80", "0.054"], ["70348.70", "0.420"], ["70354.40", "0.002"], ["70355.10", "0.000"], ["70463.90", "0.005"], ["70464.00", "0.072"], ["70494.90", "111.982"]], "a": [["70495.00", "1.237"], ["70500.50", "0.009"], ["70505.30", "0.003"], ["70505.60", "0.002"], ["70506.50", "0.001"], ["70506.80", "0.018"], ["70513.40", "0.002"], ["70524.10", "0.005"], ["70536.00", "0.106"], ["70536.80", "0.002"], ["70612.30", "0.126"], ["70625.50", "0.215"], ["70718.60", "0.009"], ["71199.90", "2.245"], ["71376.10", "0.000"], ["71587.70", "6.277"], ["71782.60", "1.393"], ["71904.80", "0.022"], ["74051.40", "0.002"]]}}
{"local_ts": 1773485109462, "server_ts": 1773485108668, "data": {"e": "depthUpdate", "E": 1773485108669, "T": 1773485108668, "s": "BTCUSDT", "U": 10109432120226, "u": 10109432125571, "pu": 10109432120071, "b": [["5000.00", "101.398"], ["7049.50", "0.028"], ["19994.90", "1.140"], ["20394.90", "1.860"], ["66940.50", "0.002"], ["69426.40", "0.862"], ["69790.00", "0.113"], ["69966.30", "0.000"], ["70248.60", "0.006"], ["70248.90", "0.000"], ["70354.00", "0.002"], ["70354.40", "0.000"]], "a": [["70501.90", "0.005"], ["70516.20", "0.008"], ["70536.00", "0.104"], ["70536.90", "0.608"], ["71199.90", "2.243"], ["73873.70", "0.002"]]}}
{"local_ts": 1773485110489, "server_ts": 1773485109690, "data": {"e": "depthUpdate", "E": 1773485109693, "T": 1773485109690, "s": "BTCUSDT", "U": 10109432168747, "u": 10109432173275, "pu": 10109432168618, "b": [["1000.00", "28.692"], ["5000.00", "101.418"], ["7049.50", "0.028"], ["20294.90", "1.410"], ["20394.90", "1.590"], ["66952.90", "0.000"], ["69418.90", "1.443"], ["69458.50", "3.291"], ["69493.90", "2.438"], ["69790.00", "0.113"], ["70142.40", "0.570"], ["70330.30", "0.107"], ["70332.80", "0.276"], ["70334.70", "0.405"], ["70363.10", "0.678"], ["70403.40", "0.496"], ["70405.80", "0.000"], ["70444.00", "0.075"], ["70444.20", "0.006"], ["70469.80", "0.002"], ["70494.90", "113.542"]], "a": [["70495.00", "1.634"], ["70500.50", "0.011"], ["70502.20", "0.000"], ["70508.30", "0.000"], ["70518.60", "0.188"], ["70519.00", "0.091"], ["70628.60", "0.576"], ["70628.70", "0.041"], ["71199.90", "2.243"], ["71749.20", "0.000"], ["74026.60", "0.002"]]}}
{"local_ts": 1773485111508, "server_ts": 1773485110712, "data": {"e": "depthUpdate", "E": 1773485110713, "T": 1773485110712, "s": "BTCUSDT", "U": 10109432217126, "u": 10109432221212, "pu": 10109432216993, "b": [["5000.00", "101.418"], ["7049.50", "0.028"], ["20194.90", "0.960"], ["20294.90", "2.040"], ["56396.00", "0.002"], ["66969.30", "0.000"], ["68962.90", "0.621"], ["69331.70", "3.033"], ["69402.20", "1.007"], ["69790.00", "0.113"], ["70277.20", "0.000"], ["70403.40", "0.312"], ["70452.10", "0.000"], ["70452.50", "0.171"], ["70479.10", "0.014"], ["70479.80", "0.000"], ["70481.40", "0.009"], ["70486.60", "0.383"], ["70492.40", "0.179"], ["70492.70", "0.000"], ["70494.90", "113.435"]], "a": [["70495.00", "3.917"], ["70501.10", "0.076"], ["70503.50", "1.421"], ["70503.60", "0.054"], ["70503.90", "0.004"], ["70504.00", "0.006"], ["70506.10", "0.002"], ["70508.40", "0.086"], ["70510.80", "0.000"], ["70514.00", "0.189"], ["70518.60", "0.004"], ["70525.70", "0.007"], ["70529.60", "0.002"], ["70530.20", "0.287"], ["70616.80", "2.586"], ["70619.30", "0.113"], ["70622.70", "0.450"], ["70678.30", "0.099"], ["70695.00", "0.214"], ["70711.70", "0.035"], ["70718.60", "0.009"], ["71199.70", "0.016"], ["71199.90", "2.245"], ["71517.20", "16.636"]]}}
{"local_ts": 1773485112529, "server_ts": 1773485111732, "data": {"e": "depthUpdate", "E": 1773485111733, "T": 1773485111732, "s": "BTCUSDT", "U": 10109432260645, "u": 10109432264619, "pu": 10109432260634, "b": [["1000.00", "28.692"], ["5000.00", "101.418"], ["7049.50", "0.028"], ["20094.90", "0.520"], ["20194.90", "2.480"], ["20294.90", "0.000"], ["66954.80", "0.004"], ["68898.50", "0.000"], ["69081.80", "0.527"], ["69099.90", "0.008"], ["69160.10", "1.678"], ["69178.20", "0.353"], ["69238.40", "0.384"], ["69256.60", "0.000"], ["69316.70", "0.380"], ["69334.90", "0.617"], ["69395.10", "0.380"], ["69413.30", "0.000"], ["69422.60", "0.000"], ["69473.40", "0.382"], ["69491.60", "0.000"], ["69551.70", "0.385"], ["69570.00", "0.847"], ["69648.30", "0.025"], ["69726.70", "0.002"], ["69790.00", "0.828"], ["69805.00", "0.022"], ["70142.40", "0.570"], ["70248.70", "0.010"], ["70332.80", "0.276"], ["70443.80", "0.065"], ["70444.20", "0.006"], ["70445.30", "0.099"], ["70452.40", "0.862"], ["70452.50", "0.086"], ["70455.30", "0.515"], ["70459.70", "0.016"], ["70462.40", "0.328"], ["70466.60", "0.053"], ["70480.70", "0.026"], ["70487.70", "0.237"], ["70487.80", "0.105"], ["70490.00", "0.111"], ["70490.10", "0.003"], ["70491.70", "0.007"], ["70492.10", "0.004"], ["70492.40", "0.018"], ["70493.90", "0.129"], ["70494.90", "112.362"]], "a": [["70495.00", "5.285"], ["70499.00", "0.407"], ["70499.60", "0.183"], ["70500.80", "0.005"], ["70501.10", "0.076"], ["70501.90", "0.005"], ["70502.00", "0.018"], ["70502.10", "0.002"], ["70503.00", "0.004"], ["70503.10", "0.524"], ["70504.10", "0.099"], ["70505.50", "0.024"], ["70506.70", "0.048"], ["70507.30", "0.347"], ["70507.50", "0.011"], ["70507.60", "0.301"], ["70507.80", "0.037"], ["70508.50", "0.025"], ["70508.80", "0.556"], ["70514.00", "0.012"], ["70514.50", "0.006"], ["70516.60", "0.004"], ["70518.20", "0.187"], ["70584.60", "11.206"], ["70586.40", "0.002"], ["70689.50", "0.002"], ["70695.00", "0.212"], ["71023.70", "0.703"], ["71199.90", "2.243"], ["71215.20", "0.000"], ["71293.50", "0.000"], ["71371.90", "0.000"], ["71450.20", "0.000"], ["71528.60", "0.000"], ["71562.80", "0.767"], ["71606.90", "0.000"], ["71685.30", "0.000"], ["71763.60", "0.039"], ["71842.00", "0.002"], ["71920.30", "0.005"], ["74033.50", "0.000"]]}}
{"local_ts": 1773485113553, "server_ts": 1773485112756, "data": {"e": "depthUpdate", "E": 1773485112757, "T": 1773485112756, "s": "BTCUSDT", "U": 10109432321001, "u": 10109432325327, "pu": 10109432320882, "b": [["1000.00", "28.692"], ["5000.00", "101.398"], ["7049.50", "0.000"], ["19994.90", "0.260"], ["20094.90", "2.550"], ["20194.90", "0.190"], ["33000.00", "3.785"], ["66939.30", "0.000"], ["69208.90", "0.025"], ["69385.80", "0.619"], ["69790.00", "0.828"], ["70280.30", "0.000"], ["70323.10", "0.000"], ["70350.80", "0.078"], ["70359.20", "0.184"], ["70362.00", "0.000"], ["70386.50", "0.294"], ["70388.60", "0.000"], ["70388.90", "0.006"], ["70394.00", "0.003"], ["70397.70", "0.000"], ["70400.10", "0.342"], ["70400.50", "0.000"], ["70400.80", "0.307"], ["70401.20", "0.288"], ["70401.60", "2.361"], ["70401.90", "0.000"], ["70417.80", "0.092"], ["70420.00", "0.888"], ["70421.50", "0.002"], ["70425.30", "0.157"], ["70427.50", "0.544"], ["70428.40", "0.164"], ["70429.00", "0.004"], ["70429.30", "0.002"], ["70429.60", "0.002"], ["70429.70", "0.387"], ["70430.00", "0.893"], ["70430.10", "1.070"], ["70430.40", "0.342"], ["70430.80", "0.842"], ["70443.40", "0.005"], ["70443.50", "0.344"], ["70445.60", "0.004"], ["70452.40", "0.842"], ["70454.70", "0.003"], ["70455.30", "0.515"], ["70460.80", "0.034"], ["70464.10", "0.002"], ["70464.60", "0.005"], ["70467.50", "0.020"], ["70473.20", "0.293"], ["70476.10", "0.049"], ["70477.30", "0.513"], ["70482.90", "0.638"], ["70483.90", "0.000"], ["70484.90", "0.123"], ["70485.50", "0.002"], ["70486.70", "0.000"], ["70487.00", "0.022"], ["70487.10", "0.007"], ["70487.40", "0.002"], ["70487.70", "0.413"], ["70487.80", "0.005"], ["70488.10", "0.003"], ["70488.50", "0.011"], ["70489.10", "0.081"], ["70490.00", "0.126"], ["70491.70", "0.015"], ["70492.60", "0.064"], ["70493.10", "0.019"], ["70493.40", "0.000"], ["70494.70", "0.082"], ["70494.90", "108.342"]], "a": [["70495.00", "5.958"], ["70495.20", "0.002"], ["70495.30", "0.360"], ["70495.40", "2.195"], ["70495.50", "0.003"], ["70495.70", "0.017"], ["70499.20", "0.002"], ["70499.40", "0.000"], ["70500.70", "0.002"], ["70501.20", "1.423"], ["70503.20", "0.213"], ["70504.50", "0.004"], ["70505.60", "0.002"], ["70506.10", "0.004"], ["70506.70", "0.120"], ["70508.00", "0.007"], ["70508.40", "0.004"], ["70508.60", "1.066"], ["70508.70", "0.000"], ["70509.10", "0.002"], ["70509.40", "0.212"], ["70509.80", "0.011"], ["70512.90", "0.000"], ["70516.00", "0.224"], ["70516.10", "1.261"], ["70516.80", "0.292"], ["70517.00", "0.000"], ["70518.20", "0.003"], ["70518.40", "0.325"], ["70523.60", "0.005"], ["70536.50", "0.040"], ["70536.90", "0.581"], ["70537.20", "0.500"], ["70537.60", "0.000"], ["70537.90", "0.000"], ["70538.00", "0.023"], ["70538.30", "0.002"], ["70538.60", "0.002"], ["70539.20", "0.002"], ["70539.50", "0.004"], ["70540.20", "0.057"], ["70542.40", "0.088"], ["70543.00", "0.002"], ["70562.00", "0.081"], ["70565.20", "0.000"], ["70565.70", "0.000"], ["70566.10", "0.000"], ["70566.40", "0.018"], ["70566.80", "0.000"], ["70567.10", "0.049"], ["70567.50", "0.002"], ["70569.00", "0.003"], ["70571.30", "0.002"], ["70573.70", "0.090"], ["70575.00", "0.259"], ["70576.50", "0.000"], ["70584.60", "11.204"], ["70605.20", "0.108"], ["70610.70", "0.000"], ["70638.80", "0.004"], ["70661.00", "0.002"], ["70669.90", "0.000"], ["70689.50", "0.000"], ["70731.50", "0.010"], ["70766.50", "0.783"], ["71199.80", "0.007"], ["71199.90", "2.243"], ["71481.90", "0.584"], ["71496.00", "1.482"], ["71904.80", "0.022"], ["74019.80", "0.006"]]}}
{"local_ts": 1773485114575, "server_ts": 1773485113779, "data": {"e": "depthUpdate", "E": 1773485113781, "T": 1773485113779, "s": "BTCUSDT", "U": 10109432358848, "u": 10109432361936, "pu": 10109432358780, "b": [["5000.00", "101.398"], ["7049.50", "0.000"], ["19994.90", "2.390"], ["20094.90", "0.490"], ["20394.90", "0.120"], ["66939.50", "0.000"], ["66939.60", "0.002"], ["69281.80", "0.002"], ["69305.30", "0.000"], ["69472.70", "12.661"], ["69790.00", "0.828"], ["70249.00", "0.034"], ["70312.00", "0.019"], ["70312.80", "0.002"], ["70332.80", "0.276"], ["70339.80", "0.303"], ["70444.00", "0.075"], ["70444.20", "0.006"], ["70459.70", "0.016"], ["70465.20", "0.024"], ["70465.30", "0.573"], ["70476.00", "1.230"], ["70476.90", "0.004"], ["70490.10", "0.010"], ["70490.60", "0.000"], ["70491.70", "0.015"]], "a": [["70495.00", "6.364"], ["70495.30", "0.360"], ["70495.40", "2.195"], ["70509.00", "0.041"], ["70518.40", "0.141"], ["70571.30", "0.000"], ["70575.00", "0.261"], ["70638.80", "0.002"], ["70650.00", "1.325"], ["70652.40", "0.002"], ["71046.90", "0.025"], ["71059.80", "1.855"], ["71199.90", "2.243"], ["71249.90", "3.243"], ["72257.40", "0.276"]]}}
{"local_ts": 1773485115595, "server_ts": 1773485114802, "data": {"e": "depthUpdate", "E": 1773485114803, "T": 1773485114802, "s": "BTCUSDT", "U": 10109432394609, "u": 10109432397898, "pu": 10109432394537, "b": [["1000.00", "28.842"], ["5000.00", "101.418"], ["7049.50", "0.056"], ["19994.90", "0.810"], ["20394.90", "2.190"], ["33000.00", "3.789"], ["56396.00", "0.002"], ["66959.20", "0.002"], ["68363.70", "0.626"], ["69493.90", "2.724"], ["69790.00", "0.828"], ["69800.00", "88.006"], ["69930.90", "0.289"], ["70142.40", "0.712"], ["70269.30", "0.239"], ["70312.80", "0.000"], ["70316.30", "0.002"], ["70444.00", "0.073"], ["70444.20", "0.008"], ["70483.20", "0.000"], ["70484.30", "0.088"], ["70487.90", "0.034"], ["70492.50", "0.002"], ["70492.70", "0.000"], ["70494.30", "0.015"], ["70494.60", "0.139"], ["70494.80", "0.069"]], "a": [["70495.00", "5.747"], ["70495.40", "2.195"], ["70496.60", "0.227"], ["70496.80", "0.002"], ["70502.00", "0.018"], ["70502.60", "0.056"], ["70504.40", "0.004"], ["70505.60", "0.032"], ["70518.60", "0.004"], ["70561.40", "0.702"], ["70566.90", "0.002"], ["70575.00", "0.259"], ["70584.80", "0.004"], ["70652.40", "0.000"], ["70674.80", "0.003"], ["70691.80", "0.004"], ["70720.50", "0.022"], ["71054.60", "3.256"], ["71059.80", "1.207"], ["71199.90", "2.243"], ["71496.00", "1.760"], ["71572.10", "0.970"]]}}
{"local_ts": 1773485116617, "server_ts": 1773485115824, "data": {"e": "depthUpdate", "E": 1773485115825, "T": 1773485115824, "s": "BTCUSDT", "U": 10109432433596, "u": 10109432437393, "pu": 10109432433490, "b": [["5000.00", "101.418"], ["7049.50", "0.056"], ["20294.90", "1.750"], ["20394.90", "1.250"], ["66939.40", "0.000"], ["69543.20", "1.076"], ["69790.00", "0.828"], ["70310.10", "0.002"], ["70316.30", "0.000"], ["70332.80", "0.276"], ["70360.40", "7.657"], ["70364.20", "0.096"], ["70459.70", "0.044"], ["70470.70", "0.000"], ["70487.90", "0.006"], ["70494.80", "0.012"], ["70494.90", "106.319"]], "a": [["70495.00", "5.409"], ["70502.00", "0.018"], ["70503.90", "0.007"], ["70504.10", "0.200"], ["70518.60", "0.188"], ["70519.30", "0.006"], ["70557.90", "0.002"], ["70566.90", "0.000"], ["70577.60", "0.002"], ["70584.80", "0.002"], ["70627.00", "8.328"], ["70630.80", "0.000"], ["70718.80", "0.003"], ["71199.90", "2.243"], ["71702.00", "0.279"], ["74021.50", "0.032"]]}}
{"local_ts": 1773485117639, "server_ts": 1773485116846, "data": {"e": "depthUpdate", "E": 1773485116847, "T": 1773485116846, "s": "BTCUSDT", "U": 10109432468729, "u": 10109432471888, "pu": 10109432468648, "b": [["1000.00", "28.692"], ["5000.00", "101.418"], ["7049.50", "0.056"], ["20194.90", "1.300"], ["20294.90", "1.700"], ["63445.40", "0.034"], ["66970.00", "0.002"], ["66970.30", "0.010"], ["69158.30", "4.332"], ["69578.50", "3.444"], ["69790.00", "0.828"], ["70142.40", "0.712"], ["70279.90", "0.004"], ["70283.10", "0.002"], ["70310.10", "0.000"], ["70313.50", "0.028"], ["70333.80", "0.045"], ["70431.40", "0.095"], ["70442.40", "0.002"], ["70442.70", "0.001"], ["70487.10", "0.009"], ["70488.80", "0.023"], ["70489.00", "0.004"], ["70492.30", "0.017"]], "a": [["70496.10", "0.003"], ["70500.90", "0.000"], ["70501.00", "0.006"], ["70501.60", "1.420"], ["70507.70", "0.004"], ["70518.50", "0.000"], ["70557.90", "0.000"], ["70563.20", "0.091"], ["70718.50", "0.000"], ["71199.80", "0.007"], ["71199.90", "2.243"], ["71238.10", "0.000"], ["71238.30", "0.915"], ["73314.70", "0.042"], ["74049.80", "0.002"], ["77544.50", "0.034"]]}}
{"local_ts": 1773485118660, "server_ts": 1773485117866, "data": {"e": "depthUpdate", "E": 1773485117867, "T": 1773485117866, "s": "BTCUSDT", "U": 10109432507520, "u": 10109432512106, "pu": 10109432507517, "b": [["1000.00", "28.692"], ["5000.00", "101.438"], ["7049.50", "0.028"], ["20094.90", "0.850"], ["20194.90", "2.150"], ["52000.00", "53.744"], ["56396.00", "0.002"], ["63445.40", "0.034"], ["66970.00", "0.002"], ["69074.60", "1.734"], ["69790.00", "0.828"], ["70313.50", "0.026"], ["70332.80", "0.276"], ["70384.30", "0.002"], ["70386.70", "0.004"], ["70395.50", "0.094"], ["70398.00", "0.019"], ["70398.30", "0.000"], ["70398.60", "1.441"], ["70398.70", "0.018"], ["70399.00", "0.004"], ["70399.40", "2.626"], ["70399.70", "0.006"], ["70417.80", "0.031"], ["70417.90", "0.063"], ["70419.30", "0.055"], ["70419.40", "0.061"], ["70425.30", "0.103"], ["70425.40", "1.295"], ["70426.80", "0.258"], ["70426.90", "0.359"], ["70427.20", "0.906"], ["70427.50", "4.217"], ["70427.60", "0.058"], ["70427.90", "0.057"], ["70428.20", "0.014"], ["70428.30", "0.039"], ["70428.60", "0.002"], ["70468.90", "0.003"], ["70469.70", "0.011"], ["70470.10", "0.591"], ["70472.90", "0.000"], ["70473.90", "0.078"], ["70474.90", "0.042"], ["70475.60", "0.010"], ["70476.60", "0.000"], ["70484.50", "0.001"], ["70484.60", "0.394"], ["70484.90", "0.188"], ["70485.20", "0.003"], ["70485.30", "0.058"], ["70485.60", "0.061"], ["70485.90", "0.343"], ["70486.00", "0.059"], ["70486.30", "0.003"], ["70487.60", "0.039"], ["70492.00", "0.000"], ["70492.10", "0.004"], ["70492.90", "0.074"]], "a": [["70498.60", "0.011"], ["70498.90", "0.190"], ["70503.70", "0.022"], ["70505.30", "0.000"], ["70505.40", "0.028"], ["70505.60", "0.004"], ["70505.70", "0.050"], ["70506.00", "0.049"], ["70506.10", "0.038"], ["70506.30", "0.005"], ["70506.40", "0.108"], ["70506.70", "0.048"], ["70506.80", "0.245"], ["70507.00", "0.018"], ["70516.60", "0.004"], ["70520.80", "1.002"], ["70521.70", "0.070"], ["70527.40", "0.288"], ["70534.10", "0.013"], ["70534.20", "0.162"], ["70534.50", "0.003"], ["70534.60", "0.036"], ["70534.80", "0.300"], ["70534.90", "0.036"], ["70535.20", "1.947"], ["70535.30", "0.044"], ["70535.50", "0.006"], ["70535.60", "0.180"], ["70535.90", "0.003"], ["70536.20", "0.036"], ["70536.50", "0.004"], ["70537.00", "0.053"], ["70539.40", "0.097"], ["70539.60", "0.004"], ["70539.90", "0.064"], ["70540.20", "0.021"], ["70560.80", "0.002"], ["70563.00", "0.092"], ["70563.10", "0.078"], ["70563.20", "0.089"], ["70563.30", "0.184"], ["70563.40", "1.351"], ["70563.70", "6.303"], ["70563.80", "0.036"], ["70564.00", "0.247"], ["70564.10", "0.036"], ["70564.40", "0.000"], ["70564.50", "0.399"], ["70564.70", "0.002"], ["70566.30", "0.010"], ["70572.00", "0.081"], ["70572.20", "0.511"], ["70573.50", "0.036"], ["70573.70", "0.054"], ["70591.00", "0.026"], ["70718.80", "0.003"], ["71199.80", "0.007"], ["71199.90", "2.243"], ["74021.50", "0.030"], ["77544.50", "0.034"], ["89523.20", "0.000"]]}}
{"local_ts": 1773485119684, "server_ts": 1773485118888, "data": {"e": "depthUpdate", "E": 1773485118889, "T": 1773485118888, "s": "BTCUSDT", "U": 10109432628204, "u": 10109432635849, "pu": 10109432628039, "b": [["5000.00", "101.418"], ["7050.20", "0.028"], ["20001.20", "0.290"], ["20094.90", "1.490"], ["20101.20", "0.370"], ["20194.90", "0.020"], ["63451.10", "0.008"], ["66960.60", "0.000"], ["66974.00", "0.000"], ["69477.40", "0.863"], ["69771.10", "0.000"], ["69796.20", "0.014"], ["69935.60", "0.000"], ["70138.70", "0.010"], ["70335.50", "0.159"], ["70363.70", "0.047"], ["70367.20", "0.040"], ["70376.30", "0.000"], ["70399.00", "0.004"], ["70427.50", "0.590"], ["70427.90", "0.170"], ["70452.00", "0.878"], ["70453.60", "0.010"], ["70457.90", "0.001"], ["70460.50", "0.088"], ["70463.90", "0.053"], ["70466.10", "0.003"], ["70469.80", "0.042"], ["70470.20", "0.002"], ["70470.40", "0.014"], ["70473.00", "0.000"], ["70478.40", "0.122"], ["70478.50", "0.090"], ["70480.30", "0.045"], ["70484.00", "0.302"], ["70486.90", "0.000"], ["70490.60", "0.007"], ["70491.70", "1.265"], ["70492.80", "0.016"], ["70493.20", "0.000"], ["70493.30", "0.455"], ["70493.80", "0.003"], ["70494.10", "1.145"], ["70494.20", "0.005"], ["70494.30", "0.404"], ["70494.40", "0.076"], ["70494.90", "0.120"], ["70495.60", "0.010"], ["70495.90", "0.011"], ["70496.50", "0.075"], ["70497.00", "0.006"], ["70497.50", "0.009"], ["70497.60", "0.560"], ["70499.60", "0.050"], ["70499.70", "0.015"], ["70499.80", "0.001"], ["70499.90", "0.334"], ["70500.00", "0.078"], ["70500.50", "0.002"], ["70500.60", "0.007"], ["70500.70", "0.002"], ["70500.80", "0.000"], ["70500.90", "0.000"], ["70501.00", "0.000"], ["70501.20", "113.623"]], "a": [["70501.30", "0.219"], ["70501.40", "0.002"], ["70504.90", "0.006"], ["70507.50", "0.005"], ["70507.60", "0.195"], ["70508.30", "0.000"], ["70508.80", "0.002"], ["70509.20", "0.000"], ["70509.50", "0.004"], ["70509.60", "0.004"], ["70509.90", "0.003"], ["70510.20", "0.011"], ["70510.30", "0.004"], ["70510.60", "0.002"], ["70510.70", "0.058"], ["70510.80", "0.511"], ["70510.90", "0.024"], ["70511.00", "0.006"], ["70511.90", "0.000"], ["70513.50", "0.007"], ["70514.50", "0.021"], ["70516.20", "0.054"], ["70520.70", "0.506"], ["70521.30", "0.004"], ["70523.50", "0.009"], ["70529.50", "1.133"], ["70532.10", "0.076"], ["70536.50", "0.000"], ["70538.40", "0.004"], ["70560.80", "0.000"], ["70563.00", "0.000"], ["70567.20", "0.362"], ["70567.60", "0.000"], ["70568.10", "2.080"], ["70571.00", "0.091"], ["70574.30", "0.283"], ["70593.00", "1.580"], ["70604.60", "0.000"], ["70631.80", "0.071"], ["70634.10", "0.071"], ["70647.00", "0.089"], ["70735.00", "0.013"], ["71206.30", "0.000"], ["72122.80", "0.692"], ["74047.50", "0.052"], ["77551.40", "0.002"], ["89523.20", "0.000"]]}}
{"local_ts": 1773485120702, "server_ts": 1773485119908, "data": {"e": "depthUpdate", "E": 1773485119911, "T": 1773485119908, "s": "BTCUSDT", "U": 10109432695313, "u": 10109432701011, "pu": 10109432695256, "b": [["1000.00", "28.692"], ["5000.00", "101.418"], ["7050.20", "0.028"], ["20001.20", "2.360"], ["20094.90", "0.270"], ["20401.20", "0.230"], ["63451.10", "0.008"], ["66958.80", "0.062"], ["66976.00", "0.005"], ["68501.20", "0.006"], ["69478.90", "0.862"], ["69796.20", "0.014"], ["70068.20", "0.002"], ["70148.70", "0.007"], ["70254.50", "0.004"], ["70348.90", "0.095"], ["70440.90", "0.010"], ["70451.30", "0.219"], ["70451.40", "0.186"], ["70470.10", "0.696"], ["70482.60", "0.027"], ["70483.90", "0.918"], ["70487.00", "0.079"], ["70488.20", "0.049"], ["70494.20", "0.070"], ["70496.40", "0.001"], ["70497.30", "0.023"], ["70501.20", "113.044"]], "a": [["70504.90", "0.004"], ["70507.50", "0.005"], ["70507.60", "0.240"], ["70508.30", "0.000"], ["70510.90", "0.003"], ["70511.20", "0.063"], ["70514.70", "0.080"], ["70518.20", "0.277"], ["70518.90", "0.995"], ["70524.00", "0.007"], ["70524.80", "0.344"], ["70524.90", "0.015"], ["70563.20", "0.174"], ["70647.00", "0.087"], ["71206.30", "0.000"], ["74030.70", "0.004"], ["77551.40", "0.002"], ["89523.20", "0.000"]]}}
{"local_ts": 1773485121729, "server_ts": 1773485120930, "data": {"e": "depthUpdate", "E": 1773485120931, "T": 1773485120930, "s": "BTCUSDT", "U": 10109432834878, "u": 10109432847476, "pu": 10109432834839, "b": [["5000.00", "101.418"], ["7050.70", "0.028"], ["19999.50", "0.000"], ["20001.20", "0.570"], ["20306.70", "0.080"], ["20406.70", "0.330"], ["63456.00", "10.176"], ["66486.40", "0.002"], ["66949.40", "0.000"], ["66978.00", "0.000"], ["69630.30", "2.139"], ["69801.60", "0.027"], ["70099.30", "0.000"], ["70127.80", "0.427"], ["70142.90", "0.004"], ["70157.50", "1.576"], ["70181.90", "5.123"], ["70222.10", "16.020"], ["70231.50", "0.002"], ["70254.80", "0.000"], ["70255.30", "0.002"], ["70257.60", "0.008"], ["70271.70", "0.023"], ["70279.90", "3.751"], ["70290.40", "1.485"], ["70308.70", "0.007"], ["70322.00", "4.642"], ["70322.20", "0.054"], ["70350.80", "0.000"], ["70351.60", "0.159"], ["70355.10", "0.000"], ["70360.80", "0.015"], ["70361.40", "0.014"], ["70362.20", "0.000"], ["70364.50", "0.110"], ["70369.20", "0.000"], ["70373.70", "0.212"], ["70373.80", "0.110"], ["70374.50", "0.300"], ["70376.30", "0.213"], ["70379.80", "2.266"], ["70390.40", "0.876"], ["70393.90", "0.000"], ["70397.40", "0.046"], ["70398.00", "0.276"], ["70398.80", "0.202"], ["70400.90", "0.000"], ["70401.90", "0.317"], ["70402.00", "0.881"], ["70402.70", "0.526"], ["70404.50", "0.238"], ["70409.80", "0.202"], ["70423.70", "0.187"], ["70423.90", "0.224"], ["70424.80", "0.321"], ["70427.70", "0.000"], ["70430.60", "0.395"], ["70434.40", "0.953"], ["70444.70", "0.282"], ["70445.80", "0.000"], ["70446.90", "0.000"], ["70448.30", "0.002"], ["70448.50", "0.111"], ["70455.40", "0.108"], ["70455.70", "0.017"], ["70456.10", "0.143"], ["70457.00", "0.000"], ["70457.40", "0.039"], ["70457.70", "0.048"], ["70459.20", "0.004"], ["70464.40", "0.015"], ["70470.80", "0.020"], ["70472.80", "0.088"], ["70473.20", "0.295"], ["70478.50", "0.088"], ["70482.30", "0.108"], ["70482.70", "0.003"], ["70483.00", "0.010"], ["70483.40", "0.009"], ["70484.10", "0.007"], ["70484.60", "0.261"], ["70484.70", "0.007"], ["70484.90", "0.062"], ["70485.30", "0.078"], ["70489.10", "0.068"], ["70490.60", "0.392"], ["70490.90", "0.565"], ["70491.50", "0.038"], ["70491.60", "0.100"], ["70493.30", "0.667"], ["70495.00", "0.005"], ["70496.00", "0.017"], ["70496.80", "0.072"], ["70497.40", "0.009"], ["70497.60", "0.349"], ["70498.50", "0.028"], ["70499.30", "0.026"], ["70500.70", "0.009"], ["70501.20", "0.059"], ["70501.50", "0.004"], ["70502.40", "0.011"], ["70502.60", "0.015"], ["70502.80", "0.000"], ["70503.60", "0.010"], ["70503.70", "0.025"], ["70503.80", "0.032"], ["70503.90", "2.725"], ["70504.10", "0.004"], ["70504.20", "0.201"], ["70504.30", "0.003"], ["70504.90", "0.000"], ["70505.00", "0.066"], ["70505.50", "0.004"], ["70506.00", "0.000"], ["70506.30", "0.000"], ["70506.40", "0.000"], ["70506.50", "0.002"], ["70506.60", "0.203"], ["70506.70", "113.520"]], "a": [["70506.80", "0.932"], ["70507.00", "0.002"], ["70509.60", "0.002"], ["70509.90", "0.016"], ["70511.50", "0.114"], ["70512.10", "0.002"], ["70513.10", "0.003"], ["70513.80", "0.001"], ["70515.20", "0.002"], ["70515.30", "1.531"], ["70517.40", "0.007"], ["70518.90", "0.343"], ["70523.10", "0.003"], ["70523.20", "0.090"], ["70524.40", "0.270"], ["70524.80", "0.547"], ["70525.00", "0.778"], ["70525.10", "0.007"], ["70526.60", "0.000"], ["70528.00", "0.003"], ["70528.20", "0.000"], ["70528.60", "0.205"], ["70528.70", "0.002"], ["70529.40", "0.013"], ["70529.90", "0.007"], ["70530.30", "0.011"], ["70530.60", "0.010"], ["70531.20", "0.028"], ["70537.30", "0.023"], ["70537.70", "0.029"], ["70539.30", "0.479"], ["70543.80", "0.149"], ["70544.70", "0.069"], ["70549.10", "0.379"], ["70549.20", "0.024"], ["70549.30", "0.294"], ["70552.00", "0.275"], ["70553.50", "0.262"], ["70555.40", "0.297"], ["70556.10", "0.003"], ["70558.00", "0.000"], ["70559.10", "0.782"], ["70563.80", "0.841"], ["70572.20", "0.528"], ["70573.80", "0.187"], ["70653.20", "0.091"], ["70666.90", "2.386"], ["70679.60", "6.247"], ["70692.00", "0.072"], ["70727.20", "0.008"], ["70756.90", "0.000"], ["71211.90", "0.048"], ["71458.50", "1.117"], ["74062.60", "0.002"], ["77557.50", "0.002"], ["89523.20", "0.000"]]}}
{"local_ts": 1773485122743, "server_ts": 1773485121950, "data": {"e": "depthUpdate", "E": 1773485121951, "T": 1773485121950, "s": "BTCUSDT", "U": 10109432933792, "u": 10109432939040, "pu": 10109432933764, "b": [["1000.00", "28.692"], ["5000.00", "101.418"], ["7050.90", "0.000"], ["20308.30", "1.060"], ["20401.20", "0.070"], ["20403.20", "0.840"], ["20403.70", "0.030"], ["20403.90", "0.000"], ["20405.10", "0.000"], ["20406.00", "0.000"], ["20406.70", "0.000"], ["33000.00", "3.785"], ["63457.50", "0.000"], ["66982.00", "0.000"], ["69448.30", "3.722"], ["69485.30", "1.716"], ["69531.40", "0.011"], ["69803.20", "0.000"], ["69854.20", "0.002"], ["70155.80", "0.000"], ["70321.80", "0.002"], ["70356.00", "12.382"], ["70369.30", "0.008"], ["70377.90", "0.000"], ["70415.50", "6.584"], ["70451.30", "3.771"], ["70458.10", "0.004"], ["70458.40", "0.114"], ["70471.20", "0.206"], ["70473.10", "1.852"], ["70474.50", "0.067"], ["70474.60", "0.105"], ["70484.00", "0.289"], ["70492.90", "0.057"], ["70493.90", "0.194"], ["70501.00", "0.005"], ["70501.30", "0.115"], ["70503.90", "0.345"], ["70504.40", "0.001"], ["70504.80", "0.086"], ["70505.20", "0.001"], ["70505.40", "0.001"], ["70506.00", "0.003"], ["70506.10", "0.000"], ["70506.20", "0.002"], ["70506.70", "0.007"], ["70506.90", "0.003"], ["70507.40", "0.005"], ["70507.70", "0.033"], ["70507.90", "0.000"], ["70508.10", "0.002"], ["70508.20", "0.131"], ["70508.30", "110.636"]], "a": [["70508.40", "3.181"], ["70509.70", "0.015"], ["70510.10", "0.000"], ["70511.00", "0.020"], ["70511.50", "0.001"], ["70512.20", "0.009"], ["70512.50", "0.000"], ["70513.00", "0.019"], ["70515.70", "0.026"], ["70515.80", "0.018"], ["70517.40", "0.004"], ["70517.70", "0.060"], ["70518.00", "0.029"], ["70518.20", "0.021"], ["70518.50", "0.087"], ["70521.20", "0.060"], ["70522.20", "0.003"], ["70528.90", "0.161"], ["70530.50", "0.296"], ["70537.50", "0.002"], ["70539.50", "0.846"], ["70547.70", "1.825"], ["70550.50", "0.048"], ["70550.70", "0.152"], ["70569.30", "3.517"], ["70605.00", "6.766"], ["70611.10", "0.020"], ["70614.00", "0.009"], ["70620.40", "0.009"], ["70622.20", "0.043"], ["70630.00", "1.104"], ["70635.80", "0.239"], ["70664.50", "12.106"], ["70665.30", "3.312"], ["70665.80", "0.000"], ["70679.60", "6.265"], ["70684.70", "0.099"], ["70717.80", "2.404"], ["70758.60", "0.022"], ["71213.40", "0.000"], ["71213.50", "0.000"], ["71455.30", "0.000"], ["71460.30", "1.117"], ["74040.40", "0.000"], ["77559.20", "0.000"], ["89523.20", "0.000"]]}}
