{"local_ts": 1773485368058, "server_ts": 1773485367266, "data": {"e": "depthUpdate", "E": 1773485367267, "T": 1773485367266, "s": "BTCUSDT", "U": 10109444632015, "u": 10109444634235, "pu": 10109444631990, "b": [["1000.00", "28.842"], ["5000.00", "101.418"], ["7050.00", "0.453"], ["19999.90", "0.040"], ["20299.90", "0.390"], ["20399.90", "2.570"], ["66951.70", "0.000"], ["66961.90", "0.002"], ["69498.80", "2.861"], ["69515.00", "3.544"], ["69794.90", "6.488"], ["69795.00", "0.479"], ["70254.00", "0.077"]], "a": [["70535.20", "1.552"], ["70723.40", "0.007"], ["70852.40", "0.000"], ["71205.00", "5.334"], ["71684.40", "1.393"], ["75425.00", "0.052"]]}}
{"local_ts": 1773485369081, "server_ts": 1773485368288, "data": {"e": "depthUpdate", "E": 1773485368289, "T": 1773485368288, "s": "BTCUSDT", "U": 10109444660518, "u": 10109444663080, "pu": 10109444660454, "b": [["1000.00", "28.842"], ["5000.00", "101.418"], ["7050.00", "0.453"], ["20199.90", "0.210"], ["20299.90", "2.480"], ["20399.90", "0.310"], ["33000.00", "3.785"], ["66944.20", "0.000"], ["69794.90", "6.490"], ["70147.40", "4.519"], ["70453.50", "0.003"], ["70453.60", "1.200"], ["70493.80", "0.086"], ["70495.30", "0.005"]], "a": [["70500.00", "2.682"], ["70506.80", "0.066"], ["70521.50", "0.570"], ["70521.60", "0.768"], ["70549.30", "0.170"], ["71205.00", "5.755"], ["71698.50", "4.458"], ["74034.10", "0.002"]]}}
{"local_ts": 1773485370102, "server_ts": 1773485369308, "data": {"e": "depthUpdate", "E": 1773485369311, "T": 1773485369308, "s": "BTCUSDT", "U": 10109444694997, "u": 10109444698165, "pu": 10109444694973, "b": [["5000.00", "101.418"], ["7050.00", "0.453"], ["20099.90", "0.060"], ["20199.90", "2.340"], ["20299.90", "0.600"], ["66953.90", "0.005"], ["69158.30", "0.000"], ["69284.10", "0.000"], ["69458.60", "2.730"], ["69794.90", "7.203"], ["69795.00", "0.483"], ["70364.50", "0.000"], ["70365.20", "0.000"], ["70493.70", "0.085"], ["70493.80", "0.001"]], "a": [["70537.00", "0.460"], ["70543.20", "0.009"], ["70630.70", "0.220"], ["70676.20", "0.175"], ["70715.90", "0.008"], ["70723.70", "2.009"], ["71204.90", "0.000"], ["71205.00", "6.456"], ["71909.90", "0.012"], ["73319.90", "0.082"], ["74045.80", "0.000"]]}}
{"local_ts": 1773485371124, "server_ts": 1773485370332, "data": {"e": "depthUpdate", "E": 1773485370333, "T": 1773485370332, "s": "BTCUSDT", "U": 10109444730435, "u": 10109444733612, "pu": 10109444730400, "b": [["1000.00", "28.842"], ["5000.00", "101.418"], ["7050.00", "0.453"], ["20099.90", "2.020"], ["20199.90", "0.980"], ["33000.00", "3.789"], ["66954.00", "0.002"], ["66974.00", "0.000"], ["69108.80", "3.097"], ["69473.00", "0.862"], ["69794.90", "7.203"], ["70147.40", "4.519"], ["70453.40", "0.004"], ["70453.50", "0.001"], ["70464.70", "0.072"], ["70493.70", "0.184"]], "a": [["70535.20", "1.640"], ["70699.90", "0.000"], ["71205.00", "6.456"], ["74045.80", "0.002"]]}}
{"local_ts": 1773485372148, "server_ts": 1773485371356, "data": {"e": "depthUpdate", "E": 1773485371357, "T": 1773485371356, "s": "BTCUSDT", "U": 10109444767911, "u": 10109444771175, "pu": 10109444767855, "b": [["5000.00", "101.418"], ["7050.00", "0.425"], ["19999.90", "1.580"], ["20099.90", "1.420"], ["66947.10", "0.000"], ["69543.50", "0.000"], ["69579.90", "0.000"], ["69794.90", "7.203"], ["70147.40", "4.519"], ["70284.30", "0.002"], ["70404.80", "0.000"], ["70411.90", "0.136"], ["70418.90", "0.014"], ["70469.70", "0.006"]], "a": [["70507.30", "0.002"], ["70523.20", "0.034"], ["70535.20", "1.576"], ["70559.90", "1.068"], ["70571.10", "0.000"], ["70581.20", "0.028"], ["70588.20", "0.000"], ["70590.90", "0.007"], ["70595.30", "0.000"], ["70676.20", "0.115"], ["71205.00", "6.456"], ["71268.50", "4.200"], ["71433.00", "0.068"], ["71566.60", "1.128"], ["71619.80", "2.788"], ["74049.80", "0.002"]]}}
{"local_ts": 1773485373174, "server_ts": 1773485372380, "data": {"e": "depthUpdate", "E": 1773485372381, "T": 1773485372380, "s": "BTCUSDT", "U": 10109444806740, "u": 10109444810110, "pu": 10109444806636, "b": [["1000.00", "28.842"], ["5000.00", "101.418"], ["7050.00", "0.425"], ["19999.90", "1.860"], ["20399.90", "1.140"], ["69402.50", "0.000"], ["69407.10", "0.374"], ["69794.90", "7.203"], ["70167.40", "11.076"], ["70181.80", "0.657"], ["70404.80", "0.000"], ["70411.90", "0.136"], ["70418.90", "0.014"], ["70464.70", "0.002"], ["70480.20", "0.009"], ["70480.60", "0.000"], ["70486.70", "0.448"], ["70487.30", "0.027"], ["70488.00", "0.112"], ["70488.40", "0.643"], ["70489.30", "0.008"], ["70489.40", "0.007"], ["70490.30", "0.415"], ["70492.30", "0.008"], ["70499.90", "3.898"]], "a": [["70500.60", "0.002"], ["70502.20", "0.150"], ["70506.60", "0.000"], ["70510.30", "0.119"], ["70510.60", "0.000"], ["70513.50", "0.024"], ["70513.80", "0.138"], ["70523.10", "0.007"], ["70523.60", "1.712"], ["70523.90", "0.592"], ["70535.20", "1.576"], ["70559.90", "1.066"], ["70563.30", "0.271"], ["70581.20", "0.028"], ["70588.20", "0.000"], ["70591.80", "0.002"], ["70595.30", "0.002"], ["70723.80", "0.217"], ["70744.00", "0.250"], ["70821.80", "0.648"], ["70844.90", "3.255"], ["71055.70", "3.240"], ["71059.80", "1.207"], ["71205.00", "6.076"], ["71249.90", "0.003"], ["74025.60", "0.000"]]}}
{"local_ts": 1773485374195, "server_ts": 1773485373401, "data": {"e": "depthUpdate", "E": 1773485373403, "T": 1773485373401, "s": "BTCUSDT", "U": 10109444840612, "u": 10109444843711, "pu": 10109444840554, "b": [["1000.00", "28.842"], ["5000.00", "101.418"], ["7050.00", "0.481"], ["19999.90", "0.000"], ["20299.90", "0.690"], ["20399.90", "2.310"], ["66966.40", "0.000"], ["68948.90", "0.007"], ["69794.90", "7.203"], ["70147.40", "4.519"], ["70365.30", "0.907"], ["70431.20", "0.064"], ["70452.90", "0.004"], ["70453.10", "1.068"], ["70482.30", "0.169"], ["70489.30", "0.012"], ["70492.00", "0.088"]], "a": [["70500.00", "3.132"], ["70500.60", "0.002"], ["70502.80", "0.030"], ["70504.30", "0.000"], ["70504.80", "0.013"], ["70507.80", "0.217"], ["70510.00", "0.088"], ["70510.60", "0.000"], ["70529.10", "0.250"], ["70537.40", "0.047"], ["70549.80", "0.085"], ["70563.30", "0.271"], ["70565.10", "0.227"], ["70591.80", "0.000"], ["70630.70", "3.063"], ["71205.00", "6.076"], ["71760.80", "1.698"], ["72618.70", "0.000"], ["74049.40", "0.002"]]}}
{"local_ts": 1773485375215, "server_ts": 1773485374420, "data": {"e": "depthUpdate", "E": 1773485374423, "T": 1773485374420, "s": "BTCUSDT", "U": 10109444890085, "u": 10109444893480, "pu": 10109444890051, "b": [["5000.00", "101.418"], ["7050.00", "0.481"], ["20199.90", "0.320"], ["20299.90", "2.600"], ["20399.90", "0.080"], ["69498.80", "3.147"], ["70147.50", "1.136"], ["70254.00", "0.073"], ["70316.60", "0.159"], ["70431.20", "0.120"], ["70452.60", "0.004"], ["70452.80", "0.042"]], "a": [["70549.80", "0.269"], ["70565.10", "0.225"], ["70566.10", "0.002"], ["71205.00", "6.076"], ["74043.00", "0.002"], ["74046.40", "0.002"]]}}
{"local_ts": 1773485376236, "server_ts": 1773485375444, "data": {"e": "depthUpdate", "E": 1773485375445, "T": 1773485375444, "s": "BTCUSDT", "U": 10109444926145, "u": 10109444929116, "pu": 10109444926039, "b": [["1000.00", "28.992"], ["5000.00", "101.418"], ["7050.00", "0.481"], ["20099.90", "0.170"], ["20199.90", "2.450"], ["20299.90", "0.380"], ["33000.00", "3.785"], ["69297.30", "0.009"], ["69477.70", "38.266"], ["69794.90", "7.203"], ["70147.40", "4.519"], ["70147.50", "1.132"], ["70254.00", "0.077"], ["70365.30", "0.080"], ["70482.30", "0.169"], ["70483.60", "0.009"], ["70489.30", "0.005"], ["70492.20", "0.393"]], "a": [["70500.00", "2.996"], ["70505.40", "0.068"], ["70509.50", "0.037"], ["70510.60", "0.000"], ["70561.60", "0.045"], ["70630.70", "2.607"], ["71205.00", "6.076"], ["71719.60", "0.347"], ["74049.80", "0.000"], ["89523.20", "0.000"]]}}
{"local_ts": 1773485377263, "server_ts": 1773485376468, "data": {"e": "depthUpdate", "E": 1773485376469, "T": 1773485376468, "s": "BTCUSDT", "U": 10109444966970, "u": 10109444970533, "pu": 10109444966901, "b": [["5000.00", "101.418"], ["7050.00", "0.453"], ["19999.90", "0.030"], ["20099.90", "2.300"], ["20199.90", "0.670"], ["69173.60", "2.824"], ["69794.90", "7.203"], ["70365.30", "0.998"], ["70444.30", "0.389"], ["70453.10", "1.066"], ["70453.20", "0.004"], ["70459.60", "0.840"]], "a": [["70630.70", "3.061"], ["71205.00", "6.076"], ["71522.20", "34.702"], ["71592.70", "11.579"], ["74035.40", "0.000"], ["89523.20", "0.000"]]}}
{"local_ts": 1773485378288, "server_ts": 1773485377488, "data": {"e": "depthUpdate", "E": 1773485377491, "T": 1773485377488, "s": "BTCUSDT", "U": 10109445008283, "u": 10109445011756, "pu": 10109445008263, "b": [["1000.00", "28.842"], ["5000.00", "101.418"], ["7050.00", "0.453"], ["19999.90", "1.910"], ["20099.90", "1.090"], ["33000.00", "3.789"], ["66957.30", "0.002"], ["69522.90", "4.308"], ["69794.90", "5.772"], ["70076.00", "39.660"], ["70076.50", "5.974"], ["70181.30", "33.100"], ["70258.60", "27.018"], ["70259.00", "6.131"], ["70284.30", "0.006"], ["70341.30", "0.549"], ["70365.30", "0.080"], ["70444.70", "0.321"], ["70451.30", "0.015"], ["70459.60", "0.840"], ["70467.40", "0.004"], ["70467.50", "1.848"], ["70487.50", "0.642"], ["70496.40", "0.201"]], "a": [["70529.30", "0.007"], ["70537.90", "0.036"], ["70559.10", "0.285"], ["70630.70", "2.607"], ["70744.90", "26.896"], ["70822.70", "31.327"], ["70841.90", "0.211"], ["70929.00", "39.736"], ["71205.00", "6.076"], ["71416.50", "10.068"], ["71609.10", "1.803"], ["89523.20", "0.000"]]}}
{"local_ts": 1773485379307, "server_ts": 1773485378514, "data": {"e": "depthUpdate", "E": 1773485378515, "T": 1773485378514, "s": "BTCUSDT", "U": 10109445041699, "u": 10109445043747, "pu": 10109445041652, "b": [["1000.00", "28.842"], ["5000.00", "101.418"], ["7050.00", "0.453"], ["19999.90", "1.530"], ["20399.90", "1.470"], ["66941.90", "0.002"], ["66960.30", "0.000"], ["69407.20", "16.259"], ["69477.70", "39.272"], ["69794.90", "5.772"], ["69830.20", "5.140"], ["70147.40", "4.519"], ["70207.60", "0.006"], ["70475.90", "0.562"], ["70499.60", "0.220"]], "a": [["70644.10", "0.095"], ["71205.00", "6.076"], ["71482.50", "0.466"], ["71522.20", "35.679"], ["71628.00", "7.080"], ["89523.20", "0.000"]]}}
{"local_ts": 1773485380337, "server_ts": 1773485379536, "data": {"e": "depthUpdate", "E": 1773485379539, "T": 1773485379536, "s": "BTCUSDT", "U": 10109445071583, "u": 10109445074216, "pu": 10109445071520, "b": [["5000.00", "101.418"], ["7050.00", "0.425"], ["20299.90", "1.030"], ["20399.90", "1.970"], ["33000.00", "3.789"], ["56400.00", "6.994"], ["66975.00", "0.088"], ["69336.70", "6.929"], ["69794.90", "7.203"], ["70355.70", "0.523"], ["70362.90", "0.017"], ["70369.60", "0.933"], ["70384.90", "1.127"], ["70395.10", "0.000"], ["70401.40", "0.213"], ["70406.10", "0.585"], ["70411.90", "0.229"], ["70415.30", "0.142"], ["70419.60", "0.000"], ["70423.40", "0.839"], ["70426.30", "0.000"], ["70429.20", "0.119"], ["70431.10", "0.001"], ["70473.30", "0.035"], ["70499.80", "0.191"]], "a": [["70644.10", "0.093"], ["70644.40", "0.002"], ["71205.00", "6.076"], ["71592.70", "12.972"], ["72271.00", "2.486"], ["74041.80", "0.000"], ["89523.20", "0.000"]]}}
{"local_ts": 1773485381353, "server_ts": 1773485380560, "data": {"e": "depthUpdate", "E": 1773485380561, "T": 1773485380560, "s": "BTCUSDT", "U": 10109445103836, "u": 10109445106720, "pu": 10109445103749, "b": [["1000.00", "28.842"], ["5000.00", "101.418"], ["7050.00", "0.425"], ["20199.90", "0.590"], ["20299.90", "2.410"], ["20399.90", "0.000"], ["56400.00", "6.994"], ["66940.00", "0.052"], ["69266.20", "12.687"], ["69794.90", "7.203"], ["69795.00", "0.099"], ["70253.90", "0.147"], ["70254.00", "0.073"], ["70354.00", "0.039"], ["70361.80", "0.088"], ["70365.40", "0.887"], ["70369.20", "0.039"], ["70384.60", "0.063"], ["70394.80", "0.929"], ["70401.10", "0.131"], ["70405.70", "0.060"], ["70411.50", "0.039"], ["70414.90", "0.053"], ["70419.20", "0.352"], ["70423.00", "0.053"], ["70425.90", "0.042"], ["70428.80", "0.095"], ["70432.00", "0.053"], ["70444.10", "0.362"], ["70453.30", "0.044"], ["70478.90", "0.003"], ["70479.80", "0.072"], ["70481.00", "0.003"], ["70489.30", "0.008"], ["70492.40", "0.010"], ["70499.20", "0.017"], ["70499.50", "0.000"], ["70499.80", "0.111"]], "a": [["70500.00", "2.121"], ["70501.10", "0.001"], ["70501.20", "0.004"], ["70501.30", "0.018"], ["70504.30", "0.021"], ["70510.60", "0.018"], ["70523.40", "0.002"], ["70525.40", "0.291"], ["70526.10", "0.353"], ["70526.60", "0.000"], ["70527.60", "0.080"], ["70527.80", "0.000"], ["70630.70", "2.931"], ["70642.60", "0.002"], ["70644.40", "0.000"], ["71064.00", "1.126"], ["71205.00", "6.076"], ["71780.70", "0.000"], ["74025.00", "0.361"], ["89523.20", "0.000"]]}}
{"local_ts": 1773485382374, "server_ts": 1773485381582, "data": {"e": "depthUpdate", "E": 1773485381583, "T": 1773485381582, "s": "BTCUSDT", "U": 10109445137588, "u": 10109445140361, "pu": 10109445137549, "b": [["5000.00", "101.418"], ["7050.00", "0.425"], ["20099.90", "0.290"], ["20199.90", "2.560"], ["20299.90", "0.150"], ["56400.00", "6.994"], ["69794.90", "7.203"], ["70076.00", "0.000"], ["70076.50", "0.063"], ["70147.40", "4.483"], ["70181.30", "0.002"], ["70181.80", "0.264"], ["70258.60", "0.010"], ["70259.00", "1.610"], ["70365.40", "0.887"], ["70453.00", "0.010"], ["70453.10", "1.068"], ["70464.70", "0.002"]], "a": [["70535.20", "1.573"], ["70625.70", "0.083"], ["70630.60", "0.328"], ["70640.50", "1.280"], ["70642.60", "0.000"], ["70742.40", "1.746"], ["70744.90", "0.002"], ["70822.50", "0.508"], ["70822.70", "0.000"], ["70834.90", "0.000"], ["70852.50", "4.723"], ["70929.00", "0.004"], ["71205.00", "6.078"], ["71346.00", "7.695"], ["71501.10", "2.502"], ["74035.00", "0.026"], ["89523.20", "0.000"]]}}
{"local_ts": 1773485383395, "server_ts": 1773485382604, "data": {"e": "depthUpdate", "E": 1773485382605, "T": 1773485382604, "s": "BTCUSDT", "U": 10109445166752, "u": 10109445170959, "pu": 10109445166431, "b": [["1000.00", "28.842"], ["5000.00", "101.438"], ["7050.00", "0.481"], ["19999.90", "0.140"], ["20099.90", "2.420"], ["20199.90", "0.440"], ["56400.00", "6.994"], ["66947.20", "0.000"], ["69794.90", "6.487"], ["70147.40", "4.483"], ["70323.00", "0.525"], ["70353.70", "0.159"], ["70431.20", "0.120"], ["70453.30", "0.040"], ["70453.40", "0.004"], ["70488.60", "0.027"], ["70489.10", "0.005"], ["70497.90", "0.000"], ["70499.30", "0.002"], ["70499.80", "0.090"]], "a": [["70628.10", "1.900"], ["70640.50", "1.278"], ["70650.80", "0.096"], ["70665.80", "0.018"], ["71205.00", "5.375"], ["74051.40", "0.004"], ["89523.20", "0.000"]]}}
{"local_ts": 1773485384418, "server_ts": 1773485383624, "data": {"e": "depthUpdate", "E": 1773485383627, "T": 1773485383624, "s": "BTCUSDT", "U": 10109445199193, "u": 10109445201831, "pu": 10109445199070, "b": [["1000.00", "28.842"], ["5000.00", "101.418"], ["7050.00", "0.481"], ["19999.90", "2.250"], ["20099.90", "0.750"], ["56400.00", "6.994"], ["66970.30", "0.002"], ["69794.90", "6.487"], ["70289.60", "0.271"], ["70326.70", "3.612"], ["70341.30", "0.549"], ["70365.40", "0.887"], ["70482.30", "0.113"], ["70488.00", "0.112"], ["70489.00", "0.002"], ["70493.40", "0.284"], ["70493.50", "0.246"], ["70499.80", "0.126"]], "a": [["70501.60", "0.025"], ["70502.40", "0.005"], ["70502.50", "0.025"], ["70504.90", "0.018"], ["70505.00", "0.027"], ["70517.60", "0.365"], ["70630.60", "0.579"], ["70669.40", "4.083"], ["70676.20", "0.175"], ["70706.40", "0.877"], ["70719.90", "0.000"], ["71204.90", "0.007"], ["71205.00", "5.375"], ["74028.70", "0.002"], ["89523.20", "0.000"]]}}
{"local_ts": 1773485385442, "server_ts": 1773485384648, "data": {"e": "depthUpdate", "E": 1773485384649, "T": 1773485384648, "s": "BTCUSDT", "U": 10109445226980, "u": 10109445230168, "pu": 10109445226912, "b": [["5000.00", "101.438"], ["7050.00", "0.481"], ["19999.90", "1.190"], ["20399.90", "1.810"], ["33000.00", "3.785"], ["56400.00", "6.994"], ["66946.00", "0.006"], ["66960.50", "0.002"], ["69090.00", "3.695"], ["69565.70", "3.592"], ["69794.90", "6.487"], ["70147.40", "4.483"], ["70254.00", "0.077"], ["70464.70", "0.002"], ["70488.00", "0.112"], ["70488.40", "0.007"], ["70489.10", "0.005"], ["70490.30", "0.185"], ["70492.90", "0.270"], ["70493.40", "0.100"]], "a": [["70507.00", "0.036"], ["70517.90", "1.151"], ["70518.10", "0.005"], ["70528.60", "0.279"], ["70529.40", "0.266"], ["70535.20", "1.573"], ["71205.00", "5.375"], ["71494.00", "0.838"], ["71567.10", "0.845"], ["71591.60", "0.279"], ["72271.90", "2.486"], ["89523.20", "0.000"]]}}
{"local_ts": 1773485386465, "server_ts": 1773485385672, "data": {"e": "depthUpdate", "E": 1773485385673, "T": 1773485385672, "s": "BTCUSDT", "U": 10109445261741, "u": 10109445264850, "pu": 10109445261701, "b": [["1000.00", "28.842"], ["5000.00", "101.418"], ["7050.00", "0.453"], ["20299.90", "1.370"], ["20399.90", "1.630"], ["66950.30", "0.004"], ["69427.30", "0.000"], ["69794.90", "5.056"], ["70365.50", "1.034"], ["70464.70", "0.070"], ["70479.20", "0.075"], ["70480.30", "0.028"], ["70488.00", "0.114"], ["70488.40", "0.005"], ["70490.30", "0.001"], ["70495.40", "0.098"]], "a": [["70502.50", "0.067"], ["70503.40", "0.021"], ["70504.50", "0.000"], ["70504.90", "0.018"], ["70505.80", "0.003"], ["70507.00", "0.029"], ["70507.20", "0.002"], ["70508.70", "0.000"], ["70509.90", "0.112"], ["70519.70", "0.017"], ["70520.90", "0.035"], ["70524.50", "0.007"], ["70525.10", "1.386"], ["70535.20", "1.601"], ["70630.60", "0.453"], ["71205.00", "3.973"], ["73319.90", "0.106"], ["89523.20", "0.000"]]}}
{"local_ts": 1773485387492, "server_ts": 1773485386692, "data": {"e": "depthUpdate", "E": 1773485386697, "T": 1773485386692, "s": "BTCUSDT", "U": 10109445294147, "u": 10109445297268, "pu": 10109445294042, "b": [["5000.00", "101.418"], ["7050.00", "0.453"], ["20199.90", "0.920"], ["20299.90", "2.080"], ["33000.00", "3.789"], ["66975.00", "0.086"], ["67680.00", "0.165"], ["69794.90", "5.772"], ["70430.20", "1.341"], ["70493.00", "0.525"], ["70499.80", "0.064"]], "a": [["70500.00", "1.485"], ["70502.40", "0.028"], ["70507.10", "0.009"], ["70517.40", "0.092"], ["70517.50", "0.023"], ["70517.60", "0.365"], ["70519.70", "0.002"], ["70567.50", "0.045"], ["71205.00", "4.674"], ["71733.70", "18.942"], ["74056.60", "0.002"], ["89523.20", "0.000"]]}}
{"local_ts": 1773485388511, "server_ts": 1773485387717, "data": {"e": "depthUpdate", "E": 1773485387719, "T": 1773485387717, "s": "BTCUSDT", "U": 10109445336869, "u": 10109445340750, "pu": 10109445336852, "b": [["1000.00", "28.842"], ["5000.00", "101.418"], ["7050.00", "0.453"], ["20099.90", "0.480"], ["20199.90", "2.520"], ["20299.90", "0.000"], ["66973.00", "0.030"], ["69794.90", "6.845"], ["69795.00", "0.099"], ["70000.00", "127.765"], ["70147.40", "4.519"], ["70247.40", "1.284"], ["70254.00", "0.077"], ["70254.20", "0.239"], ["70302.50", "0.121"], ["70473.40", "0.003"], ["70491.70", "0.003"], ["70491.90", "0.006"], ["70494.30", "0.000"]], "a": [["70500.00", "1.257"], ["70505.20", "0.001"], ["70506.70", "0.003"], ["70506.80", "0.009"], ["70549.30", "0.329"], ["70852.50", "4.547"], ["71028.70", "2.109"], ["71205.00", "4.674"], ["71568.40", "0.000"], ["74034.10", "0.002"]]}}
{"local_ts": 1773485389534, "server_ts": 1773485388740, "data": {"e": "depthUpdate", "E": 1773485388741, "T": 1773485388740, "s": "BTCUSDT", "U": 10109445372123, "u": 10109445375086, "pu": 10109445372106, "b": [["1000.00", "28.842"], ["5000.00", "101.418"], ["7050.00", "0.425"], ["19999.90", "0.250"], ["20099.90", "2.540"], ["20199.90", "0.210"], ["33000.00", "3.789"], ["66956.30", "0.025"], ["69794.90", "6.845"], ["70492.90", "0.271"]], "a": [["70504.80", "0.028"], ["70505.00", "0.006"], ["70507.00", "0.039"], ["71205.00", "6.076"], ["71324.90", "2.939"], ["71569.10", "0.000"], ["71712.90", "0.696"], ["71715.80", "0.696"], ["74053.00", "0.050"]]}}
{"local_ts": 1773485390552, "server_ts": 1773485389759, "data": {"e": "depthUpdate", "E": 1773485389761, "T": 1773485389759, "s": "BTCUSDT", "U": 10109445404279, "u": 10109445407557, "pu": 10109445404131, "b": [["5000.00", "101.418"], ["7050.00", "0.425"], ["19999.90", "2.380"], ["20099.90", "0.520"], ["20399.90", "0.100"], ["66953.00", "0.002"], ["69583.40", "10.619"], ["69794.90", "8.276"], ["70147.40", "4.590"], ["70320.10", "0.000"], ["70344.80", "6.607"], ["70365.50", "0.850"], ["70447.10", "0.004"], ["70453.00", "0.007"], ["70453.10", "1.068"], ["70463.30", "0.002"], ["70486.70", "0.448"], ["70489.30", "0.003"], ["70490.20", "0.915"], ["70492.00", "0.091"], ["70493.00", "0.523"]], "a": [["70500.00", "1.668"], ["70502.80", "0.030"], ["70503.40", "0.006"], ["70506.30", "0.002"], ["70507.10", "0.007"], ["70507.50", "0.061"], ["70507.70", "0.019"], ["70515.90", "0.400"], ["70517.00", "0.015"], ["70518.30", "0.042"], ["70523.80", "0.007"], ["70524.60", "0.646"], ["70535.20", "1.612"], ["70563.40", "0.136"], ["70592.10", "0.051"], ["70601.60", "0.164"], ["70633.70", "0.573"], ["71205.00", "6.076"], ["71346.00", "10.494"], ["71480.00", "6.747"], ["72272.00", "4.972"], ["74040.70", "0.166"]]}}
{"local_ts": 1773485391572, "server_ts": 1773485390780, "data": {"e": "depthUpdate", "E": 1773485390781, "T": 1773485390780, "s": "BTCUSDT", "U": 10109445437573, "u": 10109445440385, "pu": 10109445437503, "b": [["1000.00", "28.842"], ["5000.00", "101.398"], ["7050.00", "0.425"], ["19999.90", "0.860"], ["20399.90", "2.140"], ["66968.40", "0.000"], ["66974.00", "0.000"], ["69308.50", "0.863"], ["69548.20", "4.300"], ["69718.30", "2.361"], ["69794.90", "8.276"], ["69894.00", "0.012"], ["70320.10", "0.159"], ["70431.20", "0.064"], ["70447.10", "0.000"], ["70453.10", "1.066"], ["70453.20", "0.004"], ["70463.30", "0.006"], ["70464.70", "0.002"], ["70473.00", "0.000"], ["70473.30", "0.000"], ["70476.00", "0.271"], ["70488.90", "0.000"], ["70489.30", "0.003"], ["70489.70", "0.001"], ["70490.40", "0.660"], ["70491.10", "0.069"], ["70492.40", "0.012"], ["70492.90", "0.271"]], "a": [["70500.00", "1.556"], ["70502.30", "0.002"], ["70502.80", "0.030"], ["70505.20", "0.001"], ["70506.50", "0.006"], ["70507.00", "0.039"], ["70510.60", "0.015"], ["70517.60", "0.365"], ["70521.10", "0.374"], ["70524.80", "0.002"], ["70525.70", "1.152"], ["70526.40", "0.000"], ["70527.40", "0.070"], ["70527.90", "0.049"], ["70535.10", "0.556"], ["70535.20", "1.513"], ["70544.40", "0.266"], ["70549.30", "0.031"], ["70563.40", "0.051"], ["70849.00", "0.002"], ["71205.00", "6.076"], ["73319.90", "0.114"]]}}
{"local_ts": 1773485392599, "server_ts": 1773485391804, "data": {"e": "depthUpdate", "E": 1773485391805, "T": 1773485391804, "s": "BTCUSDT", "U": 10109445471750, "u": 10109445474627, "pu": 10109445471640, "b": [["5000.00", "101.418"], ["7050.00", "0.481"], ["20299.90", "1.700"], ["20399.90", "1.300"], ["66973.70", "0.000"], ["69078.80", "0.000"], ["69086.00", "0.680"], ["69157.10", "0.002"], ["69164.30", "0.890"], ["69235.50", "0.004"], ["69242.60", "0.382"], ["69313.80", "0.000"], ["69321.00", "0.412"], ["69392.10", "0.934"], ["69399.30", "0.380"], ["69470.40", "0.002"], ["69477.60", "0.382"], ["69548.80", "0.000"], ["69556.00", "0.461"], ["69627.10", "0.000"], ["69634.30", "0.380"], ["69705.40", "0.002"], ["69712.60", "0.395"], ["69783.70", "0.004"], ["69790.90", "0.380"], ["69794.90", "8.276"], ["70414.40", "0.624"], ["70447.00", "0.045"], ["70453.10", "1.066"], ["70453.20", "0.004"], ["70454.00", "0.730"], ["70463.30", "0.006"], ["70473.10", "0.006"], ["70489.30", "0.000"], ["70492.60", "0.405"]], "a": [["70510.60", "0.061"], ["70676.20", "0.175"], ["71193.50", "0.000"], ["71200.90", "0.382"], ["71205.00", "6.076"], ["71271.80", "0.068"], ["71279.20", "0.380"], ["71350.10", "0.000"], ["71357.50", "0.380"], ["71428.40", "0.005"], ["71506.80", "0.000"], ["71585.10", "0.209"], ["71663.40", "0.002"], ["71716.10", "1.391"], ["71741.70", "0.019"], ["71820.10", "0.000"], ["71898.40", "0.000"], ["71975.70", "0.000"]]}}
{"local_ts": 1773485393625, "server_ts": 1773485392824, "data": {"e": "depthUpdate", "E": 1773485392827, "T": 1773485392824, "s": "BTCUSDT", "U": 10109445509116, "u": 10109445512675, "pu": 10109445509077, "b": [["1000.00", "28.842"], ["5000.00", "101.418"], ["7050.00", "0.481"], ["20199.90", "1.250"], ["20299.90", "1.750"], ["66957.20", "0.029"], ["69794.90", "8.276"], ["70147.40", "4.661"], ["70147.50", "0.000"], ["70254.00", "0.077"], ["70492.60", "0.405"]], "a": [["70503.20", "0.016"], ["70510.60", "0.061"], ["70513.80", "0.005"], ["70521.10", "0.374"], ["70549.30", "0.031"], ["71205.00", "6.076"], ["71346.00", "12.174"], ["71572.80", "0.698"], ["74040.10", "0.046"]]}}
{"local_ts": 1773485394640, "server_ts": 1773485393845, "data": {"e": "depthUpdate", "E": 1773485393847, "T": 1773485393845, "s": "BTCUSDT", "U": 10109445581777, "u": 10109445591683, "pu": 10109445581680, "b": [["1000.00", "28.842"], ["5000.00", "101.418"], ["7050.00", "0.481"], ["20099.90", "0.800"], ["20199.90", "2.200"], ["33000.00", "3.785"], ["56400.00", "6.997"], ["63449.90", "0.010"], ["68363.20", "0.000"], ["69548.20", "4.987"], ["69642.80", "0.059"], ["69794.90", "8.276"], ["70333.30", "0.866"], ["70335.40", "0.172"], ["70452.90", "0.007"], ["70453.00", "0.009"], ["70469.10", "0.000"], ["70471.80", "1.582"], ["70482.30", "1.494"], ["70483.60", "0.019"], ["70484.20", "0.189"], ["70484.30", "0.014"], ["70485.30", "0.027"], ["70485.70", "0.004"], ["70485.90", "0.345"], ["70486.00", "1.038"], ["70486.70", "0.456"], ["70487.00", "0.085"], ["70487.60", "0.346"], ["70490.20", "0.874"], ["70496.70", "0.004"], ["70499.90", "3.097"]], "a": [["70500.00", "2.858"], ["70507.70", "0.014"], ["70511.80", "0.151"], ["70514.10", "0.083"], ["70515.00", "0.515"], ["70515.10", "0.476"], ["70515.30", "0.469"], ["70515.40", "0.118"], ["70515.60", "0.200"], ["70517.40", "0.092"], ["70520.30", "0.002"], ["70521.00", "0.783"], ["70522.90", "0.000"], ["70523.00", "0.033"], ["70523.60", "1.081"], ["70523.70", "0.548"], ["70525.30", "0.002"], ["70528.30", "0.248"], ["70549.30", "0.091"], ["70676.20", "0.115"], ["70723.40", "0.000"], ["70817.00", "0.007"], ["71205.00", "6.076"], ["72270.00", "1.367"], ["72627.40", "0.592"], ["74056.80", "0.000"], ["77550.00", "0.089"]]}}
{"local_ts": 1773485395661, "server_ts": 1773485394868, "data": {"e": "depthUpdate", "E": 1773485394869, "T": 1773485394868, "s": "BTCUSDT", "U": 10109445648387, "u": 10109445653964, "pu": 10109445648250, "b": [["5000.00", "101.398"], ["7050.00", "0.453"], ["19999.90", "0.390"], ["20099.90", "2.570"], ["20199.90", "0.040"], ["63449.90", "0.010"], ["66942.00", "0.002"], ["66971.90", "0.000"], ["69386.20", "0.038"], ["69580.00", "1.932"], ["69794.90", "8.276"], ["70147.40", "4.661"], ["70333.30", "0.864"], ["70333.90", "0.007"], ["70365.30", "0.812"], ["70365.40", "0.003"], ["70396.30", "0.511"], ["70437.10", "0.108"], ["70464.70", "0.067"], ["70482.30", "1.672"], ["70487.00", "0.000"], ["70490.30", "0.086"], ["70495.50", "0.095"]], "a": [["70505.40", "0.121"], ["70515.30", "0.554"], ["70515.50", "0.021"], ["70535.20", "1.541"], ["70539.50", "0.001"], ["70631.00", "0.552"], ["70633.00", "0.000"], ["71055.70", "0.000"], ["71059.80", "1.855"], ["71249.90", "3.243"], ["71431.70", "0.000"], ["71565.70", "0.418"], ["77550.00", "0.089"]]}}
{"local_ts": 1773485396681, "server_ts": 1773485395888, "data": {"e": "depthUpdate", "E": 1773485395889, "T": 1773485395888, "s": "BTCUSDT", "U": 10109445751460, "u": 10109445756073, "pu": 10109445751378, "b": [["1000.00", "28.842"], ["5000.00", "101.418"], ["7050.00", "0.453"], ["19999.90", "2.490"], ["20099.90", "0.300"], ["20399.90", "0.210"], ["33000.00", "3.789"], ["56400.00", "7.002"], ["63449.90", "0.010"], ["66955.70", "0.002"], ["68968.00", "0.620"], ["69794.90", "8.634"], ["70215.90", "0.000"], ["70316.60", "0.099"], ["70333.90", "0.005"], ["70340.70", "0.002"], ["70353.50", "0.077"], ["70356.80", "1.708"], ["70403.30", "0.094"], ["70412.10", "0.002"], ["70413.00", "0.926"], ["70443.40", "0.005"], ["70447.30", "0.045"], ["70451.00", "0.226"], ["70452.60", "0.004"], ["70452.80", "0.042"], ["70460.90", "0.019"], ["70463.30", "0.002"], ["70464.70", "0.043"], ["70466.60", "0.001"], ["70468.60", "0.021"], ["70477.80", "1.088"], ["70478.40", "0.366"], ["70481.30", "0.263"], ["70482.30", "1.144"], ["70482.40", "0.185"], ["70486.90", "0.085"], ["70487.20", "0.077"]], "a": [["70500.00", "4.659"], ["70518.80", "0.187"], ["70523.50", "0.076"], ["70524.90", "0.253"], ["70535.20", "1.543"], ["70549.70", "0.085"], ["70554.50", "3.583"], ["70555.60", "0.060"], ["70567.00", "0.114"], ["70651.70", "0.000"], ["70665.80", "0.018"], ["70676.20", "0.175"], ["70679.80", "2.587"], ["71205.00", "6.076"], ["71255.00", "3.455"], ["77550.00", "0.089"]]}}
{"local_ts": 1773485397703, "server_ts": 1773485396912, "data": {"e": "depthUpdate", "E": 1773485396913, "T": 1773485396912, "s": "BTCUSDT", "U": 10109445823280, "u": 10109445828497, "pu": 10109445823206, "b": [["5000.00", "101.418"], ["7050.00", "0.453"], ["19999.90", "0.590"], ["20299.90", "0.060"], ["20399.90", "2.350"], ["63449.90", "0.010"], ["66974.90", "0.004"], ["66975.00", "0.092"], ["69269.70", "0.000"], ["69407.20", "17.697"], ["69477.70", "43.153"], ["69794.90", "8.634"], ["69935.90", "1.648"], ["70329.70", "0.092"], ["70340.70", "0.000"], ["70365.40", "0.735"], ["70451.00", "0.222"], ["70453.00", "0.007"], ["70453.20", "0.004"], ["70462.30", "0.090"], ["70476.20", "0.070"], ["70477.40", "0.004"], ["70478.50", "0.007"], ["70479.50", "0.010"], ["70480.10", "1.211"], ["70482.30", "1.117"], ["70482.40", "0.001"], ["70483.80", "0.003"], ["70484.90", "0.208"], ["70485.30", "0.029"], ["70485.80", "0.549"], ["70486.20", "0.192"], ["70486.30", "0.002"], ["70486.90", "0.269"], ["70487.10", "0.060"], ["70488.20", "0.012"], ["70488.30", "0.005"], ["70489.20", "0.000"], ["70489.90", "0.025"], ["70491.30", "0.000"], ["70492.00", "0.088"], ["70492.30", "0.005"], ["70492.40", "0.011"], ["70492.90", "0.239"], ["70493.20", "0.065"], ["70495.40", "0.006"], ["70496.00", "0.008"], ["70496.50", "0.115"], ["70496.90", "0.002"], ["70497.40", "0.000"]], "a": [["70500.00", "4.167"], ["70505.70", "0.089"], ["70506.80", "0.039"], ["70508.00", "0.085"], ["70508.70", "0.061"], ["70511.00", "0.080"], ["70514.10", "0.002"], ["70516.90", "0.052"], ["70520.70", "0.195"], ["70525.60", "0.003"], ["70525.80", "0.007"], ["70526.00", "0.250"], ["70528.30", "0.052"], ["70528.60", "0.281"], ["70550.70", "0.123"], ["70587.40", "0.541"], ["70630.90", "0.537"], ["70676.20", "0.175"], ["71205.00", "6.076"], ["71909.90", "0.012"], ["74030.60", "0.002"], ["77550.00", "0.089"]]}}
{"local_ts": 1773485398723, "server_ts": 1773485397928, "data": {"e": "depthUpdate", "E": 1773485397933, "T": 1773485397928, "s": "BTCUSDT", "U": 10109445876354, "u": 10109445881197, "pu": 10109445876226, "b": [["1000.00", "28.842"], ["5000.00", "101.418"], ["7050.00", "0.453"], ["20299.90", "2.010"], ["20399.90", "0.990"], ["69477.70", "42.147"], ["69794.90", "8.634"], ["69795.00", "0.103"], ["70041.90", "0.002"], ["70147.40", "4.661"], ["70245.10", "0.000"], ["70254.00", "0.073"], ["70289.60", "0.000"], ["70329.70", "0.090"], ["70330.50", "1.261"], ["70333.10", "0.002"], ["70447.10", "0.038"], ["70452.90", "0.007"], ["70453.00", "0.009"], ["70454.60", "0.004"], ["70482.30", "0.848"], ["70484.00", "0.632"], ["70484.90", "0.208"], ["70486.40", "0.000"], ["70486.70", "0.048"], ["70490.20", "0.112"], ["70491.10", "0.180"], ["70492.90", "0.052"], ["70493.10", "0.050"], ["70497.70", "0.000"], ["70499.90", "1.420"]], "a": [["70501.20", "0.006"], ["70511.60", "0.128"], ["70511.80", "0.002"], ["70515.10", "0.321"], ["70515.30", "0.069"], ["70517.60", "0.330"], ["70521.60", "0.664"], ["70528.60", "0.279"], ["70535.10", "0.556"], ["70545.20", "0.011"], ["70549.30", "0.130"], ["70706.40", "0.016"], ["70743.50", "0.033"], ["70812.10", "0.000"], ["70863.30", "0.004"], ["71034.30", "0.000"], ["71180.60", "0.021"], ["71205.00", "6.076"], ["74049.20", "0.002"], ["89523.20", "0.000"]]}}
{"local_ts": 1773485399743, "server_ts": 1773485398952, "data": {"e": "depthUpdate", "E": 1773485398953, "T": 1773485398952, "s": "BTCUSDT", "U": 10109445923130, "u": 10109445927114, "pu": 10109445923105, "b": [["1000.00", "28.842"], ["5000.00", "101.438"], ["7050.00", "0.425"], ["20199.90", "1.570"], ["20299.90", "1.430"], ["56400.00", "6.994"], ["63449.90", "0.008"], ["66954.60", "0.019"], ["69794.90", "8.634"], ["70365.40", "0.003"], ["70367.20", "7.384"], ["70484.20", "0.189"]], "a": [["70500.00", "4.502"], ["70501.20", "0.004"], ["70503.90", "0.013"], ["70510.30", "0.003"], ["70510.90", "0.144"], ["70517.40", "0.027"], ["70517.50", "0.207"], ["70518.30", "0.007"], ["70519.70", "0.178"], ["70543.40", "0.002"], ["70545.20", "0.011"], ["70557.00", "0.014"], ["70630.60", "9.600"], ["70630.90", "0.190"], ["71205.00", "5.375"], ["71755.50", "0.000"], ["77550.00", "0.087"], ["89523.20", "0.000"]]}}
{"local_ts": 1773485400769, "server_ts": 1773485399976, "data": {"e": "depthUpdate", "E": 1773485399977, "T": 1773485399976, "s": "BTCUSDT", "U": 10109445972846, "u": 10109445977542, "pu": 10109445972748, "b": [["5000.00", "101.418"], ["7050.00", "0.425"], ["20099.90", "1.120"], ["20199.90", "1.880"], ["56400.00", "6.994"], ["63449.90", "0.008"], ["66971.30", "0.000"], ["66974.00", "0.000"], ["66974.90", "0.006"], ["66975.00", "0.090"], ["69636.50", "1.433"], ["69731.50", "8.870"], ["69794.90", "8.634"], ["70147.40", "4.661"], ["70323.70", "0.304"], ["70365.40", "0.003"], ["70408.80", "0.001"], ["70470.60", "0.000"], ["70472.50", "0.008"], ["70482.30", "1.215"], ["70484.20", "0.189"], ["70486.70", "0.048"], ["70487.30", "0.069"], ["70489.40", "0.010"], ["70489.50", "0.004"], ["70489.70", "0.004"], ["70493.00", "0.017"], ["70493.10", "0.071"], ["70496.80", "0.002"], ["70497.50", "0.011"]], "a": [["70500.00", "4.338"], ["70502.80", "0.030"], ["70507.10", "0.007"], ["70507.70", "0.004"], ["70630.90", "0.190"], ["70645.20", "0.039"], ["70650.50", "0.293"], ["70815.70", "0.000"], ["71205.00", "5.515"], ["77550.00", "0.087"], ["89523.20", "0.000"]]}}
{"local_ts": 1773485401788, "server_ts": 1773485400995, "data": {"e": "depthUpdate", "E": 1773485400997, "T": 1773485400995, "s": "BTCUSDT", "U": 10109446040075, "u": 10109446046930, "pu": 10109446039979, "b": [["1000.00", "28.842"], ["5000.00", "101.418"], ["7050.00", "0.425"], ["19999.90", "0.670"], ["20099.90", "2.330"], ["20199.90", "0.000"], ["56400.00", "6.994"], ["63449.90", "0.008"], ["68376.10", "3.504"], ["69794.90", "8.634"], ["70452.80", "0.042"], ["70452.90", "0.009"], ["70482.60", "0.074"], ["70483.60", "0.004"]], "a": [["70500.00", "4.336"], ["70507.70", "0.004"], ["70517.60", "0.330"], ["70523.50", "0.006"], ["70524.90", "0.253"], ["70552.00", "0.006"], ["71205.00", "5.515"], ["71268.40", "6.019"], ["71489.50", "0.000"], ["71596.40", "0.634"], ["74030.30", "0.004"], ["77550.00", "0.087"], ["89523.20", "0.000"]]}}
{"local_ts": 1773485402810, "server_ts": 1773485402018, "data": {"e": "depthUpdate", "E": 1773485402019, "T": 1773485402018, "s": "BTCUSDT", "U": 10109446105189, "u": 10109446111394, "pu": 10109446105162, "b": [["5000.00", "101.418"], ["7050.00", "0.481"], ["19999.90", "2.590"], ["20099.90", "0.090"], ["20399.90", "0.320"], ["33000.00", "3.785"], ["63449.90", "0.008"], ["66946.20", "0.000"], ["69111.10", "1.254"], ["69433.10", "0.430"], ["69453.30", "0.000"], ["69794.90", "8.636"], ["70041.60", "1.600"], ["70444.50", "0.102"], ["70445.40", "8.515"], ["70453.00", "0.007"], ["70453.10", "1.068"], ["70469.20", "0.127"], ["70469.70", "0.002"], ["70470.00", "4.938"], ["70470.20", "0.320"], ["70484.70", "0.024"], ["70485.50", "0.005"], ["70485.90", "0.343"], ["70486.10", "0.595"]], "a": [["70500.00", "4.400"], ["70519.60", "0.637"], ["70519.90", "0.003"], ["70532.70", "0.002"], ["70536.50", "1.660"], ["70549.30", "0.373"], ["70550.00", "1.888"], ["70557.80", "0.003"], ["70558.30", "8.501"], ["71205.00", "6.216"], ["77550.00", "0.087"], ["89523.20", "0.000"]]}}
{"local_ts": 1773485403831, "server_ts": 1773485403037, "data": {"e": "depthUpdate", "E": 1773485403039, "T": 1773485403037, "s": "BTCUSDT", "U": 10109446236465, "u": 10109446247122, "pu": 10109446236455, "b": [["1000.00", "28.842"], ["5000.00", "101.418"], ["7050.00", "0.481"], ["19999.90", "0.390"], ["20299.90", "0.170"], ["20399.90", "2.440"], ["56400.00", "6.994"], ["66966.60", "0.002"], ["66974.90", "0.006"], ["69718.30", "0.000"], ["69794.90", "9.349"], ["70147.40", "4.661"], ["70147.50", "1.136"], ["70254.10", "0.000"], ["70449.00", "0.003"], ["70449.10", "0.000"], ["70450.80", "8.514"], ["70451.40", "0.694"], ["70452.00", "0.006"], ["70472.70", "0.186"], ["70475.50", "0.273"], ["70476.00", "0.023"], ["70476.10", "0.001"], ["70476.70", "0.224"], ["70476.90", "0.004"], ["70477.30", "0.091"], ["70482.30", "0.272"], ["70487.20", "0.060"], ["70489.60", "0.640"], ["70490.70", "0.020"], ["70490.80", "0.110"], ["70491.00", "0.001"], ["70491.50", "0.018"]], "a": [["70503.60", "0.001"], ["70504.70", "0.000"], ["70505.60", "0.004"], ["70505.70", "0.000"], ["70506.60", "0.000"], ["70506.70", "0.000"], ["70506.80", "0.087"], ["70506.90", "0.034"], ["70507.00", "0.042"], ["70507.10", "0.005"], ["70507.20", "0.002"], ["70507.30", "0.002"], ["70507.40", "0.058"], ["70507.50", "0.004"], ["70507.60", "0.008"], ["70507.70", "0.004"], ["70507.80", "0.217"], ["70507.90", "0.000"], ["70508.00", "0.028"], ["70508.10", "0.002"], ["70508.20", "0.003"], ["70508.30", "0.659"], ["70508.40", "1.105"], ["70508.50", "0.082"], ["70508.60", "0.000"], ["70508.70", "0.061"], ["70508.80", "0.092"], ["70508.90", "0.005"], ["70509.00", "0.005"], ["70509.10", "0.183"], ["70509.20", "0.000"], ["70510.20", "0.005"], ["70510.40", "0.016"], ["70511.30", "0.003"], ["70511.40", "0.186"], ["70511.50", "0.002"], ["70511.60", "0.288"], ["70511.70", "0.024"], ["70512.70", "0.006"], ["70518.70", "0.345"], ["70518.90", "0.633"], ["70519.00", "0.164"], ["70525.00", "1.658"], ["70526.10", "0.283"], ["70526.80", "0.007"], ["70530.90", "0.254"], ["70532.00", "0.073"], ["70532.70", "0.000"], ["70533.30", "0.064"], ["70535.70", "0.129"], ["70544.80", "0.020"], ["70545.00", "0.001"], ["70549.30", "0.294"], ["70559.10", "0.038"], ["70565.00", "8.503"], ["70566.60", "0.294"], ["70567.70", "0.003"], ["70568.30", "0.041"], ["70593.60", "0.129"], ["70723.60", "0.000"], ["71204.90", "0.007"], ["71205.00", "6.216"], ["71440.20", "3.050"], ["71522.20", "37.495"], ["72027.30", "0.000"], ["74038.90", "0.000"], ["89523.20", "0.000"]]}}
{"local_ts": 1773485404853, "server_ts": 1773485404060, "data": {"e": "depthUpdate", "E": 1773485404061, "T": 1773485404060, "s": "BTCUSDT", "U": 10109446314669, "u": 10109446321182, "pu": 10109446314512, "b": [["1000.00", "28.842"], ["5000.00", "101.418"], ["7050.00", "0.481"], ["20199.90", "0.020"], ["20299.90", "2.300"], ["20399.90", "0.680"], ["33000.00", "3.785"], ["66964.90", "0.000"], ["69399.20", "12.662"], ["69786.70", "0.000"], ["69794.90", "9.349"], ["70453.60", "1.210"], ["70453.70", "0.273"], ["70487.20", "0.056"]], "a": [["70510.50", "0.017"], ["70512.70", "0.003"], ["70513.00", "0.039"], ["70514.30", "0.023"], ["70515.50", "0.029"], ["70524.50", "0.000"], ["70525.20", "0.932"], ["70525.80", "0.005"], ["70526.00", "0.002"], ["70527.00", "0.007"], ["70543.70", "0.820"], ["70544.80", "0.018"], ["70564.80", "0.097"], ["70568.30", "0.039"], ["71205.00", "6.356"], ["71522.20", "39.310"], ["72032.10", "2.978"], ["89523.20", "0.000"]]}}
{"local_ts": 1773485405872, "server_ts": 1773485405080, "data": {"e": "depthUpdate", "E": 1773485405081, "T": 1773485405080, "s": "BTCUSDT", "U": 10109446374097, "u": 10109446377855, "pu": 10109446373954, "b": [["5000.00", "101.418"], ["7050.00", "0.453"], ["20199.90", "1.890"], ["20299.90", "1.110"], ["67680.00", "0.195"], ["69534.10", "1.720"], ["69794.90", "9.349"], ["70147.40", "4.661"], ["70147.50", "1.136"], ["70253.60", "0.000"], ["70452.60", "0.002"], ["70452.80", "0.044"], ["70472.80", "0.001"], ["70473.60", "0.022"], ["70481.90", "0.083"], ["70485.60", "0.025"], ["70486.60", "0.653"], ["70486.70", "0.048"], ["70487.20", "0.056"], ["70488.10", "0.049"], ["70489.90", "0.073"], ["70491.40", "0.007"], ["70492.80", "0.268"], ["70496.70", "0.003"], ["70496.90", "1.068"], ["70497.00", "0.494"]], "a": [["70500.00", "3.478"], ["70503.80", "0.055"], ["70505.30", "0.024"], ["70506.60", "0.015"], ["70506.90", "0.057"], ["70509.00", "0.026"], ["70512.70", "0.003"], ["70513.90", "0.006"], ["70518.10", "0.005"], ["70519.40", "0.004"], ["70520.60", "0.012"], ["70525.40", "0.291"], ["70527.30", "0.000"], ["70536.10", "0.080"], ["70541.90", "0.010"], ["70543.70", "0.818"], ["70564.80", "0.095"], ["71205.00", "6.356"], ["74056.60", "0.000"]]}}
{"local_ts": 1773485406893, "server_ts": 1773485406100, "data": {"e": "depthUpdate", "E": 1773485406103, "T": 1773485406100, "s": "BTCUSDT", "U": 10109446469339, "u": 10109446478603, "pu": 10109446469204, "b": [["1000.00", "29.042"], ["5000.00", "101.418"], ["7050.00", "0.453"], ["20099.90", "1.440"], ["20199.90", "1.560"], ["33000.00", "3.789"], ["55765.50", "0.000"], ["66973.00", "0.030"], ["66974.90", "0.008"], ["66975.00", "0.086"], ["67680.00", "0.207"], ["68385.00", "0.303"], ["69477.70", "44.015"], ["69498.80", "3.718"], ["69566.60", "0.719"], ["69794.90", "9.492"], ["70100.00", "48.827"], ["70430.00", "0.562"], ["70440.00", "0.034"], ["70441.90", "8.517"], ["70443.50", "0.430"], ["70444.20", "0.494"], ["70445.80", "0.001"], ["70452.40", "1.153"], ["70452.60", "0.004"], ["70453.30", "0.040"], ["70460.40", "0.514"], ["70466.10", "0.464"], ["70467.00", "0.054"], ["70467.50", "0.002"], ["70467.70", "0.004"], ["70468.20", "0.021"], ["70469.10", "0.000"], ["70474.60", "0.513"], ["70475.10", "0.073"], ["70475.20", "0.781"], ["70475.70", "0.017"], ["70476.10", "0.008"], ["70477.00", "0.004"], ["70477.40", "0.011"], ["70477.60", "0.022"], ["70478.60", "0.002"], ["70479.30", "0.016"], ["70480.00", "0.753"], ["70480.80", "0.642"], ["70481.70", "0.000"], ["70482.40", "0.006"], ["70483.00", "0.010"], ["70483.30", "0.000"], ["70483.60", "0.008"], ["70485.70", "0.007"], ["70487.20", "0.002"], ["70487.60", "0.023"], ["70492.80", "0.266"], ["70493.40", "0.901"], ["70495.10", "0.196"], ["70495.30", "0.011"], ["70499.90", "0.482"]], "a": [["70500.00", "5.544"], ["70503.60", "0.207"], ["70505.90", "0.003"], ["70506.90", "0.055"], ["70508.00", "0.038"], ["70508.10", "0.017"], ["70512.60", "0.039"], ["70512.70", "0.003"], ["70514.30", "0.028"], ["70514.40", "0.004"], ["70515.10", "0.830"], ["70516.20", "0.660"], ["70516.60", "0.528"], ["70519.20", "0.205"], ["70520.00", "0.085"], ["70520.10", "0.312"], ["70520.60", "0.009"], ["70521.30", "0.010"], ["70521.70", "0.070"], ["70521.90", "0.248"], ["70524.30", "0.004"], ["70524.70", "0.151"], ["70524.90", "0.005"], ["70529.50", "1.341"], ["70531.40", "0.032"], ["70532.90", "0.024"], ["70536.10", "0.078"], ["70536.40", "0.066"], ["70536.90", "0.087"], ["70538.50", "0.005"], ["70541.90", "0.008"], ["70545.60", "0.010"], ["70549.30", "0.234"], ["70552.70", "0.000"], ["70554.90", "8.596"], ["70558.90", "0.004"], ["70567.60", "0.000"], ["71205.00", "6.356"]]}}
{"local_ts": 1773485407921, "server_ts": 1773485407122, "data": {"e": "depthUpdate", "E": 1773485407123, "T": 1773485407122, "s": "BTCUSDT", "U": 10109446539166, "u": 10109446545197, "pu": 10109446539046, "b": [["5000.00", "101.418"], ["7050.00", "0.453"], ["19999.90", "0.990"], ["20099.90", "2.010"], ["55765.50", "0.002"], ["69135.40", "0.391"], ["69497.90", "2.156"], ["69583.40", "12.341"], ["69794.90", "9.492"], ["69795.00", "0.099"], ["70253.50", "0.360"], ["70316.60", "0.099"], ["70452.00", "0.008"], ["70452.60", "0.099"], ["70453.30", "0.922"], ["70460.40", "1.356"], ["70465.10", "0.094"], ["70465.20", "8.186"], ["70465.50", "0.178"], ["70467.00", "0.103"], ["70467.50", "0.844"], ["70474.60", "1.355"], ["70476.60", "0.069"], ["70481.20", "0.003"], ["70481.70", "0.842"], ["70483.20", "0.638"], ["70484.70", "0.022"], ["70484.80", "0.000"], ["70484.90", "0.208"], ["70485.00", "0.149"], ["70485.10", "0.002"], ["70485.20", "0.021"], ["70485.30", "0.027"], ["70485.40", "0.287"], ["70485.50", "0.005"], ["70485.60", "0.004"], ["70485.70", "0.007"], ["70485.80", "0.016"], ["70485.90", "0.343"], ["70486.10", "0.597"], ["70486.20", "0.008"], ["70486.30", "0.002"], ["70486.40", "0.000"], ["70486.50", "0.407"], ["70486.60", "0.015"], ["70486.80", "0.522"], ["70487.20", "0.002"], ["70489.50", "0.004"], ["70489.70", "0.007"], ["70490.80", "0.617"], ["70491.60", "0.347"], ["70492.80", "0.000"], ["70493.30", "0.313"], ["70493.70", "0.004"], ["70494.00", "0.002"], ["70494.40", "0.003"], ["70494.70", "0.005"], ["70495.10", "0.196"], ["70497.00", "0.119"]], "a": [["70500.00", "5.139"], ["70505.80", "0.200"], ["70506.90", "0.055"], ["70507.00", "0.731"], ["70512.70", "0.003"], ["70518.00", "0.010"], ["70518.70", "0.641"], ["70519.30", "0.088"], ["70519.80", "0.008"], ["70522.60", "0.061"], ["70524.30", "0.846"], ["70524.90", "0.253"], ["70528.50", "1.086"], ["70529.50", "1.364"], ["70529.70", "0.015"], ["70531.40", "0.849"], ["70535.00", "0.184"], ["70535.10", "0.520"], ["70536.00", "0.106"], ["70536.20", "0.002"], ["70538.50", "0.847"], ["70541.00", "0.020"], ["70545.60", "0.852"], ["70552.70", "0.842"], ["70582.00", "0.005"], ["70582.50", "0.002"], ["70676.20", "0.175"], ["71205.00", "6.356"], ["71536.40", "13.381"], ["74052.90", "0.002"]]}}
{"local_ts": 1773485408936, "server_ts": 1773485408144, "data": {"e": "depthUpdate", "E": 1773485408145, "T": 1773485408144, "s": "BTCUSDT", "U": 10109446589490, "u": 10109446593630, "pu": 10109446589411, "b": [["1000.00", "29.242"], ["5000.00", "101.398"], ["7050.00", "0.425"], ["19999.90", "2.450"], ["20099.90", "0.000"], ["20399.90", "0.550"], ["55765.50", "0.000"], ["66947.10", "0.000"], ["69794.90", "9.492"], ["70147.40", "4.661"], ["70446.90", "0.000"], ["70471.90", "0.327"], ["70487.20", "0.002"], ["70489.90", "0.224"], ["70491.10", "0.112"], ["70492.90", "0.256"], ["70499.20", "0.748"]], "a": [["70500.00", "4.340"], ["70507.00", "0.731"], ["70512.70", "0.003"], ["70582.50", "0.000"], ["70589.60", "0.002"], ["70676.20", "0.175"], ["71205.00", "6.356"], ["71457.60", "0.559"], ["71522.20", "39.310"], ["74048.80", "0.000"], ["74054.80", "0.044"]]}}
{"local_ts": 1773485409962, "server_ts": 1773485409162, "data": {"e": "depthUpdate", "E": 1773485409165, "T": 1773485409162, "s": "BTCUSDT", "U": 10109446632587, "u": 10109446637172, "pu": 10109446632478, "b": [["1000.00", "29.242"], ["5000.00", "101.418"], ["7050.00", "0.425"], ["19999.90", "0.180"], ["20299.90", "0.270"], ["20399.90", "2.550"], ["55765.50", "0.002"], ["56400.00", "6.994"], ["66974.30", "0.000"], ["69477.70", "44.015"], ["69794.90", "9.492"], ["70147.50", "1.136"], ["70254.00", "0.073"], ["70431.20", "0.581"], ["70453.30", "0.082"], ["70453.40", "0.002"], ["70471.70", "1.776"], ["70471.90", "0.143"], ["70476.00", "0.533"], ["70476.80", "0.310"], ["70485.70", "0.022"], ["70489.30", "0.018"], ["70492.30", "0.005"], ["70492.60", "0.024"], ["70492.80", "0.000"], ["70492.90", "0.241"], ["70494.10", "0.003"], ["70494.20", "0.004"], ["70494.30", "0.000"], ["70495.80", "0.001"], ["70498.00", "0.021"], ["70498.20", "0.003"]], "a": [["70500.00", "4.007"], ["70501.50", "0.021"], ["70506.90", "0.034"], ["70514.60", "0.003"], ["70515.40", "0.040"], ["70523.70", "0.539"], ["70524.70", "0.221"], ["70549.20", "0.109"], ["70549.30", "0.373"], ["70549.80", "0.184"], ["70580.00", "0.145"], ["70589.60", "0.142"], ["71205.00", "6.356"], ["71501.10", "4.448"], ["71522.20", "39.310"], ["71711.40", "0.000"]]}}
{"local_ts": 1773485410978, "server_ts": 1773485410184, "data": {"e": "depthUpdate", "E": 1773485410187, "T": 1773485410184, "s": "BTCUSDT", "U": 10109446685191, "u": 10109446689964, "pu": 10109446685142, "b": [["5000.00", "101.418"], ["7050.00", "0.425"], ["20199.90", "0.120"], ["20299.90", "2.410"], ["20399.90", "0.470"], ["55765.50", "0.000"], ["66957.10", "0.023"], ["69636.90", "0.716"], ["69794.90", "8.061"], ["70147.40", "4.661"], ["70147.50", "1.132"], ["70254.10", "0.004"], ["70448.00", "0.887"], ["70462.00", "0.010"], ["70490.90", "0.007"], ["70491.20", "0.102"]], "a": [["70549.20", "0.024"], ["70580.00", "0.143"], ["70584.70", "0.002"], ["71205.00", "6.506"]]}}
{"local_ts": 1773485412000, "server_ts": 1773485411204, "data": {"e": "depthUpdate", "E": 1773485411207, "T": 1773485411204, "s": "BTCUSDT", "U": 10109446728101, "u": 10109446731639, "pu": 10109446728035, "b": [["1000.00", "28.842"], ["5000.00", "101.418"], ["7050.00", "0.481"], ["20199.90", "2.200"], ["20299.90", "0.800"], ["33000.00", "3.785"], ["55765.50", "0.002"], ["66943.80", "0.002"], ["66954.50", "0.002"], ["69794.90", "8.061"], ["69935.90", "1.571"], ["70006.40", "0.004"], ["70360.00", "0.562"], ["70360.10", "0.638"], ["70445.90", "0.000"], ["70453.50", "0.001"], ["70453.60", "1.212"], ["70462.20", "0.004"]], "a": [["70584.70", "0.000"], ["70586.00", "0.055"], ["70630.60", "0.402"], ["70638.60", "0.041"], ["70639.60", "0.088"], ["70645.60", "11.736"], ["70646.60", "0.022"], ["70652.60", "0.010"], ["70653.60", "0.009"], ["70659.60", "0.000"], ["70660.60", "0.007"], ["70666.60", "0.094"], ["70667.60", "0.007"], ["70673.60", "0.000"], ["70674.60", "0.007"], ["70676.20", "0.175"], ["70680.60", "0.204"], ["70681.60", "0.011"], ["70687.60", "0.000"], ["70688.60", "0.518"], ["70688.70", "0.003"], ["70834.90", "0.211"], ["70988.00", "0.127"], ["70988.30", "0.724"], ["70993.60", "0.008"], ["71064.00", "5.762"], ["71205.00", "6.356"], ["71287.30", "0.000"], ["71287.90", "0.731"], ["71346.00", "13.292"], ["71586.60", "0.000"]]}}
{"local_ts": 1773485413028, "server_ts": 1773485412232, "data": {"e": "depthUpdate", "E": 1773485412235, "T": 1773485412232, "s": "BTCUSDT", "U": 10109446766184, "u": 10109446769455, "pu": 10109446766169, "b": [["5000.00", "101.418"], ["7050.00", "0.481"], ["20099.90", "1.770"], ["20199.90", "1.230"], ["55765.50", "0.000"], ["66955.90", "0.000"], ["69450.40", "0.574"], ["69472.70", "7.345"], ["69477.70", "44.159"], ["69653.90", "7.592"], ["69794.90", "9.492"], ["70337.80", "0.000"], ["70342.20", "2.745"], ["70351.90", "12.528"], ["70352.00", "0.020"], ["70353.30", "2.890"], ["70401.40", "0.213"], ["70408.50", "0.338"], ["70410.50", "6.557"], ["70413.00", "1.956"], ["70415.50", "0.073"], ["70445.40", "11.877"], ["70464.70", "0.030"], ["70466.60", "1.784"], ["70477.20", "0.052"], ["70480.10", "0.006"], ["70480.50", "1.205"], ["70488.70", "0.023"], ["70489.30", "0.000"], ["70490.60", "0.101"], ["70492.90", "0.112"], ["70496.00", "0.000"], ["70497.70", "0.000"], ["70499.90", "1.741"]], "a": [["70507.00", "0.724"], ["70532.10", "2.431"], ["70535.20", "1.561"], ["70553.20", "1.104"], ["70553.30", "4.341"], ["70577.70", "1.240"], ["70577.80", "0.071"], ["70584.70", "0.000"], ["70588.10", "6.512"], ["70591.80", "0.000"], ["70591.90", "0.071"], ["70637.20", "0.007"], ["70639.60", "0.081"], ["70644.00", "2.689"], ["70644.20", "0.007"], ["70646.40", "0.026"], ["70646.50", "12.428"], ["70646.60", "0.015"], ["70651.20", "0.007"], ["70653.60", "0.002"], ["70658.20", "0.518"], ["70660.60", "0.000"], ["70665.20", "0.015"], ["70667.60", "0.000"], ["70669.80", "0.000"], ["70672.20", "0.120"], ["70674.60", "0.000"], ["70676.20", "0.076"], ["70679.20", "0.009"], ["70681.60", "0.004"], ["70683.30", "0.000"], ["70686.20", "17.020"], ["70688.60", "0.511"], ["70834.90", "0.211"], ["71205.00", "6.736"]]}}
{"local_ts": 1773485414049, "server_ts": 1773485413256, "data": {"e": "depthUpdate", "E": 1773485413257, "T": 1773485413256, "s": "BTCUSDT", "U": 10109446798774, "u": 10109446801770, "pu": 10109446798718, "b": [["1000.00", "28.842"], ["5000.00", "101.418"], ["7050.00", "0.481"], ["19999.90", "1.330"], ["20099.90", "1.670"], ["33000.00", "3.789"], ["55765.50", "0.002"], ["66945.30", "0.002"], ["68790.70", "0.000"], ["69407.20", "19.063"], ["69477.70", "46.027"], ["69597.50", "0.007"], ["69786.90", "5.974"], ["69794.90", "9.492"], ["70147.40", "4.661"], ["70360.80", "0.015"], ["70401.40", "0.213"], ["70401.50", "0.018"], ["70406.40", "0.114"], ["70406.50", "0.150"], ["70408.50", "0.267"], ["70408.60", "0.071"], ["70413.50", "0.000"], ["70413.60", "0.142"], ["70415.50", "0.002"], ["70415.60", "0.355"], ["70420.50", "0.002"], ["70420.60", "0.145"], ["70453.40", "0.002"], ["70453.50", "0.003"], ["70454.50", "0.007"], ["70462.00", "0.010"], ["70473.70", "0.038"], ["70484.50", "0.638"], ["70484.80", "0.002"], ["70486.10", "0.602"], ["70486.20", "0.005"], ["70487.60", "0.141"], ["70496.40", "0.019"]], "a": [["70500.00", "4.153"], ["70501.10", "0.001"], ["70522.70", "0.266"], ["70523.10", "0.070"], ["70525.30", "0.002"], ["70525.80", "0.255"], ["70534.80", "0.007"], ["70547.40", "0.004"], ["70575.70", "0.000"], ["70575.80", "0.142"], ["70577.80", "0.000"], ["70577.90", "0.091"], ["70582.70", "0.000"], ["70582.80", "0.144"], ["70584.80", "0.004"], ["70584.90", "0.071"], ["70589.80", "0.263"], ["70589.90", "2.530"], ["70591.90", "0.000"], ["70592.00", "0.073"], ["70604.60", "0.000"], ["70617.00", "0.007"], ["70624.00", "0.007"], ["70630.60", "0.002"], ["70631.00", "0.210"], ["70637.20", "0.000"], ["70638.00", "1.427"], ["70644.20", "0.000"], ["70645.00", "0.266"], ["70651.20", "0.000"], ["70652.00", "0.014"], ["70658.20", "0.511"], ["70659.00", "0.017"], ["70665.20", "0.008"], ["70666.00", "0.232"], ["70672.20", "0.113"], ["70679.20", "0.002"], ["70686.20", "17.013"], ["70723.80", "0.217"], ["70834.90", "0.000"], ["71196.80", "4.354"], ["71196.90", "0.028"], ["71205.00", "6.736"], ["71566.30", "1.422"], ["74027.50", "0.000"]]}}
{"local_ts": 1773485415073, "server_ts": 1773485414282, "data": {"e": "depthUpdate", "E": 1773485414283, "T": 1773485414282, "s": "BTCUSDT", "U": 10109446839425, "u": 10109446843381, "pu": 10109446839399, "b": [["1000.00", "28.842"], ["5000.00", "101.398"], ["7050.00", "0.453"], ["19999.90", "2.110"], ["20399.90", "0.890"], ["66966.60", "0.000"], ["69794.90", "9.506"], ["70316.60", "0.099"], ["70401.60", "0.018"], ["70408.70", "0.165"], ["70415.70", "0.089"], ["70444.20", "8.521"], ["70444.30", "2.023"], ["70447.50", "0.671"], ["70453.30", "0.040"], ["70453.50", "0.003"], ["70464.70", "0.002"], ["70467.70", "0.004"], ["70468.90", "1.308"], ["70469.10", "0.000"], ["70474.10", "0.000"], ["70474.70", "0.091"], ["70475.60", "0.141"], ["70475.90", "0.584"], ["70476.20", "0.000"], ["70479.20", "0.012"], ["70479.40", "0.444"], ["70480.30", "0.028"], ["70481.70", "0.007"], ["70482.20", "0.015"], ["70482.70", "0.641"], ["70483.00", "0.010"], ["70483.60", "0.406"], ["70483.90", "0.007"], ["70485.10", "0.009"], ["70485.20", "0.021"], ["70486.60", "0.298"], ["70487.00", "0.027"], ["70487.40", "0.004"], ["70487.50", "0.025"], ["70487.60", "0.141"], ["70495.40", "0.024"], ["70499.90", "0.596"]], "a": [["70500.00", "4.431"], ["70510.90", "0.005"], ["70511.30", "0.144"], ["70512.60", "0.018"], ["70514.60", "0.010"], ["70516.00", "0.000"], ["70518.10", "0.146"], ["70518.80", "0.345"], ["70519.10", "0.515"], ["70519.60", "0.000"], ["70520.20", "0.086"], ["70520.50", "0.010"], ["70520.80", "1.085"], ["70521.20", "0.601"], ["70521.30", "0.057"], ["70522.30", "0.004"], ["70523.10", "0.070"], ["70523.70", "0.539"], ["70525.90", "0.525"], ["70526.70", "0.005"], ["70535.20", "1.513"], ["70540.80", "0.008"], ["70577.90", "0.020"], ["70578.00", "0.116"], ["70584.90", "0.000"], ["70585.00", "0.123"], ["70592.00", "0.002"], ["70592.10", "0.122"], ["70617.00", "0.000"], ["70624.00", "0.000"], ["70631.00", "0.203"], ["70638.00", "1.420"], ["70645.00", "0.259"], ["70652.00", "0.007"], ["70659.00", "0.010"], ["70666.00", "0.225"], ["71205.00", "6.750"]]}}
{"local_ts": 1773485416093, "server_ts": 1773485415302, "data": {"e": "depthUpdate", "E": 1773485415303, "T": 1773485415302, "s": "BTCUSDT", "U": 10109446885609, "u": 10109446891032, "pu": 10109446885473, "b": [["5000.00", "101.418"], ["7050.00", "0.453"], ["19999.90", "0.010"], ["20299.90", "0.450"], ["20399.90", "2.540"], ["33000.00", "3.789"], ["69089.90", "0.888"], ["69442.40", "1.663"], ["69455.60", "9.844"], ["69597.50", "0.028"], ["69794.90", "9.541"], ["70147.40", "4.589"], ["70253.80", "0.004"], ["70364.80", "0.004"], ["70364.90", "8.313"], ["70472.80", "0.166"], ["70475.00", "0.008"], ["70475.30", "0.152"], ["70475.60", "0.000"], ["70475.70", "0.512"], ["70476.10", "0.001"], ["70476.30", "0.000"], ["70476.90", "0.011"], ["70477.10", "0.070"], ["70478.90", "1.212"], ["70479.20", "0.005"], ["70483.20", "0.000"], ["70483.40", "0.052"], ["70483.60", "0.406"], ["70483.70", "1.714"], ["70484.30", "0.014"], ["70485.30", "0.042"], ["70485.40", "0.063"], ["70485.50", "0.005"], ["70485.60", "0.004"], ["70485.70", "0.007"], ["70485.80", "0.127"], ["70485.90", "0.343"], ["70486.00", "0.468"], ["70486.10", "0.595"], ["70486.20", "0.005"], ["70486.30", "0.002"], ["70486.40", "0.000"], ["70486.60", "0.298"], ["70486.80", "0.522"], ["70486.90", "0.000"], ["70487.00", "0.012"], ["70487.10", "0.403"], ["70487.20", "0.087"], ["70487.40", "0.004"], ["70487.50", "0.025"], ["70487.60", "0.002"], ["70487.70", "0.003"], ["70487.90", "0.018"], ["70491.10", "0.251"], ["70495.90", "0.085"], ["70496.00", "0.000"], ["70499.90", "0.596"]], "a": [["70500.00", "4.377"], ["70506.80", "0.024"], ["70507.70", "0.002"], ["70510.70", "0.157"], ["70511.30", "0.003"], ["70511.40", "0.281"], ["70511.60", "0.385"], ["70515.10", "0.830"], ["70515.70", "0.007"], ["70515.90", "0.000"], ["70516.80", "0.002"], ["70519.10", "0.005"], ["70519.60", "1.147"], ["70519.70", "0.002"], ["70523.60", "0.006"], ["70523.80", "0.077"], ["70525.90", "0.525"], ["70526.60", "0.052"], ["70529.70", "0.028"], ["70534.00", "0.057"], ["70544.20", "0.008"], ["70549.30", "0.334"], ["70630.80", "8.416"], ["70676.20", "0.175"], ["70834.90", "0.211"], ["71205.00", "6.918"], ["71402.40", "0.028"], ["71512.90", "0.017"], ["71557.50", "0.014"], ["71910.00", "8.894"], ["74043.20", "0.000"]]}}
{"local_ts": 1773485417117, "server_ts": 1773485416320, "data": {"e": "depthUpdate", "E": 1773485416325, "T": 1773485416320, "s": "BTCUSDT", "U": 10109446957478, "u": 10109446962093, "pu": 10109446957319, "b": [["1000.00", "28.842"], ["5000.00", "101.418"], ["7050.00", "0.453"], ["20199.90", "0.240"], ["20299.90", "2.510"], ["20399.90", "0.250"], ["66941.70", "0.000"], ["69089.90", "0.909"], ["69315.50", "0.862"], ["69794.90", "9.548"], ["69795.00", "0.483"], ["70253.90", "0.143"], ["70284.50", "4.903"], ["70361.90", "0.000"], ["70362.00", "0.865"], ["70401.70", "1.068"], ["70401.80", "1.136"], ["70408.80", "0.003"], ["70408.90", "0.071"], ["70415.80", "0.000"], ["70415.90", "0.071"], ["70423.50", "0.002"], ["70424.00", "0.005"], ["70426.80", "0.528"], ["70427.20", "0.842"], ["70427.60", "0.080"], ["70427.90", "0.009"], ["70428.30", "0.120"], ["70428.60", "0.002"], ["70429.00", "0.004"], ["70445.70", "0.299"], ["70445.90", "0.000"], ["70447.90", "0.380"], ["70448.10", "0.005"], ["70448.50", "0.000"], ["70448.80", "0.843"], ["70449.20", "0.002"], ["70449.50", "0.094"], ["70449.90", "0.000"], ["70468.90", "1.010"], ["70469.10", "0.248"], ["70469.60", "0.320"], ["70469.70", "0.002"], ["70470.20", "0.072"], ["70472.80", "0.166"], ["70473.50", "0.496"], ["70474.50", "0.009"], ["70474.70", "0.021"], ["70475.20", "0.851"], ["70475.30", "0.152"], ["70475.60", "0.510"], ["70476.10", "0.001"], ["70476.20", "0.000"], ["70476.40", "0.000"], ["70476.90", "0.011"], ["70477.10", "0.070"], ["70477.30", "0.091"], ["70477.60", "0.004"], ["70477.90", "0.012"], ["70478.50", "0.007"], ["70483.20", "0.638"], ["70483.70", "1.076"], ["70484.30", "0.014"], ["70484.80", "0.007"], ["70485.00", "0.209"], ["70485.50", "0.020"], ["70486.00", "0.468"], ["70487.80", "0.017"], ["70487.90", "0.003"], ["70488.00", "0.026"], ["70488.10", "0.045"], ["70488.20", "0.000"], ["70488.30", "0.003"], ["70488.40", "0.005"], ["70488.50", "0.031"], ["70488.60", "0.010"], ["70488.70", "0.023"], ["70488.80", "0.003"], ["70488.90", "0.000"], ["70489.00", "0.000"], ["70489.10", "0.203"], ["70489.20", "0.000"], ["70489.30", "0.000"], ["70489.90", "0.004"], ["70490.20", "0.112"], ["70490.60", "0.000"], ["70490.90", "0.007"], ["70491.10", "0.168"], ["70491.30", "0.000"], ["70491.60", "0.347"], ["70491.80", "0.002"], ["70497.40", "0.000"], ["70497.70", "0.008"], ["70498.90", "0.001"], ["70499.30", "0.140"]], "a": [["70500.00", "4.555"], ["70506.80", "0.034"], ["70506.90", "0.034"], ["70508.40", "1.221"], ["70508.70", "0.000"], ["70509.10", "0.082"], ["70509.40", "0.015"], ["70509.80", "0.062"], ["70510.10", "0.000"], ["70510.70", "0.157"], ["70511.50", "0.002"], ["70514.20", "0.007"], ["70515.00", "0.004"], ["70517.80", "0.145"], ["70518.50", "0.003"], ["70519.60", "0.000"], ["70520.00", "0.595"], ["70521.00", "0.005"], ["70521.50", "0.045"], ["70521.80", "0.006"], ["70521.90", "0.000"], ["70522.30", "0.074"], ["70522.50", "0.007"], ["70522.90", "0.009"], ["70523.80", "0.077"], ["70524.60", "0.009"], ["70529.20", "0.612"], ["70529.60", "0.002"], ["70529.90", "0.033"], ["70530.30", "0.004"], ["70530.60", "0.000"], ["70530.90", "0.006"], ["70531.00", "0.511"], ["70532.00", "0.073"], ["70532.10", "0.620"], ["70550.10", "0.994"], ["70550.50", "0.048"], ["70550.80", "2.687"], ["70551.20", "0.282"], ["70551.50", "0.257"], ["70551.90", "0.004"], ["70552.10", "0.855"], ["70554.00", "0.004"], ["70554.20", "0.017"], ["70578.10", "0.000"], ["70578.20", "0.073"], ["70585.10", "0.000"], ["70585.20", "0.079"], ["70592.20", "0.000"], ["70592.30", "0.113"], ["70630.70", "3.131"], ["70834.90", "0.000"], ["71205.00", "6.231"], ["71750.00", "3.238"], ["89523.20", "0.000"]]}}
{"local_ts": 1773485418137, "server_ts": 1773485417344, "data": {"e": "depthUpdate", "E": 1773485417345, "T": 1773485417344, "s": "BTCUSDT", "U": 10109447000116, "u": 10109447003804, "pu": 10109447000017, "b": [["5000.00", "101.418"], ["7050.00", "0.425"], ["20099.90", "0.090"], ["20199.90", "2.370"], ["20299.90", "0.540"], ["66959.00", "0.000"], ["66974.00", "0.000"], ["68384.90", "0.000"], ["69434.40", "12.473"], ["69578.50", "1.722"], ["69589.50", "0.007"], ["69637.20", "0.717"], ["69786.90", "5.953"], ["69794.90", "8.832"], ["70401.90", "0.000"], ["70409.00", "0.357"], ["70416.00", "0.006"], ["70464.70", "0.041"], ["70465.40", "0.027"], ["70472.80", "0.081"], ["70486.00", "0.751"], ["70486.60", "0.015"], ["70487.20", "0.087"]], "a": [["70535.00", "0.184"], ["70535.20", "1.545"], ["70542.20", "0.015"], ["70544.20", "0.008"], ["70578.20", "0.002"], ["70585.20", "0.008"], ["70592.30", "0.042"], ["71205.00", "6.238"], ["71394.20", "0.007"], ["71536.40", "13.507"], ["71549.30", "10.889"], ["71901.80", "0.002"], ["89523.20", "0.000"]]}}
{"local_ts": 1773485419163, "server_ts": 1773485418365, "data": {"e": "depthUpdate", "E": 1773485418367, "T": 1773485418365, "s": "BTCUSDT", "U": 10109447040630, "u": 10109447050443, "pu": 10109447040585, "b": [["1000.00", "28.842"], ["5000.00", "101.418"], ["7050.00", "0.425"], ["20099.20", "0.060"], ["20099.60", "0.010"], ["20099.70", "0.010"], ["20099.80", "0.010"], ["20099.90", "2.010"], ["20199.90", "0.900"], ["65860.30", "0.000"], ["66964.30", "0.000"], ["69090.00", "4.072"], ["69261.20", "0.000"], ["69794.20", "0.000"], ["69794.60", "0.002"], ["69794.80", "0.000"], ["69794.90", "7.408"], ["70065.60", "0.000"], ["70130.30", "0.084"], ["70147.40", "4.661"], ["70176.80", "0.000"], ["70182.60", "6.950"], ["70187.10", "10.000"], ["70233.60", "10.000"], ["70285.20", "0.043"], ["70316.40", "6.689"], ["70316.50", "0.159"], ["70316.60", "0.159"], ["70319.80", "0.053"], ["70342.10", "10.010"], ["70344.10", "0.122"], ["70344.50", "0.117"], ["70344.60", "0.039"], ["70344.70", "0.039"], ["70362.50", "1.140"], ["70377.20", "0.002"], ["70397.50", "0.046"], ["70398.10", "0.002"], ["70401.20", "0.255"], ["70402.00", "0.948"], ["70404.80", "0.255"], ["70409.10", "0.085"], ["70409.70", "0.225"], ["70411.70", "0.547"], ["70416.10", "0.076"], ["70422.00", "0.067"], ["70428.50", "0.109"], ["70430.90", "0.123"], ["70436.40", "0.060"], ["70439.90", "0.057"], ["70442.20", "8.517"], ["70443.40", "0.062"], ["70444.20", "0.009"], ["70444.70", "0.272"], ["70445.30", "0.189"], ["70445.70", "0.299"], ["70446.20", "0.072"], ["70446.90", "0.057"], ["70447.00", "0.002"], ["70448.20", "0.042"], ["70449.50", "0.094"], ["70450.40", "0.057"], ["70450.60", "0.032"], ["70450.70", "0.004"], ["70451.90", "0.625"], ["70452.00", "0.006"], ["70452.20", "0.007"], ["70452.30", "0.008"], ["70452.40", "1.153"], ["70452.60", "0.002"], ["70453.00", "0.007"], ["70453.20", "0.002"], ["70454.50", "0.003"], ["70455.00", "0.048"], ["70455.70", "0.000"], ["70456.20", "0.030"], ["70456.40", "0.002"], ["70456.50", "0.005"], ["70457.00", "0.004"], ["70457.20", "0.011"], ["70457.50", "0.002"], ["70457.60", "0.526"], ["70457.70", "0.037"], ["70458.50", "0.023"], ["70459.10", "0.016"], ["70460.40", "0.535"], ["70461.00", "0.002"], ["70461.90", "0.003"], ["70462.40", "0.307"], ["70463.00", "0.001"], ["70463.60", "0.032"], ["70463.80", "0.042"], ["70464.20", "0.002"], ["70464.30", "0.161"], ["70464.40", "0.021"], ["70464.50", "0.230"], ["70464.70", "0.058"], ["70466.40", "0.023"], ["70467.00", "0.351"], ["70467.40", "0.052"], ["70467.90", "0.125"], ["70468.00", "0.002"], ["70468.10", "0.006"], ["70468.40", "0.006"], ["70469.00", "0.557"], ["70469.10", "0.000"], ["70469.60", "0.283"], ["70469.70", "0.002"], ["70469.90", "0.034"], ["70470.20", "0.072"], ["70470.40", "0.006"], ["70470.60", "0.004"], ["70470.90", "0.019"], ["70471.20", "0.287"], ["70471.30", "0.009"], ["70471.70", "1.588"], ["70471.90", "0.143"], ["70472.00", "0.029"], ["70472.20", "0.010"], ["70472.40", "0.517"], ["70472.50", "0.010"], ["70472.70", "0.017"], ["70472.90", "0.000"], ["70473.00", "0.070"], ["70473.40", "0.664"], ["70473.80", "0.021"], ["70474.10", "0.141"], ["70474.20", "0.000"], ["70474.30", "0.068"], ["70474.40", "0.031"], ["70474.50", "0.009"], ["70474.60", "0.513"], ["70474.70", "0.021"], ["70475.00", "0.787"], ["70475.20", "0.852"], ["70475.60", "0.000"], ["70475.80", "0.021"], ["70475.90", "0.584"], ["70476.00", "0.030"], ["70476.20", "0.070"], ["70476.40", "0.000"], ["70476.60", "0.012"], ["70476.90", "0.011"], ["70477.00", "0.007"], ["70477.20", "0.045"], ["70477.30", "0.091"], ["70477.40", "0.004"], ["70477.60", "0.004"], ["70477.90", "1.238"], ["70478.10", "0.001"], ["70478.30", "0.389"], ["70478.40", "0.360"], ["70478.50", "0.007"], ["70478.60", "0.002"], ["70478.70", "0.010"], ["70478.80", "0.076"], ["70478.90", "0.000"], ["70479.20", "0.005"], ["70479.50", "0.010"], ["70479.80", "0.030"], ["70479.90", "0.000"], ["70480.20", "0.002"], ["70480.30", "0.007"], ["70480.40", "0.386"], ["70480.50", "0.141"], ["70480.70", "0.009"], ["70481.40", "0.667"], ["70481.60", "0.597"], ["70481.70", "0.000"], ["70482.20", "0.084"], ["70482.50", "1.119"], ["70482.60", "0.002"], ["70482.70", "0.011"], ["70483.00", "0.012"], ["70483.10", "0.053"], ["70483.20", "0.000"], ["70483.50", "0.007"], ["70483.60", "0.406"], ["70483.80", "0.010"], ["70483.90", "0.007"], ["70484.00", "0.001"], ["70484.10", "0.513"], ["70484.20", "0.005"], ["70484.30", "0.071"], ["70484.40", "0.002"], ["70484.50", "0.143"], ["70484.60", "0.001"], ["70484.70", "0.305"], ["70484.90", "0.235"], ["70485.10", "0.005"], ["70485.20", "0.000"], ["70485.30", "0.027"], ["70485.40", "0.000"], ["70486.00", "0.076"], ["70486.10", "0.594"], ["70486.50", "0.425"], ["70486.70", "0.048"], ["70486.90", "0.056"], ["70487.20", "0.002"], ["70487.50", "0.004"], ["70488.00", "0.026"], ["70488.30", "0.000"], ["70488.60", "0.011"], ["70488.70", "0.015"], ["70489.00", "0.000"], ["70489.10", "0.005"], ["70489.40", "0.005"], ["70489.70", "0.000"], ["70490.00", "0.433"], ["70490.10", "0.596"], ["70490.40", "0.226"], ["70490.70", "1.069"], ["70490.80", "0.462"], ["70490.90", "0.773"], ["70491.00", "0.004"], ["70491.10", "0.098"], ["70492.00", "0.001"], ["70492.10", "0.000"], ["70492.90", "0.001"], ["70493.00", "0.009"], ["70493.10", "0.015"], ["70493.50", "0.176"], ["70493.60", "0.002"], ["70493.70", "0.006"], ["70493.80", "0.003"], ["70494.20", "0.001"], ["70494.30", "0.000"], ["70494.50", "0.007"], ["70495.10", "0.196"], ["70495.20", "0.185"], ["70495.30", "0.000"], ["70495.50", "0.003"], ["70495.60", "0.000"], ["70495.90", "0.064"], ["70496.30", "0.215"], ["70497.00", "0.009"], ["70498.10", "0.000"], ["70499.00", "0.046"], ["70499.20", "1.303"], ["70499.40", "0.000"], ["70499.60", "0.000"], ["70499.70", "0.000"], ["70499.80", "0.000"], ["70499.90", "0.000"]], "a": [["70499.30", "18.674"], ["70499.40", "0.102"], ["70499.50", "0.559"], ["70499.60", "0.006"], ["70499.70", "0.000"], ["70499.80", "0.055"], ["70499.90", "0.012"], ["70500.00", "1.461"], ["70500.10", "0.021"], ["70500.20", "0.000"], ["70500.40", "0.004"], ["70500.50", "0.216"], ["70501.20", "0.004"], ["70501.90", "0.032"], ["70502.40", "0.013"], ["70502.70", "0.001"], ["70503.10", "0.011"], ["70503.30", "0.004"], ["70503.60", "0.016"], ["70503.70", "0.002"], ["70504.00", "0.138"], ["70504.40", "0.004"], ["70504.80", "0.005"], ["70505.40", "0.000"], ["70505.70", "0.000"], ["70506.60", "0.003"], ["70506.90", "0.034"], ["70507.00", "0.070"], ["70507.40", "0.004"], ["70507.50", "0.006"], ["70507.70", "0.002"], ["70507.80", "0.217"], ["70507.90", "0.000"], ["70508.00", "0.301"], ["70508.10", "0.017"], ["70508.20", "0.003"], ["70508.30", "0.007"], ["70508.40", "1.172"], ["70508.80", "0.118"], ["70509.50", "0.134"], ["70509.70", "0.144"], ["70510.10", "0.003"], ["70510.80", "0.206"], ["70511.00", "0.103"], ["70511.30", "0.003"], ["70514.00", "0.003"], ["70514.50", "0.009"], ["70514.80", "0.022"], ["70515.70", "0.005"], ["70516.00", "0.029"], ["70516.50", "0.144"], ["70516.60", "0.004"], ["70516.70", "0.554"], ["70516.80", "0.002"], ["70517.30", "0.000"], ["70517.60", "0.006"], ["70517.80", "0.642"], ["70518.00", "0.012"], ["70518.20", "0.005"], ["70518.30", "0.004"], ["70518.50", "0.513"], ["70518.60", "0.002"], ["70518.70", "0.003"], ["70518.80", "0.345"], ["70519.30", "0.003"], ["70519.70", "0.002"], ["70519.90", "0.010"], ["70520.00", "0.088"], ["70520.60", "0.010"], ["70520.70", "0.088"], ["70520.90", "0.037"], ["70521.10", "0.019"], ["70521.40", "0.599"], ["70521.50", "0.040"], ["70521.60", "0.664"], ["70521.90", "0.000"], ["70522.10", "0.010"], ["70522.30", "0.004"], ["70522.50", "0.000"], ["70522.60", "0.309"], ["70523.10", "0.070"], ["70523.30", "0.045"], ["70523.80", "0.005"], ["70523.90", "0.054"], ["70524.00", "0.216"], ["70524.70", "0.000"], ["70524.80", "0.002"], ["70524.90", "0.005"], ["70526.60", "0.000"], ["70527.50", "0.083"], ["70528.20", "0.000"], ["70531.00", "0.808"], ["70534.00", "0.061"], ["70534.90", "0.080"], ["70535.00", "0.182"], ["70535.20", "1.513"], ["70536.30", "0.183"], ["70537.00", "0.321"], ["70538.40", "0.002"], ["70538.50", "0.005"], ["70540.80", "0.010"], ["70542.00", "0.002"], ["70545.30", "0.016"], ["70546.10", "0.010"], ["70546.80", "0.044"], ["70548.60", "0.033"], ["70549.00", "0.072"], ["70549.10", "0.159"], ["70549.90", "0.589"], ["70550.40", "0.147"], ["70552.70", "0.000"], ["70555.50", "8.697"], ["70556.30", "0.000"], ["70558.70", "0.961"], ["70559.60", "0.000"], ["70562.70", "0.000"], ["70563.30", "0.002"], ["70563.40", "0.051"], ["70563.70", "6.303"], ["70573.30", "0.295"], ["70578.30", "0.002"], ["70578.40", "0.073"], ["70585.30", "0.000"], ["70585.40", "0.080"], ["70592.40", "1.539"], ["70592.50", "0.071"], ["70630.70", "3.132"], ["70665.00", "0.169"], ["70668.50", "0.181"], ["70672.00", "1.318"], ["70672.40", "0.000"], ["70675.90", "0.767"], ["70676.00", "2.697"], ["70676.20", "0.016"], ["70679.70", "34.899"], ["70806.40", "0.211"], ["70841.90", "0.000"], ["70908.70", "7.092"], ["71204.30", "6.672"], ["71204.70", "0.000"], ["71204.80", "0.000"], ["71204.90", "0.000"], ["71205.00", "4.843"], ["71488.70", "0.015"], ["71490.10", "0.002"], ["71491.60", "0.000"], ["71493.80", "0.002"], ["71495.60", "0.005"], ["71497.90", "0.005"], ["71499.70", "0.716"], ["71499.90", "0.004"], ["71531.30", "1.761"], ["71910.00", "1.844"], ["89523.20", "0.000"]]}}
{"local_ts": 1773485420179, "server_ts": 1773485419388, "data": {"e": "depthUpdate", "E": 1773485419389, "T": 1773485419388, "s": "BTCUSDT", "U": 10109447086344, "u": 10109447091147, "pu": 10109447086257, "b": [["1000.00", "28.842"], ["5000.00", "101.418"], ["7050.00", "0.425"], ["19999.20", "1.660"], ["20099.90", "0.350"], ["66962.10", "0.002"], ["69794.20", "1.442"], ["70447.50", "2.300"], ["70448.10", "0.056"], ["70451.40", "0.694"], ["70451.80", "0.044"], ["70455.60", "0.030"], ["70456.30", "0.002"], ["70468.90", "1.124"], ["70473.00", "0.000"], ["70474.10", "0.000"], ["70475.40", "0.206"], ["70475.60", "0.141"], ["70476.00", "0.023"], ["70476.10", "0.511"], ["70476.20", "0.070"], ["70476.70", "0.003"], ["70476.90", "0.004"], ["70477.80", "1.073"], ["70477.90", "0.026"], ["70478.60", "0.009"], ["70479.20", "0.012"], ["70479.80", "0.023"], ["70480.50", "0.000"], ["70481.90", "0.010"], ["70482.60", "0.143"], ["70484.40", "0.002"], ["70484.70", "0.024"], ["70493.50", "0.062"], ["70495.00", "0.023"], ["70495.10", "0.196"], ["70496.90", "0.002"], ["70497.00", "0.008"], ["70499.10", "0.046"], ["70499.20", "4.143"]], "a": [["70499.30", "10.907"], ["70500.00", "0.979"], ["70500.20", "0.003"], ["70504.60", "0.081"], ["70507.10", "0.007"], ["70507.80", "0.219"], ["70510.60", "0.000"], ["70511.30", "0.144"], ["70519.80", "0.005"], ["70520.60", "0.520"], ["70520.90", "0.035"], ["70521.00", "0.005"], ["70521.90", "0.014"], ["70524.90", "0.005"], ["70526.00", "0.061"], ["70549.90", "0.320"], ["70556.80", "1.886"], ["70556.90", "0.008"], ["70806.40", "0.000"], ["70813.00", "0.261"], ["71204.30", "6.676"], ["71728.70", "1.114"], ["71888.80", "0.334"], ["72122.80", "0.000"], ["89523.20", "0.000"]]}}
{"local_ts": 1773485421203, "server_ts": 1773485420410, "data": {"e": "depthUpdate", "E": 1773485420411, "T": 1773485420410, "s": "BTCUSDT", "U": 10109447119036, "u": 10109447121843, "pu": 10109447119027, "b": [["1000.00", "28.992"], ["5000.00", "101.418"], ["7050.00", "0.481"], ["19999.20", "1.790"], ["20399.20", "1.210"], ["33000.00", "3.785"], ["66960.00", "0.641"], ["66974.20", "0.002"], ["69180.90", "0.364"], ["69283.70", "2.884"], ["69576.40", "0.000"], ["69794.20", "1.438"], ["70146.70", "0.000"], ["70319.40", "0.355"], ["70439.50", "0.017"], ["70465.10", "0.004"], ["70472.00", "0.029"], ["70472.70", "0.087"], ["70490.10", "0.506"], ["70491.60", "0.362"], ["70499.20", "4.080"]], "a": [["70499.30", "10.344"], ["70500.60", "0.002"], ["70500.90", "0.000"], ["70501.10", "0.003"], ["70502.30", "0.002"], ["70502.90", "0.006"], ["70506.30", "0.028"], ["70507.70", "0.072"], ["70511.00", "0.067"], ["70513.10", "1.332"], ["70534.00", "0.057"], ["70536.30", "0.147"], ["70545.30", "0.020"], ["70561.60", "0.043"], ["70562.70", "0.081"], ["70679.10", "0.159"], ["71028.00", "0.725"], ["71204.30", "7.459"], ["71426.50", "0.000"], ["89523.20", "0.000"]]}}
{"local_ts": 1773485422224, "server_ts": 1773485421432, "data": {"e": "depthUpdate", "E": 1773485421433, "T": 1773485421432, "s": "BTCUSDT", "U": 10109447147031, "u": 10109447150765, "pu": 10109447146962, "b": [["1000.00", "28.842"], ["5000.00", "101.418"], ["7050.00", "0.481"], ["20299.20", "0.770"], ["20399.20", "2.230"], ["55765.50", "0.000"], ["66948.80", "0.000"], ["66971.50", "0.002"], ["69794.20", "1.438"], ["70002.40", "0.000"], ["70315.90", "0.163"], ["70319.40", "0.355"], ["70423.70", "0.002"], ["70424.20", "0.043"], ["70427.00", "0.027"], ["70427.40", "0.002"], ["70427.80", "2.240"], ["70428.10", "0.159"], ["70428.50", "0.012"], ["70428.80", "0.095"], ["70429.20", "0.119"], ["70439.70", "0.784"], ["70445.90", "0.004"], ["70446.00", "0.063"], ["70446.10", "0.000"], ["70448.10", "0.002"], ["70448.30", "0.023"], ["70448.40", "0.321"], ["70448.70", "0.000"], ["70448.80", "0.908"], ["70449.00", "0.000"], ["70449.10", "0.058"], ["70449.40", "0.005"], ["70449.70", "0.519"], ["70450.10", "0.000"], ["70451.40", "0.696"], ["70451.50", "0.085"], ["70454.50", "0.003"], ["70465.20", "8.078"], ["70472.70", "0.186"], ["70483.60", "0.421"], ["70484.50", "0.000"], ["70484.60", "0.639"], ["70487.10", "0.418"], ["70487.20", "0.087"], ["70490.10", "0.114"], ["70490.20", "0.067"], ["70490.40", "0.006"], ["70490.50", "0.148"], ["70490.80", "0.106"], ["70490.90", "0.576"], ["70491.10", "0.001"], ["70491.50", "0.018"], ["70491.70", "0.006"], ["70491.80", "0.002"], ["70493.40", "0.516"], ["70496.00", "0.000"], ["70499.20", "3.188"]], "a": [["70499.30", "10.852"], ["70499.60", "0.014"], ["70501.10", "0.022"], ["70504.70", "0.000"], ["70505.40", "0.152"], ["70508.40", "1.080"], ["70508.80", "0.092"], ["70509.10", "0.082"], ["70509.40", "0.051"], ["70509.50", "0.073"], ["70509.80", "0.170"], ["70510.10", "0.129"], ["70510.20", "0.000"], ["70511.00", "0.031"], ["70518.70", "0.187"], ["70519.40", "0.036"], ["70520.20", "0.596"], ["70521.80", "0.006"], ["70522.60", "0.138"], ["70529.30", "0.007"], ["70529.60", "0.002"], ["70530.00", "0.092"], ["70530.30", "0.040"], ["70530.40", "0.014"], ["70530.70", "0.038"], ["70531.00", "0.547"], ["70532.00", "0.109"], ["70532.10", "0.620"], ["70534.00", "0.061"], ["70536.30", "0.111"], ["70543.90", "0.003"], ["70549.80", "0.269"], ["70550.20", "0.030"], ["70550.50", "0.048"], ["70550.90", "2.246"], ["70551.20", "0.282"], ["70551.60", "0.447"], ["70551.90", "0.004"], ["70552.10", "0.855"], ["70554.10", "0.004"], ["70554.20", "0.053"], ["70554.30", "0.002"], ["70561.60", "0.007"], ["70562.70", "0.000"], ["70679.10", "0.000"], ["71204.30", "8.074"], ["89523.20", "0.000"]]}}
{"local_ts": 1773485423254, "server_ts": 1773485422457, "data": {"e": "depthUpdate", "E": 1773485422459, "T": 1773485422457, "s": "BTCUSDT", "U": 10109447181314, "u": 10109447184297, "pu": 10109447181191, "b": [["5000.00", "101.418"], ["7050.00", "0.481"], ["20199.20", "0.380"], ["20299.20", "2.570"], ["20399.20", "0.050"], ["33000.00", "3.789"], ["55765.50", "0.002"], ["69279.30", "0.576"], ["69794.20", "2.869"], ["70253.30", "0.006"], ["70284.60", "0.004"], ["70324.70", "3.727"], ["70363.40", "0.865"], ["70449.60", "0.203"], ["70463.50", "0.000"], ["70463.80", "0.042"], ["70476.10", "0.086"], ["70496.10", "0.019"], ["70496.40", "0.208"]], "a": [["70499.30", "10.917"], ["70533.10", "1.092"], ["70544.20", "0.004"], ["70554.10", "0.038"], ["70630.00", "1.560"], ["70668.80", "2.822"], ["70722.90", "2.240"], ["71204.20", "2.231"], ["71204.30", "8.074"], ["71760.80", "1.350"], ["74028.40", "0.002"], ["74032.00", "0.005"], ["89523.20", "0.000"]]}}
{"local_ts": 1773485424278, "server_ts": 1773485423484, "data": {"e": "depthUpdate", "E": 1773485423485, "T": 1773485423484, "s": "BTCUSDT", "U": 10109447209209, "u": 10109447212558, "pu": 10109447209165, "b": [["1000.00", "28.842"], ["5000.00", "101.418"], ["7050.00", "0.453"], ["20099.20", "0.210"], ["20199.20", "2.480"], ["20299.20", "0.310"], ["55765.50", "0.000"], ["69794.20", "2.869"], ["69794.40", "0.036"], ["70253.10", "0.004"], ["70451.40", "0.694"], ["70451.50", "0.087"], ["70472.00", "0.114"], ["70480.80", "0.008"], ["70481.50", "0.004"], ["70496.20", "0.016"], ["70496.60", "0.003"], ["70499.20", "3.554"]], "a": [["70499.30", "10.604"], ["70502.60", "0.002"], ["70507.10", "0.007"], ["70507.60", "0.010"], ["70518.70", "0.272"], ["70520.20", "0.086"], ["70520.50", "0.513"], ["70522.00", "0.739"], ["70522.30", "0.011"], ["70522.60", "0.061"], ["70522.70", "0.266"], ["70522.80", "0.289"], ["70522.90", "0.079"], ["70546.40", "0.277"], ["70549.80", "0.000"], ["70675.50", "0.163"], ["71204.30", "8.074"], ["74034.10", "0.002"], ["89523.20", "0.000"]]}}
{"local_ts": 1773485425298, "server_ts": 1773485424504, "data": {"e": "depthUpdate", "E": 1773485424507, "T": 1773485424504, "s": "BTCUSDT", "U": 10109447244034, "u": 10109447248481, "pu": 10109447243947, "b": [["5000.00", "101.418"], ["7050.00", "0.453"], ["19999.20", "0.060"], ["20099.20", "2.330"], ["20199.20", "0.610"], ["55765.50", "0.002"], ["66950.80", "0.002"], ["69433.70", "1.724"], ["69434.00", "0.862"], ["69794.20", "2.869"], ["70319.40", "0.415"], ["70451.50", "0.085"], ["70451.60", "0.310"], ["70470.40", "0.058"], ["70471.20", "0.287"], ["70471.30", "0.002"], ["70472.00", "0.029"], ["70473.40", "0.154"], ["70474.70", "0.036"], ["70475.90", "0.848"], ["70476.10", "0.511"], ["70476.20", "0.000"], ["70477.10", "0.080"], ["70477.90", "0.033"], ["70478.20", "0.004"], ["70484.20", "0.007"], ["70484.50", "0.638"], ["70484.80", "0.000"], ["70484.90", "0.223"], ["70485.20", "0.000"], ["70485.30", "0.419"], ["70486.20", "0.022"], ["70487.20", "0.087"], ["70487.50", "0.019"], ["70488.00", "0.026"], ["70492.50", "0.081"], ["70493.60", "0.258"], ["70495.00", "0.008"], ["70496.10", "0.061"], ["70496.40", "0.151"], ["70496.70", "0.001"], ["70496.80", "0.002"], ["70497.60", "0.000"], ["70498.00", "0.000"], ["70499.20", "2.834"]], "a": [["70499.30", "10.621"], ["70520.00", "0.725"], ["70521.00", "0.515"], ["70521.20", "0.538"], ["70521.30", "0.048"], ["70521.70", "0.000"], ["70521.90", "0.000"], ["70524.90", "0.253"], ["70526.50", "0.002"], ["71164.70", "0.701"], ["71204.30", "8.074"], ["71714.80", "0.695"], ["74054.30", "0.000"], ["89523.20", "0.000"]]}}
{"local_ts": 1773485426319, "server_ts": 1773485425528, "data": {"e": "depthUpdate", "E": 1773485425529, "T": 1773485425528, "s": "BTCUSDT", "U": 10109447279894, "u": 10109447283383, "pu": 10109447279817, "b": [["1000.00", "28.842"], ["5000.00", "101.418"], ["7050.00", "0.453"], ["19999.20", "2.010"], ["20099.20", "0.990"], ["55765.50", "0.000"], ["56399.00", "0.000"], ["68499.20", "0.000"], ["69794.20", "2.869"], ["70146.70", "0.000"], ["70167.40", "11.724"], ["70178.40", "1.201"], ["70363.80", "0.684"], ["70446.90", "0.158"], ["70488.60", "0.120"], ["70499.20", "2.836"]], "a": [["70500.30", "0.000"], ["70509.00", "0.062"], ["70520.30", "0.532"], ["70521.00", "0.005"], ["70523.60", "0.076"], ["70524.50", "0.000"], ["70529.90", "0.130"], ["70630.00", "1.095"], ["70737.50", "0.018"], ["70815.30", "0.000"], ["70844.90", "3.417"], ["70999.90", "0.648"], ["71049.20", "3.246"], ["71204.30", "8.074"], ["74030.90", "0.002"], ["89523.20", "0.000"]]}}
{"local_ts": 1773485427344, "server_ts": 1773485426552, "data": {"e": "depthUpdate", "E": 1773485426553, "T": 1773485426552, "s": "BTCUSDT", "U": 10109447319533, "u": 10109447323736, "pu": 10109447319522, "b": [["1000.00", "28.842"], ["5000.00", "101.438"], ["7050.00", "0.425"], ["19999.20", "1.430"], ["20399.20", "1.570"], ["55765.50", "0.002"], ["56399.00", "0.004"], ["66973.80", "0.000"], ["69432.70", "0.430"], ["69477.40", "0.000"], ["69515.00", "0.099"], ["69575.10", "69.472"], ["69618.70", "0.903"], ["69784.40", "58.153"], ["69794.20", "2.869"], ["69945.20", "45.356"], ["69990.20", "0.014"], ["70017.60", "0.004"], ["70253.60", "0.004"], ["70302.50", "0.003"], ["70305.30", "0.511"], ["70423.80", "0.000"], ["70424.30", "0.000"], ["70427.10", "1.227"], ["70427.50", "0.544"], ["70427.90", "0.009"], ["70428.20", "0.063"], ["70428.60", "0.002"], ["70428.90", "0.096"], ["70429.30", "0.000"], ["70445.10", "0.150"], ["70446.00", "0.002"], ["70446.20", "0.133"], ["70446.40", "0.075"], ["70448.20", "0.042"], ["70448.40", "0.260"], ["70448.60", "0.202"], ["70448.80", "0.843"], ["70448.90", "0.334"], ["70449.10", "0.000"], ["70449.30", "0.063"], ["70449.50", "0.094"], ["70449.80", "0.040"], ["70450.20", "0.005"], ["70452.30", "0.010"], ["70452.60", "0.002"], ["70470.40", "0.006"], ["70472.50", "0.062"], ["70476.20", "0.000"], ["70476.30", "0.000"], ["70477.30", "0.091"], ["70477.40", "0.074"], ["70478.00", "0.075"], ["70478.50", "0.014"], ["70478.80", "0.076"], ["70480.10", "0.006"], ["70481.40", "1.872"], ["70481.90", "0.003"], ["70483.10", "0.060"], ["70484.80", "0.000"], ["70485.30", "0.113"], ["70485.40", "0.002"], ["70485.80", "0.129"], ["70486.00", "0.714"], ["70486.40", "0.000"], ["70486.80", "0.517"], ["70487.20", "0.009"], ["70487.40", "0.004"], ["70487.90", "0.215"], ["70488.60", "0.391"], ["70490.20", "0.006"], ["70490.30", "0.191"], ["70490.40", "0.078"], ["70490.50", "0.022"], ["70490.70", "1.197"], ["70490.80", "0.002"], ["70490.90", "0.518"], ["70491.10", "0.059"], ["70491.20", "0.014"], ["70491.60", "0.347"], ["70491.90", "0.003"], ["70492.10", "0.005"], ["70492.30", "0.397"], ["70493.50", "0.064"], ["70494.70", "0.008"], ["70495.60", "0.227"], ["70496.70", "0.058"], ["70497.50", "0.007"], ["70498.30", "0.002"], ["70499.20", "4.525"]], "a": [["70499.30", "5.633"], ["70500.00", "0.975"], ["70500.50", "0.219"], ["70501.50", "0.167"], ["70501.60", "0.027"], ["70502.50", "0.010"], ["70502.80", "0.007"], ["70502.90", "0.006"], ["70504.20", "0.019"], ["70505.50", "0.057"], ["70505.80", "0.110"], ["70507.00", "0.703"], ["70507.20", "0.005"], ["70508.40", "1.080"], ["70508.70", "0.000"], ["70509.10", "0.082"], ["70509.30", "0.036"], ["70509.40", "0.015"], ["70509.70", "0.113"], ["70509.80", "0.077"], ["70510.00", "0.182"], ["70510.10", "0.093"], ["70510.80", "0.214"], ["70512.50", "0.000"], ["70512.90", "0.144"], ["70513.20", "0.002"], ["70514.80", "0.022"], ["70515.10", "0.434"], ["70515.60", "0.219"], ["70515.70", "0.012"], ["70516.80", "0.017"], ["70518.70", "0.003"], ["70519.00", "0.592"], ["70519.10", "0.005"], ["70519.70", "0.144"], ["70521.00", "0.005"], ["70521.70", "0.000"], ["70521.80", "0.643"], ["70521.90", "0.000"], ["70522.30", "0.521"], ["70523.10", "0.000"], ["70523.40", "0.023"], ["70523.60", "0.013"], ["70524.20", "0.003"], ["70524.70", "0.070"], ["70525.40", "0.361"], ["70526.00", "0.004"], ["70526.50", "0.002"], ["70527.60", "0.006"], ["70528.30", "0.248"], ["70528.40", "0.823"], ["70529.20", "0.612"], ["70529.60", "0.002"], ["70529.90", "0.047"], ["70530.20", "0.045"], ["70530.30", "0.004"], ["70530.50", "0.095"], ["70530.60", "0.000"], ["70530.70", "0.002"], ["70530.90", "0.114"], ["70531.00", "0.511"], ["70531.10", "0.044"], ["70531.90", "0.106"], ["70532.00", "0.109"], ["70532.10", "0.620"], ["70533.10", "1.168"], ["70535.00", "0.218"], ["70536.10", "0.135"], ["70549.80", "0.269"], ["70550.10", "0.994"], ["70550.50", "0.048"], ["70550.80", "2.723"], ["70551.20", "0.282"], ["70551.50", "0.257"], ["70551.90", "0.004"], ["70552.10", "0.855"], ["70552.50", "0.036"], ["70553.90", "0.040"], ["70554.10", "0.038"], ["70554.20", "0.017"], ["70675.50", "0.163"], ["70722.80", "2.592"], ["71072.40", "0.000"], ["71204.20", "2.231"], ["71204.30", "8.074"], ["73319.20", "0.984"], ["89523.20", "0.000"]]}}
{"local_ts": 1773485428365, "server_ts": 1773485427574, "data": {"e": "depthUpdate", "E": 1773485427575, "T": 1773485427574, "s": "BTCUSDT", "U": 10109447366378, "u": 10109447371637, "pu": 10109447366298, "b": [["5000.00", "101.418"], ["7050.00", "0.425"], ["20299.20", "1.120"], ["20399.20", "1.880"], ["55765.50", "0.000"], ["56399.00", "0.000"], ["66965.10", "0.002"], ["66969.70", "0.000"], ["68791.20", "0.624"], ["69406.50", "2.932"], ["69477.00", "4.744"], ["69794.20", "2.871"], ["70253.00", "1.012"], ["70444.50", "0.210"], ["70450.20", "0.009"], ["70451.50", "0.085"], ["70451.60", "0.310"], ["70463.80", "0.039"], ["70464.10", "1.756"], ["70471.90", "0.143"], ["70472.70", "0.186"], ["70474.80", "0.004"], ["70476.10", "0.001"], ["70476.20", "0.070"], ["70476.90", "0.004"], ["70477.10", "0.000"], ["70477.40", "0.011"], ["70478.10", "0.001"], ["70478.20", "0.011"], ["70483.20", "0.000"], ["70484.70", "0.660"], ["70487.00", "0.015"], ["70487.20", "0.002"], ["70487.30", "0.012"], ["70487.40", "0.004"], ["70487.60", "0.002"], ["70487.70", "0.098"], ["70487.80", "0.110"], ["70487.90", "0.205"], ["70488.00", "0.083"], ["70488.10", "0.072"], ["70488.20", "0.000"], ["70488.30", "0.021"], ["70488.40", "0.005"], ["70488.50", "0.031"], ["70488.60", "0.120"], ["70488.70", "0.015"], ["70488.80", "0.003"], ["70489.00", "0.000"], ["70489.30", "0.015"], ["70489.40", "0.005"], ["70491.60", "0.347"], ["70492.20", "0.198"], ["70493.20", "0.057"], ["70493.70", "0.004"], ["70494.60", "0.023"], ["70495.60", "0.007"], ["70496.00", "0.000"], ["70497.30", "0.012"], ["70499.10", "0.028"], ["70499.20", "1.973"]], "a": [["70506.30", "0.010"], ["70507.60", "0.008"], ["70509.70", "0.210"], ["70515.90", "0.002"], ["70516.30", "0.017"], ["70517.90", "0.002"], ["70518.50", "0.144"], ["70518.60", "0.087"], ["70519.30", "0.003"], ["70520.00", "0.725"], ["70520.70", "0.011"], ["70520.80", "1.000"], ["70521.00", "0.005"], ["70521.30", "0.055"], ["70521.80", "0.013"], ["70521.90", "0.085"], ["70522.70", "0.336"], ["70531.40", "1.848"], ["70531.50", "0.000"], ["70549.80", "0.000"], ["70553.10", "0.039"], ["70578.30", "0.041"], ["70647.70", "0.642"], ["70900.00", "11.870"], ["71204.30", "8.074"], ["71468.00", "4.330"], ["73319.20", "0.986"]]}}
{"local_ts": 1773485429391, "server_ts": 1773485428596, "data": {"e": "depthUpdate", "E": 1773485428597, "T": 1773485428596, "s": "BTCUSDT", "U": 10109447402187, "u": 10109447405259, "pu": 10109447402172, "b": [["1000.00", "28.992"], ["5000.00", "101.418"], ["7050.00", "0.425"], ["20199.20", "0.680"], ["20299.20", "2.320"], ["20399.20", "0.000"], ["56399.00", "0.000"], ["66965.10", "0.000"], ["69390.10", "0.617"], ["69794.20", "2.869"], ["70315.90", "0.163"], ["70319.40", "0.355"], ["70325.10", "0.000"], ["70325.50", "3.849"], ["70342.20", "2.763"], ["70350.70", "0.088"], ["70353.30", "1.244"], ["70364.20", "0.911"], ["70364.50", "0.000"], ["70368.00", "1.836"], ["70409.40", "0.776"], ["70444.20", "0.483"], ["70451.90", "0.625"], ["70452.20", "0.007"], ["70472.80", "0.166"], ["70475.90", "0.812"], ["70476.20", "0.070"], ["70477.30", "0.091"], ["70477.90", "0.005"], ["70486.90", "0.085"], ["70490.00", "0.438"], ["70492.20", "0.049"], ["70492.80", "0.015"], ["70493.30", "0.439"], ["70493.80", "0.001"], ["70495.10", "0.211"], ["70495.20", "0.014"], ["70495.30", "0.000"], ["70495.40", "0.003"], ["70495.50", "0.006"], ["70495.60", "0.000"], ["70495.70", "0.000"], ["70496.50", "0.005"], ["70499.20", "1.862"]], "a": [["70499.70", "0.000"], ["70500.90", "0.000"], ["70501.50", "0.167"], ["70506.30", "0.028"], ["70514.90", "0.006"], ["70515.90", "0.000"], ["70516.90", "0.186"], ["70519.30", "0.003"], ["70520.00", "0.725"], ["70522.90", "0.079"], ["70525.00", "1.023"], ["70536.30", "0.139"], ["70550.00", "1.651"], ["70552.70", "0.000"], ["70566.30", "0.785"], ["70584.50", "0.589"], ["70587.70", "1.487"], ["70630.10", "3.046"], ["70644.00", "0.973"], ["70646.40", "0.008"], ["70646.50", "0.215"], ["70668.80", "2.806"], ["70669.80", "0.018"], ["70675.50", "0.064"], ["70679.10", "0.159"], ["70723.20", "0.014"], ["70851.70", "0.000"], ["71204.30", "9.476"], ["71474.90", "0.907"], ["71535.60", "3.000"], ["71813.20", "0.000"], ["72271.20", "0.000"], ["74058.60", "0.004"]]}}
{"local_ts": 1773485430407, "server_ts": 1773485429616, "data": {"e": "depthUpdate", "E": 1773485429617, "T": 1773485429616, "s": "BTCUSDT", "U": 10109447438796, "u": 10109447442316, "pu": 10109447438555, "b": [["5000.00", "101.418"], ["7050.00", "0.481"], ["20099.20", "0.320"], ["20199.20", "2.590"], ["20299.20", "0.090"], ["33000.00", "3.789"], ["56399.00", "0.000"], ["66959.40", "0.002"], ["68384.20", "0.003"], ["69216.10", "1.009"], ["69392.10", "0.287"], ["69547.50", "1.504"], ["69653.20", "3.446"], ["69794.20", "2.869"], ["69924.60", "0.788"], ["70452.00", "0.006"], ["70452.20", "0.009"], ["70464.40", "1.828"], ["70494.20", "0.016"], ["70494.80", "0.001"]], "a": [["70507.50", "0.062"], ["70507.60", "0.008"], ["70512.50", "0.000"], ["70512.80", "1.516"], ["70512.90", "0.144"], ["70513.00", "0.039"], ["70514.90", "0.004"], ["70523.00", "0.086"], ["70529.90", "0.043"], ["70722.70", "10.121"], ["71204.20", "2.224"], ["71204.30", "9.476"], ["71992.20", "0.003"], ["72035.70", "0.000"], ["74024.30", "0.000"]]}}
{"local_ts": 1773485431431, "server_ts": 1773485430638, "data": {"e": "depthUpdate", "E": 1773485430639, "T": 1773485430638, "s": "BTCUSDT", "U": 10109447477273, "u": 10109447481441, "pu": 10109447477133, "b": [["1000.00", "28.842"], ["5000.00", "101.418"], ["7050.00", "0.481"], ["19999.20", "0.170"], ["20099.20", "2.440"], ["20199.20", "0.390"], ["56399.00", "0.000"], ["66974.20", "0.002"], ["66974.30", "0.010"], ["69213.60", "1.442"], ["69582.70", "2.870"], ["69794.20", "2.869"], ["70146.70", "0.000"], ["70319.40", "0.415"], ["70448.10", "0.058"], ["70452.00", "0.008"], ["70452.20", "0.007"], ["70472.60", "0.400"], ["70472.80", "0.468"], ["70473.50", "0.496"], ["70473.60", "0.022"], ["70473.70", "0.003"], ["70480.50", "1.205"], ["70481.40", "0.667"], ["70483.20", "0.007"], ["70483.70", "1.076"], ["70485.80", "0.129"], ["70486.00", "0.076"], ["70486.20", "0.007"], ["70486.90", "0.638"], ["70487.50", "0.004"], ["70488.60", "0.305"], ["70490.00", "0.583"], ["70492.20", "0.049"], ["70494.90", "0.006"], ["70495.10", "0.196"], ["70497.90", "0.000"], ["70498.50", "0.008"], ["70499.20", "2.991"]], "a": [["70499.30", "5.927"], ["70500.10", "0.022"], ["70500.40", "0.004"], ["70500.70", "0.124"], ["70500.80", "0.002"], ["70501.40", "0.058"], ["70501.70", "0.000"], ["70502.60", "0.002"], ["70502.80", "0.028"], ["70502.90", "0.021"], ["70504.20", "0.019"], ["70504.80", "0.005"], ["70506.10", "0.057"], ["70506.30", "0.028"], ["70506.80", "0.024"], ["70507.00", "0.724"], ["70515.60", "0.204"], ["70516.80", "0.002"], ["70520.10", "0.227"], ["70520.70", "0.195"], ["70522.40", "0.018"], ["70523.00", "0.084"], ["70549.80", "0.085"], ["70722.70", "10.114"], ["71063.30", "0.281"], ["71204.20", "2.231"], ["71204.30", "9.476"], ["74038.20", "0.000"], ["74057.80", "0.007"], ["74057.90", "0.002"]]}}
{"local_ts": 1773485432449, "server_ts": 1773485431656, "data": {"e": "depthUpdate", "E": 1773485431659, "T": 1773485431656, "s": "BTCUSDT", "U": 10109447525534, "u": 10109447529959, "pu": 10109447525528, "b": [["1000.00", "28.842"], ["5000.00", "101.438"], ["7049.90", "0.056"], ["19999.00", "1.170"], ["19999.20", "1.100"], ["20099.20", "0.690"], ["20399.00", "0.020"], ["66974.00", "0.020"], ["66974.10", "0.002"], ["66974.30", "0.004"], ["68791.10", "0.624"], ["69462.80", "1.365"], ["69636.20", "0.717"], ["69794.00", "0.709"], ["69804.80", "0.794"], ["69927.60", "0.000"], ["70071.40", "39.940"], ["70176.60", "32.388"], ["70215.10", "0.254"], ["70253.90", "27.031"], ["70450.20", "0.127"], ["70451.20", "0.004"], ["70451.30", "0.009"], ["70451.50", "0.470"], ["70451.90", "0.688"], ["70452.20", "0.065"], ["70452.90", "0.045"], ["70474.10", "0.000"], ["70475.60", "0.510"], ["70478.70", "0.004"], ["70481.50", "0.145"], ["70482.20", "0.086"], ["70490.80", "1.464"], ["70491.10", "0.189"], ["70491.50", "0.076"], ["70492.20", "0.039"]], "a": [["70508.20", "0.028"], ["70508.90", "0.038"], ["70509.20", "0.108"], ["70509.60", "0.218"], ["70518.60", "0.002"], ["70519.40", "1.183"], ["70522.40", "0.016"], ["70523.70", "0.541"], ["70527.80", "0.025"], ["70528.50", "0.780"], ["70528.80", "0.402"], ["70529.20", "0.792"], ["70529.70", "0.038"], ["70529.90", "0.079"], ["70547.40", "0.029"], ["70548.10", "0.038"], ["70548.50", "0.036"], ["70548.80", "0.216"], ["70550.10", "0.356"], ["70562.50", "0.101"], ["70722.90", "2.247"], ["70737.50", "27.525"], ["70815.30", "32.106"], ["70921.60", "39.511"], ["71204.00", "0.025"], ["71204.10", "0.005"], ["72271.30", "2.486"], ["74032.60", "0.003"], ["74045.60", "0.002"]]}}
{"local_ts": 1773485433472, "server_ts": 1773485432680, "data": {"e": "depthUpdate", "E": 1773485432681, "T": 1773485432680, "s": "BTCUSDT", "U": 10109447580407, "u": 10109447585420, "pu": 10109447580285, "b": [["5000.00", "101.418"], ["7049.90", "0.028"], ["19999.00", "1.110"], ["20399.00", "1.890"], ["66941.50", "0.000"], ["66957.50", "0.004"], ["69300.50", "2.005"], ["69334.20", "0.000"], ["69794.00", "0.709"], ["70319.20", "0.159"], ["70451.00", "0.222"], ["70451.20", "0.004"], ["70472.60", "0.348"], ["70486.70", "0.104"], ["70487.00", "0.057"], ["70488.00", "0.041"], ["70488.10", "0.072"], ["70488.40", "0.008"], ["70488.60", "0.105"], ["70489.70", "0.021"], ["70491.90", "0.003"], ["70492.00", "0.001"]], "a": [["70499.10", "13.460"], ["70504.00", "0.022"], ["70506.00", "0.018"], ["70506.10", "0.057"], ["70506.70", "0.000"], ["70508.30", "0.008"], ["70509.70", "0.221"], ["70509.80", "0.074"], ["70528.90", "0.583"], ["70606.60", "0.000"], ["70622.00", "0.000"], ["71028.00", "1.428"], ["71179.40", "0.031"], ["71204.10", "0.005"]]}}
{"local_ts": 1773485434495, "server_ts": 1773485433701, "data": {"e": "depthUpdate", "E": 1773485433703, "T": 1773485433701, "s": "BTCUSDT", "U": 10109447638726, "u": 10109447644022, "pu": 10109447638664, "b": [["1000.00", "28.842"], ["5000.00", "101.418"], ["7049.90", "0.028"], ["20299.00", "1.440"], ["20399.00", "1.560"], ["66963.10", "0.002"], ["66974.30", "0.002"], ["69371.90", "8.738"], ["69794.00", "0.709"], ["70200.00", "24.399"], ["70467.00", "0.302"], ["70467.70", "0.004"], ["70468.00", "0.002"], ["70476.20", "0.007"], ["70476.90", "0.004"], ["70481.20", "0.005"], ["70481.30", "0.844"]], "a": [["70519.00", "0.672"], ["70519.30", "0.073"], ["70520.40", "0.006"], ["70521.50", "0.288"], ["70523.10", "0.000"], ["70532.60", "0.014"], ["71204.00", "0.032"], ["71204.10", "0.005"], ["71530.80", "0.008"], ["71565.40", "0.837"], ["71590.40", "4.184"], ["71782.40", "1.086"]]}}
{"local_ts": 1773485435516, "server_ts": 1773485434723, "data": {"e": "depthUpdate", "E": 1773485434725, "T": 1773485434723, "s": "BTCUSDT", "U": 10109447698543, "u": 10109447704561, "pu": 10109447698281, "b": [["5000.00", "101.418"], ["7049.90", "0.028"], ["20199.00", "0.990"], ["20299.00", "2.010"], ["54444.00", "8.067"], ["66947.10", "0.000"], ["66970.20", "40.002"], ["66975.00", "0.082"], ["69336.70", "7.289"], ["69794.00", "0.709"], ["70147.40", "4.625"], ["70319.20", "0.159"], ["70451.50", "0.470"], ["70451.60", "0.310"], ["70463.80", "0.036"], ["70470.80", "0.026"], ["70476.10", "0.140"], ["70480.60", "0.000"], ["70481.40", "0.808"], ["70492.00", "1.578"], ["70493.30", "0.349"]], "a": [["70506.10", "0.057"], ["70519.90", "0.003"], ["70534.30", "0.043"], ["71204.10", "0.005"], ["71780.20", "1.414"], ["72191.10", "0.346"]]}}
{"local_ts": 1773485436537, "server_ts": 1773485435745, "data": {"e": "depthUpdate", "E": 1773485435747, "T": 1773485435745, "s": "BTCUSDT", "U": 10109447758848, "u": 10109447763115, "pu": 10109447758718, "b": [["1000.00", "28.842"], ["5000.00", "101.418"], ["7049.70", "0.000"], ["20096.50", "0.550"], ["20196.50", "0.870"], ["20199.00", "1.540"], ["20299.00", "0.000"], ["66936.80", "0.040"], ["69791.50", "0.000"], ["70144.00", "3.033"], ["70442.10", "0.095"], ["70449.70", "0.521"], ["70450.30", "0.202"], ["70462.00", "0.044"], ["70472.40", "0.517"], ["70474.50", "0.276"], ["70475.50", "0.003"], ["70478.10", "0.189"], ["70478.30", "0.024"], ["70485.50", "0.007"], ["70485.90", "0.346"], ["70489.50", "0.035"], ["70495.70", "0.002"], ["70495.80", "0.002"]], "a": [["70496.60", "5.735"], ["70500.20", "0.017"], ["70503.60", "0.091"], ["70504.10", "0.004"], ["70504.90", "0.003"], ["70505.80", "0.006"], ["70506.40", "0.000"], ["70507.20", "0.057"], ["70509.40", "0.000"], ["70511.90", "0.000"], ["70512.60", "0.020"], ["70513.20", "0.025"], ["70513.40", "0.000"], ["70514.40", "0.004"], ["70519.90", "0.010"], ["70529.70", "0.118"], ["70549.80", "0.126"], ["71201.60", "0.000"], ["71369.20", "0.000"], ["74049.60", "0.004"]]}}
{"local_ts": 1773485437558, "server_ts": 1773485436765, "data": {"e": "depthUpdate", "E": 1773485436767, "T": 1773485436765, "s": "BTCUSDT", "U": 10109447802294, "u": 10109447807263, "pu": 10109447802291, "b": [["1000.00", "28.842"], ["5000.00", "101.418"], ["7049.70", "0.000"], ["19996.50", "0.270"], ["20096.50", "2.560"], ["20196.50", "0.170"], ["33000.00", "3.785"], ["66955.50", "0.010"], ["69078.80", "1.734"], ["69580.00", "2.793"], ["69791.50", "0.000"], ["69826.80", "1.576"], ["70215.40", "0.010"], ["70218.10", "0.028"], ["70390.90", "0.080"], ["70393.60", "0.000"], ["70450.30", "0.324"], ["70451.60", "0.502"], ["70451.70", "0.191"], ["70452.00", "0.071"], ["70452.40", "1.211"], ["70453.10", "1.104"], ["70473.20", "0.303"], ["70482.30", "0.161"], ["70482.60", "0.002"], ["70483.00", "0.014"], ["70483.60", "0.006"], ["70485.90", "0.346"], ["70489.50", "0.038"], ["70490.90", "0.402"], ["70491.20", "0.239"], ["70491.60", "0.122"], ["70492.30", "0.043"]], "a": [["70496.60", "5.582"], ["70496.80", "0.002"], ["70497.90", "0.008"], ["70503.60", "0.092"], ["70504.30", "0.000"], ["70504.70", "0.058"], ["70507.20", "0.003"], ["70507.80", "0.744"], ["70508.00", "0.026"], ["70508.70", "0.036"], ["70509.10", "0.190"], ["70509.40", "0.216"], ["70510.00", "1.461"], ["70512.50", "0.000"], ["70513.20", "0.027"], ["70513.40", "0.002"], ["70514.60", "0.003"], ["70516.00", "0.028"], ["70516.60", "0.089"], ["70519.90", "0.054"], ["70522.20", "0.017"], ["70522.30", "0.013"], ["70522.40", "0.016"], ["70522.50", "0.000"], ["70522.60", "0.394"], ["70527.60", "0.031"], ["70528.30", "0.203"], ["70528.70", "0.878"], ["70528.80", "0.380"], ["70529.00", "0.406"], ["70529.50", "1.375"], ["70529.70", "0.038"], ["70547.20", "0.028"], ["70547.90", "0.229"], ["70548.30", "0.100"], ["70548.60", "0.182"], ["70548.70", "0.036"], ["70550.00", "1.698"], ["70602.20", "0.002"], ["70604.90", "0.046"], ["70676.40", "0.159"], ["70720.30", "0.034"], ["70813.70", "0.000"], ["71201.60", "0.000"], ["71479.00", "0.907"], ["73316.40", "0.006"]]}}
{"local_ts": 1773485438579, "server_ts": 1773485437788, "data": {"e": "depthUpdate", "E": 1773485437789, "T": 1773485437788, "s": "BTCUSDT", "U": 10109447843230, "u": 10109447846034, "pu": 10109447843178, "b": [["5000.00", "101.418"], ["7049.70", "0.000"], ["19996.50", "2.400"], ["20096.50", "0.470"], ["20396.50", "0.130"], ["55765.50", "0.002"], ["66965.90", "0.000"], ["69186.70", "0.000"], ["69211.20", "0.618"], ["69387.80", "0.617"], ["69464.60", "0.000"], ["69791.50", "0.715"], ["70450.30", "0.324"], ["70450.50", "0.102"], ["70473.30", "0.000"], ["70474.60", "0.583"], ["70480.90", "0.000"], ["70490.90", "0.412"]], "a": [["70502.60", "0.023"], ["70502.90", "0.063"], ["70504.90", "0.024"], ["70509.90", "0.400"], ["70510.10", "0.095"], ["70511.50", "0.002"], ["70513.50", "0.403"], ["70524.60", "0.349"], ["70529.20", "0.002"], ["71201.60", "0.000"], ["71373.10", "0.000"], ["71443.60", "0.699"], ["71573.00", "0.710"], ["71624.50", "0.982"], ["74056.40", "0.002"], ["89523.20", "0.000"]]}}
{"local_ts": 1773485439599, "server_ts": 1773485438808, "data": {"e": "depthUpdate", "E": 1773485438809, "T": 1773485438808, "s": "BTCUSDT", "U": 10109447876473, "u": 10109447879100, "pu": 10109447876378, "b": [["1000.00", "28.842"], ["5000.00", "101.418"], ["7049.70", "0.056"], ["19996.50", "0.790"], ["20396.50", "2.210"], ["33000.00", "3.789"], ["55765.50", "0.000"], ["56397.00", "0.000"], ["66963.30", "0.000"], ["68762.40", "0.000"], ["69368.60", "2.016"], ["69477.80", "0.004"], ["69791.50", "0.715"], ["70250.50", "0.236"], ["70472.30", "0.261"], ["70473.10", "0.037"], ["70473.60", "0.162"], ["70474.40", "0.689"], ["70474.60", "0.513"], ["70480.80", "0.061"], ["70482.40", "0.718"]], "a": [["70499.90", "0.272"], ["70504.90", "0.003"], ["70506.40", "0.654"], ["70517.50", "0.023"], ["70518.70", "0.513"], ["70519.80", "0.005"], ["70520.20", "0.156"], ["70520.60", "0.079"], ["70521.90", "0.000"], ["70522.00", "0.824"], ["71201.60", "0.000"], ["71228.70", "0.002"], ["71502.50", "0.717"], ["71782.60", "0.698"], ["74051.80", "0.002"], ["89523.20", "0.000"]]}}
{"local_ts": 1773485440621, "server_ts": 1773485439830, "data": {"e": "depthUpdate", "E": 1773485439831, "T": 1773485439830, "s": "BTCUSDT", "U": 10109447911179, "u": 10109447915414, "pu": 10109447911146, "b": [["5000.00", "101.418"], ["7049.70", "0.056"], ["20296.50", "1.760"], ["20396.50", "1.240"], ["55765.50", "0.002"], ["63446.80", "0.002"], ["68728.40", "2.614"], ["68729.50", "0.016"], ["69791.50", "0.715"], ["70316.70", "0.404"], ["70362.70", "0.882"], ["70450.30", "0.324"], ["70450.50", "0.102"], ["70483.60", "0.004"], ["70483.90", "0.007"], ["70496.50", "4.554"]], "a": [["70496.60", "5.123"], ["70497.30", "0.167"], ["70500.50", "0.004"], ["70505.00", "0.009"], ["70506.00", "0.010"], ["70507.00", "0.011"], ["70508.80", "0.056"], ["70517.30", "0.000"], ["70517.80", "0.145"], ["70520.70", "0.011"], ["70521.60", "0.749"], ["70522.00", "0.739"], ["70523.30", "0.066"], ["70629.30", "0.994"], ["70810.30", "0.213"], ["71010.70", "0.003"], ["71201.60", "0.000"], ["71695.00", "1.402"], ["71714.40", "0.696"], ["74043.30", "0.000"], ["74055.00", "0.139"], ["77546.30", "0.002"], ["89523.20", "0.000"]]}}
{"local_ts": 1773485441644, "server_ts": 1773485440852, "data": {"e": "depthUpdate", "E": 1773485440855, "T": 1773485440852, "s": "BTCUSDT", "U": 10109447948393, "u": 10109447950829, "pu": 10109447948371, "b": [["1000.00", "28.842"], ["5000.00", "101.418"], ["7049.70", "0.056"], ["20196.50", "1.320"], ["20296.50", "1.680"], ["55765.50", "0.000"], ["63446.80", "0.002"], ["66943.30", "0.002"], ["66968.40", "0.000"], ["66971.60", "0.005"], ["69118.60", "0.000"], ["69791.50", "0.715"], ["70144.00", "3.033"], ["70316.70", "0.563"], ["70320.30", "0.455"], ["70362.70", "0.000"]], "a": [["70496.60", "5.007"], ["70496.90", "0.171"], ["70500.20", "0.017"], ["70506.00", "0.010"], ["70506.70", "0.000"], ["70510.00", "1.034"], ["70629.20", "0.004"], ["70810.30", "0.002"], ["71060.60", "0.582"], ["71201.60", "0.000"], ["77546.30", "0.002"], ["89523.20", "0.000"]]}}
{"local_ts": 1773485442666, "server_ts": 1773485441872, "data": {"e": "depthUpdate", "E": 1773485441875, "T": 1773485441872, "s": "BTCUSDT", "U": 10109447985778, "u": 10109447988525, "pu": 10109447985759, "b": [["1000.00", "28.842"], ["5000.00", "101.398"], ["7049.70", "0.028"], ["20096.50", "0.870"], ["20196.50", "2.130"], ["55765.50", "0.002"], ["56397.00", "0.000"], ["63446.80", "0.002"], ["66951.80", "0.000"], ["69791.50", "0.715"], ["70144.10", "0.000"], ["70250.80", "0.008"], ["70362.80", "0.000"], ["70414.50", "0.078"], ["70414.60", "0.252"], ["70450.40", "0.122"], ["70451.70", "0.385"], ["70452.00", "0.071"], ["70452.40", "1.211"], ["70452.70", "0.054"], ["70453.10", "1.104"], ["70461.30", "0.322"], ["70473.20", "0.303"], ["70482.60", "0.002"], ["70483.00", "0.012"], ["70483.60", "0.006"], ["70490.90", "0.412"], ["70491.30", "0.180"], ["70491.60", "0.122"], ["70492.00", "0.059"], ["70492.30", "0.043"]], "a": [["70507.70", "0.681"], ["70508.10", "0.038"], ["70508.40", "1.116"], ["70508.80", "0.156"], ["70509.20", "0.216"], ["70527.40", "0.025"], ["70527.70", "0.302"], ["70528.10", "0.055"], ["70528.40", "0.807"], ["70528.60", "0.372"], ["70528.80", "0.524"], ["70529.20", "0.038"], ["70529.40", "0.054"], ["70531.80", "0.108"], ["70547.00", "0.087"], ["70547.30", "0.547"], ["70547.70", "0.314"], ["70548.00", "0.052"], ["70548.40", "0.221"], ["70549.70", "0.072"], ["70629.10", "0.024"], ["70637.60", "0.151"], ["71201.60", "0.000"], ["71490.60", "0.496"], ["71547.00", "0.279"], ["77546.30", "0.002"], ["89523.20", "0.000"], ["115844.00", "0.000"]]}}
{"local_ts": 1773485443685, "server_ts": 1773485442892, "data": {"e": "depthUpdate", "E": 1773485442895, "T": 1773485442892, "s": "BTCUSDT", "U": 10109448026803, "u": 10109448029598, "pu": 10109448026731, "b": [["5000.00", "101.418"], ["7049.70", "0.028"], ["19996.50", "0.440"], ["20096.50", "2.540"], ["20196.50", "0.020"], ["55765.50", "0.000"], ["63446.80", "0.002"], ["69791.50", "0.715"], ["70362.80", "0.000"], ["70450.50", "0.102"], ["70450.60", "0.075"], ["70489.40", "0.005"]], "a": [["70496.60", "5.712"], ["70499.90", "0.918"], ["70500.00", "0.806"], ["70503.50", "0.032"], ["70503.60", "0.083"], ["70504.90", "0.015"], ["70507.70", "0.027"], ["70629.00", "0.020"], ["71201.60", "0.000"], ["71589.30", "6.277"], ["74045.00", "0.174"], ["77546.30", "0.002"], ["89523.20", "0.000"]]}}
{"local_ts": 1773485444705, "server_ts": 1773485443914, "data": {"e": "depthUpdate", "E": 1773485443915, "T": 1773485443914, "s": "BTCUSDT", "U": 10109448196912, "u": 10109448207941, "pu": 10109448196793, "b": [["1000.00", "28.842"], ["5000.00", "101.418"], ["7051.00", "0.028"], ["20009.90", "0.990"], ["20096.50", "0.260"], ["20409.90", "0.230"], ["55765.50", "0.002"], ["63458.90", "0.009"], ["66964.70", "0.004"], ["66969.10", "0.000"], ["69210.60", "0.722"], ["69804.80", "0.794"], ["70124.90", "0.000"], ["70169.60", "0.014"], ["70198.50", "10.228"], ["70200.10", "0.007"], ["70245.00", "13.620"], ["70246.60", "0.016"], ["70297.50", "0.000"], ["70304.00", "0.373"], ["70333.60", "0.002"], ["70340.70", "0.039"], ["70352.00", "0.263"], ["70353.50", "10.302"], ["70355.10", "0.300"], ["70366.10", "0.405"], ["70367.30", "0.353"], ["70368.30", "0.000"], ["70374.10", "0.000"], ["70384.10", "0.516"], ["70409.40", "0.615"], ["70419.40", "0.012"], ["70419.70", "0.202"], ["70420.70", "0.024"], ["70426.00", "0.041"], ["70426.70", "0.200"], ["70427.70", "2.667"], ["70430.90", "0.307"], ["70432.30", "0.379"], ["70433.10", "0.054"], ["70434.10", "0.000"], ["70435.00", "0.050"], ["70436.40", "0.000"], ["70440.80", "1.131"], ["70441.80", "0.002"], ["70441.90", "0.002"], ["70444.70", "0.000"], ["70454.70", "0.007"], ["70455.60", "0.024"], ["70456.10", "8.519"], ["70457.10", "0.032"], ["70459.90", "0.211"], ["70460.60", "0.002"], ["70469.10", "0.002"], ["70470.70", "0.134"], ["70471.10", "0.159"], ["70471.20", "2.016"], ["70471.90", "0.148"], ["70472.90", "0.412"], ["70473.50", "0.155"], ["70474.60", "0.710"], ["70478.50", "0.327"], ["70479.40", "0.444"], ["70480.00", "0.755"], ["70480.40", "0.275"], ["70480.50", "0.000"], ["70481.20", "0.003"], ["70481.50", "0.072"], ["70481.70", "0.659"], ["70482.30", "0.021"], ["70483.20", "0.040"], ["70483.60", "0.074"], ["70484.70", "0.022"], ["70484.80", "0.141"], ["70485.00", "0.149"], ["70485.10", "0.052"], ["70485.20", "0.696"], ["70485.70", "0.007"], ["70485.80", "0.007"], ["70485.90", "0.430"], ["70486.00", "0.006"], ["70486.30", "0.002"], ["70486.60", "0.219"], ["70486.70", "0.046"], ["70486.80", "0.013"], ["70487.10", "0.002"], ["70487.30", "0.010"], ["70487.40", "0.011"], ["70487.60", "0.257"], ["70488.60", "0.007"], ["70488.90", "1.205"], ["70490.00", "0.405"], ["70490.10", "0.000"], ["70490.80", "0.009"], ["70491.00", "0.008"], ["70491.60", "0.005"], ["70491.70", "0.144"], ["70492.00", "0.004"], ["70492.20", "0.005"], ["70492.60", "0.150"], ["70492.70", "0.002"], ["70492.80", "0.004"], ["70492.90", "0.216"], ["70493.20", "0.638"], ["70493.30", "0.522"], ["70493.40", "0.009"], ["70494.10", "0.003"], ["70494.40", "0.094"], ["70494.50", "0.225"], ["70494.90", "0.003"], ["70495.00", "0.006"], ["70495.10", "0.012"], ["70495.20", "0.107"], ["70495.40", "0.283"], ["70495.50", "0.005"], ["70496.50", "0.028"], ["70496.70", "0.000"], ["70496.80", "0.002"], ["70497.00", "0.026"], ["70498.20", "0.211"], ["70499.30", "0.002"], ["70499.90", "0.003"], ["70500.70", "0.011"], ["70501.00", "0.008"], ["70502.00", "0.001"], ["70502.40", "0.769"], ["70502.70", "0.017"], ["70502.80", "0.008"], ["70503.70", "0.000"], ["70504.30", "0.384"], ["70504.70", "0.010"], ["70504.90", "0.287"], ["70505.00", "0.007"], ["70505.30", "0.021"], ["70506.10", "0.003"], ["70506.40", "0.012"], ["70506.90", "0.000"], ["70508.10", "0.003"], ["70508.20", "0.001"], ["70508.80", "0.012"], ["70509.10", "0.012"], ["70509.80", "0.004"], ["70509.90", "0.086"]], "a": [["70510.00", "8.114"], ["70510.40", "0.030"], ["70512.10", "0.002"], ["70512.20", "0.005"], ["70517.60", "0.024"], ["70518.70", "0.003"], ["70518.80", "0.007"], ["70519.10", "0.347"], ["70520.60", "0.010"], ["70520.70", "0.011"], ["70521.60", "0.003"], ["70523.70", "0.346"], ["70524.80", "0.009"], ["70524.90", "0.032"], ["70525.10", "0.009"], ["70527.10", "0.021"], ["70528.10", "0.104"], ["70528.80", "0.074"], ["70529.90", "0.010"], ["70530.50", "0.512"], ["70532.10", "0.003"], ["70532.70", "0.000"], ["70532.90", "0.143"], ["70534.40", "0.000"], ["70534.70", "0.089"], ["70535.00", "0.253"], ["70535.70", "0.125"], ["70538.90", "0.066"], ["70539.60", "0.009"], ["70543.60", "0.008"], ["70543.70", "0.273"], ["70543.80", "0.102"], ["70547.40", "0.106"], ["70549.40", "0.204"], ["70549.70", "0.072"], ["70553.10", "1.664"], ["70555.10", "0.003"], ["70557.70", "7.867"], ["70558.60", "0.006"], ["70560.90", "0.000"], ["70561.90", "0.200"], ["70565.20", "0.005"], ["70567.90", "0.502"], ["70568.90", "0.200"], ["70571.80", "0.075"], ["70590.60", "0.002"], ["70600.50", "0.050"], ["70625.70", "0.000"], ["70635.90", "0.003"], ["70662.70", "0.277"], ["70733.70", "0.002"], ["70838.70", "0.009"], ["70843.20", "0.000"], ["70870.90", "0.002"], ["70871.10", "0.000"], ["70871.90", "0.386"], ["70872.10", "0.236"], ["70917.80", "0.007"], ["71048.50", "0.232"], ["71059.80", "4.447"], ["71215.10", "0.477"], ["77561.00", "0.002"], ["89523.20", "0.000"]]}}
{"local_ts": 1773485445731, "server_ts": 1773485444939, "data": {"e": "depthUpdate", "E": 1773485444941, "T": 1773485444939, "s": "BTCUSDT", "U": 10109448343346, "u": 10109448350737, "pu": 10109448342827, "b": [["5000.00", "101.418"], ["7050.90", "0.000"], ["19996.50", "0.550"], ["19999.80", "0.000"], ["20000.60", "0.000"], ["20008.90", "0.000"], ["20308.90", "0.080"], ["20408.90", "2.160"], ["20409.90", "0.200"], ["55765.50", "0.000"], ["56407.00", "0.000"], ["63458.00", "0.264"], ["69582.50", "65.182"], ["69791.90", "55.589"], ["69803.80", "0.000"], ["69932.50", "0.150"], ["69952.90", "0.002"], ["70156.50", "0.004"], ["70213.70", "3.818"], ["70224.10", "0.002"], ["70249.20", "0.005"], ["70268.20", "0.219"], ["70430.90", "0.038"], ["70431.00", "0.008"], ["70452.90", "0.004"], ["70453.60", "9.727"], ["70458.80", "1.357"], ["70459.10", "0.003"], ["70471.90", "0.090"], ["70478.60", "0.109"], ["70483.20", "0.070"], ["70483.80", "0.513"], ["70484.40", "0.002"], ["70484.50", "0.000"], ["70485.40", "0.007"], ["70486.20", "0.007"], ["70489.10", "0.008"], ["70490.90", "0.005"], ["70491.40", "0.005"], ["70491.80", "0.007"], ["70496.20", "0.157"], ["70497.30", "0.063"], ["70497.50", "0.102"], ["70497.80", "0.000"], ["70504.90", "0.284"], ["70508.90", "0.907"]], "a": [["70509.00", "12.785"], ["70510.00", "1.688"], ["70515.40", "0.003"], ["70518.30", "0.003"], ["70533.20", "0.002"], ["70534.10", "0.132"], ["70538.80", "0.219"], ["70541.30", "2.070"], ["70565.00", "0.002"], ["70566.80", "8.503"], ["70568.90", "0.200"], ["70666.70", "12.749"], ["70678.60", "0.250"], ["70679.20", "0.000"], ["70710.60", "0.008"], ["70711.30", "0.002"], ["70716.50", "0.004"], ["70733.60", "0.000"], ["70743.20", "0.002"], ["71023.60", "0.009"], ["71214.10", "0.000"], ["71571.00", "0.033"], ["71628.00", "3.872"], ["74039.00", "0.038"], ["74056.90", "0.002"], ["77559.90", "0.000"], ["89523.20", "0.000"]]}}
{"local_ts": 1773485446753, "server_ts": 1773485445962, "data": {"e": "depthUpdate", "E": 1773485445963, "T": 1773485445962, "s": "BTCUSDT", "U": 10109448416430, "u": 10109448423951, "pu": 10109448416316, "b": [["1000.00", "28.842"], ["5000.00", "101.398"], ["7050.90", "0.000"], ["20308.90", "2.090"], ["20408.90", "0.910"], ["33000.00", "3.785"], ["63458.00", "0.264"], ["66950.60", "0.002"], ["66958.70", "0.000"], ["69298.10", "1.445"], ["69387.40", "0.617"], ["69803.80", "0.002"], ["69924.70", "0.002"], ["70156.40", "0.002"], ["70156.50", "0.000"], ["70263.00", "0.708"], ["70304.90", "0.240"], ["70308.40", "0.208"], ["70457.20", "0.008"], ["70457.30", "0.057"], ["70459.20", "0.006"], ["70459.40", "0.006"], ["70460.00", "0.235"], ["70460.80", "0.655"], ["70466.40", "0.002"], ["70474.50", "0.086"], ["70476.50", "0.024"], ["70478.40", "1.145"], ["70478.60", "0.024"], ["70484.10", "0.581"], ["70484.80", "0.567"], ["70484.90", "0.207"], ["70485.50", "0.005"], ["70488.50", "0.031"], ["70488.70", "0.211"], ["70489.90", "0.003"], ["70491.10", "0.006"], ["70492.00", "0.004"], ["70492.50", "0.641"], ["70493.60", "0.003"], ["70494.00", "0.002"], ["70496.10", "0.000"], ["70496.50", "0.047"], ["70496.70", "0.000"], ["70498.70", "0.000"], ["70500.80", "0.001"], ["70501.90", "0.044"], ["70502.20", "0.007"], ["70502.60", "0.514"], ["70502.70", "0.131"], ["70504.90", "0.000"], ["70506.30", "0.004"], ["70508.90", "0.145"]], "a": [["70509.00", "12.985"], ["70512.60", "0.012"], ["70514.60", "0.014"], ["70515.40", "0.013"], ["70518.30", "0.013"], ["70523.60", "1.075"], ["70536.20", "0.106"], ["70547.40", "0.052"], ["70565.30", "0.283"], ["70578.90", "1.571"], ["70584.90", "0.000"], ["71214.10", "0.000"], ["71478.80", "5.526"], ["71545.50", "1.255"], ["77559.90", "0.000"], ["89523.20", "0.000"]]}}
{"local_ts": 1773485447778, "server_ts": 1773485446984, "data": {"e": "depthUpdate", "E": 1773485446987, "T": 1773485446984, "s": "BTCUSDT", "U": 10109448489795, "u": 10109448496032, "pu": 10109448489768, "b": [["1000.00", "28.842"], ["5000.00", "101.418"], ["7050.90", "0.000"], ["20208.90", "1.650"], ["20308.90", "1.350"], ["20309.00", "0.007"], ["56407.00", "0.000"], ["63458.00", "0.264"], ["66953.50", "0.002"], ["69122.10", "0.000"], ["69239.70", "1.463"], ["69653.90", "6.161"], ["69803.80", "0.000"], ["69854.20", "0.002"], ["69944.80", "0.000"], ["70147.40", "4.553"], ["70262.90", "0.004"], ["70287.00", "0.080"], ["70293.30", "0.361"], ["70330.40", "10.240"], ["70369.10", "0.692"], ["70452.20", "0.074"], ["70452.40", "1.218"], ["70454.50", "0.061"], ["70454.80", "2.682"], ["70455.10", "0.068"], ["70455.50", "0.063"], ["70455.80", "0.061"], ["70456.20", "0.042"], ["70460.50", "0.003"], ["70460.80", "0.598"], ["70464.40", "0.000"], ["70481.80", "0.206"], ["70484.20", "0.400"], ["70486.80", "0.006"], ["70487.50", "0.005"], ["70488.60", "0.011"], ["70488.90", "0.000"], ["70490.10", "0.141"], ["70497.00", "0.502"], ["70497.40", "0.194"], ["70497.70", "0.061"], ["70498.10", "0.611"], ["70498.40", "0.159"], ["70500.60", "0.024"], ["70501.10", "0.057"], ["70504.80", "0.060"], ["70506.60", "0.085"], ["70508.90", "0.844"]], "a": [["70509.00", "13.067"], ["70512.60", "0.004"], ["70515.70", "0.030"], ["70516.00", "0.068"], ["70516.40", "0.042"], ["70516.70", "0.109"], ["70517.10", "0.185"], ["70536.80", "0.027"], ["70537.20", "0.418"], ["70537.50", "0.328"], ["70537.90", "0.036"], ["70538.10", "0.055"], ["70538.20", "0.182"], ["70539.30", "0.118"], ["70539.40", "0.054"], ["70540.10", "0.538"], ["70547.60", "0.515"], ["70550.20", "0.023"], ["70559.60", "0.077"], ["70561.70", "0.046"], ["70561.90", "0.317"], ["70610.10", "0.160"], ["70612.30", "0.254"], ["70614.70", "0.163"], ["70616.80", "0.176"], ["70619.70", "0.158"], ["70624.60", "0.181"], ["70628.50", "0.539"], ["70632.30", "0.172"], ["70636.10", "0.080"], ["70639.90", "1.247"], ["70678.70", "3.376"], ["70704.90", "0.112"], ["70715.70", "0.731"], ["70766.30", "0.003"], ["71023.50", "0.009"], ["71214.10", "0.000"], ["71359.50", "0.000"], ["72271.30", "0.000"], ["74067.00", "0.050"], ["77559.90", "0.000"], ["89523.20", "0.000"]]}}
{"local_ts": 1773485448803, "server_ts": 1773485448010, "data": {"e": "depthUpdate", "E": 1773485448011, "T": 1773485448010, "s": "BTCUSDT", "U": 10109448544455, "u": 10109448551021, "pu": 10109448544363, "b": [["5000.00", "101.438"], ["7050.90", "0.056"], ["20108.90", "1.210"], ["20208.90", "1.790"], ["33000.00", "3.789"], ["56407.00", "0.128"], ["63458.00", "0.264"], ["64451.50", "0.004"], ["66974.60", "0.002"], ["69472.40", "1.293"], ["69803.80", "0.000"], ["70100.00", "48.827"], ["70156.40", "0.038"], ["70482.50", "0.508"]], "a": [["70509.00", "13.137"], ["70529.20", "0.002"], ["70529.30", "0.092"], ["70556.60", "0.007"], ["71214.10", "0.000"], ["71450.00", "6.192"], ["71520.50", "2.768"], ["71522.20", "28.560"], ["71566.60", "2.106"], ["71661.30", "0.000"], ["71802.20", "0.000"], ["71848.70", "2.780"], ["71876.00", "0.308"], ["72624.20", "0.006"], ["77559.90", "0.000"], ["89523.20", "0.000"]]}}
{"local_ts": 1773485449826, "server_ts": 1773485449032, "data": {"e": "depthUpdate", "E": 1773485449033, "T": 1773485449032, "s": "BTCUSDT", "U": 10109448601499, "u": 10109448606269, "pu": 10109448601477, "b": [["1000.00", "28.842"], ["5000.00", "101.418"], ["7050.90", "0.056"], ["20008.90", "0.770"], ["20108.90", "2.230"], ["63458.00", "0.264"], ["66980.90", "0.002"], ["69317.30", "0.288"], ["69434.10", "0.022"], ["69803.80", "0.000"], ["69970.50", "1.428"], ["70431.30", "0.024"], ["70445.40", "0.000"], ["70459.60", "1.094"], ["70459.70", "0.009"], ["70474.40", "0.003"], ["70474.60", "0.574"], ["70478.90", "0.000"], ["70479.90", "0.000"], ["70480.70", "0.293"], ["70487.70", "0.256"], ["70489.20", "0.000"], ["70489.90", "0.005"], ["70492.80", "0.030"], ["70494.80", "0.061"], ["70498.30", "0.164"], ["70507.70", "0.002"]], "a": [["70509.00", "9.853"], ["70509.50", "0.397"], ["70510.30", "0.000"], ["70510.80", "0.635"], ["70515.00", "0.010"], ["70515.70", "0.030"], ["70518.70", "0.299"], ["70526.60", "0.121"], ["70546.30", "0.021"], ["70554.70", "0.000"], ["70554.80", "0.000"], ["70572.50", "0.001"], ["70586.60", "0.047"], ["71214.10", "0.000"], ["77559.90", "0.000"]]}}
{"local_ts": 1773485450845, "server_ts": 1773485450054, "data": {"e": "depthUpdate", "E": 1773485450055, "T": 1773485450054, "s": "BTCUSDT", "U": 10109448651377, "u": 10109448657828, "pu": 10109448651344, "b": [["5000.00", "101.418"], ["7050.90", "0.056"], ["20008.90", "2.580"], ["20108.90", "0.050"], ["20408.90", "0.370"], ["63458.00", "0.264"], ["69803.80", "0.000"], ["70322.10", "23.119"], ["70459.60", "1.096"], ["70459.70", "0.007"], ["70460.40", "1.353"], ["70467.50", "0.928"], ["70469.20", "0.129"], ["70469.30", "0.044"], ["70474.60", "1.416"], ["70481.70", "1.501"], ["70484.20", "0.615"], ["70487.60", "0.259"], ["70488.10", "0.044"], ["70488.80", "1.086"], ["70496.20", "0.000"], ["70499.20", "0.048"], ["70499.40", "0.010"]], "a": [["70516.60", "0.012"], ["70521.70", "0.007"], ["70524.30", "0.848"], ["70531.40", "0.849"], ["70538.50", "0.847"], ["70545.60", "0.852"], ["70552.70", "0.842"], ["70554.80", "0.042"], ["70559.80", "0.870"], ["71214.10", "0.000"], ["71662.80", "0.000"], ["71875.80", "0.007"], ["74050.40", "0.002"], ["74066.90", "0.000"]]}}
{"local_ts": 1773485451866, "server_ts": 1773485451076, "data": {"e": "depthUpdate", "E": 1773485451077, "T": 1773485451076, "s": "BTCUSDT", "U": 10109448705407, "u": 10109448709887, "pu": 10109448705268, "b": [["1000.00", "28.842"], ["5000.00", "101.418"], ["7050.90", "0.028"], ["20008.90", "0.320"], ["20308.90", "0.200"], ["20408.90", "2.480"], ["69803.80", "0.000"], ["70156.40", "0.074"], ["70322.10", "23.218"], ["70350.30", "0.000"], ["70439.20", "0.003"], ["70460.40", "1.353"], ["70467.50", "0.928"], ["70473.70", "0.070"], ["70474.60", "1.416"], ["70480.70", "0.123"], ["70481.70", "1.505"], ["70487.70", "0.388"], ["70488.80", "1.086"], ["70496.20", "0.000"], ["70498.30", "0.159"], ["70501.80", "0.008"]], "a": [["70509.00", "9.553"], ["70511.80", "0.004"], ["70515.90", "0.000"], ["70521.70", "0.007"], ["70524.30", "0.848"], ["70531.40", "0.849"], ["70533.50", "0.009"], ["70538.50", "0.847"], ["70544.20", "0.036"], ["70545.60", "0.852"], ["70552.70", "0.842"], ["70554.90", "0.097"], ["70559.80", "0.870"], ["70576.50", "0.000"], ["70593.60", "0.045"], ["70732.60", "0.009"], ["71214.10", "0.000"], ["71319.10", "0.009"], ["71567.00", "3.292"], ["74063.90", "0.004"]]}}
{"local_ts": 1773485452887, "server_ts": 1773485452092, "data": {"e": "depthUpdate", "E": 1773485452097, "T": 1773485452092, "s": "BTCUSDT", "U": 10109448750825, "u": 10109448754621, "pu": 10109448750659, "b": [["1000.00", "28.842"], ["5000.00", "101.418"], ["7050.90", "0.028"], ["20208.90", "0.050"], ["20308.90", "2.320"], ["20408.90", "0.630"], ["66968.10", "0.002"], ["66970.40", "0.006"], ["69275.00", "1.314"], ["69803.80", "2.145"], ["69803.90", "0.010"], ["70262.50", "0.014"], ["70263.20", "0.000"], ["70351.20", "0.002"], ["70392.20", "0.000"], ["70411.60", "0.024"], ["70429.90", "0.072"], ["70430.40", "0.965"], ["70433.90", "0.490"], ["70434.20", "0.070"], ["70434.60", "0.061"], ["70437.30", "0.051"], ["70440.70", "0.072"], ["70447.90", "0.003"], ["70454.80", "1.018"], ["70455.00", "0.372"], ["70456.10", "0.364"], ["70456.40", "0.042"], ["70466.40", "0.002"], ["70471.20", "0.206"], ["70487.60", "0.257"], ["70488.20", "0.010"], ["70496.20", "0.000"], ["70497.30", "0.289"], ["70497.60", "0.239"], ["70498.30", "0.262"], ["70498.70", "0.042"], ["70501.80", "0.008"]], "a": [["70509.00", "9.511"], ["70515.40", "0.013"], ["70515.60", "0.236"], ["70515.90", "0.000"], ["70516.00", "0.130"], ["70516.70", "0.137"], ["70517.10", "0.185"], ["70519.80", "0.003"], ["70521.70", "0.007"], ["70523.40", "0.002"], ["70529.30", "0.029"], ["70529.40", "1.491"], ["70536.80", "0.027"], ["70537.10", "0.061"], ["70538.10", "0.055"], ["70538.20", "0.182"], ["70541.30", "0.279"], ["70542.60", "0.010"], ["70548.80", "0.170"], ["70554.90", "0.097"], ["70557.60", "1.689"], ["70558.60", "0.042"], ["70559.00", "0.065"], ["70559.30", "0.201"], ["70559.50", "0.036"], ["70582.80", "0.394"], ["70593.40", "0.090"], ["70607.00", "2.760"], ["70666.70", "0.002"], ["70732.30", "0.003"], ["71023.70", "0.008"], ["71204.90", "0.007"], ["71214.10", "2.103"], ["71236.70", "0.008"], ["71256.90", "0.700"], ["71449.80", "0.021"], ["71662.90", "0.008"], ["71876.00", "0.312"]]}}
{"local_ts": 1773485453908, "server_ts": 1773485453118, "data": {"e": "depthUpdate", "E": 1773485453119, "T": 1773485453118, "s": "BTCUSDT", "U": 10109448815513, "u": 10109448819100, "pu": 10109448815453, "b": [["5000.00", "101.418"], ["7051.20", "0.028"], ["20211.60", "1.760"], ["20308.90", "1.020"], ["33000.00", "3.785"], ["56407.00", "0.000"], ["66971.40", "0.004"], ["66986.00", "0.000"], ["68377.60", "1.252"], ["69383.40", "0.000"], ["69453.90", "0.428"], ["69455.60", "9.140"], ["69806.50", "0.000"], ["70159.00", "0.080"], ["70328.30", "0.000"], ["70460.40", "0.511"], ["70463.10", "0.406"], ["70463.20", "0.850"], ["70467.50", "0.000"], ["70469.70", "0.000"], ["70469.80", "0.044"], ["70474.60", "0.574"], ["70481.40", "0.067"], ["70481.70", "0.414"], ["70488.80", "0.044"], ["70497.00", "0.030"], ["70498.90", "0.511"], ["70501.00", "0.003"], ["70504.50", "0.001"], ["70504.60", "0.116"], ["70508.90", "0.110"]], "a": [["70511.70", "2.675"], ["70518.70", "0.372"], ["70522.30", "0.068"], ["70524.40", "0.001"], ["70529.30", "0.012"], ["70531.10", "0.035"], ["70531.40", "0.007"], ["70536.00", "0.290"], ["70536.10", "0.346"], ["70538.50", "0.005"], ["70545.60", "0.002"], ["70546.40", "0.025"], ["70549.40", "0.147"], ["70549.70", "1.066"], ["70552.70", "0.000"], ["70559.80", "0.026"], ["70573.10", "0.014"], ["70631.10", "0.056"], ["70641.90", "0.015"], ["70735.40", "0.007"], ["70743.00", "0.018"], ["71026.40", "0.012"], ["71216.80", "0.000"], ["71239.50", "0.008"], ["71316.60", "0.003"], ["71452.50", "0.011"], ["71665.60", "0.011"], ["71878.70", "0.012"], ["74042.90", "0.002"]]}}
{"local_ts": 1773485454936, "server_ts": 1773485454141, "data": {"e": "depthUpdate", "E": 1773485454143, "T": 1773485454141, "s": "BTCUSDT", "U": 10109448852455, "u": 10109448856781, "pu": 10109448852448, "b": [["1000.00", "28.842"], ["5000.00", "101.418"], ["7051.20", "0.000"], ["20111.60", "1.540"], ["20211.60", "1.240"], ["56409.00", "0.200"], ["66966.00", "0.006"], ["66983.50", "0.006"], ["66983.60", "0.004"], ["69277.90", "0.721"], ["69665.60", "0.000"], ["69791.90", "0.000"], ["69806.50", "0.000"], ["69952.80", "0.000"], ["70262.40", "0.007"], ["70454.30", "0.138"], ["70460.40", "0.511"], ["70462.80", "0.268"], ["70462.90", "0.005"], ["70466.40", "0.002"], ["70467.50", "0.000"], ["70474.60", "0.574"], ["70481.70", "0.414"], ["70481.90", "0.187"], ["70488.80", "0.044"], ["70498.90", "0.511"], ["70501.00", "0.006"], ["70504.40", "1.069"], ["70504.60", "0.174"], ["70511.50", "0.008"]], "a": [["70511.70", "2.682"], ["70518.70", "0.372"], ["70522.30", "0.068"], ["70524.40", "0.001"], ["70528.20", "0.283"], ["70530.40", "0.196"], ["70531.40", "0.007"], ["70536.00", "0.106"], ["70536.10", "0.077"], ["70538.50", "0.005"], ["70545.60", "0.002"], ["70550.50", "0.005"], ["70552.70", "0.000"], ["70557.50", "1.005"], ["70559.80", "0.026"], ["70575.20", "0.083"], ["70746.50", "0.012"], ["71023.70", "0.000"], ["71059.70", "0.004"], ["71216.80", "0.000"], ["71224.30", "0.000"], ["71236.70", "0.000"], ["71280.10", "0.012"], ["71280.30", "1.433"], ["71662.90", "0.000"], ["74044.90", "0.002"], ["89523.10", "0.000"]]}}
{"local_ts": 1773485455955, "server_ts": 1773485455164, "data": {"e": "depthUpdate", "E": 1773485455165, "T": 1773485455164, "s": "BTCUSDT", "U": 10109448889749, "u": 10109448893186, "pu": 10109448889672, "b": [["5000.00", "101.418"], ["7051.20", "0.000"], ["20011.60", "1.100"], ["20111.60", "1.900"], ["33000.00", "3.785"], ["69293.20", "1.428"], ["69448.00", "0.686"], ["69464.50", "1.868"], ["69806.50", "0.000"], ["70069.80", "0.036"], ["70470.00", "4.877"], ["70470.10", "0.678"], ["70500.00", "0.032"], ["70501.00", "0.003"], ["70504.50", "0.001"], ["70504.60", "0.117"], ["70508.20", "0.049"], ["70508.80", "0.002"], ["70511.60", "9.328"]], "a": [["70511.70", "2.848"], ["70518.70", "0.344"], ["70522.30", "0.065"], ["70523.00", "0.233"], ["70528.00", "0.193"], ["70528.20", "0.014"], ["70530.40", "0.012"], ["70530.90", "0.005"], ["70532.70", "0.205"], ["70544.10", "0.018"], ["70555.30", "0.051"], ["70677.40", "0.062"], ["70735.30", "0.000"], ["71026.40", "0.020"], ["71216.80", "0.102"], ["71239.50", "0.016"], ["71452.50", "0.019"], ["71665.60", "0.019"], ["71878.70", "0.020"], ["74064.90", "0.000"], ["74071.70", "0.002"]]}}
{"local_ts": 1773485456976, "server_ts": 1773485456184, "data": {"e": "depthUpdate", "E": 1773485456185, "T": 1773485456184, "s": "BTCUSDT", "U": 10109448922497, "u": 10109448925967, "pu": 10109448922449, "b": [["1000.00", "28.842"], ["5000.00", "101.418"], ["7051.20", "0.000"], ["20011.60", "2.350"], ["20111.60", "0.000"], ["20411.60", "0.650"], ["68380.20", "0.626"], ["69806.50", "0.000"], ["69841.70", "0.774"], ["70159.00", "0.080"], ["70432.90", "0.000"], ["70440.60", "0.162"], ["70486.00", "0.367"], ["70487.00", "0.000"], ["70491.30", "0.014"], ["70492.30", "0.089"]], "a": [["70511.70", "2.846"], ["70514.70", "0.058"], ["70520.80", "1.024"], ["70525.80", "0.087"], ["70528.00", "0.009"], ["70532.50", "0.098"], ["70532.60", "0.189"], ["70532.70", "0.593"], ["70538.60", "0.002"], ["70539.40", "0.073"], ["70544.10", "0.018"], ["70545.80", "0.596"], ["70555.90", "0.457"], ["70557.50", "1.065"], ["70564.30", "0.080"], ["70574.40", "0.108"], ["70815.90", "0.033"], ["71026.40", "0.012"], ["71129.50", "0.033"], ["71216.80", "0.000"], ["71239.50", "0.008"], ["71444.50", "0.033"], ["71452.50", "0.011"], ["71501.10", "2.780"], ["71665.60", "0.011"], ["71760.90", "0.033"], ["71878.70", "0.012"], ["72078.70", "0.033"], ["72397.80", "0.046"], ["72718.40", "0.033"], ["73040.50", "0.035"], ["73363.90", "0.033"], ["73688.80", "0.046"], ["74015.10", "0.033"], ["74071.70", "0.000"], ["74342.90", "0.033"], ["74672.10", "0.033"], ["75002.80", "0.033"]]}}
{"local_ts": 1773485457997, "server_ts": 1773485457206, "data": {"e": "depthUpdate", "E": 1773485457207, "T": 1773485457206, "s": "BTCUSDT", "U": 10109448956186, "u": 10109448959930, "pu": 10109448956053, "b": [["1000.00", "28.842"], ["5000.00", "101.418"], ["7051.20", "0.056"], ["20011.60", "0.110"], ["20311.60", "0.310"], ["20411.60", "2.580"], ["33000.00", "3.789"], ["69249.00", "3.447"], ["69524.50", "0.000"], ["69578.20", "0.718"], ["69806.50", "0.000"], ["70265.70", "0.004"], ["70349.40", "0.107"], ["70378.20", "0.576"], ["70430.70", "10.892"], ["70431.30", "0.087"], ["70435.10", "0.213"], ["70435.40", "0.068"], ["70435.80", "0.061"], ["70436.50", "0.042"], ["70456.20", "0.060"], ["70456.40", "0.351"], ["70457.50", "0.105"], ["70457.90", "0.983"], ["70499.20", "0.429"], ["70499.50", "0.234"], ["70500.30", "0.606"], ["70501.00", "0.046"], ["70503.80", "0.041"], ["70504.00", "0.323"]], "a": [["70511.70", "2.563"], ["70521.80", "0.065"], ["70522.30", "0.004"], ["70522.50", "0.154"], ["70522.80", "0.340"], ["70525.80", "0.321"], ["70526.00", "0.002"], ["70529.30", "0.012"], ["70540.80", "0.010"], ["70542.70", "0.002"], ["70543.20", "0.066"], ["70544.20", "0.220"], ["70557.50", "0.881"], ["70564.50", "0.061"], ["70565.60", "0.180"], ["70565.90", "0.064"], ["70568.10", "0.038"], ["70643.70", "0.592"], ["70644.70", "0.198"], ["70645.90", "0.012"], ["70646.80", "0.000"], ["70658.50", "0.457"], ["70659.60", "0.092"], ["70660.50", "0.184"], ["70666.40", "0.285"], ["70669.80", "0.000"], ["70735.10", "0.007"], ["71026.30", "0.008"], ["71216.80", "0.000"], ["71239.40", "0.078"], ["71452.40", "0.011"], ["71665.50", "0.013"], ["71810.00", "0.011"], ["71878.60", "0.004"], ["74069.50", "0.050"]]}}
{"local_ts": 1773485459021, "server_ts": 1773485458228, "data": {"e": "depthUpdate", "E": 1773485458231, "T": 1773485458228, "s": "BTCUSDT", "U": 10109448988861, "u": 10109448991875, "pu": 10109448988835, "b": [["5000.00", "101.418"], ["7051.20", "0.056"], ["20211.60", "0.160"], ["20311.60", "2.440"], ["20411.60", "0.400"], ["66950.90", "0.000"], ["66959.00", "0.002"], ["68000.00", "181.469"], ["68239.50", "0.000"], ["69406.50", "0.499"], ["69477.00", "4.600"], ["69806.50", "0.000"], ["69806.60", "0.000"], ["70159.00", "0.080"], ["70159.10", "0.004"], ["70356.40", "0.095"], ["70361.40", "0.014"], ["70363.30", "0.164"], ["70373.30", "0.344"], ["70374.60", "0.000"], ["70378.50", "0.041"], ["70385.20", "0.000"], ["70409.70", "0.000"], ["70424.40", "0.045"], ["70425.40", "0.002"], ["70428.30", "0.120"], ["70429.20", "0.171"], ["70435.50", "0.306"], ["70439.00", "0.041"], ["70504.60", "0.174"]], "a": [["70511.70", "2.327"], ["70518.70", "0.372"], ["70547.00", "0.365"], ["71026.40", "0.004"], ["71216.80", "0.000"], ["71239.50", "0.000"], ["71452.50", "0.007"], ["71665.60", "0.007"], ["71878.70", "0.008"], ["72627.00", "0.140"]]}}
{"local_ts": 1773485460040, "server_ts": 1773485459250, "data": {"e": "depthUpdate", "E": 1773485459251, "T": 1773485459250, "s": "BTCUSDT", "U": 10109449022377, "u": 10109449025147, "pu": 10109449022360, "b": [["1000.00", "28.842"], ["5000.00", "101.418"], ["7051.20", "0.056"], ["20111.60", "0.010"], ["20211.60", "2.290"], ["20311.60", "0.700"], ["69401.80", "0.000"], ["69559.70", "0.286"], ["69806.50", "0.000"], ["70358.10", "0.000"], ["70363.10", "0.000"], ["70363.30", "0.164"], ["70373.30", "0.385"], ["70378.30", "0.601"], ["70412.50", "0.003"], ["70419.50", "6.998"], ["70426.60", "0.375"]], "a": [["70511.70", "2.431"], ["70517.20", "0.005"], ["70588.80", "0.017"], ["70595.90", "0.000"], ["70602.90", "0.015"], ["70643.60", "0.589"], ["71026.30", "0.012"], ["71216.80", "0.000"], ["71239.40", "0.082"], ["71452.40", "0.015"], ["71452.50", "0.003"], ["71621.00", "0.000"], ["71665.50", "0.017"], ["71665.60", "0.003"], ["71878.60", "0.012"], ["71878.70", "0.004"], ["71899.70", "0.254"], ["74041.10", "0.002"], ["74043.90", "0.000"]]}}
{"local_ts": 1773485461062, "server_ts": 1773485460268, "data": {"e": "depthUpdate", "E": 1773485460273, "T": 1773485460268, "s": "BTCUSDT", "U": 10109449073616, "u": 10109449081568, "pu": 10109449073377, "b": [["5000.00", "101.418"], ["7051.20", "0.028"], ["20111.60", "1.860"], ["20211.60", "1.140"], ["66973.80", "0.002"], ["69806.50", "0.000"], ["70463.70", "0.004"], ["70463.80", "0.005"], ["70492.40", "0.512"], ["70493.30", "0.522"], ["70500.60", "0.681"], ["70500.90", "0.059"], ["70501.00", "0.053"], ["70504.40", "1.066"]], "a": [["70511.70", "1.827"], ["70522.30", "0.007"], ["70541.00", "0.248"], ["70541.90", "0.065"], ["70547.00", "0.305"], ["70629.30", "0.511"], ["70653.20", "0.042"], ["70659.70", "0.094"], ["70660.60", "0.131"], ["70735.50", "0.002"], ["71026.30", "0.008"], ["71216.80", "0.000"], ["71239.40", "0.074"], ["71452.40", "0.011"], ["71665.50", "0.013"], ["71878.60", "0.008"], ["74053.40", "0.000"], ["74056.40", "0.000"], ["89523.20", "0.012"]]}}
{"local_ts": 1773485462089, "server_ts": 1773485461292, "data": {"e": "depthUpdate", "E": 1773485461293, "T": 1773485461292, "s": "BTCUSDT", "U": 10109449264306, "u": 10109449279481, "pu": 10109449264142, "b": [["1000.00", "28.842"], ["5000.00", "101.418"], ["7049.50", "0.028"], ["19994.90", "0.650"], ["20111.60", "1.500"], ["66935.10", "0.126"], ["66985.70", "0.000"], ["67536.00", "2.002"], ["68239.50", "1.000"], ["68376.10", "0.000"], ["69790.00", "0.113"], ["70159.00", "0.364"], ["70196.60", "0.276"], ["70260.20", "0.004"], ["70318.50", "0.605"], ["70323.00", "0.523"], ["70328.30", "0.092"], ["70330.00", "0.455"], ["70346.10", "0.161"], ["70351.60", "0.185"], ["70355.70", "0.530"], ["70382.30", "0.003"], ["70389.30", "0.000"], ["70398.50", "0.530"], ["70401.80", "0.023"], ["70405.20", "0.350"], ["70405.40", "0.101"], ["70405.60", "0.922"], ["70407.60", "0.189"], ["70408.90", "0.000"], ["70409.20", "1.000"], ["70411.90", "0.099"], ["70412.60", "0.087"], ["70415.40", "0.345"], ["70415.80", "0.002"], ["70415.90", "0.079"], ["70416.80", "0.283"], ["70420.70", "0.002"], ["70424.40", "0.045"], ["70426.60", "0.296"], ["70428.60", "0.114"], ["70433.60", "0.406"], ["70435.70", "0.093"], ["70440.70", "0.074"], ["70442.00", "0.277"], ["70443.20", "0.000"], ["70445.50", "0.218"], ["70446.40", "0.016"], ["70447.50", "0.001"], ["70450.30", "0.315"], ["70453.10", "1.067"], ["70453.60", "1.234"], ["70454.30", "0.010"], ["70454.80", "0.963"], ["70455.50", "0.007"], ["70465.30", "2.047"], ["70465.80", "0.031"], ["70466.20", "0.003"], ["70467.50", "0.006"], ["70468.50", "0.072"], ["70469.30", "0.000"], ["70470.20", "0.002"], ["70471.20", "0.385"], ["70472.80", "0.730"], ["70473.00", "0.000"], ["70473.30", "0.000"], ["70473.60", "0.143"], ["70474.00", "0.008"], ["70474.60", "0.573"], ["70474.90", "0.346"], ["70476.60", "0.000"], ["70477.30", "0.106"], ["70478.20", "0.316"], ["70479.50", "0.020"], ["70479.90", "0.509"], ["70480.80", "0.153"], ["70480.90", "0.307"], ["70481.10", "0.000"], ["70481.40", "0.139"], ["70481.60", "0.207"], ["70482.50", "0.009"], ["70482.90", "0.016"], ["70483.90", "0.007"], ["70484.30", "0.006"], ["70484.60", "0.016"], ["70484.70", "0.005"], ["70484.90", "0.204"], ["70485.00", "0.149"], ["70485.10", "0.003"], ["70485.20", "0.000"], ["70485.30", "0.007"], ["70485.40", "0.057"], ["70485.50", "0.005"], ["70485.60", "0.004"], ["70485.70", "0.007"], ["70485.80", "0.007"], ["70485.90", "0.000"], ["70486.00", "0.005"], ["70486.20", "0.005"], ["70486.30", "0.003"], ["70486.40", "0.000"], ["70486.50", "0.109"], ["70486.60", "0.011"], ["70486.70", "0.048"], ["70486.80", "0.050"], ["70486.90", "0.312"], ["70487.00", "0.001"], ["70487.10", "0.002"], ["70487.30", "0.010"], ["70487.40", "0.038"], ["70487.50", "0.041"], ["70487.70", "0.003"], ["70487.90", "0.093"], ["70488.00", "0.010"], ["70488.10", "0.044"], ["70488.20", "0.001"], ["70488.50", "0.039"], ["70488.60", "0.002"], ["70488.70", "0.003"], ["70489.40", "0.006"], ["70489.50", "0.004"], ["70490.90", "0.006"], ["70491.20", "0.021"], ["70492.30", "0.004"], ["70492.80", "0.003"], ["70493.00", "0.000"], ["70493.70", "0.004"], ["70494.40", "0.000"], ["70494.90", "0.374"]], "a": [["70495.00", "14.880"], ["70495.90", "0.112"], ["70496.50", "0.021"], ["70497.00", "0.031"], ["70497.10", "0.000"], ["70498.00", "0.018"], ["70498.50", "0.029"], ["70499.90", "0.022"], ["70500.50", "0.011"], ["70501.30", "0.004"], ["70502.00", "0.038"], ["70502.10", "0.005"], ["70502.40", "0.000"], ["70503.30", "0.006"], ["70503.60", "0.144"], ["70503.70", "0.037"], ["70503.80", "0.003"], ["70504.10", "0.061"], ["70504.40", "0.005"], ["70505.10", "0.006"], ["70505.60", "0.002"], ["70505.80", "0.004"], ["70507.80", "0.042"], ["70508.50", "0.063"], ["70508.60", "0.076"], ["70509.00", "0.157"], ["70509.10", "0.054"], ["70511.10", "0.022"], ["70511.70", "0.191"], ["70515.70", "0.075"], ["70516.00", "0.007"], ["70517.40", "0.107"], ["70517.90", "0.581"], ["70518.00", "0.012"], ["70518.30", "0.009"], ["70518.80", "0.003"], ["70519.60", "0.005"], ["70521.80", "0.029"], ["70522.10", "0.045"], ["70522.20", "0.002"], ["70522.50", "0.574"], ["70522.60", "0.004"], ["70522.90", "0.002"], ["70523.00", "0.042"], ["70523.60", "0.004"], ["70523.80", "0.005"], ["70524.10", "0.019"], ["70525.90", "0.517"], ["70528.00", "0.021"], ["70530.00", "0.099"], ["70531.70", "0.004"], ["70533.00", "0.007"], ["70533.10", "1.931"], ["70534.50", "0.084"], ["70535.90", "0.003"], ["70537.00", "0.404"], ["70537.30", "0.544"], ["70538.70", "0.031"], ["70540.10", "0.538"], ["70541.50", "0.002"], ["70542.90", "0.000"], ["70543.70", "0.342"], ["70544.00", "0.285"], ["70544.40", "0.266"], ["70545.80", "0.592"], ["70547.20", "0.262"], ["70554.30", "0.002"], ["70557.10", "0.069"], ["70558.40", "0.071"], ["70561.40", "0.248"], ["70563.80", "0.002"], ["70564.60", "0.331"], ["70566.40", "0.730"], ["70574.90", "0.688"], ["70577.00", "0.020"], ["70578.00", "0.045"], ["70578.90", "1.058"], ["70580.30", "0.511"], ["70581.40", "0.776"], ["70581.90", "0.071"], ["70587.70", "1.412"], ["70589.00", "0.086"], ["70899.00", "0.211"], ["71026.40", "0.008"], ["71199.90", "0.140"], ["71445.10", "1.397"], ["71514.00", "19.065"], ["71587.10", "0.002"], ["75017.20", "0.006"], ["89523.20", "0.012"]]}}
{"local_ts": 1773485463103, "server_ts": 1773485462312, "data": {"e": "depthUpdate", "E": 1773485462313, "T": 1773485462312, "s": "BTCUSDT", "U": 10109449401882, "u": 10109449429138, "pu": 10109449401615, "b": [["1000.00", "28.842"], ["5000.00", "101.418"], ["7049.50", "0.028"], ["19994.90", "2.040"], ["19995.80", "0.000"], ["19995.90", "0.000"], ["19996.60", "0.000"], ["19996.90", "0.000"], ["20394.90", "0.960"], ["33000.00", "3.785"], ["66938.50", "0.000"], ["69571.90", "57.126"], ["69781.30", "48.537"], ["69790.00", "0.113"], ["69942.10", "39.134"], ["70325.60", "0.107"], ["70330.60", "0.092"], ["70335.00", "0.005"], ["70335.50", "0.092"], ["70336.90", "0.092"], ["70339.80", "0.002"], ["70349.20", "0.041"], ["70352.90", "0.041"], ["70403.70", "0.000"], ["70406.80", "0.000"], ["70409.60", "1.077"], ["70414.90", "0.075"], ["70415.50", "0.060"], ["70419.20", "0.626"], ["70419.60", "0.063"], ["70420.30", "0.645"], ["70420.60", "0.041"], ["70423.60", "1.940"], ["70437.90", "0.000"], ["70438.80", "0.000"], ["70439.00", "0.430"], ["70439.10", "0.000"], ["70439.90", "0.080"], ["70440.30", "0.050"], ["70440.40", "0.015"], ["70440.60", "0.400"], ["70447.70", "8.517"], ["70448.30", "0.018"], ["70449.30", "0.013"], ["70452.00", "0.004"], ["70456.60", "0.036"], ["70458.30", "0.144"], ["70459.90", "0.209"], ["70466.90", "0.347"], ["70467.50", "0.006"], ["70468.90", "0.865"], ["70469.00", "0.010"], ["70469.60", "0.266"], ["70469.70", "0.039"], ["70470.20", "0.288"], ["70471.20", "0.317"], ["70471.50", "0.000"], ["70472.90", "0.314"], ["70474.70", "0.248"], ["70475.50", "0.012"], ["70477.10", "0.510"], ["70478.50", "0.007"], ["70479.40", "0.756"], ["70479.90", "0.015"], ["70481.20", "0.003"], ["70483.80", "0.006"], ["70484.30", "0.600"], ["70484.40", "0.096"], ["70484.90", "0.310"], ["70485.20", "0.100"], ["70486.70", "0.049"], ["70487.30", "0.521"], ["70487.90", "0.032"], ["70490.00", "0.522"], ["70490.20", "0.517"], ["70491.30", "0.208"], ["70494.90", "5.847"]], "a": [["70495.00", "0.584"], ["70495.10", "0.000"], ["70495.20", "0.000"], ["70495.70", "0.002"], ["70498.50", "0.003"], ["70501.30", "0.005"], ["70504.00", "0.090"], ["70504.70", "0.002"], ["70505.10", "0.006"], ["70510.80", "0.000"], ["70511.90", "0.186"], ["70512.60", "0.150"], ["70514.30", "0.484"], ["70515.20", "0.463"], ["70516.10", "0.187"], ["70516.80", "0.463"], ["70517.20", "0.025"], ["70517.30", "0.272"], ["70517.40", "0.342"], ["70518.30", "0.006"], ["70518.40", "0.557"], ["70519.20", "0.026"], ["70519.70", "0.000"], ["70520.60", "0.007"], ["70520.80", "1.060"], ["70521.30", "0.023"], ["70521.90", "0.392"], ["70522.90", "0.086"], ["70523.10", "0.000"], ["70523.30", "0.637"], ["70523.80", "0.003"], ["70524.00", "0.077"], ["70524.40", "0.057"], ["70524.50", "0.005"], ["70524.70", "1.154"], ["70525.00", "0.084"], ["70526.40", "0.002"], ["70526.50", "0.004"], ["70527.10", "0.072"], ["70527.20", "0.269"], ["70527.60", "0.006"], ["70528.00", "0.009"], ["70528.20", "0.000"], ["70528.70", "1.425"], ["70528.80", "1.925"], ["70528.90", "0.012"], ["70529.00", "0.201"], ["70529.10", "0.063"], ["70529.20", "0.020"], ["70529.30", "0.030"], ["70529.40", "0.295"], ["70529.50", "0.904"], ["70529.60", "0.001"], ["70529.70", "0.002"], ["70529.80", "0.065"], ["70530.10", "0.060"], ["70530.40", "0.091"], ["70530.50", "1.939"], ["70530.60", "0.002"], ["70530.70", "0.004"], ["70530.90", "0.005"], ["70531.20", "0.127"], ["70532.20", "0.019"], ["70532.70", "0.572"], ["70536.30", "1.089"], ["70536.90", "0.007"], ["70539.30", "0.084"], ["70541.00", "0.000"], ["70542.20", "0.015"], ["70544.30", "0.259"], ["70545.50", "0.080"], ["70545.70", "0.008"], ["70545.80", "0.512"], ["70546.40", "0.002"], ["70547.90", "0.161"], ["70549.20", "0.007"], ["70550.10", "0.309"], ["70550.50", "0.055"], ["70551.20", "0.411"], ["70551.50", "0.522"], ["70551.80", "0.040"], ["70554.00", "0.040"], ["70554.30", "0.038"], ["70559.00", "0.029"], ["70572.00", "0.047"], ["70572.90", "1.141"], ["70590.00", "0.077"], ["70622.90", "10.511"], ["70627.50", "0.001"], ["70633.20", "0.000"], ["70643.40", "0.122"], ["70648.60", "0.209"], ["70648.90", "0.092"], ["70649.90", "0.678"], ["70651.80", "0.092"], ["70652.50", "0.000"], ["70653.90", "0.000"], ["70655.80", "0.227"], ["70666.70", "0.002"], ["70669.50", "10.002"], ["70700.50", "0.002"], ["70700.60", "15.471"], ["70718.70", "0.000"], ["70731.60", "0.588"], ["70797.60", "0.005"], ["70817.40", "0.000"], ["70831.50", "0.007"], ["70910.80", "0.000"], ["71199.90", "0.140"], ["71639.90", "0.696"], ["74028.60", "0.002"], ["75369.40", "0.002"], ["89523.20", "0.000"]]}}
{"local_ts": 1773485464123, "server_ts": 1773485463328, "data": {"e": "depthUpdate", "E": 1773485463333, "T": 1773485463328, "s": "BTCUSDT", "U": 10109449495892, "u": 10109449501433, "pu": 10109449495873, "b": [["5000.00", "101.418"], ["7049.50", "0.028"], ["19994.90", "0.000"], ["20294.90", "0.510"], ["20394.90", "2.490"], ["66965.70", "0.000"], ["66970.00", "0.002"], ["69209.20", "0.722"], ["69293.40", "4.072"], ["69790.00", "0.113"], ["70142.40", "0.427"], ["70192.70", "0.171"], ["70318.70", "0.000"], ["70331.20", "10.092"], ["70398.60", "0.000"], ["70403.10", "0.110"], ["70403.50", "0.014"], ["70405.70", "0.025"], ["70410.20", "0.071"], ["70412.70", "0.000"], ["70415.40", "0.345"], ["70417.20", "0.073"], ["70433.80", "0.364"], ["70439.90", "0.103"], ["70446.90", "0.024"], ["70448.40", "0.340"], ["70448.70", "0.310"], ["70450.40", "0.048"], ["70456.60", "0.016"], ["70457.00", "0.004"], ["70457.60", "0.003"], ["70459.70", "0.034"], ["70459.80", "0.190"], ["70463.00", "0.100"], ["70464.90", "0.031"], ["70465.50", "0.014"], ["70466.10", "0.544"], ["70468.90", "0.742"], ["70469.00", "0.008"], ["70469.60", "0.303"], ["70469.70", "0.006"], ["70470.80", "0.000"], ["70473.20", "0.319"], ["70474.10", "0.000"], ["70476.50", "0.003"], ["70478.30", "0.032"], ["70479.40", "0.464"], ["70479.50", "1.213"], ["70479.60", "0.370"], ["70481.80", "0.022"], ["70482.50", "1.237"], ["70483.70", "0.169"], ["70484.30", "0.283"], ["70486.20", "0.007"], ["70487.20", "0.653"], ["70488.00", "0.402"], ["70492.80", "0.004"], ["70493.20", "0.000"], ["70494.70", "0.026"], ["70494.90", "6.219"]], "a": [["70498.80", "0.002"], ["70499.50", "0.007"], ["70509.10", "0.050"], ["70510.10", "0.001"], ["70512.10", "0.007"], ["70516.10", "0.187"], ["70517.60", "0.203"], ["70520.80", "1.060"], ["70526.40", "0.070"], ["70526.50", "0.002"], ["70527.10", "0.004"], ["70527.20", "0.271"], ["70528.30", "0.735"], ["70530.20", "0.190"], ["70530.60", "0.054"], ["70534.10", "0.059"], ["70551.60", "0.449"], ["70553.10", "0.003"], ["70567.10", "0.005"], ["70575.00", "0.214"], ["70581.80", "0.073"], ["70582.00", "0.061"], ["70588.80", "0.088"], ["70589.10", "0.002"], ["70595.90", "0.071"], ["70600.00", "37.976"], ["70649.40", "0.003"], ["70651.20", "0.092"], ["70651.90", "0.000"], ["70653.70", "0.092"], ["70719.00", "0.107"], ["70730.60", "0.164"], ["71199.90", "0.140"], ["71446.70", "0.283"], ["74800.00", "46.735"], ["77800.00", "20.860"], ["80800.00", "1.878"], ["89523.20", "0.000"]]}}
{"local_ts": 1773485465146, "server_ts": 1773485464350, "data": {"e": "depthUpdate", "E": 1773485464353, "T": 1773485464350, "s": "BTCUSDT", "U": 10109449572695, "u": 10109449582033, "pu": 10109449572658, "b": [["1000.00", "28.842"], ["5000.00", "101.438"], ["7049.50", "0.000"], ["20194.90", "0.260"], ["20294.90", "2.540"], ["20394.90", "0.200"], ["33000.00", "3.789"], ["69790.00", "0.113"], ["70315.10", "0.004"], ["70322.20", "3.768"], ["70332.80", "0.092"], ["70336.30", "3.517"], ["70343.30", "13.099"], ["70403.00", "0.018"], ["70403.10", "0.092"], ["70404.20", "6.820"], ["70410.10", "0.071"], ["70410.20", "0.000"], ["70417.10", "0.229"], ["70417.20", "0.002"], ["70441.00", "3.636"], ["70448.80", "1.223"], ["70448.90", "0.270"], ["70463.70", "1.859"], ["70476.60", "0.004"], ["70477.10", "0.000"], ["70478.70", "0.072"], ["70479.40", "1.215"], ["70486.00", "0.008"], ["70486.60", "0.025"], ["70487.00", "0.008"], ["70491.30", "0.202"], ["70494.90", "6.012"]], "a": [["70500.00", "0.006"], ["70500.70", "0.000"], ["70502.30", "0.011"], ["70502.60", "0.083"], ["70503.30", "0.025"], ["70513.00", "0.018"], ["70515.80", "0.010"], ["70517.30", "0.003"], ["70517.60", "0.200"], ["70521.80", "0.004"], ["70522.50", "1.154"], ["70522.70", "0.003"], ["70523.90", "0.512"], ["70528.20", "0.248"], ["70529.40", "0.099"], ["70534.90", "1.842"], ["70543.80", "0.574"], ["70548.40", "0.067"], ["70557.60", "5.282"], ["70580.20", "0.073"], ["70581.80", "0.002"], ["70587.20", "0.312"], ["70588.80", "0.017"], ["70593.70", "2.356"], ["70594.30", "0.071"], ["70594.50", "6.663"], ["70595.90", "0.000"], ["70655.30", "2.908"], ["70655.40", "12.578"], ["70655.60", "0.000"], ["70718.90", "0.000"], ["70772.30", "0.007"], ["71199.90", "0.140"], ["72202.90", "0.596"], ["74025.60", "0.002"], ["89523.20", "0.000"]]}}
{"local_ts": 1773485466167, "server_ts": 1773485465374, "data": {"e": "depthUpdate", "E": 1773485465375, "T": 1773485465374, "s": "BTCUSDT", "U": 10109449651610, "u": 10109449661200, "pu": 10109449651563, "b": [["5000.00", "101.418"], ["7049.50", "0.000"], ["20094.90", "0.090"], ["20102.40", "0.020"], ["20194.90", "2.350"], ["20202.40", "0.050"], ["20294.90", "0.490"], ["40000.00", "41.317"], ["69092.40", "0.003"], ["69790.00", "0.113"], ["69797.40", "0.010"], ["70122.30", "0.142"], ["70136.10", "0.005"], ["70142.50", "2.139"], ["70146.50", "0.000"], ["70176.90", "0.000"], ["70207.90", "0.266"], ["70221.50", "0.062"], ["70221.90", "0.000"], ["70248.50", "3.520"], ["70286.00", "0.238"], ["70322.60", "0.152"], ["70323.00", "4.352"], ["70324.00", "0.066"], ["70324.70", "0.362"], ["70325.50", "0.362"], ["70343.30", "13.060"], ["70343.80", "0.039"], ["70345.10", "0.039"], ["70346.60", "0.039"], ["70347.30", "0.042"], ["70361.80", "0.008"], ["70369.40", "0.010"], ["70371.50", "0.159"], ["70372.70", "0.002"], ["70373.20", "1.101"], ["70373.60", "0.083"], ["70388.00", "1.368"], ["70389.30", "0.002"], ["70396.50", "0.005"], ["70400.80", "0.564"], ["70402.70", "6.986"], ["70402.80", "0.018"], ["70403.00", "0.000"], ["70403.50", "0.000"], ["70404.80", "0.000"], ["70408.40", "0.267"], ["70408.80", "0.001"], ["70409.80", "0.236"], ["70410.00", "0.172"], ["70410.10", "0.000"], ["70411.00", "1.226"], ["70415.30", "0.000"], ["70415.80", "0.000"], ["70416.90", "0.584"], ["70417.10", "0.158"], ["70417.30", "0.014"], ["70420.70", "0.000"], ["70426.60", "0.289"], ["70428.30", "0.043"], ["70428.80", "0.138"], ["70430.30", "0.000"], ["70431.40", "0.000"], ["70431.50", "0.063"], ["70431.90", "0.228"], ["70433.70", "0.002"], ["70434.00", "0.008"], ["70436.50", "0.002"], ["70442.90", "0.080"], ["70443.10", "0.033"], ["70443.70", "0.034"], ["70444.00", "0.060"], ["70446.20", "0.002"], ["70448.60", "0.001"], ["70448.90", "0.268"], ["70449.30", "0.008"], ["70450.00", "0.068"], ["70450.30", "8.841"], ["70450.40", "0.045"], ["70450.80", "0.003"], ["70451.00", "0.003"], ["70451.20", "0.000"], ["70452.60", "0.006"], ["70452.70", "0.097"], ["70453.60", "1.206"], ["70456.40", "0.002"], ["70456.80", "0.004"], ["70457.90", "0.412"], ["70458.10", "0.006"], ["70458.50", "0.002"], ["70458.70", "0.150"], ["70458.90", "0.003"], ["70459.00", "0.000"], ["70459.80", "0.134"], ["70460.00", "0.102"], ["70461.10", "0.293"], ["70461.20", "0.002"], ["70462.30", "0.002"], ["70462.80", "0.272"], ["70463.20", "0.840"], ["70463.40", "0.003"], ["70463.70", "1.862"], ["70464.10", "0.002"], ["70464.90", "0.013"], ["70465.00", "0.991"], ["70465.10", "0.047"], ["70466.20", "0.031"], ["70466.30", "0.011"], ["70466.50", "0.686"], ["70466.60", "0.001"], ["70467.30", "0.056"], ["70467.60", "0.758"], ["70467.70", "0.087"], ["70468.00", "0.094"], ["70468.40", "0.006"], ["70469.60", "0.266"], ["70469.70", "0.004"], ["70470.20", "0.240"], ["70470.30", "0.092"], ["70470.40", "0.914"], ["70470.70", "0.696"], ["70471.10", "0.040"], ["70471.80", "1.496"], ["70472.10", "0.132"], ["70472.30", "0.472"], ["70472.40", "1.006"], ["70472.50", "0.286"], ["70472.70", "0.002"], ["70472.80", "0.015"], ["70472.90", "0.210"], ["70473.30", "0.000"], ["70473.40", "0.003"], ["70473.50", "0.002"], ["70473.70", "0.003"], ["70473.80", "0.176"], ["70474.10", "0.026"], ["70474.20", "0.174"], ["70475.00", "0.792"], ["70475.30", "0.008"], ["70475.50", "0.198"], ["70475.60", "0.001"], ["70475.80", "0.087"], ["70476.00", "0.031"], ["70476.10", "0.001"], ["70476.40", "0.000"], ["70476.90", "0.030"], ["70477.10", "0.052"], ["70477.20", "0.006"], ["70477.30", "0.002"], ["70478.00", "0.548"], ["70478.10", "0.005"], ["70478.20", "0.130"], ["70478.30", "0.004"], ["70478.70", "0.002"], ["70478.80", "0.001"], ["70478.90", "0.248"], ["70479.60", "0.370"], ["70479.80", "0.000"], ["70479.90", "0.015"], ["70480.10", "0.190"], ["70480.20", "0.513"], ["70480.50", "0.008"], ["70480.80", "0.017"], ["70480.90", "0.008"], ["70481.00", "0.010"], ["70481.10", "0.000"], ["70481.20", "0.057"], ["70481.30", "0.288"], ["70481.40", "0.752"], ["70481.70", "0.004"], ["70481.90", "0.073"], ["70482.40", "0.000"], ["70482.50", "1.063"], ["70482.70", "0.144"], ["70482.90", "0.001"], ["70483.10", "0.004"], ["70483.50", "0.035"], ["70483.60", "0.004"], ["70483.70", "0.007"], ["70483.80", "0.003"], ["70483.90", "0.515"], ["70484.00", "0.273"], ["70484.30", "0.003"], ["70484.40", "0.002"], ["70484.50", "0.060"], ["70484.60", "0.065"], ["70484.70", "0.005"], ["70484.80", "0.023"], ["70484.90", "0.331"], ["70485.30", "0.007"], ["70485.40", "0.000"], ["70486.00", "0.006"], ["70486.20", "1.210"], ["70486.30", "0.010"], ["70486.70", "0.047"], ["70486.80", "0.010"], ["70486.90", "0.041"], ["70487.00", "0.001"], ["70487.10", "0.002"], ["70487.30", "0.528"], ["70487.40", "0.004"], ["70487.50", "0.000"], ["70487.60", "0.264"], ["70487.80", "0.002"], ["70487.90", "0.398"], ["70488.00", "0.010"], ["70488.20", "0.061"], ["70488.30", "0.000"], ["70488.60", "0.103"], ["70488.70", "0.003"], ["70488.80", "0.003"], ["70489.00", "0.000"], ["70489.10", "0.008"], ["70489.50", "0.007"], ["70489.90", "0.143"], ["70490.00", "0.602"], ["70490.30", "0.374"], ["70490.40", "0.006"], ["70490.50", "0.213"], ["70490.60", "0.000"], ["70490.80", "0.018"], ["70490.90", "0.023"], ["70491.10", "0.001"], ["70491.20", "0.270"], ["70491.30", "0.211"], ["70491.40", "0.099"], ["70491.50", "0.020"], ["70491.60", "0.085"], ["70491.80", "0.003"], ["70491.90", "0.000"], ["70492.00", "0.008"], ["70492.20", "0.662"], ["70492.30", "0.007"], ["70492.40", "0.009"], ["70492.50", "0.017"], ["70492.60", "0.283"], ["70492.70", "0.006"], ["70492.80", "0.019"], ["70492.90", "0.440"], ["70493.00", "0.011"], ["70493.30", "0.023"], ["70493.40", "0.009"], ["70493.50", "0.007"], ["70493.60", "0.012"], ["70493.70", "0.020"], ["70493.90", "0.049"], ["70494.00", "0.007"], ["70494.10", "0.027"], ["70494.20", "0.003"], ["70494.30", "0.003"], ["70494.40", "0.006"], ["70494.50", "0.009"], ["70494.60", "0.002"], ["70494.70", "0.017"], ["70494.80", "0.119"], ["70494.90", "0.296"], ["70495.00", "1.247"], ["70495.10", "0.002"], ["70495.20", "0.256"], ["70495.30", "0.002"], ["70495.40", "0.884"], ["70495.50", "0.387"], ["70495.70", "0.000"], ["70495.90", "0.000"], ["70496.00", "0.473"], ["70496.20", "0.000"], ["70496.30", "0.000"], ["70496.40", "0.002"], ["70496.50", "0.002"], ["70496.70", "0.002"], ["70496.80", "0.026"], ["70496.90", "0.574"], ["70497.00", "0.006"], ["70497.30", "0.000"], ["70497.40", "0.202"], ["70497.50", "0.002"], ["70497.70", "0.000"], ["70497.80", "0.000"], ["70497.90", "0.000"], ["70498.00", "0.000"], ["70498.10", "0.219"], ["70498.20", "0.003"], ["70498.40", "0.000"], ["70498.50", "0.000"], ["70498.60", "0.016"], ["70498.70", "0.014"], ["70498.80", "0.016"], ["70498.90", "0.014"], ["70499.00", "0.016"], ["70499.10", "0.014"], ["70499.20", "0.014"], ["70499.30", "0.017"], ["70499.40", "0.014"], ["70499.50", "0.014"], ["70499.60", "0.000"], ["70499.80", "0.021"], ["70499.90", "0.014"], ["70500.00", "0.272"], ["70500.10", "0.000"], ["70500.20", "0.002"], ["70500.30", "0.000"], ["70500.40", "0.000"], ["70500.50", "0.006"], ["70500.70", "0.212"], ["70500.80", "0.000"], ["70500.90", "0.002"], ["70501.10", "0.000"], ["70501.20", "0.000"], ["70501.30", "0.000"], ["70501.70", "0.002"], ["70501.80", "0.021"], ["70501.90", "0.000"], ["70502.00", "0.000"], ["70502.20", "0.000"], ["70502.30", "0.367"], ["70502.40", "6.929"]], "a": [["70495.00", "0.000"], ["70495.50", "0.000"], ["70495.60", "0.000"], ["70495.80", "0.000"], ["70496.00", "0.000"], ["70496.10", "0.000"], ["70496.30", "0.000"], ["70496.50", "0.000"], ["70496.80", "0.000"], ["70496.90", "0.000"], ["70497.00", "0.000"], ["70497.10", "0.000"], ["70497.40", "0.000"], ["70497.50", "0.000"], ["70497.90", "0.000"], ["70498.00", "0.000"], ["70498.10", "0.000"], ["70498.20", "0.000"], ["70498.50", "0.000"], ["70498.60", "0.000"], ["70498.70", "0.000"], ["70498.80", "0.000"], ["70498.90", "0.000"], ["70499.00", "0.000"], ["70499.10", "0.000"], ["70499.20", "0.000"], ["70499.30", "0.000"], ["70499.40", "0.000"], ["70499.50", "0.000"], ["70499.60", "0.000"], ["70499.70", "0.000"], ["70499.90", "0.000"], ["70500.00", "0.000"], ["70500.20", "0.000"], ["70500.30", "0.000"], ["70500.40", "0.000"], ["70500.50", "0.000"], ["70500.60", "0.000"], ["70500.80", "0.000"], ["70500.90", "0.000"], ["70501.00", "0.000"], ["70501.20", "0.000"], ["70501.30", "0.000"], ["70501.40", "0.000"], ["70501.60", "0.000"], ["70501.90", "0.000"], ["70502.00", "0.000"], ["70502.10", "0.000"], ["70502.30", "0.000"], ["70502.40", "0.000"], ["70502.50", "2.701"], ["70502.60", "0.002"], ["70502.80", "0.002"], ["70502.90", "0.003"], ["70503.00", "0.004"], ["70503.10", "0.000"], ["70503.30", "0.001"], ["70503.60", "0.009"], ["70503.70", "0.037"], ["70504.00", "0.034"], ["70504.10", "0.000"], ["70504.30", "0.023"], ["70504.60", "0.003"], ["70504.70", "0.002"], ["70504.80", "0.001"], ["70505.20", "0.000"], ["70505.40", "0.003"], ["70505.60", "0.002"], ["70506.00", "0.002"], ["70506.30", "0.005"], ["70506.40", "0.000"], ["70506.90", "0.023"], ["70507.10", "0.023"], ["70507.20", "0.010"], ["70507.30", "0.014"], ["70507.50", "0.006"], ["70508.30", "0.001"], ["70508.40", "0.198"], ["70508.90", "0.000"], ["70509.00", "0.013"], ["70509.30", "0.003"], ["70509.90", "0.037"], ["70510.10", "0.001"], ["70510.20", "0.008"], ["70510.30", "0.000"], ["70510.40", "0.006"], ["70510.50", "0.000"], ["70510.70", "0.000"], ["70510.80", "0.002"], ["70510.90", "0.004"], ["70511.00", "0.010"], ["70511.30", "0.002"], ["70511.60", "0.002"], ["70511.70", "0.109"], ["70511.90", "0.183"], ["70512.00", "0.033"], ["70512.10", "0.005"], ["70512.40", "0.008"], ["70512.50", "0.013"], ["70512.60", "0.041"], ["70512.80", "0.005"], ["70513.10", "0.008"], ["70513.20", "0.004"], ["70513.30", "0.202"], ["70514.40", "0.013"], ["70514.60", "0.020"], ["70514.90", "0.003"], ["70515.20", "0.002"], ["70515.50", "0.005"], ["70515.60", "0.003"], ["70516.00", "0.007"], ["70516.10", "0.005"], ["70516.20", "0.000"], ["70516.40", "0.013"], ["70517.60", "0.004"], ["70517.70", "0.000"], ["70517.80", "0.004"], ["70517.90", "0.223"], ["70518.20", "0.063"], ["70518.40", "1.187"], ["70518.50", "0.002"], ["70518.60", "0.047"], ["70518.70", "0.077"], ["70518.90", "0.350"], ["70519.00", "0.074"], ["70519.10", "0.014"], ["70519.20", "0.034"], ["70519.40", "0.009"], ["70519.50", "0.021"], ["70519.60", "0.004"], ["70519.70", "0.002"], ["70519.90", "0.217"], ["70520.00", "0.065"], ["70520.10", "0.002"], ["70520.20", "0.000"], ["70520.70", "0.358"], ["70520.90", "0.381"], ["70521.00", "0.004"], ["70521.50", "0.035"], ["70521.60", "0.022"], ["70521.80", "0.515"], ["70521.90", "1.729"], ["70522.20", "0.002"], ["70522.50", "0.006"], ["70522.60", "0.011"], ["70522.90", "0.006"], ["70523.00", "0.040"], ["70523.50", "0.003"], ["70523.60", "0.037"], ["70523.70", "0.039"], ["70523.80", "0.005"], ["70524.00", "0.029"], ["70524.20", "0.514"], ["70524.30", "0.061"], ["70524.40", "0.000"], ["70524.70", "0.121"], ["70524.80", "0.009"], ["70524.90", "0.434"], ["70525.00", "0.084"], ["70525.40", "0.003"], ["70525.50", "0.059"], ["70525.70", "0.000"], ["70525.80", "0.058"], ["70525.90", "0.019"], ["70526.00", "0.191"], ["70526.40", "0.002"], ["70526.50", "0.004"], ["70527.10", "0.002"], ["70527.20", "0.269"], ["70527.30", "0.003"], ["70527.40", "0.000"], ["70527.80", "0.000"], ["70527.90", "0.047"], ["70528.10", "0.081"], ["70528.20", "1.577"], ["70528.30", "0.224"], ["70528.40", "0.095"], ["70528.50", "0.093"], ["70528.60", "1.351"], ["70528.80", "0.667"], ["70529.10", "0.120"], ["70529.20", "0.085"], ["70529.40", "0.047"], ["70529.80", "0.575"], ["70530.10", "0.130"], ["70530.40", "0.602"], ["70530.50", "0.349"], ["70531.50", "0.000"], ["70531.80", "0.005"], ["70532.00", "0.006"], ["70532.50", "0.124"], ["70532.60", "0.513"], ["70532.80", "0.004"], ["70532.90", "0.083"], ["70533.00", "0.263"], ["70533.50", "0.002"], ["70533.70", "0.308"], ["70533.80", "0.000"], ["70534.40", "0.136"], ["70536.10", "0.005"], ["70536.50", "0.000"], ["70537.20", "0.222"], ["70538.40", "0.004"], ["70538.90", "0.002"], ["70539.50", "0.005"], ["70539.70", "0.069"], ["70539.80", "0.148"], ["70540.30", "0.001"], ["70540.80", "0.010"], ["70541.00", "0.000"], ["70541.10", "0.003"], ["70542.10", "1.985"], ["70542.30", "0.004"], ["70543.00", "0.002"], ["70543.30", "0.137"], ["70543.90", "0.000"], ["70544.20", "0.112"], ["70544.30", "0.044"], ["70544.50", "0.003"], ["70544.70", "0.192"], ["70545.70", "0.714"], ["70546.10", "0.015"], ["70547.60", "0.191"], ["70547.80", "0.004"], ["70547.90", "0.101"], ["70548.20", "0.064"], ["70548.30", "0.277"], ["70549.70", "1.126"], ["70550.10", "0.314"], ["70550.40", "0.068"], ["70551.20", "0.439"], ["70551.50", "0.576"], ["70552.60", "0.007"], ["70555.30", "0.100"], ["70555.50", "0.194"], ["70557.20", "0.000"], ["70558.10", "0.127"], ["70558.50", "0.004"], ["70558.80", "0.034"], ["70561.80", "0.005"], ["70564.00", "0.223"], ["70564.50", "0.002"], ["70565.30", "0.058"], ["70565.40", "0.005"], ["70567.60", "8.782"], ["70572.60", "0.074"], ["70572.80", "0.003"], ["70579.50", "0.095"], ["70580.20", "0.002"], ["70582.00", "0.005"], ["70582.50", "0.000"], ["70586.60", "0.260"], ["70587.10", "0.211"], ["70587.20", "0.241"], ["70588.40", "1.461"], ["70589.20", "2.099"], ["70589.40", "0.003"], ["70589.70", "0.207"], ["70593.60", "0.114"], ["70593.70", "2.145"], ["70594.30", "0.000"], ["70594.90", "0.024"], ["70598.80", "0.000"], ["70605.30", "0.084"], ["70607.40", "0.080"], ["70609.50", "0.084"], ["70610.10", "0.174"], ["70622.10", "0.005"], ["70622.90", "0.511"], ["70626.80", "0.186"], ["70661.30", "0.714"], ["70662.40", "10.003"], ["70663.80", "0.094"], ["70665.50", "1.908"], ["70669.50", "0.002"], ["70675.20", "0.064"], ["70700.60", "5.471"], ["70702.60", "0.243"], ["70709.00", "10.000"], ["70718.70", "0.007"], ["70740.10", "10.051"], ["70799.70", "0.266"], ["70800.40", "0.529"], ["70885.50", "0.002"], ["71023.60", "0.002"], ["71199.90", "0.140"], ["71207.50", "0.004"], ["71517.20", "8.259"], ["71670.00", "0.002"], ["71956.30", "0.474"], ["73022.40", "0.003"], ["74033.20", "0.005"]]}}
{"local_ts": 1773485467188, "server_ts": 1773485466396, "data": {"e": "depthUpdate", "E": 1773485466397, "T": 1773485466396, "s": "BTCUSDT", "U": 10109449714403, "u": 10109449718676, "pu": 10109449714346, "b": [["1000.00", "28.842"], ["5000.00", "101.418"], ["7050.30", "0.000"], ["20102.40", "2.080"], ["20194.90", "0.830"], ["66944.90", "0.002"], ["66970.20", "40.002"], ["66970.30", "0.004"], ["66986.10", "0.002"], ["69472.70", "3.750"], ["69797.40", "0.010"], ["69902.70", "0.183"], ["70149.90", "0.000"], ["70196.60", "0.009"], ["70198.60", "0.000"], ["70200.10", "0.007"], ["70360.10", "0.184"], ["70369.30", "0.921"], ["70402.80", "0.000"], ["70408.90", "0.018"], ["70409.80", "0.165"], ["70415.90", "0.150"], ["70416.90", "0.513"], ["70423.00", "0.085"], ["70453.60", "1.203"], ["70453.70", "0.265"], ["70456.80", "0.000"], ["70464.60", "0.161"], ["70465.10", "0.004"], ["70471.50", "0.000"], ["70472.80", "0.100"], ["70472.90", "0.125"], ["70482.80", "0.072"], ["70486.80", "0.010"]], "a": [["70502.50", "3.132"], ["70503.30", "0.003"], ["70503.60", "0.001"], ["70508.10", "0.000"], ["70510.80", "0.059"], ["70516.40", "0.013"], ["70516.60", "0.158"], ["70517.80", "0.004"], ["70517.90", "0.181"], ["70518.00", "0.016"], ["70522.90", "0.006"], ["70524.30", "0.054"], ["70525.00", "0.095"], ["70527.20", "0.269"], ["70527.40", "0.021"], ["70549.70", "1.069"], ["70571.60", "0.004"], ["70579.50", "0.024"], ["70585.40", "0.080"], ["70586.60", "0.189"], ["70587.10", "0.388"], ["70592.50", "0.071"], ["70593.60", "0.043"], ["70599.50", "1.215"], ["70621.80", "0.198"], ["70633.80", "0.000"], ["70638.40", "0.532"], ["71109.00", "0.016"], ["71157.50", "0.004"], ["71207.50", "0.004"], ["71346.00", "7.556"], ["71348.50", "0.560"], ["71565.80", "0.842"], ["74044.40", "0.002"]]}}
{"local_ts": 1773485468207, "server_ts": 1773485467416, "data": {"e": "depthUpdate", "E": 1773485467417, "T": 1773485467416, "s": "BTCUSDT", "U": 10109449755005, "u": 10109449758320, "pu": 10109449754931, "b": [["1000.00", "28.842"], ["5000.00", "101.398"], ["7050.30", "0.056"], ["20002.40", "1.730"], ["20102.40", "1.180"], ["66953.10", "0.002"], ["66977.30", "0.004"], ["67675.10", "0.632"], ["69797.40", "0.010"], ["69797.50", "0.000"], ["70256.60", "0.004"], ["70353.70", "0.081"], ["70354.70", "0.081"], ["70358.90", "0.554"], ["70360.20", "0.238"], ["70364.90", "0.283"], ["70366.90", "0.000"], ["70369.30", "0.876"], ["70425.60", "0.143"], ["70426.10", "0.101"], ["70429.60", "0.338"], ["70429.90", "0.270"], ["70430.60", "0.062"], ["70431.00", "0.046"], ["70460.10", "0.018"], ["70472.50", "0.093"], ["70472.70", "0.265"], ["70472.80", "0.195"], ["70491.10", "0.005"], ["70491.80", "0.000"], ["70492.00", "0.010"], ["70495.00", "1.275"], ["70501.10", "0.049"], ["70502.30", "0.107"], ["70502.40", "6.608"]], "a": [["70508.20", "0.076"], ["70509.60", "0.018"], ["70511.70", "0.107"], ["70512.40", "0.008"], ["70513.10", "0.008"], ["70515.70", "0.003"], ["70516.60", "0.143"], ["70517.70", "0.269"], ["70518.20", "0.077"], ["70522.80", "0.239"], ["70529.70", "0.012"], ["70530.20", "0.078"], ["70557.70", "7.844"], ["70638.10", "0.628"], ["71207.50", "0.004"], ["76954.30", "0.002"]]}}
{"local_ts": 1773485469230, "server_ts": 1773485468437, "data": {"e": "depthUpdate", "E": 1773485468439, "T": 1773485468437, "s": "BTCUSDT", "U": 10109449879129, "u": 10109449886056, "pu": 10109449879116, "b": [["5000.00", "101.418"], ["7050.40", "0.056"], ["20002.40", "1.280"], ["20003.60", "0.380"], ["20403.60", "1.280"], ["66960.90", "0.002"], ["66978.00", "0.000"], ["69653.90", "5.014"], ["69798.60", "0.000"], ["69935.90", "0.143"], ["70151.00", "0.042"], ["70151.10", "0.000"], ["70426.00", "0.022"], ["70426.50", "0.742"], ["70440.10", "0.000"], ["70455.30", "0.582"], ["70455.40", "0.108"], ["70466.20", "0.051"], ["70470.10", "0.636"], ["70471.90", "0.391"], ["70472.70", "0.265"], ["70485.20", "0.019"], ["70487.40", "1.216"], ["70492.00", "0.286"], ["70492.80", "0.022"], ["70493.00", "0.011"], ["70496.10", "0.003"], ["70502.60", "0.246"], ["70503.60", "3.775"]], "a": [["70503.70", "3.952"], ["70514.30", "0.006"], ["70514.60", "0.057"], ["70515.10", "0.002"], ["70515.30", "0.033"], ["70520.70", "0.309"], ["70547.50", "0.086"], ["70567.20", "0.271"], ["70581.30", "0.000"], ["70588.80", "0.088"], ["70595.90", "0.071"], ["70602.90", "0.086"], ["70686.00", "0.504"], ["70686.20", "0.000"], ["70696.70", "36.400"], ["70845.90", "0.007"], ["70846.30", "0.000"], ["71208.70", "0.000"], ["71328.60", "0.560"], ["71631.80", "0.976"], ["74041.20", "0.000"], ["74225.50", "0.052"]]}}
{"local_ts": 1773485470249, "server_ts": 1773485469458, "data": {"e": "depthUpdate", "E": 1773485469459, "T": 1773485469458, "s": "BTCUSDT", "U": 10109449948420, "u": 10109449954611, "pu": 10109449948394, "b": [["1000.00", "28.842"], ["5000.00", "101.418"], ["7050.40", "0.056"], ["20303.60", "0.830"], ["20403.60", "2.170"], ["69199.30", "1.804"], ["69632.20", "0.716"], ["69798.60", "0.000"], ["69932.50", "0.079"], ["70151.00", "0.042"], ["70257.90", "0.004"], ["70464.80", "0.012"], ["70475.50", "0.167"], ["70484.20", "1.071"], ["70485.10", "0.584"], ["70485.90", "0.000"], ["70489.70", "0.036"], ["70493.00", "0.014"], ["70496.00", "0.471"], ["70496.70", "0.394"]], "a": [["70503.70", "4.682"], ["70510.80", "0.017"], ["70510.90", "0.004"], ["70511.20", "0.028"], ["70511.60", "0.015"], ["70514.30", "0.003"], ["70519.40", "0.513"], ["70519.50", "0.022"], ["70531.50", "0.057"], ["70532.70", "0.646"], ["70591.40", "0.002"], ["70594.80", "0.048"], ["70595.80", "0.085"], ["70596.80", "0.324"], ["70597.80", "0.128"], ["70598.20", "0.046"], ["70600.10", "0.086"], ["70600.60", "0.259"], ["70602.00", "0.085"], ["70602.70", "0.003"], ["70603.80", "0.141"], ["70605.60", "0.121"], ["70606.70", "1.487"], ["70608.90", "0.098"], ["70609.50", "0.165"], ["70612.00", "0.106"], ["70613.80", "0.161"], ["70616.40", "0.366"], ["70727.10", "0.009"], ["70785.80", "0.003"], ["71060.60", "0.512"], ["71140.10", "0.000"], ["71208.70", "0.002"], ["71342.60", "0.000"], ["71631.80", "1.952"], ["74051.50", "0.052"]]}}
{"local_ts": 1773485471270, "server_ts": 1773485470477, "data": {"e": "depthUpdate", "E": 1773485470479, "T": 1773485470477, "s": "BTCUSDT", "U": 10109449999351, "u": 10109450012649, "pu": 10109449999304, "b": [["5000.00", "101.398"], ["7050.40", "0.028"], ["20203.60", "0.410"], ["20303.60", "2.560"], ["20403.60", "0.030"], ["69092.40", "0.003"], ["69415.80", "0.010"], ["69433.70", "0.430"], ["69509.50", "0.358"], ["69798.60", "0.715"], ["69939.70", "0.007"], ["70257.40", "0.000"], ["70259.70", "26.567"], ["70318.50", "0.513"], ["70360.20", "0.161"], ["70363.70", "0.082"], ["70368.40", "0.004"], ["70412.20", "0.532"], ["70412.40", "0.052"], ["70419.20", "0.384"], ["70419.40", "0.101"], ["70426.30", "0.076"], ["70426.50", "0.671"], ["70442.50", "0.008"], ["70450.60", "0.004"], ["70450.70", "0.421"], ["70450.80", "0.003"], ["70450.90", "0.087"], ["70463.90", "0.007"], ["70466.20", "0.031"], ["70468.10", "0.010"], ["70470.60", "0.280"], ["70472.40", "1.033"], ["70473.60", "0.191"], ["70475.20", "0.213"], ["70475.30", "0.036"], ["70475.40", "0.521"], ["70475.50", "0.082"], ["70477.50", "0.002"], ["70478.90", "0.052"], ["70479.30", "0.018"], ["70482.40", "0.015"], ["70482.60", "0.002"], ["70483.10", "0.000"], ["70483.70", "0.007"], ["70484.80", "0.093"], ["70484.90", "0.213"], ["70485.40", "0.510"], ["70485.60", "0.074"], ["70487.40", "0.004"], ["70489.20", "0.008"], ["70489.30", "0.053"], ["70490.00", "0.666"], ["70490.10", "1.066"], ["70490.80", "0.004"], ["70491.10", "0.009"], ["70491.90", "0.004"], ["70492.10", "0.064"], ["70492.40", "0.002"], ["70492.50", "0.005"], ["70492.60", "0.638"], ["70492.90", "0.387"], ["70493.00", "0.011"], ["70494.20", "0.006"], ["70495.40", "0.103"], ["70496.30", "0.000"], ["70496.40", "1.599"], ["70496.50", "0.982"], ["70496.80", "0.116"], ["70498.30", "0.056"], ["70503.60", "4.767"]], "a": [["70503.70", "2.034"], ["70503.80", "0.003"], ["70510.60", "0.000"], ["70514.30", "0.018"], ["70515.60", "0.003"], ["70515.70", "0.142"], ["70515.90", "0.000"], ["70517.20", "0.003"], ["70517.30", "0.000"], ["70517.50", "0.005"], ["70517.60", "0.346"], ["70518.00", "0.283"], ["70518.10", "0.002"], ["70518.20", "0.003"], ["70518.30", "0.067"], ["70518.40", "0.111"], ["70519.40", "0.143"], ["70519.50", "0.512"], ["70519.70", "0.008"], ["70520.00", "0.067"], ["70520.20", "0.005"], ["70520.40", "0.035"], ["70520.60", "0.007"], ["70520.80", "1.063"], ["70520.90", "0.009"], ["70521.20", "0.000"], ["70521.70", "0.000"], ["70521.80", "0.606"], ["70521.90", "0.511"], ["70522.00", "0.739"], ["70522.10", "0.005"], ["70522.20", "0.009"], ["70522.80", "0.204"], ["70523.10", "0.000"], ["70523.40", "0.002"], ["70523.50", "0.006"], ["70523.70", "0.108"], ["70524.00", "1.095"], ["70524.10", "0.349"], ["70524.70", "0.121"], ["70524.80", "0.513"], ["70524.90", "0.789"], ["70525.90", "0.006"], ["70527.10", "0.002"], ["70527.50", "0.002"], ["70527.70", "0.006"], ["70527.80", "0.022"], ["70527.90", "0.005"], ["70528.50", "0.738"], ["70528.70", "0.988"], ["70528.80", "0.515"], ["70528.90", "0.012"], ["70529.60", "0.010"], ["70529.70", "0.017"], ["70531.00", "0.015"], ["70532.20", "0.019"], ["70532.60", "0.027"], ["70532.70", "0.574"], ["70533.50", "0.017"], ["70533.70", "0.310"], ["70534.10", "0.041"], ["70534.50", "0.086"], ["70534.70", "0.017"], ["70534.80", "0.007"], ["70534.90", "0.072"], ["70535.00", "0.026"], ["70535.10", "0.187"], ["70535.60", "0.052"], ["70536.00", "0.119"], ["70537.00", "0.422"], ["70539.50", "0.001"], ["70541.30", "0.278"], ["70543.60", "1.079"], ["70545.00", "0.009"], ["70549.20", "0.270"], ["70549.50", "0.629"], ["70551.00", "0.716"], ["70551.10", "0.130"], ["70554.60", "0.086"], ["70560.10", "0.057"], ["70566.20", "0.003"], ["70567.30", "8.634"], ["70588.50", "0.073"], ["70588.80", "0.017"], ["70595.60", "0.181"], ["70595.90", "0.000"], ["70602.60", "0.939"], ["70602.90", "0.015"], ["70727.00", "0.000"], ["70727.40", "0.230"], ["70825.00", "31.491"], ["70842.50", "0.000"], ["70843.50", "0.031"], ["70931.20", "37.992"], ["71208.60", "0.002"], ["71208.70", "0.701"], ["71346.00", "7.276"], ["74053.80", "0.000"]]}}
{"local_ts": 1773485472294, "server_ts": 1773485471496, "data": {"e": "depthUpdate", "E": 1773485471499, "T": 1773485471496, "s": "BTCUSDT", "U": 10109450173762, "u": 10109450185723, "pu": 10109450173238, "b": [["1000.00", "28.842"], ["5000.00", "101.438"], ["7050.40", "0.028"], ["20103.60", "0.220"], ["20203.60", "2.490"], ["20303.60", "0.290"], ["33000.00", "3.785"], ["56403.00", "0.000"], ["66970.30", "0.002"], ["69288.30", "0.005"], ["69333.30", "0.217"], ["69481.30", "6.036"], ["69798.60", "0.715"], ["70000.50", "0.009"], ["70151.00", "0.042"], ["70151.10", "0.000"], ["70323.80", "0.162"], ["70433.60", "0.413"], ["70451.80", "0.099"], ["70455.50", "0.004"], ["70455.90", "0.150"], ["70468.40", "0.018"], ["70470.50", "0.084"], ["70470.70", "0.367"], ["70471.90", "0.354"], ["70472.70", "0.364"], ["70473.60", "0.171"], ["70474.50", "0.093"], ["70477.10", "0.000"], ["70478.50", "0.022"], ["70479.80", "0.163"], ["70480.50", "0.057"], ["70481.00", "0.003"], ["70481.30", "0.221"], ["70481.90", "0.003"], ["70482.20", "0.349"], ["70482.30", "0.022"], ["70482.60", "0.002"], ["70483.50", "0.018"], ["70484.30", "0.010"], ["70484.90", "0.227"], ["70485.20", "0.004"], ["70486.00", "0.144"], ["70486.50", "0.067"], ["70486.60", "0.011"], ["70488.10", "0.215"], ["70493.00", "0.011"], ["70494.30", "0.038"], ["70495.90", "0.014"], ["70496.20", "0.346"], ["70496.30", "1.066"], ["70496.50", "0.143"], ["70496.60", "0.052"], ["70496.90", "0.645"], ["70497.00", "0.126"], ["70498.30", "0.000"], ["70499.10", "0.000"], ["70500.10", "0.039"], ["70500.50", "0.051"], ["70501.10", "0.024"], ["70502.60", "0.004"], ["70503.00", "0.000"], ["70503.10", "0.000"], ["70503.30", "0.009"], ["70503.40", "0.002"], ["70503.50", "0.002"]], "a": [["70503.70", "4.440"], ["70514.30", "0.084"], ["70517.80", "0.328"], ["70530.60", "0.002"], ["70530.70", "0.006"], ["70531.30", "0.002"], ["70531.40", "0.007"], ["70532.30", "0.030"], ["70532.40", "0.095"], ["70534.10", "0.039"], ["70563.70", "6.305"], ["70564.60", "0.048"], ["70565.80", "0.021"], ["70569.30", "0.004"], ["70571.30", "0.004"], ["70832.50", "0.007"], ["70833.90", "0.012"], ["71208.70", "0.701"], ["71443.50", "2.234"], ["71710.50", "0.011"], ["71913.70", "0.062"], ["74031.90", "0.003"]]}}
{"local_ts": 1773485473311, "server_ts": 1773485472518, "data": {"e": "depthUpdate", "E": 1773485472521, "T": 1773485472518, "s": "BTCUSDT", "U": 10109450252258, "u": 10109450259629, "pu": 10109450252088, "b": [["1000.00", "28.842"], ["5000.00", "101.438"], ["7050.40", "0.028"], ["20003.60", "0.070"], ["20103.60", "2.340"], ["20203.60", "0.590"], ["56403.00", "0.004"], ["66967.80", "0.000"], ["68952.50", "0.000"], ["69159.50", "0.000"], ["69798.60", "0.715"], ["69939.70", "0.003"], ["70257.60", "0.008"], ["70428.80", "0.157"], ["70431.80", "0.050"], ["70432.30", "0.196"], ["70433.40", "0.054"], ["70433.70", "0.040"], ["70456.20", "0.002"], ["70456.30", "0.004"], ["70468.40", "0.018"], ["70468.50", "0.085"], ["70477.00", "0.061"], ["70478.90", "0.000"], ["70479.50", "0.012"], ["70481.30", "0.206"], ["70488.00", "0.648"], ["70488.80", "0.003"], ["70489.60", "0.023"], ["70490.50", "0.219"], ["70491.20", "0.259"], ["70492.70", "0.002"], ["70495.60", "0.383"], ["70500.80", "0.015"], ["70501.20", "0.022"], ["70502.20", "0.002"], ["70502.30", "0.004"], ["70502.50", "0.015"], ["70502.70", "0.008"], ["70503.60", "3.756"]], "a": [["70503.70", "3.675"], ["70503.90", "0.002"], ["70504.10", "0.000"], ["70504.20", "0.004"], ["70504.30", "0.000"], ["70505.60", "0.004"], ["70505.90", "0.000"], ["70506.10", "0.005"], ["70508.00", "0.001"], ["70509.30", "0.016"], ["70510.80", "0.007"], ["70512.60", "0.195"], ["70513.60", "0.003"], ["70514.70", "0.014"], ["70515.00", "0.007"], ["70519.40", "0.082"], ["70528.50", "0.077"], ["70529.40", "0.295"], ["70530.10", "0.024"], ["70530.30", "0.857"], ["70546.00", "0.881"], ["70547.50", "0.086"], ["70553.70", "0.029"], ["70554.10", "0.131"], ["70555.10", "0.108"], ["70555.30", "0.132"], ["70588.30", "0.463"], ["70727.40", "0.223"], ["71208.60", "0.002"], ["71208.70", "0.701"], ["71595.60", "0.598"], ["74036.80", "0.002"]]}}
{"local_ts": 1773485474332, "server_ts": 1773485473540, "data": {"e": "depthUpdate", "E": 1773485473541, "T": 1773485473540, "s": "BTCUSDT", "U": 10109450311163, "u": 10109450339726, "pu": 10109450311039, "b": [["5000.00", "101.418"], ["7050.40", "0.000"], ["20003.60", "2.030"], ["20103.60", "0.970"], ["33000.00", "3.789"], ["40000.00", "41.317"], ["56403.00", "0.000"], ["69340.30", "2.016"], ["69791.50", "0.000"], ["69798.60", "0.717"], ["69843.10", "1.492"], ["70151.00", "0.042"], ["70151.10", "0.000"], ["70257.30", "0.000"], ["70340.50", "0.511"], ["70370.50", "0.000"], ["70370.60", "1.032"], ["70433.10", "0.081"], ["70435.10", "0.120"], ["70449.10", "0.003"], ["70449.50", "0.356"], ["70449.90", "0.003"], ["70450.20", "0.101"], ["70450.50", "0.000"], ["70450.60", "0.004"], ["70450.70", "0.108"], ["70450.80", "0.003"], ["70451.00", "0.000"], ["70451.10", "0.058"], ["70451.40", "0.694"], ["70451.50", "0.006"], ["70451.70", "0.000"], ["70451.80", "0.042"], ["70451.90", "0.623"], ["70453.50", "0.000"], ["70454.00", "8.567"], ["70456.00", "0.852"], ["70456.10", "0.260"], ["70462.90", "0.003"], ["70464.80", "0.005"], ["70467.20", "0.535"], ["70467.60", "0.675"], ["70471.40", "0.001"], ["70471.80", "1.576"], ["70473.50", "0.009"], ["70473.60", "0.227"], ["70474.50", "0.011"], ["70474.60", "0.515"], ["70475.10", "0.548"], ["70475.20", "0.213"], ["70475.30", "0.089"], ["70475.40", "0.757"], ["70476.40", "0.000"], ["70476.90", "0.030"], ["70478.40", "0.347"], ["70478.50", "0.059"], ["70478.70", "0.002"], ["70479.00", "0.162"], ["70479.40", "0.464"], ["70479.50", "0.010"], ["70480.10", "0.006"], ["70480.90", "0.000"], ["70482.10", "0.002"], ["70482.30", "0.270"], ["70482.40", "0.067"], ["70482.50", "1.063"], ["70482.60", "0.082"], ["70482.80", "0.002"], ["70482.90", "0.001"], ["70483.10", "0.000"], ["70483.20", "0.141"], ["70483.50", "0.018"], ["70483.60", "0.011"], ["70484.30", "0.003"], ["70484.70", "0.002"], ["70485.00", "0.159"], ["70485.40", "0.000"], ["70485.60", "0.012"], ["70485.70", "0.000"], ["70485.80", "0.005"], ["70486.60", "0.151"], ["70486.70", "1.252"], ["70487.00", "0.040"], ["70487.10", "0.030"], ["70487.60", "0.264"], ["70487.70", "0.004"], ["70488.10", "0.128"], ["70488.50", "0.031"], ["70488.60", "0.004"], ["70489.10", "0.008"], ["70489.30", "0.000"], ["70489.70", "0.018"], ["70489.80", "0.858"], ["70489.90", "0.004"], ["70490.00", "0.714"], ["70490.10", "0.141"], ["70490.50", "0.215"], ["70490.70", "0.009"], ["70490.80", "0.019"], ["70491.10", "0.009"], ["70491.30", "0.209"], ["70491.40", "0.002"], ["70492.00", "0.022"], ["70492.20", "0.007"], ["70492.30", "0.007"], ["70492.50", "0.003"], ["70492.60", "0.000"], ["70492.70", "0.002"], ["70492.80", "0.006"], ["70493.10", "0.504"], ["70493.20", "0.713"], ["70493.50", "0.009"], ["70493.80", "0.155"], ["70493.90", "0.001"], ["70494.00", "0.002"], ["70494.20", "0.011"], ["70494.30", "0.021"], ["70494.40", "0.035"], ["70494.50", "0.001"], ["70494.70", "0.002"], ["70494.80", "0.056"], ["70494.90", "0.014"], ["70495.20", "0.016"], ["70495.60", "0.382"], ["70495.70", "0.015"], ["70496.00", "0.126"], ["70496.10", "0.001"], ["70496.20", "0.374"], ["70496.40", "0.730"], ["70496.50", "0.211"], ["70496.60", "0.121"], ["70496.70", "0.403"], ["70496.80", "0.006"], ["70496.90", "0.904"], ["70497.00", "0.050"], ["70497.50", "0.644"], ["70497.60", "0.002"], ["70497.70", "0.009"], ["70498.10", "0.014"], ["70498.40", "0.021"], ["70498.50", "0.015"], ["70498.60", "0.007"], ["70499.20", "0.083"], ["70499.30", "0.018"], ["70500.00", "0.212"], ["70500.10", "0.164"], ["70500.30", "0.008"], ["70500.40", "0.014"], ["70500.50", "0.010"], ["70500.60", "0.026"], ["70500.90", "0.017"], ["70501.10", "0.003"], ["70502.60", "0.000"], ["70502.80", "0.010"], ["70503.30", "0.000"], ["70503.40", "0.000"], ["70503.50", "0.639"], ["70503.60", "6.084"]], "a": [["70503.70", "1.331"], ["70503.80", "0.002"], ["70504.00", "0.035"], ["70504.50", "0.004"], ["70505.30", "0.000"], ["70505.40", "0.002"], ["70505.60", "0.004"], ["70506.20", "0.000"], ["70507.00", "0.212"], ["70507.30", "0.009"], ["70507.50", "0.004"], ["70507.90", "0.073"], ["70508.20", "0.002"], ["70508.30", "0.003"], ["70508.40", "0.005"], ["70508.50", "0.007"], ["70508.60", "0.004"], ["70509.10", "0.009"], ["70509.30", "0.004"], ["70509.40", "0.080"], ["70509.90", "0.000"], ["70510.00", "0.032"], ["70510.40", "0.006"], ["70510.60", "0.000"], ["70510.80", "0.009"], ["70510.90", "0.004"], ["70511.00", "0.029"], ["70511.10", "0.000"], ["70511.30", "0.002"], ["70511.60", "0.040"], ["70511.70", "0.180"], ["70511.80", "0.005"], ["70512.20", "0.041"], ["70512.30", "0.028"], ["70512.40", "0.012"], ["70512.60", "0.174"], ["70512.70", "0.152"], ["70512.80", "0.002"], ["70512.90", "0.223"], ["70513.30", "0.000"], ["70513.60", "0.003"], ["70513.70", "0.003"], ["70513.90", "0.010"], ["70514.00", "0.003"], ["70514.10", "0.000"], ["70514.50", "0.006"], ["70514.60", "0.000"], ["70514.70", "0.014"], ["70514.80", "0.006"], ["70514.90", "0.003"], ["70515.00", "0.007"], ["70515.10", "0.002"], ["70515.20", "0.002"], ["70515.50", "0.020"], ["70515.60", "0.009"], ["70515.70", "0.005"], ["70515.80", "0.019"], ["70515.90", "0.000"], ["70516.00", "0.000"], ["70516.10", "0.005"], ["70516.30", "0.002"], ["70516.50", "0.030"], ["70516.70", "0.009"], ["70516.80", "0.002"], ["70516.90", "0.003"], ["70517.00", "0.022"], ["70517.10", "0.006"], ["70517.20", "0.003"], ["70517.30", "0.015"], ["70517.40", "0.005"], ["70517.50", "0.062"], ["70517.60", "0.019"], ["70517.70", "0.000"], ["70517.90", "0.007"], ["70518.00", "0.014"], ["70518.10", "0.002"], ["70518.30", "0.067"], ["70518.40", "0.111"], ["70518.50", "0.002"], ["70518.60", "0.002"], ["70518.70", "0.194"], ["70518.80", "0.563"], ["70519.20", "0.005"], ["70519.30", "0.002"], ["70519.40", "0.002"], ["70519.50", "0.004"], ["70519.60", "0.183"], ["70519.70", "0.000"], ["70519.80", "0.004"], ["70519.90", "0.217"], ["70520.00", "0.067"], ["70520.20", "0.022"], ["70520.40", "0.035"], ["70520.60", "0.007"], ["70520.70", "0.014"], ["70520.90", "0.011"], ["70521.10", "0.020"], ["70521.40", "0.007"], ["70521.50", "0.063"], ["70521.60", "0.001"], ["70521.80", "0.372"], ["70521.90", "0.000"], ["70522.00", "0.739"], ["70522.40", "0.034"], ["70523.00", "0.053"], ["70523.10", "0.000"], ["70523.50", "0.006"], ["70523.60", "0.018"], ["70523.90", "0.002"], ["70524.00", "0.009"], ["70524.10", "0.010"], ["70524.20", "0.003"], ["70524.60", "0.363"], ["70524.70", "0.003"], ["70524.80", "0.002"], ["70524.90", "0.789"], ["70525.70", "0.511"], ["70525.80", "0.615"], ["70526.00", "1.095"], ["70526.20", "0.550"], ["70526.30", "0.003"], ["70526.40", "0.000"], ["70526.90", "0.003"], ["70527.00", "0.005"], ["70527.10", "0.106"], ["70527.20", "0.269"], ["70527.40", "0.015"], ["70527.50", "0.002"], ["70527.70", "0.006"], ["70527.80", "0.022"], ["70527.90", "0.005"], ["70528.00", "0.917"], ["70528.10", "0.002"], ["70528.20", "0.000"], ["70528.40", "0.144"], ["70528.50", "0.086"], ["70528.60", "0.479"], ["70528.70", "1.003"], ["70528.80", "0.005"], ["70529.10", "0.021"], ["70529.60", "0.020"], ["70529.70", "0.002"], ["70529.90", "0.022"], ["70530.10", "0.024"], ["70530.20", "0.519"], ["70530.30", "0.004"], ["70530.40", "0.131"], ["70530.60", "0.000"], ["70530.70", "0.004"], ["70531.00", "0.000"], ["70531.10", "0.036"], ["70531.20", "0.090"], ["70531.30", "0.004"], ["70531.40", "0.009"], ["70531.60", "0.003"], ["70531.90", "0.114"], ["70532.20", "0.004"], ["70532.50", "0.013"], ["70532.60", "1.946"], ["70532.70", "1.084"], ["70532.80", "0.643"], ["70533.00", "0.089"], ["70533.20", "0.002"], ["70533.60", "0.002"], ["70533.70", "0.062"], ["70533.80", "0.000"], ["70533.90", "0.085"], ["70534.10", "0.005"], ["70534.70", "0.002"], ["70534.80", "0.007"], ["70534.90", "0.142"], ["70535.00", "0.026"], ["70535.20", "0.063"], ["70535.30", "0.006"], ["70535.40", "0.159"], ["70535.60", "0.000"], ["70535.70", "0.079"], ["70535.90", "0.516"], ["70536.00", "0.104"], ["70536.10", "0.005"], ["70536.20", "0.003"], ["70536.50", "0.000"], ["70536.90", "0.028"], ["70537.60", "0.000"], ["70537.80", "0.088"], ["70538.00", "0.271"], ["70538.50", "0.005"], ["70539.00", "0.215"], ["70539.60", "1.666"], ["70539.70", "0.832"], ["70539.80", "0.148"], ["70540.20", "0.006"], ["70540.30", "0.001"], ["70540.70", "0.378"], ["70540.80", "0.052"], ["70541.80", "0.066"], ["70542.10", "0.408"], ["70542.50", "0.311"], ["70543.10", "0.020"], ["70543.30", "0.549"], ["70543.40", "0.271"], ["70543.60", "0.013"], ["70544.50", "0.005"], ["70545.10", "7.802"], ["70548.40", "0.010"], ["70549.50", "0.189"], ["70549.80", "0.095"], ["70550.30", "0.109"], ["70550.40", "0.053"], ["70551.10", "0.130"], ["70551.60", "0.498"], ["70552.70", "0.000"], ["70554.60", "0.086"], ["70558.10", "0.184"], ["70559.40", "0.002"], ["70565.90", "0.004"], ["70567.60", "0.000"], ["70567.80", "0.034"], ["70570.60", "8.500"], ["70587.10", "0.000"], ["70588.30", "0.252"], ["70588.90", "0.002"], ["70590.30", "0.053"], ["70590.60", "0.002"], ["70596.80", "0.501"], ["70598.90", "0.327"], ["70624.90", "0.164"], ["70636.60", "0.572"], ["70636.80", "2.584"], ["70637.80", "0.002"], ["70671.30", "0.604"], ["70672.20", "1.719"], ["70677.40", "0.186"], ["70837.00", "0.267"], ["70844.20", "0.007"], ["71208.70", "0.701"], ["71566.30", "0.586"], ["71913.70", "0.065"], ["74063.30", "0.040"], ["89523.20", "0.000"], ["100000.00", "23.659"]]}}
{"local_ts": 1773485475353, "server_ts": 1773485474562, "data": {"e": "depthUpdate", "E": 1773485474563, "T": 1773485474562, "s": "BTCUSDT", "U": 10109450411419, "u": 10109450416879, "pu": 10109450411354, "b": [["1000.00", "28.842"], ["5000.00", "101.418"], ["7050.40", "0.000"], ["20003.60", "1.410"], ["20403.60", "1.590"], ["56403.00", "0.000"], ["66948.50", "0.002"], ["69798.30", "0.100"], ["69798.60", "1.430"], ["70408.60", "0.000"], ["70408.70", "0.020"], ["70415.60", "0.262"], ["70415.70", "0.089"], ["70422.70", "0.004"], ["70422.80", "0.368"], ["70491.10", "0.005"], ["70500.40", "0.017"], ["70501.20", "0.003"], ["70502.00", "0.061"], ["70503.50", "0.646"], ["70503.60", "5.695"]], "a": [["70503.70", "1.331"], ["70510.50", "0.002"], ["70516.70", "0.066"], ["70525.80", "0.476"], ["70526.10", "0.266"], ["70527.10", "0.026"], ["70527.30", "0.080"], ["70536.40", "0.088"], ["70538.20", "0.009"], ["70539.00", "0.102"], ["70539.70", "0.834"], ["70554.60", "0.029"], ["70557.80", "0.005"], ["70559.30", "0.094"], ["70586.00", "0.081"], ["70586.30", "0.000"], ["70593.10", "0.149"], ["70593.40", "0.019"], ["70600.10", "0.157"], ["70600.40", "0.043"], ["71208.70", "0.703"], ["74055.20", "0.000"], ["89523.20", "0.000"]]}}
{"local_ts": 1773485476373, "server_ts": 1773485475580, "data": {"e": "depthUpdate", "E": 1773485475583, "T": 1773485475580, "s": "BTCUSDT", "U": 10109450472462, "u": 10109450476607, "pu": 10109450472423, "b": [["5000.00", "101.418"], ["7050.40", "0.000"], ["20303.60", "1.140"], ["20403.60", "1.860"], ["56403.00", "0.000"], ["66948.50", "0.000"], ["66967.10", "0.002"], ["66978.00", "0.000"], ["69472.70", "1.882"], ["69798.60", "2.861"], ["70151.00", "0.042"], ["70456.00", "0.852"], ["70456.10", "0.260"], ["70473.70", "0.030"], ["70473.80", "0.003"], ["70478.50", "0.059"], ["70480.50", "0.248"], ["70484.00", "0.273"], ["70484.40", "0.002"], ["70484.90", "0.297"], ["70485.70", "0.070"], ["70486.40", "0.000"], ["70487.50", "0.511"], ["70492.60", "0.000"], ["70493.50", "0.009"], ["70494.50", "0.003"], ["70494.60", "0.640"], ["70500.30", "0.031"], ["70502.40", "0.048"], ["70503.60", "5.914"]], "a": [["70516.60", "0.059"], ["70517.80", "0.429"], ["70531.60", "0.003"], ["70532.00", "0.006"], ["70533.10", "2.003"], ["70534.10", "0.075"], ["70535.80", "0.002"], ["70536.60", "0.253"], ["70542.50", "0.501"], ["70550.40", "0.011"], ["70727.10", "0.009"], ["71208.60", "0.002"], ["71208.70", "0.701"], ["71567.50", "0.881"], ["89523.20", "0.000"]]}}
{"local_ts": 1773485477397, "server_ts": 1773485476601, "data": {"e": "depthUpdate", "E": 1773485476605, "T": 1773485476601, "s": "BTCUSDT", "U": 10109450527188, "u": 10109450532045, "pu": 10109450527046, "b": [["1000.00", "28.842"], ["5000.00", "101.418"], ["7050.40", "0.056"], ["20203.60", "0.690"], ["20303.60", "2.310"], ["20403.60", "0.000"], ["56403.00", "0.000"], ["68376.20", "0.000"], ["69798.60", "2.861"], ["69798.70", "0.004"], ["70077.20", "0.002"], ["70080.50", "0.707"], ["70151.00", "0.042"], ["70151.10", "0.000"], ["70182.50", "0.000"], ["70185.10", "1.820"], ["70200.00", "24.388"], ["70257.60", "0.004"], ["70259.70", "0.000"], ["70262.30", "1.715"], ["70408.70", "0.020"], ["70415.70", "0.089"], ["70422.80", "0.368"], ["70456.10", "0.260"], ["70456.30", "0.002"], ["70473.70", "0.106"]], "a": [["70503.70", "1.143"], ["70535.70", "0.000"], ["70536.60", "0.057"], ["70585.30", "0.000"], ["70585.40", "0.080"], ["70592.40", "1.493"], ["70592.50", "0.071"], ["70599.40", "0.046"], ["70599.50", "1.215"], ["70746.50", "0.240"], ["70747.10", "0.000"], ["70822.50", "0.508"], ["70825.00", "0.055"], ["70931.20", "0.009"], ["71209.00", "0.054"], ["71405.40", "0.000"], ["71420.50", "1.470"], ["73323.80", "0.025"], ["74040.90", "0.100"], ["89523.20", "0.000"]]}}
{"local_ts": 1773485478417, "server_ts": 1773485477624, "data": {"e": "depthUpdate", "E": 1773485477625, "T": 1773485477624, "s": "BTCUSDT", "U": 10109450579159, "u": 10109450583670, "pu": 10109450579038, "b": [["1000.00", "28.842"], ["5000.00", "101.418"], ["7050.40", "0.056"], ["20103.60", "0.320"], ["20203.60", "2.610"], ["20303.60", "0.070"], ["56403.00", "0.000"], ["66946.00", "0.008"], ["68503.60", "0.002"], ["69798.60", "2.861"], ["70147.50", "0.569"], ["70257.60", "0.008"], ["70408.70", "0.020"], ["70415.70", "0.089"], ["70422.80", "0.368"], ["70426.70", "0.249"], ["70431.80", "0.050"], ["70432.40", "0.187"], ["70433.40", "0.058"], ["70433.80", "0.402"], ["70456.30", "0.004"], ["70456.40", "0.002"], ["70475.30", "0.089"], ["70482.70", "0.003"], ["70483.10", "0.007"], ["70483.90", "0.075"], ["70484.40", "0.002"], ["70485.00", "0.152"], ["70496.50", "0.007"], ["70496.60", "0.072"]], "a": [["70503.70", "1.551"], ["70506.50", "0.005"], ["70506.60", "0.001"], ["70506.70", "0.004"], ["70506.80", "0.000"], ["70507.00", "0.214"], ["70507.10", "0.001"], ["70507.20", "0.003"], ["70507.30", "0.009"], ["70507.50", "0.004"], ["70507.60", "0.005"], ["70507.90", "0.073"], ["70508.00", "0.001"], ["70508.20", "0.002"], ["70508.50", "0.022"], ["70508.60", "0.002"], ["70510.00", "0.053"], ["70510.70", "0.001"], ["70515.60", "0.013"], ["70516.40", "0.030"], ["70553.70", "0.029"], ["70554.10", "0.131"], ["70555.10", "0.108"], ["70555.30", "0.132"], ["70585.10", "0.264"], ["70585.20", "0.008"], ["70592.20", "0.071"], ["70592.30", "1.961"], ["70599.20", "0.312"], ["70599.30", "0.245"], ["70727.20", "0.008"], ["70780.90", "0.000"], ["71208.70", "0.703"], ["74051.30", "0.003"], ["89523.20", "0.000"]]}}
{"local_ts": 1773485479439, "server_ts": 1773485478648, "data": {"e": "depthUpdate", "E": 1773485478649, "T": 1773485478648, "s": "BTCUSDT", "U": 10109450653665, "u": 10109450658187, "pu": 10109450653596, "b": [["5000.00", "101.418"], ["7050.40", "0.056"], ["20003.60", "0.180"], ["20103.60", "2.450"], ["20203.60", "0.370"], ["33000.00", "3.785"], ["56403.00", "0.000"], ["69537.70", "0.999"], ["69798.60", "2.861"], ["70151.10", "0.000"], ["70341.50", "0.093"], ["70344.40", "0.108"], ["70350.00", "1.021"], ["70360.20", "0.081"], ["70363.70", "0.002"], ["70426.70", "0.200"], ["70456.30", "0.002"], ["70456.50", "0.004"], ["70466.80", "0.840"], ["70469.50", "0.006"], ["70473.10", "0.008"], ["70473.70", "0.721"], ["70478.90", "0.197"], ["70496.20", "0.390"], ["70496.60", "0.072"], ["70497.10", "0.007"], ["70502.40", "0.048"], ["70502.90", "0.216"], ["70503.60", "5.905"]], "a": [["70503.70", "0.919"], ["70510.70", "0.001"], ["70511.70", "0.195"], ["70516.50", "0.003"], ["70518.50", "0.284"], ["70518.60", "0.004"], ["70520.80", "1.003"], ["70526.60", "0.000"], ["70528.80", "0.021"], ["70536.50", "0.002"], ["70542.50", "0.362"], ["70544.10", "0.005"], ["70554.00", "0.004"], ["70557.30", "1.181"], ["70567.10", "0.000"], ["70568.00", "0.018"], ["70569.80", "0.000"], ["70572.00", "0.045"], ["70727.40", "0.230"], ["70852.50", "0.144"], ["71208.60", "0.002"], ["71208.70", "0.701"], ["71209.00", "0.348"], ["71840.50", "4.170"], ["74032.70", "0.004"], ["74038.90", "0.002"], ["89523.20", "0.000"]]}}
{"local_ts": 1773485480460, "server_ts": 1773485479670, "data": {"e": "depthUpdate", "E": 1773485479671, "T": 1773485479670, "s": "BTCUSDT", "U": 10109450725072, "u": 10109450731969, "pu": 10109450725029, "b": [["1000.00", "28.842"], ["5000.00", "101.418"], ["7050.40", "0.028"], ["20003.60", "2.300"], ["20103.60", "0.670"], ["20403.60", "0.030"], ["66950.50", "0.008"], ["69798.60", "2.861"], ["69798.70", "0.000"], ["70257.50", "0.247"], ["70408.60", "0.018"], ["70415.60", "0.333"], ["70422.70", "0.075"], ["70456.50", "0.002"], ["70457.00", "0.006"], ["70474.50", "0.011"], ["70474.60", "0.515"], ["70475.20", "0.213"], ["70475.30", "0.089"], ["70475.60", "0.270"], ["70475.70", "0.015"], ["70478.10", "0.249"], ["70496.60", "0.070"], ["70501.50", "0.057"]], "a": [["70503.70", "2.694"], ["70516.60", "0.513"], ["70517.30", "0.000"], ["70517.60", "0.004"], ["70518.80", "0.933"], ["70519.90", "1.285"], ["70520.00", "0.069"], ["70523.10", "0.007"], ["70524.50", "0.076"], ["70525.00", "0.234"], ["70530.00", "0.137"], ["70530.70", "0.074"], ["70585.10", "0.264"], ["70592.20", "0.071"], ["70599.20", "0.312"], ["70727.40", "0.223"], ["70850.90", "0.084"], ["71208.60", "0.009"], ["71208.70", "0.703"], ["71526.00", "16.055"], ["72624.50", "0.000"], ["74053.30", "0.000"], ["89523.20", "0.000"]]}}
{"local_ts": 1773485481485, "server_ts": 1773485480692, "data": {"e": "depthUpdate", "E": 1773485480695, "T": 1773485480692, "s": "BTCUSDT", "U": 10109450783382, "u": 10109450787705, "pu": 10109450783291, "b": [["5000.00", "101.418"], ["7050.40", "0.028"], ["20003.60", "1.080"], ["20403.60", "1.920"], ["33000.00", "3.789"], ["56403.00", "0.000"], ["70147.40", "0.142"], ["70151.10", "0.143"], ["70152.80", "0.051"], ["70456.50", "0.002"], ["70456.60", "0.012"], ["70496.60", "0.049"]], "a": [["70503.70", "2.550"], ["70504.30", "0.009"], ["70506.30", "0.000"], ["70510.70", "0.001"], ["70512.30", "0.003"], ["70512.60", "0.176"], ["70512.70", "0.152"], ["70512.80", "0.002"], ["70514.10", "0.017"], ["70727.60", "0.007"], ["71208.70", "0.701"], ["71596.40", "0.036"], ["74040.20", "0.000"], ["74056.60", "0.002"], ["89523.20", "0.000"]]}}
{"local_ts": 1773485482511, "server_ts": 1773485481716, "data": {"e": "depthUpdate", "E": 1773485481719, "T": 1773485481716, "s": "BTCUSDT", "U": 10109450834382, "u": 10109450842672, "pu": 10109450834233, "b": [["1000.00", "28.842"], ["5000.00", "101.438"], ["7050.40", "0.028"], ["20303.60", "1.480"], ["20403.60", "1.520"], ["66945.50", "0.000"], ["67732.90", "0.005"], ["69410.80", "8.059"], ["69467.20", "1.886"], ["69798.60", "2.861"], ["70151.10", "0.143"], ["70316.80", "0.000"], ["70320.30", "0.455"], ["70323.00", "0.505"], ["70337.90", "0.606"], ["70345.00", "0.013"], ["70348.50", "0.683"], ["70354.80", "12.546"], ["70354.90", "0.114"], ["70408.60", "0.018"], ["70413.60", "6.574"], ["70415.60", "0.333"], ["70422.70", "0.075"], ["70430.90", "0.123"], ["70443.70", "0.034"], ["70447.20", "0.080"], ["70448.70", "3.868"], ["70448.80", "0.941"], ["70450.20", "0.004"], ["70450.30", "0.288"], ["70450.40", "0.045"], ["70450.50", "0.005"], ["70450.70", "0.108"], ["70469.50", "0.006"], ["70469.60", "0.349"], ["70469.90", "1.880"], ["70475.40", "1.061"], ["70475.60", "0.270"], ["70476.40", "0.000"], ["70477.90", "0.253"], ["70479.00", "0.167"], ["70483.10", "0.000"], ["70485.40", "0.510"], ["70490.60", "0.003"], ["70490.90", "0.008"], ["70491.50", "0.020"], ["70493.10", "0.947"], ["70493.30", "0.540"], ["70503.60", "5.143"]], "a": [["70503.70", "3.953"], ["70504.80", "0.000"], ["70505.40", "0.002"], ["70505.50", "0.001"], ["70505.70", "0.009"], ["70506.30", "0.002"], ["70507.00", "0.002"], ["70507.10", "0.213"], ["70507.20", "0.003"], ["70507.50", "0.013"], ["70507.60", "0.024"], ["70507.80", "0.004"], ["70508.00", "0.001"], ["70508.40", "0.098"], ["70508.60", "0.004"], ["70509.10", "0.079"], ["70509.40", "0.083"], ["70509.60", "0.007"], ["70510.00", "0.032"], ["70510.30", "0.000"], ["70510.40", "0.006"], ["70510.50", "0.002"], ["70510.60", "0.000"], ["70510.70", "0.009"], ["70510.80", "0.007"], ["70510.90", "0.205"], ["70511.00", "0.008"], ["70511.10", "0.000"], ["70511.20", "0.030"], ["70511.30", "0.002"], ["70511.40", "0.009"], ["70511.50", "0.044"], ["70512.70", "0.152"], ["70512.80", "0.023"], ["70513.20", "0.004"], ["70527.00", "0.005"], ["70527.80", "0.157"], ["70528.50", "0.650"], ["70528.80", "0.028"], ["70529.70", "0.512"], ["70530.10", "0.024"], ["70530.30", "0.004"], ["70531.30", "0.074"], ["70531.60", "0.073"], ["70533.00", "0.068"], ["70533.50", "0.002"], ["70534.10", "0.253"], ["70534.40", "0.079"], ["70534.50", "0.171"], ["70534.70", "0.002"], ["70534.90", "0.072"], ["70535.70", "0.052"], ["70542.50", "0.362"], ["70544.00", "0.338"], ["70557.20", "0.829"], ["70585.00", "0.125"], ["70592.10", "0.076"], ["70599.10", "0.071"], ["71208.70", "0.701"], ["71507.50", "0.698"], ["73237.70", "0.026"], ["74038.50", "0.009"], ["89523.20", "0.000"]]}}
