{"local_ts": 1773486827367, "server_ts": 1773486827336, "data": {"e": "depthUpdate", "E": 1773486827339, "T": 1773486827336, "s": "BTCUSDT", "U": 10109526641559, "u": 10109526646649, "pu": 10109526641490, "b": [["1000.00", "26.292"], ["5000.00", "101.418"], ["7061.30", "0.000"], ["20212.80", "0.080"], ["20312.80", "2.370"], ["20412.80", "0.550"], ["67058.20", "0.002"], ["67082.00", "0.044"], ["69292.30", "1.688"], ["69341.80", "0.360"], ["69345.30", "0.720"], ["70520.50", "0.005"], ["70527.50", "0.000"], ["70534.60", "0.000"], ["70585.60", "0.115"], ["70585.70", "0.002"], ["70598.10", "0.253"], ["70599.30", "0.000"], ["70603.60", "0.127"], ["70604.50", "0.021"], ["70605.80", "0.036"], ["70606.20", "0.022"], ["70609.50", "0.021"], ["70610.40", "0.642"], ["70610.70", "0.175"]], "a": [["70617.90", "0.085"], ["70618.00", "0.075"], ["70618.10", "0.003"], ["70618.70", "0.003"], ["70619.90", "0.001"], ["70632.90", "0.000"], ["70697.10", "0.000"], ["70704.20", "0.000"], ["70711.20", "0.053"], ["71179.10", "0.000"], ["71319.00", "5.872"], ["71344.40", "0.000"], ["71687.90", "0.417"], ["72731.20", "0.006"], ["89523.20", "0.000"]]}}
{"local_ts": 1773486828387, "server_ts": 1773486828357, "data": {"e": "depthUpdate", "E": 1773486828359, "T": 1773486828357, "s": "BTCUSDT", "U": 10109526693246, "u": 10109526697721, "pu": 10109526693227, "b": [["5000.00", "101.418"], ["7061.30", "0.000"], ["20212.80", "2.080"], ["20312.80", "0.920"], ["67058.00", "0.004"], ["67082.00", "0.044"], ["69821.30", "0.000"], ["69906.70", "5.148"], ["70302.10", "0.106"], ["70366.30", "0.006"], ["70429.20", "0.220"], ["70436.30", "0.161"], ["70468.40", "12.420"], ["70527.60", "6.700"], ["70558.30", "0.045"], ["70559.80", "0.520"], ["70562.50", "0.043"], ["70562.90", "3.446"], ["70563.00", "1.036"], ["70584.30", "1.847"], ["70596.30", "0.247"], ["70598.10", "0.058"], ["70600.00", "0.037"], ["70600.70", "0.516"], ["70602.10", "0.002"], ["70604.60", "0.002"], ["70605.00", "0.010"], ["70605.20", "0.404"], ["70608.60", "0.045"], ["70609.40", "0.639"], ["70609.50", "0.191"], ["70609.70", "0.230"], ["70609.80", "0.207"], ["70612.80", "4.799"]], "a": [["70612.90", "0.968"], ["70615.50", "0.151"], ["70618.20", "0.104"], ["70622.50", "0.002"], ["70623.20", "0.004"], ["70628.70", "0.024"], ["70628.80", "0.457"], ["70630.70", "0.178"], ["70655.00", "2.588"], ["70655.80", "0.029"], ["70666.20", "1.414"], ["70676.20", "3.957"], ["70681.00", "0.031"], ["70683.50", "0.019"], ["70711.10", "2.446"], ["70711.20", "6.345"], ["70711.90", "0.003"], ["70767.90", "2.400"], ["70769.40", "12.123"], ["70771.80", "0.161"], ["70778.80", "1.129"], ["70836.80", "0.007"], ["71283.50", "0.010"], ["71319.00", "5.872"], ["71874.90", "0.699"], ["72043.90", "0.553"], ["89523.20", "0.000"]]}}
{"local_ts": 1773486829409, "server_ts": 1773486829378, "data": {"e": "depthUpdate", "E": 1773486829379, "T": 1773486829378, "s": "BTCUSDT", "U": 10109526741043, "u": 10109526745158, "pu": 10109526741020, "b": [["1000.00", "26.292"], ["5000.00", "101.418"], ["7061.90", "0.000"], ["20119.00", "1.250"], ["20212.80", "1.370"], ["33000.00", "3.785"], ["67088.00", "0.050"], ["69100.50", "0.008"], ["69200.60", "0.006"], ["69607.30", "0.009"], ["70100.10", "3.739"], ["70222.10", "16.020"], ["70244.30", "0.192"], ["70259.70", "0.783"], ["70301.00", "0.027"], ["70382.60", "0.002"], ["70520.30", "0.017"], ["70527.30", "0.092"], ["70534.40", "0.342"], ["70580.00", "2.014"], ["70581.50", "0.018"], ["70588.20", "0.126"], ["70588.30", "0.002"], ["70588.50", "1.070"], ["70594.10", "0.026"], ["70594.80", "0.213"], ["70601.20", "0.214"], ["70608.40", "0.129"], ["70611.80", "0.003"], ["70612.00", "0.019"], ["70612.80", "0.073"], ["70613.80", "0.003"], ["70619.00", "7.672"]], "a": [["70619.70", "0.031"], ["70626.10", "0.059"], ["70629.20", "0.000"], ["70629.70", "0.005"], ["70630.60", "0.009"], ["70632.00", "0.374"], ["70633.10", "0.001"], ["70643.50", "0.310"], ["70664.40", "0.068"], ["70672.40", "0.814"], ["70685.50", "0.541"], ["70696.90", "0.249"], ["70704.00", "0.082"], ["70711.00", "0.443"], ["70938.90", "0.000"], ["70940.90", "0.006"], ["71059.80", "7.403"], ["71175.20", "3.240"], ["71325.30", "0.000"], ["74169.00", "1.800"], ["89523.20", "0.000"]]}}
{"local_ts": 1773486830428, "server_ts": 1773486830400, "data": {"e": "depthUpdate", "E": 1773486830401, "T": 1773486830400, "s": "BTCUSDT", "U": 10109526781442, "u": 10109526784822, "pu": 10109526781351, "b": [["1000.00", "26.292"], ["5000.00", "101.398"], ["7061.90", "0.000"], ["20119.00", "1.430"], ["20519.00", "1.190"], ["69912.80", "0.000"], ["70070.10", "46.299"], ["70173.90", "0.002"], ["70478.70", "0.088"], ["70507.10", "0.000"], ["70537.10", "0.450"], ["70543.60", "0.052"], ["70571.00", "0.463"], ["70571.20", "0.925"], ["70586.30", "0.004"], ["70588.00", "0.944"], ["70588.10", "0.089"], ["70592.00", "0.277"], ["70603.10", "0.112"]], "a": [["70632.20", "0.072"], ["70649.00", "0.010"], ["70663.50", "0.018"], ["70679.90", "0.067"], ["70687.10", "0.123"], ["70709.90", "0.547"], ["70760.10", "0.007"], ["70767.20", "0.007"], ["70771.90", "12.138"], ["70774.30", "0.344"], ["70779.00", "0.000"], ["70781.40", "0.249"], ["70786.10", "0.000"], ["70788.50", "0.024"], ["70793.20", "0.000"], ["70795.60", "0.007"], ["70800.30", "0.000"], ["70802.70", "0.007"], ["70807.40", "0.000"], ["70809.80", "1.076"], ["70814.50", "0.000"], ["70821.60", "0.190"], ["71177.50", "38.971"], ["71325.30", "0.000"], ["71953.80", "0.682"], ["74173.90", "0.004"], ["89523.20", "0.006"]]}}
{"local_ts": 1773486831454, "server_ts": 1773486831424, "data": {"e": "depthUpdate", "E": 1773486831425, "T": 1773486831424, "s": "BTCUSDT", "U": 10109526818152, "u": 10109526820785, "pu": 10109526818077, "b": [["5000.00", "101.438"], ["7061.90", "0.056"], ["20419.00", "0.750"], ["20519.00", "2.250"], ["33000.00", "3.789"], ["67068.80", "0.000"], ["67814.30", "0.018"], ["69619.10", "0.000"], ["69849.30", "0.723"], ["69912.80", "0.000"], ["70470.20", "13.000"], ["70529.50", "6.778"], ["70571.50", "0.005"], ["70571.60", "0.795"], ["70608.40", "0.124"], ["70611.70", "0.032"]], "a": [["70619.10", "57.757"], ["70625.60", "1.890"], ["70629.70", "0.002"], ["70713.10", "6.774"], ["70760.10", "0.000"], ["70767.20", "0.000"], ["70771.80", "12.341"], ["70774.30", "0.337"], ["70778.00", "0.426"], ["70781.40", "0.242"], ["70816.90", "1.764"], ["70824.00", "0.898"], ["70831.10", "0.019"], ["70838.20", "0.007"], ["71325.30", "0.000"]]}}
{"local_ts": 1773486832474, "server_ts": 1773486832444, "data": {"e": "depthUpdate", "E": 1773486832445, "T": 1773486832444, "s": "BTCUSDT", "U": 10109526860518, "u": 10109526864985, "pu": 10109526860388, "b": [["1000.00", "26.292"], ["5000.00", "101.418"], ["7061.90", "0.056"], ["20319.00", "0.360"], ["20419.00", "2.580"], ["20519.00", "0.060"], ["67056.00", "0.000"], ["67075.60", "0.000"], ["67794.30", "0.010"], ["69912.80", "0.000"], ["70520.60", "0.017"], ["70527.60", "0.091"], ["70534.70", "0.625"], ["70545.00", "0.048"], ["70571.80", "0.005"], ["70571.90", "0.008"], ["70608.40", "0.127"], ["70611.80", "0.003"], ["70617.40", "0.214"]], "a": [["70619.10", "57.710"], ["70624.90", "0.060"], ["70626.20", "0.057"], ["70627.50", "0.006"], ["70629.70", "0.005"], ["70633.10", "0.401"], ["70639.00", "1.199"], ["70641.10", "0.022"], ["70697.20", "0.004"], ["70697.30", "2.016"], ["70704.30", "0.016"], ["70704.40", "0.071"], ["70711.30", "0.133"], ["70711.40", "0.161"], ["70785.10", "0.007"], ["70788.50", "0.017"], ["70792.20", "0.304"], ["70795.60", "0.000"], ["70799.30", "0.007"], ["70802.70", "0.000"], ["70806.40", "0.049"], ["70809.80", "1.069"], ["70813.50", "0.020"], ["70816.90", "1.757"], ["70820.60", "0.007"], ["70824.00", "0.891"], ["70827.70", "0.007"], ["70831.10", "0.012"], ["70834.80", "0.007"], ["70838.20", "0.000"], ["71325.30", "0.700"], ["71657.20", "2.020"], ["71917.80", "0.000"], ["72043.70", "0.000"], ["74159.00", "0.404"]]}}
{"local_ts": 1773486833494, "server_ts": 1773486833464, "data": {"e": "depthUpdate", "E": 1773486833465, "T": 1773486833464, "s": "BTCUSDT", "U": 10109526902038, "u": 10109526906011, "pu": 10109526902002, "b": [["5000.00", "101.418"], ["7061.90", "0.056"], ["20219.00", "0.190"], ["20319.00", "2.470"], ["20419.00", "0.340"], ["67053.10", "0.002"], ["69665.60", "0.286"], ["69912.80", "0.714"], ["69912.90", "0.004"], ["70011.60", "0.000"], ["70372.50", "0.002"], ["70443.30", "0.010"], ["70520.70", "0.028"], ["70527.70", "0.071"], ["70534.80", "0.095"], ["70549.10", "0.083"], ["70558.70", "0.043"], ["70560.40", "0.912"], ["70588.10", "0.004"], ["70588.20", "0.126"], ["70588.30", "0.036"], ["70608.40", "0.083"], ["70609.00", "0.053"], ["70609.20", "0.563"], ["70611.80", "0.000"], ["70619.00", "6.780"]], "a": [["70619.10", "57.858"], ["70629.70", "0.005"], ["70630.30", "0.039"], ["70630.40", "0.046"], ["70633.10", "0.404"], ["70648.30", "0.005"], ["70649.00", "0.010"], ["70651.70", "0.003"], ["70654.70", "0.147"], ["70655.60", "0.025"], ["70656.40", "0.000"], ["70667.30", "0.078"], ["70667.40", "0.001"], ["70679.10", "0.649"], ["70680.70", "0.025"], ["70697.40", "0.071"], ["70704.50", "0.073"], ["70711.50", "0.071"], ["70785.10", "0.000"], ["70788.20", "0.007"], ["70792.20", "0.297"], ["70795.30", "0.522"], ["70799.30", "0.000"], ["70802.40", "0.269"], ["70806.40", "0.042"], ["70809.50", "0.015"], ["70813.50", "0.013"], ["70816.60", "0.013"], ["70820.60", "0.000"], ["70823.70", "0.007"], ["70827.70", "0.000"], ["70830.80", "0.007"], ["70834.80", "0.000"], ["70837.90", "0.007"], ["70843.20", "0.000"], ["71325.20", "0.572"], ["71325.30", "0.700"], ["71702.10", "0.904"], ["72754.80", "3.981"], ["74159.20", "0.000"]]}}
{"local_ts": 1773486834519, "server_ts": 1773486834484, "data": {"e": "depthUpdate", "E": 1773486834485, "T": 1773486834484, "s": "BTCUSDT", "U": 10109526954620, "u": 10109526959069, "pu": 10109526954557, "b": [["1000.00", "26.292"], ["5000.00", "101.418"], ["7061.90", "0.028"], ["20119.00", "0.040"], ["20219.00", "2.320"], ["20319.00", "0.640"], ["67080.90", "0.002"], ["67794.30", "0.016"], ["69200.60", "0.000"], ["69463.00", "0.000"], ["69912.80", "0.714"], ["70265.90", "0.000"], ["70496.90", "0.000"], ["70502.40", "0.444"], ["70571.80", "0.003"], ["70571.90", "0.010"], ["70590.30", "0.247"], ["70608.90", "0.192"], ["70609.10", "0.003"], ["70609.60", "0.141"], ["70614.90", "0.003"], ["70615.10", "0.016"], ["70617.60", "0.083"], ["70618.00", "0.057"], ["70618.30", "0.000"], ["70618.40", "0.103"], ["70618.90", "0.005"], ["70619.00", "6.606"]], "a": [["70619.10", "57.526"], ["70619.80", "0.004"], ["70623.00", "0.065"], ["70624.40", "0.002"], ["70624.50", "0.015"], ["70625.40", "0.008"], ["70626.80", "0.008"], ["70633.30", "0.000"], ["70644.90", "0.005"], ["70645.00", "0.004"], ["70646.10", "0.513"], ["70647.00", "0.003"], ["70649.60", "0.006"], ["70650.20", "0.021"], ["70651.70", "0.001"], ["70654.20", "0.049"], ["70662.20", "0.023"], ["70681.80", "0.110"], ["70700.00", "25.319"], ["70787.20", "0.015"], ["70788.20", "0.000"], ["70794.30", "0.009"], ["70795.30", "0.515"], ["70801.40", "0.007"], ["70802.40", "0.262"], ["70808.50", "33.382"], ["70809.50", "0.008"], ["70815.60", "0.007"], ["70816.60", "0.006"], ["70822.70", "0.007"], ["70823.70", "0.000"], ["70829.80", "2.225"], ["70830.80", "0.000"], ["70836.90", "0.010"], ["70837.90", "0.000"], ["70843.20", "0.007"], ["71290.00", "1.544"], ["71325.20", "0.565"], ["71325.30", "0.700"], ["72031.40", "0.013"], ["72396.70", "2.758"]]}}
{"local_ts": 1773486835535, "server_ts": 1773486835504, "data": {"e": "depthUpdate", "E": 1773486835507, "T": 1773486835504, "s": "BTCUSDT", "U": 10109526998384, "u": 10109527002701, "pu": 10109526998360, "b": [["1000.00", "26.292"], ["5000.00", "101.438"], ["7061.90", "0.028"], ["20119.00", "1.950"], ["20219.00", "1.050"], ["66872.40", "0.000"], ["67794.30", "0.020"], ["69912.80", "1.428"], ["70387.60", "0.000"], ["70406.30", "0.000"], ["70529.80", "0.006"], ["70571.90", "0.008"], ["70572.00", "0.099"], ["70589.00", "0.085"], ["70589.10", "0.005"], ["70590.30", "0.063"], ["70617.80", "0.002"], ["70619.00", "5.911"]], "a": [["70619.10", "57.637"], ["70622.50", "0.059"], ["70629.40", "0.002"], ["70634.10", "0.005"], ["70634.30", "0.025"], ["70637.20", "0.181"], ["70649.60", "0.074"], ["70666.00", "0.124"], ["70687.90", "0.000"], ["70700.00", "25.280"], ["70769.00", "0.000"], ["70839.60", "0.003"], ["71325.30", "0.700"], ["71586.60", "0.279"], ["74166.30", "0.000"]]}}
{"local_ts": 1773486836556, "server_ts": 1773486836528, "data": {"e": "depthUpdate", "E": 1773486836529, "T": 1773486836528, "s": "BTCUSDT", "U": 10109527041502, "u": 10109527045162, "pu": 10109527041420, "b": [["5000.00", "101.418"], ["7061.90", "0.028"], ["20119.00", "1.490"], ["20519.00", "1.510"], ["56495.00", "0.004"], ["67073.40", "0.002"], ["69448.90", "0.654"], ["69747.80", "1.213"], ["69792.80", "2.319"], ["69912.80", "1.428"], ["69912.90", "0.004"], ["70265.90", "0.036"], ["70302.20", "2.229"], ["70372.70", "0.004"], ["70463.60", "0.045"], ["70474.10", "0.171"], ["70594.50", "0.021"], ["70594.60", "0.019"], ["70609.10", "0.003"], ["70609.30", "0.008"], ["70614.40", "0.001"], ["70614.90", "0.024"], ["70615.00", "0.398"], ["70619.00", "5.769"]], "a": [["70619.10", "57.394"], ["70626.20", "0.100"], ["70629.40", "0.000"], ["70633.30", "0.020"], ["70636.60", "0.011"], ["70643.30", "0.005"], ["70645.70", "0.003"], ["70649.60", "0.004"], ["70650.70", "0.160"], ["70654.80", "0.083"], ["70681.30", "0.000"], ["70770.90", "0.161"], ["70774.40", "0.002"], ["71325.30", "0.700"], ["72031.40", "0.016"]]}}
{"local_ts": 1773486837576, "server_ts": 1773486837548, "data": {"e": "depthUpdate", "E": 1773486837549, "T": 1773486837548, "s": "BTCUSDT", "U": 10109527079704, "u": 10109527083579, "pu": 10109527079614, "b": [["1000.00", "26.292"], ["5000.00", "101.398"], ["7061.90", "0.000"], ["20419.00", "1.060"], ["20519.00", "1.940"], ["56495.00", "0.004"], ["67027.10", "0.000"], ["67057.70", "0.000"], ["67088.10", "0.010"], ["69369.80", "0.030"], ["69448.90", "0.008"], ["69912.80", "1.428"], ["70393.00", "0.057"], ["70609.80", "0.005"], ["70610.10", "0.058"], ["70614.90", "0.003"]], "a": [["70619.10", "57.360"], ["70636.60", "0.009"], ["70638.80", "0.005"], ["70743.80", "0.174"], ["70747.90", "0.228"], ["70845.00", "21.174"], ["71325.30", "1.120"], ["71560.90", "0.698"], ["73443.80", "0.022"]]}}
{"local_ts": 1773486838605, "server_ts": 1773486838568, "data": {"e": "depthUpdate", "E": 1773486838571, "T": 1773486838568, "s": "BTCUSDT", "U": 10109527120279, "u": 10109527125060, "pu": 10109527120238, "b": [["5000.00", "101.418"], ["7061.90", "0.000"], ["20319.00", "0.610"], ["20419.00", "2.390"], ["20519.00", "0.000"], ["33000.00", "3.785"], ["56495.00", "0.000"], ["67060.90", "0.000"], ["69383.20", "1.151"], ["69627.90", "0.717"], ["69912.80", "1.428"], ["70483.30", "0.664"], ["70534.10", "1.153"], ["70536.40", "0.074"], ["70558.50", "0.077"], ["70560.50", "0.119"], ["70572.10", "0.094"], ["70572.20", "0.280"], ["70608.90", "0.214"], ["70609.40", "0.191"], ["70615.60", "0.005"], ["70618.50", "0.002"], ["70618.70", "0.000"], ["70618.80", "0.000"], ["70618.90", "0.005"]], "a": [["70619.10", "57.401"], ["70620.80", "0.021"], ["70630.40", "0.118"], ["70630.90", "0.108"], ["70654.80", "0.064"], ["70656.00", "0.076"], ["70679.20", "0.065"], ["70681.20", "0.072"], ["70726.00", "0.260"], ["70726.20", "0.265"], ["70750.20", "0.426"], ["70842.50", "0.283"], ["71325.20", "0.565"], ["71325.30", "1.120"], ["71572.50", "0.349"], ["73443.80", "0.024"], ["74150.00", "3.493"], ["74181.50", "0.052"]]}}
{"local_ts": 1773486839619, "server_ts": 1773486839590, "data": {"e": "depthUpdate", "E": 1773486839591, "T": 1773486839590, "s": "BTCUSDT", "U": 10109527159093, "u": 10109527162711, "pu": 10109527159071, "b": [["1000.00", "26.292"], ["5000.00", "101.418"], ["7061.90", "0.000"], ["20219.00", "0.290"], ["20319.00", "2.580"], ["20419.00", "0.130"], ["56495.00", "0.000"], ["69393.90", "0.009"], ["69559.80", "0.002"], ["69627.90", "0.000"], ["69912.80", "1.428"], ["70265.90", "0.036"], ["70583.70", "0.001"], ["70612.00", "0.098"]], "a": [["70626.10", "0.030"], ["70654.40", "0.023"], ["71325.30", "1.120"], ["71572.50", "0.837"], ["74160.90", "0.000"], ["74179.00", "0.145"], ["89523.20", "0.000"]]}}
{"local_ts": 1773486840642, "server_ts": 1773486840612, "data": {"e": "depthUpdate", "E": 1773486840613, "T": 1773486840612, "s": "BTCUSDT", "U": 10109527212090, "u": 10109527223073, "pu": 10109527211995, "b": [["1000.00", "26.292"], ["5000.00", "101.398"], ["7061.90", "0.056"], ["20119.00", "0.140"], ["20219.00", "2.430"], ["20319.00", "0.430"], ["33000.00", "3.789"], ["56495.00", "0.000"], ["69221.60", "0.000"], ["69343.10", "0.575"], ["69574.80", "0.627"], ["69730.20", "0.000"], ["69912.80", "1.428"], ["69928.00", "0.074"], ["70471.60", "0.086"], ["70589.80", "0.100"], ["70589.90", "0.219"], ["70598.80", "0.374"], ["70599.70", "0.148"], ["70604.00", "0.095"], ["70604.80", "0.207"], ["70612.00", "0.742"], ["70614.30", "0.009"], ["70615.90", "0.003"], ["70617.40", "0.229"], ["70617.60", "0.080"], ["70618.00", "0.000"], ["70618.30", "0.000"], ["70618.80", "0.000"], ["70619.00", "6.174"]], "a": [["70619.30", "0.042"], ["70619.50", "0.059"], ["70620.30", "0.018"], ["70621.50", "0.003"], ["70621.80", "0.002"], ["70623.10", "0.017"], ["70624.20", "0.021"], ["70635.10", "0.612"], ["70643.10", "1.073"], ["70645.00", "0.004"], ["70646.90", "1.189"], ["70648.90", "0.002"], ["70671.40", "0.550"], ["70674.60", "0.093"], ["70693.20", "0.004"], ["70704.90", "0.069"], ["70740.90", "0.170"], ["70746.70", "0.275"], ["70843.10", "0.283"], ["71325.10", "0.000"], ["71325.30", "1.122"], ["71342.30", "0.005"], ["71540.10", "0.000"], ["71690.70", "0.000"], ["71695.50", "1.212"], ["71713.70", "2.925"], ["74151.60", "0.000"], ["89523.20", "0.000"]]}}
{"local_ts": 1773486841663, "server_ts": 1773486841634, "data": {"e": "depthUpdate", "E": 1773486841635, "T": 1773486841634, "s": "BTCUSDT", "U": 10109527274033, "u": 10109527279353, "pu": 10109527274017, "b": [["5000.00", "101.418"], ["7061.90", "0.056"], ["20119.00", "2.270"], ["20219.00", "0.730"], ["67066.50", "0.000"], ["67088.20", "0.006"], ["69484.40", "0.000"], ["69517.30", "0.287"], ["69765.40", "0.286"], ["69912.80", "1.428"], ["70156.00", "1.860"], ["70408.20", "0.260"], ["70572.20", "0.280"], ["70572.30", "0.003"], ["70594.90", "0.082"], ["70608.70", "1.581"], ["70608.80", "1.049"], ["70612.00", "0.034"]], "a": [["70619.10", "55.404"], ["70622.40", "0.008"], ["70626.10", "0.004"], ["70635.30", "0.007"], ["70636.30", "0.009"], ["70666.50", "0.002"], ["70668.00", "0.020"], ["70674.60", "0.091"], ["70704.90", "0.067"], ["70843.00", "0.299"], ["70999.90", "4.247"], ["71000.00", "26.104"], ["71325.30", "2.520"], ["73443.80", "0.032"], ["74178.40", "0.002"], ["89523.20", "0.000"]]}}
{"local_ts": 1773486842687, "server_ts": 1773486842656, "data": {"e": "depthUpdate", "E": 1773486842657, "T": 1773486842656, "s": "BTCUSDT", "U": 10109527317603, "u": 10109527322822, "pu": 10109527317520, "b": [["1000.00", "26.292"], ["5000.00", "101.418"], ["7061.90", "0.056"], ["20119.00", "1.170"], ["20519.00", "1.830"], ["56495.00", "0.000"], ["67088.10", "0.004"], ["67088.20", "0.010"], ["69912.80", "1.435"], ["70435.40", "2.399"], ["70521.50", "0.982"], ["70527.90", "0.142"], ["70528.50", "0.071"], ["70534.90", "0.144"], ["70535.60", "0.071"], ["70542.00", "0.846"], ["70572.20", "0.278"], ["70572.30", "0.005"], ["70596.30", "0.000"], ["70598.20", "0.251"], ["70609.50", "0.064"], ["70609.80", "0.005"], ["70610.50", "0.647"], ["70611.00", "0.004"], ["70612.00", "0.062"]], "a": [["70619.10", "55.395"], ["70622.80", "0.000"], ["70623.00", "0.023"], ["70623.50", "0.000"], ["70625.40", "0.071"], ["70625.60", "0.026"], ["70626.10", "0.073"], ["70645.30", "0.005"], ["70646.00", "0.636"], ["70653.00", "0.002"], ["70654.00", "0.315"], ["70666.50", "0.000"], ["70668.00", "0.018"], ["70675.00", "0.701"], ["70686.10", "0.146"], ["70697.50", "0.024"], ["70697.60", "0.253"], ["70698.10", "0.073"], ["70704.60", "0.375"], ["70704.70", "0.399"], ["70705.20", "0.071"], ["70711.60", "0.000"], ["70711.70", "0.223"], ["70712.20", "0.071"], ["71325.20", "0.565"], ["71325.30", "2.527"], ["71713.70", "3.272"], ["74165.50", "0.050"], ["74169.30", "0.002"], ["89523.20", "0.000"]]}}
{"local_ts": 1773486843708, "server_ts": 1773486843680, "data": {"e": "depthUpdate", "E": 1773486843681, "T": 1773486843680, "s": "BTCUSDT", "U": 10109527361107, "u": 10109527365794, "pu": 10109527360952, "b": [["5000.00", "101.418"], ["7061.90", "0.028"], ["20419.00", "1.390"], ["20519.00", "1.610"], ["49433.30", "0.000"], ["69483.00", "4.742"], ["69588.90", "21.261"], ["69912.80", "1.435"], ["70435.40", "2.399"], ["70483.90", "0.000"], ["70484.00", "0.662"], ["70531.00", "0.074"], ["70531.70", "1.518"], ["70533.40", "0.081"], ["70533.70", "0.231"], ["70534.10", "1.182"], ["70572.00", "0.097"], ["70572.10", "0.096"], ["70591.40", "0.186"], ["70609.50", "0.021"], ["70611.30", "0.017"], ["70612.00", "0.060"], ["70613.10", "0.008"], ["70615.00", "0.424"], ["70616.00", "0.005"]], "a": [["70619.10", "55.436"], ["70622.90", "0.004"], ["70623.70", "0.005"], ["70624.50", "0.012"], ["70625.20", "0.000"], ["70626.10", "0.073"], ["70626.20", "0.094"], ["70629.70", "0.010"], ["70637.20", "0.004"], ["70643.20", "0.090"], ["70653.10", "5.566"], ["70654.00", "0.068"], ["70671.90", "0.513"], ["70675.00", "0.699"], ["70679.50", "0.566"], ["70686.10", "0.144"], ["70750.20", "0.426"], ["71325.30", "2.527"], ["73443.80", "0.038"], ["74172.90", "0.000"], ["89523.20", "0.000"]]}}
{"local_ts": 1773486844730, "server_ts": 1773486844700, "data": {"e": "depthUpdate", "E": 1773486844701, "T": 1773486844700, "s": "BTCUSDT", "U": 10109527397518, "u": 10109527402215, "pu": 10109527397432, "b": [["1000.00", "26.292"], ["5000.00", "101.398"], ["7061.90", "0.028"], ["20319.00", "0.930"], ["20419.00", "2.070"], ["62622.30", "0.000"], ["67066.10", "0.000"], ["69489.10", "3.446"], ["69553.10", "2.871"], ["69595.00", "3.982"], ["69912.80", "2.863"], ["70089.40", "1.453"], ["70265.90", "0.036"], ["70361.00", "0.074"], ["70364.00", "0.002"], ["70365.80", "2.508"], ["70366.80", "0.585"], ["70408.10", "0.289"], ["70445.20", "4.020"], ["70484.00", "0.662"], ["70561.30", "0.005"], ["70570.20", "0.560"], ["70590.90", "1.026"], ["70591.00", "0.350"], ["70591.40", "0.186"], ["70591.60", "0.356"], ["70601.50", "0.001"], ["70602.30", "0.083"], ["70603.00", "0.509"], ["70603.60", "0.192"], ["70604.20", "0.003"], ["70608.40", "0.010"], ["70609.80", "0.005"], ["70610.20", "0.637"], ["70610.80", "0.064"], ["70611.10", "0.012"], ["70612.00", "0.099"], ["70618.30", "0.000"], ["70619.00", "5.692"]], "a": [["70620.40", "0.001"], ["70621.10", "0.001"], ["70622.00", "0.035"], ["70622.40", "0.008"], ["70623.10", "0.002"], ["70623.20", "0.028"], ["70623.70", "0.005"], ["70626.10", "0.030"], ["70649.10", "0.000"], ["70650.00", "4.528"], ["70650.90", "0.025"], ["70653.00", "0.002"], ["70654.00", "0.315"], ["70670.10", "0.002"], ["70671.90", "0.511"], ["70673.00", "0.004"], ["70679.50", "0.564"], ["70750.20", "0.425"], ["70789.00", "2.792"], ["70826.10", "0.236"], ["70864.10", "0.000"], ["70868.50", "1.251"], ["71325.30", "3.927"], ["71629.50", "0.702"], ["71652.00", "0.000"], ["89523.20", "0.000"]]}}
{"local_ts": 1773486845748, "server_ts": 1773486845720, "data": {"e": "depthUpdate", "E": 1773486845721, "T": 1773486845720, "s": "BTCUSDT", "U": 10109527436659, "u": 10109527439619, "pu": 10109527436626, "b": [["1000.00", "26.292"], ["5000.00", "101.398"], ["7061.90", "0.028"], ["20219.00", "0.490"], ["20319.00", "2.510"], ["20419.00", "0.000"], ["33000.00", "3.785"], ["67067.90", "0.002"], ["69383.20", "4.605"], ["69595.00", "10.007"], ["69598.00", "6.101"], ["69771.60", "2.573"], ["69912.80", "2.863"], ["70435.40", "2.399"], ["70461.50", "0.452"], ["70462.80", "0.190"], ["70466.90", "0.378"], ["70480.90", "0.000"], ["70482.30", "0.000"], ["70483.80", "0.834"], ["70527.80", "0.142"], ["70527.90", "0.000"], ["70534.80", "0.219"], ["70534.90", "0.002"], ["70541.90", "0.661"], ["70542.00", "0.704"], ["70570.30", "0.039"], ["70580.70", "0.005"], ["70604.80", "0.233"], ["70608.40", "0.007"], ["70611.30", "0.014"], ["70611.50", "0.005"], ["70612.00", "0.099"]], "a": [["70619.10", "55.238"], ["70622.30", "0.212"], ["70623.40", "0.010"], ["70623.60", "0.005"], ["70624.10", "0.000"], ["70624.20", "0.000"], ["70624.40", "0.002"], ["70625.90", "0.016"], ["70626.10", "0.030"], ["70626.20", "0.026"], ["70629.70", "0.013"], ["70636.80", "0.007"], ["70697.40", "0.142"], ["70697.60", "0.111"], ["70704.50", "0.144"], ["70704.70", "0.257"], ["70711.50", "0.142"], ["70711.70", "0.081"], ["70774.70", "0.190"], ["70789.40", "0.006"], ["71325.30", "3.927"], ["71537.80", "0.000"], ["71540.20", "8.886"], ["71657.20", "3.901"], ["71784.30", "1.948"], ["89523.20", "0.000"]]}}
{"local_ts": 1773486846770, "server_ts": 1773486846740, "data": {"e": "depthUpdate", "E": 1773486846741, "T": 1773486846740, "s": "BTCUSDT", "U": 10109527478544, "u": 10109527481853, "pu": 10109527478465, "b": [["5000.00", "101.418"], ["7061.90", "0.000"], ["20119.00", "0.250"], ["20219.00", "2.540"], ["20319.00", "0.210"], ["67073.60", "0.000"], ["69324.10", "1.442"], ["69906.70", "3.720"], ["69912.80", "2.863"], ["70266.10", "0.138"], ["70372.60", "0.004"], ["70521.80", "0.032"], ["70528.80", "0.095"], ["70535.90", "0.085"], ["70588.60", "0.170"], ["70591.40", "0.186"], ["70591.50", "0.184"], ["70608.40", "0.010"], ["70611.40", "0.022"], ["70611.50", "0.005"], ["70612.00", "0.097"], ["70619.00", "5.692"]], "a": [["70619.10", "55.216"], ["70623.00", "0.023"], ["70626.10", "0.030"], ["70626.70", "0.002"], ["70629.70", "0.013"], ["70632.70", "0.000"], ["70698.40", "0.344"], ["70705.50", "0.071"], ["70712.50", "6.606"], ["70746.70", "0.275"], ["70747.80", "0.002"], ["70770.90", "0.161"], ["71325.30", "3.927"], ["71537.10", "6.422"], ["71600.70", "3.414"], ["71619.40", "0.278"], ["71643.10", "13.383"], ["71742.70", "2.644"], ["72336.20", "1.184"], ["89523.20", "0.000"]]}}
{"local_ts": 1773486847791, "server_ts": 1773486847760, "data": {"e": "depthUpdate", "E": 1773486847763, "T": 1773486847760, "s": "BTCUSDT", "U": 10109527520013, "u": 10109527523527, "pu": 10109527519872, "b": [["1000.00", "26.692"], ["5000.00", "101.418"], ["7061.90", "0.000"], ["20119.00", "2.390"], ["20219.00", "0.510"], ["20519.00", "0.100"], ["33000.00", "3.785"], ["67088.00", "0.050"], ["69912.80", "2.863"], ["70100.10", "3.739"], ["70222.10", "16.020"], ["70265.90", "0.036"], ["70302.10", "0.000"], ["70484.30", "0.757"], ["70571.60", "0.795"], ["70571.80", "0.003"], ["70591.50", "0.283"], ["70591.60", "0.356"], ["70591.70", "0.185"], ["70595.20", "0.005"], ["70598.70", "1.043"], ["70599.30", "0.000"], ["70602.00", "1.242"], ["70602.90", "0.002"], ["70605.60", "0.144"], ["70606.30", "0.021"], ["70608.40", "0.014"], ["70612.00", "0.029"], ["70612.10", "0.429"], ["70613.90", "0.342"], ["70615.10", "0.020"], ["70615.50", "0.000"], ["70616.30", "0.000"]], "a": [["70619.10", "55.214"], ["70621.20", "0.004"], ["70626.10", "0.002"], ["70626.20", "0.094"], ["70747.80", "0.002"], ["70750.20", "0.424"], ["70843.30", "0.002"], ["70843.40", "0.013"], ["70945.00", "2.986"], ["71051.50", "0.000"], ["71059.80", "7.403"], ["71179.40", "3.271"], ["71325.30", "3.927"], ["71713.70", "9.122"], ["72031.40", "0.010"], ["73443.80", "0.044"], ["74168.20", "0.002"], ["89523.20", "0.000"]]}}
{"local_ts": 1773486848815, "server_ts": 1773486848786, "data": {"e": "depthUpdate", "E": 1773486848787, "T": 1773486848786, "s": "BTCUSDT", "U": 10109527556088, "u": 10109527558563, "pu": 10109527556086, "b": [["5000.00", "101.418"], ["7061.90", "0.000"], ["20119.00", "0.850"], ["20519.00", "2.150"], ["56495.00", "0.000"], ["69439.80", "0.000"], ["69581.00", "1.869"], ["69733.80", "0.000"], ["69912.80", "2.863"], ["70266.00", "1.134"], ["70372.40", "0.004"], ["70461.70", "0.097"], ["70472.30", "19.490"], ["70521.90", "0.019"], ["70528.90", "0.071"], ["70530.60", "6.435"], ["70534.00", "0.173"], ["70534.70", "0.597"], ["70536.00", "0.093"], ["70536.40", "0.081"], ["70536.70", "0.322"], ["70537.10", "0.522"], ["70565.60", "3.333"], ["70571.30", "0.068"], ["70571.80", "0.003"], ["70571.90", "0.010"], ["70591.50", "0.184"], ["70607.50", "0.062"], ["70608.60", "0.004"], ["70609.70", "0.289"], ["70610.10", "0.046"], ["70612.20", "0.741"], ["70615.70", "0.004"], ["70615.90", "0.060"], ["70616.20", "0.002"]], "a": [["70619.10", "55.304"], ["70624.00", "0.043"], ["70629.60", "0.013"], ["70629.70", "0.010"], ["70664.70", "0.049"], ["70698.50", "0.071"], ["70705.60", "0.071"], ["70712.60", "0.090"], ["70747.80", "0.000"], ["70778.30", "0.002"], ["70843.10", "0.276"], ["71325.30", "3.927"], ["74164.10", "0.007"], ["74164.20", "0.000"], ["74172.90", "0.002"], ["89523.20", "0.000"]]}}
{"local_ts": 1773486849837, "server_ts": 1773486849808, "data": {"e": "depthUpdate", "E": 1773486849809, "T": 1773486849808, "s": "BTCUSDT", "U": 10109527584821, "u": 10109527587259, "pu": 10109527584785, "b": [["1000.00", "26.842"], ["5000.00", "101.418"], ["7061.90", "0.056"], ["20419.00", "1.710"], ["20519.00", "1.290"], ["33000.00", "3.789"], ["67055.10", "0.005"], ["68619.00", "0.243"], ["69121.20", "0.000"], ["69698.50", "67.959"], ["69908.30", "54.383"], ["69912.80", "4.291"], ["70025.70", "0.000"], ["70069.40", "45.252"], ["70195.80", "37.578"], ["70195.90", "5.861"], ["70265.90", "0.036"], ["70287.10", "0.000"], ["70431.90", "0.027"], ["70435.40", "2.399"], ["70460.10", "0.100"], ["70471.20", "12.676"], ["70522.00", "0.017"], ["70529.00", "0.002"], ["70530.20", "6.939"], ["70536.10", "0.006"], ["70562.50", "0.656"], ["70565.30", "3.393"], ["70574.20", "0.004"], ["70581.50", "0.018"], ["70591.50", "0.014"], ["70614.00", "0.024"], ["70614.50", "0.003"], ["70616.30", "0.010"], ["70617.60", "0.095"], ["70617.90", "0.010"], ["70618.20", "0.000"], ["70618.50", "0.000"], ["70618.80", "0.021"], ["70618.90", "0.007"]], "a": [["70619.10", "55.304"], ["70620.40", "0.009"], ["70624.00", "0.064"], ["70643.20", "0.092"], ["70676.20", "4.055"], ["70698.60", "0.886"], ["70705.70", "0.007"], ["70711.60", "6.704"], ["70712.70", "0.011"], ["70770.90", "0.161"], ["70771.00", "12.468"], ["70778.00", "0.267"], ["70778.30", "0.000"], ["70785.10", "0.000"], ["70786.30", "0.002"], ["70945.00", "7.477"], ["70945.10", "32.631"], ["71325.30", "5.327"], ["71343.10", "55.846"], ["71557.10", "64.840"], ["71607.70", "0.000"], ["89523.20", "0.000"]]}}
{"local_ts": 1773486850872, "server_ts": 1773486850828, "data": {"e": "depthUpdate", "E": 1773486850829, "T": 1773486850828, "s": "BTCUSDT", "U": 10109527620687, "u": 10109527625608, "pu": 10109527620611, "b": [["1000.00", "26.442"], ["5000.00", "101.398"], ["7061.90", "0.056"], ["20319.00", "1.260"], ["20419.00", "1.740"], ["67053.50", "0.000"], ["67794.30", "0.044"], ["69912.80", "4.291"], ["69912.90", "0.000"], ["70054.00", "0.389"], ["70304.80", "0.061"], ["70612.90", "0.480"]], "a": [["70619.10", "55.127"], ["70624.00", "0.043"], ["70750.70", "7.950"], ["70786.30", "0.000"], ["71325.30", "5.327"]]}}
{"local_ts": 1773486851878, "server_ts": 1773486851850, "data": {"e": "depthUpdate", "E": 1773486851851, "T": 1773486851850, "s": "BTCUSDT", "U": 10109527662768, "u": 10109527666326, "pu": 10109527662743, "b": [["5000.00", "101.418"], ["7061.90", "0.056"], ["20219.00", "0.810"], ["20319.00", "2.190"], ["63557.10", "0.008"], ["67056.90", "0.007"], ["69206.70", "0.015"], ["69606.60", "2.894"], ["70054.00", "0.532"], ["70266.00", "1.138"], ["70372.40", "0.000"], ["70435.40", "2.399"], ["70522.10", "0.108"], ["70529.10", "0.410"], ["70536.20", "0.089"], ["70591.40", "0.186"], ["70591.50", "0.198"], ["70616.00", "0.020"], ["70616.10", "0.000"], ["70616.20", "0.002"], ["70616.40", "0.000"], ["70616.50", "0.000"], ["70616.60", "0.025"], ["70616.70", "0.002"], ["70616.80", "0.000"], ["70616.90", "0.001"], ["70617.10", "0.000"], ["70617.20", "0.000"], ["70617.30", "0.004"], ["70617.40", "0.214"], ["70617.50", "0.002"], ["70617.60", "0.080"], ["70617.80", "0.002"]], "a": [["70655.40", "0.002"], ["70656.40", "0.052"], ["70698.70", "0.072"], ["70705.80", "0.285"], ["70712.80", "0.290"], ["70770.90", "0.101"], ["71116.30", "0.061"], ["71200.40", "0.019"], ["71325.30", "5.327"], ["73443.80", "0.054"], ["74180.00", "29.822"], ["77681.00", "0.002"]]}}
{"local_ts": 1773486852902, "server_ts": 1773486852872, "data": {"e": "depthUpdate", "E": 1773486852873, "T": 1773486852872, "s": "BTCUSDT", "U": 10109527701460, "u": 10109527704562, "pu": 10109527701291, "b": [["1000.00", "26.442"], ["5000.00", "101.418"], ["7061.90", "0.028"], ["20119.00", "0.400"], ["20219.00", "2.570"], ["20319.00", "0.030"], ["63557.10", "0.008"], ["67057.60", "0.000"], ["69531.10", "0.000"], ["69531.50", "0.000"], ["69665.40", "5.515"], ["69912.80", "4.291"], ["70406.50", "0.000"], ["70445.80", "3.883"], ["70447.50", "0.320"], ["70484.60", "0.837"], ["70522.10", "0.091"], ["70522.20", "0.019"], ["70529.10", "0.339"], ["70529.20", "0.487"], ["70536.20", "0.018"], ["70536.30", "0.073"], ["70591.40", "0.356"], ["70591.50", "0.198"]], "a": [["70624.00", "0.043"], ["70626.20", "0.064"], ["70633.30", "0.107"], ["70698.70", "0.001"], ["70698.80", "0.213"], ["70705.80", "0.214"], ["70705.90", "0.072"], ["70712.80", "0.219"], ["70712.90", "0.165"], ["70750.10", "0.426"], ["70789.00", "2.817"], ["70843.10", "0.283"], ["71325.20", "0.565"], ["71325.30", "5.327"], ["71572.50", "1.394"], ["74174.90", "0.004"], ["77681.00", "0.002"]]}}
{"local_ts": 1773486853928, "server_ts": 1773486853897, "data": {"e": "depthUpdate", "E": 1773486853899, "T": 1773486853897, "s": "BTCUSDT", "U": 10109527737320, "u": 10109527741600, "pu": 10109527737218, "b": [["5000.00", "101.418"], ["7061.90", "0.028"], ["20119.00", "2.490"], ["20219.00", "0.290"], ["20519.00", "0.220"], ["56495.00", "0.000"], ["63557.10", "0.008"], ["69206.70", "0.012"], ["69771.60", "7.296"], ["69912.80", "4.291"], ["70054.00", "0.603"], ["70435.40", "2.399"], ["70484.60", "0.176"], ["70522.20", "0.019"], ["70529.20", "0.487"], ["70531.40", "0.154"], ["70532.10", "0.067"], ["70533.80", "0.151"], ["70534.10", "1.227"], ["70534.50", "0.072"], ["70536.30", "0.073"], ["70591.40", "0.370"], ["70591.50", "0.014"], ["70591.60", "0.172"], ["70596.30", "0.000"], ["70598.20", "0.251"], ["70604.80", "0.286"], ["70610.60", "0.057"], ["70610.90", "0.002"], ["70611.10", "0.011"], ["70611.20", "0.519"], ["70611.90", "0.024"], ["70619.00", "5.273"]], "a": [["70619.10", "54.883"], ["70624.90", "0.054"], ["70625.90", "0.058"], ["70626.40", "0.064"], ["70628.40", "0.028"], ["70629.70", "0.013"], ["70632.50", "0.005"], ["70641.10", "0.001"], ["70642.30", "0.548"], ["70644.80", "0.511"], ["70646.70", "0.000"], ["70698.80", "0.213"], ["70705.90", "0.072"], ["70712.90", "0.165"], ["70750.10", "0.000"], ["71184.10", "4.743"], ["71325.30", "5.327"], ["71466.50", "6.428"], ["71843.40", "4.200"], ["73443.80", "0.058"], ["74169.10", "0.002"], ["77681.00", "0.002"]]}}
{"local_ts": 1773486854954, "server_ts": 1773486854916, "data": {"e": "depthUpdate", "E": 1773486854919, "T": 1773486854916, "s": "BTCUSDT", "U": 10109527771589, "u": 10109527773979, "pu": 10109527771558, "b": [["1000.00", "26.442"], ["5000.00", "101.418"], ["7061.90", "0.028"], ["20119.00", "0.590"], ["20419.00", "0.070"], ["20519.00", "2.340"], ["63557.10", "0.008"], ["67075.10", "0.006"], ["67079.00", "0.002"], ["67794.30", "0.052"], ["69912.80", "5.719"], ["70265.90", "0.036"], ["70522.20", "0.002"], ["70522.30", "0.017"], ["70529.20", "0.416"], ["70529.30", "0.073"], ["70536.30", "0.002"], ["70536.40", "0.073"], ["70596.30", "0.247"], ["70598.20", "0.004"]], "a": [["70622.30", "0.269"], ["70646.90", "0.696"], ["70698.80", "0.142"], ["70698.90", "0.074"], ["70705.90", "0.001"], ["70706.00", "0.113"], ["70712.90", "0.094"], ["70713.00", "0.317"], ["71325.30", "5.327"], ["72748.70", "0.000"], ["77681.00", "0.002"]]}}
{"local_ts": 1773486855968, "server_ts": 1773486855936, "data": {"e": "depthUpdate", "E": 1773486855939, "T": 1773486855936, "s": "BTCUSDT", "U": 10109527804844, "u": 10109527808044, "pu": 10109527804827, "b": [["1000.00", "26.442"], ["5000.00", "101.418"], ["7061.90", "0.000"], ["20419.00", "2.030"], ["20519.00", "0.970"], ["63557.10", "0.006"], ["67065.40", "0.002"], ["69623.30", "1.434"], ["69912.80", "5.719"], ["70265.90", "0.072"], ["70522.30", "0.017"], ["70529.30", "0.073"], ["70536.40", "0.073"], ["70608.90", "0.001"]], "a": [["70698.90", "0.074"], ["70706.00", "0.113"], ["70713.00", "0.317"], ["70842.80", "0.000"], ["70972.20", "3.201"], ["71325.20", "0.572"], ["71325.30", "5.327"], ["71388.80", "2.666"], ["73443.80", "0.066"], ["77681.00", "0.000"]]}}
{"local_ts": 1773486856987, "server_ts": 1773486856960, "data": {"e": "depthUpdate", "E": 1773486856961, "T": 1773486856960, "s": "BTCUSDT", "U": 10109527840216, "u": 10109527843485, "pu": 10109527840113, "b": [["5000.00", "101.418"], ["7061.90", "0.000"], ["20319.00", "1.590"], ["20419.00", "1.410"], ["33000.00", "3.785"], ["56495.00", "0.000"], ["63557.10", "0.006"], ["67088.00", "0.050"], ["69362.10", "0.003"], ["69540.00", "0.074"], ["69912.80", "5.719"], ["70266.00", "1.138"], ["70372.70", "0.004"], ["70522.30", "0.017"], ["70529.30", "0.073"], ["70536.40", "0.073"], ["70572.80", "0.282"], ["70573.00", "0.281"], ["70609.30", "0.005"], ["70609.40", "0.186"], ["70609.50", "0.023"], ["70609.90", "0.638"], ["70610.50", "0.010"], ["70611.20", "0.516"], ["70612.00", "0.021"], ["70618.70", "0.000"], ["70618.80", "0.036"], ["70619.00", "5.132"]], "a": [["70619.10", "54.652"], ["70619.50", "0.059"], ["70619.70", "0.010"], ["70619.90", "0.001"], ["70620.10", "0.005"], ["70620.80", "0.000"], ["70621.20", "0.005"], ["70623.10", "0.002"], ["70624.40", "0.017"], ["70624.80", "0.004"], ["70624.90", "0.691"], ["70625.70", "0.015"], ["70626.10", "0.002"], ["70626.20", "0.118"], ["70629.70", "0.005"], ["70632.50", "0.002"], ["70633.30", "0.080"], ["70634.70", "0.018"], ["70636.00", "0.015"], ["70645.50", "0.016"], ["70646.00", "0.636"], ["70647.90", "0.001"], ["70652.80", "0.021"], ["70654.00", "0.315"], ["70660.70", "0.007"], ["70698.90", "0.003"], ["70699.00", "0.313"], ["70706.00", "0.042"], ["70706.10", "0.073"], ["70713.00", "0.246"], ["70713.10", "0.351"], ["70770.90", "0.161"], ["70842.60", "1.076"], ["71325.10", "0.000"], ["71325.30", "5.327"], ["71572.50", "3.624"], ["71686.00", "5.264"], ["74155.30", "0.002"], ["74184.80", "0.000"], ["77681.00", "0.000"]]}}
{"local_ts": 1773486858009, "server_ts": 1773486857980, "data": {"e": "depthUpdate", "E": 1773486857981, "T": 1773486857980, "s": "BTCUSDT", "U": 10109527870965, "u": 10109527873585, "pu": 10109527870920, "b": [["1000.00", "26.442"], ["5000.00", "101.418"], ["7061.90", "0.000"], ["20219.00", "1.140"], ["20319.00", "1.860"], ["63557.10", "0.006"], ["67067.20", "0.002"], ["69912.80", "5.719"], ["69912.90", "0.000"], ["70265.90", "0.108"], ["70372.60", "0.004"], ["70372.80", "0.002"], ["70522.40", "0.017"], ["70529.40", "0.114"], ["70536.50", "0.083"], ["70572.60", "1.086"], ["70572.80", "0.280"], ["70591.50", "0.184"], ["70595.10", "0.007"], ["70595.70", "0.000"], ["70596.30", "0.000"], ["70598.20", "0.251"], ["70604.80", "0.260"], ["70608.40", "0.007"], ["70609.60", "0.192"], ["70611.20", "0.516"], ["70611.90", "0.087"], ["70617.80", "0.002"]], "a": [["70619.10", "54.577"], ["70621.70", "0.008"], ["70623.90", "0.008"], ["70625.20", "0.003"], ["70626.20", "0.118"], ["70626.50", "0.004"], ["70626.60", "0.020"], ["70626.80", "0.008"], ["70627.70", "0.004"], ["70627.90", "0.126"], ["70629.70", "0.005"], ["70632.50", "0.005"], ["70633.30", "0.080"], ["70637.20", "0.019"], ["70699.00", "0.313"], ["70706.10", "0.073"], ["70713.10", "0.351"], ["70764.10", "0.000"], ["70767.20", "0.002"], ["70843.00", "0.292"], ["71325.20", "0.572"], ["71325.30", "6.027"], ["71631.50", "2.090"], ["77681.00", "0.000"]]}}
{"local_ts": 1773486859030, "server_ts": 1773486859001, "data": {"e": "depthUpdate", "E": 1773486859003, "T": 1773486859001, "s": "BTCUSDT", "U": 10109527905262, "u": 10109527908389, "pu": 10109527905211, "b": [["5000.00", "101.418"], ["7061.90", "0.056"], ["20119.00", "0.690"], ["20219.00", "2.310"], ["20319.00", "0.000"], ["33000.00", "3.789"], ["63557.10", "0.006"], ["67075.10", "0.006"], ["67088.10", "0.010"], ["69665.40", "1.933"], ["70484.90", "0.966"], ["70522.40", "0.017"], ["70529.40", "0.114"], ["70534.50", "0.148"], ["70535.10", "0.046"], ["70536.50", "0.083"], ["70536.80", "0.194"], ["70537.20", "0.210"], ["70537.50", "0.072"]], "a": [["70621.10", "0.073"], ["70626.20", "0.102"], ["70638.30", "0.002"], ["70646.20", "0.237"], ["70657.20", "0.713"], ["70699.00", "0.242"], ["70699.10", "0.071"], ["70706.10", "0.002"], ["70706.20", "0.076"], ["70713.10", "0.280"], ["70713.20", "0.074"], ["70750.10", "0.424"], ["70765.10", "0.002"], ["70767.20", "0.000"], ["70770.90", "0.101"], ["70855.70", "0.000"], ["70968.10", "0.000"], ["71325.30", "6.027"], ["71643.10", "19.936"], ["71854.90", "3.336"], ["71952.90", "0.000"], ["71962.80", "0.062"], ["74176.70", "0.002"], ["77681.00", "0.000"]]}}
{"local_ts": 1773486860053, "server_ts": 1773486860021, "data": {"e": "depthUpdate", "E": 1773486860023, "T": 1773486860021, "s": "BTCUSDT", "U": 10109527935935, "u": 10109527938833, "pu": 10109527935928, "b": [["1000.00", "26.592"], ["5000.00", "101.418"], ["7061.90", "0.056"], ["20119.00", "2.600"], ["20219.00", "0.080"], ["20519.00", "0.320"], ["56495.00", "0.000"], ["63557.10", "0.006"], ["67068.50", "0.002"], ["69541.60", "0.430"], ["69912.80", "6.433"], ["70195.90", "0.000"], ["70265.90", "0.108"], ["70301.30", "0.000"], ["70378.70", "0.000"], ["70447.50", "0.320"], ["70595.10", "0.000"], ["70596.10", "1.076"], ["70596.30", "0.000"], ["70598.20", "0.392"], ["70598.80", "0.118"], ["70607.40", "0.000"], ["70607.80", "0.008"], ["70618.10", "0.010"]], "a": [["70620.40", "0.001"], ["70620.80", "0.007"], ["70620.90", "0.003"], ["70621.40", "0.000"], ["70624.00", "0.045"], ["70624.80", "0.654"], ["70625.50", "0.057"], ["70625.80", "0.002"], ["70626.30", "0.007"], ["70627.60", "0.008"], ["70628.10", "0.002"], ["70628.40", "0.009"], ["70628.90", "0.008"], ["70629.10", "0.085"], ["70630.20", "0.240"], ["70630.30", "0.150"], ["70631.60", "0.004"], ["70632.80", "0.006"], ["70632.90", "0.023"], ["70633.50", "0.432"], ["70633.70", "0.019"], ["70634.20", "0.002"], ["70634.90", "0.040"], ["70635.50", "0.400"], ["70636.10", "0.005"], ["70636.20", "0.020"], ["70637.00", "0.355"], ["70637.50", "0.058"], ["70637.90", "1.172"], ["70638.80", "0.018"], ["70640.10", "0.074"], ["70641.30", "0.015"], ["70642.60", "0.017"], ["70643.30", "0.007"], ["70643.90", "0.080"], ["70645.10", "0.015"], ["70646.40", "0.008"], ["70646.70", "0.021"], ["70647.60", "0.014"], ["70648.70", "0.021"], ["70648.90", "0.002"], ["70650.60", "0.038"], ["70658.60", "0.062"], ["70765.10", "0.000"], ["70766.70", "0.006"], ["70842.80", "0.007"], ["70867.00", "0.002"], ["70945.00", "2.986"], ["71051.40", "0.031"], ["71325.30", "6.027"], ["71866.00", "1.828"], ["73443.80", "0.078"], ["77681.00", "0.000"], ["89523.20", "0.000"]]}}
{"local_ts": 1773486861074, "server_ts": 1773486861042, "data": {"e": "depthUpdate", "E": 1773486861043, "T": 1773486861042, "s": "BTCUSDT", "U": 10109528016089, "u": 10109528022927, "pu": 10109528015999, "b": [["1000.00", "26.592"], ["5000.00", "101.418"], ["7062.70", "0.056"], ["20119.00", "0.380"], ["20426.50", "0.170"], ["20519.00", "1.860"], ["20519.40", "0.000"], ["20524.90", "0.110"], ["20526.50", "0.470"], ["69920.20", "0.000"], ["70136.10", "0.005"], ["70261.80", "0.000"], ["70273.30", "0.000"], ["70318.60", "0.000"], ["70324.20", "0.018"], ["70471.10", "0.088"], ["70473.90", "0.000"], ["70488.10", "0.264"], ["70489.20", "0.000"], ["70490.90", "0.266"], ["70499.10", "0.003"], ["70524.50", "0.198"], ["70528.70", "0.002"], ["70534.40", "0.274"], ["70534.80", "0.002"], ["70536.80", "0.194"], ["70537.40", "0.017"], ["70537.50", "0.072"], ["70538.20", "0.010"], ["70544.40", "0.074"], ["70544.50", "0.000"], ["70551.50", "0.162"], ["70551.60", "0.012"], ["70559.80", "0.516"], ["70561.90", "0.853"], ["70567.00", "0.047"], ["70569.70", "0.103"], ["70570.00", "0.285"], ["70574.00", "1.170"], ["70577.10", "0.091"], ["70577.50", "0.004"], ["70581.10", "0.855"], ["70582.20", "8.502"], ["70582.50", "1.068"], ["70582.90", "0.782"], ["70583.70", "0.001"], ["70583.90", "0.000"], ["70585.30", "0.005"], ["70586.70", "0.002"], ["70588.10", "0.002"], ["70588.20", "0.896"], ["70589.50", "0.000"], ["70594.80", "0.215"], ["70595.30", "0.860"], ["70595.80", "0.005"], ["70597.40", "0.008"], ["70598.50", "0.087"], ["70598.90", "0.000"], ["70601.80", "1.078"], ["70602.40", "0.858"], ["70602.60", "0.048"], ["70604.70", "0.000"], ["70605.00", "0.007"], ["70606.40", "0.444"], ["70606.50", "0.000"], ["70610.00", "0.290"], ["70610.40", "0.296"], ["70610.60", "1.308"], ["70610.70", "0.055"], ["70611.30", "0.104"], ["70611.50", "0.002"], ["70612.00", "0.011"], ["70612.10", "0.008"], ["70613.80", "0.016"], ["70614.10", "0.521"], ["70615.70", "0.005"], ["70615.90", "0.006"], ["70616.30", "1.068"], ["70618.60", "0.113"], ["70618.70", "0.342"], ["70619.00", "0.419"], ["70619.40", "0.248"], ["70619.90", "0.003"], ["70620.00", "0.128"], ["70620.70", "0.005"], ["70620.90", "0.072"], ["70621.10", "0.791"], ["70621.30", "0.070"], ["70621.40", "0.189"], ["70622.00", "0.001"], ["70622.10", "0.003"], ["70622.30", "0.003"], ["70622.50", "1.127"], ["70622.80", "0.001"], ["70623.00", "0.084"], ["70623.10", "0.003"], ["70623.20", "0.032"], ["70624.00", "0.000"], ["70624.90", "0.399"], ["70626.40", "0.081"], ["70626.50", "8.763"]], "a": [["70626.60", "4.538"], ["70626.70", "0.001"], ["70626.80", "0.002"], ["70627.00", "0.004"], ["70627.30", "0.000"], ["70628.40", "0.007"], ["70628.80", "0.002"], ["70629.40", "0.008"], ["70629.50", "0.005"], ["70630.10", "0.001"], ["70630.80", "0.009"], ["70631.90", "0.005"], ["70632.70", "0.001"], ["70633.40", "0.004"], ["70634.10", "0.010"], ["70634.50", "0.003"], ["70634.80", "0.003"], ["70635.60", "0.006"], ["70635.80", "0.000"], ["70635.90", "0.020"], ["70637.20", "0.020"], ["70637.30", "0.002"], ["70637.40", "0.004"], ["70638.70", "0.000"], ["70640.20", "0.000"], ["70640.30", "0.008"], ["70640.60", "0.015"], ["70641.00", "0.030"], ["70641.60", "0.024"], ["70642.00", "0.031"], ["70642.10", "0.180"], ["70642.20", "0.072"], ["70642.40", "0.073"], ["70642.50", "0.039"], ["70643.30", "0.021"], ["70644.40", "0.008"], ["70644.60", "0.010"], ["70644.80", "0.003"], ["70645.60", "0.008"], ["70646.30", "0.006"], ["70647.40", "0.003"], ["70647.70", "0.004"], ["70647.80", "0.113"], ["70648.70", "0.080"], ["70648.90", "0.006"], ["70650.70", "0.007"], ["70650.80", "0.009"], ["70651.90", "0.003"], ["70652.10", "0.855"], ["70652.60", "0.061"], ["70652.70", "0.528"], ["70653.00", "0.006"], ["70653.80", "0.255"], ["70654.10", "0.869"], ["70654.40", "0.001"], ["70656.00", "0.040"], ["70656.60", "0.636"], ["70657.60", "0.002"], ["70657.90", "0.007"], ["70659.20", "1.382"], ["70659.50", "0.002"], ["70660.50", "0.000"], ["70661.00", "0.000"], ["70661.40", "0.017"], ["70661.90", "0.039"], ["70664.70", "0.333"], ["70666.30", "0.855"], ["70666.40", "0.087"], ["70669.00", "0.628"], ["70670.40", "0.002"], ["70671.00", "0.093"], ["70671.70", "0.007"], ["70672.40", "0.754"], ["70673.10", "0.021"], ["70673.40", "0.856"], ["70673.60", "0.005"], ["70677.20", "0.024"], ["70677.50", "0.199"], ["70677.90", "1.286"], ["70679.50", "0.001"], ["70680.20", "0.005"], ["70680.50", "0.882"], ["70686.20", "0.038"], ["70688.90", "0.102"], ["70695.30", "8.487"], ["70699.00", "1.020"], ["70702.60", "0.609"], ["70703.90", "0.000"], ["70704.00", "0.047"], ["70705.80", "0.211"], ["70706.40", "0.000"], ["70707.20", "1.508"], ["70707.90", "0.892"], ["70712.10", "0.004"], ["70712.80", "0.202"], ["70713.40", "0.007"], ["70713.70", "0.340"], ["70714.10", "0.071"], ["70715.60", "0.044"], ["70720.80", "0.002"], ["70721.20", "0.114"], ["70727.80", "0.350"], ["70728.10", "1.933"], ["70728.20", "0.071"], ["70735.00", "0.044"], ["70737.50", "0.056"], ["70741.20", "0.116"], ["70748.80", "0.089"], ["70751.00", "0.009"], ["70766.70", "0.090"], ["70767.90", "0.651"], ["70771.30", "2.382"], ["70783.50", "0.092"], ["70808.10", "0.029"], ["70842.80", "0.000"], ["71332.90", "0.023"], ["74183.60", "0.010"], ["89523.20", "0.000"]]}}
{"local_ts": 1773486862092, "server_ts": 1773486862062, "data": {"e": "depthUpdate", "E": 1773486862063, "T": 1773486862062, "s": "BTCUSDT", "U": 10109528074779, "u": 10109528083746, "pu": 10109528074753, "b": [["5000.00", "101.418"], ["7062.70", "0.056"], ["20326.50", "0.020"], ["20426.50", "2.300"], ["20519.00", "0.680"], ["33000.00", "3.785"], ["67065.50", "0.000"], ["67073.80", "0.002"], ["67801.50", "0.008"], ["69666.60", "1.100"], ["69920.20", "0.000"], ["69987.00", "2.242"], ["69994.40", "0.016"], ["70065.60", "0.002"], ["70138.70", "0.010"], ["70273.30", "0.000"], ["70300.00", "22.371"], ["70324.40", "0.004"], ["70534.90", "0.016"], ["70535.60", "0.000"], ["70551.60", "0.010"], ["70566.20", "0.043"], ["70574.00", "1.170"], ["70576.80", "0.475"], ["70580.10", "9.386"], ["70581.10", "0.855"], ["70582.10", "0.460"], ["70588.20", "0.856"], ["70590.00", "1.814"], ["70595.30", "0.860"], ["70595.80", "0.150"], ["70596.70", "0.164"], ["70597.30", "0.074"], ["70597.70", "0.131"], ["70599.80", "0.009"], ["70599.90", "0.065"], ["70600.50", "0.000"], ["70600.60", "0.003"], ["70602.40", "0.858"], ["70603.30", "0.208"], ["70603.40", "0.040"], ["70603.80", "0.929"], ["70604.00", "0.002"], ["70604.10", "0.001"], ["70610.40", "0.002"], ["70613.80", "0.012"], ["70614.90", "0.002"], ["70615.10", "0.007"], ["70616.20", "0.004"], ["70616.30", "1.068"], ["70616.60", "0.025"], ["70616.70", "0.517"], ["70616.80", "0.000"], ["70617.70", "0.003"], ["70618.40", "0.008"], ["70619.40", "0.405"], ["70619.50", "0.971"], ["70619.60", "0.881"], ["70620.00", "0.137"], ["70620.20", "0.001"], ["70620.50", "0.004"], ["70620.70", "0.005"], ["70620.80", "0.000"], ["70620.90", "0.213"], ["70621.00", "0.001"], ["70621.10", "0.226"], ["70621.50", "0.012"], ["70622.30", "0.060"], ["70622.40", "0.001"], ["70622.90", "0.056"], ["70624.30", "0.021"], ["70624.40", "0.004"], ["70624.80", "0.006"]], "a": [["70626.60", "5.508"], ["70626.70", "0.079"], ["70630.80", "0.028"], ["70635.00", "0.654"], ["70637.20", "0.005"], ["70637.50", "0.006"], ["70637.70", "0.531"], ["70638.70", "0.036"], ["70641.60", "0.004"], ["70641.80", "0.199"], ["70642.90", "0.000"], ["70643.10", "0.074"], ["70645.40", "1.180"], ["70646.40", "0.014"], ["70647.90", "0.001"], ["70648.80", "0.212"], ["70652.10", "0.855"], ["70654.30", "0.000"], ["70654.80", "0.674"], ["70657.30", "0.013"], ["70657.40", "0.026"], ["70658.00", "0.006"], ["70658.10", "0.511"], ["70659.20", "0.873"], ["70659.40", "0.004"], ["70659.50", "0.002"], ["70660.10", "0.097"], ["70660.20", "0.000"], ["70660.80", "0.203"], ["70660.90", "0.023"], ["70661.50", "0.289"], ["70661.60", "0.000"], ["70666.30", "0.855"], ["70667.80", "0.002"], ["70673.40", "0.856"], ["70673.60", "0.003"], ["70674.00", "0.008"], ["70680.50", "0.882"], ["70804.00", "0.002"], ["70808.10", "0.027"], ["70908.50", "0.000"], ["70972.20", "3.236"], ["71256.70", "0.042"], ["71264.20", "0.016"], ["71332.90", "0.023"], ["72808.50", "0.000"], ["89523.20", "0.000"]]}}
{"local_ts": 1773486863119, "server_ts": 1773486863088, "data": {"e": "depthUpdate", "E": 1773486863089, "T": 1773486863088, "s": "BTCUSDT", "U": 10109528125554, "u": 10109528130215, "pu": 10109528125501, "b": [["1000.00", "26.592"], ["5000.00", "101.398"], ["7062.70", "0.028"], ["20326.50", "1.910"], ["20426.50", "1.090"], ["56495.00", "0.000"], ["56501.00", "0.121"], ["64803.70", "0.002"], ["67068.30", "0.000"], ["67088.20", "0.008"], ["69920.20", "0.000"], ["70554.30", "1.121"], ["70556.70", "0.097"], ["70558.30", "0.094"], ["70558.80", "1.584"], ["70591.40", "0.499"], ["70593.00", "0.023"], ["70593.70", "0.555"], ["70596.10", "1.071"], ["70600.90", "0.001"], ["70601.50", "0.001"], ["70613.80", "0.082"], ["70613.90", "0.041"], ["70616.20", "0.006"], ["70619.40", "0.351"], ["70619.70", "0.804"], ["70622.00", "0.003"], ["70622.40", "0.006"], ["70626.40", "0.083"]], "a": [["70626.70", "0.107"], ["70627.00", "0.061"], ["70651.70", "0.003"], ["70657.50", "0.004"], ["70672.50", "1.070"], ["70674.00", "0.006"], ["70693.20", "0.000"], ["70694.70", "0.182"], ["70708.80", "0.036"], ["70709.00", "0.235"], ["70710.90", "0.000"], ["70712.60", "0.015"], ["70712.90", "0.000"], ["70726.20", "0.255"], ["70750.90", "0.228"], ["70753.70", "0.093"], ["70758.70", "0.099"], ["70760.70", "0.101"], ["70761.60", "0.097"], ["70768.90", "0.093"], ["70770.20", "0.000"], ["70804.00", "0.000"], ["70850.80", "0.011"], ["71332.80", "0.007"], ["71332.90", "0.023"], ["71396.40", "0.970"], ["71705.00", "0.517"], ["73451.60", "0.008"], ["89523.20", "0.000"]]}}
{"local_ts": 1773486864141, "server_ts": 1773486864108, "data": {"e": "depthUpdate", "E": 1773486864113, "T": 1773486864108, "s": "BTCUSDT", "U": 10109528169574, "u": 10109528174285, "pu": 10109528169440, "b": [["5000.00", "101.418"], ["7062.70", "0.028"], ["20226.50", "1.460"], ["20326.50", "1.540"], ["33000.00", "3.785"], ["64451.50", "0.004"], ["69677.30", "0.716"], ["69920.20", "0.000"], ["70435.80", "0.159"], ["70541.00", "0.148"], ["70541.60", "0.324"], ["70543.30", "0.226"], ["70543.70", "0.136"], ["70544.00", "0.072"], ["70561.10", "0.109"], ["70561.50", "0.013"], ["70569.10", "0.000"], ["70569.50", "0.005"], ["70577.10", "0.086"], ["70577.50", "0.092"], ["70585.20", "0.007"], ["70585.50", "0.520"], ["70591.20", "0.956"], ["70593.00", "0.018"], ["70593.40", "0.005"], ["70613.80", "0.012"], ["70615.90", "0.003"], ["70619.40", "0.404"], ["70626.50", "5.507"]], "a": [["70626.70", "0.119"], ["70637.20", "0.005"], ["70650.60", "0.017"], ["70661.70", "0.450"], ["70661.90", "0.039"], ["70671.90", "0.513"], ["70672.50", "1.068"], ["70676.60", "0.180"], ["70683.90", "0.217"], ["70684.30", "0.066"], ["70684.70", "0.036"], ["70685.60", "1.565"], ["70686.30", "0.078"], ["70692.10", "0.201"], ["70840.00", "0.053"], ["71332.90", "0.023"], ["71791.90", "0.626"], ["72031.40", "0.007"], ["74192.80", "0.002"], ["89523.20", "0.000"]]}}
{"local_ts": 1773486865160, "server_ts": 1773486865132, "data": {"e": "depthUpdate", "E": 1773486865133, "T": 1773486865132, "s": "BTCUSDT", "U": 10109528215381, "u": 10109528219257, "pu": 10109528215287, "b": [["1000.00", "26.592"], ["5000.00", "101.418"], ["7062.70", "0.028"], ["20126.50", "1.020"], ["20226.50", "1.980"], ["69920.20", "0.000"], ["69934.40", "0.714"], ["70273.30", "0.000"], ["70273.40", "0.009"], ["70471.10", "0.088"], ["70531.50", "0.017"], ["70534.70", "1.261"], ["70535.30", "0.558"], ["70538.50", "0.071"], ["70545.60", "0.073"], ["70555.80", "0.049"], ["70557.20", "0.000"], ["70576.10", "0.002"], ["70590.60", "0.009"], ["70613.80", "0.012"], ["70615.90", "0.006"], ["70619.40", "0.407"], ["70625.30", "0.008"], ["70625.90", "0.000"], ["70626.50", "5.533"]], "a": [["70626.60", "4.773"], ["70626.90", "0.054"], ["70627.20", "0.000"], ["70627.60", "0.008"], ["70628.30", "1.915"], ["70629.20", "0.214"], ["70629.90", "0.006"], ["70630.00", "0.057"], ["70630.40", "0.002"], ["70630.50", "0.018"], ["70635.40", "0.156"], ["70637.20", "0.002"], ["70671.90", "0.511"], ["70694.40", "0.912"], ["70708.20", "0.114"], ["70715.30", "0.071"], ["70722.30", "0.071"], ["71332.90", "0.023"], ["74158.90", "0.000"], ["89523.20", "0.000"]]}}
{"local_ts": 1773486866181, "server_ts": 1773486866152, "data": {"e": "depthUpdate", "E": 1773486866153, "T": 1773486866152, "s": "BTCUSDT", "U": 10109528246736, "u": 10109528249742, "pu": 10109528246731, "b": [["1000.00", "26.592"], ["5000.00", "101.418"], ["7062.70", "0.000"], ["20126.50", "2.430"], ["20226.50", "0.000"], ["20526.50", "0.570"], ["20526.60", "0.000"], ["33000.00", "3.789"], ["56501.00", "0.121"], ["63563.90", "0.000"], ["67055.00", "0.042"], ["69877.30", "1.428"], ["69920.20", "0.716"], ["70384.70", "0.165"], ["70531.50", "0.017"], ["70538.50", "0.071"], ["70545.60", "0.073"], ["70570.00", "0.285"], ["70579.00", "0.002"], ["70579.30", "0.021"], ["70595.30", "0.860"], ["70603.90", "0.043"], ["70604.90", "0.014"], ["70605.40", "0.116"], ["70606.50", "0.007"], ["70607.20", "0.000"], ["70608.80", "0.247"], ["70608.90", "0.001"], ["70609.00", "0.010"], ["70609.60", "1.205"], ["70612.20", "0.946"], ["70612.30", "0.132"], ["70613.10", "0.014"], ["70613.20", "0.073"], ["70613.30", "0.000"], ["70613.80", "0.012"], ["70614.10", "0.536"], ["70614.20", "0.070"], ["70619.40", "0.247"], ["70619.70", "0.804"], ["70620.30", "0.637"], ["70620.80", "0.015"], ["70621.00", "0.001"], ["70621.20", "0.029"], ["70623.50", "0.002"], ["70623.60", "0.000"], ["70623.70", "0.001"], ["70623.80", "0.001"], ["70624.00", "0.021"], ["70624.10", "0.006"], ["70624.20", "0.000"], ["70624.30", "0.000"], ["70624.40", "0.004"], ["70626.20", "0.002"]], "a": [["70626.60", "4.890"], ["70626.80", "0.004"], ["70626.90", "0.057"], ["70628.30", "1.912"], ["70629.30", "0.001"], ["70629.50", "0.036"], ["70629.60", "0.010"], ["70630.40", "0.017"], ["70630.60", "0.023"], ["70631.50", "0.000"], ["70644.90", "0.685"], ["70645.00", "0.861"], ["70645.40", "0.010"], ["70646.60", "0.000"], ["70657.50", "0.011"], ["70658.50", "0.002"], ["70659.20", "0.934"], ["70660.60", "0.000"], ["70661.00", "0.070"], ["70661.50", "0.293"], ["70664.60", "0.095"], ["70666.30", "0.855"], ["70672.20", "0.002"], ["70673.40", "0.856"], ["70673.50", "0.002"], ["70679.90", "0.006"], ["70708.20", "0.114"], ["70715.30", "0.071"], ["70722.30", "0.071"], ["71332.90", "0.723"], ["71617.70", "0.000"], ["74174.50", "0.065"], ["74175.80", "0.000"], ["89523.20", "0.000"]]}}
{"local_ts": 1773486867202, "server_ts": 1773486867168, "data": {"e": "depthUpdate", "E": 1773486867173, "T": 1773486867168, "s": "BTCUSDT", "U": 10109528280335, "u": 10109528283521, "pu": 10109528280276, "b": [["5000.00", "101.418"], ["7062.70", "0.000"], ["20126.50", "0.170"], ["20426.50", "0.280"], ["20526.50", "2.550"], ["67095.20", "0.004"], ["69920.20", "0.714"], ["70100.10", "0.499"], ["70206.50", "5.912"], ["70222.10", "18.612"], ["70273.50", "0.006"], ["70280.40", "0.000"], ["70308.60", "0.648"], ["70308.70", "0.113"], ["70384.70", "0.161"], ["70471.10", "0.088"], ["70492.70", "0.618"], ["70578.90", "0.005"], ["70579.00", "0.002"], ["70580.10", "9.388"], ["70590.00", "2.412"], ["70596.70", "0.184"], ["70608.40", "0.007"], ["70612.30", "0.079"], ["70615.90", "0.003"], ["70619.40", "0.302"], ["70624.70", "0.017"], ["70625.30", "0.015"], ["70625.80", "0.002"], ["70626.50", "5.500"]], "a": [["70627.30", "0.000"], ["70627.60", "0.000"], ["70627.70", "0.001"], ["70630.30", "0.150"], ["70630.70", "0.017"], ["70633.20", "0.003"], ["70634.00", "0.000"], ["70637.20", "0.005"], ["70639.90", "0.029"], ["70640.80", "0.000"], ["70641.30", "0.012"], ["70646.20", "0.162"], ["70646.60", "0.000"], ["70654.90", "0.680"], ["70660.00", "0.160"], ["70661.50", "0.293"], ["70672.20", "0.002"], ["70693.50", "0.006"], ["70709.60", "0.153"], ["70758.60", "0.613"], ["70758.70", "0.099"], ["70796.10", "0.159"], ["70952.60", "0.665"], ["71059.80", "9.995"], ["71249.90", "0.003"], ["71332.90", "0.723"], ["74188.70", "0.000"], ["89523.20", "0.000"]]}}
{"local_ts": 1773486868226, "server_ts": 1773486868196, "data": {"e": "depthUpdate", "E": 1773486868197, "T": 1773486868196, "s": "BTCUSDT", "U": 10109528318918, "u": 10109528322036, "pu": 10109528318864, "b": [["1000.00", "26.592"], ["5000.00", "101.398"], ["7062.70", "0.000"], ["20326.50", "0.130"], ["20426.50", "2.420"], ["20526.50", "0.450"], ["67087.00", "0.000"], ["67801.50", "0.028"], ["69214.00", "0.880"], ["69920.20", "0.714"], ["70459.00", "0.002"], ["70472.00", "0.002"], ["70530.50", "0.002"], ["70531.50", "0.017"], ["70538.50", "0.071"], ["70545.60", "0.073"], ["70573.50", "0.082"], ["70586.90", "0.045"], ["70591.50", "0.358"], ["70594.70", "0.058"], ["70596.60", "0.187"], ["70596.70", "0.000"]], "a": [["70627.40", "0.003"], ["70628.40", "0.007"], ["70629.00", "0.004"], ["70630.30", "0.005"], ["70671.80", "0.004"], ["70693.40", "0.005"], ["70708.10", "0.800"], ["70708.20", "0.043"], ["70711.30", "0.511"], ["70711.40", "0.090"], ["70715.20", "0.088"], ["70715.30", "0.000"], ["70722.20", "0.327"], ["70722.30", "0.000"], ["70761.80", "0.180"], ["70770.40", "1.789"], ["70770.50", "0.604"], ["70796.10", "0.159"], ["71332.90", "0.723"], ["71933.20", "1.040"], ["89523.20", "0.000"]]}}
{"local_ts": 1773486869245, "server_ts": 1773486869216, "data": {"e": "depthUpdate", "E": 1773486869217, "T": 1773486869216, "s": "BTCUSDT", "U": 10109528356548, "u": 10109528359886, "pu": 10109528356499, "b": [["5000.00", "101.438"], ["7062.70", "0.056"], ["20326.50", "2.230"], ["20426.50", "0.770"], ["67060.00", "0.002"], ["67065.80", "0.002"], ["67095.20", "0.008"], ["70273.30", "0.000"], ["70543.90", "0.628"], ["70544.60", "0.423"], ["70546.30", "0.151"], ["70546.60", "0.117"], ["70547.00", "0.166"], ["70578.70", "0.006"], ["70579.00", "0.004"], ["70581.10", "0.000"], ["70588.20", "0.001"], ["70591.50", "0.188"], ["70591.60", "0.356"], ["70595.30", "0.005"], ["70602.40", "0.003"], ["70606.50", "0.000"], ["70608.90", "1.458"], ["70609.50", "0.034"]], "a": [["70638.30", "0.114"], ["70645.00", "0.006"], ["70652.10", "0.000"], ["70659.20", "0.018"], ["70661.50", "0.318"], ["70666.30", "0.036"], ["70672.20", "0.002"], ["70673.40", "0.001"], ["70686.70", "0.036"], ["70687.00", "0.095"], ["70687.40", "0.108"], ["70688.30", "0.025"], ["70689.00", "0.074"], ["71332.90", "0.723"], ["72394.60", "0.000"], ["74183.00", "0.052"], ["89523.20", "0.000"]]}}
{"local_ts": 1773486870268, "server_ts": 1773486870236, "data": {"e": "depthUpdate", "E": 1773486870237, "T": 1773486870236, "s": "BTCUSDT", "U": 10109528398577, "u": 10109528403961, "pu": 10109528398524, "b": [["1000.00", "26.592"], ["5000.00", "101.418"], ["7062.70", "0.056"], ["20226.50", "1.780"], ["20326.50", "1.220"], ["56501.00", "0.121"], ["69800.20", "0.453"], ["69920.20", "0.714"], ["70061.50", "0.002"], ["70273.40", "0.045"], ["70531.50", "0.017"], ["70538.50", "0.071"], ["70545.60", "0.073"], ["70578.60", "0.019"], ["70578.70", "0.006"], ["70591.60", "0.002"], ["70596.60", "0.187"], ["70596.80", "0.000"], ["70596.90", "0.090"], ["70615.90", "0.006"], ["70619.30", "0.015"], ["70619.50", "1.176"]], "a": [["70626.60", "4.418"], ["70629.20", "0.069"], ["70630.90", "0.000"], ["70631.10", "0.003"], ["70631.20", "0.016"], ["70633.60", "0.035"], ["70637.20", "0.005"], ["70642.40", "0.001"], ["70643.10", "0.061"], ["70661.50", "0.314"], ["70680.80", "0.000"], ["70708.10", "0.800"], ["70715.20", "0.088"], ["70722.20", "0.327"], ["70748.10", "0.555"], ["70850.40", "0.000"], ["70850.70", "0.007"], ["70952.20", "0.008"], ["71030.50", "0.140"], ["71332.90", "0.723"], ["71849.30", "0.280"], ["72039.10", "0.000"], ["74169.20", "0.004"]]}}
{"local_ts": 1773486871284, "server_ts": 1773486871256, "data": {"e": "depthUpdate", "E": 1773486871257, "T": 1773486871256, "s": "BTCUSDT", "U": 10109528438211, "u": 10109528441522, "pu": 10109528438169, "b": [["1000.00", "26.592"], ["5000.00", "101.418"], ["7062.70", "0.056"], ["20126.50", "1.330"], ["20226.50", "1.670"], ["33000.00", "3.785"], ["67065.60", "0.000"], ["67095.00", "0.000"], ["69920.20", "0.714"], ["70301.60", "0.106"], ["70435.80", "0.159"], ["70464.10", "0.039"], ["70477.60", "0.126"], ["70537.30", "0.000"], ["70570.00", "0.366"], ["70572.70", "0.018"], ["70572.80", "0.424"], ["70586.20", "0.000"], ["70591.50", "0.188"], ["70594.50", "0.020"], ["70596.30", "0.000"], ["70596.60", "0.003"], ["70604.20", "0.052"], ["70615.90", "0.006"], ["70619.30", "0.015"], ["70619.50", "1.174"], ["70621.80", "0.009"], ["70622.00", "0.003"], ["70623.20", "0.019"], ["70625.70", "0.000"], ["70626.50", "5.814"]], "a": [["70626.60", "4.389"], ["70626.80", "0.002"], ["70627.00", "0.076"], ["70633.60", "0.033"], ["70637.20", "0.005"], ["70661.60", "0.004"], ["70665.40", "0.044"], ["70669.10", "0.079"], ["70671.10", "0.006"], ["70685.10", "0.004"], ["70686.30", "0.072"], ["70687.00", "0.095"], ["70696.60", "5.153"], ["70711.50", "0.010"], ["70722.60", "0.000"], ["70722.70", "0.305"], ["70771.40", "0.176"], ["70781.40", "0.335"], ["70781.50", "0.313"], ["70797.10", "0.018"], ["70799.60", "0.159"], ["71297.60", "1.398"], ["71332.90", "0.723"], ["71333.40", "0.049"], ["71551.00", "1.262"], ["71686.00", "6.939"], ["71753.90", "3.450"], ["71756.60", "3.469"], ["71883.90", "0.017"], ["71897.90", "1.395"], ["71920.10", "2.231"], ["71968.50", "1.390"], ["71974.00", "0.208"]]}}
{"local_ts": 1773486872308, "server_ts": 1773486872276, "data": {"e": "depthUpdate", "E": 1773486872277, "T": 1773486872276, "s": "BTCUSDT", "U": 10109528475958, "u": 10109528479182, "pu": 10109528475889, "b": [["5000.00", "101.418"], ["7062.70", "0.028"], ["20126.50", "2.120"], ["20526.50", "0.880"], ["67064.20", "0.002"], ["68680.00", "1.171"], ["69390.50", "2.302"], ["69915.50", "0.004"], ["69920.20", "0.714"], ["70076.70", "0.003"], ["70273.30", "0.000"], ["70273.40", "0.151"], ["70273.50", "0.006"], ["70301.60", "0.000"], ["70380.20", "0.000"], ["70467.60", "0.268"], ["70478.70", "12.721"], ["70479.20", "3.702"], ["70531.50", "0.017"], ["70537.50", "0.000"], ["70538.50", "0.071"], ["70538.90", "1.566"], ["70545.60", "0.073"], ["70572.40", "0.000"], ["70581.10", "0.000"], ["70591.50", "0.004"], ["70594.10", "0.002"], ["70596.50", "0.298"], ["70615.90", "0.003"], ["70619.20", "0.000"], ["70619.40", "0.460"], ["70619.50", "1.174"], ["70620.10", "0.345"], ["70621.40", "0.000"], ["70622.50", "0.034"], ["70626.50", "4.929"]], "a": [["70633.60", "0.090"], ["70637.20", "0.002"], ["70708.10", "0.800"], ["70715.20", "0.088"], ["70722.20", "0.327"], ["70722.30", "6.611"], ["70738.90", "0.088"], ["71321.20", "4.334"], ["71332.90", "0.723"], ["71406.00", "0.056"], ["71466.50", "6.428"], ["71704.60", "1.671"]]}}
{"local_ts": 1773486873330, "server_ts": 1773486873300, "data": {"e": "depthUpdate", "E": 1773486873301, "T": 1773486873300, "s": "BTCUSDT", "U": 10109528507353, "u": 10109528511206, "pu": 10109528507291, "b": [["1000.00", "26.592"], ["5000.00", "101.418"], ["7062.70", "0.028"], ["20126.50", "0.010"], ["20426.50", "0.450"], ["20526.50", "2.540"], ["33000.00", "3.785"], ["62664.20", "0.002"], ["67065.30", "0.000"], ["67068.80", "0.000"], ["68507.70", "0.005"], ["69387.40", "0.000"], ["70531.50", "0.017"], ["70538.50", "0.071"], ["70545.60", "0.073"], ["70570.00", "0.366"], ["70570.20", "0.284"], ["70572.50", "0.003"], ["70591.50", "0.004"], ["70596.50", "0.114"], ["70619.30", "0.012"]], "a": [["70637.20", "0.005"], ["70681.70", "0.050"], ["70684.50", "0.041"], ["70685.90", "0.469"], ["70696.20", "0.382"], ["70700.30", "0.041"], ["70704.90", "0.026"], ["70707.50", "0.231"], ["70708.10", "0.800"], ["70709.60", "0.112"], ["70710.80", "0.289"], ["70714.60", "0.009"], ["70714.70", "0.183"], ["70715.20", "0.088"], ["70717.80", "0.000"], ["70721.30", "0.084"], ["70722.20", "0.327"], ["70739.80", "0.000"], ["70749.90", "4.892"], ["70758.30", "0.638"], ["70758.40", "0.007"], ["70764.70", "0.041"], ["70771.40", "0.096"], ["70777.10", "0.043"], ["70777.60", "0.000"], ["70796.10", "0.159"], ["70898.40", "0.000"], ["71183.90", "0.010"], ["71332.90", "2.123"], ["71348.60", "53.917"], ["71562.70", "66.644"], ["71617.80", "0.556"], ["71670.30", "0.000"], ["73451.60", "0.016"]]}}
{"local_ts": 1773486874349, "server_ts": 1773486874320, "data": {"e": "depthUpdate", "E": 1773486874323, "T": 1773486874320, "s": "BTCUSDT", "U": 10109528539957, "u": 10109528542503, "pu": 10109528539828, "b": [["5000.00", "101.418"], ["7062.70", "0.028"], ["20326.50", "0.240"], ["20426.50", "2.510"], ["20526.50", "0.250"], ["69214.00", "0.877"], ["69489.10", "4.452"], ["69595.00", "18.759"], ["69779.00", "4.664"], ["69920.20", "0.714"], ["69920.30", "0.004"], ["70061.50", "0.358"], ["70385.80", "0.005"], ["70435.80", "0.159"], ["70531.40", "0.023"], ["70531.50", "0.000"], ["70534.60", "0.142"], ["70537.80", "0.041"], ["70538.40", "0.074"], ["70538.50", "0.000"], ["70541.60", "0.423"], ["70544.80", "0.000"], ["70545.50", "0.071"], ["70545.60", "0.002"], ["70546.20", "0.003"], ["70548.40", "1.044"], ["70548.70", "0.514"], ["70548.80", "1.277"], ["70551.90", "0.000"], ["70557.30", "10.119"], ["70557.40", "0.000"], ["70558.90", "2.632"], ["70562.90", "0.003"], ["70604.00", "0.046"], ["70615.90", "0.003"], ["70617.50", "0.079"], ["70619.20", "0.000"], ["70619.50", "0.951"], ["70620.20", "0.001"], ["70623.70", "0.001"], ["70624.50", "0.000"], ["70626.00", "0.070"], ["70626.50", "5.659"]], "a": [["70629.60", "0.067"], ["70633.60", "0.033"], ["70637.20", "0.005"], ["70642.00", "0.026"], ["70642.10", "0.000"], ["70670.80", "0.000"], ["70690.20", "0.003"], ["70704.30", "1.019"], ["70704.60", "0.517"], ["70707.60", "0.011"], ["70708.10", "0.800"], ["70711.70", "0.223"], ["70714.70", "0.041"], ["70715.20", "0.088"], ["70718.70", "0.144"], ["70721.70", "0.048"], ["70722.20", "0.327"], ["70743.30", "6.491"], ["70744.30", "0.096"], ["70750.90", "0.134"], ["70752.90", "0.000"], ["70754.00", "0.264"], ["70796.10", "0.159"], ["71332.90", "2.123"], ["71588.00", "5.225"], ["74167.90", "0.002"], ["74182.20", "0.002"]]}}
{"local_ts": 1773486875372, "server_ts": 1773486875340, "data": {"e": "depthUpdate", "E": 1773486875343, "T": 1773486875340, "s": "BTCUSDT", "U": 10109528573016, "u": 10109528576464, "pu": 10109528572999, "b": [["1000.00", "26.592"], ["5000.00", "101.418"], ["7062.70", "0.000"], ["20226.50", "0.090"], ["20326.50", "2.360"], ["20426.50", "0.550"], ["33000.00", "3.789"], ["69769.10", "0.008"], ["69920.20", "0.714"], ["70051.60", "1.220"], ["70273.40", "0.045"], ["70491.00", "0.086"], ["70596.70", "0.269"], ["70596.80", "0.000"], ["70615.90", "0.006"], ["70617.70", "0.107"], ["70619.30", "0.015"], ["70619.50", "0.928"], ["70626.50", "5.895"]], "a": [["70626.60", "3.857"], ["70627.10", "0.000"], ["70628.20", "0.015"], ["70628.60", "0.000"], ["70633.60", "0.035"], ["70637.20", "0.005"], ["70661.50", "0.289"], ["70671.40", "0.597"], ["70761.40", "0.000"], ["71332.90", "2.123"], ["74168.60", "0.019"], ["74180.30", "0.000"]]}}
{"local_ts": 1773486876397, "server_ts": 1773486876364, "data": {"e": "depthUpdate", "E": 1773486876365, "T": 1773486876364, "s": "BTCUSDT", "U": 10109528608596, "u": 10109528612089, "pu": 10109528608500, "b": [["1000.00", "26.592"], ["5000.00", "101.418"], ["7062.70", "0.000"], ["20226.50", "2.100"], ["20326.50", "0.900"], ["69524.40", "6.461"], ["69595.00", "9.720"], ["69920.20", "0.714"], ["70418.00", "0.017"], ["70531.40", "0.023"], ["70538.40", "0.074"], ["70545.50", "0.071"], ["70578.60", "0.019"], ["70578.70", "0.006"], ["70615.90", "0.003"], ["70619.30", "0.012"]], "a": [["70628.80", "0.002"], ["70629.80", "0.060"], ["70637.20", "0.005"], ["70648.40", "0.000"], ["70648.90", "0.013"], ["70655.10", "0.000"], ["70655.30", "0.003"], ["70655.70", "0.638"], ["70656.50", "0.010"], ["70708.10", "0.800"], ["70715.20", "0.088"], ["70722.20", "0.327"], ["70796.10", "0.159"], ["71332.90", "2.123"], ["74169.50", "0.054"]]}}
{"local_ts": 1773486877417, "server_ts": 1773486877388, "data": {"e": "depthUpdate", "E": 1773486877389, "T": 1773486877388, "s": "BTCUSDT", "U": 10109528642058, "u": 10109528645043, "pu": 10109528641988, "b": [["5000.00", "101.418"], ["7062.70", "0.000"], ["20126.50", "1.660"], ["20226.50", "1.340"], ["67073.90", "0.002"], ["67079.20", "0.000"], ["69453.80", "2.659"], ["69595.00", "8.716"], ["69920.30", "0.000"], ["70047.40", "0.000"], ["70380.30", "0.000"], ["70492.80", "0.000"], ["70576.60", "0.286"], ["70590.60", "0.005"], ["70619.30", "0.012"], ["70623.00", "0.016"]], "a": [["70637.20", "0.005"], ["70758.00", "0.500"], ["71332.90", "3.523"], ["71643.10", "12.128"], ["71650.70", "12.129"], ["71756.60", "9.871"], ["71784.30", "1.141"]]}}
{"local_ts": 1773486878438, "server_ts": 1773486878408, "data": {"e": "depthUpdate", "E": 1773486878409, "T": 1773486878408, "s": "BTCUSDT", "U": 10109528680437, "u": 10109528683644, "pu": 10109528680367, "b": [["1000.00", "26.592"], ["5000.00", "101.418"], ["7062.70", "0.056"], ["20126.50", "1.790"], ["20526.50", "1.210"], ["67074.00", "0.002"], ["67095.20", "0.004"], ["67095.30", "0.012"], ["67801.50", "0.046"], ["69195.30", "1.740"], ["69375.70", "0.004"], ["69920.20", "1.785"], ["69920.40", "0.647"], ["70380.40", "0.266"], ["70604.60", "0.074"], ["70615.90", "0.006"], ["70619.20", "0.003"]], "a": [["70628.60", "1.559"], ["70631.30", "0.000"], ["70631.60", "0.004"], ["70631.70", "0.017"], ["70637.20", "0.002"], ["70639.90", "0.031"], ["70640.50", "0.008"], ["70641.90", "0.028"], ["70813.60", "0.000"], ["70815.60", "0.007"], ["70820.70", "0.000"], ["70822.70", "0.007"], ["70827.80", "0.008"], ["70829.80", "2.225"], ["70834.90", "0.511"], ["70836.90", "0.010"], ["70842.00", "0.000"], ["70844.00", "0.007"], ["70849.10", "0.000"], ["70851.10", "0.007"], ["70856.20", "0.011"], ["70858.20", "0.007"], ["70863.30", "0.004"], ["70865.30", "0.012"], ["71721.30", "6.279"], ["72039.10", "0.009"], ["74168.10", "0.000"]]}}
{"local_ts": 1773486879457, "server_ts": 1773486879429, "data": {"e": "depthUpdate", "E": 1773486879431, "T": 1773486879429, "s": "BTCUSDT", "U": 10109528727514, "u": 10109528730984, "pu": 10109528727424, "b": [["5000.00", "101.418"], ["7062.70", "0.056"], ["20426.50", "0.760"], ["20526.50", "2.240"], ["68507.70", "0.005"], ["69214.00", "0.883"], ["69920.20", "1.785"], ["70578.70", "0.008"], ["70578.90", "0.003"], ["70591.20", "0.891"], ["70604.60", "0.074"], ["70612.60", "0.511"], ["70613.60", "0.312"]], "a": [["70640.50", "0.065"], ["70660.00", "0.084"], ["70661.90", "0.011"], ["70669.40", "0.038"], ["70690.00", "5.244"], ["70815.60", "0.000"], ["70816.50", "0.009"], ["70822.70", "0.000"], ["70823.60", "2.241"], ["70829.80", "2.218"], ["70830.70", "0.009"], ["70836.90", "0.003"], ["70837.80", "0.007"], ["70844.00", "0.000"], ["70844.90", "4.375"], ["70850.30", "0.091"], ["70851.10", "0.000"], ["70852.00", "0.056"], ["70858.20", "0.000"], ["70859.10", "0.222"], ["70865.30", "0.005"], ["70866.20", "0.007"], ["71332.80", "0.000"], ["71332.90", "3.663"], ["74158.20", "0.002"]]}}
{"local_ts": 1773486880479, "server_ts": 1773486880450, "data": {"e": "depthUpdate", "E": 1773486880451, "T": 1773486880450, "s": "BTCUSDT", "U": 10109528773922, "u": 10109528778589, "pu": 10109528773880, "b": [["1000.00", "26.592"], ["5000.00", "101.438"], ["7062.70", "0.056"], ["20326.50", "0.360"], ["20426.50", "2.590"], ["20526.50", "0.050"], ["33000.00", "3.785"], ["67066.00", "0.274"], ["67070.60", "0.002"], ["67801.50", "0.050"], ["69626.40", "0.651"], ["69920.20", "1.785"], ["70273.40", "0.045"], ["70273.50", "0.006"], ["70380.40", "0.266"], ["70492.80", "0.000"], ["70604.60", "0.073"]], "a": [["70637.10", "0.021"], ["70641.00", "0.005"], ["70641.80", "0.181"], ["70655.90", "0.637"], ["70657.60", "0.511"], ["70658.60", "0.868"], ["70660.60", "0.036"], ["70666.40", "0.108"], ["70673.10", "0.069"], ["70675.40", "0.005"], ["70707.70", "0.166"], ["70710.40", "0.256"], ["70757.90", "10.000"], ["70796.10", "0.159"], ["70815.60", "0.007"], ["70816.50", "0.002"], ["70822.70", "0.007"], ["70823.60", "2.234"], ["70829.80", "2.225"], ["70830.70", "0.002"], ["70836.90", "0.010"], ["70837.80", "0.000"], ["70844.00", "0.007"], ["70844.90", "4.368"], ["70850.10", "0.000"], ["70850.20", "0.289"], ["70851.10", "0.007"], ["70852.00", "0.049"], ["70858.20", "0.007"], ["70859.10", "0.215"], ["70865.30", "0.012"], ["70866.20", "0.000"], ["71297.50", "0.000"], ["71332.90", "3.663"], ["71550.10", "0.000"], ["89523.20", "0.000"]]}}
{"local_ts": 1773486881502, "server_ts": 1773486881472, "data": {"e": "depthUpdate", "E": 1773486881473, "T": 1773486881472, "s": "BTCUSDT", "U": 10109528821987, "u": 10109528827534, "pu": 10109528821913, "b": [["1000.00", "26.592"], ["5000.00", "101.418"], ["7062.70", "0.028"], ["20226.50", "0.200"], ["20326.50", "2.470"], ["20426.50", "0.330"], ["56501.00", "0.125"], ["67801.40", "1.262"], ["69920.20", "3.213"], ["70495.00", "0.259"], ["70498.20", "0.217"], ["70604.60", "0.073"], ["70606.50", "0.000"], ["70608.80", "0.890"], ["70623.00", "0.203"], ["70626.50", "6.281"]], "a": [["70626.60", "1.407"], ["70626.70", "0.106"], ["70629.30", "0.098"], ["70632.20", "0.000"], ["70634.90", "0.058"], ["70637.40", "0.004"], ["70641.80", "0.456"], ["70642.60", "0.024"], ["70642.90", "0.002"], ["70643.90", "0.006"], ["70644.10", "0.018"], ["70644.30", "0.008"], ["70645.60", "0.008"], ["70658.60", "0.868"], ["70659.70", "0.005"], ["70660.50", "0.070"], ["70809.40", "0.007"], ["70815.60", "0.000"], ["70816.50", "0.009"], ["70822.70", "0.000"], ["70823.60", "2.241"], ["70829.80", "2.218"], ["70830.70", "0.009"], ["70836.90", "0.003"], ["70837.80", "0.007"], ["70844.00", "0.000"], ["70844.90", "4.375"], ["70850.20", "0.289"], ["70851.10", "0.000"], ["70852.00", "0.056"], ["70858.20", "0.000"], ["70859.10", "0.222"], ["70865.30", "0.005"], ["71332.80", "0.000"], ["71332.90", "3.663"], ["72039.10", "0.006"], ["74174.20", "0.000"], ["89523.20", "0.000"]]}}
{"local_ts": 1773486882531, "server_ts": 1773486882494, "data": {"e": "depthUpdate", "E": 1773486882495, "T": 1773486882494, "s": "BTCUSDT", "U": 10109528869204, "u": 10109528874132, "pu": 10109528869055, "b": [["5000.00", "101.418"], ["7062.70", "0.028"], ["20126.50", "0.050"], ["20226.50", "2.320"], ["20326.50", "0.630"], ["33000.00", "3.785"], ["69588.30", "1.923"], ["69713.70", "0.000"], ["69920.20", "3.213"], ["70273.40", "0.055"], ["70273.50", "0.002"], ["70380.50", "0.000"], ["70418.70", "0.004"], ["70579.00", "0.004"], ["70579.10", "0.003"], ["70604.60", "0.030"], ["70619.60", "0.880"], ["70623.00", "0.203"], ["70626.50", "6.265"]], "a": [["70626.60", "1.397"], ["70626.70", "0.106"], ["70633.20", "0.003"], ["70633.70", "0.006"], ["70634.40", "0.112"], ["70636.00", "0.000"], ["70636.30", "0.002"], ["70636.90", "0.018"], ["70641.90", "0.009"], ["70642.60", "0.022"], ["70643.50", "0.000"], ["70658.60", "0.868"], ["70658.70", "0.104"], ["70809.40", "0.000"], ["70850.00", "3.519"], ["70866.20", "0.007"], ["71332.80", "0.000"], ["71332.90", "5.063"], ["71639.10", "2.261"], ["71688.20", "0.019"], ["74189.60", "0.006"], ["89523.20", "0.000"]]}}
{"local_ts": 1773486883542, "server_ts": 1773486883513, "data": {"e": "depthUpdate", "E": 1773486883515, "T": 1773486883513, "s": "BTCUSDT", "U": 10109528927990, "u": 10109528934113, "pu": 10109528927799, "b": [["1000.00", "26.592"], ["5000.00", "101.418"], ["7062.70", "0.028"], ["20126.50", "1.970"], ["20226.50", "1.030"], ["67065.10", "0.000"], ["67078.40", "0.002"], ["69920.20", "3.213"], ["70492.80", "0.584"], ["70556.80", "0.877"], ["70578.30", "0.976"], ["70578.40", "0.884"], ["70593.70", "0.555"], ["70609.80", "0.159"], ["70619.00", "0.201"], ["70619.30", "0.012"], ["70620.10", "0.004"], ["70626.50", "6.731"]], "a": [["70626.60", "1.236"], ["70637.20", "0.002"], ["70638.80", "0.060"], ["70640.60", "0.015"], ["70641.20", "0.017"], ["70641.90", "0.007"], ["70643.40", "0.021"], ["70644.00", "0.027"], ["70670.10", "0.000"], ["70672.80", "0.032"], ["70694.30", "0.006"], ["70757.80", "0.555"], ["70796.10", "0.159"], ["71000.00", "26.296"], ["71332.90", "5.063"], ["71558.20", "0.837"], ["89523.20", "0.000"]]}}
{"local_ts": 1773486884566, "server_ts": 1773486884536, "data": {"e": "depthUpdate", "E": 1773486884539, "T": 1773486884536, "s": "BTCUSDT", "U": 10109528986970, "u": 10109528993306, "pu": 10109528986944, "b": [["5000.00", "101.418"], ["7062.70", "0.000"], ["20126.50", "1.470"], ["20526.50", "1.530"], ["33000.00", "3.789"], ["56501.00", "0.121"], ["68507.70", "0.005"], ["69214.00", "0.892"], ["69227.00", "1.238"], ["69543.40", "2.162"], ["69920.20", "3.213"], ["70308.80", "0.004"], ["70380.40", "0.266"], ["70520.20", "0.093"], ["70578.70", "0.008"], ["70578.90", "0.003"], ["70599.60", "0.458"], ["70599.70", "0.004"], ["70599.80", "0.000"], ["70599.90", "0.096"], ["70604.60", "0.073"], ["70626.50", "6.818"]], "a": [["70632.30", "0.004"], ["70633.30", "0.000"], ["70634.30", "0.000"], ["70644.00", "0.025"], ["70645.10", "0.002"], ["70647.80", "0.058"], ["70669.60", "1.753"], ["70672.80", "0.030"], ["70704.60", "0.005"], ["70706.00", "0.000"], ["71332.90", "5.063"], ["71558.20", "0.000"], ["71608.30", "2.438"], ["72039.10", "0.173"], ["74193.10", "0.000"], ["89523.20", "0.000"]]}}
{"local_ts": 1773486885594, "server_ts": 1773486885556, "data": {"e": "depthUpdate", "E": 1773486885561, "T": 1773486885556, "s": "BTCUSDT", "U": 10109529040297, "u": 10109529045828, "pu": 10109529040103, "b": [["1000.00", "26.592"], ["5000.00", "101.438"], ["7062.70", "0.000"], ["20426.50", "1.080"], ["20526.50", "1.920"], ["56501.00", "0.121"], ["67092.70", "0.000"], ["67801.50", "0.060"], ["68507.70", "0.000"], ["69214.00", "8.756"], ["69425.80", "4.004"], ["69920.20", "3.213"], ["70273.40", "0.045"], ["70273.50", "0.006"], ["70380.50", "0.000"], ["70492.80", "0.669"], ["70578.90", "0.005"], ["70579.00", "0.002"], ["70600.50", "0.006"], ["70604.60", "0.030"], ["70615.20", "0.012"], ["70615.90", "0.006"], ["70616.10", "0.213"], ["70617.50", "0.004"], ["70618.50", "0.018"], ["70618.90", "0.014"], ["70619.20", "0.920"], ["70619.30", "0.015"], ["70624.60", "0.000"], ["70625.20", "0.006"], ["70626.50", "6.908"]], "a": [["70626.60", "1.074"], ["70635.40", "0.004"], ["70635.50", "0.004"], ["70637.20", "0.005"], ["70638.50", "0.004"], ["70638.80", "0.003"], ["70638.90", "0.060"], ["70640.50", "0.287"], ["70642.80", "1.767"], ["70644.00", "0.010"], ["70644.40", "0.146"], ["70644.60", "0.514"], ["70662.90", "0.012"], ["70667.90", "0.005"], ["70669.60", "1.751"], ["70672.70", "0.002"], ["70757.70", "0.864"], ["70796.10", "0.159"], ["70850.00", "3.526"], ["70856.10", "0.106"], ["71332.80", "0.000"], ["71332.90", "5.063"], ["71947.30", "0.764"], ["74162.30", "0.007"], ["89523.20", "0.000"]]}}
{"local_ts": 1773486886614, "server_ts": 1773486886577, "data": {"e": "depthUpdate", "E": 1773486886581, "T": 1773486886577, "s": "BTCUSDT", "U": 10109529086831, "u": 10109529091742, "pu": 10109529086824, "b": [["1000.00", "26.592"], ["5000.00", "101.418"], ["7062.70", "0.000"], ["20326.50", "0.630"], ["20426.50", "2.370"], ["20526.50", "0.000"], ["56501.00", "0.121"], ["67070.70", "0.017"], ["67080.30", "0.000"], ["69920.20", "3.213"], ["69920.30", "0.000"], ["70380.40", "0.270"], ["70534.90", "0.144"], ["70535.30", "0.575"], ["70541.90", "0.661"], ["70542.30", "0.071"], ["70549.00", "0.142"], ["70549.40", "0.073"], ["70599.70", "0.089"], ["70599.80", "0.000"], ["70615.90", "0.003"], ["70617.50", "0.007"], ["70619.20", "0.283"], ["70622.80", "0.003"], ["70626.50", "6.942"]], "a": [["70626.60", "1.687"], ["70632.50", "0.058"], ["70637.20", "0.005"], ["70638.80", "0.006"], ["70639.00", "0.025"], ["70647.80", "0.217"], ["70667.90", "0.003"], ["70672.20", "0.004"], ["70674.30", "0.000"], ["70704.50", "0.144"], ["70711.60", "0.142"], ["70711.90", "0.074"], ["70712.00", "1.173"], ["70718.60", "0.200"], ["70719.00", "1.276"], ["70719.10", "0.000"], ["70726.00", "0.331"], ["70726.10", "0.046"], ["70850.10", "0.007"], ["71332.90", "5.063"], ["71705.70", "0.835"], ["72395.30", "0.000"], ["89523.20", "0.000"]]}}
{"local_ts": 1773486887640, "server_ts": 1773486887600, "data": {"e": "depthUpdate", "E": 1773486887601, "T": 1773486887600, "s": "BTCUSDT", "U": 10109529166652, "u": 10109529171819, "pu": 10109529166516, "b": [["5000.00", "101.418"], ["7062.70", "0.000"], ["20226.50", "0.300"], ["20326.50", "2.580"], ["20426.50", "0.120"], ["56501.00", "0.121"], ["69920.20", "4.641"], ["70273.40", "0.045"], ["70380.40", "0.266"], ["70492.80", "0.650"], ["70578.50", "0.200"], ["70578.60", "0.019"], ["70609.80", "0.470"], ["70611.10", "0.137"], ["70612.00", "0.520"], ["70613.00", "0.000"], ["70613.10", "0.005"], ["70615.20", "0.007"], ["70619.60", "0.878"], ["70619.90", "0.010"], ["70620.00", "0.765"], ["70620.70", "0.026"], ["70622.80", "0.171"]], "a": [["70641.60", "0.112"], ["70649.80", "0.006"], ["70655.90", "0.001"], ["70656.60", "0.693"], ["70657.80", "0.028"], ["70659.60", "0.074"], ["70661.40", "0.014"], ["70672.20", "0.002"], ["70676.50", "0.074"], ["70757.70", "0.644"], ["71687.90", "0.000"], ["74182.40", "0.002"], ["89523.20", "0.000"]]}}
{"local_ts": 1773486888648, "server_ts": 1773486888620, "data": {"e": "depthUpdate", "E": 1773486888621, "T": 1773486888620, "s": "BTCUSDT", "U": 10109529224448, "u": 10109529231264, "pu": 10109529223854, "b": [["1000.00", "26.592"], ["5000.00", "101.418"], ["7062.70", "0.056"], ["20126.50", "0.150"], ["20226.50", "2.430"], ["20326.50", "0.420"], ["56501.00", "0.121"], ["69403.60", "1.151"], ["69743.70", "0.135"], ["69920.20", "4.641"], ["70300.00", "21.654"], ["70301.60", "0.106"], ["70467.60", "0.268"], ["70478.60", "0.005"], ["70481.90", "13.007"], ["70482.00", "0.136"], ["70482.60", "3.095"], ["70500.00", "4.145"], ["70541.20", "6.721"], ["70542.00", "2.186"], ["70576.50", "3.436"], ["70578.60", "0.019"], ["70578.70", "0.006"], ["70597.90", "1.931"], ["70600.10", "0.088"], ["70600.20", "0.113"], ["70611.50", "0.189"], ["70615.20", "0.005"], ["70617.60", "0.005"], ["70619.10", "1.194"], ["70622.50", "0.036"], ["70623.40", "0.016"], ["70625.20", "0.637"], ["70626.50", "7.011"]], "a": [["70629.20", "0.118"], ["70629.40", "0.001"], ["70630.60", "0.006"], ["70631.90", "0.036"], ["70644.40", "0.005"], ["70645.20", "0.142"], ["70647.40", "0.024"], ["70659.80", "0.019"], ["70660.60", "0.657"], ["70662.20", "0.017"], ["70662.90", "0.008"], ["70663.00", "0.070"], ["70664.40", "0.055"], ["70665.20", "0.097"], ["70667.50", "1.848"], ["70688.90", "3.525"], ["70724.20", "7.438"], ["70783.60", "0.018"], ["70783.70", "12.870"], ["70797.10", "0.000"], ["70799.60", "0.000"], ["70850.00", "3.519"], ["70850.80", "0.011"], ["70856.10", "0.106"], ["71332.80", "0.007"], ["71332.90", "5.063"], ["74183.00", "0.052"], ["89523.20", "0.000"]]}}
{"local_ts": 1773486889673, "server_ts": 1773486889644, "data": {"e": "depthUpdate", "E": 1773486889645, "T": 1773486889644, "s": "BTCUSDT", "U": 10109529279737, "u": 10109529284982, "pu": 10109529279730, "b": [["5000.00", "101.418"], ["7062.70", "0.056"], ["20126.50", "2.290"], ["20226.50", "0.710"], ["33000.00", "3.785"], ["67062.50", "0.033"], ["68507.70", "0.000"], ["69920.20", "4.643"], ["70578.50", "0.202"], ["70578.60", "0.017"], ["70594.70", "0.406"], ["70597.90", "1.836"], ["70599.90", "0.008"], ["70619.90", "0.192"], ["70623.00", "0.203"], ["70626.20", "0.304"], ["70626.50", "6.986"]], "a": [["70631.90", "0.028"], ["70635.00", "0.654"], ["70641.80", "0.179"], ["70642.80", "0.007"], ["70647.80", "0.217"], ["70647.90", "0.001"], ["70648.80", "0.232"], ["70667.50", "1.833"], ["70667.90", "0.000"], ["70673.10", "0.018"], ["70677.50", "0.115"], ["70683.10", "0.635"], ["70799.60", "0.060"], ["70856.10", "0.000"], ["71332.90", "5.063"], ["71544.70", "8.383"], ["71546.60", "0.006"], ["71615.40", "2.161"], ["71687.80", "1.381"], ["71753.70", "2.070"], ["71899.70", "0.004"], ["74178.40", "0.000"], ["89523.20", "0.006"]]}}
{"local_ts": 1773486890692, "server_ts": 1773486890664, "data": {"e": "depthUpdate", "E": 1773486890665, "T": 1773486890664, "s": "BTCUSDT", "U": 10109529329684, "u": 10109529334670, "pu": 10109529329474, "b": [["1000.00", "26.592"], ["5000.00", "101.418"], ["7062.70", "0.056"], ["20126.50", "1.150"], ["20526.50", "1.850"], ["56501.00", "0.121"], ["67095.00", "0.000"], ["67095.20", "0.002"], ["67095.30", "0.012"], ["69602.40", "15.640"], ["69920.20", "5.355"], ["69940.30", "0.250"], ["70273.40", "0.117"], ["70300.00", "21.654"], ["70566.80", "2.165"], ["70578.50", "0.202"], ["70578.60", "0.017"], ["70579.40", "8.506"], ["70580.10", "0.889"], ["70621.60", "0.642"], ["70622.60", "0.511"]], "a": [["70635.00", "0.002"], ["70637.70", "0.691"], ["70637.80", "0.028"], ["70647.80", "0.157"], ["70673.10", "0.021"], ["70673.80", "0.402"], ["70696.50", "0.000"], ["70696.90", "8.496"], ["70707.90", "10.974"], ["70714.20", "0.036"], ["70786.50", "0.098"], ["70809.40", "0.000"], ["70850.70", "0.007"], ["70866.70", "0.000"], ["71059.70", "0.004"], ["71187.20", "0.002"], ["71249.90", "3.243"], ["71332.90", "5.763"], ["71622.40", "1.552"], ["71921.60", "0.694"], ["74192.80", "0.000"]]}}
{"local_ts": 1773486891722, "server_ts": 1773486891684, "data": {"e": "depthUpdate", "E": 1773486891687, "T": 1773486891684, "s": "BTCUSDT", "U": 10109529376912, "u": 10109529380743, "pu": 10109529376868, "b": [["1000.00", "26.592"], ["5000.00", "101.418"], ["7062.70", "0.028"], ["20426.50", "1.400"], ["20526.50", "1.600"], ["33000.00", "3.785"], ["67092.90", "0.000"], ["69355.20", "2.016"], ["69707.90", "1.004"], ["69920.20", "6.068"], ["69920.30", "0.004"], ["70380.20", "0.000"]], "a": [["70647.80", "0.157"], ["70707.90", "10.972"], ["70709.80", "1.743"], ["70786.50", "0.096"], ["70792.50", "0.002"], ["71332.90", "5.763"], ["71615.30", "0.144"], ["71615.40", "2.858"], ["72039.10", "9.392"]]}}
{"local_ts": 1773486892738, "server_ts": 1773486892710, "data": {"e": "depthUpdate", "E": 1773486892711, "T": 1773486892710, "s": "BTCUSDT", "U": 10109529427017, "u": 10109529431034, "pu": 10109529426959, "b": [["5000.00", "101.418"], ["7062.70", "0.028"], ["20326.50", "0.960"], ["20426.50", "2.040"], ["67073.70", "0.004"], ["69355.20", "4.896"], ["69602.40", "16.501"], ["69920.20", "6.068"], ["70273.40", "0.117"], ["70578.50", "0.200"], ["70578.60", "0.019"], ["70600.60", "0.017"], ["70600.70", "0.085"], ["70615.90", "0.006"], ["70619.20", "0.339"], ["70623.80", "0.001"], ["70625.60", "0.083"], ["70626.40", "0.121"], ["70626.50", "6.405"]], "a": [["70629.20", "0.132"], ["70637.20", "0.005"], ["70637.80", "1.657"], ["70637.90", "0.035"], ["70647.80", "0.118"], ["70657.20", "0.206"], ["70657.70", "0.551"], ["70658.00", "0.642"], ["70658.80", "0.518"], ["70660.50", "0.000"], ["70661.50", "0.490"], ["70708.70", "0.360"], ["70709.80", "1.741"], ["70788.70", "0.002"], ["70792.50", "0.000"], ["70850.20", "0.289"], ["71332.90", "5.763"], ["71650.70", "20.632"]]}}
{"local_ts": 1773486893764, "server_ts": 1773486893732, "data": {"e": "depthUpdate", "E": 1773486893733, "T": 1773486893732, "s": "BTCUSDT", "U": 10109529475999, "u": 10109529479892, "pu": 10109529475864, "b": [["1000.00", "26.592"], ["5000.00", "101.418"], ["7062.70", "0.028"], ["20226.50", "0.520"], ["20326.50", "2.480"], ["20426.50", "0.000"], ["33000.00", "3.789"], ["67094.50", "0.002"], ["67801.50", "0.076"], ["69779.00", "9.669"], ["69920.20", "6.068"], ["70182.90", "0.299"], ["70498.60", "0.041"], ["70534.90", "0.144"], ["70541.90", "0.661"], ["70549.00", "0.142"], ["70578.50", "0.200"], ["70578.60", "0.019"], ["70600.70", "0.085"], ["70600.80", "0.031"], ["70609.70", "0.128"]], "a": [["70630.20", "0.215"], ["70642.10", "0.021"], ["70647.80", "0.217"], ["70685.90", "0.101"], ["70690.00", "5.159"], ["70691.10", "0.000"], ["70704.40", "0.142"], ["70704.50", "0.002"], ["70708.70", "0.358"], ["70710.30", "0.004"], ["70711.50", "0.152"], ["70711.60", "0.000"], ["70714.50", "0.019"], ["70718.50", "0.392"], ["70718.60", "0.058"], ["70753.70", "0.179"], ["70759.10", "0.045"], ["70760.10", "0.086"], ["70764.00", "0.669"], ["70788.70", "0.000"], ["70794.60", "0.002"], ["74178.80", "0.002"]]}}
{"local_ts": 1773486894784, "server_ts": 1773486894752, "data": {"e": "depthUpdate", "E": 1773486894755, "T": 1773486894752, "s": "BTCUSDT", "U": 10109529522696, "u": 10109529528495, "pu": 10109529522460, "b": [["5000.00", "101.418"], ["7062.70", "0.000"], ["20126.50", "0.260"], ["20226.50", "2.550"], ["20326.50", "0.190"], ["69920.20", "6.425"], ["69920.30", "0.000"], ["70000.00", "125.188"], ["70273.50", "0.006"], ["70380.20", "0.000"], ["70442.90", "0.000"], ["70579.00", "0.002"], ["70579.10", "0.005"], ["70594.80", "0.367"], ["70595.30", "0.113"], ["70600.60", "0.102"], ["70600.70", "0.000"], ["70604.70", "0.002"], ["70606.50", "0.007"], ["70623.10", "0.187"]], "a": [["70647.80", "0.217"], ["70658.40", "0.000"], ["70659.20", "0.654"], ["70659.50", "0.523"], ["70665.70", "0.002"], ["70666.90", "0.247"], ["70710.30", "0.002"], ["70711.60", "0.002"], ["70716.60", "0.222"], ["70794.60", "0.000"], ["70799.40", "0.213"], ["71169.00", "0.397"], ["71332.90", "5.763"], ["73451.60", "0.058"], ["74191.30", "0.002"]]}}
{"local_ts": 1773486895803, "server_ts": 1773486895776, "data": {"e": "depthUpdate", "E": 1773486895777, "T": 1773486895776, "s": "BTCUSDT", "U": 10109529586744, "u": 10109529590854, "pu": 10109529586565, "b": [["1000.00", "26.592"], ["5000.00", "101.418"], ["7062.70", "0.000"], ["20126.50", "2.390"], ["20226.50", "0.490"], ["20526.50", "0.120"], ["67092.00", "0.002"], ["69432.90", "0.575"], ["69920.20", "6.425"], ["70273.40", "0.117"], ["70548.20", "0.330"], ["70578.90", "0.005"], ["70579.00", "0.002"], ["70605.40", "0.009"], ["70606.50", "0.000"], ["70619.50", "0.889"], ["70621.90", "0.022"], ["70622.30", "0.021"], ["70623.70", "0.031"], ["70624.90", "0.233"], ["70626.50", "5.870"]], "a": [["70626.60", "1.012"], ["70633.60", "0.007"], ["70634.90", "0.124"], ["70640.30", "0.010"], ["70647.80", "0.217"], ["70656.50", "0.010"], ["70658.40", "0.000"], ["70690.90", "0.050"], ["70763.90", "0.172"], ["70825.90", "0.000"], ["71332.90", "5.063"], ["71474.10", "7.265"], ["72039.10", "9.380"]]}}
{"local_ts": 1773486896824, "server_ts": 1773486896796, "data": {"e": "depthUpdate", "E": 1773486896797, "T": 1773486896796, "s": "BTCUSDT", "U": 10109529655320, "u": 10109529660211, "pu": 10109529655219, "b": [["5000.00", "101.418"], ["7063.00", "0.252"], ["20126.50", "0.830"], ["20530.00", "0.570"], ["69334.00", "0.150"], ["69461.20", "2.661"], ["69923.70", "0.000"], ["69997.80", "0.019"], ["70273.40", "0.081"], ["70442.80", "0.159"], ["70482.00", "0.136"], ["70494.40", "0.129"], ["70523.00", "7.990"], ["70544.00", "0.108"], ["70550.80", "0.288"], ["70556.40", "0.162"], ["70561.90", "0.000"], ["70563.20", "0.389"], ["70565.40", "0.780"], ["70565.70", "0.049"], ["70570.70", "0.009"], ["70573.50", "0.081"], ["70577.70", "0.001"], ["70579.80", "0.008"], ["70580.70", "0.001"], ["70581.20", "0.296"], ["70586.00", "0.002"], ["70589.90", "0.217"], ["70591.30", "1.676"], ["70592.70", "0.004"], ["70596.40", "1.232"], ["70597.50", "0.028"], ["70604.10", "0.268"], ["70608.20", "0.003"], ["70610.70", "0.002"], ["70611.90", "0.022"], ["70612.10", "1.221"], ["70613.50", "0.002"], ["70613.90", "0.023"], ["70614.20", "0.150"], ["70614.40", "0.003"], ["70614.90", "0.002"], ["70616.10", "0.076"], ["70618.90", "0.061"], ["70619.50", "0.904"], ["70621.00", "0.014"], ["70621.30", "0.002"], ["70621.70", "0.020"], ["70623.00", "0.150"], ["70623.10", "0.414"], ["70623.30", "1.066"], ["70623.40", "0.008"], ["70624.30", "0.001"], ["70624.90", "0.005"], ["70625.20", "0.339"], ["70625.90", "0.003"], ["70627.00", "0.001"], ["70629.70", "0.003"], ["70630.00", "3.303"]], "a": [["70630.10", "9.028"], ["70632.30", "0.053"], ["70633.80", "0.002"], ["70634.60", "0.003"], ["70635.30", "0.215"], ["70635.40", "0.003"], ["70636.00", "0.003"], ["70636.30", "0.079"], ["70636.40", "0.027"], ["70636.70", "0.003"], ["70637.20", "0.004"], ["70637.70", "0.382"], ["70639.00", "0.003"], ["70639.10", "0.005"], ["70640.60", "0.005"], ["70641.80", "0.001"], ["70641.90", "0.005"], ["70643.30", "0.003"], ["70643.50", "0.021"], ["70644.30", "0.000"], ["70644.40", "0.010"], ["70644.60", "0.002"], ["70646.40", "0.424"], ["70646.60", "0.000"], ["70646.90", "0.022"], ["70647.10", "0.323"], ["70651.30", "0.005"], ["70652.70", "0.075"], ["70653.70", "0.001"], ["70654.60", "0.395"], ["70654.70", "0.647"], ["70654.90", "0.026"], ["70655.60", "0.001"], ["70656.00", "0.004"], ["70656.70", "0.024"], ["70659.20", "0.088"], ["70660.60", "0.000"], ["70661.40", "0.372"], ["70661.60", "0.029"], ["70668.80", "0.072"], ["70668.90", "1.867"], ["70672.70", "0.055"], ["70679.50", "0.001"], ["70681.20", "0.001"], ["70681.40", "0.779"], ["70685.40", "0.112"], ["70686.30", "0.007"], ["70689.40", "0.219"], ["70689.90", "1.658"], ["70690.20", "3.438"], ["70693.70", "0.041"], ["70696.80", "0.060"], ["70700.20", "0.018"], ["70700.70", "0.023"], ["70703.90", "0.283"], ["70708.00", "0.718"], ["70723.80", "1.604"], ["70724.20", "0.002"], ["70821.20", "0.019"], ["70823.20", "0.024"], ["70844.80", "0.350"], ["70850.70", "0.000"], ["71336.40", "0.000"], ["74178.00", "0.050"]]}}
{"local_ts": 1773486897845, "server_ts": 1773486897816, "data": {"e": "depthUpdate", "E": 1773486897817, "T": 1773486897816, "s": "BTCUSDT", "U": 10109529697911, "u": 10109529701678, "pu": 10109529697841, "b": [["5000.00", "101.418"], ["7063.00", "0.308"], ["20430.00", "1.730"], ["20526.50", "0.950"], ["20530.00", "0.320"], ["67084.60", "0.002"], ["69544.60", "0.000"], ["69549.20", "0.465"], ["69676.50", "0.287"], ["69923.70", "0.000"], ["70276.90", "0.040"], ["70492.40", "0.685"], ["70542.30", "0.119"], ["70581.50", "0.020"], ["70581.60", "0.007"], ["70592.80", "0.841"], ["70598.60", "0.511"], ["70600.20", "0.272"], ["70600.40", "0.000"], ["70600.50", "0.020"], ["70601.80", "1.159"], ["70601.90", "0.829"], ["70602.70", "0.393"], ["70612.10", "1.223"]], "a": [["70630.10", "6.127"], ["70654.60", "0.231"], ["70693.80", "0.870"], ["70760.90", "1.003"], ["70771.40", "0.135"], ["70816.00", "0.320"], ["70821.20", "0.017"], ["71336.40", "0.000"], ["71747.00", "0.056"], ["71934.80", "0.279"], ["74194.60", "0.000"]]}}
{"local_ts": 1773486898864, "server_ts": 1773486898836, "data": {"e": "depthUpdate", "E": 1773486898837, "T": 1773486898836, "s": "BTCUSDT", "U": 10109529733191, "u": 10109529736527, "pu": 10109529733105, "b": [["1000.00", "26.592"], ["5000.00", "101.418"], ["7063.00", "0.308"], ["20330.00", "1.280"], ["20430.00", "1.720"], ["33000.00", "3.785"], ["63567.00", "0.002"], ["67078.70", "0.002"], ["67091.30", "0.000"], ["67098.50", "0.002"], ["68206.10", "0.021"], ["69206.10", "0.002"], ["69923.70", "0.000"], ["70475.70", "0.255"], ["70479.00", "0.084"], ["70592.80", "0.841"], ["70594.70", "0.335"], ["70599.10", "0.445"], ["70599.20", "0.379"], ["70600.10", "0.357"], ["70600.20", "0.102"], ["70600.50", "0.020"], ["70604.50", "0.055"]], "a": [["70630.10", "6.123"], ["70662.00", "0.048"], ["70665.40", "0.038"], ["70674.40", "0.005"], ["70796.10", "0.159"], ["70816.00", "0.318"], ["70816.80", "0.002"], ["71336.40", "0.700"], ["71567.00", "0.362"], ["77693.10", "0.002"]]}}
{"local_ts": 1773486899884, "server_ts": 1773486899856, "data": {"e": "depthUpdate", "E": 1773486899857, "T": 1773486899856, "s": "BTCUSDT", "U": 10109529772625, "u": 10109529776651, "pu": 10109529772587, "b": [["5000.00", "101.398"], ["7063.00", "0.308"], ["20230.00", "0.830"], ["20330.00", "2.170"], ["56504.00", "0.000"], ["63567.00", "0.002"], ["67068.80", "0.000"], ["67098.00", "0.000"], ["68844.40", "2.617"], ["69847.20", "0.002"], ["69923.70", "0.714"], ["69923.80", "0.000"], ["70277.00", "0.108"], ["70383.30", "0.002"], ["70383.80", "0.256"], ["70416.90", "10.594"], ["70417.10", "0.299"], ["70442.80", "0.000"], ["70446.40", "0.185"], ["70454.10", "0.000"], ["70454.20", "3.530"], ["70454.30", "0.803"], ["70493.10", "1.061"], ["70534.90", "0.002"], ["70535.30", "0.700"], ["70541.90", "0.519"], ["70542.30", "0.261"], ["70549.00", "0.000"], ["70549.40", "0.144"], ["70575.80", "0.000"], ["70581.90", "0.005"], ["70582.10", "0.481"], ["70593.70", "0.542"], ["70597.40", "0.060"], ["70600.10", "0.003"], ["70601.70", "0.002"], ["70602.10", "0.186"], ["70603.90", "0.170"], ["70604.40", "0.003"], ["70614.70", "0.000"], ["70615.00", "0.278"], ["70615.80", "0.092"], ["70616.80", "0.509"], ["70619.40", "0.210"], ["70622.80", "0.001"], ["70623.10", "0.414"]], "a": [["70630.10", "5.753"], ["70637.10", "0.034"], ["70637.20", "1.552"], ["70639.90", "0.098"], ["70640.70", "0.041"], ["70644.50", "0.004"], ["70646.20", "0.010"], ["70651.70", "0.002"], ["70652.50", "0.057"], ["70658.90", "0.001"], ["70659.80", "0.660"], ["70659.90", "0.005"], ["70661.10", "0.512"], ["70663.40", "0.025"], ["70663.80", "0.010"], ["70664.30", "0.200"], ["70665.00", "0.861"], ["70669.00", "0.347"], ["70671.20", "0.054"], ["70676.20", "0.019"], ["70679.90", "0.021"], ["70704.40", "0.000"], ["70708.00", "0.860"], ["70711.50", "0.000"], ["70715.10", "0.142"], ["70718.50", "0.250"], ["70722.10", "0.142"], ["70761.00", "0.749"], ["70799.80", "3.961"], ["70816.80", "0.000"], ["70818.30", "0.002"], ["70833.70", "0.000"], ["70836.90", "0.862"], ["70853.60", "0.000"], ["70854.20", "10.321"], ["71336.30", "0.000"], ["71336.40", "0.700"], ["74176.20", "0.002"], ["77693.10", "0.002"], ["89523.20", "0.000"]]}}
{"local_ts": 1773486900909, "server_ts": 1773486900876, "data": {"e": "depthUpdate", "E": 1773486900877, "T": 1773486900876, "s": "BTCUSDT", "U": 10109529873891, "u": 10109529884931, "pu": 10109529873855, "b": [["1000.00", "26.592"], ["5000.00", "101.418"], ["7063.00", "0.280"], ["20130.00", "0.400"], ["20230.00", "2.570"], ["20330.00", "0.030"], ["67080.80", "0.002"], ["67804.80", "0.028"], ["69394.00", "0.409"], ["69611.30", "1.148"], ["69913.80", "0.000"], ["69923.70", "0.714"], ["70465.10", "0.042"], ["70470.30", "0.094"], ["70471.30", "0.000"], ["70474.90", "0.135"], ["70475.50", "0.011"], ["70475.90", "0.093"], ["70477.40", "0.093"], ["70552.30", "0.094"], ["70566.40", "0.000"], ["70582.10", "0.481"], ["70582.30", "0.005"], ["70602.00", "0.193"], ["70603.90", "0.184"], ["70604.80", "0.294"], ["70604.90", "0.012"], ["70609.50", "0.034"], ["70614.60", "0.128"], ["70615.60", "0.004"], ["70616.40", "0.509"], ["70618.20", "0.001"], ["70619.40", "0.280"], ["70621.20", "0.317"], ["70622.20", "0.004"], ["70622.50", "0.067"], ["70622.80", "0.015"], ["70622.90", "0.092"], ["70623.00", "0.118"], ["70623.40", "0.026"], ["70626.50", "1.130"], ["70626.90", "0.362"], ["70630.00", "5.568"]], "a": [["70630.10", "0.287"], ["70630.80", "0.002"], ["70630.90", "0.000"], ["70631.00", "0.000"], ["70631.10", "0.000"], ["70631.30", "0.000"], ["70631.60", "0.061"], ["70632.80", "0.016"], ["70633.40", "0.000"], ["70634.50", "0.000"], ["70640.40", "0.007"], ["70640.70", "0.041"], ["70643.20", "0.000"], ["70644.10", "0.002"], ["70644.50", "0.061"], ["70647.10", "0.191"], ["70647.20", "0.004"], ["70647.60", "0.028"], ["70647.80", "0.373"], ["70649.00", "0.008"], ["70649.70", "0.043"], ["70651.50", "0.015"], ["70652.60", "0.019"], ["70654.20", "0.019"], ["70657.40", "0.013"], ["70658.40", "0.079"], ["70663.10", "0.003"], ["70664.40", "0.019"], ["70672.50", "1.068"], ["70678.70", "0.810"], ["70679.40", "0.010"], ["70684.80", "0.000"], ["70689.40", "0.315"], ["70693.70", "0.038"], ["70695.10", "0.010"], ["70707.80", "0.000"], ["70796.10", "0.159"], ["70818.30", "0.000"], ["70823.60", "2.236"], ["71336.40", "1.029"], ["89523.20", "0.000"]]}}
{"local_ts": 1773486901926, "server_ts": 1773486901896, "data": {"e": "depthUpdate", "E": 1773486901899, "T": 1773486901896, "s": "BTCUSDT", "U": 10109529965787, "u": 10109529974588, "pu": 10109529965692, "b": [["1000.00", "26.592"], ["5000.00", "101.438"], ["7063.20", "0.028"], ["20131.40", "1.950"], ["20230.00", "0.290"], ["20531.40", "0.220"], ["33000.00", "3.785"], ["63568.30", "0.002"], ["66129.00", "4.005"], ["66832.50", "3.000"], ["67080.80", "0.000"], ["67099.80", "0.006"], ["69571.60", "0.007"], ["69638.40", "0.038"], ["69879.80", "0.785"], ["69925.10", "0.131"], ["70002.70", "0.040"], ["70156.00", "0.322"], ["70447.80", "0.159"], ["70475.70", "0.084"], ["70479.00", "0.000"], ["70485.60", "0.000"], ["70488.30", "0.505"], ["70490.70", "0.002"], ["70515.40", "0.002"], ["70591.50", "0.188"], ["70596.10", "1.105"], ["70597.80", "0.279"], ["70603.00", "0.026"], ["70604.00", "0.008"], ["70605.20", "0.641"], ["70605.70", "0.000"], ["70606.20", "0.007"], ["70609.60", "0.002"], ["70610.60", "0.336"], ["70612.10", "0.005"], ["70613.20", "0.004"], ["70614.80", "0.509"], ["70615.10", "0.007"], ["70616.40", "0.000"], ["70617.40", "0.005"], ["70618.30", "0.008"], ["70622.50", "0.117"], ["70623.20", "0.013"], ["70623.30", "1.068"], ["70623.40", "0.644"], ["70623.90", "0.001"], ["70624.60", "0.002"], ["70625.20", "0.000"], ["70626.10", "0.066"], ["70626.60", "0.521"], ["70626.80", "0.365"], ["70627.10", "0.000"], ["70627.50", "0.017"], ["70627.60", "0.005"], ["70628.00", "0.008"], ["70628.70", "0.005"], ["70629.00", "0.006"], ["70629.10", "0.072"], ["70629.20", "0.000"], ["70629.30", "0.000"], ["70629.40", "0.000"], ["70629.60", "0.007"], ["70629.90", "0.008"], ["70630.00", "0.469"], ["70630.10", "0.002"], ["70630.40", "0.097"], ["70631.20", "0.103"], ["70631.30", "0.640"], ["70631.40", "7.926"]], "a": [["70631.50", "4.796"], ["70631.60", "0.062"], ["70631.90", "0.005"], ["70632.50", "0.001"], ["70632.80", "0.001"], ["70633.10", "0.058"], ["70633.80", "0.002"], ["70633.90", "0.003"], ["70634.60", "0.010"], ["70634.80", "0.004"], ["70635.40", "0.003"], ["70636.40", "0.055"], ["70636.70", "0.004"], ["70636.90", "0.000"], ["70637.00", "0.008"], ["70637.10", "0.006"], ["70637.30", "0.073"], ["70637.50", "0.035"], ["70637.90", "0.212"], ["70638.30", "0.002"], ["70639.30", "0.028"], ["70639.50", "0.097"], ["70639.90", "0.116"], ["70640.20", "0.005"], ["70640.30", "0.008"], ["70641.00", "0.012"], ["70641.20", "0.072"], ["70641.30", "0.000"], ["70642.20", "0.015"], ["70643.40", "0.021"], ["70643.50", "0.015"], ["70645.40", "0.031"], ["70645.90", "0.018"], ["70647.10", "0.015"], ["70650.90", "0.009"], ["70651.60", "0.015"], ["70657.30", "0.059"], ["70657.40", "0.013"], ["70659.00", "0.056"], ["70659.40", "0.642"], ["70660.20", "0.511"], ["70661.20", "0.022"], ["70661.50", "0.656"], ["70661.60", "0.004"], ["70662.10", "0.011"], ["70662.70", "0.002"], ["70663.50", "0.000"], ["70663.80", "0.067"], ["70664.00", "0.006"], ["70665.50", "0.019"], ["70666.10", "0.595"], ["70666.80", "0.113"], ["70667.50", "0.039"], ["70668.80", "0.001"], ["70668.90", "0.252"], ["70669.60", "1.803"], ["70673.40", "0.001"], ["70674.30", "0.004"], ["70677.90", "0.367"], ["70678.20", "0.136"], ["70701.60", "8.509"], ["70702.40", "0.000"], ["70720.90", "0.006"], ["70777.60", "0.002"], ["71337.80", "0.007"], ["71535.60", "0.007"], ["72039.10", "0.000"], ["72044.10", "0.016"], ["74190.20", "0.002"], ["77694.60", "0.002"], ["89523.20", "0.000"]]}}
{"local_ts": 1773486902963, "server_ts": 1773486902920, "data": {"e": "depthUpdate", "E": 1773486902921, "T": 1773486902920, "s": "BTCUSDT", "U": 10109530023866, "u": 10109530028284, "pu": 10109530023816, "b": [["5000.00", "101.418"], ["7063.20", "0.028"], ["20130.00", "0.110"], ["20131.40", "0.460"], ["20431.40", "0.070"], ["20531.40", "2.350"], ["63568.30", "0.010"], ["67065.20", "0.010"], ["69091.10", "0.000"], ["69290.90", "4.326"], ["69883.10", "0.857"], ["69925.10", "0.131"], ["69982.90", "0.000"], ["70278.20", "0.106"], ["70373.70", "0.000"], ["70417.10", "0.000"], ["70437.20", "2.500"], ["70494.30", "0.001"], ["70496.50", "1.144"], ["70497.30", "8.837"], ["70500.10", "2.525"], ["70581.90", "0.005"], ["70583.40", "0.047"], ["70583.50", "0.300"], ["70590.60", "0.009"], ["70591.50", "0.188"], ["70592.00", "0.416"], ["70605.30", "0.624"], ["70605.40", "0.013"], ["70605.50", "0.096"], ["70620.80", "0.072"], ["70623.70", "0.032"], ["70630.00", "0.385"], ["70630.10", "0.059"], ["70631.40", "7.629"]], "a": [["70631.50", "4.037"], ["70633.10", "0.001"], ["70634.20", "0.059"], ["70640.70", "0.002"], ["70640.90", "0.003"], ["70641.20", "0.051"], ["70642.10", "0.039"], ["70642.20", "0.000"], ["70643.50", "0.000"], ["70643.70", "0.015"], ["70654.10", "0.031"], ["70659.20", "0.024"], ["70759.00", "6.573"], ["70759.70", "1.532"], ["70759.80", "0.205"], ["70763.50", "7.947"], ["70772.80", "0.039"], ["70836.90", "0.003"], ["70855.00", "0.018"], ["70855.10", "0.012"], ["70884.50", "0.000"], ["70953.00", "0.008"], ["71337.70", "0.000"], ["71337.80", "0.007"], ["71474.10", "6.986"], ["71669.80", "1.323"], ["71693.90", "0.005"], ["74188.70", "0.000"], ["77694.60", "0.010"], ["89523.20", "0.000"]]}}
{"local_ts": 1773486903972, "server_ts": 1773486903940, "data": {"e": "depthUpdate", "E": 1773486903941, "T": 1773486903940, "s": "BTCUSDT", "U": 10109530074850, "u": 10109530080998, "pu": 10109530074681, "b": [["1000.00", "26.592"], ["5000.00", "101.418"], ["7063.20", "0.000"], ["20431.40", "2.040"], ["20531.40", "0.960"], ["33000.00", "3.789"], ["63568.30", "0.008"], ["69310.60", "0.432"], ["69431.30", "2.588"], ["69925.10", "0.131"], ["70212.80", "6.233"], ["70278.20", "0.000"], ["70303.00", "0.217"], ["70318.50", "4.901"], ["70537.00", "1.582"], ["70538.70", "0.364"], ["70542.90", "0.280"], ["70544.50", "0.000"], ["70545.10", "0.021"], ["70546.20", "0.003"], ["70546.80", "0.002"], ["70547.20", "0.094"], ["70547.50", "0.202"], ["70547.90", "0.278"], ["70548.20", "0.330"], ["70564.60", "0.000"], ["70565.90", "0.002"], ["70568.70", "0.085"], ["70569.60", "0.115"], ["70570.30", "0.056"], ["70571.20", "0.871"], ["70571.30", "0.000"], ["70571.40", "0.012"], ["70571.60", "0.010"], ["70572.00", "0.094"], ["70572.30", "0.000"], ["70572.60", "1.191"], ["70583.30", "0.037"], ["70583.40", "0.045"], ["70619.90", "0.529"], ["70620.00", "0.012"], ["70620.10", "0.008"], ["70620.30", "0.027"], ["70620.40", "0.021"], ["70620.50", "0.000"], ["70620.60", "0.124"], ["70620.80", "0.007"], ["70621.10", "0.003"], ["70621.50", "0.104"], ["70621.70", "0.000"], ["70624.20", "0.010"], ["70626.50", "0.595"]], "a": [["70631.50", "2.727"], ["70638.20", "0.003"], ["70638.40", "0.000"], ["70638.80", "0.004"], ["70639.20", "0.006"], ["70639.30", "0.003"], ["70639.50", "0.057"], ["70639.60", "0.004"], ["70639.80", "0.002"], ["70639.90", "0.026"], ["70640.00", "0.165"], ["70642.10", "0.036"], ["70646.30", "0.015"], ["70657.10", "0.206"], ["70662.80", "0.010"], ["70663.20", "0.012"], ["70663.40", "0.000"], ["70663.60", "0.000"], ["70663.90", "0.315"], ["70664.30", "0.092"], ["70664.50", "0.233"], ["70665.10", "0.053"], ["70665.20", "0.002"], ["70665.40", "0.010"], ["70666.10", "0.842"], ["70666.70", "0.004"], ["70667.60", "0.000"], ["70668.90", "0.005"], ["70674.30", "0.004"], ["70687.30", "0.000"], ["70687.60", "0.002"], ["70688.00", "1.261"], ["70688.30", "0.061"], ["70688.40", "0.000"], ["70688.50", "0.000"], ["70688.70", "0.020"], ["70689.60", "0.602"], ["70690.30", "0.019"], ["70691.20", "0.000"], ["70694.00", "0.493"], ["70695.30", "0.002"], ["70878.50", "5.417"], ["70956.50", "4.661"], ["71337.80", "0.007"], ["71643.10", "6.272"], ["71784.30", "0.167"], ["74174.30", "0.002"], ["77694.60", "0.008"], ["89523.20", "0.000"]]}}
{"local_ts": 1773486904991, "server_ts": 1773486904960, "data": {"e": "depthUpdate", "E": 1773486904965, "T": 1773486904960, "s": "BTCUSDT", "U": 10109530121676, "u": 10109530124886, "pu": 10109530121584, "b": [["5000.00", "101.418"], ["7063.20", "0.000"], ["20331.40", "1.590"], ["20431.40", "1.410"], ["56505.00", "0.000"], ["63568.30", "0.016"], ["67077.60", "0.006"], ["69217.40", "0.011"], ["69607.20", "2.010"], ["69642.60", "7.597"], ["69925.10", "0.131"], ["70278.20", "0.142"], ["70385.30", "0.004"], ["70444.20", "0.002"], ["70494.40", "0.129"], ["70501.30", "0.625"], ["70503.20", "0.582"], ["70505.70", "0.129"], ["70509.90", "0.171"], ["70514.20", "12.554"], ["70582.80", "0.004"], ["70582.90", "0.002"], ["70600.00", "0.950"], ["70622.10", "0.180"], ["70624.20", "0.010"]], "a": [["70631.50", "3.140"], ["70642.10", "0.061"], ["70645.20", "0.001"], ["70669.10", "0.079"], ["70670.60", "0.158"], ["70676.70", "0.417"], ["70759.90", "0.085"], ["70762.50", "0.089"], ["70902.60", "0.447"], ["71196.60", "0.142"], ["71337.80", "1.407"], ["71401.00", "0.020"], ["72031.10", "0.594"], ["77694.60", "0.016"], ["89523.20", "0.000"]]}}
{"local_ts": 1773486906018, "server_ts": 1773486905988, "data": {"e": "depthUpdate", "E": 1773486905989, "T": 1773486905988, "s": "BTCUSDT", "U": 10109530159673, "u": 10109530163976, "pu": 10109530159628, "b": [["1000.00", "26.592"], ["5000.00", "101.418"], ["7063.20", "0.000"], ["20231.40", "1.160"], ["20331.40", "1.840"], ["63568.30", "0.016"], ["67083.60", "0.000"], ["69217.40", "0.002"], ["69218.80", "0.016"], ["69348.70", "1.255"], ["69430.70", "3.164"], ["69602.40", "10.474"], ["69925.10", "0.131"], ["70278.20", "0.284"], ["70471.50", "2.473"], ["70480.50", "0.041"], ["70481.60", "0.000"], ["70486.70", "0.557"], ["70490.70", "0.043"], ["70494.70", "0.668"], ["70500.00", "4.024"], ["70501.10", "0.102"], ["70510.80", "0.002"], ["70533.80", "0.041"], ["70537.70", "0.041"], ["70539.60", "0.047"], ["70546.70", "0.047"], ["70547.30", "0.135"], ["70550.20", "0.190"], ["70552.90", "0.556"], ["70554.10", "0.109"], ["70582.80", "0.004"], ["70582.90", "0.002"], ["70615.40", "0.074"], ["70616.60", "0.025"], ["70617.80", "0.007"], ["70621.30", "0.004"], ["70624.40", "0.007"], ["70626.50", "0.593"], ["70629.50", "0.084"]], "a": [["70631.70", "0.000"], ["70631.80", "0.002"], ["70632.40", "0.057"], ["70638.50", "0.004"], ["70639.90", "0.008"], ["70649.10", "0.041"], ["70708.20", "0.002"], ["70709.80", "1.702"], ["70762.50", "0.675"], ["70778.30", "0.041"], ["71320.40", "0.000"], ["71337.80", "1.407"], ["73456.70", "0.218"], ["77694.60", "0.016"], ["89523.20", "0.000"], ["115844.00", "0.170"]]}}
{"local_ts": 1773486907036, "server_ts": 1773486907007, "data": {"e": "depthUpdate", "E": 1773486907009, "T": 1773486907007, "s": "BTCUSDT", "U": 10109530205465, "u": 10109530210962, "pu": 10109530205388, "b": [["5000.00", "101.418"], ["7063.20", "0.056"], ["20131.40", "0.700"], ["20231.40", "2.300"], ["20331.40", "0.000"], ["63568.30", "0.016"], ["67077.60", "0.004"], ["67099.00", "0.000"], ["67099.40", "0.002"], ["68914.50", "0.621"], ["69138.80", "0.391"], ["69351.00", "0.127"], ["69531.80", "5.099"], ["69536.60", "5.028"], ["69607.20", "11.046"], ["69649.60", "3.438"], ["69925.10", "0.131"], ["70444.20", "0.161"], ["70447.80", "0.000"], ["70500.50", "0.086"], ["70583.80", "0.005"], ["70585.40", "0.011"], ["70590.10", "0.141"], ["70595.40", "0.117"], ["70596.10", "1.105"], ["70602.50", "0.052"], ["70603.10", "0.333"], ["70603.90", "0.170"], ["70605.10", "0.000"], ["70605.20", "0.556"], ["70605.30", "0.709"], ["70607.20", "0.002"], ["70614.10", "0.578"], ["70615.50", "0.052"], ["70616.80", "0.070"], ["70620.80", "0.000"], ["70622.60", "0.666"], ["70624.20", "0.007"], ["70631.40", "7.581"]], "a": [["70631.50", "1.205"], ["70634.70", "0.000"], ["70637.30", "0.073"], ["70642.10", "0.125"], ["70643.90", "0.009"], ["70645.80", "0.060"], ["70646.10", "0.189"], ["70646.80", "0.016"], ["70649.10", "0.435"], ["70649.20", "0.030"], ["70650.00", "4.529"], ["70650.10", "0.026"], ["70650.20", "1.169"], ["70650.40", "0.030"], ["70650.70", "0.000"], ["70651.10", "0.006"], ["70652.40", "0.199"], ["70652.60", "0.004"], ["70652.80", "0.021"], ["70652.90", "0.041"], ["70653.00", "1.083"], ["70654.10", "0.016"], ["70654.40", "0.007"], ["70655.00", "0.028"], ["70655.30", "0.003"], ["70655.40", "0.010"], ["70656.60", "0.000"], ["70657.30", "0.040"], ["70657.90", "0.007"], ["70659.20", "0.024"], ["70660.00", "0.092"], ["70660.40", "0.830"], ["70661.70", "0.451"], ["70662.40", "0.638"], ["70662.70", "0.513"], ["70662.90", "1.846"], ["70664.10", "0.039"], ["70664.20", "0.040"], ["70665.40", "0.025"], ["70666.70", "0.089"], ["70666.80", "0.113"], ["70667.00", "0.063"], ["70668.00", "0.035"], ["70668.90", "0.252"], ["70669.00", "0.368"], ["70669.20", "0.027"], ["70669.40", "0.070"], ["70670.50", "0.017"], ["70670.90", "0.026"], ["70671.70", "0.009"], ["70672.10", "0.052"], ["70672.90", "0.024"], ["70673.00", "1.631"], ["70677.80", "0.057"], ["70681.30", "0.061"], ["70688.20", "0.009"], ["70699.50", "0.002"], ["70700.50", "1.795"], ["70701.50", "8.486"], ["70707.20", "2.638"], ["70732.60", "0.134"], ["70739.10", "0.114"], ["70758.10", "0.126"], ["70809.10", "0.000"], ["71337.80", "1.547"], ["71726.30", "3.285"], ["71832.20", "1.668"], ["72044.10", "0.016"], ["74163.60", "0.009"], ["77694.60", "0.016"], ["89523.20", "0.000"]]}}
{"local_ts": 1773486908057, "server_ts": 1773486908028, "data": {"e": "depthUpdate", "E": 1773486908029, "T": 1773486908028, "s": "BTCUSDT", "U": 10109530276039, "u": 10109530282782, "pu": 10109530275893, "b": [["1000.00", "26.592"], ["5000.00", "101.418"], ["7063.20", "0.056"], ["20131.40", "2.600"], ["20231.40", "0.070"], ["20531.40", "0.330"], ["56505.00", "0.000"], ["63568.30", "0.016"], ["68914.50", "0.000"], ["69280.40", "0.002"], ["69461.20", "0.649"], ["69602.40", "4.449"], ["69628.40", "0.286"], ["69925.10", "0.131"], ["70278.20", "3.266"], ["70433.60", "2.129"], ["70437.20", "2.659"], ["70444.20", "0.062"], ["70465.40", "1.921"], ["70478.60", "0.023"], ["70481.90", "0.002"], ["70482.00", "0.025"], ["70482.60", "1.128"], ["70541.10", "0.000"], ["70541.70", "1.110"], ["70560.90", "0.005"], ["70574.90", "0.131"], ["70576.60", "0.285"], ["70576.70", "1.087"], ["70597.90", "0.005"], ["70602.00", "0.179"], ["70603.90", "0.184"], ["70607.00", "0.062"], ["70607.10", "0.088"]], "a": [["70645.70", "0.006"], ["70671.00", "7.878"], ["70692.20", "0.003"], ["70698.50", "0.002"], ["70722.00", "1.456"], ["70723.30", "0.107"], ["70780.70", "0.460"], ["70782.10", "0.186"], ["70782.20", "0.093"], ["70797.10", "0.018"], ["70802.10", "0.000"], ["70804.90", "0.002"], ["70855.20", "0.007"], ["70896.40", "0.294"], ["70984.60", "0.007"], ["71337.80", "1.547"], ["71650.70", "10.736"], ["71655.70", "13.931"], ["71761.60", "3.896"], ["71791.90", "1.600"], ["74170.80", "0.005"], ["74197.70", "0.000"], ["77694.60", "0.016"], ["89523.20", "0.000"]]}}
{"local_ts": 1773486909097, "server_ts": 1773486909058, "data": {"e": "depthUpdate", "E": 1773486909061, "T": 1773486909058, "s": "BTCUSDT", "U": 10109530335871, "u": 10109530342496, "pu": 10109530335752, "b": [["1000.00", "26.592"], ["5000.00", "101.418"], ["7063.20", "0.056"], ["20131.40", "0.350"], ["20431.40", "0.180"], ["20531.40", "2.470"], ["69466.00", "3.019"], ["69552.20", "1.004"], ["69925.10", "0.131"], ["70433.60", "2.030"], ["70538.40", "0.003"], ["70540.20", "1.502"], ["70544.40", "0.003"], ["70545.90", "0.000"], ["70546.60", "0.000"], ["70547.70", "0.088"], ["70548.30", "0.002"], ["70548.60", "0.090"], ["70548.70", "0.372"], ["70549.00", "0.000"], ["70549.40", "0.002"], ["70549.70", "0.697"], ["70566.10", "1.066"], ["70567.40", "0.022"], ["70570.20", "0.001"], ["70571.00", "0.539"], ["70571.10", "0.085"], ["70571.80", "0.003"], ["70572.70", "0.101"], ["70572.90", "0.294"], ["70573.10", "0.662"], ["70573.40", "0.000"], ["70573.70", "0.119"], ["70573.80", "0.772"], ["70574.10", "0.085"], ["70574.90", "0.050"], ["70580.70", "3.544"], ["70602.00", "1.825"], ["70618.70", "0.000"], ["70621.30", "0.087"], ["70621.40", "0.000"], ["70621.60", "0.001"], ["70621.80", "0.005"], ["70621.90", "0.131"], ["70622.10", "0.137"], ["70622.30", "0.516"], ["70622.50", "0.143"], ["70622.60", "0.532"], ["70623.00", "0.118"], ["70623.20", "0.298"]], "a": [["70640.90", "0.003"], ["70641.00", "0.048"], ["70641.10", "0.000"], ["70641.40", "0.002"], ["70641.80", "0.001"], ["70642.00", "0.579"], ["70642.10", "0.100"], ["70642.20", "0.337"], ["70642.30", "0.000"], ["70642.50", "0.007"], ["70642.60", "0.099"], ["70642.70", "0.000"], ["70649.70", "0.020"], ["70651.00", "0.009"], ["70651.60", "0.000"], ["70652.20", "0.017"], ["70653.00", "1.089"], ["70657.10", "0.183"], ["70663.60", "0.070"], ["70665.40", "0.046"], ["70665.50", "0.021"], ["70665.90", "0.533"], ["70666.00", "0.023"], ["70666.20", "1.122"], ["70666.60", "0.097"], ["70666.90", "0.000"], ["70667.00", "0.027"], ["70667.10", "0.000"], ["70667.30", "0.095"], ["70667.80", "0.002"], ["70668.10", "0.040"], ["70669.40", "0.034"], ["70670.30", "0.007"], ["70670.90", "1.827"], ["70689.90", "1.658"], ["70690.30", "0.019"], ["70690.70", "0.017"], ["70691.00", "0.000"], ["70691.20", "0.000"], ["70691.30", "0.002"], ["70691.40", "0.211"], ["70692.30", "3.691"], ["70693.00", "0.002"], ["70693.90", "1.190"], ["70696.60", "5.154"], ["70698.00", "0.018"], ["70718.90", "0.045"], ["70723.30", "0.001"], ["70803.50", "0.019"], ["70804.90", "0.000"], ["71161.20", "0.702"], ["71337.80", "1.547"], ["71565.90", "5.090"], ["74163.60", "0.007"], ["74179.50", "0.052"], ["89523.20", "0.000"]]}}
{"local_ts": 1773486910110, "server_ts": 1773486910080, "data": {"e": "depthUpdate", "E": 1773486910081, "T": 1773486910080, "s": "BTCUSDT", "U": 10109530395921, "u": 10109530402088, "pu": 10109530395730, "b": [["5000.00", "101.398"], ["7063.20", "0.028"], ["20331.40", "0.040"], ["20431.40", "2.310"], ["20531.40", "0.650"], ["67076.20", "0.002"], ["67095.30", "0.000"], ["69619.00", "0.000"], ["69730.10", "0.135"], ["69870.70", "0.013"], ["69925.10", "1.559"], ["70318.60", "0.000"], ["70384.90", "0.004"], ["70433.60", "2.030"], ["70465.40", "1.882"], ["70485.90", "0.033"], ["70488.10", "0.264"], ["70574.90", "0.050"], ["70581.10", "0.000"], ["70583.20", "0.004"], ["70583.30", "0.035"], ["70587.90", "1.778"], ["70588.00", "0.006"], ["70588.20", "0.001"], ["70592.00", "0.277"], ["70592.60", "0.182"], ["70595.30", "0.117"], ["70599.60", "0.458"], ["70601.90", "1.200"], ["70602.40", "0.003"], ["70603.10", "0.484"], ["70604.90", "0.151"], ["70606.60", "0.002"], ["70606.90", "0.098"], ["70609.50", "0.034"], ["70611.50", "0.254"], ["70611.60", "0.269"], ["70612.10", "0.005"], ["70612.90", "0.515"], ["70615.10", "0.000"], ["70615.80", "1.216"], ["70617.10", "0.079"], ["70618.70", "0.000"], ["70622.50", "0.198"], ["70623.30", "1.706"], ["70624.00", "0.003"], ["70624.10", "0.009"], ["70624.30", "0.200"], ["70628.90", "0.000"], ["70629.60", "0.014"], ["70631.40", "5.193"]], "a": [["70631.50", "1.045"], ["70641.00", "0.041"], ["70641.10", "0.255"], ["70641.30", "0.043"], ["70642.10", "0.111"], ["70645.30", "0.080"], ["70648.50", "0.000"], ["70652.10", "0.001"], ["70653.30", "0.715"], ["70653.50", "0.015"], ["70655.10", "0.019"], ["70655.30", "0.024"], ["70655.80", "0.029"], ["70656.50", "0.018"], ["70657.00", "0.000"], ["70658.80", "0.000"], ["70659.20", "1.169"], ["70659.50", "0.016"], ["70666.10", "0.671"], ["70666.30", "0.000"], ["70667.40", "0.039"], ["70668.60", "0.006"], ["70668.90", "0.288"], ["70669.90", "0.290"], ["70670.90", "1.827"], ["70672.90", "0.003"], ["70673.40", "0.001"], ["70680.50", "0.002"], ["70682.90", "0.218"], ["70697.70", "8.487"], ["70699.50", "0.002"], ["70755.30", "0.184"], ["70772.80", "0.000"], ["70803.50", "0.017"], ["70823.70", "0.002"], ["70868.10", "0.000"], ["71192.80", "0.017"], ["71249.90", "3.243"], ["71337.80", "2.947"], ["71742.70", "0.000"], ["71926.60", "1.389"], ["89523.20", "0.000"]]}}
{"local_ts": 1773486911135, "server_ts": 1773486911104, "data": {"e": "depthUpdate", "E": 1773486911107, "T": 1773486911104, "s": "BTCUSDT", "U": 10109530510103, "u": 10109530515108, "pu": 10109530510036, "b": [["1000.00", "26.742"], ["5000.00", "101.418"], ["7063.20", "0.028"], ["20331.40", "1.950"], ["20431.40", "1.050"], ["33000.00", "3.785"], ["69335.40", "8.640"], ["69925.10", "1.559"], ["70278.20", "3.692"], ["70278.30", "0.000"], ["70384.70", "0.165"], ["70478.60", "0.023"], ["70484.00", "0.002"], ["70574.90", "0.131"], ["70595.10", "1.763"], ["70599.60", "0.655"], ["70605.10", "0.000"], ["70605.20", "0.085"], ["70605.70", "0.000"], ["70607.30", "0.002"], ["70609.00", "0.064"], ["70609.30", "0.010"], ["70610.10", "1.203"], ["70615.60", "0.287"], ["70617.10", "0.152"], ["70618.70", "0.007"], ["70622.20", "0.131"], ["70622.70", "0.346"], ["70624.30", "0.448"], ["70625.70", "0.016"], ["70626.20", "0.142"]], "a": [["70638.40", "0.002"], ["70644.10", "0.059"], ["70645.00", "0.103"], ["70645.40", "1.170"], ["70645.50", "0.166"], ["70648.60", "0.021"], ["70649.90", "0.010"], ["70653.60", "0.161"], ["70661.40", "0.007"], ["70662.40", "0.249"], ["70664.70", "0.086"], ["70665.60", "0.052"], ["70666.90", "1.758"], ["70678.30", "0.068"], ["70679.20", "0.006"], ["70755.30", "0.182"], ["70786.90", "0.005"], ["70792.10", "0.009"], ["70797.10", "0.018"], ["70823.70", "0.000"], ["71200.00", "11.814"], ["71337.80", "2.947"], ["71401.40", "2.584"], ["71600.00", "113.568"], ["74192.50", "0.050"], ["89523.20", "0.000"]]}}
{"local_ts": 1773486912156, "server_ts": 1773486912128, "data": {"e": "depthUpdate", "E": 1773486912129, "T": 1773486912128, "s": "BTCUSDT", "U": 10109530561001, "u": 10109530566470, "pu": 10109530560976, "b": [["5000.00", "101.418"], ["7063.20", "0.028"], ["20231.40", "1.510"], ["20331.40", "1.490"], ["63302.30", "0.000"], ["67069.60", "0.000"], ["69395.40", "1.155"], ["69543.20", "0.000"], ["69548.20", "1.434"], ["69925.10", "1.559"], ["69925.20", "0.000"], ["70096.80", "0.712"], ["70370.40", "0.000"], ["70384.70", "0.165"], ["70581.10", "0.000"], ["70583.80", "0.007"], ["70584.00", "0.073"], ["70588.20", "0.001"], ["70595.30", "0.117"], ["70599.00", "0.241"], ["70600.10", "0.117"], ["70602.40", "0.003"], ["70607.20", "0.059"], ["70609.50", "0.034"], ["70615.10", "0.000"], ["70616.90", "0.003"], ["70618.70", "0.000"], ["70619.90", "0.003"], ["70620.10", "0.008"], ["70621.00", "0.640"], ["70621.30", "0.251"], ["70621.40", "0.000"], ["70621.70", "0.070"]], "a": [["70633.30", "0.003"], ["70633.40", "0.000"], ["70633.60", "0.000"], ["70633.80", "0.017"], ["70639.70", "0.023"], ["70651.00", "0.008"], ["70652.10", "0.001"], ["70659.20", "0.024"], ["70663.80", "0.253"], ["70664.90", "0.000"], ["70666.30", "0.000"], ["70673.40", "0.001"], ["70676.40", "0.008"], ["70679.20", "0.004"], ["70680.50", "0.002"], ["70765.70", "0.039"], ["70769.20", "0.136"], ["70792.10", "0.007"], ["70794.00", "0.159"], ["70797.50", "6.343"], ["70855.30", "0.000"], ["70855.60", "0.002"], ["71156.30", "0.707"], ["71332.90", "0.863"], ["71337.70", "0.000"], ["71337.80", "2.947"], ["71688.60", "0.000"], ["71723.70", "0.032"]]}}
{"local_ts": 1773486913179, "server_ts": 1773486913150, "data": {"e": "depthUpdate", "E": 1773486913151, "T": 1773486913150, "s": "BTCUSDT", "U": 10109530624707, "u": 10109530632220, "pu": 10109530624689, "b": [["1000.00", "26.592"], ["5000.00", "101.418"], ["7063.20", "0.000"], ["20131.40", "1.060"], ["20231.40", "1.940"], ["33000.00", "3.789"], ["69925.10", "1.559"], ["70278.20", "3.692"], ["70518.30", "1.520"], ["70524.00", "0.352"], ["70553.70", "0.003"], ["70567.80", "0.195"], ["70583.80", "0.005"], ["70584.10", "0.251"], ["70600.10", "0.003"], ["70601.30", "0.344"], ["70601.40", "0.633"], ["70603.10", "0.790"], ["70613.10", "0.058"], ["70613.80", "0.005"], ["70618.70", "0.000"], ["70620.80", "0.004"], ["70623.90", "0.256"], ["70624.00", "0.342"], ["70624.40", "0.067"], ["70624.70", "0.002"], ["70625.50", "0.005"], ["70626.80", "0.005"], ["70627.90", "0.002"], ["70630.10", "0.302"]], "a": [["70631.50", "1.708"], ["70632.90", "0.011"], ["70638.50", "0.053"], ["70642.10", "0.118"], ["70643.60", "0.143"], ["70644.20", "0.018"], ["70647.20", "0.096"], ["70657.20", "0.225"], ["70659.10", "0.009"], ["70659.50", "0.650"], ["70665.00", "0.818"], ["70666.70", "0.004"], ["70666.80", "0.513"], ["70667.00", "0.007"], ["70668.10", "0.000"], ["70673.00", "0.002"], ["70676.40", "0.006"], ["70683.40", "0.021"], ["70695.10", "0.119"], ["70709.20", "0.040"], ["70832.40", "0.000"], ["70834.70", "0.036"], ["71337.80", "2.947"], ["71847.00", "0.013"], ["74188.80", "0.587"]]}}
{"local_ts": 1773486914203, "server_ts": 1773486914172, "data": {"e": "depthUpdate", "E": 1773486914175, "T": 1773486914172, "s": "BTCUSDT", "U": 10109530707156, "u": 10109530712795, "pu": 10109530707043, "b": [["1000.00", "26.592"], ["5000.00", "101.418"], ["7063.20", "0.000"], ["20131.40", "2.380"], ["20231.40", "0.000"], ["20531.40", "0.620"], ["67080.80", "0.000"], ["67087.40", "0.000"], ["69195.40", "0.000"], ["69548.50", "0.000"], ["69703.80", "0.000"], ["69901.50", "0.002"], ["69925.10", "2.994"], ["70403.20", "0.042"], ["70444.20", "0.002"], ["70523.10", "0.006"], ["70538.30", "0.000"], ["70540.10", "0.000"], ["70544.30", "0.000"], ["70545.80", "0.000"], ["70546.50", "0.000"], ["70547.60", "0.093"], ["70548.20", "0.330"], ["70548.50", "0.093"], ["70548.90", "0.000"], ["70549.20", "0.001"], ["70549.30", "0.000"], ["70549.60", "1.059"], ["70564.30", "0.065"], ["70566.00", "0.321"], ["70567.30", "0.025"], ["70569.30", "0.142"], ["70570.10", "0.511"], ["70570.90", "0.072"], ["70571.00", "0.463"], ["70571.10", "0.140"], ["70571.70", "0.090"], ["70572.00", "0.225"], ["70572.60", "1.188"], ["70572.80", "0.421"], ["70573.00", "0.281"], ["70573.30", "0.016"], ["70573.70", "0.043"], ["70574.00", "0.315"], ["70583.90", "0.000"], ["70584.10", "0.251"], ["70607.00", "0.005"], ["70619.60", "0.519"], ["70619.70", "0.712"], ["70619.80", "0.079"], ["70620.90", "0.135"], ["70621.30", "0.004"], ["70621.40", "0.057"], ["70621.50", "0.123"], ["70621.70", "0.000"], ["70621.80", "0.005"], ["70622.00", "1.198"], ["70622.20", "0.009"], ["70622.50", "0.007"], ["70622.90", "0.273"], ["70623.10", "0.006"], ["70624.40", "0.097"], ["70627.50", "0.004"], ["70627.80", "0.206"]], "a": [["70632.90", "0.013"], ["70638.50", "0.032"], ["70640.20", "0.030"], ["70640.40", "0.007"], ["70640.60", "0.005"], ["70640.80", "0.118"], ["70640.90", "0.060"], ["70641.00", "0.066"], ["70641.30", "0.000"], ["70641.50", "0.176"], ["70641.60", "0.002"], ["70641.70", "0.165"], ["70641.80", "0.037"], ["70641.90", "0.083"], ["70642.00", "0.051"], ["70642.10", "0.043"], ["70642.20", "0.000"], ["70665.00", "1.224"], ["70665.20", "0.063"], ["70665.40", "0.226"], ["70665.50", "0.021"], ["70665.70", "1.525"], ["70666.10", "0.595"], ["70666.20", "1.158"], ["70666.40", "0.087"], ["70666.60", "0.097"], ["70667.10", "0.036"], ["70667.30", "0.059"], ["70667.60", "0.168"], ["70668.90", "0.053"], ["70669.60", "1.787"], ["70669.80", "1.394"], ["70687.30", "0.002"], ["70689.50", "0.271"], ["70689.80", "1.726"], ["70690.10", "0.002"], ["70690.50", "0.252"], ["70690.70", "0.017"], ["70690.80", "0.044"], ["70690.90", "0.050"], ["70691.80", "0.261"], ["70692.50", "0.002"], ["70693.40", "0.002"], ["70696.10", "0.003"], ["70697.50", "0.063"], ["70855.00", "0.018"], ["71314.70", "0.000"], ["71337.80", "2.947"], ["71512.40", "0.000"], ["71667.80", "0.003"], ["71669.80", "2.436"], ["72020.80", "0.002"]]}}
{"local_ts": 1773486915223, "server_ts": 1773486915192, "data": {"e": "depthUpdate", "E": 1773486915197, "T": 1773486915192, "s": "BTCUSDT", "U": 10109530759599, "u": 10109530763147, "pu": 10109530759508, "b": [["5000.00", "101.418"], ["7063.20", "0.000"], ["20131.40", "0.130"], ["20431.40", "0.300"], ["20531.40", "2.570"], ["56505.00", "0.000"], ["69218.80", "0.060"], ["69571.90", "4.341"], ["69661.50", "0.000"], ["69925.10", "3.015"], ["70500.00", "4.019"], ["70583.90", "0.002"], ["70584.50", "0.004"], ["70624.30", "0.039"], ["70627.50", "0.002"]], "a": [["70636.50", "0.014"], ["70639.60", "0.004"], ["70645.70", "0.003"], ["71337.80", "4.347"], ["71502.80", "2.094"], ["71535.60", "0.035"], ["71691.00", "0.247"], ["71953.00", "0.382"], ["72031.50", "0.388"], ["72044.10", "0.019"], ["72044.20", "0.028"], ["74169.20", "0.004"], ["74187.70", "0.152"]]}}
{"local_ts": 1773486916259, "server_ts": 1773486916220, "data": {"e": "depthUpdate", "E": 1773486916221, "T": 1773486916220, "s": "BTCUSDT", "U": 10109530806753, "u": 10109530811478, "pu": 10109530806547, "b": [["1000.00", "26.592"], ["5000.00", "101.418"], ["7063.20", "0.056"], ["20331.40", "0.150"], ["20431.40", "2.440"], ["20531.40", "0.410"], ["67091.20", "0.000"], ["69925.10", "3.036"], ["70049.80", "0.000"], ["70061.60", "0.016"], ["70278.20", "3.692"], ["70278.30", "0.000"], ["70553.70", "0.000"], ["70567.80", "0.192"], ["70622.20", "0.009"], ["70623.70", "0.006"], ["70624.30", "0.039"], ["70629.60", "0.007"], ["70630.00", "0.500"], ["70631.10", "0.035"], ["70631.30", "0.109"], ["70631.40", "3.690"]], "a": [["70631.50", "2.310"], ["70632.50", "0.001"], ["70632.80", "0.001"], ["70633.50", "0.018"], ["70633.90", "0.003"], ["70635.10", "0.000"], ["70635.40", "0.158"], ["70635.50", "0.054"], ["70638.40", "0.000"], ["70639.70", "0.021"], ["70640.10", "0.002"], ["70642.10", "0.054"], ["70695.10", "0.010"], ["70709.20", "0.037"], ["71337.80", "4.347"]]}}
{"local_ts": 1773486917274, "server_ts": 1773486917245, "data": {"e": "depthUpdate", "E": 1773486917247, "T": 1773486917245, "s": "BTCUSDT", "U": 10109530852255, "u": 10109530855216, "pu": 10109530852230, "b": [["5000.00", "101.418"], ["7063.20", "0.056"], ["20231.40", "0.010"], ["20331.40", "2.280"], ["20431.40", "0.710"], ["67099.00", "0.000"], ["69920.20", "2.855"], ["69925.10", "3.036"], ["69925.20", "0.004"], ["70384.50", "0.000"], ["70534.10", "1.127"], ["70541.10", "0.071"], ["70548.20", "0.401"], ["70584.00", "0.075"], ["70584.10", "0.249"], ["70623.90", "0.259"], ["70624.30", "0.052"], ["70628.00", "0.011"], ["70629.40", "0.002"], ["70629.90", "0.006"], ["70630.70", "0.007"], ["70631.20", "0.082"], ["70631.40", "3.613"]], "a": [["70631.50", "2.968"], ["70633.60", "0.057"], ["70634.60", "0.010"], ["70635.10", "0.015"], ["70636.50", "0.014"], ["70637.90", "0.027"], ["70638.20", "0.001"], ["70642.10", "0.051"], ["70643.10", "0.026"], ["70695.10", "0.013"], ["70710.80", "0.174"], ["70717.90", "0.158"], ["70724.90", "0.327"], ["70854.00", "0.228"], ["71337.80", "4.347"], ["71482.50", "1.725"], ["74179.40", "0.004"]]}}
{"local_ts": 1773486918294, "server_ts": 1773486918266, "data": {"e": "depthUpdate", "E": 1773486918267, "T": 1773486918266, "s": "BTCUSDT", "U": 10109530898313, "u": 10109530902478, "pu": 10109530898260, "b": [["1000.00", "26.592"], ["5000.00", "101.438"], ["7063.20", "0.028"], ["20231.40", "1.850"], ["20331.40", "1.150"], ["67072.00", "0.007"], ["67099.80", "0.010"], ["67099.90", "0.006"], ["69592.90", "0.070"], ["69610.10", "9.754"], ["69925.10", "3.036"], ["70278.20", "3.692"], ["70447.80", "0.060"], ["70534.20", "0.056"], ["70541.20", "0.071"], ["70548.30", "0.073"], ["70583.60", "0.366"], ["70583.90", "0.002"], ["70605.50", "0.096"], ["70605.60", "0.003"], ["70624.40", "0.121"], ["70625.30", "0.058"], ["70626.40", "0.307"], ["70627.30", "0.016"]], "a": [["70634.80", "0.006"], ["70638.50", "0.034"], ["70641.00", "0.066"], ["70656.20", "0.053"], ["70657.00", "0.636"], ["70710.80", "0.103"], ["70710.90", "0.208"], ["70717.90", "0.087"], ["70718.00", "0.148"], ["70724.90", "0.256"], ["70725.00", "0.144"], ["70756.00", "0.004"], ["70855.40", "0.520"], ["70855.80", "0.002"], ["71305.40", "6.577"], ["71337.70", "0.000"], ["71337.80", "4.347"], ["71933.60", "0.002"], ["72000.00", "232.283"], ["74173.10", "0.000"]]}}
{"local_ts": 1773486919317, "server_ts": 1773486919288, "data": {"e": "depthUpdate", "E": 1773486919289, "T": 1773486919288, "s": "BTCUSDT", "U": 10109530975715, "u": 10109530981365, "pu": 10109530975586, "b": [["1000.00", "26.592"], ["5000.00", "101.418"], ["7063.40", "0.028"], ["20133.40", "0.350"], ["20231.40", "1.600"], ["67096.20", "0.002"], ["69231.90", "0.618"], ["69446.40", "0.002"], ["69483.00", "0.000"], ["69925.20", "0.000"], ["69927.10", "0.000"], ["70300.20", "0.029"], ["70331.90", "0.013"], ["70332.10", "0.015"], ["70389.90", "0.004"], ["70414.10", "0.000"], ["70426.90", "0.000"], ["70432.10", "0.869"], ["70488.80", "0.028"], ["70491.90", "0.004"], ["70497.80", "0.222"], ["70524.30", "0.096"], ["70534.20", "0.039"], ["70538.20", "0.159"], ["70541.20", "0.000"], ["70545.20", "0.488"], ["70548.30", "0.002"], ["70552.30", "0.307"], ["70555.60", "0.160"], ["70555.70", "0.003"], ["70564.70", "2.483"], ["70565.60", "0.000"], ["70566.60", "0.111"], ["70569.80", "0.175"], ["70570.20", "0.000"], ["70571.60", "0.089"], ["70573.20", "0.110"], ["70573.40", "0.057"], ["70574.30", "0.142"], ["70577.10", "0.030"], ["70578.70", "0.005"], ["70581.70", "0.105"], ["70581.80", "0.000"], ["70584.00", "0.207"], ["70584.20", "0.025"], ["70584.30", "0.000"], ["70585.20", "0.007"], ["70585.50", "0.517"], ["70587.00", "0.034"], ["70591.00", "0.143"], ["70595.50", "0.003"], ["70598.20", "2.245"], ["70599.30", "0.068"], ["70599.90", "0.248"], ["70600.10", "0.117"], ["70605.10", "0.177"], ["70608.90", "0.009"], ["70609.00", "0.303"], ["70609.50", "0.021"], ["70609.60", "0.002"], ["70609.70", "0.113"], ["70610.50", "0.318"], ["70611.00", "0.005"], ["70611.10", "0.004"], ["70611.70", "0.048"], ["70611.80", "0.000"], ["70612.20", "0.002"], ["70612.40", "0.009"], ["70612.50", "0.010"], ["70613.10", "0.006"], ["70613.20", "0.000"], ["70613.30", "0.007"], ["70613.60", "0.563"], ["70615.00", "0.240"], ["70615.80", "0.526"], ["70616.60", "0.003"], ["70617.20", "0.604"], ["70617.30", "0.147"], ["70618.60", "0.000"], ["70619.10", "0.116"], ["70619.20", "0.053"], ["70620.10", "0.005"], ["70620.20", "0.003"], ["70620.60", "0.124"], ["70621.20", "0.008"], ["70621.40", "0.002"], ["70621.50", "0.105"], ["70621.60", "0.000"], ["70621.90", "0.961"], ["70622.10", "0.477"], ["70622.90", "0.005"], ["70623.00", "0.012"], ["70623.10", "0.088"], ["70623.20", "0.074"], ["70623.40", "0.006"], ["70623.70", "0.063"], ["70624.30", "0.305"], ["70625.10", "0.004"], ["70625.70", "0.002"], ["70626.10", "0.002"], ["70626.40", "0.193"], ["70626.50", "0.989"], ["70627.00", "0.002"], ["70627.20", "0.014"], ["70628.40", "0.004"], ["70629.00", "0.006"], ["70629.20", "0.001"], ["70629.40", "0.029"], ["70629.50", "0.001"], ["70630.30", "0.007"], ["70630.50", "0.001"], ["70631.00", "0.019"], ["70631.40", "0.239"], ["70631.70", "0.203"], ["70631.90", "0.022"], ["70632.30", "0.001"], ["70632.60", "0.001"], ["70632.70", "0.003"], ["70633.00", "0.001"], ["70633.30", "0.005"], ["70633.40", "2.495"]], "a": [["70633.50", "8.389"], ["70636.40", "0.077"], ["70636.60", "0.003"], ["70637.40", "0.002"], ["70637.80", "0.053"], ["70638.00", "0.007"], ["70638.50", "0.004"], ["70639.60", "0.213"], ["70640.00", "0.291"], ["70640.10", "0.003"], ["70640.30", "0.001"], ["70640.80", "0.003"], ["70640.90", "0.001"], ["70641.10", "0.001"], ["70641.60", "0.062"], ["70641.80", "0.005"], ["70641.90", "0.008"], ["70642.30", "0.001"], ["70642.50", "0.027"], ["70642.70", "0.007"], ["70643.00", "0.062"], ["70643.10", "0.193"], ["70643.20", "0.000"], ["70643.30", "0.288"], ["70643.40", "0.000"], ["70643.50", "0.088"], ["70643.60", "0.342"], ["70643.70", "0.037"], ["70643.90", "0.007"], ["70644.00", "0.012"], ["70644.10", "0.093"], ["70644.20", "0.078"], ["70644.30", "0.001"], ["70644.60", "0.001"], ["70645.00", "0.005"], ["70645.40", "0.001"], ["70645.50", "0.004"], ["70645.80", "0.024"], ["70645.90", "0.039"], ["70646.00", "0.011"], ["70646.10", "0.006"], ["70646.20", "0.255"], ["70646.50", "0.001"], ["70646.60", "0.108"], ["70646.80", "0.526"], ["70647.00", "0.000"], ["70647.10", "0.001"], ["70647.30", "0.004"], ["70647.50", "0.004"], ["70647.60", "0.170"], ["70647.70", "0.004"], ["70648.10", "0.000"], ["70648.30", "0.008"], ["70648.70", "0.000"], ["70649.30", "0.001"], ["70649.50", "0.004"], ["70649.70", "0.073"], ["70649.90", "0.655"], ["70650.50", "0.004"], ["70651.00", "1.093"], ["70651.10", "1.175"], ["70651.90", "0.004"], ["70652.60", "0.205"], ["70653.30", "0.689"], ["70654.80", "0.010"], ["70655.20", "0.003"], ["70656.80", "0.271"], ["70656.90", "0.683"], ["70657.30", "0.011"], ["70658.30", "0.002"], ["70659.40", "0.007"], ["70661.80", "0.086"], ["70662.70", "0.006"], ["70663.00", "0.003"], ["70664.40", "0.019"], ["70664.50", "0.290"], ["70665.50", "0.021"], ["70665.70", "0.024"], ["70666.00", "0.057"], ["70667.50", "0.332"], ["70667.60", "0.736"], ["70667.80", "0.002"], ["70667.90", "0.005"], ["70668.50", "0.040"], ["70668.60", "0.004"], ["70668.80", "0.033"], ["70668.90", "0.039"], ["70669.30", "0.073"], ["70669.40", "1.472"], ["70671.90", "0.036"], ["70675.60", "0.008"], ["70675.90", "0.540"], ["70679.00", "0.237"], ["70684.10", "1.813"], ["70685.50", "0.030"], ["70685.60", "0.300"], ["70686.20", "0.002"], ["70686.60", "0.001"], ["70688.20", "0.004"], ["70690.90", "0.051"], ["70691.90", "0.066"], ["70692.60", "0.289"], ["70692.90", "0.036"], ["70693.40", "0.002"], ["70693.70", "0.039"], ["70695.70", "0.599"], ["70697.10", "0.003"], ["70697.90", "0.002"], ["70698.50", "0.318"], ["70700.30", "0.042"], ["70700.50", "0.038"], ["70701.20", "0.710"], ["70702.70", "0.115"], ["70705.70", "3.431"], ["70710.30", "0.002"], ["70710.90", "0.090"], ["70711.20", "0.015"], ["70714.80", "0.074"], ["70715.30", "0.036"], ["70716.00", "0.327"], ["70718.00", "0.077"], ["70721.10", "0.228"], ["70721.90", "0.726"], ["70725.00", "0.049"], ["70728.90", "1.139"], ["70732.60", "0.050"], ["70739.10", "0.112"], ["70751.40", "0.097"], ["70753.00", "0.093"], ["70758.10", "0.128"], ["70784.10", "0.005"], ["70788.40", "0.001"], ["70792.60", "0.002"], ["70808.40", "0.000"], ["70809.10", "0.002"], ["70818.90", "0.054"], ["70845.90", "0.000"], ["70855.20", "0.000"], ["70936.10", "0.271"], ["71337.70", "0.000"], ["71339.80", "0.000"], ["74163.30", "0.000"], ["74174.70", "0.012"]]}}
{"local_ts": 1773486920340, "server_ts": 1773486920312, "data": {"e": "depthUpdate", "E": 1773486920313, "T": 1773486920312, "s": "BTCUSDT", "U": 10109531018066, "u": 10109531022398, "pu": 10109531018044, "b": [["5000.00", "101.398"], ["7063.40", "0.028"], ["20131.40", "0.670"], ["20133.40", "1.350"], ["20133.50", "0.000"], ["20135.80", "0.000"], ["20533.40", "0.970"], ["33000.00", "3.785"], ["67067.40", "0.000"], ["69785.80", "0.429"], ["69927.10", "0.000"], ["70359.20", "0.000"], ["70374.30", "18.676"], ["70503.90", "0.005"], ["70586.90", "0.047"], ["70587.00", "0.034"], ["70605.50", "0.186"], ["70625.00", "0.007"], ["70625.20", "0.023"], ["70625.60", "0.004"], ["70629.90", "0.200"], ["70632.70", "0.017"], ["70633.20", "0.004"]], "a": [["70633.50", "6.846"], ["70633.60", "0.003"], ["70635.10", "0.064"], ["70636.40", "0.020"], ["70637.80", "0.054"], ["70639.30", "0.018"], ["70639.60", "0.215"], ["70642.90", "0.187"], ["70643.30", "0.164"], ["70643.50", "0.076"], ["70644.10", "0.165"], ["70644.60", "0.003"], ["70658.70", "0.002"], ["70758.10", "0.216"], ["70760.40", "0.091"], ["70773.60", "10.110"], ["70778.30", "0.000"], ["70788.30", "0.000"], ["71332.90", "0.163"], ["71339.80", "0.000"], ["71763.00", "0.029"], ["72853.40", "0.000"]]}}
{"local_ts": 1773486921359, "server_ts": 1773486921332, "data": {"e": "depthUpdate", "E": 1773486921333, "T": 1773486921332, "s": "BTCUSDT", "U": 10109531058098, "u": 10109531061687, "pu": 10109531058002, "b": [["1000.00", "26.592"], ["5000.00", "101.398"], ["7063.40", "0.028"], ["20131.40", "0.000"], ["20433.40", "0.520"], ["20533.40", "2.480"], ["65153.80", "0.025"], ["67086.90", "0.004"], ["68631.40", "0.000"], ["69927.10", "0.000"], ["70100.10", "3.739"], ["70222.10", "16.020"], ["70280.20", "0.142"], ["70313.60", "0.002"], ["70349.70", "0.000"], ["70351.60", "0.004"], ["70386.80", "0.162"], ["70391.00", "0.000"], ["70525.60", "0.000"], ["70527.50", "0.154"], ["70575.30", "0.088"], ["70602.20", "0.200"], ["70602.30", "0.324"], ["70604.30", "0.368"], ["70605.40", "0.188"], ["70622.80", "0.346"], ["70624.70", "0.642"], ["70625.20", "0.023"], ["70626.30", "0.003"], ["70629.90", "0.205"], ["70633.40", "4.466"]], "a": [["70633.70", "0.002"], ["70634.90", "0.000"], ["70644.10", "0.111"], ["70645.90", "0.054"], ["70651.50", "0.000"], ["70659.00", "0.002"], ["70675.40", "0.009"], ["70737.30", "0.351"], ["70739.40", "2.868"], ["70750.10", "0.241"], ["70914.10", "0.000"], ["70916.20", "0.564"], ["70956.90", "0.000"], ["71059.80", "7.403"], ["71190.90", "3.240"], ["71339.80", "0.000"]]}}
{"local_ts": 1773486922381, "server_ts": 1773486922350, "data": {"e": "depthUpdate", "E": 1773486922353, "T": 1773486922350, "s": "BTCUSDT", "U": 10109531100044, "u": 10109531103866, "pu": 10109531099978, "b": [["5000.00", "101.418"], ["7063.40", "0.000"], ["20333.40", "0.260"], ["20433.40", "2.540"], ["20533.40", "0.200"], ["33000.00", "3.789"], ["67099.90", "0.008"], ["67808.10", "0.020"], ["69927.10", "0.000"], ["70068.40", "0.020"], ["70280.20", "0.072"], ["70301.40", "0.106"], ["70314.80", "0.000"], ["70315.00", "5.079"], ["70387.00", "0.002"], ["70395.30", "5.017"], ["70615.20", "0.007"], ["70617.30", "0.199"], ["70622.80", "1.035"], ["70624.90", "0.016"], ["70625.50", "0.005"], ["70625.60", "0.001"], ["70626.10", "0.002"], ["70626.20", "0.075"], ["70627.20", "0.288"], ["70627.80", "0.840"], ["70629.90", "0.203"], ["70630.10", "0.010"], ["70630.70", "0.339"], ["70631.40", "0.163"], ["70631.50", "0.155"], ["70631.80", "0.009"], ["70633.30", "0.149"]], "a": [["70633.50", "1.316"], ["70639.80", "0.017"], ["70644.10", "0.111"], ["70645.20", "0.007"], ["70646.90", "0.457"], ["70648.80", "0.059"], ["70649.70", "0.037"], ["70661.60", "0.038"], ["70661.80", "0.033"], ["70662.30", "0.000"], ["70662.70", "0.006"], ["70663.50", "0.636"], ["70668.60", "0.002"], ["70669.30", "0.004"], ["70670.60", "0.801"], ["70672.70", "0.003"], ["70673.90", "0.055"], ["70675.90", "0.588"], ["70767.00", "0.849"], ["70882.20", "7.232"], ["70883.10", "0.000"], ["71339.80", "0.000"], ["73458.80", "0.006"], ["74192.90", "0.000"], ["74193.00", "0.052"]]}}
{"local_ts": 1773486923401, "server_ts": 1773486923369, "data": {"e": "depthUpdate", "E": 1773486923373, "T": 1773486923369, "s": "BTCUSDT", "U": 10109531137095, "u": 10109531140578, "pu": 10109531137009, "b": [["1000.00", "26.592"], ["5000.00", "101.418"], ["7063.40", "0.000"], ["20233.40", "0.110"], ["20333.40", "2.390"], ["20433.40", "0.500"], ["61430.80", "0.000"], ["67086.90", "0.002"], ["69220.80", "0.014"], ["69432.60", "0.934"], ["69586.50", "0.000"], ["69927.10", "0.000"], ["70280.20", "0.072"], ["70435.60", "0.177"], ["70562.70", "0.006"], ["70599.00", "0.057"], ["70606.70", "0.251"], ["70612.20", "0.004"], ["70614.50", "0.271"], ["70616.40", "0.001"], ["70616.50", "0.031"], ["70617.20", "0.668"], ["70618.20", "0.008"], ["70619.70", "0.630"], ["70620.90", "0.000"], ["70621.60", "0.141"], ["70622.20", "0.003"], ["70622.80", "0.792"], ["70626.40", "0.431"], ["70627.70", "0.000"], ["70628.40", "0.002"], ["70628.50", "0.003"], ["70633.40", "5.529"]], "a": [["70640.50", "0.030"], ["70643.90", "0.562"], ["70644.00", "0.535"], ["70644.60", "0.003"], ["70648.70", "0.015"], ["70648.80", "0.002"], ["70649.20", "0.139"], ["70650.00", "4.530"], ["70650.10", "0.004"], ["70650.80", "0.030"], ["70651.20", "1.372"], ["70651.40", "0.005"], ["70651.70", "0.002"], ["70652.50", "0.018"], ["70652.90", "0.544"], ["70653.80", "0.274"], ["70654.70", "0.002"], ["70654.90", "0.103"], ["70655.10", "0.015"], ["70656.30", "0.027"], ["70656.40", "0.001"], ["70656.90", "0.542"], ["70657.70", "0.038"], ["70661.50", "0.818"], ["70661.80", "0.033"], ["70662.70", "0.006"], ["70664.00", "0.004"], ["70665.20", "0.002"], ["70666.50", "0.041"], ["70667.80", "0.110"], ["70668.60", "0.023"], ["70670.60", "0.640"], ["70672.50", "0.002"], ["70675.90", "0.588"], ["70700.50", "0.042"], ["71339.80", "0.019"], ["74186.60", "0.002"], ["89523.20", "0.000"]]}}
{"local_ts": 1773486924419, "server_ts": 1773486924392, "data": {"e": "depthUpdate", "E": 1773486924393, "T": 1773486924392, "s": "BTCUSDT", "U": 10109531176630, "u": 10109531180799, "pu": 10109531176415, "b": [["1000.00", "26.592"], ["5000.00", "101.418"], ["7063.40", "0.000"], ["20233.40", "2.170"], ["20333.40", "0.830"], ["61426.90", "0.000"], ["67073.70", "0.002"], ["67101.00", "0.002"], ["69225.10", "0.144"], ["69927.10", "0.007"], ["70538.20", "0.017"], ["70545.20", "0.346"], ["70552.30", "0.165"], ["70567.20", "1.117"], ["70573.80", "0.850"], ["70574.00", "0.372"], ["70574.90", "0.107"], ["70587.30", "8.507"], ["70587.90", "1.505"], ["70596.40", "0.843"], ["70599.00", "0.057"], ["70602.90", "0.344"], ["70605.60", "0.003"], ["70605.70", "0.098"], ["70606.70", "0.251"], ["70622.50", "0.082"], ["70622.70", "0.931"], ["70622.80", "0.671"], ["70623.70", "0.063"], ["70624.30", "0.360"], ["70626.20", "0.075"]], "a": [["70642.30", "0.025"], ["70642.80", "0.033"], ["70643.90", "0.039"], ["70644.00", "0.050"], ["70644.10", "0.139"], ["70644.30", "0.005"], ["70646.00", "0.011"], ["70646.60", "0.144"], ["70647.00", "0.015"], ["70647.60", "0.235"], ["70653.70", "0.342"], ["70656.40", "0.001"], ["70656.50", "0.003"], ["70656.60", "1.169"], ["70667.30", "0.084"], ["70667.50", "0.296"], ["70667.80", "0.078"], ["70668.30", "0.046"], ["70668.80", "0.199"], ["70671.70", "0.045"], ["70678.80", "0.004"], ["70691.70", "0.025"], ["70692.80", "0.036"], ["70694.40", "0.004"], ["70714.90", "0.077"], ["70715.00", "0.271"], ["70722.00", "2.657"], ["70722.10", "0.000"], ["70729.00", "0.071"], ["70729.10", "0.138"], ["70799.50", "0.468"], ["89523.20", "0.000"]]}}
{"local_ts": 1773486925456, "server_ts": 1773486925416, "data": {"e": "depthUpdate", "E": 1773486925417, "T": 1773486925416, "s": "BTCUSDT", "U": 10109531219445, "u": 10109531222783, "pu": 10109531219340, "b": [["5000.00", "101.418"], ["7063.40", "0.056"], ["20133.40", "1.730"], ["20233.40", "1.270"], ["67073.50", "0.002"], ["67101.70", "0.002"], ["67101.80", "0.004"], ["69927.10", "0.007"], ["70068.30", "0.855"], ["70500.40", "0.673"], ["70564.20", "0.042"]], "a": [["70669.70", "0.213"], ["70670.50", "0.249"], ["70765.10", "0.657"], ["70765.20", "0.000"], ["70840.00", "0.068"], ["70841.90", "0.000"], ["70847.10", "0.007"], ["70849.00", "0.002"], ["70854.20", "6.771"], ["70856.10", "0.000"], ["70857.00", "0.227"], ["70861.30", "0.009"], ["70863.20", "0.511"], ["70868.40", "0.767"], ["70870.30", "0.000"], ["70875.50", "0.715"], ["70877.40", "0.074"], ["70882.60", "0.009"], ["70884.50", "0.000"], ["70889.70", "0.009"], ["70891.60", "0.007"], ["70999.90", "4.247"], ["71339.80", "0.702"], ["71712.60", "0.417"], ["74173.10", "0.000"], ["89523.20", "0.000"]]}}
{"local_ts": 1773486926467, "server_ts": 1773486926438, "data": {"e": "depthUpdate", "E": 1773486926441, "T": 1773486926438, "s": "BTCUSDT", "U": 10109531280882, "u": 10109531285815, "pu": 10109531280790, "b": [["1000.00", "26.592"], ["5000.00", "101.398"], ["7063.40", "0.056"], ["20133.40", "1.720"], ["20533.40", "1.280"], ["67085.70", "0.002"], ["69927.10", "0.721"], ["70280.20", "0.072"], ["70500.40", "0.673"], ["70590.80", "0.000"], ["70591.90", "0.002"], ["70599.60", "0.614"], ["70605.10", "0.321"], ["70605.50", "0.186"], ["70605.60", "0.187"], ["70605.80", "0.000"], ["70606.00", "0.598"], ["70611.90", "0.027"], ["70620.90", "0.000"], ["70622.40", "0.144"], ["70622.80", "0.668"], ["70626.20", "0.072"], ["70627.00", "0.172"], ["70629.90", "0.200"], ["70630.10", "0.349"], ["70630.60", "0.002"], ["70631.20", "0.002"], ["70631.40", "0.141"], ["70631.60", "0.008"], ["70633.40", "5.602"]], "a": [["70633.50", "1.009"], ["70633.60", "0.058"], ["70640.00", "0.007"], ["70640.10", "0.004"], ["70644.10", "0.139"], ["70644.70", "0.004"], ["70646.90", "0.457"], ["70648.20", "0.002"], ["70648.90", "0.009"], ["70649.10", "0.057"], ["70649.90", "0.514"], ["70650.20", "0.003"], ["70650.80", "0.143"], ["70651.20", "1.368"], ["70651.80", "0.005"], ["70652.20", "0.002"], ["70652.30", "0.000"], ["70652.50", "0.010"], ["70652.60", "0.219"], ["70652.80", "0.040"], ["70653.10", "5.026"], ["70653.50", "0.020"], ["70653.70", "0.342"], ["70654.40", "0.000"], ["70654.80", "0.003"], ["70654.90", "0.038"], ["70656.20", "0.018"], ["70656.30", "0.005"], ["70656.70", "1.170"], ["70656.80", "0.291"], ["70656.90", "0.521"], ["70657.40", "0.031"], ["70657.60", "0.002"], ["70658.80", "0.015"], ["70658.90", "0.068"], ["70660.10", "0.044"], ["70661.40", "0.067"], ["70662.30", "0.000"], ["70662.60", "0.017"], ["70663.40", "0.636"], ["70663.90", "0.332"], ["70665.10", "0.030"], ["70666.40", "0.087"], ["70667.70", "0.072"], ["70667.80", "0.008"], ["70668.60", "0.023"], ["70668.80", "0.199"], ["70668.90", "0.005"], ["70670.60", "0.640"], ["70672.50", "0.004"], ["70677.80", "0.057"], ["70678.90", "0.003"], ["70765.10", "0.665"], ["70796.00", "0.121"], ["70799.50", "0.408"], ["70840.00", "0.061"], ["70841.90", "0.007"], ["70847.10", "0.000"], ["70849.00", "0.009"], ["70854.20", "6.764"], ["70856.10", "0.007"], ["70861.30", "0.002"], ["70863.20", "0.518"], ["70868.40", "0.760"], ["70870.30", "0.007"], ["70875.50", "0.708"], ["70877.40", "0.081"], ["70882.60", "0.002"], ["70884.50", "0.007"], ["70889.70", "0.002"], ["70891.60", "0.014"], ["71339.80", "0.700"], ["71403.40", "0.558"], ["74631.50", "0.065"], ["89523.20", "0.000"]]}}
{"local_ts": 1773486927487, "server_ts": 1773486927456, "data": {"e": "depthUpdate", "E": 1773486927461, "T": 1773486927456, "s": "BTCUSDT", "U": 10109531324879, "u": 10109531328938, "pu": 10109531324770, "b": [["5000.00", "101.418"], ["7063.40", "0.056"], ["20433.40", "0.830"], ["20533.40", "2.170"], ["33000.00", "3.785"], ["67079.20", "0.000"], ["67099.90", "0.004"], ["69927.10", "0.721"], ["69927.20", "0.006"], ["70387.50", "0.002"], ["70613.70", "0.018"], ["70615.60", "0.319"]], "a": [["70644.50", "0.007"], ["70647.60", "0.302"], ["70648.50", "0.017"], ["70841.90", "0.000"], ["70844.60", "0.009"], ["70849.00", "0.002"], ["70851.70", "0.007"], ["70856.10", "0.000"], ["70856.90", "0.007"], ["70858.80", "0.007"], ["70863.20", "0.511"], ["70865.90", "0.032"], ["70870.30", "0.000"], ["70873.00", "0.010"], ["70877.40", "0.074"], ["70880.10", "0.007"], ["70884.50", "0.000"], ["70887.20", "0.012"], ["70891.60", "0.007"], ["70894.30", "0.007"], ["70983.10", "0.074"], ["71339.60", "0.000"], ["71339.80", "0.700"], ["89523.20", "0.000"]]}}
{"local_ts": 1773486928515, "server_ts": 1773486928476, "data": {"e": "depthUpdate", "E": 1773486928481, "T": 1773486928476, "s": "BTCUSDT", "U": 10109531367768, "u": 10109531371451, "pu": 10109531367656, "b": [["1000.00", "26.592"], ["5000.00", "101.418"], ["7063.40", "0.028"], ["20333.40", "0.410"], ["20433.40", "2.560"], ["20533.40", "0.030"], ["67068.60", "0.000"], ["67087.10", "0.002"], ["67101.80", "0.000"], ["69644.50", "1.164"], ["69927.10", "0.721"], ["70280.20", "0.214"], ["70435.60", "0.336"], ["70439.20", "0.159"], ["70448.90", "0.000"], ["70449.10", "0.000"], ["70449.30", "0.002"], ["70449.80", "0.015"], ["70478.60", "0.018"], ["70483.30", "0.054"], ["70486.50", "1.078"], ["70500.40", "0.673"], ["70545.10", "0.638"], ["70573.40", "0.081"], ["70586.50", "0.005"], ["70586.70", "0.002"], ["70605.10", "0.321"], ["70606.00", "0.598"], ["70606.10", "0.002"], ["70619.20", "0.079"]], "a": [["70641.40", "0.016"], ["70647.60", "0.302"], ["70657.40", "0.016"], ["70676.00", "2.192"], ["70697.60", "3.413"], ["70731.50", "2.405"], ["70765.10", "0.665"], ["70783.30", "0.005"], ["70791.80", "2.086"], ["70792.10", "0.059"], ["70792.20", "12.623"], ["70821.10", "0.007"], ["70828.20", "0.459"], ["70835.30", "0.217"], ["70842.40", "0.158"], ["70844.60", "0.002"], ["70849.50", "0.007"], ["70851.70", "0.000"], ["70856.60", "0.013"], ["70858.80", "0.000"], ["70863.70", "0.007"], ["70865.90", "0.025"], ["70870.80", "0.007"], ["70873.00", "0.003"], ["70877.20", "0.106"], ["70880.10", "0.000"], ["70887.20", "0.005"], ["70894.30", "0.000"], ["71194.50", "0.002"], ["71249.90", "3.243"], ["71339.80", "0.700"], ["71519.10", "0.698"], ["71826.00", "0.049"], ["89523.20", "0.000"]]}}
{"local_ts": 1773486929534, "server_ts": 1773486929500, "data": {"e": "depthUpdate", "E": 1773486929501, "T": 1773486929500, "s": "BTCUSDT", "U": 10109531415520, "u": 10109531421066, "pu": 10109531415370, "b": [["1000.00", "26.592"], ["5000.00", "101.418"], ["7063.40", "0.028"], ["20233.40", "0.220"], ["20333.40", "2.500"], ["20433.40", "0.280"], ["33000.00", "3.789"], ["67069.30", "0.002"], ["68492.20", "0.625"], ["69220.80", "0.014"], ["69362.90", "0.187"], ["69554.50", "0.432"], ["69927.10", "0.721"], ["70439.20", "0.000"], ["70442.70", "0.000"], ["70449.80", "0.174"], ["70488.40", "12.374"], ["70547.30", "6.626"], ["70567.20", "1.117"], ["70573.80", "0.933"], ["70574.00", "0.372"], ["70574.90", "0.215"], ["70606.00", "0.513"], ["70606.20", "0.086"], ["70606.50", "0.045"], ["70609.00", "0.182"], ["70622.50", "0.156"], ["70622.70", "1.014"], ["70623.00", "0.136"], ["70623.70", "0.063"], ["70623.80", "0.110"], ["70624.20", "0.205"], ["70624.30", "0.360"], ["70625.00", "0.014"], ["70626.40", "0.401"], ["70627.00", "0.002"], ["70628.00", "0.012"], ["70628.10", "0.000"], ["70628.20", "0.601"], ["70628.30", "0.382"], ["70628.40", "0.188"], ["70630.10", "0.010"], ["70630.20", "0.013"], ["70631.60", "0.347"], ["70633.40", "4.701"]], "a": [["70635.50", "0.001"], ["70637.20", "0.003"], ["70640.50", "0.030"], ["70641.10", "0.001"], ["70641.90", "0.026"], ["70642.50", "0.088"], ["70642.60", "0.049"], ["70643.60", "0.130"], ["70643.70", "0.072"], ["70643.90", "0.060"], ["70644.50", "0.007"], ["70644.90", "0.004"], ["70645.10", "0.000"], ["70645.40", "0.015"], ["70646.70", "0.015"], ["70647.00", "0.000"], ["70647.20", "0.204"], ["70647.60", "0.362"], ["70648.30", "0.021"], ["70648.40", "0.000"], ["70648.50", "0.002"], ["70648.80", "0.009"], ["70648.90", "0.002"], ["70649.60", "0.015"], ["70649.70", "0.016"], ["70650.80", "0.143"], ["70650.90", "0.040"], ["70651.20", "1.362"], ["70652.80", "0.021"], ["70652.90", "0.026"], ["70655.00", "0.022"], ["70656.20", "0.018"], ["70657.50", "0.019"], ["70658.70", "0.002"], ["70660.00", "0.075"], ["70661.20", "0.000"], ["70663.00", "0.639"], ["70664.40", "0.128"], ["70664.60", "0.284"], ["70666.70", "0.025"], ["70666.90", "0.030"], ["70667.10", "0.025"], ["70668.00", "0.097"], ["70668.60", "0.023"], ["70668.80", "0.160"], ["70671.40", "0.175"], ["70691.40", "0.236"], ["70692.40", "0.089"], ["70733.40", "6.838"], ["70774.80", "0.132"], ["70793.40", "13.073"], ["70799.50", "0.507"], ["70821.10", "0.000"], ["70824.50", "0.007"], ["70828.20", "0.452"], ["70831.60", "0.009"], ["70835.30", "0.210"], ["70838.70", "0.009"], ["70842.40", "0.151"], ["70845.80", "0.015"], ["70849.50", "0.000"], ["70852.90", "0.022"], ["70856.60", "0.006"], ["70860.00", "7.110"], ["70863.70", "0.000"], ["70867.10", "0.007"], ["70870.80", "0.000"], ["70874.20", "0.007"], ["70880.70", "0.000"], ["71339.80", "0.700"], ["71653.80", "0.004"], ["71703.00", "0.000"], ["71749.00", "2.085"], ["72174.40", "1.186"], ["77343.60", "0.214"], ["89523.20", "0.000"]]}}
{"local_ts": 1773486930562, "server_ts": 1773486930524, "data": {"e": "depthUpdate", "E": 1773486930525, "T": 1773486930524, "s": "BTCUSDT", "U": 10109531461823, "u": 10109531467101, "pu": 10109531461732, "b": [["5000.00", "101.418"], ["7063.40", "0.028"], ["20133.40", "0.070"], ["20233.40", "2.350"], ["20333.40", "0.580"], ["56507.00", "0.005"], ["67101.70", "0.008"], ["69220.80", "0.008"], ["69927.10", "0.723"], ["69962.40", "0.998"], ["70280.30", "0.004"], ["70387.30", "0.000"], ["70435.60", "0.336"], ["70568.10", "0.139"], ["70573.40", "0.081"], ["70582.70", "0.003"], ["70583.10", "0.599"], ["70583.80", "0.005"], ["70586.40", "0.001"], ["70586.50", "0.005"], ["70591.90", "0.022"], ["70599.20", "0.405"], ["70599.60", "0.594"], ["70602.50", "0.000"], ["70604.30", "0.031"], ["70605.10", "0.597"], ["70605.50", "0.356"], ["70606.90", "0.002"], ["70609.00", "0.012"], ["70609.10", "0.187"], ["70610.70", "0.024"], ["70612.00", "0.017"], ["70612.40", "0.148"], ["70613.20", "0.015"], ["70613.60", "0.473"], ["70613.70", "0.265"], ["70614.50", "0.039"], ["70614.90", "0.008"], ["70615.00", "0.406"], ["70615.50", "0.006"], ["70615.60", "1.275"], ["70615.70", "0.566"], ["70615.80", "0.032"], ["70616.40", "0.001"], ["70616.60", "0.012"], ["70617.00", "0.015"], ["70617.20", "0.616"], ["70617.50", "0.513"], ["70618.00", "0.067"], ["70618.30", "0.017"], ["70619.10", "0.113"], ["70619.20", "0.000"], ["70619.50", "1.351"], ["70619.60", "0.148"], ["70620.80", "0.285"], ["70620.90", "0.000"], ["70621.20", "0.010"], ["70621.40", "0.000"], ["70621.60", "0.015"], ["70622.00", "0.013"], ["70622.10", "0.009"], ["70622.50", "0.235"], ["70622.70", "1.098"], ["70622.80", "0.670"], ["70622.90", "0.245"], ["70623.20", "0.062"], ["70623.30", "0.003"], ["70623.80", "0.108"], ["70624.00", "0.010"], ["70624.60", "0.290"], ["70625.00", "0.007"], ["70625.20", "0.023"], ["70625.30", "0.007"], ["70625.40", "0.016"], ["70625.50", "0.642"], ["70625.80", "0.002"], ["70626.00", "0.004"], ["70626.10", "0.002"], ["70626.20", "0.072"], ["70626.70", "0.000"], ["70627.00", "0.002"], ["70627.10", "0.008"], ["70627.50", "0.010"], ["70628.00", "0.349"], ["70628.20", "0.004"], ["70628.30", "0.015"], ["70628.40", "0.002"], ["70628.50", "0.003"], ["70629.10", "0.002"], ["70629.50", "0.001"], ["70629.60", "0.007"], ["70629.90", "0.003"], ["70630.00", "0.371"], ["70630.10", "0.010"], ["70630.60", "0.002"], ["70630.90", "0.000"], ["70631.20", "0.000"], ["70631.60", "0.008"], ["70631.70", "0.128"], ["70631.90", "0.000"], ["70632.40", "0.000"], ["70632.50", "0.002"], ["70633.30", "0.092"], ["70633.40", "4.924"]], "a": [["70633.50", "2.941"], ["70633.60", "0.059"], ["70636.40", "0.022"], ["70637.20", "0.001"], ["70638.80", "0.022"], ["70639.30", "0.060"], ["70640.30", "0.016"], ["70641.30", "0.021"], ["70641.80", "0.002"], ["70642.40", "0.007"], ["70643.10", "0.527"], ["70643.30", "0.043"], ["70643.90", "0.024"], ["70644.10", "0.142"], ["70644.50", "0.000"], ["70644.70", "0.601"], ["70644.80", "0.138"], ["70645.20", "0.003"], ["70645.40", "0.000"], ["70645.50", "0.603"], ["70645.60", "0.362"], ["70645.80", "0.002"], ["70646.70", "0.000"], ["70647.50", "0.522"], ["70647.60", "0.734"], ["70648.50", "0.143"], ["70648.80", "0.002"], ["70649.30", "0.003"], ["70649.90", "0.514"], ["70650.10", "0.006"], ["70650.80", "0.002"], ["70651.00", "0.013"], ["70651.30", "0.023"], ["70651.60", "0.000"], ["70652.40", "0.015"], ["70653.60", "1.171"], ["70654.70", "0.010"], ["70656.40", "0.001"], ["70656.50", "0.003"], ["70656.80", "0.299"], ["70657.00", "0.141"], ["70657.50", "0.004"], ["70658.10", "0.000"], ["70661.40", "0.059"], ["70661.50", "1.327"], ["70661.70", "0.639"], ["70662.70", "0.014"], ["70662.80", "0.010"], ["70663.70", "0.000"], ["70664.50", "0.233"], ["70664.70", "0.293"], ["70666.20", "0.492"], ["70668.80", "0.160"], ["70670.40", "0.038"], ["70671.60", "0.052"], ["70672.80", "0.016"], ["70674.30", "0.000"], ["70675.10", "0.077"], ["70676.00", "0.405"], ["70695.70", "0.592"], ["70697.60", "0.004"], ["70698.50", "0.356"], ["70733.30", "0.210"], ["70760.30", "0.088"], ["70799.50", "0.567"], ["71339.80", "0.700"], ["72046.10", "0.019"], ["74171.50", "0.224"], ["74182.00", "0.056"], ["89523.20", "0.000"]]}}
{"local_ts": 1773486931574, "server_ts": 1773486931544, "data": {"e": "depthUpdate", "E": 1773486931547, "T": 1773486931544, "s": "BTCUSDT", "U": 10109531507962, "u": 10109531512515, "pu": 10109531507895, "b": [["1000.00", "26.592"], ["5000.00", "101.418"], ["7063.40", "0.000"], ["20133.40", "2.050"], ["20233.40", "0.950"], ["33000.00", "3.789"], ["56507.00", "0.005"], ["67094.20", "0.002"], ["67101.70", "0.014"], ["69616.50", "0.000"], ["69637.50", "0.718"], ["69927.10", "0.721"], ["70280.20", "0.108"], ["70582.70", "3.448"], ["70599.80", "0.517"], ["70600.10", "0.187"], ["70604.30", "1.830"], ["70605.10", "0.544"], ["70605.40", "0.634"], ["70605.50", "0.356"], ["70605.60", "0.003"], ["70608.90", "0.009"], ["70609.10", "0.003"], ["70610.40", "0.030"], ["70615.60", "0.048"], ["70615.70", "0.197"], ["70616.80", "0.052"], ["70618.10", "0.000"], ["70621.10", "0.103"], ["70622.80", "0.673"], ["70625.50", "0.003"], ["70626.10", "0.005"], ["70629.90", "0.003"]], "a": [["70633.50", "0.975"], ["70636.40", "0.020"], ["70638.80", "0.003"], ["70639.60", "0.270"], ["70640.00", "0.022"], ["70640.10", "0.007"], ["70642.80", "0.023"], ["70644.10", "0.139"], ["70644.20", "0.021"], ["70646.40", "0.027"], ["70647.40", "0.001"], ["70649.40", "0.775"], ["70657.70", "0.031"], ["70658.50", "0.009"], ["70659.80", "0.019"], ["70662.30", "0.000"], ["70666.00", "0.053"], ["70668.00", "0.133"], ["70668.10", "0.004"], ["70670.30", "0.007"], ["70675.30", "1.881"], ["70677.80", "0.000"], ["70694.00", "0.111"], ["70696.90", "3.389"], ["70796.00", "0.061"], ["71262.10", "0.479"], ["71304.50", "1.988"], ["71339.80", "0.700"], ["71598.50", "0.024"], ["74192.10", "0.000"], ["89523.20", "0.000"]]}}
{"local_ts": 1773486932598, "server_ts": 1773486932568, "data": {"e": "depthUpdate", "E": 1773486932569, "T": 1773486932568, "s": "BTCUSDT", "U": 10109531553647, "u": 10109531560575, "pu": 10109531553571, "b": [["5000.00", "101.418"], ["7063.40", "0.000"], ["20133.40", "1.390"], ["20533.40", "1.610"], ["56507.00", "0.005"], ["67088.10", "0.000"], ["67101.70", "0.016"], ["67808.10", "0.038"], ["69644.50", "2.310"], ["69927.10", "0.721"], ["70300.00", "21.654"], ["70435.60", "0.000"], ["70500.50", "0.723"], ["70545.20", "0.273"], ["70555.70", "0.003"], ["70569.80", "0.180"], ["70586.70", "0.004"], ["70586.90", "0.045"], ["70599.80", "0.378"], ["70600.10", "0.003"], ["70605.40", "0.096"], ["70605.50", "0.002"], ["70606.20", "0.001"], ["70606.30", "0.003"], ["70606.40", "0.353"], ["70606.90", "0.141"], ["70608.70", "1.582"], ["70608.90", "0.547"], ["70612.20", "0.004"], ["70613.20", "0.000"], ["70616.30", "1.209"], ["70617.20", "0.616"], ["70617.80", "0.014"], ["70618.50", "0.012"], ["70619.50", "1.281"], ["70619.60", "1.203"], ["70620.90", "0.000"], ["70622.80", "0.495"], ["70623.00", "0.469"], ["70623.30", "0.144"], ["70623.70", "0.144"], ["70625.50", "0.010"], ["70626.00", "0.002"], ["70626.70", "0.000"], ["70627.00", "0.370"], ["70627.10", "0.008"], ["70628.00", "0.180"], ["70628.10", "0.167"], ["70628.40", "0.696"], ["70628.50", "0.005"], ["70629.30", "0.033"], ["70629.40", "0.037"], ["70629.90", "0.200"], ["70630.10", "0.010"], ["70630.20", "0.013"], ["70630.60", "0.179"], ["70631.60", "0.347"], ["70631.80", "0.176"], ["70632.60", "0.002"], ["70633.20", "0.006"], ["70633.40", "4.670"]], "a": [["70633.50", "0.792"], ["70635.40", "0.000"], ["70637.00", "0.006"], ["70638.80", "0.001"], ["70639.50", "0.001"], ["70643.10", "0.002"], ["70643.80", "0.000"], ["70644.10", "0.142"], ["70645.30", "0.014"], ["70645.80", "0.007"], ["70646.70", "0.000"], ["70646.80", "0.017"], ["70647.00", "0.000"], ["70647.30", "0.007"], ["70647.40", "0.001"], ["70648.30", "0.006"], ["70649.30", "0.008"], ["70649.40", "0.754"], ["70649.50", "0.061"], ["70649.70", "0.016"], ["70649.80", "0.004"], ["70650.80", "0.002"], ["70651.10", "1.072"], ["70651.30", "0.023"], ["70651.40", "0.005"], ["70652.40", "0.141"], ["70652.70", "0.008"], ["70653.00", "0.458"], ["70653.40", "0.029"], ["70653.60", "0.002"], ["70653.90", "0.014"], ["70654.10", "0.000"], ["70654.60", "0.006"], ["70655.20", "0.010"], ["70655.40", "0.005"], ["70655.50", "0.009"], ["70655.90", "0.002"], ["70656.00", "0.004"], ["70656.10", "0.001"], ["70656.40", "0.008"], ["70656.50", "0.502"], ["70656.60", "1.168"], ["70656.70", "0.059"], ["70656.80", "0.213"], ["70657.10", "0.013"], ["70658.00", "0.008"], ["70658.20", "0.019"], ["70658.40", "0.000"], ["70658.80", "0.141"], ["70659.60", "0.996"], ["70660.00", "0.096"], ["70660.90", "0.016"], ["70662.10", "0.018"], ["70662.20", "0.015"], ["70663.10", "0.003"], ["70663.40", "0.015"], ["70663.80", "0.699"], ["70664.70", "0.308"], ["70665.50", "0.021"], ["70665.90", "0.055"], ["70666.80", "0.146"], ["70667.20", "0.015"], ["70667.90", "0.032"], ["70668.10", "0.004"], ["70668.40", "0.017"], ["70668.80", "0.059"], ["70669.70", "0.228"], ["70669.80", "0.575"], ["70671.00", "7.791"], ["70671.80", "0.058"], ["70672.20", "0.002"], ["70673.70", "0.021"], ["70675.70", "0.073"], ["70676.60", "0.185"], ["70677.80", "0.057"], ["70678.40", "0.022"], ["70679.20", "0.012"], ["70697.10", "3.588"], ["70711.20", "0.015"], ["70723.40", "0.019"], ["70733.30", "0.122"], ["70760.50", "0.089"], ["70765.00", "4.714"], ["70765.10", "0.000"], ["70767.20", "10.087"], ["70778.30", "0.000"], ["70808.90", "0.414"], ["70809.50", "0.008"], ["70811.80", "0.000"], ["70813.80", "10.198"], ["70840.90", "1.679"], ["70842.90", "0.002"], ["70845.00", "31.172"], ["70856.20", "0.011"], ["70857.00", "0.220"], ["70871.70", "1.582"], ["70874.00", "0.000"], ["70876.10", "10.000"], ["70887.40", "0.000"], ["70917.60", "0.170"], ["70918.50", "0.000"], ["71339.70", "0.009"], ["71339.80", "1.400"]]}}
{"local_ts": 1773486933618, "server_ts": 1773486933590, "data": {"e": "depthUpdate", "E": 1773486933591, "T": 1773486933590, "s": "BTCUSDT", "U": 10109531614609, "u": 10109531620012, "pu": 10109531614604, "b": [["1000.00", "26.592"], ["5000.00", "101.418"], ["7063.40", "0.000"], ["20433.40", "1.160"], ["20533.40", "1.840"], ["56507.00", "0.005"], ["67101.00", "0.002"], ["69446.80", "0.575"], ["69616.20", "1.144"], ["69927.10", "0.721"], ["70280.20", "0.108"], ["70426.70", "0.274"], ["70598.10", "7.827"], ["70599.80", "0.517"], ["70605.40", "0.266"], ["70606.30", "0.003"], ["70606.70", "0.296"], ["70606.80", "0.089"], ["70606.90", "0.030"], ["70610.70", "0.009"], ["70611.40", "0.000"], ["70613.00", "0.004"], ["70613.70", "0.265"], ["70615.50", "0.331"], ["70618.60", "0.509"], ["70619.90", "0.073"], ["70620.90", "0.000"], ["70626.40", "0.357"], ["70626.60", "0.784"], ["70627.70", "0.177"], ["70628.00", "0.010"], ["70628.20", "0.174"], ["70628.50", "0.003"], ["70629.30", "0.033"], ["70629.50", "0.081"], ["70633.40", "4.564"]], "a": [["70633.50", "0.673"], ["70635.80", "0.002"], ["70637.00", "0.004"], ["70640.50", "0.002"], ["70641.10", "0.115"], ["70641.80", "0.525"], ["70641.90", "0.026"], ["70644.60", "2.080"], ["70645.30", "0.014"], ["70646.60", "0.087"], ["70650.00", "4.930"], ["70650.10", "0.006"], ["70651.20", "1.362"], ["70651.40", "0.020"], ["70652.50", "0.555"], ["70654.40", "0.007"], ["70656.40", "0.001"], ["70661.50", "0.825"], ["70662.10", "0.654"], ["70662.80", "0.519"], ["70663.10", "0.003"], ["70663.40", "0.000"], ["70663.80", "0.063"], ["70664.70", "0.293"], ["70664.90", "0.002"], ["70665.90", "0.040"], ["70666.60", "0.192"], ["70667.20", "0.000"], ["70668.70", "0.000"], ["70668.80", "0.192"], ["70669.30", "0.337"], ["70671.40", "0.087"], ["70672.70", "0.055"], ["70673.70", "0.000"], ["70675.70", "0.000"], ["70675.90", "0.542"], ["70676.60", "0.185"], ["70677.80", "0.000"], ["71339.80", "2.100"], ["71459.90", "1.537"], ["71763.60", "1.429"], ["74183.80", "0.000"]]}}
{"local_ts": 1773486934637, "server_ts": 1773486934608, "data": {"e": "depthUpdate", "E": 1773486934611, "T": 1773486934608, "s": "BTCUSDT", "U": 10109531666330, "u": 10109531671009, "pu": 10109531666304, "b": [["1000.00", "26.592"], ["5000.00", "101.438"], ["7063.40", "0.056"], ["20333.40", "0.710"], ["20433.40", "2.290"], ["20533.40", "0.000"], ["56507.00", "0.005"], ["67081.00", "0.002"], ["67101.70", "0.012"], ["67101.80", "0.004"], ["69927.10", "1.435"], ["70432.80", "0.177"], ["70539.50", "0.203"], ["70548.80", "3.339"], ["70549.40", "0.078"], ["70550.40", "0.057"], ["70568.10", "0.139"], ["70578.80", "0.293"], ["70586.90", "0.047"], ["70587.10", "0.014"], ["70604.70", "0.004"], ["70605.10", "0.544"], ["70605.50", "0.370"], ["70605.60", "0.173"], ["70609.60", "0.002"], ["70615.00", "0.406"], ["70616.80", "0.000"], ["70617.90", "1.157"], ["70618.00", "0.067"], ["70618.60", "0.150"], ["70618.90", "0.076"], ["70619.00", "0.027"], ["70619.20", "0.053"], ["70619.50", "2.484"], ["70619.60", "0.000"], ["70620.80", "0.285"], ["70621.70", "0.151"], ["70622.80", "0.495"], ["70622.90", "0.192"], ["70623.80", "0.110"], ["70624.20", "0.202"], ["70626.10", "0.639"], ["70626.30", "0.000"], ["70626.40", "0.393"], ["70626.80", "1.586"], ["70627.70", "0.000"], ["70628.30", "0.015"], ["70629.90", "0.006"], ["70630.00", "0.364"], ["70630.60", "0.002"], ["70631.70", "0.023"], ["70632.30", "0.001"], ["70632.90", "0.007"], ["70633.30", "0.092"], ["70633.40", "5.136"]], "a": [["70633.50", "2.331"], ["70633.60", "0.059"], ["70634.90", "0.057"], ["70639.60", "0.001"], ["70640.00", "0.010"], ["70640.50", "0.037"], ["70640.60", "0.005"], ["70641.20", "0.042"], ["70641.70", "0.002"], ["70641.80", "0.002"], ["70644.90", "0.011"], ["70646.50", "0.021"], ["70649.60", "0.080"], ["70661.60", "0.004"], ["70664.60", "0.284"], ["70665.90", "0.040"], ["70667.90", "0.016"], ["70669.80", "0.554"], ["70674.30", "0.000"], ["70675.90", "0.540"], ["70678.10", "0.520"], ["70693.30", "0.027"], ["70694.10", "0.316"], ["70700.10", "0.049"], ["70857.30", "0.007"], ["71339.70", "0.002"], ["71339.80", "2.107"], ["74173.90", "0.002"]]}}
{"local_ts": 1773486935661, "server_ts": 1773486935628, "data": {"e": "depthUpdate", "E": 1773486935631, "T": 1773486935628, "s": "BTCUSDT", "U": 10109531703803, "u": 10109531707721, "pu": 10109531703778, "b": [["5000.00", "101.418"], ["7063.40", "0.056"], ["20233.40", "0.330"], ["20333.40", "2.600"], ["20433.40", "0.070"], ["56507.00", "0.005"], ["65000.00", "96.671"], ["65400.00", "757.164"], ["65800.00", "14.936"], ["66200.00", "7.923"], ["66600.00", "4.178"], ["67000.00", "44.932"], ["67097.40", "0.004"], ["67400.00", "1.763"], ["67800.00", "14.282"], ["68200.00", "28.916"], ["68600.00", "28.433"], ["69000.00", "162.963"], ["69400.00", "26.891"], ["69501.30", "8.068"], ["69607.20", "17.788"], ["69800.00", "87.066"], ["69927.10", "1.435"], ["70200.00", "23.085"], ["70461.70", "3.222"], ["70500.60", "0.716"], ["70578.10", "0.000"], ["70586.40", "0.003"], ["70586.50", "0.003"], ["70596.90", "0.005"], ["70597.40", "0.428"], ["70600.00", "0.995"], ["70604.80", "0.207"], ["70604.90", "0.107"], ["70605.10", "0.321"], ["70605.40", "0.450"], ["70605.50", "0.172"], ["70605.60", "0.187"], ["70606.70", "0.253"], ["70606.80", "0.132"], ["70617.90", "0.648"], ["70618.90", "0.006"], ["70619.20", "0.079"], ["70620.10", "0.514"], ["70621.20", "0.078"], ["70624.30", "0.360"], ["70626.10", "0.639"], ["70626.20", "0.087"], ["70626.40", "0.545"], ["70630.10", "0.020"]], "a": [["70633.50", "2.101"], ["70638.60", "0.002"], ["70639.90", "0.001"], ["70640.50", "0.037"], ["70641.90", "0.528"], ["70642.10", "0.000"], ["70643.20", "0.082"], ["70643.80", "0.000"], ["70644.10", "0.139"], ["70645.10", "0.000"], ["70646.30", "0.073"], ["70647.50", "0.004"], ["70647.80", "0.000"], ["70648.20", "0.017"], ["70649.20", "0.073"], ["70649.30", "0.001"], ["70649.40", "0.769"], ["70649.80", "0.011"], ["70650.70", "0.015"], ["70651.20", "1.364"], ["70652.20", "0.017"], ["70653.30", "0.678"], ["70653.50", "0.023"], ["70654.00", "0.023"], ["70654.90", "0.097"], ["70655.40", "0.005"], ["70656.00", "0.025"], ["70656.20", "0.018"], ["70656.70", "0.059"], ["70656.80", "0.213"], ["70657.90", "1.086"], ["70658.00", "0.029"], ["70659.20", "0.018"], ["70661.30", "0.008"], ["70662.00", "0.044"], ["70662.10", "0.010"], ["70662.30", "0.000"], ["70663.00", "0.003"], ["70663.20", "0.014"], ["70663.50", "0.636"], ["70664.10", "0.548"], ["70664.50", "0.233"], ["70665.70", "0.024"], ["70666.80", "0.076"], ["70667.00", "0.003"], ["70667.90", "0.107"], ["70669.80", "0.575"], ["70671.80", "0.037"], ["70672.20", "0.002"], ["70673.50", "0.894"], ["70673.70", "0.000"], ["70674.30", "0.057"], ["70678.10", "0.518"], ["70680.50", "0.004"], ["70765.00", "4.576"], ["70803.50", "0.781"], ["70803.90", "3.324"], ["70857.20", "0.007"], ["70857.30", "0.000"], ["71339.70", "0.002"], ["71339.80", "2.100"], ["71400.00", "11.804"], ["71800.00", "145.799"], ["72200.00", "11.782"], ["72600.00", "34.221"], ["73000.00", "63.000"], ["73400.00", "9.263"], ["73800.00", "47.170"], ["74200.00", "23.136"], ["74600.00", "9.436"], ["75000.00", "293.375"]]}}
{"local_ts": 1773486936682, "server_ts": 1773486936650, "data": {"e": "depthUpdate", "E": 1773486936651, "T": 1773486936650, "s": "BTCUSDT", "U": 10109531746242, "u": 10109531749499, "pu": 10109531746210, "b": [["1000.00", "26.742"], ["5000.00", "101.418"], ["7063.40", "0.056"], ["20133.40", "0.180"], ["20233.40", "2.450"], ["20333.40", "0.370"], ["33000.00", "3.785"], ["56507.00", "0.005"], ["67088.50", "0.002"], ["67101.80", "0.006"], ["69408.90", "1.440"], ["69489.10", "0.000"], ["69607.20", "14.776"], ["69644.70", "0.006"], ["70066.30", "0.356"], ["70273.00", "19.726"], ["70280.20", "0.108"], ["70350.90", "0.639"], ["70568.10", "0.000"], ["70604.90", "0.079"], ["70605.10", "0.321"], ["70605.40", "0.450"], ["70605.50", "0.186"], ["70622.80", "0.498"], ["70626.10", "0.642"]], "a": [["70633.50", "2.256"], ["70640.00", "0.007"], ["70644.10", "0.139"], ["70661.90", "0.005"], ["70674.00", "0.276"], ["70680.50", "0.002"], ["70856.90", "0.007"], ["71198.60", "0.140"], ["71339.70", "0.002"], ["71339.80", "2.125"], ["71601.20", "0.279"], ["71621.90", "1.390"], ["71716.70", "1.047"], ["74172.90", "0.002"]]}}
{"local_ts": 1773486937697, "server_ts": 1773486937669, "data": {"e": "depthUpdate", "E": 1773486937671, "T": 1773486937669, "s": "BTCUSDT", "U": 10109531786209, "u": 10109531790293, "pu": 10109531786159, "b": [["5000.00", "101.418"], ["7063.40", "0.028"], ["20133.40", "2.300"], ["20233.40", "0.670"], ["20533.40", "0.030"], ["67821.50", "0.000"], ["69536.60", "4.023"], ["69538.60", "5.025"], ["69609.20", "17.501"], ["69783.80", "0.154"], ["69927.10", "1.435"], ["70586.40", "0.003"], ["70596.80", "0.004"], ["70605.00", "0.282"], ["70605.10", "0.349"], ["70605.40", "0.096"], ["70605.70", "0.013"], ["70609.00", "0.019"], ["70622.80", "0.495"], ["70625.20", "0.030"], ["70625.60", "0.001"], ["70626.10", "0.639"], ["70626.40", "0.545"], ["70627.00", "0.186"]], "a": [["70633.50", "2.294"], ["70640.50", "0.037"], ["70641.90", "0.048"], ["70644.10", "0.142"], ["70647.40", "0.004"], ["70681.90", "0.024"], ["70758.00", "0.590"], ["70760.50", "0.179"], ["71339.80", "3.500"], ["71621.90", "1.112"], ["71657.70", "7.041"], ["71728.30", "2.855"], ["71761.60", "4.591"], ["72365.30", "0.000"], ["74177.50", "0.201"]]}}
{"local_ts": 1773486938718, "server_ts": 1773486938688, "data": {"e": "depthUpdate", "E": 1773486938691, "T": 1773486938688, "s": "BTCUSDT", "U": 10109531830839, "u": 10109531834390, "pu": 10109531830754, "b": [["1000.00", "26.892"], ["5000.00", "101.418"], ["7063.40", "0.028"], ["20133.40", "1.090"], ["20533.40", "1.910"], ["33000.00", "3.789"], ["67097.90", "0.002"], ["69220.80", "0.011"], ["69466.00", "3.019"], ["69607.20", "9.756"], ["69700.00", "13.667"], ["69927.10", "1.435"], ["69962.40", "1.711"], ["70280.20", "0.108"], ["70280.30", "0.000"], ["70387.40", "0.005"], ["70586.40", "0.003"], ["70586.50", "0.003"], ["70598.10", "7.791"], ["70599.30", "0.068"], ["70605.10", "0.321"], ["70605.20", "1.389"], ["70605.40", "0.096"], ["70605.90", "0.103"], ["70606.00", "0.513"], ["70606.20", "0.001"], ["70606.90", "0.209"], ["70611.90", "0.020"], ["70622.80", "0.495"], ["70624.50", "0.016"], ["70626.10", "0.639"], ["70626.40", "0.545"], ["70633.40", "4.890"]], "a": [["70633.50", "2.270"], ["70639.60", "0.001"], ["70640.50", "0.037"], ["70641.80", "0.525"], ["70641.90", "0.571"], ["70643.20", "0.082"], ["70644.10", "0.142"], ["70646.60", "0.087"], ["70647.40", "0.004"], ["70648.00", "0.015"], ["70648.20", "0.002"], ["70649.30", "0.024"], ["70649.50", "0.002"], ["70650.10", "0.006"], ["70650.60", "0.017"], ["70650.70", "0.000"], ["70651.90", "0.019"], ["70652.00", "0.162"], ["70652.20", "0.002"], ["70653.20", "0.020"], ["70653.50", "0.008"], ["70654.00", "0.023"], ["70654.10", "0.000"], ["70654.50", "0.023"], ["70654.70", "0.002"], ["70655.80", "0.022"], ["70656.00", "0.025"], ["70657.20", "0.219"], ["70658.50", "0.024"], ["70659.80", "0.019"], ["70661.00", "0.000"], ["70662.30", "0.000"], ["70663.50", "0.636"], ["70664.80", "0.786"], ["70665.90", "0.040"], ["70666.00", "0.053"], ["70667.90", "0.037"], ["70668.10", "0.029"], ["70668.80", "0.197"], ["70669.80", "0.554"], ["70671.80", "0.037"], ["70674.30", "0.057"], ["70679.20", "0.012"], ["70689.40", "0.020"], ["71339.80", "3.500"], ["71655.70", "8.774"], ["71796.90", "0.974"]]}}
{"local_ts": 1773486939753, "server_ts": 1773486939711, "data": {"e": "depthUpdate", "E": 1773486939713, "T": 1773486939711, "s": "BTCUSDT", "U": 10109532021648, "u": 10109532058298, "pu": 10109532021506, "b": [["1000.00", "26.892"], ["5000.00", "101.418"], ["7065.10", "0.028"], ["20451.00", "0.580"], ["20533.40", "1.540"], ["69238.00", "0.754"], ["69584.20", "0.713"], ["69626.60", "0.715"], ["69654.80", "0.018"], ["69697.20", "0.710"], ["69925.10", "3.036"], ["69944.50", "0.002"], ["70100.10", "3.739"], ["70222.10", "15.372"], ["70301.30", "0.106"], ["70319.90", "0.000"], ["70321.20", "0.000"], ["70351.80", "0.270"], ["70406.60", "0.002"], ["70421.70", "0.665"], ["70427.30", "0.004"], ["70429.20", "0.043"], ["70481.90", "0.096"], ["70492.00", "0.000"], ["70497.10", "0.002"], ["70508.40", "0.002"], ["70508.50", "0.018"], ["70508.60", "0.088"], ["70509.00", "0.000"], ["70509.10", "0.000"], ["70510.10", "1.312"], ["70513.60", "0.840"], ["70514.30", "0.006"], ["70548.00", "1.796"], ["70551.00", "0.103"], ["70555.00", "2.004"], ["70557.80", "0.000"], ["70558.40", "1.202"], ["70558.80", "1.542"], ["70564.90", "0.041"], ["70570.90", "0.122"], ["70571.90", "0.089"], ["70575.60", "0.392"], ["70579.00", "0.093"], ["70580.60", "0.055"], ["70580.80", "0.071"], ["70581.40", "0.015"], ["70582.70", "0.160"], ["70583.40", "0.010"], ["70583.90", "0.081"], ["70585.50", "0.511"], ["70585.90", "0.002"], ["70587.00", "0.027"], ["70587.40", "0.091"], ["70587.70", "0.063"], ["70589.40", "0.083"], ["70590.00", "1.810"], ["70591.20", "0.065"], ["70592.50", "0.027"], ["70592.90", "0.002"], ["70593.70", "0.511"], ["70594.00", "8.500"], ["70595.00", "1.802"], ["70595.40", "0.063"], ["70595.60", "0.268"], ["70596.90", "0.000"], ["70598.00", "0.004"], ["70598.20", "2.208"], ["70598.30", "0.200"], ["70599.00", "0.298"], ["70599.20", "0.274"], ["70599.30", "0.030"], ["70599.40", "0.104"], ["70599.70", "0.002"], ["70599.80", "0.179"], ["70600.10", "0.072"], ["70600.80", "0.002"], ["70601.20", "0.204"], ["70601.40", "0.526"], ["70601.90", "1.264"], ["70602.20", "0.001"], ["70602.40", "0.009"], ["70602.60", "0.275"], ["70603.30", "0.002"], ["70603.60", "0.893"], ["70603.80", "0.675"], ["70604.00", "0.000"], ["70604.20", "0.024"], ["70604.30", "0.000"], ["70604.40", "0.065"], ["70604.70", "0.002"], ["70605.00", "0.003"], ["70605.10", "0.329"], ["70605.40", "0.002"], ["70606.40", "0.266"], ["70606.80", "0.012"], ["70607.20", "0.842"], ["70607.30", "0.111"], ["70607.90", "0.006"], ["70608.20", "0.000"], ["70609.00", "0.007"], ["70609.30", "0.031"], ["70609.60", "0.036"], ["70610.70", "0.100"], ["70611.00", "0.415"], ["70612.10", "0.003"], ["70612.40", "0.008"], ["70613.50", "0.009"], ["70613.70", "0.085"], ["70613.80", "0.594"], ["70614.10", "0.000"], ["70614.40", "0.843"], ["70614.70", "0.000"], ["70614.80", "0.034"], ["70614.90", "0.270"], ["70615.00", "0.381"], ["70615.50", "0.529"], ["70615.80", "0.264"], ["70615.90", "0.023"], ["70616.40", "0.000"], ["70616.60", "0.005"], ["70617.70", "0.274"], ["70617.80", "0.007"], ["70617.90", "0.620"], ["70618.00", "0.119"], ["70618.20", "0.267"], ["70618.60", "0.104"], ["70620.00", "0.037"], ["70621.40", "0.000"], ["70622.50", "0.063"], ["70622.60", "0.000"], ["70623.20", "0.321"], ["70624.00", "0.247"], ["70624.50", "0.094"], ["70625.60", "0.513"], ["70626.30", "0.001"], ["70626.60", "0.265"], ["70626.90", "0.463"], ["70627.00", "0.005"], ["70628.40", "0.003"], ["70628.60", "0.009"], ["70629.80", "0.004"], ["70629.90", "0.217"], ["70630.20", "0.010"], ["70630.70", "0.000"], ["70631.50", "0.152"], ["70631.80", "0.006"], ["70632.00", "0.007"], ["70632.30", "0.021"], ["70632.40", "0.027"], ["70633.10", "0.002"], ["70633.40", "0.975"], ["70633.70", "0.000"], ["70634.60", "0.000"], ["70635.10", "0.839"], ["70635.90", "0.090"], ["70636.00", "0.061"], ["70636.10", "0.155"], ["70636.30", "0.247"], ["70636.60", "0.000"], ["70636.70", "0.012"], ["70636.80", "0.085"], ["70637.40", "0.133"], ["70637.90", "0.010"], ["70638.30", "0.001"], ["70639.10", "0.005"], ["70639.20", "0.002"], ["70639.70", "0.001"], ["70640.20", "0.021"], ["70640.40", "0.006"], ["70640.50", "0.004"], ["70640.70", "0.003"], ["70641.70", "0.356"], ["70641.90", "0.461"], ["70642.00", "0.618"], ["70642.10", "0.511"], ["70642.20", "0.339"], ["70642.40", "0.000"], ["70642.50", "0.285"], ["70642.60", "0.619"], ["70642.80", "0.117"], ["70643.00", "0.118"], ["70643.20", "0.063"], ["70643.50", "0.063"], ["70643.70", "0.005"], ["70643.90", "0.138"], ["70644.00", "0.013"], ["70644.40", "0.003"], ["70644.90", "0.232"], ["70645.10", "0.005"], ["70645.20", "0.001"], ["70645.70", "0.008"], ["70646.40", "0.000"], ["70646.60", "0.001"], ["70647.00", "0.004"], ["70647.10", "0.000"], ["70647.40", "0.005"], ["70648.20", "0.002"], ["70648.30", "0.002"], ["70650.50", "0.004"], ["70651.00", "0.240"]], "a": [["70651.10", "8.917"], ["70651.50", "0.002"], ["70651.60", "0.012"], ["70651.80", "0.000"], ["70652.50", "0.000"], ["70652.90", "0.030"], ["70653.30", "0.000"], ["70653.90", "0.000"], ["70654.50", "0.004"], ["70655.10", "0.043"], ["70655.40", "0.002"], ["70655.50", "0.000"], ["70656.90", "0.005"], ["70657.00", "0.015"], ["70657.10", "0.025"], ["70657.20", "1.896"], ["70658.10", "0.000"], ["70658.20", "0.004"], ["70658.30", "0.206"], ["70658.80", "0.033"], ["70659.00", "0.475"], ["70659.10", "0.214"], ["70659.20", "0.263"], ["70659.30", "0.001"], ["70659.50", "0.087"], ["70659.80", "0.003"], ["70659.90", "0.214"], ["70660.30", "0.025"], ["70660.50", "0.003"], ["70660.60", "0.025"], ["70661.20", "0.001"], ["70661.40", "0.141"], ["70661.60", "0.006"], ["70661.70", "0.039"], ["70661.90", "0.041"], ["70662.00", "0.046"], ["70662.10", "0.002"], ["70662.20", "0.043"], ["70662.30", "0.000"], ["70662.40", "0.003"], ["70662.50", "0.003"], ["70662.90", "0.120"], ["70663.20", "0.003"], ["70663.50", "0.001"], ["70663.60", "0.110"], ["70663.80", "0.036"], ["70663.90", "0.004"], ["70664.30", "0.001"], ["70664.60", "0.001"], ["70664.70", "0.478"], ["70664.80", "0.359"], ["70664.90", "0.141"], ["70665.00", "0.009"], ["70665.20", "0.005"], ["70665.30", "0.005"], ["70665.50", "0.003"], ["70665.90", "0.015"], ["70666.00", "0.001"], ["70666.30", "0.000"], ["70666.40", "0.297"], ["70666.50", "0.008"], ["70666.70", "0.022"], ["70667.10", "0.001"], ["70667.50", "0.004"], ["70667.80", "0.001"], ["70668.20", "0.106"], ["70668.50", "0.004"], ["70668.70", "0.001"], ["70669.40", "0.001"], ["70669.60", "0.021"], ["70669.80", "0.001"], ["70670.50", "0.834"], ["70670.60", "0.460"], ["70670.80", "0.020"], ["70671.10", "0.540"], ["70671.50", "1.428"], ["70672.30", "0.002"], ["70672.50", "0.024"], ["70672.70", "0.002"], ["70672.90", "0.004"], ["70673.70", "0.000"], ["70675.80", "0.003"], ["70676.30", "0.415"], ["70677.10", "0.000"], ["70679.90", "0.397"], ["70680.00", "2.764"], ["70683.10", "0.283"], ["70685.90", "0.157"], ["70686.10", "0.027"], ["70686.60", "0.026"], ["70688.10", "0.072"], ["70688.20", "0.029"], ["70688.30", "0.000"], ["70690.00", "4.714"], ["70690.10", "0.004"], ["70692.20", "0.003"], ["70692.80", "0.004"], ["70693.30", "0.057"], ["70693.40", "0.038"], ["70694.80", "0.002"], ["70695.40", "0.122"], ["70696.30", "0.289"], ["70697.00", "0.077"], ["70697.50", "0.004"], ["70698.00", "0.546"], ["70698.50", "0.152"], ["70700.50", "0.066"], ["70702.90", "0.035"], ["70703.60", "0.089"], ["70703.90", "0.454"], ["70704.00", "0.041"], ["70704.20", "0.001"], ["70704.40", "0.000"], ["70704.50", "0.002"], ["70705.00", "0.000"], ["70705.10", "0.014"], ["70705.30", "0.002"], ["70705.80", "0.211"], ["70705.90", "0.004"], ["70706.10", "0.002"], ["70707.10", "0.583"], ["70707.30", "0.246"], ["70707.40", "0.024"], ["70707.60", "0.037"], ["70707.80", "1.068"], ["70709.70", "0.000"], ["70711.10", "0.126"], ["70712.60", "0.040"], ["70714.20", "0.072"], ["70714.40", "0.043"], ["70714.60", "0.039"], ["70714.80", "0.005"], ["70715.10", "7.786"], ["70719.00", "0.104"], ["70720.50", "0.012"], ["70721.40", "0.002"], ["70722.00", "0.503"], ["70722.70", "0.454"], ["70723.20", "0.144"], ["70727.40", "0.933"], ["70731.50", "0.151"], ["70734.80", "0.663"], ["70735.00", "0.008"], ["70735.40", "0.684"], ["70738.40", "0.267"], ["70738.60", "2.723"], ["70744.30", "0.079"], ["70744.70", "0.015"], ["70754.90", "0.077"], ["70759.60", "0.003"], ["70760.00", "1.053"], ["70760.90", "0.090"], ["70762.90", "1.057"], ["70767.70", "0.000"], ["70770.20", "0.511"], ["70776.90", "0.601"], ["70798.20", "9.893"], ["70805.10", "0.390"], ["70805.60", "0.002"], ["70809.10", "0.002"], ["70813.00", "0.061"], ["70815.80", "1.640"], ["70817.30", "2.240"], ["70820.40", "0.000"], ["70833.70", "0.000"], ["70847.60", "0.000"], ["70851.10", "0.002"], ["70876.90", "0.007"], ["70913.80", "1.264"], ["70960.70", "0.082"], ["70960.90", "0.000"], ["71059.80", "7.403"], ["71067.40", "3.240"], ["71337.80", "1.547"], ["71357.60", "0.000"], ["71404.30", "1.676"], ["71477.60", "0.559"], ["71794.60", "0.000"], ["74192.70", "0.002"], ["74199.40", "0.002"], ["89523.20", "0.000"]]}}
{"local_ts": 1773486940770, "server_ts": 1773486940732, "data": {"e": "depthUpdate", "E": 1773486940733, "T": 1773486940732, "s": "BTCUSDT", "U": 10109532178548, "u": 10109532185125, "pu": 10109532178283, "b": [["5000.00", "101.418"], ["7064.40", "0.028"], ["20343.70", "1.020"], ["20443.70", "1.010"], ["20444.40", "0.000"], ["20444.90", "0.000"], ["20446.60", "0.090"], ["20446.90", "0.010"], ["20448.00", "0.160"], ["20451.00", "0.350"], ["20451.70", "0.000"], ["20452.40", "0.000"], ["20452.80", "0.000"], ["20453.00", "0.000"], ["20453.30", "0.000"], ["56515.00", "0.000"], ["67818.00", "0.101"], ["69937.30", "0.000"], ["70078.70", "0.000"], ["70370.10", "0.004"], ["70397.40", "0.000"], ["70516.30", "0.004"], ["70534.80", "0.002"], ["70552.00", "0.744"], ["70563.60", "0.006"], ["70575.60", "0.127"], ["70589.10", "0.126"], ["70591.60", "0.003"], ["70592.30", "0.003"], ["70593.00", "0.009"], ["70593.70", "0.514"], ["70595.70", "0.049"], ["70596.00", "0.009"], ["70596.10", "1.073"], ["70600.40", "0.170"], ["70606.70", "0.017"], ["70608.40", "0.319"], ["70609.90", "0.089"], ["70610.10", "0.000"], ["70619.30", "0.118"], ["70619.60", "0.042"], ["70626.50", "0.508"], ["70629.70", "0.045"], ["70630.20", "0.006"], ["70633.60", "0.009"], ["70634.00", "0.031"], ["70635.40", "0.047"], ["70636.80", "0.002"]], "a": [["70643.80", "5.631"], ["70650.90", "0.437"], ["70651.00", "0.159"], ["70651.10", "0.058"], ["70652.50", "0.001"], ["70655.90", "0.175"], ["70657.40", "0.005"], ["70675.00", "0.655"], ["70675.80", "0.006"], ["70687.10", "1.917"], ["70693.30", "0.101"], ["70695.90", "0.005"], ["70696.60", "5.155"], ["70698.70", "0.059"], ["70701.10", "0.078"], ["70706.40", "0.009"], ["70713.00", "0.209"], ["70714.60", "0.070"], ["70762.90", "1.055"], ["70771.00", "0.094"], ["70813.50", "13.151"], ["70851.10", "0.000"], ["71023.00", "0.528"], ["71350.20", "0.000"], ["72013.30", "0.010"], ["74201.20", "0.002"], ["89523.20", "0.000"]]}}
{"local_ts": 1773486941786, "server_ts": 1773486941752, "data": {"e": "depthUpdate", "E": 1773486941755, "T": 1773486941752, "s": "BTCUSDT", "U": 10109532227024, "u": 10109532231097, "pu": 10109532226951, "b": [["1000.00", "26.892"], ["5000.00", "101.418"], ["7064.40", "0.000"], ["20243.70", "0.570"], ["20343.70", "2.430"], ["20443.70", "0.000"], ["33000.00", "3.785"], ["67098.00", "0.002"], ["68841.90", "0.000"], ["69937.30", "0.708"], ["69962.30", "0.013"], ["70290.50", "0.000"], ["70461.90", "1.131"], ["70471.20", "4.235"], ["70510.00", "0.675"], ["70528.70", "0.004"], ["70534.80", "0.000"], ["70597.00", "0.219"], ["70597.10", "0.002"], ["70599.40", "0.108"], ["70600.40", "0.368"], ["70603.90", "0.312"], ["70608.00", "0.004"], ["70608.40", "0.291"], ["70615.20", "0.005"], ["70615.30", "0.001"], ["70615.90", "0.012"], ["70616.00", "0.016"], ["70622.00", "1.212"], ["70622.80", "0.724"], ["70629.80", "0.063"], ["70633.10", "0.000"], ["70634.70", "0.003"], ["70636.60", "0.000"], ["70636.70", "0.026"], ["70640.60", "0.003"], ["70642.90", "0.005"], ["70643.00", "0.002"], ["70643.70", "3.047"]], "a": [["70643.80", "4.797"], ["70647.80", "0.032"], ["70650.20", "0.002"], ["70650.30", "0.001"], ["70653.20", "0.025"], ["70654.40", "0.078"], ["70656.80", "0.179"], ["70656.90", "0.473"], ["70657.90", "0.300"], ["70665.90", "0.091"], ["70666.20", "0.048"], ["70670.30", "0.071"], ["70677.60", "0.009"], ["70677.70", "0.014"], ["70677.80", "0.000"], ["70705.00", "0.283"], ["70726.90", "0.000"], ["70769.60", "0.002"], ["70771.00", "0.092"], ["70775.30", "0.242"], ["70814.10", "1.360"], ["71350.20", "1.399"], ["71774.10", "0.695"], ["74184.20", "0.000"], ["89523.20", "0.000"]]}}
{"local_ts": 1773486942806, "server_ts": 1773486942776, "data": {"e": "depthUpdate", "E": 1773486942777, "T": 1773486942776, "s": "BTCUSDT", "U": 10109532293124, "u": 10109532307072, "pu": 10109532293057, "b": [["5000.00", "101.418"], ["7064.40", "0.000"], ["20141.70", "0.010"], ["20143.10", "0.120"], ["20241.70", "0.010"], ["20243.00", "0.010"], ["20243.10", "0.240"], ["20243.70", "2.300"], ["20343.70", "0.160"], ["67079.40", "0.000"], ["67093.00", "0.006"], ["69935.30", "0.000"], ["69936.60", "0.076"], ["69936.70", "0.000"], ["69937.40", "0.000"], ["70001.20", "0.004"], ["70011.40", "0.016"], ["70076.90", "0.155"], ["70176.20", "0.000"], ["70186.40", "2.210"], ["70351.60", "0.000"], ["70361.90", "0.004"], ["70397.60", "0.000"], ["70397.70", "1.560"], ["70465.10", "0.099"], ["70466.40", "0.267"], ["70522.00", "0.002"], ["70523.00", "6.722"], ["70527.50", "0.000"], ["70528.70", "0.002"], ["70537.80", "0.002"], ["70549.10", "0.014"], ["70551.80", "0.002"], ["70555.40", "0.000"], ["70569.00", "0.025"], ["70571.00", "0.560"], ["70572.70", "0.103"], ["70573.40", "0.000"], ["70574.10", "0.128"], ["70575.00", "0.089"], ["70577.10", "0.089"], ["70578.10", "0.001"], ["70583.10", "1.031"], ["70585.20", "0.124"], ["70586.50", "0.081"], ["70588.20", "0.001"], ["70588.80", "0.004"], ["70589.60", "0.036"], ["70590.30", "0.359"], ["70592.50", "0.034"], ["70592.80", "0.848"], ["70593.00", "0.005"], ["70595.10", "0.006"], ["70596.20", "0.513"], ["70596.50", "0.071"], ["70596.60", "0.001"], ["70598.00", "0.008"], ["70598.30", "0.200"], ["70599.00", "0.298"], ["70599.10", "0.003"], ["70599.30", "0.118"], ["70600.10", "0.074"], ["70600.30", "0.268"], ["70602.10", "0.075"], ["70603.00", "0.001"], ["70603.10", "0.003"], ["70605.40", "0.104"], ["70605.50", "0.002"], ["70605.70", "0.000"], ["70606.30", "0.104"], ["70606.50", "0.028"], ["70606.80", "0.005"], ["70607.40", "0.056"], ["70607.80", "0.029"], ["70609.30", "0.008"], ["70610.20", "0.070"], ["70612.80", "0.060"], ["70614.80", "0.000"], ["70615.20", "0.005"], ["70615.30", "0.001"], ["70615.90", "0.012"], ["70616.00", "0.016"], ["70617.10", "0.052"], ["70617.20", "0.373"], ["70617.60", "0.027"], ["70618.50", "1.215"], ["70618.80", "0.060"], ["70619.60", "0.000"], ["70621.50", "0.021"], ["70621.60", "0.000"], ["70623.30", "0.289"], ["70623.80", "0.002"], ["70624.30", "0.093"], ["70625.60", "0.001"], ["70626.10", "0.293"], ["70626.20", "0.013"], ["70627.60", "0.078"], ["70627.70", "0.020"], ["70627.80", "0.202"], ["70627.90", "0.033"], ["70628.30", "0.296"], ["70628.40", "0.645"], ["70628.60", "0.009"], ["70628.90", "0.088"], ["70629.10", "0.258"], ["70629.20", "0.079"], ["70629.40", "0.430"], ["70630.70", "0.000"], ["70631.10", "0.003"], ["70631.70", "0.023"], ["70632.50", "0.012"], ["70632.70", "1.359"], ["70633.20", "0.117"], ["70635.40", "0.331"], ["70635.70", "0.009"], ["70636.10", "0.002"], ["70636.40", "0.018"], ["70636.70", "0.007"], ["70636.90", "0.006"], ["70637.10", "0.003"], ["70637.30", "0.003"], ["70637.60", "0.003"], ["70638.00", "0.005"], ["70638.10", "0.004"], ["70638.40", "0.456"], ["70638.50", "0.010"], ["70638.60", "0.472"], ["70639.80", "0.006"], ["70640.70", "0.003"], ["70640.80", "0.082"], ["70641.10", "0.002"], ["70641.50", "0.231"], ["70641.60", "1.300"], ["70641.70", "0.296"], ["70641.80", "0.000"], ["70642.00", "0.000"], ["70642.20", "0.000"], ["70642.30", "0.000"], ["70642.40", "0.000"], ["70642.50", "0.000"], ["70642.60", "0.000"], ["70642.70", "0.000"], ["70642.80", "0.000"], ["70642.90", "0.000"], ["70643.00", "0.000"], ["70643.10", "0.000"]], "a": [["70641.80", "12.304"], ["70641.90", "0.002"], ["70642.00", "0.004"], ["70642.10", "0.000"], ["70642.20", "0.003"], ["70642.30", "0.000"], ["70642.40", "0.000"], ["70642.50", "0.000"], ["70642.60", "0.000"], ["70642.70", "0.690"], ["70642.80", "0.000"], ["70642.90", "0.000"], ["70643.00", "1.296"], ["70643.10", "1.083"], ["70643.20", "0.107"], ["70643.30", "0.110"], ["70643.40", "0.002"], ["70643.50", "0.003"], ["70643.60", "0.000"], ["70643.70", "0.000"], ["70643.80", "0.058"], ["70643.90", "0.000"], ["70644.30", "0.003"], ["70644.80", "0.000"], ["70646.10", "0.001"], ["70647.70", "0.001"], ["70647.80", "0.006"], ["70648.20", "0.094"], ["70648.70", "0.003"], ["70648.80", "0.006"], ["70649.70", "0.003"], ["70650.00", "0.005"], ["70650.10", "0.000"], ["70650.60", "0.057"], ["70650.90", "0.404"], ["70651.00", "0.251"], ["70651.10", "0.000"], ["70651.20", "0.003"], ["70651.30", "0.003"], ["70651.70", "0.021"], ["70652.30", "0.000"], ["70652.40", "0.006"], ["70652.60", "0.004"], ["70654.40", "0.073"], ["70656.80", "0.131"], ["70656.90", "0.040"], ["70657.10", "0.001"], ["70657.80", "0.012"], ["70657.90", "0.448"], ["70659.20", "0.220"], ["70661.20", "0.000"], ["70662.80", "0.004"], ["70665.90", "0.081"], ["70666.50", "0.569"], ["70667.20", "0.011"], ["70669.30", "0.006"], ["70670.30", "0.000"], ["70670.40", "0.002"], ["70673.60", "0.010"], ["70674.90", "0.000"], ["70675.00", "0.687"], ["70675.20", "0.116"], ["70677.70", "0.011"], ["70678.00", "0.751"], ["70680.10", "0.066"], ["70682.30", "0.004"], ["70685.20", "0.068"], ["70685.50", "0.146"], ["70685.90", "0.086"], ["70686.20", "0.333"], ["70689.90", "0.988"], ["70691.70", "0.003"], ["70694.80", "0.089"], ["70695.10", "0.013"], ["70695.20", "0.036"], ["70695.40", "0.058"], ["70695.90", "0.002"], ["70698.30", "0.099"], ["70700.50", "0.063"], ["70703.30", "0.253"], ["70711.90", "0.013"], ["70716.20", "0.193"], ["70718.50", "0.250"], ["70719.90", "0.000"], ["70725.10", "0.010"], ["70728.30", "0.000"], ["70730.00", "0.248"], ["70732.70", "0.008"], ["70734.40", "0.350"], ["70739.40", "0.041"], ["70740.70", "0.181"], ["70744.70", "0.007"], ["70749.70", "0.243"], ["70754.40", "0.000"], ["70767.80", "0.012"], ["70769.60", "0.000"], ["70786.60", "0.039"], ["70790.10", "0.039"], ["70791.60", "0.017"], ["70795.10", "0.513"], ["70797.20", "0.060"], ["70916.20", "0.560"], ["70926.60", "0.004"], ["71093.50", "0.000"], ["71103.90", "0.008"], ["71159.50", "0.008"], ["71271.30", "0.000"], ["71281.70", "0.016"], ["71348.20", "0.000"], ["71349.50", "0.000"], ["71349.60", "0.000"], ["71372.90", "0.032"], ["71586.40", "0.018"], ["71641.80", "0.707"], ["71644.50", "0.000"], ["71644.70", "0.009"], ["71646.70", "0.003"], ["71647.00", "1.382"], ["71799.90", "0.008"], ["71872.50", "0.000"], ["72013.40", "0.008"], ["72056.00", "0.009"], ["89523.20", "0.000"]]}}
