{"local_ts": 1773486511971, "server_ts": 1773486511937, "data": {"e": "depthUpdate", "E": 1773486511939, "T": 1773486511937, "s": "BTCUSDT", "U": 10109509109003, "u": 10109509126635, "pu": 10109509108908, "b": [["5000.00", "101.418"], ["7063.70", "0.000"], ["20136.10", "2.300"], ["20140.00", "0.230"], ["20240.00", "0.220"], ["20536.10", "0.250"], ["56512.00", "0.011"], ["63572.50", "0.000"], ["67104.30", "0.002"], ["69343.50", "0.000"], ["69788.60", "2.878"], ["69929.70", "0.000"], ["70282.90", "0.000"], ["70354.30", "0.004"], ["70358.10", "0.000"], ["70527.30", "0.003"], ["70528.30", "0.017"], ["70530.20", "0.563"], ["70534.00", "12.552"], ["70538.30", "0.000"], ["70588.80", "0.070"], ["70589.20", "0.986"], ["70589.30", "0.009"], ["70590.30", "0.003"], ["70590.40", "0.000"], ["70590.50", "0.000"], ["70590.60", "0.015"], ["70590.70", "0.091"], ["70590.90", "0.057"], ["70591.00", "0.279"], ["70609.00", "0.064"], ["70614.80", "0.184"], ["70622.00", "0.161"], ["70625.80", "0.564"], ["70628.10", "0.007"], ["70628.90", "0.217"], ["70629.60", "0.001"], ["70631.80", "0.238"], ["70632.60", "0.214"], ["70632.80", "0.001"], ["70633.90", "0.002"], ["70634.20", "0.217"], ["70635.60", "0.010"], ["70636.10", "5.572"]], "a": [["70637.50", "0.069"], ["70638.40", "0.000"], ["70639.80", "0.000"], ["70640.20", "0.374"], ["70640.50", "0.004"], ["70641.90", "0.003"], ["70642.20", "0.002"], ["70643.10", "0.004"], ["70643.30", "0.029"], ["70645.20", "0.006"], ["70645.80", "0.010"], ["70646.10", "0.172"], ["70646.20", "0.000"], ["70646.40", "0.464"], ["70646.60", "0.125"], ["70649.60", "0.101"], ["70652.10", "0.350"], ["70654.40", "0.001"], ["70654.90", "0.000"], ["70655.60", "0.002"], ["70656.00", "0.147"], ["70665.30", "0.002"], ["70667.00", "0.016"], ["70667.50", "0.250"], ["70668.00", "0.569"], ["70668.60", "1.153"], ["70675.00", "0.104"], ["70678.60", "0.535"], ["70679.60", "0.000"], ["70679.70", "0.064"], ["70679.80", "0.029"], ["70679.90", "0.004"], ["70680.00", "2.856"], ["70680.30", "0.015"], ["70685.30", "0.014"], ["70693.00", "0.059"], ["70694.10", "0.052"], ["70727.80", "0.256"], ["70742.10", "0.092"], ["70745.90", "0.000"], ["70842.80", "0.002"], ["70885.50", "0.002"], ["71342.60", "0.000"], ["71510.70", "2.092"], ["74168.00", "0.203"], ["74172.30", "0.002"], ["74199.80", "0.009"], ["77699.80", "0.000"]]}}
{"local_ts": 1773486512993, "server_ts": 1773486512958, "data": {"e": "depthUpdate", "E": 1773486512959, "T": 1773486512958, "s": "BTCUSDT", "U": 10109509379888, "u": 10109509391578, "pu": 10109509379860, "b": [["1000.00", "26.142"], ["5000.00", "101.418"], ["7066.00", "0.000"], ["20136.10", "0.520"], ["20459.10", "0.100"], ["20559.10", "0.540"], ["56527.00", "0.000"], ["63593.20", "0.000"], ["63923.20", "0.002"], ["67104.90", "0.000"], ["69345.00", "6.486"], ["69421.30", "1.141"], ["69558.80", "0.000"], ["69592.10", "0.427"], ["69623.90", "0.717"], ["69633.30", "0.856"], ["69668.60", "1.026"], ["69952.50", "0.000"], ["70290.40", "0.074"], ["70488.00", "2.397"], ["70547.80", "3.756"], ["70549.40", "1.677"], ["70554.00", "0.000"], ["70568.90", "0.000"], ["70569.70", "0.000"], ["70571.20", "1.432"], ["70571.90", "0.006"], ["70572.90", "1.642"], ["70573.00", "0.721"], ["70574.80", "1.205"], ["70579.00", "0.009"], ["70584.00", "0.285"], ["70593.60", "0.018"], ["70594.20", "0.799"], ["70595.80", "0.033"], ["70607.40", "0.433"], ["70608.10", "0.003"], ["70608.60", "0.002"], ["70609.10", "0.054"], ["70609.90", "0.048"], ["70610.30", "0.003"], ["70614.20", "0.002"], ["70622.40", "0.824"], ["70622.50", "0.285"], ["70625.50", "0.074"], ["70625.70", "0.738"], ["70627.20", "0.252"], ["70627.80", "1.149"], ["70628.20", "0.079"], ["70630.80", "0.227"], ["70631.10", "0.171"], ["70631.30", "0.005"], ["70631.40", "0.004"], ["70632.00", "0.009"], ["70632.10", "0.524"], ["70632.60", "0.042"], ["70637.70", "0.005"], ["70638.00", "0.002"], ["70639.40", "0.141"], ["70640.40", "0.004"], ["70641.40", "0.000"], ["70641.60", "0.029"], ["70642.40", "0.285"], ["70642.50", "1.571"], ["70642.60", "0.364"], ["70642.80", "0.079"], ["70642.90", "0.292"], ["70643.10", "0.077"], ["70643.20", "0.084"], ["70643.50", "0.025"], ["70643.60", "0.089"], ["70643.90", "0.060"], ["70645.00", "0.010"], ["70645.10", "1.067"], ["70645.30", "0.000"], ["70647.20", "1.004"], ["70647.30", "0.001"], ["70648.20", "0.072"], ["70648.50", "0.000"], ["70649.70", "0.004"], ["70649.80", "0.001"], ["70650.50", "0.344"], ["70650.60", "0.457"], ["70652.00", "0.019"], ["70653.50", "0.326"], ["70653.60", "0.006"], ["70655.30", "0.012"], ["70655.60", "0.004"], ["70656.00", "0.003"], ["70656.50", "0.000"], ["70658.60", "0.006"], ["70658.70", "0.000"], ["70658.90", "0.002"], ["70659.00", "0.673"], ["70659.10", "13.680"]], "a": [["70659.20", "0.235"], ["70661.70", "0.010"], ["70662.80", "0.004"], ["70663.00", "0.338"], ["70663.60", "0.004"], ["70666.00", "0.239"], ["70666.60", "0.093"], ["70667.00", "0.028"], ["70667.40", "0.061"], ["70667.80", "0.063"], ["70668.10", "0.109"], ["70668.50", "0.220"], ["70668.70", "0.006"], ["70669.50", "0.002"], ["70669.60", "0.002"], ["70669.80", "0.006"], ["70671.00", "0.041"], ["70671.20", "0.002"], ["70676.80", "1.074"], ["70677.50", "0.019"], ["70677.70", "0.622"], ["70679.00", "0.156"], ["70679.60", "0.000"], ["70682.60", "0.022"], ["70683.40", "0.007"], ["70684.60", "0.005"], ["70690.90", "0.026"], ["70691.60", "0.003"], ["70694.10", "0.515"], ["70694.50", "0.167"], ["70698.00", "0.060"], ["70698.70", "0.011"], ["70699.20", "2.093"], ["70699.40", "0.003"], ["70701.50", "0.046"], ["70710.60", "0.786"], ["70717.60", "0.003"], ["70721.70", "2.130"], ["70722.00", "4.177"], ["70734.80", "1.800"], ["70736.90", "0.038"], ["70739.00", "0.127"], ["70740.00", "0.562"], ["70741.00", "0.077"], ["70743.70", "0.036"], ["70746.60", "0.002"], ["70747.00", "0.283"], ["70753.20", "1.367"], ["70756.20", "2.927"], ["70759.10", "6.677"], ["70770.20", "0.000"], ["70770.60", "2.896"], ["70770.80", "0.481"], ["70773.60", "0.151"], ["70816.90", "2.387"], ["70820.00", "5.115"], ["70820.20", "12.503"], ["70892.30", "0.003"], ["70918.30", "0.038"], ["70956.00", "0.002"], ["71365.80", "0.486"], ["71662.30", "9.827"], ["71683.80", "0.975"], ["71738.70", "0.834"], ["71754.40", "0.974"], ["71768.20", "1.392"], ["72760.10", "0.000"], ["72920.20", "0.947"], ["72971.60", "2.124"], ["73042.10", "0.000"], ["73132.20", "0.670"], ["73202.90", "0.669"], ["73253.60", "0.002"], ["73324.10", "1.078"], ["73414.90", "0.204"], ["73485.50", "0.136"], ["77725.10", "0.000"], ["89523.20", "0.000"]]}}
{"local_ts": 1773486514011, "server_ts": 1773486513979, "data": {"e": "depthUpdate", "E": 1773486513981, "T": 1773486513979, "s": "BTCUSDT", "U": 10109509486993, "u": 10109509493621, "pu": 10109509486812, "b": [["5000.00", "101.418"], ["7066.70", "0.000"], ["20466.30", "0.480"], ["20536.10", "0.050"], ["20542.10", "0.000"], ["20543.60", "0.010"], ["20543.90", "0.000"], ["20545.00", "0.020"], ["20547.10", "0.000"], ["20549.50", "0.010"], ["20549.90", "0.010"], ["20552.40", "0.010"], ["20555.10", "0.020"], ["20559.00", "0.010"], ["20559.10", "0.000"], ["33000.00", "3.785"], ["63599.70", "0.000"], ["67100.10", "0.002"], ["69215.20", "0.000"], ["69303.20", "0.363"], ["69544.60", "0.000"], ["69551.10", "0.236"], ["69634.50", "7.179"], ["69656.90", "0.860"], ["69740.50", "3.408"], ["69883.20", "0.000"], ["69951.30", "0.002"], ["69953.20", "2.063"], ["69959.60", "0.000"], ["69987.80", "1.414"], ["70368.80", "0.259"], ["70379.90", "0.648"], ["70409.10", "0.000"], ["70451.50", "0.000"], ["70453.60", "0.000"], ["70509.60", "0.000"], ["70512.00", "0.006"], ["70514.00", "0.058"], ["70559.60", "0.383"], ["70563.20", "1.412"], ["70564.40", "0.000"], ["70566.80", "0.376"], ["70570.40", "0.288"], ["70574.40", "0.266"], ["70576.00", "0.002"], ["70588.60", "1.004"], ["70598.60", "0.128"], ["70602.70", "0.088"], ["70604.80", "0.006"], ["70607.10", "0.006"], ["70610.70", "0.060"], ["70611.60", "0.019"], ["70612.20", "0.003"], ["70613.30", "0.002"], ["70614.20", "0.059"], ["70614.30", "0.017"], ["70614.90", "0.595"], ["70616.80", "0.075"], ["70617.80", "0.059"], ["70619.30", "2.105"], ["70621.30", "0.059"], ["70623.10", "1.860"], ["70623.90", "0.087"], ["70627.80", "0.292"], ["70627.90", "0.042"], ["70631.00", "0.567"], ["70631.70", "0.000"], ["70633.40", "0.019"], ["70633.50", "0.061"], ["70634.10", "0.003"], ["70634.20", "0.004"], ["70636.00", "0.038"], ["70636.30", "0.688"], ["70636.90", "0.011"], ["70637.00", "0.324"], ["70637.60", "0.081"], ["70637.70", "0.007"], ["70638.00", "0.199"], ["70638.80", "0.005"], ["70640.20", "0.513"], ["70640.50", "0.413"], ["70640.60", "0.061"], ["70640.90", "0.060"], ["70641.50", "0.000"], ["70641.60", "0.004"], ["70642.00", "0.003"], ["70642.40", "0.001"], ["70642.50", "0.085"], ["70642.90", "0.321"], ["70643.20", "0.005"], ["70643.90", "0.255"], ["70644.00", "2.208"], ["70644.30", "0.000"], ["70644.70", "0.002"], ["70646.00", "0.000"], ["70646.50", "0.027"], ["70647.00", "0.244"], ["70647.20", "0.687"], ["70647.30", "1.082"], ["70647.40", "0.379"], ["70647.60", "0.053"], ["70649.10", "0.520"], ["70649.20", "1.202"], ["70649.60", "0.000"], ["70649.90", "0.966"], ["70650.00", "1.112"], ["70650.20", "0.620"], ["70650.50", "0.341"], ["70650.60", "0.776"], ["70651.20", "0.052"], ["70651.80", "0.006"], ["70651.90", "1.068"], ["70652.00", "0.014"], ["70652.20", "0.473"], ["70652.70", "0.003"], ["70653.80", "0.008"], ["70653.90", "0.123"], ["70654.00", "0.007"], ["70654.20", "0.028"], ["70654.80", "0.000"], ["70655.00", "0.058"], ["70655.40", "0.006"], ["70655.80", "0.009"], ["70656.10", "0.000"], ["70656.20", "0.012"], ["70657.90", "0.009"], ["70658.10", "0.007"], ["70658.40", "0.003"], ["70658.60", "0.004"], ["70658.80", "0.001"], ["70659.00", "0.028"], ["70659.10", "0.017"], ["70659.20", "1.068"], ["70659.30", "0.004"], ["70659.70", "0.005"], ["70659.90", "0.000"], ["70660.00", "0.052"], ["70660.10", "0.000"], ["70660.20", "0.004"], ["70660.30", "0.287"], ["70660.40", "0.007"], ["70660.50", "0.003"], ["70660.90", "0.001"], ["70661.10", "0.003"], ["70661.20", "0.001"], ["70661.50", "0.002"], ["70661.60", "0.020"], ["70661.80", "0.005"], ["70661.90", "0.001"], ["70662.10", "0.021"], ["70662.30", "0.001"], ["70662.40", "0.228"], ["70662.60", "0.005"], ["70663.00", "0.001"], ["70663.30", "0.001"], ["70663.90", "0.025"], ["70664.00", "0.002"], ["70664.20", "0.021"], ["70664.60", "0.006"], ["70664.90", "0.000"], ["70665.80", "0.000"], ["70665.90", "0.000"], ["70666.10", "0.003"], ["70666.20", "0.072"], ["70666.30", "1.994"]], "a": [["70666.40", "3.673"], ["70666.50", "0.003"], ["70666.90", "0.057"], ["70667.00", "0.000"], ["70667.10", "0.000"], ["70667.90", "0.215"], ["70668.50", "0.025"], ["70668.90", "0.007"], ["70670.10", "0.005"], ["70671.30", "0.081"], ["70671.40", "0.483"], ["70671.60", "0.030"], ["70671.80", "0.098"], ["70671.90", "0.423"], ["70672.20", "0.110"], ["70672.80", "0.074"], ["70672.90", "0.001"], ["70673.30", "0.023"], ["70673.40", "0.016"], ["70673.90", "0.001"], ["70674.60", "0.004"], ["70674.70", "0.037"], ["70674.80", "0.116"], ["70675.40", "0.035"], ["70675.60", "0.025"], ["70676.20", "0.000"], ["70676.30", "0.006"], ["70676.40", "0.000"], ["70676.50", "0.164"], ["70676.60", "0.025"], ["70683.70", "0.001"], ["70683.80", "0.002"], ["70685.10", "0.020"], ["70686.50", "0.003"], ["70688.40", "0.005"], ["70689.60", "0.014"], ["70690.90", "0.019"], ["70691.90", "0.092"], ["70692.90", "0.000"], ["70694.70", "0.099"], ["70694.80", "0.002"], ["70697.50", "0.144"], ["70697.80", "0.029"], ["70698.10", "0.002"], ["70698.30", "0.042"], ["70701.60", "0.893"], ["70704.90", "0.029"], ["70707.00", "0.424"], ["70707.60", "0.013"], ["70711.50", "0.035"], ["70712.20", "0.003"], ["70712.90", "0.049"], ["70713.50", "0.020"], ["70713.60", "0.097"], ["70716.50", "0.005"], ["70719.30", "0.092"], ["70721.50", "0.605"], ["70722.70", "0.089"], ["70723.70", "2.116"], ["70727.20", "0.034"], ["70730.00", "0.168"], ["70733.20", "0.127"], ["70734.80", "1.132"], ["70744.20", "0.003"], ["70747.00", "0.000"], ["70752.00", "0.010"], ["70754.20", "0.085"], ["70754.80", "0.000"], ["70763.30", "0.312"], ["70770.60", "2.837"], ["70772.60", "0.117"], ["70772.70", "0.135"], ["70773.30", "0.146"], ["70779.20", "0.336"], ["70780.20", "0.005"], ["70781.80", "0.088"], ["70782.90", "0.094"], ["70784.40", "0.024"], ["70785.80", "0.263"], ["70788.20", "0.179"], ["70789.10", "0.037"], ["70793.10", "0.043"], ["70793.50", "0.128"], ["70793.60", "0.036"], ["70811.20", "0.001"], ["70815.50", "0.003"], ["70834.30", "0.000"], ["70853.90", "0.032"], ["70883.30", "0.002"], ["70911.10", "0.281"], ["70916.00", "0.002"], ["70917.70", "0.000"], ["70983.30", "0.000"], ["71034.50", "4.956"], ["71179.90", "0.008"], ["71237.30", "0.129"], ["71373.10", "0.000"], ["71723.10", "0.000"], ["71724.70", "0.000"], ["71761.70", "7.728"], ["72079.70", "0.074"], ["77733.00", "0.006"], ["89523.20", "0.000"]]}}
{"local_ts": 1773486515037, "server_ts": 1773486514997, "data": {"e": "depthUpdate", "E": 1773486515001, "T": 1773486514997, "s": "BTCUSDT", "U": 10109509549914, "u": 10109509556473, "pu": 10109509549871, "b": [["1000.00", "26.142"], ["5000.00", "101.418"], ["7066.30", "0.000"], ["20362.40", "1.590"], ["20459.10", "1.050"], ["20462.40", "0.270"], ["56530.00", "0.010"], ["63596.20", "0.000"], ["67113.70", "0.000"], ["69215.80", "0.005"], ["69219.40", "0.619"], ["69249.20", "0.005"], ["69294.30", "6.001"], ["69297.80", "1.381"], ["69372.80", "0.029"], ["69376.30", "0.379"], ["69451.30", "0.120"], ["69454.80", "0.552"], ["69529.70", "0.000"], ["69533.30", "0.410"], ["69608.20", "0.000"], ["69611.80", "4.685"], ["69686.70", "0.265"], ["69690.20", "1.799"], ["69765.20", "0.000"], ["69768.70", "0.379"], ["69843.60", "0.002"], ["69847.20", "0.379"], ["69922.10", "0.011"], ["69925.70", "0.379"], ["69955.80", "0.000"], ["70313.00", "0.074"], ["70472.00", "1.830"], ["70565.90", "2.566"], ["70567.50", "0.002"], ["70570.40", "0.282"], ["70570.80", "0.001"], ["70571.40", "0.212"], ["70573.50", "0.043"], ["70573.80", "0.002"], ["70577.10", "0.686"], ["70578.40", "0.931"], ["70580.10", "0.036"], ["70581.90", "0.002"], ["70582.20", "0.042"], ["70583.10", "0.005"], ["70585.10", "0.000"], ["70585.30", "0.356"], ["70586.20", "0.000"], ["70600.80", "0.006"], ["70602.90", "0.036"], ["70606.50", "0.409"], ["70611.80", "0.338"], ["70613.50", "0.050"], ["70614.00", "0.006"], ["70614.10", "0.003"], ["70615.80", "0.370"], ["70618.10", "0.011"], ["70624.30", "0.006"], ["70629.00", "1.065"], ["70635.00", "1.162"], ["70636.30", "0.555"], ["70640.10", "0.351"], ["70643.90", "0.534"], ["70645.00", "0.018"], ["70645.30", "0.057"], ["70645.40", "0.001"], ["70646.20", "0.020"], ["70647.20", "0.013"], ["70647.80", "0.202"], ["70647.90", "0.518"], ["70649.50", "0.113"], ["70650.00", "1.112"], ["70650.60", "0.008"], ["70651.80", "0.010"], ["70652.10", "0.285"], ["70655.40", "0.047"], ["70659.10", "0.082"], ["70659.20", "0.462"], ["70660.00", "0.051"], ["70660.30", "0.166"], ["70661.00", "0.002"], ["70662.30", "0.007"]], "a": [["70662.50", "2.387"], ["70662.60", "0.003"], ["70666.70", "0.080"], ["70669.00", "0.441"], ["70669.10", "0.002"], ["70671.20", "0.146"], ["70673.80", "0.010"], ["70675.50", "0.010"], ["70677.10", "0.000"], ["70678.90", "0.003"], ["70679.20", "0.689"], ["70679.50", "0.001"], ["70680.40", "0.039"], ["70681.10", "0.002"], ["70683.10", "0.003"], ["70683.20", "0.002"], ["70683.90", "0.000"], ["70684.90", "0.003"], ["70686.90", "0.007"], ["70688.00", "1.264"], ["70690.70", "0.002"], ["70691.20", "0.000"], ["70691.40", "0.213"], ["70691.70", "0.638"], ["70692.50", "0.509"], ["70692.70", "0.095"], ["70694.30", "0.156"], ["70695.70", "0.323"], ["70696.50", "0.062"], ["70696.70", "0.004"], ["70697.90", "0.054"], ["70698.10", "0.004"], ["70699.10", "0.249"], ["70699.40", "0.005"], ["70700.10", "0.025"], ["70701.00", "0.030"], ["70701.40", "0.045"], ["70702.50", "0.038"], ["70702.80", "0.029"], ["70703.50", "0.126"], ["70704.90", "0.080"], ["70705.00", "0.005"], ["70706.90", "0.537"], ["70707.00", "0.438"], ["70707.40", "0.007"], ["70708.20", "0.007"], ["70709.30", "0.052"], ["70710.60", "0.013"], ["70712.10", "0.006"], ["70713.20", "0.005"], ["70715.00", "0.271"], ["70716.40", "0.042"], ["70717.00", "0.045"], ["70717.80", "0.202"], ["70718.70", "0.050"], ["70722.20", "0.284"], ["70764.30", "0.126"], ["70913.10", "0.045"], ["71021.20", "0.000"], ["71334.70", "0.000"], ["71338.30", "0.394"], ["71369.10", "0.008"], ["71413.20", "0.000"], ["71416.80", "0.379"], ["71491.60", "1.396"], ["71570.10", "0.979"], ["71648.60", "0.697"], ["71668.20", "0.836"], ["71727.10", "0.000"], ["71738.90", "0.000"], ["71757.80", "1.959"], ["71805.50", "0.017"], ["71828.40", "0.973"], ["71884.00", "0.143"], ["71962.50", "0.004"], ["72041.00", "0.855"], ["74216.30", "0.002"], ["77728.70", "0.000"], ["89523.20", "0.000"]]}}
{"local_ts": 1773486516051, "server_ts": 1773486516020, "data": {"e": "depthUpdate", "E": 1773486516021, "T": 1773486516020, "s": "BTCUSDT", "U": 10109509609470, "u": 10109509618133, "pu": 10109509609313, "b": [["1000.00", "26.142"], ["5000.00", "101.418"], ["7066.30", "0.056"], ["20262.40", "1.240"], ["20362.40", "1.760"], ["33000.00", "3.789"], ["63596.20", "0.000"], ["67835.90", "2.431"], ["68520.80", "0.000"], ["68542.60", "0.008"], ["69223.40", "0.012"], ["69600.00", "15.673"], ["69601.00", "4.663"], ["69637.80", "6.974"], ["69673.10", "4.693"], ["69955.80", "0.000"], ["70627.10", "0.049"], ["70638.80", "0.289"], ["70642.20", "0.000"], ["70644.10", "0.365"], ["70644.40", "0.073"], ["70645.20", "0.000"], ["70651.80", "0.013"], ["70655.30", "0.012"], ["70655.40", "0.012"], ["70660.00", "0.053"]], "a": [["70662.50", "1.959"], ["70666.40", "0.134"], ["70667.00", "0.006"], ["70669.50", "0.002"], ["70673.10", "0.006"], ["70676.60", "0.079"], ["70686.70", "0.085"], ["70686.80", "0.003"], ["70697.80", "0.063"], ["70701.90", "0.032"], ["70726.60", "0.283"], ["70744.40", "0.010"], ["71369.10", "0.008"], ["71514.40", "1.263"], ["72759.10", "0.000"], ["74215.20", "0.006"], ["77728.70", "0.000"], ["89523.20", "0.000"]]}}
{"local_ts": 1773486517073, "server_ts": 1773486517041, "data": {"e": "depthUpdate", "E": 1773486517043, "T": 1773486517041, "s": "BTCUSDT", "U": 10109509671425, "u": 10109509680078, "pu": 10109509671358, "b": [["5000.00", "101.418"], ["7066.30", "0.056"], ["20162.40", "0.790"], ["20262.40", "2.210"], ["67102.80", "0.002"], ["67127.90", "0.000"], ["67835.90", "3.062"], ["68542.60", "0.011"], ["69671.50", "0.010"], ["69743.80", "6.390"], ["69955.80", "0.354"], ["70362.60", "0.000"], ["70413.00", "0.706"], ["70468.10", "0.162"], ["70489.30", "3.597"], ["70489.60", "1.097"], ["70489.80", "0.258"], ["70528.10", "2.106"], ["70609.50", "0.852"], ["70614.20", "0.002"], ["70614.30", "0.017"], ["70616.60", "1.923"], ["70623.70", "0.862"], ["70630.80", "0.854"], ["70631.30", "0.005"], ["70633.40", "0.019"], ["70633.50", "0.061"], ["70634.10", "0.003"], ["70634.20", "0.004"], ["70636.80", "0.000"], ["70638.30", "0.263"], ["70647.50", "0.566"], ["70649.70", "0.007"], ["70651.80", "0.207"], ["70655.30", "0.009"], ["70660.10", "0.003"], ["70662.40", "5.372"]], "a": [["70662.50", "1.084"], ["70672.40", "0.025"], ["70673.10", "0.007"], ["70676.60", "0.082"], ["70680.50", "1.382"], ["70687.20", "0.118"], ["70687.60", "1.149"], ["70694.70", "0.852"], ["70701.80", "0.925"], ["70708.90", "0.862"], ["70716.00", "0.859"], ["70772.20", "0.066"], ["70795.50", "0.280"], ["70815.40", "0.513"], ["70825.50", "0.002"], ["70834.30", "0.634"], ["70886.20", "0.518"], ["71005.80", "0.000"], ["71006.20", "0.007"], ["71369.00", "5.010"], ["71369.10", "0.008"], ["71557.90", "0.000"], ["71749.30", "0.466"], ["72782.30", "0.011"], ["89523.20", "0.000"]]}}
{"local_ts": 1773486518094, "server_ts": 1773486518063, "data": {"e": "depthUpdate", "E": 1773486518065, "T": 1773486518063, "s": "BTCUSDT", "U": 10109509751016, "u": 10109509767983, "pu": 10109509750677, "b": [["1000.00", "26.142"], ["5000.00", "101.418"], ["7066.30", "0.056"], ["20162.40", "2.580"], ["20262.40", "0.040"], ["20562.40", "0.380"], ["56530.00", "0.010"], ["67120.10", "0.002"], ["68519.00", "4.576"], ["68636.10", "0.000"], ["69263.80", "0.618"], ["69433.40", "0.288"], ["69720.40", "0.716"], ["69955.80", "0.354"], ["70309.10", "0.176"], ["70400.00", "12.062"], ["70410.00", "2.608"], ["70610.60", "0.000"], ["70619.30", "0.007"], ["70627.10", "0.052"], ["70635.40", "0.177"], ["70635.90", "0.000"], ["70649.70", "0.003"], ["70651.80", "0.207"], ["70652.10", "0.299"], ["70655.30", "0.009"], ["70657.50", "0.007"], ["70662.40", "5.198"]], "a": [["70669.70", "0.057"], ["70670.10", "0.026"], ["70673.10", "0.007"], ["70675.20", "0.029"], ["70694.30", "0.156"], ["70697.80", "0.059"], ["70913.90", "3.257"], ["71651.70", "0.066"], ["71683.70", "4.089"], ["71711.40", "0.417"], ["89523.20", "0.000"]]}}
{"local_ts": 1773486519116, "server_ts": 1773486519084, "data": {"e": "depthUpdate", "E": 1773486519085, "T": 1773486519084, "s": "BTCUSDT", "U": 10109509856187, "u": 10109509863019, "pu": 10109509856017, "b": [["5000.00", "101.418"], ["7066.40", "0.028"], ["20162.40", "0.310"], ["20463.40", "0.210"], ["20563.40", "1.090"], ["67836.90", "0.002"], ["69667.80", "0.575"], ["69933.50", "3.495"], ["69956.80", "0.043"], ["69956.90", "0.004"], ["70416.90", "0.511"], ["70574.60", "0.000"], ["70577.50", "0.005"], ["70582.60", "0.513"], ["70585.50", "0.005"], ["70590.60", "0.446"], ["70593.40", "0.133"], ["70598.70", "0.000"], ["70601.50", "0.787"], ["70606.50", "0.404"], ["70607.20", "1.125"], ["70609.40", "0.010"], ["70625.30", "0.096"], ["70628.10", "0.003"], ["70650.70", "0.978"], ["70652.80", "0.004"], ["70654.90", "0.003"], ["70660.80", "0.005"]], "a": [["70663.50", "0.840"], ["70672.90", "0.001"], ["70675.70", "0.345"], ["70680.90", "0.002"], ["70683.70", "0.008"], ["70688.80", "0.287"], ["70691.70", "0.009"], ["70691.80", "0.261"], ["70692.60", "1.948"], ["70696.80", "0.060"], ["70698.80", "0.000"], ["70699.70", "0.023"], ["70704.90", "0.075"], ["70707.70", "0.021"], ["70732.30", "0.787"], ["70831.30", "1.025"], ["70835.90", "0.000"], ["71000.00", "86.840"], ["71346.40", "1.810"], ["71370.10", "0.022"], ["73405.90", "0.000"], ["74206.00", "0.068"], ["89523.20", "0.000"]]}}
{"local_ts": 1773486520141, "server_ts": 1773486520106, "data": {"e": "depthUpdate", "E": 1773486520107, "T": 1773486520106, "s": "BTCUSDT", "U": 10109509929458, "u": 10109509939208, "pu": 10109509929427, "b": [["1000.00", "26.142"], ["5000.00", "101.418"], ["7066.40", "0.028"], ["20363.90", "0.030"], ["20364.50", "0.030"], ["20463.90", "1.150"], ["20464.50", "0.050"], ["20562.40", "0.580"], ["20563.40", "0.030"], ["67122.10", "0.000"], ["69249.20", "0.048"], ["69296.90", "0.004"], ["69657.80", "0.002"], ["69658.00", "0.438"], ["69659.90", "0.002"], ["69662.40", "0.020"], ["69664.50", "0.016"], ["69835.60", "1.144"], ["69957.30", "13.137"], ["69957.90", "0.000"], ["70003.30", "0.004"], ["70310.10", "0.000"], ["70394.40", "0.272"], ["70410.10", "0.000"], ["70410.20", "0.004"], ["70469.10", "0.022"], ["70469.60", "0.000"], ["70470.20", "0.338"], ["70473.70", "0.159"], ["70493.10", "0.006"], ["70501.40", "0.511"], ["70502.00", "0.039"], ["70505.50", "0.039"], ["70533.90", "0.010"], ["70550.90", "0.005"], ["70558.20", "0.263"], ["70570.80", "0.000"], ["70576.00", "0.002"], ["70588.40", "1.288"], ["70603.80", "0.004"], ["70604.40", "0.097"], ["70607.40", "0.433"], ["70608.00", "0.004"], ["70610.40", "0.009"], ["70611.50", "0.081"], ["70613.60", "0.878"], ["70613.70", "0.002"], ["70615.00", "8.579"], ["70615.90", "0.511"], ["70616.00", "0.010"], ["70622.70", "0.090"], ["70625.00", "0.037"], ["70625.30", "0.068"], ["70625.70", "0.094"], ["70625.90", "0.810"], ["70628.60", "0.056"], ["70642.40", "0.282"], ["70642.70", "0.006"], ["70646.10", "0.142"], ["70646.60", "0.509"], ["70647.20", "0.360"], ["70647.40", "0.381"], ["70647.70", "0.027"], ["70647.90", "0.062"], ["70648.30", "0.197"], ["70649.10", "0.079"], ["70649.70", "0.003"], ["70650.30", "0.422"], ["70651.10", "0.007"], ["70651.20", "0.045"], ["70652.20", "0.001"], ["70653.30", "0.308"], ["70653.70", "0.511"], ["70653.90", "0.020"], ["70654.10", "0.007"], ["70654.40", "0.000"], ["70656.00", "0.061"], ["70656.30", "0.001"], ["70656.70", "0.526"], ["70656.80", "0.200"], ["70657.00", "0.445"], ["70657.40", "0.005"], ["70657.50", "0.007"], ["70657.90", "0.410"], ["70658.00", "0.003"], ["70658.80", "0.015"], ["70659.30", "0.003"], ["70660.30", "0.002"], ["70660.60", "0.105"], ["70660.80", "0.005"], ["70661.50", "0.002"], ["70662.80", "0.006"], ["70663.00", "0.002"], ["70663.70", "0.000"], ["70663.80", "0.001"], ["70663.90", "0.108"], ["70664.00", "0.002"], ["70664.10", "0.249"], ["70664.40", "0.003"], ["70664.50", "15.878"]], "a": [["70664.00", "0.000"], ["70664.60", "0.194"], ["70664.80", "0.000"], ["70664.90", "0.002"], ["70668.20", "0.000"], ["70668.50", "0.050"], ["70668.60", "0.002"], ["70668.80", "0.000"], ["70671.30", "0.003"], ["70671.60", "0.005"], ["70671.70", "0.004"], ["70671.80", "0.014"], ["70671.90", "0.000"], ["70672.50", "0.003"], ["70672.60", "0.002"], ["70673.00", "0.005"], ["70673.20", "0.059"], ["70674.60", "0.065"], ["70675.20", "0.010"], ["70677.70", "0.029"], ["70678.10", "0.007"], ["70678.20", "0.002"], ["70678.30", "0.093"], ["70679.20", "0.701"], ["70680.20", "0.057"], ["70682.20", "0.079"], ["70683.40", "0.006"], ["70685.20", "0.007"], ["70687.80", "0.216"], ["70688.60", "0.080"], ["70688.70", "0.005"], ["70689.30", "0.104"], ["70690.00", "3.629"], ["70692.60", "1.928"], ["70693.00", "0.023"], ["70695.80", "0.000"], ["70695.90", "0.480"], ["70696.30", "0.280"], ["70696.40", "0.953"], ["70698.00", "0.883"], ["70699.30", "1.094"], ["70700.10", "0.025"], ["70700.40", "0.044"], ["70702.80", "0.004"], ["70702.90", "0.096"], ["70703.00", "0.002"], ["70711.60", "0.028"], ["70724.30", "0.000"], ["70724.80", "0.002"], ["70726.20", "0.251"], ["70726.90", "0.092"], ["70734.60", "0.414"], ["70749.70", "0.036"], ["70751.80", "13.021"], ["70780.80", "0.045"], ["70781.00", "0.121"], ["70789.10", "0.003"], ["70813.70", "0.097"], ["70830.70", "0.060"], ["70915.40", "0.553"], ["71370.10", "0.022"], ["71370.60", "0.000"], ["71371.20", "0.000"], ["71668.00", "0.316"], ["72077.80", "0.003"], ["89523.20", "0.000"]]}}
{"local_ts": 1773486521160, "server_ts": 1773486521128, "data": {"e": "depthUpdate", "E": 1773486521129, "T": 1773486521128, "s": "BTCUSDT", "U": 10109510010762, "u": 10109510016148, "pu": 10109510010623, "b": [["1000.00", "26.142"], ["5000.00", "101.418"], ["7066.70", "0.028"], ["20366.20", "1.840"], ["20463.40", "0.600"], ["20463.90", "0.390"], ["69641.60", "2.128"], ["69959.50", "0.000"], ["70409.90", "0.002"], ["70418.30", "0.000"], ["70614.70", "0.215"], ["70617.90", "0.005"], ["70618.00", "0.840"], ["70653.50", "0.296"], ["70655.60", "0.000"], ["70659.10", "0.079"], ["70662.50", "0.009"]], "a": [["70666.30", "3.033"], ["70671.70", "0.024"], ["70672.80", "0.019"], ["70676.90", "0.003"], ["70678.60", "0.003"], ["70679.00", "0.173"], ["70680.00", "2.737"], ["70680.40", "0.096"], ["70681.50", "0.220"], ["70684.10", "0.385"], ["70693.00", "0.003"], ["70695.00", "0.237"], ["70799.00", "0.461"], ["70890.10", "0.272"], ["70917.80", "0.000"], ["71006.80", "0.007"], ["71373.00", "2.229"], ["71631.40", "0.278"], ["71748.40", "0.417"], ["71963.30", "1.326"], ["73492.90", "0.004"], ["74211.70", "0.002"], ["89523.20", "0.000"]]}}
{"local_ts": 1773486522181, "server_ts": 1773486522148, "data": {"e": "depthUpdate", "E": 1773486522149, "T": 1773486522148, "s": "BTCUSDT", "U": 10109510108811, "u": 10109510115794, "pu": 10109510108770, "b": [["5000.00", "101.438"], ["7066.30", "0.000"], ["20262.40", "1.460"], ["20366.20", "0.730"], ["67094.10", "0.002"], ["67108.00", "0.202"], ["67129.30", "0.008"], ["68872.90", "2.612"], ["69249.20", "0.057"], ["69955.80", "3.208"], ["70500.60", "0.012"], ["70524.40", "0.840"], ["70535.80", "0.000"], ["70537.10", "0.529"], ["70545.20", "0.281"], ["70556.40", "0.752"], ["70563.40", "0.089"], ["70569.40", "0.004"], ["70570.50", "1.247"], ["70576.40", "0.000"], ["70577.90", "0.176"], ["70583.50", "0.200"], ["70586.50", "0.000"], ["70604.30", "0.006"], ["70604.90", "0.002"], ["70605.90", "8.496"], ["70607.60", "0.007"], ["70609.10", "0.056"], ["70609.40", "0.327"], ["70614.00", "0.004"], ["70614.20", "0.004"], ["70619.30", "0.051"], ["70620.70", "0.293"], ["70621.70", "0.020"], ["70624.10", "0.394"], ["70624.40", "0.003"], ["70625.20", "0.001"], ["70627.10", "0.008"], ["70629.90", "0.000"], ["70630.60", "0.490"], ["70631.20", "0.000"], ["70631.30", "0.014"], ["70631.40", "0.099"], ["70631.80", "0.064"], ["70632.00", "0.007"], ["70632.10", "0.000"], ["70632.40", "0.332"], ["70632.50", "0.208"], ["70633.50", "0.004"], ["70633.80", "0.028"], ["70633.90", "0.057"], ["70635.00", "1.671"], ["70635.10", "0.247"], ["70635.30", "0.145"], ["70635.90", "0.243"], ["70636.10", "0.073"], ["70636.70", "0.000"], ["70636.90", "0.003"], ["70637.00", "0.326"], ["70637.60", "0.079"], ["70637.70", "0.139"], ["70638.00", "0.002"], ["70638.10", "0.000"], ["70638.50", "0.059"], ["70638.60", "0.070"], ["70638.70", "0.000"], ["70639.20", "0.007"], ["70640.40", "0.002"], ["70640.50", "1.220"], ["70641.40", "0.052"], ["70641.70", "0.009"], ["70642.50", "0.022"], ["70642.60", "0.143"], ["70642.90", "0.000"], ["70643.00", "0.254"], ["70643.10", "0.012"], ["70643.50", "0.004"], ["70643.70", "0.000"], ["70643.80", "0.008"], ["70643.90", "0.558"], ["70644.50", "0.004"], ["70645.70", "0.637"], ["70645.80", "0.283"], ["70645.90", "0.002"], ["70646.60", "0.000"], ["70646.80", "0.169"], ["70647.50", "0.007"], ["70647.70", "0.538"], ["70648.30", "0.090"], ["70649.20", "0.007"], ["70649.70", "0.003"], ["70650.10", "0.043"], ["70650.20", "0.974"], ["70650.30", "0.002"], ["70650.80", "0.540"], ["70650.90", "0.004"], ["70651.00", "0.009"], ["70651.10", "1.073"], ["70651.80", "0.144"], ["70652.40", "0.001"], ["70653.00", "0.004"], ["70653.30", "0.007"], ["70653.60", "0.025"], ["70655.30", "0.009"], ["70655.40", "0.014"], ["70656.10", "0.112"], ["70659.10", "0.075"], ["70660.00", "0.050"]], "a": [["70662.50", "12.101"], ["70662.90", "0.244"], ["70663.90", "0.003"], ["70664.40", "0.004"], ["70665.90", "0.195"], ["70666.00", "0.134"], ["70666.30", "0.127"], ["70667.40", "0.001"], ["70668.00", "0.023"], ["70669.40", "0.037"], ["70669.50", "0.007"], ["70671.60", "0.346"], ["70671.90", "0.000"], ["70672.80", "0.017"], ["70673.20", "0.006"], ["70673.30", "0.210"], ["70673.80", "0.032"], ["70678.50", "0.412"], ["70679.30", "0.006"], ["70681.10", "0.000"], ["70681.40", "0.000"], ["70681.90", "0.509"], ["70682.10", "0.638"], ["70682.30", "0.000"], ["70683.30", "0.009"], ["70684.40", "0.003"], ["70684.80", "0.000"], ["70685.40", "0.016"], ["70686.80", "0.000"], ["70686.90", "0.077"], ["70687.10", "0.106"], ["70687.20", "0.161"], ["70688.70", "0.005"], ["70689.30", "0.022"], ["70690.20", "0.002"], ["70690.30", "0.005"], ["70690.40", "0.047"], ["70690.90", "0.017"], ["70691.00", "0.000"], ["70691.70", "0.254"], ["70693.50", "0.006"], ["70693.80", "0.004"], ["70697.80", "0.273"], ["70702.70", "7.807"], ["70711.90", "0.006"], ["70712.20", "0.014"], ["70747.30", "0.323"], ["70780.40", "0.182"], ["70828.60", "0.101"], ["70962.70", "0.136"], ["71369.10", "0.008"], ["72075.70", "0.018"], ["74224.90", "0.000"], ["89523.20", "0.000"]]}}
{"local_ts": 1773486523199, "server_ts": 1773486523168, "data": {"e": "depthUpdate", "E": 1773486523169, "T": 1773486523168, "s": "BTCUSDT", "U": 10109510172669, "u": 10109510178696, "pu": 10109510172622, "b": [["1000.00", "26.142"], ["5000.00", "101.438"], ["7065.80", "0.000"], ["20157.80", "0.980"], ["20262.40", "1.390"], ["33000.00", "3.785"], ["67124.00", "0.000"], ["69509.70", "1.622"], ["69633.50", "1.015"], ["69951.20", "0.000"], ["70309.10", "0.070"], ["70425.10", "0.000"], ["70594.20", "0.088"], ["70607.60", "0.007"], ["70607.70", "0.000"], ["70607.90", "0.085"], ["70609.50", "0.406"], ["70616.60", "1.068"], ["70623.70", "0.016"], ["70624.80", "0.220"], ["70630.80", "0.002"], ["70631.60", "0.279"], ["70637.80", "0.037"], ["70637.90", "0.514"], ["70640.00", "1.250"], ["70644.50", "0.150"], ["70646.20", "0.042"], ["70649.10", "0.002"], ["70650.80", "0.046"], ["70650.90", "1.076"], ["70652.30", "0.216"], ["70656.50", "0.008"], ["70656.60", "0.000"], ["70657.70", "0.085"], ["70657.80", "2.409"]], "a": [["70657.90", "4.013"], ["70658.90", "0.000"], ["70662.50", "0.078"], ["70664.30", "0.000"], ["70664.90", "0.074"], ["70665.90", "0.195"], ["70666.00", "0.771"], ["70666.20", "0.094"], ["70667.60", "0.003"], ["70669.30", "0.028"], ["70678.50", "0.012"], ["70680.50", "0.515"], ["70683.60", "0.000"], ["70687.10", "0.036"], ["70687.40", "0.009"], ["70687.50", "0.018"], ["70687.60", "0.002"], ["70688.00", "1.334"], ["70688.10", "0.003"], ["70688.20", "0.007"], ["70690.40", "0.047"], ["70691.10", "0.000"], ["70691.70", "0.256"], ["70693.20", "0.002"], ["70694.70", "0.000"], ["70695.90", "0.463"], ["70696.90", "0.008"], ["70697.00", "0.004"], ["70697.10", "0.085"], ["70701.80", "0.008"], ["70708.90", "0.010"], ["70717.30", "0.000"], ["70723.00", "0.216"], ["71364.50", "0.004"], ["71580.40", "0.019"], ["72071.00", "0.022"], ["72777.60", "0.000"], ["73484.20", "0.004"], ["74216.90", "0.002"]]}}
{"local_ts": 1773486524220, "server_ts": 1773486524188, "data": {"e": "depthUpdate", "E": 1773486524191, "T": 1773486524188, "s": "BTCUSDT", "U": 10109510246769, "u": 10109510250616, "pu": 10109510246732, "b": [["5000.00", "101.418"], ["7065.60", "0.000"], ["20155.90", "1.440"], ["20157.80", "0.820"], ["20257.80", "0.000"], ["20555.90", "0.660"], ["67092.10", "0.002"], ["67129.00", "0.000"], ["67129.40", "0.000"], ["69608.00", "0.043"], ["69949.30", "0.007"], ["70411.40", "0.000"], ["70592.30", "0.120"], ["70607.50", "0.078"], ["70607.60", "0.007"], ["70609.30", "0.112"], ["70609.40", "0.305"], ["70609.50", "0.052"], ["70616.60", "1.068"], ["70618.70", "0.184"], ["70620.60", "0.029"], ["70621.90", "0.106"], ["70623.70", "0.072"], ["70629.90", "0.000"], ["70630.80", "0.002"], ["70631.20", "0.164"], ["70631.90", "0.000"], ["70632.90", "0.142"], ["70637.90", "0.514"], ["70638.20", "0.007"], ["70641.20", "0.003"], ["70644.50", "0.150"], ["70644.70", "0.004"], ["70645.00", "0.016"], ["70645.30", "0.000"], ["70645.50", "0.062"], ["70646.00", "0.003"], ["70647.70", "0.102"], ["70648.80", "0.140"], ["70648.90", "0.000"], ["70649.60", "0.023"], ["70650.10", "0.022"], ["70652.10", "0.302"], ["70653.60", "0.004"], ["70654.20", "0.007"], ["70654.30", "0.003"], ["70655.10", "0.002"], ["70655.80", "0.005"], ["70655.90", "2.222"]], "a": [["70656.00", "6.252"], ["70656.10", "0.001"], ["70657.30", "0.138"], ["70657.50", "0.003"], ["70657.80", "0.003"], ["70657.90", "0.069"], ["70660.50", "0.002"], ["70663.00", "0.003"], ["70663.80", "0.004"], ["70665.80", "0.028"], ["70666.60", "0.092"], ["70673.40", "0.011"], ["70680.50", "0.515"], ["70682.40", "0.010"], ["70683.90", "0.509"], ["70685.80", "0.000"], ["70686.80", "0.140"], ["70687.60", "0.002"], ["70691.30", "0.104"], ["70694.70", "0.000"], ["70701.80", "0.008"], ["70708.80", "0.000"], ["70710.10", "0.004"], ["70880.10", "0.007"], ["70881.20", "0.000"], ["70918.00", "0.289"], ["71018.70", "0.002"], ["71362.60", "0.002"], ["74215.20", "0.006"], ["74215.80", "0.000"]]}}
{"local_ts": 1773486525243, "server_ts": 1773486525208, "data": {"e": "depthUpdate", "E": 1773486525213, "T": 1773486525208, "s": "BTCUSDT", "U": 10109510349587, "u": 10109510358914, "pu": 10109510349470, "b": [["1000.00", "26.142"], ["5000.00", "101.418"], ["7064.70", "0.056"], ["20155.90", "0.100"], ["20446.80", "0.300"], ["20546.80", "0.600"], ["20555.90", "1.750"], ["33000.00", "3.789"], ["56518.00", "0.000"], ["67105.70", "0.002"], ["68000.00", "181.492"], ["69419.50", "0.004"], ["69940.30", "0.000"], ["70302.60", "0.000"], ["70400.00", "11.956"], ["70411.40", "0.004"], ["70518.00", "0.005"], ["70535.30", "0.076"], ["70550.20", "0.163"], ["70550.90", "0.064"], ["70553.00", "0.144"], ["70555.20", "0.122"], ["70559.00", "0.227"], ["70562.20", "0.071"], ["70563.50", "0.948"], ["70566.00", "1.428"], ["70569.30", "0.074"], ["70573.10", "0.002"], ["70574.10", "0.000"], ["70574.30", "0.006"], ["70581.90", "0.289"], ["70582.80", "3.625"], ["70583.10", "0.004"], ["70595.00", "0.004"], ["70598.20", "0.005"], ["70598.90", "0.018"], ["70599.60", "0.035"], ["70600.10", "0.043"], ["70600.30", "0.152"], ["70607.90", "0.572"], ["70611.50", "0.778"], ["70614.00", "0.008"], ["70619.80", "0.004"], ["70619.90", "0.149"], ["70620.30", "0.002"], ["70622.50", "0.274"], ["70624.00", "1.251"], ["70625.60", "0.003"], ["70639.20", "0.006"], ["70639.80", "0.002"], ["70642.50", "0.006"], ["70643.20", "0.015"], ["70643.50", "0.003"], ["70644.00", "0.020"], ["70644.20", "0.011"], ["70646.70", "0.002"], ["70646.80", "1.205"]], "a": [["70646.90", "7.173"], ["70647.00", "0.001"], ["70648.00", "0.044"], ["70651.30", "0.008"], ["70651.80", "0.055"], ["70653.90", "0.001"], ["70656.00", "0.094"], ["70656.90", "0.028"], ["70657.60", "0.029"], ["70658.70", "0.073"], ["70660.50", "0.038"], ["70663.40", "0.006"], ["70673.40", "0.008"], ["70682.20", "0.004"], ["70691.70", "0.009"], ["70719.70", "0.362"], ["70732.10", "0.147"], ["70734.80", "1.732"], ["70736.10", "0.002"], ["70739.20", "0.545"], ["70743.20", "0.252"], ["70746.20", "0.157"], ["70750.20", "0.043"], ["70890.00", "0.209"], ["71353.40", "0.000"], ["71742.80", "0.417"], ["72077.80", "0.003"], ["75721.60", "0.002"]]}}
{"local_ts": 1773486526265, "server_ts": 1773486526232, "data": {"e": "depthUpdate", "E": 1773486526233, "T": 1773486526232, "s": "BTCUSDT", "U": 10109510455879, "u": 10109510460940, "pu": 10109510455853, "b": [["1000.00", "26.142"], ["5000.00", "101.418"], ["7064.40", "0.056"], ["20343.90", "0.160"], ["20443.90", "1.780"], ["20446.80", "0.630"], ["20546.80", "0.390"], ["67111.70", "0.005"], ["69667.80", "0.003"], ["69937.50", "0.009"], ["70464.60", "0.000"], ["70474.30", "0.006"], ["70511.10", "0.000"], ["70515.30", "0.009"], ["70516.00", "0.376"], ["70597.20", "0.006"], ["70597.40", "0.281"], ["70608.00", "0.072"], ["70615.70", "0.079"], ["70616.70", "0.305"], ["70625.20", "0.268"], ["70627.30", "0.002"], ["70629.20", "0.127"], ["70629.30", "0.511"], ["70629.40", "0.650"], ["70629.60", "0.980"], ["70629.80", "0.199"], ["70630.10", "0.005"], ["70630.60", "0.006"], ["70631.00", "0.004"], ["70631.10", "0.004"], ["70632.50", "0.479"], ["70634.10", "0.005"], ["70634.80", "0.073"], ["70636.30", "0.017"], ["70636.40", "0.851"], ["70636.60", "0.273"], ["70637.00", "0.471"], ["70637.50", "0.000"], ["70638.20", "0.003"], ["70638.60", "0.008"], ["70639.70", "0.001"], ["70640.00", "0.447"], ["70641.50", "0.287"], ["70643.80", "0.024"]], "a": [["70644.00", "3.371"], ["70646.40", "0.002"], ["70646.90", "0.013"], ["70647.90", "0.000"], ["70649.90", "0.002"], ["70653.60", "0.005"], ["70658.70", "0.224"], ["70661.50", "0.004"], ["70665.90", "0.446"], ["70667.30", "0.094"], ["70668.20", "0.021"], ["70668.30", "0.078"], ["70668.50", "1.075"], ["70670.40", "0.010"], ["70672.10", "0.000"], ["70672.60", "0.508"], ["70672.70", "1.264"], ["70675.60", "0.514"], ["70675.70", "0.588"], ["70676.10", "0.072"], ["70676.40", "0.893"], ["70679.40", "0.101"], ["70679.80", "0.003"], ["70680.40", "0.343"], ["70682.90", "0.002"], ["70683.30", "1.934"], ["70684.00", "0.003"], ["70689.60", "0.005"], ["70693.20", "1.934"], ["70710.50", "0.717"], ["70712.80", "0.221"], ["70714.30", "1.738"], ["70714.80", "0.003"], ["70737.60", "0.315"], ["70757.10", "0.007"], ["70779.40", "0.085"], ["70867.70", "19.388"], ["70945.60", "0.000"], ["71350.40", "0.180"], ["74210.40", "0.002"], ["75280.80", "0.002"]]}}
{"local_ts": 1773486527288, "server_ts": 1773486527252, "data": {"e": "depthUpdate", "E": 1773486527253, "T": 1773486527252, "s": "BTCUSDT", "U": 10109510528564, "u": 10109510543288, "pu": 10109510528534, "b": [["5000.00", "101.418"], ["7065.10", "0.056"], ["20248.90", "0.010"], ["20343.90", "2.140"], ["20347.90", "0.010"], ["20348.90", "0.090"], ["20351.00", "0.030"], ["20351.50", "0.000"], ["20353.50", "0.010"], ["20354.50", "0.010"], ["20443.90", "0.700"], ["69249.20", "0.045"], ["69937.50", "0.009"], ["69942.40", "0.000"], ["69942.50", "0.008"], ["69944.50", "0.002"], ["69946.40", "0.000"], ["69946.50", "0.000"], ["69947.60", "0.016"], ["69948.00", "0.000"], ["69948.10", "0.000"], ["69948.30", "0.000"], ["70168.00", "0.480"], ["70218.60", "0.000"], ["70254.20", "0.002"], ["70258.30", "0.004"], ["70294.40", "0.000"], ["70306.40", "0.114"], ["70311.90", "0.000"], ["70312.70", "0.106"], ["70324.10", "0.000"], ["70345.80", "0.004"], ["70397.60", "0.000"], ["70447.90", "0.000"], ["70451.00", "6.711"], ["70461.60", "32.605"], ["70462.40", "0.002"], ["70462.70", "0.670"], ["70463.00", "0.060"], ["70463.10", "0.376"], ["70463.20", "0.060"], ["70463.70", "0.161"], ["70463.80", "0.191"], ["70463.90", "0.062"], ["70464.10", "0.060"], ["70464.60", "0.159"], ["70467.40", "0.003"], ["70470.20", "0.002"], ["70495.80", "0.087"], ["70496.50", "0.096"], ["70507.50", "0.088"], ["70509.80", "0.041"], ["70512.60", "0.017"], ["70517.20", "0.005"], ["70519.20", "0.002"], ["70521.30", "0.002"], ["70523.40", "0.002"], ["70524.10", "0.004"], ["70525.50", "0.002"], ["70533.90", "0.012"], ["70543.70", "0.019"], ["70545.10", "0.000"], ["70546.80", "0.358"], ["70548.80", "0.365"], ["70550.90", "0.081"], ["70552.10", "1.068"], ["70552.40", "0.796"], ["70555.60", "0.445"], ["70556.20", "0.044"], ["70557.90", "0.872"], ["70558.40", "0.041"], ["70558.70", "1.809"], ["70560.30", "0.129"], ["70560.60", "0.086"], ["70561.90", "0.056"], ["70562.80", "0.094"], ["70565.00", "0.074"], ["70569.10", "0.496"], ["70570.60", "0.002"], ["70571.10", "0.000"], ["70571.70", "0.000"], ["70574.40", "0.208"], ["70574.90", "0.050"], ["70577.40", "0.000"], ["70577.70", "0.344"], ["70579.60", "0.050"], ["70580.10", "0.019"], ["70580.20", "0.114"], ["70583.20", "0.556"], ["70583.90", "0.000"], ["70584.50", "0.004"], ["70584.80", "0.285"], ["70585.10", "0.000"], ["70585.30", "0.354"], ["70585.60", "0.921"], ["70585.70", "0.003"], ["70586.10", "0.084"], ["70586.40", "0.112"], ["70586.70", "0.083"], ["70586.80", "0.081"], ["70587.20", "0.676"], ["70587.40", "0.368"], ["70587.50", "0.081"], ["70591.90", "0.000"], ["70592.30", "0.042"], ["70594.30", "0.003"], ["70594.40", "0.595"], ["70595.00", "0.002"], ["70596.30", "0.006"], ["70597.00", "0.000"], ["70597.90", "8.500"], ["70598.00", "1.814"], ["70598.20", "0.002"], ["70598.30", "0.006"], ["70598.70", "0.005"], ["70598.90", "0.017"], ["70599.00", "0.054"], ["70599.10", "0.201"], ["70599.60", "0.016"], ["70600.20", "0.007"], ["70601.20", "0.004"], ["70601.60", "0.123"], ["70601.70", "0.231"], ["70602.30", "0.006"], ["70602.40", "0.005"], ["70603.30", "1.899"], ["70603.90", "0.072"], ["70604.00", "0.363"], ["70604.10", "0.360"], ["70604.50", "0.200"], ["70605.00", "0.002"], ["70605.20", "0.357"], ["70605.80", "0.038"], ["70605.90", "0.003"], ["70606.00", "0.024"], ["70606.60", "0.949"], ["70607.30", "0.515"], ["70607.60", "0.325"], ["70607.80", "0.071"], ["70608.00", "0.004"], ["70608.40", "0.003"], ["70608.60", "0.442"], ["70608.90", "0.000"], ["70609.60", "0.007"], ["70609.70", "0.006"], ["70610.00", "1.005"], ["70610.30", "0.003"], ["70610.60", "0.003"], ["70610.90", "0.515"], ["70611.30", "0.009"], ["70611.50", "0.778"], ["70611.70", "0.002"], ["70612.20", "0.061"], ["70612.70", "0.003"], ["70612.80", "0.007"], ["70612.90", "0.180"], ["70613.00", "0.173"], ["70613.20", "0.000"], ["70613.30", "0.002"], ["70614.10", "0.048"], ["70614.20", "0.028"], ["70615.00", "0.081"], ["70615.10", "0.004"], ["70615.20", "0.056"], ["70615.40", "0.349"], ["70615.50", "0.042"], ["70615.70", "0.056"], ["70616.20", "0.018"], ["70617.00", "0.000"], ["70617.20", "0.279"], ["70617.60", "0.082"], ["70617.90", "0.003"], ["70618.00", "0.840"], ["70618.90", "0.059"], ["70619.00", "0.072"], ["70619.40", "1.070"], ["70619.50", "0.613"], ["70619.80", "0.572"], ["70619.90", "0.119"], ["70620.40", "0.017"], ["70620.50", "0.004"], ["70620.90", "0.003"], ["70621.00", "0.354"], ["70621.20", "0.004"], ["70621.60", "0.844"], ["70621.90", "0.019"], ["70622.10", "0.466"], ["70622.40", "0.057"], ["70622.70", "0.000"], ["70622.80", "0.004"], ["70622.90", "0.000"], ["70623.00", "0.036"], ["70623.30", "0.010"], ["70623.60", "0.003"], ["70623.80", "0.000"], ["70624.00", "0.013"], ["70624.20", "0.000"], ["70624.50", "0.003"], ["70624.60", "0.000"], ["70624.70", "0.000"], ["70624.90", "0.588"], ["70625.20", "0.248"], ["70625.60", "0.001"], ["70625.90", "0.219"], ["70626.20", "0.022"], ["70626.50", "0.517"], ["70626.60", "0.007"], ["70626.70", "0.401"], ["70626.80", "0.021"], ["70626.90", "0.003"], ["70627.10", "0.012"], ["70627.20", "0.141"], ["70627.50", "0.004"], ["70627.60", "0.002"], ["70627.70", "0.002"], ["70627.80", "0.084"], ["70628.00", "0.028"], ["70628.10", "0.253"], ["70628.20", "0.315"], ["70628.30", "0.002"], ["70628.40", "0.098"], ["70628.50", "0.002"], ["70628.90", "0.217"], ["70629.00", "1.492"], ["70629.20", "0.000"], ["70629.40", "0.022"], ["70629.50", "2.790"], ["70629.60", "0.980"], ["70629.70", "0.349"], ["70629.80", "0.246"], ["70629.90", "0.002"], ["70630.00", "0.565"], ["70630.10", "0.005"], ["70630.30", "0.000"], ["70630.40", "0.002"], ["70630.70", "0.029"], ["70630.90", "0.429"], ["70631.00", "0.002"], ["70631.10", "0.040"], ["70631.40", "0.029"], ["70631.50", "0.241"], ["70631.60", "0.016"], ["70631.80", "0.522"], ["70632.00", "0.073"], ["70632.10", "0.169"], ["70632.20", "0.009"], ["70632.30", "0.002"], ["70632.40", "0.077"], ["70632.60", "0.014"], ["70632.70", "0.018"], ["70632.80", "0.009"], ["70632.90", "0.581"], ["70633.00", "0.305"], ["70633.10", "0.006"], ["70633.20", "0.002"], ["70633.30", "0.061"], ["70633.40", "0.007"], ["70633.50", "0.118"], ["70633.60", "0.024"], ["70633.70", "0.001"], ["70633.80", "0.007"], ["70634.00", "0.512"], ["70634.10", "0.429"], ["70634.20", "0.031"], ["70634.50", "0.425"], ["70634.60", "0.000"], ["70634.70", "0.015"], ["70634.80", "0.487"], ["70634.90", "0.375"], ["70635.00", "0.026"], ["70635.10", "0.048"], ["70635.20", "0.081"], ["70635.40", "0.009"], ["70635.50", "0.140"], ["70635.60", "0.120"], ["70635.70", "0.002"], ["70636.00", "0.004"], ["70636.30", "0.013"], ["70636.50", "0.174"], ["70636.60", "0.541"], ["70636.70", "0.208"], ["70636.80", "0.007"], ["70636.90", "0.640"], ["70637.00", "0.432"], ["70637.10", "0.165"], ["70637.20", "0.008"], ["70637.30", "0.000"], ["70637.40", "0.460"], ["70637.50", "1.577"], ["70637.60", "0.542"], ["70637.70", "0.011"], ["70637.80", "0.135"], ["70637.90", "0.007"], ["70638.00", "0.002"], ["70638.20", "0.000"], ["70638.30", "0.008"], ["70638.50", "0.003"], ["70638.60", "0.008"], ["70638.70", "0.000"], ["70638.80", "0.003"], ["70638.90", "0.004"], ["70639.00", "0.003"], ["70639.10", "0.078"], ["70639.20", "0.006"], ["70639.30", "0.000"], ["70639.40", "0.001"], ["70639.50", "0.000"], ["70639.90", "0.251"], ["70640.00", "0.007"], ["70640.10", "0.565"], ["70640.20", "0.003"], ["70640.30", "0.211"], ["70640.40", "0.004"], ["70640.50", "0.149"], ["70640.60", "0.518"], ["70640.80", "0.000"], ["70641.00", "0.002"], ["70641.10", "0.002"], ["70641.20", "0.004"], ["70641.30", "0.214"], ["70641.40", "0.010"], ["70641.50", "0.003"], ["70641.60", "0.000"], ["70641.70", "0.026"], ["70641.80", "0.004"], ["70641.90", "0.006"], ["70642.10", "0.011"], ["70642.20", "0.010"], ["70642.30", "0.212"], ["70642.40", "0.006"], ["70642.60", "0.002"], ["70643.00", "0.272"], ["70643.10", "0.002"], ["70643.20", "0.288"], ["70643.30", "0.021"], ["70643.70", "0.000"], ["70643.80", "0.003"], ["70643.90", "0.661"], ["70644.00", "0.487"], ["70644.10", "0.000"], ["70644.20", "0.002"], ["70644.30", "0.021"], ["70644.50", "0.000"], ["70644.60", "0.000"], ["70644.70", "0.029"], ["70644.80", "0.000"], ["70644.90", "0.000"], ["70645.00", "0.010"], ["70645.30", "0.000"], ["70645.40", "0.000"], ["70645.50", "0.002"], ["70645.70", "0.000"], ["70645.80", "0.075"], ["70645.90", "0.000"], ["70646.00", "0.000"], ["70646.10", "0.000"], ["70646.30", "0.000"], ["70646.40", "0.002"], ["70646.50", "0.003"], ["70646.70", "0.000"], ["70646.80", "0.000"], ["70646.90", "0.002"], ["70647.00", "0.000"], ["70647.10", "0.003"], ["70647.20", "0.000"], ["70647.30", "0.000"], ["70647.40", "0.000"], ["70647.50", "0.004"], ["70647.60", "0.000"], ["70647.90", "0.000"], ["70648.00", "0.000"], ["70648.10", "0.003"], ["70648.20", "0.002"], ["70648.30", "0.000"], ["70648.50", "0.002"], ["70648.60", "0.002"], ["70648.70", "0.000"], ["70648.80", "0.000"], ["70648.90", "3.046"], ["70649.00", "0.000"], ["70649.10", "0.000"], ["70649.20", "0.000"], ["70649.30", "0.000"], ["70649.40", "0.000"], ["70649.50", "0.000"], ["70649.90", "0.000"], ["70650.00", "0.000"], ["70650.10", "0.000"], ["70650.20", "0.000"], ["70650.40", "0.000"], ["70650.60", "0.000"], ["70650.70", "0.000"], ["70650.80", "0.000"], ["70650.90", "0.000"], ["70651.00", "0.000"], ["70651.10", "0.000"], ["70651.30", "0.000"], ["70651.50", "0.000"], ["70651.60", "0.000"], ["70651.70", "0.000"], ["70651.80", "0.000"], ["70652.10", "0.000"], ["70652.40", "0.000"], ["70653.00", "0.000"], ["70653.50", "0.000"], ["70654.50", "0.000"]], "a": [["70644.00", "0.000"], ["70644.10", "0.000"], ["70644.60", "0.000"], ["70644.70", "0.000"], ["70644.80", "0.000"], ["70644.90", "0.000"], ["70645.00", "0.000"], ["70645.40", "0.000"], ["70645.50", "0.000"], ["70645.60", "0.000"], ["70645.80", "0.000"], ["70646.10", "0.000"], ["70646.50", "0.000"], ["70646.90", "0.000"], ["70647.00", "0.000"], ["70647.30", "0.000"], ["70647.40", "0.000"], ["70647.50", "0.000"], ["70647.70", "0.000"], ["70647.80", "0.000"], ["70648.00", "0.000"], ["70648.10", "0.000"], ["70648.20", "0.000"], ["70648.30", "0.000"], ["70648.40", "0.000"], ["70648.60", "0.000"], ["70648.70", "0.000"], ["70648.90", "0.000"], ["70649.00", "4.462"], ["70649.10", "0.133"], ["70649.20", "0.000"], ["70649.30", "0.000"], ["70649.40", "0.000"], ["70649.50", "0.002"], ["70649.60", "0.021"], ["70649.70", "0.000"], ["70649.80", "0.000"], ["70649.90", "0.000"], ["70650.00", "0.002"], ["70650.10", "0.000"], ["70650.20", "0.000"], ["70650.30", "0.000"], ["70650.40", "0.000"], ["70650.50", "0.002"], ["70650.70", "0.000"], ["70650.80", "0.026"], ["70650.90", "0.000"], ["70651.00", "0.044"], ["70651.10", "0.059"], ["70651.20", "0.000"], ["70651.30", "0.000"], ["70651.40", "0.003"], ["70651.50", "0.000"], ["70651.60", "0.003"], ["70651.70", "0.000"], ["70651.80", "0.000"], ["70651.90", "0.000"], ["70652.00", "0.000"], ["70652.10", "0.000"], ["70652.20", "0.000"], ["70652.30", "0.000"], ["70652.40", "0.000"], ["70652.50", "0.000"], ["70652.60", "0.002"], ["70652.70", "0.000"], ["70652.80", "0.000"], ["70652.90", "0.000"], ["70653.00", "0.002"], ["70653.10", "0.005"], ["70653.20", "0.000"], ["70653.30", "0.021"], ["70653.40", "0.000"], ["70653.50", "0.638"], ["70653.60", "0.350"], ["70653.70", "0.000"], ["70653.80", "0.000"], ["70653.90", "0.000"], ["70654.00", "0.000"], ["70654.10", "0.003"], ["70654.20", "0.002"], ["70654.30", "0.000"], ["70654.40", "0.000"], ["70654.50", "0.293"], ["70654.60", "0.271"], ["70654.70", "0.003"], ["70654.80", "0.077"], ["70654.90", "0.024"], ["70655.00", "0.004"], ["70655.20", "0.002"], ["70655.30", "0.000"], ["70655.40", "0.023"], ["70655.50", "0.000"], ["70655.60", "0.002"], ["70655.70", "0.175"], ["70655.80", "0.004"], ["70656.00", "0.041"], ["70656.20", "0.000"], ["70656.30", "0.005"], ["70657.00", "0.009"], ["70657.10", "0.000"], ["70657.50", "0.005"], ["70657.60", "0.575"], ["70657.70", "0.004"], ["70657.80", "0.003"], ["70657.90", "0.590"], ["70658.00", "0.287"], ["70658.20", "0.000"], ["70658.30", "0.165"], ["70658.50", "0.000"], ["70658.60", "0.510"], ["70658.80", "0.002"], ["70659.00", "0.004"], ["70659.10", "0.005"], ["70659.50", "0.020"], ["70659.60", "0.007"], ["70659.70", "0.511"], ["70659.80", "0.456"], ["70659.90", "0.000"], ["70660.00", "0.053"], ["70660.20", "0.023"], ["70660.30", "0.030"], ["70660.50", "0.040"], ["70660.70", "0.002"], ["70660.80", "0.009"], ["70660.90", "0.021"], ["70661.00", "0.008"], ["70661.10", "0.001"], ["70661.20", "0.108"], ["70661.40", "0.514"], ["70661.50", "0.191"], ["70661.60", "0.008"], ["70661.70", "0.000"], ["70661.80", "0.010"], ["70661.90", "0.014"], ["70662.00", "0.003"], ["70662.10", "0.016"], ["70662.20", "0.007"], ["70662.30", "0.000"], ["70662.40", "0.027"], ["70662.50", "0.059"], ["70662.60", "0.007"], ["70662.70", "0.000"], ["70662.80", "0.011"], ["70662.90", "0.023"], ["70663.10", "0.060"], ["70663.20", "0.000"], ["70663.30", "0.159"], ["70663.40", "0.000"], ["70663.60", "0.000"], ["70663.70", "0.000"], ["70663.80", "0.516"], ["70663.90", "0.021"], ["70664.00", "0.007"], ["70664.10", "0.000"], ["70664.30", "0.000"], ["70664.40", "0.004"], ["70664.50", "0.208"], ["70664.60", "0.003"], ["70664.70", "0.017"], ["70664.80", "0.033"], ["70665.00", "0.019"], ["70665.20", "0.002"], ["70665.30", "0.003"], ["70665.40", "0.007"], ["70665.50", "0.059"], ["70665.60", "0.454"], ["70665.70", "0.455"], ["70665.90", "0.022"], ["70666.00", "0.642"], ["70666.10", "0.005"], ["70666.20", "0.091"], ["70666.30", "0.038"], ["70666.40", "0.106"], ["70666.50", "0.006"], ["70666.60", "0.092"], ["70666.70", "0.014"], ["70667.00", "0.006"], ["70667.20", "0.003"], ["70667.30", "0.014"], ["70668.00", "0.026"], ["70668.10", "1.066"], ["70668.20", "0.511"], ["70668.30", "0.007"], ["70668.40", "0.003"], ["70668.70", "0.003"], ["70668.80", "0.018"], ["70669.00", "0.036"], ["70669.40", "0.250"], ["70669.50", "0.002"], ["70669.60", "0.674"], ["70669.70", "0.349"], ["70670.10", "0.004"], ["70670.20", "0.023"], ["70670.40", "0.002"], ["70670.60", "0.005"], ["70670.90", "0.000"], ["70671.20", "0.059"], ["70671.40", "0.975"], ["70671.50", "0.501"], ["70671.60", "0.012"], ["70671.70", "0.004"], ["70671.80", "0.000"], ["70671.90", "0.594"], ["70672.00", "1.176"], ["70672.10", "0.000"], ["70672.20", "0.047"], ["70672.30", "0.014"], ["70672.40", "0.019"], ["70672.60", "0.529"], ["70672.70", "0.031"], ["70673.30", "0.210"], ["70673.80", "1.928"], ["70673.90", "0.000"], ["70674.10", "0.009"], ["70674.20", "0.009"], ["70674.30", "0.152"], ["70674.70", "0.060"], ["70675.20", "0.641"], ["70675.30", "0.003"], ["70675.50", "0.010"], ["70675.60", "0.306"], ["70675.70", "0.715"], ["70675.80", "0.057"], ["70675.90", "0.004"], ["70676.20", "0.000"], ["70676.40", "0.030"], ["70676.80", "0.008"], ["70676.90", "0.513"], ["70677.20", "0.015"], ["70677.40", "0.055"], ["70677.60", "0.000"], ["70677.70", "0.004"], ["70677.80", "0.000"], ["70678.00", "0.171"], ["70678.40", "0.002"], ["70678.80", "0.006"], ["70678.90", "0.076"], ["70679.00", "0.242"], ["70679.10", "0.456"], ["70679.30", "0.006"], ["70679.40", "0.605"], ["70679.50", "0.634"], ["70679.80", "1.278"], ["70679.90", "0.006"], ["70680.00", "3.581"], ["70680.20", "0.000"], ["70680.40", "0.039"], ["70680.50", "0.002"], ["70681.00", "0.006"], ["70681.30", "0.010"], ["70681.40", "0.000"], ["70681.50", "0.012"], ["70681.60", "0.010"], ["70681.90", "0.000"], ["70682.20", "0.004"], ["70682.50", "0.002"], ["70682.70", "0.000"], ["70682.80", "0.002"], ["70683.10", "0.514"], ["70683.20", "0.831"], ["70683.30", "0.005"], ["70683.50", "0.259"], ["70683.60", "0.868"], ["70683.90", "0.057"], ["70684.30", "0.014"], ["70684.60", "0.005"], ["70684.80", "0.000"], ["70685.00", "0.013"], ["70685.30", "0.014"], ["70685.40", "0.063"], ["70685.50", "0.513"], ["70685.60", "1.520"], ["70685.80", "0.007"], ["70686.10", "0.045"], ["70686.30", "0.006"], ["70686.40", "0.351"], ["70686.80", "0.020"], ["70686.90", "0.003"], ["70687.10", "0.038"], ["70687.90", "0.004"], ["70688.20", "0.052"], ["70688.70", "0.005"], ["70689.80", "0.517"], ["70690.20", "0.052"], ["70690.30", "0.003"], ["70691.70", "0.011"], ["70692.20", "0.003"], ["70692.60", "1.078"], ["70693.20", "0.000"], ["70693.90", "0.511"], ["70694.50", "0.002"], ["70694.90", "0.241"], ["70695.30", "0.002"], ["70695.50", "0.002"], ["70696.20", "0.366"], ["70696.50", "0.261"], ["70697.90", "0.002"], ["70698.00", "0.018"], ["70698.50", "0.396"], ["70698.70", "0.165"], ["70699.00", "0.306"], ["70699.80", "0.287"], ["70702.90", "0.011"], ["70705.00", "0.006"], ["70706.10", "0.002"], ["70706.40", "0.000"], ["70710.50", "0.714"], ["70712.90", "0.048"], ["70713.50", "0.017"], ["70713.60", "0.002"], ["70714.00", "0.137"], ["70714.30", "0.469"], ["70714.40", "0.053"], ["70715.30", "0.000"], ["70715.60", "0.070"], ["70717.00", "0.050"], ["70717.50", "2.089"], ["70718.20", "0.011"], ["70718.80", "0.020"], ["70718.90", "1.096"], ["70719.20", "8.483"], ["70721.40", "0.019"], ["70723.60", "0.003"], ["70724.60", "0.454"], ["70725.70", "0.154"], ["70727.70", "0.071"], ["70729.00", "0.049"], ["70729.90", "0.049"], ["70731.20", "0.000"], ["70733.30", "0.034"], ["70734.80", "1.803"], ["70736.60", "0.097"], ["70737.40", "0.014"], ["70738.80", "0.000"], ["70740.50", "0.610"], ["70741.80", "0.278"], ["70741.90", "0.003"], ["70742.20", "2.621"], ["70742.90", "0.216"], ["70744.10", "0.172"], ["70747.30", "0.231"], ["70749.30", "0.086"], ["70757.50", "0.299"], ["70758.60", "0.015"], ["70760.70", "0.008"], ["70761.50", "0.005"], ["70762.80", "0.032"], ["70774.00", "4.766"], ["70776.80", "10.542"], ["70784.00", "0.937"], ["70784.10", "0.043"], ["70797.40", "0.099"], ["70797.50", "0.192"], ["70799.50", "0.608"], ["70801.00", "2.002"], ["70811.00", "0.011"], ["70813.80", "0.385"], ["70815.30", "0.093"], ["70816.10", "0.002"], ["70816.40", "0.002"], ["70816.60", "0.006"], ["70817.10", "0.022"], ["70819.30", "0.604"], ["70820.80", "0.000"], ["70822.90", "2.087"], ["70823.50", "10.341"], ["70829.50", "1.493"], ["70830.80", "0.000"], ["70838.10", "0.511"], ["70851.90", "0.003"], ["70854.20", "1.938"], ["70854.60", "10.011"], ["70855.40", "0.516"], ["70858.90", "0.010"], ["70860.50", "0.000"], ["70861.80", "0.302"], ["70861.90", "0.000"], ["70862.40", "0.038"], ["70885.70", "10.007"], ["70885.80", "0.394"], ["70886.80", "0.000"], ["70887.80", "0.106"], ["70889.20", "0.000"], ["70891.60", "0.007"], ["70894.80", "0.000"], ["70922.70", "0.000"], ["70946.20", "0.286"], ["70948.60", "0.279"], ["70949.30", "0.341"], ["70950.80", "0.284"], ["70998.40", "0.002"], ["71008.10", "0.037"], ["71022.20", "0.290"], ["71350.40", "0.180"], ["71355.50", "0.002"], ["71357.60", "0.000"], ["71358.10", "0.000"], ["71359.00", "0.000"], ["71359.60", "0.000"], ["71360.10", "0.000"], ["71361.10", "0.210"], ["71636.50", "0.000"], ["71644.80", "0.020"], ["71646.90", "0.000"], ["71649.10", "0.002"], ["71651.10", "0.021"], ["71653.50", "0.002"], ["71654.20", "0.012"], ["71654.50", "0.019"], ["72067.60", "0.003"], ["72395.80", "1.023"], ["72763.30", "0.008"], ["72796.40", "0.588"], ["74195.90", "0.003"], ["74200.40", "0.002"], ["100000.00", "23.620"]]}}
{"local_ts": 1773486528304, "server_ts": 1773486528274, "data": {"e": "depthUpdate", "E": 1773486528275, "T": 1773486528274, "s": "BTCUSDT", "U": 10109510588556, "u": 10109510594672, "pu": 10109510588516, "b": [["1000.00", "26.142"], ["5000.00", "101.418"], ["7064.90", "0.028"], ["20248.90", "1.870"], ["20343.90", "1.130"], ["20348.90", "0.000"], ["67088.50", "0.000"], ["67116.00", "0.022"], ["69236.00", "0.003"], ["69942.40", "0.000"], ["70295.70", "2.388"], ["70302.70", "0.106"], ["70306.40", "0.008"], ["70481.40", "0.003"], ["70491.70", "0.009"], ["70584.50", "0.000"], ["70601.70", "0.235"], ["70601.80", "0.001"], ["70603.90", "0.610"], ["70604.00", "0.354"], ["70604.10", "0.006"], ["70605.20", "0.007"], ["70606.50", "0.440"], ["70620.80", "0.323"], ["70624.10", "0.000"], ["70629.30", "0.009"], ["70631.10", "0.004"], ["70638.30", "0.007"], ["70641.90", "0.043"], ["70643.20", "0.288"], ["70643.90", "0.665"], ["70644.30", "0.001"], ["70644.50", "0.003"], ["70645.80", "0.007"], ["70648.90", "2.243"]], "a": [["70649.00", "4.803"], ["70650.20", "0.021"], ["70650.30", "0.108"], ["70653.20", "0.001"], ["70654.50", "0.131"], ["70656.00", "0.075"], ["70679.00", "0.270"], ["70687.90", "0.103"], ["70733.60", "0.002"], ["70839.60", "4.560"], ["71265.30", "0.004"], ["71355.50", "0.002"], ["71481.90", "0.768"], ["71583.50", "1.530"], ["71638.10", "0.567"], ["71874.90", "0.006"], ["74184.50", "0.052"]]}}
{"local_ts": 1773486529337, "server_ts": 1773486529292, "data": {"e": "depthUpdate", "E": 1773486529295, "T": 1773486529292, "s": "BTCUSDT", "U": 10109510652589, "u": 10109510657935, "pu": 10109510652536, "b": [["5000.00", "101.398"], ["7064.90", "0.028"], ["20148.90", "1.420"], ["20248.90", "1.580"], ["67092.70", "0.002"], ["69942.40", "0.000"], ["70302.70", "0.000"], ["70551.10", "0.000"], ["70551.20", "0.241"], ["70558.10", "6.599"], ["70558.20", "0.328"], ["70565.20", "0.502"], ["70565.30", "0.071"], ["70571.20", "1.072"], ["70585.30", "0.276"], ["70603.90", "0.426"], ["70611.00", "0.186"], ["70613.60", "0.279"], ["70620.80", "0.322"], ["70628.80", "0.374"], ["70633.70", "0.254"], ["70640.30", "0.211"], ["70640.80", "0.003"], ["70645.90", "0.001"]], "a": [["70649.00", "3.972"], ["70650.30", "0.051"], ["70652.50", "0.003"], ["70670.00", "0.274"], ["70684.30", "0.204"], ["70712.60", "0.018"], ["70726.70", "0.005"], ["70727.80", "0.327"], ["70733.60", "0.000"], ["70734.90", "0.516"], ["70736.40", "0.240"], ["70741.90", "0.071"], ["70775.50", "8.782"], ["70865.80", "0.000"], ["70871.00", "0.009"], ["71355.40", "0.787"], ["71355.50", "0.002"]]}}
{"local_ts": 1773486530346, "server_ts": 1773486530312, "data": {"e": "depthUpdate", "E": 1773486530315, "T": 1773486530312, "s": "BTCUSDT", "U": 10109510705938, "u": 10109510710210, "pu": 10109510705788, "b": [["1000.00", "26.142"], ["5000.00", "101.418"], ["7064.90", "0.028"], ["20148.90", "2.030"], ["20548.90", "0.970"], ["33000.00", "3.785"], ["67116.30", "0.002"], ["69878.80", "1.429"], ["69942.40", "0.000"], ["70295.70", "2.388"], ["70397.90", "2.171"], ["70398.30", "0.000"], ["70551.20", "0.241"], ["70554.70", "0.343"], ["70555.90", "0.312"], ["70558.20", "0.328"], ["70561.70", "0.552"], ["70562.90", "0.230"], ["70565.30", "0.071"], ["70568.80", "0.292"], ["70570.00", "0.387"], ["70602.40", "0.010"], ["70603.90", "0.072"], ["70609.50", "0.001"], ["70611.00", "0.002"], ["70616.60", "0.011"], ["70620.90", "0.047"], ["70623.70", "0.006"], ["70630.80", "0.002"], ["70631.60", "0.016"], ["70645.50", "0.006"]], "a": [["70649.40", "0.269"], ["70666.30", "0.038"], ["70673.40", "0.008"], ["70680.50", "0.002"], ["70687.60", "0.712"], ["70687.90", "0.283"], ["70694.70", "0.000"], ["70701.80", "0.000"], ["70725.60", "0.002"], ["70725.70", "0.154"], ["70727.90", "0.071"], ["70732.70", "0.087"], ["70732.80", "0.142"], ["70735.00", "0.079"], ["70738.90", "0.097"], ["70739.70", "0.002"], ["70739.80", "0.142"], ["70741.40", "0.045"], ["70742.00", "0.073"], ["70775.50", "8.780"], ["70871.00", "0.007"], ["70900.50", "0.915"], ["70903.60", "0.000"], ["71355.50", "0.702"], ["71816.60", "0.277"], ["72790.70", "0.588"], ["74207.00", "0.054"], ["148391.20", "0.002"]]}}
{"local_ts": 1773486531367, "server_ts": 1773486531336, "data": {"e": "depthUpdate", "E": 1773486531337, "T": 1773486531336, "s": "BTCUSDT", "U": 10109510763089, "u": 10109510769031, "pu": 10109510763002, "b": [["1000.00", "26.142"], ["5000.00", "101.418"], ["7064.80", "0.000"], ["20148.90", "0.000"], ["20447.70", "0.530"], ["20547.70", "1.730"], ["20548.90", "0.720"], ["69213.60", "1.731"], ["69231.10", "0.012"], ["69941.20", "0.714"], ["70551.30", "0.017"], ["70558.30", "0.206"], ["70565.40", "0.071"], ["70600.40", "0.006"], ["70600.60", "0.112"], ["70605.30", "0.170"], ["70608.40", "0.003"], ["70610.60", "0.003"], ["70612.40", "0.000"], ["70620.40", "0.060"], ["70621.00", "0.326"], ["70621.10", "0.000"], ["70621.20", "0.032"], ["70622.90", "0.000"], ["70634.20", "0.004"], ["70637.10", "0.168"], ["70640.40", "0.025"], ["70640.60", "0.281"], ["70643.70", "0.024"], ["70644.00", "0.165"], ["70647.70", "1.086"]], "a": [["70647.80", "6.944"], ["70650.40", "0.004"], ["70655.50", "0.001"], ["70657.50", "0.008"], ["70658.40", "0.003"], ["70727.90", "0.000"], ["70728.00", "1.335"], ["70735.00", "0.008"], ["70735.10", "0.156"], ["70737.20", "0.002"], ["70738.90", "0.095"], ["70739.70", "0.004"], ["70741.40", "0.043"], ["70742.00", "0.002"], ["70742.10", "0.161"], ["70870.90", "0.002"], ["70949.20", "0.007"], ["71354.30", "0.000"], ["71496.80", "0.848"], ["71592.40", "0.975"], ["71673.40", "2.090"], ["71744.10", "0.977"], ["72060.70", "0.010"], ["74188.50", "0.055"], ["89523.20", "0.000"]]}}
{"local_ts": 1773486532391, "server_ts": 1773486532360, "data": {"e": "depthUpdate", "E": 1773486532361, "T": 1773486532360, "s": "BTCUSDT", "U": 10109510810000, "u": 10109510813840, "pu": 10109510809874, "b": [["5000.00", "101.418"], ["7064.80", "0.000"], ["20347.70", "0.270"], ["20447.70", "2.550"], ["20547.70", "0.180"], ["33000.00", "3.785"], ["67083.40", "0.000"], ["69559.20", "0.768"], ["69941.20", "2.142"], ["70493.10", "0.003"], ["70493.30", "0.049"], ["70495.60", "0.000"], ["70501.90", "0.093"], ["70504.50", "0.121"], ["70507.30", "0.131"], ["70516.20", "0.652"], ["70520.70", "0.011"], ["70551.30", "0.017"], ["70558.30", "0.206"], ["70565.40", "0.071"], ["70600.20", "0.007"], ["70600.30", "0.005"], ["70604.10", "0.190"], ["70621.00", "0.326"], ["70638.10", "0.000"], ["70638.20", "0.081"], ["70644.00", "0.165"], ["70647.70", "1.086"]], "a": [["70647.80", "6.888"], ["70647.90", "0.006"], ["70666.90", "0.060"], ["70728.00", "1.335"], ["70735.10", "0.156"], ["70737.20", "0.000"], ["70737.40", "0.016"], ["70737.70", "0.002"], ["70739.70", "0.002"], ["70742.10", "0.161"], ["70781.40", "0.412"], ["70785.50", "0.008"], ["70786.80", "0.000"], ["70792.60", "0.009"], ["70793.90", "0.187"], ["70799.70", "0.048"], ["70801.00", "2.002"], ["70806.80", "0.007"], ["70808.10", "0.027"], ["70813.90", "0.009"], ["70815.20", "0.253"], ["70821.00", "0.455"], ["70822.30", "0.093"], ["70828.10", "0.262"], ["70829.40", "0.000"], ["70835.20", "0.009"], ["70836.50", "1.865"], ["71354.30", "0.000"], ["71597.60", "0.290"], ["71737.20", "0.696"], ["72060.70", "0.016"], ["74209.30", "0.002"], ["89523.20", "0.000"]]}}
{"local_ts": 1773486533413, "server_ts": 1773486533380, "data": {"e": "depthUpdate", "E": 1773486533381, "T": 1773486533380, "s": "BTCUSDT", "U": 10109510867035, "u": 10109510874440, "pu": 10109510866985, "b": [["1000.00", "26.142"], ["5000.00", "101.418"], ["7064.80", "0.000"], ["20247.70", "0.120"], ["20347.70", "2.400"], ["20447.70", "0.480"], ["67096.50", "0.000"], ["69639.60", "1.609"], ["69941.20", "2.142"], ["69941.30", "0.009"], ["70294.50", "0.036"], ["70397.90", "0.000"], ["70401.50", "0.000"], ["70453.40", "0.000"], ["70464.00", "0.361"], ["70492.20", "12.942"], ["70551.30", "0.000"], ["70551.40", "0.042"], ["70552.00", "6.632"], ["70552.60", "1.642"], ["70558.30", "0.135"], ["70558.40", "0.114"], ["70565.40", "0.000"], ["70565.50", "0.073"], ["70571.70", "0.184"], ["70580.60", "0.004"], ["70588.10", "3.500"], ["70599.70", "0.000"], ["70600.70", "0.290"], ["70600.80", "0.031"], ["70604.10", "0.190"], ["70610.00", "2.852"], ["70610.50", "0.000"], ["70610.60", "0.142"], ["70612.40", "0.164"], ["70620.40", "0.060"], ["70629.90", "0.072"], ["70631.20", "0.000"], ["70633.80", "0.035"], ["70635.40", "0.009"], ["70638.90", "0.034"], ["70640.30", "0.213"], ["70640.60", "0.006"], ["70640.70", "0.511"], ["70641.50", "0.011"], ["70642.30", "0.126"], ["70645.50", "0.005"], ["70647.70", "0.136"]], "a": [["70647.80", "6.733"], ["70648.00", "0.023"], ["70648.10", "0.000"], ["70648.20", "0.000"], ["70648.40", "0.000"], ["70648.50", "0.134"], ["70648.60", "0.400"], ["70679.60", "0.579"], ["70682.50", "1.796"], ["70683.10", "0.563"], ["70683.30", "0.006"], ["70686.70", "0.161"], ["70704.40", "3.365"], ["70728.00", "1.335"], ["70735.10", "0.156"], ["70735.80", "0.051"], ["70737.40", "0.014"], ["70739.60", "0.439"], ["70740.10", "6.582"], ["70742.10", "0.161"], ["70743.20", "0.252"], ["70784.80", "0.007"], ["70785.50", "0.001"], ["70791.90", "0.699"], ["70792.60", "0.002"], ["70799.00", "0.468"], ["70799.50", "12.979"], ["70799.70", "0.041"], ["70806.10", "0.007"], ["70806.80", "0.000"], ["70813.20", "0.261"], ["70813.90", "0.002"], ["70820.30", "0.011"], ["70821.00", "0.448"], ["70827.40", "0.007"], ["70828.10", "0.255"], ["70834.50", "0.071"], ["70835.20", "0.002"], ["70871.40", "0.210"], ["70871.50", "0.002"], ["70899.70", "0.000"], ["71354.30", "0.000"], ["71673.40", "2.926"], ["72048.90", "0.598"], ["74190.90", "0.002"], ["89523.20", "0.000"]]}}
{"local_ts": 1773486534432, "server_ts": 1773486534401, "data": {"e": "depthUpdate", "E": 1773486534403, "T": 1773486534401, "s": "BTCUSDT", "U": 10109510939955, "u": 10109510947521, "pu": 10109510939623, "b": [["5000.00", "101.418"], ["7064.80", "0.056"], ["20247.70", "2.190"], ["20347.70", "0.810"], ["33000.00", "3.789"], ["67085.00", "0.000"], ["67116.50", "0.004"], ["67116.60", "0.002"], ["69837.40", "0.066"], ["69941.20", "2.142"], ["70397.90", "0.000"], ["70492.60", "2.995"], ["70551.40", "0.042"], ["70558.40", "0.114"], ["70565.50", "0.073"], ["70571.70", "0.184"], ["70571.90", "0.238"], ["70590.10", "1.151"], ["70594.50", "8.497"], ["70597.90", "0.009"], ["70598.00", "0.002"], ["70605.30", "0.306"], ["70610.60", "0.135"], ["70611.00", "0.894"], ["70613.60", "0.276"], ["70620.20", "0.486"], ["70625.20", "0.510"], ["70625.70", "0.007"], ["70626.30", "0.072"], ["70626.80", "1.224"], ["70627.50", "0.306"], ["70629.20", "0.141"], ["70630.10", "0.013"], ["70631.20", "0.283"], ["70632.40", "0.077"], ["70635.30", "0.077"], ["70638.20", "0.023"], ["70638.90", "0.249"], ["70640.20", "0.024"], ["70641.10", "0.010"]], "a": [["70647.80", "6.685"], ["70648.30", "0.002"], ["70648.40", "0.133"], ["70648.50", "0.000"], ["70653.20", "0.172"], ["70653.30", "0.642"], ["70653.40", "0.477"], ["70653.50", "0.006"], ["70654.90", "0.007"], ["70658.60", "0.201"], ["70664.80", "0.210"], ["70667.20", "0.000"], ["70676.10", "0.101"], ["70676.90", "0.000"], ["70678.90", "0.323"], ["70681.90", "0.000"], ["70686.70", "0.258"], ["70704.00", "0.768"], ["70728.10", "0.582"], ["70735.20", "0.160"], ["70735.90", "0.484"], ["70742.20", "1.770"], ["70775.20", "0.024"], ["70782.30", "0.007"], ["70784.80", "0.000"], ["70789.40", "4.862"], ["70791.90", "0.692"], ["70796.50", "0.007"], ["70799.00", "0.461"], ["70803.60", "0.014"], ["70806.10", "0.000"], ["70810.70", "0.015"], ["70813.20", "0.254"], ["70817.80", "0.035"], ["70820.30", "0.004"], ["70824.90", "0.027"], ["70827.40", "0.000"], ["70834.50", "0.064"], ["70899.70", "0.000"], ["71354.30", "0.000"], ["72060.70", "0.025"], ["72775.10", "0.016"], ["74182.70", "0.002"], ["89523.20", "0.000"]]}}
{"local_ts": 1773486535456, "server_ts": 1773486535424, "data": {"e": "depthUpdate", "E": 1773486535427, "T": 1773486535424, "s": "BTCUSDT", "U": 10109511020994, "u": 10109511026265, "pu": 10109511020853, "b": [["1000.00", "26.142"], ["5000.00", "101.418"], ["7064.80", "0.056"], ["20147.50", "1.110"], ["20247.70", "1.250"], ["67115.10", "0.000"], ["69236.00", "0.000"], ["69777.90", "0.000"], ["69941.00", "0.000"], ["70294.50", "0.142"], ["70464.00", "0.202"], ["70551.40", "0.042"], ["70558.40", "0.114"], ["70565.50", "0.073"], ["70569.80", "0.000"], ["70572.80", "0.259"], ["70583.90", "0.004"], ["70594.40", "0.011"], ["70594.60", "2.012"], ["70612.20", "0.061"], ["70614.80", "0.002"], ["70615.00", "0.684"], ["70620.90", "0.003"], ["70628.10", "0.512"], ["70629.10", "0.015"], ["70632.40", "0.079"], ["70632.80", "0.002"], ["70635.70", "0.257"], ["70635.80", "0.660"], ["70637.00", "0.011"], ["70647.50", "1.986"]], "a": [["70647.60", "5.962"], ["70647.70", "0.145"], ["70647.80", "0.162"], ["70648.00", "0.083"], ["70648.90", "0.022"], ["70649.00", "0.129"], ["70649.10", "0.001"], ["70649.30", "0.002"], ["70649.40", "0.212"], ["70650.30", "0.054"], ["70653.20", "0.007"], ["70658.30", "0.094"], ["70682.90", "0.002"], ["70689.70", "0.217"], ["70711.20", "0.012"], ["70725.30", "0.022"], ["70728.10", "0.582"], ["70735.20", "0.160"], ["70742.20", "1.770"], ["70775.20", "0.017"], ["70782.30", "0.000"], ["70783.90", "0.007"], ["70789.40", "4.855"], ["70791.00", "0.016"], ["70796.50", "0.000"], ["70798.10", "0.366"], ["70803.60", "0.007"], ["70805.20", "0.007"], ["70810.70", "0.008"], ["70812.30", "0.679"], ["70817.20", "2.584"], ["70817.80", "0.028"], ["70819.40", "0.010"], ["70824.90", "0.020"], ["70826.50", "0.009"], ["70833.60", "0.007"], ["70966.50", "0.035"], ["71354.10", "0.000"], ["71398.00", "0.890"], ["72039.60", "0.295"], ["72060.50", "0.005"], ["74214.10", "0.000"], ["89523.20", "0.000"]]}}
{"local_ts": 1773486536483, "server_ts": 1773486536444, "data": {"e": "depthUpdate", "E": 1773486536447, "T": 1773486536444, "s": "BTCUSDT", "U": 10109511076460, "u": 10109511085268, "pu": 10109511076417, "b": [["1000.00", "26.142"], ["5000.00", "101.418"], ["7064.80", "0.056"], ["20147.50", "1.700"], ["20547.50", "1.300"], ["67115.00", "0.011"], ["69941.00", "0.000"], ["69941.10", "0.000"], ["70294.50", "0.036"], ["70401.10", "0.004"], ["70463.80", "0.251"], ["70567.60", "1.491"], ["70597.90", "0.530"], ["70599.10", "0.205"], ["70607.70", "0.684"], ["70620.40", "0.060"], ["70621.80", "0.004"], ["70621.90", "0.047"], ["70635.10", "0.119"], ["70643.80", "0.003"], ["70647.50", "1.980"]], "a": [["70647.60", "4.979"], ["70647.70", "0.105"], ["70650.70", "0.002"], ["70650.90", "0.000"], ["70653.40", "0.456"], ["70659.00", "0.113"], ["70672.20", "0.070"], ["70692.80", "0.106"], ["70726.60", "0.036"], ["70750.00", "2.094"], ["70783.90", "0.000"], ["70790.60", "3.497"], ["70791.00", "0.009"], ["70797.70", "0.029"], ["70798.10", "0.359"], ["70804.80", "0.602"], ["70805.20", "0.000"], ["70811.90", "0.021"], ["70812.30", "0.672"], ["70819.00", "0.007"], ["70819.40", "0.003"], ["70826.10", "0.023"], ["70826.50", "0.002"], ["70833.20", "0.007"], ["70833.60", "0.000"], ["70840.30", "0.007"], ["70966.50", "4.771"], ["71354.10", "0.000"], ["72060.70", "0.022"], ["74215.20", "0.008"], ["89523.20", "0.000"]]}}
{"local_ts": 1773486537504, "server_ts": 1773486537472, "data": {"e": "depthUpdate", "E": 1773486537475, "T": 1773486537472, "s": "BTCUSDT", "U": 10109511131648, "u": 10109511136708, "pu": 10109511131345, "b": [["5000.00", "101.398"], ["7064.80", "0.028"], ["20447.50", "0.870"], ["20547.50", "2.130"], ["67101.50", "40.002"], ["67115.20", "0.000"], ["69941.00", "0.007"], ["70397.70", "2.432"], ["70401.10", "0.004"], ["70556.40", "2.369"], ["70563.40", "1.648"], ["70590.10", "0.000"], ["70590.30", "1.245"], ["70600.70", "0.290"], ["70600.90", "0.511"], ["70612.20", "1.074"], ["70620.40", "0.017"], ["70621.00", "0.370"], ["70633.30", "0.138"], ["70640.50", "0.005"], ["70643.90", "0.072"]], "a": [["70647.60", "4.783"], ["70651.00", "0.004"], ["70654.60", "0.064"], ["70659.10", "0.041"], ["70660.50", "0.004"], ["70661.80", "0.013"], ["70664.80", "0.033"], ["70694.00", "0.490"], ["70899.60", "2.701"], ["71354.10", "0.000"], ["71857.70", "2.208"], ["89523.20", "0.000"]]}}
{"local_ts": 1773486538528, "server_ts": 1773486538492, "data": {"e": "depthUpdate", "E": 1773486538495, "T": 1773486538492, "s": "BTCUSDT", "U": 10109511177190, "u": 10109511180396, "pu": 10109511177180, "b": [["1000.00", "26.142"], ["5000.00", "101.438"], ["7064.40", "0.028"], ["20343.20", "0.440"], ["20443.20", "1.250"], ["20447.50", "1.290"], ["20547.50", "0.020"], ["67101.50", "40.000"], ["67116.50", "0.000"], ["67116.60", "0.004"], ["69640.20", "0.286"], ["69892.20", "1.848"], ["69936.80", "0.002"], ["70294.30", "0.072"], ["70486.50", "2.705"], ["70545.70", "6.846"], ["70545.80", "1.519"], ["70565.50", "0.073"], ["70579.60", "0.000"], ["70590.10", "0.587"], ["70593.40", "1.328"], ["70593.50", "0.018"], ["70607.90", "0.156"], ["70615.50", "0.853"], ["70627.80", "0.005"], ["70628.80", "0.353"], ["70629.00", "0.977"], ["70629.60", "0.344"], ["70632.60", "0.017"], ["70634.40", "0.004"], ["70636.80", "0.002"], ["70638.70", "0.003"], ["70639.50", "0.001"], ["70639.80", "0.002"], ["70639.90", "0.009"], ["70642.30", "0.062"]], "a": [["70643.30", "2.948"], ["70647.60", "0.104"], ["70648.30", "0.006"], ["70653.50", "0.007"], ["70654.10", "0.006"], ["70654.70", "0.028"], ["70655.40", "0.063"], ["70657.00", "0.006"], ["70661.10", "0.007"], ["70664.40", "0.006"], ["70671.70", "0.025"], ["70673.00", "0.011"], ["70673.70", "0.024"], ["70675.20", "0.072"], ["70678.50", "0.012"], ["70678.60", "0.377"], ["70685.10", "0.291"], ["70711.20", "0.012"], ["70725.30", "0.022"], ["70734.40", "0.659"], ["70850.90", "1.024"], ["71333.70", "0.002"], ["71349.70", "0.000"], ["71910.30", "0.000"], ["74195.50", "0.052"], ["89523.20", "0.000"]]}}
{"local_ts": 1773486539546, "server_ts": 1773486539516, "data": {"e": "depthUpdate", "E": 1773486539517, "T": 1773486539516, "s": "BTCUSDT", "U": 10109511214124, "u": 10109511217391, "pu": 10109511214023, "b": [["5000.00", "101.418"], ["7064.40", "0.028"], ["20243.20", "0.230"], ["20343.20", "2.520"], ["20443.20", "0.250"], ["33000.00", "3.785"], ["67077.70", "0.000"], ["67087.40", "0.002"], ["69936.80", "0.002"], ["70078.10", "0.015"], ["70463.10", "0.535"], ["70483.50", "0.000"], ["70511.80", "0.630"], ["70555.40", "1.190"], ["70583.20", "1.059"], ["70591.90", "0.000"], ["70593.70", "0.276"], ["70593.80", "0.114"], ["70598.40", "0.421"], ["70604.90", "0.006"], ["70605.30", "0.306"], ["70607.90", "0.312"], ["70611.90", "0.712"], ["70628.40", "0.390"], ["70636.20", "0.030"]], "a": [["70643.30", "3.499"], ["70650.30", "0.087"], ["70675.60", "0.504"], ["70678.60", "0.321"], ["70781.80", "0.127"], ["71349.70", "0.000"], ["72000.00", "232.234"], ["89523.20", "0.000"]]}}
{"local_ts": 1773486540568, "server_ts": 1773486540538, "data": {"e": "depthUpdate", "E": 1773486540539, "T": 1773486540538, "s": "BTCUSDT", "U": 10109511378160, "u": 10109511388343, "pu": 10109511378151, "b": [["1000.00", "26.142"], ["5000.00", "101.418"], ["7062.40", "0.000"], ["20123.70", "0.080"], ["20223.70", "1.190"], ["20243.20", "1.140"], ["20343.20", "0.550"], ["56499.00", "0.181"], ["69642.00", "3.025"], ["69917.50", "0.000"], ["70270.60", "0.096"], ["70300.00", "21.379"], ["70301.40", "0.000"], ["70304.20", "0.000"], ["70304.30", "0.790"], ["70467.90", "0.088"], ["70472.40", "0.085"], ["70476.90", "0.090"], ["70480.00", "0.139"], ["70483.10", "2.750"], ["70486.00", "0.177"], ["70487.90", "0.266"], ["70506.30", "0.021"], ["70508.00", "7.401"], ["70508.80", "0.005"], ["70518.50", "0.002"], ["70529.80", "0.021"], ["70552.70", "0.858"], ["70553.80", "0.666"], ["70563.30", "0.089"], ["70563.70", "0.081"], ["70566.80", "0.336"], ["70571.40", "0.212"], ["70571.70", "0.059"], ["70577.80", "0.003"], ["70581.30", "0.089"], ["70584.90", "1.013"], ["70585.70", "0.328"], ["70588.40", "0.275"], ["70589.80", "0.059"], ["70590.50", "0.003"], ["70591.20", "0.516"], ["70591.50", "0.009"], ["70591.90", "0.023"], ["70593.50", "0.671"], ["70597.70", "0.018"], ["70598.40", "0.007"], ["70599.60", "0.019"], ["70600.30", "0.003"], ["70602.10", "0.017"], ["70603.40", "0.007"], ["70604.80", "1.209"], ["70608.00", "0.019"], ["70609.30", "0.011"], ["70609.50", "0.003"], ["70610.00", "0.752"], ["70610.70", "0.088"], ["70611.00", "0.127"], ["70611.10", "0.104"], ["70611.80", "0.000"], ["70611.90", "0.511"], ["70612.80", "2.085"], ["70613.10", "0.005"], ["70613.20", "0.170"], ["70613.30", "0.060"], ["70614.00", "0.000"], ["70616.70", "0.028"], ["70619.40", "0.017"], ["70619.50", "0.011"], ["70620.90", "0.000"], ["70621.00", "0.000"], ["70623.00", "0.000"], ["70623.40", "0.002"], ["70623.50", "0.002"], ["70623.70", "2.342"]], "a": [["70623.80", "6.162"], ["70623.90", "0.116"], ["70625.40", "0.000"], ["70626.10", "0.007"], ["70629.30", "0.466"], ["70629.50", "0.001"], ["70630.50", "0.203"], ["70630.80", "0.047"], ["70631.00", "0.020"], ["70632.80", "0.001"], ["70633.50", "0.309"], ["70633.90", "0.003"], ["70634.20", "0.063"], ["70634.40", "0.000"], ["70635.20", "0.241"], ["70637.00", "0.040"], ["70638.50", "0.005"], ["70638.70", "0.019"], ["70640.30", "0.003"], ["70641.50", "0.080"], ["70642.30", "0.008"], ["70643.00", "0.003"], ["70643.30", "0.102"], ["70643.70", "0.060"], ["70644.40", "0.028"], ["70645.00", "0.028"], ["70645.10", "0.002"], ["70646.50", "0.632"], ["70647.10", "0.005"], ["70647.90", "0.000"], ["70648.60", "0.344"], ["70649.30", "0.000"], ["70650.00", "0.149"], ["70650.70", "0.000"], ["70651.40", "0.003"], ["70651.50", "0.000"], ["70655.60", "0.516"], ["70655.80", "0.049"], ["70656.10", "0.025"], ["70656.40", "0.000"], ["70656.50", "0.002"], ["70659.00", "0.003"], ["70659.10", "0.048"], ["70660.50", "0.107"], ["70661.50", "0.986"], ["70662.30", "3.503"], ["70662.70", "0.000"], ["70663.60", "0.045"], ["70664.10", "0.280"], ["70664.20", "0.086"], ["70665.50", "0.007"], ["70666.20", "0.801"], ["70666.90", "0.001"], ["70668.30", "0.097"], ["70668.80", "0.088"], ["70669.70", "0.256"], ["70670.30", "0.089"], ["70671.10", "0.002"], ["70671.20", "0.088"], ["70672.60", "0.561"], ["70672.90", "0.085"], ["70674.00", "0.007"], ["70675.40", "0.005"], ["70676.20", "0.402"], ["70676.60", "0.002"], ["70676.80", "0.465"], ["70677.30", "0.085"], ["70677.50", "0.072"], ["70678.20", "0.002"], ["70678.90", "0.088"], ["70679.60", "0.284"], ["70681.70", "0.094"], ["70682.50", "1.837"], ["70683.50", "8.492"], ["70687.40", "0.139"], ["70702.90", "0.291"], ["70720.70", "0.094"], ["70754.90", "0.085"], ["70758.10", "0.087"], ["70800.40", "0.761"], ["70898.40", "0.000"], ["71074.50", "0.000"], ["71330.00", "0.872"], ["71647.80", "4.710"], ["71691.10", "7.752"], ["71718.50", "4.435"], ["71754.30", "3.864"], ["71761.70", "6.770"], ["71805.70", "0.000"], ["72060.50", "0.008"], ["74199.10", "0.000"]]}}
{"local_ts": 1773486541592, "server_ts": 1773486541556, "data": {"e": "depthUpdate", "E": 1773486541561, "T": 1773486541556, "s": "BTCUSDT", "U": 10109511500983, "u": 10109511508543, "pu": 10109511500978, "b": [["1000.00", "26.142"], ["5000.00", "101.418"], ["7062.20", "0.000"], ["20122.00", "1.890"], ["20223.70", "0.350"], ["33000.00", "3.789"], ["56498.00", "0.000"], ["56499.00", "0.181"], ["69209.60", "0.006"], ["69915.80", "3.968"], ["70172.80", "0.000"], ["70223.30", "0.021"], ["70428.80", "0.018"], ["70470.40", "0.087"], ["70475.40", "0.374"], ["70478.10", "0.181"], ["70480.20", "0.172"], ["70484.20", "0.085"], ["70490.60", "0.664"], ["70511.80", "0.008"], ["70544.30", "0.003"], ["70554.90", "0.006"], ["70558.40", "0.046"], ["70567.10", "0.003"], ["70581.10", "0.088"], ["70581.20", "0.279"], ["70582.60", "0.070"], ["70607.10", "1.081"], ["70607.80", "0.005"], ["70607.90", "0.380"], ["70610.90", "0.003"], ["70611.40", "0.054"], ["70615.00", "0.405"], ["70621.30", "0.000"], ["70621.40", "0.015"]], "a": [["70622.10", "7.886"], ["70622.20", "0.075"], ["70623.30", "0.002"], ["70623.60", "0.101"], ["70623.70", "0.046"], ["70623.80", "0.341"], ["70627.30", "0.655"], ["70629.10", "0.067"], ["70629.70", "0.004"], ["70630.70", "0.000"], ["70631.10", "0.003"], ["70632.70", "0.001"], ["70634.60", "0.028"], ["70638.90", "1.185"], ["70639.70", "0.000"], ["70647.70", "0.005"], ["70651.90", "0.000"], ["70652.00", "0.325"], ["70653.20", "0.322"], ["70655.90", "0.046"], ["70657.50", "0.010"], ["70660.90", "0.133"], ["70685.70", "0.005"], ["70699.80", "0.255"], ["70710.20", "0.002"], ["70711.90", "0.019"], ["70722.70", "2.089"], ["70758.90", "0.496"], ["70781.60", "3.871"], ["70890.90", "0.012"], ["70966.50", "0.035"], ["71089.20", "0.002"], ["71328.30", "1.450"], ["71506.60", "0.698"], ["71541.90", "4.994"], ["71542.40", "1.439"], ["71577.70", "12.044"], ["71646.10", "4.835"], ["71687.10", "4.597"], ["71716.70", "2.902"], ["71757.80", "1.959"], ["74171.90", "0.002"], ["74180.80", "0.000"]]}}
{"local_ts": 1773486542613, "server_ts": 1773486542584, "data": {"e": "depthUpdate", "E": 1773486542585, "T": 1773486542584, "s": "BTCUSDT", "U": 10109511579766, "u": 10109511585748, "pu": 10109511579751, "b": [["5000.00", "101.418"], ["7062.20", "0.000"], ["20122.00", "1.350"], ["20522.00", "1.650"], ["56499.00", "0.181"], ["67061.20", "0.000"], ["69908.00", "43.269"], ["69915.80", "3.968"], ["69929.90", "0.714"], ["70193.70", "0.171"], ["70449.00", "0.159"], ["70521.00", "6.805"], ["70528.00", "0.844"], ["70588.60", "0.199"], ["70595.80", "0.005"], ["70595.90", "0.171"], ["70596.00", "0.288"], ["70597.40", "0.007"], ["70599.30", "0.512"], ["70600.30", "0.003"], ["70600.80", "0.070"], ["70601.50", "0.000"], ["70608.00", "0.656"], ["70608.40", "0.003"], ["70609.00", "0.017"], ["70609.20", "0.006"], ["70611.40", "0.054"], ["70615.00", "0.007"], ["70618.90", "0.007"]], "a": [["70629.10", "0.003"], ["70629.60", "0.000"], ["70632.70", "0.143"], ["70640.90", "0.003"], ["70642.20", "0.000"], ["70642.70", "0.020"], ["70643.30", "0.096"], ["70643.40", "0.639"], ["70643.90", "0.510"], ["70644.00", "0.080"], ["70644.50", "0.000"], ["70645.70", "0.000"], ["70651.90", "0.000"], ["70653.20", "0.458"], ["70680.00", "2.737"], ["71328.30", "1.450"], ["71329.10", "0.000"], ["71701.80", "0.836"]]}}
{"local_ts": 1773486543643, "server_ts": 1773486543612, "data": {"e": "depthUpdate", "E": 1773486543613, "T": 1773486543612, "s": "BTCUSDT", "U": 10109511665213, "u": 10109511671368, "pu": 10109511665107, "b": [["1000.00", "26.142"], ["5000.00", "101.418"], ["7062.20", "0.056"], ["20422.00", "1.220"], ["20522.00", "1.780"], ["56499.00", "0.181"], ["67071.80", "0.024"], ["67090.00", "0.016"], ["69209.60", "0.015"], ["69562.20", "0.430"], ["70268.90", "0.000"], ["70275.30", "3.560"], ["70574.30", "0.008"], ["70574.40", "0.217"], ["70593.70", "0.054"], ["70607.80", "0.056"], ["70611.40", "0.054"], ["70613.20", "0.151"], ["70619.30", "0.007"], ["70620.80", "0.002"]], "a": [["70624.40", "0.009"], ["70626.40", "0.002"], ["70629.40", "0.012"], ["70632.70", "0.001"], ["70644.70", "0.755"], ["70646.50", "0.000"], ["70648.30", "0.000"], ["70649.00", "0.111"], ["70649.30", "0.636"], ["70650.40", "0.043"], ["70664.50", "0.282"], ["70687.10", "2.403"], ["70698.60", "0.977"], ["70712.40", "0.004"], ["70738.70", "0.058"], ["70740.90", "0.000"], ["70746.10", "0.097"], ["70748.90", "0.000"], ["70754.60", "0.002"], ["70845.90", "0.000"], ["70846.30", "0.007"], ["71328.20", "0.011"], ["71328.30", "1.450"], ["71469.60", "2.772"], ["71507.00", "0.003"], ["71540.20", "4.844"], ["71577.70", "1.664"], ["74169.70", "0.000"], ["74175.70", "0.000"]]}}
{"local_ts": 1773486544664, "server_ts": 1773486544632, "data": {"e": "depthUpdate", "E": 1773486544633, "T": 1773486544632, "s": "BTCUSDT", "U": 10109511723522, "u": 10109511728819, "pu": 10109511723347, "b": [["5000.00", "101.418"], ["7062.20", "0.056"], ["20322.00", "0.770"], ["20422.00", "2.230"], ["56498.00", "0.000"], ["69915.80", "3.968"], ["70057.00", "0.008"], ["70570.00", "1.208"], ["70573.30", "0.020"], ["70575.20", "0.005"], ["70575.40", "0.003"], ["70580.90", "0.009"], ["70603.80", "0.165"], ["70604.40", "0.000"], ["70604.80", "0.460"], ["70610.90", "0.000"], ["70611.40", "0.054"], ["70612.10", "0.001"], ["70612.30", "0.637"], ["70615.00", "0.048"]], "a": [["70622.10", "2.593"], ["70627.40", "0.218"], ["70627.50", "0.012"], ["70627.80", "0.006"], ["70629.10", "0.037"], ["70635.10", "0.652"], ["70636.10", "0.005"], ["70640.60", "0.421"], ["70643.90", "0.011"], ["70655.50", "1.143"], ["70655.90", "0.016"], ["70657.00", "0.250"], ["70657.20", "0.044"], ["70671.40", "0.973"], ["71328.30", "1.450"], ["71515.90", "0.000"], ["72405.80", "2.485"], ["72662.90", "0.495"], ["74188.40", "0.000"]]}}
{"local_ts": 1773486545690, "server_ts": 1773486545656, "data": {"e": "depthUpdate", "E": 1773486545657, "T": 1773486545656, "s": "BTCUSDT", "U": 10109511778759, "u": 10109511784356, "pu": 10109511778680, "b": [["1000.00", "26.142"], ["5000.00", "101.418"], ["7062.20", "0.056"], ["20222.00", "0.370"], ["20322.00", "2.580"], ["20422.00", "0.050"], ["56498.00", "0.000"], ["69703.90", "0.860"], ["69915.80", "3.968"], ["70268.90", "3.267"], ["70573.60", "8.506"], ["70573.70", "2.153"], ["70575.50", "0.003"], ["70575.60", "0.039"], ["70575.70", "0.003"], ["70586.70", "0.005"], ["70598.30", "0.058"], ["70599.60", "0.013"], ["70600.70", "0.365"], ["70602.10", "0.017"], ["70612.30", "0.637"], ["70613.50", "0.001"], ["70615.00", "0.045"], ["70618.60", "0.001"], ["70620.70", "0.001"], ["70621.80", "0.002"], ["70621.90", "0.020"]], "a": [["70622.10", "1.639"], ["70629.10", "0.038"], ["70647.50", "1.608"], ["70657.40", "0.057"], ["70664.50", "0.229"], ["71328.30", "1.532"], ["71328.80", "0.000"], ["71518.00", "0.213"], ["71589.60", "0.278"], ["71646.10", "21.143"], ["71682.30", "0.000"], ["71739.00", "0.000"], ["74173.00", "0.050"]]}}
{"local_ts": 1773486546709, "server_ts": 1773486546676, "data": {"e": "depthUpdate", "E": 1773486546677, "T": 1773486546676, "s": "BTCUSDT", "U": 10109511837581, "u": 10109511842700, "pu": 10109511837389, "b": [["5000.00", "101.418"], ["7062.20", "0.028"], ["20122.00", "0.200"], ["20222.00", "2.470"], ["20322.00", "0.330"], ["33000.00", "3.785"], ["69209.60", "0.012"], ["69560.60", "0.000"], ["69598.00", "5.902"], ["69915.80", "3.968"], ["69915.90", "0.000"], ["70268.90", "3.693"], ["70276.20", "0.120"], ["70563.00", "0.936"], ["70585.40", "0.066"], ["70586.00", "1.996"], ["70588.50", "0.451"], ["70596.10", "0.028"], ["70606.00", "0.008"], ["70610.30", "0.158"], ["70611.40", "0.001"], ["70611.60", "0.000"], ["70612.00", "0.004"], ["70612.30", "0.000"], ["70612.80", "1.110"], ["70613.20", "0.151"], ["70614.60", "0.216"], ["70615.00", "0.007"], ["70619.60", "0.005"], ["70622.00", "3.891"]], "a": [["70622.10", "3.373"], ["70629.10", "0.003"], ["70629.60", "0.002"], ["70631.00", "0.005"], ["70632.30", "0.015"], ["70632.70", "0.001"], ["70637.30", "0.004"], ["70640.60", "0.435"], ["70641.50", "0.101"], ["70641.90", "0.007"], ["70649.10", "0.001"], ["70649.60", "0.009"], ["70650.50", "0.017"], ["70651.20", "0.070"], ["70652.80", "0.005"], ["70653.80", "0.000"], ["70653.90", "0.424"], ["70655.00", "0.267"], ["70655.10", "0.922"], ["70656.60", "0.171"], ["70657.10", "0.280"], ["70657.30", "0.135"], ["70658.40", "0.858"], ["70658.60", "0.002"], ["70664.50", "0.388"], ["70664.90", "0.018"], ["70666.10", "0.061"], ["70667.40", "0.758"], ["70668.70", "0.003"], ["70683.40", "0.087"], ["70688.00", "1.346"], ["70745.50", "0.171"], ["70748.50", "0.190"], ["70754.20", "0.168"], ["70757.80", "0.085"], ["70825.50", "0.000"], ["70974.90", "1.093"], ["70975.20", "3.797"], ["71328.30", "1.450"], ["71673.90", "0.000"], ["72034.50", "0.020"], ["72036.10", "0.000"], ["74169.90", "0.002"]]}}
{"local_ts": 1773486548115, "server_ts": 1773486547593, "data": {"e": "depthUpdate", "E": 1773486547595, "T": 1773486547593, "s": "BTCUSDT", "U": 10109511897611, "u": 10109511906187, "pu": 10109511897371, "b": [["5000.00", "101.418"], ["7062.20", "0.000"], ["20122.00", "2.170"], ["20222.00", "0.830"], ["56498.00", "0.000"], ["67075.60", "0.002"], ["67115.20", "0.004"], ["69396.60", "0.720"], ["69538.00", "1.007"], ["69562.20", "0.000"], ["70415.80", "0.000"], ["70556.20", "0.099"], ["70559.80", "0.535"], ["70565.60", "0.024"], ["70574.70", "0.004"], ["70574.90", "0.052"], ["70579.70", "0.057"], ["70591.50", "0.011"], ["70592.10", "0.003"], ["70592.20", "0.000"], ["70592.80", "0.090"], ["70592.90", "0.009"], ["70597.30", "0.512"], ["70608.10", "0.399"], ["70608.80", "0.030"], ["70613.20", "0.394"], ["70614.70", "0.004"], ["70615.00", "0.518"], ["70616.60", "0.372"], ["70617.80", "0.105"], ["70619.40", "0.003"]], "a": [["70655.90", "0.003"], ["70846.20", "0.212"], ["71000.00", "86.279"], ["71054.90", "0.042"], ["71328.30", "1.450"], ["71358.00", "0.326"], ["74155.10", "0.000"]]}}
{"local_ts": 1773486549154, "server_ts": 1773486549124, "data": {"e": "depthUpdate", "E": 1773486549125, "T": 1773486549124, "s": "BTCUSDT", "U": 10109511982276, "u": 10109511987219, "pu": 10109511982173, "b": [["5000.00", "101.418"], ["7062.20", "0.028"], ["20122.00", "0.240"], ["20422.00", "0.240"], ["20522.00", "2.520"], ["56412.20", "0.000"], ["69200.00", "38.714"], ["69749.70", "0.715"], ["69915.80", "5.039"], ["70441.90", "0.004"], ["70449.00", "0.159"], ["70490.20", "8.029"], ["70574.80", "0.855"], ["70575.00", "0.018"], ["70602.30", "0.076"], ["70603.20", "0.002"], ["70609.30", "0.011"], ["70615.00", "0.546"], ["70615.10", "0.397"], ["70615.30", "0.088"], ["70615.50", "0.185"], ["70617.00", "0.002"], ["70622.00", "3.886"]], "a": [["70622.10", "3.173"], ["70627.80", "0.008"], ["70629.10", "0.062"], ["70631.70", "0.004"], ["70632.00", "0.008"], ["70721.00", "0.126"], ["70753.00", "2.295"], ["70755.90", "9.369"], ["70886.90", "0.108"], ["71328.30", "1.590"], ["71699.10", "0.417"], ["74174.30", "0.002"], ["89523.20", "0.000"]]}}
{"local_ts": 1773486550176, "server_ts": 1773486550144, "data": {"e": "depthUpdate", "E": 1773486550147, "T": 1773486550144, "s": "BTCUSDT", "U": 10109512026802, "u": 10109512030668, "pu": 10109512026652, "b": [["1000.00", "26.142"], ["5000.00", "101.418"], ["7062.20", "0.000"], ["20322.00", "0.090"], ["20422.00", "2.370"], ["20522.00", "0.540"], ["33000.00", "3.785"], ["69562.70", "0.017"], ["69718.00", "0.075"], ["69915.80", "5.053"], ["70268.90", "3.693"], ["70449.00", "0.000"], ["70452.50", "0.676"], ["70508.00", "7.466"], ["70520.90", "0.277"], ["70521.60", "2.291"], ["70522.30", "0.053"], ["70523.00", "0.086"], ["70574.30", "0.008"], ["70574.40", "0.217"], ["70588.50", "0.527"], ["70588.60", "0.199"], ["70590.50", "0.054"], ["70590.70", "0.005"], ["70593.80", "0.635"], ["70603.40", "0.007"], ["70604.40", "1.203"], ["70608.30", "0.009"], ["70609.00", "0.014"], ["70609.30", "0.011"], ["70613.10", "0.172"], ["70613.20", "0.179"], ["70615.20", "0.184"], ["70615.30", "0.442"], ["70616.60", "0.372"], ["70616.70", "0.154"], ["70617.80", "0.107"], ["70619.40", "0.003"], ["70622.00", "3.595"]], "a": [["70622.10", "3.444"], ["70626.20", "0.005"], ["70627.80", "0.006"], ["70636.10", "0.005"], ["70644.60", "0.003"], ["70644.90", "0.849"], ["70646.40", "0.080"], ["70654.80", "0.845"], ["70655.50", "1.167"], ["70664.50", "0.254"], ["70704.40", "0.125"], ["71328.30", "1.590"], ["71329.40", "0.016"], ["71469.60", "4.163"], ["71527.10", "1.696"], ["71615.80", "0.000"], ["74158.20", "0.002"], ["74188.00", "2.391"], ["89523.20", "0.000"]]}}
{"local_ts": 1773486551197, "server_ts": 1773486551166, "data": {"e": "depthUpdate", "E": 1773486551167, "T": 1773486551166, "s": "BTCUSDT", "U": 10109512076000, "u": 10109512079642, "pu": 10109512075875, "b": [["1000.00", "26.142"], ["5000.00", "101.418"], ["7062.20", "0.000"], ["20322.00", "2.100"], ["20422.00", "0.900"], ["67085.70", "0.002"], ["67090.90", "0.010"], ["67091.00", "37.254"], ["68503.30", "0.005"], ["68858.60", "0.000"], ["69915.80", "5.074"], ["69955.80", "1.781"], ["70461.40", "13.103"], ["70468.40", "0.160"], ["70475.60", "0.000"], ["70505.50", "0.000"], ["70520.90", "0.277"], ["70521.50", "0.963"], ["70521.60", "2.248"], ["70522.30", "0.000"], ["70522.60", "0.515"], ["70523.30", "6.783"], ["70561.30", "3.612"], ["70570.00", "1.208"], ["70570.60", "8.505"], ["70571.40", "0.215"], ["70573.00", "2.514"], ["70575.00", "0.018"], ["70575.20", "0.005"], ["70585.10", "1.869"], ["70588.60", "0.199"], ["70615.00", "0.546"]], "a": [["70622.10", "3.195"], ["70626.20", "0.003"], ["70629.10", "0.067"], ["70660.90", "0.172"], ["70663.20", "1.943"], ["70687.10", "3.853"], ["70724.70", "2.472"], ["70725.60", "7.200"], ["70781.90", "0.000"], ["70787.60", "3.425"], ["70789.20", "13.604"], ["70887.70", "0.005"], ["71328.30", "1.590"], ["71373.00", "1.529"], ["71641.10", "1.670"], ["71716.70", "16.094"], ["74165.30", "0.053"], ["74172.80", "0.000"], ["74177.20", "0.000"], ["89523.20", "0.000"]]}}
{"local_ts": 1773486552218, "server_ts": 1773486552188, "data": {"e": "depthUpdate", "E": 1773486552189, "T": 1773486552188, "s": "BTCUSDT", "U": 10109512112771, "u": 10109512116518, "pu": 10109512112724, "b": [["5000.00", "101.418"], ["7062.20", "0.000"], ["20222.00", "1.660"], ["20322.00", "1.340"], ["33000.00", "3.789"], ["69915.80", "5.090"], ["70057.00", "0.293"], ["70572.60", "1.085"], ["70575.40", "0.005"], ["70575.50", "0.003"], ["70595.60", "0.325"], ["70607.90", "0.006"], ["70615.00", "0.548"], ["70615.60", "0.210"], ["70617.90", "0.011"], ["70619.60", "0.023"], ["70622.00", "4.330"]], "a": [["70622.10", "3.101"], ["70622.20", "0.130"], ["70629.10", "0.065"], ["70630.70", "0.004"], ["70636.00", "0.028"], ["70638.30", "0.526"], ["70638.90", "0.006"], ["70639.70", "0.007"], ["70639.80", "0.220"], ["70640.70", "0.513"], ["70641.10", "0.016"], ["70642.30", "0.005"], ["70643.80", "0.000"], ["70645.00", "0.060"], ["70645.10", "0.002"], ["70650.40", "0.043"], ["70654.10", "0.204"], ["70655.30", "0.555"], ["70664.50", "0.254"], ["70845.70", "0.017"], ["71328.20", "0.018"], ["71328.30", "2.990"], ["71436.70", "0.004"], ["72034.50", "0.008"], ["74184.70", "0.002"], ["89523.20", "0.000"]]}}
{"local_ts": 1773486553238, "server_ts": 1773486553208, "data": {"e": "depthUpdate", "E": 1773486553209, "T": 1773486553208, "s": "BTCUSDT", "U": 10109512153450, "u": 10109512158166, "pu": 10109512153403, "b": [["1000.00", "26.142"], ["5000.00", "101.418"], ["7062.20", "0.056"], ["20122.00", "1.200"], ["20222.00", "1.800"], ["67090.90", "0.010"], ["67091.00", "37.252"], ["69915.80", "5.088"], ["69993.40", "0.035"], ["70268.90", "3.693"], ["70375.00", "0.273"], ["70528.70", "0.019"], ["70528.80", "0.000"], ["70535.70", "0.081"], ["70535.80", "0.000"], ["70542.80", "0.071"], ["70542.90", "0.431"], ["70561.30", "3.615"], ["70562.10", "0.077"], ["70572.00", "0.010"], ["70573.00", "1.344"], ["70574.50", "8.716"], ["70575.50", "0.005"], ["70575.70", "0.003"], ["70580.90", "0.098"], ["70581.00", "0.288"], ["70590.40", "0.002"], ["70601.50", "0.007"], ["70602.90", "0.268"], ["70603.80", "0.092"], ["70604.40", "0.000"], ["70605.90", "1.208"], ["70607.30", "0.000"], ["70607.90", "0.004"], ["70609.30", "0.014"], ["70609.50", "0.144"], ["70610.00", "0.589"], ["70612.10", "0.001"], ["70612.20", "0.028"], ["70612.30", "0.003"], ["70612.80", "1.111"], ["70612.90", "1.111"], ["70614.10", "0.052"], ["70615.50", "0.011"], ["70617.10", "0.007"], ["70617.90", "0.001"], ["70619.40", "0.003"], ["70619.60", "0.023"], ["70620.10", "0.002"], ["70620.80", "0.058"], ["70622.00", "9.526"]], "a": [["70622.10", "1.773"], ["70624.00", "0.002"], ["70625.40", "0.002"], ["70626.30", "0.000"], ["70626.70", "0.000"], ["70627.00", "0.000"], ["70627.30", "0.005"], ["70627.70", "0.018"], ["70631.10", "0.011"], ["70635.40", "0.005"], ["70636.30", "0.280"], ["70637.00", "0.044"], ["70637.10", "0.016"], ["70637.70", "0.000"], ["70638.90", "0.154"], ["70639.70", "0.000"], ["70639.90", "0.000"], ["70640.60", "0.271"], ["70640.70", "0.511"], ["70640.80", "0.004"], ["70641.20", "0.007"], ["70641.30", "0.012"], ["70641.40", "0.080"], ["70641.60", "0.007"], ["70641.80", "0.009"], ["70642.80", "1.179"], ["70643.50", "0.020"], ["70644.60", "0.144"], ["70645.70", "0.000"], ["70646.30", "0.001"], ["70646.50", "0.015"], ["70646.70", "0.003"], ["70647.30", "0.004"], ["70648.30", "0.000"], ["70648.50", "0.009"], ["70648.80", "0.000"], ["70649.30", "0.636"], ["70650.00", "0.662"], ["70650.90", "0.000"], ["70651.60", "0.000"], ["70653.10", "0.075"], ["70653.90", "0.424"], ["70654.90", "0.398"], ["70657.00", "0.003"], ["70657.70", "0.247"], ["70658.40", "0.843"], ["70659.30", "0.052"], ["70666.60", "0.429"], ["70670.10", "0.067"], ["70670.20", "0.125"], ["70670.40", "0.002"], ["70686.70", "0.003"], ["70688.50", "8.486"], ["70698.40", "0.405"], ["70705.40", "0.205"], ["70712.50", "0.072"], ["70719.50", "0.073"], ["71328.30", "4.390"], ["74174.40", "0.000"], ["89523.20", "0.000"]]}}
{"local_ts": 1773486554266, "server_ts": 1773486554229, "data": {"e": "depthUpdate", "E": 1773486554231, "T": 1773486554229, "s": "BTCUSDT", "U": 10109512203717, "u": 10109512211260, "pu": 10109512203683, "b": [["5000.00", "101.418"], ["7062.20", "0.000"], ["7062.80", "0.056"], ["20122.00", "2.240"], ["20127.30", "0.000"], ["20527.30", "0.440"], ["67079.90", "0.005"], ["67084.20", "0.015"], ["69209.60", "0.061"], ["69921.00", "0.046"], ["70326.50", "0.022"], ["70429.60", "0.000"], ["70450.80", "0.054"], ["70453.10", "0.090"], ["70468.40", "0.039"], ["70480.60", "0.203"], ["70543.40", "0.000"], ["70548.90", "0.080"], ["70552.90", "0.560"], ["70558.80", "1.825"], ["70563.00", "1.047"], ["70565.30", "0.093"], ["70567.10", "0.003"], ["70569.80", "0.002"], ["70572.70", "0.385"], ["70574.60", "0.100"], ["70576.80", "0.168"], ["70577.50", "0.004"], ["70577.90", "0.413"], ["70578.30", "0.027"], ["70581.40", "0.032"], ["70582.20", "0.408"], ["70582.30", "0.698"], ["70584.60", "0.618"], ["70588.30", "0.531"], ["70588.60", "0.015"], ["70588.70", "0.011"], ["70589.10", "0.134"], ["70589.20", "0.849"], ["70590.40", "0.002"], ["70592.00", "0.355"], ["70592.40", "0.357"], ["70594.20", "0.004"], ["70594.30", "0.000"], ["70594.90", "0.667"], ["70595.00", "0.057"], ["70595.60", "0.275"], ["70595.70", "1.105"], ["70596.30", "0.360"], ["70596.40", "0.187"], ["70597.00", "0.002"], ["70597.10", "0.022"], ["70597.70", "0.091"], ["70597.80", "0.004"], ["70598.10", "0.023"], ["70599.00", "0.244"], ["70607.60", "0.002"], ["70609.20", "0.247"], ["70610.10", "0.016"], ["70610.50", "0.511"], ["70610.70", "0.022"], ["70613.10", "0.002"], ["70613.20", "0.004"], ["70613.70", "0.128"], ["70615.10", "1.868"], ["70616.70", "0.005"], ["70617.20", "0.027"], ["70617.80", "0.008"], ["70618.90", "0.004"], ["70619.00", "0.163"], ["70619.70", "0.002"], ["70620.00", "0.025"], ["70620.50", "0.637"], ["70621.20", "0.006"], ["70621.40", "0.018"], ["70622.00", "1.560"], ["70622.10", "0.362"], ["70622.40", "0.005"], ["70622.80", "0.020"], ["70624.10", "0.000"], ["70626.20", "0.000"], ["70626.30", "0.012"], ["70626.40", "0.001"], ["70626.50", "0.150"], ["70626.60", "0.029"], ["70626.70", "0.002"], ["70627.30", "15.367"]], "a": [["70627.40", "1.742"], ["70631.10", "0.003"], ["70633.10", "0.105"], ["70633.70", "0.005"], ["70634.40", "0.134"], ["70634.60", "0.320"], ["70634.70", "0.001"], ["70635.30", "0.009"], ["70635.90", "0.007"], ["70636.00", "0.007"], ["70637.50", "0.001"], ["70637.60", "0.208"], ["70637.70", "0.000"], ["70637.80", "0.149"], ["70638.00", "0.062"], ["70638.50", "0.005"], ["70639.10", "0.000"], ["70639.30", "0.000"], ["70640.30", "0.653"], ["70641.00", "0.016"], ["70642.10", "0.003"], ["70643.10", "0.215"], ["70643.30", "0.108"], ["70643.70", "0.071"], ["70646.50", "0.000"], ["70646.60", "0.015"], ["70649.60", "0.516"], ["70649.90", "0.004"], ["70650.00", "0.153"], ["70650.30", "0.028"], ["70650.70", "0.000"], ["70650.80", "0.040"], ["70651.00", "0.006"], ["70651.10", "1.172"], ["70651.20", "0.000"], ["70651.40", "0.005"], ["70651.50", "0.000"], ["70651.70", "0.003"], ["70651.80", "0.077"], ["70652.40", "0.091"], ["70652.50", "0.021"], ["70653.10", "0.516"], ["70653.20", "0.454"], ["70653.50", "0.007"], ["70653.60", "0.143"], ["70653.80", "0.002"], ["70653.90", "0.327"], ["70654.10", "0.204"], ["70654.50", "0.696"], ["70654.60", "0.003"], ["70655.20", "0.006"], ["70655.30", "0.557"], ["70655.50", "0.049"], ["70656.00", "0.058"], ["70656.20", "0.637"], ["70656.90", "0.047"], ["70658.40", "0.843"], ["70659.60", "0.729"], ["70659.90", "0.006"], ["70660.20", "0.291"], ["70661.40", "0.007"], ["70661.50", "0.986"], ["70661.70", "0.042"], ["70664.80", "0.096"], ["70670.50", "0.004"], ["70671.00", "0.088"], ["70671.50", "0.002"], ["70671.60", "0.087"], ["70671.80", "0.048"], ["70673.30", "0.302"], ["70674.60", "0.048"], ["70675.30", "0.003"], ["70676.00", "0.312"], ["70676.70", "0.070"], ["70679.70", "0.081"], ["70683.60", "0.031"], ["70685.80", "0.101"], ["70691.50", "0.019"], ["70692.40", "0.602"], ["70693.50", "0.004"], ["70693.90", "0.677"], ["70698.30", "0.283"], ["70698.60", "0.377"], ["70714.10", "0.721"], ["70766.00", "0.000"], ["70796.40", "2.913"], ["70799.90", "0.000"], ["70807.50", "0.099"], ["70808.40", "0.054"], ["70840.80", "0.005"], ["70846.40", "0.000"], ["70881.70", "0.000"], ["71333.70", "0.002"], ["71485.70", "4.689"], ["89523.20", "0.000"]]}}
{"local_ts": 1773486555281, "server_ts": 1773486555250, "data": {"e": "depthUpdate", "E": 1773486555251, "T": 1773486555250, "s": "BTCUSDT", "U": 10109512265787, "u": 10109512270811, "pu": 10109512265671, "b": [["1000.00", "26.142"], ["5000.00", "101.438"], ["7062.80", "0.056"], ["20122.00", "0.050"], ["20427.50", "0.360"], ["20527.30", "1.110"], ["20527.50", "1.160"], ["67073.60", "0.000"], ["67082.70", "0.006"], ["69749.80", "0.715"], ["69921.20", "0.000"], ["70274.20", "0.000"], ["70340.30", "0.014"], ["70345.80", "0.008"], ["70516.00", "0.349"], ["70516.20", "0.018"], ["70521.70", "0.002"], ["70528.70", "0.074"], ["70529.30", "0.043"], ["70529.70", "0.055"], ["70538.70", "3.668"], ["70542.50", "0.664"], ["70545.70", "0.074"], ["70551.20", "0.039"], ["70552.80", "1.052"], ["70579.00", "0.014"], ["70579.30", "0.016"], ["70602.60", "0.029"], ["70604.40", "0.012"], ["70608.10", "0.274"], ["70611.80", "0.004"], ["70613.20", "0.020"], ["70616.60", "1.205"], ["70618.60", "0.001"], ["70625.10", "0.002"]], "a": [["70632.60", "0.002"], ["70648.00", "0.058"], ["70648.30", "0.021"], ["70652.80", "0.005"], ["70658.90", "0.010"], ["70668.70", "0.003"], ["70670.60", "0.005"], ["70670.80", "0.000"], ["70677.00", "0.231"], ["70687.70", "0.000"], ["70688.90", "0.004"], ["70702.40", "0.025"], ["70702.80", "0.025"], ["70703.50", "0.038"], ["70710.90", "0.049"], ["70716.20", "0.074"], ["70722.70", "2.103"], ["70723.30", "0.072"], ["70727.90", "0.000"], ["70730.30", "0.076"], ["70733.40", "0.047"], ["70904.70", "0.000"], ["70910.20", "0.004"], ["71333.90", "0.000"], ["89523.20", "0.000"]]}}
{"local_ts": 1773486556306, "server_ts": 1773486556274, "data": {"e": "depthUpdate", "E": 1773486556275, "T": 1773486556274, "s": "BTCUSDT", "U": 10109512320499, "u": 10109512331662, "pu": 10109512320454, "b": [["1000.00", "26.142"], ["5000.00", "101.418"], ["7062.80", "0.028"], ["20327.50", "0.170"], ["20329.20", "0.010"], ["20329.90", "0.020"], ["20427.50", "2.430"], ["20429.90", "0.040"], ["20527.30", "0.330"], ["40000.00", "41.317"], ["67079.90", "0.003"], ["69629.90", "0.016"], ["69648.10", "0.002"], ["69658.00", "0.432"], ["69659.90", "0.000"], ["69662.40", "0.008"], ["69663.90", "0.071"], ["69921.20", "0.000"], ["69922.00", "0.084"], ["69922.90", "0.002"], ["69923.40", "0.259"], ["69923.60", "3.596"], ["70028.70", "0.000"], ["70230.10", "0.084"], ["70288.50", "0.000"], ["70292.00", "0.008"], ["70305.00", "0.188"], ["70331.20", "0.000"], ["70331.30", "0.112"], ["70452.60", "0.834"], ["70453.10", "0.090"], ["70454.50", "0.000"], ["70460.40", "0.083"], ["70467.50", "0.161"], ["70471.90", "7.560"], ["70472.10", "0.597"], ["70474.50", "0.008"], ["70485.10", "0.039"], ["70492.00", "0.000"], ["70505.30", "0.511"], ["70506.60", "0.341"], ["70508.10", "1.664"], ["70508.70", "0.005"], ["70522.20", "0.006"], ["70530.80", "0.042"], ["70531.10", "0.002"], ["70537.30", "0.335"], ["70540.80", "0.044"], ["70542.50", "0.920"], ["70544.80", "1.293"], ["70545.10", "0.104"], ["70546.90", "0.142"], ["70551.40", "0.004"], ["70553.20", "0.959"], ["70558.90", "0.006"], ["70561.70", "0.552"], ["70569.10", "3.528"], ["70569.40", "0.005"], ["70569.80", "0.399"], ["70571.40", "0.214"], ["70573.60", "0.002"], ["70574.20", "0.000"], ["70577.50", "0.002"], ["70577.60", "0.796"], ["70578.50", "0.200"], ["70579.50", "0.008"], ["70579.60", "0.021"], ["70579.80", "0.008"], ["70580.00", "1.231"], ["70580.10", "0.022"], ["70580.20", "0.067"], ["70582.60", "0.070"], ["70582.80", "0.070"], ["70582.90", "0.000"], ["70583.20", "0.132"], ["70583.40", "0.009"], ["70583.50", "0.201"], ["70583.70", "0.000"], ["70583.80", "0.189"], ["70583.90", "0.187"], ["70584.00", "0.358"], ["70584.90", "0.409"], ["70585.10", "0.005"], ["70585.20", "0.007"], ["70585.30", "0.344"], ["70585.60", "0.874"], ["70585.80", "0.391"], ["70585.90", "0.000"], ["70586.80", "0.085"], ["70587.80", "0.872"], ["70588.40", "8.773"], ["70588.50", "0.539"], ["70588.60", "0.069"], ["70589.10", "0.004"], ["70590.20", "0.139"], ["70590.60", "0.022"], ["70590.90", "0.069"], ["70591.90", "0.003"], ["70592.10", "0.000"], ["70592.80", "0.921"], ["70592.90", "1.887"], ["70593.10", "0.108"], ["70593.50", "0.529"], ["70593.60", "0.086"], ["70593.80", "0.223"], ["70594.60", "0.488"], ["70594.70", "0.071"], ["70595.70", "1.105"], ["70595.90", "0.057"], ["70596.10", "0.857"], ["70596.20", "0.000"], ["70596.30", "0.008"], ["70596.40", "0.954"], ["70596.50", "0.000"], ["70596.90", "0.000"], ["70597.30", "0.526"], ["70597.40", "0.087"], ["70597.90", "0.663"], ["70598.10", "0.086"], ["70599.00", "0.054"], ["70600.10", "0.028"], ["70600.50", "0.020"], ["70601.20", "0.002"], ["70601.30", "0.004"], ["70601.90", "0.002"], ["70602.00", "0.844"], ["70602.50", "0.518"], ["70602.60", "0.012"], ["70603.60", "0.000"], ["70604.30", "0.025"], ["70604.80", "0.311"], ["70604.90", "0.000"], ["70605.40", "0.008"], ["70605.90", "0.003"], ["70606.10", "0.307"], ["70606.20", "0.003"], ["70606.30", "0.000"], ["70606.60", "0.048"], ["70606.70", "0.050"], ["70606.80", "0.019"], ["70606.90", "0.021"], ["70607.40", "0.000"], ["70607.60", "0.640"], ["70607.70", "0.007"], ["70607.90", "0.292"], ["70608.10", "0.281"], ["70608.30", "0.008"], ["70608.50", "0.010"], ["70610.20", "0.000"], ["70610.30", "0.450"], ["70610.50", "0.553"], ["70611.00", "0.004"], ["70611.10", "0.003"], ["70611.90", "0.496"], ["70612.20", "0.030"], ["70612.30", "0.052"], ["70612.70", "0.681"], ["70613.00", "0.376"], ["70613.10", "0.008"], ["70613.20", "0.016"], ["70613.30", "0.038"], ["70613.50", "0.029"], ["70613.60", "0.277"], ["70613.80", "0.405"], ["70613.90", "0.254"], ["70614.50", "0.000"], ["70614.60", "0.006"], ["70615.20", "0.015"], ["70615.30", "0.086"], ["70615.50", "0.080"], ["70616.10", "0.056"], ["70616.30", "0.070"], ["70616.40", "0.005"], ["70616.60", "0.002"], ["70617.00", "0.153"], ["70617.20", "0.299"], ["70617.30", "0.004"], ["70617.50", "0.060"], ["70617.60", "0.005"], ["70617.80", "0.008"], ["70617.90", "0.056"], ["70618.10", "0.005"], ["70618.20", "0.511"], ["70618.50", "0.511"], ["70619.00", "0.391"], ["70619.10", "0.008"], ["70619.30", "0.014"], ["70619.40", "0.011"], ["70619.60", "0.464"], ["70619.70", "0.002"], ["70619.80", "0.458"], ["70619.90", "0.501"], ["70620.00", "0.360"], ["70620.30", "0.151"], ["70620.40", "0.006"], ["70620.50", "0.000"], ["70620.60", "0.125"], ["70620.70", "0.108"], ["70620.90", "1.209"], ["70621.20", "0.006"], ["70621.30", "0.056"], ["70621.60", "0.054"], ["70621.70", "0.001"], ["70621.80", "0.005"], ["70622.00", "1.324"], ["70622.10", "0.008"], ["70622.30", "0.003"], ["70622.40", "0.001"], ["70622.50", "0.003"], ["70622.60", "0.001"], ["70622.80", "0.028"], ["70622.90", "0.295"], ["70623.10", "0.147"], ["70623.20", "0.002"], ["70623.30", "0.005"], ["70623.40", "0.004"], ["70623.70", "0.004"], ["70623.80", "0.001"], ["70623.90", "0.011"], ["70624.10", "0.009"], ["70624.20", "0.009"], ["70624.30", "0.011"], ["70624.40", "0.018"], ["70624.50", "0.299"], ["70624.80", "0.004"], ["70624.90", "0.012"], ["70625.00", "0.006"], ["70625.10", "0.018"], ["70625.50", "0.019"], ["70625.70", "0.007"], ["70625.90", "0.637"], ["70626.10", "0.007"], ["70626.30", "0.000"], ["70626.60", "0.003"], ["70626.90", "0.003"], ["70627.10", "0.000"], ["70627.20", "0.084"], ["70627.30", "0.037"], ["70627.40", "0.003"], ["70627.50", "10.492"], ["70627.60", "0.140"], ["70627.70", "0.002"], ["70627.80", "0.080"], ["70627.90", "0.511"], ["70628.00", "0.003"], ["70628.10", "0.000"], ["70628.20", "0.001"], ["70628.30", "0.000"], ["70628.40", "0.002"], ["70628.60", "0.000"], ["70628.70", "0.000"], ["70628.80", "0.002"], ["70628.90", "0.000"], ["70629.00", "0.212"], ["70629.10", "0.001"], ["70629.20", "0.452"], ["70629.30", "1.447"], ["70629.40", "0.000"], ["70629.50", "0.021"], ["70629.60", "0.001"], ["70629.70", "7.182"], ["70629.80", "0.024"], ["70629.90", "15.872"]], "a": [["70627.60", "0.000"], ["70627.70", "0.000"], ["70627.80", "0.000"], ["70627.90", "0.000"], ["70628.00", "0.000"], ["70628.10", "0.000"], ["70628.20", "0.000"], ["70628.40", "0.000"], ["70628.50", "0.000"], ["70628.70", "0.000"], ["70628.80", "0.000"], ["70629.00", "0.000"], ["70629.20", "0.000"], ["70629.30", "0.000"], ["70629.50", "0.000"], ["70629.70", "0.000"], ["70629.80", "0.000"], ["70629.90", "0.000"], ["70630.00", "0.888"], ["70630.10", "0.004"], ["70630.30", "0.002"], ["70630.60", "0.000"], ["70631.00", "0.003"], ["70631.80", "0.003"], ["70632.10", "0.002"], ["70632.20", "0.002"], ["70632.30", "0.000"], ["70632.50", "0.003"], ["70632.60", "0.000"], ["70632.70", "0.001"], ["70632.80", "0.002"], ["70633.20", "0.003"], ["70633.50", "0.007"], ["70633.70", "0.001"], ["70634.50", "0.008"], ["70634.60", "0.095"], ["70634.70", "0.056"], ["70634.90", "0.003"], ["70635.00", "0.015"], ["70635.30", "0.012"], ["70635.50", "0.000"], ["70635.80", "0.006"], ["70635.90", "0.000"], ["70636.40", "0.021"], ["70637.10", "0.012"], ["70637.20", "0.001"], ["70637.40", "0.005"], ["70637.50", "0.001"], ["70637.60", "0.006"], ["70637.70", "0.000"], ["70637.90", "0.011"], ["70638.20", "0.034"], ["70638.50", "0.005"], ["70638.60", "0.001"], ["70639.00", "0.003"], ["70639.10", "0.000"], ["70639.50", "0.003"], ["70639.60", "0.004"], ["70639.70", "0.000"], ["70639.80", "0.013"], ["70639.90", "0.003"], ["70640.00", "0.456"], ["70640.10", "0.006"], ["70640.30", "0.071"], ["70640.40", "0.004"], ["70640.50", "0.055"], ["70640.60", "0.125"], ["70641.00", "0.002"], ["70641.20", "0.000"], ["70641.40", "0.000"], ["70641.80", "0.062"], ["70642.00", "0.009"], ["70642.10", "0.000"], ["70642.20", "0.061"], ["70642.80", "0.005"], ["70643.30", "0.118"], ["70644.10", "0.039"], ["70644.60", "0.712"], ["70644.70", "0.447"], ["70644.80", "0.002"], ["70645.40", "0.037"], ["70645.60", "0.007"], ["70646.50", "0.000"], ["70646.60", "0.150"], ["70646.80", "0.165"], ["70646.90", "0.014"], ["70647.30", "0.003"], ["70647.40", "0.074"], ["70647.50", "1.026"], ["70647.60", "0.022"], ["70647.70", "0.007"], ["70648.20", "0.009"], ["70648.70", "0.003"], ["70648.80", "0.000"], ["70649.50", "0.005"], ["70649.60", "0.003"], ["70649.70", "1.581"], ["70649.80", "0.003"], ["70650.10", "0.001"], ["70650.20", "0.020"], ["70650.90", "0.002"], ["70651.00", "0.285"], ["70651.60", "0.003"], ["70651.70", "0.003"], ["70651.80", "0.005"], ["70652.30", "0.004"], ["70652.80", "0.012"], ["70652.90", "0.143"], ["70653.00", "0.203"], ["70653.60", "0.002"], ["70653.80", "0.000"], ["70654.00", "0.000"], ["70654.30", "0.045"], ["70654.40", "0.010"], ["70654.50", "0.698"], ["70654.90", "0.005"], ["70655.50", "0.101"], ["70655.70", "0.009"], ["70656.40", "1.226"], ["70656.50", "1.066"], ["70656.60", "0.032"], ["70656.70", "0.000"], ["70657.10", "0.282"], ["70657.20", "0.029"], ["70657.30", "0.125"], ["70657.40", "0.017"], ["70657.70", "0.010"], ["70657.80", "0.003"], ["70658.00", "0.735"], ["70658.10", "0.026"], ["70658.40", "0.843"], ["70658.50", "0.094"], ["70659.00", "0.003"], ["70659.20", "0.003"], ["70659.40", "0.002"], ["70659.50", "0.143"], ["70659.60", "0.040"], ["70659.70", "0.007"], ["70660.00", "0.106"], ["70660.10", "0.129"], ["70660.20", "0.203"], ["70660.30", "0.003"], ["70660.40", "0.003"], ["70661.00", "0.003"], ["70661.10", "0.636"], ["70661.60", "0.034"], ["70661.80", "0.008"], ["70662.30", "1.624"], ["70662.70", "0.017"], ["70662.90", "0.009"], ["70663.00", "0.013"], ["70663.10", "0.003"], ["70663.20", "0.012"], ["70663.60", "0.524"], ["70663.80", "0.007"], ["70664.00", "0.048"], ["70664.30", "0.100"], ["70664.40", "0.074"], ["70665.70", "0.015"], ["70665.90", "0.001"], ["70666.10", "0.236"], ["70666.70", "0.205"], ["70667.00", "0.008"], ["70668.20", "0.511"], ["70668.80", "0.103"], ["70669.50", "0.315"], ["70670.10", "0.082"], ["70670.20", "0.002"], ["70670.60", "0.026"], ["70670.80", "0.000"], ["70671.30", "0.007"], ["70671.90", "0.000"], ["70672.00", "1.280"], ["70672.20", "0.055"], ["70672.30", "0.020"], ["70672.50", "0.176"], ["70672.60", "0.602"], ["70672.90", "0.103"], ["70673.30", "0.347"], ["70673.70", "0.015"], ["70673.80", "1.931"], ["70674.50", "0.858"], ["70675.10", "0.029"], ["70675.60", "0.003"], ["70675.70", "0.004"], ["70675.80", "0.016"], ["70676.30", "0.528"], ["70676.50", "0.023"], ["70677.00", "0.231"], ["70677.20", "0.018"], ["70677.90", "0.008"], ["70678.30", "0.015"], ["70679.40", "0.605"], ["70679.50", "0.579"], ["70680.60", "0.263"], ["70680.80", "0.000"], ["70682.10", "0.002"], ["70682.20", "0.053"], ["70682.30", "0.000"], ["70683.30", "0.002"], ["70684.60", "0.006"], ["70686.50", "0.335"], ["70687.70", "0.057"], ["70689.60", "0.002"], ["70689.70", "0.217"], ["70689.80", "0.614"], ["70690.00", "3.726"], ["70692.10", "0.054"], ["70695.00", "0.253"], ["70696.40", "0.615"], ["70696.60", "5.153"], ["70699.20", "0.603"], ["70701.40", "0.008"], ["70701.50", "9.527"], ["70713.80", "0.046"], ["70713.90", "0.000"], ["70716.40", "0.011"], ["70718.00", "0.133"], ["70721.20", "0.038"], ["70722.60", "0.007"], ["70729.00", "0.000"], ["70735.20", "1.795"], ["70735.70", "0.000"], ["70737.60", "0.310"], ["70738.70", "0.270"], ["70738.90", "1.182"], ["70779.00", "0.001"], ["70799.50", "0.507"], ["70852.30", "0.000"], ["70887.80", "0.106"], ["70981.70", "0.007"], ["71009.30", "0.004"], ["71333.90", "0.037"], ["71334.10", "0.000"], ["71334.30", "0.000"], ["71335.60", "0.049"], ["71336.10", "0.356"], ["71336.30", "4.201"], ["71475.00", "0.029"], ["71610.80", "2.781"], ["71824.40", "0.000"], ["72034.50", "0.011"], ["73452.70", "0.005"], ["74797.00", "2.053"], ["89523.20", "0.000"]]}}
{"local_ts": 1773486557334, "server_ts": 1773486557294, "data": {"e": "depthUpdate", "E": 1773486557295, "T": 1773486557294, "s": "BTCUSDT", "U": 10109512428289, "u": 10109512436730, "pu": 10109512428176, "b": [["5000.00", "101.418"], ["7063.00", "0.280"], ["20229.90", "0.050"], ["20329.90", "2.140"], ["20427.50", "0.630"], ["33000.00", "3.785"], ["69561.90", "0.000"], ["69750.00", "9.182"], ["69923.60", "3.592"], ["70556.90", "0.522"], ["70582.80", "0.000"], ["70582.90", "0.085"], ["70588.60", "0.069"], ["70601.30", "0.056"], ["70604.20", "0.000"], ["70605.40", "0.010"], ["70610.00", "0.594"], ["70622.50", "0.003"], ["70622.90", "0.291"], ["70623.00", "0.861"], ["70625.10", "0.014"], ["70625.90", "0.013"], ["70626.80", "0.003"], ["70629.90", "17.531"]], "a": [["70630.00", "0.810"], ["70633.70", "0.001"], ["70637.00", "0.008"], ["70640.60", "0.199"], ["70643.20", "0.003"], ["70643.80", "0.003"], ["70644.90", "0.219"], ["70658.30", "0.000"], ["70672.20", "0.002"], ["70672.30", "0.090"], ["70694.70", "0.004"], ["70884.30", "0.111"], ["70887.80", "0.000"], ["71336.30", "4.199"], ["74165.50", "0.052"]]}}
{"local_ts": 1773486558352, "server_ts": 1773486558321, "data": {"e": "depthUpdate", "E": 1773486558323, "T": 1773486558321, "s": "BTCUSDT", "U": 10109512486248, "u": 10109512491111, "pu": 10109512486062, "b": [["1000.00", "26.142"], ["5000.00", "101.418"], ["7063.00", "0.280"], ["20229.90", "1.990"], ["20327.50", "0.100"], ["20329.20", "0.000"], ["20329.90", "0.910"], ["67074.50", "0.002"], ["67085.50", "0.022"], ["67098.00", "0.000"], ["68597.10", "0.005"], ["69574.50", "1.866"], ["69656.20", "0.015"], ["69923.60", "3.590"], ["70276.80", "0.015"], ["70582.80", "3.190"], ["70619.30", "0.011"], ["70622.40", "0.001"], ["70626.80", "0.003"]], "a": [["70639.10", "0.225"], ["70639.80", "0.004"], ["70639.90", "0.006"], ["70640.60", "0.196"], ["70727.00", "0.001"], ["70809.40", "0.000"], ["70821.00", "0.450"], ["70856.20", "0.011"], ["70884.30", "0.005"], ["71336.30", "4.199"], ["71654.10", "2.717"], ["71679.10", "0.000"], ["71866.00", "4.052"], ["71895.60", "3.306"]]}}
{"local_ts": 1773486559373, "server_ts": 1773486559344, "data": {"e": "depthUpdate", "E": 1773486559345, "T": 1773486559344, "s": "BTCUSDT", "U": 10109512583148, "u": 10109512590899, "pu": 10109512582968, "b": [["5000.00", "101.418"], ["7063.00", "0.252"], ["20129.90", "1.550"], ["20229.90", "1.450"], ["33000.00", "3.789"], ["67063.80", "0.009"], ["67091.00", "37.254"], ["68844.90", "2.611"], ["69923.60", "3.590"], ["70540.80", "0.061"], ["70540.90", "0.003"], ["70547.80", "0.833"], ["70547.90", "0.278"], ["70554.90", "0.077"], ["70555.00", "0.045"], ["70580.50", "0.081"], ["70583.10", "0.174"], ["70583.20", "0.047"], ["70583.80", "0.005"], ["70584.30", "0.085"], ["70584.40", "0.004"], ["70623.00", "0.861"], ["70626.80", "0.003"], ["70627.70", "0.018"], ["70629.90", "17.871"]], "a": [["70633.30", "0.001"], ["70633.60", "0.017"], ["70637.10", "0.012"], ["70637.80", "0.075"], ["70638.30", "0.150"], ["70639.10", "0.002"], ["70639.30", "0.009"], ["70639.80", "0.004"], ["70639.90", "0.006"], ["70646.40", "0.009"], ["70646.50", "0.000"], ["70646.80", "0.165"], ["70647.20", "0.026"], ["70649.00", "0.088"], ["70649.30", "0.163"], ["70649.90", "0.002"], ["70650.10", "0.001"], ["70650.40", "0.017"], ["70650.60", "0.015"], ["70651.00", "0.006"], ["70651.70", "0.003"], ["70651.90", "0.358"], ["70652.00", "0.518"], ["70652.10", "0.010"], ["70652.30", "0.004"], ["70652.40", "0.017"], ["70653.10", "0.535"], ["70653.30", "0.082"], ["70654.30", "0.045"], ["70654.40", "0.018"], ["70654.60", "0.003"], ["70654.70", "0.006"], ["70655.60", "0.045"], ["70655.90", "0.003"], ["70656.90", "0.034"], ["70657.20", "0.029"], ["70658.10", "0.155"], ["70658.30", "0.099"], ["70658.50", "0.094"], ["70659.70", "0.000"], ["70661.00", "0.016"], ["70662.20", "0.085"], ["70663.50", "0.000"], ["70672.50", "0.091"], ["70673.10", "0.000"], ["70673.70", "0.085"], ["70673.80", "1.931"], ["70690.00", "3.726"], ["70697.80", "0.177"], ["70700.20", "0.080"], ["70717.50", "0.776"], ["70717.70", "0.179"], ["70719.90", "0.005"], ["70724.60", "0.571"], ["70724.80", "0.212"], ["70730.40", "0.454"], ["70731.60", "0.074"], ["70731.80", "0.245"], ["70799.50", "0.408"], ["70821.00", "0.448"], ["71336.30", "4.199"], ["71718.10", "0.002"], ["72034.50", "0.005"], ["72039.90", "0.013"], ["72105.00", "0.000"], ["74161.50", "0.050"]]}}
{"local_ts": 1773486560397, "server_ts": 1773486560366, "data": {"e": "depthUpdate", "E": 1773486560367, "T": 1773486560366, "s": "BTCUSDT", "U": 10109512659081, "u": 10109512663489, "pu": 10109512659049, "b": [["1000.00", "26.142"], ["5000.00", "101.418"], ["7063.00", "0.252"], ["20129.90", "1.900"], ["20529.90", "1.100"], ["67087.20", "0.000"], ["69923.60", "3.590"], ["70276.80", "0.015"], ["70516.70", "0.067"], ["70528.30", "0.087"], ["70529.30", "0.220"], ["70530.00", "0.125"], ["70530.40", "0.053"], ["70531.10", "0.055"], ["70562.80", "0.096"], ["70584.00", "0.439"], ["70584.10", "0.158"], ["70615.80", "0.087"], ["70619.30", "0.014"], ["70619.90", "0.000"], ["70622.20", "0.832"], ["70622.90", "0.075"], ["70626.80", "0.003"]], "a": [["70637.00", "0.036"], ["70640.60", "0.216"], ["70643.70", "0.131"], ["70643.90", "0.001"], ["70648.00", "0.037"], ["70693.60", "0.005"], ["70693.90", "0.603"], ["70695.10", "0.010"], ["70700.20", "0.078"], ["70719.90", "0.003"], ["70731.10", "2.286"], ["70735.80", "0.801"], ["70738.90", "1.182"], ["70773.60", "0.158"], ["70776.00", "0.002"], ["70780.70", "1.221"], ["70783.10", "0.012"], ["70787.80", "0.101"], ["70790.20", "0.000"], ["70794.90", "0.104"], ["70797.30", "0.002"], ["70802.00", "0.024"], ["70804.40", "0.000"], ["70809.10", "0.009"], ["70811.50", "0.072"], ["70816.20", "0.007"], ["70818.60", "0.000"], ["70823.30", "0.023"], ["70825.70", "0.000"], ["74165.50", "0.052"]]}}
{"local_ts": 1773486561423, "server_ts": 1773486561392, "data": {"e": "depthUpdate", "E": 1773486561395, "T": 1773486561392, "s": "BTCUSDT", "U": 10109512708281, "u": 10109512713313, "pu": 10109512708216, "b": [["5000.00", "101.418"], ["7063.00", "0.252"], ["20129.90", "0.000"], ["20429.90", "0.670"], ["20529.90", "2.330"], ["67092.00", "0.004"], ["67097.30", "0.000"], ["69217.40", "0.008"], ["69627.00", "0.300"], ["69757.60", "0.716"], ["69923.60", "3.597"], ["69923.70", "2.142"], ["70294.50", "0.000"], ["70383.40", "0.006"], ["70540.40", "0.019"], ["70540.50", "0.016"], ["70547.40", "0.073"], ["70547.50", "0.202"], ["70554.50", "0.167"], ["70554.60", "0.086"], ["70596.60", "0.201"], ["70601.40", "1.097"], ["70615.50", "0.054"], ["70621.40", "0.018"], ["70621.50", "0.006"], ["70622.90", "0.008"], ["70626.80", "0.003"], ["70629.90", "17.263"]], "a": [["70630.00", "0.848"], ["70633.30", "0.001"], ["70634.30", "0.002"], ["70635.00", "0.024"], ["70636.10", "0.007"], ["70636.70", "0.003"], ["70637.00", "0.008"], ["70640.80", "0.061"], ["70640.90", "0.005"], ["70649.30", "0.148"], ["70649.60", "0.003"], ["70650.20", "0.000"], ["70650.70", "0.000"], ["70661.80", "0.107"], ["70693.60", "0.003"], ["70693.90", "0.601"], ["70702.80", "0.002"], ["70717.10", "0.150"], ["70717.20", "0.012"], ["70724.20", "0.073"], ["70724.30", "0.000"], ["70729.20", "0.005"], ["70731.20", "0.071"], ["70731.30", "0.004"], ["70773.60", "0.151"], ["70776.70", "0.007"], ["70780.70", "1.214"], ["70783.80", "0.518"], ["70787.80", "0.094"], ["70790.90", "0.100"], ["70794.90", "0.097"], ["70798.00", "0.009"], ["70799.50", "0.468"], ["70802.00", "0.017"], ["70805.10", "5.197"], ["70809.10", "0.002"], ["70812.20", "0.007"], ["70816.20", "0.000"], ["70819.30", "0.521"], ["70823.30", "0.016"], ["70826.40", "0.009"], ["71336.30", "4.199"], ["72039.90", "0.004"], ["72042.50", "0.027"], ["74181.50", "0.052"]]}}
{"local_ts": 1773486562446, "server_ts": 1773486562416, "data": {"e": "depthUpdate", "E": 1773486562417, "T": 1773486562416, "s": "BTCUSDT", "U": 10109512760267, "u": 10109512765267, "pu": 10109512760201, "b": [["1000.00", "26.142"], ["5000.00", "101.418"], ["7063.10", "0.056"], ["20330.90", "0.320"], ["20430.90", "1.680"], ["20529.90", "0.090"], ["67064.40", "0.002"], ["67084.70", "0.002"], ["67090.90", "0.006"], ["67091.00", "37.254"], ["67099.40", "0.002"], ["69924.60", "0.002"], ["70019.00", "0.054"], ["70276.80", "0.015"], ["70581.50", "0.099"], ["70588.80", "0.188"], ["70595.60", "0.312"], ["70596.60", "0.017"], ["70602.30", "0.032"], ["70613.80", "0.005"], ["70616.40", "0.056"], ["70619.00", "0.642"], ["70622.00", "1.417"], ["70623.90", "0.066"], ["70624.50", "1.343"], ["70625.50", "0.006"], ["70629.90", "0.048"], ["70630.90", "18.018"]], "a": [["70631.00", "1.506"], ["70631.10", "0.001"], ["70631.60", "0.002"], ["70631.70", "0.002"], ["70631.90", "0.000"], ["70632.20", "0.059"], ["70634.30", "0.023"], ["70638.00", "0.102"], ["70639.50", "0.221"], ["70639.70", "0.013"], ["70639.80", "0.006"], ["70646.50", "0.000"], ["70647.70", "0.007"], ["70647.90", "0.000"], ["70648.40", "0.000"], ["70648.50", "0.303"], ["70648.60", "0.021"], ["70649.90", "0.143"], ["70650.10", "0.016"], ["70653.10", "0.598"], ["70653.30", "0.002"], ["70661.10", "0.000"], ["70662.60", "0.017"], ["70666.30", "0.038"], ["70673.60", "0.057"], ["70673.70", "0.085"], ["70684.00", "0.099"], ["70702.80", "0.000"], ["70705.00", "0.038"], ["70725.90", "0.513"], ["70776.30", "0.007"], ["70776.70", "0.000"], ["70783.40", "0.007"], ["70783.80", "0.511"], ["70790.50", "0.036"], ["70790.90", "0.093"], ["70797.60", "0.012"], ["70798.00", "0.002"], ["70804.70", "0.012"], ["70805.10", "5.190"], ["70811.80", "0.010"], ["70812.20", "0.000"], ["70818.90", "0.007"], ["70819.30", "0.514"], ["70826.00", "0.023"], ["70826.40", "0.002"], ["71337.30", "0.000"], ["71584.40", "1.115"], ["71810.50", "0.002"], ["72042.50", "0.018"], ["72772.10", "0.607"]]}}
{"local_ts": 1773486563472, "server_ts": 1773486563440, "data": {"e": "depthUpdate", "E": 1773486563441, "T": 1773486563440, "s": "BTCUSDT", "U": 10109512799664, "u": 10109512803790, "pu": 10109512799527, "b": [["1000.00", "26.142"], ["5000.00", "101.418"], ["7063.10", "0.056"], ["20230.90", "0.170"], ["20330.90", "2.450"], ["20429.90", "0.290"], ["20430.60", "0.010"], ["20430.90", "0.080"], ["67065.10", "0.000"], ["68511.90", "0.005"], ["69924.60", "0.004"], ["70498.80", "0.215"], ["70499.10", "0.701"], ["70581.50", "0.099"], ["70588.80", "0.004"], ["70620.30", "0.072"], ["70623.00", "0.762"], ["70623.40", "0.003"], ["70624.50", "1.343"], ["70627.90", "0.001"], ["70629.90", "0.038"], ["70630.90", "16.401"]], "a": [["70631.00", "1.354"], ["70632.20", "0.002"], ["70634.50", "0.030"], ["70636.50", "0.008"], ["70639.80", "0.006"], ["70641.60", "0.008"], ["70644.70", "0.448"], ["70652.40", "0.039"], ["70652.70", "0.002"], ["70654.10", "0.219"], ["70659.30", "0.099"], ["70729.70", "0.100"], ["70737.00", "0.064"], ["70765.40", "0.693"], ["70765.60", "0.090"], ["70776.30", "0.000"], ["70777.60", "0.096"], ["70783.40", "0.000"], ["70784.70", "0.100"], ["70790.50", "0.029"], ["70791.80", "0.048"], ["70797.60", "0.005"], ["70798.90", "0.012"], ["70804.70", "0.005"], ["70806.00", "0.758"], ["70811.80", "0.003"], ["70813.10", "0.009"], ["70818.90", "0.000"], ["70820.20", "0.007"], ["70826.00", "0.016"], ["70827.30", "0.007"], ["71337.30", "0.000"], ["71392.10", "0.000"], ["71825.00", "0.014"], ["72042.50", "0.012"], ["72424.10", "2.481"]]}}
{"local_ts": 1773486564491, "server_ts": 1773486564460, "data": {"e": "depthUpdate", "E": 1773486564461, "T": 1773486564460, "s": "BTCUSDT", "U": 10109512836361, "u": 10109512842553, "pu": 10109512836233, "b": [["5000.00", "101.438"], ["7063.10", "0.056"], ["20130.90", "0.020"], ["20230.90", "2.300"], ["20330.90", "0.680"], ["67069.80", "0.002"], ["67071.80", "0.022"], ["67088.10", "0.000"], ["67099.40", "0.004"], ["69649.50", "0.000"], ["69924.60", "0.716"], ["69924.70", "0.000"], ["70277.70", "0.050"], ["70277.80", "0.024"], ["70582.50", "1.078"], ["70582.60", "0.075"], ["70583.50", "0.358"], ["70583.60", "0.000"], ["70583.70", "0.000"], ["70588.60", "0.185"], ["70617.30", "1.203"], ["70618.10", "0.005"], ["70620.30", "0.075"], ["70623.30", "0.008"], ["70625.50", "0.006"], ["70627.90", "0.001"], ["70630.90", "16.405"]], "a": [["70631.00", "1.360"], ["70632.10", "0.059"], ["70634.50", "0.030"], ["70641.60", "0.008"], ["70642.70", "0.062"], ["70648.10", "0.036"], ["70652.40", "0.024"], ["70652.70", "0.000"], ["70654.10", "0.204"], ["70665.10", "2.022"], ["70672.80", "0.185"], ["70673.00", "0.002"], ["70732.50", "0.516"], ["70737.00", "0.062"], ["71337.30", "0.000"], ["71634.00", "1.057"], ["71867.00", "1.132"], ["72042.50", "0.009"]]}}
{"local_ts": 1773486565516, "server_ts": 1773486565481, "data": {"e": "depthUpdate", "E": 1773486565483, "T": 1773486565481, "s": "BTCUSDT", "U": 10109512886435, "u": 10109512896659, "pu": 10109512886402, "b": [["1000.00", "26.142"], ["5000.00", "101.418"], ["7063.10", "0.028"], ["20130.90", "1.890"], ["20230.90", "1.110"], ["40000.00", "41.317"], ["67099.00", "0.000"], ["68865.10", "0.073"], ["69218.30", "0.009"], ["69924.60", "2.144"], ["70210.00", "0.268"], ["70318.40", "0.159"], ["70395.30", "1.547"], ["70450.80", "0.054"], ["70520.70", "0.123"], ["70532.40", "0.371"], ["70533.00", "0.045"], ["70533.50", "0.057"], ["70534.20", "0.065"], ["70562.80", "0.200"], ["70575.70", "0.000"], ["70576.90", "3.250"], ["70582.20", "0.046"], ["70582.30", "0.613"], ["70598.30", "2.333"], ["70600.10", "0.382"], ["70600.40", "0.358"], ["70600.50", "0.238"], ["70608.40", "0.539"], ["70609.40", "0.204"], ["70610.60", "0.010"], ["70611.00", "0.004"], ["70611.80", "0.032"], ["70613.10", "0.002"], ["70613.70", "0.025"], ["70613.90", "0.000"], ["70614.10", "0.052"], ["70614.20", "0.001"], ["70614.80", "0.000"], ["70615.10", "0.672"], ["70615.80", "0.543"], ["70615.90", "0.249"], ["70616.10", "0.070"], ["70616.50", "0.206"], ["70617.30", "0.000"], ["70617.40", "0.062"], ["70617.50", "0.053"], ["70617.70", "0.028"], ["70617.80", "0.038"], ["70617.90", "0.005"], ["70618.30", "0.001"], ["70618.70", "0.514"], ["70619.10", "0.015"], ["70619.30", "0.400"], ["70619.70", "1.830"], ["70620.30", "0.072"], ["70621.00", "0.160"], ["70621.10", "0.070"], ["70621.40", "0.122"], ["70622.00", "1.413"], ["70622.30", "0.344"], ["70622.50", "0.000"], ["70622.60", "0.001"], ["70622.70", "0.009"], ["70622.80", "0.024"], ["70622.90", "0.149"], ["70623.10", "0.011"], ["70623.30", "0.005"], ["70623.40", "0.004"], ["70623.60", "0.029"], ["70623.80", "0.010"], ["70623.90", "0.080"], ["70624.00", "0.609"], ["70624.50", "1.253"], ["70624.60", "0.019"], ["70624.80", "0.026"], ["70624.90", "0.015"], ["70625.00", "0.075"], ["70625.50", "0.011"], ["70625.90", "0.015"], ["70627.00", "0.003"], ["70627.70", "0.655"], ["70627.90", "0.001"], ["70628.30", "0.000"], ["70629.10", "0.004"], ["70629.90", "0.035"], ["70630.80", "0.282"], ["70630.90", "17.005"]], "a": [["70631.00", "0.220"], ["70634.30", "0.002"], ["70635.40", "0.001"], ["70635.70", "0.000"], ["70637.40", "0.007"], ["70638.40", "0.053"], ["70639.00", "0.000"], ["70639.30", "0.087"], ["70639.80", "0.006"], ["70640.30", "0.008"], ["70640.60", "0.135"], ["70641.60", "0.008"], ["70643.30", "0.142"], ["70643.90", "0.072"], ["70644.00", "0.669"], ["70645.60", "0.013"], ["70646.20", "0.002"], ["70646.60", "0.030"], ["70646.90", "0.038"], ["70647.40", "0.522"], ["70648.20", "0.122"], ["70648.40", "0.000"], ["70648.50", "0.029"], ["70649.30", "0.000"], ["70649.40", "0.005"], ["70649.50", "0.292"], ["70649.80", "0.003"], ["70649.90", "0.002"], ["70651.20", "0.007"], ["70651.30", "0.152"], ["70652.00", "0.325"], ["70652.40", "0.017"], ["70652.60", "0.002"], ["70652.90", "0.002"], ["70653.10", "0.516"], ["70653.20", "0.459"], ["70653.30", "0.082"], ["70653.70", "0.008"], ["70653.80", "0.008"], ["70653.90", "0.327"], ["70654.70", "0.013"], ["70654.90", "0.003"], ["70655.00", "1.178"], ["70655.10", "0.845"], ["70656.20", "0.029"], ["70656.40", "0.007"], ["70657.00", "0.005"], ["70657.30", "0.008"], ["70658.30", "0.141"], ["70658.40", "0.843"], ["70658.90", "0.025"], ["70659.30", "0.000"], ["70659.80", "0.454"], ["70660.00", "0.127"], ["70660.40", "0.003"], ["70660.80", "0.004"], ["70661.10", "0.000"], ["70661.20", "0.511"], ["70661.40", "0.062"], ["70661.50", "0.696"], ["70661.90", "0.012"], ["70662.50", "0.045"], ["70662.80", "0.513"], ["70663.70", "0.000"], ["70663.80", "0.643"], ["70665.00", "0.009"], ["70665.30", "0.006"], ["70665.40", "0.005"], ["70665.90", "0.022"], ["70666.00", "0.891"], ["70666.50", "0.002"], ["70667.20", "0.004"], ["70667.40", "0.843"], ["70667.90", "0.163"], ["70669.00", "0.028"], ["70670.10", "0.373"], ["70670.20", "0.017"], ["70671.10", "0.022"], ["70671.30", "0.254"], ["70671.40", "0.973"], ["70672.50", "0.030"], ["70673.90", "0.057"], ["70676.20", "0.453"], ["70677.50", "0.074"], ["70682.40", "0.000"], ["70685.80", "0.000"], ["70691.50", "0.000"], ["70696.00", "0.375"], ["70699.60", "0.270"], ["70705.50", "0.036"], ["70715.60", "1.500"], ["70725.60", "0.002"], ["70729.90", "0.002"], ["70732.50", "0.514"], ["70737.10", "0.559"], ["70741.70", "0.364"], ["70800.50", "0.172"], ["70878.50", "1.402"], ["70888.80", "0.144"], ["70955.60", "0.136"], ["71337.30", "0.002"], ["71683.70", "1.456"], ["72042.50", "0.003"], ["74183.10", "0.002"]]}}
{"local_ts": 1773486566539, "server_ts": 1773486566508, "data": {"e": "depthUpdate", "E": 1773486566509, "T": 1773486566508, "s": "BTCUSDT", "U": 10109512964933, "u": 10109512972815, "pu": 10109512964855, "b": [["5000.00", "101.418"], ["7063.10", "0.028"], ["20130.90", "1.550"], ["20530.90", "1.450"], ["33000.00", "3.785"], ["69635.00", "0.465"], ["69924.60", "2.144"], ["70277.70", "0.050"], ["70292.00", "0.012"], ["70339.00", "0.028"], ["70384.20", "0.000"], ["70499.00", "0.605"], ["70559.50", "0.108"], ["70575.60", "0.105"], ["70595.60", "0.277"], ["70600.10", "0.382"], ["70600.50", "0.034"], ["70600.70", "0.184"], ["70613.70", "0.025"], ["70614.10", "0.013"], ["70615.20", "0.262"], ["70616.10", "0.070"], ["70617.80", "0.038"], ["70620.30", "0.082"], ["70622.00", "0.366"], ["70622.10", "0.519"], ["70622.30", "0.344"], ["70623.50", "0.006"], ["70623.70", "0.149"], ["70624.00", "0.616"], ["70625.20", "0.000"], ["70625.40", "0.283"], ["70626.00", "0.639"], ["70626.60", "0.005"], ["70626.70", "0.511"], ["70627.90", "0.001"], ["70630.80", "0.301"], ["70630.90", "17.236"]], "a": [["70637.10", "0.042"], ["70637.40", "0.007"], ["70641.60", "0.005"], ["70646.70", "0.030"], ["70648.00", "0.037"], ["70648.90", "0.004"], ["70651.80", "0.005"], ["70652.30", "0.147"], ["70655.50", "0.024"], ["70656.10", "0.021"], ["70658.00", "0.670"], ["70659.30", "0.240"], ["70661.50", "0.696"], ["70662.10", "0.652"], ["70666.30", "0.040"], ["70679.20", "0.988"], ["70710.50", "0.750"], ["70729.90", "0.000"], ["70735.40", "0.002"], ["70765.00", "2.587"], ["71337.30", "0.054"], ["72016.10", "0.594"], ["74196.00", "0.130"]]}}
{"local_ts": 1773486567558, "server_ts": 1773486567528, "data": {"e": "depthUpdate", "E": 1773486567529, "T": 1773486567528, "s": "BTCUSDT", "U": 10109513042215, "u": 10109513049799, "pu": 10109513042066, "b": [["1000.00", "26.142"], ["5000.00", "101.418"], ["7063.10", "0.028"], ["20430.90", "1.010"], ["20530.90", "1.990"], ["56505.00", "0.000"], ["67088.60", "0.000"], ["68511.90", "0.005"], ["69218.30", "0.875"], ["69924.60", "2.144"], ["70277.70", "0.086"], ["70499.00", "0.605"], ["70557.60", "0.115"], ["70579.90", "1.293"], ["70581.50", "0.099"], ["70581.70", "0.004"], ["70582.70", "0.000"], ["70596.30", "0.002"], ["70598.20", "7.821"], ["70599.60", "0.009"], ["70600.10", "0.212"], ["70600.20", "0.005"], ["70600.40", "0.174"], ["70600.50", "0.388"], ["70600.70", "0.000"], ["70601.30", "0.000"], ["70612.70", "0.711"], ["70613.60", "0.275"], ["70620.30", "0.072"], ["70621.80", "0.003"], ["70622.00", "0.481"], ["70623.50", "0.003"], ["70623.60", "0.029"], ["70623.90", "0.014"], ["70625.30", "0.003"], ["70627.40", "0.001"], ["70627.90", "0.001"], ["70630.90", "16.815"]], "a": [["70631.00", "0.141"], ["70634.20", "0.005"], ["70636.70", "0.003"], ["70637.10", "0.014"], ["70637.20", "0.001"], ["70638.00", "0.004"], ["70641.60", "0.008"], ["70644.20", "0.004"], ["70644.80", "0.099"], ["70648.00", "0.073"], ["70648.90", "0.004"], ["70649.60", "0.024"], ["70649.70", "1.580"], ["70650.90", "0.000"], ["70651.30", "0.011"], ["70651.60", "0.047"], ["70653.00", "0.182"], ["70653.90", "0.325"], ["70654.00", "0.021"], ["70654.40", "0.003"], ["70656.50", "1.068"], ["70659.30", "0.240"], ["70669.60", "0.609"], ["70671.00", "0.088"], ["70671.70", "0.006"], ["70680.20", "0.084"], ["70712.40", "0.040"], ["70735.40", "0.000"], ["70764.90", "0.673"], ["70797.00", "0.132"], ["70854.70", "0.009"], ["70984.00", "0.000"], ["71337.30", "0.000"], ["72043.60", "0.020"]]}}
{"local_ts": 1773486568584, "server_ts": 1773486568552, "data": {"e": "depthUpdate", "E": 1773486568555, "T": 1773486568552, "s": "BTCUSDT", "U": 10109513104171, "u": 10109513108748, "pu": 10109513104111, "b": [["1000.00", "26.142"], ["5000.00", "101.418"], ["7063.10", "0.000"], ["20330.90", "0.570"], ["20430.90", "2.430"], ["20530.90", "0.000"], ["33000.00", "3.789"], ["56505.00", "0.004"], ["67090.60", "0.000"], ["67099.40", "0.006"], ["69500.80", "0.719"], ["69924.60", "2.144"], ["70277.70", "0.122"], ["70300.00", "21.629"], ["70459.30", "5.804"], ["70528.30", "0.087"], ["70581.50", "0.099"], ["70600.10", "0.396"], ["70600.20", "0.005"], ["70600.50", "0.034"]], "a": [["70854.80", "0.049"], ["71337.30", "0.000"], ["71659.40", "0.000"], ["71683.70", "0.627"], ["71709.80", "0.007"], ["71817.60", "0.606"], ["74186.60", "0.002"]]}}
{"local_ts": 1773486569606, "server_ts": 1773486569572, "data": {"e": "depthUpdate", "E": 1773486569577, "T": 1773486569572, "s": "BTCUSDT", "U": 10109513173064, "u": 10109513179981, "pu": 10109513172940, "b": [["5000.00", "101.418"], ["7063.10", "0.000"], ["20231.90", "0.120"], ["20330.90", "2.320"], ["20331.90", "0.230"], ["20430.90", "0.160"], ["56505.00", "0.000"], ["67073.50", "0.002"], ["69925.60", "0.000"], ["70277.70", "0.122"], ["70278.70", "0.143"], ["70357.00", "0.038"], ["70420.90", "10.000"], ["70445.90", "0.000"], ["70448.00", "1.315"], ["70451.80", "0.167"], ["70473.00", "0.131"], ["70483.80", "0.837"], ["70490.30", "0.529"], ["70513.70", "0.041"], ["70521.20", "0.160"], ["70521.70", "1.365"], ["70543.00", "0.040"], ["70580.00", "1.234"], ["70580.40", "0.011"], ["70583.20", "0.049"], ["70583.30", "0.002"], ["70586.00", "0.084"], ["70589.50", "0.124"], ["70596.30", "0.000"], ["70596.60", "0.086"], ["70600.10", "0.215"], ["70610.30", "0.101"], ["70614.10", "0.007"], ["70615.20", "0.129"], ["70617.20", "0.795"], ["70618.20", "0.072"], ["70619.80", "0.009"], ["70620.20", "0.444"], ["70621.30", "0.125"], ["70621.40", "0.126"], ["70621.70", "0.050"], ["70622.40", "0.008"], ["70623.10", "0.004"], ["70624.40", "1.073"], ["70624.60", "0.640"], ["70624.80", "0.017"], ["70624.90", "0.014"], ["70625.10", "0.013"], ["70625.20", "0.000"], ["70625.60", "0.026"], ["70626.30", "0.000"], ["70627.10", "0.005"], ["70627.50", "0.008"], ["70630.10", "0.003"], ["70630.80", "0.032"], ["70630.90", "0.580"], ["70631.00", "0.002"], ["70631.30", "0.049"], ["70631.50", "0.215"], ["70631.60", "0.370"], ["70631.70", "0.002"], ["70631.80", "0.473"], ["70631.90", "21.790"]], "a": [["70632.00", "0.915"], ["70632.40", "0.002"], ["70634.40", "0.000"], ["70635.60", "0.041"], ["70635.70", "0.000"], ["70637.10", "0.013"], ["70637.20", "0.001"], ["70638.50", "0.075"], ["70639.70", "0.000"], ["70639.80", "0.023"], ["70639.90", "0.460"], ["70640.60", "0.146"], ["70641.20", "0.000"], ["70642.60", "0.000"], ["70643.40", "0.033"], ["70643.50", "0.057"], ["70643.60", "0.000"], ["70643.70", "0.739"], ["70643.90", "0.001"], ["70644.00", "0.010"], ["70645.00", "0.046"], ["70647.00", "0.000"], ["70648.30", "0.057"], ["70648.90", "0.283"], ["70649.50", "0.036"], ["70650.30", "0.037"], ["70650.70", "0.000"], ["70651.50", "0.000"], ["70651.70", "0.024"], ["70652.80", "0.006"], ["70652.90", "0.073"], ["70653.70", "0.016"], ["70654.40", "1.172"], ["70656.00", "0.113"], ["70656.30", "0.007"], ["70660.30", "0.082"], ["70660.70", "0.651"], ["70661.10", "0.509"], ["70661.30", "0.006"], ["70661.70", "0.000"], ["70662.20", "0.100"], ["70662.50", "0.045"], ["70662.80", "0.004"], ["70663.70", "0.000"], ["70664.70", "0.070"], ["70664.80", "0.035"], ["70666.60", "0.442"], ["70667.30", "0.053"], ["70669.00", "0.275"], ["70669.50", "0.068"], ["70669.80", "0.003"], ["70671.30", "0.007"], ["70671.40", "0.973"], ["70671.70", "0.006"], ["70672.70", "0.005"], ["70673.90", "0.005"], ["70686.30", "0.007"], ["70693.10", "0.651"], ["70694.60", "0.003"], ["70700.70", "0.729"], ["70701.40", "0.005"], ["70707.20", "0.113"], ["70727.30", "0.088"], ["70740.50", "0.128"], ["70749.40", "0.085"], ["70786.30", "0.000"], ["70798.00", "0.161"], ["70985.20", "0.007"], ["71338.30", "0.015"], ["71598.60", "0.279"], ["89523.20", "0.000"]]}}
{"local_ts": 1773486570654, "server_ts": 1773486570598, "data": {"e": "depthUpdate", "E": 1773486570599, "T": 1773486570598, "s": "BTCUSDT", "U": 10109513231591, "u": 10109513236017, "pu": 10109513231425, "b": [["1000.00", "26.142"], ["5000.00", "101.418"], ["7063.20", "0.000"], ["20131.90", "0.130"], ["20231.90", "2.260"], ["20330.90", "0.450"], ["33000.00", "3.789"], ["56505.00", "0.000"], ["67070.00", "59.545"], ["69466.50", "1.006"], ["69501.80", "2.020"], ["69517.50", "4.985"], ["69536.10", "1.008"], ["69588.10", "9.390"], ["69606.80", "4.877"], ["69638.40", "3.622"], ["69784.00", "0.167"], ["69925.60", "0.000"], ["70499.00", "0.000"], ["70499.70", "0.612"], ["70522.20", "0.071"], ["70533.80", "0.072"], ["70534.50", "0.043"], ["70534.90", "0.055"], ["70535.60", "0.053"], ["70574.10", "0.519"], ["70584.10", "0.003"], ["70584.20", "0.004"], ["70615.90", "0.002"], ["70616.60", "1.214"], ["70617.70", "0.021"], ["70618.00", "0.078"], ["70621.30", "0.000"], ["70622.00", "0.429"], ["70622.30", "0.347"], ["70625.10", "0.025"]], "a": [["70632.00", "1.732"], ["70638.60", "0.009"], ["70642.30", "0.007"], ["70644.30", "0.061"], ["70645.60", "0.013"], ["70646.10", "0.323"], ["70646.20", "0.016"], ["70646.80", "0.165"], ["70648.10", "0.036"], ["70648.50", "0.170"], ["70649.60", "0.003"], ["70660.20", "0.201"], ["70660.30", "0.249"], ["70661.10", "0.509"], ["70662.40", "0.131"], ["70663.90", "0.021"], ["70664.80", "0.105"], ["70670.10", "0.333"], ["70671.80", "0.008"], ["70711.50", "0.036"], ["70764.60", "0.553"], ["70764.70", "0.000"], ["71338.30", "0.015"], ["71966.90", "0.000"], ["74176.50", "0.052"], ["89523.20", "0.000"]]}}
{"local_ts": 1773486571755, "server_ts": 1773486571720, "data": {"e": "depthUpdate", "E": 1773486571725, "T": 1773486571720, "s": "BTCUSDT", "U": 10109513289649, "u": 10109513294160, "pu": 10109513289549, "b": [["1000.00", "26.142"], ["5000.00", "101.438"], ["7063.20", "0.028"], ["20131.90", "2.350"], ["20230.90", "0.000"], ["20231.90", "0.580"], ["20531.90", "0.070"], ["67086.30", "0.002"], ["69514.00", "0.616"], ["69862.00", "0.818"], ["69925.60", "0.000"], ["70277.70", "0.122"], ["70278.80", "0.000"], ["70350.30", "0.004"], ["70540.40", "0.144"], ["70540.60", "0.002"], ["70547.40", "0.144"], ["70547.60", "0.000"], ["70554.50", "0.238"], ["70554.70", "0.510"], ["70583.50", "0.275"], ["70583.80", "0.000"], ["70584.90", "0.086"], ["70585.00", "0.551"], ["70596.60", "0.065"], ["70608.00", "0.004"], ["70609.20", "0.007"], ["70616.10", "0.070"], ["70617.10", "0.005"], ["70624.90", "0.014"], ["70628.80", "0.024"]], "a": [["70638.10", "0.005"], ["70638.30", "0.000"], ["70638.40", "0.057"], ["70638.60", "0.001"], ["70638.70", "0.000"], ["70638.80", "0.008"], ["70638.90", "0.003"], ["70639.00", "0.000"], ["70639.10", "0.003"], ["70639.20", "0.002"], ["70639.40", "0.004"], ["70639.50", "0.005"], ["70639.60", "0.077"], ["70639.70", "0.000"], ["70639.90", "0.465"], ["70640.00", "0.003"], ["70640.50", "0.006"], ["70644.00", "0.662"], ["70655.40", "0.513"], ["70656.50", "1.068"], ["70660.20", "0.201"], ["70660.80", "0.009"], ["70661.10", "0.000"], ["70661.90", "0.514"], ["70662.80", "0.004"], ["70663.80", "0.236"], ["70664.70", "0.000"], ["70664.80", "0.035"], ["70665.50", "0.164"], ["70667.30", "0.053"], ["70690.10", "0.004"], ["70690.80", "0.025"], ["70710.00", "0.171"], ["70711.80", "0.002"], ["70717.10", "0.221"], ["70718.90", "0.094"], ["70724.10", "0.190"], ["70725.90", "0.511"], ["70855.80", "0.002"], ["71338.30", "0.015"], ["71762.00", "0.017"], ["72043.60", "0.023"], ["72349.40", "1.183"]]}}
{"local_ts": 1773486572785, "server_ts": 1773486572744, "data": {"e": "depthUpdate", "E": 1773486572745, "T": 1773486572744, "s": "BTCUSDT", "U": 10109513337225, "u": 10109513341757, "pu": 10109513337217, "b": [["1000.00", "26.142"], ["5000.00", "101.418"], ["7063.20", "0.000"], ["20131.90", "0.950"], ["20531.90", "2.050"], ["33000.00", "3.789"], ["67096.50", "0.002"], ["68864.40", "0.000"], ["70100.10", "3.739"], ["70222.10", "16.020"], ["70315.30", "0.000"], ["70387.20", "0.426"], ["70392.70", "0.000"]], "a": [["70641.20", "0.057"], ["70656.50", "1.066"], ["70657.10", "0.284"], ["70686.60", "0.007"], ["70690.10", "0.002"], ["70700.10", "0.711"], ["70957.80", "0.059"], ["70999.90", "13.710"], ["71059.80", "9.995"], ["71193.30", "0.002"], ["71338.30", "0.715"], ["71357.00", "0.008"], ["71808.90", "0.002"], ["72770.70", "3.293"], ["74190.90", "0.000"]]}}
{"local_ts": 1773486573798, "server_ts": 1773486573765, "data": {"e": "depthUpdate", "E": 1773486573767, "T": 1773486573765, "s": "BTCUSDT", "U": 10109513389334, "u": 10109513395529, "pu": 10109513388946, "b": [["5000.00", "101.418"], ["7063.20", "0.000"], ["20431.90", "1.600"], ["20531.90", "1.400"], ["67080.80", "0.000"], ["67082.80", "0.002"], ["67100.00", "3.868"], ["69628.90", "0.352"], ["69712.40", "67.488"], ["69922.20", "53.281"], ["69925.60", "0.714"], ["70103.70", "0.000"], ["70278.70", "0.143"], ["70583.10", "0.004"], ["70583.50", "0.273"], ["70600.40", "0.258"], ["70610.10", "0.007"], ["70610.80", "0.017"], ["70617.90", "0.514"], ["70618.60", "0.455"], ["70629.00", "0.007"]], "a": [["70657.10", "0.282"], ["70666.80", "0.073"], ["70675.00", "0.012"], ["70686.60", "0.005"], ["70699.80", "0.491"], ["70745.20", "0.002"], ["71191.80", "47.782"], ["71355.50", "56.336"], ["71569.60", "69.379"]]}}
{"local_ts": 1773486574817, "server_ts": 1773486574784, "data": {"e": "depthUpdate", "E": 1773486574787, "T": 1773486574784, "s": "BTCUSDT", "U": 10109513453720, "u": 10109513459189, "pu": 10109513453700, "b": [["1000.00", "26.142"], ["5000.00", "101.418"], ["7063.20", "0.000"], ["20331.90", "1.150"], ["20431.90", "1.850"], ["67094.90", "0.002"], ["69218.30", "0.878"], ["69627.90", "2.437"], ["69635.40", "0.000"], ["69925.60", "0.714"], ["70582.60", "0.075"], ["70583.20", "0.047"], ["70602.10", "0.191"], ["70621.30", "0.003"], ["70624.00", "0.209"], ["70625.10", "0.015"]], "a": [["70632.00", "0.457"], ["70636.20", "0.048"], ["70646.20", "0.015"], ["70675.00", "0.010"], ["70680.80", "0.002"], ["70745.20", "0.000"], ["71338.30", "0.715"], ["72043.60", "0.002"], ["72044.60", "0.017"]]}}
{"local_ts": 1773486575843, "server_ts": 1773486575810, "data": {"e": "depthUpdate", "E": 1773486575811, "T": 1773486575810, "s": "BTCUSDT", "U": 10109513515119, "u": 10109513520876, "pu": 10109513515001, "b": [["5000.00", "101.418"], ["7063.20", "0.056"], ["20231.90", "0.710"], ["20331.90", "2.290"], ["20431.90", "0.000"], ["56506.00", "0.000"], ["67084.70", "0.002"], ["69497.10", "0.003"], ["69634.80", "0.003"], ["69925.60", "0.714"], ["70472.00", "0.002"], ["70582.50", "1.078"], ["70584.00", "0.002"], ["70598.70", "0.019"], ["70600.20", "0.359"], ["70600.40", "0.258"], ["70602.10", "0.177"], ["70610.60", "0.046"], ["70618.40", "0.087"], ["70619.90", "0.007"], ["70625.10", "0.015"]], "a": [["70643.70", "0.132"], ["70645.20", "0.009"], ["70654.20", "0.004"], ["70655.00", "0.014"], ["70662.40", "0.767"], ["70669.00", "0.028"], ["70669.90", "0.250"], ["70695.60", "0.066"], ["70760.90", "0.594"], ["71303.00", "3.501"], ["71338.30", "0.715"], ["72044.60", "0.014"], ["72349.40", "1.775"], ["74165.80", "0.002"]]}}
{"local_ts": 1773486576863, "server_ts": 1773486576832, "data": {"e": "depthUpdate", "E": 1773486576833, "T": 1773486576832, "s": "BTCUSDT", "U": 10109513586135, "u": 10109513589793, "pu": 10109513585951, "b": [["1000.00", "26.142"], ["5000.00", "101.418"], ["7064.00", "0.056"], ["20139.80", "0.340"], ["20231.90", "1.430"], ["20239.80", "1.160"], ["20331.90", "0.070"], ["63575.80", "0.002"], ["69933.40", "0.000"], ["69999.80", "0.000"], ["70007.50", "0.016"], ["70278.70", "0.143"], ["70456.10", "0.256"], ["70524.00", "0.002"], ["70548.90", "0.013"], ["70588.80", "0.002"], ["70589.10", "0.006"], ["70600.20", "0.337"], ["70603.80", "0.007"], ["70604.50", "0.006"], ["70612.40", "0.072"], ["70618.90", "0.004"], ["70623.30", "0.106"], ["70629.20", "0.022"], ["70630.20", "0.285"], ["70632.50", "0.003"]], "a": [["70639.90", "3.856"], ["70650.50", "0.005"], ["70675.20", "0.003"], ["70684.60", "0.004"], ["70692.10", "0.007"], ["70746.40", "0.146"], ["71205.20", "0.000"], ["71346.30", "0.000"], ["71500.00", "35.879"], ["71700.00", "16.187"], ["74196.30", "0.002"], ["77703.90", "0.002"]]}}
{"local_ts": 1773486577882, "server_ts": 1773486577852, "data": {"e": "depthUpdate", "E": 1773486577853, "T": 1773486577852, "s": "BTCUSDT", "U": 10109513629896, "u": 10109513633931, "pu": 10109513629837, "b": [["1000.00", "26.142"], ["5000.00", "101.418"], ["7064.00", "0.056"], ["20139.80", "2.460"], ["20231.90", "0.360"], ["20539.80", "0.180"], ["33000.00", "3.785"], ["63575.80", "0.002"], ["69207.40", "1.733"], ["69713.70", "4.584"], ["69933.40", "0.000"], ["70385.10", "0.002"], ["70393.20", "0.021"], ["70465.60", "0.085"], ["70472.10", "0.511"], ["70568.30", "0.178"], ["70589.90", "0.606"], ["70590.20", "0.005"], ["70600.20", "0.153"], ["70602.90", "0.184"], ["70604.50", "0.083"], ["70612.50", "0.004"], ["70613.10", "0.286"], ["70620.50", "0.030"], ["70623.20", "0.454"], ["70624.80", "0.600"], ["70626.80", "0.359"], ["70631.30", "0.000"], ["70632.60", "0.294"], ["70633.00", "0.017"], ["70633.10", "0.636"], ["70636.20", "0.082"]], "a": [["70639.90", "3.714"], ["70643.10", "0.003"], ["70643.40", "0.031"], ["70643.80", "0.000"], ["70644.20", "0.004"], ["70644.50", "0.000"], ["70644.90", "0.038"], ["70646.70", "0.322"], ["70647.40", "0.031"], ["70650.90", "0.000"], ["70654.10", "0.082"], ["70667.70", "0.000"], ["70667.80", "0.034"], ["70668.20", "0.511"], ["70668.50", "0.693"], ["70668.70", "0.512"], ["70671.50", "0.002"], ["70672.20", "0.072"], ["70675.20", "0.031"], ["70675.90", "0.001"], ["70676.90", "0.000"], ["70678.40", "0.052"], ["70679.00", "0.440"], ["70727.40", "1.790"], ["71346.30", "0.140"], ["74179.60", "0.000"], ["77703.90", "0.002"]]}}
{"local_ts": 1773486578904, "server_ts": 1773486578872, "data": {"e": "depthUpdate", "E": 1773486578873, "T": 1773486578872, "s": "BTCUSDT", "U": 10109513666333, "u": 10109513669929, "pu": 10109513666269, "b": [["5000.00", "101.418"], ["7064.00", "0.028"], ["20139.80", "0.660"], ["20439.80", "0.030"], ["20539.80", "2.310"], ["56506.00", "0.000"], ["63575.80", "0.002"], ["67084.50", "0.002"], ["67249.10", "4.500"], ["67621.30", "0.007"], ["68519.10", "0.010"], ["69803.50", "1.147"], ["69933.40", "0.000"], ["70286.60", "0.000"], ["70304.40", "0.000"], ["70314.70", "0.207"], ["70389.50", "0.004"], ["70561.00", "0.006"], ["70590.30", "0.013"], ["70590.40", "0.088"], ["70600.50", "0.327"], ["70600.60", "0.001"], ["70602.90", "0.170"], ["70635.60", "0.387"], ["70639.70", "0.063"], ["70639.80", "10.785"]], "a": [["70644.70", "0.002"], ["70646.40", "0.021"], ["70646.90", "0.066"], ["70647.00", "0.028"], ["70648.20", "0.005"], ["70648.30", "0.085"], ["70679.60", "0.284"], ["70679.70", "1.903"], ["70698.50", "0.004"], ["71346.30", "0.140"], ["77703.90", "0.002"], ["89523.20", "0.000"]]}}
{"local_ts": 1773486579925, "server_ts": 1773486579896, "data": {"e": "depthUpdate", "E": 1773486579897, "T": 1773486579896, "s": "BTCUSDT", "U": 10109513701227, "u": 10109513705676, "pu": 10109513701225, "b": [["1000.00", "26.142"], ["5000.00", "101.418"], ["7064.00", "0.028"], ["20439.80", "1.930"], ["20539.80", "1.070"], ["33000.00", "3.789"], ["63575.80", "0.002"], ["67269.10", "0.002"], ["69712.40", "0.000"], ["69933.40", "0.000"], ["70244.30", "0.192"], ["70452.60", "0.163"], ["70485.00", "0.141"], ["70486.50", "0.900"], ["70488.60", "12.375"], ["70489.60", "2.274"], ["70543.40", "0.014"], ["70544.90", "0.427"], ["70548.60", "0.010"], ["70578.30", "0.025"], ["70580.00", "0.817"], ["70582.80", "3.449"], ["70590.60", "0.090"], ["70590.80", "0.108"], ["70600.50", "0.143"], ["70601.50", "0.184"], ["70603.40", "0.017"], ["70603.60", "0.840"], ["70604.10", "1.827"], ["70604.50", "0.190"], ["70606.00", "0.046"], ["70606.10", "0.071"], ["70608.00", "0.079"], ["70619.80", "0.002"], ["70622.40", "0.248"], ["70632.90", "0.412"], ["70635.50", "0.370"], ["70635.90", "0.002"], ["70637.00", "0.076"], ["70638.30", "0.075"], ["70638.40", "0.101"], ["70639.80", "10.781"]], "a": [["70639.90", "3.682"], ["70646.90", "0.087"], ["70647.10", "0.458"], ["70647.20", "0.006"], ["70647.40", "0.067"], ["70648.10", "0.138"], ["70648.20", "0.002"], ["70652.00", "0.042"], ["70652.30", "0.020"], ["70652.80", "0.656"], ["70653.40", "0.115"], ["70653.50", "0.044"], ["70653.80", "0.514"], ["70654.00", "0.175"], ["70668.20", "0.592"], ["70669.60", "0.513"], ["70676.20", "0.453"], ["70678.90", "0.252"], ["70679.00", "0.193"], ["70679.70", "0.022"], ["70679.90", "0.156"], ["70680.10", "0.013"], ["70700.90", "0.005"], ["70742.80", "0.042"], ["70745.40", "0.326"], ["70748.30", "0.135"], ["71346.30", "0.140"], ["71355.50", "0.002"], ["72759.00", "0.026"], ["73015.50", "0.002"], ["74185.40", "0.000"], ["77703.90", "0.002"], ["89523.20", "0.000"]]}}
{"local_ts": 1773486580951, "server_ts": 1773486580916, "data": {"e": "depthUpdate", "E": 1773486580919, "T": 1773486580916, "s": "BTCUSDT", "U": 10109513764423, "u": 10109513769025, "pu": 10109513764332, "b": [["5000.00", "101.418"], ["7064.00", "0.028"], ["20339.80", "1.480"], ["20439.80", "1.520"], ["56512.00", "0.011"], ["63575.80", "0.002"], ["69933.40", "0.000"], ["70290.10", "0.000"], ["70590.60", "0.007"], ["70590.70", "0.005"], ["70594.60", "0.377"], ["70604.50", "0.236"], ["70608.70", "0.187"], ["70615.70", "0.057"], ["70617.30", "0.000"], ["70617.70", "0.141"], ["70619.80", "0.249"], ["70621.70", "0.007"], ["70624.50", "1.038"], ["70628.60", "0.000"], ["70629.50", "0.043"], ["70629.60", "0.129"], ["70632.90", "0.657"], ["70633.50", "0.015"], ["70633.80", "0.069"], ["70636.50", "0.004"], ["70639.00", "0.008"], ["70639.70", "0.026"]], "a": [["70639.90", "4.102"], ["70640.90", "0.005"], ["70641.30", "0.002"], ["70642.10", "0.000"], ["70642.60", "0.056"], ["70643.30", "0.034"], ["70644.10", "0.000"], ["70646.00", "0.071"], ["70654.00", "0.175"], ["70654.10", "0.005"], ["70654.30", "0.243"], ["70655.30", "0.141"], ["70659.90", "0.012"], ["70661.00", "0.010"], ["70661.70", "0.067"], ["70665.50", "0.009"], ["70666.30", "0.676"], ["70667.20", "0.513"], ["70668.20", "0.592"], ["70675.10", "0.000"], ["70675.20", "0.031"], ["70676.60", "0.139"], ["71346.30", "0.140"], ["72759.00", "0.026"], ["74200.80", "0.002"], ["77703.90", "0.002"], ["89523.20", "0.000"]]}}
{"local_ts": 1773486581970, "server_ts": 1773486581940, "data": {"e": "depthUpdate", "E": 1773486581941, "T": 1773486581940, "s": "BTCUSDT", "U": 10109513807479, "u": 10109513811070, "pu": 10109513807365, "b": [["1000.00", "26.142"], ["5000.00", "101.418"], ["7064.00", "0.000"], ["20239.80", "1.040"], ["20339.80", "1.960"], ["20439.90", "0.000"], ["33000.00", "3.789"], ["63575.80", "0.000"], ["67074.70", "0.000"], ["67107.80", "0.004"], ["67107.90", "0.212"], ["69933.40", "0.000"], ["69958.90", "4.273"], ["70286.60", "0.568"], ["70286.70", "0.337"], ["70304.30", "0.896"], ["70392.50", "0.000"], ["70590.90", "0.071"], ["70591.00", "0.284"], ["70604.50", "0.190"], ["70619.80", "0.249"], ["70621.30", "0.000"], ["70630.30", "0.166"], ["70630.90", "0.948"], ["70632.40", "1.149"], ["70632.70", "0.141"], ["70633.00", "0.377"], ["70636.10", "0.003"], ["70636.50", "0.004"], ["70638.30", "0.063"], ["70639.80", "6.488"]], "a": [["70648.70", "0.022"], ["70661.60", "0.007"], ["70667.80", "0.034"], ["70669.80", "0.003"], ["70675.20", "0.003"], ["70885.50", "0.009"], ["71155.40", "0.004"], ["71328.30", "2.990"], ["71346.30", "0.140"], ["77703.90", "0.000"], ["89523.20", "0.000"]]}}
{"local_ts": 1773486582992, "server_ts": 1773486582960, "data": {"e": "depthUpdate", "E": 1773486582963, "T": 1773486582960, "s": "BTCUSDT", "U": 10109513866656, "u": 10109513871085, "pu": 10109513866637, "b": [["1000.00", "26.142"], ["5000.00", "101.418"], ["7064.00", "0.000"], ["20139.80", "0.590"], ["20239.80", "2.410"], ["20339.80", "0.000"], ["56512.00", "0.011"], ["63575.80", "0.000"], ["67073.10", "0.002"], ["69862.80", "0.145"], ["69933.40", "0.000"], ["70286.60", "0.816"], ["70304.30", "0.790"], ["70590.60", "0.090"], ["70590.80", "0.108"], ["70590.90", "0.069"], ["70591.50", "0.008"], ["70591.70", "0.003"], ["70597.60", "0.065"], ["70600.40", "0.074"], ["70630.00", "0.899"], ["70632.80", "0.057"], ["70637.00", "0.013"]], "a": [["70646.90", "0.682"], ["70680.10", "0.100"], ["70680.30", "0.003"], ["70865.70", "0.007"], ["70989.90", "0.000"], ["70993.10", "0.704"], ["70993.20", "0.012"], ["71346.30", "0.140"], ["71558.20", "1.674"], ["74199.30", "0.002"], ["77703.90", "0.000"], ["89523.20", "0.000"]]}}
{"local_ts": 1773486584017, "server_ts": 1773486583980, "data": {"e": "depthUpdate", "E": 1773486583985, "T": 1773486583980, "s": "BTCUSDT", "U": 10109513952749, "u": 10109513960227, "pu": 10109513952610, "b": [["5000.00", "101.418"], ["7064.00", "0.000"], ["20139.80", "2.560"], ["20239.80", "0.150"], ["20539.80", "0.290"], ["56512.00", "0.011"], ["63575.80", "0.000"], ["67073.80", "0.000"], ["69933.40", "0.000"], ["70286.60", "0.710"], ["70591.70", "0.003"], ["70591.80", "0.004"], ["70592.70", "0.004"], ["70592.90", "0.116"], ["70608.90", "0.413"], ["70633.00", "0.017"], ["70637.00", "0.013"], ["70639.30", "0.127"], ["70639.80", "7.919"]], "a": [["70643.90", "0.067"], ["70644.20", "0.002"], ["70661.10", "0.892"], ["70676.10", "0.004"], ["70682.00", "0.366"], ["70682.20", "0.099"], ["70732.20", "0.011"], ["70883.00", "0.007"], ["71346.20", "0.000"], ["71346.30", "1.540"], ["71723.40", "0.698"], ["71734.50", "1.563"], ["71835.60", "0.002"], ["74204.10", "0.002"], ["77703.90", "0.000"], ["89523.20", "0.000"]]}}
{"local_ts": 1773486585036, "server_ts": 1773486585005, "data": {"e": "depthUpdate", "E": 1773486585007, "T": 1773486585005, "s": "BTCUSDT", "U": 10109514034259, "u": 10109514041016, "pu": 10109514034235, "b": [["1000.00", "26.142"], ["5000.00", "101.418"], ["7064.00", "0.056"], ["20139.80", "0.440"], ["20439.80", "0.140"], ["20539.80", "2.420"], ["56512.00", "0.011"], ["63575.80", "0.000"], ["67083.10", "0.000"], ["67100.20", "0.005"], ["67107.00", "0.034"], ["69933.40", "0.000"], ["70286.70", "0.195"], ["70349.50", "0.002"], ["70393.30", "0.006"], ["70575.70", "0.166"], ["70576.80", "0.083"], ["70580.80", "0.083"], ["70619.70", "0.518"], ["70623.00", "0.118"], ["70633.30", "0.682"], ["70634.10", "0.002"], ["70634.60", "0.005"], ["70636.30", "0.059"], ["70637.00", "0.013"], ["70639.80", "8.523"]], "a": [["70641.60", "0.005"], ["70644.70", "0.002"], ["70645.10", "0.074"], ["70645.30", "0.003"], ["70650.70", "0.038"], ["70657.70", "0.000"], ["70659.00", "0.158"], ["70669.10", "2.065"], ["70670.90", "0.000"], ["70750.50", "0.013"], ["71346.30", "1.540"], ["71621.80", "0.905"], ["71960.90", "0.762"], ["73465.40", "0.016"], ["74181.30", "0.000"], ["77703.90", "0.000"], ["89523.20", "0.000"]]}}
{"local_ts": 1773486586062, "server_ts": 1773486586028, "data": {"e": "depthUpdate", "E": 1773486586029, "T": 1773486586028, "s": "BTCUSDT", "U": 10109514098144, "u": 10109514105463, "pu": 10109514098058, "b": [["5000.00", "101.418"], ["7064.00", "0.056"], ["20439.80", "2.260"], ["20539.80", "0.740"], ["63575.80", "0.000"], ["69933.40", "1.428"], ["69947.50", "0.927"], ["70300.80", "4.215"], ["70393.40", "0.004"], ["70507.70", "1.057"], ["70523.00", "0.031"], ["70546.80", "0.127"], ["70546.90", "0.361"], ["70550.30", "0.009"], ["70553.80", "0.077"], ["70553.90", "0.000"], ["70554.70", "0.144"], ["70557.30", "0.002"], ["70560.90", "0.250"], ["70561.00", "0.002"], ["70561.70", "0.694"], ["70562.10", "0.171"], ["70564.40", "0.371"], ["70568.80", "0.434"], ["70576.20", "0.000"], ["70592.30", "0.006"], ["70592.50", "0.366"], ["70611.50", "0.082"], ["70623.00", "0.112"], ["70624.80", "0.526"], ["70625.60", "0.037"], ["70625.70", "0.003"], ["70625.80", "0.079"], ["70626.60", "0.007"], ["70632.70", "0.201"], ["70637.00", "0.013"], ["70639.80", "8.332"]], "a": [["70645.10", "0.005"], ["70646.80", "0.109"], ["70647.40", "0.658"], ["70649.60", "0.014"], ["70652.80", "0.004"], ["70653.10", "0.027"], ["70653.30", "0.061"], ["70655.80", "0.123"], ["70668.20", "1.228"], ["70670.20", "0.002"], ["70671.70", "0.004"], ["70672.50", "0.073"], ["70673.70", "0.000"], ["70674.50", "0.859"], ["70676.10", "0.002"], ["70678.50", "0.284"], ["70678.60", "0.003"], ["70681.70", "0.014"], ["70681.90", "0.085"], ["70703.50", "0.002"], ["70717.60", "0.002"], ["70720.10", "0.000"], ["70723.50", "0.071"], ["70723.60", "0.000"], ["70724.50", "0.142"], ["70727.20", "0.004"], ["70730.60", "0.076"], ["70730.70", "0.006"], ["70731.60", "0.145"], ["70734.20", "0.031"], ["70737.60", "0.295"], ["70737.70", "0.000"], ["70738.60", "0.685"], ["70775.00", "1.263"], ["71346.30", "2.940"], ["74171.80", "0.000"], ["74181.50", "0.052"], ["74188.20", "0.000"], ["77703.90", "0.000"], ["89523.20", "0.000"]]}}
{"local_ts": 1773486587078, "server_ts": 1773486587048, "data": {"e": "depthUpdate", "E": 1773486587049, "T": 1773486587048, "s": "BTCUSDT", "U": 10109514160640, "u": 10109514165607, "pu": 10109514160517, "b": [["1000.00", "26.142"], ["5000.00", "101.418"], ["7064.00", "0.056"], ["20339.80", "1.810"], ["20439.80", "1.190"], ["33000.00", "3.785"], ["67099.30", "0.000"], ["68520.70", "0.075"], ["70286.60", "0.852"], ["70286.70", "0.195"], ["70393.70", "0.006"], ["70627.10", "0.012"], ["70632.80", "0.004"], ["70637.00", "0.013"]], "a": [["70646.90", "0.002"], ["70647.00", "0.073"], ["70647.40", "0.006"], ["70651.10", "0.028"], ["70652.80", "0.656"], ["70676.30", "0.515"], ["70676.40", "0.042"], ["71346.30", "2.940"], ["71877.20", "0.000"], ["89523.20", "0.000"]]}}
{"local_ts": 1773486588137, "server_ts": 1773486588068, "data": {"e": "depthUpdate", "E": 1773486588069, "T": 1773486588068, "s": "BTCUSDT", "U": 10109514214158, "u": 10109514222052, "pu": 10109514214014, "b": [["1000.00", "26.142"], ["5000.00", "101.438"], ["7064.00", "0.028"], ["20239.80", "1.330"], ["20239.90", "0.020"], ["20339.80", "1.650"], ["40000.00", "41.356"], ["56512.00", "0.011"], ["67086.00", "0.202"], ["68520.70", "0.075"], ["69544.90", "2.369"], ["69630.90", "0.007"], ["69647.40", "0.016"], ["69933.50", "0.639"], ["69940.90", "0.002"], ["70244.20", "0.000"], ["70248.80", "0.052"], ["70304.30", "0.790"], ["70322.40", "0.106"], ["70353.40", "0.000"], ["70355.30", "0.000"], ["70361.80", "0.008"], ["70436.50", "0.089"], ["70452.60", "0.004"], ["70452.70", "0.000"], ["70458.00", "0.511"], ["70459.80", "0.014"], ["70466.80", "0.672"], ["70467.20", "0.161"], ["70473.80", "0.000"], ["70477.30", "0.173"], ["70480.90", "0.000"], ["70481.00", "0.000"], ["70484.50", "0.053"], ["70484.90", "0.241"], ["70487.10", "0.129"], ["70492.90", "0.002"], ["70493.50", "7.019"], ["70505.90", "0.000"], ["70506.40", "0.000"], ["70507.60", "0.754"], ["70510.00", "0.043"], ["70517.10", "0.000"], ["70517.40", "0.001"], ["70519.20", "0.002"], ["70521.30", "0.028"], ["70524.10", "0.002"], ["70541.40", "0.012"], ["70542.00", "0.700"], ["70545.20", "0.002"], ["70547.20", "0.002"], ["70547.90", "0.278"], ["70548.80", "0.096"], ["70549.00", "0.000"], ["70551.00", "0.301"], ["70554.00", "0.854"], ["70554.80", "0.055"], ["70556.20", "0.041"], ["70562.10", "0.171"], ["70564.40", "0.093"], ["70567.40", "0.052"], ["70567.70", "0.008"], ["70570.10", "0.000"], ["70570.20", "0.049"], ["70574.00", "0.315"], ["70574.60", "0.002"], ["70576.20", "0.000"], ["70576.80", "0.283"], ["70578.50", "0.203"], ["70583.30", "0.028"], ["70583.50", "0.272"], ["70585.20", "0.002"], ["70585.50", "3.629"], ["70586.10", "0.004"], ["70586.80", "0.000"], ["70588.00", "0.135"], ["70588.20", "1.066"], ["70590.40", "0.059"], ["70590.50", "0.003"], ["70591.40", "0.002"], ["70591.50", "0.004"], ["70591.90", "0.005"], ["70592.40", "0.689"], ["70592.50", "0.278"], ["70592.60", "0.115"], ["70593.40", "1.413"], ["70594.70", "0.035"], ["70595.30", "0.006"], ["70597.40", "0.032"], ["70597.50", "0.158"], ["70598.40", "0.075"], ["70598.70", "0.000"], ["70599.10", "0.371"], ["70600.90", "0.000"], ["70601.20", "0.002"], ["70601.50", "0.243"], ["70601.60", "0.000"], ["70602.40", "0.222"], ["70602.70", "0.247"], ["70602.80", "0.635"], ["70602.90", "0.354"], ["70603.40", "0.017"], ["70604.30", "0.000"], ["70604.40", "0.004"], ["70604.50", "0.069"], ["70604.80", "0.713"], ["70605.00", "0.088"], ["70605.40", "0.002"], ["70606.00", "0.032"], ["70606.10", "0.105"], ["70606.20", "0.002"], ["70607.40", "0.000"], ["70607.70", "0.354"], ["70608.00", "0.004"], ["70608.10", "0.045"], ["70609.50", "0.003"], ["70609.70", "0.004"], ["70609.80", "0.003"], ["70610.00", "0.584"], ["70610.30", "0.002"], ["70610.80", "0.857"], ["70611.50", "0.005"], ["70611.80", "0.000"], ["70612.10", "0.031"], ["70613.00", "0.446"], ["70614.40", "0.866"], ["70615.10", "0.670"], ["70615.60", "0.004"], ["70616.00", "0.017"], ["70616.10", "0.276"], ["70616.60", "0.061"], ["70618.60", "0.455"], ["70618.70", "0.005"], ["70619.50", "0.005"], ["70621.70", "0.000"], ["70622.00", "0.201"], ["70622.10", "0.519"], ["70622.50", "0.000"], ["70623.00", "0.015"], ["70623.20", "0.022"], ["70623.30", "0.002"], ["70623.40", "0.034"], ["70624.30", "0.003"], ["70624.80", "0.017"], ["70625.60", "0.031"], ["70625.70", "0.007"], ["70625.80", "0.005"], ["70626.10", "0.003"], ["70626.30", "0.420"], ["70626.50", "0.462"], ["70626.80", "0.010"], ["70626.90", "0.021"], ["70627.10", "0.008"], ["70627.80", "0.000"], ["70628.00", "0.005"], ["70628.40", "0.004"], ["70628.70", "0.000"], ["70629.10", "0.513"], ["70629.30", "0.264"], ["70629.70", "0.566"], ["70629.90", "0.070"], ["70630.00", "0.790"], ["70630.60", "0.071"], ["70630.80", "0.036"], ["70630.90", "0.946"], ["70631.10", "0.003"], ["70631.20", "0.001"], ["70631.30", "0.003"], ["70631.40", "0.022"], ["70631.50", "0.206"], ["70631.60", "0.057"], ["70631.70", "0.003"], ["70631.80", "0.275"], ["70631.90", "0.033"], ["70632.00", "0.202"], ["70632.10", "0.002"], ["70632.20", "0.000"], ["70632.30", "0.007"], ["70632.40", "0.513"], ["70632.60", "0.005"], ["70632.70", "0.002"], ["70632.80", "0.000"], ["70632.90", "0.261"], ["70633.00", "0.014"], ["70633.30", "0.641"], ["70633.40", "0.045"], ["70633.50", "0.512"], ["70633.60", "0.000"], ["70633.70", "0.003"], ["70633.80", "0.061"], ["70634.10", "0.004"], ["70634.30", "0.000"], ["70634.40", "0.004"], ["70634.80", "0.004"], ["70634.90", "0.012"], ["70635.10", "0.026"], ["70635.20", "0.000"], ["70635.40", "0.283"], ["70635.50", "0.001"], ["70636.20", "0.657"], ["70636.40", "0.002"], ["70636.90", "0.001"], ["70637.00", "0.029"], ["70637.20", "0.283"], ["70637.30", "0.007"], ["70637.70", "0.004"], ["70637.80", "0.004"], ["70637.90", "0.003"], ["70638.20", "0.002"], ["70638.30", "0.002"], ["70638.40", "0.435"], ["70638.50", "0.002"], ["70638.60", "0.002"], ["70639.20", "0.000"], ["70639.30", "0.005"], ["70639.40", "0.002"], ["70639.70", "0.028"], ["70639.80", "0.374"], ["70639.90", "1.968"], ["70640.00", "4.716"], ["70640.10", "0.511"], ["70640.30", "0.393"], ["70640.40", "0.000"], ["70640.50", "0.018"], ["70640.70", "0.230"], ["70640.90", "0.000"], ["70641.00", "0.002"], ["70641.10", "0.000"], ["70641.20", "0.668"], ["70641.40", "0.005"], ["70641.50", "0.000"], ["70641.70", "0.861"], ["70641.80", "0.000"], ["70642.00", "0.002"], ["70642.20", "0.430"], ["70642.30", "0.024"], ["70642.40", "1.125"], ["70642.50", "0.014"], ["70642.60", "0.014"], ["70642.70", "0.014"], ["70642.80", "0.186"], ["70642.90", "0.002"], ["70643.00", "0.000"], ["70643.20", "0.358"], ["70643.30", "0.028"], ["70643.40", "0.240"], ["70643.60", "0.409"], ["70643.70", "0.000"], ["70643.80", "0.190"], ["70643.90", "0.307"], ["70644.00", "0.016"], ["70644.10", "0.014"], ["70644.20", "0.018"], ["70644.30", "0.014"], ["70644.50", "0.889"], ["70644.60", "0.014"], ["70644.70", "0.014"], ["70644.90", "0.014"], ["70645.00", "0.018"], ["70645.10", "0.014"], ["70645.20", "0.014"], ["70645.30", "0.016"], ["70645.40", "0.014"], ["70645.60", "0.014"], ["70645.70", "0.022"], ["70645.80", "0.014"], ["70645.90", "0.016"], ["70646.10", "0.014"], ["70646.20", "0.014"], ["70646.30", "0.014"], ["70646.40", "0.014"], ["70646.70", "0.014"], ["70646.80", "0.000"], ["70646.90", "0.003"], ["70647.00", "0.000"], ["70647.10", "0.000"], ["70647.20", "0.000"], ["70647.30", "0.057"], ["70647.40", "7.356"]], "a": [["70639.90", "0.000"], ["70640.00", "0.000"], ["70640.10", "0.000"], ["70640.20", "0.000"], ["70640.50", "0.000"], ["70640.60", "0.000"], ["70640.80", "0.000"], ["70641.00", "0.000"], ["70641.10", "0.000"], ["70641.20", "0.000"], ["70641.30", "0.000"], ["70641.60", "0.000"], ["70641.80", "0.000"], ["70641.90", "0.000"], ["70642.30", "0.000"], ["70642.50", "0.000"], ["70642.60", "0.000"], ["70642.70", "0.000"], ["70642.80", "0.000"], ["70642.90", "0.000"], ["70643.00", "0.000"], ["70643.10", "0.000"], ["70643.30", "0.000"], ["70643.40", "0.000"], ["70643.70", "0.000"], ["70643.90", "0.000"], ["70644.00", "0.000"], ["70644.10", "0.000"], ["70644.20", "0.000"], ["70644.30", "0.000"], ["70644.40", "0.000"], ["70644.60", "0.000"], ["70644.70", "0.000"], ["70644.80", "0.000"], ["70645.00", "0.000"], ["70645.10", "0.000"], ["70645.20", "0.000"], ["70645.30", "0.000"], ["70645.40", "0.000"], ["70645.50", "0.000"], ["70645.70", "0.000"], ["70645.80", "0.000"], ["70645.90", "0.000"], ["70646.00", "0.000"], ["70646.20", "0.000"], ["70646.30", "0.000"], ["70646.40", "0.000"], ["70646.50", "0.000"], ["70646.80", "0.000"], ["70646.90", "0.000"], ["70647.00", "0.000"], ["70647.10", "0.000"], ["70647.20", "0.000"], ["70647.30", "0.000"], ["70647.40", "0.000"], ["70647.50", "3.160"], ["70647.60", "0.019"], ["70647.80", "0.092"], ["70648.00", "0.001"], ["70648.20", "0.004"], ["70648.30", "0.001"], ["70648.60", "0.004"], ["70648.90", "0.005"], ["70649.00", "0.086"], ["70649.40", "0.002"], ["70649.60", "0.003"], ["70650.20", "0.000"], ["70650.30", "0.026"], ["70650.40", "0.038"], ["70650.60", "0.000"], ["70651.10", "0.028"], ["70651.60", "0.000"], ["70652.70", "0.078"], ["70652.80", "0.658"], ["70652.90", "0.002"], ["70653.40", "0.118"], ["70653.50", "0.074"], ["70653.60", "0.006"], ["70653.70", "0.021"], ["70653.80", "0.000"], ["70654.00", "0.021"], ["70654.60", "0.005"], ["70654.80", "0.006"], ["70655.00", "0.005"], ["70655.50", "0.009"], ["70655.60", "0.003"], ["70656.00", "0.036"], ["70656.10", "0.080"], ["70656.40", "0.002"], ["70657.10", "0.002"], ["70657.20", "0.002"], ["70657.50", "0.007"], ["70658.80", "0.000"], ["70659.20", "0.144"], ["70659.30", "0.119"], ["70659.40", "0.004"], ["70659.70", "0.191"], ["70659.80", "0.003"], ["70660.80", "0.006"], ["70661.00", "0.457"], ["70661.10", "0.222"], ["70661.20", "0.000"], ["70661.30", "0.014"], ["70661.50", "0.893"], ["70661.60", "0.009"], ["70661.70", "0.022"], ["70662.00", "0.155"], ["70662.10", "0.012"], ["70662.30", "0.003"], ["70662.40", "0.005"], ["70662.90", "0.014"], ["70663.10", "0.020"], ["70663.30", "0.008"], ["70663.80", "0.007"], ["70663.90", "0.061"], ["70664.10", "0.007"], ["70664.30", "0.102"], ["70664.60", "0.430"], ["70664.80", "0.033"], ["70665.00", "0.015"], ["70665.10", "0.005"], ["70665.30", "0.010"], ["70665.50", "0.520"], ["70665.60", "0.000"], ["70665.70", "0.022"], ["70666.10", "0.000"], ["70666.20", "0.089"], ["70666.30", "0.005"], ["70666.50", "0.074"], ["70666.60", "0.092"], ["70666.90", "0.035"], ["70667.80", "0.559"], ["70668.10", "1.066"], ["70668.20", "0.010"], ["70668.50", "0.051"], ["70668.80", "0.090"], ["70669.20", "0.019"], ["70669.40", "0.178"], ["70669.70", "0.216"], ["70669.90", "0.003"], ["70670.00", "0.295"], ["70670.90", "0.511"], ["70671.40", "0.473"], ["70672.00", "1.282"], ["70673.00", "0.509"], ["70673.40", "0.005"], ["70673.70", "0.021"], ["70673.80", "1.420"], ["70673.90", "0.003"], ["70675.20", "0.003"], ["70675.30", "0.003"], ["70676.30", "0.543"], ["70676.40", "0.840"], ["70676.60", "0.157"], ["70678.80", "0.164"], ["70678.90", "0.164"], ["70680.50", "0.002"], ["70680.90", "0.138"], ["70681.20", "0.147"], ["70681.70", "0.009"], ["70681.90", "0.002"], ["70682.00", "0.366"], ["70682.70", "0.121"], ["70682.90", "0.011"], ["70683.20", "0.004"], ["70683.90", "0.000"], ["70685.10", "0.007"], ["70686.40", "0.005"], ["70687.60", "0.002"], ["70687.70", "0.059"], ["70687.90", "0.141"], ["70690.40", "0.017"], ["70691.80", "0.261"], ["70694.10", "0.035"], ["70698.30", "0.005"], ["70699.40", "0.000"], ["70701.50", "1.098"], ["70702.20", "0.254"], ["70702.40", "0.003"], ["70703.50", "0.004"], ["70707.20", "0.107"], ["70708.00", "0.004"], ["70708.20", "0.002"], ["70708.60", "0.006"], ["70709.00", "0.022"], ["70714.30", "0.000"], ["70714.80", "0.013"], ["70717.40", "0.293"], ["70717.60", "0.002"], ["70718.90", "0.006"], ["70722.00", "0.552"], ["70722.10", "0.047"], ["70726.80", "0.000"], ["70732.50", "0.514"], ["70740.10", "0.069"], ["70750.20", "0.043"], ["70752.30", "0.431"], ["70752.80", "0.332"], ["70754.40", "0.002"], ["70774.50", "0.675"], ["70802.90", "0.099"], ["70807.60", "0.514"], ["70815.10", "2.252"], ["70822.10", "0.252"], ["70829.10", "0.002"], ["70842.80", "0.000"], ["70843.90", "0.004"], ["70844.50", "0.004"], ["70844.70", "0.000"], ["70863.80", "0.009"], ["70878.00", "0.007"], ["70887.20", "0.109"], ["70892.80", "0.366"], ["70892.90", "0.000"], ["70893.60", "0.000"], ["70893.70", "0.000"], ["70898.30", "4.067"], ["70944.40", "0.270"], ["70998.40", "0.002"], ["71346.20", "0.007"], ["71346.30", "2.940"], ["71346.40", "1.110"], ["71349.80", "0.000"], ["71350.10", "0.000"], ["71354.00", "0.049"], ["71643.10", "1.112"], ["73697.80", "0.000"], ["73873.70", "0.000"], ["74049.60", "0.002"], ["74171.80", "0.005"], ["74181.50", "0.052"], ["77306.50", "0.000"], ["77482.60", "0.000"], ["77658.70", "0.000"]]}}
{"local_ts": 1773486589227, "server_ts": 1773486589196, "data": {"e": "depthUpdate", "E": 1773486589197, "T": 1773486589196, "s": "BTCUSDT", "U": 10109514266017, "u": 10109514270016, "pu": 10109514265871, "b": [["1000.00", "26.142"], ["5000.00", "101.418"], ["7064.80", "0.000"], ["20147.40", "1.180"], ["20239.80", "1.020"], ["20247.40", "0.790"], ["33000.00", "3.785"], ["66564.70", "0.002"], ["69643.80", "0.574"], ["69940.90", "0.000"], ["70417.90", "0.019"], ["70463.70", "0.161"], ["70500.00", "3.033"], ["70508.10", "0.598"], ["70515.90", "0.160"], ["70597.50", "0.160"], ["70597.90", "0.083"], ["70608.70", "0.541"], ["70608.80", "0.354"], ["70610.30", "0.104"], ["70631.20", "0.008"], ["70632.20", "0.125"], ["70634.10", "0.002"], ["70635.30", "0.005"], ["70636.80", "0.006"], ["70639.90", "0.014"], ["70640.40", "0.075"], ["70640.70", "0.216"], ["70646.90", "0.002"], ["70647.00", "0.002"], ["70647.40", "11.266"]], "a": [["70647.50", "3.223"], ["70653.10", "0.006"], ["70654.50", "0.335"], ["70658.10", "0.002"], ["70663.90", "0.000"], ["70664.60", "0.350"], ["70666.40", "0.191"], ["70670.90", "0.551"], ["70674.90", "0.001"], ["70675.70", "0.509"], ["70678.30", "0.000"], ["70679.30", "0.070"], ["70680.20", "0.116"], ["70683.60", "0.004"], ["70683.70", "0.085"], ["70687.70", "0.002"], ["70690.70", "0.004"], ["70694.00", "0.462"], ["70695.50", "0.712"], ["70807.60", "0.516"], ["70983.10", "0.002"], ["71354.00", "1.444"], ["71730.50", "0.000"], ["74185.10", "0.010"], ["74214.20", "0.067"], ["89523.20", "0.000"]]}}
{"local_ts": 1773486590251, "server_ts": 1773486590220, "data": {"e": "depthUpdate", "E": 1773486590221, "T": 1773486590220, "s": "BTCUSDT", "U": 10109514309869, "u": 10109514314647, "pu": 10109514309719, "b": [["5000.00", "101.418"], ["7064.80", "0.056"], ["20147.40", "2.260"], ["20547.40", "0.740"], ["67080.40", "0.002"], ["67085.60", "0.000"], ["67098.90", "0.000"], ["69305.10", "1.445"], ["69373.40", "4.610"], ["69665.40", "1.720"], ["69901.80", "0.150"], ["69940.90", "0.000"], ["70347.40", "0.002"], ["70567.50", "0.002"], ["70568.70", "0.178"], ["70573.70", "10.116"], ["70574.90", "0.050"], ["70575.30", "0.104"], ["70575.60", "0.037"], ["70576.00", "0.004"], ["70576.40", "0.355"], ["70576.70", "1.031"], ["70593.40", "1.332"], ["70598.60", "0.002"], ["70599.00", "0.056"], ["70601.70", "0.007"], ["70602.10", "0.002"], ["70602.40", "0.105"], ["70602.70", "0.206"], ["70602.80", "0.563"], ["70603.10", "0.007"], ["70603.50", "0.006"], ["70603.80", "0.007"], ["70603.90", "0.002"], ["70608.70", "0.187"], ["70608.80", "0.000"], ["70609.00", "0.178"], ["70627.50", "1.917"], ["70629.00", "0.002"], ["70629.10", "0.080"], ["70629.30", "0.009"], ["70629.60", "0.057"], ["70629.70", "0.681"], ["70630.00", "0.665"], ["70630.20", "0.528"], ["70630.40", "0.075"], ["70630.70", "0.004"], ["70630.90", "0.633"], ["70636.80", "0.006"], ["70639.90", "0.014"], ["70640.40", "0.075"], ["70644.80", "0.002"]], "a": [["70647.50", "3.052"], ["70650.40", "0.013"], ["70650.70", "0.002"], ["70650.80", "0.044"], ["70651.00", "0.006"], ["70651.10", "0.003"], ["70651.40", "0.003"], ["70651.80", "0.005"], ["70651.90", "0.036"], ["70652.10", "0.075"], ["70652.40", "0.043"], ["70652.70", "0.093"], ["70653.20", "0.021"], ["70654.50", "0.335"], ["70657.20", "0.002"], ["70658.10", "0.002"], ["70659.60", "0.007"], ["70661.20", "0.000"], ["70664.40", "0.006"], ["70665.40", "0.076"], ["70666.30", "0.045"], ["70670.90", "0.511"], ["70673.60", "0.057"], ["70677.40", "0.055"], ["70677.70", "0.094"], ["70678.10", "0.007"], ["70678.40", "0.000"], ["70678.50", "0.084"], ["70678.70", "0.062"], ["70678.80", "0.006"], ["70679.10", "0.544"], ["70679.60", "0.284"], ["70682.20", "0.014"], ["70682.70", "0.000"], ["70690.70", "0.002"], ["70704.40", "0.000"], ["70704.50", "0.067"], ["70704.70", "0.257"], ["70705.10", "0.002"], ["70705.40", "0.134"], ["70705.50", "0.036"], ["70705.60", "0.036"], ["70705.80", "0.250"], ["70706.10", "0.006"], ["70706.20", "0.092"], ["70707.40", "1.150"], ["70712.40", "10.160"], ["70713.60", "0.000"], ["71354.00", "1.446"], ["72052.60", "0.005"], ["89523.20", "0.000"]]}}
{"local_ts": 1773486591271, "server_ts": 1773486591240, "data": {"e": "depthUpdate", "E": 1773486591241, "T": 1773486591240, "s": "BTCUSDT", "U": 10109514364896, "u": 10109514370583, "pu": 10109514364733, "b": [["1000.00", "26.142"], ["5000.00", "101.398"], ["7064.80", "0.056"], ["20147.40", "0.060"], ["20447.40", "0.350"], ["20547.40", "2.590"], ["33000.00", "3.789"], ["40000.00", "41.317"], ["67099.70", "0.002"], ["69940.90", "0.000"], ["70294.20", "0.003"], ["70484.90", "0.241"], ["70507.90", "0.000"], ["70562.60", "0.112"], ["70575.50", "0.087"], ["70598.60", "0.004"], ["70599.10", "0.371"], ["70621.90", "0.212"], ["70629.70", "0.494"], ["70634.30", "0.000"], ["70635.70", "0.009"], ["70635.90", "0.028"], ["70636.40", "0.010"], ["70636.60", "0.290"], ["70636.80", "0.010"], ["70636.90", "0.022"], ["70637.00", "0.038"], ["70637.70", "0.018"], ["70638.00", "0.018"], ["70638.60", "0.009"], ["70643.40", "0.245"], ["70647.40", "12.253"]], "a": [["70647.50", "1.704"], ["70650.20", "0.000"], ["70655.30", "0.454"], ["70662.10", "0.278"], ["70663.20", "0.010"], ["70665.60", "0.000"], ["70666.50", "0.010"], ["70679.30", "0.099"], ["70683.10", "2.306"], ["70711.50", "0.002"], ["70713.20", "0.007"], ["70779.90", "0.000"], ["71354.00", "1.444"], ["89523.20", "0.000"]]}}
{"local_ts": 1773486592291, "server_ts": 1773486592257, "data": {"e": "depthUpdate", "E": 1773486592261, "T": 1773486592257, "s": "BTCUSDT", "U": 10109514428392, "u": 10109514434104, "pu": 10109514428123, "b": [["1000.00", "26.142"], ["5000.00", "101.418"], ["7064.80", "0.056"], ["20347.40", "0.180"], ["20447.40", "2.470"], ["20547.40", "0.350"], ["67094.60", "0.006"], ["69940.90", "0.000"], ["70316.00", "0.102"], ["70316.70", "0.018"], ["70639.90", "0.011"]], "a": [["70647.50", "1.829"], ["70651.20", "0.025"], ["70657.20", "0.010"], ["70658.10", "0.000"], ["70660.10", "0.024"], ["70684.40", "0.002"], ["70711.50", "0.000"], ["71354.00", "1.444"], ["89523.20", "0.000"]]}}
{"local_ts": 1773486593309, "server_ts": 1773486593277, "data": {"e": "depthUpdate", "E": 1773486593281, "T": 1773486593277, "s": "BTCUSDT", "U": 10109514506293, "u": 10109514520939, "pu": 10109514506018, "b": [["5000.00", "101.418"], ["7064.80", "0.028"], ["20247.40", "0.030"], ["20347.40", "2.320"], ["20447.40", "0.650"], ["69234.50", "0.030"], ["69373.40", "3.458"], ["69940.90", "0.000"], ["70294.20", "0.039"], ["70314.00", "0.018"], ["70401.10", "0.004"], ["70547.40", "0.000"], ["70547.50", "0.219"], ["70554.40", "0.092"], ["70554.50", "0.206"], ["70561.50", "0.000"], ["70561.60", "0.358"], ["70587.30", "0.006"], ["70594.30", "0.088"], ["70594.40", "0.081"], ["70597.70", "0.089"], ["70597.90", "0.085"], ["70598.30", "2.347"], ["70608.90", "0.229"], ["70616.30", "0.004"], ["70630.80", "0.224"], ["70633.50", "0.385"], ["70635.50", "0.058"], ["70636.80", "0.521"], ["70639.90", "0.011"], ["70640.50", "0.700"], ["70640.60", "0.003"], ["70642.50", "0.000"], ["70643.00", "0.371"], ["70644.00", "0.005"], ["70644.70", "0.021"], ["70647.30", "0.107"], ["70647.40", "8.099"]], "a": [["70647.50", "3.834"], ["70648.40", "0.000"], ["70648.50", "0.001"], ["70654.60", "0.012"], ["70658.10", "0.003"], ["70675.80", "0.095"], ["70679.30", "0.000"], ["70680.60", "0.615"], ["70681.90", "0.002"], ["70682.80", "0.193"], ["70683.00", "0.252"], ["70683.60", "0.089"], ["70683.80", "0.002"], ["70684.40", "0.000"], ["70705.90", "0.093"], ["70724.10", "0.048"], ["70724.20", "0.073"], ["70731.20", "0.000"], ["70731.30", "0.075"], ["70738.20", "0.213"], ["70738.30", "0.075"], ["70782.90", "0.008"], ["70871.20", "0.000"], ["71353.90", "0.010"], ["71354.00", "1.444"], ["74199.10", "0.002"], ["89523.20", "0.000"]]}}
{"local_ts": 1773486594330, "server_ts": 1773486594300, "data": {"e": "depthUpdate", "E": 1773486594301, "T": 1773486594300, "s": "BTCUSDT", "U": 10109514575137, "u": 10109514580485, "pu": 10109514575064, "b": [["1000.00", "26.142"], ["5000.00", "101.418"], ["7064.80", "0.028"], ["20247.40", "1.940"], ["20347.40", "1.060"], ["67115.00", "0.019"], ["68508.20", "3.498"], ["69820.80", "0.572"], ["69940.90", "0.000"], ["70294.30", "0.000"], ["70400.50", "0.000"], ["70400.70", "0.351"], ["70594.20", "0.089"], ["70594.30", "0.003"], ["70598.50", "0.014"], ["70632.70", "0.172"], ["70632.80", "0.296"], ["70639.90", "0.330"]], "a": [["70647.50", "4.201"], ["70656.40", "0.004"], ["70658.10", "0.003"], ["70661.20", "0.003"], ["70677.00", "0.258"], ["70678.60", "0.404"], ["70681.00", "0.008"], ["70871.80", "0.002"], ["71203.00", "0.000"], ["71212.70", "3.644"], ["71354.00", "1.444"], ["74198.40", "0.004"], ["74199.40", "0.000"], ["89523.20", "0.000"]]}}
{"local_ts": 1773486595353, "server_ts": 1773486595322, "data": {"e": "depthUpdate", "E": 1773486595323, "T": 1773486595322, "s": "BTCUSDT", "U": 10109514626567, "u": 10109514631770, "pu": 10109514626511, "b": [["5000.00", "101.418"], ["7064.80", "0.028"], ["20147.40", "1.490"], ["20247.40", "1.510"], ["67107.90", "0.214"], ["68858.40", "0.000"], ["69940.90", "0.002"], ["70308.30", "0.106"], ["70400.80", "0.002"], ["70533.50", "0.004"], ["70537.30", "0.328"], ["70539.30", "0.000"], ["70546.50", "0.042"], ["70547.70", "0.000"], ["70548.40", "0.330"], ["70548.50", "0.000"], ["70548.80", "0.096"], ["70549.20", "0.000"], ["70549.30", "0.000"], ["70549.50", "0.083"], ["70549.70", "0.603"], ["70549.90", "0.000"], ["70550.40", "0.092"], ["70554.70", "0.002"], ["70555.40", "0.254"], ["70561.80", "0.002"], ["70562.50", "0.091"], ["70562.80", "0.096"], ["70568.00", "0.000"], ["70569.20", "1.002"], ["70574.20", "0.000"], ["70575.30", "0.000"], ["70575.40", "0.003"], ["70575.70", "0.166"], ["70576.00", "0.004"], ["70576.10", "0.005"], ["70576.40", "0.283"], ["70576.70", "1.080"], ["70576.80", "0.145"], ["70577.10", "0.084"], ["70580.30", "0.053"], ["70581.00", "0.340"], ["70594.30", "0.003"], ["70594.40", "0.166"], ["70603.70", "0.543"], ["70612.10", "0.031"], ["70629.10", "0.004"], ["70629.40", "0.003"], ["70629.50", "0.254"], ["70629.80", "0.006"], ["70630.20", "0.456"], ["70630.50", "0.003"], ["70630.90", "0.287"], ["70631.60", "0.000"], ["70632.80", "0.112"], ["70633.70", "0.059"], ["70634.40", "0.057"], ["70647.40", "9.137"]], "a": [["70647.50", "2.984"], ["70650.10", "0.001"], ["70650.40", "0.013"], ["70650.80", "0.008"], ["70651.10", "0.003"], ["70651.20", "0.000"], ["70651.30", "0.025"], ["70651.40", "0.003"], ["70651.50", "0.003"], ["70651.90", "0.000"], ["70652.00", "0.026"], ["70652.30", "0.079"], ["70652.70", "0.000"], ["70654.50", "0.105"], ["70657.40", "0.008"], ["70658.50", "0.004"], ["70659.90", "0.014"], ["70671.20", "0.039"], ["70676.20", "0.618"], ["70677.00", "0.233"], ["70677.30", "0.000"], ["70677.70", "0.058"], ["70678.00", "0.242"], ["70678.10", "0.007"], ["70678.40", "0.000"], ["70678.70", "0.051"], ["70679.10", "0.544"], ["70679.30", "0.159"], ["70681.80", "0.014"], ["70682.20", "0.014"], ["70682.80", "0.241"], ["70683.70", "0.000"], ["70683.80", "0.087"], ["70692.10", "0.052"], ["70703.80", "0.000"], ["70704.20", "0.000"], ["70704.50", "0.031"], ["70704.70", "0.282"], ["70704.90", "0.026"], ["70705.20", "0.002"], ["70705.30", "0.002"], ["70705.40", "0.159"], ["70705.50", "0.000"], ["70705.60", "0.000"], ["70706.80", "0.000"], ["70711.80", "0.202"], ["70712.90", "0.046"], ["70713.90", "0.738"], ["70714.30", "0.077"], ["70724.40", "0.003"], ["70725.10", "0.074"], ["70731.50", "1.669"], ["70732.20", "0.074"], ["70738.50", "0.042"], ["70739.20", "0.071"], ["71196.00", "0.086"], ["71354.00", "2.247"], ["71478.60", "0.140"], ["72060.40", "0.285"], ["74213.70", "0.002"], ["89523.20", "0.000"]]}}
{"local_ts": 1773486596379, "server_ts": 1773486596345, "data": {"e": "depthUpdate", "E": 1773486596347, "T": 1773486596345, "s": "BTCUSDT", "U": 10109514673685, "u": 10109514678097, "pu": 10109514673386, "b": [["1000.00", "26.142"], ["5000.00", "101.418"], ["7064.80", "0.000"], ["20147.40", "1.950"], ["20547.40", "1.050"], ["69234.50", "0.027"], ["69940.90", "0.714"], ["70294.20", "0.039"], ["70308.30", "0.000"], ["70562.60", "0.075"], ["70590.80", "0.000"], ["70603.70", "0.189"], ["70613.10", "0.356"], ["70630.90", "0.179"], ["70636.80", "0.521"], ["70638.20", "0.006"], ["70640.00", "0.007"], ["70640.40", "0.006"], ["70640.60", "0.003"], ["70647.30", "0.107"], ["70647.40", "8.439"]], "a": [["70647.50", "3.592"], ["70650.10", "0.001"], ["70651.50", "0.007"], ["70653.40", "0.041"], ["70654.50", "0.077"], ["70658.10", "0.003"], ["70659.50", "0.002"], ["70661.30", "0.032"], ["70679.20", "1.025"], ["70710.50", "3.291"], ["70753.80", "0.010"], ["70756.60", "0.085"], ["70801.40", "0.002"], ["70804.90", "0.000"], ["70871.90", "0.007"], ["71353.90", "0.003"], ["71354.00", "2.144"], ["71633.00", "0.000"], ["71650.70", "0.840"], ["74198.10", "0.005"], ["74211.30", "0.000"], ["89523.20", "0.000"]]}}
{"local_ts": 1773486597396, "server_ts": 1773486597364, "data": {"e": "depthUpdate", "E": 1773486597367, "T": 1773486597364, "s": "BTCUSDT", "U": 10109514720499, "u": 10109514723011, "pu": 10109514720477, "b": [["1000.00", "26.142"], ["5000.00", "101.418"], ["7064.80", "0.000"], ["20147.40", "0.000"], ["20447.40", "0.600"], ["20547.40", "2.400"], ["67088.20", "0.004"], ["67092.60", "0.002"], ["67103.00", "0.000"], ["69940.90", "2.142"], ["69941.00", "0.007"], ["70400.40", "0.044"], ["70400.90", "0.000"], ["70548.50", "0.108"], ["70548.70", "0.296"], ["70555.50", "0.000"], ["70555.70", "0.112"], ["70559.50", "0.000"], ["70562.60", "0.004"], ["70562.80", "0.167"], ["70589.90", "0.491"], ["70630.80", "0.116"], ["70644.20", "0.004"]], "a": [["70650.60", "0.000"], ["70652.30", "0.036"], ["70652.60", "0.060"], ["70653.40", "0.104"], ["70675.40", "0.016"], ["70680.20", "0.000"], ["70683.70", "0.085"], ["70712.40", "10.129"], ["70718.20", "0.002"], ["70725.20", "1.088"], ["70725.30", "0.071"], ["70732.30", "0.504"], ["70732.40", "0.073"], ["70739.30", "1.542"], ["70739.40", "0.071"], ["70749.50", "0.008"], ["70753.80", "0.008"], ["70756.60", "0.092"], ["70763.70", "0.009"], ["70770.80", "0.007"], ["70777.90", "0.010"], ["70785.00", "0.724"], ["70792.10", "0.012"], ["70799.20", "0.048"], ["70801.40", "0.000"], ["70829.00", "0.315"], ["70836.10", "0.000"], ["70843.20", "0.000"], ["70850.30", "0.084"], ["70857.40", "0.009"], ["70864.50", "0.002"], ["70871.60", "0.009"], ["70878.70", "0.039"], ["71212.70", "4.556"], ["71354.00", "2.369"], ["71495.30", "4.747"], ["71764.70", "0.811"], ["74179.80", "0.005"], ["89523.20", "0.000"]]}}
{"local_ts": 1773486598420, "server_ts": 1773486598388, "data": {"e": "depthUpdate", "E": 1773486598391, "T": 1773486598388, "s": "BTCUSDT", "U": 10109514776090, "u": 10109514781286, "pu": 10109514776020, "b": [["5000.00", "101.418"], ["7064.80", "0.000"], ["20347.40", "0.290"], ["20447.40", "2.580"], ["20547.40", "0.130"], ["33000.00", "3.785"], ["68239.50", "0.000"], ["69940.90", "2.142"], ["70294.20", "0.039"], ["70481.40", "0.003"], ["70498.50", "12.668"], ["70521.30", "0.000"], ["70548.70", "0.279"], ["70548.80", "0.113"], ["70555.70", "0.994"], ["70555.80", "0.274"], ["70557.40", "6.548"], ["70562.80", "0.096"], ["70562.90", "0.251"], ["70587.30", "0.006"], ["70592.70", "3.485"], ["70598.30", "0.016"], ["70598.40", "0.075"], ["70614.10", "1.839"], ["70615.60", "0.201"], ["70637.20", "0.000"], ["70639.80", "0.542"], ["70644.10", "0.001"], ["70647.40", "9.405"]], "a": [["70651.20", "0.099"], ["70652.60", "0.053"], ["70653.20", "0.057"], ["70675.40", "0.014"], ["70687.20", "1.783"], ["70707.40", "1.162"], ["70708.40", "3.388"], ["70718.20", "0.000"], ["70725.30", "0.000"], ["70725.50", "0.073"], ["70732.40", "0.002"], ["70732.60", "0.073"], ["70735.80", "0.803"], ["70739.40", "0.000"], ["70739.60", "0.394"], ["70742.20", "2.388"], ["70743.40", "6.427"], ["70748.80", "0.048"], ["70749.50", "0.001"], ["70756.60", "0.085"], ["70763.70", "0.002"], ["70770.80", "0.000"], ["70777.90", "0.003"], ["70785.00", "0.717"], ["70792.10", "0.005"], ["70795.60", "0.007"], ["70799.20", "0.041"], ["70801.80", "2.114"], ["70801.90", "12.490"], ["70802.50", "0.000"], ["70802.70", "0.007"], ["70809.80", "0.007"], ["70816.90", "0.015"], ["70824.00", "0.898"], ["70831.10", "0.019"], ["70838.20", "0.007"], ["70845.30", "0.007"], ["71354.00", "2.144"], ["74186.80", "0.008"], ["74197.60", "0.002"]]}}
{"local_ts": 1773486599440, "server_ts": 1773486599410, "data": {"e": "depthUpdate", "E": 1773486599411, "T": 1773486599410, "s": "BTCUSDT", "U": 10109514823205, "u": 10109514828521, "pu": 10109514823183, "b": [["1000.00", "26.142"], ["5000.00", "101.418"], ["7064.80", "0.056"], ["20247.40", "0.140"], ["20347.40", "2.430"], ["20447.40", "0.430"], ["67115.10", "0.002"], ["69234.50", "0.030"], ["69940.90", "2.142"], ["70308.30", "0.106"], ["70311.80", "0.106"], ["70515.20", "0.000"], ["70548.80", "0.096"], ["70548.90", "0.020"], ["70555.80", "0.203"], ["70555.90", "0.155"], ["70562.90", "0.180"], ["70563.00", "0.774"], ["70591.20", "0.513"], ["70592.70", "3.488"], ["70594.20", "0.004"], ["70594.30", "0.088"], ["70607.30", "0.068"], ["70615.30", "0.000"], ["70616.30", "0.004"], ["70616.70", "0.172"], ["70636.80", "0.517"], ["70640.10", "0.646"], ["70643.50", "0.012"], ["70647.40", "9.386"]], "a": [["70647.50", "0.695"], ["70650.20", "0.000"], ["70650.50", "0.002"], ["70652.00", "0.062"], ["70652.40", "0.068"], ["70652.60", "0.045"], ["70652.70", "0.133"], ["70653.30", "0.002"], ["70653.40", "0.005"], ["70654.50", "0.035"], ["70655.10", "0.000"], ["70658.10", "0.111"], ["70661.40", "0.786"], ["70675.80", "0.194"], ["70679.30", "0.099"], ["70682.80", "0.137"], ["70683.60", "0.004"], ["70683.70", "0.085"], ["70725.50", "0.002"], ["70725.60", "0.073"], ["70732.60", "0.002"], ["70732.70", "0.071"], ["70734.50", "0.007"], ["70735.80", "0.801"], ["70739.60", "0.323"], ["70739.70", "0.073"], ["70748.80", "0.046"], ["70749.20", "0.088"], ["70783.70", "0.000"], ["70793.70", "0.007"], ["70795.60", "0.000"], ["70800.80", "0.007"], ["70802.70", "0.000"], ["70806.50", "0.060"], ["70807.90", "0.009"], ["70809.80", "0.000"], ["70815.00", "0.033"], ["70816.90", "0.008"], ["70822.10", "0.259"], ["70824.00", "0.891"], ["70829.20", "0.009"], ["70831.10", "0.012"], ["70836.30", "0.009"], ["70838.20", "0.000"], ["70843.40", "0.013"], ["70845.30", "0.000"], ["71354.00", "2.144"], ["71686.00", "1.366"], ["72060.40", "0.291"], ["74184.20", "0.002"]]}}
{"local_ts": 1773486600461, "server_ts": 1773486600428, "data": {"e": "depthUpdate", "E": 1773486600431, "T": 1773486600428, "s": "BTCUSDT", "U": 10109514882106, "u": 10109514890963, "pu": 10109514882084, "b": [["5000.00", "101.418"], ["7064.80", "0.056"], ["20247.40", "2.260"], ["20347.40", "0.740"], ["33000.00", "3.789"], ["67104.60", "0.002"], ["67115.00", "0.017"], ["69940.90", "2.142"], ["70304.80", "0.167"], ["70308.30", "0.000"], ["70311.80", "0.000"], ["70514.70", "0.007"], ["70515.00", "0.595"], ["70573.50", "0.074"], ["70580.60", "0.053"], ["70581.30", "0.053"], ["70587.30", "0.087"], ["70591.20", "0.513"], ["70592.70", "0.015"], ["70594.20", "0.004"], ["70598.20", "0.010"], ["70598.30", "0.016"], ["70612.10", "0.228"], ["70613.10", "0.540"], ["70614.10", "0.003"], ["70616.30", "0.004"], ["70616.70", "0.002"], ["70619.10", "0.192"], ["70621.70", "0.021"], ["70628.80", "0.017"], ["70629.80", "0.006"], ["70630.00", "0.680"], ["70631.20", "1.204"], ["70631.30", "0.085"], ["70631.90", "0.033"], ["70632.50", "0.811"], ["70632.90", "0.137"], ["70633.30", "0.024"], ["70633.80", "0.160"], ["70634.00", "0.054"], ["70634.70", "0.054"], ["70635.00", "0.135"], ["70635.10", "0.025"], ["70635.60", "0.024"], ["70635.70", "0.002"], ["70635.90", "0.024"], ["70636.00", "0.003"], ["70636.20", "0.657"], ["70636.30", "0.061"], ["70636.60", "0.000"], ["70636.70", "0.003"], ["70636.80", "0.534"], ["70636.90", "0.910"], ["70637.00", "0.031"], ["70637.10", "0.361"], ["70637.60", "0.004"], ["70637.80", "0.004"], ["70638.20", "0.018"], ["70638.80", "0.001"], ["70639.00", "1.155"], ["70639.10", "0.001"], ["70639.30", "0.005"], ["70639.40", "0.062"], ["70639.50", "0.015"], ["70639.60", "0.023"], ["70640.00", "0.010"], ["70640.10", "0.007"], ["70640.40", "0.073"], ["70640.80", "0.003"], ["70640.90", "0.001"], ["70641.10", "0.000"], ["70641.30", "0.001"], ["70641.40", "0.008"], ["70641.60", "0.001"], ["70642.00", "0.024"], ["70642.60", "0.000"], ["70642.80", "0.002"], ["70643.80", "0.002"], ["70644.20", "0.004"], ["70644.30", "0.003"], ["70644.70", "0.000"], ["70644.80", "0.214"], ["70645.10", "0.000"], ["70645.20", "0.000"], ["70645.30", "0.002"], ["70645.40", "0.000"], ["70645.90", "0.004"], ["70646.20", "0.002"], ["70646.40", "0.082"], ["70646.50", "0.000"], ["70646.80", "0.000"], ["70647.00", "0.000"], ["70647.20", "0.082"], ["70647.30", "0.162"], ["70647.40", "8.223"]], "a": [["70647.50", "4.324"], ["70648.00", "0.000"], ["70648.10", "0.008"], ["70648.20", "0.004"], ["70648.30", "0.001"], ["70648.40", "0.015"], ["70648.50", "0.022"], ["70649.00", "0.017"], ["70649.10", "0.004"], ["70649.30", "0.059"], ["70649.80", "0.018"], ["70650.30", "0.056"], ["70650.50", "0.010"], ["70651.00", "0.027"], ["70651.30", "0.025"], ["70651.40", "0.006"], ["70652.00", "0.026"], ["70652.30", "0.070"], ["70653.10", "0.100"], ["70653.40", "0.062"], ["70658.10", "0.017"], ["70658.40", "0.010"], ["70659.20", "0.005"], ["70660.30", "0.003"], ["70661.30", "0.002"], ["70661.80", "0.008"], ["70661.90", "0.012"], ["70662.00", "0.038"], ["70663.30", "0.142"], ["70664.40", "0.395"], ["70664.80", "0.040"], ["70665.20", "0.301"], ["70666.70", "0.004"], ["70666.80", "0.073"], ["70669.20", "0.014"], ["70670.80", "0.000"], ["70672.80", "0.942"], ["70678.00", "0.242"], ["70678.70", "0.051"], ["70679.20", "1.040"], ["70679.70", "0.005"], ["70680.20", "0.000"], ["70682.80", "0.137"], ["70683.60", "0.004"], ["70704.70", "0.282"], ["70705.40", "0.159"], ["70715.00", "0.350"], ["70734.50", "0.005"], ["70734.90", "0.447"], ["70782.00", "0.602"], ["70782.10", "0.041"], ["70821.20", "0.024"], ["70828.30", "0.007"], ["70835.40", "0.220"], ["70995.80", "0.007"], ["70999.20", "0.007"], ["71354.00", "2.144"]]}}
{"local_ts": 1773486601481, "server_ts": 1773486601452, "data": {"e": "depthUpdate", "E": 1773486601453, "T": 1773486601452, "s": "BTCUSDT", "U": 10109514950385, "u": 10109514955480, "pu": 10109514950317, "b": [["1000.00", "26.142"], ["5000.00", "101.418"], ["7064.80", "0.056"], ["20147.40", "1.810"], ["20247.40", "1.190"], ["67104.70", "0.002"], ["68943.00", "0.300"], ["69340.40", "2.877"], ["69537.10", "3.588"], ["69552.40", "5.096"], ["69608.90", "5.449"], ["69940.90", "2.142"], ["69949.20", "1.299"], ["69976.20", "1.285"], ["70180.90", "0.000"], ["70294.20", "0.111"], ["70294.30", "1.130"], ["70304.80", "0.061"], ["70308.30", "0.000"], ["70400.50", "0.000"], ["70613.10", "0.002"], ["70613.30", "0.359"], ["70613.40", "0.231"], ["70615.30", "0.184"], ["70625.00", "0.004"], ["70635.00", "0.127"], ["70636.80", "0.516"], ["70638.30", "0.002"], ["70640.00", "0.007"], ["70640.80", "0.016"], ["70643.10", "0.021"], ["70644.20", "0.033"], ["70644.40", "0.001"], ["70644.50", "0.072"], ["70646.50", "0.008"], ["70647.40", "8.868"]], "a": [["70647.50", "3.016"], ["70658.10", "0.015"], ["70672.20", "0.084"], ["70683.80", "0.080"], ["70734.90", "0.445"], ["70738.80", "2.002"], ["70785.70", "0.062"], ["70787.80", "0.101"], ["70792.80", "0.005"], ["70794.90", "0.104"], ["70799.90", "0.000"], ["70802.00", "0.024"], ["70807.00", "0.002"], ["70809.10", "0.009"], ["70814.10", "0.000"], ["70816.20", "0.007"], ["70821.20", "0.017"], ["70823.30", "0.023"], ["70828.30", "0.000"], ["70830.40", "0.007"], ["70835.40", "0.213"], ["70837.50", "0.011"], ["71354.00", "2.144"], ["71656.20", "11.079"], ["71762.10", "2.922"], ["71797.40", "0.974"], ["74202.30", "0.000"]]}}
