{"local_ts": 1773486715904, "server_ts": 1773486715874, "data": {"e": "depthUpdate", "E": 1773486715875, "T": 1773486715874, "s": "BTCUSDT", "U": 10109520283627, "u": 10109520288080, "pu": 10109520283521, "b": [["1000.00", "26.292"], ["5000.00", "101.418"], ["7062.30", "0.028"], ["20122.60", "2.470"], ["20222.60", "0.330"], ["20522.60", "0.200"], ["63560.30", "0.002"], ["67062.50", "0.031"], ["67081.90", "0.002"], ["67564.80", "0.002"], ["67592.20", "0.006"], ["67593.70", "0.018"], ["67614.20", "0.022"], ["67633.50", "0.000"], ["67641.10", "0.010"], ["67666.70", "0.009"], ["67670.40", "0.018"], ["67675.90", "0.000"], ["67689.60", "8.624"], ["67693.40", "0.016"], ["67694.60", "0.096"], ["67704.00", "0.674"], ["67708.80", "0.020"], ["67723.20", "0.008"], ["67724.50", "0.006"], ["67727.10", "0.002"], ["67732.80", "0.002"], ["67747.20", "0.030"], ["67752.90", "0.012"], ["67755.10", "0.016"], ["67755.40", "0.073"], ["67759.20", "0.036"], ["67764.50", "0.000"], ["67775.70", "0.010"], ["67789.30", "0.020"], ["67795.80", "0.013"], ["67798.30", "0.008"], ["67799.50", "0.038"], ["67802.90", "0.012"], ["67814.90", "0.014"], ["67825.00", "0.022"], ["67843.00", "0.002"], ["69810.40", "1.144"], ["69916.40", "0.714"], ["70269.50", "0.043"], ["70534.10", "1.120"], ["70569.10", "0.188"], ["70569.60", "0.240"], ["70569.90", "0.172"], ["70588.60", "1.907"], ["70590.50", "0.003"], ["70591.60", "0.000"], ["70598.10", "7.797"], ["70598.90", "0.002"], ["70599.00", "0.054"], ["70599.10", "0.288"], ["70602.60", "1.248"], ["70604.90", "0.859"], ["70607.50", "0.003"], ["70607.80", "0.182"], ["70608.40", "0.775"], ["70608.70", "1.562"], ["70610.20", "0.000"], ["70612.00", "0.002"], ["70615.00", "0.018"], ["70615.60", "0.137"], ["70616.50", "0.058"], ["70617.60", "0.007"], ["70620.10", "0.063"], ["70621.20", "0.002"], ["70622.50", "0.001"], ["70622.60", "1.554"]], "a": [["70622.70", "6.675"], ["70622.80", "0.079"], ["70624.60", "0.437"], ["70626.00", "0.008"], ["70628.50", "0.003"], ["70629.70", "0.002"], ["70629.80", "0.011"], ["70630.00", "0.217"], ["70631.10", "0.000"], ["70633.10", "0.021"], ["70633.30", "0.000"], ["70633.50", "0.008"], ["70634.00", "0.009"], ["70651.70", "0.003"], ["70653.70", "0.001"], ["70693.30", "0.002"], ["70846.70", "0.542"], ["71328.90", "0.002"], ["71641.80", "0.697"], ["72041.70", "0.003"], ["73200.50", "0.100"], ["73237.80", "0.002"], ["73241.70", "0.008"], ["73267.70", "0.008"], ["73298.10", "0.014"], ["73300.80", "0.015"], ["73313.80", "0.019"], ["73315.20", "0.008"], ["73315.90", "0.012"], ["73317.70", "0.014"], ["73319.80", "0.006"], ["73326.30", "0.006"], ["73330.50", "0.038"], ["73338.70", "0.002"], ["73341.90", "0.054"], ["73355.30", "0.000"], ["73356.90", "0.002"], ["73363.80", "0.008"], ["73365.00", "0.022"], ["73370.20", "0.002"], ["73381.40", "0.805"], ["73393.50", "0.026"], ["73393.90", "0.002"], ["73401.70", "0.043"], ["73404.70", "0.008"], ["73404.80", "0.002"], ["73445.40", "0.016"], ["73454.00", "0.028"], ["73454.20", "0.004"], ["73456.10", "0.014"], ["73460.90", "0.010"], ["73472.20", "0.016"], ["73477.90", "0.002"], ["73485.40", "0.028"], ["77685.00", "0.002"], ["89523.20", "0.000"]]}}
{"local_ts": 1773486716931, "server_ts": 1773486716896, "data": {"e": "depthUpdate", "E": 1773486716899, "T": 1773486716896, "s": "BTCUSDT", "U": 10109520322091, "u": 10109520325875, "pu": 10109520322036, "b": [["1000.00", "26.292"], ["5000.00", "101.418"], ["7062.30", "0.028"], ["20122.60", "0.620"], ["20422.60", "0.050"], ["20522.60", "2.330"], ["56498.10", "0.000"], ["63560.30", "0.002"], ["67100.50", "0.015"], ["69216.60", "0.005"], ["69640.90", "0.934"], ["69859.90", "0.030"], ["69916.40", "0.714"], ["70453.10", "0.257"], ["70489.30", "0.809"], ["70531.30", "1.220"], ["70532.80", "0.395"], ["70537.50", "0.000"], ["70538.80", "1.613"], ["70540.70", "0.002"], ["70544.10", "0.000"], ["70544.90", "0.003"], ["70545.10", "1.000"], ["70545.40", "0.009"], ["70545.80", "0.000"], ["70546.10", "2.031"], ["70546.50", "0.000"], ["70546.80", "0.117"], ["70547.20", "0.043"], ["70554.80", "0.072"], ["70559.00", "0.003"], ["70559.30", "1.795"], ["70560.00", "0.178"], ["70561.10", "0.073"], ["70561.40", "0.052"], ["70564.50", "2.584"], ["70565.30", "0.093"], ["70569.00", "0.000"], ["70569.60", "0.087"], ["70569.70", "0.147"], ["70570.10", "0.000"], ["70570.40", "0.319"], ["70570.80", "0.000"], ["70571.10", "0.002"], ["70571.50", "0.513"], ["70575.10", "0.500"], ["70576.70", "0.551"], ["70598.90", "0.002"], ["70599.00", "0.139"], ["70601.40", "0.643"], ["70602.60", "1.205"], ["70604.80", "0.725"], ["70604.90", "0.975"], ["70607.50", "0.003"], ["70608.30", "0.002"], ["70608.40", "0.022"], ["70608.60", "0.686"], ["70608.70", "1.288"], ["70609.00", "0.547"], ["70609.40", "0.009"], ["70609.70", "0.401"], ["70609.80", "0.003"], ["70610.00", "0.466"], ["70610.10", "0.000"], ["70610.30", "0.127"], ["70611.40", "0.003"], ["70615.50", "0.452"], ["70615.60", "0.165"], ["70615.80", "0.064"], ["70617.20", "0.000"], ["70618.50", "0.005"], ["70618.60", "0.001"], ["70618.70", "0.036"], ["70620.10", "0.063"], ["70622.60", "1.521"]], "a": [["70622.70", "6.034"], ["70622.80", "0.077"], ["70624.20", "0.002"], ["70626.60", "0.034"], ["70629.70", "0.067"], ["70633.10", "0.025"], ["70633.40", "0.064"], ["70633.70", "0.024"], ["70634.10", "0.079"], ["70634.40", "0.305"], ["70634.50", "0.599"], ["70634.80", "0.659"], ["70635.20", "0.004"], ["70636.20", "0.003"], ["70636.80", "0.001"], ["70637.10", "0.039"], ["70639.20", "0.025"], ["70639.30", "0.003"], ["70657.40", "0.035"], ["70657.70", "0.036"], ["70658.80", "0.888"], ["70659.00", "0.093"], ["70661.20", "0.036"], ["70664.20", "0.000"], ["70664.60", "0.021"], ["70664.90", "0.005"], ["70665.30", "0.004"], ["70665.60", "0.000"], ["70665.90", "0.017"], ["70666.00", "0.306"], ["70666.20", "1.375"], ["70668.20", "0.000"], ["70668.40", "0.002"], ["70683.80", "0.123"], ["70686.30", "0.109"], ["70688.30", "0.036"], ["70688.50", "0.000"], ["70688.90", "0.085"], ["70689.20", "0.000"], ["70689.60", "0.379"], ["70689.90", "1.209"], ["70690.30", "0.040"], ["70690.40", "0.004"], ["70691.10", "0.085"], ["70694.70", "0.000"], ["70695.50", "0.002"], ["70700.40", "0.003"], ["70754.00", "0.584"], ["70792.20", "0.548"], ["70847.20", "0.000"], ["70905.20", "0.007"], ["71328.90", "1.402"], ["71853.80", "0.698"], ["74181.40", "0.000"], ["74188.70", "0.002"], ["77685.00", "0.002"], ["89523.20", "0.000"]]}}
{"local_ts": 1773486717951, "server_ts": 1773486717919, "data": {"e": "depthUpdate", "E": 1773486717921, "T": 1773486717919, "s": "BTCUSDT", "U": 10109520402924, "u": 10109520409763, "pu": 10109520402909, "b": [["5000.00", "101.418"], ["7062.20", "0.028"], ["20422.00", "1.910"], ["20522.60", "0.430"], ["63559.80", "0.002"], ["67070.80", "0.002"], ["69210.40", "0.008"], ["69363.30", "0.000"], ["69598.00", "7.893"], ["69915.80", "5.445"], ["69951.10", "1.354"], ["70268.90", "0.000"], ["70488.70", "0.855"], ["70531.20", "0.130"], ["70567.90", "0.003"], ["70574.30", "0.004"], ["70574.40", "0.214"], ["70586.70", "0.002"], ["70600.20", "0.322"], ["70601.20", "0.048"], ["70611.40", "0.188"], ["70613.20", "0.073"], ["70613.70", "0.000"], ["70613.80", "0.004"], ["70615.60", "0.191"], ["70620.10", "0.006"], ["70620.30", "0.008"], ["70622.00", "0.243"]], "a": [["70622.10", "10.202"], ["70622.60", "0.180"], ["70622.70", "0.264"], ["70623.20", "0.000"], ["70623.90", "0.004"], ["70624.20", "0.000"], ["70626.50", "0.221"], ["70626.60", "0.004"], ["70627.50", "0.002"], ["70628.30", "0.060"], ["70629.20", "0.126"], ["70632.70", "0.026"], ["70649.60", "0.030"], ["70657.40", "0.035"], ["70726.70", "0.256"], ["70754.10", "0.321"], ["71187.10", "0.790"], ["71328.30", "1.450"], ["71469.60", "4.164"], ["72035.30", "0.015"], ["73446.90", "0.002"], ["74173.80", "0.036"], ["77684.30", "0.002"], ["89523.20", "0.000"]]}}
{"local_ts": 1773486718973, "server_ts": 1773486718944, "data": {"e": "depthUpdate", "E": 1773486718945, "T": 1773486718944, "s": "BTCUSDT", "U": 10109520473804, "u": 10109520482820, "pu": 10109520473510, "b": [["1000.00", "26.292"], ["5000.00", "101.418"], ["7062.20", "0.000"], ["20322.00", "1.540"], ["20422.00", "1.460"], ["33000.00", "3.785"], ["56498.00", "0.000"], ["63559.80", "0.000"], ["67091.50", "0.056"], ["67091.60", "0.002"], ["69789.10", "0.000"], ["69915.80", "6.873"], ["70195.90", "5.810"], ["70268.90", "0.004"], ["70300.70", "0.219"], ["70300.80", "7.765"], ["70339.50", "0.177"], ["70377.50", "3.976"], ["70571.60", "0.011"], ["70574.20", "0.186"], ["70574.30", "0.004"], ["70593.30", "0.042"], ["70593.40", "1.331"], ["70611.40", "0.084"], ["70619.30", "0.013"], ["70621.70", "0.002"], ["70621.90", "0.004"]], "a": [["70622.10", "10.558"], ["70626.70", "0.002"], ["70629.20", "0.126"], ["70864.70", "4.433"], ["71328.30", "1.450"], ["71734.50", "0.000"], ["74154.30", "0.002"], ["74178.00", "0.050"], ["77684.30", "0.000"], ["89523.20", "0.000"]]}}
{"local_ts": 1773486719994, "server_ts": 1773486719966, "data": {"e": "depthUpdate", "E": 1773486719967, "T": 1773486719966, "s": "BTCUSDT", "U": 10109520535505, "u": 10109520541751, "pu": 10109520535501, "b": [["5000.00", "101.418"], ["7062.20", "0.000"], ["20222.00", "1.100"], ["20322.00", "1.900"], ["56498.00", "0.000"], ["63559.80", "0.000"], ["67090.00", "0.036"], ["69395.90", "1.156"], ["69680.10", "1.108"], ["69915.80", "6.880"], ["70057.00", "0.008"], ["70452.50", "0.676"], ["70483.60", "0.087"], ["70488.20", "0.090"], ["70493.40", "0.085"], ["70498.30", "0.085"], ["70500.00", "3.419"], ["70503.20", "0.713"], ["70506.00", "3.308"], ["70506.10", "0.087"], ["70507.30", "0.088"], ["70508.80", "0.090"], ["70510.50", "0.000"], ["70510.80", "0.002"], ["70513.90", "0.000"], ["70569.60", "0.002"], ["70569.70", "0.064"], ["70573.60", "0.002"], ["70574.40", "0.214"], ["70574.50", "0.005"], ["70619.30", "0.013"]], "a": [["70622.10", "10.299"], ["70628.10", "0.208"], ["70630.70", "0.004"], ["70631.30", "0.282"], ["70846.00", "2.088"], ["71151.80", "0.702"], ["71328.20", "0.018"], ["71328.30", "2.850"], ["74168.00", "0.198"], ["77684.30", "0.000"], ["89523.20", "0.000"]]}}
{"local_ts": 1773486721015, "server_ts": 1773486720984, "data": {"e": "depthUpdate", "E": 1773486720987, "T": 1773486720984, "s": "BTCUSDT", "U": 10109520611560, "u": 10109520616763, "pu": 10109520611483, "b": [["1000.00", "26.292"], ["5000.00", "101.418"], ["7062.20", "0.000"], ["20122.00", "0.650"], ["20222.00", "2.350"], ["20322.00", "0.000"], ["33000.00", "3.785"], ["63559.80", "0.000"], ["69668.60", "1.363"], ["69915.80", "6.880"], ["70057.00", "0.079"], ["70268.90", "0.000"], ["70476.80", "0.080"], ["70487.70", "0.085"], ["70492.80", "0.097"], ["70493.90", "0.168"], ["70494.70", "3.495"], ["70496.00", "0.094"], ["70498.50", "0.000"], ["70502.00", "0.001"], ["70502.40", "0.008"], ["70505.20", "0.000"], ["70506.50", "0.758"], ["70507.30", "0.002"], ["70508.50", "0.018"], ["70508.60", "1.320"], ["70511.90", "0.000"], ["70516.50", "0.000"], ["70517.00", "0.006"], ["70522.00", "0.017"], ["70522.80", "0.001"], ["70525.60", "0.000"], ["70561.50", "0.042"], ["70568.00", "0.042"], ["70572.10", "0.048"], ["70574.30", "0.143"], ["70574.50", "0.007"], ["70574.60", "0.002"], ["70597.40", "0.255"], ["70598.30", "0.087"], ["70602.60", "0.106"], ["70609.80", "0.640"], ["70610.90", "0.000"], ["70611.40", "0.328"], ["70613.60", "0.286"], ["70615.60", "0.023"], ["70619.40", "0.017"], ["70620.80", "0.061"], ["70622.00", "0.813"]], "a": [["70626.20", "0.000"], ["70626.50", "0.335"], ["70628.90", "0.658"], ["70629.00", "0.003"], ["70629.20", "0.126"], ["70629.30", "0.008"], ["70632.70", "0.029"], ["70634.30", "0.005"], ["70641.00", "0.005"], ["70642.20", "0.000"], ["70643.90", "0.023"], ["70645.10", "0.266"], ["70645.20", "0.001"], ["70646.30", "0.636"], ["70647.00", "0.000"], ["70654.30", "0.015"], ["70655.60", "0.020"], ["70846.70", "0.542"], ["71328.20", "0.011"], ["71328.30", "2.850"], ["71780.40", "2.780"], ["72418.80", "0.041"], ["74169.00", "1.802"], ["74172.00", "0.050"], ["77684.30", "0.000"]]}}
{"local_ts": 1773486722037, "server_ts": 1773486722005, "data": {"e": "depthUpdate", "E": 1773486722007, "T": 1773486722005, "s": "BTCUSDT", "U": 10109520667873, "u": 10109520675766, "pu": 10109520667770, "b": [["1000.00", "26.292"], ["5000.00", "101.418"], ["7062.20", "0.056"], ["20122.00", "2.580"], ["20222.00", "0.110"], ["20522.00", "0.310"], ["63559.80", "0.000"], ["67059.00", "0.002"], ["67090.10", "0.000"], ["67091.60", "0.002"], ["69209.60", "0.092"], ["69230.70", "0.460"], ["69492.00", "1.006"], ["69598.00", "11.769"], ["69915.80", "6.880"], ["69990.00", "1.678"], ["69990.60", "0.000"], ["70164.90", "0.008"], ["70165.50", "0.000"], ["70178.30", "0.007"], ["70300.00", "54.586"], ["70339.60", "0.004"], ["70482.70", "0.436"], ["70487.60", "0.184"], ["70491.70", "0.172"], ["70527.80", "0.000"], ["70529.10", "0.001"], ["70534.40", "0.278"], ["70535.40", "0.000"], ["70535.70", "0.000"], ["70536.10", "0.006"], ["70536.40", "0.002"], ["70536.80", "0.115"], ["70537.10", "0.004"], ["70537.50", "0.000"], ["70554.80", "0.000"], ["70555.10", "0.103"], ["70555.60", "0.000"], ["70559.30", "1.727"], ["70559.60", "0.365"], ["70559.90", "0.210"], ["70560.00", "0.030"], ["70560.30", "0.148"], ["70560.40", "0.840"], ["70560.70", "0.094"], ["70561.10", "0.001"], ["70561.40", "0.074"], ["70561.70", "0.602"], ["70561.80", "0.005"], ["70572.10", "0.134"], ["70574.30", "0.143"], ["70597.40", "0.340"], ["70597.70", "0.141"], ["70598.30", "0.002"], ["70598.60", "0.002"], ["70602.50", "0.069"], ["70602.60", "0.009"], ["70604.30", "0.456"], ["70608.00", "0.012"], ["70608.60", "0.027"], ["70608.90", "0.148"], ["70609.00", "0.124"], ["70609.30", "0.154"], ["70609.60", "0.349"], ["70609.70", "0.155"], ["70610.00", "0.488"], ["70610.40", "0.052"], ["70611.40", "0.331"], ["70613.10", "0.173"], ["70613.20", "0.088"], ["70615.00", "0.018"], ["70615.50", "0.139"], ["70615.60", "0.023"], ["70619.30", "0.013"], ["70621.80", "0.000"], ["70622.00", "0.155"]], "a": [["70622.10", "10.145"], ["70622.20", "0.373"], ["70626.40", "0.681"], ["70626.60", "0.004"], ["70629.00", "0.003"], ["70629.10", "0.459"], ["70629.20", "0.026"], ["70629.30", "0.062"], ["70630.10", "0.092"], ["70630.20", "0.003"], ["70632.70", "0.026"], ["70633.00", "0.039"], ["70633.10", "0.002"], ["70633.30", "0.022"], ["70633.40", "0.026"], ["70633.70", "0.100"], ["70633.80", "0.005"], ["70634.10", "0.076"], ["70634.20", "0.588"], ["70634.50", "0.542"], ["70635.10", "0.184"], ["70635.80", "0.016"], ["70638.20", "1.252"], ["70638.80", "0.000"], ["70642.60", "0.018"], ["70649.30", "0.000"], ["70652.20", "0.059"], ["70653.00", "0.253"], ["70653.60", "0.159"], ["70657.00", "0.028"], ["70657.30", "0.043"], ["70657.40", "0.010"], ["70657.70", "0.000"], ["70658.10", "0.000"], ["70658.40", "0.915"], ["70658.60", "0.038"], ["70658.70", "1.091"], ["70658.80", "0.664"], ["70659.00", "0.057"], ["70660.80", "0.238"], ["70661.00", "0.003"], ["70661.20", "0.000"], ["70681.30", "0.089"], ["70681.70", "0.031"], ["70682.00", "0.366"], ["70682.40", "0.000"], ["70682.70", "0.000"], ["70683.10", "2.340"], ["70683.20", "0.090"], ["70683.40", "0.138"], ["70683.80", "0.087"], ["70687.50", "0.004"], ["70687.90", "0.200"], ["70688.30", "0.000"], ["71082.00", "0.066"], ["71082.60", "0.000"], ["71259.70", "0.018"], ["71260.30", "0.002"], ["71328.30", "2.850"], ["71635.40", "1.394"], ["71697.90", "0.847"], ["72034.50", "0.026"], ["77684.30", "0.000"]]}}
{"local_ts": 1773486723064, "server_ts": 1773486723032, "data": {"e": "depthUpdate", "E": 1773486723033, "T": 1773486723032, "s": "BTCUSDT", "U": 10109520754015, "u": 10109520759237, "pu": 10109520753924, "b": [["5000.00", "101.418"], ["7062.00", "0.056"], ["20122.00", "0.390"], ["20419.60", "0.160"], ["20519.60", "1.110"], ["20522.00", "1.240"], ["33000.00", "3.789"], ["56496.00", "0.000"], ["56498.00", "0.004"], ["63557.60", "0.000"], ["69038.80", "0.006"], ["69468.80", "4.315"], ["69610.10", "20.583"], ["69710.20", "4.585"], ["69913.40", "0.000"], ["70268.90", "0.000"], ["70570.20", "0.302"], ["70594.60", "0.008"], ["70595.30", "0.003"], ["70595.80", "0.090"], ["70597.90", "0.052"], ["70598.30", "0.286"], ["70598.50", "0.004"], ["70599.10", "0.223"], ["70601.80", "0.007"], ["70602.00", "0.578"], ["70602.30", "1.203"], ["70604.80", "0.718"], ["70605.20", "0.005"], ["70605.50", "0.008"], ["70606.90", "0.040"], ["70607.30", "0.007"], ["70607.80", "0.003"], ["70609.00", "0.124"], ["70609.50", "0.285"], ["70610.40", "0.336"], ["70610.80", "0.024"], ["70612.80", "0.001"], ["70613.80", "0.004"], ["70619.60", "1.993"]], "a": [["70619.70", "8.536"], ["70619.90", "0.272"], ["70624.10", "0.008"], ["70625.20", "0.000"], ["70626.40", "0.681"], ["70626.80", "0.006"], ["70628.90", "0.006"], ["70630.30", "0.005"], ["70632.10", "0.043"], ["70634.40", "0.305"], ["70635.10", "0.205"], ["70636.60", "0.017"], ["70638.30", "1.575"], ["70639.10", "0.019"], ["70639.90", "1.071"], ["70640.60", "0.019"], ["70641.90", "0.022"], ["70642.10", "0.020"], ["70643.10", "0.023"], ["70643.20", "0.020"], ["70644.10", "0.660"], ["70644.50", "0.045"], ["70644.80", "0.000"], ["70645.50", "0.142"], ["70650.70", "0.070"], ["70651.30", "0.023"], ["70652.00", "0.146"], ["70653.20", "0.456"], ["70771.70", "0.041"], ["70792.70", "0.159"], ["71194.90", "0.081"], ["71325.90", "0.000"], ["71646.10", "10.420"], ["71787.40", "2.106"], ["74176.50", "0.052"], ["77681.70", "0.003"]]}}
{"local_ts": 1773486724084, "server_ts": 1773486724052, "data": {"e": "depthUpdate", "E": 1773486724055, "T": 1773486724052, "s": "BTCUSDT", "U": 10109520797819, "u": 10109520802355, "pu": 10109520797781, "b": [["1000.00", "26.292"], ["5000.00", "101.398"], ["7062.00", "0.056"], ["20319.60", "0.010"], ["20419.60", "2.300"], ["20519.60", "0.690"], ["67054.10", "0.000"], ["68504.20", "0.000"], ["69454.40", "2.012"], ["69595.60", "5.020"], ["69913.40", "0.000"], ["70572.70", "0.232"], ["70572.80", "0.394"], ["70584.30", "0.000"], ["70596.00", "0.566"], ["70596.10", "0.553"], ["70596.20", "0.335"], ["70596.30", "0.095"], ["70606.90", "0.036"], ["70619.60", "2.010"]], "a": [["70622.10", "0.772"], ["70628.70", "0.057"], ["70632.90", "0.057"], ["70655.00", "0.002"], ["70731.60", "0.089"], ["70734.10", "0.102"], ["70737.20", "0.086"], ["70843.40", "0.013"], ["71325.90", "0.000"], ["71608.30", "0.000"], ["71643.70", "2.440"], ["71749.60", "1.671"], ["71784.90", "0.974"], ["71846.50", "0.695"], ["72402.20", "2.482"], ["73663.30", "1.356"], ["74153.70", "0.002"]]}}
{"local_ts": 1773486725106, "server_ts": 1773486725072, "data": {"e": "depthUpdate", "E": 1773486725077, "T": 1773486725072, "s": "BTCUSDT", "U": 10109520845801, "u": 10109520850161, "pu": 10109520845628, "b": [["5000.00", "101.418"], ["7062.00", "0.028"], ["20319.60", "1.870"], ["20419.60", "1.130"], ["67084.60", "0.000"], ["67088.60", "0.002"], ["68501.10", "0.007"], ["69607.10", "0.728"], ["69913.40", "1.428"], ["70486.20", "0.855"], ["70547.10", "0.004"], ["70549.70", "0.514"], ["70605.90", "0.005"], ["70606.80", "0.019"], ["70609.00", "0.124"], ["70617.10", "0.006"], ["70619.60", "1.860"]], "a": [["70619.70", "7.889"], ["70622.70", "0.012"], ["70627.20", "0.000"], ["70627.40", "0.006"], ["70629.30", "0.004"], ["70632.90", "0.000"], ["70636.40", "0.043"], ["70640.00", "0.002"], ["70642.00", "0.028"], ["70642.10", "0.000"], ["70644.50", "0.682"], ["70645.80", "0.003"], ["70662.90", "0.018"], ["70663.10", "0.060"], ["70666.60", "0.150"], ["70670.10", "0.057"], ["70684.80", "0.008"], ["70687.30", "0.823"], ["70733.90", "0.090"], ["70737.10", "0.645"], ["70753.70", "0.200"], ["70754.00", "0.264"], ["70826.00", "0.008"], ["71325.90", "0.000"], ["71646.10", "14.324"], ["71714.30", "2.927"]]}}
{"local_ts": 1773486726140, "server_ts": 1773486726096, "data": {"e": "depthUpdate", "E": 1773486726097, "T": 1773486726096, "s": "BTCUSDT", "U": 10109520911157, "u": 10109520918839, "pu": 10109520911087, "b": [["1000.00", "26.692"], ["5000.00", "101.418"], ["7061.60", "0.028"], ["20215.60", "1.310"], ["20319.60", "1.030"], ["56492.00", "0.004"], ["67060.40", "0.000"], ["69909.40", "0.000"], ["69938.60", "0.000"], ["70262.50", "0.010"], ["70290.80", "0.108"], ["70451.20", "7.553"], ["70454.30", "0.000"], ["70454.40", "0.003"], ["70454.70", "0.000"], ["70553.80", "0.606"], ["70559.80", "0.511"], ["70566.90", "0.000"], ["70571.30", "0.078"], ["70571.40", "0.012"], ["70572.40", "0.003"], ["70574.00", "0.542"], ["70579.30", "0.388"], ["70579.40", "0.009"], ["70581.10", "0.239"], ["70581.20", "0.513"], ["70587.30", "0.011"], ["70587.40", "0.007"], ["70587.60", "0.301"], ["70588.20", "1.066"], ["70589.50", "0.002"], ["70590.00", "0.108"], ["70594.00", "0.000"], ["70594.20", "0.004"], ["70594.40", "0.085"], ["70594.50", "0.194"], ["70595.30", "0.008"], ["70595.40", "0.456"], ["70598.40", "0.007"], ["70599.20", "1.823"], ["70602.90", "0.661"], ["70603.20", "0.264"], ["70603.30", "0.000"]], "a": [["70619.50", "0.014"], ["70622.00", "0.674"], ["70623.20", "0.007"], ["70624.00", "0.008"], ["70624.60", "0.007"], ["70627.00", "0.004"], ["70627.20", "0.002"], ["70627.30", "0.001"], ["70627.50", "0.006"], ["70627.70", "0.008"], ["70627.80", "0.000"], ["70629.10", "0.457"], ["70629.20", "0.026"], ["70629.30", "0.034"], ["70629.60", "0.022"], ["70645.00", "0.018"], ["70646.00", "0.000"], ["70646.60", "0.247"], ["70647.40", "0.023"], ["70649.10", "0.000"], ["70649.90", "0.123"], ["70652.10", "0.010"], ["70657.70", "0.078"], ["70659.20", "0.021"], ["70666.30", "0.005"], ["70689.50", "0.399"], ["70792.20", "0.389"], ["71321.90", "0.000"], ["72010.00", "0.048"], ["74152.40", "0.002"]]}}
{"local_ts": 1773486727154, "server_ts": 1773486727116, "data": {"e": "depthUpdate", "E": 1773486727117, "T": 1773486727116, "s": "BTCUSDT", "U": 10109520977644, "u": 10109520982482, "pu": 10109520977627, "b": [["1000.00", "26.692"], ["5000.00", "101.418"], ["7061.30", "0.028"], ["20112.10", "0.690"], ["20215.60", "0.670"], ["69199.90", "0.011"], ["69425.90", "0.288"], ["69539.50", "8.759"], ["69610.10", "12.551"], ["69858.60", "0.002"], ["69906.00", "0.007"], ["70297.90", "0.106"], ["70439.10", "0.003"], ["70503.00", "0.042"], ["70544.80", "0.072"], ["70551.20", "0.167"], ["70552.30", "0.178"], ["70552.60", "0.050"], ["70559.80", "0.511"], ["70564.90", "0.075"], ["70565.00", "0.047"], ["70566.40", "0.000"], ["70566.90", "0.000"], ["70574.00", "0.542"], ["70576.80", "1.032"], ["70581.10", "0.000"], ["70583.40", "0.126"], ["70588.10", "0.004"], ["70588.20", "1.066"], ["70588.60", "0.251"], ["70590.00", "0.122"], ["70590.70", "0.000"], ["70595.30", "0.015"], ["70598.00", "0.004"], ["70598.20", "0.587"], ["70599.40", "0.284"], ["70600.10", "0.000"], ["70601.30", "0.007"], ["70601.50", "0.007"], ["70601.80", "0.659"], ["70602.50", "0.011"], ["70602.80", "0.218"], ["70603.10", "0.198"], ["70603.80", "0.132"], ["70604.20", "0.564"], ["70611.70", "0.008"], ["70612.10", "3.537"]], "a": [["70612.20", "6.025"], ["70612.30", "0.766"], ["70612.40", "0.226"], ["70617.20", "0.060"], ["70617.90", "0.000"], ["70619.30", "0.015"], ["70620.10", "0.005"], ["70620.20", "0.003"], ["70621.60", "0.118"], ["70621.90", "0.061"], ["70622.10", "0.721"], ["70622.60", "0.095"], ["70622.80", "0.011"], ["70623.00", "0.114"], ["70626.50", "0.723"], ["70628.30", "0.005"], ["70630.00", "0.299"], ["70636.40", "0.028"], ["70645.00", "0.023"], ["70647.40", "0.027"], ["70647.50", "0.455"], ["70647.70", "0.067"], ["70648.80", "0.279"], ["70651.80", "1.844"], ["70652.10", "0.010"], ["70659.20", "0.028"], ["70673.10", "0.025"], ["70673.50", "0.063"], ["70674.60", "0.076"], ["70681.00", "0.042"], ["71318.30", "0.000"], ["71706.80", "1.663"], ["71742.60", "0.000"], ["71848.00", "1.114"], ["71863.80", "0.000"], ["74177.50", "0.201"]]}}
{"local_ts": 1773486728168, "server_ts": 1773486728136, "data": {"e": "depthUpdate", "E": 1773486728139, "T": 1773486728136, "s": "BTCUSDT", "U": 10109521035573, "u": 10109521043462, "pu": 10109521035424, "b": [["5000.00", "101.418"], ["7061.30", "0.000"], ["20112.10", "2.470"], ["20212.10", "0.000"], ["20512.10", "0.530"], ["33000.00", "3.785"], ["67046.60", "0.012"], ["67074.10", "0.000"], ["67088.60", "0.002"], ["67088.70", "0.010"], ["69556.00", "0.081"], ["69906.00", "0.007"], ["70259.00", "0.963"], ["70442.60", "0.003"], ["70446.20", "0.181"], ["70510.80", "0.045"], ["70564.80", "0.972"], ["70565.10", "0.262"], ["70576.80", "1.004"], ["70598.00", "0.007"], ["70599.40", "0.284"], ["70601.50", "0.012"], ["70605.10", "0.028"], ["70612.10", "3.244"]], "a": [["70613.80", "0.004"], ["70614.40", "0.001"], ["70614.60", "0.057"], ["70619.20", "0.051"], ["70619.30", "0.015"], ["70622.80", "0.004"], ["70647.50", "0.302"], ["70785.20", "0.348"], ["70788.70", "0.000"], ["71318.30", "0.000"], ["71381.90", "0.766"], ["71433.70", "0.000"], ["71530.20", "1.384"], ["71568.40", "1.674"], ["71600.80", "0.557"], ["71917.90", "0.033"], ["72024.40", "0.006"]]}}
{"local_ts": 1773486729191, "server_ts": 1773486729158, "data": {"e": "depthUpdate", "E": 1773486729159, "T": 1773486729158, "s": "BTCUSDT", "U": 10109521119341, "u": 10109521134819, "pu": 10109521119323, "b": [["1000.00", "26.692"], ["5000.00", "101.418"], ["7061.00", "0.000"], ["20112.10", "0.190"], ["20410.00", "0.130"], ["20510.00", "0.260"], ["20512.10", "2.240"], ["67049.00", "0.006"], ["68849.90", "0.000"], ["69197.80", "0.006"], ["69207.30", "0.003"], ["69233.20", "0.649"], ["69515.60", "0.997"], ["69515.90", "1.996"], ["69551.80", "0.000"], ["69552.40", "1.808"], ["69586.50", "3.984"], ["69623.00", "2.612"], ["69738.90", "0.716"], ["69903.90", "0.002"], ["69941.40", "0.004"], ["70259.10", "0.003"], ["70297.90", "0.000"], ["70437.00", "0.060"], ["70438.30", "0.143"], ["70448.50", "0.002"], ["70452.20", "0.122"], ["70461.10", "0.265"], ["70462.50", "0.025"], ["70465.50", "0.000"], ["70481.80", "3.594"], ["70487.00", "0.041"], ["70494.70", "0.004"], ["70513.40", "0.160"], ["70523.10", "0.009"], ["70528.30", "0.184"], ["70531.10", "0.184"], ["70532.10", "0.024"], ["70539.00", "0.007"], ["70545.40", "0.789"], ["70550.20", "0.070"], ["70552.30", "0.180"], ["70555.70", "0.001"], ["70559.80", "3.449"], ["70561.70", "0.779"], ["70562.10", "0.344"], ["70562.30", "0.609"], ["70563.10", "0.044"], ["70563.30", "0.031"], ["70565.10", "0.147"], ["70566.60", "0.863"], ["70566.90", "0.000"], ["70568.20", "0.000"], ["70570.00", "0.274"], ["70572.70", "0.016"], ["70574.00", "0.317"], ["70574.60", "0.004"], ["70575.00", "0.090"], ["70575.80", "0.031"], ["70576.50", "0.097"], ["70576.80", "1.001"], ["70577.60", "0.810"], ["70578.30", "0.026"], ["70581.00", "0.285"], ["70581.10", "0.000"], ["70581.50", "1.333"], ["70581.70", "0.125"], ["70581.90", "0.790"], ["70582.30", "0.571"], ["70582.40", "0.522"], ["70583.00", "0.000"], ["70583.10", "0.002"], ["70583.40", "0.024"], ["70584.40", "0.008"], ["70584.50", "1.207"], ["70585.10", "0.000"], ["70585.20", "0.155"], ["70585.80", "0.005"], ["70585.90", "0.002"], ["70586.50", "0.008"], ["70586.60", "0.000"], ["70587.20", "0.294"], ["70587.50", "0.373"], ["70588.20", "1.066"], ["70588.90", "0.100"], ["70589.20", "0.161"], ["70589.80", "0.015"], ["70590.00", "0.088"], ["70591.20", "0.539"], ["70592.40", "0.013"], ["70593.50", "0.514"], ["70594.50", "0.351"], ["70595.30", "0.010"], ["70595.60", "0.276"], ["70595.90", "0.000"], ["70597.20", "0.432"], ["70597.60", "0.005"], ["70597.80", "0.642"], ["70598.10", "0.109"], ["70598.60", "0.017"], ["70598.80", "0.008"], ["70599.00", "0.083"], ["70599.10", "0.203"], ["70599.40", "0.004"], ["70599.60", "0.007"], ["70599.90", "0.219"], ["70600.60", "0.016"], ["70600.70", "0.000"], ["70601.00", "0.033"], ["70602.20", "0.171"], ["70602.80", "0.442"], ["70602.90", "0.021"], ["70603.10", "0.387"], ["70603.30", "0.003"], ["70603.50", "0.079"], ["70604.20", "0.054"], ["70605.30", "0.007"], ["70606.30", "0.000"], ["70606.90", "0.017"], ["70607.00", "0.003"], ["70607.30", "0.002"], ["70607.50", "0.001"], ["70607.60", "0.634"], ["70607.70", "0.003"], ["70608.10", "0.015"], ["70609.30", "0.029"], ["70609.50", "0.000"], ["70609.70", "0.002"], ["70609.80", "0.000"], ["70609.90", "0.000"], ["70610.00", "0.443"]], "a": [["70610.10", "11.014"], ["70610.20", "0.244"], ["70610.30", "0.002"], ["70610.40", "0.080"], ["70611.00", "0.002"], ["70611.20", "0.086"], ["70611.30", "0.000"], ["70611.70", "0.007"], ["70611.80", "0.001"], ["70612.00", "0.016"], ["70612.20", "0.647"], ["70612.40", "0.007"], ["70613.00", "0.000"], ["70613.40", "0.005"], ["70614.80", "0.078"], ["70615.70", "0.048"], ["70616.10", "0.007"], ["70616.20", "0.027"], ["70616.50", "0.006"], ["70617.20", "0.005"], ["70618.30", "0.019"], ["70619.40", "0.005"], ["70619.50", "0.658"], ["70619.60", "0.526"], ["70619.70", "0.124"], ["70620.50", "0.002"], ["70620.70", "0.004"], ["70620.80", "0.838"], ["70620.90", "0.005"], ["70622.00", "0.533"], ["70622.40", "0.287"], ["70624.30", "0.592"], ["70626.30", "1.182"], ["70626.40", "0.028"], ["70627.80", "0.009"], ["70631.50", "0.000"], ["70631.90", "0.003"], ["70633.20", "0.009"], ["70633.30", "0.636"], ["70634.40", "0.316"], ["70636.40", "0.006"], ["70639.80", "0.011"], ["70639.90", "1.104"], ["70640.10", "0.249"], ["70640.40", "0.717"], ["70640.50", "1.061"], ["70640.60", "0.004"], ["70641.20", "0.014"], ["70641.90", "0.009"], ["70642.00", "0.008"], ["70642.20", "0.000"], ["70642.60", "0.002"], ["70642.70", "0.000"], ["70643.20", "0.000"], ["70643.30", "0.011"], ["70643.40", "0.002"], ["70644.00", "1.187"], ["70644.10", "0.034"], ["70644.40", "0.005"], ["70645.00", "0.005"], ["70646.50", "0.068"], ["70646.60", "0.002"], ["70646.90", "0.550"], ["70648.10", "0.353"], ["70651.40", "0.003"], ["70652.10", "0.003"], ["70656.30", "0.000"], ["70659.20", "0.021"], ["70661.40", "1.300"], ["70662.80", "0.004"], ["70663.70", "0.037"], ["70669.10", "1.894"], ["70673.60", "0.000"], ["70674.40", "0.223"], ["70682.60", "0.951"], ["70686.60", "0.002"], ["70693.40", "0.005"], ["70695.10", "0.084"], ["70698.40", "0.379"], ["70699.50", "0.002"], ["70739.10", "1.564"], ["70739.20", "3.492"], ["70739.40", "0.000"], ["70752.50", "2.066"], ["70760.00", "0.421"], ["70762.00", "0.000"], ["70777.80", "0.207"], ["70788.60", "2.676"], ["70796.00", "2.469"], ["70805.60", "0.122"], ["70815.10", "2.252"], ["70819.50", "0.000"], ["70822.90", "0.663"], ["70836.00", "7.173"], ["70850.90", "0.564"], ["70851.60", "0.511"], ["70891.40", "0.000"], ["70899.90", "0.000"], ["70911.20", "0.000"], ["71310.90", "0.003"], ["71316.20", "0.002"], ["71318.20", "0.000"], ["71636.00", "0.999"], ["71671.90", "5.016"], ["71706.60", "0.966"], ["71744.00", "0.014"], ["71921.70", "0.347"], ["72022.30", "0.003"]]}}
{"local_ts": 1773486730210, "server_ts": 1773486730180, "data": {"e": "depthUpdate", "E": 1773486730181, "T": 1773486730180, "s": "BTCUSDT", "U": 10109521219503, "u": 10109521229090, "pu": 10109521219383, "b": [["5000.00", "101.418"], ["7061.00", "0.000"], ["20310.00", "0.120"], ["20410.00", "2.380"], ["20412.10", "0.000"], ["20511.10", "0.000"], ["20512.10", "0.000"], ["33000.00", "3.785"], ["67077.80", "0.002"], ["69423.80", "0.288"], ["69607.30", "0.296"], ["69903.90", "0.000"], ["70528.30", "0.000"], ["70531.10", "0.000"], ["70532.10", "0.208"], ["70560.00", "0.401"], ["70562.60", "0.002"], ["70562.70", "0.004"], ["70577.60", "0.790"], ["70581.70", "0.072"], ["70583.60", "0.018"], ["70585.40", "0.259"], ["70586.90", "0.053"], ["70587.90", "0.031"], ["70590.10", "1.203"], ["70590.70", "0.000"], ["70595.80", "0.569"], ["70596.10", "0.708"], ["70597.30", "0.637"], ["70597.60", "0.003"], ["70598.10", "0.111"], ["70602.90", "0.021"], ["70603.10", "0.387"], ["70603.30", "0.171"], ["70604.10", "0.059"], ["70607.50", "0.001"], ["70607.70", "0.060"], ["70610.00", "2.536"]], "a": [["70610.10", "8.345"], ["70610.90", "0.007"], ["70611.30", "0.002"], ["70612.10", "0.004"], ["70615.10", "0.073"], ["70615.90", "0.035"], ["70616.70", "0.173"], ["70617.20", "0.005"], ["70618.50", "0.070"], ["70618.70", "0.656"], ["70619.50", "0.008"], ["70619.80", "0.005"], ["70620.00", "0.006"], ["70623.60", "0.002"], ["70624.90", "0.003"], ["70626.10", "1.232"], ["70630.60", "0.006"], ["70631.50", "0.000"], ["70633.10", "0.636"], ["70633.70", "0.023"], ["70634.90", "0.018"], ["70636.20", "0.020"], ["70636.50", "0.000"], ["70636.80", "0.003"], ["70637.70", "0.070"], ["70637.90", "0.000"], ["70638.90", "0.000"], ["70639.80", "0.011"], ["70640.10", "0.002"], ["70641.20", "0.261"], ["70642.20", "0.000"], ["70643.50", "0.328"], ["70651.60", "0.000"], ["70669.00", "0.541"], ["70669.10", "0.700"], ["70670.60", "0.005"], ["70671.80", "8.488"], ["71316.20", "0.000"], ["71628.10", "0.697"], ["71780.40", "2.085"], ["74170.70", "0.000"], ["89523.20", "0.000"]]}}
{"local_ts": 1773486731232, "server_ts": 1773486731200, "data": {"e": "depthUpdate", "E": 1773486731201, "T": 1773486731200, "s": "BTCUSDT", "U": 10109521327987, "u": 10109521334400, "pu": 10109521327967, "b": [["1000.00", "26.292"], ["5000.00", "101.418"], ["7060.90", "0.000"], ["20308.30", "1.180"], ["20410.00", "0.580"], ["67046.70", "0.002"], ["67054.10", "0.000"], ["67079.00", "0.020"], ["69209.60", "0.014"], ["69562.70", "0.017"], ["69718.00", "0.082"], ["69902.20", "0.000"], ["69915.80", "6.845"], ["70256.90", "0.000"], ["70472.80", "0.826"], ["70476.50", "0.000"], ["70508.40", "0.024"], ["70508.60", "0.124"], ["70509.00", "0.109"], ["70509.10", "0.056"], ["70526.00", "0.005"], ["70555.00", "0.019"], ["70561.10", "0.044"], ["70561.20", "0.005"], ["70591.40", "0.002"], ["70591.50", "0.310"], ["70594.30", "0.652"], ["70594.70", "0.003"], ["70595.20", "0.031"], ["70601.40", "0.304"], ["70607.90", "0.002"], ["70608.30", "2.482"]], "a": [["70610.40", "0.058"], ["70611.30", "0.000"], ["70612.20", "0.483"], ["70612.40", "0.039"], ["70615.50", "0.002"], ["70622.10", "0.521"], ["70623.30", "0.537"], ["70624.00", "0.957"], ["70624.70", "0.008"], ["70629.60", "0.645"], ["70630.40", "0.000"], ["70634.50", "0.527"], ["70645.80", "0.047"], ["70654.50", "0.002"], ["70654.60", "0.003"], ["70739.30", "0.274"], ["70742.40", "0.435"], ["70767.30", "0.003"], ["71314.50", "0.000"], ["71329.40", "0.009"], ["71527.10", "0.020"], ["71682.50", "0.014"], ["72035.60", "0.014"], ["74176.50", "0.050"], ["89523.20", "0.000"]]}}
{"local_ts": 1773486732252, "server_ts": 1773486732222, "data": {"e": "depthUpdate", "E": 1773486732223, "T": 1773486732222, "s": "BTCUSDT", "U": 10109521401586, "u": 10109521409267, "pu": 10109521401570, "b": [["1000.00", "26.292"], ["5000.00", "101.418"], ["7060.90", "0.056"], ["20208.30", "1.740"], ["20308.30", "1.260"], ["33000.00", "3.789"], ["67077.90", "0.002"], ["69478.60", "0.719"], ["69718.00", "0.068"], ["69902.20", "0.007"], ["69915.80", "6.831"], ["70255.30", "0.571"], ["70290.30", "0.004"], ["70290.60", "0.106"], ["70365.80", "0.000"], ["70431.80", "4.800"], ["70435.30", "0.161"], ["70458.40", "12.729"], ["70515.90", "0.017"], ["70516.00", "0.000"], ["70516.80", "6.217"], ["70522.90", "0.071"], ["70523.00", "0.233"], ["70530.00", "0.311"], ["70530.10", "0.003"], ["70546.90", "0.155"], ["70548.00", "0.127"], ["70548.30", "0.050"], ["70548.70", "0.332"], ["70552.10", "3.462"], ["70552.70", "1.044"], ["70559.80", "0.511"], ["70561.30", "0.003"], ["70561.50", "0.065"], ["70566.90", "0.028"], ["70574.00", "0.317"], ["70581.10", "0.000"], ["70587.10", "0.303"], ["70588.20", "1.066"], ["70588.50", "0.004"], ["70588.90", "0.163"], ["70589.90", "0.217"], ["70590.00", "0.062"], ["70590.30", "0.093"], ["70597.70", "0.400"], ["70599.60", "0.220"], ["70600.70", "0.126"], ["70601.10", "0.067"], ["70601.40", "0.058"], ["70604.20", "0.001"]], "a": [["70608.70", "0.010"], ["70609.70", "0.653"], ["70609.80", "0.134"], ["70609.90", "0.002"], ["70612.00", "0.018"], ["70612.10", "0.007"], ["70615.10", "0.003"], ["70615.60", "0.008"], ["70616.60", "0.003"], ["70616.90", "0.025"], ["70617.30", "0.034"], ["70617.60", "0.038"], ["70617.70", "0.482"], ["70618.70", "0.140"], ["70619.00", "0.007"], ["70623.30", "0.574"], ["70637.90", "0.000"], ["70643.30", "0.034"], ["70643.60", "0.028"], ["70644.00", "1.248"], ["70645.00", "0.041"], ["70645.10", "0.040"], ["70652.10", "0.000"], ["70659.20", "0.021"], ["70666.80", "3.615"], ["70669.60", "0.025"], ["70670.00", "0.297"], ["70670.30", "0.040"], ["70670.40", "0.027"], ["70671.40", "0.534"], ["70692.50", "0.127"], ["70692.60", "1.072"], ["70699.60", "0.341"], ["70699.70", "0.025"], ["70702.40", "6.543"], ["70706.60", "0.165"], ["70706.70", "0.010"], ["70761.80", "12.822"], ["70784.90", "0.252"], ["70792.00", "0.607"], ["71329.40", "0.002"], ["71682.50", "0.000"], ["71847.20", "0.004"], ["71944.80", "0.000"], ["72035.60", "0.000"], ["74152.70", "0.000"], ["89523.20", "0.000"]]}}
{"local_ts": 1773486733275, "server_ts": 1773486733244, "data": {"e": "depthUpdate", "E": 1773486733245, "T": 1773486733244, "s": "BTCUSDT", "U": 10109521496293, "u": 10109521504287, "pu": 10109521496288, "b": [["5000.00", "101.398"], ["7060.80", "0.056"], ["20107.60", "0.850"], ["20208.30", "1.690"], ["69646.70", "0.000"], ["69901.50", "0.011"], ["70256.90", "0.000"], ["70505.00", "0.162"], ["70513.40", "0.002"], ["70518.10", "0.000"], ["70560.60", "0.458"], ["70560.90", "0.084"], ["70581.60", "0.004"], ["70581.70", "0.006"], ["70582.30", "0.605"], ["70582.40", "0.513"], ["70589.00", "0.142"], ["70589.10", "0.118"], ["70597.00", "0.145"], ["70604.70", "0.001"], ["70607.60", "0.507"]], "a": [["70607.70", "9.730"], ["70608.40", "0.670"], ["70608.70", "0.002"], ["70609.10", "0.009"], ["70610.70", "0.016"], ["70612.40", "0.015"], ["70612.70", "0.012"], ["70614.80", "0.018"], ["70618.30", "0.133"], ["70628.50", "0.000"], ["70628.90", "0.643"], ["70632.90", "0.710"], ["70637.00", "0.717"], ["70637.10", "0.010"], ["70637.70", "0.000"], ["70637.80", "0.090"], ["70640.40", "0.847"], ["70655.80", "0.052"], ["71313.80", "0.008"], ["71629.00", "0.572"], ["72772.00", "0.031"], ["74164.20", "0.002"], ["89523.20", "0.000"]]}}
{"local_ts": 1773486734295, "server_ts": 1773486734261, "data": {"e": "depthUpdate", "E": 1773486734265, "T": 1773486734261, "s": "BTCUSDT", "U": 10109521590494, "u": 10109521596631, "pu": 10109521590381, "b": [["1000.00", "26.292"], ["5000.00", "101.418"], ["7060.80", "0.056"], ["20107.60", "2.160"], ["20507.60", "0.840"], ["67067.20", "0.000"], ["69197.80", "0.012"], ["69901.50", "0.023"], ["70472.00", "0.090"], ["70482.50", "2.067"], ["70494.10", "0.162"], ["70495.20", "0.055"], ["70495.90", "0.141"], ["70510.50", "0.017"], ["70515.80", "0.278"], ["70517.50", "0.071"], ["70522.80", "0.001"], ["70524.60", "0.071"], ["70529.90", "0.203"], ["70559.80", "0.513"], ["70560.20", "0.007"], ["70580.30", "0.248"], ["70581.10", "0.000"], ["70581.50", "1.330"], ["70583.40", "0.111"], ["70591.90", "0.004"], ["70592.10", "0.063"], ["70592.40", "0.070"], ["70592.50", "0.685"], ["70593.00", "0.000"], ["70595.50", "0.143"], ["70596.60", "0.053"], ["70597.00", "0.171"], ["70597.30", "0.053"], ["70599.60", "0.014"], ["70600.00", "0.594"], ["70600.30", "0.022"], ["70600.50", "0.000"], ["70600.60", "0.029"], ["70600.70", "0.001"], ["70601.10", "0.000"], ["70601.20", "0.059"], ["70601.40", "0.005"], ["70602.00", "0.446"], ["70602.10", "0.005"], ["70604.00", "0.792"], ["70604.70", "0.001"], ["70607.50", "0.017"]], "a": [["70607.70", "9.075"], ["70608.00", "0.091"], ["70608.30", "1.091"], ["70608.40", "0.347"], ["70609.90", "0.025"], ["70611.60", "0.002"], ["70611.70", "0.033"], ["70611.80", "0.026"], ["70612.20", "0.360"], ["70613.70", "0.015"], ["70614.70", "0.062"], ["70614.80", "0.015"], ["70616.60", "0.008"], ["70618.30", "0.136"], ["70687.20", "0.114"], ["70692.40", "0.000"], ["70694.30", "0.073"], ["70699.50", "0.002"], ["70701.30", "0.071"], ["70706.50", "0.000"], ["71313.80", "0.008"], ["89523.20", "0.000"]]}}
{"local_ts": 1773486735314, "server_ts": 1773486735284, "data": {"e": "depthUpdate", "E": 1773486735285, "T": 1773486735284, "s": "BTCUSDT", "U": 10109521733831, "u": 10109521742468, "pu": 10109521733548, "b": [["5000.00", "101.418"], ["7061.50", "0.028"], ["20107.60", "0.030"], ["20414.20", "0.420"], ["20507.60", "1.640"], ["20514.20", "0.730"], ["67080.50", "0.002"], ["68677.80", "0.009"], ["69267.70", "1.447"], ["69908.10", "0.200"], ["70458.80", "0.000"], ["70462.40", "0.131"], ["70521.60", "2.334"], ["70523.20", "0.017"], ["70527.20", "0.289"], ["70527.30", "0.021"], ["70527.60", "0.022"], ["70530.20", "0.353"], ["70537.30", "0.074"], ["70558.90", "0.304"], ["70561.30", "0.000"], ["70561.80", "0.002"], ["70566.70", "0.852"], ["70566.80", "0.280"], ["70580.90", "0.279"], ["70590.50", "0.006"], ["70590.60", "0.005"], ["70595.20", "0.020"], ["70595.50", "0.151"], ["70595.80", "0.073"], ["70596.10", "0.320"], ["70596.50", "0.544"], ["70596.60", "0.000"], ["70596.90", "0.006"], ["70597.70", "0.434"], ["70599.70", "0.004"], ["70599.90", "0.168"], ["70600.20", "1.205"], ["70600.70", "0.022"], ["70600.80", "0.511"], ["70602.00", "0.074"], ["70602.40", "0.151"], ["70602.60", "0.147"], ["70602.80", "0.340"], ["70603.00", "0.180"], ["70603.60", "0.002"], ["70603.70", "0.154"], ["70603.80", "0.000"], ["70604.00", "0.057"], ["70605.40", "0.212"], ["70605.50", "0.369"], ["70606.70", "0.021"], ["70606.80", "0.004"], ["70607.00", "0.000"], ["70607.40", "0.461"], ["70607.60", "0.008"], ["70608.50", "0.005"], ["70611.40", "0.003"], ["70612.40", "0.168"], ["70613.20", "0.004"], ["70614.20", "15.290"]], "a": [["70614.30", "0.954"], ["70615.40", "0.036"], ["70616.00", "0.003"], ["70618.30", "0.024"], ["70623.60", "0.000"], ["70623.80", "0.003"], ["70624.80", "0.002"], ["70624.90", "0.028"], ["70625.00", "0.004"], ["70625.20", "0.213"], ["70625.60", "0.099"], ["70625.90", "0.704"], ["70626.10", "0.036"], ["70626.30", "0.113"], ["70626.40", "0.007"], ["70626.50", "0.344"], ["70627.80", "0.000"], ["70628.00", "0.002"], ["70628.10", "0.065"], ["70628.80", "0.038"], ["70638.20", "0.172"], ["70639.40", "0.002"], ["70643.60", "0.003"], ["70644.00", "0.848"], ["70645.00", "0.040"], ["70645.70", "0.193"], ["70647.90", "0.001"], ["70648.30", "0.513"], ["70654.00", "0.371"], ["70656.40", "0.002"], ["70657.00", "0.003"], ["70657.70", "0.020"], ["70679.80", "1.173"], ["70696.80", "0.121"], ["70697.20", "0.126"], ["70697.50", "0.060"], ["70697.90", "0.110"], ["70699.00", "0.421"], ["70699.90", "0.671"], ["70700.90", "0.079"], ["70707.00", "0.495"], ["70708.40", "0.045"], ["70714.00", "0.073"], ["70715.80", "0.109"], ["70783.60", "0.000"], ["70784.10", "0.448"], ["70784.40", "0.024"], ["71320.40", "0.000"], ["71689.50", "0.417"], ["89523.20", "0.000"]]}}
{"local_ts": 1773486736343, "server_ts": 1773486736304, "data": {"e": "depthUpdate", "E": 1773486736305, "T": 1773486736304, "s": "BTCUSDT", "U": 10109521808893, "u": 10109521814778, "pu": 10109521808645, "b": [["1000.00", "26.292"], ["5000.00", "101.438"], ["7061.50", "0.028"], ["20314.20", "0.220"], ["20414.20", "2.500"], ["20507.60", "0.200"], ["67078.80", "0.000"], ["69601.50", "1.886"], ["69908.10", "0.200"], ["69937.00", "0.000"], ["70261.10", "0.000"], ["70367.60", "0.000"], ["70471.20", "0.383"], ["70538.50", "0.018"], ["70546.70", "0.000"], ["70578.90", "0.085"], ["70590.00", "0.124"]], "a": [["70614.30", "2.897"], ["70616.20", "0.147"], ["70622.10", "0.158"], ["70644.40", "0.005"], ["70645.10", "0.636"], ["70646.10", "0.578"], ["70649.60", "0.006"], ["70717.60", "0.017"], ["70726.00", "0.260"], ["71320.40", "0.700"], ["71602.80", "0.000"], ["71928.30", "0.486"], ["89523.20", "0.000"]]}}
{"local_ts": 1773486737354, "server_ts": 1773486737324, "data": {"e": "depthUpdate", "E": 1773486737325, "T": 1773486737324, "s": "BTCUSDT", "U": 10109521865109, "u": 10109521871298, "pu": 10109521864987, "b": [["1000.00", "26.292"], ["5000.00", "101.418"], ["7061.50", "0.028"], ["20214.20", "0.070"], ["20314.20", "2.360"], ["20414.20", "0.570"], ["33000.00", "3.785"], ["69202.00", "0.293"], ["69604.30", "2.727"], ["69908.10", "0.200"], ["69908.20", "0.000"], ["70194.40", "37.931"], ["70195.90", "5.901"], ["70264.70", "0.000"], ["70299.90", "31.918"], ["70300.00", "22.020"], ["70367.70", "0.004"], ["70377.30", "26.949"], ["70434.10", "0.159"], ["70472.00", "0.002"], ["70522.90", "0.017"], ["70523.10", "0.000"], ["70529.90", "0.244"], ["70530.10", "0.003"], ["70537.00", "1.650"], ["70537.20", "0.004"], ["70550.20", "0.240"], ["70552.00", "0.141"], ["70553.80", "0.150"], ["70561.20", "0.003"], ["70571.80", "8.588"], ["70574.00", "0.317"], ["70578.90", "0.085"], ["70585.90", "0.026"], ["70587.10", "0.005"], ["70596.50", "0.114"], ["70597.20", "0.007"], ["70598.40", "0.119"], ["70598.50", "0.975"], ["70600.00", "0.070"], ["70603.60", "0.005"], ["70604.10", "0.675"], ["70605.40", "0.425"], ["70606.70", "0.160"], ["70607.20", "0.054"], ["70608.40", "0.293"], ["70610.50", "0.001"], ["70610.70", "0.645"], ["70611.40", "0.008"], ["70611.70", "0.000"], ["70611.80", "0.006"], ["70614.20", "11.280"]], "a": [["70614.30", "1.085"], ["70615.30", "0.003"], ["70617.80", "0.144"], ["70621.90", "0.000"], ["70622.10", "0.158"], ["70622.40", "0.009"], ["70622.80", "0.512"], ["70624.20", "0.001"], ["70624.90", "0.273"], ["70625.60", "0.432"], ["70627.10", "0.057"], ["70627.50", "0.027"], ["70628.00", "0.063"], ["70629.30", "0.120"], ["70631.50", "0.021"], ["70636.40", "0.148"], ["70642.50", "0.003"], ["70642.80", "0.144"], ["70649.60", "0.006"], ["70654.00", "0.371"], ["70654.50", "0.131"], ["70655.10", "0.025"], ["70656.40", "0.002"], ["70656.90", "0.074"], ["70682.70", "0.025"], ["70684.50", "0.072"], ["70699.60", "0.341"], ["70699.70", "0.023"], ["70706.70", "0.071"], ["70706.80", "0.000"], ["70713.70", "0.128"], ["70713.80", "0.000"], ["70865.20", "28.135"], ["70941.60", "4.791"], ["70943.10", "31.429"], ["71049.50", "38.975"], ["71320.40", "0.700"], ["71697.70", "0.695"], ["74172.50", "0.053"], ["89523.20", "0.000"]]}}
{"local_ts": 1773486738385, "server_ts": 1773486738347, "data": {"e": "depthUpdate", "E": 1773486738349, "T": 1773486738347, "s": "BTCUSDT", "U": 10109521919876, "u": 10109521929612, "pu": 10109521919777, "b": [["5000.00", "101.418"], ["7061.50", "0.000"], ["20214.20", "2.050"], ["20314.20", "0.950"], ["67062.90", "0.002"], ["67091.00", "37.248"], ["69830.70", "0.809"], ["69908.10", "0.200"], ["69976.40", "0.000"], ["69982.20", "0.016"], ["70151.30", "0.005"], ["70157.20", "0.008"], ["70261.10", "0.000"], ["70300.00", "22.562"], ["70326.70", "0.000"], ["70332.60", "0.073"], ["70455.30", "0.819"], ["70480.60", "0.705"], ["70502.50", "0.000"], ["70508.40", "0.026"], ["70522.80", "0.018"], ["70522.90", "0.000"], ["70529.80", "0.247"], ["70529.90", "0.173"], ["70536.90", "0.071"], ["70537.00", "1.579"], ["70561.20", "0.084"], ["70578.60", "0.045"], ["70610.80", "0.013"]], "a": [["70615.30", "0.001"], ["70615.40", "0.038"], ["70630.60", "0.025"], ["70699.40", "0.177"], ["70699.50", "0.002"], ["70706.50", "0.071"], ["70706.60", "0.094"], ["70713.50", "0.088"], ["70713.60", "0.002"], ["70714.20", "0.036"], ["70720.10", "0.092"], ["70748.90", "0.448"], ["70749.00", "0.254"], ["70838.00", "0.000"], ["70891.00", "0.013"], ["70896.90", "0.004"], ["71068.20", "0.000"], ["71074.10", "0.008"], ["71245.90", "0.000"], ["71251.80", "0.016"], ["71320.30", "0.007"], ["71320.40", "0.700"], ["72019.80", "0.022"], ["72020.50", "0.000"], ["72026.50", "0.006"], ["89523.20", "0.000"]]}}
{"local_ts": 1773486739401, "server_ts": 1773486739368, "data": {"e": "depthUpdate", "E": 1773486739371, "T": 1773486739368, "s": "BTCUSDT", "U": 10109521977216, "u": 10109521981462, "pu": 10109521977155, "b": [["1000.00", "26.292"], ["5000.00", "101.418"], ["7061.50", "0.000"], ["20114.20", "1.610"], ["20214.20", "1.390"], ["33000.00", "3.789"], ["69908.10", "0.200"], ["70367.70", "0.004"], ["70480.60", "0.000"], ["70522.70", "0.019"], ["70529.70", "0.075"], ["70536.80", "0.114"], ["70603.60", "0.002"], ["70607.20", "0.120"], ["70610.80", "0.013"], ["70611.60", "0.075"]], "a": [["70614.30", "1.064"], ["70615.40", "0.036"], ["70621.30", "0.036"], ["70621.80", "0.002"], ["70621.90", "0.003"], ["70622.90", "0.822"], ["70624.90", "0.276"], ["70628.40", "0.956"], ["70699.30", "1.173"], ["70706.40", "0.105"], ["70713.40", "0.076"], ["70748.70", "0.055"], ["71320.40", "0.700"], ["72026.50", "0.009"], ["74149.80", "0.000"], ["74150.80", "0.006"], ["89523.20", "0.000"]]}}
{"local_ts": 1773486740423, "server_ts": 1773486740392, "data": {"e": "depthUpdate", "E": 1773486740395, "T": 1773486740392, "s": "BTCUSDT", "U": 10109522023248, "u": 10109522027482, "pu": 10109522023179, "b": [["5000.00", "101.418"], ["7061.50", "0.000"], ["20114.20", "1.830"], ["20514.20", "1.170"], ["69908.10", "0.200"], ["70434.10", "0.159"], ["70541.20", "0.000"], ["70567.70", "0.010"], ["70570.90", "0.057"], ["70571.80", "8.591"], ["70578.90", "0.085"], ["70603.00", "0.238"], ["70603.60", "0.005"], ["70610.80", "0.003"], ["70611.30", "0.001"], ["70611.60", "0.065"]], "a": [["70614.30", "1.615"], ["70614.50", "0.006"], ["70616.60", "1.589"], ["70621.70", "0.001"], ["70621.80", "0.002"], ["70624.90", "0.273"], ["70628.80", "0.110"], ["70649.60", "0.006"], ["70670.90", "0.002"], ["70699.30", "1.066"], ["70712.90", "0.094"], ["70715.40", "0.104"], ["70720.00", "0.770"], ["70722.50", "0.007"], ["70727.10", "0.021"], ["70729.60", "0.111"], ["70734.20", "0.031"], ["70736.70", "0.007"], ["70741.30", "0.084"], ["70743.80", "0.007"], ["70748.40", "0.000"], ["70750.90", "0.007"], ["70755.50", "0.139"], ["70758.00", "0.594"], ["70762.60", "0.005"], ["70765.10", "0.007"], ["71320.40", "0.700"], ["74175.40", "0.000"], ["89523.20", "0.000"]]}}
{"local_ts": 1773486741444, "server_ts": 1773486741412, "data": {"e": "depthUpdate", "E": 1773486741415, "T": 1773486741412, "s": "BTCUSDT", "U": 10109522072548, "u": 10109522076753, "pu": 10109522072503, "b": [["1000.00", "26.292"], ["5000.00", "101.418"], ["7061.50", "0.056"], ["20414.20", "0.720"], ["20514.20", "2.280"], ["33000.00", "3.789"], ["67052.10", "0.008"], ["67604.10", "0.005"], ["67612.80", "0.030"], ["67651.20", "0.002"], ["67652.40", "0.036"], ["67667.60", "0.819"], ["67667.90", "0.002"], ["67668.40", "0.002"], ["67682.40", "0.008"], ["67745.00", "0.046"], ["67755.40", "0.063"], ["67756.80", "0.000"], ["67789.70", "0.004"], ["67812.80", "0.006"], ["67814.90", "0.012"], ["67815.90", "0.017"], ["67820.50", "0.020"], ["67833.90", "0.026"], ["68832.70", "2.611"], ["69908.10", "0.200"], ["70261.10", "0.000"], ["70367.60", "0.004"], ["70480.50", "0.693"], ["70567.60", "0.882"], ["70567.70", "0.012"], ["70590.20", "0.000"], ["70590.30", "0.094"], ["70598.60", "0.376"], ["70599.30", "0.000"], ["70610.20", "0.003"], ["70614.20", "10.717"]], "a": [["70614.30", "0.703"], ["70621.70", "0.009"], ["70623.70", "0.058"], ["70626.30", "0.041"], ["70633.40", "0.037"], ["70647.70", "0.004"], ["70649.70", "0.032"], ["70651.00", "0.006"], ["70654.00", "0.371"], ["70656.10", "1.858"], ["70656.30", "0.000"], ["70662.70", "0.006"], ["70715.40", "0.097"], ["70716.50", "0.105"], ["70722.50", "0.000"], ["70723.60", "0.007"], ["70729.60", "0.104"], ["70730.70", "0.013"], ["70736.70", "0.000"], ["70737.80", "0.010"], ["70743.80", "0.000"], ["70744.90", "0.009"], ["70748.10", "1.106"], ["70748.20", "0.003"], ["70750.90", "0.000"], ["70752.00", "0.020"], ["70758.00", "0.587"], ["70759.10", "0.095"], ["70765.10", "0.000"], ["70766.20", "0.035"], ["70790.80", "0.099"], ["70838.40", "0.002"], ["71320.30", "0.000"], ["71320.40", "0.700"], ["71712.80", "0.418"], ["73242.10", "0.222"], ["73284.80", "0.000"], ["73290.20", "0.026"], ["73297.20", "0.008"], ["73303.40", "0.007"], ["73308.30", "0.004"], ["73316.90", "0.040"], ["73401.90", "0.002"], ["73418.90", "0.010"], ["73441.50", "0.014"], ["73448.30", "0.012"], ["73453.70", "0.002"], ["73463.90", "0.004"], ["73467.20", "0.006"], ["73467.40", "0.029"], ["73472.20", "0.014"], ["73486.80", "0.024"]]}}
{"local_ts": 1773486742464, "server_ts": 1773486742436, "data": {"e": "depthUpdate", "E": 1773486742437, "T": 1773486742436, "s": "BTCUSDT", "U": 10109522116872, "u": 10109522121354, "pu": 10109522116807, "b": [["1000.00", "26.292"], ["5000.00", "101.418"], ["7061.50", "0.056"], ["20314.20", "0.340"], ["20414.20", "2.600"], ["20514.20", "0.060"], ["67081.20", "0.000"], ["69201.90", "0.007"], ["69399.60", "0.288"], ["69555.00", "26.988"], ["69649.40", "0.000"], ["69710.30", "0.007"], ["69720.00", "0.289"], ["69908.10", "0.207"], ["70365.00", "0.005"], ["70462.40", "0.131"], ["70522.70", "0.078"], ["70527.40", "0.132"], ["70543.60", "0.067"], ["70552.10", "0.073"], ["70553.90", "0.125"], ["70566.90", "0.000"], ["70567.60", "0.882"], ["70567.70", "0.012"], ["70574.00", "0.317"], ["70581.10", "0.000"], ["70588.20", "0.001"], ["70590.70", "0.008"], ["70590.90", "0.005"], ["70591.00", "0.425"], ["70593.00", "0.129"], ["70595.30", "0.040"], ["70599.50", "0.008"], ["70605.50", "0.980"], ["70606.80", "0.134"], ["70607.30", "0.061"], ["70611.40", "0.012"]], "a": [["70614.30", "1.220"], ["70623.60", "0.002"], ["70624.00", "0.000"], ["70624.70", "0.003"], ["70627.40", "0.030"], ["70627.90", "0.062"], ["70628.10", "0.055"], ["70629.20", "0.139"], ["70637.90", "0.045"], ["70645.00", "0.004"], ["70652.10", "0.070"], ["70654.40", "0.246"], ["70655.00", "0.027"], ["70659.20", "0.078"], ["70660.10", "0.036"], ["70666.30", "0.002"], ["70680.80", "0.123"], ["70682.60", "0.197"], ["70691.00", "0.121"], ["70713.60", "0.009"], ["70716.50", "0.098"], ["70720.70", "0.105"], ["70723.60", "0.000"], ["70727.80", "0.357"], ["70730.70", "0.006"], ["70734.90", "0.454"], ["70737.80", "0.003"], ["70742.00", "0.818"], ["70744.90", "0.002"], ["70749.10", "0.093"], ["70752.00", "0.013"], ["70756.20", "1.948"], ["70759.10", "0.088"], ["70763.30", "0.036"], ["70766.20", "0.028"], ["70838.30", "0.007"], ["71320.40", "0.702"], ["71320.50", "0.009"], ["71384.00", "2.238"], ["71518.20", "0.007"], ["71653.10", "0.697"], ["71673.50", "0.010"], ["71934.80", "0.626"], ["72026.60", "0.011"]]}}
{"local_ts": 1773486743496, "server_ts": 1773486743460, "data": {"e": "depthUpdate", "E": 1773486743461, "T": 1773486743460, "s": "BTCUSDT", "U": 10109522153910, "u": 10109522158073, "pu": 10109522153862, "b": [["5000.00", "101.418"], ["7061.50", "0.056"], ["20214.20", "0.190"], ["20314.20", "2.460"], ["20414.20", "0.350"], ["67057.00", "0.005"], ["67083.00", "0.002"], ["67083.50", "2.236"], ["68832.90", "2.614"], ["69754.50", "0.003"], ["69908.10", "0.207"], ["69968.80", "1.714"], ["69992.60", "0.004"], ["70261.10", "0.000"], ["70367.80", "0.002"], ["70480.40", "0.682"], ["70566.40", "0.000"], ["70574.30", "0.008"], ["70590.10", "0.434"], ["70590.30", "0.100"], ["70590.40", "0.000"], ["70590.70", "0.008"], ["70611.40", "0.012"]], "a": [["70614.30", "1.215"], ["70661.70", "0.046"], ["70711.30", "10.293"], ["70712.10", "0.011"], ["70713.60", "0.002"], ["70717.10", "0.046"], ["70719.20", "0.099"], ["70720.70", "0.098"], ["70723.30", "0.045"], ["70726.30", "0.046"], ["70727.80", "0.350"], ["70731.20", "0.088"], ["70733.40", "0.007"], ["70734.90", "0.447"], ["70740.50", "0.007"], ["70742.00", "0.811"], ["70747.60", "0.007"], ["70747.70", "0.408"], ["70749.10", "0.086"], ["70754.70", "0.093"], ["70756.20", "1.941"], ["70761.80", "0.007"], ["70763.30", "0.029"], ["71320.40", "0.700"], ["71779.40", "0.974"], ["73438.80", "0.014"]]}}
{"local_ts": 1773486744511, "server_ts": 1773486744480, "data": {"e": "depthUpdate", "E": 1773486744483, "T": 1773486744480, "s": "BTCUSDT", "U": 10109522202873, "u": 10109522207237, "pu": 10109522202794, "b": [["1000.00", "26.292"], ["5000.00", "101.398"], ["7061.50", "0.028"], ["20114.20", "0.040"], ["20214.20", "2.310"], ["20314.20", "0.650"], ["69484.40", "2.442"], ["69908.10", "0.207"], ["70480.40", "0.000"], ["70567.70", "0.012"], ["70567.80", "0.718"], ["70585.90", "0.026"], ["70590.10", "0.519"], ["70590.20", "0.000"], ["70590.30", "0.021"], ["70600.00", "0.063"], ["70610.80", "0.011"]], "a": [["70614.30", "0.493"], ["70622.20", "0.013"], ["70624.90", "0.273"], ["70627.90", "0.062"], ["70631.80", "0.016"], ["70634.10", "0.000"], ["70635.50", "0.111"], ["70636.80", "0.001"], ["70639.40", "0.015"], ["70646.10", "0.677"], ["70703.70", "0.007"], ["70710.80", "0.409"], ["70712.10", "0.004"], ["70717.90", "0.100"], ["70719.20", "0.092"], ["70725.00", "0.056"], ["70726.30", "0.039"], ["70732.10", "0.083"], ["70733.40", "0.000"], ["70739.20", "3.499"], ["70740.50", "0.000"], ["70746.30", "0.007"], ["70747.60", "0.000"], ["70753.40", "0.048"], ["70754.70", "0.086"], ["70761.80", "0.000"], ["70864.80", "0.000"], ["71177.40", "0.007"], ["71320.40", "0.840"], ["73438.80", "0.020"], ["74177.00", "0.065"]]}}
{"local_ts": 1773486745536, "server_ts": 1773486745502, "data": {"e": "depthUpdate", "E": 1773486745503, "T": 1773486745502, "s": "BTCUSDT", "U": 10109522272385, "u": 10109522277880, "pu": 10109522272350, "b": [["5000.00", "101.418"], ["7061.50", "0.028"], ["20114.20", "1.940"], ["20214.20", "1.060"], ["67057.90", "0.002"], ["69908.10", "0.207"], ["70331.70", "0.354"], ["70567.70", "0.012"], ["70567.80", "0.718"], ["70600.40", "1.203"], ["70600.90", "0.008"], ["70601.60", "0.009"], ["70602.90", "0.509"], ["70603.60", "0.005"], ["70604.10", "0.675"], ["70610.70", "0.020"], ["70611.50", "0.015"], ["70614.20", "10.283"]], "a": [["70614.30", "1.030"], ["70621.70", "0.001"], ["70622.00", "0.002"], ["70622.90", "0.839"], ["70623.50", "0.005"], ["70624.90", "0.276"], ["70625.40", "0.062"], ["70625.80", "0.460"], ["70626.70", "0.017"], ["70628.10", "0.004"], ["70628.40", "0.026"], ["70634.40", "0.311"], ["70635.60", "0.022"], ["70656.20", "0.180"], ["70721.00", "0.018"], ["71320.30", "0.007"], ["71320.40", "2.240"], ["73438.80", "0.030"], ["74161.70", "0.000"]]}}
{"local_ts": 1773486746554, "server_ts": 1773486746524, "data": {"e": "depthUpdate", "E": 1773486746525, "T": 1773486746524, "s": "BTCUSDT", "U": 10109522330785, "u": 10109522335008, "pu": 10109522330581, "b": [["1000.00", "26.292"], ["5000.00", "101.418"], ["7061.50", "0.028"], ["20114.20", "1.510"], ["20514.20", "1.490"], ["33000.00", "3.785"], ["56491.00", "0.004"], ["67789.70", "0.014"], ["69378.50", "2.970"], ["69908.10", "0.207"], ["70261.10", "0.036"], ["70434.10", "0.159"], ["70567.70", "0.010"], ["70567.80", "0.720"], ["70578.30", "0.976"], ["70601.60", "0.009"], ["70602.60", "0.003"], ["70610.70", "0.010"], ["70611.50", "0.005"], ["70612.90", "0.009"], ["70613.20", "0.004"], ["70614.20", "10.329"]], "a": [["70614.30", "0.972"], ["70620.20", "0.005"], ["70622.90", "0.843"], ["70623.20", "0.007"], ["70624.50", "0.020"], ["70625.70", "0.653"], ["70627.20", "0.000"], ["70628.30", "0.969"], ["70628.60", "0.140"], ["70628.90", "0.081"], ["70629.80", "0.303"], ["70632.10", "0.012"], ["70633.60", "0.004"], ["70635.00", "0.132"], ["70635.10", "0.007"], ["70639.40", "0.015"], ["70641.70", "0.024"], ["70643.50", "0.278"], ["70644.40", "0.005"], ["70646.80", "0.970"], ["70648.20", "0.061"], ["70650.90", "0.070"], ["70652.30", "0.346"], ["70854.30", "0.309"], ["71320.30", "0.000"], ["71320.40", "2.242"], ["71579.20", "0.000"], ["71643.70", "7.808"], ["73438.70", "0.000"], ["74179.10", "0.000"]]}}
{"local_ts": 1773486747574, "server_ts": 1773486747544, "data": {"e": "depthUpdate", "E": 1773486747545, "T": 1773486747544, "s": "BTCUSDT", "U": 10109522371118, "u": 10109522375630, "pu": 10109522371030, "b": [["1000.00", "26.292"], ["5000.00", "101.418"], ["7061.50", "0.000"], ["20414.20", "1.050"], ["20514.20", "1.950"], ["56491.00", "0.000"], ["67789.70", "0.022"], ["69300.00", "36.969"], ["69908.10", "0.207"], ["70434.10", "0.159"], ["70480.40", "0.000"], ["70513.80", "0.066"], ["70523.80", "0.076"], ["70525.60", "0.053"], ["70528.50", "0.125"], ["70590.10", "0.519"], ["70590.40", "0.000"], ["70590.70", "0.008"], ["70607.20", "0.204"]], "a": [["70614.30", "1.163"], ["70621.30", "0.001"], ["70626.50", "0.509"], ["70628.20", "0.095"], ["70632.10", "0.025"], ["70633.00", "0.141"], ["70633.20", "0.009"], ["70633.50", "0.536"], ["70643.50", "0.276"], ["70646.10", "0.677"], ["70646.50", "0.007"], ["70646.90", "0.550"], ["70650.50", "0.623"], ["70651.70", "0.006"], ["70680.70", "0.252"], ["70680.80", "0.148"], ["70747.40", "0.070"], ["71320.40", "2.240"], ["72013.50", "1.188"], ["74149.00", "0.052"], ["74164.50", "0.054"]]}}
{"local_ts": 1773486748595, "server_ts": 1773486748564, "data": {"e": "depthUpdate", "E": 1773486748565, "T": 1773486748564, "s": "BTCUSDT", "U": 10109522423921, "u": 10109522431067, "pu": 10109522423788, "b": [["5000.00", "101.418"], ["7061.50", "0.000"], ["20314.20", "0.430"], ["20315.30", "0.010"], ["20316.50", "0.160"], ["20414.20", "2.400"], ["20416.50", "0.000"], ["20514.20", "0.000"], ["33000.00", "3.789"], ["40000.00", "41.356"], ["56493.00", "0.000"], ["67048.80", "0.002"], ["67061.10", "0.000"], ["68501.70", "0.002"], ["69202.00", "0.299"], ["69204.20", "0.003"], ["69869.90", "3.070"], ["69910.30", "0.000"], ["70216.00", "0.609"], ["70226.00", "0.020"], ["70261.10", "0.036"], ["70301.70", "0.106"], ["70302.30", "0.327"], ["70303.50", "0.000"], ["70314.90", "0.000"], ["70435.80", "0.159"], ["70436.40", "0.159"], ["70462.40", "0.092"], ["70463.30", "0.003"], ["70464.10", "0.000"], ["70464.70", "0.039"], ["70465.90", "0.002"], ["70468.20", "0.039"], ["70488.40", "0.840"], ["70490.80", "0.002"], ["70496.10", "0.000"], ["70496.70", "0.004"], ["70521.70", "0.085"], ["70523.30", "0.186"], ["70528.70", "0.073"], ["70528.90", "0.000"], ["70529.20", "0.616"], ["70530.30", "0.142"], ["70535.80", "0.071"], ["70535.90", "0.014"], ["70536.20", "0.218"], ["70537.10", "0.450"], ["70537.40", "0.142"], ["70546.30", "0.003"], ["70547.50", "0.204"], ["70549.80", "0.094"], ["70550.10", "0.068"], ["70550.40", "0.236"], ["70558.30", "0.000"], ["70559.20", "0.000"], ["70559.60", "0.296"], ["70560.30", "0.000"], ["70562.20", "0.563"], ["70562.90", "0.000"], ["70563.50", "0.084"], ["70564.80", "0.967"], ["70566.40", "0.100"], ["70567.10", "0.695"], ["70567.20", "0.006"], ["70567.50", "0.002"], ["70567.70", "0.010"], ["70567.80", "0.718"], ["70568.40", "0.005"], ["70570.50", "0.142"], ["70570.90", "0.000"], ["70571.10", "0.002"], ["70571.80", "8.506"], ["70572.40", "0.003"], ["70572.80", "0.284"], ["70573.50", "0.088"], ["70574.50", "0.033"], ["70577.30", "0.070"], ["70578.60", "0.017"], ["70579.50", "0.070"], ["70579.60", "0.000"], ["70580.00", "2.027"], ["70580.40", "0.136"], ["70580.70", "0.003"], ["70581.30", "0.061"], ["70582.40", "0.335"], ["70582.50", "1.115"], ["70583.30", "0.546"], ["70583.50", "0.200"], ["70583.60", "0.003"], ["70584.10", "0.477"], ["70584.30", "0.000"], ["70584.70", "0.088"], ["70585.30", "0.280"], ["70585.90", "0.028"], ["70586.80", "0.158"], ["70590.00", "0.724"], ["70590.10", "0.018"], ["70590.20", "0.000"], ["70590.50", "0.088"], ["70591.00", "0.338"], ["70591.50", "0.004"], ["70593.40", "0.002"], ["70593.70", "0.020"], ["70594.10", "0.024"], ["70594.80", "0.212"], ["70595.00", "0.032"], ["70595.40", "0.032"], ["70595.50", "0.006"], ["70596.30", "0.000"], ["70597.40", "0.013"], ["70597.70", "0.441"], ["70597.80", "0.002"], ["70598.40", "0.030"], ["70598.60", "0.015"], ["70598.70", "0.162"], ["70598.80", "0.007"], ["70599.00", "0.450"], ["70599.10", "0.117"], ["70599.30", "0.247"], ["70600.00", "0.010"], ["70600.60", "0.003"], ["70600.90", "0.001"], ["70601.00", "0.064"], ["70601.70", "0.006"], ["70601.80", "0.005"], ["70601.90", "0.227"], ["70602.10", "0.002"], ["70602.20", "0.007"], ["70602.30", "1.072"], ["70602.40", "1.206"], ["70602.50", "0.000"], ["70602.80", "0.279"], ["70603.00", "0.000"], ["70603.10", "0.514"], ["70603.40", "0.006"], ["70603.60", "0.000"], ["70603.80", "0.019"], ["70603.90", "0.065"], ["70604.00", "0.072"], ["70604.10", "0.605"], ["70604.40", "0.001"], ["70604.60", "0.002"], ["70605.00", "0.517"], ["70605.20", "0.107"], ["70605.30", "0.000"], ["70605.40", "0.212"], ["70605.60", "0.042"], ["70605.70", "0.141"], ["70605.80", "0.019"], ["70605.90", "0.006"], ["70606.00", "0.006"], ["70606.20", "0.000"], ["70606.30", "0.125"], ["70606.40", "0.000"], ["70606.50", "0.002"], ["70606.60", "0.077"], ["70606.70", "0.165"], ["70606.80", "0.004"], ["70606.90", "0.234"], ["70607.20", "0.190"], ["70607.30", "0.046"], ["70607.40", "0.458"], ["70607.50", "0.064"], ["70607.90", "0.129"], ["70608.00", "1.124"], ["70608.10", "0.000"], ["70608.20", "0.565"], ["70608.30", "0.862"], ["70608.40", "0.062"], ["70608.50", "0.002"], ["70608.70", "0.101"], ["70608.80", "0.022"], ["70609.30", "0.002"], ["70609.40", "0.005"], ["70609.60", "0.449"], ["70609.80", "0.004"], ["70610.20", "0.010"], ["70610.80", "0.001"], ["70611.00", "0.021"], ["70611.60", "0.067"], ["70611.90", "0.692"], ["70612.10", "0.003"], ["70612.20", "0.459"], ["70612.30", "0.308"], ["70613.00", "0.025"], ["70613.20", "0.005"], ["70613.50", "0.001"], ["70613.90", "0.000"], ["70614.10", "0.011"], ["70614.20", "0.213"], ["70614.30", "0.168"], ["70614.40", "0.366"], ["70614.60", "0.021"], ["70614.70", "0.000"], ["70614.80", "0.004"], ["70614.90", "0.005"], ["70615.00", "0.006"], ["70615.10", "0.000"], ["70615.20", "0.002"], ["70615.30", "0.206"], ["70615.40", "0.000"], ["70615.50", "0.000"], ["70615.60", "0.000"], ["70615.70", "0.000"], ["70615.80", "0.000"], ["70616.00", "0.002"], ["70616.10", "0.002"], ["70616.20", "0.000"], ["70616.30", "0.000"], ["70616.40", "0.001"], ["70616.50", "10.368"]], "a": [["70614.30", "0.000"], ["70614.40", "0.000"], ["70614.50", "0.000"], ["70614.70", "0.000"], ["70614.80", "0.000"], ["70615.00", "0.000"], ["70615.20", "0.000"], ["70615.30", "0.000"], ["70615.40", "0.000"], ["70615.50", "0.000"], ["70615.60", "0.000"], ["70615.70", "0.000"], ["70615.80", "0.000"], ["70615.90", "0.000"], ["70616.00", "0.000"], ["70616.10", "0.000"], ["70616.20", "0.000"], ["70616.30", "0.000"], ["70616.40", "0.000"], ["70616.50", "0.000"], ["70616.60", "1.998"], ["70616.70", "0.007"], ["70616.80", "0.006"], ["70617.00", "0.000"], ["70617.20", "0.158"], ["70617.30", "0.002"], ["70618.10", "0.008"], ["70618.80", "0.002"], ["70618.90", "0.003"], ["70619.20", "0.003"], ["70619.30", "0.201"], ["70619.50", "0.062"], ["70619.60", "0.005"], ["70620.20", "0.005"], ["70620.30", "0.110"], ["70620.40", "0.001"], ["70620.90", "0.024"], ["70621.00", "0.003"], ["70621.30", "0.001"], ["70621.50", "0.067"], ["70621.60", "0.005"], ["70622.40", "0.010"], ["70623.00", "0.008"], ["70623.50", "0.000"], ["70623.70", "0.003"], ["70624.40", "0.002"], ["70624.50", "0.021"], ["70624.90", "0.006"], ["70625.10", "0.085"], ["70625.60", "0.007"], ["70625.70", "0.455"], ["70625.80", "0.006"], ["70626.00", "0.007"], ["70626.10", "0.002"], ["70626.80", "0.006"], ["70626.90", "0.023"], ["70627.20", "0.003"], ["70627.40", "0.003"], ["70627.50", "0.031"], ["70628.10", "0.008"], ["70628.20", "0.690"], ["70628.30", "0.925"], ["70628.40", "0.038"], ["70628.60", "0.129"], ["70628.70", "0.072"], ["70629.40", "0.007"], ["70629.50", "0.005"], ["70629.60", "0.008"], ["70629.70", "0.002"], ["70629.80", "0.004"], ["70630.50", "0.003"], ["70630.60", "0.004"], ["70630.70", "0.023"], ["70630.80", "0.012"], ["70630.90", "0.344"], ["70631.00", "0.260"], ["70631.10", "0.000"], ["70631.20", "0.001"], ["70631.30", "0.164"], ["70631.60", "0.283"], ["70631.70", "0.005"], ["70631.80", "0.004"], ["70631.90", "0.524"], ["70632.10", "0.022"], ["70632.20", "0.000"], ["70632.40", "0.003"], ["70632.50", "0.072"], ["70632.80", "0.006"], ["70632.90", "0.021"], ["70633.00", "0.000"], ["70633.10", "1.523"], ["70633.40", "0.029"], ["70633.50", "0.343"], ["70633.60", "0.008"], ["70633.70", "0.008"], ["70634.10", "0.141"], ["70634.20", "0.516"], ["70634.30", "0.000"], ["70634.40", "0.331"], ["70634.50", "0.019"], ["70634.90", "0.003"], ["70635.00", "0.132"], ["70635.10", "0.000"], ["70635.30", "0.058"], ["70635.80", "0.001"], ["70635.90", "0.009"], ["70636.40", "0.517"], ["70636.50", "0.000"], ["70636.70", "0.057"], ["70636.90", "0.018"], ["70637.10", "0.008"], ["70637.40", "0.005"], ["70637.50", "0.103"], ["70637.90", "0.047"], ["70638.00", "0.057"], ["70638.10", "0.000"], ["70638.20", "0.107"], ["70638.60", "1.218"], ["70638.70", "0.004"], ["70639.00", "0.125"], ["70639.20", "0.004"], ["70639.40", "0.511"], ["70639.50", "1.081"], ["70639.60", "0.564"], ["70639.70", "0.297"], ["70639.80", "0.022"], ["70639.90", "0.029"], ["70640.00", "0.341"], ["70640.10", "0.002"], ["70640.40", "0.007"], ["70640.50", "0.477"], ["70640.70", "0.017"], ["70640.80", "0.000"], ["70641.00", "0.007"], ["70641.10", "0.142"], ["70641.20", "0.014"], ["70641.50", "0.000"], ["70641.60", "0.004"], ["70641.70", "0.058"], ["70641.90", "0.007"], ["70642.00", "0.021"], ["70642.10", "0.511"], ["70642.50", "0.003"], ["70642.60", "0.011"], ["70642.90", "0.229"], ["70643.00", "0.025"], ["70643.20", "0.226"], ["70643.30", "0.026"], ["70643.70", "0.280"], ["70644.50", "0.667"], ["70644.60", "0.033"], ["70644.80", "0.161"], ["70644.90", "0.185"], ["70645.00", "0.004"], ["70645.20", "0.078"], ["70645.80", "0.036"], ["70646.10", "0.518"], ["70646.20", "0.697"], ["70646.50", "0.005"], ["70646.60", "0.002"], ["70647.00", "0.003"], ["70647.50", "0.009"], ["70647.60", "0.849"], ["70647.80", "0.017"], ["70648.40", "0.636"], ["70648.50", "0.008"], ["70648.60", "0.004"], ["70648.80", "0.209"], ["70649.00", "0.045"], ["70649.10", "0.509"], ["70649.50", "0.005"], ["70650.00", "3.678"], ["70650.50", "0.556"], ["70650.80", "0.050"], ["70650.90", "0.070"], ["70651.30", "0.002"], ["70651.80", "0.024"], ["70652.50", "0.023"], ["70653.00", "0.079"], ["70653.30", "0.005"], ["70654.00", "0.124"], ["70656.00", "0.276"], ["70656.20", "0.160"], ["70657.10", "0.000"], ["70657.70", "0.017"], ["70658.00", "0.028"], ["70658.20", "0.000"], ["70659.20", "0.130"], ["70659.50", "0.004"], ["70659.60", "0.004"], ["70660.30", "0.006"], ["70661.20", "0.022"], ["70661.50", "0.289"], ["70661.60", "0.046"], ["70662.60", "0.048"], ["70662.70", "0.006"], ["70663.90", "0.316"], ["70669.10", "0.004"], ["70670.80", "0.239"], ["70670.90", "0.003"], ["70676.60", "0.002"], ["70678.90", "0.007"], ["70683.10", "4.048"], ["70683.40", "0.102"], ["70685.50", "0.519"], ["70687.90", "0.131"], ["70692.90", "0.142"], ["70698.30", "0.071"], ["70700.00", "25.448"], ["70705.40", "0.074"], ["70707.00", "0.566"], ["70712.40", "0.074"], ["70727.00", "0.001"], ["70731.30", "0.049"], ["70735.20", "0.009"], ["70765.60", "0.006"], ["70786.10", "0.110"], ["70789.00", "0.132"], ["70789.60", "0.099"], ["70793.10", "0.110"], ["70852.60", "0.106"], ["70857.80", "0.276"], ["70885.60", "4.190"], ["70899.60", "2.021"], ["71265.30", "0.002"], ["71287.50", "0.748"], ["71300.50", "0.000"], ["71320.40", "2.240"], ["71320.50", "0.009"], ["71321.40", "21.290"], ["71321.60", "0.000"], ["71322.80", "0.000"], ["72026.50", "0.009"], ["72028.90", "0.003"], ["75984.40", "0.000"], ["76160.30", "0.000"], ["76336.20", "0.000"], ["76512.00", "0.312"]]}}
{"local_ts": 1773486749613, "server_ts": 1773486749584, "data": {"e": "depthUpdate", "E": 1773486749585, "T": 1773486749584, "s": "BTCUSDT", "U": 10109522465005, "u": 10109522468779, "pu": 10109522464909, "b": [["1000.00", "26.292"], ["5000.00", "101.418"], ["7061.70", "0.000"], ["20216.50", "0.290"], ["20316.50", "2.130"], ["20414.20", "0.140"], ["56493.00", "0.000"], ["67077.80", "0.000"], ["67085.70", "0.004"], ["69684.00", "0.716"], ["69908.10", "2.349"], ["69910.30", "0.000"], ["70281.10", "3.941"], ["70481.30", "0.199"], ["70521.70", "0.085"], ["70528.70", "0.073"], ["70535.80", "0.071"], ["70538.50", "0.019"], ["70586.80", "0.154"], ["70590.20", "0.000"], ["70590.30", "0.106"], ["70591.10", "0.374"], ["70595.50", "0.013"], ["70596.10", "0.036"], ["70608.70", "0.101"], ["70609.40", "0.007"], ["70613.30", "0.070"], ["70614.60", "0.023"], ["70616.50", "10.522"]], "a": [["70616.60", "1.715"], ["70621.90", "0.072"], ["70628.80", "0.038"], ["70629.00", "0.002"], ["70629.20", "0.029"], ["70629.70", "0.017"], ["70634.90", "0.031"], ["70635.00", "0.104"], ["70644.60", "0.031"], ["70646.60", "0.002"], ["70647.40", "0.511"], ["70649.50", "0.075"], ["70651.60", "0.002"], ["70684.50", "0.726"], ["70698.30", "0.071"], ["70705.40", "0.074"], ["70712.40", "0.074"], ["70747.50", "0.000"], ["70852.60", "0.000"], ["70853.20", "0.106"], ["71322.80", "0.000"], ["71640.50", "0.837"], ["74162.80", "0.002"]]}}
{"local_ts": 1773486750669, "server_ts": 1773486750506, "data": {"e": "depthUpdate", "E": 1773486750507, "T": 1773486750506, "s": "BTCUSDT", "U": 10109522506903, "u": 10109522511757, "pu": 10109522506751, "b": [["1000.00", "26.292"], ["5000.00", "101.418"], ["7061.70", "0.028"], ["20116.50", "0.060"], ["20216.50", "2.330"], ["20314.20", "0.050"], ["20316.50", "0.550"], ["67059.20", "0.002"], ["67791.90", "0.016"], ["69690.70", "0.000"], ["69698.30", "0.004"], ["69910.30", "0.002"], ["70281.10", "3.835"], ["70369.80", "0.004"], ["70432.90", "0.000"], ["70436.40", "0.159"], ["70460.60", "13.074"], ["70521.20", "6.707"], ["70568.90", "0.005"], ["70569.00", "0.005"], ["70579.70", "0.000"], ["70587.80", "0.077"], ["70593.10", "0.026"], ["70601.90", "0.201"], ["70603.30", "0.002"], ["70605.90", "0.006"], ["70607.10", "0.012"], ["70608.80", "0.022"], ["70609.50", "0.003"], ["70611.30", "0.640"], ["70612.00", "0.000"], ["70613.20", "0.005"], ["70616.50", "10.424"]], "a": [["70616.60", "1.672"], ["70621.20", "0.004"], ["70622.40", "0.018"], ["70623.60", "0.002"], ["70623.80", "0.057"], ["70624.60", "0.013"], ["70625.00", "0.316"], ["70625.10", "1.049"], ["70626.40", "0.655"], ["70627.20", "0.024"], ["70628.40", "0.036"], ["70629.00", "0.002"], ["70629.30", "0.008"], ["70629.50", "0.062"], ["70630.00", "1.483"], ["70630.30", "0.024"], ["70630.50", "0.018"], ["70631.20", "0.001"], ["70631.60", "0.003"], ["70631.80", "0.019"], ["70633.30", "0.002"], ["70637.40", "0.005"], ["70637.80", "0.010"], ["70638.50", "0.018"], ["70646.70", "1.769"], ["70648.40", "0.000"], ["70651.40", "0.002"], ["70652.50", "0.023"], ["70653.40", "0.002"], ["70653.80", "0.096"], ["70658.20", "1.867"], ["70659.80", "0.024"], ["70662.70", "0.002"], ["70669.60", "0.099"], ["70717.30", "6.757"], ["70738.40", "0.089"], ["70778.10", "12.621"], ["70793.10", "0.170"], ["70796.70", "0.000"], ["70840.50", "0.002"], ["70840.70", "0.007"], ["71322.80", "0.000"], ["71466.40", "0.000"], ["74170.70", "0.000"], ["89523.20", "0.000"]]}}
{"local_ts": 1773486751763, "server_ts": 1773486751733, "data": {"e": "depthUpdate", "E": 1773486751735, "T": 1773486751733, "s": "BTCUSDT", "U": 10109522558220, "u": 10109522561340, "pu": 10109522558199, "b": [["1000.00", "26.292"], ["5000.00", "101.418"], ["7061.70", "0.000"], ["20116.50", "2.360"], ["20216.50", "0.560"], ["20516.50", "0.080"], ["67071.20", "0.000"], ["67071.80", "0.024"], ["69910.30", "0.000"], ["70263.40", "0.000"], ["70567.20", "0.010"], ["70568.60", "0.005"], ["70568.80", "0.292"], ["70568.90", "8.503"], ["70570.10", "2.335"], ["70571.80", "0.003"], ["70573.80", "0.778"], ["70583.40", "0.271"], ["70588.20", "0.001"], ["70590.40", "0.000"], ["70590.50", "0.088"], ["70590.70", "0.004"], ["70594.20", "0.023"], ["70594.90", "0.005"], ["70598.20", "0.056"], ["70599.50", "0.014"], ["70599.70", "0.074"], ["70600.70", "0.021"], ["70602.70", "0.016"], ["70604.00", "0.002"], ["70604.20", "0.141"], ["70605.70", "0.000"], ["70605.90", "0.013"], ["70606.60", "0.079"], ["70607.10", "0.292"], ["70608.10", "0.637"], ["70608.30", "0.579"], ["70608.80", "0.022"], ["70609.10", "0.001"], ["70609.20", "0.010"], ["70609.50", "0.067"], ["70609.80", "0.017"], ["70610.20", "0.003"], ["70611.30", "0.005"], ["70612.10", "0.058"], ["70612.40", "0.170"], ["70612.50", "0.057"], ["70614.30", "0.000"], ["70615.30", "0.211"], ["70615.80", "0.070"], ["70615.90", "0.003"], ["70616.20", "0.000"]], "a": [["70616.60", "3.607"], ["70619.20", "0.005"], ["70620.50", "0.005"], ["70623.10", "0.070"], ["70624.90", "0.003"], ["70625.20", "0.999"], ["70627.20", "0.000"], ["70628.20", "0.038"], ["70629.50", "0.062"], ["70630.20", "0.002"], ["70630.80", "0.292"], ["70630.90", "0.344"], ["70632.10", "0.028"], ["70632.20", "0.000"], ["70633.20", "1.619"], ["70633.50", "0.507"], ["70634.10", "0.036"], ["70635.40", "0.019"], ["70636.30", "0.009"], ["70636.90", "1.175"], ["70637.00", "0.719"], ["70638.10", "0.027"], ["70639.90", "0.029"], ["70645.60", "0.535"], ["70647.10", "0.034"], ["70653.70", "0.004"], ["70655.10", "0.375"], ["70657.60", "0.002"], ["70683.10", "3.385"], ["70683.30", "8.523"], ["70683.70", "6.325"], ["70687.00", "0.784"], ["70687.80", "0.204"], ["70687.90", "0.134"], ["71322.80", "0.000"], ["71573.70", "0.000"], ["71692.60", "0.418"], ["73441.20", "0.014"]]}}
{"local_ts": 1773486752782, "server_ts": 1773486752753, "data": {"e": "depthUpdate", "E": 1773486752755, "T": 1773486752753, "s": "BTCUSDT", "U": 10109522629743, "u": 10109522632770, "pu": 10109522629644, "b": [["5000.00", "101.438"], ["7061.70", "0.000"], ["20116.50", "0.930"], ["20516.50", "2.070"], ["33000.00", "3.789"], ["67052.60", "0.107"], ["67078.80", "0.002"], ["67083.60", "0.004"], ["69802.10", "3.583"], ["69910.30", "1.428"], ["70263.40", "0.000"], ["70432.90", "0.000"], ["70436.40", "0.159"], ["70513.60", "2.412"], ["70518.40", "0.068"], ["70520.60", "0.148"], ["70524.30", "0.151"], ["70524.60", "0.167"], ["70524.90", "1.100"], ["70605.90", "0.374"], ["70609.60", "0.012"], ["70613.00", "0.004"]], "a": [["70616.60", "3.964"], ["70621.90", "0.002"], ["70623.70", "0.005"], ["70630.80", "0.012"], ["70680.20", "0.151"], ["70683.40", "0.174"], ["70786.10", "0.209"], ["70789.60", "0.000"], ["71322.80", "1.400"], ["71503.00", "0.000"], ["71653.20", "0.000"], ["73441.20", "0.022"]]}}
{"local_ts": 1773486753803, "server_ts": 1773486753774, "data": {"e": "depthUpdate", "E": 1773486753775, "T": 1773486753774, "s": "BTCUSDT", "U": 10109522671144, "u": 10109522677542, "pu": 10109522671020, "b": [["1000.00", "26.292"], ["5000.00", "101.418"], ["7061.70", "0.000"], ["20416.50", "1.620"], ["20516.50", "1.380"], ["67791.90", "0.042"], ["69202.00", "0.284"], ["69204.20", "0.024"], ["69525.10", "1.006"], ["69595.70", "0.020"], ["69601.50", "0.595"], ["69910.30", "1.432"], ["70419.30", "3.885"], ["70528.30", "0.184"], ["70564.30", "0.320"], ["70564.70", "2.260"], ["70564.90", "0.426"], ["70566.20", "2.450"], ["70566.30", "0.546"], ["70566.50", "0.001"], ["70570.90", "0.057"], ["70571.70", "0.090"], ["70573.70", "0.000"], ["70574.40", "0.271"], ["70575.90", "0.002"], ["70583.30", "0.008"], ["70583.40", "0.087"], ["70583.50", "0.200"], ["70583.60", "0.003"], ["70584.10", "0.482"], ["70584.70", "0.275"], ["70584.90", "0.002"], ["70586.00", "0.561"], ["70588.30", "0.138"], ["70589.00", "0.000"], ["70589.10", "0.092"], ["70589.40", "0.077"], ["70590.00", "0.973"], ["70590.20", "0.021"], ["70591.30", "0.679"], ["70592.20", "0.021"], ["70592.70", "0.086"], ["70593.40", "0.002"], ["70593.70", "0.509"], ["70594.30", "0.070"], ["70595.10", "0.000"], ["70596.10", "0.078"], ["70596.20", "0.003"], ["70596.30", "1.203"], ["70596.60", "0.000"], ["70597.30", "0.011"], ["70598.20", "0.004"], ["70598.40", "0.005"], ["70598.60", "0.015"], ["70599.90", "0.065"], ["70600.00", "0.070"], ["70600.10", "0.003"], ["70600.50", "0.008"], ["70600.70", "0.021"], ["70601.30", "1.010"], ["70601.40", "0.007"], ["70603.20", "0.017"], ["70603.60", "0.201"], ["70603.70", "0.083"], ["70604.50", "0.272"], ["70605.10", "0.007"], ["70605.30", "0.000"], ["70605.50", "0.565"], ["70605.90", "0.239"], ["70607.00", "0.007"], ["70608.50", "0.002"], ["70608.60", "0.023"], ["70609.40", "0.005"], ["70609.50", "0.034"], ["70609.60", "0.010"], ["70609.70", "0.275"], ["70610.10", "0.001"], ["70610.20", "0.018"], ["70610.30", "0.001"], ["70611.50", "0.002"], ["70611.90", "0.000"], ["70612.20", "0.005"], ["70612.60", "0.005"], ["70612.70", "0.015"], ["70613.00", "0.004"], ["70613.20", "0.005"], ["70613.60", "0.000"], ["70614.10", "0.006"], ["70614.30", "0.005"], ["70614.70", "0.000"], ["70616.30", "0.002"], ["70616.50", "0.178"]], "a": [["70616.60", "5.732"], ["70616.80", "0.088"], ["70619.00", "0.214"], ["70621.40", "0.021"], ["70622.00", "0.002"], ["70623.00", "0.008"], ["70623.70", "0.018"], ["70624.00", "0.002"], ["70624.30", "0.620"], ["70624.70", "0.006"], ["70624.80", "0.005"], ["70625.00", "0.007"], ["70625.20", "1.004"], ["70625.80", "0.517"], ["70626.00", "0.007"], ["70626.20", "0.000"], ["70626.40", "0.028"], ["70626.50", "0.277"], ["70626.70", "0.012"], ["70627.00", "0.024"], ["70627.20", "0.000"], ["70627.60", "0.100"], ["70627.90", "0.052"], ["70629.00", "0.002"], ["70629.10", "0.018"], ["70629.20", "0.031"], ["70630.10", "0.014"], ["70633.50", "0.492"], ["70636.80", "0.001"], ["70637.60", "0.646"], ["70637.80", "0.512"], ["70638.40", "0.050"], ["70639.50", "1.127"], ["70639.70", "0.276"], ["70640.30", "0.014"], ["70640.40", "0.007"], ["70641.30", "0.070"], ["70641.40", "0.009"], ["70641.50", "0.000"], ["70643.50", "0.276"], ["70644.10", "0.034"], ["70645.20", "0.078"], ["70647.90", "0.053"], ["70651.70", "0.006"], ["70654.10", "1.451"], ["70656.20", "0.000"], ["70656.60", "0.004"], ["70669.60", "0.099"], ["70676.10", "0.000"], ["70676.20", "1.660"], ["70676.60", "0.108"], ["70694.30", "0.111"], ["70728.00", "3.367"], ["70784.10", "0.634"], ["70786.10", "0.209"], ["70789.60", "0.000"], ["71322.80", "1.400"], ["71608.40", "1.185"], ["71610.00", "1.476"], ["71616.60", "0.006"], ["72028.90", "0.018"], ["74167.20", "0.000"]]}}
{"local_ts": 1773486754826, "server_ts": 1773486754794, "data": {"e": "depthUpdate", "E": 1773486754795, "T": 1773486754794, "s": "BTCUSDT", "U": 10109522738841, "u": 10109522747538, "pu": 10109522738475, "b": [["5000.00", "101.418"], ["7061.70", "0.000"], ["20316.50", "1.170"], ["20416.50", "1.830"], ["67085.00", "0.000"], ["69364.50", "1.065"], ["69525.00", "1.010"], ["69610.50", "0.004"], ["69910.30", "1.428"], ["70051.60", "2.360"], ["70432.90", "0.000"], ["70436.40", "0.159"], ["70515.10", "0.247"], ["70522.10", "0.162"], ["70528.30", "0.000"], ["70529.20", "0.687"], ["70562.30", "8.637"], ["70562.40", "2.021"], ["70564.90", "0.072"], ["70566.30", "0.008"], ["70583.30", "0.546"], ["70584.70", "0.453"], ["70589.70", "0.085"], ["70589.90", "0.262"], ["70593.70", "0.000"], ["70594.30", "0.509"], ["70595.00", "0.032"], ["70599.90", "0.050"], ["70600.70", "0.023"], ["70608.40", "0.019"], ["70609.40", "0.241"], ["70613.20", "0.026"], ["70616.50", "0.697"]], "a": [["70633.50", "0.487"], ["70653.20", "0.473"], ["70676.60", "0.002"], ["70679.70", "1.462"], ["70691.70", "0.000"], ["70691.80", "0.422"], ["70698.80", "0.142"], ["70698.90", "0.074"], ["70705.80", "0.301"], ["70705.90", "0.256"], ["70784.10", "0.651"], ["70853.60", "0.000"], ["70854.30", "0.285"], ["70864.90", "0.007"], ["71322.70", "1.400"], ["71322.80", "1.400"], ["71464.00", "1.961"], ["71581.70", "0.557"], ["71640.50", "3.765"], ["71644.90", "0.007"], ["71746.50", "1.669"], ["72025.10", "0.277"], ["72028.90", "0.021"], ["74148.30", "0.004"]]}}
{"local_ts": 1773486755845, "server_ts": 1773486755814, "data": {"e": "depthUpdate", "E": 1773486755815, "T": 1773486755814, "s": "BTCUSDT", "U": 10109522815574, "u": 10109522819490, "pu": 10109522815550, "b": [["1000.00", "26.292"], ["5000.00", "101.398"], ["7061.30", "0.056"], ["20212.30", "0.720"], ["20316.50", "1.570"], ["56490.00", "0.000"], ["67085.70", "0.008"], ["69768.30", "0.013"], ["69842.60", "0.930"], ["69906.20", "0.000"], ["70050.80", "0.000"], ["70100.10", "0.499"], ["70189.00", "6.808"], ["70222.10", "18.612"], ["70259.20", "0.002"], ["70262.80", "0.000"], ["70262.90", "0.004"], ["70291.90", "5.608"], ["70294.50", "7.042"], ["70300.10", "0.500"], ["70301.60", "0.106"], ["70368.80", "0.259"], ["70369.30", "9.580"], ["70370.00", "0.022"], ["70439.80", "0.261"], ["70440.60", "1.238"], ["70460.50", "0.091"], ["70461.90", "2.897"], ["70515.20", "0.002"], ["70522.20", "0.002"], ["70529.20", "0.416"], ["70529.30", "0.000"], ["70530.70", "0.200"], ["70536.20", "0.018"], ["70537.70", "1.202"], ["70550.40", "0.000"], ["70551.90", "0.236"], ["70554.10", "0.003"], ["70556.20", "1.218"], ["70564.60", "0.002"], ["70564.80", "0.969"], ["70577.00", "0.029"], ["70581.10", "0.042"], ["70583.30", "0.008"], ["70583.40", "0.271"], ["70587.40", "0.010"], ["70588.70", "0.364"], ["70588.80", "0.238"], ["70590.00", "0.714"], ["70591.10", "0.558"], ["70594.90", "1.210"], ["70595.70", "0.013"], ["70598.40", "0.005"], ["70598.50", "0.902"], ["70601.70", "0.680"], ["70609.20", "0.003"], ["70612.30", "3.660"]], "a": [["70612.40", "7.763"], ["70619.70", "0.021"], ["70620.40", "0.269"], ["70623.00", "0.011"], ["70627.50", "0.031"], ["70633.50", "0.343"], ["70634.20", "0.548"], ["70634.30", "0.203"], ["70635.60", "0.005"], ["70636.40", "0.517"], ["70637.00", "0.717"], ["70637.80", "1.148"], ["70646.80", "0.461"], ["70647.70", "0.004"], ["70648.40", "0.052"], ["70649.90", "0.113"], ["70656.40", "0.002"], ["70686.00", "0.045"], ["70691.80", "0.351"], ["70698.90", "0.003"], ["70705.90", "0.185"], ["70772.90", "0.000"], ["70857.50", "35.455"], ["70938.30", "4.866"], ["70938.90", "0.000"], ["71184.70", "0.002"], ["71265.30", "0.004"], ["71318.50", "0.000"], ["71467.10", "0.693"], ["71640.50", "13.525"], ["71746.50", "4.591"], ["71926.60", "0.002"], ["74176.50", "0.052"]]}}
{"local_ts": 1773486756869, "server_ts": 1773486756836, "data": {"e": "depthUpdate", "E": 1773486756839, "T": 1773486756836, "s": "BTCUSDT", "U": 10109522865853, "u": 10109522870221, "pu": 10109522865801, "b": [["1000.00", "26.292"], ["5000.00", "101.418"], ["7061.30", "0.056"], ["20112.30", "0.340"], ["20212.30", "2.600"], ["20312.30", "0.060"], ["63551.10", "0.006"], ["67052.50", "0.002"], ["69906.20", "1.428"], ["70259.20", "0.002"], ["70478.20", "0.098"], ["70515.30", "0.026"], ["70522.30", "0.124"], ["70529.40", "0.114"], ["70564.80", "0.969"], ["70565.00", "0.049"], ["70580.20", "0.251"], ["70588.70", "0.180"], ["70588.80", "0.068"], ["70588.90", "0.000"], ["70593.90", "0.009"], ["70595.00", "0.643"], ["70597.40", "0.011"], ["70604.00", "0.387"]], "a": [["70616.50", "0.697"], ["70622.30", "0.024"], ["70633.20", "0.007"], ["70647.50", "0.009"], ["70655.70", "0.004"], ["70661.90", "0.047"], ["70691.90", "0.071"], ["70699.00", "0.313"], ["70706.00", "0.164"], ["70745.60", "0.581"], ["70775.50", "0.000"], ["70776.60", "0.093"], ["70785.40", "0.161"], ["71617.90", "1.115"], ["77673.60", "0.002"]]}}
{"local_ts": 1773486757900, "server_ts": 1773486757864, "data": {"e": "depthUpdate", "E": 1773486757865, "T": 1773486757864, "s": "BTCUSDT", "U": 10109522910755, "u": 10109522915168, "pu": 10109522910635, "b": [["5000.00", "101.418"], ["7061.30", "0.056"], ["20112.30", "2.470"], ["20212.30", "0.340"], ["20512.30", "0.190"], ["33000.00", "3.785"], ["58500.00", "62.375"], ["63551.10", "0.006"], ["67065.10", "0.000"], ["69326.30", "0.716"], ["69906.20", "1.428"], ["70069.20", "1.140"], ["70259.00", "0.963"], ["70259.20", "0.002"], ["70510.90", "0.074"], ["70515.70", "0.090"], ["70521.50", "2.453"], ["70521.90", "0.052"], ["70562.20", "0.563"], ["70564.30", "0.035"], ["70578.60", "0.019"], ["70580.00", "2.018"], ["70580.20", "0.067"], ["70580.30", "0.424"], ["70583.30", "0.546"], ["70583.40", "0.005"], ["70588.70", "0.010"], ["70588.80", "0.068"], ["70594.40", "0.072"], ["70604.00", "0.196"], ["70607.90", "0.000"], ["70612.30", "3.880"]], "a": [["70612.40", "6.963"], ["70612.50", "0.003"], ["70615.70", "0.003"], ["70616.40", "0.027"], ["70625.80", "0.513"], ["70630.80", "0.008"], ["70631.90", "0.525"], ["70636.50", "0.000"], ["70648.00", "0.051"], ["70648.30", "0.517"], ["70649.90", "0.071"], ["70677.80", "0.108"], ["70968.80", "0.003"], ["71318.50", "0.000"], ["74164.70", "0.002"], ["77673.60", "0.002"]]}}
{"local_ts": 1773486758918, "server_ts": 1773486758888, "data": {"e": "depthUpdate", "E": 1773486758889, "T": 1773486758888, "s": "BTCUSDT", "U": 10109522951470, "u": 10109522955770, "pu": 10109522951396, "b": [["1000.00", "26.292"], ["5000.00", "101.398"], ["7061.30", "0.028"], ["20112.30", "0.630"], ["20412.30", "0.040"], ["20512.30", "2.330"], ["56490.00", "0.000"], ["63551.10", "0.006"], ["67079.00", "0.002"], ["69468.80", "0.650"], ["69906.20", "1.428"], ["70515.40", "0.021"], ["70522.40", "0.071"], ["70529.50", "0.249"], ["70588.80", "0.323"], ["70588.90", "0.184"], ["70589.00", "0.000"], ["70601.00", "0.353"], ["70601.60", "0.474"], ["70605.30", "0.028"]], "a": [["70616.20", "0.002"], ["70617.70", "0.000"], ["70618.40", "0.058"], ["70619.40", "0.064"], ["70633.50", "0.551"], ["70636.50", "0.002"], ["70657.30", "1.209"], ["70692.00", "0.093"], ["70699.10", "0.071"], ["70706.10", "0.073"], ["70793.90", "0.004"], ["70794.40", "0.000"], ["72730.70", "0.009"], ["77673.60", "0.002"]]}}
{"local_ts": 1773486759942, "server_ts": 1773486759912, "data": {"e": "depthUpdate", "E": 1773486759913, "T": 1773486759912, "s": "BTCUSDT", "U": 10109522998918, "u": 10109523003536, "pu": 10109522998764, "b": [["5000.00", "101.418"], ["7061.30", "0.028"], ["20412.30", "1.970"], ["20512.30", "1.030"], ["33000.00", "3.785"], ["63551.10", "0.006"], ["67060.70", "0.000"], ["69786.70", "5.281"], ["69906.20", "1.428"], ["70047.40", "3.778"], ["70155.30", "0.084"], ["70159.50", "0.000"], ["70259.20", "0.038"], ["70330.70", "0.004"], ["70334.90", "0.000"], ["70439.30", "2.918"], ["70477.00", "7.980"], ["70478.20", "0.098"], ["70479.20", "2.984"], ["70495.00", "0.170"], ["70496.50", "1.144"], ["70506.50", "0.760"], ["70510.70", "2.005"], ["70583.40", "0.175"], ["70588.60", "0.146"], ["70600.50", "0.008"], ["70603.50", "0.141"], ["70608.90", "0.023"]], "a": [["70612.40", "6.939"], ["70636.40", "0.519"], ["70649.40", "0.148"], ["70718.20", "0.002"], ["70722.40", "0.022"], ["70742.20", "2.986"], ["70743.30", "14.645"], ["70744.90", "0.002"], ["70759.70", "0.000"], ["70760.00", "0.421"], ["70760.10", "0.000"], ["70766.00", "0.018"], ["70783.70", "0.000"], ["70785.40", "0.161"], ["70793.90", "0.002"], ["70795.90", "0.096"], ["70895.00", "0.273"], ["70899.20", "0.000"], ["71072.20", "0.008"], ["71076.50", "0.004"], ["71249.90", "0.019"], ["71254.10", "0.000"], ["71318.50", "0.000"], ["71482.00", "2.820"], ["71687.60", "0.418"], ["77673.60", "0.002"]]}}
{"local_ts": 1773486760966, "server_ts": 1773486760936, "data": {"e": "depthUpdate", "E": 1773486760937, "T": 1773486760936, "s": "BTCUSDT", "U": 10109523051464, "u": 10109523058450, "pu": 10109523051091, "b": [["1000.00", "26.292"], ["5000.00", "101.418"], ["7061.30", "0.000"], ["20312.30", "1.520"], ["20412.30", "1.480"], ["56490.00", "0.000"], ["63551.10", "0.004"], ["67076.50", "0.000"], ["69200.10", "0.019"], ["69269.80", "0.000"], ["69906.20", "1.428"], ["70259.20", "0.074"], ["70269.60", "0.000"], ["70273.00", "0.286"], ["70298.10", "0.000"], ["70301.60", "0.106"], ["70440.60", "1.148"], ["70515.50", "0.069"], ["70522.50", "0.073"], ["70529.60", "0.071"], ["70564.40", "0.005"], ["70564.60", "0.004"], ["70583.40", "0.005"], ["70588.70", "0.265"], ["70612.30", "3.491"]], "a": [["70612.40", "7.052"], ["70620.50", "0.860"], ["70621.00", "0.003"], ["70625.70", "0.927"], ["70626.40", "0.003"], ["70633.80", "0.031"], ["70633.90", "0.003"], ["70692.10", "0.005"], ["70692.20", "0.074"], ["70699.20", "1.092"], ["70699.30", "1.137"], ["70706.20", "0.015"], ["70706.30", "0.115"], ["70780.70", "0.636"], ["70795.90", "0.094"], ["70798.40", "0.005"], ["71199.50", "0.843"], ["71318.50", "0.702"], ["71826.90", "0.625"], ["77673.60", "0.000"]]}}
{"local_ts": 1773486761988, "server_ts": 1773486761952, "data": {"e": "depthUpdate", "E": 1773486761957, "T": 1773486761952, "s": "BTCUSDT", "U": 10109523105738, "u": 10109523109341, "pu": 10109523105654, "b": [["1000.00", "26.292"], ["5000.00", "101.418"], ["7061.30", "0.000"], ["20212.30", "1.070"], ["20312.30", "1.930"], ["33000.00", "3.789"], ["63551.10", "0.004"], ["67057.50", "0.000"], ["69554.50", "0.002"], ["69631.30", "1.145"], ["69906.20", "2.142"], ["70262.80", "0.106"], ["70301.60", "0.000"], ["70564.10", "0.005"], ["70564.30", "0.035"], ["70584.00", "0.103"], ["70588.70", "0.010"], ["70602.30", "1.077"], ["70605.80", "0.029"], ["70605.90", "0.464"], ["70608.90", "0.023"], ["70612.20", "0.008"], ["70612.30", "3.389"]], "a": [["70612.40", "6.310"], ["70612.80", "0.241"], ["70616.60", "0.088"], ["70624.00", "0.023"], ["70626.10", "0.030"], ["70643.60", "0.077"], ["70654.10", "1.361"], ["70655.40", "0.004"], ["70657.50", "0.008"], ["70759.90", "0.284"], ["70784.70", "0.002"], ["70785.40", "0.101"], ["70798.40", "0.003"], ["70836.00", "7.166"], ["71172.70", "0.007"], ["71318.50", "0.700"], ["71650.40", "1.672"], ["72011.60", "0.594"], ["77673.60", "0.000"], ["89523.20", "0.000"]]}}
{"local_ts": 1773486763007, "server_ts": 1773486762976, "data": {"e": "depthUpdate", "E": 1773486762979, "T": 1773486762976, "s": "BTCUSDT", "U": 10109523148141, "u": 10109523152283, "pu": 10109523148048, "b": [["5000.00", "101.398"], ["7061.30", "0.000"], ["20112.30", "0.630"], ["20212.30", "2.370"], ["20312.30", "0.000"], ["56490.00", "0.000"], ["63551.10", "0.004"], ["69906.20", "2.142"], ["70189.00", "6.575"], ["70259.20", "0.074"], ["70292.50", "5.560"], ["70369.30", "0.000"], ["70370.00", "9.603"], ["70432.20", "0.159"], ["70439.30", "2.918"], ["70440.60", "0.651"], ["70478.10", "0.102"], ["70562.70", "0.002"], ["70564.00", "0.840"], ["70564.10", "0.005"], ["70575.20", "0.124"], ["70596.60", "0.251"], ["70598.50", "0.431"], ["70601.70", "1.317"], ["70602.00", "0.011"]], "a": [["70612.40", "6.355"], ["70618.70", "0.008"], ["70620.20", "0.318"], ["70620.30", "0.656"], ["70620.60", "0.002"], ["70620.80", "0.072"], ["70623.00", "0.008"], ["70744.60", "0.086"], ["70779.10", "0.002"], ["70780.70", "0.330"], ["70783.70", "0.000"], ["70784.70", "0.000"], ["70935.20", "4.988"], ["71318.50", "0.700"], ["71852.50", "0.000"], ["74176.20", "0.002"], ["77673.60", "0.000"], ["89523.20", "0.000"]]}}
{"local_ts": 1773486764029, "server_ts": 1773486763996, "data": {"e": "depthUpdate", "E": 1773486763999, "T": 1773486763996, "s": "BTCUSDT", "U": 10109523185731, "u": 10109523188821, "pu": 10109523185656, "b": [["1000.00", "26.292"], ["5000.00", "101.418"], ["7061.30", "0.000"], ["20112.30", "2.580"], ["20212.30", "0.120"], ["20512.30", "0.300"], ["63551.10", "0.004"], ["67049.40", "0.005"], ["67070.80", "0.002"], ["68493.90", "0.005"], ["69906.20", "2.142"], ["69968.80", "0.003"], ["70432.20", "0.000"], ["70510.10", "3.672"], ["70550.20", "0.102"], ["70580.80", "0.042"], ["70580.90", "0.277"], ["70601.70", "1.317"]], "a": [["70612.40", "6.352"], ["70613.60", "0.084"], ["70620.20", "0.318"], ["70623.50", "0.157"], ["71318.50", "0.700"], ["71565.70", "2.230"], ["77673.60", "0.000"], ["89523.20", "0.000"]]}}
{"local_ts": 1773486765054, "server_ts": 1773486765020, "data": {"e": "depthUpdate", "E": 1773486765021, "T": 1773486765020, "s": "BTCUSDT", "U": 10109523252505, "u": 10109523256888, "pu": 10109523252488, "b": [["5000.00", "101.418"], ["7061.30", "0.056"], ["20112.30", "0.420"], ["20412.30", "0.150"], ["20512.30", "2.430"], ["56490.00", "0.000"], ["63551.10", "0.004"], ["67065.40", "0.002"], ["67085.80", "0.002"], ["69354.30", "0.719"], ["69906.20", "2.142"], ["70047.40", "3.778"], ["70431.50", "0.177"], ["70440.60", "1.178"], ["70478.10", "0.806"], ["70539.60", "0.026"], ["70564.80", "0.967"], ["70564.90", "0.074"], ["70580.50", "0.003"], ["70601.70", "0.677"], ["70604.20", "0.002"], ["70605.30", "0.000"], ["70605.70", "0.354"], ["70606.70", "0.008"], ["70608.30", "0.007"], ["70608.50", "0.432"], ["70612.30", "4.169"]], "a": [["70612.40", "1.444"], ["70619.40", "0.010"], ["70620.10", "0.017"], ["70623.00", "0.011"], ["70627.00", "0.101"], ["70645.80", "0.042"], ["70677.20", "0.018"], ["70744.30", "0.495"], ["70780.70", "0.670"], ["71318.50", "0.702"], ["71687.80", "5.940"], ["73436.80", "0.035"], ["74149.90", "0.000"], ["77673.60", "0.000"], ["89523.20", "0.000"]]}}
{"local_ts": 1773486766073, "server_ts": 1773486766042, "data": {"e": "depthUpdate", "E": 1773486766043, "T": 1773486766042, "s": "BTCUSDT", "U": 10109523308795, "u": 10109523321019, "pu": 10109523308541, "b": [["1000.00", "26.292"], ["5000.00", "101.418"], ["7061.30", "0.056"], ["20412.30", "2.270"], ["20414.40", "0.020"], ["20512.30", "0.710"], ["40000.00", "41.356"], ["67069.10", "0.011"], ["69200.10", "0.037"], ["69202.20", "1.734"], ["69334.00", "1.589"], ["69513.70", "0.000"], ["69605.60", "0.002"], ["69607.70", "0.865"], ["69607.90", "2.052"], ["69614.40", "0.019"], ["69631.50", "0.002"], ["69906.20", "2.142"], ["69908.30", "0.002"], ["70214.80", "0.000"], ["70259.20", "0.074"], ["70300.10", "0.606"], ["70300.20", "0.135"], ["70301.60", "0.000"], ["70434.20", "0.000"], ["70434.30", "0.159"], ["70435.80", "0.060"], ["70437.90", "0.159"], ["70462.50", "0.025"], ["70462.60", "0.000"], ["70464.00", "0.202"], ["70464.70", "0.000"], ["70466.10", "0.039"], ["70494.00", "0.009"], ["70494.70", "0.000"], ["70500.10", "1.154"], ["70508.10", "0.603"], ["70516.40", "0.000"], ["70541.90", "0.519"], ["70546.00", "0.842"], ["70559.30", "0.010"], ["70559.80", "1.367"], ["70564.80", "0.967"], ["70564.90", "0.072"], ["70565.00", "0.049"], ["70565.10", "0.136"], ["70566.20", "0.041"], ["70566.60", "2.584"], ["70566.70", "1.272"], ["70566.90", "1.208"], ["70567.90", "0.147"], ["70568.50", "0.418"], ["70571.50", "0.005"], ["70573.20", "0.092"], ["70573.40", "0.000"], ["70574.00", "1.171"], ["70574.40", "0.214"], ["70580.20", "0.251"], ["70581.10", "0.854"], ["70582.60", "0.697"], ["70583.00", "0.861"], ["70583.30", "0.362"], ["70584.00", "0.024"], ["70584.10", "0.236"], ["70584.20", "0.084"], ["70585.80", "0.089"], ["70588.00", "0.914"], ["70588.20", "0.855"], ["70588.30", "0.002"], ["70588.50", "1.070"], ["70588.60", "0.003"], ["70589.00", "0.000"], ["70589.20", "0.011"], ["70589.40", "0.164"], ["70589.50", "0.002"], ["70589.70", "0.111"], ["70590.20", "0.000"], ["70590.30", "0.006"], ["70590.50", "0.003"], ["70591.10", "0.814"], ["70591.30", "0.516"], ["70591.60", "0.000"], ["70591.80", "0.069"], ["70592.10", "0.054"], ["70592.20", "0.000"], ["70593.00", "0.011"], ["70594.90", "0.004"], ["70595.00", "0.549"], ["70595.10", "0.247"], ["70595.30", "0.859"], ["70595.50", "0.082"], ["70595.70", "0.006"], ["70595.80", "0.068"], ["70596.10", "0.530"], ["70596.60", "0.181"], ["70596.80", "0.000"], ["70597.30", "0.074"], ["70597.40", "0.018"], ["70597.60", "0.060"], ["70598.20", "0.004"], ["70598.50", "0.666"], ["70598.60", "0.511"], ["70598.70", "0.083"], ["70599.30", "0.456"], ["70599.60", "0.009"], ["70599.90", "0.439"], ["70600.20", "0.004"], ["70601.60", "0.409"], ["70601.70", "0.677"], ["70602.00", "1.214"], ["70602.20", "0.022"], ["70602.50", "0.000"], ["70602.80", "0.275"], ["70603.10", "0.003"], ["70603.80", "0.087"], ["70604.00", "0.189"], ["70604.10", "0.049"], ["70604.40", "0.073"], ["70604.70", "0.126"], ["70604.90", "0.007"], ["70605.00", "0.058"], ["70605.10", "0.007"], ["70605.30", "0.000"], ["70605.40", "0.212"], ["70605.50", "0.726"], ["70605.60", "0.553"], ["70605.70", "0.000"], ["70605.80", "0.029"], ["70605.90", "0.011"], ["70606.20", "0.008"], ["70606.30", "0.643"], ["70606.40", "0.003"], ["70606.50", "0.002"], ["70606.80", "0.025"], ["70607.20", "0.001"], ["70607.40", "0.000"], ["70608.10", "0.295"], ["70608.20", "0.003"], ["70608.60", "0.002"], ["70608.80", "0.001"], ["70609.00", "0.012"], ["70609.10", "0.071"], ["70609.40", "0.000"], ["70609.50", "0.009"], ["70609.80", "0.003"], ["70609.90", "0.007"], ["70610.80", "0.003"], ["70611.80", "0.003"], ["70612.00", "0.000"], ["70612.10", "0.002"], ["70612.20", "0.006"], ["70612.30", "0.256"], ["70612.40", "1.710"], ["70612.50", "0.005"], ["70612.60", "0.641"], ["70612.70", "0.000"], ["70612.90", "0.004"], ["70613.00", "0.000"], ["70613.30", "0.000"], ["70613.50", "0.005"], ["70613.60", "0.002"], ["70613.70", "0.647"], ["70613.80", "0.030"], ["70614.00", "0.000"], ["70614.10", "0.003"], ["70614.20", "1.751"], ["70614.30", "2.171"], ["70614.40", "10.688"]], "a": [["70612.40", "0.000"], ["70612.50", "0.000"], ["70612.60", "0.000"], ["70612.70", "0.000"], ["70612.80", "0.000"], ["70613.10", "0.000"], ["70613.40", "0.000"], ["70613.60", "0.000"], ["70613.80", "0.000"], ["70614.10", "0.000"], ["70614.20", "0.000"], ["70614.50", "2.236"], ["70614.60", "0.002"], ["70614.80", "0.002"], ["70615.10", "0.000"], ["70615.50", "0.002"], ["70615.60", "0.002"], ["70616.00", "0.002"], ["70616.60", "0.035"], ["70617.40", "0.000"], ["70619.10", "0.212"], ["70619.40", "0.069"], ["70619.50", "0.015"], ["70620.30", "0.005"], ["70620.40", "0.655"], ["70621.20", "0.002"], ["70621.90", "0.072"], ["70622.30", "0.011"], ["70622.40", "0.010"], ["70622.70", "0.003"], ["70624.20", "0.001"], ["70624.30", "0.002"], ["70624.40", "0.297"], ["70624.70", "0.003"], ["70625.10", "0.004"], ["70625.20", "0.156"], ["70625.80", "0.030"], ["70626.70", "0.000"], ["70627.20", "0.490"], ["70627.40", "0.005"], ["70627.90", "0.049"], ["70628.80", "0.055"], ["70629.20", "0.034"], ["70629.30", "0.000"], ["70629.40", "0.000"], ["70630.60", "0.010"], ["70630.70", "0.002"], ["70630.80", "0.008"], ["70631.10", "0.280"], ["70631.60", "0.514"], ["70631.70", "0.005"], ["70631.90", "0.014"], ["70632.10", "0.014"], ["70632.60", "0.007"], ["70633.40", "0.022"], ["70633.50", "0.551"], ["70633.60", "0.004"], ["70633.70", "0.038"], ["70634.10", "0.148"], ["70635.00", "0.124"], ["70635.10", "0.007"], ["70635.40", "0.004"], ["70635.60", "0.026"], ["70636.00", "0.002"], ["70636.30", "0.002"], ["70636.60", "0.002"], ["70637.00", "0.719"], ["70637.10", "0.008"], ["70637.20", "1.174"], ["70637.30", "0.004"], ["70637.60", "0.010"], ["70637.90", "0.920"], ["70638.00", "0.112"], ["70638.20", "0.000"], ["70638.70", "0.004"], ["70639.90", "0.032"], ["70640.10", "0.002"], ["70640.80", "0.141"], ["70641.10", "0.008"], ["70641.30", "0.000"], ["70641.60", "1.149"], ["70642.00", "0.013"], ["70642.20", "0.000"], ["70644.00", "0.846"], ["70645.00", "0.858"], ["70645.10", "0.000"], ["70646.00", "0.083"], ["70646.10", "0.515"], ["70646.90", "0.620"], ["70647.50", "0.009"], ["70649.90", "0.289"], ["70652.10", "0.854"], ["70653.60", "0.023"], ["70653.80", "0.204"], ["70654.50", "0.070"], ["70655.40", "0.000"], ["70656.00", "0.004"], ["70658.00", "0.012"], ["70658.80", "1.157"], ["70659.20", "1.582"], ["70665.80", "0.573"], ["70666.30", "0.856"], ["70669.30", "0.059"], ["70674.70", "0.013"], ["70676.90", "0.004"], ["70683.00", "3.337"], ["70683.10", "9.017"], ["70685.50", "0.522"], ["70729.20", "0.003"], ["70732.60", "0.093"], ["70794.50", "0.110"], ["70794.60", "0.099"], ["70987.60", "3.728"], ["71300.50", "0.000"], ["71318.50", "0.700"], ["71320.40", "1.540"], ["71320.60", "0.004"], ["71636.30", "2.537"], ["72024.60", "0.059"], ["72026.70", "0.006"], ["72730.70", "0.010"], ["76160.30", "0.000"], ["76336.20", "0.000"], ["89523.20", "0.000"]]}}
{"local_ts": 1773486767098, "server_ts": 1773486767066, "data": {"e": "depthUpdate", "E": 1773486767067, "T": 1773486767066, "s": "BTCUSDT", "U": 10109523376788, "u": 10109523382171, "pu": 10109523376525, "b": [["1000.00", "26.292"], ["5000.00", "101.418"], ["7061.50", "0.028"], ["20314.90", "0.740"], ["20412.30", "1.150"], ["20414.40", "0.000"], ["33000.00", "3.785"], ["67081.70", "0.004"], ["67081.80", "0.010"], ["69200.10", "0.028"], ["69202.20", "0.012"], ["69202.30", "0.000"], ["69908.80", "0.010"], ["70368.10", "0.036"], ["70368.50", "0.004"], ["70562.60", "0.530"], ["70566.80", "0.280"], ["70567.10", "0.616"], ["70579.10", "0.003"], ["70590.30", "0.006"], ["70590.40", "0.085"], ["70592.30", "0.000"], ["70598.20", "0.004"], ["70602.20", "0.019"], ["70604.30", "0.003"], ["70606.00", "0.013"], ["70606.90", "0.010"], ["70607.00", "0.004"], ["70607.10", "0.299"], ["70607.70", "0.001"], ["70608.30", "0.007"], ["70608.60", "0.004"], ["70609.20", "0.007"], ["70610.20", "0.000"], ["70610.90", "0.339"], ["70612.20", "0.006"], ["70612.50", "0.120"], ["70614.30", "0.091"], ["70614.40", "0.368"], ["70614.90", "14.177"]], "a": [["70615.00", "1.773"], ["70615.10", "0.003"], ["70618.00", "0.087"], ["70620.10", "0.064"], ["70624.10", "0.000"], ["70624.20", "0.316"], ["70625.50", "0.003"], ["70629.50", "0.026"], ["70629.80", "0.019"], ["70631.50", "0.021"], ["70633.60", "0.035"], ["70633.70", "0.010"], ["70635.00", "0.104"], ["70636.90", "1.175"], ["70637.30", "0.024"], ["70639.30", "0.003"], ["70649.80", "0.000"], ["70651.30", "0.044"], ["70651.70", "0.063"], ["70653.60", "0.002"], ["70658.70", "0.063"], ["70662.20", "0.015"], ["70679.40", "1.668"], ["70987.60", "3.658"], ["71285.60", "0.700"], ["71321.10", "0.008"], ["74176.40", "0.007"], ["89523.20", "0.000"]]}}
{"local_ts": 1773486768117, "server_ts": 1773486768086, "data": {"e": "depthUpdate", "E": 1773486768087, "T": 1773486768086, "s": "BTCUSDT", "U": 10109523426167, "u": 10109523430409, "pu": 10109523426029, "b": [["5000.00", "101.418"], ["7061.50", "0.028"], ["20214.90", "1.400"], ["20314.40", "0.790"], ["20314.90", "0.810"], ["56490.00", "0.000"], ["56492.00", "0.000"], ["67063.80", "0.009"], ["69202.70", "0.020"], ["69908.80", "0.010"], ["70261.30", "0.016"], ["70478.40", "0.000"], ["70478.60", "0.709"], ["70561.50", "0.023"], ["70561.60", "0.289"], ["70561.90", "0.000"], ["70567.20", "0.215"], ["70567.30", "0.027"], ["70569.50", "0.091"], ["70569.60", "0.007"], ["70577.50", "0.007"], ["70577.60", "0.279"], ["70585.50", "0.520"], ["70585.60", "0.000"], ["70590.00", "0.716"], ["70593.40", "0.007"], ["70593.50", "0.003"], ["70597.30", "0.122"], ["70601.80", "0.009"], ["70602.20", "0.069"], ["70606.90", "0.007"], ["70607.00", "0.007"], ["70611.00", "0.005"], ["70612.20", "0.006"], ["70613.50", "0.072"], ["70613.70", "0.002"], ["70614.10", "0.001"], ["70614.50", "0.105"], ["70614.90", "11.558"]], "a": [["70615.00", "3.959"], ["70620.50", "0.023"], ["70623.60", "0.006"], ["70624.40", "0.110"], ["70629.90", "0.005"], ["70630.70", "0.009"], ["70634.70", "0.004"], ["70636.30", "1.174"], ["70643.20", "0.226"], ["70658.00", "0.034"], ["70659.70", "0.005"], ["70659.80", "0.019"], ["70667.70", "0.005"], ["70667.80", "0.002"], ["70675.70", "0.007"], ["70675.80", "0.075"], ["70676.20", "0.496"], ["70683.70", "6.305"], ["70683.80", "0.087"], ["70691.70", "0.005"], ["70691.80", "0.346"], ["70745.80", "0.741"], ["70838.80", "0.007"], ["70857.40", "0.006"], ["70968.00", "0.089"], ["71321.10", "0.708"], ["71691.50", "0.417"], ["72755.70", "0.588"], ["89523.20", "0.000"]]}}
{"local_ts": 1773486769135, "server_ts": 1773486769105, "data": {"e": "depthUpdate", "E": 1773486769107, "T": 1773486769105, "s": "BTCUSDT", "U": 10109523462607, "u": 10109523467767, "pu": 10109523462602, "b": [["1000.00", "26.292"], ["5000.00", "101.418"], ["7061.50", "0.028"], ["20114.90", "0.950"], ["20214.90", "2.050"], ["33000.00", "3.789"], ["67083.90", "0.002"], ["68848.70", "0.000"], ["69485.20", "0.008"], ["69908.80", "0.010"], ["70281.10", "3.693"], ["70297.40", "7.135"], ["70368.80", "0.259"], ["70374.10", "6.182"], ["70539.60", "0.022"], ["70566.80", "0.280"], ["70567.00", "0.011"], ["70602.20", "0.069"], ["70607.60", "0.948"], ["70608.50", "0.303"], ["70613.70", "0.002"], ["70614.10", "0.001"], ["70614.90", "11.567"]], "a": [["70672.40", "1.011"], ["70791.50", "0.253"], ["70795.10", "0.101"], ["71321.10", "0.708"], ["71441.20", "0.559"], ["72024.60", "0.056"], ["89523.20", "0.000"]]}}
{"local_ts": 1773486770156, "server_ts": 1773486770124, "data": {"e": "depthUpdate", "E": 1773486770127, "T": 1773486770124, "s": "BTCUSDT", "U": 10109523521320, "u": 10109523529133, "pu": 10109523521232, "b": [["5000.00", "101.438"], ["7061.50", "0.028"], ["20114.90", "2.500"], ["20214.90", "0.000"], ["20514.90", "0.500"], ["56492.00", "0.000"], ["67050.60", "0.002"], ["69401.70", "5.482"], ["69696.90", "1.947"], ["69758.20", "0.000"], ["69908.80", "0.010"], ["70440.00", "4.152"], ["70466.60", "0.276"], ["70467.70", "0.000"], ["70468.20", "2.216"], ["70474.60", "0.092"], ["70478.90", "0.694"], ["70537.20", "0.003"], ["70559.80", "0.513"], ["70562.60", "0.947"], ["70566.90", "0.000"], ["70567.10", "0.616"], ["70567.20", "0.213"], ["70568.80", "0.205"], ["70574.00", "0.317"], ["70581.10", "0.000"], ["70588.20", "0.081"], ["70591.10", "0.900"], ["70591.70", "0.007"], ["70595.30", "0.005"], ["70598.10", "0.064"], ["70599.10", "0.010"], ["70600.10", "0.001"], ["70600.50", "0.070"], ["70601.50", "0.076"], ["70602.20", "0.069"], ["70607.90", "0.057"], ["70612.20", "0.006"], ["70614.90", "11.892"]], "a": [["70620.30", "0.264"], ["70622.00", "0.063"], ["70637.90", "0.045"], ["70642.00", "0.663"], ["70643.20", "0.466"], ["70645.00", "0.004"], ["70652.10", "0.000"], ["70659.20", "0.728"], ["70666.30", "0.002"], ["70679.00", "1.166"], ["70692.70", "0.013"], ["70710.60", "2.605"], ["70711.20", "0.053"], ["70745.80", "0.672"], ["70770.60", "3.677"], ["70784.60", "2.087"], ["70791.50", "0.154"], ["70795.10", "0.002"], ["70839.20", "0.007"], ["70850.10", "0.000"], ["71321.00", "0.000"], ["71321.10", "0.708"], ["71638.90", "2.788"], ["71662.30", "4.391"], ["71852.30", "0.002"], ["74143.70", "0.000"], ["74174.50", "0.065"], ["89523.20", "0.000"]]}}
{"local_ts": 1773486771176, "server_ts": 1773486771148, "data": {"e": "depthUpdate", "E": 1773486771149, "T": 1773486771148, "s": "BTCUSDT", "U": 10109523580964, "u": 10109523585208, "pu": 10109523580869, "b": [["1000.00", "26.292"], ["5000.00", "101.418"], ["7061.50", "0.000"], ["20114.90", "0.200"], ["20415.00", "0.260"], ["20514.90", "1.510"], ["20515.00", "1.030"], ["56492.00", "0.000"], ["67071.90", "0.000"], ["69202.20", "0.009"], ["69908.90", "0.000"], ["70261.90", "0.033"], ["70467.20", "0.323"], ["70518.70", "0.000"], ["70525.70", "0.000"], ["70532.80", "0.287"], ["70567.20", "0.213"], ["70567.30", "0.029"], ["70577.60", "0.279"], ["70582.20", "1.784"], ["70588.20", "0.081"], ["70602.30", "1.077"], ["70604.40", "0.003"], ["70607.30", "0.292"], ["70607.70", "0.011"], ["70608.00", "0.060"], ["70608.60", "0.016"]], "a": [["70615.10", "3.280"], ["70622.10", "0.039"], ["70624.60", "0.119"], ["70625.70", "0.001"], ["70642.00", "0.647"], ["70653.70", "1.843"], ["70655.20", "0.062"], ["70695.40", "0.056"], ["70702.50", "0.000"], ["70709.50", "0.080"], ["70711.90", "1.359"], ["70775.20", "0.092"], ["70784.10", "0.579"], ["70968.10", "0.175"], ["71321.30", "0.000"], ["71462.40", "0.139"], ["71850.80", "1.112"], ["72026.70", "0.006"], ["74172.80", "0.002"], ["89523.20", "0.000"]]}}
{"local_ts": 1773486772198, "server_ts": 1773486772170, "data": {"e": "depthUpdate", "E": 1773486772171, "T": 1773486772170, "s": "BTCUSDT", "U": 10109523619052, "u": 10109523623412, "pu": 10109523618988, "b": [["1000.00", "26.292"], ["5000.00", "101.418"], ["7061.50", "0.000"], ["20315.00", "0.110"], ["20415.00", "2.390"], ["20514.90", "0.500"], ["20515.00", "0.000"], ["67074.80", "0.002"], ["69633.50", "1.010"], ["69908.90", "0.000"], ["70300.80", "4.321"], ["70459.60", "0.264"], ["70463.20", "0.039"], ["70560.90", "3.611"], ["70582.20", "1.863"], ["70607.70", "0.011"], ["70608.00", "0.058"], ["70611.90", "0.001"]], "a": [["70615.10", "3.264"], ["70622.10", "0.039"], ["70623.50", "0.002"], ["70643.30", "0.099"], ["70653.70", "1.768"], ["70674.90", "3.286"], ["71321.30", "0.000"], ["71690.50", "0.417"], ["71992.10", "0.556"], ["72043.00", "1.670"]]}}
{"local_ts": 1773486773222, "server_ts": 1773486773192, "data": {"e": "depthUpdate", "E": 1773486773193, "T": 1773486773192, "s": "BTCUSDT", "U": 10109523652446, "u": 10109523655870, "pu": 10109523652311, "b": [["5000.00", "101.418"], ["7061.50", "0.000"], ["20315.00", "2.170"], ["20415.00", "0.830"], ["67066.40", "0.000"], ["67071.70", "0.000"], ["69202.70", "0.038"], ["69908.90", "0.000"], ["70261.90", "0.029"], ["70562.60", "0.969"], ["70583.60", "0.000"], ["70589.60", "0.085"], ["70589.70", "0.111"], ["70589.90", "0.262"], ["70598.90", "0.002"], ["70608.00", "0.058"], ["70615.00", "10.331"]], "a": [["70617.70", "0.010"], ["70618.50", "0.000"], ["70619.20", "0.004"], ["70622.10", "0.039"], ["70622.80", "0.027"], ["70624.10", "0.169"], ["70624.80", "0.023"], ["70628.20", "0.930"], ["70629.60", "0.029"], ["70791.60", "0.159"], ["70795.20", "4.394"], ["71321.30", "0.000"], ["72027.20", "0.010"], ["73439.70", "0.018"], ["74161.10", "0.000"], ["74164.10", "0.000"], ["74172.70", "0.002"]]}}
{"local_ts": 1773486774243, "server_ts": 1773486774214, "data": {"e": "depthUpdate", "E": 1773486774215, "T": 1773486774214, "s": "BTCUSDT", "U": 10109523695719, "u": 10109523702355, "pu": 10109523695659, "b": [["1000.00", "26.292"], ["5000.00", "101.418"], ["7061.50", "0.056"], ["20215.00", "1.720"], ["20315.00", "1.280"], ["67060.10", "0.000"], ["67790.40", "0.028"], ["69186.90", "1.731"], ["69202.70", "0.032"], ["69697.10", "0.004"], ["70068.00", "44.728"], ["70300.80", "7.703"], ["70368.80", "0.263"], ["70377.50", "4.033"], ["70566.80", "0.282"], ["70567.10", "0.614"], ["70583.20", "0.565"], ["70598.20", "0.063"], ["70598.30", "0.006"], ["70604.40", "0.125"], ["70605.30", "0.000"], ["70606.20", "0.033"], ["70606.30", "0.360"], ["70606.80", "0.033"], ["70607.30", "0.006"], ["70607.90", "0.004"], ["70608.10", "0.002"], ["70608.50", "0.004"], ["70608.80", "0.185"], ["70612.10", "0.002"]], "a": [["70625.70", "0.004"], ["70784.10", "0.579"], ["70862.10", "4.423"], ["71321.30", "0.000"], ["74156.60", "0.000"]]}}
{"local_ts": 1773486775267, "server_ts": 1773486775236, "data": {"e": "depthUpdate", "E": 1773486775239, "T": 1773486775236, "s": "BTCUSDT", "U": 10109523759247, "u": 10109523762979, "pu": 10109523759198, "b": [["5000.00", "101.418"], ["7061.50", "0.056"], ["20115.00", "1.280"], ["20215.00", "1.720"], ["66872.40", "0.035"], ["67059.40", "0.002"], ["67078.10", "0.000"], ["67790.40", "0.667"], ["69460.40", "4.314"], ["69719.60", "1.285"], ["69908.90", "0.000"], ["70364.00", "0.519"], ["70525.90", "0.053"], ["70552.30", "0.145"], ["70567.00", "0.009"], ["70567.20", "0.076"], ["70598.10", "0.525"], ["70598.30", "0.000"], ["70599.10", "0.010"], ["70599.30", "0.526"], ["70600.40", "0.000"], ["70601.70", "0.677"], ["70605.20", "0.006"], ["70606.00", "0.014"], ["70606.10", "0.639"], ["70606.80", "0.026"], ["70607.20", "0.001"], ["70607.50", "0.004"], ["70608.30", "0.009"], ["70608.50", "0.002"], ["70609.00", "0.015"], ["70610.90", "0.339"], ["70612.50", "0.125"], ["70615.00", "10.293"]], "a": [["70615.10", "1.013"], ["70618.10", "0.008"], ["70618.20", "0.002"], ["70618.70", "0.100"], ["70624.30", "0.059"], ["70627.90", "0.028"], ["70632.20", "0.020"], ["70634.30", "0.009"], ["70636.50", "0.057"], ["70636.90", "0.003"], ["70639.20", "1.247"], ["70639.30", "0.003"], ["70646.90", "0.651"], ["70651.30", "0.044"], ["70654.40", "0.000"], ["70662.20", "0.015"], ["70680.80", "0.087"], ["70795.20", "4.355"], ["71321.30", "0.148"]]}}
{"local_ts": 1773486776289, "server_ts": 1773486776259, "data": {"e": "depthUpdate", "E": 1773486776261, "T": 1773486776259, "s": "BTCUSDT", "U": 10109523797079, "u": 10109523801179, "pu": 10109523797024, "b": [["1000.00", "26.292"], ["5000.00", "101.418"], ["7061.50", "0.056"], ["20115.00", "2.170"], ["20515.00", "0.830"], ["33000.00", "3.785"], ["67054.50", "0.002"], ["67054.80", "0.000"], ["67790.40", "0.677"], ["69379.20", "2.303"], ["69908.90", "0.000"], ["70261.90", "0.065"], ["70542.90", "0.284"], ["70597.70", "0.007"], ["70598.10", "0.016"], ["70599.30", "0.456"], ["70599.90", "0.120"], ["70600.40", "0.509"], ["70601.50", "0.070"], ["70604.40", "0.232"], ["70607.30", "0.009"], ["70607.60", "0.311"], ["70608.50", "0.004"], ["70608.80", "0.197"]], "a": [["70615.10", "0.190"], ["70617.80", "0.005"], ["70618.00", "0.366"], ["70620.40", "0.001"], ["70620.60", "0.008"], ["70625.70", "0.004"], ["70628.60", "0.080"], ["70630.80", "0.008"], ["70632.50", "0.021"], ["70634.30", "0.012"], ["70634.70", "0.004"], ["70635.30", "0.004"], ["70636.00", "0.007"], ["70636.50", "0.059"], ["70643.20", "0.367"], ["70643.30", "0.256"], ["70644.40", "0.514"], ["70645.60", "0.005"], ["70646.60", "0.070"], ["70647.40", "0.002"], ["70648.40", "0.070"], ["70649.70", "0.074"], ["70651.30", "0.002"], ["70680.40", "0.043"], ["70851.70", "0.000"], ["71321.30", "0.140"]]}}
{"local_ts": 1773486777321, "server_ts": 1773486777280, "data": {"e": "depthUpdate", "E": 1773486777281, "T": 1773486777280, "s": "BTCUSDT", "U": 10109523852650, "u": 10109523856975, "pu": 10109523852523, "b": [["1000.00", "26.292"], ["5000.00", "101.418"], ["7061.50", "0.028"], ["20115.00", "0.030"], ["20415.00", "0.410"], ["20515.00", "2.560"], ["67080.80", "0.002"], ["67084.00", "0.002"], ["67790.40", "0.681"], ["69613.70", "1.994"], ["69908.90", "0.000"], ["70440.90", "1.208"], ["70479.60", "0.041"], ["70518.90", "0.058"], ["70525.90", "0.124"], ["70533.00", "0.073"], ["70567.30", "0.027"], ["70567.40", "0.022"], ["70578.10", "0.004"], ["70589.40", "0.077"], ["70589.50", "0.087"], ["70591.80", "0.079"], ["70600.70", "0.089"], ["70604.40", "0.232"], ["70607.30", "0.009"]], "a": [["70625.70", "0.004"], ["70632.90", "0.028"], ["70633.00", "0.007"], ["70695.50", "0.071"], ["70702.60", "0.687"], ["70709.60", "0.220"], ["70745.90", "0.000"], ["70784.10", "0.580"], ["70795.20", "4.394"], ["70839.00", "1.170"], ["71321.20", "5.033"], ["71321.30", "1.540"]]}}
{"local_ts": 1773486778333, "server_ts": 1773486778304, "data": {"e": "depthUpdate", "E": 1773486778305, "T": 1773486778304, "s": "BTCUSDT", "U": 10109523897345, "u": 10109523900177, "pu": 10109523897162, "b": [["5000.00", "101.418"], ["7061.50", "0.028"], ["20315.00", "0.220"], ["20415.00", "2.510"], ["20515.00", "0.270"], ["33000.00", "3.789"], ["67070.40", "0.002"], ["67076.90", "0.000"], ["67084.00", "0.002"], ["67084.20", "0.017"], ["67536.00", "0.002"], ["68239.50", "0.000"], ["68833.40", "2.610"], ["69908.90", "0.000"], ["70261.90", "0.065"], ["70405.70", "0.000"], ["70590.00", "1.864"], ["70590.20", "0.000"], ["70595.80", "0.605"], ["70599.00", "0.145"], ["70599.40", "1.208"], ["70599.50", "0.066"], ["70601.30", "0.005"], ["70604.40", "0.104"], ["70607.30", "0.006"]], "a": [["70615.10", "2.956"], ["70618.30", "0.011"], ["70621.40", "0.057"], ["70625.70", "0.061"], ["70627.80", "0.021"], ["70647.80", "0.017"], ["70649.70", "0.017"], ["70658.70", "0.063"], ["70795.20", "4.454"], ["70838.90", "0.291"], ["71321.30", "1.540"], ["71533.10", "2.514"], ["72027.40", "1.408"]]}}
{"local_ts": 1773486779355, "server_ts": 1773486779320, "data": {"e": "depthUpdate", "E": 1773486779325, "T": 1773486779320, "s": "BTCUSDT", "U": 10109523929296, "u": 10109523932001, "pu": 10109523929208, "b": [["1000.00", "26.292"], ["5000.00", "101.418"], ["7061.50", "0.028"], ["20215.00", "0.070"], ["20315.00", "2.350"], ["20415.00", "0.580"], ["67084.00", "0.002"], ["69602.20", "0.718"], ["69908.90", "0.000"], ["70479.80", "0.930"], ["70519.00", "0.000"], ["70526.00", "0.003"], ["70533.10", "0.205"], ["70604.40", "0.104"], ["70607.30", "0.006"], ["70611.40", "0.013"]], "a": [["70615.10", "3.079"], ["70618.40", "0.001"], ["70621.80", "0.005"], ["70625.70", "0.061"], ["70626.80", "0.006"], ["70695.60", "0.002"], ["70702.70", "0.030"], ["70709.70", "0.000"], ["70745.80", "0.778"], ["71321.30", "1.540"], ["73439.70", "0.024"], ["74179.90", "0.002"]]}}
{"local_ts": 1773486780385, "server_ts": 1773486780348, "data": {"e": "depthUpdate", "E": 1773486780349, "T": 1773486780348, "s": "BTCUSDT", "U": 10109523971210, "u": 10109523977338, "pu": 10109523971110, "b": [["5000.00", "101.418"], ["7061.50", "0.000"], ["20215.00", "2.060"], ["20315.00", "0.940"], ["67084.00", "0.002"], ["69672.80", "0.717"], ["69908.90", "0.000"], ["70519.00", "0.017"], ["70526.00", "0.074"], ["70533.10", "0.276"], ["70566.80", "0.280"], ["70567.50", "0.004"], ["70567.60", "0.884"], ["70579.30", "0.389"], ["70583.20", "0.623"], ["70593.70", "0.000"], ["70594.80", "0.460"], ["70595.10", "0.000"], ["70604.40", "0.107"], ["70606.30", "0.643"], ["70606.80", "0.098"], ["70607.30", "0.009"]], "a": [["70625.70", "0.001"], ["70628.60", "0.000"], ["70644.30", "0.004"], ["70645.40", "0.094"], ["70695.60", "0.073"], ["70702.70", "0.101"], ["70709.70", "0.071"], ["70713.70", "0.064"], ["70738.80", "0.129"], ["71486.70", "1.398"], ["72027.40", "1.411"], ["74158.60", "0.002"], ["74164.80", "0.000"]]}}
{"local_ts": 1773486781402, "server_ts": 1773486781369, "data": {"e": "depthUpdate", "E": 1773486781371, "T": 1773486781369, "s": "BTCUSDT", "U": 10109524042047, "u": 10109524047413, "pu": 10109524041999, "b": [["1000.00", "26.292"], ["5000.00", "101.418"], ["7061.50", "0.000"], ["20115.00", "1.610"], ["20215.00", "1.390"], ["66832.50", "3.000"], ["67084.00", "0.002"], ["67084.30", "0.009"], ["67084.40", "0.010"], ["67536.00", "2.002"], ["69908.90", "0.000"], ["70261.90", "0.065"], ["70262.20", "0.000"], ["70300.00", "21.993"], ["70367.50", "0.006"], ["70404.00", "0.007"], ["70434.90", "0.159"], ["70441.00", "0.031"], ["70547.10", "0.041"], ["70548.50", "0.980"], ["70554.10", "0.000"], ["70555.50", "0.213"], ["70567.30", "0.025"], ["70567.50", "0.004"], ["70568.20", "0.004"], ["70569.60", "0.248"], ["70586.00", "0.228"], ["70586.10", "0.088"], ["70586.60", "0.035"], ["70600.70", "0.000"], ["70608.00", "0.055"], ["70611.40", "0.013"], ["70615.00", "4.375"]], "a": [["70615.10", "2.710"], ["70615.30", "0.000"], ["70615.40", "0.002"], ["70619.70", "0.020"], ["70620.10", "0.009"], ["70621.60", "0.060"], ["70621.70", "1.856"], ["70622.10", "0.037"], ["70622.30", "0.000"], ["70622.40", "0.010"], ["70630.10", "0.007"], ["70631.00", "0.236"], ["70631.10", "0.000"], ["70639.40", "0.652"], ["70784.10", "0.381"], ["70784.70", "0.000"], ["70821.80", "0.000"], ["70855.20", "0.106"], ["71321.30", "2.940"], ["71850.90", "2.570"], ["71925.90", "0.694"], ["74151.50", "0.055"], ["74178.90", "0.009"]]}}
{"local_ts": 1773486782423, "server_ts": 1773486782392, "data": {"e": "depthUpdate", "E": 1773486782393, "T": 1773486782392, "s": "BTCUSDT", "U": 10109524104335, "u": 10109524108619, "pu": 10109524104236, "b": [["5000.00", "101.418"], ["7061.50", "0.000"], ["20115.00", "1.830"], ["20515.00", "1.170"], ["67055.80", "0.002"], ["67084.00", "0.002"], ["69401.70", "0.878"], ["69428.70", "0.288"], ["70537.30", "0.006"], ["70551.40", "0.094"], ["70567.30", "0.025"], ["70567.40", "0.024"], ["70581.00", "0.044"], ["70583.40", "0.189"], ["70583.70", "0.170"], ["70597.80", "0.511"], ["70598.00", "0.004"], ["70598.60", "0.511"], ["70608.90", "0.033"], ["70615.00", "2.852"]], "a": [["70617.40", "0.002"], ["70619.70", "0.018"], ["70678.70", "0.079"], ["70692.80", "0.137"], ["70719.80", "0.007"], ["70720.90", "0.008"], ["70726.90", "6.499"], ["70728.00", "3.367"], ["70734.00", "0.007"], ["70735.10", "0.000"], ["70741.10", "0.055"], ["70742.20", "2.986"], ["70748.20", "0.010"], ["70749.30", "0.084"], ["70755.30", "0.009"], ["70756.40", "0.002"], ["70762.40", "0.009"], ["70763.50", "0.025"], ["70769.50", "0.007"], ["70770.60", "1.546"], ["70855.20", "0.000"], ["71321.30", "2.940"], ["71850.90", "4.308"], ["74180.40", "0.006"], ["89523.20", "0.000"]]}}
{"local_ts": 1773486783441, "server_ts": 1773486783412, "data": {"e": "depthUpdate", "E": 1773486783413, "T": 1773486783412, "s": "BTCUSDT", "U": 10109524143615, "u": 10109524147553, "pu": 10109524143508, "b": [["1000.00", "26.292"], ["5000.00", "101.418"], ["7061.50", "0.056"], ["20415.00", "0.720"], ["20515.00", "2.280"], ["69202.70", "0.026"], ["69592.60", "8.537"], ["69767.60", "2.862"], ["69908.90", "0.000"], ["70261.90", "0.065"], ["70519.00", "0.000"], ["70519.10", "0.019"], ["70526.00", "0.003"], ["70526.10", "6.390"], ["70533.10", "0.205"], ["70533.20", "0.071"], ["70579.70", "0.046"], ["70605.50", "0.857"], ["70606.70", "0.054"], ["70608.00", "0.003"], ["70614.40", "0.269"], ["70615.00", "2.767"]], "a": [["70615.10", "3.741"], ["70617.40", "0.002"], ["70622.10", "0.065"], ["70625.90", "0.704"], ["70650.40", "0.184"], ["70695.70", "0.458"], ["70702.80", "0.071"], ["70709.80", "0.112"], ["70719.80", "0.000"], ["70721.80", "0.007"], ["70726.90", "6.492"], ["70728.90", "13.622"], ["70734.00", "0.000"], ["70736.00", "0.982"], ["70741.10", "0.048"], ["70743.10", "0.007"], ["70748.20", "0.003"], ["70750.20", "0.007"], ["70755.30", "0.002"], ["70757.30", "0.016"], ["70762.40", "0.002"], ["70764.40", "0.007"], ["70769.50", "0.000"], ["70771.50", "0.046"], ["70791.60", "0.159"], ["71321.30", "2.940"], ["74174.10", "0.000"], ["74176.90", "0.005"], ["89523.20", "0.000"]]}}
{"local_ts": 1773486784467, "server_ts": 1773486784432, "data": {"e": "depthUpdate", "E": 1773486784435, "T": 1773486784432, "s": "BTCUSDT", "U": 10109524184390, "u": 10109524190537, "pu": 10109524184349, "b": [["1000.00", "26.292"], ["5000.00", "101.418"], ["7061.50", "0.056"], ["20315.00", "0.340"], ["20415.00", "2.590"], ["20515.00", "0.070"], ["67068.20", "0.000"], ["67074.40", "0.002"], ["67084.40", "0.008"], ["69319.70", "0.719"], ["69486.60", "0.000"], ["69520.50", "2.658"], ["69591.10", "9.759"], ["69592.60", "4.520"], ["69908.90", "0.000"], ["70281.10", "3.551"], ["70405.50", "0.004"], ["70537.30", "0.006"], ["70551.40", "0.137"], ["70568.20", "0.000"], ["70570.70", "0.010"], ["70576.90", "0.007"], ["70583.40", "0.269"], ["70588.20", "0.001"], ["70589.20", "0.008"], ["70590.40", "0.000"], ["70591.20", "0.011"], ["70595.00", "0.438"], ["70595.90", "1.722"], ["70597.50", "0.510"], ["70597.70", "0.000"], ["70597.80", "0.002"], ["70597.90", "0.008"], ["70598.50", "0.596"], ["70599.40", "1.215"], ["70602.10", "0.002"], ["70602.70", "0.011"], ["70602.90", "0.141"], ["70603.10", "0.003"], ["70603.30", "0.002"], ["70603.90", "0.008"], ["70604.60", "0.002"], ["70607.10", "0.029"], ["70608.10", "0.429"], ["70615.00", "3.449"]], "a": [["70615.10", "3.747"], ["70617.40", "0.000"], ["70618.00", "0.092"], ["70625.60", "0.099"], ["70626.00", "0.026"], ["70626.90", "0.021"], ["70628.50", "0.000"], ["70628.70", "0.000"], ["70629.50", "0.005"], ["70629.90", "0.012"], ["70631.10", "0.015"], ["70634.70", "1.183"], ["70634.80", "0.217"], ["70635.10", "0.007"], ["70635.70", "0.002"], ["70636.30", "0.002"], ["70640.90", "0.013"], ["70641.30", "0.636"], ["70641.80", "0.509"], ["70642.00", "0.484"], ["70642.60", "0.002"], ["70642.70", "0.000"], ["70648.20", "0.897"], ["70649.80", "0.247"], ["70649.90", "0.002"], ["70678.70", "0.018"], ["70692.80", "0.031"], ["70720.10", "0.097"], ["70721.80", "0.000"], ["70727.20", "0.034"], ["70728.90", "13.615"], ["70734.30", "0.055"], ["70736.00", "0.975"], ["70741.40", "0.189"], ["70743.10", "0.000"], ["70748.50", "0.026"], ["70750.20", "0.000"], ["70755.60", "0.016"], ["70757.30", "0.009"], ["70762.70", "0.026"], ["70764.40", "0.000"], ["70769.80", "0.007"], ["70771.50", "0.039"], ["70791.60", "0.159"], ["71321.30", "2.940"], ["71709.60", "6.825"], ["71925.90", "0.000"], ["72770.90", "0.000"], ["73477.00", "0.140"], ["73777.00", "1.017"], ["89523.20", "0.000"]]}}
{"local_ts": 1773486785483, "server_ts": 1773486785452, "data": {"e": "depthUpdate", "E": 1773486785455, "T": 1773486785452, "s": "BTCUSDT", "U": 10109524241196, "u": 10109524246039, "pu": 10109524241134, "b": [["5000.00", "101.398"], ["7061.90", "0.056"], ["20219.00", "0.180"], ["20315.00", "1.840"], ["20319.00", "0.610"], ["20415.00", "0.360"], ["33000.00", "3.785"], ["67071.80", "0.022"], ["67794.30", "0.004"], ["69074.50", "1.243"], ["69521.90", "1.005"], ["69633.40", "1.935"], ["69912.80", "0.000"], ["70194.30", "0.000"], ["70299.80", "0.005"], ["70377.20", "0.002"], ["70569.80", "0.002"], ["70570.00", "0.276"], ["70571.90", "0.054"], ["70573.30", "0.384"], ["70589.40", "0.077"], ["70589.50", "0.087"], ["70598.70", "0.268"], ["70599.50", "0.004"], ["70600.40", "0.052"], ["70601.30", "0.005"], ["70601.40", "0.004"], ["70601.70", "0.501"], ["70602.20", "0.000"], ["70604.80", "0.381"], ["70606.10", "0.002"], ["70606.30", "0.210"], ["70607.10", "0.029"], ["70608.40", "0.006"], ["70611.90", "0.019"], ["70615.30", "1.615"], ["70615.40", "0.264"], ["70615.50", "0.012"], ["70617.30", "0.007"], ["70619.00", "12.697"]], "a": [["70619.10", "1.751"], ["70622.90", "0.006"], ["70625.80", "0.027"], ["70627.90", "0.653"], ["70628.00", "0.006"], ["70628.10", "0.002"], ["70629.70", "0.002"], ["70630.80", "0.063"], ["70630.90", "0.006"], ["70632.80", "0.006"], ["70633.20", "0.007"], ["70633.30", "0.456"], ["70635.00", "0.006"], ["70635.20", "0.035"], ["70638.70", "0.004"], ["70640.30", "0.262"], ["70643.30", "0.225"], ["70645.40", "0.046"], ["70645.50", "0.025"], ["70646.10", "0.002"], ["70646.20", "0.928"], ["70653.90", "0.249"], ["70654.00", "0.196"], ["70654.40", "0.028"], ["70654.50", "0.041"], ["70655.70", "0.003"], ["70656.10", "0.036"], ["70656.40", "0.048"], ["70656.50", "2.359"], ["70658.10", "0.036"], ["70662.10", "0.000"], ["70673.70", "0.000"], ["70720.10", "0.090"], ["70727.20", "0.027"], ["70731.80", "0.252"], ["70734.30", "0.048"], ["70738.90", "0.138"], ["70741.40", "0.182"], ["70746.00", "0.007"], ["70748.50", "0.019"], ["70753.10", "0.007"], ["70755.60", "0.009"], ["70760.20", "0.011"], ["70762.70", "0.021"], ["70767.30", "0.010"], ["70769.80", "0.000"], ["70774.40", "0.007"], ["70781.50", "0.320"], ["70863.40", "0.000"], ["70864.10", "0.000"], ["70941.30", "0.000"], ["71047.70", "0.085"], ["71325.30", "0.000"], ["74152.50", "0.052"], ["89523.20", "0.000"]]}}
{"local_ts": 1773486786517, "server_ts": 1773486786474, "data": {"e": "depthUpdate", "E": 1773486786475, "T": 1773486786474, "s": "BTCUSDT", "U": 10109524378325, "u": 10109524399054, "pu": 10109524378238, "b": [["1000.00", "26.292"], ["5000.00", "101.438"], ["7061.50", "0.028"], ["20115.00", "0.030"], ["20215.00", "1.480"], ["20219.00", "0.770"], ["20315.00", "0.660"], ["69095.70", "0.621"], ["69908.90", "0.002"], ["70261.90", "3.332"], ["70434.90", "0.159"], ["70435.40", "2.417"], ["70440.30", "0.092"], ["70535.70", "0.017"], ["70537.80", "0.183"], ["70551.60", "0.058"], ["70560.10", "8.504"], ["70561.30", "0.050"], ["70561.80", "0.002"], ["70564.90", "0.258"], ["70568.00", "0.228"], ["70568.60", "0.008"], ["70581.10", "0.021"], ["70581.40", "0.014"], ["70583.00", "0.882"], ["70586.20", "0.015"], ["70586.90", "0.176"], ["70587.10", "0.015"], ["70587.20", "0.011"], ["70587.30", "0.015"], ["70587.40", "0.010"], ["70588.00", "0.971"], ["70588.80", "0.004"], ["70589.20", "0.008"], ["70590.10", "0.000"], ["70590.50", "0.512"], ["70591.80", "0.004"], ["70592.00", "0.462"], ["70592.40", "0.006"], ["70592.50", "0.018"], ["70593.30", "0.000"], ["70593.80", "0.185"], ["70594.00", "0.070"], ["70594.70", "0.000"], ["70594.90", "0.014"], ["70596.10", "0.000"], ["70596.60", "0.017"], ["70596.80", "0.000"], ["70596.90", "0.010"], ["70597.70", "0.637"], ["70597.80", "0.048"], ["70598.30", "0.002"], ["70598.50", "0.431"], ["70598.70", "0.000"], ["70598.80", "0.005"], ["70599.00", "0.055"], ["70599.10", "0.003"], ["70599.20", "0.000"], ["70599.70", "0.004"], ["70601.30", "0.003"], ["70602.50", "0.511"], ["70602.60", "0.006"], ["70603.30", "0.013"], ["70604.00", "0.002"], ["70604.10", "0.004"], ["70604.90", "0.002"], ["70605.40", "0.007"], ["70605.60", "0.343"], ["70606.10", "0.002"], ["70606.30", "0.069"], ["70607.90", "0.003"], ["70611.20", "0.000"], ["70614.10", "0.000"], ["70614.30", "0.000"], ["70614.40", "0.000"], ["70614.50", "0.000"], ["70614.60", "0.000"], ["70614.70", "0.000"], ["70614.90", "0.000"], ["70615.00", "0.000"]], "a": [["70614.10", "0.886"], ["70614.20", "2.790"], ["70614.40", "0.498"], ["70614.50", "3.072"], ["70614.60", "0.190"], ["70614.70", "1.362"], ["70614.80", "1.279"], ["70615.00", "1.676"], ["70615.10", "10.866"], ["70618.50", "0.024"], ["70618.60", "0.737"], ["70618.80", "0.000"], ["70619.10", "60.085"], ["70623.80", "0.003"], ["70623.90", "0.008"], ["70629.00", "0.002"], ["70631.90", "0.017"], ["70633.20", "0.007"], ["70633.90", "0.639"], ["70634.70", "1.024"], ["70634.80", "0.005"], ["70636.70", "0.000"], ["70637.10", "0.254"], ["70643.70", "0.000"], ["70651.30", "0.154"], ["70671.50", "0.004"], ["70673.20", "8.490"], ["70676.90", "0.003"], ["70690.10", "0.017"], ["70691.10", "0.085"], ["70715.80", "0.080"], ["70722.90", "0.009"], ["70730.00", "0.170"], ["70731.80", "0.245"], ["70737.10", "0.606"], ["70738.90", "0.131"], ["70744.20", "0.097"], ["70746.00", "0.000"], ["70750.50", "0.013"], ["70751.30", "0.048"], ["70753.10", "0.000"], ["70758.40", "0.048"], ["70760.20", "0.004"], ["70765.50", "0.007"], ["70767.30", "0.003"], ["70774.40", "0.000"], ["70781.50", "0.313"], ["70851.60", "0.511"], ["70878.60", "0.000"], ["70972.20", "3.096"], ["70987.40", "0.020"], ["71321.30", "4.342"], ["71617.80", "1.390"], ["71711.20", "1.950"], ["74168.60", "0.019"], ["89523.20", "0.000"]]}}
{"local_ts": 1773486787523, "server_ts": 1773486787492, "data": {"e": "depthUpdate", "E": 1773486787495, "T": 1773486787492, "s": "BTCUSDT", "U": 10109524545298, "u": 10109524553522, "pu": 10109524545138, "b": [["5000.00", "101.418"], ["7060.80", "0.028"], ["20107.10", "1.460"], ["20215.00", "0.420"], ["33000.00", "3.789"], ["67047.70", "0.002"], ["68488.80", "0.018"], ["69523.80", "1.440"], ["69588.20", "3.080"], ["69901.00", "0.709"], ["70100.10", "3.739"], ["70222.10", "16.020"], ["70291.10", "0.002"], ["70466.90", "1.176"], ["70485.90", "0.193"], ["70500.30", "0.529"], ["70500.40", "0.248"], ["70540.90", "0.017"], ["70541.50", "0.000"], ["70545.00", "0.002"], ["70550.40", "0.000"], ["70551.60", "8.563"], ["70557.50", "0.009"], ["70559.60", "0.298"], ["70559.70", "0.008"], ["70584.30", "0.002"], ["70585.10", "0.000"], ["70593.20", "0.119"], ["70596.50", "0.198"], ["70600.30", "0.001"], ["70606.50", "0.002"], ["70607.10", "0.570"]], "a": [["70607.20", "12.432"], ["70613.20", "0.072"], ["70614.30", "0.083"], ["70614.70", "0.003"], ["70614.80", "0.021"], ["70615.10", "0.005"], ["70617.80", "0.144"], ["70618.50", "0.304"], ["70620.00", "0.031"], ["70622.60", "0.017"], ["70630.80", "0.091"], ["70630.90", "0.003"], ["70665.40", "8.498"], ["70665.90", "0.017"], ["70678.40", "0.151"], ["70679.90", "0.031"], ["70702.60", "0.609"], ["70737.90", "0.331"], ["71159.70", "0.007"], ["71308.90", "4.010"], ["71313.30", "0.000"], ["71631.00", "1.539"], ["72019.30", "0.009"], ["89523.20", "0.000"]]}}
{"local_ts": 1773486788548, "server_ts": 1773486788516, "data": {"e": "depthUpdate", "E": 1773486788517, "T": 1773486788516, "s": "BTCUSDT", "U": 10109524639926, "u": 10109524645484, "pu": 10109524639904, "b": [["1000.00", "26.442"], ["5000.00", "101.418"], ["7060.50", "0.028"], ["20107.10", "0.500"], ["20504.80", "1.470"], ["67058.20", "0.002"], ["69510.50", "1.006"], ["69581.10", "2.010"], ["69898.80", "0.000"], ["70251.80", "0.426"], ["70444.30", "0.360"], ["70553.20", "0.967"], ["70558.60", "0.163"], ["70558.80", "1.593"], ["70558.90", "0.467"], ["70559.10", "0.363"], ["70569.50", "0.059"], ["70580.30", "0.337"], ["70580.40", "0.455"], ["70583.10", "0.269"], ["70583.60", "0.519"], ["70584.30", "0.054"], ["70584.60", "0.006"], ["70586.00", "0.000"], ["70586.60", "0.509"], ["70587.80", "0.005"], ["70588.00", "1.935"], ["70589.00", "0.029"], ["70589.30", "0.069"], ["70590.20", "0.000"], ["70590.70", "0.197"], ["70591.20", "0.322"], ["70591.80", "0.011"], ["70592.80", "0.001"], ["70593.10", "0.006"], ["70594.20", "0.011"], ["70594.40", "0.285"], ["70595.20", "0.003"], ["70596.30", "0.072"], ["70597.70", "0.002"], ["70598.10", "0.643"], ["70598.80", "0.016"], ["70598.90", "0.007"], ["70599.70", "0.398"], ["70601.30", "0.003"], ["70603.60", "0.062"], ["70604.80", "4.354"]], "a": [["70604.90", "2.451"], ["70605.20", "0.004"], ["70610.00", "0.009"], ["70612.80", "0.010"], ["70614.60", "0.306"], ["70614.70", "0.002"], ["70614.80", "0.003"], ["70615.20", "0.007"], ["70615.30", "0.000"], ["70615.50", "0.324"], ["70616.00", "0.010"], ["70616.10", "0.097"], ["70617.20", "0.030"], ["70618.70", "0.216"], ["70619.10", "60.019"], ["70621.30", "0.000"], ["70632.50", "0.000"], ["70633.50", "1.232"], ["70640.20", "0.034"], ["70642.60", "0.027"], ["70644.20", "0.079"], ["70651.40", "0.008"], ["70663.50", "0.018"], ["70669.30", "0.089"], ["70669.40", "0.037"], ["70670.20", "0.038"], ["70670.90", "0.393"], ["70671.00", "0.090"], ["70672.40", "9.222"], ["70674.60", "0.093"], ["70676.60", "0.002"], ["70676.90", "0.002"], ["70678.90", "0.006"], ["70692.40", "0.228"], ["70762.80", "0.004"], ["70843.60", "0.007"], ["71310.90", "0.003"], ["71628.70", "1.934"], ["71664.40", "0.836"], ["71680.30", "0.427"], ["74157.80", "0.078"], ["89523.20", "0.000"]]}}
{"local_ts": 1773486789566, "server_ts": 1773486789538, "data": {"e": "depthUpdate", "E": 1773486789539, "T": 1773486789538, "s": "BTCUSDT", "U": 10109524687453, "u": 10109524691990, "pu": 10109524687346, "b": [["1000.00", "26.292"], ["5000.00", "101.418"], ["7060.50", "0.000"], ["20404.80", "1.030"], ["20504.80", "1.970"], ["56484.00", "0.000"], ["69095.70", "0.002"], ["69566.90", "0.431"], ["69615.60", "6.867"], ["69898.80", "0.000"], ["70358.30", "0.347"], ["70535.70", "0.049"], ["70580.10", "1.084"], ["70596.30", "0.072"], ["70597.70", "0.118"], ["70598.60", "0.538"], ["70599.70", "0.398"], ["70601.50", "0.026"], ["70604.80", "4.535"]], "a": [["70604.90", "1.780"], ["70605.30", "0.002"], ["70606.60", "0.215"], ["70609.60", "0.001"], ["70611.00", "0.057"], ["70612.90", "0.599"], ["70613.00", "0.724"], ["70613.80", "0.024"], ["70615.40", "0.014"], ["70813.10", "0.038"], ["70820.20", "0.000"], ["71310.90", "0.003"], ["71628.70", "3.868"], ["71664.30", "4.110"], ["74162.90", "0.002"], ["89523.20", "0.000"]]}}
{"local_ts": 1773486790595, "server_ts": 1773486790560, "data": {"e": "depthUpdate", "E": 1773486790563, "T": 1773486790560, "s": "BTCUSDT", "U": 10109524740127, "u": 10109524746316, "pu": 10109524739844, "b": [["5000.00", "101.398"], ["7060.50", "0.000"], ["20304.80", "0.590"], ["20404.80", "2.410"], ["20504.80", "0.000"], ["56484.00", "0.000"], ["67068.30", "0.002"], ["67074.60", "0.008"], ["69847.60", "0.000"], ["69898.80", "0.000"], ["70455.00", "0.000"], ["70457.90", "2.254"], ["70469.40", "0.250"], ["70515.20", "0.002"], ["70516.30", "2.155"], ["70551.30", "0.000"], ["70552.80", "1.541"], ["70559.40", "0.017"], ["70559.50", "0.003"], ["70567.70", "0.142"], ["70569.50", "0.056"], ["70573.00", "0.281"], ["70579.80", "0.010"], ["70579.90", "0.008"], ["70580.00", "2.020"], ["70580.10", "1.130"], ["70580.30", "0.153"], ["70580.50", "0.088"], ["70590.70", "0.507"], ["70591.40", "0.191"], ["70592.40", "0.110"], ["70594.20", "0.011"], ["70595.40", "0.177"], ["70595.80", "0.070"], ["70596.30", "0.072"], ["70597.00", "0.054"], ["70597.10", "0.017"], ["70597.70", "0.153"], ["70599.50", "0.006"]], "a": [["70604.90", "1.458"], ["70605.00", "0.048"], ["70612.70", "0.260"], ["70613.00", "0.724"], ["70614.30", "0.112"], ["70615.40", "0.014"], ["70615.50", "0.324"], ["70615.90", "0.002"], ["70616.50", "0.033"], ["70619.20", "0.010"], ["70629.40", "0.029"], ["70630.50", "0.003"], ["70631.00", "0.551"], ["70640.20", "0.034"], ["70647.20", "0.002"], ["70668.70", "1.302"], ["70668.80", "0.048"], ["70699.90", "0.456"], ["70704.60", "1.323"], ["70705.00", "0.093"], ["70712.40", "0.051"], ["70735.80", "0.004"], ["70765.60", "0.005"], ["70859.30", "0.040"], ["71310.90", "0.039"], ["72031.40", "0.007"], ["89523.20", "0.000"]]}}
{"local_ts": 1773486791611, "server_ts": 1773486791581, "data": {"e": "depthUpdate", "E": 1773486791583, "T": 1773486791581, "s": "BTCUSDT", "U": 10109524798497, "u": 10109524802544, "pu": 10109524798381, "b": [["1000.00", "26.292"], ["5000.00", "101.418"], ["7060.50", "0.000"], ["20204.80", "0.290"], ["20304.80", "2.560"], ["20404.80", "0.150"], ["56484.00", "0.000"], ["69197.00", "0.000"], ["69438.90", "0.000"], ["69453.10", "0.002"], ["69898.80", "1.428"], ["70251.80", "0.462"], ["70516.50", "1.209"], ["70559.00", "0.002"], ["70559.20", "2.158"], ["70580.40", "0.285"], ["70583.70", "0.249"], ["70584.90", "0.002"], ["70588.60", "0.510"], ["70589.90", "0.289"], ["70590.70", "0.197"], ["70591.10", "1.197"], ["70591.40", "0.007"], ["70594.20", "0.008"], ["70595.20", "0.006"], ["70596.30", "0.709"], ["70597.10", "0.017"], ["70598.80", "0.014"]], "a": [["70604.90", "1.680"], ["70612.80", "0.517"], ["70612.90", "0.599"], ["70614.70", "0.020"], ["70615.40", "0.018"], ["70615.90", "0.000"], ["70616.50", "0.066"], ["70617.30", "0.392"], ["70624.70", "0.002"], ["70633.50", "0.921"], ["70639.30", "2.284"], ["70641.30", "0.000"], ["70672.10", "1.848"], ["70693.20", "0.000"], ["70829.30", "0.012"], ["71310.80", "0.000"], ["71310.90", "0.003"], ["74137.50", "0.117"], ["89523.20", "0.000"]]}}
{"local_ts": 1773486792631, "server_ts": 1773486792602, "data": {"e": "depthUpdate", "E": 1773486792603, "T": 1773486792602, "s": "BTCUSDT", "U": 10109524854118, "u": 10109524861637, "pu": 10109524853967, "b": [["5000.00", "101.418"], ["7060.50", "0.056"], ["20104.80", "0.140"], ["20204.80", "2.410"], ["20304.80", "0.450"], ["56484.00", "0.000"], ["67054.80", "0.000"], ["69192.80", "0.022"], ["69531.10", "0.861"], ["69623.40", "1.577"], ["69898.80", "1.430"], ["70300.00", "21.993"], ["70429.70", "0.177"], ["70482.70", "0.086"], ["70483.70", "0.693"], ["70516.50", "0.002"], ["70517.60", "2.833"], ["70528.90", "0.139"], ["70548.50", "0.000"], ["70549.50", "0.283"], ["70553.80", "0.028"], ["70555.50", "0.016"], ["70556.50", "0.211"], ["70562.50", "1.836"], ["70569.50", "0.045"], ["70569.60", "0.020"], ["70570.60", "0.322"], ["70576.50", "0.028"], ["70580.10", "1.127"], ["70587.60", "0.247"], ["70588.60", "0.001"], ["70588.90", "0.097"], ["70590.00", "2.442"], ["70590.20", "1.203"], ["70590.60", "0.064"], ["70591.30", "1.024"], ["70591.50", "0.133"], ["70592.40", "0.006"], ["70593.20", "0.116"], ["70593.40", "0.000"], ["70596.70", "0.127"], ["70597.90", "0.438"], ["70598.80", "0.365"], ["70599.30", "0.637"], ["70600.60", "0.008"], ["70601.40", "0.516"], ["70602.10", "0.015"], ["70604.80", "5.851"]], "a": [["70604.90", "0.480"], ["70607.60", "0.000"], ["70612.00", "0.003"], ["70612.90", "0.514"], ["70613.00", "0.581"], ["70614.70", "0.018"], ["70617.10", "0.132"], ["70617.70", "0.011"], ["70621.10", "0.022"], ["70621.90", "0.057"], ["70622.60", "0.005"], ["70622.80", "0.015"], ["70634.70", "1.192"], ["70636.90", "1.027"], ["70640.20", "0.006"], ["70641.00", "0.005"], ["70645.50", "0.068"], ["70647.60", "0.007"], ["70668.80", "1.378"], ["70698.60", "0.886"], ["70707.20", "1.412"], ["70709.80", "0.241"], ["70710.80", "0.202"], ["70716.80", "0.216"], ["70717.80", "0.041"], ["70767.30", "0.063"], ["70809.80", "1.069"], ["71020.40", "0.397"], ["71020.60", "0.200"], ["71021.40", "0.000"], ["71021.60", "0.000"], ["71310.90", "0.005"], ["71706.30", "0.279"]]}}
{"local_ts": 1773486793653, "server_ts": 1773486793624, "data": {"e": "depthUpdate", "E": 1773486793625, "T": 1773486793624, "s": "BTCUSDT", "U": 10109524933917, "u": 10109524943418, "pu": 10109524933886, "b": [["1000.00", "26.292"], ["5000.00", "101.398"], ["7061.50", "0.056"], ["20115.00", "0.990"], ["20204.80", "0.760"], ["56484.00", "0.000"], ["67074.60", "0.006"], ["67074.70", "0.004"], ["67269.10", "0.002"], ["67893.50", "0.002"], ["68824.60", "2.839"], ["69202.70", "0.017"], ["69908.90", "0.000"], ["70251.80", "0.498"], ["70431.40", "0.341"], ["70455.60", "0.385"], ["70473.80", "0.136"], ["70525.40", "0.074"], ["70528.30", "0.184"], ["70561.80", "8.506"], ["70562.20", "0.618"], ["70562.50", "1.794"], ["70563.20", "0.778"], ["70563.80", "0.018"], ["70569.50", "0.065"], ["70577.30", "0.023"], ["70578.10", "0.011"], ["70578.20", "0.349"], ["70579.90", "0.008"], ["70580.30", "0.086"], ["70580.50", "0.018"], ["70582.80", "0.087"], ["70582.90", "0.004"], ["70583.20", "0.364"], ["70586.40", "0.086"], ["70587.10", "0.283"], ["70587.90", "0.965"], ["70588.60", "0.001"], ["70589.60", "0.067"], ["70590.20", "0.000"], ["70590.90", "0.512"], ["70591.60", "0.017"], ["70591.80", "0.072"], ["70592.10", "0.071"], ["70592.30", "0.002"], ["70592.60", "0.114"], ["70592.70", "1.207"], ["70593.10", "0.012"], ["70593.30", "0.002"], ["70593.40", "0.007"], ["70593.70", "0.511"], ["70593.90", "0.011"], ["70595.00", "0.619"], ["70595.40", "0.009"], ["70599.10", "0.370"], ["70599.40", "0.640"], ["70599.50", "0.072"], ["70600.70", "0.128"], ["70601.80", "1.073"], ["70602.00", "0.154"], ["70602.30", "0.016"], ["70602.60", "0.079"], ["70602.80", "0.296"], ["70603.70", "0.003"], ["70603.90", "0.002"], ["70604.40", "0.139"], ["70604.60", "0.002"], ["70605.20", "0.344"], ["70605.30", "0.810"], ["70605.40", "0.121"], ["70605.90", "0.000"], ["70608.00", "0.095"], ["70613.40", "0.000"], ["70615.00", "0.300"]], "a": [["70615.10", "7.884"], ["70615.60", "0.002"], ["70616.80", "0.048"], ["70617.10", "0.215"], ["70617.70", "0.017"], ["70617.80", "0.040"], ["70617.90", "0.504"], ["70618.10", "0.166"], ["70619.60", "0.006"], ["70621.70", "0.004"], ["70622.10", "0.037"], ["70625.80", "0.019"], ["70626.60", "0.492"], ["70630.80", "0.406"], ["70636.10", "0.665"], ["70640.80", "0.006"], ["70642.10", "0.003"], ["70645.30", "0.009"], ["70650.60", "0.017"], ["70655.30", "0.003"], ["70656.00", "0.043"], ["70656.70", "0.004"], ["70657.40", "7.850"], ["70662.60", "0.000"], ["70663.90", "0.386"], ["70664.10", "0.037"], ["70676.20", "2.241"], ["70676.30", "4.387"], ["70676.70", "0.005"], ["70703.60", "0.000"], ["70711.90", "2.230"], ["70712.80", "0.219"], ["70715.30", "0.000"], ["70770.50", "0.610"], ["70770.60", "3.611"], ["70774.00", "1.898"], ["70828.60", "0.011"], ["71321.30", "4.342"], ["71932.00", "0.000"], ["71950.20", "0.000"], ["72396.10", "2.482"], ["74178.70", "0.004"]]}}
{"local_ts": 1773486794674, "server_ts": 1773486794644, "data": {"e": "depthUpdate", "E": 1773486794645, "T": 1773486794644, "s": "BTCUSDT", "U": 10109525008385, "u": 10109525013649, "pu": 10109525008365, "b": [["1000.00", "26.292"], ["5000.00", "101.418"], ["7061.50", "0.056"], ["20104.80", "0.750"], ["20115.00", "0.450"], ["20515.00", "1.800"], ["33000.00", "3.785"], ["56484.00", "0.000"], ["66916.90", "0.002"], ["67070.90", "0.002"], ["67078.50", "0.000"], ["67541.80", "0.002"], ["67790.40", "1.332"], ["69340.90", "0.000"], ["69908.90", "0.000"], ["70251.90", "0.000"], ["70368.70", "35.004"], ["70558.60", "0.217"], ["70566.60", "2.609"], ["70568.00", "0.065"], ["70568.80", "0.305"], ["70579.70", "0.035"], ["70581.20", "0.293"], ["70583.20", "0.770"], ["70583.40", "0.368"], ["70583.80", "0.175"], ["70584.60", "0.006"], ["70585.90", "0.015"], ["70587.80", "0.012"], ["70588.70", "0.108"], ["70589.20", "0.008"], ["70590.10", "0.676"], ["70591.80", "0.002"], ["70593.00", "0.026"], ["70593.50", "0.003"], ["70593.80", "1.262"], ["70594.40", "0.000"], ["70594.80", "0.213"], ["70594.90", "0.032"], ["70595.20", "0.017"], ["70596.00", "0.424"], ["70596.20", "0.720"], ["70596.30", "0.227"], ["70596.50", "0.186"], ["70596.70", "0.000"], ["70597.30", "0.138"], ["70597.50", "0.068"], ["70598.80", "0.027"], ["70598.90", "0.005"], ["70599.10", "0.102"], ["70599.80", "0.000"], ["70601.00", "0.023"], ["70601.10", "0.428"], ["70601.60", "0.007"], ["70602.00", "0.011"], ["70602.20", "0.000"], ["70604.40", "0.003"], ["70605.30", "0.312"], ["70605.40", "0.002"], ["70605.80", "0.002"], ["70606.30", "0.114"], ["70606.40", "0.001"], ["70606.50", "0.339"], ["70608.10", "0.003"], ["70608.20", "0.009"], ["70608.30", "0.002"], ["70608.40", "0.005"], ["70608.50", "0.291"], ["70614.50", "0.000"]], "a": [["70615.10", "4.201"], ["70617.10", "0.227"], ["70617.70", "0.027"], ["70617.80", "0.009"], ["70618.10", "0.164"], ["70618.20", "0.003"], ["70618.60", "0.396"], ["70618.70", "0.009"], ["70618.80", "0.220"], ["70618.90", "1.266"], ["70619.30", "0.036"], ["70619.40", "0.029"], ["70619.60", "0.103"], ["70620.00", "0.137"], ["70620.10", "0.037"], ["70620.50", "0.000"], ["70620.80", "0.000"], ["70621.40", "0.007"], ["70622.30", "0.021"], ["70622.40", "0.007"], ["70622.90", "0.667"], ["70623.00", "0.008"], ["70625.50", "0.008"], ["70626.80", "0.041"], ["70627.00", "0.004"], ["70628.30", "0.006"], ["70628.60", "0.977"], ["70633.20", "0.007"], ["70636.00", "0.000"], ["70636.10", "0.027"], ["70641.30", "0.048"], ["70643.70", "0.070"], ["70643.80", "0.258"], ["70646.70", "0.036"], ["70650.40", "0.229"], ["70663.50", "0.089"], ["70663.60", "0.511"], ["70679.40", "2.758"], ["70696.30", "0.036"], ["70696.70", "0.061"], ["70697.00", "0.076"], ["70698.70", "0.026"], ["70699.40", "0.036"], ["70828.50", "0.007"], ["71140.40", "0.000"], ["71321.30", "4.340"], ["71850.90", "7.644"], ["72027.40", "1.402"]]}}
{"local_ts": 1773486795704, "server_ts": 1773486795664, "data": {"e": "depthUpdate", "E": 1773486795665, "T": 1773486795664, "s": "BTCUSDT", "U": 10109525061809, "u": 10109525065827, "pu": 10109525061800, "b": [["5000.00", "101.418"], ["7061.50", "0.056"], ["20415.00", "1.350"], ["20515.00", "1.650"], ["67069.70", "0.000"], ["69343.90", "0.360"], ["69439.00", "0.722"], ["69835.20", "1.431"], ["69908.90", "0.000"], ["70398.30", "0.000"], ["70471.60", "0.019"], ["70542.50", "0.051"], ["70544.60", "0.282"], ["70559.80", "2.755"], ["70567.80", "0.718"], ["70568.00", "0.065"], ["70578.90", "0.009"], ["70579.60", "0.098"], ["70583.20", "0.225"], ["70584.50", "0.901"], ["70591.60", "0.511"], ["70592.10", "1.204"], ["70593.20", "0.116"], ["70593.30", "0.009"], ["70598.70", "0.283"], ["70599.10", "0.014"], ["70599.60", "1.096"], ["70600.40", "0.000"], ["70601.40", "0.531"], ["70601.70", "0.005"], ["70604.40", "0.417"], ["70604.70", "0.010"], ["70605.30", "0.427"], ["70607.90", "0.006"]], "a": [["70615.10", "4.853"], ["70616.60", "0.038"], ["70616.90", "0.008"], ["70617.90", "0.479"], ["70618.60", "0.297"], ["70618.90", "0.783"], ["70622.00", "0.059"], ["70626.80", "0.039"], ["70628.40", "0.153"], ["70632.80", "0.154"], ["70636.30", "0.153"], ["70643.80", "0.347"], ["70658.80", "1.153"], ["70673.60", "1.631"], ["70745.90", "0.000"], ["71293.00", "1.967"], ["71321.30", "4.340"], ["72027.40", "1.408"]]}}
{"local_ts": 1773486796717, "server_ts": 1773486796684, "data": {"e": "depthUpdate", "E": 1773486796687, "T": 1773486796684, "s": "BTCUSDT", "U": 10109525132163, "u": 10109525137418, "pu": 10109525132012, "b": [["1000.00", "26.292"], ["5000.00", "101.418"], ["7061.40", "0.028"], ["20313.60", "0.610"], ["20415.00", "1.500"], ["33000.00", "3.789"], ["67051.40", "0.002"], ["67789.10", "0.004"], ["69439.00", "0.720"], ["69786.70", "2.564"], ["69907.50", "0.005"], ["70261.90", "3.332"], ["70367.40", "0.004"], ["70528.90", "0.000"], ["70529.70", "0.002"], ["70535.90", "0.017"], ["70550.00", "0.379"], ["70552.80", "1.662"], ["70560.10", "0.000"], ["70562.90", "0.000"], ["70563.60", "0.005"], ["70567.40", "0.022"], ["70567.50", "0.004"], ["70577.30", "0.059"], ["70578.30", "0.978"], ["70579.30", "0.026"], ["70582.20", "0.128"], ["70582.30", "0.007"], ["70582.40", "0.004"], ["70583.60", "0.509"], ["70584.60", "0.176"], ["70584.90", "0.002"], ["70590.40", "0.000"], ["70592.70", "0.061"], ["70594.50", "0.007"], ["70595.70", "0.219"], ["70596.30", "0.227"], ["70596.50", "0.207"], ["70598.50", "0.849"], ["70598.60", "1.175"], ["70599.60", "0.474"], ["70599.70", "0.008"], ["70601.30", "0.018"], ["70601.90", "0.589"], ["70603.00", "0.278"], ["70605.40", "0.456"], ["70605.50", "0.010"], ["70606.50", "0.000"], ["70612.60", "0.001"], ["70613.50", "0.003"], ["70613.60", "1.664"]], "a": [["70613.70", "11.824"], ["70615.10", "0.315"], ["70616.40", "0.004"], ["70616.50", "0.212"], ["70617.00", "0.007"], ["70617.20", "0.058"], ["70618.80", "0.119"], ["70620.60", "0.001"], ["70622.90", "0.014"], ["70624.40", "0.011"], ["70633.00", "0.000"], ["70634.10", "0.636"], ["70636.80", "0.000"], ["70638.40", "0.367"], ["70640.30", "0.003"], ["70641.30", "0.247"], ["70647.60", "0.052"], ["70648.50", "0.008"], ["70649.00", "0.006"], ["70663.40", "0.004"], ["70668.40", "0.002"], ["70669.60", "0.636"], ["70677.30", "0.090"], ["70691.40", "0.214"], ["71319.80", "0.016"], ["71592.50", "0.002"], ["71919.20", "0.347"]]}}
{"local_ts": 1773486797738, "server_ts": 1773486797710, "data": {"e": "depthUpdate", "E": 1773486797711, "T": 1773486797710, "s": "BTCUSDT", "U": 10109525201551, "u": 10109525208826, "pu": 10109525201430, "b": [["5000.00", "101.418"], ["7061.40", "0.028"], ["20213.60", "0.460"], ["20313.60", "2.540"], ["20413.60", "0.000"], ["67067.80", "0.000"], ["67789.10", "0.008"], ["68613.60", "0.003"], ["69192.80", "0.004"], ["69589.70", "0.863"], ["69907.50", "0.005"], ["70082.70", "0.002"], ["70437.10", "1.506"], ["70553.60", "0.081"], ["70560.00", "0.030"], ["70566.60", "2.583"], ["70582.00", "0.977"], ["70582.10", "0.457"], ["70583.10", "0.165"], ["70601.20", "0.205"], ["70602.00", "0.223"], ["70602.20", "0.000"], ["70603.00", "0.101"], ["70603.50", "0.639"], ["70606.50", "0.002"]], "a": [["70613.70", "9.664"], ["70617.20", "0.000"], ["70617.60", "0.012"], ["70620.60", "0.003"], ["70623.70", "0.010"], ["70624.40", "0.004"], ["70638.90", "0.000"], ["70639.80", "0.513"], ["70663.40", "0.002"], ["70665.50", "0.021"], ["70676.10", "2.309"], ["70676.20", "8.494"], ["71144.50", "0.024"], ["71319.80", "0.016"], ["72755.80", "1.176"]]}}
{"local_ts": 1773486798765, "server_ts": 1773486798732, "data": {"e": "depthUpdate", "E": 1773486798733, "T": 1773486798732, "s": "BTCUSDT", "U": 10109525277999, "u": 10109525284989, "pu": 10109525277782, "b": [["1000.00", "26.292"], ["5000.00", "101.418"], ["7061.40", "0.028"], ["20113.60", "0.250"], ["20213.60", "2.520"], ["20313.60", "0.230"], ["67074.70", "0.004"], ["67789.10", "0.012"], ["69613.30", "0.000"], ["69766.30", "1.144"], ["69907.50", "0.005"], ["70260.50", "0.000"], ["70528.90", "0.071"], ["70558.70", "1.914"], ["70567.00", "0.006"], ["70567.30", "0.099"], ["70590.00", "1.840"], ["70593.60", "0.456"], ["70597.70", "0.075"], ["70598.00", "0.395"], ["70603.00", "0.101"], ["70605.10", "0.146"], ["70606.50", "0.000"]], "a": [["70613.70", "9.636"], ["70618.80", "0.094"], ["70619.00", "8.963"], ["70620.60", "0.001"], ["70624.30", "0.003"], ["70628.70", "0.516"], ["70630.10", "0.016"], ["70630.80", "0.406"], ["70632.20", "0.480"], ["70645.80", "0.457"], ["70665.50", "0.019"], ["70672.40", "0.751"], ["70690.90", "0.023"], ["71319.80", "0.016"], ["72035.70", "0.594"], ["74157.00", "0.052"]]}}
{"local_ts": 1773486799781, "server_ts": 1773486799750, "data": {"e": "depthUpdate", "E": 1773486799753, "T": 1773486799750, "s": "BTCUSDT", "U": 10109525336890, "u": 10109525342753, "pu": 10109525336839, "b": [["1000.00", "26.292"], ["5000.00", "101.418"], ["7061.40", "0.000"], ["20113.60", "2.380"], ["20213.60", "0.530"], ["20513.60", "0.090"], ["67789.10", "0.022"], ["68473.00", "1.273"], ["68848.30", "0.292"], ["69201.40", "0.024"], ["69327.10", "0.578"], ["69907.50", "0.005"], ["70366.10", "0.262"], ["70366.80", "4.312"], ["70476.30", "0.654"], ["70560.60", "0.002"], ["70562.20", "0.561"], ["70567.30", "0.097"], ["70567.50", "0.004"], ["70567.70", "0.003"], ["70579.30", "0.023"], ["70581.20", "0.272"], ["70582.10", "0.542"], ["70582.20", "0.043"], ["70583.70", "0.000"], ["70588.30", "0.002"], ["70589.60", "0.069"], ["70592.30", "0.009"], ["70593.70", "1.714"], ["70595.10", "0.070"], ["70596.20", "0.516"], ["70597.10", "0.008"], ["70597.20", "0.346"], ["70597.60", "0.006"], ["70598.10", "0.076"], ["70598.30", "0.017"], ["70598.80", "0.006"], ["70599.70", "0.156"], ["70599.80", "0.000"], ["70599.90", "0.023"], ["70601.10", "0.436"], ["70602.50", "0.658"], ["70603.00", "0.449"], ["70603.30", "0.022"], ["70603.60", "0.004"], ["70603.80", "0.112"], ["70604.60", "0.002"], ["70605.10", "0.141"], ["70605.30", "0.057"], ["70605.40", "0.002"], ["70605.50", "0.013"], ["70605.60", "0.117"], ["70605.80", "0.002"], ["70606.00", "0.005"], ["70606.20", "0.001"], ["70606.40", "0.001"], ["70606.50", "0.000"], ["70606.70", "0.005"], ["70606.90", "0.000"], ["70607.00", "0.006"], ["70609.60", "0.001"], ["70613.50", "0.003"], ["70613.60", "1.720"]], "a": [["70613.70", "9.638"], ["70616.50", "0.212"], ["70620.40", "0.008"], ["70620.60", "0.001"], ["70624.90", "0.003"], ["70625.70", "0.144"], ["70629.70", "0.030"], ["70638.20", "0.000"], ["70639.30", "0.013"], ["70642.50", "0.003"], ["70643.70", "0.070"], ["70644.60", "0.002"], ["70645.70", "0.250"], ["70690.90", "0.014"], ["70691.10", "0.087"], ["70744.60", "0.406"], ["70769.10", "0.252"], ["70846.70", "0.641"], ["71319.80", "0.016"], ["71839.80", "2.778"], ["74172.50", "0.055"]]}}
{"local_ts": 1773486800801, "server_ts": 1773486800772, "data": {"e": "depthUpdate", "E": 1773486800773, "T": 1773486800772, "s": "BTCUSDT", "U": 10109525392892, "u": 10109525397819, "pu": 10109525392848, "b": [["5000.00", "101.418"], ["7061.40", "0.000"], ["20113.60", "0.880"], ["20513.60", "2.120"], ["67789.10", "0.661"], ["69907.50", "0.719"], ["70292.20", "0.000"], ["70292.40", "0.032"], ["70553.60", "0.081"], ["70567.00", "0.008"], ["70567.10", "0.524"], ["70574.30", "0.024"], ["70578.30", "1.049"], ["70578.80", "0.042"], ["70583.70", "0.184"], ["70585.10", "0.021"], ["70590.40", "0.000"], ["70600.30", "0.003"], ["70600.60", "0.003"], ["70601.20", "0.205"], ["70601.30", "0.347"], ["70602.00", "0.238"], ["70602.30", "0.145"], ["70602.60", "0.006"], ["70603.00", "0.151"], ["70604.30", "0.650"], ["70604.70", "0.021"], ["70605.00", "0.529"], ["70605.20", "0.005"], ["70605.70", "0.347"], ["70605.90", "0.000"], ["70606.20", "0.001"], ["70606.60", "0.002"], ["70606.70", "0.429"], ["70607.70", "0.003"], ["70607.80", "0.012"], ["70609.40", "0.002"], ["70613.60", "3.626"]], "a": [["70619.90", "0.037"], ["70621.80", "0.654"], ["70622.70", "0.003"], ["70622.80", "0.000"], ["70622.90", "0.004"], ["70638.00", "0.005"], ["70640.30", "1.919"], ["70643.10", "0.008"], ["70644.30", "0.074"], ["70647.20", "0.029"], ["70649.00", "0.034"], ["70691.10", "0.085"], ["70705.80", "0.306"], ["71319.80", "0.716"], ["71558.30", "1.675"], ["71888.00", "14.337"], ["74158.80", "0.000"]]}}
{"local_ts": 1773486801824, "server_ts": 1773486801792, "data": {"e": "depthUpdate", "E": 1773486801795, "T": 1773486801792, "s": "BTCUSDT", "U": 10109525442103, "u": 10109525445994, "pu": 10109525441941, "b": [["1000.00", "26.292"], ["5000.00", "101.418"], ["7061.40", "0.000"], ["20413.60", "1.670"], ["20513.60", "1.330"], ["33000.00", "3.785"], ["67069.60", "0.000"], ["67082.90", "0.007"], ["67789.10", "0.663"], ["69293.10", "0.362"], ["69907.50", "0.719"], ["69907.60", "0.000"], ["70260.50", "0.000"], ["70367.30", "0.004"], ["70399.90", "0.004"], ["70507.30", "0.117"], ["70542.70", "0.056"], ["70553.60", "0.000"], ["70583.70", "0.170"], ["70590.70", "0.212"], ["70590.90", "0.003"], ["70605.50", "0.202"], ["70611.20", "0.003"], ["70611.60", "0.000"]], "a": [["70615.80", "0.002"], ["70616.10", "0.061"], ["70618.60", "0.180"], ["70618.80", "0.094"], ["70620.80", "0.015"], ["70622.10", "0.016"], ["70632.70", "0.015"], ["70679.90", "0.078"], ["71319.80", "0.716"], ["71626.50", "0.697"], ["74155.40", "0.005"], ["89523.20", "0.000"]]}}
{"local_ts": 1773486802845, "server_ts": 1773486802815, "data": {"e": "depthUpdate", "E": 1773486802817, "T": 1773486802815, "s": "BTCUSDT", "U": 10109525502805, "u": 10109525507756, "pu": 10109525502693, "b": [["5000.00", "101.438"], ["7061.40", "0.056"], ["20313.60", "1.220"], ["20413.60", "1.780"], ["48525.00", "0.000"], ["50528.00", "0.000"], ["53125.00", "0.010"], ["67082.30", "0.006"], ["67084.30", "0.003"], ["67084.40", "0.004"], ["69575.60", "1.363"], ["69721.60", "0.000"], ["69907.50", "0.719"], ["69907.60", "0.000"], ["70367.40", "0.000"], ["70433.50", "23.660"], ["70506.10", "0.173"], ["70507.20", "0.004"], ["70513.90", "0.000"], ["70516.00", "0.000"], ["70516.70", "0.002"], ["70517.80", "0.003"], ["70518.40", "0.000"], ["70518.70", "0.000"], ["70519.10", "0.002"], ["70519.40", "0.000"], ["70519.80", "0.000"], ["70537.00", "1.582"], ["70537.90", "0.016"], ["70538.80", "1.678"], ["70542.30", "0.000"], ["70543.60", "0.002"], ["70544.30", "0.000"], ["70545.20", "0.275"], ["70545.30", "0.000"], ["70545.40", "0.009"], ["70545.60", "0.002"], ["70546.00", "0.842"], ["70546.30", "0.003"], ["70546.70", "0.000"], ["70547.10", "0.113"], ["70562.50", "0.640"], ["70566.10", "1.069"], ["70566.60", "1.473"], ["70566.70", "0.852"], ["70567.70", "0.003"], ["70581.20", "0.272"], ["70583.20", "0.204"], ["70588.60", "0.248"], ["70590.00", "2.492"], ["70590.20", "0.184"], ["70590.70", "0.073"], ["70591.90", "0.004"], ["70592.00", "0.275"], ["70592.30", "0.511"], ["70593.40", "0.070"], ["70594.80", "0.213"], ["70595.10", "0.007"], ["70596.20", "0.516"], ["70596.90", "0.010"], ["70597.00", "0.236"], ["70597.60", "0.004"], ["70598.80", "0.063"], ["70598.90", "0.000"], ["70599.00", "0.074"], ["70599.20", "0.268"], ["70599.30", "0.151"], ["70599.40", "0.005"], ["70599.50", "0.013"], ["70599.70", "0.426"], ["70600.10", "0.003"], ["70600.40", "0.637"], ["70600.70", "0.166"], ["70600.80", "0.074"], ["70602.00", "0.039"], ["70603.00", "0.843"], ["70603.50", "0.059"], ["70605.60", "0.122"], ["70607.30", "0.023"], ["70608.00", "0.013"], ["70610.10", "0.021"], ["70610.60", "0.016"], ["70611.80", "0.000"], ["70613.50", "0.020"]], "a": [["70613.70", "7.103"], ["70615.30", "0.000"], ["70615.60", "0.002"], ["70616.70", "0.022"], ["70616.90", "0.038"], ["70617.10", "0.656"], ["70617.20", "0.058"], ["70617.70", "0.015"], ["70618.50", "0.000"], ["70618.60", "0.201"], ["70618.70", "0.023"], ["70619.10", "60.011"], ["70619.20", "0.007"], ["70619.40", "0.019"], ["70619.60", "0.006"], ["70619.80", "0.004"], ["70619.90", "0.001"], ["70620.10", "0.001"], ["70620.30", "0.044"], ["70620.40", "0.044"], ["70620.70", "0.082"], ["70620.80", "0.000"], ["70622.00", "0.074"], ["70628.80", "0.018"], ["70630.10", "0.026"], ["70631.30", "0.000"], ["70632.60", "0.000"], ["70635.80", "0.511"], ["70636.30", "0.002"], ["70636.70", "2.338"], ["70637.50", "0.512"], ["70638.60", "0.002"], ["70640.30", "1.413"], ["70641.40", "0.400"], ["70643.40", "0.000"], ["70644.30", "0.004"], ["70644.40", "0.252"], ["70645.60", "0.048"], ["70646.00", "0.000"], ["70646.10", "0.000"], ["70646.30", "0.000"], ["70646.60", "0.553"], ["70646.70", "0.000"], ["70647.00", "0.003"], ["70647.20", "0.040"], ["70647.90", "0.057"], ["70648.10", "0.328"], ["70648.30", "0.005"], ["70650.50", "0.553"], ["70651.20", "1.352"], ["70651.30", "0.002"], ["70651.40", "0.044"], ["70672.50", "1.068"], ["70672.80", "0.110"], ["70673.20", "0.002"], ["70673.50", "0.002"], ["70673.70", "0.007"], ["70673.90", "0.000"], ["70674.10", "0.547"], ["70674.60", "8.580"], ["70674.80", "0.003"], ["70675.50", "0.093"], ["70676.80", "0.018"], ["70679.40", "1.671"], ["70680.80", "0.000"], ["70681.20", "0.000"], ["70682.10", "0.210"], ["70682.30", "1.045"], ["70700.00", "25.270"], ["70828.10", "0.262"], ["71060.00", "1.139"], ["71319.60", "0.000"], ["71319.80", "0.716"], ["89523.20", "0.000"]]}}
{"local_ts": 1773486803879, "server_ts": 1773486803836, "data": {"e": "depthUpdate", "E": 1773486803839, "T": 1773486803836, "s": "BTCUSDT", "U": 10109525558431, "u": 10109525563261, "pu": 10109525558411, "b": [["1000.00", "26.292"], ["5000.00", "101.418"], ["7061.40", "0.056"], ["20213.60", "0.780"], ["20313.60", "2.220"], ["33000.00", "3.789"], ["56491.00", "0.000"], ["63552.20", "0.002"], ["67070.00", "59.545"], ["68832.90", "2.615"], ["69907.50", "0.719"], ["70250.10", "0.000"], ["70260.50", "0.000"], ["70367.20", "0.004"], ["70367.60", "0.000"], ["70558.90", "1.166"], ["70572.50", "0.007"], ["70583.60", "0.347"], ["70588.50", "1.070"], ["70590.20", "0.431"], ["70590.30", "0.190"], ["70591.40", "0.002"], ["70592.30", "0.002"], ["70593.50", "0.007"], ["70595.20", "0.512"], ["70595.30", "0.077"], ["70596.50", "0.114"], ["70603.00", "0.707"], ["70605.20", "0.516"], ["70606.50", "0.139"]], "a": [["70618.60", "0.192"], ["70618.70", "0.052"], ["70637.30", "0.004"], ["70637.50", "0.003"], ["70638.70", "0.660"], ["70639.10", "0.515"], ["70676.20", "2.164"], ["70769.10", "0.252"], ["71319.80", "0.716"], ["71448.40", "1.118"], ["74158.70", "0.370"], ["77675.10", "0.002"], ["89523.20", "0.000"]]}}
{"local_ts": 1773486804891, "server_ts": 1773486804860, "data": {"e": "depthUpdate", "E": 1773486804863, "T": 1773486804860, "s": "BTCUSDT", "U": 10109525605142, "u": 10109525609883, "pu": 10109525605121, "b": [["1000.00", "26.292"], ["5000.00", "101.418"], ["7061.40", "0.056"], ["20113.60", "0.380"], ["20213.60", "2.580"], ["20313.60", "0.040"], ["63552.20", "0.002"], ["67061.80", "0.000"], ["69907.50", "0.719"], ["70553.60", "0.081"], ["70561.20", "0.003"], ["70563.40", "0.018"], ["70563.70", "0.021"], ["70566.70", "9.350"], ["70567.00", "0.006"], ["70567.10", "0.526"], ["70568.70", "0.005"], ["70569.60", "0.005"], ["70580.10", "0.994"], ["70580.30", "0.178"], ["70580.40", "0.101"], ["70580.50", "0.003"], ["70580.60", "0.000"], ["70583.60", "0.486"], ["70588.30", "0.002"], ["70589.30", "0.013"], ["70590.20", "0.000"], ["70590.30", "0.006"], ["70590.40", "0.184"], ["70592.10", "0.248"], ["70593.80", "1.262"], ["70595.10", "0.007"], ["70595.40", "0.002"], ["70596.10", "1.076"], ["70596.20", "0.516"], ["70596.70", "0.070"], ["70597.30", "0.143"], ["70597.50", "0.516"], ["70597.80", "0.002"], ["70598.40", "0.027"], ["70598.70", "0.070"], ["70599.60", "0.461"], ["70602.10", "0.098"], ["70603.00", "0.487"], ["70603.70", "0.517"], ["70603.80", "0.115"], ["70604.30", "0.639"], ["70604.80", "0.360"], ["70605.50", "0.354"], ["70606.50", "0.414"], ["70606.60", "0.061"], ["70609.00", "0.027"], ["70611.10", "0.102"], ["70613.50", "0.020"], ["70613.60", "2.716"]], "a": [["70613.70", "6.684"], ["70613.90", "0.000"], ["70615.00", "0.043"], ["70615.10", "0.244"], ["70616.40", "0.004"], ["70616.50", "0.140"], ["70616.70", "0.037"], ["70617.10", "0.003"], ["70617.20", "0.058"], ["70617.70", "0.007"], ["70618.70", "0.048"], ["70618.80", "0.094"], ["70619.00", "8.996"], ["70619.60", "0.042"], ["70622.70", "0.673"], ["70624.40", "0.004"], ["70624.90", "0.010"], ["70638.70", "0.024"], ["70639.10", "0.006"], ["70639.20", "0.006"], ["70639.70", "0.003"], ["70639.80", "0.009"], ["70639.90", "0.134"], ["70640.30", "1.413"], ["70640.50", "0.023"], ["70640.60", "0.160"], ["70640.90", "0.649"], ["70641.20", "0.014"], ["70641.30", "0.000"], ["70641.50", "0.511"], ["70643.70", "0.000"], ["70643.80", "0.063"], ["70644.30", "0.074"], ["70645.40", "0.070"], ["70646.80", "0.107"], ["70648.00", "0.190"], ["70649.50", "0.002"], ["70649.90", "0.247"], ["70651.60", "0.052"], ["70669.70", "0.293"], ["70669.80", "0.550"], ["70669.90", "0.303"], ["70673.70", "0.068"], ["70675.50", "0.197"], ["70675.80", "0.286"], ["70676.70", "0.008"], ["70678.90", "8.490"], ["71319.80", "0.716"], ["72379.00", "0.693"], ["77675.10", "0.002"], ["89523.20", "0.000"]]}}
{"local_ts": 1773486805913, "server_ts": 1773486805884, "data": {"e": "depthUpdate", "E": 1773486805885, "T": 1773486805884, "s": "BTCUSDT", "U": 10109525641718, "u": 10109525644990, "pu": 10109525641662, "b": [["5000.00", "101.418"], ["7061.40", "0.028"], ["20113.60", "2.480"], ["20213.60", "0.310"], ["20513.60", "0.210"], ["63552.20", "0.002"], ["67789.10", "1.300"], ["69346.20", "0.000"], ["69907.50", "0.719"], ["70261.90", "3.296"], ["70518.70", "0.104"], ["70567.10", "0.524"], ["70567.20", "0.079"], ["70569.60", "0.005"], ["70578.30", "1.041"], ["70580.20", "0.076"], ["70583.80", "0.191"], ["70587.10", "0.015"], ["70589.00", "0.000"], ["70590.40", "0.000"], ["70590.90", "0.003"], ["70593.20", "1.211"], ["70593.80", "0.059"], ["70596.20", "0.586"], ["70596.70", "0.000"], ["70602.10", "0.268"], ["70605.20", "0.573"], ["70605.50", "0.270"], ["70605.70", "0.006"], ["70606.70", "0.005"], ["70609.30", "0.001"], ["70609.50", "0.000"], ["70609.60", "0.001"], ["70609.80", "0.005"], ["70611.10", "0.051"], ["70611.50", "0.002"], ["70612.40", "0.000"], ["70612.50", "0.220"], ["70613.20", "0.002"], ["70613.50", "0.005"], ["70613.60", "2.034"]], "a": [["70613.70", "7.326"], ["70613.80", "0.038"], ["70613.90", "0.000"], ["70614.00", "0.002"], ["70614.50", "0.002"], ["70614.70", "0.057"], ["70614.90", "0.000"], ["70615.00", "0.058"], ["70616.60", "0.002"], ["70616.70", "0.001"], ["70617.20", "0.319"], ["70618.10", "0.003"], ["70618.60", "0.194"], ["70618.70", "0.027"], ["70618.80", "0.094"], ["70619.20", "0.028"], ["70619.40", "0.040"], ["70619.90", "0.001"], ["70620.70", "0.015"], ["70621.10", "0.011"], ["70622.30", "0.655"], ["70628.80", "0.025"], ["70630.10", "0.019"], ["70633.40", "0.695"], ["70635.30", "0.025"], ["70639.00", "0.021"], ["70639.90", "0.770"], ["70640.70", "0.511"], ["70643.00", "0.095"], ["70643.90", "0.008"], ["70644.30", "0.004"], ["70644.80", "0.070"], ["70649.00", "0.034"], ["71319.80", "0.716"], ["71664.30", "0.836"], ["71932.10", "0.000"], ["74155.80", "0.004"], ["77675.10", "0.002"], ["89523.20", "0.000"]]}}
{"local_ts": 1773486806932, "server_ts": 1773486806904, "data": {"e": "depthUpdate", "E": 1773486806905, "T": 1773486806904, "s": "BTCUSDT", "U": 10109525681556, "u": 10109525685167, "pu": 10109525681454, "b": [["1000.00", "26.292"], ["5000.00", "101.418"], ["7061.30", "0.028"], ["20113.60", "0.430"], ["20412.80", "0.060"], ["20512.80", "2.120"], ["20513.60", "0.210"], ["62800.00", "5.203"], ["63500.00", "26.399"], ["63551.50", "0.002"], ["69343.80", "0.720"], ["69906.70", "0.000"], ["70260.50", "0.000"], ["70478.20", "0.098"], ["70513.40", "0.108"], ["70566.20", "0.043"], ["70566.30", "0.015"], ["70577.50", "0.002"], ["70580.20", "0.076"], ["70581.40", "0.049"], ["70581.50", "0.020"], ["70584.60", "0.288"], ["70597.60", "0.004"], ["70598.40", "0.028"], ["70601.00", "0.005"], ["70601.20", "0.408"], ["70601.30", "0.003"], ["70602.30", "0.418"], ["70612.80", "2.579"]], "a": [["70618.40", "0.007"], ["70648.20", "0.947"], ["70677.00", "0.298"], ["70744.20", "0.090"], ["71319.00", "0.972"], ["71578.90", "0.704"], ["71594.40", "0.976"], ["74176.70", "0.000"], ["77674.20", "0.002"], ["89523.20", "0.000"]]}}
{"local_ts": 1773486807953, "server_ts": 1773486807924, "data": {"e": "depthUpdate", "E": 1773486807925, "T": 1773486807924, "s": "BTCUSDT", "U": 10109525729530, "u": 10109525733982, "pu": 10109525729376, "b": [["5000.00", "101.418"], ["7061.30", "0.028"], ["20412.80", "2.000"], ["20512.80", "1.000"], ["63551.50", "0.002"], ["67055.20", "0.000"], ["69906.70", "0.000"], ["70366.50", "0.006"], ["70432.70", "0.159"], ["70439.40", "0.000"], ["70439.50", "4.498"], ["70478.30", "2.686"], ["70507.90", "0.000"], ["70509.00", "0.109"], ["70515.70", "0.022"], ["70517.90", "0.000"], ["70518.50", "0.000"], ["70519.60", "0.042"], ["70520.20", "0.000"], ["70520.60", "0.000"], ["70520.90", "0.205"], ["70521.30", "0.002"], ["70521.60", "2.248"], ["70523.20", "0.002"], ["70538.80", "1.613"], ["70539.70", "0.002"], ["70544.20", "0.004"], ["70545.50", "0.000"], ["70546.10", "2.035"], ["70547.10", "0.041"], ["70547.20", "0.002"], ["70547.40", "0.074"], ["70547.80", "0.855"], ["70548.10", "0.056"], ["70548.50", "0.000"], ["70566.30", "0.017"], ["70566.50", "0.004"], ["70581.20", "0.272"], ["70581.30", "0.160"], ["70582.80", "0.141"], ["70583.10", "0.349"], ["70591.60", "0.082"], ["70597.90", "0.017"], ["70598.50", "0.615"], ["70600.70", "0.101"], ["70600.80", "0.002"], ["70600.90", "0.009"], ["70601.10", "0.012"], ["70601.20", "0.276"], ["70601.40", "0.516"], ["70601.50", "0.003"], ["70601.90", "0.834"], ["70602.00", "0.011"], ["70602.30", "0.181"], ["70602.50", "0.000"], ["70602.70", "0.193"], ["70604.00", "0.136"], ["70605.80", "0.067"], ["70611.20", "0.003"], ["70612.30", "0.015"], ["70612.80", "2.583"]], "a": [["70612.90", "8.241"], ["70613.40", "0.004"], ["70613.60", "0.009"], ["70617.90", "0.081"], ["70618.10", "0.007"], ["70618.50", "0.369"], ["70618.70", "0.018"], ["70618.90", "0.359"], ["70619.30", "0.000"], ["70619.60", "0.658"], ["70619.80", "0.004"], ["70619.90", "0.029"], ["70620.00", "0.887"], ["70620.10", "0.001"], ["70620.30", "0.008"], ["70620.40", "0.008"], ["70620.50", "0.038"], ["70645.80", "0.457"], ["70646.10", "0.000"], ["70646.30", "0.036"], ["70646.50", "0.002"], ["70646.80", "0.293"], ["70647.20", "0.004"], ["70647.40", "0.038"], ["70648.10", "0.276"], ["70648.50", "0.008"], ["70650.70", "0.090"], ["70651.40", "0.000"], ["70672.70", "0.002"], ["70673.00", "0.002"], ["70673.40", "0.001"], ["70673.70", "0.003"], ["70673.90", "0.000"], ["70674.10", "0.511"], ["70674.30", "0.036"], ["70675.00", "0.701"], ["70675.70", "0.002"], ["70677.00", "0.262"], ["70681.40", "0.000"], ["70682.30", "1.009"], ["70701.40", "0.003"], ["70744.00", "0.007"], ["70782.90", "1.735"], ["70783.10", "0.020"], ["71319.00", "0.972"], ["71558.30", "0.000"], ["71637.60", "1.672"], ["73437.30", "0.000"], ["73437.40", "0.008"], ["74173.70", "0.057"], ["77674.20", "0.002"], ["89523.20", "0.000"]]}}
{"local_ts": 1773486808973, "server_ts": 1773486808944, "data": {"e": "depthUpdate", "E": 1773486808947, "T": 1773486808944, "s": "BTCUSDT", "U": 10109525766128, "u": 10109525769354, "pu": 10109525766017, "b": [["1000.00", "26.292"], ["5000.00", "101.418"], ["7061.30", "0.000"], ["20312.80", "1.550"], ["20412.80", "1.450"], ["56490.00", "0.000"], ["56491.00", "0.000"], ["63551.50", "0.000"], ["67076.10", "0.002"], ["69496.10", "0.616"], ["69852.20", "1.057"], ["69906.70", "0.000"], ["70259.70", "0.000"], ["70291.50", "0.106"], ["70292.20", "0.000"], ["70292.30", "0.003"], ["70292.40", "0.016"], ["70404.10", "0.000"], ["70439.50", "0.000"], ["70440.90", "0.418"], ["70478.40", "0.000"], ["70523.20", "0.000"], ["70556.40", "0.006"], ["70566.90", "0.000"], ["70577.50", "0.002"], ["70592.70", "0.006"], ["70594.90", "0.010"], ["70595.50", "0.132"], ["70596.20", "0.523"], ["70596.30", "0.000"], ["70602.00", "0.195"], ["70602.30", "0.420"], ["70603.90", "0.015"], ["70604.30", "0.002"], ["70604.40", "0.024"], ["70604.90", "0.010"], ["70605.50", "0.022"], ["70605.70", "0.198"], ["70607.10", "0.019"], ["70608.00", "0.016"], ["70610.00", "0.015"], ["70610.20", "0.057"], ["70611.20", "0.005"], ["70612.30", "0.021"], ["70612.70", "0.020"], ["70612.80", "2.542"]], "a": [["70612.90", "8.289"], ["70613.10", "0.000"], ["70613.40", "0.002"], ["70614.90", "0.000"], ["70615.10", "0.021"], ["70615.20", "0.002"], ["70616.00", "0.019"], ["70617.00", "0.000"], ["70617.20", "0.015"], ["70618.40", "0.009"], ["70618.70", "0.036"], ["70622.40", "0.007"], ["70623.00", "0.919"], ["70633.40", "0.554"], ["70635.30", "0.025"], ["70642.20", "0.070"], ["70644.00", "0.846"], ["70648.20", "0.895"], ["70651.00", "0.145"], ["70744.00", "0.007"], ["70780.70", "0.330"], ["70782.90", "0.008"], ["70797.80", "0.002"], ["70821.70", "0.000"], ["71319.00", "2.372"], ["74166.50", "0.052"], ["77674.20", "0.000"], ["89523.20", "0.000"]]}}
{"local_ts": 1773486809994, "server_ts": 1773486809964, "data": {"e": "depthUpdate", "E": 1773486809967, "T": 1773486809964, "s": "BTCUSDT", "U": 10109525802026, "u": 10109525805149, "pu": 10109525801995, "b": [["1000.00", "26.292"], ["5000.00", "101.418"], ["7061.30", "0.000"], ["20212.80", "1.100"], ["20312.80", "1.900"], ["56490.00", "0.000"], ["63551.50", "0.000"], ["67076.00", "0.000"], ["67082.20", "0.008"], ["67082.90", "0.007"], ["67083.00", "0.004"], ["69030.00", "0.155"], ["69201.50", "0.004"], ["69852.30", "0.007"], ["69906.70", "0.000"], ["70300.00", "21.888"], ["70478.50", "9.436"], ["70523.20", "0.002"], ["70566.00", "0.322"], ["70566.10", "1.069"], ["70581.10", "0.238"], ["70581.20", "0.272"], ["70588.60", "0.247"], ["70590.20", "0.000"], ["70593.70", "1.023"], ["70594.30", "0.214"], ["70595.10", "0.014"], ["70595.70", "0.012"], ["70597.90", "0.015"], ["70598.40", "0.028"], ["70602.30", "0.420"], ["70605.00", "0.059"], ["70605.40", "0.464"], ["70611.20", "0.003"], ["70612.60", "0.000"]], "a": [["70612.90", "7.982"], ["70619.00", "8.963"], ["70630.60", "0.152"], ["70637.70", "0.540"], ["70639.70", "0.003"], ["70641.80", "0.070"], ["70643.40", "0.000"], ["70644.60", "0.249"], ["70646.80", "0.046"], ["70705.80", "0.212"], ["70744.10", "0.489"], ["70749.00", "0.212"], ["70764.40", "0.018"], ["70766.00", "0.000"], ["70797.80", "0.000"], ["70800.90", "0.019"], ["70836.70", "0.000"], ["70837.00", "0.045"], ["71318.90", "0.000"], ["71319.00", "2.372"], ["77674.20", "0.000"], ["89523.20", "0.000"]]}}
{"local_ts": 1773486811016, "server_ts": 1773486810984, "data": {"e": "depthUpdate", "E": 1773486810987, "T": 1773486810984, "s": "BTCUSDT", "U": 10109525842635, "u": 10109525846171, "pu": 10109525842591, "b": [["5000.00", "101.418"], ["7061.30", "0.000"], ["20112.80", "0.650"], ["20212.80", "2.350"], ["20312.80", "0.000"], ["33000.00", "3.785"], ["63551.50", "0.000"], ["67066.10", "0.002"], ["67082.10", "0.005"], ["69201.40", "0.000"], ["69545.10", "1.007"], ["69906.70", "0.000"], ["69942.00", "1.092"], ["70259.70", "0.106"], ["70366.30", "0.002"], ["70478.50", "8.755"], ["70559.80", "0.601"], ["70566.30", "0.017"], ["70566.60", "0.143"], ["70566.90", "0.139"], ["70581.20", "0.272"], ["70581.30", "0.160"], ["70584.60", "0.288"], ["70595.10", "0.000"], ["70596.60", "0.012"], ["70600.80", "0.004"], ["70601.10", "0.012"], ["70602.20", "0.313"], ["70604.00", "0.136"], ["70605.70", "0.082"], ["70611.40", "0.005"], ["70612.80", "2.921"]], "a": [["70612.90", "7.629"], ["70614.70", "0.000"], ["70615.00", "0.064"], ["70615.10", "0.023"], ["70615.60", "0.017"], ["70616.10", "0.032"], ["70630.10", "0.025"], ["70676.50", "0.063"], ["70744.10", "0.172"], ["70796.10", "0.002"], ["70800.90", "0.017"], ["70836.80", "0.007"], ["71319.00", "2.372"], ["71869.70", "0.015"], ["71989.90", "0.628"], ["72025.90", "0.004"], ["73437.40", "0.014"], ["74148.20", "0.006"], ["77674.20", "0.000"]]}}
{"local_ts": 1773486812036, "server_ts": 1773486812008, "data": {"e": "depthUpdate", "E": 1773486812009, "T": 1773486812008, "s": "BTCUSDT", "U": 10109525877227, "u": 10109525881723, "pu": 10109525877217, "b": [["1000.00", "26.292"], ["5000.00", "101.418"], ["7061.30", "0.056"], ["20112.80", "2.580"], ["20212.80", "0.110"], ["20512.80", "0.310"], ["63551.50", "0.000"], ["69343.80", "0.000"], ["69447.70", "0.175"], ["69598.00", "6.962"], ["69906.70", "0.000"], ["69908.80", "1.438"], ["70050.10", "0.057"], ["70189.00", "6.721"], ["70259.70", "0.000"], ["70295.00", "0.106"], ["70501.20", "0.000"], ["70502.80", "0.840"], ["70505.40", "0.000"], ["70510.10", "3.580"], ["70535.10", "0.003"], ["70549.20", "0.001"], ["70566.50", "0.004"], ["70566.60", "0.145"], ["70572.10", "0.098"], ["70581.90", "0.407"], ["70582.00", "0.892"], ["70583.30", "0.366"], ["70587.20", "0.021"], ["70604.50", "0.021"], ["70605.80", "0.084"], ["70606.10", "0.019"], ["70606.40", "0.001"], ["70606.60", "0.002"], ["70607.10", "0.004"], ["70607.20", "0.000"], ["70608.30", "0.002"], ["70608.40", "0.005"], ["70608.80", "0.057"], ["70609.80", "0.013"], ["70610.20", "0.000"], ["70611.30", "0.000"], ["70612.00", "0.098"], ["70612.20", "0.021"]], "a": [["70612.90", "8.042"], ["70614.20", "0.000"], ["70615.00", "0.043"], ["70615.10", "0.021"], ["70615.60", "0.019"], ["70617.20", "0.000"], ["70618.00", "0.085"], ["70620.00", "0.527"], ["70633.40", "0.043"], ["70635.30", "0.025"], ["70676.50", "0.060"], ["70690.60", "0.030"], ["70771.80", "0.161"], ["70794.80", "0.002"], ["70796.10", "0.000"], ["70857.50", "35.253"], ["70935.20", "4.686"], ["71180.00", "1.750"], ["71319.00", "2.372"], ["71636.80", "2.789"], ["73437.40", "0.016"], ["74161.00", "0.052"], ["77674.20", "0.000"]]}}
{"local_ts": 1773486813062, "server_ts": 1773486813028, "data": {"e": "depthUpdate", "E": 1773486813031, "T": 1773486813028, "s": "BTCUSDT", "U": 10109525917717, "u": 10109525921132, "pu": 10109525917649, "b": [["5000.00", "101.398"], ["7061.30", "0.056"], ["20112.80", "0.400"], ["20412.80", "0.160"], ["20512.80", "2.440"], ["33000.00", "3.789"], ["56490.00", "0.004"], ["63551.50", "0.000"], ["68495.20", "0.000"], ["69685.40", "69.434"], ["69895.10", "57.743"], ["70056.20", "47.331"], ["70540.70", "0.002"], ["70547.70", "0.072"], ["70584.50", "0.927"], ["70597.40", "0.155"], ["70598.50", "0.617"], ["70598.60", "0.593"], ["70599.40", "0.010"], ["70600.10", "0.003"], ["70600.80", "0.285"], ["70601.50", "0.075"], ["70601.60", "0.000"], ["70606.40", "0.008"], ["70607.20", "0.000"]], "a": [["70612.90", "7.330"], ["70613.00", "0.112"], ["70615.60", "0.002"], ["70617.60", "0.009"], ["70617.70", "0.021"], ["70618.10", "0.011"], ["70620.80", "0.036"], ["70647.60", "0.046"], ["70674.50", "0.895"], ["70678.20", "0.174"], ["70794.80", "0.000"], ["70836.80", "0.000"], ["70837.10", "0.000"], ["71000.00", "26.680"], ["71283.60", "0.019"], ["71318.90", "0.007"], ["71319.00", "3.772"], ["71336.30", "56.429"], ["71550.30", "78.536"], ["72732.10", "0.009"], ["73437.40", "0.020"], ["74145.40", "0.000"], ["77674.20", "0.000"]]}}
{"local_ts": 1773486814082, "server_ts": 1773486814052, "data": {"e": "depthUpdate", "E": 1773486814053, "T": 1773486814052, "s": "BTCUSDT", "U": 10109525962367, "u": 10109525966433, "pu": 10109525962317, "b": [["1000.00", "26.292"], ["5000.00", "101.418"], ["7061.30", "0.056"], ["20312.80", "0.010"], ["20412.80", "2.300"], ["20512.80", "0.690"], ["67082.10", "0.005"], ["68494.50", "0.009"], ["69483.00", "2.012"], ["69588.90", "5.981"], ["69836.10", "2.002"], ["69906.70", "0.000"], ["70259.70", "0.000"], ["70566.30", "0.017"], ["70566.70", "0.850"], ["70583.30", "0.366"], ["70584.50", "0.980"], ["70598.60", "0.540"], ["70600.00", "0.125"], ["70605.80", "0.072"], ["70607.30", "0.023"], ["70607.60", "0.003"], ["70608.20", "0.014"], ["70609.10", "0.003"], ["70612.80", "2.357"]], "a": [["70612.90", "7.631"], ["70617.70", "0.004"], ["70621.20", "0.047"], ["70621.40", "0.000"], ["70624.40", "0.004"], ["70764.70", "0.159"], ["70837.30", "0.000"], ["70968.00", "0.096"], ["71319.00", "3.772"], ["71601.40", "0.200"], ["71636.80", "3.416"], ["72731.20", "0.006"], ["74162.10", "0.002"]]}}
{"local_ts": 1773486815103, "server_ts": 1773486815072, "data": {"e": "depthUpdate", "E": 1773486815075, "T": 1773486815072, "s": "BTCUSDT", "U": 10109525999352, "u": 10109526004235, "pu": 10109525999339, "b": [["1000.00", "26.292"], ["5000.00", "101.418"], ["7061.30", "0.028"], ["20312.80", "1.870"], ["20412.80", "1.130"], ["69199.90", "0.002"], ["69200.60", "0.030"], ["69204.20", "0.379"], ["69278.30", "0.000"], ["69282.60", "0.379"], ["69356.80", "0.000"], ["69361.10", "0.379"], ["69435.20", "0.000"], ["69439.60", "0.379"], ["69513.70", "0.000"], ["69518.00", "0.385"], ["69520.50", "4.669"], ["69591.10", "5.741"], ["69592.10", "0.000"], ["69596.50", "0.379"], ["69670.60", "0.000"], ["69674.90", "0.379"], ["69749.10", "0.057"], ["69753.40", "0.492"], ["69827.50", "0.007"], ["69831.90", "0.429"], ["69906.00", "0.007"], ["69906.70", "0.000"], ["69910.30", "0.379"], ["70047.90", "0.142"], ["70539.90", "0.070"], ["70542.30", "0.000"], ["70566.50", "0.004"], ["70566.60", "0.145"], ["70595.00", "0.436"], ["70595.70", "1.215"], ["70595.80", "0.511"], ["70596.30", "0.184"], ["70596.60", "0.005"], ["70597.00", "0.183"], ["70598.20", "0.004"], ["70598.60", "0.591"], ["70598.90", "0.141"], ["70599.60", "0.459"], ["70599.70", "0.017"], ["70600.10", "0.010"], ["70601.00", "0.005"], ["70601.10", "0.006"], ["70602.20", "0.304"], ["70603.90", "0.637"], ["70605.00", "0.044"], ["70605.70", "0.307"], ["70605.90", "0.424"], ["70606.10", "0.012"], ["70606.90", "0.117"], ["70607.20", "0.000"], ["70608.00", "0.002"], ["70608.30", "0.004"], ["70611.30", "0.003"], ["70612.30", "0.011"], ["70612.50", "0.217"]], "a": [["70612.90", "6.075"], ["70615.50", "0.281"], ["70615.90", "0.060"], ["70616.40", "0.198"], ["70617.70", "0.004"], ["70617.80", "0.063"], ["70618.10", "0.003"], ["70618.90", "0.355"], ["70619.80", "0.061"], ["70619.90", "0.681"], ["70620.00", "0.174"], ["70621.30", "0.036"], ["70621.60", "0.021"], ["70622.80", "0.000"], ["70623.50", "0.021"], ["70623.60", "0.004"], ["70623.80", "0.108"], ["70624.40", "0.002"], ["70625.50", "0.029"], ["70627.50", "0.288"], ["70640.40", "1.483"], ["70642.20", "0.070"], ["70643.10", "0.056"], ["70645.10", "0.000"], ["70647.10", "0.511"], ["70648.80", "0.209"], ["70649.00", "0.042"], ["70649.90", "0.605"], ["70655.20", "0.004"], ["70658.30", "0.000"], ["70658.70", "0.063"], ["70659.40", "0.002"], ["70660.10", "0.049"], ["70666.20", "1.416"], ["70694.10", "0.117"], ["70703.60", "0.002"], ["70707.80", "0.000"], ["70709.90", "0.547"], ["71318.20", "0.000"], ["71319.00", "3.772"], ["71322.70", "0.379"], ["71396.70", "0.000"], ["71401.10", "0.381"], ["71475.10", "0.000"], ["71479.60", "0.379"], ["71553.60", "0.000"], ["71558.10", "0.379"], ["71632.10", "0.004"], ["71636.50", "0.379"], ["71710.50", "0.009"], ["71715.00", "0.440"], ["71780.20", "2.527"], ["71789.00", "0.015"], ["71793.40", "0.380"], ["71867.40", "0.000"], ["71945.90", "0.000"], ["72024.30", "1.136"], ["74144.50", "0.050"], ["74166.50", "0.054"]]}}
{"local_ts": 1773486816128, "server_ts": 1773486816098, "data": {"e": "depthUpdate", "E": 1773486816099, "T": 1773486816098, "s": "BTCUSDT", "U": 10109526054188, "u": 10109526060684, "pu": 10109526054177, "b": [["5000.00", "101.418"], ["7061.30", "0.028"], ["20212.80", "1.430"], ["20312.80", "1.570"], ["56490.00", "0.004"], ["67053.00", "0.004"], ["67056.30", "0.000"], ["67788.30", "0.030"], ["69906.70", "1.437"], ["70366.40", "0.004"], ["70519.90", "0.426"], ["70558.70", "0.000"], ["70561.00", "0.175"], ["70561.10", "0.044"], ["70566.90", "0.000"], ["70567.30", "0.095"], ["70568.30", "0.014"], ["70569.00", "0.012"], ["70569.10", "0.007"], ["70574.00", "0.315"], ["70576.90", "0.009"], ["70577.00", "0.029"], ["70581.10", "0.153"], ["70583.00", "0.826"], ["70583.10", "0.165"], ["70583.40", "0.005"], ["70583.60", "0.328"], ["70583.70", "0.009"], ["70583.80", "0.014"], ["70584.40", "0.006"], ["70584.50", "0.901"], ["70585.00", "0.010"], ["70585.10", "0.000"], ["70585.20", "0.007"], ["70585.80", "0.082"], ["70585.90", "0.002"], ["70586.50", "0.008"], ["70586.60", "0.000"], ["70587.20", "0.002"], ["70587.30", "0.008"], ["70588.20", "0.001"], ["70590.30", "0.063"], ["70591.40", "0.002"], ["70592.10", "0.362"], ["70592.90", "0.005"], ["70593.00", "0.011"], ["70593.50", "0.000"], ["70593.60", "0.557"], ["70594.80", "0.213"], ["70595.30", "0.035"], ["70600.10", "0.010"], ["70600.20", "0.002"], ["70600.40", "0.000"], ["70601.00", "0.002"], ["70601.30", "0.344"], ["70601.70", "0.475"], ["70602.00", "0.199"], ["70602.30", "0.021"], ["70602.50", "0.000"], ["70603.00", "0.264"], ["70603.20", "0.045"], ["70603.80", "0.533"], ["70604.00", "0.164"], ["70604.40", "0.003"], ["70604.60", "0.002"], ["70604.70", "0.001"], ["70604.90", "0.010"], ["70605.00", "0.017"], ["70605.10", "0.004"], ["70605.50", "0.007"], ["70605.60", "0.007"], ["70605.80", "0.079"], ["70605.90", "0.426"], ["70606.00", "0.516"], ["70606.10", "0.186"], ["70606.20", "0.005"], ["70606.30", "0.187"], ["70606.50", "0.000"], ["70606.60", "0.009"], ["70606.70", "0.012"], ["70606.80", "0.125"], ["70606.90", "0.010"], ["70607.20", "0.181"], ["70607.50", "0.015"], ["70607.70", "0.015"], ["70607.80", "0.015"], ["70607.90", "0.010"], ["70608.00", "0.006"], ["70608.10", "0.003"], ["70608.20", "0.866"], ["70608.30", "0.011"], ["70608.40", "0.005"], ["70608.50", "1.067"], ["70608.60", "0.854"], ["70608.90", "0.028"], ["70609.40", "0.600"], ["70609.50", "0.375"], ["70610.30", "0.055"], ["70610.60", "0.000"], ["70611.00", "0.013"], ["70611.30", "0.007"], ["70611.90", "0.000"], ["70612.60", "0.225"], ["70612.80", "4.023"]], "a": [["70612.90", "2.865"], ["70615.60", "0.000"], ["70616.30", "0.028"], ["70616.40", "0.004"], ["70617.80", "0.059"], ["70617.90", "0.083"], ["70618.00", "0.075"], ["70618.50", "0.004"], ["70618.70", "0.003"], ["70619.00", "0.004"], ["70620.00", "0.174"], ["70620.90", "0.114"], ["70621.20", "0.015"], ["70621.40", "0.003"], ["70621.90", "0.003"], ["70622.50", "0.011"], ["70623.40", "1.604"], ["70625.60", "0.979"], ["70625.70", "0.000"], ["70625.80", "0.017"], ["70626.30", "0.007"], ["70626.40", "0.003"], ["70626.80", "0.006"], ["70627.30", "0.001"], ["70627.50", "0.012"], ["70627.60", "0.000"], ["70627.70", "0.030"], ["70628.60", "0.280"], ["70628.70", "0.005"], ["70628.90", "0.015"], ["70629.20", "0.023"], ["70629.40", "0.007"], ["70630.10", "0.025"], ["70630.50", "0.023"], ["70630.70", "0.002"], ["70630.80", "0.517"], ["70631.00", "0.062"], ["70631.90", "0.148"], ["70632.20", "0.000"], ["70632.90", "0.007"], ["70634.10", "0.000"], ["70634.50", "0.008"], ["70635.10", "0.007"], ["70635.70", "1.241"], ["70636.60", "0.002"], ["70637.10", "0.204"], ["70637.90", "0.175"], ["70639.00", "0.028"], ["70639.70", "0.000"], ["70639.80", "0.002"], ["70639.90", "0.134"], ["70640.50", "0.021"], ["70640.60", "0.000"], ["70641.20", "0.123"], ["70641.30", "0.009"], ["70641.90", "0.011"], ["70642.00", "0.006"], ["70642.60", "0.002"], ["70642.70", "0.018"], ["70643.30", "0.007"], ["70643.40", "0.002"], ["70644.00", "0.846"], ["70644.10", "0.526"], ["70644.70", "0.327"], ["70644.80", "0.002"], ["70645.00", "0.002"], ["70645.60", "0.008"], ["70647.10", "0.511"], ["70647.30", "0.147"], ["70650.10", "0.004"], ["70650.20", "0.057"], ["70651.10", "0.061"], ["70651.30", "0.003"], ["70652.10", "2.009"], ["70658.30", "0.048"], ["70659.10", "0.007"], ["70659.20", "0.018"], ["70662.20", "0.080"], ["70667.10", "0.036"], ["70667.20", "0.000"], ["70675.20", "0.063"], ["70676.50", "0.009"], ["70683.10", "0.533"], ["70683.20", "0.002"], ["70689.70", "0.145"], ["70691.20", "0.005"], ["70696.80", "0.202"], ["70703.60", "0.002"], ["70705.80", "0.214"], ["70712.50", "6.535"], ["70764.70", "0.099"], ["70768.20", "0.469"], ["70837.30", "0.000"], ["70849.50", "0.000"], ["70853.00", "0.106"], ["70897.00", "0.007"], ["71318.90", "0.000"], ["71319.00", "3.772"], ["71636.80", "9.132"], ["71643.10", "0.976"], ["71726.40", "0.439"], ["72039.90", "1.666"]]}}
{"local_ts": 1773486817148, "server_ts": 1773486817120, "data": {"e": "depthUpdate", "E": 1773486817121, "T": 1773486817120, "s": "BTCUSDT", "U": 10109526142221, "u": 10109526146689, "pu": 10109526142086, "b": [["1000.00", "26.292"], ["5000.00", "101.418"], ["7061.30", "0.028"], ["20112.80", "0.980"], ["20212.80", "2.020"], ["67788.30", "0.032"], ["69739.20", "0.572"], ["69906.70", "2.863"], ["70259.70", "0.000"], ["70565.90", "0.002"], ["70566.10", "1.071"], ["70584.90", "0.087"], ["70585.00", "0.010"], ["70599.30", "0.000"], ["70600.10", "0.003"], ["70601.30", "0.351"], ["70602.30", "0.023"], ["70604.00", "0.136"], ["70606.50", "1.037"], ["70609.30", "0.282"], ["70609.40", "0.186"], ["70610.00", "0.346"]], "a": [["70618.20", "0.132"], ["70618.50", "0.000"], ["70619.00", "0.008"], ["70631.00", "0.026"], ["70681.70", "0.009"], ["70837.00", "0.045"], ["71318.90", "0.000"], ["71696.30", "1.392"], ["71709.50", "0.000"], ["71848.60", "3.358"], ["74146.70", "0.002"], ["74178.70", "0.002"]]}}
{"local_ts": 1773486818168, "server_ts": 1773486818139, "data": {"e": "depthUpdate", "E": 1773486818141, "T": 1773486818139, "s": "BTCUSDT", "U": 10109526185781, "u": 10109526190360, "pu": 10109526185709, "b": [["5000.00", "101.418"], ["7061.30", "0.000"], ["20112.80", "2.470"], ["20212.80", "0.000"], ["20512.80", "0.530"], ["56490.00", "0.000"], ["67061.00", "0.009"], ["69906.70", "2.863"], ["70236.00", "0.345"], ["70550.90", "0.050"], ["70551.90", "0.223"], ["70593.70", "0.534"], ["70594.40", "0.000"], ["70596.10", "1.415"], ["70600.10", "0.003"], ["70605.60", "0.230"], ["70606.10", "0.229"], ["70612.80", "4.037"]], "a": [["70615.40", "0.251"], ["70618.50", "0.004"], ["70619.00", "0.006"], ["70621.20", "0.012"], ["70623.30", "0.023"], ["70623.50", "0.003"], ["70625.20", "0.105"], ["70625.70", "0.108"], ["70631.10", "0.084"], ["70652.60", "0.132"], ["70652.80", "0.555"], ["70669.30", "0.089"], ["70679.40", "1.779"], ["70680.40", "0.064"], ["70771.80", "0.161"], ["71319.00", "5.172"], ["71323.20", "0.000"], ["74153.40", "0.002"]]}}
{"local_ts": 1773486819190, "server_ts": 1773486819160, "data": {"e": "depthUpdate", "E": 1773486819161, "T": 1773486819160, "s": "BTCUSDT", "U": 10109526233877, "u": 10109526239707, "pu": 10109526233621, "b": [["1000.00", "26.292"], ["5000.00", "101.438"], ["7061.30", "0.000"], ["20112.80", "0.180"], ["20412.80", "0.270"], ["20512.80", "2.550"], ["69610.10", "10.397"], ["69906.70", "2.863"], ["70259.70", "0.000"], ["70579.50", "0.042"], ["70588.20", "0.043"], ["70606.60", "0.009"]], "a": [["70618.70", "0.007"], ["70618.80", "0.058"], ["70626.60", "0.237"], ["70628.50", "0.000"], ["70630.00", "0.918"], ["70640.20", "0.003"], ["70720.30", "0.137"], ["70836.50", "0.007"], ["70837.10", "0.000"], ["71318.90", "0.000"], ["74165.50", "0.052"]]}}
{"local_ts": 1773486820215, "server_ts": 1773486820184, "data": {"e": "depthUpdate", "E": 1773486820185, "T": 1773486820184, "s": "BTCUSDT", "U": 10109526281473, "u": 10109526287051, "pu": 10109526281354, "b": [["1000.00", "26.292"], ["5000.00", "101.418"], ["7061.30", "0.000"], ["20312.80", "0.120"], ["20412.80", "2.400"], ["20512.80", "0.480"], ["33000.00", "3.785"], ["67064.10", "0.000"], ["68830.30", "2.611"], ["69906.70", "2.863"], ["70566.30", "0.017"], ["70566.60", "0.002"], ["70584.60", "0.709"], ["70600.70", "0.000"], ["70602.90", "0.077"], ["70605.80", "0.180"], ["70606.10", "0.229"], ["70609.40", "0.359"]], "a": [["70616.40", "0.140"], ["70617.80", "0.059"], ["70618.20", "0.104"], ["70619.00", "0.006"], ["70619.90", "0.003"], ["70630.00", "0.663"], ["70636.00", "0.000"], ["70636.30", "0.059"], ["70641.80", "0.000"], ["70647.00", "0.003"], ["70647.80", "0.181"], ["70678.20", "0.174"], ["70681.70", "0.009"], ["70708.00", "0.029"], ["71319.00", "5.174"], ["71729.60", "0.597"], ["74151.50", "0.057"]]}}
{"local_ts": 1773486821239, "server_ts": 1773486821205, "data": {"e": "depthUpdate", "E": 1773486821207, "T": 1773486821205, "s": "BTCUSDT", "U": 10109526333834, "u": 10109526338462, "pu": 10109526333796, "b": [["5000.00", "101.418"], ["7061.30", "0.056"], ["20312.80", "2.200"], ["20412.80", "0.800"], ["67058.00", "0.006"], ["69906.70", "2.863"], ["70544.00", "0.048"], ["70559.80", "0.601"], ["70572.30", "0.000"], ["70580.10", "0.891"]], "a": [["70617.80", "0.065"], ["70619.00", "0.006"], ["70633.10", "0.024"], ["70771.80", "0.161"], ["70836.50", "0.000"], ["71318.90", "0.000"], ["71319.00", "5.172"], ["71687.70", "0.000"], ["71881.10", "0.021"], ["89523.20", "0.000"]]}}
{"local_ts": 1773486822257, "server_ts": 1773486822228, "data": {"e": "depthUpdate", "E": 1773486822229, "T": 1773486822228, "s": "BTCUSDT", "U": 10109526379184, "u": 10109526383578, "pu": 10109526379035, "b": [["1000.00", "26.292"], ["5000.00", "101.418"], ["7061.30", "0.056"], ["20212.80", "1.760"], ["20312.80", "1.240"], ["33000.00", "3.789"], ["69906.70", "2.863"], ["70259.70", "0.000"], ["70586.50", "0.093"], ["70586.60", "0.000"], ["70586.70", "0.004"], ["70605.80", "0.148"], ["70606.60", "0.009"], ["70608.90", "0.001"], ["70612.80", "4.562"]], "a": [["70616.00", "0.014"], ["70617.80", "0.061"], ["70618.50", "0.000"], ["70618.70", "0.007"], ["70619.90", "0.031"], ["70630.20", "0.215"], ["70705.80", "0.212"], ["71319.00", "5.172"], ["72731.20", "0.006"], ["74174.10", "0.000"], ["89523.20", "0.000"]]}}
{"local_ts": 1773486823285, "server_ts": 1773486823250, "data": {"e": "depthUpdate", "E": 1773486823251, "T": 1773486823250, "s": "BTCUSDT", "U": 10109526433147, "u": 10109526437648, "pu": 10109526433131, "b": [["5000.00", "101.418"], ["7061.30", "0.056"], ["20112.80", "1.310"], ["20212.80", "1.690"], ["67788.30", "1.298"], ["69906.70", "4.291"], ["70019.70", "0.004"], ["70366.70", "0.003"], ["70479.00", "0.807"], ["70520.80", "0.898"], ["70520.90", "0.205"], ["70527.80", "0.071"], ["70527.90", "0.823"], ["70534.90", "0.073"], ["70535.00", "0.000"], ["70554.10", "0.045"], ["70590.70", "0.118"], ["70604.70", "0.024"], ["70605.10", "0.004"], ["70608.20", "0.640"], ["70608.70", "0.076"], ["70608.80", "0.186"], ["70609.20", "0.211"], ["70609.40", "0.356"], ["70609.50", "0.191"], ["70612.80", "4.562"]], "a": [["70629.30", "0.021"], ["70631.50", "0.049"], ["70633.70", "0.004"], ["70647.80", "0.111"], ["70648.60", "0.074"], ["70652.10", "0.000"], ["70658.50", "0.025"], ["70678.20", "0.202"], ["70685.60", "1.845"], ["70697.50", "0.095"], ["70704.60", "0.446"], ["70711.60", "0.071"], ["70751.50", "0.437"], ["71319.00", "5.172"], ["71458.40", "0.558"], ["74144.50", "0.052"], ["89523.20", "0.000"]]}}
{"local_ts": 1773486824301, "server_ts": 1773486824272, "data": {"e": "depthUpdate", "E": 1773486824273, "T": 1773486824272, "s": "BTCUSDT", "U": 10109526479768, "u": 10109526484205, "pu": 10109526479585, "b": [["1000.00", "26.292"], ["5000.00", "101.418"], ["7061.30", "0.028"], ["20112.80", "2.130"], ["20512.80", "0.870"], ["67082.00", "0.044"], ["69906.70", "4.434"], ["70259.70", "0.036"], ["70599.50", "0.133"], ["70600.40", "0.000"]], "a": [["70618.20", "0.104"], ["70619.00", "0.010"], ["70629.30", "0.000"], ["70629.50", "0.026"], ["70637.20", "0.004"], ["70637.30", "0.068"], ["70644.50", "0.652"], ["70645.30", "0.026"], ["70645.40", "0.509"], ["70665.70", "0.059"], ["70962.70", "0.231"], ["70966.00", "1.323"], ["71319.00", "5.172"], ["71806.30", "0.278"], ["72731.20", "0.011"], ["73437.40", "0.046"], ["74166.20", "0.002"], ["74167.60", "0.000"], ["89523.20", "0.000"]]}}
{"local_ts": 1773486825335, "server_ts": 1773486825296, "data": {"e": "depthUpdate", "E": 1773486825297, "T": 1773486825296, "s": "BTCUSDT", "U": 10109526533662, "u": 10109526539215, "pu": 10109526533658, "b": [["1000.00", "26.292"], ["5000.00", "101.418"], ["7061.30", "0.028"], ["20112.80", "0.010"], ["20412.80", "0.440"], ["20512.80", "2.550"], ["67082.00", "0.044"], ["68494.60", "0.053"], ["69906.70", "4.434"], ["69906.80", "0.006"], ["70366.70", "0.003"], ["70520.60", "0.017"], ["70520.70", "0.011"], ["70527.60", "0.093"], ["70527.70", "0.000"], ["70534.70", "0.625"], ["70534.80", "0.024"], ["70541.80", "0.004"], ["70577.50", "0.002"], ["70584.60", "0.709"], ["70589.20", "0.013"], ["70590.20", "0.000"], ["70595.80", "0.421"], ["70596.00", "0.092"], ["70602.20", "0.002"], ["70603.50", "0.062"], ["70605.20", "0.402"], ["70605.80", "0.038"], ["70606.10", "0.002"], ["70608.70", "0.315"], ["70609.30", "0.404"], ["70609.80", "0.023"], ["70610.60", "0.514"], ["70612.80", "5.399"]], "a": [["70612.90", "0.966"], ["70615.50", "0.025"], ["70616.40", "0.004"], ["70617.80", "0.061"], ["70618.10", "0.003"], ["70618.20", "0.000"], ["70618.50", "0.000"], ["70618.80", "0.062"], ["70619.00", "0.025"], ["70619.90", "0.001"], ["70621.00", "0.002"], ["70624.80", "0.004"], ["70625.80", "0.654"], ["70632.10", "0.102"], ["70634.10", "0.000"], ["70634.30", "0.009"], ["70635.70", "0.009"], ["70636.50", "0.011"], ["70648.20", "0.840"], ["70676.50", "0.141"], ["70679.50", "0.568"], ["70680.00", "2.772"], ["70681.70", "0.141"], ["70697.20", "0.075"], ["70697.30", "1.945"], ["70704.30", "0.087"], ["70704.40", "0.000"], ["70711.30", "0.204"], ["70711.40", "0.090"], ["71319.00", "5.872"], ["72025.10", "0.015"], ["74147.70", "0.002"], ["89523.20", "0.000"]]}}
{"local_ts": 1773486826350, "server_ts": 1773486826316, "data": {"e": "depthUpdate", "E": 1773486826319, "T": 1773486826316, "s": "BTCUSDT", "U": 10109526587417, "u": 10109526591907, "pu": 10109526587361, "b": [["5000.00", "101.418"], ["7061.30", "0.028"], ["20312.80", "0.230"], ["20412.80", "2.520"], ["20512.80", "0.250"], ["67082.00", "0.044"], ["69906.70", "5.148"], ["70479.00", "0.255"], ["70483.80", "0.928"], ["70487.70", "0.217"], ["70566.50", "0.004"], ["70566.60", "0.004"], ["70586.60", "0.085"], ["70586.70", "0.004"], ["70596.00", "0.086"], ["70597.80", "0.004"], ["70605.20", "0.404"], ["70605.80", "0.104"], ["70605.90", "0.430"], ["70609.40", "0.175"], ["70609.50", "0.191"], ["70609.60", "0.187"], ["70609.80", "0.013"]], "a": [["70620.00", "0.176"], ["70660.10", "0.047"], ["70771.80", "0.161"], ["71319.00", "5.872"], ["71460.30", "2.514"], ["74147.70", "0.000"], ["89523.20", "0.000"]]}}
