{"local_ts": 1773486943827, "server_ts": 1773486943796, "data": {"e": "depthUpdate", "E": 1773486943797, "T": 1773486943796, "s": "BTCUSDT", "U": 10109532358350, "u": 10109532367685, "pu": 10109532358050, "b": [["1000.00", "26.892"], ["5000.00", "101.418"], ["7064.20", "0.000"], ["20141.50", "0.250"], ["20143.70", "0.020"], ["20243.70", "0.040"], ["20541.50", "0.120"], ["33000.00", "3.785"], ["69228.70", "0.003"], ["69871.90", "13.144"], ["69935.10", "0.002"], ["70288.50", "0.000"], ["70395.50", "0.008"], ["70434.60", "0.853"], ["70452.50", "0.517"], ["70492.50", "0.001"], ["70523.00", "6.720"], ["70538.10", "0.178"], ["70538.40", "0.005"], ["70549.60", "1.059"], ["70554.30", "0.000"], ["70571.50", "0.411"], ["70579.00", "0.123"], ["70579.10", "0.000"], ["70579.50", "0.028"], ["70585.10", "0.191"], ["70588.60", "0.184"], ["70590.30", "0.005"], ["70594.40", "0.005"], ["70595.70", "0.049"], ["70597.50", "0.020"], ["70598.00", "0.012"], ["70599.90", "0.085"], ["70600.00", "0.998"], ["70600.30", "0.129"], ["70600.50", "0.053"], ["70603.00", "0.001"], ["70604.80", "0.404"], ["70604.90", "0.069"], ["70606.20", "0.000"], ["70606.30", "0.119"], ["70609.10", "0.225"], ["70611.20", "0.518"], ["70611.60", "0.112"], ["70611.70", "0.175"], ["70611.80", "0.009"], ["70612.40", "0.008"], ["70612.50", "0.006"], ["70613.80", "0.516"], ["70613.90", "0.002"], ["70614.50", "0.003"], ["70614.60", "0.002"], ["70614.80", "0.002"], ["70615.00", "0.437"], ["70615.50", "0.571"], ["70615.70", "0.003"], ["70615.90", "0.005"], ["70616.00", "0.009"], ["70616.40", "0.000"], ["70616.60", "0.008"], ["70616.70", "0.002"], ["70616.90", "0.034"], ["70617.80", "0.008"], ["70618.10", "1.203"], ["70619.30", "0.118"], ["70619.50", "0.620"], ["70621.40", "0.001"], ["70623.10", "0.006"], ["70624.70", "0.002"], ["70625.10", "0.002"], ["70626.20", "0.013"], ["70626.50", "0.532"], ["70627.30", "0.640"], ["70627.40", "0.003"], ["70627.60", "0.317"], ["70627.90", "0.004"], ["70628.20", "0.002"], ["70629.70", "0.021"], ["70634.00", "0.004"], ["70634.70", "0.001"], ["70635.40", "0.001"], ["70636.20", "0.139"], ["70638.90", "0.003"], ["70639.30", "0.005"], ["70641.50", "0.296"]], "a": [["70641.60", "11.945"], ["70641.70", "0.231"], ["70641.80", "0.125"], ["70641.90", "0.052"], ["70643.20", "0.252"], ["70644.90", "0.001"], ["70645.10", "0.034"], ["70647.70", "0.037"], ["70648.00", "0.036"], ["70648.10", "0.137"], ["70648.30", "0.000"], ["70648.60", "0.097"], ["70648.80", "0.006"], ["70649.40", "0.001"], ["70649.80", "0.006"], ["70650.40", "0.141"], ["70651.00", "0.253"], ["70653.70", "0.000"], ["70653.80", "0.006"], ["70657.70", "0.082"], ["70660.80", "0.005"], ["70662.10", "1.149"], ["70663.30", "0.140"], ["70667.50", "1.077"], ["70668.70", "0.000"], ["70669.90", "0.452"], ["70672.00", "1.289"], ["70672.60", "0.000"], ["70673.40", "1.081"], ["70673.50", "0.520"], ["70674.10", "0.000"], ["70674.20", "0.000"], ["70674.30", "0.052"], ["70675.00", "0.671"], ["70675.50", "0.010"], ["70675.60", "0.086"], ["70676.20", "0.004"], ["70676.30", "0.002"], ["70677.60", "0.002"], ["70677.70", "0.004"], ["70678.10", "0.343"], ["70678.30", "0.000"], ["70678.40", "0.022"], ["70679.00", "0.192"], ["70682.70", "0.710"], ["70692.40", "0.017"], ["70693.10", "0.004"], ["70699.00", "0.201"], ["70707.00", "2.381"], ["70707.20", "0.593"], ["70766.10", "0.004"], ["70767.80", "0.010"], ["70862.10", "0.331"], ["71038.70", "0.044"], ["71159.40", "0.000"], ["71348.00", "0.004"], ["71350.70", "0.000"], ["71372.80", "0.007"], ["71567.60", "0.400"], ["71586.30", "1.539"], ["71749.00", "0.000"], ["71799.80", "0.258"], ["72013.30", "0.002"], ["74210.80", "0.000"], ["89523.20", "0.000"]]}}
{"local_ts": 1773486944845, "server_ts": 1773486944816, "data": {"e": "depthUpdate", "E": 1773486944817, "T": 1773486944816, "s": "BTCUSDT", "U": 10109532439181, "u": 10109532443436, "pu": 10109532438974, "b": [["1000.00", "26.892"], ["5000.00", "101.418"], ["7063.80", "0.056"], ["20141.60", "0.060"], ["20141.70", "0.000"], ["20538.00", "1.970"], ["56510.00", "0.020"], ["67103.90", "0.018"], ["69235.10", "0.002"], ["69238.00", "0.742"], ["69755.00", "0.326"], ["69931.60", "0.000"], ["70530.60", "0.072"], ["70542.90", "0.458"], ["70546.10", "2.114"], ["70548.20", "0.065"], ["70560.30", "0.143"], ["70566.00", "0.084"], ["70574.40", "0.211"], ["70580.10", "0.887"], ["70592.00", "0.274"], ["70592.20", "0.055"], ["70609.80", "0.024"], ["70611.70", "0.004"], ["70616.80", "0.007"], ["70621.40", "0.001"], ["70623.60", "0.292"], ["70626.70", "0.049"], ["70628.10", "0.000"], ["70629.50", "0.479"], ["70629.60", "0.007"], ["70630.60", "0.011"], ["70631.00", "0.034"], ["70632.60", "0.023"], ["70635.70", "0.003"], ["70635.80", "0.022"], ["70635.90", "0.007"], ["70636.80", "0.002"]], "a": [["70638.10", "9.639"], ["70638.30", "0.003"], ["70640.50", "0.231"], ["70641.60", "0.001"], ["70642.80", "0.009"], ["70643.20", "0.043"], ["70645.10", "0.067"], ["70645.60", "0.356"], ["70646.90", "0.003"], ["70648.50", "0.144"], ["70651.00", "0.110"], ["70653.20", "0.007"], ["70655.40", "1.071"], ["70655.50", "0.141"], ["70657.70", "0.513"], ["70659.30", "0.008"], ["70660.60", "0.002"], ["70660.80", "0.085"], ["70669.90", "0.207"], ["70671.10", "0.528"], ["70677.00", "0.119"], ["70689.40", "0.024"], ["70701.70", "0.003"], ["70707.40", "0.004"], ["70715.80", "0.003"], ["70721.50", "0.162"], ["70729.80", "0.000"], ["70747.20", "0.360"], ["70755.40", "0.005"], ["70791.50", "0.002"], ["70992.60", "0.026"], ["71000.40", "0.020"], ["71153.60", "0.004"], ["71344.50", "0.015"], ["71367.10", "0.004"], ["71580.50", "0.004"], ["71763.00", "0.029"], ["71794.00", "0.004"], ["72007.50", "0.004"], ["72199.70", "0.002"], ["72757.20", "0.000"], ["74191.20", "0.002"], ["89523.20", "0.000"]]}}
{"local_ts": 1773486945866, "server_ts": 1773486945838, "data": {"e": "depthUpdate", "E": 1773486945839, "T": 1773486945838, "s": "BTCUSDT", "U": 10109532489344, "u": 10109532495224, "pu": 10109532489143, "b": [["5000.00", "101.418"], ["7063.80", "0.056"], ["20438.00", "1.780"], ["20538.00", "1.220"], ["33000.00", "3.789"], ["63574.20", "0.002"], ["69790.30", "0.286"], ["69931.60", "0.000"], ["70593.20", "0.009"], ["70627.40", "0.002"], ["70635.20", "0.004"], ["70635.30", "0.002"]], "a": [["70638.10", "9.597"], ["70645.90", "0.002"], ["70648.70", "0.005"], ["71159.50", "0.000"], ["71203.20", "0.140"], ["71344.50", "0.015"], ["71372.90", "0.024"], ["71485.80", "0.289"], ["71519.10", "1.384"], ["71586.20", "0.697"], ["71586.40", "0.010"], ["71627.00", "0.059"], ["71674.40", "1.672"], ["71717.00", "0.504"], ["71799.90", "0.000"], ["72013.40", "0.000"], ["72114.80", "0.002"], ["74185.20", "0.005"], ["74198.90", "0.000"], ["77701.90", "0.002"], ["89523.20", "0.000"]]}}
{"local_ts": 1773486946888, "server_ts": 1773486946860, "data": {"e": "depthUpdate", "E": 1773486946861, "T": 1773486946860, "s": "BTCUSDT", "U": 10109532542234, "u": 10109532546388, "pu": 10109532542147, "b": [["1000.00", "26.892"], ["5000.00", "101.418"], ["7063.80", "0.056"], ["20338.00", "1.340"], ["20438.00", "1.660"], ["63574.20", "0.002"], ["67077.40", "0.020"], ["67812.50", "0.015"], ["68841.80", "0.000"], ["69719.80", "0.859"], ["69731.60", "0.000"], ["69931.60", "1.428"], ["69934.20", "0.000"], ["69966.90", "0.713"], ["70090.10", "0.000"], ["70259.70", "0.000"], ["70284.80", "0.568"], ["70391.90", "0.006"], ["70545.20", "0.964"], ["70566.80", "3.107"], ["70567.50", "0.084"], ["70599.30", "0.357"], ["70607.90", "0.010"], ["70608.20", "0.102"], ["70626.20", "1.375"], ["70627.40", "0.010"], ["70629.40", "0.001"], ["70630.10", "0.005"], ["70630.70", "0.003"], ["70631.00", "0.006"], ["70631.10", "0.006"], ["70632.40", "0.011"], ["70635.20", "0.014"], ["70635.70", "0.005"], ["70637.00", "0.009"], ["70637.10", "0.004"], ["70638.00", "2.987"]], "a": [["70638.10", "6.425"], ["70638.40", "0.080"], ["70640.50", "0.234"], ["70640.60", "0.000"], ["70641.90", "0.005"], ["70642.80", "0.002"], ["70645.80", "0.001"], ["70648.70", "0.008"], ["70650.30", "0.002"], ["70651.30", "0.003"], ["70653.20", "0.148"], ["70654.00", "0.025"], ["70662.50", "0.422"], ["70669.90", "0.147"], ["70677.00", "0.119"], ["70683.10", "0.017"], ["70683.90", "0.022"], ["70685.70", "0.051"], ["70694.60", "0.969"], ["70705.30", "0.002"], ["70800.60", "0.000"], ["70853.80", "10.002"], ["70861.20", "0.002"], ["70861.70", "0.326"], ["70966.00", "0.690"], ["70966.40", "0.018"], ["71203.20", "0.280"], ["71344.50", "1.415"], ["71824.80", "0.279"], ["77701.90", "0.002"]]}}
{"local_ts": 1773486947913, "server_ts": 1773486947883, "data": {"e": "depthUpdate", "E": 1773486947885, "T": 1773486947883, "s": "BTCUSDT", "U": 10109532581461, "u": 10109532585275, "pu": 10109532581365, "b": [["5000.00", "101.418"], ["7063.80", "0.028"], ["20238.00", "0.890"], ["20338.00", "2.110"], ["56510.00", "0.020"], ["63574.20", "0.002"], ["67085.20", "0.002"], ["69225.30", "0.021"], ["69931.60", "1.428"], ["70100.10", "0.499"], ["70222.10", "18.612"], ["70300.00", "21.639"], ["70319.40", "0.648"], ["70323.70", "0.106"], ["70599.30", "0.187"], ["70600.10", "0.358"], ["70605.20", "0.947"], ["70605.30", "0.664"], ["70613.70", "0.005"], ["70613.80", "0.562"], ["70615.60", "0.004"], ["70619.70", "0.518"], ["70622.20", "0.079"], ["70626.20", "0.734"], ["70627.40", "0.003"], ["70629.70", "0.000"], ["70630.60", "0.088"], ["70630.70", "0.003"], ["70633.00", "0.514"], ["70637.40", "0.023"], ["70638.00", "2.808"]], "a": [["70638.10", "4.657"], ["70640.20", "0.001"], ["70640.60", "0.000"], ["70641.10", "0.000"], ["70641.40", "0.007"], ["70646.80", "0.004"], ["70647.50", "0.164"], ["70647.80", "0.022"], ["70648.70", "0.008"], ["70650.80", "0.061"], ["70655.00", "0.027"], ["70656.80", "0.142"], ["70657.60", "0.718"], ["70658.70", "0.002"], ["70664.20", "0.002"], ["70664.40", "0.007"], ["70665.20", "0.642"], ["70665.60", "0.509"], ["70667.80", "0.000"], ["70669.50", "0.394"], ["70669.90", "0.147"], ["70671.90", "0.054"], ["70673.10", "0.294"], ["70677.00", "0.218"], ["70737.00", "2.257"], ["70861.20", "0.000"], ["70868.60", "0.002"], ["70889.50", "0.007"], ["70967.70", "0.652"], ["71059.80", "9.995"], ["71249.90", "0.003"], ["71344.40", "0.000"], ["71344.50", "1.415"], ["72056.00", "0.003"], ["77701.90", "0.002"]]}}
{"local_ts": 1773486948932, "server_ts": 1773486948904, "data": {"e": "depthUpdate", "E": 1773486948905, "T": 1773486948904, "s": "BTCUSDT", "U": 10109532618249, "u": 10109532621200, "pu": 10109532618218, "b": [["1000.00", "26.892"], ["5000.00", "101.418"], ["7063.80", "0.028"], ["20138.00", "0.460"], ["20238.00", "2.530"], ["20338.00", "0.010"], ["63574.20", "0.002"], ["67071.10", "0.002"], ["69931.60", "1.428"], ["70284.80", "0.710"], ["70476.00", "2.358"], ["70505.30", "1.202"], ["70539.00", "1.473"], ["70577.30", "3.705"], ["70577.40", "0.000"], ["70583.00", "0.655"], ["70592.80", "0.841"], ["70592.90", "0.026"], ["70599.30", "0.187"], ["70600.10", "0.004"], ["70600.90", "0.005"], ["70602.00", "0.360"], ["70629.00", "0.345"], ["70629.40", "0.001"], ["70630.40", "0.008"], ["70631.00", "0.034"], ["70633.40", "0.084"], ["70635.30", "0.002"], ["70638.00", "2.503"]], "a": [["70638.10", "4.765"], ["70645.40", "0.265"], ["70673.40", "1.229"], ["70685.70", "0.004"], ["70707.00", "2.097"], ["70707.10", "4.387"], ["70707.20", "0.039"], ["70772.70", "0.169"], ["70858.60", "0.004"], ["70868.60", "0.000"], ["71178.30", "0.002"], ["71344.50", "1.415"], ["71603.80", "1.810"], ["74200.30", "0.033"], ["77701.90", "0.002"]]}}
{"local_ts": 1773486949956, "server_ts": 1773486949928, "data": {"e": "depthUpdate", "E": 1773486949929, "T": 1773486949928, "s": "BTCUSDT", "U": 10109532656927, "u": 10109532660780, "pu": 10109532656818, "b": [["1000.00", "26.892"], ["5000.00", "101.418"], ["7063.80", "0.028"], ["20138.00", "2.530"], ["20238.00", "0.230"], ["20538.00", "0.240"], ["56510.00", "0.032"], ["63574.20", "0.002"], ["69931.60", "1.428"], ["70320.10", "0.106"], ["70475.30", "13.387"], ["70505.30", "1.213"], ["70530.60", "0.072"], ["70539.30", "7.152"], ["70542.90", "0.458"], ["70546.10", "2.114"], ["70548.20", "0.065"], ["70586.40", "0.046"], ["70593.00", "0.005"], ["70593.10", "0.031"], ["70600.10", "0.174"], ["70626.20", "0.541"], ["70626.50", "0.371"], ["70627.40", "0.003"], ["70630.10", "0.005"], ["70630.70", "0.003"], ["70635.30", "0.012"], ["70635.90", "0.004"], ["70638.00", "2.735"]], "a": [["70638.10", "4.445"], ["70641.50", "0.162"], ["70648.70", "0.008"], ["70650.10", "0.000"], ["70673.40", "1.070"], ["70743.40", "0.010"], ["70745.70", "7.011"], ["70770.60", "0.296"], ["70772.40", "0.182"], ["70809.50", "13.242"], ["70858.60", "0.002"], ["70859.20", "1.412"], ["71344.50", "1.415"], ["71489.60", "0.782"], ["72069.50", "1.662"], ["74198.90", "0.000"], ["74199.10", "0.002"], ["77701.90", "0.002"]]}}
{"local_ts": 1773486950980, "server_ts": 1773486950950, "data": {"e": "depthUpdate", "E": 1773486950951, "T": 1773486950950, "s": "BTCUSDT", "U": 10109532689989, "u": 10109532693094, "pu": 10109532689977, "b": [["5000.00", "101.418"], ["7063.80", "0.000"], ["20138.00", "0.530"], ["20438.00", "0.090"], ["20538.00", "2.380"], ["33000.00", "3.785"], ["40000.00", "41.317"], ["63574.20", "0.000"], ["67106.00", "0.000"], ["67106.20", "0.003"], ["69931.60", "1.428"], ["70505.30", "1.214"], ["70586.80", "0.149"], ["70599.30", "0.003"], ["70600.00", "0.948"], ["70600.10", "0.004"], ["70602.70", "0.014"], ["70603.90", "0.142"], ["70604.30", "0.013"], ["70604.40", "0.403"], ["70605.20", "0.663"], ["70605.40", "0.021"], ["70608.90", "0.354"], ["70613.90", "0.000"], ["70615.90", "0.144"], ["70616.60", "0.304"], ["70617.30", "0.007"], ["70618.20", "0.229"], ["70619.60", "1.204"], ["70620.10", "0.005"], ["70620.90", "0.000"], ["70621.60", "0.057"], ["70622.00", "0.518"], ["70622.90", "0.143"], ["70623.10", "0.006"], ["70623.60", "0.218"], ["70623.80", "0.082"], ["70624.10", "0.009"], ["70625.00", "0.169"], ["70625.40", "0.658"], ["70625.50", "0.057"], ["70625.70", "0.009"], ["70626.10", "0.002"], ["70626.70", "0.049"], ["70627.30", "0.010"], ["70627.40", "0.000"], ["70627.50", "0.012"], ["70627.90", "0.008"], ["70628.10", "0.011"], ["70628.40", "0.022"], ["70628.50", "0.113"], ["70629.20", "0.016"], ["70629.40", "0.001"], ["70629.50", "0.679"], ["70629.80", "0.017"], ["70629.90", "0.217"], ["70630.10", "0.012"], ["70630.80", "0.024"], ["70631.10", "0.008"], ["70631.70", "0.002"], ["70632.10", "0.011"], ["70635.30", "0.366"], ["70635.90", "0.004"], ["70638.00", "3.437"]], "a": [["70638.10", "3.320"], ["70642.50", "0.001"], ["70644.60", "0.214"], ["70645.60", "0.327"], ["70648.70", "0.005"], ["70649.40", "0.000"], ["70650.30", "0.005"], ["70650.80", "0.004"], ["70651.30", "0.003"], ["70651.40", "0.247"], ["70651.50", "0.003"], ["70652.20", "0.152"], ["70652.30", "0.000"], ["70652.70", "0.000"], ["70653.00", "0.002"], ["70653.30", "0.460"], ["70653.50", "0.004"], ["70653.60", "0.002"], ["70653.80", "0.013"], ["70653.90", "0.001"], ["70654.30", "0.003"], ["70654.60", "0.207"], ["70655.00", "0.006"], ["70656.10", "0.000"], ["70656.40", "0.001"], ["70656.80", "0.001"], ["70657.70", "0.002"], ["70657.90", "0.020"], ["70658.40", "0.165"], ["70658.70", "0.002"], ["70660.70", "0.002"], ["70661.60", "0.085"], ["70669.20", "0.227"], ["70673.40", "1.169"], ["70674.10", "0.000"], ["70674.40", "0.023"], ["70675.40", "0.016"], ["70677.00", "0.119"], ["70677.30", "0.003"], ["70679.40", "0.279"], ["70739.80", "0.107"], ["70772.10", "0.241"], ["70772.20", "0.019"], ["70797.00", "0.111"], ["70814.70", "0.259"], ["70859.20", "1.410"], ["71344.50", "1.417"], ["72379.70", "0.000"], ["72411.20", "0.032"], ["74183.40", "0.977"], ["77701.90", "0.000"], ["100000.00", "23.659"]]}}
{"local_ts": 1773486951999, "server_ts": 1773486951970, "data": {"e": "depthUpdate", "E": 1773486951971, "T": 1773486951970, "s": "BTCUSDT", "U": 10109532730245, "u": 10109532733598, "pu": 10109532730242, "b": [["1000.00", "26.892"], ["5000.00", "101.438"], ["7063.80", "0.000"], ["20438.00", "2.110"], ["20538.00", "0.890"], ["63574.20", "0.000"], ["69331.20", "1.113"], ["69931.60", "2.858"], ["70284.80", "0.746"], ["70445.80", "0.000"], ["70466.50", "0.000"], ["70467.50", "0.598"], ["70550.00", "0.956"], ["70577.30", "0.041"], ["70578.40", "4.721"], ["70578.90", "0.004"], ["70596.40", "0.843"], ["70599.00", "0.298"], ["70600.10", "0.188"], ["70602.90", "1.973"], ["70603.90", "0.312"], ["70604.00", "0.087"], ["70608.90", "0.000"], ["70627.40", "0.010"], ["70628.10", "0.011"], ["70630.30", "0.011"], ["70635.30", "0.012"], ["70635.90", "0.004"]], "a": [["70638.10", "5.740"], ["70648.70", "0.005"], ["70657.70", "0.004"], ["70659.60", "0.002"], ["70671.00", "0.020"], ["70673.40", "1.229"], ["70677.00", "0.119"], ["70682.80", "1.990"], ["70707.10", "0.513"], ["70707.20", "3.652"], ["70708.40", "0.092"], ["70728.00", "1.328"], ["70812.50", "0.002"], ["70814.70", "0.100"], ["70868.40", "0.760"], ["71344.50", "1.417"], ["74173.70", "0.055"], ["77701.90", "0.000"]]}}
{"local_ts": 1773486953020, "server_ts": 1773486952989, "data": {"e": "depthUpdate", "E": 1773486952991, "T": 1773486952989, "s": "BTCUSDT", "U": 10109532766572, "u": 10109532769404, "pu": 10109532766544, "b": [["5000.00", "101.418"], ["7063.80", "0.000"], ["20338.00", "1.660"], ["20438.00", "1.340"], ["33000.00", "3.789"], ["56510.00", "0.020"], ["63574.20", "0.000"], ["67102.50", "0.027"], ["69426.30", "0.000"], ["69931.60", "2.856"], ["70599.00", "0.114"], ["70603.90", "0.496"], ["70604.00", "0.271"], ["70623.80", "0.482"], ["70626.20", "0.712"], ["70626.30", "0.009"], ["70627.10", "0.001"], ["70628.00", "1.371"], ["70628.70", "0.000"], ["70629.90", "0.224"], ["70630.70", "0.000"], ["70630.80", "0.024"], ["70631.00", "0.073"], ["70633.50", "0.602"], ["70633.90", "0.003"], ["70638.00", "2.905"]], "a": [["70648.70", "0.008"], ["70861.50", "0.010"], ["70991.30", "0.879"], ["71140.60", "0.002"], ["71572.50", "4.181"], ["71662.40", "1.672"], ["77701.90", "0.000"]]}}
{"local_ts": 1773486954038, "server_ts": 1773486954008, "data": {"e": "depthUpdate", "E": 1773486954011, "T": 1773486954008, "s": "BTCUSDT", "U": 10109532797023, "u": 10109532799927, "pu": 10109532796957, "b": [["1000.00", "26.892"], ["5000.00", "101.418"], ["7063.80", "0.056"], ["20238.00", "1.210"], ["20338.00", "1.790"], ["63574.20", "0.000"], ["67072.20", "0.000"], ["67102.30", "0.002"], ["69931.60", "2.856"], ["70284.80", "0.853"], ["70613.10", "0.031"], ["70613.50", "0.053"], ["70627.40", "0.003"], ["70628.10", "0.011"], ["70629.90", "0.217"], ["70630.80", "0.027"], ["70634.00", "0.011"]], "a": [["70638.10", "5.412"], ["70644.40", "0.007"], ["70648.00", "0.000"], ["70648.70", "0.008"], ["70652.10", "0.000"], ["70662.20", "0.026"], ["70671.00", "0.062"], ["70673.40", "1.169"], ["71344.50", "1.415"], ["73463.60", "0.595"], ["77701.90", "0.000"]]}}
{"local_ts": 1773486955063, "server_ts": 1773486955032, "data": {"e": "depthUpdate", "E": 1773486955033, "T": 1773486955032, "s": "BTCUSDT", "U": 10109532836398, "u": 10109532846946, "pu": 10109532836306, "b": [["1000.00", "26.892"], ["5000.00", "101.418"], ["7063.80", "0.056"], ["20138.00", "0.770"], ["20238.00", "2.230"], ["33000.00", "3.789"], ["40000.00", "41.356"], ["56510.00", "0.020"], ["63574.20", "0.000"], ["67077.30", "0.002"], ["68524.40", "0.000"], ["69214.10", "0.381"], ["69292.50", "0.000"], ["69371.00", "0.715"], ["69449.50", "0.000"], ["69528.00", "0.193"], ["69606.40", "0.000"], ["69684.90", "0.006"], ["69763.40", "0.003"], ["69841.90", "0.000"], ["69920.30", "0.000"], ["69931.60", "2.856"], ["70513.00", "0.000"], ["70526.50", "0.187"], ["70546.10", "2.114"], ["70568.20", "0.000"], ["70588.20", "0.856"], ["70590.20", "8.499"], ["70593.00", "0.007"], ["70593.20", "0.005"], ["70593.60", "0.480"], ["70595.00", "0.542"], ["70595.30", "1.231"], ["70599.00", "0.298"], ["70599.10", "0.539"], ["70600.10", "0.358"], ["70602.40", "0.947"], ["70605.60", "0.139"], ["70608.90", "0.354"], ["70609.50", "0.855"], ["70609.70", "0.000"], ["70612.00", "0.008"], ["70612.80", "0.060"], ["70613.00", "0.305"], ["70615.00", "0.138"], ["70615.30", "0.023"], ["70616.40", "0.247"], ["70616.60", "0.860"], ["70617.80", "0.012"], ["70618.10", "0.141"], ["70618.90", "0.183"], ["70619.20", "0.052"], ["70619.80", "0.004"], ["70619.90", "0.007"], ["70620.50", "0.017"], ["70620.90", "1.203"], ["70621.00", "0.010"], ["70621.30", "0.511"], ["70621.40", "0.001"], ["70621.60", "0.127"], ["70622.50", "0.411"], ["70622.80", "0.667"], ["70623.10", "0.076"], ["70623.30", "0.003"], ["70623.70", "0.030"], ["70623.90", "0.257"], ["70624.30", "0.049"], ["70625.20", "0.006"], ["70625.30", "0.325"], ["70626.30", "0.002"], ["70626.60", "0.208"], ["70627.10", "0.008"], ["70627.40", "0.000"], ["70627.80", "0.202"], ["70627.90", "0.006"], ["70628.10", "0.004"], ["70629.10", "0.283"], ["70629.30", "0.003"], ["70629.40", "0.001"], ["70629.50", "1.280"], ["70629.80", "0.010"], ["70629.90", "0.217"], ["70630.10", "0.005"], ["70630.40", "0.008"], ["70630.50", "0.514"], ["70630.70", "0.000"], ["70630.80", "0.024"], ["70630.90", "0.057"], ["70631.10", "0.008"], ["70631.20", "0.002"], ["70631.50", "0.158"], ["70631.80", "0.013"], ["70632.10", "0.011"], ["70632.20", "0.005"], ["70632.60", "0.002"], ["70632.80", "0.208"], ["70632.90", "0.459"], ["70633.00", "0.514"], ["70633.10", "0.003"], ["70633.40", "0.075"], ["70633.70", "0.013"], ["70634.40", "0.007"], ["70634.70", "0.001"], ["70634.80", "0.000"], ["70635.00", "3.965"], ["70635.10", "1.070"], ["70635.20", "0.515"], ["70635.30", "0.002"], ["70635.40", "0.003"], ["70635.50", "0.792"], ["70635.60", "0.015"], ["70635.70", "0.008"], ["70636.60", "0.002"], ["70636.70", "0.002"], ["70637.80", "0.002"], ["70638.00", "3.723"]], "a": [["70638.10", "3.494"], ["70638.70", "0.000"], ["70640.60", "0.021"], ["70641.70", "0.058"], ["70642.50", "0.004"], ["70643.00", "0.212"], ["70643.40", "0.023"], ["70644.00", "0.031"], ["70644.90", "0.028"], ["70645.00", "0.340"], ["70645.30", "0.036"], ["70645.50", "0.099"], ["70646.50", "0.058"], ["70647.60", "0.025"], ["70648.00", "0.205"], ["70648.10", "0.204"], ["70648.70", "0.008"], ["70649.30", "0.019"], ["70649.40", "0.002"], ["70649.60", "0.023"], ["70649.70", "0.003"], ["70650.40", "0.093"], ["70650.60", "0.003"], ["70650.80", "0.611"], ["70651.00", "0.440"], ["70652.00", "0.003"], ["70652.20", "0.011"], ["70652.50", "0.222"], ["70652.80", "0.556"], ["70652.90", "0.610"], ["70653.90", "0.142"], ["70654.00", "0.057"], ["70654.10", "0.005"], ["70654.50", "0.010"], ["70655.60", "0.004"], ["70655.70", "0.422"], ["70656.30", "0.003"], ["70657.30", "0.513"], ["70657.50", "0.000"], ["70657.60", "0.008"], ["70657.70", "0.023"], ["70658.30", "0.264"], ["70658.40", "0.012"], ["70659.50", "0.089"], ["70659.70", "0.000"], ["70660.60", "0.002"], ["70661.30", "0.029"], ["70661.80", "0.005"], ["70661.90", "0.657"], ["70662.00", "0.012"], ["70662.20", "0.003"], ["70664.70", "0.460"], ["70665.50", "0.523"], ["70666.10", "0.131"], ["70666.20", "0.686"], ["70666.30", "1.231"], ["70666.40", "0.406"], ["70666.60", "0.034"], ["70668.10", "0.000"], ["70668.60", "0.007"], ["70669.00", "0.000"], ["70669.60", "0.070"], ["70669.90", "0.345"], ["70670.20", "0.005"], ["70670.30", "0.815"], ["70670.50", "0.004"], ["70671.00", "0.090"], ["70671.30", "0.078"], ["70672.50", "0.060"], ["70673.10", "0.078"], ["70673.20", "0.522"], ["70673.30", "0.698"], ["70673.40", "2.084"], ["70676.80", "0.015"], ["70677.00", "0.155"], ["70679.10", "1.128"], ["70680.10", "0.020"], ["70680.50", "0.869"], ["70683.40", "0.004"], ["70683.50", "0.032"], ["70686.10", "0.028"], ["70686.20", "0.046"], ["70687.60", "0.857"], ["70688.10", "0.035"], ["70688.20", "0.012"], ["70689.70", "0.798"], ["70693.20", "0.000"], ["70696.70", "0.000"], ["70700.30", "0.002"], ["70705.70", "0.000"], ["70707.80", "9.554"], ["70708.00", "0.004"], ["70708.40", "0.084"], ["70711.10", "0.066"], ["70713.10", "0.000"], ["70797.00", "0.072"], ["71332.90", "0.163"], ["71344.50", "1.415"], ["71411.30", "0.000"], ["71489.80", "0.003"], ["71568.30", "0.279"], ["71646.80", "0.000"], ["71725.20", "0.000"], ["71803.70", "0.000"], ["71882.20", "0.244"], ["71960.70", "0.000"], ["72039.10", "0.000"], ["72763.10", "0.030"], ["74186.60", "0.000"], ["77701.90", "0.000"]]}}
{"local_ts": 1773486956087, "server_ts": 1773486956054, "data": {"e": "depthUpdate", "E": 1773486956055, "T": 1773486956054, "s": "BTCUSDT", "U": 10109532943271, "u": 10109532953219, "pu": 10109532943263, "b": [["5000.00", "101.418"], ["7064.60", "0.056"], ["20138.00", "1.620"], ["20145.40", "0.140"], ["20149.30", "0.050"], ["20151.00", "0.000"], ["20151.90", "0.010"], ["20238.00", "0.050"], ["20541.90", "0.000"], ["20545.40", "0.100"], ["20548.60", "0.010"], ["67105.40", "0.002"], ["68526.10", "0.006"], ["69232.50", "0.003"], ["69938.90", "0.000"], ["69942.10", "0.000"], ["69942.80", "0.074"], ["70243.00", "0.027"], ["70244.20", "0.002"], ["70248.80", "0.054"], ["70254.20", "0.002"], ["70284.90", "0.004"], ["70294.40", "0.002"], ["70320.40", "0.109"], ["70331.40", "0.000"], ["70340.70", "0.000"], ["70344.30", "0.000"], ["70392.10", "2.589"], ["70431.40", "0.005"], ["70438.60", "0.002"], ["70442.10", "0.000"], ["70449.00", "0.000"], ["70451.30", "2.518"], ["70465.30", "2.487"], ["70465.40", "16.452"], ["70468.80", "0.173"], ["70481.70", "0.093"], ["70485.20", "0.008"], ["70492.50", "0.000"], ["70494.70", "0.093"], ["70499.00", "0.000"], ["70509.20", "0.002"], ["70509.70", "0.000"], ["70509.80", "0.134"], ["70522.60", "0.515"], ["70524.70", "0.278"], ["70538.50", "0.006"], ["70539.90", "0.022"], ["70545.20", "0.969"], ["70552.80", "1.691"], ["70559.30", "0.051"], ["70559.40", "0.015"], ["70567.20", "0.231"], ["70574.50", "0.053"], ["70574.80", "0.845"], ["70574.90", "0.053"], ["70577.00", "0.031"], ["70578.50", "0.200"], ["70578.60", "0.004"], ["70579.60", "0.000"], ["70583.10", "0.611"], ["70584.30", "0.000"], ["70584.80", "0.275"], ["70585.00", "0.000"], ["70585.40", "0.011"], ["70585.70", "0.089"], ["70587.60", "0.002"], ["70588.90", "0.081"], ["70590.20", "0.000"], ["70591.30", "1.312"], ["70592.30", "8.500"], ["70592.80", "0.842"], ["70595.30", "1.231"], ["70595.80", "0.002"], ["70596.30", "0.004"], ["70596.60", "0.001"], ["70596.80", "0.000"], ["70597.20", "0.005"], ["70597.60", "0.005"], ["70598.30", "0.204"], ["70598.80", "0.279"], ["70599.00", "0.253"], ["70599.10", "0.203"], ["70599.20", "0.619"], ["70599.30", "0.187"], ["70600.30", "0.000"], ["70600.40", "0.070"], ["70601.60", "0.004"], ["70602.40", "0.947"], ["70603.00", "0.330"], ["70603.20", "0.141"], ["70603.40", "0.277"], ["70604.00", "0.169"], ["70604.20", "0.142"], ["70604.40", "0.000"], ["70604.80", "0.292"], ["70605.40", "0.087"], ["70605.50", "0.002"], ["70605.70", "0.000"], ["70606.00", "0.571"], ["70606.60", "0.069"], ["70606.80", "0.005"], ["70606.90", "0.366"], ["70607.40", "0.000"], ["70607.90", "0.008"], ["70608.20", "0.100"], ["70608.30", "0.005"], ["70609.10", "0.003"], ["70609.50", "0.855"], ["70610.00", "0.278"], ["70610.20", "0.098"], ["70611.10", "0.002"], ["70611.20", "0.574"], ["70611.90", "0.100"], ["70612.60", "0.366"], ["70612.70", "0.001"], ["70613.00", "0.284"], ["70613.70", "0.009"], ["70614.00", "0.008"], ["70614.40", "0.843"], ["70614.50", "0.007"], ["70615.00", "0.006"], ["70615.30", "0.001"], ["70615.40", "0.015"], ["70615.90", "0.003"], ["70616.00", "0.007"], ["70616.30", "1.111"], ["70616.60", "0.869"], ["70616.70", "0.011"], ["70617.10", "0.079"], ["70618.60", "0.000"], ["70619.00", "0.255"], ["70620.30", "0.000"], ["70620.70", "0.057"], ["70620.90", "0.002"], ["70621.00", "0.284"], ["70621.20", "0.014"], ["70621.50", "0.004"], ["70621.90", "0.007"], ["70622.20", "0.002"], ["70623.00", "0.010"], ["70623.30", "1.722"], ["70623.60", "0.009"], ["70623.70", "0.865"], ["70624.00", "0.006"], ["70624.30", "0.047"], ["70624.50", "0.000"], ["70624.70", "0.125"], ["70625.30", "0.403"], ["70625.50", "0.053"], ["70625.60", "0.012"], ["70625.80", "0.000"], ["70625.90", "0.085"], ["70626.00", "0.253"], ["70626.20", "0.887"], ["70626.30", "0.072"], ["70626.50", "0.067"], ["70626.70", "0.169"], ["70626.90", "0.005"], ["70627.10", "0.001"], ["70627.20", "0.002"], ["70627.30", "0.002"], ["70627.60", "0.342"], ["70627.70", "0.511"], ["70627.80", "0.204"], ["70627.90", "0.004"], ["70628.00", "1.088"], ["70628.10", "0.007"], ["70628.20", "0.576"], ["70628.60", "0.010"], ["70628.80", "0.002"], ["70629.10", "0.002"], ["70629.30", "0.002"], ["70629.50", "0.664"], ["70629.60", "0.007"], ["70629.70", "0.002"], ["70629.90", "0.216"], ["70630.00", "0.443"], ["70630.10", "0.005"], ["70630.20", "0.013"], ["70630.90", "0.283"], ["70631.00", "0.062"], ["70631.10", "0.002"], ["70631.40", "0.647"], ["70631.50", "0.162"], ["70631.60", "0.061"], ["70631.70", "0.000"], ["70631.80", "0.011"], ["70631.90", "0.000"], ["70632.50", "0.002"], ["70632.70", "0.905"], ["70632.90", "0.465"], ["70633.10", "0.008"], ["70633.20", "0.126"], ["70633.30", "0.016"], ["70633.40", "0.067"], ["70633.60", "0.009"], ["70633.90", "0.003"], ["70634.00", "0.003"], ["70634.10", "0.053"], ["70634.20", "0.003"], ["70634.40", "0.000"], ["70634.70", "0.000"], ["70634.80", "0.005"], ["70634.90", "0.020"], ["70635.10", "0.003"], ["70635.20", "0.790"], ["70635.40", "0.648"], ["70635.60", "0.007"], ["70635.70", "0.005"], ["70635.80", "0.001"], ["70635.90", "0.011"], ["70636.00", "0.000"], ["70636.20", "0.015"], ["70636.50", "0.677"], ["70636.60", "0.151"], ["70636.70", "0.000"], ["70636.80", "0.009"], ["70636.90", "0.023"], ["70637.20", "0.004"], ["70637.30", "0.003"], ["70637.40", "0.002"], ["70637.50", "0.002"], ["70637.60", "0.007"], ["70637.80", "0.000"], ["70637.90", "0.005"], ["70638.00", "0.923"], ["70638.10", "0.840"], ["70638.20", "0.003"], ["70638.30", "0.812"], ["70638.40", "0.459"], ["70638.70", "0.074"], ["70638.80", "0.001"], ["70638.90", "0.005"], ["70639.00", "0.000"], ["70639.10", "0.457"], ["70639.20", "0.615"], ["70639.30", "0.006"], ["70639.40", "0.123"], ["70641.00", "0.008"], ["70641.60", "0.003"], ["70641.70", "0.007"], ["70641.80", "0.212"], ["70641.90", "0.004"], ["70642.00", "0.288"], ["70642.10", "0.000"], ["70642.20", "0.000"], ["70642.30", "0.003"], ["70642.40", "0.001"], ["70642.90", "0.213"], ["70643.00", "0.084"], ["70643.30", "0.001"], ["70643.60", "0.006"], ["70643.70", "0.003"], ["70643.80", "0.000"], ["70644.00", "0.009"], ["70644.20", "0.000"], ["70644.30", "0.000"], ["70644.40", "0.001"], ["70644.70", "0.005"], ["70645.00", "0.000"], ["70645.10", "0.001"], ["70645.20", "0.004"], ["70645.40", "1.226"], ["70645.60", "0.000"], ["70645.70", "0.000"], ["70646.00", "0.000"], ["70646.30", "0.000"], ["70646.40", "0.000"], ["70646.70", "0.000"], ["70647.40", "0.000"], ["70647.50", "0.000"], ["70647.80", "0.000"], ["70648.40", "0.000"], ["70648.60", "0.000"], ["70649.00", "0.000"], ["70649.30", "0.000"]], "a": [["70645.50", "12.148"], ["70645.60", "0.002"], ["70645.70", "0.002"], ["70645.80", "0.002"], ["70645.90", "0.000"], ["70646.10", "0.000"], ["70646.20", "0.000"], ["70646.30", "0.000"], ["70646.40", "0.002"], ["70646.50", "0.000"], ["70646.60", "0.000"], ["70646.70", "0.007"], ["70646.80", "0.000"], ["70647.00", "0.002"], ["70647.30", "0.003"], ["70647.40", "0.025"], ["70647.50", "0.002"], ["70647.60", "0.021"], ["70647.90", "0.003"], ["70648.30", "0.040"], ["70648.40", "0.040"], ["70648.50", "0.003"], ["70648.60", "0.005"], ["70648.70", "0.005"], ["70648.80", "0.212"], ["70648.90", "0.000"], ["70649.00", "0.000"], ["70649.10", "0.003"], ["70649.20", "0.000"], ["70649.30", "0.005"], ["70649.40", "0.617"], ["70649.50", "0.001"], ["70649.60", "0.080"], ["70649.70", "0.001"], ["70649.80", "0.000"], ["70649.90", "0.000"], ["70650.00", "0.004"], ["70650.10", "0.002"], ["70650.40", "0.003"], ["70650.60", "0.025"], ["70650.80", "0.027"], ["70651.00", "0.143"], ["70651.10", "0.039"], ["70651.30", "0.000"], ["70651.60", "0.002"], ["70651.70", "0.040"], ["70651.90", "0.039"], ["70652.00", "0.115"], ["70652.10", "0.287"], ["70652.20", "0.094"], ["70652.30", "0.005"], ["70652.40", "0.302"], ["70652.50", "0.000"], ["70653.10", "0.001"], ["70653.30", "0.004"], ["70654.30", "0.006"], ["70654.50", "0.010"], ["70654.60", "0.039"], ["70655.00", "0.006"], ["70655.10", "0.041"], ["70655.20", "0.059"], ["70655.30", "0.001"], ["70655.40", "0.009"], ["70655.90", "0.007"], ["70656.00", "0.003"], ["70656.10", "0.000"], ["70656.30", "0.003"], ["70656.40", "0.007"], ["70656.50", "0.141"], ["70657.30", "0.002"], ["70657.40", "0.291"], ["70657.50", "0.002"], ["70658.00", "0.187"], ["70658.10", "0.455"], ["70658.20", "0.152"], ["70658.50", "0.002"], ["70658.70", "0.198"], ["70658.80", "0.007"], ["70658.90", "0.002"], ["70659.60", "0.009"], ["70659.90", "0.058"], ["70660.10", "0.008"], ["70660.30", "0.000"], ["70660.60", "0.001"], ["70660.70", "0.000"], ["70660.80", "0.026"], ["70661.20", "0.004"], ["70661.30", "0.002"], ["70661.40", "0.009"], ["70661.60", "0.005"], ["70662.00", "0.019"], ["70662.40", "0.010"], ["70662.50", "0.309"], ["70662.60", "0.218"], ["70662.80", "0.008"], ["70662.90", "0.068"], ["70663.20", "0.157"], ["70663.40", "0.000"], ["70663.50", "0.021"], ["70663.60", "0.010"], ["70663.90", "1.254"], ["70664.00", "0.002"], ["70664.10", "0.000"], ["70664.30", "0.342"], ["70664.40", "0.007"], ["70664.60", "0.004"], ["70664.80", "0.010"], ["70664.90", "0.001"], ["70665.00", "0.008"], ["70665.20", "0.013"], ["70665.60", "0.003"], ["70665.90", "0.000"], ["70666.30", "0.855"], ["70666.40", "0.209"], ["70666.80", "0.020"], ["70667.20", "1.077"], ["70667.80", "0.001"], ["70667.90", "0.005"], ["70668.60", "0.007"], ["70669.00", "0.000"], ["70669.10", "0.286"], ["70669.80", "0.002"], ["70670.00", "0.053"], ["70670.20", "0.005"], ["70671.40", "0.018"], ["70671.70", "0.040"], ["70671.80", "0.028"], ["70671.90", "0.074"], ["70672.00", "1.296"], ["70673.30", "0.266"], ["70673.40", "0.929"], ["70673.50", "0.005"], ["70673.80", "0.349"], ["70674.10", "0.045"], ["70674.20", "0.009"], ["70674.30", "0.000"], ["70674.50", "0.013"], ["70674.90", "0.264"], ["70675.60", "0.059"], ["70676.20", "0.013"], ["70676.30", "0.004"], ["70676.80", "0.010"], ["70677.00", "0.020"], ["70677.20", "0.061"], ["70677.70", "0.002"], ["70678.40", "0.138"], ["70678.50", "0.987"], ["70679.40", "0.314"], ["70679.50", "0.320"], ["70680.00", "2.649"], ["70680.50", "0.867"], ["70680.60", "0.002"], ["70680.70", "0.003"], ["70680.80", "0.042"], ["70681.20", "0.029"], ["70681.90", "0.003"], ["70683.00", "0.009"], ["70683.10", "0.017"], ["70683.50", "0.024"], ["70684.30", "0.025"], ["70685.10", "0.004"], ["70686.90", "0.004"], ["70687.00", "0.620"], ["70687.10", "0.036"], ["70687.60", "0.857"], ["70687.80", "0.227"], ["70688.50", "0.004"], ["70692.50", "0.004"], ["70692.70", "0.000"], ["70693.10", "0.004"], ["70693.80", "0.017"], ["70694.30", "0.090"], ["70694.70", "0.855"], ["70694.90", "0.003"], ["70695.10", "0.013"], ["70696.30", "0.121"], ["70696.40", "0.005"], ["70696.50", "1.212"], ["70697.90", "0.003"], ["70698.20", "0.031"], ["70699.60", "0.307"], ["70700.70", "0.039"], ["70701.80", "1.366"], ["70703.50", "0.005"], ["70703.80", "0.000"], ["70706.30", "8.488"], ["70707.80", "1.075"], ["70709.30", "0.001"], ["70714.00", "0.383"], ["70714.40", "0.007"], ["70715.90", "0.723"], ["70716.00", "0.047"], ["70716.90", "0.029"], ["70721.80", "1.517"], ["70722.30", "6.303"], ["70724.20", "0.069"], ["70724.50", "0.036"], ["70726.10", "0.213"], ["70728.00", "1.364"], ["70731.70", "0.241"], ["70734.40", "0.336"], ["70737.30", "0.457"], ["70738.10", "0.232"], ["70738.50", "0.036"], ["70744.70", "0.007"], ["70746.30", "0.000"], ["70746.40", "0.528"], ["70752.30", "0.050"], ["70754.90", "0.077"], ["70756.50", "0.093"], ["70758.60", "0.149"], ["70759.10", "0.004"], ["70768.20", "0.365"], ["70783.30", "0.044"], ["70789.80", "0.000"], ["70793.50", "0.000"], ["70796.80", "0.061"], ["70797.40", "0.610"], ["70797.80", "0.069"], ["70801.00", "2.001"], ["70801.30", "6.489"], ["70809.40", "0.415"], ["70810.50", "0.005"], ["70852.40", "0.000"], ["70855.90", "0.000"], ["70884.20", "0.000"], ["70884.40", "0.000"], ["70885.70", "0.113"], ["70946.40", "0.625"], ["70949.30", "0.058"], ["71217.40", "2.804"], ["71352.00", "0.000"], ["71355.00", "0.017"], ["71355.90", "0.136"], ["71606.00", "1.125"], ["71638.50", "0.005"], ["71641.40", "0.002"], ["71649.40", "0.010"], ["72764.80", "0.006"], ["89523.20", "0.000"], ["100000.00", "23.620"]]}}
{"local_ts": 1773486957137, "server_ts": 1773486957072, "data": {"e": "depthUpdate", "E": 1773486957075, "T": 1773486957072, "s": "BTCUSDT", "U": 10109533003372, "u": 10109533007155, "pu": 10109533003342, "b": [["1000.00", "26.892"], ["5000.00", "101.418"], ["7064.60", "0.028"], ["20138.00", "0.330"], ["20445.40", "0.200"], ["20545.40", "2.250"], ["69437.10", "0.146"], ["69766.20", "0.718"], ["69938.90", "0.000"], ["70292.20", "0.000"], ["70320.40", "0.003"], ["70324.00", "0.106"], ["70505.20", "0.078"], ["70506.70", "0.704"], ["70598.40", "0.143"], ["70598.50", "0.004"], ["70599.20", "0.265"], ["70603.00", "0.338"], ["70603.90", "0.496"], ["70604.00", "0.523"], ["70616.50", "0.045"], ["70624.50", "0.003"], ["70625.50", "0.143"], ["70626.80", "0.509"], ["70627.10", "0.001"], ["70627.30", "0.004"], ["70628.10", "0.000"], ["70629.70", "0.008"], ["70629.80", "0.109"], ["70629.90", "0.223"], ["70632.70", "0.905"], ["70636.60", "0.363"], ["70638.40", "0.515"], ["70638.50", "0.004"], ["70639.20", "0.016"], ["70644.10", "0.002"]], "a": [["70665.70", "0.021"], ["70690.90", "0.061"], ["70709.30", "0.512"], ["70754.50", "0.513"], ["70776.90", "0.511"], ["70777.00", "5.389"], ["70884.70", "1.702"], ["70885.70", "0.007"], ["71352.00", "0.000"], ["71501.80", "0.000"], ["74171.20", "0.000"], ["74202.30", "0.002"], ["89523.20", "0.000"]]}}
{"local_ts": 1773486958225, "server_ts": 1773486958196, "data": {"e": "depthUpdate", "E": 1773486958199, "T": 1773486958196, "s": "BTCUSDT", "U": 10109533052997, "u": 10109533056342, "pu": 10109533052862, "b": [["1000.00", "26.892"], ["5000.00", "101.398"], ["7064.60", "0.000"], ["20345.40", "0.130"], ["20445.40", "2.420"], ["20545.40", "0.450"], ["66832.50", "0.000"], ["69938.90", "0.714"], ["69974.40", "0.004"], ["70398.90", "0.000"], ["70549.60", "1.074"], ["70556.60", "0.071"], ["70563.70", "0.089"], ["70598.60", "0.514"], ["70598.80", "0.281"], ["70599.00", "0.056"], ["70599.10", "0.224"], ["70599.30", "0.187"], ["70599.50", "0.004"], ["70603.00", "0.159"], ["70603.10", "0.541"], ["70604.80", "0.365"], ["70610.10", "0.051"], ["70620.60", "0.270"], ["70623.90", "0.001"], ["70627.00", "0.601"], ["70627.60", "0.007"], ["70629.00", "0.005"], ["70629.70", "0.234"], ["70630.60", "0.004"], ["70630.70", "0.000"], ["70632.50", "0.235"], ["70634.00", "0.024"], ["70636.60", "0.375"], ["70637.10", "0.006"], ["70638.00", "1.052"], ["70638.30", "1.271"], ["70638.50", "0.002"], ["70639.20", "0.020"], ["70640.10", "0.140"], ["70642.30", "0.003"], ["70642.70", "0.002"]], "a": [["70645.50", "10.225"], ["70652.60", "0.004"], ["70694.20", "0.516"], ["70694.30", "0.090"], ["70726.30", "0.071"], ["70726.40", "0.023"], ["70728.40", "0.005"], ["70729.40", "0.084"], ["70733.40", "0.073"], ["70733.50", "0.060"], ["70740.40", "0.071"], ["70740.50", "0.088"], ["70793.90", "0.039"], ["71352.00", "0.700"], ["71903.50", "0.023"], ["72300.00", "11.301"], ["74191.30", "0.002"], ["74199.90", "0.000"]]}}
{"local_ts": 1773486959246, "server_ts": 1773486959216, "data": {"e": "depthUpdate", "E": 1773486959219, "T": 1773486959216, "s": "BTCUSDT", "U": 10109533098273, "u": 10109533101707, "pu": 10109533098254, "b": [["1000.00", "26.892"], ["5000.00", "101.418"], ["7064.60", "0.056"], ["20345.40", "2.230"], ["20445.40", "0.770"], ["67078.00", "0.012"], ["67102.50", "0.025"], ["69394.40", "0.000"], ["69606.90", "1.364"], ["69938.90", "0.714"], ["70013.20", "0.000"], ["70363.70", "0.004"], ["70398.80", "0.202"], ["70549.60", "1.074"], ["70556.60", "0.071"], ["70563.70", "0.089"], ["70599.00", "0.594"], ["70599.10", "0.226"], ["70599.30", "0.003"], ["70603.00", "0.442"], ["70604.00", "0.353"], ["70610.10", "0.023"], ["70626.40", "0.061"], ["70628.00", "1.353"], ["70628.60", "0.010"], ["70628.90", "0.070"], ["70630.30", "0.015"], ["70633.80", "0.006"], ["70634.30", "0.005"], ["70634.80", "0.002"], ["70634.90", "0.020"], ["70636.60", "0.189"], ["70638.30", "1.092"], ["70638.50", "0.004"], ["70640.20", "0.000"], ["70645.40", "2.661"]], "a": [["70645.50", "9.207"], ["70652.60", "0.002"], ["70658.30", "0.001"], ["70659.80", "0.023"], ["70660.90", "0.005"], ["70673.40", "0.004"], ["70673.50", "0.005"], ["70674.10", "0.009"], ["70674.20", "0.009"], ["70725.60", "0.088"], ["70726.30", "0.071"], ["70728.40", "0.003"], ["70733.40", "0.073"], ["70740.40", "0.071"], ["70869.30", "0.007"], ["71305.40", "2.801"], ["71316.50", "0.000"], ["71352.00", "0.700"], ["71613.20", "0.000"], ["72050.80", "0.044"], ["74195.00", "0.072"]]}}
{"local_ts": 1773486960266, "server_ts": 1773486960236, "data": {"e": "depthUpdate", "E": 1773486960239, "T": 1773486960236, "s": "BTCUSDT", "U": 10109533133450, "u": 10109533137789, "pu": 10109533133410, "b": [["5000.00", "101.418"], ["7064.60", "0.056"], ["20245.40", "1.780"], ["20345.40", "1.220"], ["67091.50", "0.056"], ["68526.00", "0.130"], ["69582.50", "1.249"], ["69938.90", "0.714"], ["70220.40", "7.169"], ["70292.30", "0.003"], ["70302.80", "0.000"], ["70331.00", "0.171"], ["70399.00", "0.004"], ["70401.80", "26.267"], ["70401.90", "6.027"], ["70533.30", "0.084"], ["70545.50", "0.065"], ["70548.70", "0.455"], ["70550.80", "0.249"], ["70599.00", "0.240"], ["70599.50", "0.006"], ["70599.60", "0.458"], ["70603.10", "0.187"], ["70604.00", "0.169"], ["70607.20", "0.903"], ["70627.50", "0.115"], ["70627.70", "0.907"], ["70631.40", "0.007"], ["70634.80", "0.005"], ["70635.50", "0.173"], ["70638.30", "1.095"], ["70638.50", "0.004"], ["70642.40", "0.003"], ["70645.40", "2.676"]], "a": [["70652.60", "0.002"], ["70656.10", "0.000"], ["70677.20", "0.112"], ["70677.50", "0.004"], ["70679.40", "0.272"], ["70685.30", "0.014"], ["70690.00", "3.654"], ["70889.10", "7.999"], ["71352.00", "0.970"]]}}
{"local_ts": 1773486961288, "server_ts": 1773486961257, "data": {"e": "depthUpdate", "E": 1773486961259, "T": 1773486961257, "s": "BTCUSDT", "U": 10109533195998, "u": 10109533202875, "pu": 10109533195904, "b": [["1000.00", "26.892"], ["5000.00", "101.418"], ["7064.60", "0.056"], ["20145.40", "1.330"], ["20245.40", "1.670"], ["67090.20", "0.003"], ["67104.70", "0.002"], ["67536.00", "2.002"], ["68239.50", "1.000"], ["69593.70", "0.000"], ["69938.90", "0.714"], ["70292.20", "0.064"], ["70468.80", "0.173"], ["70588.90", "0.081"], ["70599.00", "0.410"], ["70599.10", "0.224"], ["70599.20", "0.267"], ["70599.50", "0.143"], ["70603.00", "0.538"], ["70603.10", "0.003"], ["70604.20", "0.187"], ["70604.80", "0.459"], ["70614.80", "0.017"], ["70616.10", "0.015"], ["70624.90", "0.000"], ["70625.00", "0.087"], ["70626.10", "0.673"], ["70627.40", "0.072"], ["70629.00", "0.465"], ["70635.50", "0.003"], ["70635.60", "0.007"], ["70636.60", "0.057"], ["70636.70", "0.003"], ["70638.50", "0.004"], ["70640.10", "0.001"], ["70642.60", "0.001"], ["70645.40", "2.654"]], "a": [["70656.10", "0.003"], ["70658.00", "0.202"], ["70671.40", "0.017"], ["70737.30", "0.457"], ["70870.20", "0.009"], ["71316.50", "0.000"], ["71352.00", "0.700"], ["71563.90", "1.674"], ["72058.40", "0.014"]]}}
{"local_ts": 1773486962307, "server_ts": 1773486962276, "data": {"e": "depthUpdate", "E": 1773486962279, "T": 1773486962276, "s": "BTCUSDT", "U": 10109533255327, "u": 10109533259337, "pu": 10109533255151, "b": [["5000.00", "101.418"], ["7064.60", "0.028"], ["20145.40", "2.120"], ["20545.40", "0.880"], ["33000.00", "3.785"], ["49438.60", "0.004"], ["64627.20", "0.017"], ["69232.50", "0.018"], ["69606.90", "2.726"], ["69938.90", "0.714"], ["70599.90", "0.004"], ["70600.00", "0.950"], ["70600.20", "0.188"], ["70614.80", "0.017"], ["70625.50", "0.534"], ["70626.80", "0.007"], ["70634.80", "0.005"], ["70638.30", "1.310"], ["70638.50", "0.006"], ["70639.60", "0.003"], ["70640.20", "0.002"]], "a": [["70645.50", "9.179"], ["70652.60", "0.004"], ["70656.10", "0.000"], ["70659.60", "0.002"], ["70660.00", "0.002"], ["70660.60", "0.002"], ["70714.50", "0.514"], ["70715.90", "0.723"], ["70737.30", "0.351"], ["70740.90", "0.373"], ["70870.00", "1.086"], ["71316.50", "0.000"], ["71352.00", "0.700"], ["71766.60", "19.349"], ["74198.80", "0.057"]]}}
{"local_ts": 1773486963331, "server_ts": 1773486963300, "data": {"e": "depthUpdate", "E": 1773486963303, "T": 1773486963300, "s": "BTCUSDT", "U": 10109533293793, "u": 10109533297714, "pu": 10109533293677, "b": [["1000.00", "26.892"], ["5000.00", "101.418"], ["7064.60", "0.028"], ["20145.40", "0.010"], ["20445.40", "0.450"], ["20545.40", "2.540"], ["69938.90", "0.714"], ["70292.10", "0.147"], ["70549.70", "0.697"], ["70556.70", "0.508"], ["70563.80", "0.018"], ["70599.70", "0.007"], ["70599.90", "0.004"], ["70609.30", "0.104"], ["70609.40", "0.092"], ["70618.60", "0.000"], ["70620.30", "0.141"], ["70620.90", "0.002"], ["70627.50", "0.241"], ["70627.90", "0.214"], ["70630.90", "0.283"], ["70631.30", "0.010"], ["70634.30", "0.007"], ["70634.40", "0.000"], ["70636.60", "0.080"], ["70636.90", "0.023"], ["70639.60", "0.001"], ["70642.70", "0.002"], ["70645.40", "1.638"]], "a": [["70651.40", "0.021"], ["70671.40", "0.011"], ["70671.90", "0.513"], ["70672.70", "0.002"], ["70674.60", "0.366"], ["70675.30", "0.089"], ["70698.70", "0.002"], ["70698.90", "0.105"], ["70726.40", "0.023"], ["70733.50", "0.060"], ["70740.50", "0.088"], ["70740.90", "0.267"], ["71352.00", "0.700"], ["71528.60", "0.264"], ["74180.50", "0.052"], ["77710.00", "0.022"]]}}
{"local_ts": 1773486964352, "server_ts": 1773486964324, "data": {"e": "depthUpdate", "E": 1773486964325, "T": 1773486964324, "s": "BTCUSDT", "U": 10109533334412, "u": 10109533340057, "pu": 10109533334331, "b": [["1000.00", "26.892"], ["5000.00", "101.418"], ["7064.60", "0.028"], ["20345.40", "0.240"], ["20445.40", "2.520"], ["20545.40", "0.240"], ["33000.00", "3.789"], ["67099.50", "0.004"], ["69232.60", "0.004"], ["69637.20", "0.716"], ["69642.20", "1.430"], ["69663.40", "1.862"], ["69938.90", "1.428"], ["69939.00", "0.004"], ["70399.00", "0.000"], ["70468.80", "0.173"], ["70509.50", "0.205"], ["70509.60", "0.631"], ["70549.70", "0.714"], ["70556.70", "0.579"], ["70563.80", "0.089"], ["70600.30", "0.170"], ["70621.10", "0.018"], ["70622.40", "0.250"], ["70622.90", "0.002"], ["70623.40", "0.002"], ["70624.20", "0.254"], ["70624.60", "0.002"], ["70626.60", "0.654"], ["70627.10", "0.001"], ["70627.60", "0.163"], ["70628.00", "1.406"], ["70632.80", "0.210"], ["70634.30", "0.007"], ["70634.40", "0.636"], ["70634.80", "0.005"], ["70634.90", "0.036"], ["70635.00", "3.965"], ["70638.30", "1.082"], ["70639.60", "0.001"], ["70642.70", "0.002"], ["70645.40", "1.532"]], "a": [["70656.10", "0.003"], ["70659.60", "0.002"], ["70669.70", "0.665"], ["70670.30", "0.000"], ["70671.30", "0.000"], ["70671.80", "0.512"], ["70672.70", "0.002"], ["70674.10", "0.079"], ["70675.10", "0.532"], ["70676.60", "0.328"], ["70677.20", "0.317"], ["70677.30", "0.273"], ["70677.90", "0.019"], ["70680.80", "0.094"], ["70681.80", "0.043"], ["70705.80", "3.625"], ["70726.40", "0.094"], ["70733.50", "0.131"], ["70740.50", "0.159"], ["70777.20", "0.211"], ["71352.00", "1.400"], ["71493.20", "0.977"], ["71672.70", "0.000"], ["74180.50", "0.050"]]}}
{"local_ts": 1773486965380, "server_ts": 1773486965350, "data": {"e": "depthUpdate", "E": 1773486965351, "T": 1773486965350, "s": "BTCUSDT", "U": 10109533377074, "u": 10109533381133, "pu": 10109533377049, "b": [["5000.00", "101.418"], ["7064.60", "0.000"], ["20245.40", "0.090"], ["20345.40", "2.380"], ["20445.40", "0.530"], ["20445.50", "0.007"], ["67088.50", "0.000"], ["68858.10", "0.000"], ["69938.90", "1.428"], ["70292.10", "0.147"], ["70399.10", "0.000"], ["70465.30", "2.487"], ["70470.60", "0.004"], ["70471.10", "3.973"], ["70509.70", "0.000"], ["70509.90", "0.827"], ["70549.70", "0.714"], ["70556.70", "0.579"], ["70563.80", "0.089"], ["70599.80", "0.181"], ["70600.00", "0.952"], ["70631.60", "0.269"], ["70634.80", "0.005"], ["70635.40", "0.356"], ["70636.10", "0.060"], ["70638.20", "0.212"]], "a": [["70656.10", "0.000"], ["70677.30", "0.203"], ["70726.40", "0.094"], ["70733.50", "0.131"], ["70740.50", "0.159"], ["70777.20", "0.208"], ["70816.10", "1.165"], ["70856.10", "0.007"], ["71059.70", "0.004"], ["71202.10", "0.000"], ["71249.90", "3.243"], ["71352.00", "1.400"], ["71710.10", "0.000"]]}}
{"local_ts": 1773486966405, "server_ts": 1773486966372, "data": {"e": "depthUpdate", "E": 1773486966375, "T": 1773486966372, "s": "BTCUSDT", "U": 10109533425372, "u": 10109533429252, "pu": 10109533425323, "b": [["1000.00", "27.292"], ["5000.00", "101.418"], ["7064.60", "0.000"], ["20245.40", "2.120"], ["20345.40", "0.880"], ["33000.00", "3.789"], ["67087.40", "0.000"], ["67113.00", "0.000"], ["69515.10", "1.015"], ["69566.60", "0.002"], ["69649.30", "0.639"], ["69938.90", "1.428"], ["70292.20", "1.166"], ["70292.30", "0.205"], ["70406.30", "0.004"], ["70446.80", "0.000"], ["70447.50", "0.227"], ["70462.70", "16.976"], ["70468.80", "0.173"], ["70510.10", "1.312"], ["70510.20", "0.655"], ["70552.70", "1.179"], ["70559.70", "0.142"], ["70566.80", "3.200"], ["70599.50", "0.395"], ["70603.00", "0.369"], ["70610.10", "0.083"], ["70617.10", "0.079"], ["70625.60", "0.202"], ["70626.80", "0.000"], ["70634.80", "0.005"], ["70635.60", "0.007"], ["70636.40", "0.005"], ["70636.60", "0.073"], ["70638.20", "0.209"], ["70638.30", "1.140"], ["70638.50", "0.004"], ["70640.10", "0.001"], ["70642.10", "0.000"], ["70642.70", "0.002"], ["70645.40", "1.817"]], "a": [["70645.80", "0.006"], ["70650.90", "0.061"], ["70670.20", "0.065"], ["70722.30", "6.303"], ["70722.40", "0.265"], ["70729.40", "0.084"], ["70729.50", "0.142"], ["70736.40", "0.127"], ["70736.50", "0.142"], ["70777.30", "0.209"], ["70869.40", "0.000"], ["71202.70", "0.007"], ["71352.00", "1.400"], ["74185.60", "0.002"], ["89523.20", "0.000"]]}}
{"local_ts": 1773486967422, "server_ts": 1773486967393, "data": {"e": "depthUpdate", "E": 1773486967395, "T": 1773486967393, "s": "BTCUSDT", "U": 10109533475861, "u": 10109533480105, "pu": 10109533475830, "b": [["5000.00", "101.418"], ["7064.60", "0.000"], ["20145.40", "1.670"], ["20245.40", "1.330"], ["69479.80", "1.006"], ["69503.30", "2.441"], ["69609.20", "10.473"], ["69621.00", "8.750"], ["69691.70", "0.853"], ["69938.90", "2.142"], ["69939.00", "0.004"], ["70292.10", "0.147"], ["70399.10", "0.000"], ["70599.90", "0.004"], ["70600.30", "0.241"], ["70610.10", "0.051"], ["70616.80", "0.053"], ["70622.40", "0.003"], ["70623.30", "0.249"], ["70634.20", "0.003"], ["70634.30", "0.005"], ["70634.90", "0.038"], ["70635.10", "0.638"], ["70638.30", "1.067"], ["70645.40", "1.911"]], "a": [["70655.90", "0.010"], ["70656.10", "0.000"], ["70660.00", "0.002"], ["70660.20", "0.002"], ["70671.30", "0.000"], ["70671.80", "0.512"], ["70699.20", "0.003"], ["70699.40", "0.085"], ["71339.80", "0.000"], ["71352.00", "2.100"], ["71706.90", "0.004"], ["71710.80", "0.418"], ["71740.50", "3.272"], ["71941.20", "1.388"], ["74202.80", "0.002"], ["74211.80", "0.266"], ["89523.20", "0.000"]]}}
{"local_ts": 1773486968445, "server_ts": 1773486968418, "data": {"e": "depthUpdate", "E": 1773486968419, "T": 1773486968418, "s": "BTCUSDT", "U": 10109533516608, "u": 10109533519647, "pu": 10109533516529, "b": [["1000.00", "27.292"], ["5000.00", "101.438"], ["7064.60", "0.056"], ["20145.40", "1.770"], ["20545.40", "1.230"], ["67111.10", "0.053"], ["69938.90", "2.142"], ["69939.00", "0.000"], ["70292.20", "1.166"], ["70432.60", "0.002"], ["70471.10", "0.000"], ["70471.80", "4.121"], ["70500.60", "11.815"], ["70510.70", "0.683"], ["70549.70", "0.697"], ["70549.80", "0.203"], ["70556.70", "0.508"], ["70556.80", "0.911"], ["70558.60", "6.226"], ["70558.90", "1.974"], ["70563.80", "0.018"], ["70563.90", "0.156"], ["70585.40", "0.011"], ["70586.20", "0.010"], ["70593.50", "3.349"], ["70595.00", "0.962"], ["70599.60", "0.460"], ["70599.70", "0.007"], ["70603.10", "0.007"], ["70607.70", "0.003"], ["70610.10", "0.023"], ["70612.80", "0.040"], ["70614.70", "1.757"], ["70624.30", "0.047"], ["70634.80", "0.002"], ["70638.20", "0.217"], ["70638.50", "0.004"], ["70642.70", "0.002"], ["70645.40", "1.741"]], "a": [["70645.80", "0.008"], ["70656.10", "0.000"], ["70684.50", "1.752"], ["70703.80", "0.817"], ["70705.70", "3.298"], ["70726.40", "0.094"], ["70733.50", "0.131"], ["70740.50", "0.159"], ["70740.60", "6.506"], ["70777.30", "0.333"], ["70799.20", "11.844"], ["70815.00", "0.026"], ["70816.10", "0.002"], ["70816.20", "2.297"], ["70869.40", "0.000"], ["70890.80", "0.007"], ["70897.90", "6.483"], ["70898.40", "0.000"], ["70905.00", "0.209"], ["70905.50", "0.004"], ["70912.10", "0.007"], ["70912.60", "0.274"], ["70919.20", "0.007"], ["70919.70", "0.000"], ["70926.30", "0.009"], ["70926.80", "0.000"], ["70933.40", "0.007"], ["70933.90", "0.000"], ["70940.50", "0.007"], ["70941.00", "0.011"], ["70948.10", "0.000"], ["71352.00", "2.100"], ["71657.70", "6.064"], ["71669.90", "5.093"], ["71684.00", "3.957"], ["71826.90", "0.348"], ["74197.50", "0.052"], ["75222.40", "0.007"], ["89523.20", "0.000"]]}}
{"local_ts": 1773486969470, "server_ts": 1773486969440, "data": {"e": "depthUpdate", "E": 1773486969443, "T": 1773486969440, "s": "BTCUSDT", "U": 10109533558108, "u": 10109533561298, "pu": 10109533557919, "b": [["1000.00", "27.292"], ["5000.00", "101.418"], ["7064.60", "0.056"], ["20445.40", "0.790"], ["20545.40", "2.210"], ["67087.00", "0.002"], ["69938.90", "2.142"], ["70292.30", "0.205"], ["70398.90", "0.004"], ["70433.30", "0.000"], ["70434.90", "0.303"], ["70472.00", "4.131"], ["70510.90", "0.678"], ["70530.00", "0.086"], ["70585.40", "0.011"], ["70587.00", "0.027"], ["70594.80", "0.212"], ["70599.60", "0.460"], ["70599.70", "0.007"], ["70604.30", "0.017"], ["70609.70", "0.089"], ["70609.80", "0.013"], ["70624.60", "0.002"], ["70626.70", "0.043"], ["70634.80", "0.002"], ["70636.60", "0.252"], ["70636.70", "0.003"], ["70638.30", "1.279"], ["70645.40", "1.520"]], "a": [["70645.50", "8.782"], ["70656.10", "0.000"], ["70658.00", "0.199"], ["70665.40", "0.006"], ["70666.00", "2.941"], ["70681.10", "0.000"], ["70777.40", "0.421"], ["70811.50", "0.002"], ["70815.00", "0.026"], ["70816.20", "2.301"], ["70853.10", "0.000"], ["70853.30", "2.910"], ["70889.20", "0.007"], ["70890.80", "0.000"], ["70896.30", "0.007"], ["70897.90", "6.476"], ["70903.40", "2.591"], ["70905.00", "0.202"], ["70910.50", "1.130"], ["70912.10", "0.000"], ["70917.60", "0.177"], ["70919.20", "0.000"], ["70924.70", "0.007"], ["70926.30", "0.002"], ["70931.80", "0.015"], ["70933.40", "0.000"], ["70938.90", "1.007"], ["70940.50", "0.000"], ["71352.00", "3.499"], ["71728.30", "0.905"], ["72058.40", "0.014"], ["74188.90", "0.000"], ["89523.20", "0.000"]]}}
{"local_ts": 1773486970489, "server_ts": 1773486970461, "data": {"e": "depthUpdate", "E": 1773486970463, "T": 1773486970461, "s": "BTCUSDT", "U": 10109533603125, "u": 10109533607339, "pu": 10109533603072, "b": [["5000.00", "101.418"], ["7064.60", "0.056"], ["20345.40", "0.380"], ["20445.40", "2.580"], ["20545.40", "0.040"], ["67095.80", "0.000"], ["69567.50", "0.482"], ["69785.80", "3.862"], ["69938.90", "2.142"], ["70292.10", "0.147"], ["70465.30", "2.646"], ["70510.90", "0.000"], ["70511.10", "0.678"], ["70567.70", "0.004"], ["70581.80", "0.000"], ["70593.40", "3.359"], ["70595.00", "0.960"], ["70599.30", "0.003"], ["70599.50", "0.582"], ["70600.10", "0.176"], ["70600.20", "0.188"], ["70603.00", "0.644"], ["70613.90", "0.015"], ["70615.20", "0.020"], ["70616.40", "0.015"], ["70617.10", "0.122"], ["70620.70", "0.116"], ["70622.00", "0.145"], ["70622.60", "0.004"], ["70625.00", "0.072"], ["70625.70", "1.212"], ["70626.20", "0.014"], ["70626.40", "0.001"], ["70626.60", "0.145"], ["70627.90", "0.135"], ["70628.10", "0.007"], ["70628.60", "0.082"], ["70628.70", "0.220"], ["70629.00", "0.455"], ["70629.30", "0.002"], ["70630.50", "0.916"], ["70630.90", "0.014"], ["70631.20", "0.000"], ["70631.50", "0.312"], ["70631.60", "0.269"], ["70632.30", "0.623"], ["70633.30", "0.016"], ["70634.70", "0.002"], ["70634.80", "0.002"], ["70634.90", "0.057"], ["70635.40", "0.002"], ["70636.60", "0.073"], ["70636.90", "0.023"], ["70637.40", "0.004"], ["70638.00", "0.958"], ["70638.20", "0.217"], ["70638.30", "0.862"], ["70638.40", "0.459"], ["70638.50", "0.004"], ["70638.60", "0.003"], ["70640.10", "0.001"], ["70641.30", "0.006"], ["70642.60", "0.001"], ["70645.40", "1.497"]], "a": [["70645.50", "8.010"], ["70647.80", "0.011"], ["70649.00", "0.000"], ["70655.80", "0.012"], ["70656.10", "0.003"], ["70658.00", "0.202"], ["70659.50", "0.085"], ["70667.70", "0.021"], ["70670.20", "0.145"], ["70677.30", "0.203"], ["70705.80", "0.211"], ["70705.90", "3.337"], ["70709.10", "0.000"], ["70723.20", "0.144"], ["70777.40", "0.333"], ["70867.10", "0.007"], ["70889.20", "0.000"], ["70890.10", "0.279"], ["70896.30", "0.000"], ["70897.20", "0.007"], ["70903.40", "2.584"], ["70904.30", "0.011"], ["70909.50", "0.000"], ["70910.50", "1.123"], ["70911.40", "0.036"], ["70917.60", "0.170"], ["70918.50", "0.007"], ["70924.70", "0.000"], ["70925.60", "0.007"], ["70931.80", "0.008"], ["70932.70", "0.007"], ["70938.90", "1.000"], ["70939.80", "0.007"], ["71352.00", "3.499"], ["71762.70", "0.602"], ["71862.00", "4.181"], ["74183.20", "0.002"], ["89523.20", "0.000"]]}}
{"local_ts": 1773486971515, "server_ts": 1773486971484, "data": {"e": "depthUpdate", "E": 1773486971487, "T": 1773486971484, "s": "BTCUSDT", "U": 10109533648525, "u": 10109533652213, "pu": 10109533648502, "b": [["1000.00", "26.892"], ["5000.00", "101.418"], ["7064.60", "0.028"], ["20245.40", "0.210"], ["20345.40", "2.480"], ["20445.40", "0.310"], ["33000.00", "3.785"], ["56516.00", "0.000"], ["69349.70", "1.439"], ["69938.90", "2.142"], ["69939.00", "0.004"], ["70292.20", "1.272"], ["70331.00", "0.065"], ["70399.10", "0.000"], ["70585.40", "0.011"], ["70592.30", "3.351"], ["70599.50", "0.340"], ["70599.70", "0.007"], ["70599.90", "0.004"], ["70603.00", "0.505"], ["70613.50", "1.773"], ["70626.10", "0.002"], ["70628.80", "0.056"], ["70634.80", "0.005"], ["70638.10", "0.843"], ["70638.20", "0.217"], ["70638.30", "0.943"], ["70638.50", "0.004"], ["70640.10", "0.001"], ["70642.70", "0.002"]], "a": [["70645.50", "8.157"], ["70656.10", "0.003"], ["70677.30", "0.203"], ["70684.50", "1.758"], ["70705.70", "3.348"], ["70737.30", "0.457"], ["70815.00", "0.026"], ["70889.20", "0.007"], ["70890.10", "0.272"], ["70896.30", "0.007"], ["70897.20", "0.000"], ["70903.40", "2.591"], ["70904.30", "0.004"], ["70910.50", "1.130"], ["70911.40", "0.029"], ["70917.60", "0.177"], ["70918.50", "0.000"], ["70924.70", "0.007"], ["70925.60", "0.000"], ["70931.80", "0.015"], ["70932.70", "0.000"], ["70938.90", "1.007"], ["70939.80", "0.000"], ["71181.00", "0.015"], ["71314.20", "0.082"], ["71352.00", "3.499"], ["74183.20", "0.000"], ["74183.40", "0.977"], ["89523.20", "0.000"]]}}
{"local_ts": 1773486972540, "server_ts": 1773486972510, "data": {"e": "depthUpdate", "E": 1773486972511, "T": 1773486972510, "s": "BTCUSDT", "U": 10109533690384, "u": 10109533694250, "pu": 10109533690380, "b": [["5000.00", "101.418"], ["7064.60", "0.028"], ["20145.40", "0.060"], ["20245.40", "2.340"], ["20345.40", "0.600"], ["67086.30", "0.000"], ["67086.90", "0.004"], ["69232.50", "0.015"], ["69938.90", "2.142"], ["70511.30", "0.511"], ["70567.50", "0.782"], ["70600.20", "0.004"], ["70612.80", "0.044"], ["70613.90", "0.000"], ["70617.10", "0.026"], ["70628.40", "0.093"], ["70631.20", "0.053"], ["70631.50", "0.312"], ["70631.70", "0.000"], ["70634.80", "0.002"], ["70636.60", "0.240"], ["70638.20", "0.220"], ["70638.30", "1.304"], ["70638.50", "0.004"], ["70642.70", "0.002"]], "a": [["70645.50", "10.094"], ["70652.60", "0.002"], ["70656.10", "0.000"], ["70668.80", "0.000"], ["70675.90", "0.626"], ["70677.90", "0.019"], ["70678.40", "0.448"], ["70777.50", "0.000"], ["70885.70", "0.113"], ["70889.20", "0.000"], ["70896.30", "0.000"], ["70897.60", "0.009"], ["70903.40", "2.584"], ["70904.70", "0.007"], ["70910.50", "1.123"], ["70911.80", "0.009"], ["70917.60", "0.170"], ["70918.90", "0.007"], ["70924.70", "0.000"], ["70926.00", "0.173"], ["70931.80", "0.008"], ["70933.10", "0.007"], ["70938.90", "1.000"], ["70940.20", "0.014"], ["70947.30", "0.007"], ["71352.00", "3.499"], ["71608.10", "0.000"], ["89523.20", "0.000"]]}}
{"local_ts": 1773486973558, "server_ts": 1773486973528, "data": {"e": "depthUpdate", "E": 1773486973531, "T": 1773486973528, "s": "BTCUSDT", "U": 10109533723949, "u": 10109533727145, "pu": 10109533723942, "b": [["1000.00", "26.892"], ["5000.00", "101.418"], ["7064.60", "0.028"], ["20145.40", "2.010"], ["20245.40", "0.990"], ["33000.00", "3.785"], ["56516.00", "0.000"], ["67111.30", "0.002"], ["69938.90", "2.142"], ["70098.70", "0.003"], ["70292.10", "0.147"], ["70292.20", "1.166"], ["70292.30", "0.209"], ["70399.40", "0.000"], ["70511.50", "0.676"], ["70595.80", "0.002"], ["70599.00", "0.226"], ["70599.60", "0.460"], ["70599.70", "0.007"], ["70604.30", "0.017"], ["70609.00", "0.155"], ["70609.10", "0.003"], ["70609.20", "0.206"], ["70620.70", "0.005"], ["70626.00", "0.002"], ["70634.80", "0.002"], ["70636.60", "0.240"], ["70638.20", "0.215"], ["70638.30", "1.026"], ["70638.50", "0.004"], ["70640.10", "0.140"], ["70642.70", "0.002"], ["70645.40", "1.611"]], "a": [["70645.50", "10.051"], ["70646.40", "0.002"], ["70653.50", "0.012"], ["70656.10", "0.000"], ["70659.50", "0.085"], ["70664.80", "0.000"], ["70678.00", "0.301"], ["70698.50", "0.127"], ["70698.80", "0.001"], ["70777.50", "0.330"], ["70869.00", "0.019"], ["70885.70", "0.007"], ["71004.40", "0.000"], ["71337.70", "0.000"], ["71352.00", "3.499"], ["71860.60", "0.902"], ["89523.20", "0.006"]]}}
{"local_ts": 1773486974580, "server_ts": 1773486974552, "data": {"e": "depthUpdate", "E": 1773486974553, "T": 1773486974552, "s": "BTCUSDT", "U": 10109533761518, "u": 10109533764694, "pu": 10109533761480, "b": [["1000.00", "26.892"], ["5000.00", "101.418"], ["7064.60", "0.000"], ["20145.40", "1.440"], ["20545.40", "1.560"], ["56516.00", "0.000"], ["67111.30", "0.000"], ["67113.20", "0.006"], ["68846.80", "0.005"], ["69938.90", "2.142"], ["69939.00", "0.000"], ["70292.30", "0.205"], ["70300.00", "21.831"], ["70399.10", "0.004"], ["70432.60", "0.006"], ["70468.80", "0.014"], ["70599.00", "0.240"], ["70599.90", "0.004"], ["70600.10", "0.360"], ["70617.70", "0.030"], ["70625.70", "1.205"], ["70626.20", "0.674"], ["70626.40", "0.001"], ["70629.50", "1.007"], ["70630.00", "0.430"], ["70630.90", "0.000"], ["70631.50", "0.312"], ["70636.60", "0.076"], ["70639.20", "0.526"], ["70644.90", "0.010"], ["70645.40", "1.762"]], "a": [["70645.90", "0.096"], ["70656.10", "0.003"], ["70657.90", "0.003"], ["71352.00", "4.898"], ["71881.80", "1.118"], ["89523.20", "0.006"]]}}
{"local_ts": 1773486975600, "server_ts": 1773486975574, "data": {"e": "depthUpdate", "E": 1773486975575, "T": 1773486975574, "s": "BTCUSDT", "U": 10109533797503, "u": 10109533800842, "pu": 10109533797458, "b": [["5000.00", "101.418"], ["7064.60", "0.000"], ["20445.40", "1.120"], ["20545.40", "1.880"], ["33000.00", "3.789"], ["56516.00", "0.000"], ["67088.70", "0.008"], ["67113.10", "0.004"], ["69938.90", "2.142"], ["70080.20", "0.148"], ["70465.30", "2.646"], ["70473.00", "4.231"], ["70511.80", "0.707"], ["70599.70", "0.007"], ["70599.80", "0.183"], ["70609.20", "0.206"], ["70609.30", "0.167"], ["70612.70", "0.016"], ["70613.90", "0.015"], ["70616.90", "0.055"], ["70623.10", "0.268"], ["70623.20", "0.197"], ["70623.30", "0.002"], ["70624.70", "0.055"], ["70625.70", "0.002"], ["70626.30", "1.375"], ["70626.40", "0.001"], ["70634.90", "0.038"], ["70635.50", "0.003"], ["70636.60", "0.076"], ["70638.50", "0.000"], ["70639.20", "0.524"], ["70642.90", "0.001"], ["70645.40", "1.769"]], "a": [["70645.50", "8.305"], ["70646.60", "0.146"], ["70647.20", "0.009"], ["70651.40", "0.021"], ["70652.60", "0.002"], ["70658.40", "0.024"], ["70662.00", "0.014"], ["70663.80", "0.023"], ["70669.00", "0.002"], ["70669.30", "0.571"], ["70678.40", "0.448"], ["70679.40", "0.272"], ["70777.50", "0.331"], ["70816.40", "2.251"], ["70885.60", "5.797"], ["70998.60", "0.007"], ["71352.00", "4.898"], ["72058.40", "0.017"], ["73471.30", "0.024"], ["89523.20", "0.006"]]}}
{"local_ts": 1773486976624, "server_ts": 1773486976596, "data": {"e": "depthUpdate", "E": 1773486976597, "T": 1773486976596, "s": "BTCUSDT", "U": 10109533832002, "u": 10109533835911, "pu": 10109533831919, "b": [["1000.00", "26.892"], ["5000.00", "101.418"], ["7064.60", "0.000"], ["20345.40", "0.680"], ["20445.40", "2.320"], ["20545.40", "0.000"], ["56516.00", "0.000"], ["67103.80", "0.002"], ["69938.90", "2.142"], ["70115.60", "2.136"], ["70292.20", "1.166"], ["70567.70", "0.004"], ["70581.80", "0.005"], ["70600.10", "0.360"], ["70600.30", "0.186"], ["70603.00", "0.505"], ["70622.90", "0.249"], ["70624.50", "0.003"], ["70625.60", "0.217"], ["70628.10", "0.000"], ["70629.50", "0.641"], ["70630.80", "0.023"], ["70631.40", "0.041"], ["70631.50", "0.398"], ["70634.80", "0.005"], ["70636.60", "0.252"], ["70636.80", "0.035"], ["70637.20", "0.000"], ["70638.10", "0.843"], ["70638.30", "0.943"], ["70638.50", "0.002"], ["70639.30", "0.010"], ["70642.90", "0.001"], ["70645.40", "1.765"]], "a": [["70645.50", "8.353"], ["70651.40", "0.011"], ["70652.60", "0.004"], ["70656.10", "0.000"], ["70668.50", "0.519"], ["70669.00", "0.000"], ["70709.10", "0.000"], ["70723.20", "0.144"], ["70998.60", "0.000"], ["71351.90", "0.007"], ["71352.00", "4.898"], ["74203.70", "0.000"]]}}
{"local_ts": 1773486977646, "server_ts": 1773486977616, "data": {"e": "depthUpdate", "E": 1773486977617, "T": 1773486977616, "s": "BTCUSDT", "U": 10109533867535, "u": 10109533876568, "pu": 10109533867497, "b": [["5000.00", "101.418"], ["7064.60", "0.056"], ["20245.40", "0.310"], ["20345.40", "2.600"], ["20445.40", "0.090"], ["56516.00", "0.000"], ["67106.40", "0.002"], ["67113.00", "0.000"], ["69232.50", "0.009"], ["69656.40", "2.821"], ["69656.50", "0.000"], ["69938.90", "2.142"], ["70226.80", "0.000"], ["70399.40", "0.004"], ["70512.20", "0.000"], ["70594.30", "8.512"], ["70595.00", "2.186"], ["70595.40", "0.005"], ["70595.80", "0.005"], ["70596.60", "0.001"], ["70597.90", "0.003"], ["70598.20", "2.038"], ["70599.10", "0.224"], ["70600.10", "0.360"], ["70600.20", "0.190"], ["70600.30", "0.227"], ["70600.40", "0.271"], ["70601.60", "0.019"], ["70602.90", "0.018"], ["70603.00", "0.550"], ["70604.20", "0.018"], ["70605.40", "0.102"], ["70606.70", "0.032"], ["70607.40", "0.052"], ["70607.90", "0.006"], ["70608.00", "0.019"], ["70608.10", "0.003"], ["70609.10", "0.024"], ["70609.20", "0.306"], ["70609.50", "0.000"], ["70610.10", "0.085"], ["70610.30", "0.049"], ["70610.60", "0.064"], ["70611.10", "0.023"], ["70611.40", "0.003"], ["70612.00", "0.002"], ["70612.70", "0.001"], ["70613.00", "0.320"], ["70613.30", "0.000"], ["70613.70", "0.004"], ["70613.90", "0.000"], ["70614.30", "0.077"], ["70615.20", "0.005"], ["70615.50", "0.000"], ["70616.50", "0.002"], ["70617.10", "0.122"], ["70617.70", "0.015"], ["70618.30", "0.002"], ["70619.00", "0.004"], ["70620.20", "0.045"], ["70620.70", "0.120"], ["70620.90", "0.249"], ["70621.20", "0.148"], ["70621.50", "0.000"], ["70622.20", "0.002"], ["70623.00", "0.010"], ["70623.10", "0.058"], ["70624.50", "1.206"], ["70624.70", "0.062"], ["70624.80", "0.007"], ["70625.00", "0.072"], ["70625.10", "0.009"], ["70625.20", "0.059"], ["70625.30", "0.022"], ["70625.50", "0.541"], ["70625.60", "0.223"], ["70625.70", "0.002"], ["70625.80", "0.509"], ["70626.30", "0.246"], ["70626.80", "0.000"], ["70627.10", "0.008"], ["70627.30", "0.000"], ["70627.50", "0.014"], ["70627.90", "0.135"], ["70628.10", "0.141"], ["70628.40", "0.007"], ["70628.70", "0.057"], ["70628.90", "0.311"], ["70629.20", "0.000"], ["70629.30", "0.010"], ["70629.40", "0.001"], ["70629.70", "0.001"], ["70629.80", "0.018"], ["70630.00", "0.370"], ["70630.60", "0.112"], ["70631.20", "0.000"], ["70631.40", "0.288"], ["70631.60", "0.355"], ["70631.70", "0.000"], ["70632.80", "0.212"], ["70633.20", "0.741"], ["70633.30", "0.016"], ["70633.40", "0.015"], ["70634.10", "0.000"], ["70634.70", "0.000"], ["70634.80", "0.005"], ["70634.90", "0.018"], ["70635.20", "0.797"], ["70636.50", "0.678"], ["70636.60", "0.252"], ["70637.60", "0.020"], ["70637.80", "0.008"], ["70638.20", "0.009"], ["70638.30", "0.789"], ["70638.40", "0.002"], ["70638.50", "0.006"], ["70639.00", "0.000"], ["70639.30", "0.008"], ["70639.50", "0.004"], ["70640.20", "0.000"], ["70641.10", "0.000"], ["70641.60", "0.218"], ["70642.40", "0.001"], ["70644.30", "0.000"], ["70644.50", "0.002"], ["70645.10", "0.100"], ["70645.30", "0.004"], ["70645.40", "0.039"]], "a": [["70645.50", "8.809"], ["70646.30", "0.307"], ["70647.20", "0.001"], ["70647.70", "0.007"], ["70648.60", "0.006"], ["70648.70", "0.005"], ["70649.10", "0.203"], ["70650.90", "0.026"], ["70651.00", "0.207"], ["70652.60", "0.002"], ["70654.10", "0.005"], ["70655.70", "0.001"], ["70655.90", "0.007"], ["70656.00", "0.003"], ["70656.10", "0.000"], ["70656.40", "0.007"], ["70656.80", "0.142"], ["70657.10", "0.003"], ["70658.00", "0.201"], ["70658.70", "0.202"], ["70660.70", "0.000"], ["70662.60", "0.208"], ["70663.60", "0.144"], ["70665.00", "0.010"], ["70665.30", "0.119"], ["70667.20", "1.079"], ["70668.50", "0.517"], ["70668.80", "0.636"], ["70669.90", "0.597"], ["70670.00", "0.106"], ["70670.20", "0.145"], ["70671.30", "0.000"], ["70672.60", "0.000"], ["70673.10", "1.658"], ["70673.80", "0.542"], ["70675.60", "0.039"], ["70675.90", "0.626"], ["70676.50", "0.247"], ["70676.60", "0.398"], ["70677.50", "0.025"], ["70677.80", "0.000"], ["70678.30", "0.009"], ["70679.00", "0.182"], ["70679.70", "0.039"], ["70680.20", "0.005"], ["70680.40", "0.091"], ["70680.70", "0.010"], ["70682.90", "0.006"], ["70698.20", "0.031"], ["70698.50", "0.148"], ["70705.30", "0.002"], ["70705.70", "0.000"], ["70706.40", "1.892"], ["70707.50", "8.673"], ["70710.80", "0.016"], ["70711.40", "0.003"], ["70724.40", "1.005"], ["70731.60", "0.003"], ["70733.80", "0.194"], ["70737.30", "0.351"], ["70739.80", "0.000"], ["70745.60", "0.188"], ["70885.70", "0.007"], ["70968.20", "0.000"], ["71352.00", "4.898"], ["71658.60", "7.663"], ["72378.20", "0.000"], ["74186.80", "0.008"]]}}
{"local_ts": 1773486978663, "server_ts": 1773486978633, "data": {"e": "depthUpdate", "E": 1773486978637, "T": 1773486978633, "s": "BTCUSDT", "U": 10109533939374, "u": 10109533944596, "pu": 10109533939257, "b": [["1000.00", "26.892"], ["5000.00", "101.398"], ["7064.60", "0.056"], ["20145.40", "0.160"], ["20245.40", "2.450"], ["20345.40", "0.390"], ["56516.00", "0.000"], ["69862.20", "0.818"], ["69938.90", "3.570"], ["70292.20", "1.166"], ["70327.50", "0.159"], ["70549.80", "0.203"], ["70556.80", "0.911"], ["70563.90", "0.156"], ["70599.60", "0.458"], ["70599.70", "0.009"], ["70620.70", "0.009"], ["70621.60", "0.075"], ["70621.70", "0.000"], ["70621.90", "0.004"], ["70638.30", "0.817"], ["70638.50", "0.006"], ["70639.30", "0.012"], ["70642.70", "0.002"], ["70645.40", "0.250"]], "a": [["70645.50", "8.398"], ["70646.70", "0.026"], ["70647.10", "0.007"], ["70648.50", "0.034"], ["70652.60", "0.002"], ["70653.40", "0.048"], ["70667.20", "1.077"], ["70669.60", "0.023"], ["70698.50", "0.042"], ["70721.90", "1.070"], ["70724.40", "1.003"], ["70726.50", "0.071"], ["70733.60", "0.071"], ["70740.60", "0.071"], ["70885.60", "5.797"], ["71351.90", "0.050"], ["71352.00", "4.898"], ["71582.50", "0.281"], ["74207.20", "0.003"]]}}
{"local_ts": 1773486979686, "server_ts": 1773486979656, "data": {"e": "depthUpdate", "E": 1773486979659, "T": 1773486979656, "s": "BTCUSDT", "U": 10109533999906, "u": 10109534004662, "pu": 10109533999846, "b": [["1000.00", "26.892"], ["5000.00", "101.418"], ["7064.20", "0.056"], ["20142.00", "1.960"], ["20145.40", "0.310"], ["20245.40", "0.620"], ["20542.00", "0.020"], ["67105.90", "0.002"], ["69935.60", "0.000"], ["70331.20", "0.106"], ["70465.40", "16.611"], ["70549.80", "0.203"], ["70556.80", "0.911"], ["70563.90", "0.156"], ["70608.20", "0.102"], ["70608.50", "0.544"], ["70608.60", "0.100"], ["70626.20", "0.014"], ["70633.70", "0.001"], ["70636.10", "0.014"], ["70639.30", "0.018"], ["70639.40", "0.063"], ["70640.60", "0.215"]], "a": [["70648.50", "0.006"], ["70655.10", "0.008"], ["70656.90", "0.002"], ["70657.10", "0.005"], ["70657.90", "0.142"], ["70662.10", "0.163"], ["70666.70", "0.002"], ["70669.60", "0.000"], ["70697.90", "0.003"], ["70698.00", "0.600"], ["70721.90", "1.068"], ["70724.30", "0.002"], ["70726.50", "0.071"], ["70733.60", "0.071"], ["70740.60", "0.071"], ["71669.90", "17.492"], ["71695.50", "1.934"], ["71801.50", "0.000"]]}}
{"local_ts": 1773486980707, "server_ts": 1773486980678, "data": {"e": "depthUpdate", "E": 1773486980679, "T": 1773486980678, "s": "BTCUSDT", "U": 10109534047714, "u": 10109534054432, "pu": 10109534047676, "b": [["5000.00", "101.418"], ["7064.20", "0.028"], ["20142.00", "1.120"], ["20542.00", "1.880"], ["33000.00", "3.785"], ["56514.00", "0.000"], ["67109.90", "0.013"], ["68857.50", "2.610"], ["69935.60", "0.000"], ["70509.70", "0.637"], ["70510.60", "8.584"], ["70510.70", "0.005"], ["70564.30", "0.137"], ["70567.70", "0.004"], ["70572.00", "0.004"], ["70575.30", "0.004"], ["70576.20", "0.039"], ["70578.40", "1.017"], ["70581.80", "0.005"], ["70593.70", "0.511"], ["70597.00", "0.217"], ["70597.10", "0.004"], ["70598.10", "0.234"], ["70603.10", "0.162"], ["70606.30", "0.013"], ["70608.50", "0.629"], ["70608.60", "0.015"], ["70628.40", "0.010"], ["70629.00", "0.005"], ["70631.80", "0.360"], ["70632.30", "0.405"], ["70636.80", "0.010"], ["70636.90", "0.017"], ["70638.50", "0.200"], ["70639.30", "0.018"], ["70641.10", "0.003"]], "a": [["70642.10", "6.784"], ["70643.70", "0.079"], ["70676.70", "0.012"], ["70677.80", "0.000"], ["70705.70", "0.003"], ["70709.10", "0.003"], ["70719.80", "0.003"], ["70723.20", "0.144"], ["70724.00", "0.018"], ["70724.30", "0.000"], ["70776.40", "0.312"], ["70777.90", "9.807"], ["70778.20", "0.016"], ["70892.60", "0.299"], ["71348.50", "0.000"], ["73467.60", "0.000"], ["74177.60", "0.000"]]}}
{"local_ts": 1773486981726, "server_ts": 1773486981696, "data": {"e": "depthUpdate", "E": 1773486981699, "T": 1773486981696, "s": "BTCUSDT", "U": 10109534107226, "u": 10109534111687, "pu": 10109534107166, "b": [["1000.00", "26.892"], ["5000.00", "101.418"], ["7064.20", "0.028"], ["20442.00", "1.430"], ["20542.00", "1.570"], ["67089.90", "0.012"], ["69433.50", "0.002"], ["69699.60", "1.435"], ["70288.80", "0.006"], ["70465.40", "16.611"], ["70509.80", "0.842"], ["70570.60", "0.124"], ["70593.70", "0.515"], ["70604.50", "0.002"], ["70613.70", "0.319"], ["70631.30", "0.347"], ["70632.80", "0.229"], ["70633.00", "0.001"], ["70633.10", "0.456"], ["70635.10", "1.068"], ["70635.40", "0.006"], ["70636.70", "0.001"], ["70638.90", "0.007"], ["70639.60", "0.003"], ["70642.00", "1.245"]], "a": [["70642.10", "6.692"], ["70643.70", "0.090"], ["70645.50", "2.676"], ["70649.20", "0.002"], ["70655.00", "0.044"], ["70655.10", "0.008"], ["70655.30", "0.003"], ["70657.80", "0.143"], ["70657.90", "0.001"], ["70658.10", "0.454"], ["70681.00", "0.102"], ["70685.30", "0.050"], ["70715.60", "0.036"], ["70719.30", "0.055"], ["70724.00", "0.016"], ["70776.20", "0.336"], ["71348.50", "0.000"], ["74204.10", "0.000"]]}}
{"local_ts": 1773486982745, "server_ts": 1773486982716, "data": {"e": "depthUpdate", "E": 1773486982719, "T": 1773486982716, "s": "BTCUSDT", "U": 10109534160482, "u": 10109534165443, "pu": 10109534160401, "b": [["5000.00", "101.418"], ["7064.20", "0.028"], ["20342.00", "0.980"], ["20442.00", "2.020"], ["33000.00", "3.789"], ["69232.50", "0.009"], ["69554.40", "0.010"], ["69794.30", "0.429"], ["69935.60", "0.000"], ["70076.90", "0.226"], ["70145.80", "0.002"], ["70590.00", "1.750"], ["70608.60", "0.015"], ["70608.70", "1.672"], ["70608.80", "0.825"], ["70609.70", "0.000"], ["70609.80", "7.859"], ["70615.30", "0.016"], ["70626.20", "0.674"], ["70626.50", "0.073"], ["70628.30", "0.052"], ["70638.00", "0.841"], ["70640.00", "0.004"]], "a": [["70643.70", "0.061"], ["70644.30", "0.021"], ["70698.10", "0.002"], ["70698.20", "0.096"], ["71207.20", "0.070"], ["71348.50", "0.000"], ["71489.80", "0.143"], ["71848.90", "0.014"], ["74196.30", "0.002"]]}}
{"local_ts": 1773486983769, "server_ts": 1773486983740, "data": {"e": "depthUpdate", "E": 1773486983741, "T": 1773486983740, "s": "BTCUSDT", "U": 10109534216604, "u": 10109534220568, "pu": 10109534216471, "b": [["1000.00", "26.892"], ["5000.00", "101.418"], ["7064.20", "0.000"], ["20242.00", "0.540"], ["20342.00", "2.460"], ["20442.00", "0.000"], ["67091.30", "0.002"], ["69723.70", "0.869"], ["69725.00", "4.666"], ["69935.60", "1.428"], ["70284.80", "0.852"], ["70288.80", "0.042"], ["70300.00", "21.689"], ["70465.40", "16.611"], ["70549.40", "0.159"], ["70552.90", "0.556"], ["70556.40", "0.213"], ["70559.90", "0.208"], ["70563.50", "0.213"], ["70567.00", "0.217"], ["70610.20", "0.368"], ["70612.00", "0.285"], ["70613.10", "0.008"], ["70613.70", "0.118"], ["70624.30", "0.158"], ["70631.40", "0.185"], ["70632.80", "0.215"], ["70633.10", "0.458"], ["70635.30", "0.021"], ["70638.50", "0.268"], ["70639.60", "0.015"]], "a": [["70676.30", "0.004"], ["70681.00", "0.042"], ["70684.50", "0.004"], ["70719.10", "0.142"], ["70722.50", "0.000"], ["70726.20", "0.393"], ["70729.60", "0.041"], ["70733.20", "0.213"], ["70736.60", "0.065"], ["74195.80", "0.000"]]}}
{"local_ts": 1773486984790, "server_ts": 1773486984764, "data": {"e": "depthUpdate", "E": 1773486984765, "T": 1773486984764, "s": "BTCUSDT", "U": 10109534257911, "u": 10109534262591, "pu": 10109534257825, "b": [["1000.00", "26.892"], ["5000.00", "101.438"], ["7064.20", "0.000"], ["20142.00", "0.270"], ["20242.00", "2.560"], ["20342.00", "0.170"], ["67108.10", "0.000"], ["67113.20", "0.004"], ["69719.20", "67.349"], ["69928.90", "55.135"], ["69935.60", "1.428"], ["70549.30", "0.017"], ["70556.30", "0.455"], ["70563.40", "0.089"], ["70593.70", "0.511"], ["70596.60", "0.001"], ["70596.90", "0.498"], ["70606.30", "0.017"], ["70607.90", "0.008"], ["70608.00", "0.169"], ["70612.00", "0.320"], ["70618.10", "0.000"], ["70619.60", "0.248"], ["70633.10", "0.477"], ["70635.00", "4.014"], ["70635.10", "0.006"], ["70635.50", "0.003"], ["70636.70", "0.001"], ["70636.80", "0.067"], ["70639.60", "0.015"]], "a": [["70645.30", "0.018"], ["70645.50", "2.935"], ["70648.90", "0.100"], ["70697.30", "0.017"], ["70697.40", "0.085"], ["70726.00", "0.372"], ["70733.10", "0.071"], ["70733.90", "0.117"], ["70740.10", "0.126"], ["70837.30", "0.002"], ["70885.80", "0.394"], ["70910.60", "0.719"], ["71348.50", "0.000"], ["71468.60", "0.563"], ["71578.90", "66.104"], ["71666.40", "1.672"], ["74174.60", "0.002"]]}}
{"local_ts": 1773486985813, "server_ts": 1773486985784, "data": {"e": "depthUpdate", "E": 1773486985787, "T": 1773486985784, "s": "BTCUSDT", "U": 10109534303992, "u": 10109534309817, "pu": 10109534303915, "b": [["5000.00", "101.418"], ["7064.20", "0.000"], ["20142.00", "2.410"], ["20242.00", "0.470"], ["20542.00", "0.120"], ["67092.80", "0.002"], ["67102.80", "0.000"], ["67109.90", "0.008"], ["67110.00", "0.093"], ["67816.40", "0.008"], ["69935.60", "1.428"], ["70509.80", "0.791"], ["70527.30", "0.023"], ["70608.00", "0.084"], ["70608.10", "0.003"], ["70608.20", "0.187"], ["70610.20", "0.620"], ["70612.00", "0.285"], ["70616.60", "0.014"], ["70626.90", "0.020"], ["70628.20", "0.015"], ["70629.40", "0.001"], ["70630.80", "0.003"], ["70631.20", "0.751"], ["70631.70", "0.022"], ["70632.10", "0.126"], ["70632.50", "0.235"], ["70632.90", "0.516"], ["70633.20", "0.105"], ["70633.30", "0.073"], ["70634.70", "0.098"], ["70635.10", "0.086"], ["70635.20", "0.799"], ["70635.30", "0.081"], ["70635.50", "0.003"], ["70636.00", "0.000"], ["70636.30", "0.004"], ["70638.00", "0.841"], ["70638.50", "0.187"], ["70639.60", "0.005"], ["70639.80", "0.003"], ["70640.50", "0.006"], ["70641.70", "0.006"]], "a": [["70642.10", "6.258"], ["70643.10", "0.057"], ["70643.80", "0.009"], ["70644.00", "0.006"], ["70649.20", "0.002"], ["70677.40", "0.017"], ["70697.40", "0.000"], ["70697.50", "0.004"], ["70697.60", "0.085"], ["70733.90", "0.011"], ["70740.30", "0.000"], ["70764.40", "0.002"], ["70775.70", "0.401"], ["70837.30", "0.000"], ["71348.50", "0.000"]]}}
{"local_ts": 1773486986838, "server_ts": 1773486986810, "data": {"e": "depthUpdate", "E": 1773486986811, "T": 1773486986810, "s": "BTCUSDT", "U": 10109534368019, "u": 10109534374652, "pu": 10109534367956, "b": [["1000.00", "26.892"], ["5000.00", "101.418"], ["7064.20", "0.056"], ["20142.00", "0.790"], ["20542.00", "2.210"], ["69935.60", "1.428"], ["70288.80", "0.078"], ["70465.40", "16.611"], ["70509.80", "0.134"], ["70527.30", "0.021"], ["70596.40", "0.843"], ["70596.50", "0.073"], ["70607.80", "0.157"], ["70607.90", "0.008"], ["70608.00", "0.084"], ["70610.20", "0.648"], ["70610.30", "0.127"], ["70618.20", "0.000"], ["70619.60", "0.016"], ["70635.50", "0.121"]], "a": [["70642.10", "6.308"], ["70697.20", "0.007"], ["70697.30", "0.102"], ["70697.40", "0.000"], ["70760.30", "0.043"], ["70764.40", "0.000"], ["70775.60", "0.000"], ["70865.80", "0.007"], ["70891.20", "0.002"], ["70912.00", "0.063"], ["71348.50", "0.000"], ["71588.00", "4.043"], ["71666.30", "0.000"], ["71725.80", "0.701"], ["73467.70", "0.014"], ["74194.30", "0.002"], ["74199.90", "0.000"], ["89523.20", "0.006"]]}}
{"local_ts": 1773486987856, "server_ts": 1773486987830, "data": {"e": "depthUpdate", "E": 1773486987831, "T": 1773486987830, "s": "BTCUSDT", "U": 10109534443862, "u": 10109534447697, "pu": 10109534443823, "b": [["5000.00", "101.418"], ["7063.90", "0.056"], ["20438.10", "1.430"], ["20542.00", "1.150"], ["33000.00", "3.785"], ["63561.60", "0.012"], ["63574.30", "0.002"], ["67082.30", "0.008"], ["67113.20", "0.002"], ["70508.10", "0.511"], ["70510.00", "0.842"], ["70552.90", "0.566"], ["70584.80", "0.275"], ["70589.30", "0.008"], ["70606.20", "0.000"], ["70606.30", "0.098"], ["70609.90", "0.004"], ["70610.20", "0.489"], ["70610.30", "0.170"], ["70621.80", "0.085"], ["70622.50", "0.003"], ["70627.50", "0.014"], ["70629.50", "0.753"]], "a": [["70639.90", "0.000"], ["70642.20", "0.061"], ["70643.30", "0.002"], ["70643.90", "0.008"], ["70644.40", "0.021"], ["70645.90", "0.079"], ["70647.30", "0.006"], ["70648.10", "0.284"], ["70648.80", "0.026"], ["70653.80", "0.006"], ["70654.30", "0.144"], ["70654.80", "0.020"], ["70654.90", "0.073"], ["70655.20", "0.117"], ["70655.40", "0.073"], ["70664.70", "0.006"], ["70666.60", "0.000"], ["70675.60", "0.041"], ["70687.50", "1.098"], ["70703.60", "0.002"], ["70706.10", "0.027"], ["70707.80", "1.104"], ["70708.60", "0.039"], ["70746.70", "0.457"], ["70760.30", "0.041"], ["70872.30", "0.002"], ["70912.00", "0.061"], ["71344.60", "0.000"], ["74207.70", "0.000"], ["77686.50", "0.012"], ["77702.00", "0.002"], ["89523.20", "0.006"]]}}
{"local_ts": 1773486988881, "server_ts": 1773486988852, "data": {"e": "depthUpdate", "E": 1773486988853, "T": 1773486988852, "s": "BTCUSDT", "U": 10109534514022, "u": 10109534520260, "pu": 10109534513997, "b": [["1000.00", "26.892"], ["5000.00", "101.418"], ["7063.90", "0.056"], ["20338.10", "1.320"], ["20438.10", "1.680"], ["63574.30", "0.010"], ["67073.10", "0.002"], ["69719.90", "0.860"], ["69931.70", "0.002"], ["70284.90", "0.036"], ["70375.00", "10.273"], ["70567.70", "0.317"], ["70584.20", "0.002"], ["70604.40", "1.937"], ["70611.60", "0.146"], ["70616.20", "0.007"], ["70616.50", "0.002"], ["70622.90", "0.004"], ["70626.00", "0.017"], ["70626.20", "0.018"], ["70628.30", "0.131"], ["70629.70", "0.081"], ["70630.10", "0.005"], ["70632.30", "0.001"], ["70633.60", "0.009"], ["70635.80", "0.639"], ["70638.10", "0.873"]], "a": [["70638.20", "9.935"], ["70641.80", "0.030"], ["70646.30", "0.078"], ["70647.80", "0.004"], ["70661.70", "0.511"], ["70662.30", "0.636"], ["70669.00", "0.047"], ["70673.50", "0.065"], ["70678.70", "1.911"], ["70744.90", "0.004"], ["70746.70", "0.455"], ["70797.10", "0.500"], ["70861.10", "0.008"], ["70872.30", "0.000"], ["71344.60", "0.000"], ["72050.90", "0.003"], ["73650.00", "2.861"], ["77702.00", "0.010"], ["89523.20", "0.006"]]}}
{"local_ts": 1773486989908, "server_ts": 1773486989876, "data": {"e": "depthUpdate", "E": 1773486989879, "T": 1773486989876, "s": "BTCUSDT", "U": 10109534589556, "u": 10109534595040, "pu": 10109534589270, "b": [["1000.00", "26.892"], ["5000.00", "101.418"], ["7063.80", "0.028"], ["20238.00", "0.820"], ["20338.10", "1.510"], ["33000.00", "3.785"], ["56510.00", "0.020"], ["63574.20", "0.002"], ["67099.00", "0.000"], ["67812.60", "0.631"], ["69554.70", "0.000"], ["69931.60", "0.000"], ["70465.00", "0.259"], ["70504.10", "0.870"], ["70592.70", "0.004"], ["70592.90", "0.026"], ["70611.50", "1.580"], ["70615.10", "0.101"], ["70616.30", "1.075"], ["70631.00", "0.057"], ["70635.80", "0.647"]], "a": [["70638.10", "7.583"], ["70638.20", "0.304"], ["70641.50", "0.003"], ["70642.20", "0.003"], ["70654.70", "0.000"], ["70655.20", "0.258"], ["70658.90", "0.080"], ["70673.40", "0.044"], ["70677.00", "0.218"], ["70677.40", "0.017"], ["70694.60", "1.073"], ["70744.90", "0.002"], ["70745.00", "0.007"], ["70770.40", "0.441"], ["70797.00", "0.171"], ["71344.50", "0.015"], ["77701.90", "0.002"], ["89523.20", "0.006"]]}}
{"local_ts": 1773486990943, "server_ts": 1773486990897, "data": {"e": "depthUpdate", "E": 1773486990899, "T": 1773486990897, "s": "BTCUSDT", "U": 10109534649259, "u": 10109534653834, "pu": 10109534649213, "b": [["5000.00", "101.418"], ["7063.80", "0.028"], ["20138.00", "0.440"], ["20238.00", "2.550"], ["20338.00", "0.010"], ["63574.20", "0.002"], ["67090.70", "0.000"], ["67098.30", "0.002"], ["70320.30", "0.004"], ["70504.20", "0.974"], ["70590.30", "0.141"], ["70593.30", "0.047"], ["70593.50", "0.164"], ["70611.40", "0.018"], ["70611.50", "1.719"], ["70615.00", "0.013"], ["70617.70", "0.002"], ["70618.50", "0.023"], ["70619.00", "0.145"], ["70619.30", "0.118"], ["70624.10", "0.022"], ["70628.20", "0.011"], ["70628.40", "0.003"], ["70628.50", "0.001"], ["70635.80", "0.647"]], "a": [["70638.10", "6.693"], ["70676.80", "0.008"], ["70678.80", "0.228"], ["70770.40", "0.467"], ["70830.80", "0.002"], ["70833.20", "2.918"], ["71309.20", "0.769"], ["71344.50", "0.015"], ["77701.90", "0.002"], ["89523.20", "0.006"]]}}
{"local_ts": 1773486991947, "server_ts": 1773486991920, "data": {"e": "depthUpdate", "E": 1773486991921, "T": 1773486991920, "s": "BTCUSDT", "U": 10109534710577, "u": 10109534717926, "pu": 10109534710335, "b": [["1000.00", "26.892"], ["5000.00", "101.418"], ["7063.80", "0.028"], ["20138.00", "2.510"], ["20238.00", "0.250"], ["20538.00", "0.240"], ["33000.00", "3.789"], ["63574.20", "0.002"], ["69931.60", "0.714"], ["70284.80", "0.852"], ["70430.60", "0.004"], ["70464.90", "0.159"], ["70584.10", "0.003"], ["70584.30", "0.068"], ["70585.80", "8.502"], ["70587.90", "1.508"], ["70590.30", "0.141"], ["70596.80", "0.057"], ["70610.90", "0.143"], ["70611.50", "1.580"], ["70611.60", "0.112"], ["70611.70", "0.019"], ["70612.90", "0.476"], ["70613.30", "0.000"], ["70613.90", "0.247"], ["70614.20", "0.061"], ["70614.90", "0.333"], ["70615.00", "1.237"], ["70615.40", "0.013"], ["70615.50", "0.015"], ["70615.70", "0.000"], ["70616.10", "0.000"], ["70616.70", "0.019"], ["70616.90", "0.062"], ["70617.70", "0.002"], ["70617.80", "0.587"], ["70618.00", "0.265"], ["70618.10", "0.007"], ["70618.50", "0.023"], ["70619.00", "0.004"], ["70619.20", "0.015"], ["70619.30", "0.118"], ["70619.50", "0.622"], ["70619.70", "0.070"], ["70620.10", "0.011"], ["70620.80", "0.237"], ["70620.90", "0.020"], ["70621.90", "0.287"], ["70622.30", "1.134"], ["70622.90", "0.004"], ["70623.70", "0.349"], ["70624.10", "0.007"], ["70624.70", "0.005"], ["70624.90", "0.637"], ["70625.40", "0.133"], ["70626.30", "0.408"], ["70626.50", "0.160"], ["70626.60", "0.166"], ["70626.70", "0.148"], ["70626.90", "0.067"], ["70627.20", "0.018"], ["70627.30", "0.008"], ["70627.50", "0.014"], ["70627.70", "0.511"], ["70628.00", "0.022"], ["70628.20", "0.004"], ["70629.50", "0.478"], ["70630.20", "0.006"], ["70630.60", "0.005"], ["70631.20", "0.000"], ["70633.30", "0.008"], ["70634.10", "0.006"], ["70635.00", "3.961"], ["70635.40", "0.002"], ["70635.80", "0.636"], ["70636.80", "0.004"], ["70637.90", "0.000"], ["70638.00", "0.323"]], "a": [["70638.10", "6.906"], ["70638.80", "0.000"], ["70639.20", "0.090"], ["70641.90", "0.053"], ["70643.30", "0.002"], ["70645.00", "0.266"], ["70646.30", "0.241"], ["70646.40", "0.080"], ["70647.30", "0.067"], ["70647.80", "0.040"], ["70648.10", "0.247"], ["70648.20", "0.002"], ["70651.30", "0.004"], ["70660.40", "0.000"], ["70661.20", "0.636"], ["70662.10", "0.511"], ["70662.20", "0.001"], ["70662.30", "0.000"], ["70662.50", "0.000"], ["70664.20", "0.042"], ["70664.60", "0.072"], ["70666.30", "0.000"], ["70666.40", "0.279"], ["70668.40", "0.004"], ["70668.80", "0.000"], ["70669.20", "0.283"], ["70671.40", "0.078"], ["70671.50", "0.789"], ["70674.60", "0.321"], ["70729.90", "0.000"], ["70828.40", "0.008"], ["70830.80", "0.000"], ["71344.50", "0.015"], ["74176.00", "0.052"], ["77701.90", "0.002"], ["89523.20", "0.006"]]}}
{"local_ts": 1773486992970, "server_ts": 1773486992941, "data": {"e": "depthUpdate", "E": 1773486992943, "T": 1773486992941, "s": "BTCUSDT", "U": 10109534798221, "u": 10109534803964, "pu": 10109534798209, "b": [["5000.00", "101.398"], ["7064.40", "0.000"], ["20138.00", "0.550"], ["20443.30", "0.090"], ["20541.50", "0.160"], ["20543.30", "0.300"], ["56515.00", "0.000"], ["63579.00", "0.004"], ["67093.10", "0.002"], ["67105.70", "0.000"], ["67109.40", "0.002"], ["69576.00", "0.021"], ["69936.90", "0.168"], ["70490.40", "0.000"], ["70543.20", "0.004"], ["70545.30", "0.047"], ["70556.10", "0.160"], ["70574.60", "0.002"], ["70582.20", "0.305"], ["70584.30", "0.000"], ["70586.70", "1.202"], ["70590.10", "0.399"], ["70595.60", "0.275"], ["70596.40", "0.845"], ["70603.60", "0.893"], ["70604.60", "0.070"], ["70605.00", "0.003"], ["70605.80", "0.022"], ["70606.20", "0.196"], ["70606.40", "0.266"], ["70617.30", "0.005"], ["70617.40", "0.524"], ["70618.00", "0.111"], ["70618.10", "0.002"], ["70618.60", "0.004"], ["70619.40", "0.210"], ["70619.50", "0.622"], ["70620.10", "0.006"], ["70620.20", "0.026"], ["70626.50", "0.804"], ["70627.80", "0.203"], ["70629.30", "0.085"], ["70630.10", "0.544"], ["70630.30", "0.118"], ["70630.40", "0.066"], ["70632.70", "0.905"], ["70633.20", "0.105"], ["70633.90", "0.003"], ["70635.20", "0.888"], ["70636.20", "0.091"], ["70638.00", "0.257"], ["70638.20", "1.014"], ["70638.70", "0.525"], ["70639.30", "0.004"], ["70639.50", "0.075"], ["70640.00", "0.007"], ["70640.30", "0.005"], ["70640.90", "0.004"], ["70641.30", "0.000"], ["70641.90", "0.001"], ["70643.20", "0.164"]], "a": [["70643.40", "3.517"], ["70643.50", "0.003"], ["70643.80", "0.000"], ["70645.10", "0.000"], ["70645.60", "0.262"], ["70645.80", "0.094"], ["70645.90", "0.078"], ["70650.20", "0.018"], ["70650.30", "0.297"], ["70650.90", "0.001"], ["70651.50", "0.025"], ["70651.70", "0.001"], ["70652.10", "0.005"], ["70652.20", "0.028"], ["70652.40", "0.004"], ["70652.60", "0.041"], ["70652.80", "0.003"], ["70654.00", "0.209"], ["70654.20", "0.000"], ["70654.60", "0.039"], ["70655.50", "0.015"], ["70657.10", "0.002"], ["70660.00", "0.023"], ["70660.40", "0.012"], ["70661.40", "0.005"], ["70662.70", "0.061"], ["70662.80", "0.005"], ["70667.70", "0.057"], ["70670.00", "0.185"], ["70672.50", "0.663"], ["70675.20", "0.163"], ["70676.00", "0.413"], ["70676.90", "0.523"], ["70683.90", "0.022"], ["70685.50", "0.095"], ["70687.70", "0.000"], ["70690.00", "3.654"], ["70690.90", "1.916"], ["70692.80", "0.025"], ["70695.20", "0.006"], ["70695.30", "0.183"], ["70695.60", "0.157"], ["70697.70", "0.003"], ["70700.70", "0.749"], ["70707.20", "0.960"], ["70710.60", "0.044"], ["70713.80", "3.531"], ["70714.50", "1.058"], ["70724.50", "0.025"], ["70726.60", "0.080"], ["70727.90", "0.041"], ["70735.80", "0.040"], ["70828.40", "0.006"], ["70852.20", "0.024"], ["70855.50", "0.000"], ["70988.60", "0.002"], ["70991.30", "0.851"], ["71349.80", "0.000"], ["73469.10", "0.609"], ["77707.70", "0.000"], ["89523.20", "0.006"]]}}
{"local_ts": 1773486993989, "server_ts": 1773486993961, "data": {"e": "depthUpdate", "E": 1773486993963, "T": 1773486993961, "s": "BTCUSDT", "U": 10109534852933, "u": 10109534857477, "pu": 10109534852908, "b": [["1000.00", "26.892"], ["5000.00", "101.418"], ["7064.40", "0.000"], ["20443.30", "2.090"], ["20538.00", "0.910"], ["20539.50", "0.000"], ["20541.50", "0.000"], ["20543.30", "0.000"], ["63579.00", "0.004"], ["67084.90", "0.000"], ["69936.90", "0.168"], ["69938.90", "2.142"], ["70290.10", "0.000"], ["70590.30", "0.187"], ["70608.00", "0.080"], ["70626.20", "0.671"], ["70632.70", "0.908"], ["70636.20", "0.041"], ["70639.10", "0.010"], ["70643.30", "11.953"]], "a": [["70643.40", "1.671"], ["70648.90", "0.004"], ["70649.70", "0.009"], ["70652.10", "0.147"], ["70654.00", "0.209"], ["70654.70", "0.144"], ["70655.70", "0.004"], ["70656.60", "0.021"], ["70656.90", "0.059"], ["70663.90", "0.145"], ["70665.50", "0.146"], ["70671.20", "0.199"], ["70671.70", "0.838"], ["70673.10", "0.016"], ["70678.70", "0.216"], ["70683.60", "0.066"], ["70846.90", "0.006"], ["70852.20", "0.022"], ["71349.80", "0.000"], ["71720.90", "0.834"], ["77707.70", "0.000"], ["89523.20", "0.006"]]}}
{"local_ts": 1773486995014, "server_ts": 1773486994986, "data": {"e": "depthUpdate", "E": 1773486994987, "T": 1773486994986, "s": "BTCUSDT", "U": 10109534909235, "u": 10109534915994, "pu": 10109534909224, "b": [["1000.00", "26.892"], ["5000.00", "101.418"], ["7064.40", "0.000"], ["20343.30", "1.650"], ["20443.30", "1.350"], ["56515.00", "0.000"], ["63579.00", "0.012"], ["67078.10", "0.002"], ["69795.60", "0.572"], ["69929.20", "0.000"], ["69936.90", "0.168"], ["69937.00", "0.004"], ["70078.20", "0.285"], ["70284.90", "0.036"], ["70397.20", "0.000"], ["70419.30", "2.723"], ["70490.00", "0.099"], ["70505.20", "0.078"], ["70505.60", "1.333"], ["70531.10", "0.000"], ["70532.40", "0.000"], ["70539.20", "0.514"], ["70542.90", "0.280"], ["70543.40", "0.000"], ["70543.60", "0.004"], ["70544.30", "0.000"], ["70544.80", "6.799"], ["70545.30", "0.047"], ["70545.60", "0.098"], ["70546.50", "0.093"], ["70546.70", "0.047"], ["70546.90", "0.096"], ["70548.70", "0.372"], ["70548.90", "0.000"], ["70560.70", "0.000"], ["70562.50", "0.002"], ["70562.80", "0.018"], ["70563.50", "0.071"], ["70568.00", "0.076"], ["70570.40", "0.369"], ["70571.00", "0.558"], ["70571.30", "0.000"], ["70572.00", "0.004"], ["70572.30", "0.000"], ["70572.80", "0.087"], ["70572.90", "0.294"], ["70573.20", "0.034"], ["70573.40", "0.000"], ["70574.70", "3.655"], ["70597.50", "0.201"], ["70625.80", "0.028"], ["70629.00", "0.005"], ["70629.10", "0.080"], ["70629.20", "0.000"], ["70629.30", "0.002"], ["70629.50", "0.792"], ["70629.60", "0.392"], ["70629.70", "0.002"], ["70630.10", "0.544"], ["70630.20", "0.005"], ["70630.40", "0.003"], ["70630.60", "0.004"], ["70630.80", "0.002"], ["70639.40", "0.005"]], "a": [["70651.20", "0.002"], ["70651.30", "0.001"], ["70651.50", "0.000"], ["70651.80", "0.010"], ["70652.20", "0.056"], ["70652.30", "0.012"], ["70652.40", "0.004"], ["70652.60", "0.005"], ["70652.70", "0.000"], ["70652.80", "0.003"], ["70652.90", "0.020"], ["70665.60", "0.071"], ["70665.80", "1.579"], ["70671.70", "0.778"], ["70672.50", "0.002"], ["70672.60", "0.000"], ["70673.00", "0.013"], ["70673.60", "0.009"], ["70673.90", "0.003"], ["70674.00", "0.007"], ["70674.10", "0.000"], ["70674.40", "0.002"], ["70674.60", "0.296"], ["70674.80", "0.628"], ["70675.30", "0.032"], ["70676.30", "0.002"], ["70678.50", "0.507"], ["70678.70", "0.117"], ["70679.20", "0.775"], ["70698.40", "0.273"], ["70698.50", "0.042"], ["70699.80", "0.252"], ["70699.90", "0.000"], ["70700.20", "0.017"], ["70700.30", "0.002"], ["70700.80", "0.002"], ["70701.10", "0.004"], ["70701.20", "0.000"], ["70701.80", "0.511"], ["70701.90", "0.005"], ["70702.10", "0.007"], ["70702.80", "0.000"], ["70705.10", "0.013"], ["70709.60", "0.293"], ["70710.60", "0.008"], ["70766.90", "0.000"], ["70775.80", "0.008"], ["70775.90", "0.327"], ["70800.80", "0.000"], ["70845.70", "0.019"], ["70846.90", "0.004"], ["70883.30", "0.002"], ["71897.30", "0.000"], ["77707.70", "0.008"], ["89523.20", "0.006"]]}}
{"local_ts": 1773486996037, "server_ts": 1773486996008, "data": {"e": "depthUpdate", "E": 1773486996009, "T": 1773486996008, "s": "BTCUSDT", "U": 10109534980690, "u": 10109534986949, "pu": 10109534980491, "b": [["1000.00", "27.042"], ["5000.00", "101.398"], ["7064.40", "0.056"], ["20243.30", "1.200"], ["20343.30", "1.800"], ["63579.00", "0.012"], ["67089.80", "0.002"], ["67808.90", "2.530"], ["68503.00", "1.458"], ["68524.00", "0.021"], ["69790.30", "4.291"], ["69936.90", "0.168"], ["70072.90", "1.424"], ["70549.30", "0.159"], ["70549.40", "0.053"], ["70556.30", "0.597"], ["70556.40", "0.000"], ["70562.70", "0.002"], ["70563.40", "0.231"], ["70563.50", "0.000"], ["70572.70", "0.123"], ["70597.50", "0.187"], ["70614.20", "0.002"], ["70618.40", "0.158"], ["70632.70", "0.908"], ["70636.10", "0.021"]], "a": [["70644.00", "0.020"], ["70644.50", "0.022"], ["70654.00", "0.000"], ["70682.50", "0.326"], ["70682.70", "0.002"], ["70726.00", "0.372"], ["70726.10", "0.142"], ["70733.10", "0.213"], ["70733.20", "0.000"], ["70740.10", "0.126"], ["70740.20", "0.087"], ["70744.80", "0.041"], ["70745.10", "0.021"], ["70885.40", "0.000"], ["70887.80", "0.162"], ["70962.70", "0.216"], ["70963.40", "0.000"], ["71059.80", "7.403"], ["71197.80", "3.240"], ["71208.50", "0.280"], ["72762.70", "0.006"], ["72984.20", "1.232"], ["74184.10", "0.000"], ["77707.70", "0.008"], ["89523.20", "0.006"]]}}
{"local_ts": 1773486997057, "server_ts": 1773486997028, "data": {"e": "depthUpdate", "E": 1773486997031, "T": 1773486997028, "s": "BTCUSDT", "U": 10109535043630, "u": 10109535049786, "pu": 10109535043617, "b": [["1000.00", "26.892"], ["5000.00", "101.418"], ["7064.40", "0.056"], ["20143.30", "0.760"], ["20243.30", "2.240"], ["63579.00", "0.012"], ["67111.00", "1.247"], ["69350.00", "6.377"], ["69515.10", "2.737"], ["69619.00", "3.012"], ["69936.90", "0.882"], ["69937.00", "0.000"], ["70223.80", "39.272"], ["70290.10", "0.000"], ["70329.30", "33.066"], ["70397.30", "0.263"], ["70400.00", "11.933"], ["70406.80", "26.754"], ["70608.00", "0.080"], ["70616.80", "0.121"], ["70626.30", "0.174"], ["70627.60", "0.266"], ["70632.70", "0.905"], ["70636.20", "0.038"], ["70639.30", "0.004"]], "a": [["70644.20", "0.073"], ["70654.00", "0.003"], ["70889.90", "50.528"], ["70967.90", "31.761"], ["71074.30", "38.042"], ["71349.80", "0.000"], ["74186.30", "0.000"], ["77707.70", "0.008"]]}}
{"local_ts": 1773486998076, "server_ts": 1773486998050, "data": {"e": "depthUpdate", "E": 1773486998051, "T": 1773486998050, "s": "BTCUSDT", "U": 10109535107819, "u": 10109535113359, "pu": 10109535107781, "b": [["5000.00", "101.418"], ["7064.40", "0.056"], ["20143.30", "2.590"], ["20243.30", "0.050"], ["20543.30", "0.360"], ["56515.00", "0.000"], ["67111.00", "1.247"], ["69515.10", "0.727"], ["69550.40", "6.030"], ["69621.00", "9.251"], ["69936.90", "2.316"], ["70078.20", "3.135"], ["70397.30", "0.263"], ["70457.50", "0.002"], ["70596.20", "0.513"], ["70596.40", "0.845"], ["70618.40", "0.116"], ["70630.60", "0.008"], ["70633.70", "0.008"], ["70634.20", "0.012"]], "a": [["70643.40", "3.200"], ["70652.50", "0.001"], ["70676.00", "0.312"], ["70681.80", "0.100"], ["70681.90", "0.511"], ["70863.90", "0.022"], ["70926.10", "0.014"], ["71314.50", "0.699"], ["71349.80", "0.700"], ["71669.90", "16.516"], ["74193.70", "0.002"]]}}
{"local_ts": 1773486999096, "server_ts": 1773486999070, "data": {"e": "depthUpdate", "E": 1773486999071, "T": 1773486999070, "s": "BTCUSDT", "U": 10109535165302, "u": 10109535168637, "pu": 10109535165274, "b": [["1000.00", "26.892"], ["5000.00", "101.418"], ["7064.40", "0.028"], ["20143.30", "0.330"], ["20443.30", "0.190"], ["20543.30", "2.480"], ["33000.00", "3.785"], ["67102.40", "0.004"], ["69936.90", "2.316"], ["69937.00", "0.000"], ["70290.10", "0.000"], ["70397.40", "0.004"], ["70571.40", "0.016"], ["70581.70", "0.085"], ["70581.80", "0.005"], ["70589.70", "0.000"], ["70589.80", "0.005"], ["70597.60", "0.003"], ["70597.70", "0.005"], ["70601.50", "0.043"], ["70605.70", "0.000"], ["70605.80", "0.027"], ["70605.90", "0.087"], ["70606.00", "0.513"], ["70612.10", "0.135"], ["70613.50", "0.011"], ["70613.60", "0.799"], ["70630.60", "0.004"]], "a": [["70659.90", "0.005"], ["70667.60", "0.020"], ["70695.20", "0.006"], ["70695.30", "0.268"], ["70695.40", "0.099"], ["70709.10", "0.000"], ["71210.70", "0.561"], ["71349.80", "0.700"], ["71600.40", "0.000"]]}}
{"local_ts": 1773487000123, "server_ts": 1773487000092, "data": {"e": "depthUpdate", "E": 1773487000095, "T": 1773487000092, "s": "BTCUSDT", "U": 10109535198644, "u": 10109535202554, "pu": 10109535198567, "b": [["5000.00", "101.418"], ["7064.40", "0.028"], ["20343.30", "0.050"], ["20443.30", "2.320"], ["20543.30", "0.630"], ["67100.00", "3.870"], ["69404.50", "0.288"], ["69936.90", "3.030"], ["69937.00", "0.000"], ["70397.10", "0.004"], ["70397.40", "0.000"], ["70534.90", "0.250"], ["70536.20", "0.018"], ["70543.00", "0.002"], ["70546.70", "0.047"], ["70547.10", "0.000"], ["70547.30", "0.043"], ["70548.00", "1.881"], ["70548.60", "0.000"], ["70549.10", "0.000"], ["70549.40", "0.000"], ["70550.20", "0.100"], ["70550.30", "0.009"], ["70550.50", "0.088"], ["70550.70", "0.072"], ["70552.40", "0.807"], ["70552.70", "1.037"], ["70566.20", "0.008"], ["70567.30", "0.025"], ["70571.80", "0.003"], ["70574.20", "0.004"], ["70574.80", "0.842"], ["70575.00", "0.085"], ["70575.10", "0.085"], ["70575.40", "0.178"], ["70575.80", "0.000"], ["70576.10", "0.096"], ["70576.60", "0.284"], ["70577.00", "0.031"], ["70577.20", "0.000"], ["70577.30", "0.127"], ["70578.40", "1.014"], ["70578.50", "0.200"], ["70578.80", "0.088"], ["70595.30", "1.232"], ["70602.40", "0.948"], ["70609.50", "0.856"], ["70616.60", "0.861"], ["70623.70", "1.202"], ["70629.00", "0.005"], ["70629.10", "0.480"], ["70629.20", "0.000"], ["70629.30", "0.002"], ["70629.40", "0.001"], ["70629.50", "0.882"], ["70629.60", "0.486"], ["70629.70", "0.002"], ["70629.80", "0.004"], ["70630.00", "0.389"], ["70630.10", "0.144"], ["70630.20", "0.005"], ["70630.40", "0.010"], ["70630.50", "0.086"], ["70630.60", "0.004"], ["70630.70", "0.000"], ["70630.80", "0.002"], ["70630.90", "0.000"], ["70639.40", "0.001"]], "a": [["70644.50", "0.076"], ["70648.50", "0.004"], ["70650.20", "0.029"], ["70651.20", "0.002"], ["70651.30", "0.001"], ["70651.50", "0.000"], ["70651.70", "0.001"], ["70651.80", "0.046"], ["70652.20", "0.061"], ["70652.30", "0.012"], ["70652.40", "0.004"], ["70652.60", "0.005"], ["70652.70", "0.072"], ["70652.80", "0.003"], ["70652.90", "0.020"], ["70654.90", "0.179"], ["70664.20", "0.059"], ["70665.20", "0.029"], ["70666.30", "0.856"], ["70671.70", "0.778"], ["70673.40", "0.860"], ["70677.50", "0.000"], ["70677.60", "0.036"], ["70678.00", "0.223"], ["70678.60", "0.040"], ["70679.00", "0.182"], ["70679.10", "0.039"], ["70679.40", "0.308"], ["70679.50", "0.268"], ["70679.60", "0.002"], ["70679.80", "0.039"], ["70679.90", "0.308"], ["70680.30", "0.001"], ["70680.50", "0.868"], ["70680.70", "0.003"], ["70681.40", "0.003"], ["70683.50", "0.024"], ["70684.30", "0.049"], ["70687.60", "0.887"], ["70694.70", "0.856"], ["70703.40", "0.002"], ["70703.50", "0.005"], ["70704.80", "0.000"], ["70704.90", "0.062"], ["70705.00", "0.000"], ["70705.30", "0.002"], ["70705.40", "0.003"], ["70705.80", "0.211"], ["70706.20", "0.038"], ["70706.80", "0.100"], ["70706.90", "0.020"], ["70707.00", "0.501"], ["70707.10", "0.513"], ["70707.80", "1.068"], ["70710.20", "0.004"], ["70714.70", "0.000"], ["70715.70", "0.555"], ["70795.30", "0.046"], ["70887.10", "0.158"], ["71314.50", "1.398"], ["71349.80", "2.077"], ["71597.10", "1.607"], ["71669.90", "8.713"], ["71738.40", "4.873"], ["71740.50", "5.638"], ["71775.80", "2.922"], ["71809.00", "1.946"], ["71811.20", "0.975"], ["72379.00", "0.417"]]}}
{"local_ts": 1773487001150, "server_ts": 1773487001114, "data": {"e": "depthUpdate", "E": 1773487001115, "T": 1773487001114, "s": "BTCUSDT", "U": 10109535233446, "u": 10109535237017, "pu": 10109535233444, "b": [["1000.00", "27.042"], ["5000.00", "101.438"], ["7064.40", "0.028"], ["20343.30", "1.970"], ["20443.30", "1.030"], ["33000.00", "3.789"], ["69230.50", "0.809"], ["69404.50", "0.000"], ["69936.90", "4.464"], ["70508.00", "7.434"], ["70549.10", "0.017"], ["70550.10", "0.277"], ["70556.10", "0.071"], ["70557.10", "0.228"], ["70563.20", "4.228"], ["70564.20", "0.184"], ["70596.00", "0.009"], ["70596.10", "1.073"], ["70606.00", "0.598"], ["70606.10", "0.102"], ["70630.60", "0.090"], ["70643.30", "11.975"]], "a": [["70655.80", "0.007"], ["70719.70", "0.142"], ["70725.80", "0.074"], ["70726.80", "0.313"], ["70732.90", "0.121"], ["70733.80", "0.230"], ["70739.90", "0.108"], ["70776.20", "0.354"], ["71349.80", "1.820"], ["74185.70", "0.002"], ["74192.40", "0.000"]]}}
{"local_ts": 1773487002160, "server_ts": 1773487002133, "data": {"e": "depthUpdate", "E": 1773487002135, "T": 1773487002133, "s": "BTCUSDT", "U": 10109535279283, "u": 10109535282939, "pu": 10109535279245, "b": [["1000.00", "27.042"], ["5000.00", "101.418"], ["7064.40", "0.000"], ["20243.30", "1.520"], ["20343.30", "1.480"], ["67085.20", "0.002"], ["69617.90", "0.003"], ["69932.60", "0.035"], ["69936.90", "4.464"], ["70097.40", "0.000"], ["70290.10", "0.000"], ["70571.20", "0.875"], ["70612.50", "0.071"], ["70613.80", "0.516"], ["70623.80", "0.032"], ["70630.60", "0.090"], ["70632.70", "1.055"], ["70635.90", "0.331"], ["70638.20", "0.006"], ["70639.40", "0.001"], ["70639.50", "0.001"]], "a": [["70645.70", "0.008"], ["70650.20", "0.029"], ["70654.00", "0.000"], ["70654.90", "0.179"], ["70678.70", "0.216"], ["70680.00", "2.651"], ["70680.10", "0.020"], ["70688.00", "1.282"], ["70696.00", "0.005"], ["70704.00", "0.076"], ["70708.80", "0.004"], ["70712.00", "0.805"], ["70897.60", "0.004"], ["70897.80", "0.000"], ["71349.80", "5.319"], ["71844.30", "0.279"], ["74193.50", "0.052"]]}}
{"local_ts": 1773487003185, "server_ts": 1773487003152, "data": {"e": "depthUpdate", "E": 1773487003155, "T": 1773487003152, "s": "BTCUSDT", "U": 10109535318422, "u": 10109535323865, "pu": 10109535318413, "b": [["5000.00", "101.418"], ["7064.40", "0.000"], ["20143.30", "1.070"], ["20243.30", "1.930"], ["69722.80", "65.146"], ["69932.60", "55.624"], ["70093.80", "44.364"], ["70588.70", "0.040"], ["70595.30", "0.376"], ["70596.40", "0.843"], ["70596.50", "0.073"], ["70597.50", "0.017"], ["70602.40", "0.092"], ["70608.00", "0.020"], ["70609.50", "0.000"], ["70611.70", "0.358"], ["70616.60", "0.005"], ["70623.70", "0.342"], ["70630.40", "0.084"], ["70630.60", "0.090"], ["70632.50", "0.002"], ["70635.30", "0.002"], ["70635.90", "0.022"]], "a": [["70666.30", "0.000"], ["70673.40", "0.002"], ["70678.70", "0.216"], ["70680.50", "0.012"], ["70687.60", "0.031"], ["70694.70", "0.000"], ["70711.90", "0.016"], ["70791.80", "0.039"], ["70795.30", "0.085"], ["70897.60", "0.002"], ["70907.20", "0.002"], ["71202.10", "45.592"], ["71349.80", "5.319"], ["71365.80", "57.145"], ["71579.90", "65.453"], ["72043.20", "0.628"], ["74183.90", "0.004"], ["74200.10", "0.000"]]}}
{"local_ts": 1773487004201, "server_ts": 1773487004174, "data": {"e": "depthUpdate", "E": 1773487004175, "T": 1773487004174, "s": "BTCUSDT", "U": 10109535372028, "u": 10109535377504, "pu": 10109535371986, "b": [["1000.00", "27.042"], ["5000.00", "101.418"], ["7064.40", "0.000"], ["20143.30", "2.380"], ["20243.30", "0.000"], ["20543.30", "0.620"], ["67087.20", "0.000"], ["69360.40", "0.000"], ["69619.00", "12.909"], ["69795.60", "2.715"], ["69936.90", "4.464"], ["69937.00", "0.000"], ["70290.10", "0.000"], ["70310.00", "0.074"], ["70397.20", "0.000"], ["70583.30", "0.173"], ["70586.80", "0.230"], ["70603.30", "0.002"], ["70611.60", "0.203"], ["70624.50", "0.074"], ["70625.60", "0.003"], ["70626.40", "0.497"], ["70630.80", "0.068"], ["70632.70", "1.055"], ["70634.70", "0.000"], ["70635.80", "0.013"], ["70636.00", "0.006"], ["70636.30", "0.074"], ["70639.30", "0.003"], ["70642.10", "0.000"], ["70643.30", "2.436"]], "a": [["70645.40", "0.006"], ["70649.00", "0.198"], ["70649.80", "0.041"], ["70650.40", "0.003"], ["70654.00", "0.003"], ["70655.10", "0.006"], ["70666.30", "0.000"], ["70667.00", "0.636"], ["70671.20", "0.057"], ["70672.30", "0.072"], ["70674.80", "0.628"], ["70674.90", "0.019"], ["70675.50", "0.008"], ["70675.60", "0.041"], ["70680.10", "0.053"], ["70691.30", "0.002"], ["70697.00", "0.089"], ["70697.10", "0.085"], ["70781.20", "0.039"], ["70820.00", "0.166"], ["70861.40", "0.002"], ["70907.20", "0.000"], ["71349.80", "7.418"], ["71561.80", "11.206"], ["71903.70", "0.003"], ["74184.60", "0.067"], ["74188.00", "2.391"]]}}
{"local_ts": 1773487005227, "server_ts": 1773487005198, "data": {"e": "depthUpdate", "E": 1773487005199, "T": 1773487005198, "s": "BTCUSDT", "U": 10109535412302, "u": 10109535417516, "pu": 10109535412230, "b": [["5000.00", "101.418"], ["7064.40", "0.000"], ["20143.30", "0.120"], ["20443.30", "0.300"], ["20543.30", "2.580"], ["56515.00", "0.000"], ["67102.90", "0.000"], ["68877.20", "0.653"], ["69449.40", "0.288"], ["69607.90", "1.183"], ["69936.90", "4.464"], ["70575.40", "0.142"], ["70575.70", "0.100"], ["70576.40", "0.094"], ["70577.60", "0.365"], ["70579.20", "0.086"], ["70596.40", "0.843"], ["70596.60", "0.003"], ["70608.00", "0.084"], ["70623.90", "0.001"], ["70624.00", "0.001"], ["70624.90", "0.509"], ["70625.30", "0.078"], ["70625.50", "0.517"], ["70626.10", "0.072"], ["70626.80", "0.000"], ["70629.30", "0.002"], ["70629.80", "0.097"], ["70629.90", "0.822"], ["70630.20", "0.058"], ["70630.30", "0.204"], ["70630.40", "0.134"], ["70630.80", "0.148"], ["70631.40", "0.046"], ["70631.90", "0.012"], ["70636.20", "0.477"], ["70640.00", "0.015"], ["70643.30", "2.614"]], "a": [["70651.70", "0.102"], ["70652.10", "0.087"], ["70652.20", "0.068"], ["70652.60", "0.038"], ["70652.70", "0.036"], ["70672.80", "1.089"], ["70673.80", "0.080"], ["70674.30", "0.000"], ["70676.90", "0.364"], ["70677.50", "0.036"], ["70677.80", "0.007"], ["70678.50", "0.504"], ["70679.40", "0.308"], ["70679.50", "0.293"], ["70679.70", "0.039"], ["70704.90", "0.062"], ["70706.10", "0.038"], ["70706.80", "0.100"], ["70707.00", "0.529"], ["70710.00", "0.638"], ["70710.10", "0.004"], ["70848.90", "0.026"], ["70861.40", "0.000"], ["71173.20", "1.402"], ["71349.80", "7.418"], ["71667.70", "17.277"], ["74184.40", "0.002"]]}}
{"local_ts": 1773487006248, "server_ts": 1773487006220, "data": {"e": "depthUpdate", "E": 1773487006223, "T": 1773487006220, "s": "BTCUSDT", "U": 10109535459141, "u": 10109535462948, "pu": 10109535459091, "b": [["1000.00", "27.042"], ["5000.00", "101.418"], ["7064.40", "0.056"], ["20343.30", "0.150"], ["20443.30", "2.440"], ["20543.30", "0.410"], ["67084.60", "0.002"], ["67111.00", "1.247"], ["67817.60", "1.912"], ["69559.00", "0.129"], ["69672.60", "0.002"], ["69936.90", "4.464"], ["69956.10", "0.000"], ["70290.10", "0.004"], ["70336.20", "0.000"], ["70466.70", "0.159"], ["70494.40", "0.106"], ["70495.20", "0.002"], ["70597.10", "0.002"], ["70597.20", "0.007"], ["70611.50", "1.859"], ["70613.30", "0.283"], ["70625.00", "1.328"], ["70625.60", "0.003"], ["70632.70", "1.052"], ["70636.00", "0.003"], ["70636.20", "0.477"], ["70636.30", "0.067"], ["70639.80", "0.006"]], "a": [["70643.40", "28.844"], ["70650.40", "0.003"], ["70654.00", "0.000"], ["70656.70", "0.141"], ["70657.90", "0.001"], ["70703.50", "0.007"], ["70710.10", "0.038"], ["70796.50", "0.000"], ["70798.10", "0.018"], ["70848.90", "0.024"], ["70858.40", "0.002"], ["71349.80", "7.418"], ["71556.20", "0.004"], ["73469.10", "0.631"], ["74208.70", "0.002"]]}}
{"local_ts": 1773487007278, "server_ts": 1773487007244, "data": {"e": "depthUpdate", "E": 1773487007247, "T": 1773487007244, "s": "BTCUSDT", "U": 10109535503803, "u": 10109535508444, "pu": 10109535503751, "b": [["1000.00", "27.042"], ["5000.00", "101.418"], ["7064.40", "0.056"], ["20243.30", "0.010"], ["20343.30", "2.280"], ["20443.30", "0.710"], ["67105.60", "0.002"], ["69630.20", "1.437"], ["69643.20", "0.000"], ["69936.90", "4.464"], ["70290.10", "0.000"], ["70548.90", "0.000"], ["70555.90", "0.002"], ["70563.00", "0.002"], ["70583.30", "0.092"], ["70588.10", "3.361"], ["70591.60", "0.184"], ["70592.10", "0.073"], ["70609.30", "1.876"], ["70610.70", "0.019"], ["70612.60", "0.366"], ["70613.30", "0.422"], ["70624.40", "1.500"], ["70625.00", "0.125"], ["70625.40", "0.047"], ["70627.10", "0.142"], ["70627.70", "0.581"], ["70627.90", "0.071"], ["70629.30", "0.002"], ["70631.20", "0.311"], ["70632.70", "0.908"], ["70633.00", "0.001"], ["70633.90", "0.060"], ["70635.30", "1.582"], ["70635.40", "0.002"], ["70636.20", "0.341"], ["70640.00", "0.015"], ["70640.10", "0.007"], ["70640.40", "0.000"], ["70643.30", "2.139"]], "a": [["70643.40", "28.884"], ["70643.80", "0.141"], ["70645.50", "3.331"], ["70654.00", "0.003"], ["70673.10", "0.016"], ["70674.40", "0.072"], ["70681.60", "1.827"], ["70699.20", "0.004"], ["70702.90", "3.435"], ["70703.50", "0.005"], ["70725.60", "0.002"], ["70732.70", "0.000"], ["70739.70", "0.227"], ["70996.60", "0.035"], ["71349.80", "8.817"], ["71479.10", "0.573"], ["73469.10", "0.633"]]}}
{"local_ts": 1773487008293, "server_ts": 1773487008266, "data": {"e": "depthUpdate", "E": 1773487008267, "T": 1773487008266, "s": "BTCUSDT", "U": 10109535549754, "u": 10109535554051, "pu": 10109535549577, "b": [["5000.00", "101.418"], ["7064.40", "0.028"], ["20243.30", "1.850"], ["20343.30", "1.150"], ["33000.00", "3.785"], ["69936.90", "6.606"], ["70466.70", "0.159"], ["70607.40", "0.000"], ["70607.50", "0.097"], ["70611.50", "1.859"], ["70613.20", "0.000"], ["70613.30", "0.346"], ["70632.70", "0.908"], ["70635.90", "0.025"]], "a": [["70654.00", "0.003"], ["70699.20", "0.002"], ["70702.40", "0.102"], ["71349.80", "8.817"], ["71526.40", "0.144"], ["71656.30", "0.698"], ["71667.70", "18.253"], ["71928.00", "0.599"], ["74181.60", "0.002"], ["89523.20", "0.006"]]}}
{"local_ts": 1773487009315, "server_ts": 1773487009288, "data": {"e": "depthUpdate", "E": 1773487009289, "T": 1773487009288, "s": "BTCUSDT", "U": 10109535596501, "u": 10109535603518, "pu": 10109535596445, "b": [["1000.00", "27.042"], ["5000.00", "101.418"], ["7064.40", "0.028"], ["20143.30", "1.410"], ["20243.30", "1.590"], ["67078.00", "0.012"], ["69572.50", "2.153"], ["69583.60", "5.023"], ["69925.70", "0.000"], ["69936.90", "6.606"], ["70290.10", "0.106"], ["70494.40", "0.088"], ["70495.00", "0.277"], ["70548.90", "0.017"], ["70555.90", "0.073"], ["70563.00", "0.073"], ["70591.30", "1.315"], ["70591.50", "8.502"], ["70593.80", "1.140"], ["70597.10", "0.004"], ["70597.20", "0.005"], ["70603.60", "0.897"], ["70613.30", "0.283"], ["70615.00", "0.142"], ["70616.80", "0.010"], ["70625.30", "0.000"], ["70625.60", "1.317"], ["70626.50", "0.089"], ["70629.00", "0.146"], ["70630.00", "0.548"], ["70631.20", "0.007"], ["70631.80", "0.256"], ["70634.50", "0.003"], ["70635.40", "0.027"], ["70636.20", "0.241"], ["70636.30", "0.003"], ["70636.60", "1.258"], ["70636.70", "0.003"], ["70637.00", "0.012"], ["70638.00", "0.200"], ["70639.70", "0.000"], ["70639.80", "0.011"], ["70639.90", "0.198"], ["70641.90", "0.008"], ["70642.20", "0.005"], ["70643.30", "4.441"]], "a": [["70643.40", "2.989"], ["70645.70", "0.026"], ["70648.20", "0.061"], ["70648.30", "0.057"], ["70657.30", "0.000"], ["70658.00", "0.303"], ["70658.90", "0.021"], ["70666.80", "0.098"], ["70678.70", "0.177"], ["70682.00", "2.192"], ["70693.10", "0.004"], ["70696.20", "0.002"], ["70699.30", "0.002"], ["70702.40", "0.100"], ["70703.30", "3.617"], ["70703.80", "0.000"], ["70704.40", "0.020"], ["70706.70", "0.005"], ["70725.50", "0.073"], ["70732.60", "0.075"], ["70739.60", "0.530"], ["70766.30", "0.093"], ["70797.10", "0.359"], ["70798.10", "0.000"], ["70867.20", "0.007"], ["71349.80", "8.817"], ["71389.60", "0.017"], ["89523.20", "0.006"]]}}
{"local_ts": 1773487010341, "server_ts": 1773487010312, "data": {"e": "depthUpdate", "E": 1773487010313, "T": 1773487010312, "s": "BTCUSDT", "U": 10109535647231, "u": 10109535651620, "pu": 10109535647137, "b": [["5000.00", "101.418"], ["7064.40", "0.028"], ["20143.30", "2.030"], ["20543.30", "0.970"], ["33000.00", "3.789"], ["69936.90", "10.175"], ["69972.50", "0.000"], ["70396.80", "0.004"], ["70402.00", "0.000"], ["70548.80", "1.445"], ["70555.80", "0.071"], ["70562.90", "0.073"], ["70575.80", "0.050"], ["70576.10", "0.088"], ["70576.70", "0.648"], ["70578.00", "0.092"], ["70579.50", "0.114"], ["70630.20", "0.185"], ["70630.60", "0.090"], ["70630.70", "0.050"], ["70631.10", "0.088"], ["70636.20", "0.314"], ["70639.80", "0.011"], ["70643.30", "4.252"]], "a": [["70644.10", "0.148"], ["70644.50", "0.081"], ["70651.60", "0.036"], ["70651.70", "0.096"], ["70651.90", "0.050"], ["70652.00", "0.042"], ["70652.50", "0.073"], ["70673.50", "0.005"], ["70674.70", "0.148"], ["70677.40", "0.053"], ["70678.40", "0.058"], ["70679.20", "1.110"], ["70679.40", "0.297"], ["70679.60", "0.038"], ["70704.70", "0.293"], ["70706.00", "0.036"], ["70706.60", "0.040"], ["70706.90", "0.025"], ["70725.50", "0.073"], ["70732.60", "0.075"], ["70739.60", "0.530"], ["71349.80", "10.216"], ["71500.00", "36.580"], ["71723.40", "0.002"], ["72762.70", "0.011"], ["74208.80", "0.002"], ["89523.20", "0.006"]]}}
{"local_ts": 1773487011378, "server_ts": 1773487011333, "data": {"e": "depthUpdate", "E": 1773487011335, "T": 1773487011333, "s": "BTCUSDT", "U": 10109535682280, "u": 10109535685632, "pu": 10109535682279, "b": [["1000.00", "27.042"], ["5000.00", "101.418"], ["7064.40", "0.000"], ["20143.30", "0.000"], ["20443.30", "0.520"], ["20543.30", "2.480"], ["67077.70", "0.002"], ["68853.90", "0.002"], ["69936.90", "10.175"], ["70587.70", "0.290"], ["70597.40", "0.007"], ["70597.50", "0.158"], ["70598.80", "0.279"], ["70604.80", "0.211"], ["70606.30", "0.013"], ["70632.70", "0.905"], ["70634.40", "0.209"], ["70635.70", "0.009"], ["70636.20", "0.162"], ["70636.80", "0.002"]], "a": [["70643.40", "4.143"], ["70655.70", "0.004"], ["70703.70", "0.283"], ["71267.80", "0.000"], ["71349.80", "10.216"], ["71800.00", "145.585"], ["72428.30", "2.481"], ["74200.30", "0.033"], ["89523.20", "0.012"]]}}
{"local_ts": 1773487012382, "server_ts": 1773487012356, "data": {"e": "depthUpdate", "E": 1773487012357, "T": 1773487012356, "s": "BTCUSDT", "U": 10109535714998, "u": 10109535719085, "pu": 10109535714962, "b": [["1000.00", "27.042"], ["5000.00", "101.418"], ["7064.40", "0.000"], ["20343.30", "0.270"], ["20443.30", "2.540"], ["20543.30", "0.190"], ["67111.10", "0.063"], ["67111.20", "0.013"], ["68643.30", "0.000"], ["69936.90", "10.175"], ["70290.10", "0.000"], ["70396.90", "0.004"], ["70597.40", "0.007"], ["70597.60", "0.592"], ["70632.70", "0.905"], ["70635.40", "0.006"], ["70635.90", "0.025"], ["70636.30", "0.003"], ["70638.10", "0.009"], ["70639.20", "0.026"], ["70639.70", "0.057"], ["70643.30", "4.548"]], "a": [["70643.40", "3.130"], ["70654.00", "0.003"], ["70657.20", "0.014"], ["70660.70", "0.000"], ["70662.10", "0.004"], ["70678.70", "0.288"], ["71349.80", "10.216"], ["71547.40", "0.000"], ["71887.70", "0.002"], ["74180.10", "0.002"], ["89523.20", "0.012"]]}}
{"local_ts": 1773487013404, "server_ts": 1773487013376, "data": {"e": "depthUpdate", "E": 1773487013379, "T": 1773487013376, "s": "BTCUSDT", "U": 10109535757247, "u": 10109535760679, "pu": 10109535757212, "b": [["5000.00", "101.418"], ["7064.40", "0.000"], ["20243.30", "0.120"], ["20343.30", "2.390"], ["20443.30", "0.490"], ["69548.30", "8.845"], ["69935.60", "0.000"], ["69936.90", "10.175"], ["69937.00", "0.004"], ["70396.70", "0.000"], ["70597.80", "0.495"], ["70597.90", "0.003"], ["70630.30", "0.763"], ["70632.70", "0.908"], ["70633.80", "0.413"], ["70636.00", "0.063"], ["70636.20", "0.599"], ["70636.30", "0.070"], ["70638.00", "0.167"], ["70643.30", "5.220"]], "a": [["70654.00", "0.000"], ["70678.70", "0.189"], ["70795.30", "0.085"], ["71349.80", "10.216"], ["71656.70", "0.716"], ["74180.30", "0.002"], ["89523.20", "0.012"]]}}
{"local_ts": 1773487014428, "server_ts": 1773487014400, "data": {"e": "depthUpdate", "E": 1773487014401, "T": 1773487014400, "s": "BTCUSDT", "U": 10109535818889, "u": 10109535822542, "pu": 10109535818794, "b": [["1000.00", "27.042"], ["5000.00", "101.398"], ["7064.40", "0.000"], ["20243.30", "2.190"], ["20343.30", "0.810"], ["67088.90", "0.000"], ["69537.20", "0.029"], ["69936.90", "10.175"], ["70290.10", "0.000"], ["70510.40", "0.879"], ["70597.40", "0.204"], ["70608.00", "0.020"], ["70614.00", "0.008"], ["70614.10", "0.063"], ["70626.40", "0.518"], ["70628.50", "0.075"], ["70635.40", "0.027"], ["70636.20", "0.359"], ["70636.30", "0.044"], ["70640.30", "0.007"], ["70642.50", "0.021"], ["70643.20", "0.106"]], "a": [["70643.40", "2.800"], ["70646.10", "0.001"], ["70647.40", "0.023"], ["70647.70", "0.001"], ["70650.20", "0.029"], ["70650.30", "0.297"], ["70654.90", "0.179"], ["70658.00", "0.023"], ["70673.90", "0.003"], ["70675.30", "0.102"], ["70678.70", "0.249"], ["70681.70", "0.093"], ["70776.90", "0.821"], ["70798.80", "0.177"], ["71349.80", "10.216"], ["71611.20", "0.278"], ["89523.20", "0.012"]]}}
{"local_ts": 1773487015447, "server_ts": 1773487015420, "data": {"e": "depthUpdate", "E": 1773487015421, "T": 1773487015420, "s": "BTCUSDT", "U": 10109535859628, "u": 10109535863645, "pu": 10109535859626, "b": [["5000.00", "101.418"], ["7064.40", "0.056"], ["20143.30", "1.730"], ["20243.30", "1.270"], ["67103.20", "0.210"], ["67111.00", "1.267"], ["67111.10", "0.061"], ["69409.70", "1.439"], ["69583.60", "8.323"], ["69936.90", "11.603"], ["70007.50", "10.697"], ["70100.10", "0.499"], ["70222.10", "15.372"], ["70224.40", "39.229"], ["70224.50", "3.240"], ["70226.80", "6.164"], ["70290.10", "0.000"], ["70329.90", "32.507"], ["70330.00", "1.053"], ["70331.80", "5.780"], ["70332.50", "0.106"], ["70407.40", "26.496"], ["70409.50", "4.273"], ["70486.40", "0.093"], ["70548.70", "0.296"], ["70555.70", "0.071"], ["70562.80", "0.075"], ["70576.10", "0.052"], ["70576.40", "0.086"], ["70577.10", "0.269"], ["70578.30", "1.062"], ["70579.80", "0.497"], ["70626.20", "0.671"], ["70630.50", "0.086"], ["70630.60", "0.390"], ["70631.00", "0.144"], ["70631.40", "0.134"]], "a": [["70651.50", "0.036"], ["70651.80", "0.035"], ["70651.90", "0.043"], ["70652.40", "0.076"], ["70677.30", "0.039"], ["70678.30", "0.036"], ["70678.70", "0.227"], ["70679.10", "0.075"], ["70679.30", "0.682"], ["70679.50", "0.304"], ["70704.60", "0.036"], ["70705.50", "0.025"], ["70705.90", "0.039"], ["70706.50", "0.036"], ["70706.80", "0.089"], ["70725.40", "0.071"], ["70732.50", "0.074"], ["70739.50", "0.071"], ["70819.30", "0.099"], ["70867.10", "0.000"], ["70885.60", "9.513"], ["70886.50", "0.173"], ["70886.60", "27.279"], ["70887.80", "0.000"], ["70964.50", "0.650"], ["70964.60", "31.782"], ["71070.90", "3.240"], ["71071.00", "39.399"], ["71249.90", "0.003"], ["71303.30", "0.000"], ["71349.80", "10.216"], ["71646.50", "0.556"], ["72074.20", "1.662"], ["72074.80", "3.324"], ["73398.50", "1.835"], ["74178.90", "0.014"], ["89523.20", "0.012"]]}}
{"local_ts": 1773487016470, "server_ts": 1773487016441, "data": {"e": "depthUpdate", "E": 1773487016445, "T": 1773487016441, "s": "BTCUSDT", "U": 10109535901209, "u": 10109535904080, "pu": 10109535901090, "b": [["1000.00", "27.042"], ["5000.00", "101.418"], ["7064.40", "0.056"], ["20143.30", "1.710"], ["20543.30", "1.290"], ["69830.90", "0.653"], ["69936.90", "11.603"], ["70597.40", "0.204"], ["70636.20", "0.235"], ["70642.60", "0.030"]], "a": [["70645.20", "0.005"], ["70646.40", "0.025"], ["70693.20", "0.042"], ["70798.80", "0.237"], ["70884.30", "0.005"], ["70886.60", "27.286"], ["70891.40", "0.000"], ["70893.70", "0.007"], ["70898.50", "0.000"], ["70900.80", "0.027"], ["70905.60", "0.000"], ["70907.90", "0.007"], ["70912.70", "0.000"], ["70915.00", "0.007"], ["70919.80", "0.000"], ["70922.10", "0.277"], ["70926.90", "6.482"], ["70929.20", "0.009"], ["70934.00", "0.265"], ["70936.30", "0.007"], ["71349.80", "10.216"], ["72776.70", "0.003"], ["74185.90", "0.002"], ["89523.20", "0.012"]]}}
{"local_ts": 1773487017496, "server_ts": 1773487017468, "data": {"e": "depthUpdate", "E": 1773487017469, "T": 1773487017468, "s": "BTCUSDT", "U": 10109535938800, "u": 10109535943222, "pu": 10109535938770, "b": [["1000.00", "27.042"], ["5000.00", "101.438"], ["7064.40", "0.028"], ["20443.30", "0.860"], ["20543.30", "2.140"], ["33000.00", "3.785"], ["67106.50", "0.000"], ["67111.10", "0.063"], ["69207.10", "0.437"], ["69936.90", "11.603"], ["70290.10", "0.072"], ["70573.10", "0.680"], ["70608.10", "0.088"], ["70608.20", "0.130"], ["70612.70", "0.001"], ["70614.40", "0.003"], ["70614.50", "0.066"], ["70631.10", "0.128"], ["70632.70", "0.905"], ["70643.30", "4.794"]], "a": [["70643.40", "2.370"], ["70647.10", "0.057"], ["70648.40", "0.002"], ["70654.90", "0.215"], ["70678.70", "0.266"], ["70683.90", "0.094"], ["70693.20", "0.000"], ["70886.60", "27.279"], ["70888.80", "0.045"], ["70893.70", "0.000"], ["70895.90", "0.007"], ["70900.80", "0.020"], ["70903.00", "0.335"], ["70907.90", "0.000"], ["70910.10", "0.007"], ["70915.00", "0.000"], ["70917.20", "0.009"], ["70922.10", "0.270"], ["70924.30", "0.012"], ["70929.20", "0.002"], ["70931.40", "0.017"], ["70936.30", "0.000"], ["70938.50", "0.274"], ["71349.80", "10.216"], ["74202.50", "0.052"], ["89523.20", "0.012"]]}}
{"local_ts": 1773487018517, "server_ts": 1773487018489, "data": {"e": "depthUpdate", "E": 1773487018491, "T": 1773487018489, "s": "BTCUSDT", "U": 10109535973815, "u": 10109535976708, "pu": 10109535973788, "b": [["5000.00", "101.398"], ["7064.40", "0.028"], ["20343.30", "0.430"], ["20443.30", "2.550"], ["20543.30", "0.020"], ["66129.00", "0.005"], ["67094.90", "0.002"], ["69936.90", "11.603"], ["70640.30", "0.007"]], "a": [["70652.00", "0.088"], ["70671.80", "0.003"], ["70678.70", "0.227"], ["70693.20", "0.000"], ["70888.80", "0.038"], ["70889.80", "0.019"], ["70895.90", "0.000"], ["70896.90", "0.007"], ["70903.00", "0.328"], ["70904.00", "0.007"], ["70910.10", "0.000"], ["70911.10", "0.009"], ["70917.20", "0.002"], ["70918.20", "0.010"], ["70924.30", "0.005"], ["70925.30", "0.007"], ["70931.40", "0.010"], ["70932.40", "0.009"], ["70938.50", "0.267"], ["70939.50", "0.007"], ["71349.80", "10.216"], ["74184.30", "0.010"], ["89523.20", "0.012"]]}}
{"local_ts": 1773487019538, "server_ts": 1773487019508, "data": {"e": "depthUpdate", "E": 1773487019511, "T": 1773487019508, "s": "BTCUSDT", "U": 10109536010953, "u": 10109536014080, "pu": 10109536010864, "b": [["1000.00", "27.042"], ["5000.00", "101.398"], ["7064.40", "0.028"], ["20243.30", "0.230"], ["20343.30", "2.500"], ["20443.30", "0.270"], ["33000.00", "3.789"], ["68860.70", "0.000"], ["69566.00", "0.935"], ["69936.90", "11.603"], ["70290.10", "0.108"], ["70552.20", "0.049"], ["70596.60", "0.004"], ["70597.00", "0.042"], ["70619.20", "0.040"], ["70635.40", "0.027"]], "a": [["70643.40", "3.378"], ["70643.80", "0.141"], ["70865.50", "0.490"], ["70889.80", "0.012"], ["70895.60", "0.007"], ["70896.90", "0.000"], ["70902.70", "0.007"], ["70904.00", "0.000"], ["70909.80", "0.007"], ["70911.10", "0.002"], ["70916.90", "10.021"], ["70918.20", "0.003"], ["70924.00", "0.033"], ["70925.30", "0.000"], ["70931.10", "0.007"], ["70932.40", "0.002"], ["70938.20", "0.274"], ["70939.50", "0.000"], ["70945.30", "0.007"], ["71349.80", "10.216"], ["74179.70", "0.002"], ["74183.00", "0.052"]]}}
{"local_ts": 1773487020561, "server_ts": 1773487020533, "data": {"e": "depthUpdate", "E": 1773487020535, "T": 1773487020533, "s": "BTCUSDT", "U": 10109536055642, "u": 10109536060428, "pu": 10109536055534, "b": [["5000.00", "101.418"], ["7064.40", "0.000"], ["20143.30", "0.080"], ["20243.30", "2.360"], ["20343.30", "0.560"], ["40000.00", "41.356"], ["56515.00", "0.000"], ["69727.00", "4.307"], ["69936.90", "11.603"], ["70576.40", "0.050"], ["70576.70", "0.640"], ["70577.40", "0.180"], ["70578.60", "0.086"], ["70580.10", "1.036"], ["70583.30", "0.332"], ["70595.00", "0.356"], ["70596.90", "0.498"], ["70597.10", "0.002"], ["70597.40", "0.204"], ["70608.00", "0.089"], ["70608.40", "0.354"], ["70608.50", "0.544"], ["70609.90", "0.188"], ["70614.80", "0.002"], ["70614.90", "0.337"], ["70615.00", "0.165"], ["70622.40", "0.271"], ["70622.90", "0.019"], ["70623.50", "0.054"], ["70623.60", "0.009"], ["70624.20", "0.217"], ["70629.10", "0.080"], ["70630.70", "0.208"], ["70630.80", "0.088"], ["70630.90", "0.375"], ["70631.20", "0.068"], ["70631.30", "0.093"], ["70631.40", "0.098"], ["70631.80", "0.428"], ["70632.50", "0.002"], ["70632.90", "0.288"], ["70633.20", "0.105"], ["70633.60", "0.009"], ["70633.80", "0.006"], ["70633.90", "0.639"], ["70634.00", "0.370"], ["70634.10", "0.000"], ["70634.20", "0.009"], ["70634.50", "0.003"], ["70634.90", "0.016"], ["70635.30", "1.579"], ["70635.50", "0.003"], ["70635.70", "0.066"], ["70635.90", "0.022"], ["70636.00", "0.001"], ["70636.20", "0.003"], ["70636.70", "0.005"], ["70636.80", "0.004"], ["70638.00", "0.037"], ["70639.90", "0.153"], ["70640.00", "0.007"], ["70643.30", "4.522"]], "a": [["70643.40", "3.692"], ["70651.10", "0.183"], ["70651.40", "0.043"], ["70651.80", "0.035"], ["70651.90", "0.065"], ["70652.30", "0.045"], ["70652.40", "0.076"], ["70658.70", "0.207"], ["70660.40", "0.004"], ["70660.70", "0.004"], ["70660.90", "0.019"], ["70661.00", "0.010"], ["70661.20", "0.007"], ["70661.30", "0.032"], ["70661.70", "0.017"], ["70661.80", "0.009"], ["70662.00", "0.030"], ["70662.20", "0.163"], ["70663.60", "0.010"], ["70670.80", "0.772"], ["70672.60", "0.000"], ["70673.40", "0.002"], ["70675.20", "0.134"], ["70677.20", "0.106"], ["70678.20", "0.324"], ["70679.10", "0.039"], ["70679.20", "1.099"], ["70679.40", "0.308"], ["70697.40", "0.085"], ["70697.70", "0.003"], ["70704.60", "0.036"], ["70705.80", "0.283"], ["70706.50", "0.036"], ["70706.70", "0.025"], ["71349.80", "10.216"], ["71576.80", "0.000"], ["74199.70", "0.000"], ["100000.00", "23.620"]]}}
{"local_ts": 1773487021586, "server_ts": 1773487021556, "data": {"e": "depthUpdate", "E": 1773487021557, "T": 1773487021556, "s": "BTCUSDT", "U": 10109536112504, "u": 10109536117949, "pu": 10109536112435, "b": [["1000.00", "27.042"], ["5000.00", "101.418"], ["7064.40", "0.000"], ["20143.30", "2.080"], ["20243.30", "0.920"], ["56515.00", "0.000"], ["67092.50", "0.002"], ["69574.30", "0.039"], ["69936.90", "11.603"], ["70511.00", "0.860"], ["70595.00", "0.002"], ["70597.40", "0.204"], ["70597.50", "0.156"], ["70597.60", "0.592"], ["70621.80", "0.015"], ["70634.50", "0.015"], ["70635.40", "0.006"], ["70635.80", "0.006"], ["70635.90", "0.025"], ["70636.20", "0.510"], ["70636.70", "0.005"], ["70637.50", "0.038"], ["70642.10", "0.204"], ["70642.40", "0.087"]], "a": [["70643.40", "3.361"], ["70645.70", "0.053"], ["70647.00", "0.003"], ["70647.70", "0.009"], ["70648.40", "0.023"], ["70654.00", "0.000"], ["70777.20", "0.350"], ["71285.60", "0.000"], ["71349.80", "10.216"], ["71681.90", "2.233"]]}}
{"local_ts": 1773487022607, "server_ts": 1773487022576, "data": {"e": "depthUpdate", "E": 1773487022577, "T": 1773487022576, "s": "BTCUSDT", "U": 10109536158259, "u": 10109536161745, "pu": 10109536158185, "b": [["1000.00", "27.042"], ["5000.00", "101.418"], ["7064.40", "0.000"], ["20143.30", "1.370"], ["20543.30", "1.630"], ["56515.00", "0.000"], ["67111.20", "0.011"], ["69306.00", "0.000"], ["69604.80", "1.419"], ["69619.00", "20.226"], ["70329.00", "0.000"], ["70397.20", "0.004"], ["70608.00", "0.048"], ["70608.50", "0.544"], ["70608.60", "0.089"], ["70625.60", "1.332"], ["70627.70", "0.511"], ["70629.00", "0.005"], ["70635.40", "0.080"], ["70636.40", "0.017"], ["70636.70", "0.009"], ["70638.30", "0.009"], ["70638.50", "0.001"], ["70638.90", "0.000"], ["70642.10", "0.147"], ["70643.30", "2.929"]], "a": [["70644.80", "0.011"], ["70661.70", "0.017"], ["70666.00", "0.088"], ["70697.70", "0.003"], ["70697.80", "0.114"], ["71349.80", "10.216"], ["71515.30", "0.697"], ["74199.30", "0.002"]]}}
{"local_ts": 1773487023626, "server_ts": 1773487023598, "data": {"e": "depthUpdate", "E": 1773487023599, "T": 1773487023598, "s": "BTCUSDT", "U": 10109536238002, "u": 10109536243455, "pu": 10109536237866, "b": [["5000.00", "101.418"], ["7064.20", "0.000"], ["20442.00", "1.180"], ["20543.30", "0.600"], ["56515.00", "0.000"], ["67109.90", "0.004"], ["69701.50", "0.000"], ["69935.60", "0.000"], ["70360.20", "0.019"], ["70361.50", "0.000"], ["70536.10", "0.086"], ["70537.40", "0.002"], ["70574.90", "0.053"], ["70600.60", "0.074"], ["70600.70", "0.003"], ["70607.90", "0.008"], ["70608.00", "0.105"], ["70610.20", "0.313"], ["70612.90", "0.476"], ["70616.70", "0.054"], ["70617.30", "0.118"], ["70620.10", "0.074"], ["70620.80", "0.524"], ["70631.40", "0.053"], ["70635.00", "4.026"], ["70638.20", "0.006"]], "a": [["70642.10", "14.222"], ["70642.90", "0.028"], ["70643.40", "0.194"], ["70645.50", "3.309"], ["70649.10", "0.004"], ["70649.70", "0.002"], ["70652.70", "0.021"], ["70662.50", "0.000"], ["70663.00", "0.642"], ["70663.50", "0.000"], ["70669.80", "0.002"], ["70670.70", "0.070"], ["70673.30", "0.142"], ["70674.30", "0.000"], ["70748.00", "0.142"], ["70749.30", "0.305"], ["71000.00", "25.872"], ["71348.50", "0.000"], ["71384.70", "0.000"], ["71721.70", "1.253"], ["71724.00", "0.001"], ["74208.30", "0.002"]]}}
{"local_ts": 1773487024648, "server_ts": 1773487024621, "data": {"e": "depthUpdate", "E": 1773487024623, "T": 1773487024621, "s": "BTCUSDT", "U": 10109536314139, "u": 10109536319424, "pu": 10109536314076, "b": [["1000.00", "27.042"], ["5000.00", "101.418"], ["7063.90", "0.056"], ["20338.60", "0.570"], ["20442.00", "1.850"], ["56511.00", "0.007"], ["69225.90", "0.010"], ["69579.10", "0.007"], ["69734.50", "0.026"], ["69932.20", "0.000"], ["69932.30", "0.721"], ["70288.60", "0.000"], ["70306.60", "3.688"], ["70310.00", "0.074"], ["70581.80", "0.000"], ["70582.10", "0.621"], ["70585.90", "0.186"], ["70591.40", "0.122"], ["70593.50", "0.047"], ["70593.60", "0.480"], ["70604.90", "0.003"], ["70606.60", "1.760"], ["70607.60", "0.150"], ["70608.20", "0.102"], ["70608.30", "0.090"], ["70610.70", "0.015"], ["70612.60", "0.366"], ["70614.00", "0.008"], ["70614.10", "0.063"], ["70615.00", "0.165"], ["70615.20", "0.005"], ["70616.10", "0.247"], ["70617.00", "0.052"], ["70620.80", "0.524"], ["70621.20", "0.066"], ["70621.50", "0.022"], ["70622.90", "0.856"], ["70623.70", "0.362"], ["70624.70", "0.004"], ["70624.80", "0.026"], ["70625.50", "0.006"], ["70625.60", "0.024"], ["70627.10", "0.012"], ["70627.30", "0.637"], ["70627.80", "0.361"], ["70628.00", "0.062"], ["70629.40", "0.001"], ["70629.80", "0.006"], ["70629.90", "0.217"], ["70630.10", "0.027"], ["70630.80", "0.090"], ["70631.60", "0.179"], ["70631.70", "0.084"], ["70632.10", "0.095"], ["70635.00", "3.970"], ["70635.80", "0.009"], ["70636.30", "0.063"], ["70636.80", "0.007"], ["70636.90", "0.002"], ["70637.40", "0.003"], ["70637.70", "0.009"], ["70638.50", "0.001"], ["70638.60", "1.804"]], "a": [["70638.70", "12.327"], ["70640.40", "0.000"], ["70640.80", "0.009"], ["70643.00", "18.678"], ["70644.40", "0.103"], ["70645.50", "3.285"], ["70645.70", "0.007"], ["70646.00", "0.000"], ["70646.10", "0.022"], ["70646.80", "0.004"], ["70649.30", "0.005"], ["70653.70", "0.000"], ["70655.50", "0.017"], ["70661.40", "0.005"], ["70662.30", "0.636"], ["70665.30", "0.009"], ["70669.90", "0.090"], ["70671.10", "0.251"], ["70672.10", "0.004"], ["70673.60", "0.058"], ["70699.50", "0.002"], ["70701.50", "8.486"], ["70780.00", "4.200"], ["70787.00", "0.090"], ["70862.30", "0.007"], ["70865.50", "0.490"], ["71345.10", "0.000"], ["71348.70", "0.097"], ["71469.90", "1.676"], ["71546.50", "0.007"], ["71701.90", "0.007"], ["71737.00", "0.002"], ["71737.10", "1.949"], ["73080.20", "0.002"], ["74170.90", "0.002"], ["74195.60", "0.000"]]}}
{"local_ts": 1773487025669, "server_ts": 1773487025640, "data": {"e": "depthUpdate", "E": 1773487025643, "T": 1773487025640, "s": "BTCUSDT", "U": 10109536369021, "u": 10109536373516, "pu": 10109536368774, "b": [["5000.00", "101.418"], ["7063.90", "0.056"], ["20238.60", "0.350"], ["20338.60", "2.590"], ["20438.60", "0.060"], ["56511.00", "0.007"], ["67085.30", "0.000"], ["67109.70", "0.002"], ["69932.20", "0.000"], ["70073.50", "0.006"], ["70306.60", "3.582"], ["70310.10", "0.106"], ["70506.90", "0.994"], ["70576.60", "0.330"], ["70576.90", "0.086"], ["70577.60", "0.459"], ["70577.90", "0.053"], ["70578.80", "0.088"], ["70580.30", "1.086"], ["70593.60", "0.482"], ["70593.70", "0.511"], ["70624.90", "0.000"], ["70625.20", "0.158"], ["70625.90", "0.003"], ["70628.00", "0.050"], ["70629.40", "0.001"], ["70630.80", "0.074"], ["70631.00", "0.188"], ["70631.40", "0.056"], ["70631.50", "0.450"], ["70631.60", "0.181"], ["70631.90", "0.602"], ["70633.70", "0.001"], ["70635.80", "0.009"], ["70636.10", "0.007"], ["70636.40", "0.003"], ["70636.60", "0.773"], ["70638.60", "1.848"]], "a": [["70639.30", "0.112"], ["70640.00", "0.010"], ["70645.70", "0.007"], ["70646.20", "0.003"], ["70646.50", "0.008"], ["70646.80", "0.002"], ["70649.30", "0.008"], ["70651.30", "0.037"], ["70651.60", "0.025"], ["70651.80", "0.063"], ["70652.20", "0.079"], ["70677.10", "0.614"], ["70678.10", "0.322"], ["70678.50", "0.554"], ["70678.90", "1.105"], ["70679.10", "0.028"], ["70679.30", "0.786"], ["70704.40", "0.036"], ["70705.30", "0.027"], ["70705.70", "0.036"], ["70706.30", "0.040"], ["70706.60", "0.029"], ["70777.50", "0.426"], ["71345.10", "0.000"], ["72429.50", "0.002"], ["74205.30", "0.004"]]}}
{"local_ts": 1773487026690, "server_ts": 1773487026661, "data": {"e": "depthUpdate", "E": 1773487026663, "T": 1773487026661, "s": "BTCUSDT", "U": 10109536415638, "u": 10109536419795, "pu": 10109536415538, "b": [["1000.00", "27.042"], ["5000.00", "101.418"], ["7063.90", "0.056"], ["20138.60", "0.190"], ["20238.60", "2.460"], ["20338.60", "0.350"], ["33000.00", "3.785"], ["68943.30", "0.869"], ["69812.10", "0.571"], ["69932.20", "0.000"], ["70310.10", "0.000"], ["70607.20", "0.925"], ["70607.30", "0.059"]], "a": [["70646.50", "0.006"], ["70647.90", "0.302"], ["70714.80", "0.005"], ["70715.80", "0.000"], ["71345.10", "0.000"], ["71486.40", "0.841"], ["71878.30", "2.639"], ["74197.50", "0.052"]]}}
{"local_ts": 1773487027713, "server_ts": 1773487027684, "data": {"e": "depthUpdate", "E": 1773487027685, "T": 1773487027684, "s": "BTCUSDT", "U": 10109536462548, "u": 10109536466273, "pu": 10109536462422, "b": [["1000.00", "27.042"], ["5000.00", "101.418"], ["7063.90", "0.028"], ["20138.60", "2.320"], ["20238.60", "0.640"], ["20538.60", "0.040"], ["69353.00", "0.588"], ["69477.70", "3.211"], ["69543.70", "2.018"], ["69614.30", "4.016"], ["69619.00", "13.198"], ["69619.10", "0.004"], ["69795.60", "5.290"], ["69932.20", "0.002"], ["70285.50", "0.296"], ["70392.50", "0.000"], ["70590.40", "0.184"], ["70615.90", "0.003"], ["70631.60", "0.181"], ["70632.60", "0.139"], ["70635.00", "3.966"], ["70635.70", "0.009"], ["70636.40", "0.003"], ["70637.10", "0.003"], ["70637.50", "0.023"], ["70638.10", "0.003"], ["70638.20", "0.014"]], "a": [["70638.70", "10.723"], ["70639.60", "0.001"], ["70639.90", "0.000"], ["70640.10", "0.000"], ["70645.50", "3.244"], ["70645.70", "0.007"], ["70647.90", "0.300"], ["70649.50", "0.010"], ["70706.10", "0.004"], ["70714.80", "0.003"], ["71345.10", "0.000"], ["72054.90", "0.011"], ["73464.20", "0.017"], ["74201.30", "0.000"]]}}
{"local_ts": 1773487028731, "server_ts": 1773487028704, "data": {"e": "depthUpdate", "E": 1773487028705, "T": 1773487028704, "s": "BTCUSDT", "U": 10109536507515, "u": 10109536511743, "pu": 10109536507438, "b": [["5000.00", "101.418"], ["7063.90", "0.028"], ["20138.60", "1.050"], ["20538.60", "1.950"], ["33000.00", "3.789"], ["67099.30", "0.000"], ["67109.70", "0.000"], ["67109.80", "0.002"], ["68519.40", "0.000"], ["69402.40", "1.151"], ["69513.00", "2.924"], ["69543.80", "1.005"], ["69548.30", "5.830"], ["69619.00", "11.190"], ["69685.00", "0.214"], ["69932.20", "0.002"], ["70279.30", "0.004"], ["70285.40", "3.408"], ["70402.00", "0.000"], ["70590.40", "0.184"], ["70603.30", "0.060"], ["70619.60", "0.509"], ["70620.90", "1.223"], ["70631.50", "0.452"], ["70631.70", "0.091"], ["70635.20", "0.018"], ["70636.40", "0.024"], ["70636.80", "0.002"], ["70638.50", "0.001"]], "a": [["70649.50", "0.008"], ["70650.80", "0.029"], ["70706.10", "0.002"], ["70739.30", "0.130"], ["70857.50", "2.835"], ["70875.00", "0.294"], ["70991.90", "3.376"], ["71345.10", "0.000"], ["71505.70", "2.770"], ["71667.70", "20.063"], ["71837.30", "0.967"]]}}
{"local_ts": 1773487029752, "server_ts": 1773487029723, "data": {"e": "depthUpdate", "E": 1773487029725, "T": 1773487029723, "s": "BTCUSDT", "U": 10109536548930, "u": 10109536552424, "pu": 10109536548908, "b": [["1000.00", "27.042"], ["5000.00", "101.418"], ["7063.90", "0.028"], ["20438.60", "1.490"], ["20538.60", "1.510"], ["68949.90", "0.000"], ["69261.10", "0.649"], ["69614.30", "13.052"], ["69932.20", "0.000"], ["70285.40", "3.408"], ["70465.50", "0.251"], ["70590.40", "0.000"], ["70607.10", "0.092"], ["70607.20", "0.840"], ["70620.10", "0.583"], ["70620.90", "1.223"], ["70627.10", "0.008"], ["70627.70", "0.023"], ["70628.90", "0.005"], ["70629.20", "0.269"], ["70629.70", "0.005"], ["70630.90", "0.201"], ["70631.40", "0.261"], ["70631.60", "0.184"], ["70635.00", "0.017"], ["70636.40", "0.024"], ["70636.60", "0.390"]], "a": [["70638.70", "8.437"], ["70640.70", "0.007"], ["70641.60", "0.000"], ["70645.70", "0.009"], ["70649.30", "0.008"], ["70737.70", "0.080"], ["70739.30", "0.128"], ["70857.40", "0.015"], ["70862.20", "0.279"], ["71345.10", "0.000"], ["71667.70", "18.112"], ["72054.80", "0.000"], ["72972.00", "1.095"], ["74187.80", "0.002"], ["89523.20", "0.000"]]}}
{"local_ts": 1773487030772, "server_ts": 1773487030744, "data": {"e": "depthUpdate", "E": 1773487030745, "T": 1773487030744, "s": "BTCUSDT", "U": 10109536591226, "u": 10109536594853, "pu": 10109536591004, "b": [["5000.00", "101.418"], ["7063.90", "0.000"], ["20338.60", "1.050"], ["20438.60", "1.950"], ["69423.60", "0.287"], ["69543.70", "10.848"], ["69614.30", "16.064"], ["70073.50", "0.071"], ["70300.20", "0.029"], ["70392.20", "0.000"], ["70549.10", "0.050"], ["70549.80", "0.180"], ["70550.80", "0.422"], ["70551.20", "0.057"], ["70552.50", "2.235"], ["70554.50", "0.088"], ["70593.70", "0.511"], ["70593.80", "0.860"], ["70607.20", "0.840"], ["70607.70", "0.088"], ["70614.70", "1.074"], ["70616.10", "0.262"], ["70617.30", "0.131"], ["70628.20", "0.637"], ["70628.90", "0.005"], ["70629.10", "0.000"]], "a": [["70638.70", "8.747"], ["70642.80", "0.004"], ["70643.80", "0.113"], ["70645.30", "0.031"], ["70670.60", "0.006"], ["70671.10", "0.011"], ["70700.30", "0.038"], ["70735.00", "0.010"], ["70737.70", "0.078"], ["71208.50", "1.122"], ["71345.10", "0.000"], ["71667.70", "12.260"], ["71809.00", "2.919"], ["74192.60", "0.000"], ["74205.20", "0.002"], ["89523.20", "0.000"]]}}
{"local_ts": 1773487031795, "server_ts": 1773487031768, "data": {"e": "depthUpdate", "E": 1773487031769, "T": 1773487031768, "s": "BTCUSDT", "U": 10109536631960, "u": 10109536635593, "pu": 10109536631923, "b": [["1000.00", "27.042"], ["5000.00", "101.418"], ["7063.90", "0.000"], ["20238.60", "0.610"], ["20338.60", "2.390"], ["20438.60", "0.000"], ["67087.50", "0.017"], ["69623.30", "1.434"], ["70590.40", "0.354"]], "a": [["70669.60", "0.339"], ["70676.10", "0.000"], ["70735.00", "0.008"], ["71345.10", "0.700"], ["71592.30", "0.278"], ["71723.10", "0.000"], ["71928.10", "0.000"], ["72422.90", "2.484"], ["89523.20", "0.000"]]}}
{"local_ts": 1773487032816, "server_ts": 1773487032790, "data": {"e": "depthUpdate", "E": 1773487032791, "T": 1773487032790, "s": "BTCUSDT", "U": 10109536676889, "u": 10109536680928, "pu": 10109536676833, "b": [["1000.00", "27.042"], ["5000.00", "101.418"], ["7063.90", "0.000"], ["20138.60", "0.290"], ["20238.60", "2.580"], ["20338.60", "0.130"], ["67079.50", "0.002"], ["67094.20", "0.002"], ["67106.00", "0.000"], ["69932.20", "0.714"], ["70078.20", "3.206"], ["70546.70", "0.189"], ["70553.70", "0.142"], ["70560.80", "0.000"], ["70560.90", "0.003"], ["70575.00", "0.085"], ["70590.40", "0.000"], ["70590.90", "0.250"], ["70613.90", "0.651"], ["70628.50", "0.016"], ["70629.90", "0.217"], ["70630.00", "0.186"], ["70633.30", "0.008"], ["70634.10", "0.002"], ["70635.10", "0.511"], ["70636.50", "0.673"], ["70638.00", "0.123"]], "a": [["70641.90", "0.066"], ["70672.60", "0.000"], ["70673.10", "0.263"], ["70702.30", "0.300"], ["70716.30", "0.145"], ["70716.40", "0.609"], ["70723.40", "0.019"], ["70730.40", "0.142"], ["71345.10", "0.700"], ["71608.50", "0.030"], ["89523.20", "0.000"]]}}
{"local_ts": 1773487033852, "server_ts": 1773487033810, "data": {"e": "depthUpdate", "E": 1773487033811, "T": 1773487033810, "s": "BTCUSDT", "U": 10109536716113, "u": 10109536719576, "pu": 10109536716028, "b": [["5000.00", "101.438"], ["7063.90", "0.056"], ["20138.60", "2.430"], ["20238.60", "0.430"], ["20538.60", "0.140"], ["67090.60", "0.002"], ["69932.20", "0.714"], ["70100.10", "0.499"], ["70217.10", "36.846"], ["70222.10", "18.612"], ["70288.90", "0.000"], ["70310.10", "0.106"], ["70313.70", "0.106"], ["70322.60", "31.240"], ["70322.70", "0.648"], ["70325.50", "4.917"], ["70400.00", "38.261"], ["70401.90", "5.554"], ["70465.50", "0.251"], ["70468.20", "4.546"], ["70470.20", "0.095"], ["70507.00", "0.846"], ["70582.10", "0.621"], ["70589.30", "0.009"], ["70589.60", "0.114"], ["70590.30", "0.083"], ["70592.10", "8.497"], ["70598.30", "0.208"], ["70617.50", "0.004"], ["70618.00", "0.111"], ["70618.60", "0.273"], ["70618.80", "0.242"], ["70620.00", "0.258"], ["70620.70", "0.074"], ["70620.90", "0.054"], ["70621.00", "1.203"], ["70622.10", "0.098"], ["70622.30", "0.047"], ["70622.40", "0.003"], ["70622.50", "0.003"], ["70623.70", "0.048"], ["70624.10", "0.514"], ["70624.20", "0.329"], ["70624.50", "0.004"], ["70624.60", "0.002"], ["70625.10", "0.511"], ["70625.50", "0.146"], ["70625.70", "0.072"], ["70627.00", "0.154"], ["70629.20", "0.235"], ["70629.30", "0.004"], ["70629.70", "0.002"], ["70630.40", "0.003"], ["70630.90", "0.837"], ["70631.00", "0.092"], ["70631.60", "0.262"], ["70634.10", "0.000"], ["70634.70", "0.002"], ["70634.80", "0.021"], ["70636.50", "0.673"], ["70637.80", "0.002"], ["70638.50", "0.020"], ["70638.60", "2.927"]], "a": [["70638.70", "8.120"], ["70640.50", "0.006"], ["70640.70", "0.000"], ["70640.90", "0.009"], ["70641.60", "0.000"], ["70642.70", "0.021"], ["70643.30", "0.178"], ["70644.00", "0.085"], ["70645.30", "0.031"], ["70645.70", "0.007"], ["70647.80", "0.192"], ["70647.90", "0.288"], ["70656.80", "0.001"], ["70657.50", "0.007"], ["70660.40", "0.000"], ["70660.90", "0.143"], ["70665.30", "0.009"], ["70666.30", "0.126"], ["70666.40", "0.843"], ["70667.60", "0.000"], ["70668.10", "0.509"], ["70669.60", "0.339"], ["70671.00", "0.070"], ["70671.50", "0.737"], ["70672.40", "0.073"], ["70672.60", "0.000"], ["70673.10", "0.023"], ["70674.30", "0.000"], ["70675.50", "0.051"], ["70676.50", "0.025"], ["70677.30", "0.055"], ["70703.80", "0.064"], ["70705.70", "8.484"], ["70775.10", "0.334"], ["70775.40", "0.000"], ["70813.90", "2.202"], ["70815.30", "0.000"], ["70882.40", "0.106"], ["70885.50", "6.837"], ["70885.60", "26.523"], ["70885.90", "0.000"], ["70887.80", "0.000"], ["70963.50", "0.648"], ["70963.60", "31.245"], ["71070.10", "37.360"], ["71249.90", "3.243"], ["71303.30", "0.000"], ["71345.10", "2.100"], ["71929.70", "0.002"], ["74186.20", "0.012"], ["89523.20", "0.000"]]}}
{"local_ts": 1773487034866, "server_ts": 1773487034832, "data": {"e": "depthUpdate", "E": 1773487034833, "T": 1773487034832, "s": "BTCUSDT", "U": 10109536755647, "u": 10109536760118, "pu": 10109536755516, "b": [["1000.00", "27.042"], ["5000.00", "101.418"], ["7063.90", "0.056"], ["20138.60", "0.730"], ["20538.60", "2.270"], ["56511.00", "0.007"], ["63574.70", "0.002"], ["67106.70", "0.008"], ["69790.90", "1.573"], ["69932.20", "0.721"], ["70073.50", "0.285"], ["70285.40", "3.408"], ["70310.10", "0.000"], ["70313.70", "0.000"], ["70324.30", "0.106"], ["70526.60", "0.000"], ["70550.50", "0.000"], ["70559.50", "0.002"], ["70592.20", "0.121"], ["70594.50", "0.142"], ["70607.70", "0.088"], ["70608.10", "0.003"], ["70614.10", "0.002"], ["70633.30", "0.008"], ["70638.60", "3.354"]], "a": [["70638.70", "7.536"], ["70638.80", "0.075"], ["70641.00", "0.008"], ["70641.60", "0.000"], ["70643.20", "0.059"], ["70646.90", "0.065"], ["70668.20", "0.424"], ["70684.50", "0.050"], ["70765.90", "4.349"], ["70768.20", "0.279"], ["70797.60", "0.164"], ["71345.10", "2.100"], ["71699.00", "0.236"], ["71766.60", "14.519"], ["74199.90", "0.000"], ["77702.60", "0.002"], ["89523.20", "0.000"]]}}
{"local_ts": 1773487035883, "server_ts": 1773487035852, "data": {"e": "depthUpdate", "E": 1773487035855, "T": 1773487035852, "s": "BTCUSDT", "U": 10109536801201, "u": 10109536806381, "pu": 10109536801162, "b": [["5000.00", "101.418"], ["7063.90", "0.056"], ["20438.60", "1.820"], ["20538.60", "1.180"], ["33000.00", "3.785"], ["63574.70", "0.002"], ["67097.90", "0.002"], ["67106.70", "0.008"], ["67106.80", "0.006"], ["67806.70", "0.002"], ["67813.10", "0.643"], ["69567.90", "0.066"], ["69720.30", "0.859"], ["69932.20", "0.721"], ["70073.50", "0.428"], ["70465.50", "0.251"], ["70485.40", "0.085"], ["70501.60", "0.085"], ["70551.80", "0.086"], ["70552.40", "0.809"], ["70552.60", "0.086"], ["70553.60", "0.094"], ["70553.90", "0.053"], ["70555.20", "0.150"], ["70557.20", "0.086"], ["70559.50", "0.000"], ["70588.10", "0.092"], ["70598.30", "0.250"], ["70618.00", "0.111"], ["70636.20", "0.000"], ["70636.50", "0.673"], ["70638.60", "3.346"]], "a": [["70638.70", "7.505"], ["70645.50", "3.169"], ["70646.70", "0.003"], ["70647.80", "0.134"], ["70653.80", "0.006"], ["70654.60", "0.144"], ["70703.00", "0.038"], ["70766.00", "0.220"], ["70768.20", "0.277"], ["71345.10", "2.100"], ["71973.80", "0.416"], ["77702.60", "0.002"], ["89523.20", "0.000"]]}}
{"local_ts": 1773487036902, "server_ts": 1773487036872, "data": {"e": "depthUpdate", "E": 1773487036875, "T": 1773487036872, "s": "BTCUSDT", "U": 10109536847671, "u": 10109536851063, "pu": 10109536847662, "b": [["1000.00", "27.042"], ["5000.00", "101.418"], ["7063.90", "0.028"], ["20338.60", "1.370"], ["20438.60", "1.630"], ["63574.70", "0.002"], ["69932.20", "0.721"], ["70310.20", "0.004"], ["70392.30", "2.240"], ["70485.40", "0.000"], ["70501.60", "0.170"], ["70547.00", "0.003"], ["70552.40", "0.807"], ["70582.10", "0.540"], ["70606.20", "0.085"], ["70606.40", "0.288"], ["70615.40", "0.013"], ["70615.50", "0.063"], ["70619.20", "0.015"], ["70620.00", "0.258"], ["70620.60", "0.003"], ["70625.80", "0.400"], ["70627.20", "0.009"], ["70627.60", "0.005"], ["70628.90", "0.286"], ["70629.40", "0.403"], ["70629.50", "0.691"], ["70635.10", "0.511"], ["70636.40", "0.003"], ["70638.00", "0.130"], ["70638.30", "0.004"], ["70638.60", "3.281"]], "a": [["70638.80", "0.073"], ["70639.40", "0.002"], ["70640.00", "0.022"], ["70640.20", "0.000"], ["70641.40", "0.015"], ["70641.60", "0.000"], ["70641.70", "0.001"], ["70642.00", "0.008"], ["70642.10", "0.298"], ["70645.30", "0.031"], ["70646.90", "0.065"], ["70647.80", "0.134"], ["70651.80", "0.046"], ["70674.40", "0.002"], ["70675.80", "0.247"], ["70681.50", "0.096"], ["70765.80", "0.263"], ["70766.00", "0.218"], ["71345.10", "2.100"], ["71947.30", "0.348"], ["74203.80", "0.000"], ["77702.60", "0.002"], ["89523.20", "0.000"]]}}
{"local_ts": 1773487037922, "server_ts": 1773487037892, "data": {"e": "depthUpdate", "E": 1773487037895, "T": 1773487037892, "s": "BTCUSDT", "U": 10109536889990, "u": 10109536893594, "pu": 10109536889965, "b": [["1000.00", "27.042"], ["5000.00", "101.418"], ["7063.90", "0.028"], ["20238.60", "0.920"], ["20338.60", "2.080"], ["33000.00", "3.789"], ["63574.70", "0.002"], ["69503.30", "0.000"], ["69791.00", "0.007"], ["69932.20", "0.721"], ["70310.10", "0.106"], ["70310.20", "0.000"], ["70547.00", "0.001"], ["70558.20", "0.024"], ["70594.10", "0.009"], ["70594.20", "0.819"], ["70604.10", "0.281"], ["70619.20", "0.247"], ["70620.00", "0.011"], ["70621.10", "0.018"], ["70634.40", "0.005"], ["70634.70", "0.101"], ["70635.90", "0.004"], ["70636.40", "0.003"], ["70636.90", "0.041"], ["70637.10", "0.003"], ["70638.60", "3.267"]], "a": [["70639.60", "0.001"], ["70640.70", "0.000"], ["70643.10", "0.003"], ["70674.40", "0.249"], ["70675.80", "0.000"], ["70765.80", "0.261"], ["70767.70", "0.088"], ["70862.30", "0.000"], ["71203.80", "0.222"], ["71345.00", "0.121"], ["71345.10", "2.100"], ["71874.90", "3.340"], ["74185.60", "0.002"], ["74200.90", "0.000"], ["77702.60", "0.002"], ["89523.20", "0.006"]]}}
{"local_ts": 1773487038944, "server_ts": 1773487038912, "data": {"e": "depthUpdate", "E": 1773487038915, "T": 1773487038912, "s": "BTCUSDT", "U": 10109536928858, "u": 10109536932475, "pu": 10109536928803, "b": [["5000.00", "101.398"], ["7063.90", "0.028"], ["20138.60", "0.470"], ["20238.60", "2.530"], ["20338.60", "0.000"], ["63574.70", "0.002"], ["67081.90", "0.002"], ["69402.40", "5.397"], ["69721.00", "4.296"], ["69932.20", "0.721"], ["70507.10", "0.000"], ["70543.20", "0.006"], ["70558.20", "0.022"], ["70603.30", "0.002"], ["70635.10", "0.511"], ["70636.50", "0.673"], ["70638.60", "3.266"]], "a": [["70638.70", "6.998"], ["70639.00", "0.002"], ["70639.20", "0.000"], ["70646.90", "0.008"], ["70763.80", "0.004"], ["70767.70", "0.086"], ["70774.30", "0.247"], ["71198.80", "0.000"], ["71249.90", "0.651"], ["71303.30", "3.240"], ["71345.10", "3.500"], ["71575.80", "0.070"], ["71844.00", "0.011"], ["72773.10", "1.064"], ["74174.50", "0.065"], ["77702.60", "0.002"]]}}
{"local_ts": 1773487039963, "server_ts": 1773487039935, "data": {"e": "depthUpdate", "E": 1773487039937, "T": 1773487039935, "s": "BTCUSDT", "U": 10109536967518, "u": 10109536971455, "pu": 10109536967443, "b": [["1000.00", "27.042"], ["5000.00", "101.418"], ["7063.90", "0.000"], ["20138.60", "2.520"], ["20238.60", "0.230"], ["20538.60", "0.250"], ["56511.00", "0.007"], ["63574.70", "0.000"], ["67089.50", "0.000"], ["67110.00", "0.091"], ["69932.20", "0.721"], ["70285.40", "3.408"], ["70594.20", "0.819"], ["70594.40", "0.006"], ["70607.40", "0.085"], ["70607.50", "0.012"], ["70621.10", "0.018"], ["70634.10", "0.053"], ["70634.20", "0.091"], ["70634.30", "0.056"], ["70634.50", "0.026"], ["70638.60", "3.046"]], "a": [["70638.70", "7.691"], ["70640.10", "0.006"], ["70645.40", "0.565"], ["70647.80", "0.134"], ["70662.10", "0.570"], ["70663.80", "0.002"], ["71345.10", "3.500"], ["71768.30", "0.000"], ["73464.20", "0.033"], ["74186.80", "0.010"], ["77702.60", "0.000"]]}}
{"local_ts": 1773487040986, "server_ts": 1773487040960, "data": {"e": "depthUpdate", "E": 1773487040961, "T": 1773487040960, "s": "BTCUSDT", "U": 10109537008785, "u": 10109537011683, "pu": 10109537008698, "b": [["5000.00", "101.418"], ["7063.90", "0.000"], ["20138.60", "0.520"], ["20438.60", "0.100"], ["20538.60", "2.380"], ["63574.70", "0.000"], ["69378.50", "2.322"], ["69932.20", "0.721"], ["69937.00", "0.000"], ["70401.90", "5.640"], ["70496.40", "12.567"], ["70506.90", "0.176"], ["70524.50", "0.242"], ["70542.00", "0.119"], ["70550.70", "0.252"], ["70551.00", "0.062"], ["70551.30", "0.052"], ["70552.10", "0.166"], ["70552.30", "0.180"], ["70554.40", "0.086"], ["70554.70", "6.438"], ["70556.20", "2.424"], ["70559.00", "0.000"], ["70562.00", "0.003"], ["70582.10", "0.540"], ["70589.50", "3.285"], ["70603.30", "0.060"], ["70610.70", "1.776"], ["70612.10", "0.276"], ["70636.30", "0.070"], ["70636.50", "0.673"], ["70638.10", "0.012"], ["70638.60", "3.233"]], "a": [["70638.70", "6.539"], ["70638.80", "0.075"], ["70642.10", "0.293"], ["70662.80", "0.007"], ["70680.00", "4.463"], ["70700.10", "1.207"], ["70701.30", "3.359"], ["70702.00", "0.081"], ["70735.40", "1.530"], ["70736.40", "6.482"], ["70787.00", "0.090"], ["70794.90", "12.243"], ["70819.70", "0.002"], ["70820.30", "0.004"], ["70862.00", "0.004"], ["71203.80", "1.203"], ["71345.10", "3.500"], ["74170.60", "0.005"], ["74201.20", "0.002"], ["77702.60", "0.000"]]}}
{"local_ts": 1773487042008, "server_ts": 1773487041981, "data": {"e": "depthUpdate", "E": 1773487041983, "T": 1773487041981, "s": "BTCUSDT", "U": 10109537050486, "u": 10109537053981, "pu": 10109537050444, "b": [["1000.00", "27.042"], ["5000.00", "101.418"], ["7063.90", "0.000"], ["20438.60", "2.140"], ["20538.60", "0.860"], ["63574.70", "0.000"], ["67813.10", "1.919"], ["69656.70", "3.581"], ["69932.20", "0.721"], ["70285.50", "0.300"], ["70391.80", "0.008"], ["70494.80", "12.510"], ["70507.10", "0.849"], ["70553.90", "6.527"], ["70560.90", "0.003"], ["70575.00", "0.085"], ["70589.80", "0.197"], ["70594.00", "0.219"], ["70594.20", "0.821"], ["70604.70", "0.006"], ["70619.20", "0.000"], ["70620.00", "0.258"], ["70620.60", "0.003"], ["70631.60", "0.253"], ["70638.50", "0.061"]], "a": [["70638.70", "7.500"], ["70639.30", "0.057"], ["70640.10", "0.006"], ["70640.70", "0.000"], ["70642.00", "0.008"], ["70642.10", "0.305"], ["70642.80", "0.004"], ["70643.30", "0.178"], ["70643.40", "0.048"], ["70644.60", "0.087"], ["70644.70", "0.007"], ["70648.10", "0.003"], ["70648.20", "0.087"], ["70652.20", "0.022"], ["70653.50", "0.018"], ["70658.70", "0.221"], ["70660.60", "0.022"], ["70674.50", "0.514"], ["70675.80", "0.272"], ["70678.20", "0.288"], ["70702.30", "0.264"], ["70716.40", "0.609"], ["70736.60", "6.498"], ["70736.90", "0.052"], ["70744.20", "0.644"], ["70746.50", "0.005"], ["70752.40", "12.539"], ["70773.90", "0.466"], ["70795.40", "12.535"], ["70819.70", "0.000"], ["70819.80", "0.004"], ["71345.10", "4.900"], ["71733.60", "8.238"], ["74177.60", "0.002"], ["77702.60", "0.000"]]}}
{"local_ts": 1773487043034, "server_ts": 1773487043003, "data": {"e": "depthUpdate", "E": 1773487043005, "T": 1773487043003, "s": "BTCUSDT", "U": 10109537089527, "u": 10109537092553, "pu": 10109537089492, "b": [["1000.00", "27.042"], ["5000.00", "101.418"], ["7063.90", "0.028"], ["20338.60", "1.690"], ["20438.60", "1.310"], ["33000.00", "3.785"], ["56511.00", "0.007"], ["63574.70", "0.000"], ["69932.20", "2.149"], ["70310.10", "0.000"], ["70313.70", "0.000"], ["70501.70", "0.259"], ["70574.10", "0.214"], ["70588.10", "0.092"], ["70609.40", "0.007"], ["70609.90", "0.188"], ["70611.60", "0.296"], ["70616.10", "0.000"], ["70616.20", "0.127"], ["70620.20", "0.158"], ["70623.60", "0.079"], ["70624.60", "0.002"], ["70626.20", "0.011"], ["70631.60", "0.312"], ["70633.30", "0.008"], ["70636.80", "0.037"], ["70636.90", "0.005"], ["70637.40", "0.003"], ["70638.10", "0.053"], ["70638.20", "0.006"], ["70638.30", "0.025"], ["70638.40", "0.002"], ["70638.50", "0.046"], ["70638.60", "3.027"]], "a": [["70638.70", "6.841"], ["70638.80", "0.132"], ["70639.70", "0.000"], ["70639.80", "0.015"], ["70640.20", "0.008"], ["70642.60", "0.031"], ["70651.80", "0.002"], ["70666.40", "0.843"], ["70667.60", "0.000"], ["70680.00", "2.651"], ["70701.20", "0.000"], ["70783.50", "0.039"], ["70787.00", "0.129"], ["70819.80", "0.002"], ["70822.20", "0.002"], ["70862.30", "0.000"], ["70901.90", "0.007"], ["71345.10", "4.900"], ["74183.00", "0.054"], ["77702.60", "0.000"]]}}
{"local_ts": 1773487044058, "server_ts": 1773487044026, "data": {"e": "depthUpdate", "E": 1773487044027, "T": 1773487044026, "s": "BTCUSDT", "U": 10109537128871, "u": 10109537132969, "pu": 10109537128795, "b": [["5000.00", "101.418"], ["7063.90", "0.056"], ["20238.60", "1.250"], ["20338.60", "1.750"], ["63574.70", "0.000"], ["67078.80", "0.002"], ["67083.50", "0.000"], ["67106.00", "0.020"], ["69785.80", "0.000"], ["69932.20", "2.149"], ["69932.30", "0.721"], ["70073.50", "1.568"], ["70300.00", "21.790"], ["70306.60", "3.582"], ["70324.30", "0.106"], ["70392.50", "0.000"], ["70593.90", "0.047"], ["70594.10", "0.007"], ["70609.90", "0.188"], ["70611.60", "0.112"], ["70626.20", "0.011"], ["70630.50", "0.018"], ["70630.70", "0.021"], ["70631.10", "0.128"], ["70631.60", "0.339"], ["70634.90", "0.014"], ["70636.80", "0.014"], ["70638.60", "2.985"]], "a": [["70638.70", "6.816"], ["70638.80", "0.132"], ["70640.10", "0.071"], ["70664.50", "0.060"], ["70664.60", "0.002"], ["70746.80", "0.214"], ["70752.40", "12.584"], ["70822.20", "0.000"], ["70823.50", "0.019"], ["71345.10", "4.900"], ["71503.50", "0.000"], ["71641.20", "1.796"], ["77702.60", "0.000"]]}}
{"local_ts": 1773487045080, "server_ts": 1773487045048, "data": {"e": "depthUpdate", "E": 1773487045049, "T": 1773487045048, "s": "BTCUSDT", "U": 10109537168827, "u": 10109537174518, "pu": 10109537168724, "b": [["1000.00", "27.042"], ["5000.00", "101.398"], ["7063.90", "0.056"], ["20138.60", "0.800"], ["20238.60", "2.200"], ["33000.00", "3.789"], ["67098.10", "0.000"], ["68519.50", "0.003"], ["69932.20", "2.149"], ["70285.40", "3.479"], ["70560.90", "0.006"], ["70567.70", "0.007"], ["70575.00", "0.088"], ["70582.10", "0.540"], ["70587.00", "0.035"], ["70604.70", "0.006"], ["70609.90", "0.004"], ["70623.80", "0.029"], ["70623.90", "0.001"], ["70624.50", "0.004"], ["70624.90", "0.070"], ["70625.10", "0.581"], ["70625.20", "0.143"], ["70625.90", "0.007"], ["70627.50", "0.462"], ["70629.10", "0.000"], ["70629.40", "0.403"], ["70636.40", "0.003"], ["70637.70", "0.004"], ["70637.90", "0.003"], ["70638.10", "0.046"], ["70638.30", "0.011"], ["70638.40", "0.002"], ["70638.50", "0.054"], ["70638.60", "3.188"]], "a": [["70638.70", "6.138"], ["70638.80", "0.129"], ["70639.50", "0.015"], ["70640.00", "0.002"], ["70640.40", "0.000"], ["70640.70", "0.007"], ["70640.80", "0.017"], ["70641.30", "0.000"], ["70641.80", "0.001"], ["70641.90", "0.009"], ["70642.10", "0.305"], ["70643.80", "0.085"], ["70644.20", "0.132"], ["70653.50", "0.003"], ["70671.30", "0.463"], ["70671.80", "0.073"], ["70687.20", "1.059"], ["70702.30", "0.267"], ["70705.60", "0.000"], ["70716.40", "0.612"], ["70819.70", "0.002"], ["70823.50", "0.017"], ["70862.10", "0.338"], ["70901.90", "0.000"], ["70996.50", "0.000"], ["71345.10", "5.040"], ["71486.40", "3.075"], ["74174.20", "0.002"]]}}
{"local_ts": 1773487046094, "server_ts": 1773487046068, "data": {"e": "depthUpdate", "E": 1773487046069, "T": 1773487046068, "s": "BTCUSDT", "U": 10109537213871, "u": 10109537218956, "pu": 10109537213718, "b": [["5000.00", "101.418"], ["7063.90", "0.028"], ["20138.60", "2.560"], ["20238.60", "0.040"], ["20538.60", "0.400"], ["56511.00", "0.011"], ["67090.10", "0.002"], ["67813.10", "1.923"], ["69439.00", "0.000"], ["69473.10", "4.372"], ["69560.10", "0.430"], ["69932.20", "2.149"], ["70292.20", "0.000"], ["70292.50", "0.106"], ["70292.60", "0.044"], ["70550.80", "0.146"], ["70551.10", "0.143"], ["70551.80", "0.205"], ["70554.20", "0.714"], ["70594.00", "0.221"], ["70594.10", "0.007"], ["70602.10", "0.201"], ["70603.30", "0.060"], ["70607.80", "0.086"], ["70607.90", "0.008"], ["70624.50", "0.171"], ["70625.80", "0.400"], ["70631.60", "0.175"], ["70636.40", "0.003"], ["70638.60", "2.544"]], "a": [["70700.10", "1.680"], ["70701.90", "0.077"], ["71169.00", "0.402"], ["71345.10", "5.040"], ["71641.80", "2.087"], ["71642.80", "0.023"]]}}
{"local_ts": 1773487047120, "server_ts": 1773487047092, "data": {"e": "depthUpdate", "E": 1773487047093, "T": 1773487047092, "s": "BTCUSDT", "U": 10109537255651, "u": 10109537259338, "pu": 10109537255608, "b": [["1000.00", "27.042"], ["5000.00", "101.418"], ["7063.90", "0.028"], ["20138.60", "0.290"], ["20438.60", "0.210"], ["20538.60", "2.500"], ["68519.50", "0.003"], ["69402.40", "7.699"], ["69932.20", "2.149"], ["70465.50", "0.251"], ["70582.80", "0.005"], ["70582.90", "0.000"], ["70590.80", "0.005"], ["70590.90", "0.002"], ["70594.10", "0.007"], ["70594.20", "0.821"], ["70597.90", "0.073"], ["70598.70", "0.617"], ["70598.90", "0.356"], ["70606.80", "0.012"], ["70606.90", "0.370"], ["70614.60", "0.016"], ["70614.70", "1.069"], ["70625.90", "0.003"], ["70631.70", "0.170"], ["70633.30", "0.008"], ["70634.00", "0.018"], ["70635.10", "0.511"], ["70635.90", "0.004"], ["70636.20", "0.012"], ["70636.50", "0.673"], ["70636.60", "0.390"], ["70636.70", "0.026"], ["70637.80", "0.000"], ["70638.10", "0.046"], ["70638.20", "0.006"], ["70638.30", "0.004"], ["70638.50", "0.046"], ["70638.60", "2.539"]], "a": [["70638.70", "6.919"], ["70638.80", "0.129"], ["70640.00", "0.011"], ["70640.10", "0.014"], ["70642.10", "0.311"], ["70642.70", "0.021"], ["70643.80", "0.100"], ["70644.00", "0.142"], ["70645.80", "0.129"], ["70653.50", "0.003"], ["70862.50", "0.051"], ["71198.70", "0.000"], ["71345.10", "5.040"], ["71592.30", "0.627"], ["72757.80", "0.002"], ["74203.20", "0.002"]]}}
{"local_ts": 1773487048142, "server_ts": 1773487048116, "data": {"e": "depthUpdate", "E": 1773487048117, "T": 1773487048116, "s": "BTCUSDT", "U": 10109537294345, "u": 10109537298455, "pu": 10109537294232, "b": [["1000.00", "27.042"], ["5000.00", "101.418"], ["7063.90", "0.028"], ["20338.60", "0.070"], ["20438.60", "2.340"], ["20538.60", "0.590"], ["56511.00", "0.007"], ["69720.30", "4.297"], ["69932.20", "4.648"], ["70594.50", "0.142"], ["70607.70", "0.088"], ["70607.80", "0.001"], ["70625.90", "0.003"], ["70629.10", "0.017"], ["70629.40", "0.001"], ["70631.10", "0.724"], ["70631.70", "0.170"], ["70631.80", "0.372"], ["70633.20", "0.473"], ["70633.30", "0.008"], ["70634.40", "0.003"], ["70635.90", "0.004"], ["70636.20", "0.012"], ["70636.30", "0.055"], ["70636.40", "0.003"], ["70636.80", "0.002"], ["70637.50", "0.002"], ["70638.10", "0.046"], ["70638.60", "2.501"]], "a": [["70638.70", "6.899"], ["70638.80", "0.129"], ["70639.40", "0.000"], ["70640.20", "0.008"], ["70640.60", "0.021"], ["70640.70", "0.057"], ["70641.10", "0.018"], ["70642.60", "0.052"], ["70645.80", "0.129"], ["70647.70", "0.034"], ["70653.50", "0.003"], ["71345.10", "5.040"], ["74181.80", "0.034"]]}}
{"local_ts": 1773487049163, "server_ts": 1773487049136, "data": {"e": "depthUpdate", "E": 1773487049137, "T": 1773487049136, "s": "BTCUSDT", "U": 10109537334181, "u": 10109537337550, "pu": 10109537334123, "b": [["5000.00", "101.438"], ["7063.90", "0.000"], ["20338.60", "2.030"], ["20438.60", "0.970"], ["56511.00", "0.007"], ["67084.90", "0.000"], ["67087.20", "0.000"], ["67106.70", "2.237"], ["67106.80", "0.012"], ["69225.90", "0.028"], ["69327.70", "0.000"], ["69696.20", "1.434"], ["69932.20", "4.648"], ["70285.50", "0.300"], ["70392.50", "0.000"], ["70507.20", "0.002"], ["70608.70", "1.759"], ["70608.80", "0.736"], ["70616.80", "0.003"], ["70616.90", "0.211"], ["70625.90", "0.003"], ["70629.10", "0.017"], ["70629.40", "0.001"], ["70631.70", "0.172"], ["70635.00", "0.029"], ["70635.50", "0.009"], ["70635.60", "0.004"], ["70635.70", "0.012"], ["70636.50", "0.673"]], "a": [["70638.70", "6.908"], ["70645.80", "0.131"], ["70660.50", "0.009"], ["70664.50", "0.020"], ["70665.00", "0.044"], ["70675.50", "0.008"], ["70675.60", "0.185"], ["70676.20", "0.002"], ["70676.30", "0.004"], ["70687.30", "0.011"], ["70773.30", "1.496"], ["71345.10", "5.040"], ["74183.40", "0.977"]]}}
{"local_ts": 1773487050186, "server_ts": 1773487050156, "data": {"e": "depthUpdate", "E": 1773487050157, "T": 1773487050156, "s": "BTCUSDT", "U": 10109537373048, "u": 10109537377928, "pu": 10109537372703, "b": [["1000.00", "27.042"], ["5000.00", "101.438"], ["7063.90", "0.000"], ["20238.60", "1.580"], ["20338.60", "1.420"], ["56511.00", "0.007"], ["67736.00", "0.006"], ["69225.90", "0.019"], ["69932.20", "4.648"], ["70285.40", "3.658"], ["70546.70", "0.189"], ["70553.70", "0.142"], ["70560.80", "0.142"], ["70582.10", "0.540"], ["70593.80", "0.854"], ["70593.90", "0.047"], ["70612.10", "0.137"], ["70614.20", "0.004"], ["70614.60", "0.016"], ["70616.60", "0.007"], ["70617.70", "0.002"], ["70619.00", "0.458"], ["70620.20", "0.158"], ["70621.50", "0.002"], ["70626.40", "0.512"], ["70627.00", "0.154"], ["70627.70", "0.000"], ["70628.00", "0.062"], ["70628.40", "0.286"], ["70630.60", "0.077"], ["70630.70", "0.201"], ["70631.70", "0.170"], ["70632.00", "0.022"], ["70632.70", "0.926"], ["70633.30", "0.175"], ["70633.70", "0.016"], ["70635.00", "0.014"], ["70635.30", "0.043"], ["70635.60", "0.004"], ["70636.70", "0.020"], ["70637.30", "0.021"], ["70638.50", "0.061"], ["70638.60", "3.511"]], "a": [["70638.70", "5.524"], ["70638.90", "0.129"], ["70639.40", "0.000"], ["70639.60", "0.001"], ["70639.80", "0.000"], ["70640.20", "0.000"], ["70640.40", "0.000"], ["70642.10", "0.290"], ["70643.00", "18.682"], ["70644.20", "0.023"], ["70645.50", "3.093"], ["70645.80", "0.129"], ["70647.80", "0.184"], ["70652.60", "0.004"], ["70653.80", "0.147"], ["70662.20", "0.000"], ["70662.80", "0.005"], ["70668.50", "0.002"], ["70669.20", "0.509"], ["70680.50", "0.092"], ["70716.30", "0.145"], ["70723.40", "0.161"], ["70730.40", "0.142"], ["70797.60", "0.164"], ["71345.10", "5.040"], ["74184.30", "0.012"], ["74202.60", "0.000"], ["89523.20", "0.006"]]}}
{"local_ts": 1773487051223, "server_ts": 1773487051176, "data": {"e": "depthUpdate", "E": 1773487051177, "T": 1773487051176, "s": "BTCUSDT", "U": 10109537409888, "u": 10109537412711, "pu": 10109537409830, "b": [["5000.00", "101.398"], ["7063.90", "0.000"], ["20138.60", "1.130"], ["20238.60", "1.870"], ["67106.80", "0.004"], ["69932.20", "4.648"], ["70292.20", "0.000"], ["70292.60", "0.044"], ["70544.30", "0.017"], ["70550.50", "0.603"], ["70551.30", "0.073"], ["70558.40", "0.073"], ["70628.00", "0.062"], ["70630.70", "0.239"], ["70635.10", "0.539"], ["70638.60", "4.363"]], "a": [["70638.70", "3.395"], ["70645.60", "0.298"], ["70645.90", "0.022"], ["70649.30", "0.047"], ["70652.00", "0.078"], ["70720.90", "0.077"], ["70728.00", "1.399"], ["70735.00", "0.079"], ["71345.10", "5.040"], ["71713.70", "0.835"], ["74172.50", "0.055"], ["74187.50", "0.052"], ["89523.20", "0.006"]]}}
{"local_ts": 1773487052225, "server_ts": 1773487052196, "data": {"e": "depthUpdate", "E": 1773487052199, "T": 1773487052196, "s": "BTCUSDT", "U": 10109537438862, "u": 10109537441887, "pu": 10109537438799, "b": [["1000.00", "27.042"], ["5000.00", "101.418"], ["7063.90", "0.000"], ["20138.60", "2.320"], ["20238.60", "0.000"], ["20538.60", "0.680"], ["33000.00", "3.785"], ["67079.10", "0.002"], ["69344.90", "1.851"], ["69932.20", "4.648"], ["70144.10", "0.077"], ["70636.40", "0.018"], ["70636.50", "0.673"], ["70636.60", "0.398"], ["70636.90", "0.005"], ["70638.20", "0.008"], ["70638.30", "0.013"]], "a": [["70639.00", "0.126"], ["70639.10", "0.063"], ["70643.80", "0.041"], ["70645.00", "0.094"], ["70871.00", "0.007"], ["70877.90", "0.002"], ["70880.40", "3.327"], ["71345.00", "0.121"], ["71345.10", "5.040"], ["74180.10", "0.000"], ["74200.60", "0.003"], ["89523.20", "0.006"]]}}
{"local_ts": 1773487053253, "server_ts": 1773487053219, "data": {"e": "depthUpdate", "E": 1773487053221, "T": 1773487053219, "s": "BTCUSDT", "U": 10109537473055, "u": 10109537476730, "pu": 10109537472882, "b": [["1000.00", "27.042"], ["5000.00", "101.418"], ["7063.90", "0.056"], ["20138.60", "0.090"], ["20438.60", "0.320"], ["20538.60", "2.590"], ["68872.60", "0.653"], ["69600.30", "0.004"], ["69932.20", "4.648"], ["70325.70", "0.000"], ["70585.60", "0.921"], ["70594.30", "0.683"], ["70594.40", "0.006"], ["70599.10", "0.229"], ["70603.30", "0.061"], ["70609.10", "0.088"], ["70609.20", "0.206"], ["70612.20", "0.186"], ["70614.10", "0.000"], ["70624.50", "0.074"], ["70628.10", "0.011"], ["70630.40", "0.183"], ["70630.70", "0.242"], ["70631.60", "0.178"], ["70636.50", "0.673"]], "a": [["70638.70", "3.810"], ["70649.30", "0.047"], ["70652.00", "0.078"], ["70704.10", "0.011"], ["70781.00", "0.078"], ["70877.90", "0.000"], ["70885.20", "0.002"], ["71345.10", "5.040"], ["72021.50", "0.000"], ["72051.40", "0.015"], ["74175.70", "0.000"], ["74183.50", "0.257"], ["89523.20", "0.006"]]}}
{"local_ts": 1773487054271, "server_ts": 1773487054244, "data": {"e": "depthUpdate", "E": 1773487054245, "T": 1773487054244, "s": "BTCUSDT", "U": 10109537505690, "u": 10109537509596, "pu": 10109537505597, "b": [["5000.00", "101.418"], ["7063.90", "0.056"], ["20338.60", "0.170"], ["20438.60", "2.460"], ["20538.60", "0.370"], ["33000.00", "3.789"], ["67090.20", "0.003"], ["69825.60", "1.418"], ["69932.20", "4.648"], ["70483.10", "0.000"], ["70486.50", "0.514"], ["70560.90", "0.006"], ["70575.00", "0.088"], ["70589.80", "0.201"], ["70594.10", "0.009"], ["70594.30", "0.683"], ["70598.50", "0.012"], ["70609.00", "0.092"], ["70609.10", "0.003"], ["70612.20", "0.002"], ["70627.60", "0.012"], ["70628.00", "0.065"], ["70628.10", "0.011"], ["70629.20", "0.518"], ["70629.50", "0.708"], ["70629.80", "0.018"], ["70629.90", "0.217"], ["70630.70", "0.245"], ["70636.40", "0.003"], ["70638.60", "3.691"]], "a": [["70638.80", "0.322"], ["70649.30", "0.047"], ["70702.30", "0.292"], ["70716.40", "0.612"], ["70780.00", "1.361"], ["70787.00", "0.129"], ["70885.20", "0.000"], ["70885.80", "0.290"], ["71345.10", "5.040"], ["71846.50", "0.695"], ["74198.20", "0.002"], ["89523.20", "0.006"]]}}
{"local_ts": 1773487055310, "server_ts": 1773487055268, "data": {"e": "depthUpdate", "E": 1773487055269, "T": 1773487055268, "s": "BTCUSDT", "U": 10109537541627, "u": 10109537545819, "pu": 10109537541565, "b": [["1000.00", "27.042"], ["5000.00", "101.418"], ["7063.90", "0.028"], ["20238.60", "0.030"], ["20338.60", "2.300"], ["20438.60", "0.670"], ["67106.00", "0.000"], ["67106.80", "0.002"], ["69580.90", "7.030"], ["69685.00", "1.861"], ["69932.20", "5.362"], ["70285.40", "3.658"], ["70491.60", "0.000"], ["70494.40", "0.000"], ["70497.40", "0.173"], ["70547.70", "0.350"], ["70609.40", "1.924"], ["70609.50", "0.000"], ["70617.50", "0.004"], ["70617.60", "0.067"], ["70623.60", "0.079"], ["70624.50", "0.004"], ["70628.00", "0.062"], ["70630.70", "0.242"], ["70638.60", "2.659"]], "a": [["70638.70", "4.747"], ["70642.80", "0.002"], ["70644.10", "0.018"], ["70670.30", "0.097"], ["70672.00", "1.272"], ["70674.40", "0.002"], ["70675.30", "0.064"], ["70733.00", "0.004"], ["70735.30", "0.088"], ["70880.20", "2.730"], ["70885.80", "0.288"], ["71345.10", "5.040"], ["74182.90", "0.000"], ["89523.20", "0.006"]]}}
{"local_ts": 1773487056317, "server_ts": 1773487056290, "data": {"e": "depthUpdate", "E": 1773487056291, "T": 1773487056290, "s": "BTCUSDT", "U": 10109537585445, "u": 10109537591019, "pu": 10109537585424, "b": [["5000.00", "101.418"], ["7063.90", "0.028"], ["20238.60", "1.910"], ["20338.60", "1.090"], ["68233.10", "0.002"], ["69614.30", "22.591"], ["69932.20", "5.362"], ["70073.50", "1.639"], ["70430.80", "0.000"], ["70594.10", "0.007"], ["70594.20", "0.821"], ["70609.60", "0.127"], ["70609.80", "7.796"], ["70618.90", "0.086"], ["70620.10", "0.004"], ["70627.90", "0.006"], ["70628.00", "0.330"], ["70628.60", "0.026"], ["70629.10", "0.027"], ["70629.30", "0.005"], ["70637.60", "0.014"], ["70637.90", "0.003"], ["70638.60", "1.862"]], "a": [["70638.70", "5.112"], ["70640.60", "0.008"], ["70641.90", "0.030"], ["70650.50", "0.003"], ["70651.10", "0.194"], ["70654.00", "0.454"], ["70664.80", "0.020"], ["70665.40", "0.642"], ["70724.70", "0.502"], ["70728.00", "1.240"], ["70731.80", "0.245"], ["70733.00", "0.002"], ["70733.80", "0.000"], ["70735.30", "0.000"], ["70735.50", "0.006"], ["70737.80", "0.003"], ["70740.50", "0.000"], ["70743.00", "0.335"], ["70746.20", "0.128"], ["70750.30", "0.000"], ["70752.60", "0.204"], ["70830.30", "0.000"], ["70878.80", "0.002"], ["71203.80", "1.343"], ["71345.10", "5.040"], ["71720.90", "0.000"], ["72160.20", "0.000"], ["73464.20", "0.047"], ["74195.20", "0.000"], ["89523.20", "0.006"]]}}
{"local_ts": 1773487057347, "server_ts": 1773487057308, "data": {"e": "depthUpdate", "E": 1773487057311, "T": 1773487057308, "s": "BTCUSDT", "U": 10109537628126, "u": 10109537632234, "pu": 10109537628011, "b": [["1000.00", "27.042"], ["5000.00", "101.418"], ["7063.90", "0.028"], ["20138.60", "1.460"], ["20238.60", "1.540"], ["67813.10", "2.570"], ["69614.40", "2.011"], ["69932.20", "6.076"], ["70285.40", "3.658"], ["70465.50", "0.251"], ["70487.20", "0.000"], ["70544.10", "0.816"], ["70551.10", "0.247"], ["70558.20", "0.187"], ["70594.50", "0.246"], ["70627.10", "0.322"], ["70627.50", "0.470"], ["70628.00", "0.330"], ["70628.30", "0.054"], ["70628.60", "0.026"], ["70629.30", "0.002"], ["70630.70", "0.034"], ["70631.60", "0.177"], ["70631.70", "0.000"], ["70636.40", "0.003"], ["70637.50", "0.002"], ["70637.70", "0.017"], ["70637.90", "0.024"], ["70638.10", "0.046"], ["70638.60", "1.803"]], "a": [["70638.70", "5.072"], ["70640.50", "0.008"], ["70640.60", "0.008"], ["70645.80", "0.129"], ["70649.30", "0.005"], ["70662.10", "0.593"], ["70663.10", "0.011"], ["70676.80", "0.255"], ["70720.70", "0.073"], ["70727.80", "0.325"], ["70734.80", "0.734"], ["70735.50", "0.004"], ["70736.30", "0.002"], ["71345.10", "5.740"], ["71890.20", "0.000"], ["74183.70", "0.002"], ["89523.20", "0.006"]]}}
{"local_ts": 1773487058358, "server_ts": 1773487058332, "data": {"e": "depthUpdate", "E": 1773487058333, "T": 1773487058332, "s": "BTCUSDT", "U": 10109537668205, "u": 10109537671384, "pu": 10109537668118, "b": [["1000.00", "27.042"], ["5000.00", "101.418"], ["7063.90", "0.028"], ["20138.60", "1.980"], ["20538.60", "1.020"], ["67079.90", "0.003"], ["67106.70", "2.241"], ["69614.30", "25.962"], ["69719.50", "0.007"], ["69790.90", "7.100"], ["69932.20", "6.078"], ["70285.40", "3.764"], ["70465.50", "0.251"], ["70494.90", "0.093"], ["70544.10", "0.816"], ["70551.10", "0.247"], ["70554.00", "0.856"], ["70556.20", "1.660"], ["70558.20", "0.187"], ["70589.40", "0.000"], ["70591.20", "0.361"], ["70591.40", "0.306"], ["70591.50", "0.172"], ["70594.50", "0.246"], ["70609.40", "0.007"], ["70620.00", "0.258"], ["70620.90", "0.122"], ["70626.20", "0.071"], ["70628.00", "0.047"], ["70628.60", "0.028"], ["70629.10", "0.027"], ["70630.70", "0.031"], ["70633.30", "0.008"], ["70636.80", "0.002"], ["70638.60", "1.802"]], "a": [["70642.10", "0.063"], ["70649.30", "0.008"], ["70650.50", "0.006"], ["70679.80", "0.039"], ["70700.10", "1.171"], ["70701.20", "0.039"], ["70720.70", "0.073"], ["70727.80", "0.327"], ["70730.10", "0.002"], ["70734.80", "0.734"], ["70736.30", "0.000"], ["70736.50", "0.000"], ["70787.00", "0.129"], ["70793.90", "0.189"], ["70795.80", "0.247"], ["70797.70", "0.118"], ["71342.60", "1.388"], ["71345.10", "5.742"], ["71486.40", "4.471"], ["71576.50", "0.000"], ["89523.20", "0.006"]]}}
{"local_ts": 1773487059385, "server_ts": 1773487059354, "data": {"e": "depthUpdate", "E": 1773487059355, "T": 1773487059354, "s": "BTCUSDT", "U": 10109537704724, "u": 10109537708566, "pu": 10109537704684, "b": [["5000.00", "101.398"], ["7063.90", "0.000"], ["20138.60", "0.000"], ["20438.60", "0.570"], ["20538.60", "2.430"], ["67086.80", "0.000"], ["68497.20", "0.625"], ["69932.20", "6.076"], ["70306.70", "0.000"], ["70392.60", "0.004"], ["70544.00", "0.143"], ["70551.00", "0.080"], ["70558.10", "0.071"], ["70591.20", "0.361"], ["70591.40", "0.476"], ["70591.50", "0.002"], ["70594.20", "0.819"], ["70594.30", "0.685"], ["70610.10", "0.000"], ["70610.20", "0.155"], ["70636.40", "0.006"]], "a": [["70638.70", "4.886"], ["70639.00", "0.126"], ["70642.00", "0.031"], ["70720.70", "0.073"], ["70727.80", "0.327"], ["70734.80", "0.734"], ["70739.20", "0.004"], ["70862.10", "0.338"], ["70878.60", "0.206"], ["71345.00", "0.114"], ["71345.10", "5.740"], ["71663.00", "16.443"], ["72777.30", "3.293"], ["74194.80", "0.002"], ["89523.20", "0.006"]]}}
{"local_ts": 1773487060403, "server_ts": 1773487060376, "data": {"e": "depthUpdate", "E": 1773487060377, "T": 1773487060376, "s": "BTCUSDT", "U": 10109537744313, "u": 10109537747580, "pu": 10109537744217, "b": [["1000.00", "27.042"], ["5000.00", "101.418"], ["7063.90", "0.000"], ["20338.60", "0.280"], ["20438.60", "2.570"], ["20538.60", "0.150"], ["69635.50", "3.364"], ["69932.20", "6.433"], ["70285.40", "3.658"], ["70285.50", "0.296"], ["70392.60", "0.004"], ["70591.40", "0.122"], ["70594.50", "0.107"], ["70633.30", "0.175"], ["70636.40", "0.006"]], "a": [["70638.70", "3.999"], ["70700.10", "1.171"], ["70735.40", "0.714"], ["70787.00", "0.129"], ["70862.10", "0.338"], ["71309.70", "0.000"], ["71345.10", "5.740"], ["71648.70", "1.390"], ["71651.90", "0.697"], ["71739.60", "0.005"], ["72069.70", "1.662"], ["74171.60", "0.002"], ["89523.20", "0.006"]]}}
{"local_ts": 1773487061436, "server_ts": 1773487061404, "data": {"e": "depthUpdate", "E": 1773487061405, "T": 1773487061404, "s": "BTCUSDT", "U": 10109537781770, "u": 10109537785180, "pu": 10109537781700, "b": [["5000.00", "101.418"], ["7063.90", "0.056"], ["20238.60", "0.140"], ["20338.60", "2.420"], ["20438.60", "0.440"], ["33000.00", "3.785"], ["69868.60", "5.141"], ["69932.20", "6.433"], ["69942.00", "1.519"], ["70392.50", "0.004"], ["70498.20", "0.000"], ["70544.00", "0.143"], ["70551.00", "0.163"], ["70558.10", "0.071"], ["70572.40", "0.349"], ["70589.50", "3.523"], ["70594.20", "0.819"], ["70594.30", "0.685"], ["70610.90", "2.012"], ["70637.20", "0.021"]], "a": [["70640.30", "0.000"], ["70641.50", "0.021"], ["70679.80", "1.844"], ["70689.90", "1.072"], ["70701.10", "3.581"], ["70720.60", "0.619"], ["70720.70", "0.002"], ["70727.70", "0.071"], ["70727.80", "0.256"], ["70734.70", "0.582"], ["70734.80", "0.663"], ["70769.60", "0.000"], ["71345.10", "5.740"], ["71663.00", "21.320"], ["71733.60", "14.431"], ["71768.90", "8.485"], ["71914.70", "0.000"], ["72243.30", "0.000"], ["74182.50", "0.059"]]}}
{"local_ts": 1773487062456, "server_ts": 1773487062428, "data": {"e": "depthUpdate", "E": 1773487062429, "T": 1773487062428, "s": "BTCUSDT", "U": 10109537819414, "u": 10109537825231, "pu": 10109537819313, "b": [["1000.00", "27.042"], ["5000.00", "101.418"], ["7063.90", "0.056"], ["20238.60", "2.260"], ["20338.60", "0.740"], ["69932.20", "5.719"], ["70285.40", "3.658"], ["70285.50", "0.300"], ["70392.50", "0.000"], ["70430.80", "0.004"], ["70582.10", "0.540"], ["70591.20", "0.007"], ["70610.90", "2.012"], ["70611.00", "0.178"], ["70614.00", "0.362"], ["70636.50", "0.681"], ["70638.60", "3.207"]], "a": [["70638.70", "3.659"], ["70642.50", "0.004"], ["70642.60", "0.031"], ["70648.20", "0.041"], ["70648.70", "0.134"], ["70655.60", "0.002"], ["70862.10", "0.338"], ["70913.60", "0.009"], ["70918.60", "0.008"], ["70920.70", "0.023"], ["70925.70", "0.000"], ["70927.80", "0.009"], ["70932.80", "0.000"], ["70934.90", "0.012"], ["70939.90", "0.000"], ["70942.00", "0.007"], ["70947.00", "0.000"], ["70949.10", "0.009"], ["70954.10", "0.000"], ["70956.20", "0.007"], ["70961.20", "0.015"], ["70963.30", "0.007"], ["70968.30", "0.000"], ["71200.00", "12.052"], ["71345.00", "0.114"], ["71345.10", "5.040"], ["71530.40", "0.838"], ["72051.40", "0.024"], ["74204.70", "0.002"]]}}
{"local_ts": 1773487063478, "server_ts": 1773487063452, "data": {"e": "depthUpdate", "E": 1773487063453, "T": 1773487063452, "s": "BTCUSDT", "U": 10109537862903, "u": 10109537866609, "pu": 10109537862831, "b": [["5000.00", "101.418"], ["7063.90", "0.056"], ["20138.60", "1.820"], ["20238.60", "1.180"], ["33000.00", "3.789"], ["67085.40", "0.002"], ["67106.80", "0.008"], ["69432.60", "1.081"], ["69932.20", "5.721"], ["69932.30", "0.007"], ["70324.50", "0.000"], ["70392.30", "2.244"], ["70507.30", "0.041"], ["70590.80", "0.004"], ["70594.10", "0.077"], ["70594.20", "0.821"], ["70600.10", "0.004"], ["70611.00", "0.178"], ["70611.10", "0.002"], ["70611.20", "0.518"], ["70628.00", "0.050"], ["70631.20", "0.015"], ["70638.60", "3.922"]], "a": [["70649.30", "0.005"], ["70772.70", "0.022"], ["70913.60", "0.002"], ["70920.70", "0.016"], ["70927.80", "0.002"], ["70934.90", "0.005"], ["70942.00", "0.000"], ["70949.10", "0.002"], ["70956.20", "0.000"], ["70963.30", "0.000"], ["71345.10", "5.040"], ["71868.20", "0.008"], ["74202.60", "0.000"]]}}
{"local_ts": 1773487064500, "server_ts": 1773487064473, "data": {"e": "depthUpdate", "E": 1773487064475, "T": 1773487064473, "s": "BTCUSDT", "U": 10109537903757, "u": 10109537908282, "pu": 10109537903675, "b": [["1000.00", "27.042"], ["5000.00", "101.418"], ["7063.90", "0.028"], ["20138.60", "1.630"], ["20538.60", "1.370"], ["67071.80", "0.024"], ["67106.00", "0.000"], ["67106.80", "0.006"], ["67813.10", "2.580"], ["69932.20", "5.790"], ["70507.30", "0.892"], ["70594.50", "0.142"], ["70603.30", "0.065"], ["70609.50", "0.042"], ["70613.90", "0.712"], ["70616.60", "0.028"], ["70616.70", "0.004"], ["70617.30", "0.116"], ["70617.40", "0.003"], ["70621.00", "0.000"], ["70621.10", "0.003"], ["70623.00", "1.947"], ["70623.30", "0.003"], ["70625.50", "0.005"], ["70625.70", "0.143"], ["70626.50", "1.164"], ["70629.50", "0.701"], ["70629.90", "0.413"], ["70630.10", "0.289"], ["70630.30", "0.003"], ["70630.60", "0.019"], ["70633.30", "0.008"], ["70633.60", "1.080"], ["70633.70", "0.357"], ["70635.10", "0.708"], ["70636.80", "0.059"], ["70638.60", "4.432"]], "a": [["70646.40", "0.004"], ["70651.20", "0.042"], ["70655.60", "0.002"], ["70657.50", "0.000"], ["70658.40", "0.010"], ["70661.00", "0.003"], ["70661.90", "0.147"], ["70677.60", "0.042"], ["70772.70", "0.354"], ["70797.60", "0.164"], ["70915.20", "5.450"], ["70922.30", "0.007"], ["70929.40", "0.007"], ["70936.50", "0.007"], ["70943.60", "0.021"], ["70950.70", "0.007"], ["70957.80", "0.007"], ["70964.90", "0.175"], ["71142.40", "0.000"], ["71345.10", "3.640"], ["74201.10", "0.048"]]}}
{"local_ts": 1773487065527, "server_ts": 1773487065499, "data": {"e": "depthUpdate", "E": 1773487065501, "T": 1773487065499, "s": "BTCUSDT", "U": 10109537939946, "u": 10109537943208, "pu": 10109537939692, "b": [["1000.00", "27.042"], ["5000.00", "101.418"], ["7063.90", "0.028"], ["20438.60", "0.930"], ["20538.60", "2.070"], ["33000.00", "3.789"], ["69225.90", "0.013"], ["69447.20", "0.000"], ["69525.30", "0.000"], ["69932.20", "5.790"], ["70285.40", "3.658"], ["70507.30", "0.892"], ["70614.90", "0.310"], ["70616.10", "0.000"], ["70628.00", "0.065"], ["70631.20", "0.012"], ["70635.50", "0.030"], ["70636.40", "0.006"], ["70636.50", "0.681"], ["70638.60", "2.928"]], "a": [["70638.70", "3.928"], ["70638.90", "0.102"], ["70645.20", "0.001"], ["70645.50", "3.093"], ["70646.30", "0.213"], ["70647.80", "0.210"], ["70649.30", "0.005"], ["70663.30", "0.005"], ["70772.60", "0.331"], ["70772.70", "0.022"], ["70915.20", "5.443"], ["70922.30", "0.000"], ["70929.40", "0.000"], ["70936.50", "0.000"], ["70943.60", "0.014"], ["70950.70", "0.000"], ["70957.80", "0.000"], ["70964.90", "0.168"], ["71345.10", "4.340"], ["74185.70", "0.000"], ["74198.10", "0.005"], ["74204.00", "0.100"]]}}
{"local_ts": 1773487066546, "server_ts": 1773487066520, "data": {"e": "depthUpdate", "E": 1773487066521, "T": 1773487066520, "s": "BTCUSDT", "U": 10109537975355, "u": 10109537978346, "pu": 10109537975252, "b": [["5000.00", "101.418"], ["7063.90", "0.028"], ["20338.60", "0.480"], ["20438.60", "2.520"], ["20538.60", "0.000"], ["56511.00", "0.007"], ["69517.80", "1.016"], ["69932.20", "6.504"], ["69932.30", "0.011"], ["70392.60", "0.000"], ["70465.50", "0.251"], ["70507.30", "0.893"], ["70609.90", "0.089"], ["70610.10", "0.000"], ["70610.20", "0.070"], ["70624.70", "0.072"], ["70625.70", "0.143"], ["70629.00", "0.005"], ["70629.50", "0.693"], ["70638.60", "3.912"]], "a": [["70638.70", "2.619"], ["70660.50", "0.009"], ["70661.20", "0.141"], ["70772.60", "0.332"], ["70787.00", "0.129"], ["70797.60", "0.164"], ["71345.10", "5.740"], ["71436.70", "0.004"], ["71592.30", "6.689"], ["72051.40", "0.015"], ["74178.60", "0.000"], ["74204.00", "0.102"]]}}
{"local_ts": 1773487067569, "server_ts": 1773487067542, "data": {"e": "depthUpdate", "E": 1773487067543, "T": 1773487067542, "s": "BTCUSDT", "U": 10109538009849, "u": 10109538013712, "pu": 10109538009801, "b": [["1000.00", "27.042"], ["5000.00", "101.418"], ["7063.90", "0.000"], ["20238.60", "0.250"], ["20338.60", "2.540"], ["20438.60", "0.210"], ["56511.00", "0.007"], ["67089.20", "0.000"], ["67106.70", "2.237"], ["69559.60", "0.860"], ["69932.20", "6.504"], ["70285.40", "3.658"], ["70594.50", "0.107"], ["70619.00", "0.521"], ["70628.00", "0.065"], ["70631.10", "0.062"], ["70633.30", "0.008"], ["70638.60", "2.852"]], "a": [["70639.50", "0.063"], ["70643.50", "0.025"], ["70649.30", "0.008"], ["70773.50", "0.006"], ["71345.10", "5.740"], ["71580.10", "0.558"], ["71840.80", "2.758"]]}}
{"local_ts": 1773487068593, "server_ts": 1773487068564, "data": {"e": "depthUpdate", "E": 1773487068565, "T": 1773487068564, "s": "BTCUSDT", "U": 10109538048384, "u": 10109538052418, "pu": 10109538048309, "b": [["5000.00", "101.418"], ["7063.90", "0.000"], ["20138.60", "0.110"], ["20238.60", "2.380"], ["20338.60", "0.510"], ["56511.00", "0.007"], ["67087.20", "0.000"], ["69261.10", "1.225"], ["69932.20", "6.504"], ["70592.70", "0.140"], ["70594.20", "0.821"], ["70594.30", "0.683"], ["70609.90", "0.004"], ["70610.00", "0.363"], ["70613.90", "0.694"], ["70635.10", "0.708"], ["70636.50", "0.673"], ["70638.60", "4.180"]], "a": [["70639.40", "0.062"], ["71345.10", "5.740"], ["71636.30", "0.863"], ["71651.60", "1.394"], ["71722.20", "0.696"], ["74170.60", "0.002"]]}}
{"local_ts": 1773487069612, "server_ts": 1773487069584, "data": {"e": "depthUpdate", "E": 1773487069587, "T": 1773487069584, "s": "BTCUSDT", "U": 10109538086400, "u": 10109538089629, "pu": 10109538086390, "b": [["1000.00", "27.042"], ["5000.00", "101.398"], ["7063.90", "0.000"], ["20138.60", "2.150"], ["20238.60", "0.850"], ["56511.00", "0.007"], ["67077.60", "0.004"], ["69581.10", "0.000"], ["70468.50", "0.000"], ["70559.20", "0.041"], ["70593.70", "0.581"], ["70609.40", "0.007"], ["70609.50", "0.127"], ["70621.00", "1.203"], ["70623.00", "0.747"], ["70626.40", "0.626"], ["70629.10", "0.400"]], "a": [["70694.30", "0.003"], ["70722.20", "0.712"], ["70811.40", "0.000"], ["70964.00", "0.013"], ["71345.10", "4.340"], ["71863.70", "0.694"], ["74178.00", "0.052"]]}}
{"local_ts": 1773487070634, "server_ts": 1773487070607, "data": {"e": "depthUpdate", "E": 1773487070609, "T": 1773487070607, "s": "BTCUSDT", "U": 10109538117963, "u": 10109538122018, "pu": 10109538117920, "b": [["1000.00", "27.042"], ["5000.00", "101.418"], ["7063.90", "0.056"], ["20138.60", "1.300"], ["20538.60", "1.700"], ["33000.00", "3.785"], ["56511.00", "0.007"], ["67072.40", "0.002"], ["69213.40", "0.000"], ["69932.20", "6.504"], ["69932.30", "0.007"], ["70285.40", "4.368"], ["70285.50", "0.300"], ["70288.90", "0.000"], ["70292.50", "0.000"], ["70323.70", "32.200"], ["70325.50", "5.060"], ["70401.10", "26.473"], ["70401.90", "5.713"], ["70612.10", "0.427"], ["70628.00", "0.047"], ["70631.60", "0.064"], ["70636.50", "0.673"]], "a": [["70640.60", "0.000"], ["70642.80", "0.002"], ["70651.90", "0.078"], ["70862.20", "0.279"], ["70885.50", "9.827"], ["70886.30", "26.238"], ["70964.20", "30.604"], ["71070.70", "37.613"], ["71345.10", "4.411"]]}}
{"local_ts": 1773487071665, "server_ts": 1773487071628, "data": {"e": "depthUpdate", "E": 1773487071631, "T": 1773487071628, "s": "BTCUSDT", "U": 10109538149440, "u": 10109538153056, "pu": 10109538149412, "b": [["5000.00", "101.418"], ["7063.90", "0.056"], ["20438.60", "1.260"], ["20538.60", "1.740"], ["56511.00", "0.007"], ["67106.70", "2.237"], ["69350.00", "6.366"], ["69932.20", "7.932"], ["70285.40", "4.368"], ["70569.10", "0.171"], ["70613.90", "0.863"], ["70629.70", "0.338"]], "a": [["70641.10", "0.003"], ["70650.70", "0.145"], ["70681.00", "0.042"], ["70711.40", "0.410"], ["70797.60", "0.164"], ["71345.10", "5.740"], ["71663.00", "26.405"], ["74190.00", "2.212"], ["74194.20", "0.002"]]}}
{"local_ts": 1773487072679, "server_ts": 1773487072652, "data": {"e": "depthUpdate", "E": 1773487072653, "T": 1773487072652, "s": "BTCUSDT", "U": 10109538181833, "u": 10109538185014, "pu": 10109538181821, "b": [["1000.00", "27.042"], ["5000.00", "101.418"], ["7063.90", "0.056"], ["20338.60", "0.820"], ["20438.60", "2.180"], ["33000.00", "3.789"], ["56511.00", "0.007"], ["67092.60", "0.000"], ["67813.10", "2.590"], ["69932.20", "7.932"], ["70285.40", "4.368"], ["70300.00", "21.214"], ["70611.60", "0.550"], ["70611.70", "0.188"], ["70614.00", "0.008"], ["70614.10", "0.184"], ["70614.20", "0.002"], ["70618.60", "0.273"], ["70619.20", "0.000"], ["70624.40", "0.366"], ["70625.10", "0.511"], ["70629.40", "0.466"], ["70629.60", "0.515"], ["70631.70", "0.007"], ["70633.70", "0.003"], ["70636.50", "0.673"], ["70637.70", "0.004"], ["70638.60", "3.308"]], "a": [["70638.70", "2.995"], ["70639.10", "0.135"], ["70639.20", "0.265"], ["70645.40", "0.032"], ["70645.80", "0.129"], ["70647.80", "0.240"], ["70649.70", "0.002"], ["70671.10", "0.074"], ["70672.60", "0.000"], ["71345.10", "4.480"], ["71592.30", "7.247"], ["74202.40", "0.002"]]}}
{"local_ts": 1773487073703, "server_ts": 1773487073676, "data": {"e": "depthUpdate", "E": 1773487073677, "T": 1773487073676, "s": "BTCUSDT", "U": 10109538218189, "u": 10109538221178, "pu": 10109538218084, "b": [["5000.00", "101.418"], ["7063.90", "0.028"], ["20238.60", "0.410"], ["20338.60", "2.560"], ["20438.60", "0.030"], ["67093.50", "0.000"], ["69413.50", "1.438"], ["69932.20", "6.504"], ["69942.10", "0.000"], ["70392.50", "0.004"], ["70486.90", "0.096"], ["70488.70", "0.099"], ["70489.30", "0.000"], ["70490.70", "0.085"], ["70494.60", "0.000"], ["70495.50", "0.093"], ["70594.50", "0.246"], ["70603.30", "0.002"], ["70611.70", "0.188"], ["70614.00", "0.192"], ["70614.10", "0.000"], ["70619.60", "0.000"], ["70619.70", "0.063"], ["70628.00", "0.047"], ["70629.90", "0.303"], ["70630.00", "0.188"], ["70630.30", "0.089"], ["70631.00", "0.247"], ["70631.10", "0.065"], ["70631.60", "0.101"], ["70631.70", "0.007"], ["70632.50", "1.418"], ["70633.00", "0.001"], ["70633.40", "0.013"], ["70633.70", "0.003"], ["70633.80", "0.012"], ["70635.10", "0.511"], ["70636.50", "0.673"]], "a": [["70638.70", "3.155"], ["70641.10", "0.011"], ["70645.80", "0.129"], ["70647.50", "0.064"], ["70649.30", "0.005"], ["70653.40", "0.005"], ["70653.80", "0.008"], ["70705.50", "0.096"], ["70706.90", "0.096"], ["70755.30", "0.002"], ["70758.70", "0.006"], ["70760.80", "0.009"], ["70777.10", "0.098"], ["70797.60", "0.164"], ["71345.10", "4.480"], ["71663.00", "28.217"], ["74173.40", "0.002"], ["89523.20", "0.006"]]}}
{"local_ts": 1773487074735, "server_ts": 1773487074696, "data": {"e": "depthUpdate", "E": 1773487074697, "T": 1773487074696, "s": "BTCUSDT", "U": 10109538246202, "u": 10109538248570, "pu": 10109538246156, "b": [["1000.00", "27.042"], ["5000.00", "101.418"], ["7063.90", "0.028"], ["20138.60", "0.220"], ["20238.60", "2.490"], ["20338.60", "0.290"], ["33000.00", "3.789"], ["67071.40", "0.016"], ["69591.10", "1.724"], ["69661.60", "0.000"], ["69932.20", "6.504"], ["70285.50", "0.300"], ["70392.50", "0.000"], ["70507.40", "0.942"], ["70560.50", "0.101"], ["70611.70", "0.004"], ["70627.80", "0.203"], ["70631.70", "0.009"], ["70636.50", "0.673"]], "a": [["70641.70", "0.001"], ["70643.30", "0.040"], ["70643.50", "0.003"], ["70644.40", "0.000"], ["70645.80", "0.131"], ["70653.80", "0.008"], ["70682.30", "0.007"], ["70684.00", "0.137"], ["70718.90", "0.078"], ["70754.20", "0.000"], ["70772.40", "0.360"], ["70772.50", "0.008"], ["71345.10", "4.480"], ["71641.80", "3.615"], ["89523.20", "0.006"]]}}
{"local_ts": 1773487075746, "server_ts": 1773487075720, "data": {"e": "depthUpdate", "E": 1773487075721, "T": 1773487075720, "s": "BTCUSDT", "U": 10109538281083, "u": 10109538284490, "pu": 10109538281051, "b": [["1000.00", "27.042"], ["5000.00", "101.418"], ["7063.90", "0.028"], ["20138.60", "2.350"], ["20238.60", "0.580"], ["20538.60", "0.070"], ["67086.70", "0.000"], ["67103.40", "0.004"], ["67106.00", "0.000"], ["69932.20", "7.932"], ["70285.40", "4.368"], ["70609.50", "0.042"], ["70609.60", "0.087"], ["70612.20", "0.186"], ["70628.00", "0.050"], ["70631.00", "0.250"], ["70631.70", "0.009"], ["70632.80", "0.008"]], "a": [["70638.70", "2.836"], ["70645.50", "3.121"], ["70645.80", "0.131"], ["70647.80", "0.240"], ["70648.40", "0.080"], ["70649.30", "0.005"], ["70653.20", "0.002"], ["70653.80", "0.006"], ["70746.50", "0.005"], ["70750.00", "21.895"], ["71203.80", "2.183"], ["71345.10", "5.880"], ["71408.70", "2.095"], ["71486.40", "9.496"], ["71581.00", "2.791"], ["71663.00", "29.193"], ["71722.20", "2.087"], ["89523.20", "0.006"]]}}
{"local_ts": 1773487076767, "server_ts": 1773487076740, "data": {"e": "depthUpdate", "E": 1773487076741, "T": 1773487076740, "s": "BTCUSDT", "U": 10109538312724, "u": 10109538315601, "pu": 10109538312657, "b": [["5000.00", "101.418"], ["7063.90", "0.000"], ["20138.60", "0.960"], ["20538.60", "2.040"], ["69317.70", "1.869"], ["69932.20", "7.934"], ["70285.50", "0.300"], ["70392.30", "2.240"], ["70507.40", "0.941"], ["70548.30", "0.142"], ["70548.40", "0.003"], ["70555.30", "0.142"], ["70555.40", "0.000"], ["70562.40", "0.215"], ["70562.50", "0.002"], ["70612.20", "0.186"], ["70614.40", "0.009"], ["70627.10", "0.715"], ["70630.60", "0.405"], ["70631.00", "0.195"], ["70633.30", "0.147"], ["70633.70", "0.187"], ["70636.50", "0.673"]], "a": [["70644.40", "0.000"], ["70648.20", "0.005"], ["70649.30", "0.005"], ["70652.40", "0.005"], ["70653.20", "0.000"], ["70717.90", "0.155"], ["70718.00", "0.077"], ["70725.00", "0.149"], ["70725.10", "0.010"], ["70732.00", "0.183"], ["70732.10", "0.043"], ["70745.00", "0.021"], ["70750.00", "21.893"], ["70772.40", "0.365"], ["71345.10", "5.880"], ["71717.90", "0.417"], ["71721.60", "0.000"], ["74194.80", "0.000"], ["89523.20", "0.006"]]}}
{"local_ts": 1773488574189, "server_ts": 1773488573836, "data": {"e": "depthUpdate", "E": 1773488573841, "T": 1773488573836, "s": "BTCUSDT", "U": 10109618898608, "u": 10109618901847, "pu": 10109618898539, "b": [["1000.00", "28.242"], ["5000.00", "101.418"], ["7067.20", "0.056"], ["20271.90", "0.780"], ["20371.90", "2.220"], ["33000.00", "3.789"], ["56538.00", "0.000"], ["63604.70", "0.006"], ["69633.00", "1.899"], ["69965.20", "0.000"], ["70594.50", "0.081"], ["70616.00", "0.006"], ["70643.80", "0.129"], ["70650.80", "0.330"], ["70661.30", "0.003"], ["70664.70", "0.013"], ["70665.00", "1.995"], ["70671.90", "5.216"]], "a": [["70674.30", "0.009"], ["70679.10", "0.006"], ["70681.20", "0.003"], ["70682.60", "0.005"], ["70692.10", "0.077"], ["70696.60", "0.021"], ["70707.10", "0.038"], ["70716.80", "0.025"], ["70817.30", "0.002"], ["70895.70", "0.007"], ["71227.40", "0.062"], ["71378.70", "0.017"], ["72809.30", "0.725"], ["74210.40", "0.002"], ["77739.20", "0.002"]]}}
{"local_ts": 1773488575211, "server_ts": 1773488574856, "data": {"e": "depthUpdate", "E": 1773488574861, "T": 1773488574856, "s": "BTCUSDT", "U": 10109618959241, "u": 10109618966413, "pu": 10109618959005, "b": [["5000.00", "101.418"], ["7067.20", "0.056"], ["20171.90", "0.380"], ["20271.90", "2.570"], ["20371.90", "0.050"], ["63604.70", "0.006"], ["67138.30", "0.008"], ["69576.50", "1.512"], ["69706.10", "3.317"], ["69965.20", "0.000"], ["70318.50", "0.002"], ["70346.80", "0.000"], ["70347.10", "0.000"], ["70378.60", "0.115"], ["70425.60", "0.004"], ["70484.60", "0.275"], ["70488.20", "0.162"], ["70516.40", "0.080"], ["70520.50", "1.059"], ["70576.90", "0.970"], ["70622.40", "0.084"], ["70631.30", "0.139"], ["70645.30", "0.002"], ["70664.90", "0.325"]], "a": [["70673.90", "0.009"], ["70682.30", "0.017"], ["70682.40", "0.004"], ["70693.20", "0.285"], ["70696.70", "0.141"], ["70703.50", "0.047"], ["70815.60", "1.536"], ["70817.30", "0.000"], ["70823.60", "2.236"], ["70895.60", "0.007"], ["70895.70", "0.000"], ["70937.00", "0.600"], ["70947.60", "0.106"], ["71345.40", "0.000"], ["71378.60", "0.002"], ["71378.70", "0.017"], ["71767.40", "4.870"], ["72358.20", "1.186"], ["74226.60", "0.004"], ["74235.90", "0.000"], ["77739.20", "0.002"]]}}
