{"local_ts": 1773486602502, "server_ts": 1773486602472, "data": {"e": "depthUpdate", "E": 1773486602473, "T": 1773486602472, "s": "BTCUSDT", "U": 10109514998008, "u": 10109515002845, "pu": 10109514997967, "b": [["1000.00", "26.142"], ["5000.00", "101.418"], ["7064.80", "0.028"], ["20147.40", "1.630"], ["20547.40", "1.370"], ["55882.20", "0.002"], ["67821.60", "0.012"], ["68430.10", "0.010"], ["69940.90", "2.142"], ["70209.60", "0.006"], ["70549.20", "0.000"], ["70556.20", "0.041"], ["70557.00", "0.142"], ["70557.20", "0.041"], ["70563.30", "0.129"], ["70564.00", "1.444"], ["70564.20", "0.000"], ["70571.10", "0.142"], ["70571.30", "0.178"], ["70598.60", "0.002"], ["70599.10", "0.373"], ["70613.30", "0.005"], ["70613.40", "0.047"], ["70615.30", "0.184"], ["70615.40", "0.170"], ["70616.30", "0.188"], ["70636.80", "0.514"], ["70640.10", "0.007"], ["70644.40", "0.001"]], "a": [["70647.50", "1.942"], ["70650.00", "0.209"], ["70650.10", "0.001"], ["70650.20", "0.099"], ["70650.30", "0.028"], ["70658.10", "0.018"], ["70661.40", "1.859"], ["70666.40", "0.233"], ["70674.90", "0.003"], ["70675.20", "0.639"], ["70680.20", "0.116"], ["70683.80", "0.038"], ["70725.90", "0.511"], ["70726.70", "0.144"], ["70727.60", "0.000"], ["70733.00", "0.137"], ["70733.80", "0.142"], ["70734.70", "0.000"], ["70740.00", "0.553"], ["70740.80", "0.190"], ["70741.70", "0.212"], ["71354.00", "2.144"], ["71777.90", "2.922"], ["71834.40", "0.277"], ["72408.70", "0.000"], ["74191.40", "0.002"]]}}
{"local_ts": 1773486603526, "server_ts": 1773486603494, "data": {"e": "depthUpdate", "E": 1773486603495, "T": 1773486603494, "s": "BTCUSDT", "U": 10109515043171, "u": 10109515047696, "pu": 10109515043130, "b": [["5000.00", "101.418"], ["7064.80", "0.028"], ["20447.40", "0.920"], ["20547.40", "2.080"], ["55882.20", "0.000"], ["67101.60", "0.000"], ["69234.50", "0.015"], ["69940.90", "2.356"], ["70294.20", "0.111"], ["70294.30", "1.134"], ["70400.50", "0.000"], ["70613.30", "0.175"], ["70615.30", "0.538"], ["70615.40", "0.000"], ["70616.30", "0.004"], ["70628.80", "0.002"], ["70630.50", "0.073"], ["70631.10", "0.512"], ["70631.90", "1.236"], ["70632.00", "0.012"], ["70637.70", "0.019"], ["70638.30", "0.002"], ["70638.40", "0.003"], ["70639.80", "0.134"], ["70640.00", "0.643"], ["70643.00", "0.004"], ["70643.10", "0.063"], ["70643.40", "0.175"], ["70643.60", "0.008"], ["70644.00", "0.002"], ["70644.80", "0.214"], ["70644.90", "0.000"], ["70645.10", "0.000"], ["70645.50", "0.002"], ["70645.70", "0.001"], ["70647.30", "0.255"], ["70647.40", "9.356"]], "a": [["70647.50", "1.815"], ["70650.30", "0.028"], ["70650.60", "0.015"], ["70651.30", "0.000"], ["70651.50", "0.007"], ["70651.70", "0.003"], ["70652.90", "0.023"], ["70653.30", "0.059"], ["70656.10", "0.025"], ["70656.50", "0.064"], ["70656.80", "0.051"], ["70657.20", "0.107"], ["70657.50", "0.241"], ["70658.10", "0.018"], ["70660.10", "0.144"], ["70665.20", "0.299"], ["70669.90", "0.003"], ["70670.50", "0.009"], ["70675.80", "0.155"], ["70677.10", "0.207"], ["70679.20", "1.040"], ["70679.30", "0.000"], ["70679.40", "0.581"], ["70682.80", "0.137"], ["70683.00", "0.252"], ["70683.30", "0.049"], ["70685.20", "0.014"], ["70685.30", "0.087"], ["70731.80", "0.270"], ["70732.10", "0.137"], ["70732.50", "0.575"], ["70732.80", "0.061"], ["70733.20", "0.144"], ["70740.20", "0.036"], ["70742.20", "1.569"], ["70744.10", "0.060"], ["70744.70", "0.096"], ["71354.00", "2.144"], ["71726.70", "0.835"], ["74196.70", "0.002"]]}}
{"local_ts": 1773486604546, "server_ts": 1773486604516, "data": {"e": "depthUpdate", "E": 1773486604517, "T": 1773486604516, "s": "BTCUSDT", "U": 10109515118869, "u": 10109515124443, "pu": 10109515118746, "b": [["1000.00", "26.142"], ["5000.00", "101.438"], ["7064.80", "0.028"], ["20347.40", "0.470"], ["20447.40", "2.530"], ["20547.40", "0.000"], ["55882.20", "0.002"], ["69234.50", "0.009"], ["69940.90", "2.356"], ["69941.00", "0.007"], ["70354.10", "0.004"], ["70467.20", "0.161"], ["70591.20", "0.598"], ["70591.30", "0.000"], ["70599.70", "9.592"], ["70601.20", "0.005"], ["70612.10", "0.098"], ["70613.30", "0.543"], ["70615.30", "0.000"], ["70615.60", "0.201"], ["70623.30", "0.011"], ["70624.60", "0.557"], ["70626.80", "0.250"], ["70627.60", "0.078"], ["70628.30", "0.000"], ["70628.40", "0.004"], ["70629.20", "0.004"], ["70629.40", "0.003"], ["70629.70", "0.782"], ["70630.10", "1.658"], ["70630.20", "0.526"], ["70630.40", "0.511"], ["70631.10", "0.003"], ["70631.30", "0.015"], ["70631.60", "0.070"], ["70631.80", "0.277"], ["70631.90", "1.240"], ["70632.60", "0.001"], ["70633.30", "0.340"], ["70636.80", "0.514"], ["70638.30", "0.016"], ["70638.40", "0.296"], ["70638.60", "0.638"], ["70639.40", "0.030"], ["70640.00", "0.024"], ["70640.10", "0.005"], ["70640.20", "0.348"], ["70640.30", "0.004"], ["70640.40", "0.008"], ["70640.60", "0.198"], ["70643.50", "0.003"], ["70643.60", "0.376"], ["70644.80", "0.214"], ["70644.90", "0.000"], ["70645.00", "0.011"], ["70645.10", "0.015"], ["70645.30", "0.002"], ["70645.70", "0.001"], ["70646.10", "0.021"], ["70646.80", "0.000"], ["70646.90", "0.000"], ["70647.30", "0.166"], ["70647.40", "9.571"]], "a": [["70647.50", "1.910"], ["70647.60", "0.220"], ["70648.60", "0.010"], ["70648.90", "0.004"], ["70649.00", "0.014"], ["70649.50", "0.062"], ["70649.90", "0.004"], ["70650.00", "7.209"], ["70650.10", "0.011"], ["70650.20", "0.099"], ["70650.40", "0.013"], ["70651.50", "0.052"], ["70652.00", "0.001"], ["70652.40", "0.043"], ["70652.60", "0.086"], ["70653.40", "0.005"], ["70653.70", "0.024"], ["70654.00", "0.017"], ["70654.40", "0.003"], ["70654.50", "0.007"], ["70654.60", "0.012"], ["70655.40", "0.018"], ["70658.10", "0.003"], ["70659.00", "0.165"], ["70659.70", "0.000"], ["70659.90", "0.012"], ["70660.50", "0.116"], ["70660.90", "0.042"], ["70661.10", "0.077"], ["70661.20", "0.000"], ["70661.40", "0.795"], ["70661.50", "0.267"], ["70663.00", "0.024"], ["70664.20", "0.016"], ["70664.60", "0.248"], ["70665.20", "0.163"], ["70665.50", "1.033"], ["70666.60", "0.099"], ["70666.90", "0.137"], ["70667.20", "0.004"], ["70670.70", "0.034"], ["70670.90", "0.519"], ["70674.00", "0.645"], ["70674.40", "0.766"], ["70674.80", "0.005"], ["70675.20", "0.003"], ["70675.80", "0.196"], ["70675.90", "0.001"], ["70676.10", "0.002"], ["70677.00", "0.301"], ["70678.30", "0.000"], ["70679.00", "0.223"], ["70679.30", "0.060"], ["70680.20", "0.036"], ["70680.30", "0.086"], ["70681.90", "0.249"], ["70682.80", "0.306"], ["70683.30", "0.049"], ["70684.50", "0.055"], ["70685.30", "0.087"], ["70686.40", "0.005"], ["70687.70", "0.002"], ["70696.10", "0.006"], ["70696.80", "0.060"], ["70701.20", "0.051"], ["70708.60", "0.003"], ["70713.60", "8.483"], ["70714.90", "0.517"], ["70715.60", "0.286"], ["70802.90", "0.099"], ["70806.50", "0.000"], ["70858.00", "0.281"], ["70860.80", "0.267"], ["70864.40", "0.199"], ["70864.70", "0.399"], ["70867.70", "0.305"], ["70995.80", "0.000"], ["70999.20", "0.014"], ["71318.70", "1.399"], ["71353.90", "0.003"], ["71354.00", "2.144"], ["71464.40", "0.294"], ["71731.10", "0.704"], ["74185.00", "0.090"]]}}
{"local_ts": 1773486605570, "server_ts": 1773486605538, "data": {"e": "depthUpdate", "E": 1773486605539, "T": 1773486605538, "s": "BTCUSDT", "U": 10109515165549, "u": 10109515170564, "pu": 10109515165429, "b": [["5000.00", "101.418"], ["7064.80", "0.000"], ["20247.40", "0.250"], ["20347.40", "2.530"], ["20447.40", "0.220"], ["33000.00", "3.785"], ["40000.00", "41.356"], ["55882.20", "0.000"], ["56518.00", "0.000"], ["67101.50", "40.002"], ["67115.00", "0.023"], ["69324.50", "0.000"], ["69585.50", "0.000"], ["69940.90", "3.070"], ["69941.00", "0.007"], ["70311.80", "0.000"], ["70400.80", "0.006"], ["70405.50", "5.018"], ["70512.60", "2.000"], ["70554.30", "0.017"], ["70561.30", "0.071"], ["70568.40", "0.071"], ["70573.80", "2.360"], ["70580.90", "0.053"], ["70581.60", "0.057"], ["70596.50", "0.000"], ["70598.50", "0.014"], ["70599.00", "0.056"], ["70603.90", "0.006"], ["70609.50", "0.060"], ["70613.30", "0.189"], ["70613.70", "0.184"], ["70615.30", "0.170"], ["70627.20", "0.000"], ["70628.30", "0.141"], ["70628.70", "0.000"], ["70630.00", "0.665"], ["70630.60", "0.065"], ["70631.00", "0.523"], ["70631.50", "0.260"], ["70631.60", "0.070"], ["70631.90", "1.236"], ["70632.10", "0.004"], ["70632.20", "0.125"], ["70632.80", "0.112"], ["70633.20", "0.284"], ["70634.30", "0.072"], ["70635.00", "0.180"], ["70635.20", "0.015"], ["70636.60", "0.007"], ["70637.00", "0.033"], ["70637.10", "0.361"], ["70637.30", "0.000"], ["70637.80", "0.004"], ["70638.00", "0.004"], ["70638.20", "0.003"], ["70638.30", "0.002"], ["70638.40", "0.287"], ["70639.10", "0.001"], ["70639.20", "0.638"], ["70639.40", "0.007"], ["70639.50", "0.000"], ["70639.60", "0.023"], ["70640.00", "0.007"], ["70640.40", "0.075"], ["70643.00", "0.004"], ["70643.50", "0.373"], ["70643.60", "0.006"], ["70644.90", "0.000"], ["70645.30", "0.002"], ["70646.20", "0.002"], ["70646.60", "0.102"], ["70647.10", "0.003"], ["70647.30", "0.166"]], "a": [["70647.50", "3.099"], ["70647.90", "0.027"], ["70649.00", "0.035"], ["70649.40", "0.017"], ["70650.30", "0.056"], ["70651.20", "0.000"], ["70651.40", "0.027"], ["70654.50", "0.035"], ["70655.70", "0.050"], ["70656.40", "0.029"], ["70657.40", "0.080"], ["70659.10", "0.015"], ["70660.90", "0.042"], ["70663.00", "0.009"], ["70668.80", "0.005"], ["70670.80", "0.000"], ["70674.40", "0.893"], ["70674.90", "0.003"], ["70675.30", "0.003"], ["70682.40", "0.029"], ["70682.70", "0.000"], ["70683.10", "2.348"], ["70683.30", "0.296"], ["70687.10", "0.095"], ["70709.10", "1.091"], ["70709.80", "0.070"], ["70714.80", "0.714"], ["70731.00", "2.870"], ["70731.10", "2.250"], ["70738.10", "0.277"], ["70738.20", "0.213"], ["70745.10", "0.610"], ["70745.20", "0.000"], ["70833.30", "7.713"], ["70847.40", "0.036"], ["70871.70", "3.380"], ["71163.10", "0.004"], ["71354.00", "2.844"], ["71671.90", "17.138"], ["72800.00", "31.669"]]}}
{"local_ts": 1773486606590, "server_ts": 1773486606556, "data": {"e": "depthUpdate", "E": 1773486606561, "T": 1773486606556, "s": "BTCUSDT", "U": 10109515211558, "u": 10109515215943, "pu": 10109515211471, "b": [["1000.00", "26.542"], ["5000.00", "101.418"], ["7064.80", "0.000"], ["20147.40", "0.100"], ["20247.40", "2.380"], ["20347.40", "0.520"], ["55882.20", "0.002"], ["56518.00", "0.000"], ["67083.10", "0.000"], ["69568.30", "1.292"], ["69623.00", "15.950"], ["69940.90", "3.070"], ["69941.00", "0.011"], ["70100.10", "3.739"], ["70222.10", "16.020"], ["70294.20", "0.217"], ["70328.00", "1.021"], ["70405.60", "0.009"], ["70515.10", "0.763"], ["70591.80", "0.004"], ["70591.90", "3.545"], ["70597.40", "0.034"], ["70613.30", "0.359"], ["70613.70", "0.000"], ["70615.30", "0.184"], ["70636.80", "0.008"], ["70640.10", "0.008"], ["70640.40", "0.006"], ["70644.10", "0.001"]], "a": [["70647.50", "3.064"], ["70647.80", "0.027"], ["70649.50", "0.005"], ["70651.20", "0.000"], ["70651.60", "0.000"], ["70653.10", "0.007"], ["70654.50", "0.007"], ["70658.10", "0.000"], ["70660.60", "0.023"], ["70670.80", "0.000"], ["70672.80", "0.942"], ["70781.00", "0.768"], ["70971.10", "0.000"], ["70971.20", "0.000"], ["70999.90", "13.710"], ["71354.00", "2.844"], ["71646.50", "0.000"], ["71838.40", "0.000"], ["71954.50", "1.178"]]}}
{"local_ts": 1773486607612, "server_ts": 1773486607579, "data": {"e": "depthUpdate", "E": 1773486607581, "T": 1773486607579, "s": "BTCUSDT", "U": 10109515252037, "u": 10109515255610, "pu": 10109515251886, "b": [["1000.00", "26.542"], ["5000.00", "101.418"], ["7064.80", "0.000"], ["20147.40", "2.130"], ["20247.40", "0.870"], ["33000.00", "3.785"], ["56518.00", "0.000"], ["67086.40", "0.000"], ["69940.90", "3.070"], ["70218.40", "38.124"], ["70323.90", "32.386"], ["70401.40", "27.224"], ["70515.10", "0.174"], ["70577.60", "0.841"], ["70598.50", "0.012"], ["70598.60", "0.004"], ["70619.10", "0.113"], ["70633.20", "0.363"], ["70636.80", "0.005"], ["70640.10", "0.008"], ["70644.10", "0.022"], ["70644.40", "0.001"], ["70644.50", "0.000"]], "a": [["70647.50", "3.263"], ["70647.90", "0.009"], ["70648.00", "0.000"], ["70648.60", "0.007"], ["70648.70", "0.001"], ["70658.10", "0.003"], ["70661.40", "0.798"], ["70693.00", "0.077"], ["70780.90", "0.593"], ["70819.70", "1.932"], ["70820.00", "0.166"], ["70893.60", "26.215"], ["70971.60", "30.592"], ["71078.10", "38.542"], ["71354.00", "2.844"], ["74190.00", "2.214"]]}}
{"local_ts": 1773486608629, "server_ts": 1773486608599, "data": {"e": "depthUpdate", "E": 1773486608601, "T": 1773486608599, "s": "BTCUSDT", "U": 10109515293825, "u": 10109515296903, "pu": 10109515293724, "b": [["5000.00", "101.418"], ["7064.80", "0.000"], ["20147.40", "1.320"], ["20547.40", "1.680"], ["56518.00", "0.000"], ["69940.90", "3.070"], ["69941.00", "0.011"], ["69955.10", "0.714"], ["70294.20", "0.111"], ["70294.40", "0.002"], ["70326.00", "0.116"], ["70515.10", "0.766"], ["70636.80", "0.003"], ["70640.10", "0.005"]], "a": [["70647.50", "4.158"], ["70647.80", "0.039"], ["70650.80", "0.008"], ["70658.10", "0.005"], ["70738.80", "2.000"], ["70780.80", "0.779"], ["70780.90", "0.593"], ["71354.00", "2.844"], ["71393.60", "0.701"], ["71565.90", "3.416"], ["74188.60", "0.010"], ["74198.70", "0.000"], ["89523.20", "0.000"]]}}
{"local_ts": 1773486609655, "server_ts": 1773486609624, "data": {"e": "depthUpdate", "E": 1773486609625, "T": 1773486609624, "s": "BTCUSDT", "U": 10109515329144, "u": 10109515332433, "pu": 10109515329093, "b": [["1000.00", "26.692"], ["5000.00", "101.418"], ["7064.80", "0.056"], ["20447.40", "1.250"], ["20547.40", "1.750"], ["33000.00", "3.789"], ["56518.00", "0.000"], ["68838.70", "0.000"], ["69651.50", "0.000"], ["69701.70", "0.862"], ["69940.90", "3.070"], ["69941.00", "0.007"], ["70401.00", "0.018"], ["70467.20", "0.161"], ["70476.30", "0.000"], ["70515.10", "0.174"], ["70554.20", "0.234"], ["70561.20", "0.166"], ["70568.30", "0.249"], ["70583.50", "0.200"], ["70585.00", "0.583"], ["70595.60", "0.281"], ["70595.90", "0.005"], ["70636.80", "0.003"], ["70640.00", "0.017"], ["70640.40", "0.057"], ["70644.10", "0.022"], ["70647.40", "9.316"]], "a": [["70647.50", "2.246"], ["70654.50", "0.094"], ["70656.20", "0.010"], ["70658.10", "0.000"], ["70661.30", "0.002"], ["70664.80", "0.041"], ["70684.20", "0.206"], ["70686.60", "0.004"], ["70697.20", "0.073"], ["70708.40", "0.012"], ["70730.90", "0.073"], ["70738.00", "0.085"], ["70745.00", "0.715"], ["70747.20", "0.275"], ["70763.70", "0.085"], ["70780.80", "0.084"], ["70819.70", "0.000"], ["70871.30", "0.283"], ["71354.00", "2.844"], ["71471.50", "0.019"], ["71632.00", "0.021"], ["74200.50", "0.052"], ["89523.20", "0.000"]]}}
{"local_ts": 1773486610678, "server_ts": 1773486610648, "data": {"e": "depthUpdate", "E": 1773486610649, "T": 1773486610648, "s": "BTCUSDT", "U": 10109515371761, "u": 10109515376015, "pu": 10109515371601, "b": [["5000.00", "101.418"], ["7064.80", "0.056"], ["20347.40", "0.810"], ["20447.40", "2.190"], ["56518.00", "0.000"], ["69888.00", "18.582"], ["69940.90", "4.504"], ["70300.00", "21.734"], ["70579.70", "0.073"], ["70585.40", "0.062"], ["70586.10", "0.057"], ["70599.10", "0.373"], ["70599.20", "0.622"], ["70633.70", "0.244"], ["70634.70", "0.061"], ["70635.40", "0.392"], ["70640.40", "0.057"], ["70640.80", "0.013"], ["70640.90", "0.016"], ["70642.40", "0.060"], ["70644.00", "0.002"], ["70647.40", "8.566"]], "a": [["70647.50", "2.761"], ["70648.20", "0.004"], ["70650.20", "0.127"], ["70652.80", "0.004"], ["70654.50", "0.094"], ["70655.10", "0.501"], ["70655.20", "0.675"], ["70655.50", "0.009"], ["70655.80", "0.033"], ["70656.80", "0.036"], ["70671.30", "0.003"], ["70671.40", "0.475"], ["70672.00", "1.291"], ["70672.10", "0.044"], ["70674.20", "0.000"], ["70674.70", "0.703"], ["70679.70", "0.030"], ["70680.40", "0.064"], ["70683.80", "0.074"], ["70704.40", "0.025"], ["70705.10", "0.027"], ["70710.80", "0.253"], ["70871.60", "0.016"], ["71354.00", "2.844"], ["74192.10", "0.002"], ["74204.50", "0.064"], ["89523.20", "0.000"]]}}
{"local_ts": 1773486611700, "server_ts": 1773486611668, "data": {"e": "depthUpdate", "E": 1773486611671, "T": 1773486611668, "s": "BTCUSDT", "U": 10109515411561, "u": 10109515414328, "pu": 10109515411543, "b": [["1000.00", "26.142"], ["5000.00", "101.418"], ["7064.80", "0.028"], ["20247.40", "0.400"], ["20347.40", "2.560"], ["20447.40", "0.040"], ["67098.90", "0.000"], ["69204.80", "0.000"], ["69940.90", "4.504"], ["70294.20", "0.111"], ["70429.30", "0.000"], ["70599.30", "0.003"], ["70599.50", "0.513"], ["70602.60", "0.000"], ["70619.50", "0.085"], ["70629.80", "0.006"], ["70630.30", "0.341"], ["70630.40", "0.009"], ["70631.00", "0.084"], ["70631.10", "0.512"], ["70636.40", "0.013"], ["70636.60", "0.000"], ["70636.80", "0.006"], ["70637.20", "0.000"], ["70637.90", "0.350"], ["70639.90", "0.075"], ["70640.00", "0.052"], ["70642.40", "0.018"], ["70642.60", "0.000"], ["70644.20", "0.069"], ["70645.40", "0.000"]], "a": [["70647.50", "3.856"], ["70648.10", "0.010"], ["70655.20", "0.677"], ["70656.00", "0.002"], ["70658.10", "0.007"], ["70659.20", "0.005"], ["70660.50", "0.371"], ["70661.60", "0.005"], ["70661.90", "0.012"], ["70662.60", "0.002"], ["70664.90", "0.031"], ["70665.80", "0.007"], ["70666.90", "0.194"], ["70667.00", "1.204"], ["70668.70", "0.010"], ["70669.60", "0.002"], ["70670.40", "0.143"], ["70671.20", "0.005"], ["70671.30", "0.003"], ["70671.40", "0.475"], ["70672.00", "1.291"], ["70672.10", "0.044"], ["70674.60", "0.016"], ["70675.30", "0.512"], ["70675.60", "0.003"], ["70675.70", "0.000"], ["70677.10", "0.057"], ["70872.10", "0.000"], ["71353.90", "0.003"], ["71354.00", "2.844"], ["74188.50", "0.055"], ["89523.20", "0.000"]]}}
{"local_ts": 1773486612725, "server_ts": 1773486612692, "data": {"e": "depthUpdate", "E": 1773486612695, "T": 1773486612692, "s": "BTCUSDT", "U": 10109515462385, "u": 10109515465198, "pu": 10109515462366, "b": [["1000.00", "26.142"], ["5000.00", "101.398"], ["7064.80", "0.028"], ["20147.40", "0.210"], ["20247.40", "2.500"], ["20347.40", "0.290"], ["67092.80", "0.002"], ["69940.90", "4.504"], ["70515.10", "0.764"], ["70554.00", "0.871"], ["70561.00", "0.073"], ["70568.10", "0.071"], ["70592.70", "0.004"], ["70599.00", "0.058"], ["70599.10", "0.371"], ["70619.10", "0.113"], ["70636.80", "0.003"], ["70637.80", "0.019"], ["70638.10", "0.027"], ["70640.40", "0.093"]], "a": [["70647.50", "3.904"], ["70654.50", "0.094"], ["70671.30", "0.003"], ["70671.40", "0.475"], ["70671.60", "0.002"], ["70672.00", "1.291"], ["70672.10", "0.044"], ["70684.40", "0.000"], ["70730.70", "0.077"], ["70737.80", "0.074"], ["70744.80", "0.071"], ["70780.40", "0.703"], ["70871.80", "0.009"], ["70871.90", "0.000"], ["71353.90", "0.003"], ["71354.00", "2.844"], ["74186.00", "0.067"], ["89523.20", "0.000"]]}}
{"local_ts": 1773486613754, "server_ts": 1773486613716, "data": {"e": "depthUpdate", "E": 1773486613717, "T": 1773486613716, "s": "BTCUSDT", "U": 10109515498267, "u": 10109515501587, "pu": 10109515498194, "b": [["5000.00", "101.418"], ["7064.80", "0.028"], ["20147.40", "2.340"], ["20247.40", "0.590"], ["20547.40", "0.070"], ["69940.90", "4.504"], ["70100.10", "3.739"], ["70222.10", "16.020"], ["70294.20", "0.111"], ["70324.00", "0.000"], ["70515.10", "0.764"], ["70623.30", "0.009"], ["70627.60", "0.273"], ["70632.40", "0.568"], ["70632.80", "0.127"], ["70632.90", "0.141"], ["70633.20", "0.200"], ["70633.40", "0.045"], ["70633.70", "0.543"], ["70634.00", "0.258"], ["70638.10", "0.024"], ["70638.30", "0.023"], ["70638.50", "0.358"], ["70640.00", "0.052"], ["70640.40", "0.058"], ["70640.60", "0.196"], ["70640.80", "0.013"], ["70643.60", "0.006"], ["70644.00", "0.005"], ["70644.40", "0.009"]], "a": [["70647.50", "3.882"], ["70649.30", "0.002"], ["70654.50", "0.092"], ["70654.60", "0.012"], ["70655.10", "0.764"], ["70657.90", "0.007"], ["70658.00", "0.569"], ["70672.20", "0.030"], ["70677.80", "0.005"], ["70780.30", "0.700"], ["70971.40", "0.096"], ["70971.50", "0.000"], ["70999.90", "13.710"], ["71346.30", "1.540"], ["71354.00", "2.844"], ["74203.30", "0.002"], ["74215.10", "0.004"], ["89523.20", "0.000"]]}}
{"local_ts": 1773486614770, "server_ts": 1773486614740, "data": {"e": "depthUpdate", "E": 1773486614741, "T": 1773486614740, "s": "BTCUSDT", "U": 10109515534897, "u": 10109515537686, "pu": 10109515534743, "b": [["1000.00", "26.142"], ["5000.00", "101.418"], ["7064.80", "0.000"], ["20147.40", "0.960"], ["20547.40", "2.040"], ["33000.00", "3.785"], ["55882.20", "0.000"], ["67112.60", "0.002"], ["69940.90", "4.504"], ["70002.20", "6.372"], ["70082.20", "0.142"], ["70096.10", "45.491"], ["70329.50", "7.044"], ["70602.50", "0.518"], ["70636.80", "0.003"], ["70639.60", "0.002"], ["70640.40", "0.058"], ["70641.60", "0.004"], ["70642.80", "0.002"]], "a": [["70647.50", "3.769"], ["70648.10", "0.008"], ["70654.50", "0.092"], ["70656.10", "0.050"], ["70658.10", "0.003"], ["70660.80", "0.878"], ["70660.90", "0.000"], ["70661.60", "0.007"], ["70665.60", "0.937"], ["70682.60", "0.002"], ["70799.40", "0.370"], ["71205.00", "0.280"], ["71354.00", "2.844"], ["72025.10", "0.554"], ["74203.30", "0.000"], ["89523.20", "0.000"]]}}
{"local_ts": 1773486615792, "server_ts": 1773486615760, "data": {"e": "depthUpdate", "E": 1773486615763, "T": 1773486615760, "s": "BTCUSDT", "U": 10109515570117, "u": 10109515573327, "pu": 10109515570072, "b": [["5000.00", "101.418"], ["7064.80", "0.000"], ["20447.40", "1.590"], ["20547.40", "1.410"], ["55882.20", "0.002"], ["69306.70", "0.000"], ["69422.50", "1.437"], ["69940.90", "4.504"], ["69941.00", "0.007"], ["70294.30", "1.134"], ["70341.60", "0.002"], ["70400.30", "0.000"], ["70401.70", "0.002"], ["70515.00", "0.548"], ["70579.70", "0.073"], ["70585.40", "0.062"], ["70586.10", "0.057"], ["70599.10", "0.371"], ["70599.20", "0.624"], ["70631.70", "0.075"], ["70633.60", "0.140"], ["70634.60", "0.569"], ["70635.20", "0.283"], ["70635.30", "0.056"], ["70636.80", "0.003"], ["70639.30", "0.531"], ["70639.60", "0.002"], ["70639.70", "0.001"], ["70640.40", "0.006"], ["70640.80", "0.015"]], "a": [["70647.50", "3.491"], ["70647.80", "0.138"], ["70652.90", "0.934"], ["70653.10", "0.009"], ["70653.80", "0.002"], ["70654.50", "0.064"], ["70654.90", "0.028"], ["70655.00", "0.007"], ["70655.10", "0.737"], ["70655.60", "0.030"], ["70656.60", "0.072"], ["70658.10", "0.000"], ["70659.00", "0.158"], ["70661.00", "0.459"], ["70661.60", "0.146"], ["70662.50", "0.120"], ["70679.50", "0.592"], ["70680.20", "0.025"], ["70683.60", "0.040"], ["70704.10", "0.031"], ["70704.80", "0.025"], ["70710.50", "1.137"], ["70780.20", "0.709"], ["70799.40", "0.370"], ["70871.30", "0.283"], ["71353.80", "0.000"], ["71354.00", "4.243"], ["74212.60", "0.006"], ["89523.20", "0.000"]]}}
{"local_ts": 1773486616816, "server_ts": 1773486616783, "data": {"e": "depthUpdate", "E": 1773486616785, "T": 1773486616783, "s": "BTCUSDT", "U": 10109515607531, "u": 10109515610606, "pu": 10109515607478, "b": [["1000.00", "26.142"], ["5000.00", "101.418"], ["7064.80", "0.000"], ["20347.40", "1.140"], ["20447.40", "1.860"], ["33000.00", "3.789"], ["55882.20", "0.000"], ["67115.00", "0.019"], ["69940.90", "4.504"], ["70074.70", "0.727"], ["70294.20", "0.111"], ["70294.40", "0.002"], ["70401.90", "0.004"], ["70463.70", "0.161"], ["70467.20", "0.002"], ["70481.40", "0.042"], ["70498.20", "0.000"], ["70500.20", "0.966"], ["70515.00", "0.003"], ["70557.00", "0.000"], ["70587.30", "0.087"], ["70592.00", "0.296"], ["70594.90", "0.765"], ["70613.30", "0.005"], ["70637.30", "0.015"], ["70640.40", "0.056"], ["70641.80", "0.021"]], "a": [["70647.50", "3.560"], ["70647.70", "0.004"], ["70648.30", "0.003"], ["70652.70", "0.043"], ["70652.80", "0.004"], ["70652.90", "0.004"], ["70653.80", "0.000"], ["70654.50", "0.035"], ["70655.00", "0.659"], ["70657.50", "0.006"], ["70674.80", "0.007"], ["70674.90", "0.003"], ["70675.50", "0.008"], ["70675.60", "0.003"], ["70684.40", "0.008"], ["70704.60", "0.421"], ["70705.70", "0.002"], ["70738.90", "1.176"], ["70741.30", "0.043"], ["70780.20", "0.005"], ["70799.40", "0.310"], ["70800.00", "14.871"], ["70806.50", "0.159"], ["70871.90", "0.007"], ["71212.60", "0.017"], ["71353.80", "0.000"], ["71354.00", "4.243"], ["74184.10", "0.002"], ["89523.20", "0.000"]]}}
{"local_ts": 1773486617833, "server_ts": 1773486617804, "data": {"e": "depthUpdate", "E": 1773486617805, "T": 1773486617804, "s": "BTCUSDT", "U": 10109515642567, "u": 10109515647586, "pu": 10109515642422, "b": [["1000.00", "26.142"], ["5000.00", "101.418"], ["7064.80", "0.056"], ["20247.40", "0.690"], ["20347.40", "2.310"], ["20447.40", "0.000"], ["55882.20", "0.002"], ["67091.10", "0.000"], ["69624.50", "0.000"], ["69703.10", "0.000"], ["69940.90", "4.504"], ["70294.30", "1.130"], ["70371.70", "0.000"], ["70400.50", "0.004"], ["70429.60", "0.004"], ["70569.70", "1.067"], ["70583.80", "0.003"], ["70590.90", "0.083"], ["70599.80", "0.357"], ["70599.90", "0.024"], ["70625.60", "0.028"], ["70627.60", "0.026"], ["70627.70", "0.028"], ["70628.30", "0.000"], ["70628.50", "0.056"], ["70628.90", "0.252"], ["70629.30", "0.006"], ["70630.40", "0.009"], ["70631.30", "0.000"], ["70636.00", "0.018"], ["70638.50", "0.358"], ["70638.70", "0.005"], ["70639.30", "1.152"], ["70639.80", "0.132"], ["70640.20", "0.698"], ["70640.50", "0.409"], ["70640.80", "0.013"], ["70641.50", "0.018"], ["70642.50", "0.002"], ["70643.00", "0.019"], ["70643.20", "0.022"], ["70644.30", "0.003"], ["70644.50", "0.000"], ["70645.20", "0.021"], ["70646.50", "0.000"], ["70647.00", "0.000"], ["70647.40", "7.903"]], "a": [["70647.50", "1.930"], ["70648.30", "0.001"], ["70648.90", "0.048"], ["70650.20", "0.137"], ["70657.50", "0.004"], ["70666.40", "0.195"], ["70674.70", "0.067"], ["70675.30", "0.639"], ["70676.00", "0.325"], ["70683.30", "0.049"], ["70684.20", "0.453"], ["70685.10", "0.007"], ["70685.70", "0.592"], ["70686.40", "0.005"], ["70711.10", "0.010"], ["70725.20", "1.074"], ["71354.00", "5.642"], ["74187.90", "0.015"], ["74195.20", "0.002"], ["89523.20", "0.000"]]}}
{"local_ts": 1773486618855, "server_ts": 1773486618823, "data": {"e": "depthUpdate", "E": 1773486618825, "T": 1773486618823, "s": "BTCUSDT", "U": 10109515689266, "u": 10109515702193, "pu": 10109515689141, "b": [["5000.00", "101.398"], ["7064.80", "0.056"], ["20147.40", "0.320"], ["20247.40", "2.600"], ["20347.40", "0.080"], ["55882.20", "0.000"], ["67115.10", "0.002"], ["69940.90", "4.504"], ["70294.20", "0.111"], ["70326.10", "0.018"], ["70482.80", "0.000"], ["70491.30", "0.202"], ["70498.60", "10.090"], ["70536.50", "0.006"], ["70538.80", "0.893"], ["70553.60", "0.000"], ["70558.70", "1.829"], ["70560.60", "0.088"], ["70565.70", "0.163"], ["70567.70", "0.091"], ["70567.80", "0.801"], ["70572.80", "0.073"], ["70599.60", "0.026"], ["70600.10", "0.205"], ["70629.10", "0.056"], ["70629.90", "0.000"], ["70630.10", "1.651"], ["70630.20", "0.570"], ["70633.20", "0.152"], ["70636.70", "0.003"], ["70636.80", "0.003"], ["70639.80", "0.132"], ["70640.10", "0.005"], ["70640.30", "0.088"], ["70640.40", "0.067"], ["70641.60", "0.004"], ["70642.30", "0.195"], ["70644.40", "0.001"], ["70647.40", "8.656"]], "a": [["70647.50", "0.579"], ["70649.90", "0.004"], ["70650.20", "0.028"], ["70650.40", "0.010"], ["70651.20", "0.099"], ["70652.30", "0.000"], ["70653.80", "0.000"], ["70654.50", "0.035"], ["70654.60", "0.027"], ["70654.70", "0.070"], ["70654.90", "0.680"], ["70655.00", "0.007"], ["70657.90", "0.004"], ["70658.10", "0.003"], ["70658.20", "0.059"], ["70659.00", "0.160"], ["70660.10", "0.147"], ["70660.50", "0.080"], ["70661.20", "0.020"], ["70662.00", "0.018"], ["70663.20", "0.006"], ["70664.60", "0.003"], ["70664.80", "0.043"], ["70666.40", "0.193"], ["70666.70", "0.004"], ["70669.10", "0.736"], ["70670.70", "0.034"], ["70671.00", "0.015"], ["70674.00", "0.089"], ["70674.80", "0.007"], ["70674.90", "0.003"], ["70675.10", "0.339"], ["70675.50", "0.008"], ["70675.60", "0.003"], ["70677.60", "0.096"], ["70683.30", "0.049"], ["70684.00", "0.000"], ["70684.10", "0.121"], ["70685.30", "0.087"], ["70685.40", "0.258"], ["70730.30", "0.005"], ["70735.40", "0.071"], ["70737.40", "0.000"], ["70738.80", "2.002"], ["70742.50", "0.071"], ["70744.40", "0.008"], ["70749.50", "0.072"], ["70871.80", "0.002"], ["71177.40", "0.701"], ["71353.90", "0.010"], ["71354.00", "4.243"], ["74206.10", "0.002"], ["74210.30", "0.000"], ["89523.20", "0.006"]]}}
{"local_ts": 1773486619877, "server_ts": 1773486619840, "data": {"e": "depthUpdate", "E": 1773486619845, "T": 1773486619840, "s": "BTCUSDT", "U": 10109515776368, "u": 10109515781553, "pu": 10109515776186, "b": [["1000.00", "26.142"], ["5000.00", "101.418"], ["7064.80", "0.056"], ["20147.40", "2.450"], ["20247.40", "0.380"], ["20547.40", "0.170"], ["55882.20", "0.002"], ["63582.70", "0.002"], ["67101.30", "0.002"], ["69352.70", "0.000"], ["69375.70", "0.580"], ["69608.90", "8.588"], ["69940.90", "5.218"], ["70082.20", "0.213"], ["70626.00", "0.002"], ["70627.80", "0.007"], ["70637.20", "0.015"], ["70637.30", "0.007"], ["70638.00", "0.000"], ["70639.60", "0.019"], ["70640.40", "0.067"], ["70644.40", "0.001"]], "a": [["70647.50", "0.594"], ["70651.40", "0.003"], ["70654.40", "0.003"], ["70654.50", "0.035"], ["70654.90", "0.003"], ["70655.00", "0.007"], ["70656.40", "0.007"], ["70657.70", "0.000"], ["70658.10", "0.000"], ["70659.00", "0.158"], ["70659.10", "0.011"], ["70668.00", "0.035"], ["70669.10", "0.738"], ["70669.20", "0.284"], ["70672.20", "0.032"], ["70703.20", "0.098"], ["71354.00", "4.243"], ["71589.60", "2.371"], ["71749.60", "0.697"], ["77712.20", "0.002"]]}}
{"local_ts": 1773486620900, "server_ts": 1773486620868, "data": {"e": "depthUpdate", "E": 1773486620869, "T": 1773486620868, "s": "BTCUSDT", "U": 10109515839188, "u": 10109515847155, "pu": 10109515839038, "b": [["5000.00", "101.418"], ["7065.00", "0.028"], ["20147.40", "0.670"], ["20449.90", "0.030"], ["20547.40", "2.130"], ["20549.90", "0.170"], ["40000.00", "41.356"], ["46888.00", "56.270"], ["55882.20", "0.000"], ["56518.00", "0.000"], ["63584.90", "0.002"], ["68527.90", "0.000"], ["69585.80", "2.380"], ["69725.10", "0.000"], ["69940.90", "6.646"], ["69943.40", "0.000"], ["70294.40", "0.000"], ["70438.60", "24.275"], ["70442.10", "0.000"], ["70447.90", "0.000"], ["70455.60", "0.005"], ["70465.20", "0.002"], ["70466.20", "0.159"], ["70466.30", "2.550"], ["70467.20", "0.002"], ["70469.90", "0.000"], ["70492.60", "0.000"], ["70494.30", "0.086"], ["70494.50", "0.000"], ["70494.90", "0.006"], ["70495.50", "0.000"], ["70498.00", "0.117"], ["70508.60", "1.974"], ["70513.60", "0.000"], ["70513.70", "0.570"], ["70520.50", "0.005"], ["70523.40", "0.000"], ["70525.70", "0.000"], ["70527.00", "0.000"], ["70530.60", "0.004"], ["70533.90", "0.014"], ["70534.10", "1.110"], ["70537.30", "0.045"], ["70538.90", "1.566"], ["70541.00", "0.000"], ["70551.00", "0.167"], ["70551.10", "0.092"], ["70552.40", "0.425"], ["70556.40", "0.041"], ["70562.00", "0.092"], ["70563.60", "0.144"], ["70564.90", "0.092"], ["70565.20", "0.334"], ["70565.50", "0.002"], ["70567.50", "0.094"], ["70568.60", "0.125"], ["70570.80", "0.000"], ["70575.40", "0.050"], ["70575.70", "0.219"], ["70577.30", "0.000"], ["70580.70", "0.002"], ["70581.40", "0.024"], ["70581.50", "0.016"], ["70581.90", "0.804"], ["70583.20", "0.006"], ["70583.80", "0.005"], ["70586.50", "0.295"], ["70587.40", "0.005"], ["70587.60", "0.053"], ["70588.30", "0.509"], ["70588.50", "0.282"], ["70589.80", "0.003"], ["70590.60", "0.002"], ["70591.40", "0.002"], ["70593.40", "1.328"], ["70593.90", "0.059"], ["70594.10", "0.000"], ["70594.40", "0.000"], ["70594.70", "0.085"], ["70595.00", "0.004"], ["70596.00", "0.561"], ["70596.70", "0.001"], ["70596.90", "0.814"], ["70597.90", "0.002"], ["70599.90", "0.022"], ["70600.00", "1.558"], ["70600.10", "0.205"], ["70600.40", "0.085"], ["70602.80", "0.348"], ["70603.10", "0.003"], ["70603.70", "0.001"], ["70604.60", "0.472"], ["70605.00", "0.003"], ["70605.10", "0.055"], ["70605.20", "0.006"], ["70605.60", "0.006"], ["70606.00", "0.004"], ["70606.20", "0.005"], ["70607.10", "1.069"], ["70607.50", "0.901"], ["70607.70", "8.499"], ["70608.00", "0.012"], ["70608.50", "0.088"], ["70609.50", "0.058"], ["70610.50", "0.531"], ["70611.70", "0.796"], ["70612.00", "0.005"], ["70612.10", "0.005"], ["70612.80", "1.070"], ["70613.00", "0.390"], ["70613.30", "1.830"], ["70613.80", "0.206"], ["70614.00", "0.009"], ["70614.60", "0.366"], ["70615.10", "1.034"], ["70615.20", "0.372"], ["70615.30", "0.538"], ["70615.50", "0.000"], ["70615.60", "0.252"], ["70615.90", "0.011"], ["70616.00", "0.059"], ["70616.30", "0.953"], ["70616.40", "0.357"], ["70617.10", "0.005"], ["70617.30", "0.000"], ["70617.40", "0.073"], ["70617.70", "0.019"], ["70617.80", "0.005"], ["70618.00", "0.849"], ["70618.10", "0.489"], ["70618.70", "0.000"], ["70618.80", "0.009"], ["70619.10", "0.138"], ["70619.40", "0.006"], ["70619.50", "0.087"], ["70619.90", "0.073"], ["70620.90", "0.004"], ["70622.40", "0.000"], ["70623.00", "0.004"], ["70624.40", "1.073"], ["70625.20", "0.131"], ["70625.70", "0.017"], ["70626.60", "0.006"], ["70626.90", "0.111"], ["70627.50", "0.703"], ["70627.70", "0.000"], ["70627.80", "0.000"], ["70627.90", "0.002"], ["70628.20", "0.651"], ["70629.60", "0.010"], ["70630.10", "1.635"], ["70630.20", "0.456"], ["70630.60", "0.004"], ["70630.90", "0.118"], ["70631.40", "0.017"], ["70632.40", "0.511"], ["70632.70", "0.002"], ["70632.90", "0.000"], ["70633.10", "0.146"], ["70633.20", "0.126"], ["70633.40", "0.136"], ["70634.00", "0.001"], ["70634.40", "0.141"], ["70634.70", "0.018"], ["70634.80", "0.004"], ["70634.90", "0.002"], ["70635.30", "0.117"], ["70635.70", "0.493"], ["70635.90", "0.027"], ["70636.30", "0.310"], ["70636.80", "0.056"], ["70636.90", "0.624"], ["70637.00", "0.553"], ["70637.20", "0.015"], ["70637.30", "0.000"], ["70637.40", "0.006"], ["70637.50", "0.053"], ["70637.70", "0.074"], ["70637.80", "0.004"], ["70637.90", "0.000"], ["70638.30", "0.511"], ["70638.40", "0.003"], ["70638.60", "0.002"], ["70638.80", "0.001"], ["70638.90", "0.025"], ["70639.00", "0.327"], ["70639.30", "0.519"], ["70639.50", "0.070"], ["70639.60", "0.017"], ["70639.70", "0.004"], ["70639.90", "0.072"], ["70640.00", "0.052"], ["70640.10", "0.286"], ["70640.20", "0.691"], ["70640.30", "0.035"], ["70640.40", "0.008"], ["70640.50", "0.004"], ["70640.80", "0.015"], ["70641.10", "0.000"], ["70641.60", "0.001"], ["70642.00", "0.003"], ["70642.10", "0.002"], ["70642.20", "1.079"], ["70642.30", "0.003"], ["70642.50", "0.000"], ["70642.70", "0.019"], ["70642.80", "0.009"], ["70642.90", "0.012"], ["70643.00", "0.400"], ["70643.30", "0.002"], ["70643.80", "0.206"], ["70644.00", "0.374"], ["70644.50", "0.002"], ["70644.60", "0.013"], ["70644.80", "0.002"], ["70644.90", "0.011"], ["70645.00", "0.008"], ["70645.10", "0.002"], ["70645.20", "0.006"], ["70645.40", "0.002"], ["70645.50", "0.002"], ["70645.60", "0.005"], ["70645.90", "0.005"], ["70646.00", "0.000"], ["70646.10", "0.003"], ["70646.20", "0.005"], ["70646.40", "0.005"], ["70646.60", "0.060"], ["70646.80", "0.003"], ["70646.90", "0.001"], ["70647.10", "0.636"], ["70647.20", "0.000"], ["70647.30", "0.032"], ["70647.40", "0.772"], ["70647.50", "0.941"], ["70647.60", "0.000"], ["70647.70", "0.000"], ["70647.80", "0.000"], ["70648.00", "0.080"], ["70648.10", "0.003"], ["70648.20", "0.001"], ["70648.40", "0.002"], ["70648.50", "0.000"], ["70648.60", "0.002"], ["70648.80", "0.129"], ["70648.90", "0.000"], ["70649.00", "0.341"], ["70649.10", "0.000"], ["70649.20", "0.000"], ["70649.30", "0.000"], ["70649.40", "0.000"], ["70649.50", "0.000"], ["70649.60", "0.021"], ["70649.70", "0.002"], ["70649.80", "0.039"], ["70649.90", "14.830"]], "a": [["70647.50", "0.000"], ["70647.60", "0.000"], ["70647.70", "0.000"], ["70647.80", "0.000"], ["70647.90", "0.000"], ["70648.20", "0.000"], ["70648.30", "0.000"], ["70648.50", "0.000"], ["70648.60", "0.000"], ["70648.70", "0.000"], ["70648.90", "0.000"], ["70649.00", "0.000"], ["70649.10", "0.000"], ["70649.30", "0.000"], ["70649.40", "0.000"], ["70649.50", "0.000"], ["70649.60", "0.000"], ["70649.70", "0.000"], ["70649.80", "0.000"], ["70649.90", "0.000"], ["70650.00", "6.195"], ["70650.10", "0.005"], ["70650.30", "0.025"], ["70650.40", "0.009"], ["70650.60", "0.212"], ["70650.80", "0.023"], ["70651.00", "0.004"], ["70651.70", "0.000"], ["70651.90", "0.000"], ["70652.40", "0.000"], ["70652.70", "0.099"], ["70652.80", "0.004"], ["70653.30", "0.000"], ["70654.60", "0.003"], ["70654.80", "0.006"], ["70654.90", "0.045"], ["70655.00", "0.007"], ["70655.20", "0.025"], ["70655.30", "0.277"], ["70655.50", "0.011"], ["70655.70", "0.004"], ["70655.90", "0.055"], ["70656.20", "0.001"], ["70656.30", "0.003"], ["70656.80", "0.001"], ["70656.90", "0.005"], ["70657.20", "0.002"], ["70657.90", "0.004"], ["70658.00", "0.566"], ["70658.10", "0.000"], ["70658.30", "0.001"], ["70658.80", "0.000"], ["70658.90", "0.002"], ["70659.20", "0.015"], ["70659.30", "0.000"], ["70659.50", "0.003"], ["70659.60", "0.065"], ["70659.80", "0.918"], ["70660.00", "0.032"], ["70660.10", "0.000"], ["70660.30", "0.028"], ["70660.40", "0.005"], ["70660.60", "0.002"], ["70660.80", "0.024"], ["70660.90", "0.000"], ["70661.30", "0.652"], ["70661.40", "0.460"], ["70661.50", "0.363"], ["70661.60", "0.007"], ["70661.80", "0.008"], ["70661.90", "0.007"], ["70662.40", "0.284"], ["70662.50", "0.099"], ["70662.60", "0.002"], ["70662.70", "0.002"], ["70662.80", "0.006"], ["70662.90", "0.035"], ["70663.00", "0.002"], ["70663.20", "0.014"], ["70663.30", "0.001"], ["70663.70", "0.005"], ["70663.80", "0.005"], ["70664.00", "0.040"], ["70664.10", "0.627"], ["70664.20", "0.859"], ["70664.30", "0.017"], ["70664.40", "0.008"], ["70664.60", "0.003"], ["70664.70", "0.000"], ["70664.80", "0.495"], ["70664.90", "0.024"], ["70665.00", "0.010"], ["70665.10", "0.002"], ["70665.20", "0.443"], ["70665.40", "0.154"], ["70665.90", "0.157"], ["70666.20", "0.011"], ["70666.30", "0.060"], ["70666.50", "0.513"], ["70666.60", "0.093"], ["70666.70", "0.004"], ["70667.20", "0.017"], ["70667.50", "0.004"], ["70667.60", "0.052"], ["70668.00", "0.021"], ["70668.50", "0.019"], ["70668.60", "0.004"], ["70668.70", "0.005"], ["70668.80", "0.026"], ["70668.90", "0.209"], ["70669.00", "0.536"], ["70669.10", "0.738"], ["70669.20", "0.269"], ["70669.40", "0.038"], ["70669.60", "1.174"], ["70669.70", "0.231"], ["70670.00", "0.279"], ["70670.10", "0.059"], ["70670.50", "0.141"], ["70670.80", "0.022"], ["70671.00", "0.030"], ["70671.30", "0.003"], ["70671.90", "0.511"], ["70672.20", "0.045"], ["70672.60", "1.552"], ["70672.70", "0.028"], ["70672.80", "0.102"], ["70672.90", "0.002"], ["70673.10", "0.141"], ["70673.20", "0.005"], ["70673.30", "0.220"], ["70673.40", "0.012"], ["70673.50", "0.029"], ["70673.90", "0.003"], ["70674.20", "0.007"], ["70674.70", "0.036"], ["70674.80", "0.005"], ["70674.90", "0.001"], ["70675.10", "0.339"], ["70675.50", "0.010"], ["70675.60", "0.005"], ["70675.80", "0.089"], ["70676.20", "0.618"], ["70676.30", "0.543"], ["70676.90", "0.048"], ["70677.00", "0.240"], ["70677.60", "0.002"], ["70677.70", "0.072"], ["70678.30", "0.079"], ["70678.40", "0.040"], ["70679.40", "0.520"], ["70680.00", "3.589"], ["70680.30", "0.003"], ["70680.50", "0.002"], ["70680.70", "0.002"], ["70681.40", "0.000"], ["70681.50", "0.010"], ["70681.60", "0.008"], ["70682.00", "0.366"], ["70682.60", "0.636"], ["70682.70", "0.509"], ["70682.80", "0.246"], ["70682.90", "0.009"], ["70683.10", "2.121"], ["70683.40", "7.889"], ["70683.60", "0.004"], ["70683.70", "0.085"], ["70684.10", "0.079"], ["70684.20", "0.231"], ["70684.50", "0.073"], ["70684.90", "0.025"], ["70685.20", "0.000"], ["70685.40", "0.013"], ["70685.60", "1.586"], ["70685.80", "0.000"], ["70685.90", "0.035"], ["70686.00", "0.172"], ["70686.40", "0.019"], ["70686.90", "0.070"], ["70688.30", "0.036"], ["70688.50", "0.040"], ["70688.60", "0.018"], ["70689.90", "1.025"], ["70690.60", "0.026"], ["70691.10", "0.000"], ["70691.20", "0.060"], ["70691.60", "0.014"], ["70691.70", "0.247"], ["70691.90", "0.025"], ["70692.30", "0.025"], ["70692.90", "0.000"], ["70693.00", "0.081"], ["70693.90", "0.511"], ["70694.70", "0.003"], ["70695.20", "0.110"], ["70696.50", "0.003"], ["70697.20", "0.007"], ["70697.90", "0.067"], ["70698.10", "0.002"], ["70698.60", "0.229"], ["70700.90", "0.008"], ["70701.90", "0.033"], ["70704.40", "0.001"], ["70704.60", "0.421"], ["70705.60", "0.003"], ["70705.90", "0.185"], ["70708.80", "0.067"], ["70709.30", "0.042"], ["70709.50", "0.025"], ["70709.80", "0.041"], ["70710.60", "0.157"], ["70712.00", "1.116"], ["70712.30", "0.517"], ["70713.60", "0.002"], ["70714.00", "0.045"], ["70715.20", "0.053"], ["70715.80", "0.087"], ["70716.00", "0.043"], ["70718.60", "0.017"], ["70718.70", "0.005"], ["70719.90", "0.000"], ["70720.80", "0.005"], ["70720.90", "8.488"], ["70723.80", "0.480"], ["70724.60", "0.500"], ["70727.40", "0.404"], ["70734.60", "0.198"], ["70734.70", "0.170"], ["70735.30", "0.010"], ["70737.10", "0.557"], ["70746.10", "0.087"], ["70752.40", "0.211"], ["70759.20", "0.000"], ["70769.30", "0.011"], ["70771.00", "0.239"], ["70772.40", "0.034"], ["70782.10", "0.042"], ["70783.10", "0.053"], ["70784.20", "1.054"], ["70786.90", "0.097"], ["70788.00", "0.639"], ["70789.50", "0.192"], ["70799.00", "0.454"], ["70801.90", "0.099"], ["70805.40", "0.099"], ["70807.60", "0.514"], ["70814.70", "1.563"], ["70826.70", "0.002"], ["70842.30", "0.267"], ["70852.60", "0.065"], ["70856.30", "0.271"], ["70871.50", "0.002"], ["70886.70", "0.117"], ["70931.00", "0.091"], ["70933.30", "0.360"], ["70940.20", "0.536"], ["70970.20", "0.007"], ["71263.20", "0.007"], ["71298.40", "0.002"], ["71333.70", "0.000"], ["71354.00", "4.252"], ["71356.50", "0.000"], ["71583.80", "0.000"], ["73170.10", "0.004"], ["73346.00", "0.050"], ["73521.90", "0.000"], ["74209.90", "0.002"], ["76778.20", "0.003"], ["76954.30", "0.000"], ["77130.40", "0.002"], ["77715.00", "0.002"]]}}
{"local_ts": 1773486621918, "server_ts": 1773486621888, "data": {"e": "depthUpdate", "E": 1773486621889, "T": 1773486621888, "s": "BTCUSDT", "U": 10109515897107, "u": 10109515900753, "pu": 10109515897060, "b": [["1000.00", "26.142"], ["5000.00", "101.418"], ["7065.00", "0.028"], ["20449.90", "1.910"], ["20547.40", "1.090"], ["20549.90", "0.000"], ["33000.00", "3.785"], ["55882.20", "0.002"], ["63584.90", "0.002"], ["65508.10", "0.002"], ["67117.40", "0.004"], ["69588.10", "4.410"], ["69625.50", "3.049"], ["69943.40", "0.000"], ["70033.00", "0.024"], ["70100.10", "0.499"], ["70222.10", "18.612"], ["70296.70", "0.203"], ["70332.10", "0.663"], ["70514.90", "0.636"], ["70515.00", "0.003"], ["70593.00", "3.480"], ["70594.90", "1.182"], ["70615.30", "0.354"], ["70616.30", "0.769"], ["70616.40", "0.357"], ["70617.70", "0.015"], ["70619.10", "0.322"], ["70629.10", "0.004"], ["70630.70", "0.148"], ["70633.30", "0.006"], ["70634.20", "0.007"], ["70634.70", "1.214"], ["70636.00", "0.018"], ["70636.30", "0.070"], ["70636.50", "0.512"], ["70637.20", "0.015"], ["70638.20", "0.000"], ["70639.10", "0.008"], ["70639.30", "0.516"], ["70639.40", "0.005"], ["70640.10", "0.003"], ["70640.80", "0.298"], ["70642.80", "0.009"], ["70644.30", "0.003"], ["70644.90", "0.647"], ["70645.00", "0.378"], ["70645.50", "0.002"], ["70645.60", "0.005"], ["70646.90", "0.001"], ["70649.90", "14.340"]], "a": [["70652.90", "0.002"], ["70653.10", "0.022"], ["70655.40", "0.006"], ["70656.90", "0.005"], ["70657.30", "0.060"], ["70657.90", "0.052"], ["70659.80", "0.057"], ["70660.40", "0.003"], ["70660.50", "0.080"], ["70661.00", "0.145"], ["70662.30", "0.861"], ["70662.40", "0.006"], ["70662.90", "0.037"], ["70663.10", "0.285"], ["70664.20", "0.001"], ["70665.90", "0.016"], ["70666.20", "0.152"], ["70666.70", "0.862"], ["70673.50", "0.014"], ["70680.50", "0.009"], ["70681.40", "0.509"], ["70681.50", "0.003"], ["70684.40", "0.008"], ["70685.20", "0.070"], ["70768.30", "2.544"], ["70779.90", "0.000"], ["70782.00", "0.502"], ["71295.00", "2.034"], ["71356.50", "1.399"], ["71805.10", "4.171"], ["74195.70", "0.002"], ["74204.20", "0.002"], ["77715.00", "0.002"]]}}
{"local_ts": 1773486622940, "server_ts": 1773486622908, "data": {"e": "depthUpdate", "E": 1773486622911, "T": 1773486622908, "s": "BTCUSDT", "U": 10109515944619, "u": 10109515948474, "pu": 10109515944567, "b": [["1000.00", "26.142"], ["5000.00", "101.418"], ["7065.00", "0.028"], ["20349.90", "1.460"], ["20449.90", "1.540"], ["56520.00", "0.066"], ["63584.90", "0.002"], ["67097.10", "0.002"], ["67115.10", "0.006"], ["69250.00", "20.854"], ["69588.10", "1.707"], ["69625.50", "10.868"], ["69943.40", "0.000"], ["70514.90", "0.000"], ["70515.10", "0.848"], ["70602.30", "0.004"], ["70602.70", "0.006"], ["70615.30", "0.000"], ["70616.40", "0.357"], ["70619.10", "0.138"], ["70619.20", "0.369"], ["70619.30", "0.189"], ["70639.30", "0.516"], ["70642.60", "0.000"], ["70642.80", "0.062"], ["70647.00", "0.008"], ["70649.90", "14.369"]], "a": [["70651.30", "1.564"], ["70651.40", "0.006"], ["70651.50", "0.034"], ["70652.60", "0.003"], ["70653.00", "0.008"], ["70656.90", "0.013"], ["70660.00", "0.062"], ["70660.20", "0.000"], ["70660.60", "0.005"], ["70661.40", "0.465"], ["70663.40", "0.036"], ["70682.80", "0.242"], ["70686.80", "0.047"], ["70741.00", "0.003"], ["70782.00", "0.503"], ["70801.90", "0.159"], ["71356.50", "1.399"], ["77715.00", "0.002"]]}}
{"local_ts": 1773486623962, "server_ts": 1773486623930, "data": {"e": "depthUpdate", "E": 1773486623931, "T": 1773486623930, "s": "BTCUSDT", "U": 10109515983662, "u": 10109515987398, "pu": 10109515983598, "b": [["5000.00", "101.418"], ["7065.00", "0.028"], ["20249.90", "1.010"], ["20349.90", "1.990"], ["33000.00", "3.785"], ["63584.90", "0.002"], ["69360.60", "0.000"], ["69517.40", "0.997"], ["69554.80", "6.972"], ["69851.50", "2.859"], ["69943.40", "0.000"], ["70296.70", "0.239"], ["70602.00", "0.013"], ["70602.10", "0.036"], ["70616.40", "0.187"], ["70616.70", "0.363"], ["70619.20", "0.015"], ["70619.30", "0.005"], ["70639.30", "0.519"], ["70640.80", "0.015"], ["70641.50", "0.300"], ["70642.60", "0.003"], ["70649.90", "14.388"]], "a": [["70651.90", "0.153"], ["70660.60", "0.002"], ["70666.80", "0.073"], ["70667.30", "0.144"], ["70674.00", "0.089"], ["70686.30", "0.007"], ["71476.60", "0.559"], ["74201.80", "0.000"], ["77715.00", "0.002"]]}}
{"local_ts": 1773486624981, "server_ts": 1773486624950, "data": {"e": "depthUpdate", "E": 1773486624951, "T": 1773486624950, "s": "BTCUSDT", "U": 10109516024940, "u": 10109516028621, "pu": 10109516024914, "b": [["1000.00", "26.142"], ["5000.00", "101.418"], ["7065.00", "0.000"], ["20149.90", "0.560"], ["20249.90", "2.440"], ["20349.90", "0.000"], ["56520.00", "0.066"], ["63584.90", "0.000"], ["67117.40", "0.000"], ["67117.50", "0.004"], ["69943.40", "0.000"], ["70439.20", "0.000"], ["70476.20", "0.174"], ["70515.20", "0.000"], ["70616.40", "0.357"], ["70616.70", "0.011"], ["70632.60", "0.001"], ["70634.20", "0.254"], ["70634.40", "0.001"], ["70645.20", "0.003"], ["70647.00", "0.008"], ["70647.50", "1.459"], ["70649.60", "0.116"], ["70649.80", "0.026"]], "a": [["70650.00", "5.543"], ["70651.40", "0.008"], ["70652.00", "0.016"], ["70782.00", "0.009"], ["70819.50", "0.000"], ["70856.60", "0.006"], ["70873.70", "0.000"], ["71356.50", "1.399"], ["72629.00", "0.060"], ["74187.80", "0.000"], ["77715.00", "0.000"]]}}
{"local_ts": 1773486626006, "server_ts": 1773486625973, "data": {"e": "depthUpdate", "E": 1773486625975, "T": 1773486625973, "s": "BTCUSDT", "U": 10109516068940, "u": 10109516072634, "pu": 10109516068861, "b": [["5000.00", "101.418"], ["7065.00", "0.000"], ["20149.90", "2.560"], ["20249.90", "0.160"], ["20549.90", "0.280"], ["33000.00", "3.789"], ["56520.00", "0.066"], ["63584.90", "0.000"], ["67083.80", "0.002"], ["67117.00", "0.173"], ["68530.40", "0.000"], ["69943.40", "0.000"], ["70582.60", "0.853"], ["70587.20", "0.650"], ["70588.30", "0.685"], ["70589.00", "0.053"], ["70597.40", "0.027"], ["70597.50", "0.243"], ["70614.60", "0.366"], ["70616.40", "0.187"], ["70632.60", "0.001"], ["70634.20", "0.254"], ["70636.50", "0.291"], ["70637.50", "0.127"], ["70638.20", "0.264"], ["70640.90", "0.008"], ["70642.60", "0.003"], ["70642.80", "0.062"], ["70642.90", "0.081"], ["70645.30", "0.023"], ["70645.40", "0.002"], ["70645.50", "0.372"], ["70647.60", "0.458"]], "a": [["70650.00", "5.467"], ["70652.40", "0.000"], ["70655.70", "0.002"], ["70656.20", "0.001"], ["70656.90", "0.013"], ["70657.00", "0.032"], ["70657.90", "0.054"], ["70659.80", "0.025"], ["70660.50", "0.105"], ["70660.60", "0.038"], ["70661.60", "0.221"], ["70661.70", "0.012"], ["70663.00", "0.000"], ["70663.90", "0.293"], ["70673.30", "0.225"], ["70674.50", "0.874"], ["70684.40", "0.033"], ["70685.10", "0.032"], ["70685.30", "0.015"], ["70686.20", "0.180"], ["70688.50", "0.040"], ["70706.90", "0.537"], ["70709.00", "0.047"], ["70709.80", "0.102"], ["70710.80", "0.361"], ["70715.50", "0.036"], ["70873.70", "0.000"], ["70930.10", "0.012"], ["71356.50", "1.399"], ["71617.90", "0.627"], ["71971.20", "0.922"], ["77715.00", "0.000"]]}}
{"local_ts": 1773486627025, "server_ts": 1773486626992, "data": {"e": "depthUpdate", "E": 1773486626995, "T": 1773486626992, "s": "BTCUSDT", "U": 10109516105692, "u": 10109516109065, "pu": 10109516105579, "b": [["1000.00", "26.142"], ["5000.00", "101.418"], ["7065.00", "0.000"], ["20149.90", "0.460"], ["20449.90", "0.130"], ["20549.90", "2.410"], ["63584.90", "0.000"], ["69823.30", "0.432"], ["69943.40", "0.000"], ["70296.70", "0.239"], ["70307.20", "0.000"], ["70514.50", "0.000"], ["70596.30", "0.502"], ["70597.40", "0.112"], ["70597.50", "0.158"], ["70598.90", "0.004"], ["70608.00", "0.008"], ["70614.60", "0.366"], ["70642.60", "0.000"], ["70642.90", "0.081"], ["70647.30", "0.032"], ["70649.90", "14.189"]], "a": [["70655.70", "0.337"], ["70657.00", "0.032"], ["70660.60", "0.038"], ["70663.90", "0.278"], ["70666.50", "1.068"], ["70685.30", "0.015"], ["70704.90", "0.118"], ["70711.50", "0.283"], ["70782.40", "0.000"], ["70791.60", "0.000"], ["71356.50", "1.399"], ["71654.10", "2.717"], ["74215.70", "0.000"], ["77715.00", "0.000"]]}}
{"local_ts": 1773486628048, "server_ts": 1773486628017, "data": {"e": "depthUpdate", "E": 1773486628019, "T": 1773486628017, "s": "BTCUSDT", "U": 10109516141436, "u": 10109516145330, "pu": 10109516141315, "b": [["1000.00", "26.142"], ["5000.00", "101.418"], ["7065.00", "0.056"], ["20449.90", "2.230"], ["20549.90", "0.770"], ["56520.00", "0.182"], ["63584.90", "0.000"], ["69799.60", "5.720"], ["69943.40", "0.000"], ["70082.20", "0.142"], ["70557.90", "0.654"], ["70614.60", "0.366"], ["70642.90", "0.081"]], "a": [["70657.00", "0.032"], ["70685.30", "0.015"], ["70716.70", "0.036"], ["70750.60", "0.169"], ["70769.30", "0.095"], ["70801.90", "0.159"], ["71356.50", "1.399"], ["71632.00", "1.554"], ["74190.70", "0.002"], ["77715.00", "0.000"]]}}
{"local_ts": 1773486629068, "server_ts": 1773486629037, "data": {"e": "depthUpdate", "E": 1773486629039, "T": 1773486629037, "s": "BTCUSDT", "U": 10109516181786, "u": 10109516185803, "pu": 10109516181738, "b": [["5000.00", "101.418"], ["7065.00", "0.056"], ["20349.90", "1.780"], ["20449.90", "1.220"], ["67084.80", "0.000"], ["68530.50", "0.006"], ["69943.40", "2.142"], ["70082.20", "0.071"], ["70296.70", "0.239"], ["70430.70", "0.511"], ["70597.90", "0.002"], ["70598.00", "0.087"], ["70598.10", "0.000"], ["70602.70", "0.006"], ["70603.20", "0.784"], ["70628.30", "0.006"], ["70628.90", "0.012"], ["70629.80", "0.006"], ["70632.60", "0.001"], ["70632.70", "0.249"], ["70634.20", "0.007"], ["70635.70", "0.072"], ["70636.40", "0.264"], ["70636.60", "0.000"], ["70637.20", "0.091"], ["70637.80", "0.513"], ["70638.00", "0.000"], ["70638.80", "0.071"], ["70639.30", "0.519"], ["70639.50", "0.000"], ["70642.50", "0.003"], ["70644.60", "0.002"], ["70645.30", "0.659"], ["70646.00", "0.000"], ["70647.30", "0.011"], ["70647.40", "0.542"], ["70648.30", "0.023"], ["70649.30", "0.000"], ["70649.80", "0.018"], ["70649.90", "13.727"]], "a": [["70650.00", "5.122"], ["70650.70", "0.002"], ["70651.90", "0.153"], ["70652.70", "0.100"], ["70652.80", "0.004"], ["70653.00", "0.005"], ["70653.10", "0.007"], ["70653.20", "0.000"], ["70653.30", "0.000"], ["70653.40", "0.005"], ["70653.50", "0.086"], ["70653.60", "0.006"], ["70654.20", "0.002"], ["70654.50", "0.007"], ["70657.80", "0.035"], ["70660.60", "0.078"], ["70662.40", "0.008"], ["70662.90", "0.016"], ["70670.70", "0.034"], ["70678.30", "0.000"], ["70679.70", "0.005"], ["70680.90", "0.160"], ["70681.10", "0.000"], ["70681.50", "0.003"], ["70681.60", "0.644"], ["70682.10", "0.511"], ["70685.60", "1.525"], ["70686.20", "0.250"], ["70686.90", "0.000"], ["70687.00", "0.119"], ["70688.70", "0.028"], ["70689.70", "0.428"], ["70753.30", "0.083"], ["70770.10", "0.181"], ["71212.70", "4.556"], ["71356.50", "2.101"], ["72769.40", "0.006"], ["74214.30", "0.002"], ["89523.20", "0.006"]]}}
{"local_ts": 1773486630090, "server_ts": 1773486630057, "data": {"e": "depthUpdate", "E": 1773486630059, "T": 1773486630057, "s": "BTCUSDT", "U": 10109516243844, "u": 10109516248825, "pu": 10109516243821, "b": [["1000.00", "26.142"], ["5000.00", "101.418"], ["7065.00", "0.056"], ["20249.90", "1.330"], ["20349.90", "1.670"], ["56520.00", "0.070"], ["67088.80", "0.100"], ["69943.40", "2.142"], ["69943.50", "0.011"], ["70403.10", "0.000"], ["70466.20", "0.159"], ["70614.60", "0.202"], ["70628.30", "0.006"], ["70629.50", "0.254"], ["70630.40", "0.249"], ["70632.40", "0.563"], ["70632.60", "0.001"], ["70634.60", "0.586"], ["70635.10", "0.404"], ["70637.20", "2.103"], ["70639.30", "0.005"], ["70645.70", "0.004"], ["70647.30", "0.005"], ["70649.90", "6.838"]], "a": [["70653.50", "0.068"], ["70656.90", "0.010"], ["70664.50", "0.558"], ["70675.60", "0.005"], ["70677.50", "0.072"], ["70678.40", "1.145"], ["70685.30", "0.053"], ["70685.40", "0.013"], ["70686.10", "0.306"], ["70892.70", "0.007"], ["71356.40", "0.018"], ["71356.50", "2.099"], ["74215.90", "0.005"], ["89523.20", "0.006"]]}}
{"local_ts": 1773486631110, "server_ts": 1773486631080, "data": {"e": "depthUpdate", "E": 1773486631081, "T": 1773486631080, "s": "BTCUSDT", "U": 10109516283093, "u": 10109516288086, "pu": 10109516282938, "b": [["5000.00", "101.418"], ["7065.00", "0.028"], ["20149.90", "0.890"], ["20249.90", "2.110"], ["33000.00", "3.785"], ["55882.20", "0.002"], ["67086.80", "0.002"], ["69427.70", "0.288"], ["69517.00", "2.727"], ["69519.50", "2.343"], ["69623.00", "19.680"], ["69625.50", "19.298"], ["69799.60", "5.577"], ["69879.80", "0.714"], ["69943.40", "2.142"], ["70555.80", "0.307"], ["70557.50", "6.909"], ["70562.80", "0.168"], ["70563.80", "0.147"], ["70564.50", "2.782"], ["70571.60", "0.152"], ["70593.60", "0.103"], ["70593.80", "0.059"], ["70602.20", "0.018"], ["70602.30", "0.004"], ["70622.20", "0.315"], ["70630.30", "0.341"], ["70630.40", "0.249"], ["70630.50", "0.138"], ["70634.60", "0.007"], ["70636.40", "0.652"], ["70637.20", "2.034"], ["70639.90", "0.008"], ["70640.50", "0.006"], ["70640.80", "0.003"], ["70642.20", "0.015"], ["70642.40", "0.007"], ["70643.20", "0.004"], ["70643.50", "0.015"], ["70643.60", "0.003"], ["70643.70", "0.001"], ["70644.50", "0.636"], ["70647.30", "0.005"], ["70647.50", "0.673"]], "a": [["70651.30", "1.567"], ["70671.60", "0.002"], ["70673.20", "0.045"], ["70676.70", "0.347"], ["70679.20", "1.336"], ["70680.20", "0.636"], ["70682.60", "1.640"], ["70682.90", "0.009"], ["70717.30", "0.000"], ["70718.90", "8.488"], ["70727.20", "10.261"], ["70734.30", "0.236"], ["70741.30", "0.185"], ["70801.90", "0.099"], ["71000.00", "86.462"], ["71356.50", "2.099"], ["89523.20", "0.006"]]}}
{"local_ts": 1773486632131, "server_ts": 1773486632100, "data": {"e": "depthUpdate", "E": 1773486632101, "T": 1773486632100, "s": "BTCUSDT", "U": 10109516321890, "u": 10109516325700, "pu": 10109516321837, "b": [["1000.00", "26.142"], ["5000.00", "101.418"], ["7065.00", "0.028"], ["20149.90", "2.540"], ["20249.90", "0.010"], ["20549.90", "0.450"], ["55882.20", "0.000"], ["67116.30", "0.002"], ["69552.40", "7.838"], ["69554.80", "11.413"], ["69599.30", "0.000"], ["69625.50", "27.330"], ["69788.60", "0.589"], ["69943.40", "2.142"], ["70296.70", "0.239"], ["70511.00", "0.007"], ["70593.40", "1.328"], ["70593.70", "0.003"], ["70593.80", "0.144"], ["70595.30", "0.856"], ["70602.40", "0.875"], ["70602.80", "0.366"], ["70602.90", "0.353"], ["70609.50", "0.854"], ["70616.60", "0.923"], ["70623.70", "0.857"], ["70625.00", "0.061"], ["70626.20", "0.006"], ["70627.60", "0.005"], ["70628.30", "0.006"], ["70629.40", "0.003"], ["70629.50", "0.402"], ["70630.50", "0.024"], ["70630.60", "0.004"], ["70631.70", "0.189"], ["70632.40", "0.810"], ["70635.70", "0.481"], ["70636.30", "0.126"], ["70636.40", "0.143"], ["70637.00", "0.103"], ["70637.20", "2.049"], ["70637.70", "0.011"], ["70638.70", "0.020"], ["70640.00", "1.394"], ["70640.20", "0.923"], ["70640.70", "0.000"], ["70641.10", "0.000"], ["70641.30", "0.016"], ["70641.40", "0.029"], ["70641.50", "0.003"], ["70641.80", "0.010"], ["70642.60", "0.015"], ["70642.90", "0.070"], ["70644.00", "0.529"], ["70645.20", "0.003"], ["70645.80", "0.057"], ["70646.70", "0.000"], ["70647.40", "0.524"], ["70649.90", "8.525"]], "a": [["70650.00", "5.985"], ["70650.70", "0.002"], ["70651.90", "0.150"], ["70654.80", "0.006"], ["70656.00", "0.004"], ["70664.50", "0.498"], ["70672.40", "0.878"], ["70673.40", "0.856"], ["70674.10", "0.009"], ["70678.30", "0.240"], ["70680.50", "0.855"], ["70684.30", "0.033"], ["70684.90", "0.070"], ["70686.10", "0.017"], ["70687.60", "0.855"], ["70694.70", "0.856"], ["70701.80", "0.853"], ["70745.70", "0.000"], ["70749.00", "0.254"], ["70752.80", "0.035"], ["70801.90", "0.159"], ["71356.50", "2.099"], ["71420.10", "1.405"], ["71900.50", "0.488"], ["74214.40", "0.000"], ["89523.20", "0.006"]]}}
{"local_ts": 1773486633153, "server_ts": 1773486633124, "data": {"e": "depthUpdate", "E": 1773486633125, "T": 1773486633124, "s": "BTCUSDT", "U": 10109516352341, "u": 10109516355457, "pu": 10109516352315, "b": [["1000.00", "26.142"], ["5000.00", "101.418"], ["7065.00", "0.028"], ["20149.90", "0.240"], ["20449.90", "0.240"], ["20549.90", "2.520"], ["33000.00", "3.789"], ["55882.20", "0.002"], ["56520.00", "0.066"], ["64060.40", "0.000"], ["67098.90", "0.000"], ["67112.10", "0.002"], ["69646.70", "4.297"], ["69802.10", "4.294"], ["69943.40", "2.142"], ["70084.70", "0.427"], ["70296.80", "0.000"], ["70370.90", "0.210"], ["70554.90", "0.020"], ["70555.50", "0.000"], ["70590.00", "0.671"], ["70601.60", "0.000"], ["70609.50", "0.058"], ["70616.40", "0.003"], ["70619.10", "0.357"], ["70622.10", "0.534"], ["70622.30", "0.364"], ["70623.40", "0.015"], ["70624.60", "0.284"], ["70625.90", "0.440"], ["70627.10", "0.019"], ["70628.30", "0.013"], ["70628.40", "0.019"], ["70628.90", "0.005"], ["70632.60", "0.001"], ["70633.90", "0.022"], ["70635.10", "0.011"], ["70635.90", "0.027"], ["70636.90", "1.172"], ["70637.20", "2.034"], ["70637.80", "0.074"], ["70638.50", "0.400"], ["70639.30", "0.005"], ["70639.40", "0.005"], ["70640.20", "0.925"], ["70641.40", "0.008"], ["70642.10", "0.002"], ["70642.20", "0.013"], ["70642.30", "0.001"], ["70642.90", "0.068"], ["70643.60", "0.003"], ["70645.90", "0.005"], ["70646.20", "0.003"], ["70647.30", "0.005"], ["70649.90", "7.796"]], "a": [["70650.40", "0.017"], ["70657.00", "0.032"], ["70660.60", "0.045"], ["70661.70", "0.015"], ["70683.70", "0.000"], ["70684.50", "0.075"], ["70686.10", "0.017"], ["71356.50", "2.101"], ["71674.40", "7.662"], ["71745.10", "1.952"], ["89523.20", "0.006"]]}}
{"local_ts": 1773486634180, "server_ts": 1773486634148, "data": {"e": "depthUpdate", "E": 1773486634149, "T": 1773486634148, "s": "BTCUSDT", "U": 10109516384917, "u": 10109516387824, "pu": 10109516384856, "b": [["5000.00", "101.418"], ["7065.00", "0.000"], ["20349.90", "0.090"], ["20449.90", "2.380"], ["20549.90", "0.530"], ["55882.20", "0.000"], ["67117.40", "0.010"], ["67117.50", "0.002"], ["69547.80", "0.287"], ["69943.40", "3.576"], ["70093.80", "0.854"], ["70296.70", "0.239"], ["70296.80", "0.000"], ["70335.60", "0.000"], ["70496.90", "0.002"], ["70502.40", "0.376"], ["70503.90", "0.000"], ["70509.40", "0.222"], ["70518.10", "0.000"], ["70523.60", "0.202"], ["70557.50", "6.926"], ["70564.50", "2.853"], ["70571.60", "0.223"], ["70619.10", "0.173"], ["70619.20", "0.383"], ["70623.40", "0.000"], ["70624.60", "0.269"], ["70637.20", "2.034"], ["70639.30", "0.005"], ["70641.10", "0.007"], ["70641.20", "0.000"], ["70641.30", "0.001"], ["70642.30", "0.001"], ["70642.90", "0.076"], ["70643.60", "0.003"], ["70643.90", "0.406"], ["70644.10", "0.003"], ["70646.30", "0.065"], ["70647.30", "0.005"], ["70649.90", "7.742"]], "a": [["70650.00", "7.302"], ["70650.50", "0.004"], ["70657.00", "0.032"], ["70660.30", "0.007"], ["70660.60", "0.042"], ["70664.20", "0.027"], ["70674.00", "0.096"], ["70686.10", "0.059"], ["70734.20", "0.104"], ["70741.30", "0.256"], ["70748.30", "0.170"], ["71356.50", "2.101"], ["71745.10", "5.222"], ["71919.50", "0.000"], ["74186.70", "0.008"], ["74197.30", "0.000"], ["89523.20", "0.006"]]}}
{"local_ts": 1773486635198, "server_ts": 1773486635168, "data": {"e": "depthUpdate", "E": 1773486635169, "T": 1773486635168, "s": "BTCUSDT", "U": 10109516414033, "u": 10109516416868, "pu": 10109516413886, "b": [["1000.00", "26.292"], ["5000.00", "101.418"], ["7065.00", "0.000"], ["20349.90", "2.110"], ["20449.90", "0.890"], ["33000.00", "3.789"], ["55882.20", "0.002"], ["63584.90", "0.008"], ["67089.00", "0.000"], ["67114.10", "0.000"], ["67117.00", "0.173"], ["68649.90", "0.012"], ["69943.40", "3.576"], ["70340.10", "0.000"], ["70342.40", "0.628"], ["70431.50", "0.004"], ["70602.50", "0.520"], ["70602.70", "0.006"], ["70616.60", "0.240"], ["70616.70", "0.011"], ["70619.30", "0.175"], ["70624.30", "0.023"], ["70633.20", "0.024"], ["70634.50", "0.354"], ["70635.70", "0.496"], ["70638.30", "0.002"], ["70639.00", "0.023"], ["70639.10", "0.013"], ["70639.30", "0.008"], ["70639.80", "0.117"], ["70642.20", "0.013"], ["70642.30", "0.004"], ["70642.90", "0.078"], ["70643.90", "0.370"], ["70646.30", "0.000"], ["70647.30", "0.005"]], "a": [["70650.00", "7.258"], ["70650.10", "0.015"], ["70657.00", "0.034"], ["70660.60", "0.045"], ["70669.80", "0.006"], ["70669.90", "0.028"], ["71356.50", "2.099"], ["71497.80", "2.094"], ["71533.10", "0.132"], ["74210.90", "0.002"], ["77715.00", "0.008"], ["89523.20", "0.006"]]}}
{"local_ts": 1773486636220, "server_ts": 1773486636188, "data": {"e": "depthUpdate", "E": 1773486636191, "T": 1773486636188, "s": "BTCUSDT", "U": 10109516444883, "u": 10109516448108, "pu": 10109516444845, "b": [["5000.00", "101.418"], ["7065.00", "0.000"], ["20249.90", "1.660"], ["20349.90", "1.340"], ["55882.20", "0.000"], ["56520.00", "0.066"], ["69943.40", "3.576"], ["69943.50", "0.007"], ["70097.10", "2.866"], ["70296.80", "0.004"], ["70466.20", "0.000"], ["70556.10", "0.068"], ["70563.10", "0.147"], ["70564.20", "0.053"], ["70564.90", "0.145"], ["70601.60", "0.000"], ["70602.50", "0.520"], ["70602.80", "0.366"], ["70612.40", "0.004"], ["70613.00", "0.426"], ["70613.10", "0.172"], ["70616.70", "0.011"], ["70619.30", "0.005"], ["70639.30", "0.008"], ["70640.50", "0.006"], ["70640.80", "0.003"], ["70641.00", "0.004"], ["70642.30", "0.004"], ["70642.90", "0.015"]], "a": [["70650.00", "6.080"], ["70650.80", "0.025"], ["70657.00", "0.004"], ["70660.60", "0.042"], ["70682.20", "0.007"], ["70874.00", "0.007"], ["71356.50", "2.099"], ["74191.50", "0.050"], ["89523.20", "0.006"]]}}
{"local_ts": 1773486637240, "server_ts": 1773486637208, "data": {"e": "depthUpdate", "E": 1773486637211, "T": 1773486637208, "s": "BTCUSDT", "U": 10109516479140, "u": 10109516482363, "pu": 10109516479089, "b": [["1000.00", "26.292"], ["5000.00", "101.438"], ["7065.00", "0.056"], ["20149.90", "1.210"], ["20249.90", "1.790"], ["55882.20", "0.002"], ["67083.30", "0.021"], ["67824.00", "0.020"], ["69943.40", "3.576"], ["70296.70", "0.239"], ["70517.60", "1.153"], ["70557.20", "0.041"], ["70564.20", "0.125"], ["70571.30", "0.178"], ["70594.00", "0.085"], ["70603.00", "0.005"], ["70612.40", "0.000"], ["70613.00", "0.072"], ["70613.10", "0.002"], ["70619.20", "0.185"], ["70619.30", "0.189"], ["70639.30", "0.005"], ["70642.30", "0.001"], ["70642.90", "0.079"], ["70645.40", "0.017"], ["70645.50", "0.002"], ["70647.40", "0.515"]], "a": [["70650.00", "5.708"], ["70657.00", "0.032"], ["70660.60", "0.045"], ["70682.30", "0.037"], ["70683.00", "0.090"], ["70733.90", "0.004"], ["70741.00", "0.003"], ["70748.00", "0.110"], ["70784.00", "2.950"], ["70784.10", "0.045"], ["70874.00", "0.000"], ["70874.20", "0.007"], ["71356.40", "0.011"], ["71356.50", "2.099"], ["71729.40", "0.834"], ["71795.40", "0.008"], ["74206.60", "0.000"], ["89523.20", "0.006"]]}}
{"local_ts": 1773486638261, "server_ts": 1773486638232, "data": {"e": "depthUpdate", "E": 1773486638233, "T": 1773486638232, "s": "BTCUSDT", "U": 10109516510708, "u": 10109516513857, "pu": 10109516510631, "b": [["1000.00", "26.292"], ["5000.00", "101.418"], ["7065.00", "0.056"], ["20149.90", "2.230"], ["20549.90", "0.770"], ["55882.20", "0.000"], ["67095.60", "0.000"], ["68883.70", "0.290"], ["69207.40", "0.002"], ["69943.40", "3.576"], ["70602.40", "0.022"], ["70602.70", "0.008"], ["70610.60", "0.007"], ["70614.10", "0.055"], ["70615.40", "1.755"], ["70616.60", "0.070"], ["70619.10", "0.343"], ["70619.20", "0.199"], ["70619.30", "0.005"], ["70630.40", "0.249"], ["70632.40", "0.679"], ["70639.00", "0.291"], ["70639.10", "0.013"], ["70639.30", "0.005"], ["70639.40", "0.005"], ["70640.00", "0.395"], ["70641.20", "0.021"], ["70641.50", "0.003"], ["70642.30", "0.001"], ["70642.90", "0.081"], ["70643.20", "0.004"], ["70643.30", "1.537"], ["70644.40", "0.001"], ["70644.70", "0.023"], ["70646.70", "0.021"], ["70646.80", "0.018"], ["70646.90", "0.058"], ["70649.90", "8.419"]], "a": [["70650.00", "7.206"], ["70650.10", "0.009"], ["70650.20", "0.028"], ["70651.60", "0.070"], ["70652.00", "0.001"], ["70660.60", "0.042"], ["70661.20", "0.057"], ["70708.40", "0.009"], ["70708.90", "3.561"], ["70740.90", "0.071"], ["71356.50", "2.099"], ["71719.20", "0.050"], ["74192.80", "0.002"], ["89523.20", "0.006"]]}}
{"local_ts": 1773486639286, "server_ts": 1773486639256, "data": {"e": "depthUpdate", "E": 1773486639257, "T": 1773486639256, "s": "BTCUSDT", "U": 10109516546325, "u": 10109516551055, "pu": 10109516546252, "b": [["5000.00", "101.418"], ["7065.00", "0.056"], ["20149.90", "0.050"], ["20449.90", "0.370"], ["20549.90", "2.580"], ["69943.40", "3.576"], ["70296.70", "0.239"], ["70484.70", "0.002"], ["70503.00", "0.090"], ["70547.20", "0.047"], ["70576.30", "0.122"], ["70591.20", "0.515"], ["70593.90", "0.059"], ["70594.20", "3.360"], ["70597.30", "0.515"], ["70601.30", "0.000"], ["70602.70", "0.008"], ["70602.80", "0.366"], ["70608.40", "0.045"], ["70615.10", "0.016"], ["70618.60", "0.458"], ["70619.20", "0.015"], ["70619.80", "0.214"], ["70632.00", "0.012"], ["70632.30", "0.260"], ["70632.40", "0.627"], ["70632.50", "0.821"], ["70632.80", "0.261"], ["70634.50", "0.350"], ["70634.60", "0.007"], ["70635.10", "0.411"], ["70635.70", "0.133"], ["70637.20", "1.038"], ["70638.40", "0.053"], ["70638.60", "0.402"], ["70639.30", "0.078"], ["70641.90", "0.000"], ["70642.30", "0.004"], ["70642.80", "0.002"], ["70643.60", "0.013"], ["70645.10", "0.000"], ["70646.00", "0.064"], ["70649.70", "0.017"], ["70649.80", "0.081"], ["70649.90", "9.500"]], "a": [["70650.00", "4.415"], ["70651.30", "0.000"], ["70651.50", "0.045"], ["70652.90", "0.017"], ["70653.90", "0.023"], ["70654.70", "0.023"], ["70655.60", "0.005"], ["70655.70", "0.002"], ["70656.10", "0.007"], ["70656.20", "0.016"], ["70656.90", "0.010"], ["70657.50", "0.063"], ["70659.10", "0.036"], ["70660.20", "0.004"], ["70660.60", "0.047"], ["70661.00", "0.715"], ["70664.90", "0.026"], ["70665.30", "0.002"], ["70665.70", "0.002"], ["70665.80", "0.516"], ["70665.90", "0.001"], ["70666.50", "0.002"], ["70667.50", "0.002"], ["70669.30", "0.002"], ["70670.70", "0.034"], ["70674.00", "0.009"], ["70675.40", "0.014"], ["70677.80", "0.085"], ["70682.90", "0.157"], ["70683.20", "0.224"], ["70699.70", "0.027"], ["70718.90", "0.009"], ["70720.80", "0.005"], ["70720.90", "8.488"], ["70723.60", "0.000"], ["70767.20", "0.000"], ["70770.90", "0.358"], ["70771.90", "0.000"], ["70777.10", "0.095"], ["70777.80", "3.698"], ["70784.20", "1.148"], ["70795.10", "0.004"], ["70798.30", "0.176"], ["70803.60", "0.101"], ["71356.50", "2.799"], ["71582.00", "1.114"], ["71729.80", "0.418"], ["74192.00", "0.057"]]}}
{"local_ts": 1773486640309, "server_ts": 1773486640277, "data": {"e": "depthUpdate", "E": 1773486640279, "T": 1773486640277, "s": "BTCUSDT", "U": 10109516583660, "u": 10109516587979, "pu": 10109516583606, "b": [["1000.00", "26.292"], ["5000.00", "101.398"], ["7065.00", "0.028"], ["20349.90", "0.200"], ["20449.90", "2.480"], ["20549.90", "0.320"], ["33000.00", "3.785"], ["67117.40", "0.004"], ["69566.60", "0.720"], ["69696.10", "1.503"], ["69943.40", "4.290"], ["70125.00", "0.903"], ["70402.60", "0.012"], ["70551.70", "0.034"], ["70557.00", "0.000"], ["70564.00", "1.302"], ["70571.10", "0.000"], ["70616.40", "0.173"], ["70619.30", "0.189"], ["70619.80", "0.030"], ["70629.40", "0.010"], ["70630.20", "0.456"], ["70639.30", "0.008"], ["70642.30", "0.004"], ["70642.80", "0.002"], ["70642.90", "0.015"], ["70643.60", "0.013"], ["70647.50", "0.636"], ["70649.00", "0.002"], ["70649.90", "9.482"]], "a": [["70650.00", "4.129"], ["70651.90", "0.021"], ["70652.70", "0.100"], ["70656.90", "0.010"], ["70657.00", "0.004"], ["70660.60", "0.047"], ["70733.70", "0.002"], ["70740.80", "0.000"], ["70747.80", "0.083"], ["70875.10", "0.000"], ["71356.50", "2.799"], ["71688.60", "0.557"], ["72791.70", "1.176"], ["74217.70", "0.000"], ["77590.80", "0.000"], ["77715.00", "0.012"]]}}
{"local_ts": 1773486641331, "server_ts": 1773486641296, "data": {"e": "depthUpdate", "E": 1773486641299, "T": 1773486641296, "s": "BTCUSDT", "U": 10109516625616, "u": 10109516629819, "pu": 10109516625597, "b": [["5000.00", "101.418"], ["7065.00", "0.028"], ["20249.90", "0.050"], ["20349.90", "2.330"], ["20449.90", "0.620"], ["67112.70", "0.000"], ["67234.00", "0.136"], ["69328.70", "3.497"], ["69492.00", "0.717"], ["69566.30", "0.718"], ["69943.40", "4.290"], ["70307.20", "0.000"], ["70360.20", "0.121"], ["70462.70", "0.000"], ["70466.20", "0.159"], ["70480.30", "0.028"], ["70556.50", "0.065"], ["70563.50", "0.101"], ["70564.50", "2.640"], ["70565.30", "0.146"], ["70572.20", "0.281"], ["70586.30", "0.007"], ["70601.90", "0.000"], ["70602.30", "0.004"], ["70602.50", "0.518"], ["70612.40", "0.004"], ["70625.60", "0.007"], ["70639.30", "0.005"], ["70642.30", "0.001"], ["70643.60", "0.013"], ["70644.90", "0.006"], ["70645.60", "0.012"], ["70646.00", "0.072"], ["70647.30", "0.005"], ["70647.60", "0.004"], ["70648.60", "0.012"]], "a": [["70650.00", "5.585"], ["70650.10", "1.592"], ["70657.90", "0.694"], ["70660.60", "0.042"], ["70661.00", "0.063"], ["70664.90", "0.026"], ["70671.50", "0.349"], ["70676.10", "0.209"], ["70680.20", "0.000"], ["70713.60", "0.005"], ["70727.70", "0.003"], ["70767.30", "0.213"], ["70771.10", "0.435"], ["70874.30", "0.007"], ["71356.40", "0.011"], ["71356.50", "2.799"], ["71624.90", "0.556"]]}}
{"local_ts": 1773486642362, "server_ts": 1773486642318, "data": {"e": "depthUpdate", "E": 1773486642321, "T": 1773486642318, "s": "BTCUSDT", "U": 10109516663572, "u": 10109516667357, "pu": 10109516663435, "b": [["1000.00", "26.292"], ["5000.00", "101.418"], ["7065.00", "0.028"], ["20249.90", "1.980"], ["20349.90", "1.020"], ["33000.00", "3.789"], ["61324.10", "0.700"], ["67103.80", "0.000"], ["69671.70", "0.006"], ["69943.40", "4.290"], ["70296.70", "0.239"], ["70296.80", "0.000"], ["70402.90", "0.004"], ["70601.90", "0.004"], ["70602.40", "0.022"], ["70602.50", "0.520"], ["70612.40", "0.000"], ["70616.40", "0.187"], ["70616.60", "0.424"], ["70619.20", "0.199"], ["70639.30", "0.005"], ["70642.30", "0.004"], ["70647.10", "0.000"], ["70647.30", "0.020"], ["70647.40", "0.479"], ["70647.70", "0.114"], ["70649.90", "8.936"]], "a": [["70650.00", "4.824"], ["70651.60", "0.088"], ["70652.10", "0.012"], ["70654.00", "0.067"], ["70657.90", "0.692"], ["70660.40", "0.003"], ["70660.60", "0.045"], ["70801.90", "0.099"], ["71356.50", "2.799"], ["72191.20", "1.186"]]}}
{"local_ts": 1773486643372, "server_ts": 1773486643340, "data": {"e": "depthUpdate", "E": 1773486643343, "T": 1773486643340, "s": "BTCUSDT", "U": 10109516697895, "u": 10109516700436, "pu": 10109516697861, "b": [["1000.00", "26.292"], ["5000.00", "101.418"], ["7065.00", "0.000"], ["20149.90", "1.540"], ["20249.90", "1.460"], ["56520.00", "0.066"], ["67093.60", "0.002"], ["67117.00", "0.173"], ["69850.30", "0.000"], ["69943.40", "4.290"], ["70296.80", "0.000"], ["70402.80", "0.765"], ["70466.20", "0.159"], ["70594.80", "0.436"], ["70594.90", "0.765"], ["70600.00", "1.362"], ["70616.40", "0.357"], ["70616.60", "0.070"], ["70619.10", "0.357"], ["70624.90", "0.006"], ["70639.30", "0.005"], ["70640.70", "0.015"], ["70642.40", "0.007"], ["70643.60", "0.013"], ["70643.70", "0.058"], ["70647.40", "0.479"]], "a": [["70650.00", "7.937"], ["70660.60", "0.042"], ["70874.20", "0.000"], ["71356.30", "0.007"], ["71356.50", "2.799"], ["71742.00", "0.023"], ["74208.50", "0.050"]]}}
{"local_ts": 1773486644396, "server_ts": 1773486644364, "data": {"e": "depthUpdate", "E": 1773486644365, "T": 1773486644364, "s": "BTCUSDT", "U": 10109516736535, "u": 10109516740243, "pu": 10109516736454, "b": [["5000.00", "101.418"], ["7065.00", "0.000"], ["20149.90", "1.900"], ["20549.90", "1.100"], ["33000.00", "3.789"], ["67108.80", "0.000"], ["67116.30", "0.002"], ["68883.70", "0.652"], ["70100.10", "3.739"], ["70221.90", "0.000"], ["70222.10", "16.020"], ["70296.70", "0.239"], ["70327.40", "0.000"], ["70328.50", "0.000"], ["70328.60", "1.022"], ["70403.00", "0.004"], ["70517.50", "2.399"], ["70556.60", "0.017"], ["70563.60", "0.073"], ["70570.70", "0.077"], ["70601.60", "0.004"], ["70602.40", "0.022"], ["70602.50", "0.577"], ["70612.40", "0.000"], ["70638.60", "0.402"], ["70639.40", "0.007"], ["70642.90", "0.043"]], "a": [["70657.00", "0.047"], ["70733.30", "0.105"], ["70740.40", "0.071"], ["70740.50", "0.048"], ["70747.40", "0.141"], ["70782.90", "0.523"], ["70797.30", "0.094"], ["70892.80", "0.260"], ["70893.10", "0.002"], ["70970.20", "0.129"], ["70972.60", "0.000"], ["70972.70", "0.000"], ["70999.90", "13.710"], ["71079.10", "0.000"], ["71291.10", "0.008"], ["71356.50", "2.799"], ["73475.90", "0.010"]]}}
{"local_ts": 1773486645418, "server_ts": 1773486645388, "data": {"e": "depthUpdate", "E": 1773486645389, "T": 1773486645388, "s": "BTCUSDT", "U": 10109516785217, "u": 10109516788952, "pu": 10109516785063, "b": [["1000.00", "26.292"], ["5000.00", "101.418"], ["7065.00", "0.000"], ["20149.90", "0.000"], ["20449.90", "0.660"], ["20549.90", "2.340"], ["67112.70", "0.000"], ["69433.80", "0.291"], ["69642.40", "0.000"], ["69943.40", "4.290"], ["69943.50", "0.011"], ["70403.00", "0.000"], ["70466.20", "0.159"], ["70596.90", "0.818"], ["70597.20", "0.089"], ["70612.40", "0.000"], ["70630.40", "0.002"], ["70631.00", "0.511"], ["70632.10", "0.031"], ["70632.60", "0.001"], ["70633.40", "0.149"], ["70634.50", "0.322"], ["70639.10", "0.702"], ["70639.80", "0.012"], ["70641.40", "0.011"], ["70642.70", "0.371"], ["70643.10", "0.006"], ["70644.00", "0.514"], ["70644.20", "0.004"]], "a": [["70650.00", "8.606"], ["70664.20", "0.027"], ["70678.30", "0.390"], ["70679.20", "1.334"], ["70680.40", "0.039"], ["70680.80", "0.003"], ["70681.20", "0.217"], ["70685.80", "0.005"], ["70686.20", "0.171"], ["70740.50", "0.041"], ["70742.50", "0.007"], ["70747.60", "0.086"], ["70749.60", "0.011"], ["70754.70", "0.086"], ["70756.70", "0.015"], ["70761.80", "0.000"], ["70762.70", "0.150"], ["70763.80", "0.092"], ["70768.90", "0.000"], ["70770.90", "0.365"], ["70776.00", "0.002"], ["70778.00", "0.274"], ["70783.10", "0.053"], ["70785.10", "0.007"], ["70790.20", "0.000"], ["70792.20", "0.303"], ["71356.50", "2.799"], ["71603.80", "3.205"], ["71644.10", "0.000"]]}}
{"local_ts": 1773486646442, "server_ts": 1773486646412, "data": {"e": "depthUpdate", "E": 1773486646413, "T": 1773486646412, "s": "BTCUSDT", "U": 10109516823859, "u": 10109516826759, "pu": 10109516823791, "b": [["5000.00", "101.418"], ["7065.00", "0.056"], ["20349.90", "0.310"], ["20449.90", "2.590"], ["20549.90", "0.100"], ["67116.10", "0.002"], ["69778.50", "0.767"], ["69943.40", "4.290"], ["69943.50", "0.011"], ["70303.70", "0.121"], ["70403.50", "0.000"], ["70556.90", "0.583"], ["70563.80", "0.295"], ["70564.90", "0.238"], ["70565.60", "0.053"], ["70614.60", "0.169"], ["70639.20", "0.002"], ["70639.40", "0.026"], ["70642.10", "0.002"], ["70642.50", "0.057"], ["70646.50", "0.010"], ["70646.90", "0.001"], ["70647.10", "0.000"], ["70649.90", "7.553"]], "a": [["70650.00", "7.834"], ["70654.00", "0.071"], ["70661.70", "0.012"], ["70664.20", "0.001"], ["70678.30", "0.416"], ["70685.30", "0.015"], ["70708.30", "0.286"], ["70742.50", "0.000"], ["70749.60", "0.004"], ["70756.70", "0.008"], ["70763.80", "0.085"], ["70770.90", "0.358"], ["70778.00", "0.267"], ["70785.10", "0.002"], ["70792.20", "0.296"], ["70798.40", "0.003"], ["70819.20", "0.119"], ["70826.30", "0.007"], ["70833.40", "0.007"], ["70840.50", "0.009"], ["70847.60", "0.266"], ["70854.70", "0.009"], ["70861.80", "0.244"], ["70868.90", "0.286"], ["70873.40", "0.000"], ["70873.80", "0.007"], ["71354.00", "1.444"], ["71356.50", "2.799"], ["72071.30", "0.069"], ["74202.10", "0.000"]]}}
{"local_ts": 1773486647465, "server_ts": 1773486647433, "data": {"e": "depthUpdate", "E": 1773486647435, "T": 1773486647433, "s": "BTCUSDT", "U": 10109516854360, "u": 10109516857260, "pu": 10109516854310, "b": [["1000.00", "26.292"], ["5000.00", "101.418"], ["7065.00", "0.056"], ["20249.90", "0.160"], ["20349.90", "2.450"], ["20449.90", "0.390"], ["67103.30", "0.000"], ["69943.40", "4.290"], ["70296.60", "0.075"], ["70296.70", "0.239"], ["70296.80", "0.000"], ["70303.70", "0.015"], ["70466.20", "0.159"], ["70603.90", "0.019"], ["70612.40", "0.004"], ["70640.00", "0.385"], ["70641.40", "0.008"], ["70649.90", "7.400"]], "a": [["70653.30", "0.003"], ["70653.80", "0.007"], ["70659.90", "0.160"], ["70660.10", "0.000"], ["70662.40", "0.008"], ["70662.90", "0.155"], ["70664.20", "0.001"], ["70665.90", "0.001"], ["70666.80", "1.240"], ["70674.40", "0.004"], ["70678.30", "0.416"], ["70685.90", "0.035"], ["70686.00", "0.130"], ["70689.90", "1.063"], ["70716.00", "0.009"], ["70744.30", "0.093"], ["70759.40", "0.015"], ["70766.50", "0.140"], ["70773.60", "0.161"], ["70780.70", "2.460"], ["70785.10", "0.000"], ["70787.80", "0.189"], ["70794.90", "0.104"], ["70798.70", "12.575"], ["70802.00", "0.024"], ["70809.10", "0.009"], ["70819.20", "0.112"], ["70826.30", "0.000"], ["70833.40", "0.000"], ["70840.50", "0.002"], ["70847.60", "0.259"], ["70854.70", "0.002"], ["70861.80", "0.237"], ["70868.90", "0.279"], ["70873.70", "0.007"], ["71356.40", "0.011"], ["71356.50", "2.799"]]}}
{"local_ts": 1773486648489, "server_ts": 1773486648456, "data": {"e": "depthUpdate", "E": 1773486648457, "T": 1773486648456, "s": "BTCUSDT", "U": 10109516888056, "u": 10109516890631, "pu": 10109516887934, "b": [["1000.00", "26.292"], ["5000.00", "101.418"], ["7065.00", "0.056"], ["20149.90", "0.020"], ["20249.90", "2.290"], ["20349.90", "0.690"], ["66895.90", "0.000"], ["67108.50", "0.002"], ["67117.30", "0.000"], ["67117.40", "0.004"], ["69943.40", "4.290"], ["70117.50", "0.712"], ["70642.60", "0.523"], ["70644.40", "0.009"], ["70645.40", "0.002"], ["70646.90", "0.001"], ["70649.90", "7.400"]], "a": [["70650.00", "8.317"], ["70678.40", "0.002"], ["70679.30", "0.426"], ["70680.00", "3.647"], ["70689.90", "1.061"], ["70712.60", "0.017"], ["70716.00", "0.007"], ["70752.90", "0.591"], ["70759.40", "0.008"], ["70760.00", "0.680"], ["70766.50", "0.133"], ["70767.10", "2.007"], ["70773.60", "0.154"], ["70774.20", "2.547"], ["70780.70", "2.453"], ["70781.30", "0.007"], ["70787.80", "0.182"], ["70788.40", "0.009"], ["70794.90", "0.097"], ["70795.50", "0.007"], ["70801.90", "0.000"], ["70802.00", "0.017"], ["70802.60", "0.083"], ["70809.10", "0.002"], ["71356.50", "4.198"]]}}
{"local_ts": 1773486649506, "server_ts": 1773486649472, "data": {"e": "depthUpdate", "E": 1773486649477, "T": 1773486649472, "s": "BTCUSDT", "U": 10109516919610, "u": 10109516922442, "pu": 10109516919513, "b": [["5000.00", "101.418"], ["7065.00", "0.028"], ["20149.90", "1.870"], ["20249.90", "1.130"], ["33000.00", "3.785"], ["69943.40", "5.718"], ["70155.10", "0.002"], ["70296.70", "0.239"], ["70307.20", "0.106"], ["70462.70", "0.000"], ["70466.20", "0.159"], ["70480.30", "0.028"], ["70498.80", "13.162"], ["70500.10", "2.852"], ["70555.90", "0.043"], ["70558.00", "6.870"], ["70559.30", "2.434"], ["70589.80", "0.003"], ["70593.50", "4.064"], ["70594.90", "1.166"], ["70602.30", "0.004"], ["70602.40", "0.022"], ["70614.80", "1.843"], ["70622.30", "0.364"], ["70631.90", "0.103"], ["70632.80", "0.070"], ["70638.60", "0.638"], ["70638.80", "0.147"], ["70639.60", "0.330"], ["70646.80", "0.003"]], "a": [["70650.00", "8.226"], ["70652.20", "0.006"], ["70657.80", "0.687"], ["70657.90", "0.040"], ["70659.80", "0.004"], ["70659.90", "0.157"], ["70669.70", "0.357"], ["70670.40", "0.009"], ["70671.30", "0.003"], ["70678.40", "0.000"], ["70678.60", "0.145"], ["70683.80", "1.877"], ["70705.10", "3.486"], ["70712.60", "0.015"], ["70712.70", "0.090"], ["70738.90", "1.677"], ["70740.40", "6.663"], ["70799.80", "13.112"], ["70801.90", "0.106"], ["70805.40", "0.000"], ["71356.50", "4.198"], ["71624.90", "0.000"], ["71903.40", "0.004"], ["74204.00", "0.102"]]}}
{"local_ts": 1773486650531, "server_ts": 1773486650500, "data": {"e": "depthUpdate", "E": 1773486650501, "T": 1773486650500, "s": "BTCUSDT", "U": 10109516952112, "u": 10109516955837, "pu": 10109516952024, "b": [["1000.00", "26.292"], ["5000.00", "101.418"], ["7065.00", "0.028"], ["20149.90", "1.570"], ["20549.90", "1.430"], ["67104.30", "0.000"], ["67111.90", "0.002"], ["68483.00", "0.000"], ["69642.30", "1.577"], ["69943.40", "5.718"], ["70084.70", "5.555"], ["70296.60", "0.075"], ["70584.60", "0.108"], ["70606.00", "0.044"], ["70614.60", "0.073"], ["70618.40", "0.002"], ["70620.40", "0.033"], ["70637.00", "0.023"], ["70638.40", "0.480"], ["70639.00", "0.029"], ["70640.10", "0.062"], ["70642.00", "0.024"], ["70643.80", "0.061"], ["70644.40", "0.011"], ["70646.00", "0.008"], ["70648.10", "0.011"], ["70648.40", "0.005"]], "a": [["70650.00", "8.209"], ["70658.90", "0.002"], ["70660.00", "0.039"], ["70662.60", "0.038"], ["70674.30", "0.022"], ["70678.60", "0.143"], ["70685.30", "0.043"], ["70689.50", "0.038"], ["70695.50", "0.007"], ["70712.70", "0.088"], ["70716.40", "0.040"], ["70717.70", "0.038"], ["70792.30", "0.102"], ["70874.30", "0.000"], ["71356.30", "0.007"], ["71356.50", "5.599"], ["72080.10", "0.002"], ["72082.40", "1.670"], ["72083.00", "1.662"]]}}
{"local_ts": 1773486651564, "server_ts": 1773486651526, "data": {"e": "depthUpdate", "E": 1773486651527, "T": 1773486651526, "s": "BTCUSDT", "U": 10109516993297, "u": 10109516998517, "pu": 10109516993242, "b": [["5000.00", "101.418"], ["7065.00", "0.028"], ["20449.90", "1.000"], ["20549.90", "2.000"], ["33000.00", "3.789"], ["56520.00", "0.070"], ["67097.30", "0.002"], ["67100.50", "0.013"], ["67117.50", "0.006"], ["69802.10", "9.301"], ["69943.40", "5.718"], ["70100.10", "3.739"], ["70222.10", "16.020"], ["70296.60", "0.075"], ["70327.10", "0.003"], ["70466.20", "0.159"], ["70555.40", "0.000"], ["70557.30", "0.067"], ["70564.30", "0.464"], ["70565.40", "0.053"], ["70566.10", "1.119"], ["70576.90", "0.170"], ["70582.30", "1.364"], ["70597.40", "0.027"], ["70597.50", "0.158"], ["70597.80", "0.120"], ["70601.60", "0.004"], ["70612.40", "0.000"], ["70616.40", "0.357"], ["70636.20", "0.372"], ["70643.10", "0.027"], ["70644.30", "0.003"]], "a": [["70650.00", "7.905"], ["70663.80", "0.005"], ["70674.10", "0.009"], ["70674.20", "0.011"], ["70674.80", "0.039"], ["70674.90", "0.001"], ["70686.40", "0.019"], ["70686.50", "0.324"], ["70686.70", "0.137"], ["70690.80", "0.045"], ["70717.70", "0.000"], ["70873.80", "0.000"], ["70874.30", "0.007"], ["70970.60", "0.006"], ["70999.90", "13.710"], ["71356.40", "0.011"], ["71356.50", "5.599"], ["89523.20", "0.006"]]}}
{"local_ts": 1773486652578, "server_ts": 1773486652548, "data": {"e": "depthUpdate", "E": 1773486652549, "T": 1773486652548, "s": "BTCUSDT", "U": 10109517030959, "u": 10109517034202, "pu": 10109517030833, "b": [["1000.00", "26.292"], ["5000.00", "101.418"], ["7065.00", "0.000"], ["20349.90", "0.560"], ["20449.90", "2.440"], ["20549.90", "0.000"], ["56520.00", "0.066"], ["69217.30", "7.238"], ["69943.40", "5.718"], ["69954.00", "0.000"], ["70221.50", "37.587"], ["70296.70", "0.239"], ["70327.00", "31.176"], ["70404.50", "26.541"], ["70472.00", "0.002"], ["70576.90", "0.354"], ["70616.40", "0.003"], ["70619.10", "0.357"], ["70638.00", "0.152"], ["70639.30", "0.005"], ["70642.10", "0.000"], ["70642.30", "0.004"], ["70642.90", "0.015"], ["70643.60", "0.013"], ["70644.40", "0.001"], ["70646.80", "0.003"], ["70648.10", "0.011"], ["70648.70", "0.002"]], "a": [["70650.00", "6.827"], ["70650.30", "0.033"], ["70650.40", "0.104"], ["70650.70", "0.002"], ["70652.40", "0.008"], ["70657.00", "0.004"], ["70658.80", "0.004"], ["70659.10", "0.893"], ["70660.60", "0.045"], ["70663.60", "0.514"], ["70673.80", "0.356"], ["70677.80", "0.010"], ["70892.70", "27.648"], ["70970.70", "32.774"], ["71021.40", "0.007"], ["71077.10", "40.123"], ["71356.40", "0.011"], ["71356.50", "4.304"], ["74192.00", "0.057"], ["89523.20", "0.006"]]}}
{"local_ts": 1773486653611, "server_ts": 1773486653568, "data": {"e": "depthUpdate", "E": 1773486653571, "T": 1773486653568, "s": "BTCUSDT", "U": 10109517067900, "u": 10109517070882, "pu": 10109517067881, "b": [["5000.00", "101.418"], ["7065.00", "0.000"], ["20249.90", "0.280"], ["20349.90", "2.550"], ["20449.90", "0.170"], ["33000.00", "3.789"], ["56520.00", "0.066"], ["67108.90", "0.002"], ["67117.00", "0.173"], ["68861.60", "2.609"], ["69855.10", "0.002"], ["69943.40", "5.718"], ["69943.50", "0.007"], ["70300.10", "0.504"], ["70466.20", "0.159"], ["70478.60", "0.000"], ["70517.50", "1.446"], ["70576.80", "0.499"], ["70576.90", "0.000"], ["70598.50", "0.097"], ["70598.60", "0.002"], ["70602.50", "0.520"], ["70602.70", "0.009"], ["70603.50", "0.011"], ["70612.40", "0.004"], ["70619.10", "0.173"], ["70639.30", "0.005"], ["70640.70", "0.370"], ["70642.40", "0.245"], ["70642.50", "0.007"], ["70643.90", "0.008"], ["70649.90", "4.805"]], "a": [["70650.00", "6.814"], ["70660.60", "0.045"], ["70662.00", "0.421"], ["70687.40", "0.085"], ["70687.60", "0.002"], ["70782.20", "0.000"], ["70821.20", "0.017"], ["71215.20", "1.262"], ["71356.50", "4.198"], ["74214.90", "0.000"], ["89523.20", "0.006"]]}}
{"local_ts": 1773486654620, "server_ts": 1773486654590, "data": {"e": "depthUpdate", "E": 1773486654591, "T": 1773486654590, "s": "BTCUSDT", "U": 10109517100630, "u": 10109517105558, "pu": 10109517100606, "b": [["5000.00", "101.438"], ["7065.00", "0.000"], ["20149.90", "0.130"], ["20249.90", "2.400"], ["20349.90", "0.470"], ["56520.00", "0.066"], ["67105.20", "0.048"], ["67117.40", "0.006"], ["69570.90", "0.452"], ["69731.50", "2.579"], ["69943.40", "7.146"], ["70296.60", "0.075"], ["70296.70", "0.239"], ["70517.50", "2.129"], ["70576.80", "0.315"], ["70609.50", "0.058"], ["70619.20", "0.199"], ["70640.10", "0.005"], ["70640.70", "0.370"], ["70641.00", "0.004"], ["70642.50", "0.007"], ["70643.60", "0.003"], ["70648.50", "0.000"], ["70649.90", "4.781"]], "a": [["70650.00", "6.826"], ["70650.30", "0.033"], ["70650.40", "0.112"], ["70651.90", "0.024"], ["70658.80", "0.004"], ["70674.00", "0.011"], ["70782.10", "0.507"], ["71356.50", "4.198"], ["89523.20", "0.006"]]}}
{"local_ts": 1773486655642, "server_ts": 1773486655612, "data": {"e": "depthUpdate", "E": 1773486655613, "T": 1773486655612, "s": "BTCUSDT", "U": 10109517286550, "u": 10109517306572, "pu": 10109517286407, "b": [["1000.00", "26.292"], ["5000.00", "101.418"], ["7063.50", "0.056"], ["7063.90", "0.000"], ["20135.00", "0.370"], ["20249.90", "0.790"], ["56520.00", "0.066"], ["69664.20", "0.002"], ["69928.60", "0.000"], ["70281.80", "0.000"], ["70314.50", "0.000"], ["70422.30", "10.000"], ["70438.30", "0.053"], ["70438.70", "0.075"], ["70461.50", "0.268"], ["70468.90", "10.000"], ["70472.00", "0.002"], ["70475.50", "0.188"], ["70476.90", "0.005"], ["70479.20", "2.187"], ["70492.00", "0.001"], ["70514.70", "0.010"], ["70517.10", "0.005"], ["70521.50", "0.963"], ["70528.50", "0.072"], ["70530.80", "0.108"], ["70530.90", "0.114"], ["70531.60", "0.967"], ["70533.80", "0.000"], ["70536.30", "0.036"], ["70537.70", "0.145"], ["70539.70", "0.294"], ["70540.00", "0.145"], ["70540.40", "0.117"], ["70540.80", "0.142"], ["70541.10", "0.050"], ["70541.40", "0.004"], ["70550.00", "0.434"], ["70555.10", "0.000"], ["70556.80", "0.840"], ["70567.40", "0.052"], ["70567.80", "0.718"], ["70568.00", "0.000"], ["70569.20", "1.058"], ["70572.80", "0.026"], ["70575.00", "0.212"], ["70582.70", "0.503"], ["70583.80", "0.002"], ["70584.50", "0.004"], ["70584.60", "0.130"], ["70585.30", "0.439"], ["70586.80", "0.028"], ["70587.10", "0.023"], ["70587.70", "1.145"], ["70587.80", "0.586"], ["70588.10", "0.110"], ["70588.40", "0.278"], ["70589.10", "0.005"], ["70590.00", "0.007"], ["70590.20", "0.000"], ["70591.60", "0.013"], ["70592.10", "0.000"], ["70593.80", "0.129"], ["70595.20", "0.009"], ["70595.70", "1.111"], ["70599.70", "2.959"], ["70600.90", "0.028"], ["70603.30", "0.021"], ["70604.50", "0.012"], ["70604.70", "1.181"], ["70604.80", "0.259"], ["70605.00", "0.104"], ["70605.30", "0.007"], ["70605.40", "0.002"], ["70605.50", "0.006"], ["70606.20", "0.002"], ["70606.70", "0.082"], ["70607.60", "0.674"], ["70611.40", "0.028"], ["70613.20", "0.132"], ["70613.80", "0.362"], ["70614.80", "0.000"], ["70615.40", "0.059"], ["70615.90", "0.008"], ["70616.70", "0.002"], ["70617.70", "0.004"], ["70618.10", "0.199"], ["70618.90", "0.149"], ["70619.10", "0.560"], ["70619.20", "0.027"], ["70619.80", "0.031"], ["70620.70", "0.116"], ["70621.20", "0.024"], ["70621.80", "0.000"], ["70622.20", "0.002"], ["70622.50", "0.224"], ["70622.80", "0.398"], ["70622.90", "0.537"], ["70623.20", "0.078"], ["70624.40", "0.010"], ["70624.50", "0.459"], ["70624.80", "1.069"], ["70625.70", "0.006"], ["70626.40", "0.392"], ["70627.10", "0.004"], ["70627.50", "0.702"], ["70628.10", "0.217"], ["70628.20", "0.082"], ["70628.80", "0.000"], ["70628.90", "0.000"], ["70629.20", "0.005"], ["70630.90", "0.094"], ["70631.60", "0.001"], ["70631.90", "0.033"], ["70632.30", "0.258"], ["70632.40", "0.002"], ["70632.60", "0.005"], ["70632.70", "0.001"], ["70633.50", "0.004"], ["70633.90", "0.003"], ["70634.30", "0.110"], ["70635.00", "0.132"]], "a": [["70635.10", "13.435"], ["70635.20", "0.162"], ["70636.10", "0.009"], ["70636.40", "0.000"], ["70638.20", "0.115"], ["70638.40", "0.258"], ["70638.60", "0.044"], ["70639.60", "0.003"], ["70640.00", "0.057"], ["70640.10", "0.075"], ["70640.80", "0.003"], ["70641.00", "0.003"], ["70641.10", "0.001"], ["70641.20", "0.000"], ["70641.50", "0.000"], ["70641.70", "0.003"], ["70642.20", "0.004"], ["70642.30", "0.000"], ["70642.40", "0.002"], ["70642.60", "0.003"], ["70643.50", "0.071"], ["70643.90", "0.111"], ["70644.00", "0.006"], ["70644.10", "0.003"], ["70645.70", "0.121"], ["70646.40", "0.083"], ["70646.90", "0.012"], ["70647.10", "0.514"], ["70647.40", "0.002"], ["70647.50", "0.299"], ["70647.70", "0.027"], ["70648.70", "0.038"], ["70649.00", "0.041"], ["70649.20", "1.388"], ["70649.30", "0.187"], ["70649.70", "0.166"], ["70650.00", "25.744"], ["70650.10", "0.007"], ["70650.70", "0.002"], ["70651.00", "0.008"], ["70651.50", "0.008"], ["70651.60", "0.133"], ["70651.70", "0.037"], ["70652.20", "0.147"], ["70655.40", "0.006"], ["70655.60", "0.006"], ["70658.10", "0.007"], ["70658.30", "0.000"], ["70658.60", "0.028"], ["70659.70", "0.100"], ["70659.90", "0.010"], ["70660.00", "0.143"], ["70660.90", "0.012"], ["70661.50", "0.419"], ["70662.60", "0.038"], ["70662.90", "0.260"], ["70663.00", "0.085"], ["70664.30", "0.026"], ["70666.60", "0.112"], ["70667.40", "0.758"], ["70669.70", "0.216"], ["70669.80", "0.555"], ["70671.50", "0.257"], ["70671.60", "0.071"], ["70671.90", "0.511"], ["70674.00", "0.009"], ["70679.10", "0.540"], ["70680.80", "0.090"], ["70682.70", "0.015"], ["70685.00", "0.034"], ["70685.70", "0.537"], ["70686.40", "0.002"], ["70687.10", "0.038"], ["70688.00", "1.351"], ["70688.60", "0.105"], ["70692.50", "0.000"], ["70695.10", "0.010"], ["70695.90", "0.103"], ["70697.70", "0.002"], ["70701.50", "0.057"], ["70702.80", "0.000"], ["70705.00", "0.169"], ["70706.20", "0.005"], ["70707.50", "0.190"], ["70708.20", "0.027"], ["70708.50", "0.126"], ["70709.20", "0.181"], ["70711.30", "0.043"], ["70715.60", "0.000"], ["70722.60", "0.000"], ["70723.40", "0.017"], ["70723.80", "0.241"], ["70724.70", "4.546"], ["70725.50", "0.193"], ["70729.80", "0.000"], ["70731.30", "0.052"], ["70737.90", "0.345"], ["70738.20", "0.210"], ["70750.30", "0.000"], ["70766.40", "0.000"], ["70766.70", "0.005"], ["70769.50", "0.000"], ["70769.80", "0.000"], ["70773.60", "0.151"], ["70775.80", "0.008"], ["70792.30", "0.094"], ["70854.70", "0.009"], ["70887.90", "0.000"], ["70931.00", "0.128"], ["70936.70", "0.283"], ["70986.50", "0.007"], ["70991.70", "0.004"], ["71341.50", "0.000"], ["71347.00", "0.000"], ["71411.20", "0.002"], ["73460.50", "0.002"], ["74173.70", "0.057"], ["89523.20", "0.006"]]}}
{"local_ts": 1773486656663, "server_ts": 1773486656632, "data": {"e": "depthUpdate", "E": 1773486656633, "T": 1773486656632, "s": "BTCUSDT", "U": 10109517381035, "u": 10109517387619, "pu": 10109517380879, "b": [["5000.00", "101.418"], ["7063.50", "0.056"], ["20136.60", "0.000"], ["20137.20", "0.000"], ["20138.00", "0.000"], ["20138.50", "0.000"], ["20139.40", "0.000"], ["20139.60", "0.000"], ["20140.00", "0.000"], ["20140.30", "0.000"], ["20140.60", "0.000"], ["20534.30", "1.450"], ["56507.00", "0.005"], ["68861.60", "0.000"], ["69716.10", "2.145"], ["69928.00", "0.076"], ["69975.90", "0.018"], ["70305.50", "0.031"], ["70501.90", "0.707"], ["70508.40", "0.092"], ["70514.70", "0.000"], ["70517.50", "1.446"], ["70541.80", "0.067"], ["70543.70", "0.022"], ["70548.10", "0.108"], ["70548.70", "0.650"], ["70549.40", "1.349"], ["70550.00", "0.417"], ["70573.60", "0.089"], ["70573.70", "10.238"], ["70576.60", "0.280"], ["70579.00", "0.014"], ["70579.60", "0.088"], ["70580.90", "0.002"], ["70582.20", "0.042"], ["70582.70", "0.503"], ["70582.80", "0.195"], ["70585.30", "0.328"], ["70593.40", "1.324"], ["70599.60", "0.026"], ["70599.70", "2.960"], ["70602.30", "0.000"], ["70606.20", "0.009"], ["70607.20", "1.353"], ["70612.00", "0.002"], ["70613.00", "0.015"], ["70613.20", "0.139"], ["70613.30", "0.010"], ["70614.10", "0.000"], ["70614.40", "0.236"], ["70616.10", "0.000"], ["70618.00", "0.004"], ["70618.30", "0.000"], ["70618.40", "0.147"], ["70619.10", "0.195"], ["70619.40", "0.518"], ["70619.50", "0.034"], ["70623.70", "0.009"], ["70625.70", "0.003"], ["70626.50", "0.008"], ["70626.60", "0.005"], ["70627.30", "0.035"], ["70628.90", "0.003"], ["70630.00", "0.139"], ["70630.10", "0.006"], ["70631.50", "0.001"], ["70632.90", "0.002"]], "a": [["70634.40", "13.988"], ["70634.50", "0.059"], ["70635.10", "0.335"], ["70635.20", "0.090"], ["70636.40", "0.001"], ["70637.40", "0.005"], ["70638.00", "0.031"], ["70638.90", "0.000"], ["70639.40", "0.004"], ["70640.10", "0.005"], ["70640.90", "0.070"], ["70641.40", "0.073"], ["70641.50", "0.454"], ["70642.10", "0.000"], ["70643.50", "0.001"], ["70643.80", "0.026"], ["70644.00", "0.076"], ["70645.00", "0.002"], ["70646.50", "0.062"], ["70648.50", "0.498"], ["70649.10", "0.112"], ["70649.30", "0.003"], ["70649.60", "0.002"], ["70651.20", "0.360"], ["70654.00", "0.085"], ["70654.20", "0.004"], ["70654.80", "0.003"], ["70659.50", "0.015"], ["70659.90", "0.008"], ["70660.90", "0.082"], ["70662.40", "0.005"], ["70665.20", "0.180"], ["70672.10", "1.804"], ["70673.20", "0.045"], ["70676.10", "0.000"], ["70676.20", "0.051"], ["70676.70", "0.054"], ["70678.10", "0.009"], ["70678.30", "0.000"], ["70680.00", "2.735"], ["70681.30", "0.085"], ["70684.20", "0.204"], ["70689.60", "0.003"], ["70695.90", "0.093"], ["70721.30", "0.102"], ["70725.00", "0.052"], ["70725.70", "0.009"], ["70731.30", "0.049"], ["70760.40", "0.050"], ["70766.70", "0.002"], ["70768.40", "0.427"], ["70782.10", "0.042"], ["70796.90", "0.099"], ["70858.30", "0.007"], ["71340.70", "0.000"], ["71553.10", "0.564"], ["71591.60", "0.693"], ["71767.30", "1.192"], ["74185.40", "0.002"], ["74185.50", "0.050"], ["76954.30", "0.002"], ["89523.20", "0.006"]]}}
{"local_ts": 1773486657683, "server_ts": 1773486657652, "data": {"e": "depthUpdate", "E": 1773486657653, "T": 1773486657652, "s": "BTCUSDT", "U": 10109517429844, "u": 10109517433369, "pu": 10109517429778, "b": [["1000.00", "26.292"], ["5000.00", "101.418"], ["7063.50", "0.056"], ["20434.30", "1.320"], ["20534.30", "1.680"], ["67102.50", "0.030"], ["69310.20", "0.018"], ["69680.70", "0.286"], ["69928.00", "0.074"], ["70281.10", "0.000"], ["70463.00", "2.328"], ["70501.80", "0.629"], ["70582.80", "0.549"], ["70582.90", "0.252"], ["70623.70", "0.006"], ["70627.60", "0.011"], ["70630.10", "0.006"], ["70631.50", "0.001"], ["70631.90", "0.027"]], "a": [["70634.40", "13.184"], ["70638.00", "0.003"], ["70638.40", "0.026"], ["70639.40", "0.073"], ["70641.50", "0.454"], ["70645.00", "0.002"], ["70650.00", "25.699"], ["70694.40", "0.065"], ["70701.50", "0.050"], ["70710.10", "0.002"], ["70768.20", "0.549"], ["70807.10", "1.088"], ["71340.60", "0.032"], ["71340.70", "0.000"], ["72290.60", "0.007"], ["74171.70", "0.002"], ["75239.60", "0.000"], ["89523.20", "0.006"]]}}
{"local_ts": 1773486658707, "server_ts": 1773486658676, "data": {"e": "depthUpdate", "E": 1773486658677, "T": 1773486658676, "s": "BTCUSDT", "U": 10109517476939, "u": 10109517482808, "pu": 10109517476779, "b": [["5000.00", "101.418"], ["7063.50", "0.028"], ["20334.30", "0.880"], ["20434.30", "2.120"], ["33000.00", "3.785"], ["67068.40", "0.000"], ["67090.60", "0.002"], ["69539.50", "0.360"], ["69928.00", "0.074"], ["70281.10", "0.106"], ["70516.40", "0.000"], ["70521.40", "2.602"], ["70567.00", "0.520"], ["70582.70", "0.687"], ["70582.80", "0.379"], ["70582.90", "0.068"], ["70585.00", "0.514"], ["70585.30", "0.273"], ["70585.50", "0.003"], ["70585.70", "0.070"], ["70588.50", "0.296"], ["70589.20", "0.997"], ["70598.30", "0.042"], ["70599.10", "0.201"], ["70600.20", "0.153"], ["70603.60", "1.117"], ["70604.90", "0.000"], ["70606.90", "0.021"], ["70614.40", "0.507"], ["70615.60", "0.069"], ["70616.30", "0.267"], ["70617.00", "0.637"], ["70617.10", "0.007"], ["70617.50", "0.053"], ["70618.00", "0.344"], ["70618.10", "0.200"], ["70619.20", "0.201"], ["70620.10", "0.005"], ["70620.30", "0.007"], ["70621.60", "0.057"], ["70623.40", "0.001"], ["70623.70", "0.009"], ["70625.10", "0.002"], ["70625.20", "0.000"], ["70625.50", "0.158"], ["70625.60", "0.005"], ["70625.90", "0.509"], ["70627.20", "0.000"], ["70629.80", "0.008"], ["70630.20", "0.024"], ["70632.30", "0.002"], ["70632.40", "0.002"], ["70634.20", "0.002"], ["70634.30", "0.727"]], "a": [["70634.40", "13.621"], ["70635.10", "0.256"], ["70636.10", "0.031"], ["70636.40", "0.003"], ["70637.80", "0.031"], ["70638.00", "0.007"], ["70639.40", "0.004"], ["70640.40", "0.007"], ["70640.90", "0.000"], ["70641.30", "0.025"], ["70641.60", "0.135"], ["70641.90", "0.160"], ["70643.40", "0.009"], ["70644.00", "0.006"], ["70644.10", "0.462"], ["70644.50", "0.147"], ["70645.00", "0.002"], ["70645.70", "0.006"], ["70647.70", "0.003"], ["70648.70", "0.003"], ["70649.10", "0.040"], ["70651.60", "0.097"], ["70651.70", "0.046"], ["70655.60", "0.117"], ["70660.10", "0.006"], ["70660.40", "0.252"], ["70662.30", "0.075"], ["70670.20", "0.002"], ["70680.20", "0.085"], ["70681.80", "0.104"], ["70682.60", "0.086"], ["70689.80", "0.517"], ["70692.10", "0.005"], ["70697.60", "0.004"], ["70700.20", "0.039"], ["70722.80", "0.145"], ["70736.90", "0.035"], ["70765.70", "12.449"], ["70766.10", "23.090"], ["70769.30", "0.092"], ["70773.90", "0.000"], ["70775.30", "0.000"], ["70801.80", "1.768"], ["70803.10", "10.000"], ["70826.20", "0.242"], ["70826.40", "0.002"], ["70888.70", "0.000"], ["70913.20", "0.144"], ["71340.70", "0.000"], ["71497.80", "4.047"], ["71521.70", "2.099"], ["71713.80", "0.418"], ["71726.90", "1.819"], ["89523.20", "0.006"]]}}
{"local_ts": 1773486659728, "server_ts": 1773486659697, "data": {"e": "depthUpdate", "E": 1773486659699, "T": 1773486659697, "s": "BTCUSDT", "U": 10109517532732, "u": 10109517538579, "pu": 10109517532580, "b": [["1000.00", "26.292"], ["5000.00", "101.418"], ["7063.50", "0.028"], ["20234.30", "0.440"], ["20334.30", "2.550"], ["20434.30", "0.010"], ["67097.50", "0.000"], ["67117.40", "0.000"], ["67117.50", "0.006"], ["69928.00", "0.074"], ["70084.70", "5.484"], ["70100.10", "0.499"], ["70222.10", "18.612"], ["70281.10", "0.000"], ["70302.30", "0.327"], ["70309.60", "0.648"], ["70539.40", "0.014"], ["70543.20", "0.075"], ["70577.70", "0.368"], ["70582.80", "0.181"], ["70593.30", "0.004"], ["70624.70", "0.021"], ["70627.30", "0.005"], ["70627.40", "0.001"], ["70634.30", "0.730"]], "a": [["70634.40", "12.028"], ["70636.20", "0.070"], ["70637.80", "0.003"], ["70639.60", "0.150"], ["70641.40", "0.001"], ["70641.50", "0.454"], ["70648.90", "0.002"], ["70672.40", "0.638"], ["70673.70", "0.111"], ["70721.30", "0.102"], ["70726.20", "0.251"], ["70858.70", "0.004"], ["70948.30", "0.010"], ["70950.60", "0.648"], ["70999.90", "16.302"], ["71059.80", "6.755"], ["71215.10", "0.477"], ["71340.70", "0.000"], ["71605.70", "0.000"], ["75225.50", "0.050"], ["89523.20", "0.006"]]}}
{"local_ts": 1773486660750, "server_ts": 1773486660718, "data": {"e": "depthUpdate", "E": 1773486660721, "T": 1773486660718, "s": "BTCUSDT", "U": 10109517609303, "u": 10109517616981, "pu": 10109517608882, "b": [["1000.00", "26.292"], ["5000.00", "101.398"], ["7063.50", "0.028"], ["20134.30", "0.230"], ["20234.30", "2.520"], ["20334.30", "0.250"], ["56508.00", "0.000"], ["69627.00", "0.393"], ["69708.70", "65.589"], ["69928.00", "0.081"], ["70577.70", "0.000"], ["70593.00", "0.000"], ["70593.10", "0.127"], ["70593.40", "1.326"], ["70599.60", "0.024"], ["70610.10", "0.000"], ["70612.80", "1.313"], ["70613.00", "0.017"], ["70613.30", "0.194"], ["70616.60", "0.361"], ["70616.70", "0.015"], ["70622.20", "0.002"], ["70624.60", "1.150"], ["70624.80", "1.071"], ["70624.90", "0.006"], ["70627.40", "0.001"], ["70632.40", "0.017"], ["70633.90", "0.019"], ["70634.10", "0.235"], ["70634.30", "3.502"]], "a": [["70634.40", "9.180"], ["70634.50", "0.061"], ["70635.60", "0.002"], ["70635.80", "0.015"], ["70637.60", "0.010"], ["70637.80", "0.031"], ["70640.60", "0.275"], ["70641.50", "0.454"], ["70648.60", "0.004"], ["70651.20", "0.358"], ["70651.70", "0.048"], ["70655.60", "0.119"], ["70658.40", "0.003"], ["70658.60", "0.002"], ["70659.40", "0.009"], ["70659.80", "0.509"], ["70660.00", "0.673"], ["70662.20", "0.000"], ["70662.30", "0.003"], ["70662.50", "0.046"], ["70662.90", "0.015"], ["70663.00", "0.017"], ["70664.50", "0.278"], ["70670.00", "0.274"], ["70672.40", "0.636"], ["70678.50", "0.012"], ["70682.10", "0.002"], ["70682.20", "0.092"], ["70685.60", "1.540"], ["70692.30", "0.025"], ["70693.50", "0.006"], ["70698.60", "0.886"], ["70858.80", "1.041"], ["71340.60", "0.039"], ["71340.70", "0.700"], ["71352.10", "57.978"], ["71566.20", "70.195"], ["74166.90", "0.002"], ["74186.90", "0.000"]]}}
{"local_ts": 1773486661773, "server_ts": 1773486661740, "data": {"e": "depthUpdate", "E": 1773486661741, "T": 1773486661740, "s": "BTCUSDT", "U": 10109517669745, "u": 10109517674821, "pu": 10109517669610, "b": [["5000.00", "101.418"], ["7063.50", "0.000"], ["20134.30", "2.370"], ["20234.30", "0.550"], ["20534.30", "0.080"], ["67567.70", "0.024"], ["67598.40", "0.026"], ["67599.90", "0.022"], ["67613.40", "0.004"], ["67664.70", "0.008"], ["67683.90", "0.032"], ["67713.10", "0.006"], ["67715.60", "0.004"], ["67730.70", "0.034"], ["67745.00", "0.058"], ["67747.20", "0.032"], ["67795.30", "0.008"], ["67799.10", "0.006"], ["67812.40", "1.272"], ["69438.20", "0.009"], ["69610.10", "5.881"], ["69625.50", "30.649"], ["69786.70", "1.705"], ["69928.00", "2.223"], ["70069.20", "0.142"], ["70188.20", "1.606"], ["70549.60", "1.041"], ["70586.90", "0.003"], ["70587.00", "0.027"], ["70620.20", "0.280"], ["70627.30", "0.048"], ["70631.80", "0.007"], ["70634.30", "3.349"]], "a": [["70636.00", "0.002"], ["70637.80", "0.021"], ["70637.90", "0.015"], ["70638.20", "0.124"], ["70641.10", "0.022"], ["70641.40", "0.724"], ["70667.00", "0.003"], ["71340.70", "0.700"], ["71637.40", "0.291"], ["71780.40", "7.371"], ["73202.40", "0.015"], ["73235.10", "0.234"], ["73245.20", "0.020"], ["73249.30", "0.006"], ["73298.10", "0.016"], ["73309.40", "0.008"], ["73324.20", "0.021"], ["73355.80", "0.010"], ["73367.20", "0.016"], ["73382.30", "0.020"], ["73387.00", "0.006"], ["73389.00", "0.014"], ["73390.50", "0.070"], ["73393.50", "0.028"], ["73398.80", "0.016"], ["73444.90", "0.995"], ["73449.00", "0.008"], ["73457.20", "0.006"], ["73873.70", "0.002"], ["74182.20", "0.000"]]}}
{"local_ts": 1773486662790, "server_ts": 1773486662760, "data": {"e": "depthUpdate", "E": 1773486662761, "T": 1773486662760, "s": "BTCUSDT", "U": 10109517738568, "u": 10109517744643, "pu": 10109517738441, "b": [["1000.00", "26.292"], ["5000.00", "101.418"], ["7063.50", "0.000"], ["20134.30", "0.910"], ["20534.30", "2.090"], ["33000.00", "3.789"], ["67074.60", "0.002"], ["67102.60", "0.004"], ["67102.70", "0.002"], ["69539.50", "4.380"], ["69587.00", "0.015"], ["69610.10", "11.905"], ["69611.60", "2.347"], ["70281.10", "0.106"], ["70579.10", "8.499"], ["70581.90", "0.823"], ["70586.60", "0.225"], ["70586.90", "0.003"], ["70593.70", "0.085"], ["70594.40", "0.000"], ["70599.00", "0.113"], ["70616.60", "0.025"]], "a": [["70637.40", "0.008"], ["70669.70", "0.596"], ["70682.80", "0.087"], ["70683.40", "7.887"], ["70858.50", "0.000"], ["71185.00", "0.008"], ["71340.60", "0.039"], ["71340.70", "0.700"], ["71352.10", "0.002"], ["71729.20", "3.689"]]}}
{"local_ts": 1773486663812, "server_ts": 1773486663780, "data": {"e": "depthUpdate", "E": 1773486663783, "T": 1773486663780, "s": "BTCUSDT", "U": 10109517807291, "u": 10109517813608, "pu": 10109517807077, "b": [["5000.00", "101.418"], ["7063.50", "0.000"], ["20434.30", "1.640"], ["20534.30", "1.360"], ["67096.00", "0.002"], ["67102.00", "0.000"], ["69707.30", "68.252"], ["69864.40", "2.142"], ["69917.10", "55.976"], ["69928.00", "2.223"], ["70079.70", "47.148"], ["70100.10", "0.499"], ["70222.10", "18.612"], ["70311.60", "2.928"], ["70467.10", "0.094"], ["70471.90", "0.102"], ["70476.00", "0.861"], ["70477.30", "0.267"], ["70480.20", "0.220"], ["70484.20", "0.094"], ["70486.50", "0.994"], ["70487.60", "0.098"], ["70489.90", "0.094"], ["70501.80", "0.008"], ["70583.10", "0.180"], ["70593.10", "0.040"], ["70595.50", "0.152"], ["70595.60", "0.282"], ["70599.00", "0.113"], ["70599.40", "0.002"], ["70604.80", "0.003"], ["70606.50", "0.362"], ["70613.10", "0.245"], ["70623.50", "0.060"], ["70624.30", "0.017"], ["70625.50", "0.189"], ["70627.20", "0.136"], ["70627.40", "0.005"], ["70630.30", "0.028"], ["70631.70", "0.003"], ["70632.30", "0.010"], ["70634.30", "0.379"]], "a": [["70634.40", "8.472"], ["70641.50", "0.461"], ["70657.90", "0.156"], ["70660.70", "0.000"], ["70669.70", "0.596"], ["70684.50", "0.003"], ["70684.60", "0.089"], ["70686.00", "0.047"], ["70767.50", "0.000"], ["70786.90", "0.099"], ["70788.10", "0.144"], ["70793.30", "0.096"], ["70796.50", "0.186"], ["70858.20", "0.000"], ["70876.00", "0.155"], ["70954.00", "0.648"], ["70999.90", "16.302"], ["71059.80", "6.755"], ["71188.40", "45.482"], ["71340.70", "0.700"], ["71352.10", "55.631"], ["71566.20", "67.343"], ["71658.60", "10.587"], ["71729.20", "5.639"], ["74197.90", "0.158"]]}}
{"local_ts": 1773486664832, "server_ts": 1773486664804, "data": {"e": "depthUpdate", "E": 1773486664805, "T": 1773486664804, "s": "BTCUSDT", "U": 10109517860640, "u": 10109517866402, "pu": 10109517860511, "b": [["1000.00", "26.292"], ["5000.00", "101.418"], ["7063.50", "0.056"], ["20334.30", "1.190"], ["20434.30", "1.810"], ["67102.60", "0.012"], ["69358.60", "0.000"], ["69928.00", "2.225"], ["70069.20", "0.142"], ["70281.10", "0.356"], ["70464.80", "0.511"], ["70501.70", "0.685"], ["70581.30", "0.068"], ["70582.70", "0.333"], ["70582.90", "0.238"], ["70586.10", "0.013"], ["70586.30", "0.004"], ["70596.10", "0.553"], ["70596.20", "0.091"], ["70596.30", "0.000"], ["70607.60", "0.686"], ["70608.40", "0.016"], ["70610.00", "0.583"], ["70622.60", "0.021"], ["70622.80", "0.263"], ["70623.00", "0.836"], ["70625.10", "0.017"], ["70625.40", "0.000"], ["70625.60", "0.516"], ["70627.30", "0.033"], ["70627.40", "0.005"], ["70627.50", "0.863"], ["70629.40", "0.057"], ["70631.30", "0.021"], ["70631.50", "0.011"], ["70631.60", "0.003"], ["70633.90", "0.012"], ["70634.30", "1.316"]], "a": [["70634.40", "8.167"], ["70634.70", "0.005"], ["70635.30", "0.000"], ["70641.40", "0.075"], ["70641.50", "0.454"], ["70648.60", "0.004"], ["70658.50", "0.341"], ["70685.20", "0.086"], ["70685.30", "0.100"], ["70686.00", "0.045"], ["70696.10", "0.005"], ["70767.10", "2.184"], ["70858.10", "0.000"], ["70975.20", "3.656"], ["71340.50", "0.023"], ["71340.70", "0.700"], ["74178.20", "0.002"], ["74194.60", "0.000"]]}}
{"local_ts": 1773486665861, "server_ts": 1773486665828, "data": {"e": "depthUpdate", "E": 1773486665829, "T": 1773486665828, "s": "BTCUSDT", "U": 10109517910555, "u": 10109517914034, "pu": 10109517910475, "b": [["1000.00", "26.292"], ["5000.00", "101.418"], ["7063.50", "0.056"], ["20234.30", "0.750"], ["20334.30", "2.250"], ["56508.00", "0.000"], ["67088.10", "0.002"], ["67102.70", "0.002"], ["67874.80", "1.480"], ["69568.70", "0.000"], ["69928.00", "2.223"], ["69928.10", "0.006"], ["70268.90", "0.426"], ["70269.00", "0.257"], ["70387.70", "0.000"], ["70490.60", "0.086"], ["70495.90", "0.088"], ["70501.70", "0.687"], ["70507.80", "0.000"], ["70510.40", "0.184"], ["70586.50", "0.003"], ["70586.60", "0.227"], ["70611.80", "7.829"], ["70624.70", "0.036"], ["70625.30", "0.001"], ["70625.50", "0.189"], ["70627.30", "0.005"], ["70627.40", "0.005"], ["70631.40", "0.002"]], "a": [["70634.40", "7.381"], ["70635.60", "0.303"], ["70638.20", "0.186"], ["70640.50", "0.657"], ["70641.40", "0.026"], ["70641.50", "0.461"], ["70696.10", "0.003"], ["70696.60", "5.191"], ["70767.00", "0.990"], ["70767.10", "2.000"], ["70796.90", "0.159"], ["70858.60", "0.002"], ["70974.90", "0.000"], ["70975.20", "0.703"], ["71340.60", "0.039"], ["71340.70", "0.700"], ["71344.50", "0.015"]]}}
{"local_ts": 1773486666884, "server_ts": 1773486666852, "data": {"e": "depthUpdate", "E": 1773486666853, "T": 1773486666852, "s": "BTCUSDT", "U": 10109517968942, "u": 10109517974313, "pu": 10109517968814, "b": [["5000.00", "101.418"], ["7063.50", "0.056"], ["20134.30", "0.370"], ["20234.30", "2.580"], ["20334.30", "0.050"], ["50000.00", "165.166"], ["63570.90", "0.002"], ["69552.40", "5.828"], ["69623.00", "8.636"], ["69786.70", "1.991"], ["69928.00", "2.223"], ["69928.10", "0.002"], ["70069.20", "0.285"], ["70281.20", "1.292"], ["70387.70", "0.000"], ["70387.80", "0.006"], ["70584.90", "0.140"], ["70586.50", "0.003"], ["70586.70", "0.004"], ["70611.80", "7.830"], ["70613.10", "0.245"], ["70616.60", "0.358"], ["70620.20", "0.141"], ["70620.30", "0.007"], ["70620.70", "0.137"], ["70621.30", "0.000"], ["70623.70", "0.009"], ["70627.20", "0.000"], ["70627.30", "0.048"], ["70627.60", "0.001"], ["70630.50", "0.001"], ["70630.60", "0.004"], ["70631.00", "0.003"], ["70634.30", "2.979"]], "a": [["70634.40", "6.436"], ["70636.70", "0.017"], ["70637.70", "0.004"], ["70641.40", "0.698"], ["70642.20", "0.000"], ["70645.00", "0.004"], ["70696.60", "5.153"], ["70706.90", "0.539"], ["70796.90", "0.159"], ["70881.40", "0.007"], ["70987.20", "0.000"], ["70987.60", "3.278"], ["71340.60", "0.032"], ["71340.70", "0.700"], ["71513.90", "0.000"], ["71726.60", "0.003"], ["74184.10", "0.002"], ["77697.80", "0.002"]]}}
{"local_ts": 1773486667906, "server_ts": 1773486667873, "data": {"e": "depthUpdate", "E": 1773486667875, "T": 1773486667873, "s": "BTCUSDT", "U": 10109518016546, "u": 10109518020045, "pu": 10109518016504, "b": [["1000.00", "26.292"], ["5000.00", "101.418"], ["7063.50", "0.028"], ["20134.30", "2.470"], ["20234.30", "0.330"], ["20534.30", "0.200"], ["33000.00", "3.785"], ["63570.90", "0.002"], ["67093.10", "0.002"], ["67102.60", "0.008"], ["67102.70", "0.004"], ["69928.00", "2.223"], ["70302.30", "0.327"], ["70312.90", "0.106"], ["70462.80", "2.902"], ["70501.70", "0.687"], ["70586.00", "0.009"], ["70586.30", "0.004"], ["70610.60", "0.250"], ["70611.90", "1.724"], ["70613.10", "0.433"], ["70616.10", "0.070"], ["70617.00", "0.070"], ["70618.50", "1.324"], ["70618.90", "0.013"], ["70622.90", "1.089"], ["70623.60", "0.176"], ["70623.70", "0.066"], ["70624.90", "0.006"], ["70626.10", "1.341"], ["70631.40", "0.010"], ["70631.50", "0.003"]], "a": [["70634.40", "7.225"], ["70637.70", "0.002"], ["70641.70", "0.029"], ["70643.50", "0.001"], ["70643.70", "0.002"], ["70645.00", "0.004"], ["70648.60", "0.030"], ["70658.50", "0.977"], ["70660.20", "0.000"], ["70666.20", "1.793"], ["70668.90", "0.071"], ["70669.20", "0.942"], ["70671.80", "0.000"], ["70690.30", "0.021"], ["70706.90", "0.537"], ["70766.80", "0.272"], ["70805.60", "0.951"], ["70858.30", "0.000"], ["71340.60", "0.039"], ["71340.70", "0.700"], ["74175.50", "0.050"], ["77697.80", "0.002"]]}}
{"local_ts": 1773486668929, "server_ts": 1773486668896, "data": {"e": "depthUpdate", "E": 1773486668897, "T": 1773486668896, "s": "BTCUSDT", "U": 10109518064737, "u": 10109518068344, "pu": 10109518064669, "b": [["5000.00", "101.418"], ["7063.50", "0.028"], ["20134.30", "0.630"], ["20434.30", "0.050"], ["20534.30", "2.320"], ["63570.90", "0.002"], ["68849.90", "2.610"], ["69504.20", "5.753"], ["69619.10", "0.000"], ["69631.30", "1.144"], ["70619.40", "0.801"], ["70620.50", "0.341"], ["70623.70", "0.066"]], "a": [["70634.40", "7.270"], ["70641.80", "0.000"], ["70645.00", "0.004"], ["70645.10", "0.145"], ["70858.70", "0.011"], ["70858.80", "0.000"], ["71340.60", "0.032"], ["71340.70", "0.700"], ["74174.70", "0.014"], ["74191.40", "0.000"], ["77697.80", "0.002"]]}}
{"local_ts": 1773486669947, "server_ts": 1773486669915, "data": {"e": "depthUpdate", "E": 1773486669917, "T": 1773486669915, "s": "BTCUSDT", "U": 10109518120135, "u": 10109518126897, "pu": 10109518120118, "b": [["1000.00", "26.292"], ["5000.00", "101.418"], ["7063.50", "0.028"], ["20434.30", "1.970"], ["20534.30", "1.030"], ["33000.00", "3.789"], ["63570.90", "0.002"], ["67081.70", "0.002"], ["68916.90", "1.242"], ["69316.50", "0.000"], ["69928.00", "2.223"], ["69943.40", "4.290"], ["70281.10", "3.765"], ["70556.60", "0.000"], ["70570.70", "0.006"], ["70613.10", "0.242"], ["70615.20", "0.356"], ["70623.70", "0.066"], ["70628.60", "0.016"], ["70631.00", "0.058"], ["70631.50", "0.003"], ["70631.70", "0.018"], ["70633.50", "0.010"], ["70634.10", "0.023"]], "a": [["70634.40", "7.230"], ["70634.50", "0.050"], ["70634.70", "0.020"], ["70636.00", "0.002"], ["70641.80", "0.000"], ["70641.90", "0.019"], ["70645.00", "0.007"], ["70662.70", "0.081"], ["70698.00", "0.018"], ["70712.10", "0.004"], ["70858.70", "0.011"], ["71199.50", "0.282"], ["71340.60", "0.032"], ["71340.70", "0.700"], ["71482.00", "0.865"], ["71648.90", "0.013"], ["74174.70", "0.012"], ["77697.80", "0.002"]]}}
{"local_ts": 1773486670966, "server_ts": 1773486670936, "data": {"e": "depthUpdate", "E": 1773486670937, "T": 1773486670936, "s": "BTCUSDT", "U": 10109518189117, "u": 10109518195058, "pu": 10109518188928, "b": [["1000.00", "26.292"], ["5000.00", "101.438"], ["7063.50", "0.000"], ["20334.30", "1.520"], ["20434.30", "1.480"], ["56507.00", "0.005"], ["63570.90", "0.000"], ["67086.70", "0.000"], ["69557.00", "0.864"], ["69928.00", "2.223"], ["70104.50", "0.802"], ["70464.80", "0.418"], ["70586.70", "0.004"], ["70586.80", "0.028"], ["70599.00", "0.113"], ["70616.20", "0.511"], ["70617.00", "0.070"], ["70631.70", "0.003"]], "a": [["70659.00", "0.160"], ["70669.70", "0.324"], ["70682.30", "0.037"], ["70682.40", "0.087"], ["70758.00", "0.587"], ["70858.10", "0.007"], ["70858.20", "0.000"], ["71164.20", "0.702"], ["71340.60", "0.032"], ["71340.70", "0.910"], ["77697.80", "0.000"], ["89523.20", "0.000"]]}}
{"local_ts": 1773486671987, "server_ts": 1773486671956, "data": {"e": "depthUpdate", "E": 1773486671959, "T": 1773486671956, "s": "BTCUSDT", "U": 10109518232634, "u": 10109518237894, "pu": 10109518232628, "b": [["5000.00", "101.418"], ["7063.50", "0.000"], ["20234.30", "1.080"], ["20334.30", "1.920"], ["33000.00", "3.789"], ["63570.90", "0.000"], ["69928.00", "2.937"], ["70464.80", "0.418"], ["70583.80", "0.541"], ["70584.90", "0.476"], ["70586.60", "0.225"], ["70586.70", "0.004"], ["70593.30", "0.136"], ["70593.40", "1.330"], ["70596.20", "0.003"], ["70597.50", "2.019"], ["70599.00", "0.141"], ["70610.20", "0.000"], ["70613.10", "0.242"], ["70618.30", "0.015"], ["70619.80", "0.033"], ["70620.40", "0.431"], ["70620.70", "0.137"], ["70621.30", "0.000"], ["70623.40", "0.007"], ["70623.70", "0.063"], ["70624.90", "0.006"], ["70625.00", "0.022"], ["70625.90", "0.012"], ["70626.20", "0.514"], ["70626.40", "0.512"], ["70626.90", "0.001"], ["70627.20", "0.000"], ["70629.70", "0.393"], ["70631.00", "0.024"], ["70631.10", "0.003"], ["70631.50", "0.006"], ["70632.20", "0.002"], ["70632.90", "0.002"], ["70634.30", "2.515"]], "a": [["70634.40", "7.333"], ["70634.70", "0.023"], ["70634.80", "0.057"], ["70635.10", "0.240"], ["70635.20", "0.006"], ["70636.60", "0.003"], ["70637.40", "0.008"], ["70639.70", "0.008"], ["70640.20", "0.006"], ["70640.50", "0.005"], ["70642.30", "0.006"], ["70643.40", "0.000"], ["70645.00", "0.007"], ["70648.50", "0.503"], ["70650.40", "1.916"], ["70650.60", "0.000"], ["70658.70", "0.064"], ["70665.30", "0.256"], ["70669.70", "0.367"], ["70672.40", "0.636"], ["70881.50", "0.308"], ["71340.70", "1.610"], ["71402.00", "0.560"], ["71870.50", "1.127"], ["72753.40", "0.006"], ["74177.00", "0.065"], ["77697.80", "0.000"], ["89523.20", "0.000"]]}}
{"local_ts": 1773486673009, "server_ts": 1773486672976, "data": {"e": "depthUpdate", "E": 1773486672979, "T": 1773486672976, "s": "BTCUSDT", "U": 10109518282375, "u": 10109518285241, "pu": 10109518282335, "b": [["1000.00", "26.292"], ["5000.00", "101.398"], ["7063.50", "0.000"], ["20134.30", "0.630"], ["20234.30", "2.370"], ["20334.30", "0.000"], ["56507.00", "0.009"], ["63570.90", "0.000"], ["67069.50", "0.000"], ["69340.60", "0.617"], ["69928.00", "2.937"], ["70501.60", "0.002"], ["70606.00", "0.090"], ["70620.10", "0.055"], ["70620.20", "0.172"], ["70627.80", "0.510"], ["70629.10", "0.004"], ["70631.50", "0.006"]], "a": [["70641.90", "0.019"], ["70668.50", "0.010"], ["70677.80", "0.051"], ["70766.40", "0.000"], ["70766.50", "0.041"], ["70796.90", "0.159"], ["71340.70", "1.610"], ["74195.00", "0.074"], ["77697.80", "0.000"], ["89523.20", "0.000"]]}}
{"local_ts": 1773486674035, "server_ts": 1773486674004, "data": {"e": "depthUpdate", "E": 1773486674005, "T": 1773486674004, "s": "BTCUSDT", "U": 10109518319213, "u": 10109518322234, "pu": 10109518319109, "b": [["5000.00", "101.418"], ["7063.50", "0.056"], ["20134.30", "2.580"], ["20234.30", "0.110"], ["20534.30", "0.310"], ["63570.90", "0.000"], ["67072.70", "0.002"], ["67081.80", "0.002"], ["69539.50", "11.774"], ["69928.00", "2.937"], ["70586.70", "0.002"], ["70586.80", "0.030"], ["70597.50", "2.028"], ["70599.00", "0.162"], ["70625.50", "0.151"], ["70631.50", "0.006"]], "a": [["70642.10", "0.000"], ["70647.00", "0.324"], ["70661.10", "0.163"], ["70669.70", "0.347"], ["70671.40", "2.350"], ["70858.20", "0.007"], ["70993.10", "0.774"], ["71340.70", "1.610"], ["77697.80", "0.000"], ["89523.20", "0.000"]]}}
{"local_ts": 1773486675059, "server_ts": 1773486675024, "data": {"e": "depthUpdate", "E": 1773486675025, "T": 1773486675024, "s": "BTCUSDT", "U": 10109518358909, "u": 10109518362699, "pu": 10109518358807, "b": [["1000.00", "26.292"], ["5000.00", "101.418"], ["7063.50", "0.056"], ["20134.30", "0.410"], ["20434.30", "0.160"], ["20534.30", "2.430"], ["56507.00", "0.009"], ["63570.90", "0.000"], ["67102.00", "0.000"], ["67102.70", "0.010"], ["69234.50", "0.388"], ["69234.60", "0.000"], ["69312.90", "0.379"], ["69313.00", "0.082"], ["69391.40", "0.379"], ["69391.50", "0.000"], ["69469.90", "0.379"], ["69470.00", "0.177"], ["69517.20", "0.616"], ["69548.40", "0.379"], ["69548.50", "0.000"], ["69626.90", "0.379"], ["69627.00", "0.014"], ["69705.40", "0.381"], ["69705.50", "0.000"], ["69783.90", "0.379"], ["69784.00", "0.024"], ["69862.40", "0.379"], ["69862.50", "0.000"], ["69928.00", "2.937"], ["69940.90", "2.027"], ["69941.00", "0.007"], ["70100.10", "3.739"], ["70222.10", "16.020"], ["70281.10", "3.765"], ["70311.60", "2.280"], ["70515.30", "0.009"], ["70561.80", "0.002"], ["70586.80", "0.028"], ["70586.90", "0.003"], ["70614.50", "0.057"], ["70615.30", "1.203"], ["70619.30", "0.012"], ["70619.80", "0.033"], ["70626.40", "0.512"], ["70627.20", "0.197"], ["70627.60", "0.545"], ["70629.70", "0.285"], ["70631.70", "0.003"], ["70634.30", "3.293"]], "a": [["70634.40", "3.863"], ["70637.70", "0.002"], ["70637.90", "0.000"], ["70638.50", "0.011"], ["70638.80", "0.002"], ["70639.00", "0.000"], ["70639.60", "0.150"], ["70640.10", "0.005"], ["70640.40", "0.005"], ["70640.50", "0.064"], ["70646.80", "0.723"], ["70648.50", "0.261"], ["70648.70", "0.005"], ["70649.60", "0.004"], ["70694.40", "0.201"], ["70696.20", "0.445"], ["70698.00", "0.157"], ["70699.40", "0.136"], ["70764.20", "0.176"], ["70858.10", "0.000"], ["70954.00", "0.000"], ["70993.10", "0.704"], ["70999.90", "13.710"], ["71059.80", "9.995"], ["71340.70", "1.610"], ["71354.00", "0.045"], ["71400.00", "11.782"], ["71432.50", "0.000"], ["71511.00", "0.003"], ["71589.50", "0.348"], ["71658.50", "0.843"], ["71668.00", "0.038"], ["71746.50", "0.000"], ["71825.00", "0.014"], ["71903.50", "0.023"], ["71982.00", "0.005"], ["72060.40", "0.276"], ["72351.80", "0.594"], ["74167.40", "0.004"], ["74199.10", "0.000"], ["77697.80", "0.000"], ["89523.20", "0.000"]]}}
{"local_ts": 1773486676074, "server_ts": 1773486676044, "data": {"e": "depthUpdate", "E": 1773486676045, "T": 1773486676044, "s": "BTCUSDT", "U": 10109518411795, "u": 10109518415492, "pu": 10109518411722, "b": [["1000.00", "26.292"], ["5000.00", "101.418"], ["7063.50", "0.056"], ["20434.30", "2.290"], ["20534.30", "0.710"], ["67102.60", "0.006"], ["68515.30", "0.000"], ["69928.00", "2.937"], ["70312.10", "31.021"], ["70449.90", "16.978"], ["70464.20", "0.000"], ["70464.80", "0.418"], ["70501.50", "0.691"], ["70501.60", "0.002"], ["70610.70", "0.052"], ["70612.00", "0.249"], ["70612.90", "0.459"], ["70614.00", "0.061"], ["70614.70", "0.025"], ["70620.10", "0.002"], ["70621.60", "0.004"], ["70630.20", "0.024"], ["70630.60", "0.004"], ["70631.50", "0.006"], ["70632.20", "0.002"], ["70632.30", "0.010"], ["70633.40", "0.001"], ["70634.30", "3.113"]], "a": [["70634.40", "4.422"], ["70636.50", "0.021"], ["70637.00", "0.020"], ["70637.30", "0.002"], ["70638.30", "0.017"], ["70639.50", "0.008"], ["70639.60", "0.165"], ["70640.80", "0.041"], ["70641.10", "0.028"], ["70648.50", "1.582"], ["70653.60", "0.002"], ["70667.30", "0.285"], ["70668.70", "0.003"], ["70690.90", "0.062"], ["70698.60", "0.886"], ["70766.20", "0.452"], ["70766.30", "0.005"], ["70879.30", "26.291"], ["71340.70", "2.030"], ["72753.40", "0.000"], ["74186.40", "0.000"], ["89523.20", "0.000"]]}}
{"local_ts": 1773486677097, "server_ts": 1773486677066, "data": {"e": "depthUpdate", "E": 1773486677067, "T": 1773486677066, "s": "BTCUSDT", "U": 10109518466050, "u": 10109518469332, "pu": 10109518466011, "b": [["5000.00", "101.418"], ["7063.50", "0.028"], ["20334.30", "1.850"], ["20434.30", "1.150"], ["33000.00", "3.785"], ["67089.20", "0.000"], ["68515.30", "0.006"], ["68861.80", "0.007"], ["69928.00", "2.937"], ["70286.60", "0.710"], ["70302.30", "0.221"], ["70501.50", "0.690"], ["70581.10", "1.117"], ["70586.00", "0.179"], ["70588.20", "1.922"], ["70595.10", "0.000"], ["70595.20", "0.097"], ["70595.30", "0.856"], ["70602.40", "0.875"], ["70609.50", "0.854"], ["70614.50", "1.260"], ["70615.30", "0.007"], ["70621.60", "0.000"], ["70631.70", "0.027"]], "a": [["70634.40", "4.809"], ["70652.10", "0.882"], ["70659.20", "1.001"], ["70666.30", "1.681"], ["70673.40", "0.922"], ["70680.50", "0.891"], ["70693.80", "0.576"], ["70696.30", "0.005"], ["70698.00", "8.506"], ["70698.60", "0.886"], ["70766.20", "0.452"], ["70881.60", "0.000"], ["71340.70", "2.030"], ["72753.40", "0.006"], ["89523.20", "0.000"]]}}
{"local_ts": 1773486678115, "server_ts": 1773486678084, "data": {"e": "depthUpdate", "E": 1773486678087, "T": 1773486678084, "s": "BTCUSDT", "U": 10109518503473, "u": 10109518507405, "pu": 10109518503353, "b": [["1000.00", "26.292"], ["5000.00", "101.418"], ["7063.50", "0.028"], ["20234.30", "1.400"], ["20334.30", "1.600"], ["56507.00", "0.009"], ["69928.00", "2.937"], ["70281.20", "1.292"], ["70387.70", "0.004"], ["70499.60", "8.908"], ["70500.10", "2.238"], ["70515.80", "0.018"], ["70517.50", "0.266"], ["70586.00", "0.009"], ["70586.10", "0.003"], ["70619.00", "0.894"], ["70621.60", "0.637"]], "a": [["70765.50", "9.825"], ["70780.70", "1.065"], ["70781.60", "3.870"], ["71340.70", "2.030"], ["71623.30", "1.115"], ["72753.40", "0.006"], ["74167.80", "0.018"], ["89523.20", "0.000"]]}}
{"local_ts": 1773486679138, "server_ts": 1773486679108, "data": {"e": "depthUpdate", "E": 1773486679109, "T": 1773486679108, "s": "BTCUSDT", "U": 10109518541765, "u": 10109518547018, "pu": 10109518541733, "b": [["5000.00", "101.418"], ["7063.50", "0.028"], ["20134.30", "0.960"], ["20234.30", "2.040"], ["33000.00", "3.789"], ["67102.60", "0.010"], ["69556.20", "1.046"], ["69928.00", "2.937"], ["70281.30", "0.004"], ["70387.90", "0.000"], ["70464.80", "0.418"], ["70577.80", "3.694"], ["70581.10", "1.117"], ["70583.10", "0.396"], ["70586.80", "0.032"], ["70588.20", "1.922"], ["70594.90", "1.545"], ["70595.30", "0.856"], ["70602.40", "0.875"], ["70609.50", "0.854"], ["70611.90", "1.865"], ["70613.10", "0.030"], ["70614.10", "0.509"], ["70620.50", "0.341"], ["70621.60", "0.637"], ["70621.90", "0.265"], ["70623.70", "0.203"], ["70627.30", "0.039"], ["70631.70", "0.003"], ["70632.80", "0.036"], ["70633.10", "0.000"], ["70633.20", "0.003"], ["70633.30", "0.000"], ["70633.40", "0.001"], ["70633.50", "0.002"], ["70633.60", "0.002"], ["70633.70", "0.000"], ["70633.80", "0.004"], ["70633.90", "0.004"], ["70634.20", "0.004"]], "a": [["70634.40", "4.344"], ["70635.20", "0.019"], ["70635.90", "0.000"], ["70637.00", "0.020"], ["70637.10", "0.001"], ["70637.40", "0.029"], ["70638.30", "0.017"], ["70641.40", "0.038"], ["70641.90", "0.022"], ["70645.00", "0.178"], ["70651.10", "0.007"], ["70652.10", "0.882"], ["70656.90", "0.002"], ["70657.10", "0.004"], ["70657.70", "0.636"], ["70658.00", "0.529"], ["70659.20", "0.856"], ["70660.90", "0.012"], ["70662.20", "0.070"], ["70664.70", "0.000"], ["70665.70", "0.247"], ["70666.30", "1.681"], ["70673.40", "0.922"], ["70680.50", "0.891"], ["70687.40", "0.000"], ["70878.10", "0.114"], ["70881.60", "0.000"], ["71340.70", "2.030"], ["71482.00", "2.681"], ["71631.30", "0.000"], ["74190.60", "0.000"], ["74199.30", "0.004"], ["89523.20", "0.000"]]}}
{"local_ts": 1773486680161, "server_ts": 1773486680128, "data": {"e": "depthUpdate", "E": 1773486680133, "T": 1773486680128, "s": "BTCUSDT", "U": 10109518583563, "u": 10109518589240, "pu": 10109518583391, "b": [["1000.00", "26.292"], ["5000.00", "101.418"], ["7063.50", "0.028"], ["20134.30", "2.490"], ["20234.30", "0.000"], ["20534.30", "0.510"], ["56508.00", "0.000"], ["67090.50", "0.000"], ["67100.30", "0.000"], ["67102.70", "0.002"], ["69928.00", "2.937"], ["69928.10", "0.006"], ["70281.10", "3.907"], ["70388.00", "1.677"], ["70586.30", "0.004"], ["70586.50", "0.005"], ["70610.40", "0.054"], ["70611.30", "0.000"], ["70620.90", "0.890"], ["70621.60", "0.000"], ["70632.00", "0.010"], ["70633.70", "0.057"]], "a": [["70634.40", "4.345"], ["70634.70", "0.020"], ["70634.80", "0.102"], ["70637.20", "0.032"], ["70638.60", "0.017"], ["70639.90", "0.016"], ["70640.90", "0.027"], ["70641.20", "0.015"], ["70652.30", "0.016"], ["70656.40", "0.002"], ["70656.90", "0.638"], ["70657.70", "0.000"], ["70661.90", "0.046"], ["70663.00", "0.070"], ["70663.50", "0.000"], ["70698.60", "0.286"], ["70878.10", "0.008"], ["71340.70", "2.030"], ["89523.20", "0.000"]]}}
{"local_ts": 1773486681187, "server_ts": 1773486681152, "data": {"e": "depthUpdate", "E": 1773486681155, "T": 1773486681152, "s": "BTCUSDT", "U": 10109518630421, "u": 10109518634996, "pu": 10109518630405, "b": [["1000.00", "26.292"], ["5000.00", "101.418"], ["7063.50", "0.000"], ["20134.30", "0.190"], ["20434.30", "0.260"], ["20534.30", "2.550"], ["56508.00", "0.000"], ["69919.60", "0.000"], ["69928.00", "4.365"], ["70080.80", "0.142"], ["70584.90", "0.171"], ["70585.80", "0.005"], ["70586.00", "0.007"], ["70602.50", "0.711"], ["70607.80", "0.031"], ["70608.30", "0.009"], ["70610.40", "0.054"], ["70620.20", "0.523"], ["70621.90", "0.300"], ["70631.90", "0.013"], ["70632.00", "0.010"], ["70632.20", "0.002"], ["70632.30", "0.002"], ["70632.40", "0.000"], ["70632.50", "0.003"], ["70632.60", "0.006"], ["70632.70", "0.000"], ["70632.80", "0.000"], ["70632.90", "0.002"], ["70633.10", "0.000"], ["70633.20", "0.003"], ["70633.30", "0.000"], ["70633.40", "0.001"], ["70633.50", "0.002"], ["70633.60", "0.002"], ["70633.70", "0.000"], ["70633.80", "0.004"], ["70633.90", "0.004"], ["70634.10", "0.002"], ["70634.20", "0.004"]], "a": [["70634.90", "0.173"], ["70635.00", "0.002"], ["70635.20", "0.025"], ["70655.30", "0.000"], ["70655.70", "0.002"], ["70656.20", "0.636"], ["70657.10", "0.513"], ["70663.50", "0.000"], ["70664.70", "0.247"], ["70672.40", "0.693"], ["70673.60", "0.000"], ["70858.30", "0.000"], ["71191.70", "0.002"], ["71340.50", "0.023"], ["71340.70", "3.430"], ["71355.40", "0.780"], ["71567.70", "0.021"], ["74178.40", "0.000"], ["74179.40", "0.004"]]}}
{"local_ts": 1773486682206, "server_ts": 1773486682172, "data": {"e": "depthUpdate", "E": 1773486682175, "T": 1773486682172, "s": "BTCUSDT", "U": 10109518684384, "u": 10109518692104, "pu": 10109518684369, "b": [["5000.00", "101.418"], ["7063.50", "0.000"], ["20334.30", "0.110"], ["20434.30", "2.400"], ["20534.30", "0.490"], ["67071.50", "0.002"], ["69928.00", "4.365"], ["70100.10", "0.499"], ["70222.10", "18.612"], ["70311.10", "6.019"], ["70560.60", "0.052"], ["70569.50", "0.086"], ["70586.10", "0.005"], ["70586.50", "0.003"], ["70600.70", "0.870"], ["70606.50", "0.362"], ["70607.70", "0.146"], ["70610.20", "0.509"], ["70611.50", "0.003"], ["70615.80", "0.169"], ["70618.60", "1.549"], ["70619.20", "0.077"], ["70620.20", "0.459"], ["70627.10", "0.005"], ["70627.20", "0.154"], ["70627.40", "0.005"], ["70628.50", "0.019"], ["70628.80", "0.003"], ["70629.20", "0.008"], ["70632.00", "0.010"]], "a": [["70634.40", "4.332"], ["70634.70", "0.028"], ["70635.40", "0.019"], ["70641.50", "0.007"], ["70654.20", "0.024"], ["70654.30", "0.511"], ["70654.40", "1.719"], ["70657.10", "0.004"], ["70659.10", "0.083"], ["70661.10", "0.007"], ["70661.40", "0.789"], ["70661.60", "0.007"], ["70663.50", "0.247"], ["70664.70", "0.052"], ["70667.20", "0.038"], ["70956.50", "6.616"], ["70999.90", "16.302"], ["71059.80", "6.755"], ["71190.90", "48.134"], ["71340.70", "3.430"], ["71928.10", "0.595"], ["72047.00", "0.009"]]}}
{"local_ts": 1773486683233, "server_ts": 1773486683196, "data": {"e": "depthUpdate", "E": 1773486683199, "T": 1773486683196, "s": "BTCUSDT", "U": 10109518733960, "u": 10109518737933, "pu": 10109518733914, "b": [["1000.00", "26.292"], ["5000.00", "101.418"], ["7063.50", "0.000"], ["20334.30", "2.180"], ["20434.30", "0.820"], ["67075.70", "0.000"], ["67096.50", "0.000"], ["67102.60", "0.010"], ["69928.00", "4.365"], ["70462.70", "0.000"], ["70501.50", "0.000"], ["70559.70", "0.104"], ["70591.10", "0.005"], ["70591.40", "0.002"], ["70595.50", "0.067"], ["70595.70", "1.199"], ["70598.40", "0.175"], ["70599.40", "0.127"], ["70599.80", "0.050"], ["70600.30", "0.088"], ["70600.90", "0.170"], ["70607.80", "0.198"], ["70618.90", "0.013"], ["70620.20", "0.156"], ["70620.60", "0.004"], ["70621.90", "0.161"], ["70623.70", "0.275"], ["70623.80", "0.005"], ["70626.50", "0.518"], ["70627.40", "0.007"], ["70627.60", "0.028"], ["70631.40", "0.010"], ["70634.00", "0.015"], ["70634.20", "0.062"]], "a": [["70634.40", "4.479"], ["70635.60", "0.002"], ["70637.00", "0.005"], ["70638.10", "0.003"], ["70638.40", "0.006"], ["70638.70", "0.010"], ["70639.60", "0.150"], ["70639.90", "0.016"], ["70641.50", "0.009"], ["70648.60", "0.945"], ["70649.80", "0.015"], ["70651.10", "1.192"], ["70657.40", "0.010"], ["70658.30", "0.638"], ["70659.50", "0.009"], ["70660.40", "0.014"], ["70661.90", "0.046"], ["70662.90", "0.085"], ["70668.10", "0.000"], ["70669.10", "1.250"], ["70675.90", "1.609"], ["70684.50", "0.088"], ["70684.80", "0.000"], ["70766.00", "0.000"], ["70796.90", "0.159"], ["70804.90", "0.000"], ["70858.20", "0.000"], ["71179.90", "0.709"], ["71340.50", "0.023"], ["71340.70", "4.830"], ["71398.40", "2.676"]]}}
{"local_ts": 1773486684250, "server_ts": 1773486684216, "data": {"e": "depthUpdate", "E": 1773486684219, "T": 1773486684216, "s": "BTCUSDT", "U": 10109518771909, "u": 10109518775730, "pu": 10109518771899, "b": [["5000.00", "101.418"], ["7063.50", "0.056"], ["20234.30", "1.730"], ["20334.30", "1.270"], ["33000.00", "3.785"], ["67076.40", "0.000"], ["69221.70", "0.014"], ["69412.20", "0.002"], ["69928.00", "4.365"], ["70450.70", "0.177"], ["70555.70", "0.953"], ["70587.10", "0.005"], ["70587.20", "0.279"], ["70600.70", "0.178"], ["70602.50", "0.968"], ["70609.60", "0.201"], ["70620.40", "0.435"], ["70620.70", "0.137"], ["70621.20", "0.006"], ["70621.30", "0.101"], ["70621.90", "0.007"], ["70625.50", "0.028"], ["70625.80", "0.018"], ["70626.20", "0.007"], ["70626.60", "0.515"], ["70627.20", "0.015"], ["70627.40", "0.005"], ["70627.60", "0.028"], ["70628.10", "0.015"], ["70628.60", "0.001"], ["70629.00", "0.158"], ["70631.40", "0.010"], ["70631.90", "0.005"]], "a": [["70634.40", "4.408"], ["70637.70", "0.017"], ["70637.90", "0.057"], ["70638.60", "0.017"], ["70641.50", "0.007"], ["70668.00", "0.049"], ["70693.40", "0.009"], ["70693.70", "0.077"], ["70859.00", "2.395"], ["71340.70", "4.830"], ["72435.60", "0.000"], ["72753.40", "0.006"]]}}
{"local_ts": 1773486685267, "server_ts": 1773486685238, "data": {"e": "depthUpdate", "E": 1773486685239, "T": 1773486685238, "s": "BTCUSDT", "U": 10109518810874, "u": 10109518814397, "pu": 10109518810653, "b": [["1000.00", "26.292"], ["5000.00", "101.418"], ["7063.50", "0.056"], ["20134.30", "1.280"], ["20234.30", "1.720"], ["67077.20", "0.002"], ["67102.70", "0.006"], ["69556.20", "1.477"], ["69928.00", "4.365"], ["70281.10", "3.943"], ["70537.80", "0.077"], ["70544.80", "0.003"], ["70551.90", "0.000"], ["70559.70", "0.000"], ["70584.30", "0.000"], ["70600.90", "0.184"], ["70601.60", "0.354"], ["70608.70", "0.017"], ["70610.60", "0.250"], ["70624.10", "0.000"], ["70627.40", "0.005"]], "a": [["70634.40", "4.406"], ["70637.90", "0.000"], ["70638.70", "0.067"], ["70641.50", "0.007"], ["70645.70", "0.006"], ["70680.50", "0.002"], ["70705.10", "0.002"], ["70714.40", "0.029"], ["70721.50", "0.588"], ["70728.50", "0.004"], ["71340.70", "4.830"], ["71647.10", "4.180"]]}}
{"local_ts": 1773486686288, "server_ts": 1773486686258, "data": {"e": "depthUpdate", "E": 1773486686259, "T": 1773486686258, "s": "BTCUSDT", "U": 10109518875386, "u": 10109518882577, "pu": 10109518875172, "b": [["1000.00", "26.292"], ["5000.00", "101.418"], ["7063.50", "0.056"], ["20134.30", "2.170"], ["20534.30", "0.830"], ["33000.00", "3.785"], ["67102.00", "0.000"], ["69221.70", "0.011"], ["69362.90", "0.878"], ["69928.00", "4.365"], ["70484.80", "0.085"], ["70545.20", "0.273"], ["70575.00", "0.256"], ["70581.40", "0.001"], ["70584.10", "0.061"], ["70584.50", "1.199"], ["70586.80", "0.028"], ["70587.40", "0.007"], ["70587.80", "0.003"], ["70588.00", "1.937"], ["70589.40", "0.005"], ["70596.10", "0.618"], ["70596.30", "0.085"], ["70599.00", "0.211"], ["70600.70", "0.178"], ["70602.50", "0.771"], ["70608.30", "0.186"], ["70613.70", "0.076"], ["70615.10", "0.081"], ["70615.60", "0.316"], ["70616.60", "0.032"], ["70618.10", "0.122"], ["70619.70", "0.002"], ["70621.20", "0.003"], ["70622.80", "0.157"], ["70623.90", "0.009"], ["70624.50", "0.020"], ["70624.80", "0.009"], ["70624.90", "0.006"], ["70625.00", "1.547"], ["70625.20", "0.000"], ["70625.50", "0.151"], ["70626.10", "0.003"], ["70626.30", "0.214"], ["70626.70", "0.658"], ["70627.20", "0.015"], ["70627.50", "0.793"], ["70627.60", "0.212"], ["70627.70", "0.865"], ["70628.20", "0.006"], ["70629.70", "0.491"], ["70630.00", "0.139"], ["70630.10", "0.008"], ["70630.90", "0.604"], ["70631.20", "0.001"], ["70631.30", "0.000"], ["70631.60", "0.204"], ["70631.70", "0.003"], ["70633.20", "0.005"]], "a": [["70634.40", "2.460"], ["70635.40", "0.017"], ["70637.10", "0.019"], ["70638.30", "0.005"], ["70640.30", "0.003"], ["70641.40", "0.001"], ["70642.30", "0.060"], ["70642.50", "0.042"], ["70642.60", "0.032"], ["70642.90", "0.000"], ["70645.40", "0.461"], ["70645.50", "0.654"], ["70645.60", "0.046"], ["70646.90", "0.554"], ["70647.20", "0.736"], ["70647.70", "0.144"], ["70649.30", "0.010"], ["70650.00", "3.809"], ["70651.70", "0.065"], ["70652.30", "0.342"], ["70653.00", "1.086"], ["70660.80", "0.202"], ["70660.90", "0.012"], ["70661.50", "0.401"], ["70661.60", "0.007"], ["70662.30", "0.003"], ["70663.00", "0.638"], ["70664.30", "0.002"], ["70664.90", "0.054"], ["70665.70", "0.070"], ["70669.60", "0.002"], ["70669.70", "0.483"], ["70670.60", "0.252"], ["70672.30", "0.005"], ["70673.90", "0.097"], ["70685.20", "0.086"], ["70685.40", "0.098"], ["70700.40", "1.573"], ["70701.20", "0.046"], ["70723.40", "0.019"], ["70858.60", "0.009"], ["71340.70", "4.830"], ["71404.30", "3.910"], ["71870.50", "4.461"], ["73459.70", "0.048"], ["74188.70", "0.002"]]}}
{"local_ts": 1773486687313, "server_ts": 1773486687276, "data": {"e": "depthUpdate", "E": 1773486687279, "T": 1773486687276, "s": "BTCUSDT", "U": 10109518944937, "u": 10109518948937, "pu": 10109518944932, "b": [["5000.00", "101.438"], ["7063.50", "0.028"], ["20134.30", "0.030"], ["20434.30", "0.410"], ["20534.30", "2.560"], ["67072.60", "0.000"], ["69680.70", "2.005"], ["69928.00", "5.793"], ["70281.20", "1.292"], ["70387.80", "0.006"], ["70388.30", "0.000"], ["70491.10", "0.221"], ["70501.40", "0.000"], ["70586.50", "0.003"], ["70586.60", "0.227"], ["70599.00", "0.113"], ["70601.20", "0.002"], ["70601.50", "0.000"], ["70601.80", "0.092"], ["70608.30", "0.002"], ["70608.50", "0.172"], ["70615.30", "0.017"], ["70617.80", "0.075"], ["70625.80", "0.027"], ["70626.20", "0.008"], ["70627.30", "0.076"], ["70627.40", "0.432"], ["70631.20", "0.001"], ["70631.80", "0.009"]], "a": [["70634.40", "2.349"], ["70639.40", "0.006"], ["70639.80", "0.012"], ["70641.40", "0.029"], ["70641.50", "0.009"], ["70641.70", "0.007"], ["70654.70", "0.015"], ["70654.80", "0.003"], ["70665.50", "0.007"], ["70669.10", "1.238"], ["70669.70", "0.491"], ["70690.30", "0.019"], ["70690.60", "0.026"], ["70690.90", "0.147"], ["70765.90", "0.063"], ["70858.30", "0.007"], ["71340.70", "6.230"]]}}
{"local_ts": 1773486688328, "server_ts": 1773486688298, "data": {"e": "depthUpdate", "E": 1773486688299, "T": 1773486688298, "s": "BTCUSDT", "U": 10109518984663, "u": 10109518988514, "pu": 10109518984627, "b": [["1000.00", "26.442"], ["5000.00", "101.418"], ["7063.50", "0.028"], ["20334.30", "0.220"], ["20434.30", "2.490"], ["20534.30", "0.290"], ["33000.00", "3.789"], ["67077.70", "0.002"], ["69864.40", "4.499"], ["69928.00", "5.793"], ["70508.60", "1.929"], ["70510.00", "0.930"], ["70579.70", "0.008"], ["70586.60", "0.225"], ["70586.70", "0.004"], ["70600.90", "0.184"], ["70608.40", "0.016"], ["70608.50", "0.356"], ["70619.40", "0.518"], ["70623.00", "0.476"], ["70627.40", "0.430"], ["70634.30", "4.614"]], "a": [["70634.40", "2.337"], ["70641.50", "0.007"], ["70644.60", "0.020"], ["70646.70", "0.027"], ["70647.80", "0.017"], ["70649.00", "0.005"], ["70649.50", "0.797"], ["70649.60", "0.021"], ["70649.90", "0.000"], ["70650.70", "0.020"], ["70654.50", "0.439"], ["70654.60", "0.003"], ["70669.70", "0.493"], ["70679.90", "0.006"], ["70791.50", "0.094"], ["70792.20", "0.481"], ["70793.80", "0.365"], ["70794.80", "0.000"], ["70796.00", "0.061"], ["70796.90", "0.159"], ["71340.70", "6.230"], ["71404.30", "4.888"], ["71576.50", "0.698"], ["71640.00", "1.548"], ["72753.40", "0.000"], ["74187.30", "0.000"]]}}
{"local_ts": 1773486689349, "server_ts": 1773486689318, "data": {"e": "depthUpdate", "E": 1773486689319, "T": 1773486689318, "s": "BTCUSDT", "U": 10109519021764, "u": 10109519025383, "pu": 10109519021671, "b": [["5000.00", "101.418"], ["7063.50", "0.028"], ["20234.30", "0.070"], ["20334.30", "2.340"], ["20434.30", "0.590"], ["67078.90", "0.002"], ["69368.50", "0.000"], ["69928.00", "5.793"], ["70460.90", "0.017"], ["70586.90", "0.007"], ["70587.00", "0.027"], ["70594.90", "1.545"], ["70601.40", "1.071"], ["70601.50", "0.170"], ["70601.60", "0.085"], ["70606.00", "0.090"], ["70608.50", "0.002"], ["70620.10", "0.055"], ["70620.90", "0.026"], ["70621.00", "0.509"], ["70621.70", "0.000"], ["70622.30", "0.070"], ["70622.40", "0.070"], ["70623.10", "0.663"], ["70631.80", "0.007"]], "a": [["70634.40", "2.498"], ["70638.80", "0.002"], ["70643.20", "0.002"], ["70643.60", "0.024"], ["70645.30", "0.062"], ["70647.10", "0.145"], ["70647.20", "0.020"], ["70649.30", "0.297"], ["70649.40", "0.004"], ["70662.20", "0.007"], ["70668.30", "0.151"], ["70669.30", "0.072"], ["70690.30", "0.019"], ["70690.40", "0.002"], ["70690.70", "0.102"], ["70807.10", "0.013"], ["71340.70", "6.230"], ["71482.00", "2.681"], ["71505.90", "1.394"], ["72047.00", "0.009"]]}}
{"local_ts": 1773486690371, "server_ts": 1773486690340, "data": {"e": "depthUpdate", "E": 1773486690341, "T": 1773486690340, "s": "BTCUSDT", "U": 10109519063867, "u": 10109519067997, "pu": 10109519063862, "b": [["1000.00", "26.292"], ["5000.00", "101.418"], ["7063.50", "0.000"], ["20234.30", "2.040"], ["20334.30", "0.960"], ["69716.10", "6.443"], ["69928.00", "5.793"], ["70281.10", "3.943"], ["70587.20", "0.296"], ["70587.30", "0.006"], ["70587.90", "0.003"], ["70588.20", "1.066"], ["70592.50", "8.778"], ["70600.70", "0.263"], ["70601.40", "1.071"], ["70601.60", "0.085"], ["70613.40", "0.002"], ["70614.30", "0.006"], ["70615.20", "0.363"], ["70616.80", "0.293"], ["70617.30", "0.008"], ["70617.90", "0.004"], ["70618.70", "0.000"], ["70619.50", "0.010"], ["70619.60", "0.250"], ["70620.90", "1.351"], ["70621.00", "0.000"], ["70622.30", "0.000"], ["70623.10", "1.172"], ["70624.50", "0.095"], ["70625.00", "2.038"], ["70625.60", "0.007"], ["70625.90", "0.012"], ["70626.30", "0.214"], ["70630.50", "0.001"], ["70631.00", "1.538"], ["70631.10", "0.517"], ["70631.70", "0.013"], ["70632.20", "0.665"], ["70634.30", "4.711"]], "a": [["70639.70", "0.002"], ["70639.80", "0.012"], ["70640.10", "0.009"], ["70641.40", "0.001"], ["70643.20", "0.000"], ["70646.90", "0.043"], ["70648.40", "0.653"], ["70648.50", "0.501"], ["70650.40", "0.015"], ["70653.00", "1.212"], ["70653.30", "0.006"], ["70653.40", "0.002"], ["70653.50", "0.007"], ["70658.60", "0.002"], ["70659.30", "0.007"], ["70659.40", "0.341"], ["70665.40", "0.005"], ["70666.20", "1.351"], ["70666.80", "0.098"], ["70667.10", "0.000"], ["70667.70", "0.636"], ["70668.20", "0.512"], ["70670.50", "0.002"], ["70672.20", "0.088"], ["70673.30", "0.241"], ["70674.10", "0.000"], ["70675.40", "0.252"], ["70675.70", "0.000"], ["70677.50", "0.052"], ["70690.40", "0.002"], ["70690.70", "0.102"], ["70703.10", "0.007"], ["70703.60", "0.004"], ["70705.70", "8.486"], ["71340.70", "6.317"], ["74180.40", "0.004"], ["74188.10", "0.002"], ["89523.20", "0.000"]]}}
{"local_ts": 1773486691389, "server_ts": 1773486691360, "data": {"e": "depthUpdate", "E": 1773486691361, "T": 1773486691360, "s": "BTCUSDT", "U": 10109519105499, "u": 10109519109567, "pu": 10109519105358, "b": [["1000.00", "26.292"], ["5000.00", "101.418"], ["7063.50", "0.000"], ["20134.30", "1.590"], ["20234.30", "1.410"], ["67093.30", "0.000"], ["69504.20", "4.747"], ["69539.50", "14.071"], ["69610.10", "23.595"], ["69786.70", "6.281"], ["69928.00", "4.365"], ["70305.90", "0.106"], ["70457.70", "0.000"], ["70461.20", "0.000"], ["70464.80", "0.418"], ["70478.60", "0.018"], ["70483.90", "0.000"], ["70546.00", "7.481"], ["70577.80", "0.183"], ["70581.20", "3.655"], ["70602.50", "2.761"], ["70631.80", "0.007"]], "a": [["70636.40", "1.882"], ["70639.70", "0.000"], ["70640.30", "0.005"], ["70642.90", "1.001"], ["70643.00", "0.069"], ["70644.40", "0.030"], ["70647.90", "0.016"], ["70648.40", "0.939"], ["70648.60", "0.006"], ["70673.00", "1.760"], ["70674.10", "0.000"], ["70694.20", "3.904"], ["70728.00", "2.118"], ["70729.30", "6.272"], ["70787.50", "3.905"], ["70787.60", "12.433"], ["70800.40", "0.707"], ["70803.90", "0.003"], ["70807.50", "0.000"], ["70858.90", "0.007"], ["70881.60", "0.106"], ["71340.60", "0.032"], ["71340.70", "5.530"], ["89523.20", "0.000"]]}}
{"local_ts": 1773486692410, "server_ts": 1773486692380, "data": {"e": "depthUpdate", "E": 1773486692381, "T": 1773486692380, "s": "BTCUSDT", "U": 10109519152284, "u": 10109519156633, "pu": 10109519152109, "b": [["5000.00", "101.418"], ["7063.50", "0.000"], ["20134.30", "1.860"], ["20534.30", "1.140"], ["67102.70", "0.006"], ["67874.80", "2.657"], ["69539.50", "13.066"], ["69928.00", "3.651"], ["70305.90", "0.000"], ["70501.40", "0.680"], ["70542.20", "0.045"], ["70546.40", "6.472"], ["70549.20", "0.071"], ["70556.30", "0.163"]], "a": [["70638.00", "0.009"], ["70639.70", "0.008"], ["70640.30", "0.003"], ["70644.80", "0.021"], ["70648.90", "0.017"], ["70650.50", "0.004"], ["70674.10", "0.000"], ["70718.80", "0.091"], ["70718.90", "0.095"], ["70719.80", "0.000"], ["70720.20", "0.327"], ["70725.90", "0.582"], ["70726.00", "0.260"], ["70732.90", "0.071"], ["70733.00", "0.045"], ["70748.30", "0.016"], ["70755.40", "0.003"], ["70760.50", "0.176"], ["70762.50", "0.131"], ["70765.80", "0.866"], ["70767.60", "0.007"], ["70769.60", "0.000"], ["70774.70", "0.010"], ["70776.70", "0.000"], ["70781.80", "0.101"], ["70783.80", "0.511"], ["70788.90", "0.007"], ["70790.90", "0.000"], ["70792.10", "0.187"], ["70796.00", "0.068"], ["70798.00", "0.002"], ["70803.10", "0.007"], ["70803.90", "0.162"], ["70804.10", "0.000"], ["70810.20", "0.216"], ["70858.70", "0.004"], ["70881.60", "0.000"], ["71340.60", "0.039"], ["71340.70", "5.530"], ["74184.30", "0.012"], ["89523.20", "0.000"]]}}
{"local_ts": 1773486693433, "server_ts": 1773486693404, "data": {"e": "depthUpdate", "E": 1773486693405, "T": 1773486693404, "s": "BTCUSDT", "U": 10109519202118, "u": 10109519206788, "pu": 10109519201974, "b": [["1000.00", "26.442"], ["5000.00", "101.398"], ["7063.50", "0.056"], ["20134.30", "0.000"], ["20434.30", "0.700"], ["20534.30", "2.300"], ["33000.00", "3.785"], ["67081.30", "0.002"], ["69539.50", "14.071"], ["69928.00", "5.079"], ["70212.70", "0.000"], ["70212.80", "0.364"], ["70281.30", "0.000"], ["70305.90", "0.000"], ["70318.20", "0.000"], ["70318.40", "0.164"], ["70387.90", "0.004"], ["70395.60", "0.000"], ["70398.70", "0.458"], ["70457.70", "0.000"], ["70462.50", "3.310"], ["70501.40", "0.679"], ["70522.10", "6.556"], ["70586.90", "0.003"], ["70587.00", "0.027"], ["70600.60", "0.020"], ["70600.80", "0.085"], ["70601.00", "0.088"], ["70614.40", "0.219"], ["70631.80", "0.007"]], "a": [["70635.50", "0.002"], ["70638.00", "0.007"], ["70639.70", "0.000"], ["70643.70", "0.000"], ["70645.60", "0.046"], ["70645.80", "0.123"], ["70649.00", "0.005"], ["70650.40", "0.015"], ["70689.60", "0.003"], ["70689.90", "1.804"], ["70690.00", "3.742"], ["70760.50", "0.169"], ["70763.10", "5.680"], ["70764.90", "0.090"], ["70765.80", "0.861"], ["70767.60", "0.000"], ["70768.40", "0.088"], ["70772.00", "0.022"], ["70774.70", "0.003"], ["70778.30", "0.000"], ["70779.10", "0.099"], ["70781.80", "0.094"], ["70786.20", "0.007"], ["70788.90", "0.000"], ["70793.30", "0.103"], ["70796.00", "0.061"], ["70800.40", "0.615"], ["70803.10", "0.000"], ["70804.60", "2.729"], ["70807.50", "0.007"], ["70810.20", "0.209"], ["70814.60", "0.007"], ["70858.30", "0.007"], ["70883.10", "2.683"], ["70883.60", "0.002"], ["70959.80", "0.135"], ["70961.60", "0.000"], ["71068.00", "0.116"], ["71340.60", "0.032"], ["71340.70", "6.230"], ["71658.60", "22.292"], ["71764.60", "3.896"], ["71914.70", "0.000"], ["73449.70", "0.013"], ["89523.20", "0.000"]]}}
{"local_ts": 1773486694452, "server_ts": 1773486694424, "data": {"e": "depthUpdate", "E": 1773486694425, "T": 1773486694424, "s": "BTCUSDT", "U": 10109519245817, "u": 10109519250914, "pu": 10109519245661, "b": [["5000.00", "101.438"], ["7063.50", "0.056"], ["20334.30", "0.320"], ["20434.30", "2.610"], ["20534.30", "0.070"], ["69764.30", "0.135"], ["69928.00", "5.793"], ["70454.20", "0.004"], ["70462.50", "3.308"], ["70501.40", "0.679"], ["70593.50", "0.529"], ["70595.50", "0.071"], ["70600.00", "1.397"], ["70600.20", "0.337"], ["70600.60", "0.105"], ["70600.70", "0.263"], ["70600.80", "0.085"], ["70606.00", "0.064"]], "a": [["70634.40", "1.861"], ["70636.60", "0.000"], ["70637.10", "0.001"], ["70648.50", "0.365"], ["70652.40", "0.199"], ["70652.80", "0.020"], ["70664.40", "0.079"], ["70689.70", "0.088"], ["70689.90", "1.804"], ["70694.40", "0.201"], ["70753.60", "0.257"], ["70760.70", "0.015"], ["70764.90", "0.083"], ["70765.70", "0.452"], ["70767.80", "0.017"], ["70772.00", "0.015"], ["70774.90", "0.010"], ["70779.10", "0.092"], ["70782.00", "0.016"], ["70786.20", "0.000"], ["70789.10", "0.007"], ["70793.30", "0.096"], ["70796.20", "0.009"], ["70800.40", "0.767"], ["70803.30", "0.007"], ["70804.60", "2.986"], ["70807.50", "0.000"], ["70814.60", "0.000"], ["71340.70", "6.230"], ["71840.90", "0.283"], ["74176.20", "0.002"], ["74196.90", "0.000"], ["89523.20", "0.000"]]}}
{"local_ts": 1773486695474, "server_ts": 1773486695444, "data": {"e": "depthUpdate", "E": 1773486695445, "T": 1773486695444, "s": "BTCUSDT", "U": 10109519295742, "u": 10109519300994, "pu": 10109519295677, "b": [["1000.00", "26.292"], ["5000.00", "101.418"], ["7063.50", "0.056"], ["20234.30", "0.170"], ["20334.30", "2.450"], ["20434.30", "0.380"], ["33000.00", "3.789"], ["67082.60", "0.000"], ["69424.90", "0.288"], ["69928.00", "5.793"], ["70281.10", "3.907"], ["70501.40", "0.000"], ["70600.20", "0.153"], ["70621.50", "0.402"], ["70625.00", "2.033"], ["70631.80", "0.007"]], "a": [["70639.50", "0.007"], ["70646.60", "0.245"], ["70648.90", "0.017"], ["70650.00", "4.288"], ["70650.90", "0.072"], ["70651.30", "0.002"], ["70653.70", "0.008"], ["70660.80", "0.218"], ["70667.90", "0.007"], ["70675.00", "0.017"], ["70676.30", "0.694"], ["70682.10", "0.009"], ["70689.20", "0.007"], ["70753.60", "0.250"], ["70760.70", "0.008"], ["70765.70", "0.000"], ["70767.80", "0.010"], ["70774.90", "0.003"], ["70782.00", "0.009"], ["70789.10", "0.000"], ["70796.20", "0.002"], ["70803.30", "0.000"], ["70858.30", "0.000"], ["70987.60", "3.903"], ["71340.60", "0.039"], ["71340.70", "6.232"], ["89523.20", "0.000"]]}}
{"local_ts": 1773486696499, "server_ts": 1773486696468, "data": {"e": "depthUpdate", "E": 1773486696469, "T": 1773486696468, "s": "BTCUSDT", "U": 10109519340342, "u": 10109519344726, "pu": 10109519340251, "b": [["1000.00", "26.292"], ["5000.00", "101.418"], ["7063.50", "0.028"], ["20134.30", "0.030"], ["20234.30", "2.300"], ["20334.30", "0.670"], ["56507.00", "0.005"], ["69928.00", "5.793"], ["70281.10", "3.943"], ["70309.50", "0.004"], ["70387.10", "6.523"], ["70464.80", "0.418"], ["70501.30", "0.790"], ["70598.30", "0.368"], ["70606.00", "0.064"], ["70620.10", "0.081"], ["70624.90", "0.008"], ["70625.30", "0.001"], ["70631.80", "0.007"], ["70634.30", "4.420"]], "a": [["70634.40", "2.083"], ["70639.50", "0.000"], ["70642.30", "0.003"], ["70642.80", "0.032"], ["70644.00", "0.009"], ["70644.40", "0.012"], ["70644.70", "0.004"], ["70645.00", "0.166"], ["70645.30", "0.005"], ["70645.60", "0.067"], ["70645.80", "0.076"], ["70646.10", "0.000"], ["70646.40", "0.273"], ["70646.50", "0.077"], ["70646.60", "0.238"], ["70646.70", "0.027"], ["70647.00", "0.314"], ["70647.30", "0.115"], ["70647.40", "0.006"], ["70647.70", "0.003"], ["70647.90", "0.001"], ["70648.00", "0.005"], ["70648.30", "0.002"], ["70648.40", "0.929"], ["70649.10", "0.017"], ["70649.20", "0.158"], ["70649.60", "0.000"], ["70650.40", "0.072"], ["70650.50", "0.004"], ["70651.20", "1.353"], ["70653.70", "0.001"], ["70660.80", "0.202"], ["70667.90", "0.000"], ["70675.00", "0.010"], ["70679.20", "0.992"], ["70682.10", "0.002"], ["70689.20", "0.000"], ["70718.20", "0.007"], ["70725.30", "0.007"], ["70732.40", "0.009"], ["70739.50", "0.119"], ["70746.60", "0.009"], ["70753.70", "0.048"], ["70760.80", "0.099"], ["70765.70", "0.444"], ["70767.90", "0.007"], ["70796.90", "0.159"], ["71340.70", "6.230"], ["71928.10", "1.190"], ["74171.50", "0.224"], ["89523.20", "0.000"]]}}
{"local_ts": 1773486697522, "server_ts": 1773486697492, "data": {"e": "depthUpdate", "E": 1773486697493, "T": 1773486697492, "s": "BTCUSDT", "U": 10109519391337, "u": 10109519395732, "pu": 10109519391035, "b": [["5000.00", "101.418"], ["7063.50", "0.028"], ["20134.30", "1.920"], ["20234.30", "1.080"], ["33000.00", "3.789"], ["67082.70", "0.004"], ["67102.00", "0.000"], ["67102.60", "0.006"], ["67102.70", "0.008"], ["69234.70", "3.708"], ["69928.00", "5.793"], ["70473.20", "0.000"], ["70477.90", "0.003"], ["70481.70", "0.000"], ["70562.20", "0.695"], ["70583.90", "0.283"], ["70584.00", "0.002"], ["70586.80", "0.015"], ["70587.10", "0.003"], ["70598.30", "0.000"], ["70604.80", "0.187"], ["70622.10", "0.080"], ["70623.10", "0.523"], ["70627.30", "0.360"], ["70631.90", "0.217"]], "a": [["70634.40", "1.920"], ["70639.60", "0.173"], ["70640.20", "0.014"], ["70641.40", "0.029"], ["70642.30", "0.003"], ["70642.60", "0.137"], ["70646.40", "0.205"], ["70649.60", "0.025"], ["70649.70", "0.036"], ["70649.90", "0.045"], ["70650.10", "0.009"], ["70650.20", "0.036"], ["70652.80", "0.128"], ["70655.80", "0.093"], ["70659.60", "0.076"], ["70664.30", "0.002"], ["70665.20", "0.720"], ["70666.00", "0.304"], ["70678.40", "0.002"], ["70679.20", "0.990"], ["70693.00", "0.002"], ["70695.20", "0.389"], ["70696.50", "0.000"], ["70696.90", "0.092"], ["70716.30", "0.575"], ["70716.60", "0.430"], ["70717.00", "0.038"], ["70725.30", "0.036"], ["70726.20", "0.251"], ["70858.20", "0.007"], ["71340.70", "6.230"], ["71588.00", "10.243"], ["74174.90", "0.002"], ["74188.50", "0.055"], ["89523.20", "0.000"]]}}
{"local_ts": 1773486698542, "server_ts": 1773486698512, "data": {"e": "depthUpdate", "E": 1773486698513, "T": 1773486698512, "s": "BTCUSDT", "U": 10109519441083, "u": 10109519446731, "pu": 10109519440974, "b": [["1000.00", "26.292"], ["5000.00", "101.418"], ["7063.20", "0.028"], ["20134.30", "1.510"], ["20532.00", "1.040"], ["67088.20", "0.002"], ["67099.60", "0.002"], ["69290.00", "0.388"], ["69925.70", "0.000"], ["70320.10", "0.000"], ["70387.30", "0.004"], ["70519.00", "0.000"], ["70520.90", "0.205"], ["70527.80", "0.148"], ["70528.90", "0.125"], ["70529.60", "0.085"], ["70583.90", "0.000"], ["70584.00", "0.004"], ["70585.70", "0.068"], ["70592.00", "0.283"], ["70594.00", "0.004"], ["70596.70", "0.001"], ["70618.00", "0.002"], ["70620.40", "0.219"], ["70621.40", "0.377"], ["70622.10", "0.063"], ["70629.60", "0.003"], ["70631.30", "0.057"], ["70632.00", "3.523"]], "a": [["70632.10", "7.738"], ["70633.10", "0.007"], ["70634.00", "0.000"], ["70634.40", "1.148"], ["70635.60", "0.072"], ["70636.40", "1.885"], ["70637.40", "0.014"], ["70637.80", "0.003"], ["70638.20", "0.004"], ["70639.00", "0.000"], ["70639.20", "0.004"], ["70639.80", "0.143"], ["70640.10", "0.029"], ["70640.30", "0.003"], ["70640.40", "0.032"], ["70640.50", "0.750"], ["70641.10", "0.062"], ["70641.50", "0.007"], ["70642.10", "0.072"], ["70642.60", "0.007"], ["70642.70", "0.033"], ["70642.80", "0.008"], ["70646.10", "1.435"], ["70647.80", "0.032"], ["70647.90", "0.001"], ["70648.00", "0.003"], ["70648.40", "0.001"], ["70648.50", "0.261"], ["70648.70", "1.182"], ["70649.10", "0.017"], ["70650.30", "0.046"], ["70651.60", "0.015"], ["70652.80", "0.164"], ["70655.80", "0.036"], ["70657.70", "0.702"], ["70659.50", "0.009"], ["70661.90", "0.116"], ["70665.70", "0.028"], ["70666.10", "0.616"], ["70667.40", "0.758"], ["70678.40", "0.000"], ["70683.30", "0.138"], ["70723.60", "0.142"], ["70749.90", "4.458"], ["70794.60", "0.099"], ["70798.10", "0.341"], ["70799.20", "0.002"], ["70855.80", "0.009"], ["70872.20", "0.106"], ["70878.10", "0.008"], ["70933.20", "0.140"], ["70983.60", "0.006"], ["71338.40", "0.000"], ["89523.20", "0.000"]]}}
{"local_ts": 1773486699566, "server_ts": 1773486699533, "data": {"e": "depthUpdate", "E": 1773486699535, "T": 1773486699533, "s": "BTCUSDT", "U": 10109519478880, "u": 10109519482604, "pu": 10109519478817, "b": [["5000.00", "101.418"], ["7063.20", "0.000"], ["20432.00", "1.020"], ["20532.00", "1.980"], ["40000.00", "41.317"], ["56508.00", "0.000"], ["67099.20", "0.002"], ["69201.20", "1.734"], ["69301.40", "0.245"], ["69925.70", "0.000"], ["70589.70", "0.020"], ["70597.10", "0.000"], ["70600.10", "0.000"], ["70603.70", "0.027"], ["70611.50", "0.003"], ["70612.10", "0.003"], ["70613.60", "0.839"], ["70614.10", "0.007"], ["70614.40", "0.219"], ["70615.60", "0.069"], ["70616.20", "0.009"], ["70617.10", "0.009"], ["70617.40", "0.010"], ["70617.60", "0.143"], ["70617.80", "0.059"], ["70618.10", "0.049"], ["70618.60", "0.022"], ["70619.60", "0.007"], ["70621.40", "0.377"], ["70621.90", "0.009"], ["70622.00", "0.138"], ["70622.50", "0.005"], ["70622.80", "0.179"], ["70623.00", "0.413"], ["70623.10", "0.026"], ["70623.20", "0.119"], ["70623.50", "0.514"], ["70623.80", "0.024"], ["70624.00", "0.314"], ["70624.10", "0.521"], ["70624.20", "0.032"], ["70624.60", "0.007"], ["70625.10", "0.427"], ["70626.50", "0.178"], ["70629.10", "0.019"], ["70629.90", "0.007"], ["70631.40", "0.005"], ["70631.60", "0.000"], ["70632.00", "3.476"]], "a": [["70632.10", "7.301"], ["70633.10", "0.000"], ["70633.60", "0.009"], ["70637.40", "0.012"], ["70637.50", "0.003"], ["70637.60", "0.006"], ["70637.70", "0.004"], ["70638.10", "0.157"], ["70638.80", "0.006"], ["70639.30", "0.009"], ["70639.60", "0.102"], ["70639.70", "0.000"], ["70639.90", "0.001"], ["70640.10", "0.037"], ["70641.10", "0.062"], ["70641.80", "0.133"], ["70641.90", "0.062"], ["70642.20", "0.044"], ["70642.90", "0.281"], ["70645.30", "0.005"], ["70645.50", "0.002"], ["70645.60", "0.007"], ["70645.80", "0.747"], ["70646.20", "0.008"], ["70646.40", "0.006"], ["70646.50", "0.146"], ["70647.10", "0.024"], ["70647.20", "0.012"], ["70647.40", "0.006"], ["70647.60", "0.005"], ["70647.80", "0.017"], ["70648.20", "0.010"], ["70648.50", "0.233"], ["70648.60", "0.061"], ["70648.70", "0.005"], ["70649.10", "0.002"], ["70649.40", "0.004"], ["70649.50", "0.804"], ["70649.70", "0.000"], ["70649.80", "0.094"], ["70649.90", "1.247"], ["70650.00", "4.279"], ["70650.30", "0.027"], ["70650.40", "0.030"], ["70650.80", "0.006"], ["70651.60", "0.015"], ["70651.70", "0.003"], ["70651.80", "0.023"], ["70652.00", "0.004"], ["70652.10", "0.009"], ["70652.80", "0.005"], ["70653.20", "0.597"], ["70653.80", "0.021"], ["70654.10", "0.514"], ["70655.30", "0.000"], ["70655.50", "0.110"], ["70656.40", "0.638"], ["70656.60", "0.002"], ["70657.00", "0.005"], ["70657.60", "0.511"], ["70657.70", "0.066"], ["70657.90", "0.019"], ["70659.20", "0.018"], ["70659.70", "0.363"], ["70660.50", "1.088"], ["70661.60", "0.028"], ["70661.90", "0.061"], ["70662.40", "0.075"], ["70663.30", "0.016"], ["70663.60", "0.532"], ["70664.20", "0.067"], ["70664.60", "0.018"], ["70664.70", "0.247"], ["70665.60", "0.861"], ["70666.00", "0.319"], ["70666.10", "0.614"], ["70667.20", "0.017"], ["70667.50", "0.000"], ["70668.50", "0.012"], ["70669.50", "0.002"], ["70669.80", "0.550"], ["70671.00", "0.060"], ["70672.30", "0.005"], ["70673.50", "0.002"], ["70674.80", "0.005"], ["70678.00", "0.245"], ["70678.20", "0.143"], ["70794.60", "0.099"], ["71054.00", "0.045"], ["71338.40", "0.000"], ["71729.80", "0.417"], ["71929.40", "0.694"], ["89523.20", "0.000"], ["100000.00", "23.659"]]}}
{"local_ts": 1773486700587, "server_ts": 1773486700556, "data": {"e": "depthUpdate", "E": 1773486700559, "T": 1773486700556, "s": "BTCUSDT", "U": 10109519518149, "u": 10109519521423, "pu": 10109519518070, "b": [["1000.00", "26.292"], ["5000.00", "101.418"], ["7063.20", "0.000"], ["20332.00", "0.580"], ["20432.00", "2.420"], ["20532.00", "0.000"], ["56506.00", "0.004"], ["67083.50", "0.002"], ["69517.00", "0.000"], ["69593.60", "1.362"], ["69625.50", "19.641"], ["69707.20", "64.536"], ["69917.00", "57.698"], ["69925.70", "0.000"], ["70079.50", "49.282"], ["70278.80", "0.000"], ["70499.00", "0.606"], ["70601.20", "0.004"], ["70601.30", "0.107"], ["70629.80", "0.006"]], "a": [["70632.10", "5.518"], ["70634.40", "0.855"], ["70635.60", "0.075"], ["70637.50", "1.576"], ["70638.10", "0.157"], ["70640.70", "0.027"], ["70641.00", "0.005"], ["70641.20", "0.002"], ["70641.30", "0.000"], ["70641.90", "0.007"], ["70650.00", "4.274"], ["70657.70", "0.066"], ["70663.40", "0.002"], ["70765.80", "0.876"], ["70784.10", "0.448"], ["71191.60", "46.394"], ["71338.40", "0.000"], ["71355.40", "56.694"], ["71404.30", "5.586"], ["71569.40", "64.813"], ["74171.40", "0.000"]]}}
{"local_ts": 1773486701611, "server_ts": 1773486701580, "data": {"e": "depthUpdate", "E": 1773486701581, "T": 1773486701580, "s": "BTCUSDT", "U": 10109519549490, "u": 10109519553397, "pu": 10109519549369, "b": [["1000.00", "26.292"], ["5000.00", "101.418"], ["7063.20", "0.000"], ["20232.00", "0.290"], ["20332.00", "2.560"], ["20432.00", "0.150"], ["56506.00", "0.000"], ["67065.70", "0.002"], ["67083.50", "0.000"], ["67102.80", "0.000"], ["69431.30", "0.288"], ["69925.70", "0.000"], ["70385.60", "0.004"], ["70629.70", "0.226"], ["70632.00", "3.107"]], "a": [["70632.10", "6.313"], ["70637.20", "1.079"], ["70638.20", "0.025"], ["70707.50", "0.192"], ["70707.90", "0.055"], ["70855.90", "0.024"], ["71000.00", "85.917"], ["71338.40", "0.000"], ["71340.60", "0.032"], ["72751.00", "0.018"]]}}
{"local_ts": 1773486702632, "server_ts": 1773486702601, "data": {"e": "depthUpdate", "E": 1773486702603, "T": 1773486702601, "s": "BTCUSDT", "U": 10109519591793, "u": 10109519594979, "pu": 10109519591683, "b": [["5000.00", "101.418"], ["7063.20", "0.056"], ["20132.00", "0.140"], ["20232.00", "2.410"], ["20332.00", "0.450"], ["33000.00", "3.785"], ["56506.00", "0.000"], ["67073.90", "0.002"], ["69925.70", "0.000"], ["70278.80", "0.568"], ["70458.70", "0.000"], ["70554.30", "0.003"], ["70568.40", "0.003"], ["70575.10", "0.000"], ["70596.70", "0.036"]], "a": [["70632.10", "6.106"], ["70634.40", "0.812"], ["70638.40", "0.017"], ["70667.40", "0.794"], ["70695.70", "0.390"], ["70707.50", "0.190"], ["70709.50", "0.144"], ["70709.80", "0.205"], ["71265.70", "4.203"], ["71338.40", "0.000"], ["71548.20", "8.100"], ["71550.20", "0.846"], ["71585.60", "0.279"], ["71656.30", "6.691"], ["74191.90", "0.000"]]}}
{"local_ts": 1773486703654, "server_ts": 1773486703622, "data": {"e": "depthUpdate", "E": 1773486703623, "T": 1773486703622, "s": "BTCUSDT", "U": 10109519627449, "u": 10109519631139, "pu": 10109519627431, "b": [["1000.00", "26.292"], ["5000.00", "101.438"], ["7063.20", "0.056"], ["20132.00", "2.240"], ["20232.00", "0.760"], ["56506.00", "0.004"], ["67069.20", "0.002"], ["69431.30", "0.719"], ["69925.70", "0.000"], ["70307.20", "0.000"], ["70385.70", "0.004"], ["70583.80", "0.005"], ["70584.40", "0.006"], ["70603.70", "0.001"], ["70607.40", "0.325"], ["70610.80", "0.271"], ["70614.10", "0.077"], ["70614.80", "0.000"], ["70617.80", "0.085"], ["70621.40", "0.377"], ["70629.70", "0.226"], ["70631.80", "0.007"], ["70632.00", "3.080"]], "a": [["70632.10", "5.489"], ["70636.10", "0.010"], ["70639.90", "0.001"], ["70640.40", "0.007"], ["70641.00", "0.066"], ["70641.70", "0.140"], ["70642.70", "0.033"], ["70657.70", "0.066"], ["70708.60", "0.042"], ["70709.00", "0.210"], ["70709.50", "0.142"], ["70711.20", "2.027"], ["70715.70", "0.726"], ["70715.80", "0.000"], ["70716.60", "0.364"], ["70723.90", "0.147"], ["70727.30", "0.049"], ["70728.30", "0.092"], ["70855.80", "0.009"], ["71265.60", "0.000"], ["71267.80", "4.203"], ["71338.40", "2.099"], ["71550.30", "7.817"]]}}
{"local_ts": 1773486704672, "server_ts": 1773486704642, "data": {"e": "depthUpdate", "E": 1773486704643, "T": 1773486704642, "s": "BTCUSDT", "U": 10109519661559, "u": 10109519664909, "pu": 10109519661440, "b": [["5000.00", "101.418"], ["7063.20", "0.056"], ["20132.00", "1.210"], ["20532.00", "1.790"], ["20532.10", "0.000"], ["33000.00", "3.789"], ["56506.00", "0.004"], ["69232.40", "0.618"], ["69925.70", "0.714"], ["70385.20", "0.004"], ["70565.20", "0.516"], ["70565.30", "0.097"], ["70569.40", "0.007"], ["70575.80", "0.004"], ["70582.60", "0.083"], ["70584.10", "0.066"], ["70584.20", "0.002"], ["70601.60", "0.184"], ["70610.80", "0.074"], ["70621.40", "0.377"]], "a": [["70632.10", "5.741"], ["70639.70", "0.000"], ["70642.70", "0.033"], ["70656.50", "0.514"], ["70709.00", "0.208"], ["70709.30", "0.003"], ["70794.60", "0.159"], ["71338.40", "2.799"], ["71585.60", "1.394"], ["71621.50", "2.091"], ["72044.70", "0.020"], ["74196.00", "0.132"]]}}
{"local_ts": 1773486705698, "server_ts": 1773486705661, "data": {"e": "depthUpdate", "E": 1773486705663, "T": 1773486705661, "s": "BTCUSDT", "U": 10109519696158, "u": 10109519699913, "pu": 10109519696109, "b": [["1000.00", "26.292"], ["5000.00", "101.418"], ["7063.20", "0.056"], ["20432.00", "1.340"], ["20532.00", "1.660"], ["67084.90", "0.002"], ["69711.70", "2.148"], ["69925.70", "0.714"], ["69994.20", "2.847"], ["70278.80", "0.710"], ["70487.00", "0.066"], ["70584.00", "0.002"], ["70584.40", "0.008"], ["70612.70", "1.169"], ["70613.40", "0.002"], ["70618.10", "0.449"], ["70621.70", "0.272"], ["70625.00", "0.028"]], "a": [["70638.80", "0.004"], ["70639.10", "0.016"], ["70639.70", "0.057"], ["70656.20", "0.638"], ["70708.50", "0.104"], ["70708.70", "0.270"], ["70709.30", "0.001"], ["70715.00", "0.312"], ["70715.50", "0.039"], ["70727.30", "0.010"], ["70727.40", "0.365"], ["71338.40", "2.799"], ["71613.90", "2.508"], ["74196.00", "0.130"]]}}
{"local_ts": 1773486706712, "server_ts": 1773486706680, "data": {"e": "depthUpdate", "E": 1773486706683, "T": 1773486706680, "s": "BTCUSDT", "U": 10109519737174, "u": 10109519741287, "pu": 10109519737086, "b": [["1000.00", "26.292"], ["5000.00", "101.418"], ["7063.20", "0.028"], ["20332.00", "0.890"], ["20432.00", "2.110"], ["33000.00", "3.789"], ["67076.10", "0.000"], ["67100.00", "3.868"], ["68632.00", "0.007"], ["69202.20", "1.731"], ["69670.50", "0.000"], ["69708.80", "67.547"], ["69713.80", "6.802"], ["69925.70", "0.714"], ["69996.30", "4.282"], ["70540.80", "0.152"], ["70562.70", "0.002"], ["70584.20", "0.002"], ["70584.40", "0.008"], ["70600.20", "0.729"], ["70601.60", "0.354"], ["70609.60", "0.183"], ["70621.40", "0.374"], ["70625.00", "0.028"], ["70632.00", "2.257"]], "a": [["70632.10", "5.731"], ["70634.40", "0.513"], ["70639.10", "0.016"], ["70639.30", "0.012"], ["70639.40", "0.004"], ["70642.70", "0.033"], ["70645.80", "0.444"], ["70645.90", "0.038"], ["70656.20", "0.638"], ["70680.00", "2.740"], ["70708.70", "0.268"], ["70794.60", "0.099"], ["71338.40", "2.799"], ["71402.00", "0.700"], ["71585.60", "2.788"], ["74163.70", "0.000"]]}}
{"local_ts": 1773486707734, "server_ts": 1773486707702, "data": {"e": "depthUpdate", "E": 1773486707703, "T": 1773486707702, "s": "BTCUSDT", "U": 10109519783617, "u": 10109519787112, "pu": 10109519783537, "b": [["5000.00", "101.418"], ["7063.20", "0.028"], ["20232.00", "0.450"], ["20332.00", "2.540"], ["20432.00", "0.010"], ["67906.70", "0.000"], ["69925.70", "2.857"], ["69958.10", "0.000"], ["70278.80", "0.720"], ["70580.20", "0.290"], ["70584.20", "0.004"], ["70584.40", "0.006"], ["70621.40", "0.374"], ["70625.00", "0.072"], ["70629.70", "0.226"]], "a": [["70639.10", "0.041"], ["70639.60", "0.105"], ["70641.40", "0.003"], ["71338.40", "2.799"], ["71558.50", "0.000"], ["74175.60", "0.002"], ["74195.60", "0.000"]]}}
{"local_ts": 1773486708754, "server_ts": 1773486708724, "data": {"e": "depthUpdate", "E": 1773486708725, "T": 1773486708724, "s": "BTCUSDT", "U": 10109519820012, "u": 10109519828231, "pu": 10109519819976, "b": [["1000.00", "26.292"], ["5000.00", "101.418"], ["7063.20", "0.028"], ["20132.00", "0.240"], ["20232.00", "2.510"], ["20332.00", "0.250"], ["67097.60", "0.000"], ["69925.70", "2.857"], ["70518.20", "0.200"], ["70525.20", "0.204"], ["70539.40", "0.200"], ["70580.10", "0.219"], ["70580.20", "0.276"], ["70592.60", "0.467"], ["70596.70", "0.001"], ["70600.30", "0.442"], ["70601.40", "1.071"], ["70601.50", "0.085"], ["70601.60", "0.000"], ["70605.60", "0.043"], ["70606.70", "0.003"], ["70607.60", "0.881"], ["70608.30", "0.002"], ["70608.80", "0.000"], ["70610.80", "0.095"], ["70610.90", "0.509"], ["70611.20", "0.074"], ["70611.60", "0.000"], ["70612.30", "0.007"], ["70613.00", "0.246"], ["70614.00", "0.006"], ["70618.00", "0.639"], ["70618.60", "0.024"], ["70618.90", "0.011"], ["70619.90", "0.000"], ["70620.20", "0.005"], ["70620.50", "0.000"], ["70621.00", "0.051"], ["70621.40", "0.377"], ["70623.50", "0.003"], ["70625.30", "1.088"], ["70625.40", "0.000"], ["70626.00", "0.008"], ["70626.60", "0.005"], ["70627.80", "0.000"], ["70628.20", "0.003"], ["70628.40", "0.004"], ["70629.10", "0.004"], ["70629.40", "0.007"], ["70629.60", "0.003"], ["70629.80", "0.006"], ["70630.00", "0.759"], ["70630.30", "0.028"], ["70631.00", "0.001"], ["70632.00", "0.282"]], "a": [["70632.10", "6.545"], ["70632.70", "0.007"], ["70633.70", "0.002"], ["70633.80", "0.003"], ["70633.90", "0.003"], ["70634.30", "0.142"], ["70634.40", "0.530"], ["70635.40", "0.020"], ["70635.60", "0.105"], ["70637.00", "1.011"], ["70637.10", "0.001"], ["70637.20", "0.014"], ["70637.40", "0.012"], ["70639.70", "0.000"], ["70640.40", "0.007"], ["70641.50", "0.003"], ["70642.90", "0.201"], ["70644.10", "0.003"], ["70645.90", "0.040"], ["70646.70", "1.066"], ["70649.70", "0.007"], ["70651.70", "0.003"], ["70651.80", "0.002"], ["70653.80", "0.000"], ["70655.10", "0.716"], ["70655.40", "0.514"], ["70656.40", "0.009"], ["70657.10", "0.038"], ["70657.30", "0.005"], ["70658.30", "0.000"], ["70659.40", "0.081"], ["70661.20", "0.070"], ["70667.40", "0.758"], ["70856.10", "0.007"], ["71328.30", "1.450"], ["71338.40", "2.801"], ["71693.80", "0.626"], ["72044.70", "0.023"], ["74163.70", "0.000"], ["74192.80", "0.002"]]}}
{"local_ts": 1773486709774, "server_ts": 1773486709744, "data": {"e": "depthUpdate", "E": 1773486709745, "T": 1773486709744, "s": "BTCUSDT", "U": 10109519895678, "u": 10109519900758, "pu": 10109519895509, "b": [["5000.00", "101.418"], ["7063.00", "0.252"], ["20129.10", "1.440"], ["20132.00", "0.920"], ["20232.00", "0.540"], ["20529.10", "0.090"], ["33000.00", "3.785"], ["69216.60", "0.008"], ["69616.40", "0.716"], ["69922.80", "0.000"], ["70420.00", "0.090"], ["70503.30", "0.090"], ["70508.40", "0.002"], ["70538.60", "0.279"], ["70543.70", "0.019"], ["70548.10", "0.094"], ["70573.90", "0.022"], ["70579.00", "0.094"], ["70581.80", "0.002"], ["70581.90", "0.744"], ["70599.70", "1.098"], ["70599.90", "0.022"], ["70600.00", "1.481"], ["70600.10", "0.000"], ["70609.30", "0.016"], ["70615.20", "0.354"], ["70616.60", "0.023"], ["70622.10", "1.668"], ["70626.60", "0.004"], ["70627.90", "0.003"]], "a": [["70629.20", "8.200"], ["70632.10", "0.482"], ["70634.20", "0.219"], ["70634.30", "0.007"], ["70634.90", "0.007"], ["70635.60", "0.074"], ["70636.20", "0.048"], ["70636.90", "0.657"], ["70637.00", "0.334"], ["70637.70", "0.875"], ["70655.60", "0.005"], ["70667.20", "0.000"], ["70668.60", "0.038"], ["70684.40", "0.003"], ["70689.60", "0.000"], ["70719.80", "0.003"], ["70725.00", "0.049"], ["70755.20", "0.205"], ["70760.40", "0.047"], ["70985.30", "0.739"], ["71335.50", "0.000"], ["71691.60", "8.077"], ["74168.20", "0.002"]]}}
{"local_ts": 1773486710796, "server_ts": 1773486710766, "data": {"e": "depthUpdate", "E": 1773486710767, "T": 1773486710766, "s": "BTCUSDT", "U": 10109519935520, "u": 10109519941919, "pu": 10109519935498, "b": [["1000.00", "26.292"], ["5000.00", "101.418"], ["7063.00", "0.252"], ["20129.10", "0.900"], ["20529.10", "2.100"], ["67076.30", "0.006"], ["67079.50", "0.004"], ["69219.40", "0.255"], ["69922.80", "1.071"], ["70276.00", "0.085"], ["70276.10", "0.190"], ["70538.60", "0.281"], ["70538.80", "0.893"], ["70556.70", "0.003"], ["70560.70", "0.094"], ["70570.90", "0.000"], ["70585.20", "0.009"], ["70594.00", "0.000"], ["70599.80", "0.000"], ["70600.40", "0.300"], ["70600.50", "0.000"], ["70600.60", "0.020"], ["70600.70", "0.124"], ["70600.80", "0.167"], ["70604.80", "0.253"], ["70605.40", "0.013"], ["70606.50", "0.115"], ["70607.50", "0.816"], ["70608.80", "0.509"], ["70610.50", "0.070"], ["70610.80", "0.095"], ["70611.30", "0.000"], ["70611.60", "0.002"], ["70612.10", "0.073"], ["70612.90", "0.005"], ["70613.10", "0.009"], ["70613.80", "0.026"], ["70614.10", "0.588"], ["70614.90", "0.057"], ["70617.30", "0.637"], ["70618.10", "0.108"], ["70618.50", "0.259"], ["70619.50", "0.010"], ["70619.60", "0.000"], ["70622.30", "0.001"], ["70623.60", "0.000"], ["70626.50", "0.008"], ["70626.60", "0.002"], ["70626.80", "0.009"]], "a": [["70629.20", "8.568"], ["70629.50", "0.005"], ["70630.90", "0.144"], ["70631.40", "0.002"], ["70631.50", "0.007"], ["70631.90", "0.000"], ["70632.30", "0.059"], ["70634.30", "0.659"], ["70636.80", "0.009"], ["70636.90", "0.003"], ["70639.80", "0.005"], ["70644.70", "0.114"], ["70647.20", "0.005"], ["70649.40", "0.011"], ["70651.20", "1.349"], ["70653.00", "0.514"], ["70653.50", "0.641"], ["70653.80", "0.006"], ["70655.40", "0.005"], ["70655.50", "0.110"], ["70658.30", "0.070"], ["70658.80", "0.590"], ["70660.20", "0.000"], ["70660.30", "0.249"], ["70661.20", "0.000"], ["70661.90", "0.020"], ["70663.50", "0.000"], ["70670.80", "0.001"], ["70682.00", "0.372"], ["70684.60", "0.206"], ["70691.00", "0.000"], ["70761.90", "0.009"], ["70839.30", "0.038"], ["71267.70", "0.007"], ["71335.50", "0.000"], ["71340.70", "6.230"], ["71446.60", "0.530"], ["72044.70", "0.017"], ["75280.80", "0.002"], ["89523.20", "0.000"]]}}
{"local_ts": 1773486711816, "server_ts": 1773486711784, "data": {"e": "depthUpdate", "E": 1773486711787, "T": 1773486711784, "s": "BTCUSDT", "U": 10109519987048, "u": 10109519990854, "pu": 10109519987024, "b": [["1000.00", "26.292"], ["5000.00", "101.418"], ["7063.00", "0.252"], ["20429.10", "1.650"], ["20529.10", "1.350"], ["33000.00", "3.785"], ["69922.80", "1.071"], ["70206.70", "0.000"], ["70312.20", "0.000"], ["70389.60", "0.000"], ["70452.70", "0.000"], ["70453.10", "2.886"], ["70459.60", "0.264"], ["70463.10", "0.624"], ["70478.60", "0.000"], ["70481.50", "0.018"], ["70491.90", "0.833"], ["70517.20", "0.845"], ["70517.30", "0.222"], ["70524.20", "0.000"], ["70524.30", "0.202"], ["70538.40", "0.003"], ["70538.50", "0.200"], ["70539.50", "0.060"], ["70540.80", "0.004"], ["70546.20", "0.000"], ["70547.50", "0.202"], ["70548.50", "0.000"], ["70548.90", "0.076"], ["70549.20", "0.000"], ["70564.50", "2.656"], ["70566.60", "0.002"], ["70567.30", "0.118"], ["70569.00", "0.068"], ["70569.70", "1.219"], ["70571.00", "0.846"], ["70571.70", "0.108"], ["70571.80", "0.010"], ["70572.10", "0.000"], ["70572.40", "0.002"], ["70572.50", "0.003"], ["70572.80", "0.417"], ["70573.20", "0.016"], ["70573.50", "0.009"], ["70596.10", "0.553"], ["70596.20", "0.003"], ["70596.40", "0.951"], ["70596.60", "0.019"], ["70596.70", "0.001"], ["70596.80", "0.100"], ["70600.20", "0.559"], ["70600.80", "0.081"], ["70616.90", "0.003"], ["70618.30", "0.072"], ["70618.50", "0.262"], ["70618.70", "0.146"], ["70620.40", "0.006"], ["70620.70", "0.113"], ["70621.00", "0.008"], ["70621.10", "0.000"], ["70621.40", "0.207"], ["70621.80", "0.273"], ["70622.10", "1.615"], ["70623.80", "0.142"]], "a": [["70629.20", "8.666"], ["70629.50", "0.005"], ["70634.00", "0.004"], ["70636.40", "0.004"], ["70638.20", "0.004"], ["70638.40", "0.006"], ["70639.80", "0.002"], ["70640.20", "0.014"], ["70640.50", "0.968"], ["70640.90", "0.002"], ["70641.20", "0.002"], ["70641.30", "0.072"], ["70641.60", "0.006"], ["70641.70", "0.040"], ["70641.90", "0.026"], ["70664.50", "1.951"], ["70664.60", "0.021"], ["70664.80", "0.487"], ["70665.20", "0.002"], ["70665.50", "0.005"], ["70665.90", "0.000"], ["70666.00", "0.340"], ["70666.10", "0.594"], ["70666.20", "1.387"], ["70666.40", "0.161"], ["70668.40", "0.038"], ["70668.60", "0.002"], ["70688.80", "0.302"], ["70689.10", "0.008"], ["70689.50", "0.401"], ["70689.80", "0.517"], ["70690.20", "0.000"], ["70690.30", "0.055"], ["70690.50", "0.250"], ["70690.60", "0.026"], ["70691.30", "0.102"], ["70694.90", "0.005"], ["70695.70", "0.390"], ["70760.30", "0.297"], ["70783.40", "0.018"], ["70797.10", "0.092"], ["70799.10", "0.966"], ["70799.20", "0.002"], ["70878.90", "0.011"], ["70956.80", "0.084"], ["71063.30", "0.000"], ["71335.50", "0.000"], ["71619.90", "0.976"], ["71731.50", "0.102"], ["72789.60", "0.012"], ["74173.40", "0.000"], ["74194.00", "0.052"], ["89523.20", "0.000"]]}}
{"local_ts": 1773486712841, "server_ts": 1773486712808, "data": {"e": "depthUpdate", "E": 1773486712809, "T": 1773486712808, "s": "BTCUSDT", "U": 10109520057902, "u": 10109520091578, "pu": 10109520057880, "b": [["5000.00", "101.418"], ["7062.30", "0.056"], ["7063.00", "0.252"], ["20322.80", "0.180"], ["20322.90", "0.010"], ["20324.50", "0.020"], ["20326.30", "0.250"], ["20429.10", "1.800"], ["67062.50", "0.033"], ["67079.50", "0.002"], ["67100.50", "0.019"], ["69210.40", "0.005"], ["69210.50", "0.024"], ["69213.80", "0.011"], ["69916.60", "0.015"], ["69916.70", "0.000"], ["69918.30", "0.006"], ["69920.00", "0.182"], ["70234.70", "0.002"], ["70269.70", "0.106"], ["70276.00", "0.095"], ["70278.00", "0.090"], ["70279.50", "0.000"], ["70358.10", "0.108"], ["70374.10", "2.269"], ["70405.50", "0.000"], ["70406.10", "0.585"], ["70406.80", "16.538"], ["70415.40", "0.260"], ["70416.40", "1.179"], ["70418.60", "0.005"], ["70422.10", "0.003"], ["70423.70", "0.065"], ["70438.60", "0.002"], ["70439.80", "0.846"], ["70441.10", "0.128"], ["70448.00", "1.315"], ["70451.40", "0.002"], ["70451.50", "0.060"], ["70451.80", "0.008"], ["70456.90", "0.096"], ["70459.00", "0.098"], ["70461.40", "44.013"], ["70465.50", "0.120"], ["70468.00", "0.194"], ["70468.90", "0.000"], ["70469.00", "0.010"], ["70469.40", "0.520"], ["70470.50", "0.192"], ["70471.90", "0.102"], ["70472.00", "1.831"], ["70473.70", "0.096"], ["70473.80", "0.002"], ["70474.10", "0.085"], ["70474.20", "0.005"], ["70479.20", "2.067"], ["70485.60", "0.144"], ["70495.70", "2.085"], ["70501.90", "0.003"], ["70502.40", "0.094"], ["70504.50", "0.035"], ["70505.30", "0.515"], ["70505.50", "0.002"], ["70507.30", "0.172"], ["70511.30", "0.513"], ["70512.60", "0.000"], ["70513.20", "0.248"], ["70513.90", "0.085"], ["70515.10", "0.513"], ["70515.40", "0.004"], ["70517.20", "0.873"], ["70519.50", "0.046"], ["70519.60", "0.000"], ["70520.00", "1.286"], ["70522.50", "0.002"], ["70523.90", "2.000"], ["70529.50", "0.144"], ["70530.50", "0.002"], ["70531.00", "1.697"], ["70531.40", "0.699"], ["70532.00", "0.495"], ["70533.70", "0.226"], ["70534.20", "0.002"], ["70535.30", "0.000"], ["70536.50", "0.144"], ["70538.10", "1.502"], ["70539.50", "0.084"], ["70540.90", "0.003"], ["70541.10", "0.022"], ["70541.70", "0.163"], ["70542.00", "0.702"], ["70542.90", "0.280"], ["70543.60", "0.144"], ["70545.10", "1.072"], ["70546.80", "0.167"], ["70548.00", "0.002"], ["70548.20", "0.317"], ["70548.50", "0.003"], ["70548.70", "0.294"], ["70548.90", "0.003"], ["70550.20", "0.116"], ["70550.50", "0.000"], ["70550.60", "0.003"], ["70551.40", "0.007"], ["70551.70", "0.000"], ["70552.20", "1.060"], ["70552.70", "1.044"], ["70553.20", "0.959"], ["70554.10", "0.095"], ["70554.20", "0.000"], ["70554.50", "0.002"], ["70555.00", "0.004"], ["70555.10", "0.031"], ["70555.60", "0.000"], ["70555.70", "0.000"], ["70555.80", "0.043"], ["70556.50", "0.011"], ["70556.90", "0.794"], ["70557.10", "0.021"], ["70558.70", "0.283"], ["70560.60", "0.002"], ["70561.90", "0.071"], ["70562.20", "0.629"], ["70562.40", "0.279"], ["70564.40", "0.000"], ["70564.70", "2.348"], ["70564.80", "0.968"], ["70565.10", "0.131"], ["70565.70", "0.234"], ["70566.20", "2.831"], ["70566.30", "0.192"], ["70566.40", "0.165"], ["70567.00", "0.520"], ["70567.40", "0.052"], ["70567.50", "0.190"], ["70567.90", "8.581"], ["70568.00", "0.081"], ["70568.20", "0.094"], ["70569.20", "0.074"], ["70569.70", "0.518"], ["70570.00", "0.242"], ["70570.70", "0.009"], ["70570.90", "0.000"], ["70571.20", "0.869"], ["70571.40", "0.393"], ["70571.50", "0.571"], ["70571.60", "0.687"], ["70572.40", "0.000"], ["70573.20", "0.024"], ["70573.40", "0.004"], ["70573.80", "0.775"], ["70574.00", "0.540"], ["70574.40", "0.296"], ["70574.50", "0.005"], ["70574.90", "0.204"], ["70575.10", "0.003"], ["70575.20", "0.016"], ["70575.40", "0.005"], ["70575.50", "0.000"], ["70575.80", "0.059"], ["70575.90", "0.131"], ["70576.10", "0.006"], ["70576.30", "0.091"], ["70576.50", "0.015"], ["70576.60", "0.280"], ["70576.80", "0.083"], ["70577.90", "0.429"], ["70578.40", "0.882"], ["70579.00", "0.013"], ["70579.10", "0.006"], ["70579.20", "0.047"], ["70579.30", "0.383"], ["70579.70", "0.219"], ["70579.80", "0.008"], ["70580.20", "0.071"], ["70580.40", "0.098"], ["70580.50", "0.003"], ["70581.10", "0.213"], ["70581.40", "0.127"], ["70581.90", "0.832"], ["70582.10", "0.003"], ["70582.70", "0.068"], ["70582.80", "0.000"], ["70583.10", "0.396"], ["70583.20", "0.004"], ["70583.30", "0.005"], ["70584.20", "0.082"], ["70584.60", "0.000"], ["70585.20", "0.153"], ["70585.50", "0.023"], ["70585.70", "0.000"], ["70586.00", "0.007"], ["70586.30", "0.006"], ["70586.60", "0.000"], ["70586.80", "0.000"], ["70587.40", "0.033"], ["70588.30", "0.514"], ["70588.50", "0.339"], ["70588.60", "0.101"], ["70589.00", "0.000"], ["70589.20", "0.849"], ["70589.90", "0.491"], ["70590.10", "0.000"], ["70590.40", "0.004"], ["70590.60", "0.276"], ["70590.90", "0.006"], ["70591.60", "0.010"], ["70591.70", "0.003"], ["70591.90", "0.005"], ["70592.10", "0.000"], ["70592.90", "0.254"], ["70593.10", "0.040"], ["70593.30", "0.000"], ["70593.50", "0.538"], ["70593.60", "0.011"], ["70593.70", "0.004"], ["70593.80", "0.060"], ["70593.90", "0.009"], ["70594.20", "0.004"], ["70594.30", "0.000"], ["70594.50", "0.194"], ["70594.60", "0.008"], ["70594.70", "0.008"], ["70594.80", "0.227"], ["70594.90", "0.765"], ["70595.00", "0.010"], ["70595.50", "0.011"], ["70595.60", "0.279"], ["70595.70", "0.047"], ["70595.80", "0.057"], ["70596.20", "0.003"], ["70596.30", "0.095"], ["70596.40", "0.977"], ["70596.70", "0.081"], ["70597.00", "0.007"], ["70597.10", "0.002"], ["70597.20", "0.061"], ["70597.40", "0.008"], ["70597.50", "0.274"], ["70597.60", "0.003"], ["70597.70", "0.000"], ["70597.80", "0.002"], ["70597.90", "0.000"], ["70598.10", "7.790"], ["70598.20", "1.994"], ["70598.30", "0.795"], ["70598.40", "0.007"], ["70598.50", "0.004"], ["70598.60", "0.072"], ["70598.70", "0.000"], ["70598.80", "0.041"], ["70598.90", "0.002"], ["70599.00", "0.054"], ["70599.10", "0.203"], ["70599.20", "0.620"], ["70599.80", "0.034"], ["70599.90", "0.034"], ["70600.00", "0.540"], ["70600.30", "0.008"], ["70600.40", "0.006"], ["70600.60", "0.046"], ["70600.70", "0.181"], ["70600.80", "1.344"], ["70601.00", "0.024"], ["70601.40", "0.344"], ["70601.50", "1.066"], ["70601.60", "0.000"], ["70601.70", "0.219"], ["70601.80", "0.007"], ["70601.90", "0.654"], ["70602.00", "0.294"], ["70602.20", "0.069"], ["70602.40", "0.052"], ["70602.50", "0.204"], ["70602.70", "0.004"], ["70602.80", "0.017"], ["70602.90", "0.021"], ["70603.00", "0.001"], ["70603.40", "0.031"], ["70603.60", "0.005"], ["70603.70", "0.046"], ["70603.80", "0.024"], ["70604.00", "0.893"], ["70604.10", "0.007"], ["70604.30", "0.497"], ["70604.40", "0.058"], ["70604.60", "0.262"], ["70604.70", "0.399"], ["70604.80", "0.514"], ["70604.90", "0.027"], ["70605.10", "0.618"], ["70605.20", "0.931"], ["70605.40", "0.004"], ["70605.60", "0.037"], ["70605.80", "0.072"], ["70606.10", "0.040"], ["70606.30", "0.035"], ["70606.40", "0.123"], ["70606.60", "0.005"], ["70606.70", "0.003"], ["70607.00", "0.008"], ["70607.30", "0.000"], ["70607.40", "0.009"], ["70607.60", "1.059"], ["70607.70", "0.005"], ["70607.80", "0.154"], ["70607.90", "0.208"], ["70608.00", "0.004"], ["70608.10", "0.003"], ["70608.40", "0.003"], ["70608.60", "0.647"], ["70608.70", "1.126"], ["70608.80", "0.606"], ["70608.90", "0.000"], ["70609.00", "0.299"], ["70609.10", "0.000"], ["70609.20", "0.057"], ["70609.30", "0.303"], ["70609.40", "0.009"], ["70609.60", "0.004"], ["70609.70", "0.004"], ["70609.80", "0.003"], ["70609.90", "0.008"], ["70610.20", "0.018"], ["70610.30", "0.004"], ["70610.40", "0.456"], ["70610.60", "0.014"], ["70610.70", "0.003"], ["70611.00", "0.012"], ["70611.10", "0.003"], ["70611.40", "0.189"], ["70611.50", "0.267"], ["70611.60", "0.000"], ["70611.70", "0.004"], ["70612.20", "0.393"], ["70612.50", "0.006"], ["70612.60", "0.229"], ["70612.70", "0.143"], ["70612.80", "0.116"], ["70612.90", "0.005"], ["70613.00", "0.240"], ["70613.10", "0.456"], ["70613.30", "0.003"], ["70613.40", "0.023"], ["70613.50", "0.003"], ["70613.60", "0.005"], ["70613.70", "0.000"], ["70613.80", "0.006"], ["70613.90", "0.000"], ["70614.20", "0.213"], ["70614.50", "1.066"], ["70614.70", "0.004"], ["70614.90", "0.004"], ["70615.10", "0.000"], ["70615.20", "0.000"], ["70615.50", "0.201"], ["70615.60", "0.023"], ["70615.70", "0.005"], ["70615.90", "0.002"], ["70616.40", "0.010"], ["70616.50", "0.000"], ["70616.60", "0.002"], ["70616.70", "0.000"], ["70616.90", "0.000"], ["70617.20", "0.134"], ["70617.50", "0.025"], ["70617.70", "0.000"], ["70617.80", "0.008"], ["70617.90", "0.002"], ["70618.00", "0.002"], ["70618.50", "0.261"], ["70618.60", "0.075"], ["70618.90", "0.010"], ["70619.00", "0.128"], ["70619.10", "0.004"], ["70619.20", "0.008"], ["70619.50", "0.111"], ["70619.60", "0.001"], ["70619.80", "0.003"], ["70620.00", "0.009"], ["70620.20", "0.000"], ["70620.30", "0.008"], ["70620.40", "0.003"], ["70620.50", "0.000"], ["70620.60", "0.003"], ["70620.70", "0.111"], ["70620.90", "0.001"], ["70621.00", "0.004"], ["70621.20", "0.003"], ["70621.30", "0.001"], ["70621.40", "0.082"], ["70621.50", "0.002"], ["70621.60", "0.001"], ["70621.80", "0.000"], ["70622.00", "0.127"], ["70622.10", "0.008"], ["70622.50", "0.001"], ["70622.60", "0.002"], ["70622.80", "0.135"], ["70622.90", "0.000"], ["70623.00", "0.000"], ["70623.10", "0.000"], ["70623.40", "0.000"], ["70623.50", "0.000"], ["70623.70", "0.000"], ["70623.80", "0.000"], ["70624.00", "0.000"], ["70624.20", "0.000"], ["70624.40", "0.000"], ["70624.50", "0.000"], ["70624.80", "0.000"], ["70624.90", "0.000"], ["70625.00", "0.000"], ["70625.10", "0.000"], ["70625.30", "0.000"], ["70625.50", "0.000"], ["70625.60", "0.000"], ["70625.80", "0.000"], ["70625.90", "0.000"], ["70626.00", "0.000"], ["70626.10", "0.000"], ["70626.20", "0.000"], ["70626.30", "0.000"]], "a": [["70622.90", "11.146"], ["70623.00", "0.433"], ["70623.10", "0.000"], ["70623.20", "0.002"], ["70623.30", "0.002"], ["70623.40", "0.000"], ["70623.50", "0.000"], ["70623.60", "0.121"], ["70623.70", "0.000"], ["70623.80", "0.000"], ["70623.90", "0.000"], ["70624.10", "0.000"], ["70624.30", "0.000"], ["70624.40", "0.002"], ["70624.50", "0.004"], ["70624.60", "0.439"], ["70624.70", "0.000"], ["70624.90", "0.000"], ["70625.00", "0.002"], ["70625.10", "0.000"], ["70625.20", "0.000"], ["70625.40", "0.003"], ["70625.60", "0.062"], ["70625.70", "0.000"], ["70625.80", "0.069"], ["70625.90", "0.000"], ["70626.00", "0.003"], ["70626.10", "0.000"], ["70626.20", "0.008"], ["70626.30", "0.002"], ["70626.40", "0.036"], ["70626.50", "0.240"], ["70626.80", "0.003"], ["70627.00", "0.002"], ["70627.40", "0.003"], ["70627.50", "0.002"], ["70627.90", "0.061"], ["70628.00", "0.014"], ["70628.20", "0.001"], ["70628.40", "0.012"], ["70628.60", "0.049"], ["70629.00", "0.457"], ["70629.10", "0.059"], ["70629.20", "0.722"], ["70629.70", "0.021"], ["70629.80", "0.001"], ["70629.90", "0.007"], ["70630.00", "0.008"], ["70630.10", "0.001"], ["70630.80", "0.079"], ["70631.20", "0.057"], ["70631.40", "0.030"], ["70631.50", "0.001"], ["70631.60", "0.083"], ["70631.70", "0.000"], ["70631.80", "0.004"], ["70632.10", "0.105"], ["70632.20", "0.003"], ["70632.40", "0.005"], ["70632.60", "0.000"], ["70633.20", "0.029"], ["70633.30", "0.000"], ["70633.40", "0.018"], ["70633.50", "0.008"], ["70633.60", "0.007"], ["70633.70", "0.024"], ["70633.90", "0.117"], ["70634.00", "0.007"], ["70634.20", "0.718"], ["70634.30", "1.582"], ["70634.70", "0.013"], ["70634.80", "0.704"], ["70635.10", "0.142"], ["70635.20", "0.004"], ["70635.30", "0.049"], ["70635.90", "0.009"], ["70636.40", "0.004"], ["70636.80", "0.032"], ["70636.90", "0.014"], ["70637.00", "0.653"], ["70637.10", "0.027"], ["70637.20", "0.032"], ["70637.50", "1.188"], ["70637.70", "0.040"], ["70637.80", "0.010"], ["70637.90", "0.000"], ["70638.00", "0.078"], ["70638.10", "0.016"], ["70638.60", "0.006"], ["70638.70", "0.011"], ["70639.30", "0.012"], ["70639.60", "0.007"], ["70639.70", "0.026"], ["70640.00", "0.201"], ["70640.20", "0.519"], ["70640.40", "0.009"], ["70640.50", "0.843"], ["70640.70", "0.002"], ["70641.20", "0.002"], ["70641.30", "0.097"], ["70641.50", "0.074"], ["70641.60", "0.006"], ["70642.00", "0.005"], ["70642.20", "0.636"], ["70642.60", "0.003"], ["70642.80", "0.002"], ["70643.70", "0.005"], ["70644.00", "0.259"], ["70644.30", "0.036"], ["70644.40", "0.014"], ["70644.70", "0.076"], ["70645.00", "0.159"], ["70645.10", "0.000"], ["70645.50", "0.109"], ["70645.60", "0.011"], ["70645.70", "0.086"], ["70645.80", "0.622"], ["70645.90", "1.602"], ["70646.50", "0.005"], ["70647.50", "0.006"], ["70647.60", "0.003"], ["70647.70", "0.004"], ["70647.90", "0.001"], ["70648.10", "0.000"], ["70648.20", "0.059"], ["70648.50", "0.000"], ["70649.40", "0.352"], ["70649.50", "0.797"], ["70649.80", "0.105"], ["70650.40", "0.083"], ["70650.50", "0.004"], ["70651.00", "0.011"], ["70651.10", "0.523"], ["70651.40", "0.005"], ["70651.50", "0.020"], ["70651.70", "0.003"], ["70651.80", "0.013"], ["70652.30", "0.429"], ["70652.40", "0.199"], ["70652.50", "0.035"], ["70652.80", "0.012"], ["70653.10", "5.015"], ["70653.20", "0.458"], ["70653.50", "0.009"], ["70653.80", "0.000"], ["70653.90", "0.002"], ["70654.10", "2.193"], ["70654.50", "0.312"], ["70654.60", "0.005"], ["70654.80", "0.891"], ["70655.00", "0.002"], ["70655.20", "0.002"], ["70655.30", "0.000"], ["70655.90", "0.005"], ["70656.00", "0.265"], ["70656.60", "0.000"], ["70656.70", "0.018"], ["70657.10", "0.004"], ["70657.30", "0.005"], ["70657.40", "0.010"], ["70657.70", "0.000"], ["70657.80", "0.004"], ["70658.50", "0.010"], ["70658.70", "0.752"], ["70660.00", "0.037"], ["70660.90", "0.040"], ["70661.00", "0.003"], ["70661.40", "0.521"], ["70661.80", "0.006"], ["70662.30", "0.353"], ["70663.50", "0.000"], ["70665.00", "0.716"], ["70665.30", "0.065"], ["70665.60", "0.025"], ["70666.10", "0.598"], ["70666.90", "0.003"], ["70667.00", "0.024"], ["70667.30", "0.002"], ["70668.50", "0.002"], ["70668.80", "0.311"], ["70669.10", "1.183"], ["70669.40", "0.082"], ["70670.50", "0.000"], ["70671.50", "0.182"], ["70672.20", "0.002"], ["70672.30", "0.155"], ["70672.40", "2.001"], ["70672.50", "1.083"], ["70672.80", "0.010"], ["70673.20", "0.068"], ["70673.40", "0.003"], ["70673.90", "0.036"], ["70674.20", "0.000"], ["70674.30", "0.003"], ["70674.60", "0.004"], ["70675.30", "0.033"], ["70675.80", "0.075"], ["70676.00", "0.311"], ["70676.60", "0.166"], ["70679.30", "0.144"], ["70679.40", "0.524"], ["70679.70", "0.002"], ["70681.80", "0.110"], ["70682.00", "0.366"], ["70682.20", "0.004"], ["70682.30", "0.013"], ["70682.70", "0.000"], ["70683.00", "0.032"], ["70683.80", "0.087"], ["70683.90", "0.103"], ["70684.70", "8.489"], ["70685.00", "0.201"], ["70685.60", "1.550"], ["70686.60", "0.221"], ["70686.80", "0.029"], ["70687.20", "0.542"], ["70687.50", "0.004"], ["70688.00", "1.432"], ["70688.40", "0.085"], ["70688.90", "0.113"], ["70689.30", "0.002"], ["70689.90", "1.234"], ["70690.30", "0.220"], ["70690.90", "3.577"], ["70691.40", "0.211"], ["70692.50", "0.003"], ["70693.50", "1.006"], ["70696.30", "0.193"], ["70696.40", "0.516"], ["70696.50", "0.133"], ["70697.00", "0.004"], ["70697.10", "0.106"], ["70698.20", "0.011"], ["70698.60", "0.286"], ["70698.80", "0.000"], ["70699.00", "0.301"], ["70699.20", "0.774"], ["70699.90", "1.174"], ["70700.10", "0.142"], ["70700.60", "1.069"], ["70701.10", "0.047"], ["70701.30", "0.000"], ["70704.00", "0.011"], ["70704.80", "0.212"], ["70706.40", "0.034"], ["70706.70", "0.016"], ["70707.20", "0.159"], ["70707.60", "1.731"], ["70709.90", "0.511"], ["70710.00", "0.099"], ["70710.50", "0.096"], ["70711.30", "10.159"], ["70712.40", "0.003"], ["70714.20", "0.178"], ["70714.70", "1.593"], ["70716.80", "0.016"], ["70718.40", "0.003"], ["70719.30", "0.165"], ["70720.50", "0.075"], ["70720.90", "0.026"], ["70721.80", "2.000"], ["70723.70", "2.511"], ["70724.70", "1.364"], ["70725.20", "0.071"], ["70725.40", "0.073"], ["70725.90", "7.051"], ["70726.00", "0.422"], ["70727.00", "0.074"], ["70727.40", "0.365"], ["70730.70", "0.006"], ["70731.60", "0.010"], ["70731.90", "0.022"], ["70734.30", "10.048"], ["70734.50", "0.005"], ["70734.90", "0.790"], ["70737.60", "0.222"], ["70737.90", "0.184"], ["70738.70", "0.012"], ["70738.80", "0.045"], ["70739.30", "0.000"], ["70739.40", "0.000"], ["70739.50", "0.000"], ["70742.90", "0.004"], ["70743.80", "0.004"], ["70746.30", "0.514"], ["70748.50", "0.104"], ["70750.00", "24.040"], ["70750.90", "0.217"], ["70751.10", "0.000"], ["70752.50", "0.004"], ["70756.70", "0.000"], ["70756.80", "0.000"], ["70757.20", "0.000"], ["70759.70", "2.011"], ["70762.20", "0.044"], ["70762.70", "0.150"], ["70764.80", "0.024"], ["70765.00", "2.041"], ["70765.10", "0.000"], ["70767.10", "0.000"], ["70768.60", "0.000"], ["70769.20", "0.043"], ["70769.30", "0.005"], ["70771.00", "0.002"], ["70771.10", "0.356"], ["70774.70", "0.102"], ["70778.30", "0.000"], ["70781.00", "10.076"], ["70784.80", "12.468"], ["70785.40", "0.002"], ["70786.10", "0.050"], ["70792.40", "0.247"], ["70794.00", "0.000"], ["70794.10", "0.002"], ["70795.20", "4.295"], ["70795.90", "0.345"], ["70810.90", "0.190"], ["70812.10", "10.000"], ["70815.10", "2.521"], ["70815.70", "0.000"], ["70815.80", "0.002"], ["70819.50", "0.122"], ["70831.00", "6.483"], ["70834.40", "0.022"], ["70840.90", "3.081"], ["70843.10", "0.276"], ["70843.20", "10.000"], ["70852.60", "0.000"], ["70857.50", "2.828"], ["70857.60", "0.117"], ["70871.70", "0.004"], ["70872.90", "0.000"], ["70887.70", "0.005"], ["70887.80", "0.000"], ["70889.10", "8.230"], ["70891.40", "0.004"], ["70907.30", "1.854"], ["70908.20", "10.000"], ["70924.70", "0.277"], ["70952.10", "0.000"], ["70952.20", "0.008"], ["71329.10", "0.000"], ["71329.20", "0.000"], ["71330.70", "0.000"], ["71330.80", "0.000"], ["71332.70", "0.000"], ["71624.50", "0.016"], ["71634.40", "0.000"], ["71634.80", "0.000"], ["71724.00", "1.324"], ["72035.30", "0.006"], ["72412.50", "2.483"], ["72436.30", "0.008"], ["73072.30", "0.083"], ["73107.70", "0.000"], ["74167.80", "0.018"], ["89523.20", "0.000"]]}}
{"local_ts": 1773486713857, "server_ts": 1773486713828, "data": {"e": "depthUpdate", "E": 1773486713829, "T": 1773486713828, "s": "BTCUSDT", "U": 10109520178940, "u": 10109520186115, "pu": 10109520178923, "b": [["1000.00", "26.292"], ["5000.00", "101.418"], ["7062.30", "0.056"], ["20222.60", "0.600"], ["20326.30", "0.230"], ["20326.40", "0.000"], ["20329.10", "0.000"], ["33000.00", "3.789"], ["56503.00", "0.000"], ["67076.30", "0.002"], ["69439.10", "0.000"], ["69644.00", "0.070"], ["69916.40", "0.002"], ["69916.50", "0.000"], ["70295.80", "0.274"], ["70376.30", "0.000"], ["70449.60", "0.159"], ["70460.80", "0.036"], ["70472.30", "1.679"], ["70531.80", "0.002"], ["70553.20", "0.959"], ["70567.30", "0.153"], ["70569.00", "0.422"], ["70571.60", "0.011"], ["70581.90", "1.257"], ["70585.50", "0.003"], ["70587.30", "0.006"], ["70587.60", "0.275"], ["70594.20", "0.024"], ["70600.20", "0.395"], ["70600.70", "0.077"], ["70603.20", "0.146"], ["70604.90", "0.723"], ["70605.80", "0.002"], ["70606.30", "0.000"], ["70606.40", "0.125"], ["70610.20", "0.243"], ["70612.00", "0.086"], ["70615.50", "0.507"], ["70616.80", "0.061"], ["70617.30", "0.000"], ["70617.70", "0.007"], ["70618.00", "0.002"], ["70618.40", "0.001"], ["70619.00", "0.022"], ["70619.40", "0.002"], ["70619.50", "0.011"], ["70620.10", "0.003"], ["70620.60", "0.003"], ["70620.70", "0.021"], ["70620.80", "0.021"], ["70621.00", "0.007"], ["70622.50", "0.000"], ["70622.60", "0.221"]], "a": [["70622.70", "8.982"], ["70622.90", "0.132"], ["70623.00", "0.140"], ["70623.40", "0.000"], ["70626.00", "0.004"], ["70626.50", "0.262"], ["70628.50", "0.000"], ["70629.60", "0.073"], ["70629.80", "0.004"], ["70630.50", "0.001"], ["70631.60", "0.016"], ["70631.80", "0.004"], ["70633.30", "0.000"], ["70634.10", "0.043"], ["70634.20", "0.588"], ["70634.30", "0.005"], ["70637.50", "0.003"], ["70637.70", "0.004"], ["70638.60", "0.117"], ["70638.90", "1.171"], ["70643.40", "0.636"], ["70645.30", "0.112"], ["70645.70", "0.091"], ["70647.80", "0.038"], ["70648.40", "0.006"], ["70649.80", "0.126"], ["70651.20", "1.462"], ["70656.20", "0.000"], ["70658.00", "0.036"], ["70659.20", "0.006"], ["70661.30", "0.000"], ["70666.00", "0.486"], ["70669.40", "0.080"], ["70669.80", "0.598"], ["70670.90", "0.038"], ["70679.20", "0.986"], ["70680.60", "0.292"], ["70696.90", "0.198"], ["70716.20", "0.054"], ["70765.60", "0.005"], ["70775.50", "0.093"], ["70795.70", "0.126"], ["70852.30", "0.000"], ["71328.90", "0.004"], ["72035.10", "0.005"], ["74182.60", "0.006"], ["89523.20", "0.000"]]}}
{"local_ts": 1773486714881, "server_ts": 1773486714852, "data": {"e": "depthUpdate", "E": 1773486714853, "T": 1773486714852, "s": "BTCUSDT", "U": 10109520238653, "u": 10109520242883, "pu": 10109520238576, "b": [["5000.00", "101.418"], ["7062.30", "0.056"], ["20122.60", "0.370"], ["20222.60", "2.580"], ["20322.60", "0.050"], ["63560.30", "0.002"], ["67100.50", "0.015"], ["69916.40", "0.000"], ["70307.00", "0.254"], ["70375.70", "0.002"], ["70453.10", "0.255"], ["70453.20", "0.000"], ["70514.40", "1.125"], ["70567.30", "3.588"], ["70569.00", "0.068"], ["70586.00", "0.005"], ["70588.60", "1.904"], ["70597.80", "0.002"], ["70597.90", "0.085"], ["70602.70", "0.102"], ["70604.90", "0.778"], ["70608.80", "0.941"], ["70612.00", "0.002"], ["70618.90", "0.013"], ["70620.30", "0.008"]], "a": [["70622.70", "6.296"], ["70628.90", "0.063"], ["70630.00", "0.219"], ["70630.30", "0.006"], ["70633.30", "0.003"], ["70633.50", "0.008"], ["70659.90", "1.867"], ["70681.20", "3.430"], ["70693.30", "0.108"], ["70696.90", "0.092"], ["70847.30", "0.007"], ["71328.80", "0.000"], ["71328.90", "0.002"], ["72405.30", "2.482"], ["74184.30", "0.012"], ["77685.00", "0.002"], ["89523.20", "0.000"], ["115844.00", "0.000"]]}}
