{"local_ts": 1773237571715, "server_ts": 1773237571521, "data": {"e": "depthUpdate", "E": 1773237571522, "T": 1773237571521, "s": "BTCUSDT", "U": 10088623242804, "u": 10088623254078, "pu": 10088623242646, "b": [["1000.00", "26.642"], ["5000.00", "101.418"], ["19618.30", "0.130"], ["19632.40", "0.270"], ["19718.30", "0.460"], ["19932.40", "0.140"], ["20030.40", "0.030"], ["20030.60", "0.000"], ["20032.40", "0.270"], ["33000.00", "10.800"], ["56106.00", "0.000"], ["66625.00", "0.045"], ["66625.70", "0.000"], ["68729.80", "0.003"], ["69100.70", "0.867"], ["69431.10", "1.585"], ["69592.90", "0.032"], ["69831.40", "0.036"], ["69840.40", "0.044"], ["69943.70", "13.011"], ["69953.00", "0.000"], ["69957.30", "0.054"], ["70006.00", "7.109"], ["70008.70", "0.000"], ["70010.70", "0.014"], ["70027.80", "0.160"], ["70028.60", "0.159"], ["70036.80", "0.002"], ["70041.00", "0.235"], ["70041.40", "7.361"], ["70043.40", "0.002"], ["70044.10", "3.628"], ["70052.70", "0.042"], ["70055.70", "0.020"], ["70060.10", "0.362"], ["70062.60", "0.284"], ["70063.40", "0.002"], ["70064.40", "0.313"], ["70065.50", "0.020"], ["70068.00", "1.886"], ["70069.00", "0.321"], ["70079.50", "0.001"], ["70080.70", "0.043"], ["70085.10", "0.046"], ["70088.60", "0.075"], ["70089.10", "0.075"], ["70091.20", "0.192"], ["70097.20", "0.250"], ["70100.10", "0.004"], ["70100.70", "0.005"], ["70100.80", "0.004"], ["70101.40", "0.000"], ["70102.40", "0.006"], ["70106.00", "0.214"], ["70106.20", "0.007"], ["70106.40", "0.007"], ["70107.00", "0.073"], ["70107.40", "0.002"], ["70107.60", "0.004"], ["70107.80", "0.042"], ["70108.30", "0.000"], ["70110.80", "0.061"], ["70111.90", "0.012"], ["70112.20", "0.027"], ["70112.60", "0.000"], ["70114.80", "0.100"], ["70116.00", "0.002"], ["70116.90", "0.004"], ["70117.00", "0.002"], ["70117.40", "0.025"], ["70118.10", "0.518"], ["70118.20", "0.166"], ["70118.60", "0.000"], ["70119.10", "0.011"], ["70119.50", "0.029"], ["70119.70", "0.005"], ["70120.90", "1.028"], ["70122.00", "0.347"], ["70122.50", "0.009"], ["70122.70", "0.002"], ["70122.80", "0.004"], ["70125.30", "0.022"], ["70125.50", "0.152"], ["70125.60", "0.268"], ["70127.50", "0.042"], ["70128.40", "0.044"], ["70128.80", "0.049"], ["70130.50", "0.001"], ["70130.60", "0.027"], ["70131.60", "0.000"], ["70132.30", "0.001"], ["70132.40", "2.935"]], "a": [["70132.50", "4.711"], ["70135.80", "0.049"], ["70136.00", "0.113"], ["70136.10", "0.689"], ["70138.00", "0.094"], ["70140.40", "0.010"], ["70141.90", "0.000"], ["70143.30", "0.002"], ["70143.40", "0.001"], ["70144.00", "0.007"], ["70146.50", "0.519"], ["70148.30", "0.164"], ["70150.00", "0.709"], ["70150.70", "0.000"], ["70150.80", "0.195"], ["70151.00", "0.002"], ["70151.40", "0.096"], ["70151.50", "0.300"], ["70151.70", "0.114"], ["70151.80", "0.067"], ["70151.90", "0.135"], ["70152.20", "0.002"], ["70152.30", "0.017"], ["70153.40", "0.047"], ["70153.50", "1.007"], ["70153.60", "0.608"], ["70154.20", "10.262"], ["70154.50", "0.004"], ["70155.80", "0.015"], ["70157.60", "0.000"], ["70159.10", "0.564"], ["70160.70", "1.148"], ["70161.10", "0.892"], ["70161.50", "0.001"], ["70162.30", "0.000"], ["70164.00", "0.104"], ["70164.60", "0.002"], ["70165.00", "0.423"], ["70169.20", "0.004"], ["70169.90", "0.039"], ["70170.20", "0.002"], ["70170.60", "0.053"], ["70170.80", "0.000"], ["70171.20", "0.095"], ["70171.30", "0.006"], ["70175.00", "0.009"], ["70175.10", "1.883"], ["70177.90", "0.120"], ["70178.40", "0.570"], ["70181.70", "0.000"], ["70184.60", "0.651"], ["70184.80", "0.000"], ["70185.00", "0.035"], ["70186.20", "0.531"], ["70186.70", "0.000"], ["70186.90", "0.003"], ["70188.10", "0.095"], ["70192.80", "0.095"], ["70194.70", "0.002"], ["70195.40", "0.123"], ["70196.60", "0.095"], ["70199.10", "3.733"], ["70201.50", "0.095"], ["70204.30", "1.131"], ["70205.40", "0.091"], ["70207.70", "0.091"], ["70208.00", "0.313"], ["70210.30", "0.511"], ["70213.20", "0.254"], ["70214.10", "0.111"], ["70234.80", "1.721"], ["70236.90", "0.059"], ["70237.20", "6.686"], ["70256.90", "0.000"], ["70257.30", "0.014"], ["70299.20", "12.833"], ["70350.80", "0.308"], ["70388.90", "0.103"], ["70415.90", "0.000"], ["70452.60", "0.000"], ["70671.90", "0.004"], ["70833.80", "0.000"], ["71030.70", "0.348"], ["71140.60", "0.000"], ["71282.30", "1.388"], ["71521.80", "0.000"], ["71941.90", "0.002"], ["89523.20", "0.000"]]}}
{"local_ts": 1773237572739, "server_ts": 1773237572543, "data": {"e": "depthUpdate", "E": 1773237572544, "T": 1773237572543, "s": "BTCUSDT", "U": 10088623308032, "u": 10088623334172, "pu": 10088623307976, "b": [["5000.00", "101.418"], ["19632.40", "0.880"], ["19932.40", "1.450"], ["19935.90", "0.150"], ["20013.50", "0.180"], ["20018.30", "0.200"], ["20021.50", "0.000"], ["20026.20", "0.000"], ["20027.10", "0.000"], ["20029.50", "0.000"], ["20030.40", "0.000"], ["20034.60", "0.010"], ["20035.90", "0.070"], ["40000.00", "51.271"], ["66608.10", "0.002"], ["66920.50", "0.004"], ["67621.70", "0.008"], ["68353.90", "1.207"], ["68912.30", "0.865"], ["69126.20", "0.000"], ["69129.50", "0.006"], ["69135.90", "0.016"], ["69234.40", "0.004"], ["69431.10", "1.583"], ["69432.40", "0.000"], ["69434.50", "0.002"], ["69454.20", "3.565"], ["69500.00", "17.128"], ["69831.60", "0.000"], ["69831.80", "0.151"], ["69835.50", "0.004"], ["69847.30", "0.005"], ["69856.20", "0.444"], ["69860.00", "1.627"], ["69883.30", "1.991"], ["69893.90", "1.269"], ["69894.50", "0.003"], ["69921.20", "0.269"], ["69921.70", "2.050"], ["69940.10", "2.148"], ["69942.70", "0.000"], ["69943.40", "0.045"], ["69943.80", "3.088"], ["69945.80", "0.002"], ["69946.10", "0.004"], ["69946.30", "0.000"], ["69946.90", "1.817"], ["69947.30", "0.000"], ["69956.70", "0.003"], ["69957.30", "0.000"], ["69957.90", "7.869"], ["69958.00", "8.421"], ["69958.10", "0.182"], ["69959.50", "0.091"], ["69966.40", "0.000"], ["69966.60", "0.021"], ["69966.70", "0.190"], ["69966.80", "0.184"], ["69968.60", "0.309"], ["69982.30", "1.055"], ["69985.90", "0.091"], ["69986.90", "0.353"], ["69990.10", "0.008"], ["69990.50", "0.292"], ["69994.60", "0.000"], ["69995.60", "2.303"], ["70001.20", "0.260"], ["70005.00", "0.000"], ["70005.70", "0.113"], ["70005.80", "0.443"], ["70006.10", "2.199"], ["70008.00", "0.000"], ["70008.10", "0.000"], ["70008.60", "0.849"], ["70009.90", "0.731"], ["70012.00", "0.002"], ["70016.50", "0.618"], ["70017.90", "0.029"], ["70018.30", "0.006"], ["70020.30", "0.010"], ["70020.90", "0.000"], ["70021.90", "0.855"], ["70022.70", "0.730"], ["70023.70", "2.002"], ["70024.70", "0.004"], ["70028.60", "0.078"], ["70030.50", "0.043"], ["70030.80", "0.776"], ["70031.40", "0.392"], ["70034.90", "0.558"], ["70035.70", "0.082"], ["70036.70", "0.224"], ["70041.00", "0.204"], ["70041.10", "0.396"], ["70041.50", "2.684"], ["70042.00", "0.412"], ["70043.60", "0.000"], ["70044.20", "0.525"], ["70044.70", "1.910"], ["70046.10", "0.041"], ["70047.50", "0.111"], ["70049.00", "0.074"], ["70049.10", "0.247"], ["70049.90", "0.041"], ["70050.00", "0.880"], ["70050.10", "0.004"], ["70051.70", "0.501"], ["70052.20", "0.000"], ["70052.70", "0.000"], ["70054.30", "0.861"], ["70054.40", "0.000"], ["70054.60", "0.041"], ["70055.30", "0.354"], ["70055.40", "0.046"], ["70055.80", "6.557"], ["70055.90", "1.657"], ["70056.40", "0.000"], ["70056.50", "0.006"], ["70056.80", "1.000"], ["70057.00", "0.003"], ["70058.00", "0.000"], ["70058.60", "0.431"], ["70058.80", "1.000"], ["70059.40", "0.035"], ["70060.30", "0.002"], ["70061.10", "0.000"], ["70061.50", "1.056"], ["70062.30", "0.165"], ["70062.50", "1.188"], ["70062.90", "0.060"], ["70064.90", "0.333"], ["70065.20", "0.023"], ["70065.40", "0.091"], ["70065.70", "0.000"], ["70065.80", "0.087"], ["70066.10", "0.016"], ["70066.80", "0.517"], ["70067.20", "0.235"], ["70068.70", "0.000"], ["70069.10", "0.818"], ["70069.30", "0.231"], ["70069.70", "0.011"], ["70072.30", "0.008"], ["70073.30", "0.002"], ["70073.40", "0.759"], ["70074.20", "0.360"], ["70074.50", "0.105"], ["70074.70", "0.002"], ["70075.70", "0.000"], ["70075.80", "0.661"], ["70076.40", "0.004"], ["70076.80", "0.091"], ["70077.00", "0.014"], ["70078.50", "0.331"], ["70078.90", "0.000"], ["70079.50", "0.465"], ["70079.60", "0.091"], ["70079.80", "0.092"], ["70080.30", "0.003"], ["70080.70", "0.000"], ["70081.00", "0.299"], ["70081.70", "0.000"], ["70082.30", "0.032"], ["70082.40", "0.002"], ["70082.70", "0.000"], ["70083.00", "1.249"], ["70083.10", "0.484"], ["70084.10", "0.020"], ["70084.30", "0.008"], ["70085.70", "0.000"], ["70085.90", "0.008"], ["70086.80", "0.026"], ["70087.40", "0.097"], ["70087.90", "0.095"], ["70088.40", "0.072"], ["70089.00", "0.349"], ["70089.60", "0.000"], ["70090.70", "0.247"], ["70090.80", "0.051"], ["70091.20", "0.286"], ["70091.30", "0.284"], ["70091.90", "0.024"], ["70092.10", "0.372"], ["70093.40", "0.490"], ["70094.30", "0.000"], ["70094.80", "0.000"], ["70095.00", "0.000"], ["70095.60", "0.923"], ["70095.90", "0.527"], ["70096.50", "0.098"], ["70097.10", "0.568"], ["70098.50", "0.117"], ["70099.00", "0.046"], ["70100.70", "0.076"], ["70100.80", "0.000"], ["70101.40", "0.000"], ["70101.70", "0.006"], ["70101.90", "0.008"], ["70102.10", "0.073"], ["70102.60", "0.000"], ["70104.10", "0.000"], ["70104.20", "0.002"], ["70104.30", "0.115"], ["70105.00", "1.321"], ["70105.10", "0.879"], ["70105.80", "0.000"], ["70106.20", "0.000"], ["70106.40", "0.005"], ["70106.90", "0.002"], ["70107.20", "0.002"], ["70107.80", "0.433"], ["70108.20", "0.022"], ["70108.50", "0.498"], ["70108.70", "0.084"], ["70108.80", "0.002"], ["70109.20", "0.516"], ["70109.30", "0.257"], ["70109.80", "0.009"], ["70110.30", "0.006"], ["70110.50", "0.252"], ["70110.60", "0.004"], ["70110.90", "0.005"], ["70111.30", "0.012"], ["70111.40", "0.560"], ["70111.60", "0.510"], ["70111.70", "0.081"], ["70111.80", "0.002"], ["70112.50", "0.000"], ["70112.70", "0.003"], ["70112.80", "0.000"], ["70112.90", "0.000"], ["70113.10", "0.002"], ["70113.20", "0.005"], ["70113.30", "0.001"], ["70113.40", "2.605"], ["70113.50", "0.000"], ["70113.70", "0.682"], ["70113.80", "0.000"], ["70113.90", "0.000"], ["70114.20", "0.007"], ["70114.40", "0.167"], ["70114.50", "0.004"], ["70114.60", "0.025"], ["70114.80", "0.008"], ["70114.90", "0.004"], ["70115.20", "0.057"], ["70115.30", "0.011"], ["70115.40", "0.522"], ["70115.50", "0.073"], ["70115.70", "0.513"], ["70115.80", "0.030"], ["70116.00", "0.014"], ["70116.30", "0.288"], ["70116.70", "0.053"], ["70116.90", "1.025"], ["70117.10", "0.093"], ["70117.20", "0.007"], ["70117.30", "0.009"], ["70117.40", "0.004"], ["70117.60", "1.082"], ["70118.20", "0.005"], ["70118.40", "0.005"], ["70118.90", "0.000"], ["70119.10", "0.004"], ["70119.20", "0.509"], ["70119.50", "0.012"], ["70119.60", "0.071"], ["70119.70", "0.002"], ["70119.80", "0.004"], ["70120.00", "0.004"], ["70120.10", "0.004"], ["70120.60", "0.096"], ["70120.70", "0.000"], ["70120.90", "0.009"], ["70121.00", "0.000"], ["70121.20", "0.000"], ["70121.70", "0.000"], ["70121.80", "0.002"], ["70122.10", "0.000"], ["70122.20", "1.212"], ["70122.30", "0.526"], ["70122.40", "0.001"], ["70122.50", "0.002"], ["70122.70", "0.000"], ["70123.30", "0.007"], ["70123.80", "0.023"], ["70123.90", "1.076"], ["70124.30", "0.011"], ["70124.40", "0.065"], ["70124.60", "0.000"], ["70124.80", "0.090"], ["70124.90", "0.142"], ["70125.00", "0.013"], ["70125.10", "0.004"], ["70125.20", "0.000"], ["70125.30", "0.001"], ["70125.40", "0.061"], ["70125.50", "0.000"], ["70125.60", "0.000"], ["70125.70", "0.004"], ["70125.80", "0.043"], ["70125.90", "0.611"], ["70126.00", "0.442"], ["70126.10", "0.015"], ["70126.20", "0.003"], ["70126.30", "0.021"], ["70126.50", "0.033"], ["70126.60", "0.198"], ["70126.70", "0.004"], ["70126.80", "0.037"], ["70126.90", "0.045"], ["70127.00", "1.000"], ["70127.10", "0.055"], ["70127.30", "0.004"], ["70127.40", "0.026"], ["70127.50", "0.037"], ["70127.90", "0.004"], ["70128.00", "0.009"], ["70128.20", "0.021"], ["70128.40", "0.034"], ["70128.70", "0.002"], ["70128.80", "0.011"], ["70128.90", "0.274"], ["70129.00", "0.000"], ["70129.10", "0.268"], ["70129.20", "0.047"], ["70129.40", "0.020"], ["70129.50", "0.004"], ["70129.60", "0.002"], ["70129.80", "0.000"], ["70130.40", "0.006"], ["70130.50", "0.001"], ["70130.60", "0.006"], ["70131.00", "0.038"], ["70131.10", "0.128"], ["70131.20", "0.035"], ["70131.40", "0.004"], ["70131.60", "0.023"], ["70131.70", "0.008"], ["70131.80", "0.002"], ["70132.00", "0.000"], ["70132.10", "0.006"], ["70132.30", "0.001"], ["70132.40", "0.016"], ["70132.50", "1.100"], ["70132.60", "0.207"], ["70132.70", "0.000"], ["70132.80", "0.006"], ["70132.90", "0.000"], ["70133.00", "0.039"], ["70133.10", "0.000"], ["70133.20", "0.000"], ["70133.30", "0.000"], ["70133.40", "0.000"], ["70133.50", "0.004"], ["70133.60", "0.000"], ["70133.70", "0.001"], ["70133.80", "0.102"], ["70133.90", "0.002"], ["70134.10", "0.004"], ["70134.20", "0.000"], ["70134.40", "0.002"], ["70134.50", "0.000"], ["70134.60", "0.037"], ["70134.70", "0.000"], ["70134.80", "0.002"], ["70134.90", "0.000"], ["70135.10", "0.049"], ["70135.20", "0.000"], ["70135.30", "0.000"], ["70135.60", "0.099"], ["70135.70", "0.002"], ["70135.80", "0.549"], ["70135.90", "8.407"]], "a": [["70132.50", "0.000"], ["70132.70", "0.000"], ["70133.00", "0.000"], ["70133.30", "0.000"], ["70133.40", "0.000"], ["70133.50", "0.000"], ["70133.70", "0.000"], ["70133.80", "0.000"], ["70134.30", "0.000"], ["70134.60", "0.000"], ["70134.70", "0.000"], ["70134.80", "0.000"], ["70134.90", "0.000"], ["70135.00", "0.000"], ["70135.20", "0.000"], ["70135.30", "0.000"], ["70135.40", "0.000"], ["70135.70", "0.000"], ["70135.80", "0.000"], ["70136.00", "2.599"], ["70136.10", "0.686"], ["70136.20", "0.000"], ["70136.30", "0.000"], ["70136.50", "0.000"], ["70136.90", "0.002"], ["70137.00", "0.000"], ["70137.10", "0.006"], ["70137.20", "0.021"], ["70137.30", "0.000"], ["70137.40", "0.000"], ["70137.50", "0.000"], ["70137.80", "0.000"], ["70137.90", "0.004"], ["70138.20", "0.002"], ["70138.30", "7.134"], ["70138.40", "0.003"], ["70138.50", "0.005"], ["70139.10", "0.000"], ["70139.30", "0.007"], ["70139.60", "0.005"], ["70139.90", "0.004"], ["70140.10", "0.004"], ["70140.80", "0.000"], ["70140.90", "0.004"], ["70141.20", "0.002"], ["70141.90", "0.025"], ["70142.10", "0.049"], ["70142.30", "0.008"], ["70142.80", "0.105"], ["70143.30", "0.002"], ["70143.60", "0.087"], ["70143.70", "0.086"], ["70144.30", "0.006"], ["70144.60", "0.213"], ["70145.20", "0.094"], ["70145.40", "0.008"], ["70145.80", "0.009"], ["70146.20", "0.000"], ["70146.30", "0.004"], ["70146.50", "0.001"], ["70146.90", "0.011"], ["70147.10", "0.005"], ["70147.20", "0.002"], ["70147.30", "0.005"], ["70147.50", "0.004"], ["70147.60", "0.200"], ["70147.70", "0.006"], ["70148.10", "0.002"], ["70148.30", "0.002"], ["70148.40", "0.006"], ["70148.50", "0.000"], ["70148.80", "0.006"], ["70148.90", "0.000"], ["70149.70", "0.002"], ["70149.80", "0.002"], ["70149.90", "0.433"], ["70150.00", "1.088"], ["70150.30", "0.007"], ["70150.40", "0.000"], ["70150.80", "0.167"], ["70151.00", "0.286"], ["70151.10", "0.670"], ["70151.20", "0.320"], ["70151.40", "1.101"], ["70151.50", "0.184"], ["70151.60", "1.694"], ["70151.70", "0.043"], ["70151.90", "0.132"], ["70152.30", "0.004"], ["70152.60", "0.230"], ["70152.80", "0.000"], ["70153.20", "0.347"], ["70153.30", "1.655"], ["70153.40", "0.000"], ["70153.50", "0.000"], ["70153.60", "0.092"], ["70153.70", "0.293"], ["70154.00", "0.616"], ["70154.10", "0.009"], ["70154.20", "0.003"], ["70154.30", "0.001"], ["70154.60", "0.009"], ["70154.70", "0.003"], ["70155.00", "0.664"], ["70155.20", "0.376"], ["70155.90", "0.007"], ["70156.00", "0.103"], ["70156.10", "0.008"], ["70156.20", "0.000"], ["70156.30", "0.000"], ["70156.80", "0.004"], ["70156.90", "0.002"], ["70157.20", "0.514"], ["70157.30", "1.214"], ["70157.50", "0.017"], ["70157.70", "0.014"], ["70158.20", "0.008"], ["70158.30", "0.587"], ["70158.50", "0.004"], ["70158.70", "0.000"], ["70158.90", "0.007"], ["70159.30", "0.043"], ["70159.40", "0.514"], ["70159.50", "0.381"], ["70159.60", "0.776"], ["70160.00", "0.467"], ["70160.40", "0.285"], ["70160.50", "1.082"], ["70160.60", "0.004"], ["70160.70", "0.004"], ["70160.90", "0.009"], ["70161.00", "0.636"], ["70161.10", "0.857"], ["70161.20", "0.004"], ["70161.60", "0.011"], ["70161.70", "0.004"], ["70161.80", "0.000"], ["70161.90", "0.711"], ["70162.20", "0.004"], ["70162.40", "0.004"], ["70162.50", "0.000"], ["70162.80", "0.257"], ["70163.10", "0.040"], ["70163.20", "0.009"], ["70163.30", "0.000"], ["70163.60", "0.008"], ["70163.80", "0.002"], ["70163.90", "0.000"], ["70164.00", "0.000"], ["70164.10", "0.093"], ["70164.20", "0.514"], ["70164.30", "0.004"], ["70164.50", "0.692"], ["70164.60", "0.004"], ["70164.90", "0.000"], ["70165.00", "0.265"], ["70165.20", "0.001"], ["70165.30", "0.000"], ["70165.50", "1.100"], ["70165.70", "0.008"], ["70165.90", "0.039"], ["70166.00", "0.014"], ["70166.40", "0.006"], ["70166.60", "0.000"], ["70166.70", "0.003"], ["70166.80", "0.000"], ["70167.00", "0.594"], ["70167.10", "0.300"], ["70167.20", "0.000"], ["70167.30", "0.000"], ["70167.40", "0.006"], ["70167.50", "0.008"], ["70167.60", "0.001"], ["70168.00", "0.560"], ["70168.10", "0.007"], ["70168.20", "0.000"], ["70168.60", "0.000"], ["70169.00", "0.002"], ["70169.30", "0.514"], ["70169.70", "0.123"], ["70169.90", "0.253"], ["70170.20", "0.000"], ["70170.30", "0.001"], ["70170.40", "0.116"], ["70170.50", "0.033"], ["70170.90", "0.662"], ["70171.00", "0.592"], ["70171.50", "2.174"], ["70171.60", "0.006"], ["70171.70", "0.106"], ["70171.80", "0.213"], ["70172.30", "0.000"], ["70172.50", "0.002"], ["70172.70", "0.022"], ["70172.80", "0.111"], ["70172.90", "0.096"], ["70173.10", "0.000"], ["70173.40", "10.268"], ["70173.50", "1.076"], ["70173.80", "0.058"], ["70173.90", "0.006"], ["70174.00", "1.628"], ["70174.10", "0.037"], ["70174.20", "0.089"], ["70174.50", "0.094"], ["70174.60", "0.064"], ["70175.10", "0.006"], ["70175.40", "0.510"], ["70175.70", "0.011"], ["70176.00", "0.099"], ["70176.10", "0.000"], ["70176.20", "0.091"], ["70176.60", "0.011"], ["70176.70", "0.303"], ["70177.00", "0.000"], ["70177.10", "0.288"], ["70177.20", "0.003"], ["70178.00", "0.004"], ["70178.10", "0.430"], ["70178.40", "0.000"], ["70178.50", "0.010"], ["70178.90", "0.641"], ["70179.00", "0.569"], ["70179.70", "0.004"], ["70180.40", "0.004"], ["70180.80", "0.301"], ["70181.10", "0.008"], ["70181.40", "0.299"], ["70181.50", "0.020"], ["70182.30", "0.003"], ["70183.60", "0.007"], ["70183.90", "0.102"], ["70184.10", "0.000"], ["70184.30", "0.002"], ["70184.60", "0.523"], ["70184.90", "0.118"], ["70185.00", "0.005"], ["70185.10", "0.612"], ["70185.70", "0.000"], ["70185.80", "0.000"], ["70187.50", "0.000"], ["70187.90", "0.000"], ["70188.00", "0.138"], ["70188.30", "0.000"], ["70188.80", "0.006"], ["70188.90", "0.002"], ["70189.00", "0.618"], ["70189.20", "0.000"], ["70189.30", "0.004"], ["70189.80", "0.388"], ["70190.30", "1.011"], ["70190.40", "0.003"], ["70191.00", "0.002"], ["70192.10", "0.134"], ["70193.40", "0.629"], ["70193.80", "0.006"], ["70194.70", "0.004"], ["70196.90", "0.052"], ["70197.00", "1.071"], ["70197.70", "0.145"], ["70198.50", "0.088"], ["70199.10", "0.693"], ["70199.40", "0.204"], ["70200.00", "2.758"], ["70200.50", "0.322"], ["70200.80", "0.050"], ["70202.60", "0.000"], ["70202.70", "0.002"], ["70203.10", "0.061"], ["70203.20", "0.004"], ["70203.60", "2.232"], ["70204.20", "0.065"], ["70204.30", "0.995"], ["70205.10", "0.457"], ["70205.20", "10.268"], ["70206.10", "0.004"], ["70206.50", "0.305"], ["70206.60", "0.004"], ["70207.30", "0.829"], ["70207.40", "0.514"], ["70207.90", "0.855"], ["70210.10", "0.805"], ["70211.00", "0.172"], ["70213.10", "1.103"], ["70213.30", "0.097"], ["70213.60", "0.345"], ["70213.70", "0.002"], ["70214.20", "0.322"], ["70214.60", "0.173"], ["70215.70", "0.487"], ["70218.10", "1.966"], ["70219.10", "0.368"], ["70219.20", "0.142"], ["70220.20", "0.060"], ["70221.10", "0.000"], ["70225.20", "0.672"], ["70227.20", "1.503"], ["70227.80", "2.956"], ["70228.40", "0.002"], ["70229.20", "0.091"], ["70229.60", "0.006"], ["70232.50", "0.201"], ["70234.40", "0.004"], ["70236.90", "0.041"], ["70237.70", "0.091"], ["70238.40", "0.143"], ["70242.40", "0.379"], ["70242.50", "0.414"], ["70245.80", "0.568"], ["70247.10", "0.041"], ["70247.90", "0.011"], ["70248.20", "2.048"], ["70251.10", "0.004"], ["70251.30", "0.000"], ["70254.30", "0.219"], ["70274.40", "0.013"], ["70276.30", "2.003"], ["70276.70", "1.020"], ["70277.40", "0.000"], ["70278.00", "0.519"], ["70279.90", "0.002"], ["70280.50", "0.045"], ["70280.70", "0.000"], ["70282.00", "0.666"], ["70282.20", "0.102"], ["70286.20", "0.000"], ["70287.30", "0.385"], ["70288.10", "10.000"], ["70290.90", "0.041"], ["70291.30", "0.002"], ["70291.80", "1.404"], ["70293.20", "0.330"], ["70300.90", "0.123"], ["70302.90", "0.060"], ["70306.00", "0.055"], ["70309.20", "0.000"], ["70310.00", "0.308"], ["70310.20", "0.003"], ["70310.40", "0.000"], ["70314.70", "0.043"], ["70316.60", "9.072"], ["70317.80", "0.041"], ["70322.60", "0.091"], ["70322.70", "0.159"], ["70325.50", "0.218"], ["70328.60", "0.092"], ["70336.20", "0.604"], ["70337.10", "0.002"], ["70337.40", "0.000"], ["70342.80", "0.004"], ["70346.30", "0.003"], ["70359.90", "0.126"], ["70360.20", "6.217"], ["70393.30", "0.198"], ["70418.90", "0.295"], ["70430.70", "0.144"], ["70432.90", "0.295"], ["70433.10", "0.288"], ["70433.50", "0.294"], ["70439.70", "6.519"], ["70497.10", "1.832"], ["70530.60", "0.001"], ["70833.80", "0.000"], ["70835.20", "0.000"], ["70837.40", "0.004"], ["71117.70", "0.067"], ["73000.00", "118.114"], ["89523.20", "0.000"]]}}
{"local_ts": 1773237573759, "server_ts": 1773237573563, "data": {"e": "depthUpdate", "E": 1773237573564, "T": 1773237573563, "s": "BTCUSDT", "U": 10088623438186, "u": 10088623463663, "pu": 10088623438120, "b": [["1000.00", "26.642"], ["5000.00", "101.418"], ["19632.40", "0.030"], ["19832.70", "0.010"], ["19833.60", "0.060"], ["19836.00", "1.210"], ["19932.40", "0.690"], ["19935.90", "0.010"], ["20032.60", "0.010"], ["20033.60", "0.030"], ["20036.00", "0.780"], ["33000.00", "10.804"], ["40000.00", "51.501"], ["66608.60", "0.002"], ["66619.10", "0.000"], ["68179.60", "0.000"], ["68700.00", "15.646"], ["68923.20", "2.175"], ["69075.70", "0.000"], ["69405.00", "0.006"], ["69432.30", "0.000"], ["69434.60", "0.000"], ["69550.00", "0.682"], ["69593.10", "0.002"], ["69940.00", "0.107"], ["69952.60", "0.002"], ["69970.30", "12.874"], ["70007.90", "0.207"], ["70012.00", "0.004"], ["70014.60", "0.163"], ["70018.30", "0.861"], ["70038.90", "0.043"], ["70043.40", "0.083"], ["70051.60", "0.304"], ["70054.40", "0.000"], ["70058.90", "0.497"], ["70060.00", "0.071"], ["70060.10", "0.315"], ["70060.60", "0.000"], ["70062.50", "1.184"], ["70062.60", "0.284"], ["70063.00", "0.061"], ["70063.50", "0.135"], ["70064.70", "0.091"], ["70065.10", "0.861"], ["70066.10", "0.016"], ["70069.90", "3.588"], ["70070.30", "0.016"], ["70070.60", "0.002"], ["70073.40", "0.570"], ["70074.70", "0.002"], ["70074.80", "0.024"], ["70081.30", "0.024"], ["70082.90", "0.000"], ["70087.20", "0.099"], ["70087.70", "0.257"], ["70090.30", "2.034"], ["70090.40", "0.011"], ["70090.80", "0.047"], ["70091.20", "0.004"], ["70091.30", "0.215"], ["70091.40", "0.166"], ["70092.20", "0.124"], ["70093.80", "1.879"], ["70093.90", "0.093"], ["70096.50", "0.098"], ["70096.70", "1.383"], ["70099.00", "0.098"], ["70101.40", "0.000"], ["70101.60", "0.070"], ["70102.10", "0.030"], ["70104.00", "0.040"], ["70105.00", "1.319"], ["70105.20", "0.257"], ["70106.40", "0.007"], ["70107.30", "0.006"], ["70107.80", "0.006"], ["70107.90", "0.111"], ["70108.60", "0.006"], ["70108.90", "0.002"], ["70109.40", "0.003"], ["70109.70", "0.226"], ["70109.90", "0.007"], ["70110.70", "0.332"], ["70111.90", "0.075"], ["70112.10", "0.378"], ["70112.20", "0.002"], ["70112.50", "0.007"], ["70113.70", "0.000"], ["70113.80", "1.358"], ["70113.90", "1.266"], ["70114.10", "0.072"], ["70114.30", "0.235"], ["70114.50", "0.530"], ["70114.70", "0.010"], ["70114.90", "0.077"], ["70115.00", "0.008"], ["70115.50", "0.002"], ["70115.70", "0.000"], ["70115.90", "0.008"], ["70116.20", "0.038"], ["70116.80", "0.004"], ["70117.10", "0.580"], ["70117.40", "0.004"], ["70117.60", "0.002"], ["70117.70", "0.000"], ["70117.80", "0.000"], ["70117.90", "0.012"], ["70118.10", "0.004"], ["70118.30", "0.529"], ["70118.50", "0.007"], ["70119.00", "0.202"], ["70119.20", "0.060"], ["70119.50", "0.012"], ["70119.60", "0.345"], ["70119.90", "0.041"], ["70120.20", "0.025"], ["70120.60", "0.027"], ["70120.70", "0.000"], ["70120.80", "1.589"], ["70120.90", "0.009"], ["70121.00", "0.000"], ["70121.50", "0.009"], ["70121.60", "0.006"], ["70121.80", "0.002"], ["70121.90", "0.001"], ["70122.00", "0.002"], ["70122.20", "0.002"], ["70122.40", "0.143"], ["70122.50", "0.002"], ["70123.00", "0.005"], ["70123.10", "0.000"], ["70123.40", "0.000"], ["70123.50", "0.026"], ["70123.80", "0.000"], ["70124.00", "0.009"], ["70124.10", "0.000"], ["70124.20", "0.002"], ["70124.50", "1.001"], ["70124.70", "0.000"], ["70124.90", "0.000"], ["70125.20", "0.198"], ["70125.30", "0.001"], ["70125.40", "0.924"], ["70125.50", "0.000"], ["70125.60", "0.000"], ["70125.70", "0.004"], ["70126.00", "0.334"], ["70126.10", "0.025"], ["70126.40", "0.004"], ["70126.50", "0.000"], ["70126.60", "0.009"], ["70126.80", "0.003"], ["70126.90", "0.000"], ["70127.10", "0.008"], ["70127.30", "0.000"], ["70127.90", "0.002"], ["70128.10", "0.035"], ["70128.30", "0.007"], ["70128.40", "0.005"], ["70128.80", "0.002"], ["70129.20", "0.427"], ["70129.30", "0.452"], ["70129.40", "0.043"], ["70129.50", "0.023"], ["70130.60", "0.006"], ["70131.00", "0.000"], ["70131.60", "0.002"], ["70131.70", "0.002"], ["70132.10", "0.002"], ["70132.30", "0.049"], ["70132.40", "0.020"], ["70132.50", "0.001"], ["70132.60", "0.101"], ["70132.70", "0.002"], ["70132.80", "0.000"], ["70133.20", "0.000"], ["70133.30", "0.001"], ["70133.40", "0.098"], ["70133.50", "2.030"], ["70133.60", "6.815"], ["70133.70", "0.000"], ["70133.80", "0.000"], ["70133.90", "0.000"], ["70134.10", "0.000"], ["70134.40", "0.000"], ["70134.60", "0.000"], ["70134.80", "0.000"], ["70135.30", "0.000"], ["70135.60", "0.000"], ["70135.70", "0.000"], ["70135.90", "0.000"], ["70136.00", "0.000"]], "a": [["70133.70", "4.361"], ["70133.80", "0.001"], ["70135.00", "0.002"], ["70135.20", "0.002"], ["70135.40", "0.000"], ["70135.60", "0.000"], ["70135.70", "0.000"], ["70135.80", "0.000"], ["70136.00", "0.002"], ["70136.10", "2.605"], ["70137.10", "0.004"], ["70137.20", "0.000"], ["70138.20", "0.011"], ["70138.40", "0.003"], ["70139.30", "0.056"], ["70139.70", "0.003"], ["70140.10", "0.007"], ["70140.20", "0.002"], ["70140.70", "0.002"], ["70141.20", "0.048"], ["70142.10", "0.000"], ["70142.50", "0.005"], ["70142.80", "0.005"], ["70144.50", "0.001"], ["70144.70", "0.000"], ["70145.80", "0.006"], ["70146.80", "1.071"], ["70147.00", "0.008"], ["70147.10", "0.004"], ["70147.50", "0.098"], ["70147.60", "0.000"], ["70147.90", "0.131"], ["70149.10", "0.062"], ["70149.80", "1.387"], ["70149.90", "0.433"], ["70150.00", "0.637"], ["70150.10", "0.003"], ["70150.80", "0.142"], ["70151.00", "0.000"], ["70151.10", "0.347"], ["70151.40", "0.006"], ["70151.50", "0.001"], ["70151.70", "0.000"], ["70152.80", "0.514"], ["70153.20", "0.002"], ["70153.30", "0.010"], ["70153.70", "0.352"], ["70154.00", "0.597"], ["70154.10", "0.009"], ["70155.00", "0.522"], ["70155.10", "0.380"], ["70155.50", "0.000"], ["70155.60", "0.015"], ["70156.40", "1.075"], ["70156.60", "0.003"], ["70156.90", "0.002"], ["70157.10", "0.000"], ["70157.20", "0.514"], ["70157.30", "1.360"], ["70157.60", "0.000"], ["70158.30", "0.516"], ["70158.90", "0.109"], ["70159.00", "0.004"], ["70159.10", "0.604"], ["70159.80", "0.002"], ["70160.00", "0.752"], ["70160.50", "0.056"], ["70160.80", "0.004"], ["70160.90", "0.002"], ["70161.60", "0.011"], ["70161.80", "0.214"], ["70161.90", "0.178"], ["70163.30", "0.078"], ["70163.60", "0.006"], ["70163.80", "0.145"], ["70164.00", "0.000"], ["70164.10", "0.786"], ["70164.20", "0.000"], ["70164.40", "0.004"], ["70164.50", "0.710"], ["70164.70", "0.859"], ["70165.10", "0.000"], ["70165.20", "0.001"], ["70165.30", "0.345"], ["70165.40", "1.474"], ["70165.50", "1.211"], ["70165.90", "0.037"], ["70166.00", "0.012"], ["70166.60", "0.002"], ["70166.70", "0.002"], ["70166.80", "0.000"], ["70166.90", "0.515"], ["70167.10", "0.302"], ["70167.20", "0.002"], ["70167.30", "0.000"], ["70167.40", "0.008"], ["70167.90", "0.071"], ["70168.00", "0.807"], ["70168.10", "0.007"], ["70168.30", "0.855"], ["70168.40", "0.054"], ["70168.60", "0.000"], ["70168.70", "0.301"], ["70169.10", "0.005"], ["70169.40", "0.002"], ["70169.50", "0.082"], ["70169.70", "0.142"], ["70169.90", "0.253"], ["70170.10", "0.000"], ["70170.40", "0.200"], ["70170.60", "0.053"], ["70170.80", "0.033"], ["70171.20", "0.290"], ["70171.80", "0.284"], ["70172.10", "0.033"], ["70172.20", "0.060"], ["70172.90", "0.002"], ["70173.40", "10.268"], ["70173.70", "0.086"], ["70174.90", "0.643"], ["70175.40", "0.796"], ["70175.70", "0.031"], ["70175.80", "0.234"], ["70176.70", "0.303"], ["70177.10", "0.002"], ["70177.90", "0.000"], ["70178.10", "0.024"], ["70178.20", "0.112"], ["70178.40", "0.570"], ["70178.70", "0.000"], ["70179.10", "0.882"], ["70180.40", "0.004"], ["70180.50", "0.000"], ["70181.30", "0.060"], ["70181.40", "0.413"], ["70181.70", "0.000"], ["70181.80", "0.050"], ["70183.10", "0.000"], ["70183.20", "0.000"], ["70183.30", "0.052"], ["70183.40", "0.100"], ["70183.50", "0.000"], ["70184.00", "0.000"], ["70187.80", "0.002"], ["70188.00", "0.058"], ["70188.60", "0.761"], ["70188.70", "2.210"], ["70188.80", "0.006"], ["70189.10", "0.001"], ["70189.90", "0.857"], ["70190.20", "0.597"], ["70190.30", "0.298"], ["70191.60", "0.002"], ["70191.70", "0.004"], ["70192.10", "0.050"], ["70195.60", "0.030"], ["70196.10", "0.002"], ["70196.40", "0.104"], ["70196.80", "0.086"], ["70197.00", "0.929"], ["70197.60", "0.002"], ["70198.30", "0.130"], ["70198.50", "0.004"], ["70198.60", "0.007"], ["70199.10", "0.164"], ["70199.20", "0.089"], ["70199.40", "0.204"], ["70199.70", "0.269"], ["70200.30", "0.000"], ["70202.80", "0.013"], ["70203.40", "0.103"], ["70208.20", "0.141"], ["70208.80", "0.100"], ["70215.00", "0.201"], ["70217.30", "0.000"], ["70218.10", "1.969"], ["70218.20", "0.136"], ["70218.90", "0.093"], ["70224.60", "0.000"], ["70228.40", "0.000"], ["70242.30", "0.007"], ["70244.00", "0.008"], ["70244.80", "0.438"], ["70245.30", "0.002"], ["70248.20", "2.041"], ["70251.10", "0.002"], ["70252.70", "0.008"], ["70253.00", "0.000"], ["70254.00", "0.000"], ["70257.80", "0.000"], ["70258.50", "0.034"], ["70300.90", "0.013"], ["70301.10", "0.002"], ["70301.80", "0.009"], ["70303.00", "0.013"], ["70305.60", "0.000"], ["70308.10", "0.003"], ["70319.10", "0.397"], ["70319.30", "0.091"], ["70319.50", "0.003"], ["70324.30", "0.091"], ["70675.10", "0.000"], ["70675.40", "0.004"], ["70834.10", "0.000"], ["70835.00", "0.086"], ["70837.50", "0.004"], ["71148.90", "1.948"], ["76200.60", "0.002"]]}}
{"local_ts": 1773237574780, "server_ts": 1773237574585, "data": {"e": "depthUpdate", "E": 1773237574586, "T": 1773237574585, "s": "BTCUSDT", "U": 10088623580573, "u": 10088623587075, "pu": 10088623580429, "b": [["1000.00", "26.642"], ["5000.00", "101.418"], ["19725.30", "0.650"], ["19836.00", "0.200"], ["19925.30", "0.340"], ["20035.90", "0.060"], ["20036.00", "0.000"], ["56100.00", "1.306"], ["66603.60", "0.002"], ["68722.80", "0.003"], ["69001.40", "1.151"], ["69424.00", "0.003"], ["69585.80", "0.005"], ["69848.30", "0.000"], ["70020.00", "0.205"], ["70034.80", "0.751"], ["70043.70", "0.349"], ["70057.00", "0.094"], ["70058.70", "0.055"], ["70062.20", "0.053"], ["70062.60", "0.096"], ["70065.30", "0.010"], ["70075.80", "0.661"], ["70077.30", "0.031"], ["70077.40", "0.004"], ["70078.10", "0.004"], ["70078.80", "1.077"], ["70079.50", "0.470"], ["70090.50", "0.208"], ["70090.60", "0.096"], ["70092.00", "0.316"], ["70092.80", "0.007"], ["70095.20", "0.020"], ["70097.80", "0.002"], ["70101.60", "0.000"], ["70103.00", "0.005"], ["70104.90", "0.243"], ["70106.00", "0.287"], ["70107.40", "0.038"], ["70110.10", "0.014"], ["70111.30", "0.032"], ["70111.40", "0.395"], ["70113.10", "0.038"], ["70114.20", "0.007"], ["70115.80", "0.005"], ["70115.90", "0.008"], ["70116.50", "0.006"], ["70118.30", "0.000"], ["70119.10", "0.001"], ["70119.40", "0.004"], ["70119.50", "0.286"], ["70119.60", "0.035"], ["70120.40", "0.233"], ["70120.50", "0.003"], ["70121.10", "0.000"], ["70121.20", "0.002"], ["70122.80", "0.002"], ["70124.50", "0.000"], ["70125.30", "3.824"]], "a": [["70125.40", "2.555"], ["70125.50", "0.001"], ["70127.10", "0.004"], ["70127.20", "0.002"], ["70128.50", "0.006"], ["70129.90", "0.004"], ["70130.50", "0.076"], ["70130.60", "0.016"], ["70130.70", "0.048"], ["70131.80", "0.002"], ["70132.40", "0.106"], ["70133.20", "0.000"], ["70133.30", "0.214"], ["70133.60", "0.604"], ["70135.00", "0.006"], ["70135.60", "0.057"], ["70135.90", "0.602"], ["70138.10", "1.588"], ["70139.20", "0.280"], ["70141.20", "0.007"], ["70144.20", "0.000"], ["70145.60", "1.000"], ["70147.30", "0.291"], ["70148.80", "0.006"], ["70149.50", "0.292"], ["70150.90", "0.331"], ["70155.00", "0.522"], ["70155.70", "0.006"], ["70156.90", "0.013"], ["70158.20", "0.253"], ["70158.70", "0.000"], ["70160.30", "0.091"], ["70160.40", "0.011"], ["70160.50", "0.073"], ["70162.40", "0.008"], ["70162.50", "0.012"], ["70163.30", "0.020"], ["70163.90", "0.042"], ["70164.70", "0.855"], ["70171.10", "0.574"], ["70172.70", "0.022"], ["70173.70", "0.139"], ["70177.80", "0.000"], ["70180.70", "1.122"], ["70180.80", "0.299"], ["70181.50", "0.000"], ["70186.00", "0.065"], ["70189.30", "0.004"], ["70199.00", "0.080"], ["70216.60", "0.000"], ["70242.30", "0.000"], ["70664.80", "0.000"], ["70826.70", "0.000"], ["70900.60", "1.402"], ["71149.40", "3.840"], ["71279.10", "0.000"]]}}
{"local_ts": 1773237575802, "server_ts": 1773237575604, "data": {"e": "depthUpdate", "E": 1773237575606, "T": 1773237575604, "s": "BTCUSDT", "U": 10088623667060, "u": 10088623674989, "pu": 10088623666723, "b": [["5000.00", "101.438"], ["19631.20", "0.710"], ["19731.20", "0.530"], ["19831.20", "0.670"], ["19925.30", "0.330"], ["19927.00", "0.000"], ["66598.60", "0.005"], ["66624.00", "0.026"], ["66624.60", "0.002"], ["67326.00", "0.004"], ["68904.00", "1.922"], ["69040.10", "0.005"], ["69429.90", "0.000"], ["69591.70", "0.010"], ["69892.80", "0.002"], ["70054.10", "0.129"], ["70057.00", "0.000"], ["70062.60", "0.284"], ["70100.50", "0.000"], ["70104.90", "0.309"], ["70112.60", "0.004"], ["70113.50", "0.526"], ["70114.20", "1.004"], ["70117.20", "0.494"], ["70117.30", "0.027"], ["70120.90", "0.000"], ["70121.40", "0.001"], ["70121.50", "0.004"], ["70121.60", "0.931"], ["70121.70", "0.961"], ["70121.80", "0.731"], ["70126.00", "0.008"]], "a": [["70131.30", "5.932"], ["70146.70", "0.008"], ["70162.40", "0.008"], ["70162.50", "0.012"], ["70163.10", "0.000"], ["70163.20", "0.002"], ["70163.30", "0.063"], ["70182.80", "0.063"], ["70183.30", "0.052"], ["70190.10", "0.128"], ["70190.30", "0.298"], ["70190.60", "1.238"], ["70248.20", "2.041"], ["70248.90", "0.021"], ["70670.70", "0.002"], ["70832.60", "0.000"], ["71637.60", "0.002"], ["73640.50", "0.002"]]}}
{"local_ts": 1773237576824, "server_ts": 1773237576627, "data": {"e": "depthUpdate", "E": 1773237576628, "T": 1773237576627, "s": "BTCUSDT", "U": 10088623730399, "u": 10088623736911, "pu": 10088623730326, "b": [["1000.00", "26.642"], ["5000.00", "101.398"], ["19627.00", "1.010"], ["19631.20", "0.580"], ["19725.30", "0.000"], ["19727.00", "0.520"], ["19831.20", "0.300"], ["20027.00", "0.410"], ["56102.00", "0.296"], ["66608.80", "0.002"], ["66612.50", "0.002"], ["68999.30", "0.007"], ["69040.00", "4.066"], ["69425.70", "1.438"], ["69800.30", "1.538"], ["69844.10", "0.036"], ["69859.50", "0.036"], ["69861.00", "0.036"], ["69862.20", "0.025"], ["69880.90", "2.486"], ["69888.60", "0.000"], ["70045.40", "0.116"], ["70056.90", "0.296"], ["70058.00", "0.000"], ["70062.60", "0.002"], ["70074.50", "0.034"], ["70088.40", "0.516"], ["70089.10", "0.119"], ["70090.50", "0.114"], ["70091.90", "0.249"], ["70100.00", "1.780"], ["70104.20", "0.113"], ["70115.90", "0.102"], ["70116.50", "0.253"], ["70116.60", "0.006"], ["70116.70", "0.000"], ["70117.40", "0.005"], ["70118.10", "1.004"], ["70118.20", "0.008"], ["70119.00", "0.432"], ["70119.70", "0.003"], ["70121.90", "0.410"], ["70122.00", "0.037"], ["70123.10", "0.049"], ["70125.10", "0.002"], ["70127.00", "4.656"]], "a": [["70127.10", "0.891"], ["70127.20", "0.002"], ["70133.90", "0.000"], ["70134.10", "0.088"], ["70135.30", "0.000"], ["70135.40", "0.213"], ["70137.00", "0.000"], ["70137.60", "0.255"], ["70137.70", "0.002"], ["70137.90", "0.004"], ["70138.10", "0.436"], ["70140.20", "0.105"], ["70140.90", "0.453"], ["70142.40", "0.000"], ["70143.70", "0.086"], ["70143.90", "0.350"], ["70145.20", "0.018"], ["70146.40", "0.000"], ["70146.80", "0.003"], ["70148.20", "1.000"], ["70148.50", "0.071"], ["70153.80", "0.019"], ["70161.70", "0.008"], ["70161.80", "0.002"], ["70162.20", "0.140"], ["70162.40", "0.006"], ["70162.50", "0.010"], ["70169.20", "0.313"], ["70170.90", "0.300"], ["70180.70", "0.410"], ["70180.80", "0.297"], ["70196.90", "0.050"], ["70197.20", "0.106"], ["70197.90", "0.024"], ["70318.00", "0.106"], ["70355.10", "0.000"], ["70406.00", "0.811"], ["70479.90", "0.154"], ["70700.00", "4.656"], ["70828.40", "0.046"], ["71258.00", "5.463"], ["73662.90", "0.000"]]}}
{"local_ts": 1773237577842, "server_ts": 1773237577649, "data": {"e": "depthUpdate", "E": 1773237577650, "T": 1773237577649, "s": "BTCUSDT", "U": 10088623828953, "u": 10088623837229, "pu": 10088623828905, "b": [["5000.00", "101.438"], ["19627.00", "0.140"], ["19629.90", "0.380"], ["19727.00", "0.620"], ["19929.90", "0.250"], ["20029.90", "0.760"], ["56104.00", "0.016"], ["66610.30", "0.000"], ["68129.90", "0.003"], ["69140.80", "0.000"], ["69188.40", "0.006"], ["69428.60", "0.010"], ["69700.00", "10.712"], ["69897.30", "8.784"], ["69904.30", "0.000"], ["69911.30", "0.007"], ["69914.00", "0.298"], ["69918.30", "0.006"], ["69921.00", "0.013"], ["69925.30", "0.015"], ["69928.00", "0.007"], ["69932.30", "0.002"], ["69935.00", "0.007"], ["69939.30", "0.002"], ["69942.00", "0.013"], ["69942.60", "0.007"], ["69946.30", "0.000"], ["69949.00", "0.007"], ["69956.00", "0.009"], ["69963.00", "0.007"], ["69988.00", "0.000"], ["70033.20", "0.050"], ["70038.30", "0.305"], ["70041.80", "0.000"], ["70045.30", "0.002"], ["70050.50", "0.006"], ["70057.90", "1.068"], ["70064.00", "0.034"], ["70076.90", "0.292"], ["70090.50", "0.208"], ["70092.20", "0.009"], ["70096.30", "0.071"], ["70099.00", "0.048"], ["70101.80", "0.213"], ["70109.20", "0.002"], ["70110.70", "0.550"], ["70113.50", "0.526"], ["70114.40", "0.000"], ["70114.60", "0.043"], ["70115.20", "0.004"], ["70115.80", "0.840"], ["70116.40", "1.212"], ["70117.60", "0.096"], ["70118.90", "0.029"], ["70119.10", "0.206"], ["70124.10", "0.071"], ["70126.70", "0.002"], ["70128.00", "0.004"], ["70129.90", "7.402"]], "a": [["70130.30", "0.002"], ["70136.00", "0.002"], ["70140.20", "0.028"], ["70141.90", "0.002"], ["70143.00", "0.002"], ["70143.40", "0.001"], ["70145.40", "0.011"], ["70146.20", "0.254"], ["70146.70", "0.294"], ["70146.80", "0.436"], ["70147.30", "0.012"], ["70148.90", "0.288"], ["70149.40", "0.007"], ["70150.80", "0.142"], ["70152.70", "0.050"], ["70152.80", "0.105"], ["70152.90", "0.295"], ["70153.60", "0.376"], ["70154.40", "0.092"], ["70156.00", "0.133"], ["70156.90", "0.002"], ["70157.10", "0.071"], ["70159.10", "0.007"], ["70162.40", "0.017"], ["70162.50", "0.021"], ["70163.10", "0.000"], ["70163.20", "0.002"], ["70163.30", "0.513"], ["70166.90", "0.308"], ["70168.20", "0.000"], ["70170.60", "0.217"], ["70171.10", "0.299"], ["70173.60", "0.641"], ["70183.80", "0.002"], ["70183.90", "0.104"], ["70196.90", "0.050"], ["70248.90", "0.014"], ["70264.00", "0.206"], ["70270.00", "0.129"], ["70402.40", "0.000"], ["70402.60", "0.045"], ["70402.90", "0.002"], ["70404.00", "0.000"], ["70419.30", "0.002"], ["70452.60", "0.015"], ["70453.50", "0.058"], ["70486.60", "0.000"], ["70831.30", "0.007"], ["71316.50", "0.279"], ["73654.60", "0.002"], ["73661.30", "0.002"]]}}
{"local_ts": 1773237578862, "server_ts": 1773237578669, "data": {"e": "depthUpdate", "E": 1773237578670, "T": 1773237578669, "s": "BTCUSDT", "U": 10088623977756, "u": 10088623990465, "pu": 10088623977711, "b": [["1000.00", "26.642"], ["5000.00", "101.418"], ["19639.90", "0.070"], ["19849.80", "0.100"], ["19939.90", "0.650"], ["19949.80", "0.190"], ["20029.90", "0.060"], ["20049.80", "0.190"], ["33000.00", "10.800"], ["66600.90", "0.000"], ["69135.70", "0.002"], ["69148.20", "0.002"], ["69425.30", "0.719"], ["69448.30", "0.002"], ["69610.10", "1.190"], ["69830.10", "0.000"], ["69831.80", "0.098"], ["69834.90", "0.000"], ["69914.00", "0.291"], ["69920.20", "0.007"], ["69921.00", "0.006"], ["69927.20", "0.009"], ["69928.00", "0.000"], ["69934.20", "0.007"], ["69935.00", "0.000"], ["69941.20", "0.007"], ["69942.00", "0.006"], ["69944.80", "0.018"], ["69947.60", "0.294"], ["69948.20", "0.007"], ["69949.00", "0.000"], ["69955.20", "0.007"], ["69956.00", "0.002"], ["69958.40", "0.002"], ["69960.70", "0.000"], ["69961.40", "0.053"], ["69962.20", "0.009"], ["69963.00", "0.000"], ["69969.20", "0.007"], ["69982.00", "0.095"], ["69984.70", "0.322"], ["70037.30", "7.239"], ["70046.00", "0.150"], ["70049.10", "0.290"], ["70049.20", "0.000"], ["70058.70", "0.000"], ["70062.80", "0.002"], ["70064.80", "1.283"], ["70080.50", "0.116"], ["70081.80", "0.118"], ["70085.30", "0.029"], ["70090.90", "0.502"], ["70092.30", "0.032"], ["70099.30", "0.214"], ["70100.70", "0.291"], ["70101.20", "0.000"], ["70104.20", "0.000"], ["70104.90", "0.079"], ["70113.90", "0.004"], ["70115.60", "0.300"], ["70116.80", "0.004"], ["70121.90", "0.587"], ["70122.50", "0.004"], ["70122.70", "0.036"], ["70125.50", "0.074"], ["70126.20", "0.036"], ["70126.50", "0.176"], ["70129.30", "0.016"], ["70130.10", "0.039"], ["70131.50", "0.556"], ["70132.00", "0.011"], ["70132.60", "0.012"], ["70133.10", "0.036"], ["70133.30", "0.026"], ["70133.80", "0.063"], ["70134.20", "0.025"], ["70134.30", "0.002"], ["70135.10", "0.002"], ["70139.70", "0.068"], ["70139.90", "0.052"], ["70140.40", "0.002"], ["70141.80", "0.004"], ["70142.50", "0.010"], ["70142.70", "0.004"], ["70143.00", "0.221"], ["70143.20", "0.004"], ["70143.70", "0.002"], ["70143.90", "0.006"], ["70144.90", "0.161"], ["70145.30", "0.010"], ["70146.00", "0.007"], ["70146.20", "0.005"], ["70146.30", "0.084"], ["70146.60", "0.516"], ["70146.70", "0.243"], ["70146.80", "0.005"], ["70147.10", "0.000"], ["70147.20", "0.000"], ["70148.30", "0.002"], ["70149.00", "0.002"], ["70149.80", "6.099"]], "a": [["70149.90", "0.822"], ["70150.00", "0.002"], ["70154.40", "0.004"], ["70155.10", "0.006"], ["70155.80", "0.006"], ["70156.50", "0.004"], ["70156.70", "0.002"], ["70157.00", "0.011"], ["70158.40", "0.002"], ["70160.70", "0.004"], ["70161.00", "0.452"], ["70163.80", "0.311"], ["70163.90", "0.283"], ["70164.00", "0.957"], ["70164.20", "0.975"], ["70164.30", "0.004"], ["70164.50", "0.683"], ["70165.60", "0.035"], ["70167.20", "0.515"], ["70168.00", "0.567"], ["70168.40", "0.047"], ["70168.70", "0.061"], ["70169.00", "0.097"], ["70169.40", "0.118"], ["70169.60", "0.043"], ["70169.80", "0.075"], ["70170.40", "0.000"], ["70170.60", "0.349"], ["70170.90", "0.964"], ["70172.60", "0.376"], ["70173.00", "1.010"], ["70173.30", "1.370"], ["70174.10", "0.000"], ["70174.60", "0.004"], ["70175.60", "0.014"], ["70175.80", "0.024"], ["70179.00", "0.567"], ["70179.80", "0.114"], ["70180.00", "1.360"], ["70180.60", "0.932"], ["70180.70", "0.353"], ["70181.10", "0.004"], ["70181.30", "0.048"], ["70181.40", "0.304"], ["70182.00", "0.823"], ["70182.10", "0.002"], ["70182.70", "0.859"], ["70182.80", "0.008"], ["70183.60", "0.071"], ["70186.20", "0.453"], ["70187.70", "0.003"], ["70188.00", "0.012"], ["70189.70", "0.277"], ["70190.30", "0.376"], ["70197.50", "0.201"], ["70198.60", "0.075"], ["70200.00", "2.762"], ["70200.90", "0.000"], ["70203.10", "0.009"], ["70206.70", "0.052"], ["70206.80", "0.253"], ["70208.70", "0.094"], ["70210.10", "1.036"], ["70218.40", "0.003"], ["70220.50", "0.765"], ["70227.10", "1.059"], ["70233.50", "0.000"], ["70234.20", "0.162"], ["70236.90", "0.059"], ["70239.30", "0.000"], ["70239.90", "0.178"], ["70248.90", "0.007"], ["70249.10", "0.480"], ["70250.40", "0.004"], ["70253.90", "0.738"], ["70255.10", "0.007"], ["70258.50", "0.016"], ["70259.90", "0.140"], ["70260.40", "3.576"], ["70262.90", "0.007"], ["70274.50", "2.232"], ["70274.80", "0.109"], ["70276.10", "0.109"], ["70276.20", "2.000"], ["70276.40", "0.014"], ["70278.60", "0.109"], ["70290.10", "0.111"], ["70302.70", "0.109"], ["70307.30", "0.119"], ["70311.40", "0.419"], ["70315.90", "3.504"], ["70326.80", "0.032"], ["70355.00", "0.015"], ["70363.40", "0.004"], ["70366.90", "0.006"], ["70392.10", "0.002"], ["70395.70", "0.002"], ["70402.90", "0.002"], ["70418.50", "6.524"], ["70419.30", "0.060"], ["70689.50", "0.000"], ["70795.00", "0.000"], ["70837.50", "0.137"], ["70847.90", "0.002"], ["70851.40", "0.000"], ["71135.80", "0.000"], ["71148.30", "0.002"], ["71193.60", "0.000"], ["71212.20", "0.695"], ["71248.50", "19.582"], ["71524.60", "0.692"], ["71552.80", "0.003"], ["72900.00", "65.172"], ["73000.00", "118.138"], ["73602.50", "0.000"], ["73610.50", "0.100"]]}}
{"local_ts": 1773237579880, "server_ts": 1773237579689, "data": {"e": "depthUpdate", "E": 1773237579690, "T": 1773237579689, "s": "BTCUSDT", "U": 10088624078171, "u": 10088624085052, "pu": 10088624078080, "b": [["1000.00", "26.642"], ["5000.00", "101.418"], ["19629.90", "0.000"], ["19847.00", "0.540"], ["19929.90", "0.050"], ["19939.90", "0.250"], ["19947.00", "0.080"], ["20047.00", "0.190"], ["20049.80", "0.670"], ["66638.80", "0.002"], ["66639.60", "0.002"], ["67341.20", "0.002"], ["68722.80", "0.000"], ["68754.90", "0.013"], ["69445.50", "0.000"], ["69509.20", "0.427"], ["69839.00", "0.003"], ["69843.00", "0.000"], ["69861.90", "0.036"], ["69864.40", "0.000"], ["69915.20", "6.193"], ["69917.40", "0.009"], ["69920.20", "0.000"], ["69924.40", "0.007"], ["69927.20", "0.002"], ["69931.40", "13.706"], ["69934.20", "0.000"], ["69937.50", "0.006"], ["69938.40", "0.007"], ["69941.20", "0.000"], ["69943.70", "0.002"], ["69945.40", "0.070"], ["69947.60", "0.292"], ["69948.20", "0.000"], ["69952.40", "0.009"], ["69954.30", "0.450"], ["69955.20", "0.000"], ["69959.40", "0.007"], ["69962.20", "0.002"], ["69966.40", "0.007"], ["69969.20", "0.000"], ["70022.50", "10.262"], ["70025.30", "0.041"], ["70049.60", "0.112"], ["70051.20", "0.000"], ["70051.60", "2.318"], ["70052.40", "0.000"], ["70061.20", "0.003"], ["70067.70", "0.006"], ["70078.60", "0.008"], ["70081.40", "0.000"], ["70103.30", "0.927"], ["70106.60", "0.003"], ["70108.00", "0.006"], ["70109.40", "0.002"], ["70115.00", "0.323"], ["70119.40", "0.387"], ["70123.10", "0.007"], ["70125.40", "0.629"], ["70125.50", "0.002"], ["70125.60", "0.188"], ["70126.30", "0.036"], ["70127.40", "0.002"], ["70127.50", "0.004"], ["70128.00", "0.038"], ["70128.10", "0.076"], ["70128.20", "0.003"], ["70128.40", "0.105"], ["70129.50", "0.387"], ["70129.70", "0.002"], ["70131.30", "0.020"], ["70133.00", "0.109"], ["70133.70", "0.008"], ["70134.10", "0.007"], ["70135.10", "0.000"], ["70136.90", "0.002"], ["70139.00", "0.006"], ["70139.30", "0.000"], ["70139.40", "0.151"], ["70140.30", "0.004"], ["70142.40", "0.006"], ["70143.20", "0.004"], ["70145.40", "0.002"], ["70145.50", "0.641"], ["70145.60", "0.143"], ["70147.00", "2.099"]], "a": [["70147.10", "9.227"], ["70150.50", "0.025"], ["70150.70", "0.002"], ["70161.80", "0.002"], ["70166.80", "0.285"], ["70168.60", "0.328"], ["70173.30", "1.418"], ["70176.00", "0.365"], ["70176.10", "0.605"], ["70176.50", "0.000"], ["70177.80", "0.886"], ["70177.90", "0.009"], ["70178.40", "0.071"], ["70178.50", "0.008"], ["70178.60", "0.002"], ["70178.80", "0.000"], ["70179.90", "0.009"], ["70180.00", "1.360"], ["70180.60", "0.377"], ["70180.70", "0.393"], ["70181.30", "0.115"], ["70181.90", "1.591"], ["70184.20", "0.643"], ["70185.80", "0.004"], ["70187.30", "0.024"], ["70187.50", "0.050"], ["70188.00", "0.016"], ["70188.20", "0.725"], ["70190.30", "0.302"], ["70197.70", "0.185"], ["70202.60", "0.030"], ["70202.90", "0.002"], ["70215.60", "0.003"], ["70218.40", "0.000"], ["70239.90", "0.208"], ["70242.50", "0.757"], ["70248.10", "3.940"], ["70259.90", "0.092"], ["70271.70", "0.003"], ["70274.50", "2.229"], ["70282.50", "0.002"], ["70298.10", "0.014"], ["70298.50", "0.125"], ["70303.60", "0.109"], ["70306.80", "0.109"], ["70848.60", "0.000"], ["73671.50", "0.002"], ["76374.90", "0.002"]]}}
{"local_ts": 1773237580903, "server_ts": 1773237580709, "data": {"e": "depthUpdate", "E": 1773237580710, "T": 1773237580709, "s": "BTCUSDT", "U": 10088624171068, "u": 10088624189536, "pu": 10088624171044, "b": [["5000.00", "101.418"], ["19745.30", "1.120"], ["19847.00", "0.410"], ["19945.30", "0.710"], ["20047.00", "0.030"], ["33000.00", "10.800"], ["40000.00", "51.271"], ["66622.80", "0.000"], ["68728.60", "0.000"], ["68952.90", "0.289"], ["69100.00", "3.579"], ["69217.30", "1.436"], ["69443.80", "0.000"], ["69605.70", "0.004"], ["69785.10", "0.005"], ["69906.50", "0.000"], ["69917.40", "0.002"], ["69918.60", "0.007"], ["69924.40", "0.000"], ["69925.60", "0.007"], ["69931.40", "13.699"], ["69932.60", "0.007"], ["69938.40", "0.000"], ["69939.60", "0.516"], ["69943.70", "0.000"], ["69945.40", "0.063"], ["69946.50", "0.042"], ["69946.60", "0.302"], ["69952.40", "0.002"], ["69953.60", "0.012"], ["69959.40", "0.000"], ["69960.60", "0.007"], ["69966.40", "0.000"], ["69966.50", "0.000"], ["69967.60", "0.011"], ["69980.60", "13.701"], ["69982.30", "2.957"], ["69998.90", "0.000"], ["70025.40", "0.003"], ["70038.30", "0.319"], ["70041.50", "2.684"], ["70043.10", "7.153"], ["70044.30", "1.560"], ["70044.50", "0.292"], ["70052.40", "0.000"], ["70054.60", "0.039"], ["70057.10", "0.304"], ["70060.40", "0.102"], ["70064.60", "0.092"], ["70066.70", "0.705"], ["70068.10", "0.091"], ["70071.60", "0.228"], ["70072.80", "0.002"], ["70075.20", "0.289"], ["70075.40", "0.002"], ["70081.00", "3.958"], ["70081.10", "0.000"], ["70083.50", "1.692"], ["70089.20", "0.012"], ["70090.40", "0.098"], ["70091.90", "0.447"], ["70092.70", "0.002"], ["70093.20", "0.000"], ["70094.30", "0.000"], ["70094.70", "0.282"], ["70096.90", "0.460"], ["70100.30", "0.302"], ["70102.30", "0.018"], ["70104.60", "1.939"], ["70104.80", "0.056"], ["70104.90", "0.552"], ["70105.20", "0.521"], ["70105.30", "0.117"], ["70106.00", "0.003"], ["70108.50", "0.684"], ["70108.90", "0.419"], ["70111.30", "0.003"], ["70113.30", "0.073"], ["70114.10", "0.588"], ["70114.70", "0.002"], ["70114.80", "0.004"], ["70115.40", "0.016"], ["70115.50", "0.011"], ["70116.10", "0.013"], ["70116.20", "0.032"], ["70117.20", "0.003"], ["70117.50", "0.216"], ["70117.90", "0.000"], ["70119.50", "0.197"], ["70121.50", "0.004"], ["70121.60", "0.002"], ["70121.70", "0.010"], ["70122.00", "0.002"], ["70122.20", "0.004"], ["70122.50", "0.004"], ["70123.30", "0.003"], ["70123.60", "0.007"], ["70124.10", "0.000"], ["70124.20", "0.003"], ["70125.70", "0.000"], ["70126.00", "0.009"], ["70126.20", "0.513"], ["70126.40", "0.016"], ["70126.50", "0.770"], ["70127.00", "0.002"], ["70127.40", "1.284"], ["70127.80", "0.051"], ["70127.90", "0.485"], ["70128.20", "0.097"], ["70128.40", "0.172"], ["70129.20", "1.207"], ["70129.70", "0.000"], ["70130.00", "0.008"], ["70130.60", "0.011"], ["70130.70", "0.001"], ["70130.90", "0.004"], ["70131.20", "0.217"], ["70131.60", "0.288"], ["70131.90", "0.002"], ["70132.60", "0.000"], ["70132.70", "0.004"], ["70133.10", "0.014"], ["70133.30", "0.001"], ["70133.40", "0.520"], ["70133.90", "0.290"], ["70134.00", "0.143"], ["70134.20", "0.000"], ["70134.50", "0.024"], ["70134.60", "0.002"], ["70134.80", "0.400"], ["70135.00", "0.018"], ["70135.10", "0.000"], ["70135.20", "0.004"], ["70135.30", "0.024"], ["70135.40", "0.094"], ["70135.50", "0.000"], ["70135.70", "0.031"], ["70135.80", "0.089"], ["70136.00", "0.007"], ["70136.10", "0.032"], ["70136.20", "0.000"], ["70136.40", "0.105"], ["70136.50", "0.354"], ["70137.10", "1.037"], ["70137.30", "0.319"], ["70138.10", "0.051"], ["70139.10", "0.000"], ["70139.20", "0.519"], ["70139.50", "0.000"], ["70139.80", "0.287"], ["70140.00", "0.994"], ["70140.40", "0.041"], ["70140.60", "0.345"], ["70140.70", "0.037"], ["70141.30", "0.001"], ["70141.40", "0.002"], ["70141.90", "0.004"], ["70142.60", "0.002"], ["70142.90", "0.244"], ["70143.00", "0.000"], ["70143.60", "0.004"], ["70144.10", "0.051"], ["70144.20", "0.002"], ["70145.20", "0.001"], ["70145.30", "4.741"]], "a": [["70145.40", "0.063"], ["70145.50", "0.000"], ["70146.20", "0.000"], ["70146.30", "0.009"], ["70147.60", "0.000"], ["70148.40", "0.000"], ["70149.90", "1.938"], ["70150.00", "0.008"], ["70150.60", "0.000"], ["70151.20", "0.023"], ["70152.20", "0.002"], ["70152.30", "0.007"], ["70152.40", "0.005"], ["70153.30", "0.049"], ["70154.30", "0.000"], ["70155.00", "0.000"], ["70155.50", "0.000"], ["70155.60", "0.145"], ["70155.80", "0.011"], ["70156.50", "0.004"], ["70157.70", "0.006"], ["70157.90", "0.004"], ["70158.00", "0.002"], ["70158.20", "0.119"], ["70158.30", "0.000"], ["70158.80", "0.004"], ["70158.90", "0.002"], ["70159.30", "0.004"], ["70159.40", "0.004"], ["70159.60", "0.003"], ["70160.00", "0.006"], ["70160.10", "0.286"], ["70160.20", "0.000"], ["70160.50", "0.002"], ["70160.60", "0.144"], ["70160.80", "0.000"], ["70161.00", "0.205"], ["70162.20", "0.006"], ["70162.30", "0.002"], ["70162.50", "0.001"], ["70162.60", "0.000"], ["70162.70", "0.452"], ["70162.80", "0.000"], ["70162.90", "0.250"], ["70163.10", "0.009"], ["70163.40", "0.004"], ["70163.70", "0.000"], ["70164.10", "0.072"], ["70164.20", "0.096"], ["70164.30", "0.049"], ["70164.40", "0.020"], ["70164.50", "0.577"], ["70164.60", "0.042"], ["70164.70", "0.323"], ["70164.90", "0.000"], ["70165.00", "1.213"], ["70165.30", "0.632"], ["70165.70", "0.131"], ["70166.50", "0.003"], ["70166.60", "0.003"], ["70166.80", "0.000"], ["70167.10", "0.004"], ["70167.20", "1.074"], ["70167.30", "0.404"], ["70167.80", "0.006"], ["70168.30", "0.516"], ["70168.40", "0.347"], ["70168.50", "0.007"], ["70168.60", "0.000"], ["70168.70", "0.000"], ["70169.20", "0.009"], ["70169.50", "0.002"], ["70169.60", "0.000"], ["70170.00", "0.617"], ["70170.40", "0.000"], ["70170.50", "0.003"], ["70170.60", "0.004"], ["70170.80", "0.514"], ["70170.90", "0.004"], ["70171.00", "0.087"], ["70171.20", "0.050"], ["70171.30", "0.053"], ["70171.50", "2.184"], ["70171.60", "0.003"], ["70172.50", "0.002"], ["70173.10", "1.587"], ["70173.20", "0.009"], ["70173.30", "0.288"], ["70173.60", "0.000"], ["70173.80", "0.321"], ["70174.00", "1.623"], ["70175.00", "0.223"], ["70175.60", "0.000"], ["70175.70", "0.037"], ["70175.90", "0.393"], ["70176.00", "0.014"], ["70176.10", "0.438"], ["70176.20", "0.023"], ["70176.30", "0.125"], ["70176.40", "0.294"], ["70176.50", "0.296"], ["70177.10", "0.011"], ["70177.20", "0.017"], ["70177.80", "0.879"], ["70177.90", "0.004"], ["70178.50", "0.008"], ["70178.60", "0.000"], ["70178.90", "0.518"], ["70179.20", "0.000"], ["70179.30", "0.002"], ["70179.50", "0.000"], ["70179.70", "0.014"], ["70181.30", "0.044"], ["70182.60", "0.330"], ["70182.70", "0.857"], ["70184.40", "0.010"], ["70185.20", "0.297"], ["70186.20", "0.735"], ["70187.70", "0.000"], ["70188.00", "0.016"], ["70188.50", "0.036"], ["70188.60", "2.260"], ["70189.10", "0.081"], ["70194.80", "0.003"], ["70196.80", "0.002"], ["70197.60", "0.358"], ["70198.60", "0.075"], ["70199.30", "0.085"], ["70199.70", "0.006"], ["70201.10", "0.005"], ["70201.20", "0.000"], ["70203.20", "0.056"], ["70204.60", "0.011"], ["70205.00", "0.300"], ["70209.70", "0.050"], ["70211.90", "0.006"], ["70212.20", "3.669"], ["70247.10", "0.048"], ["70250.10", "6.989"], ["70252.00", "1.563"], ["70258.50", "0.016"], ["70259.20", "0.020"], ["70296.90", "0.926"], ["70312.10", "2.380"], ["70312.40", "13.383"], ["70374.50", "0.053"], ["70443.60", "0.300"], ["70446.20", "0.000"], ["70684.90", "0.000"], ["70846.90", "0.000"], ["70991.70", "1.126"], ["71700.00", "27.711"], ["89523.20", "0.000"]]}}
{"local_ts": 1773237581930, "server_ts": 1773237581731, "data": {"e": "depthUpdate", "E": 1773237581732, "T": 1773237581731, "s": "BTCUSDT", "U": 10088624246621, "u": 10088624270845, "pu": 10088624246593, "b": [["1000.00", "26.642"], ["5000.00", "101.398"], ["19642.80", "0.010"], ["19643.30", "0.010"], ["19644.80", "0.010"], ["19645.30", "0.020"], ["19645.90", "0.010"], ["19647.60", "0.850"], ["19745.30", "0.780"], ["19747.60", "0.310"], ["19842.80", "0.010"], ["19844.60", "0.010"], ["19845.30", "0.010"], ["19847.60", "0.750"], ["19945.30", "0.220"], ["66640.20", "0.008"], ["69222.70", "0.000"], ["69400.10", "0.000"], ["69440.40", "0.002"], ["69441.10", "0.000"], ["69443.80", "0.000"], ["69444.40", "0.040"], ["69444.70", "0.000"], ["69446.10", "0.000"], ["69586.40", "1.148"], ["69604.80", "0.030"], ["69605.00", "0.010"], ["69608.00", "0.000"], ["69737.30", "0.002"], ["69846.30", "0.287"], ["69908.10", "0.008"], ["69918.60", "0.000"], ["69919.70", "0.015"], ["69925.60", "0.000"], ["69926.70", "0.007"], ["69932.60", "0.000"], ["69933.70", "0.014"], ["69939.60", "0.509"], ["69940.70", "6.575"], ["69946.50", "0.040"], ["69946.60", "0.295"], ["69946.90", "1.539"], ["69947.70", "0.009"], ["69953.60", "0.005"], ["69954.70", "6.573"], ["69959.40", "0.004"], ["69960.60", "0.000"], ["69961.70", "0.011"], ["69962.90", "0.032"], ["69967.60", "0.004"], ["69968.70", "0.319"], ["69979.60", "0.132"], ["69981.80", "0.111"], ["69991.80", "0.091"], ["69993.20", "0.093"], ["69994.10", "0.807"], ["70000.40", "0.109"], ["70020.40", "0.006"], ["70022.50", "10.370"], ["70023.30", "0.298"], ["70024.80", "0.207"], ["70025.50", "0.966"], ["70026.10", "0.111"], ["70026.70", "0.353"], ["70040.60", "0.000"], ["70041.50", "2.684"], ["70046.20", "0.041"], ["70049.00", "0.074"], ["70050.50", "0.020"], ["70050.80", "0.529"], ["70051.30", "0.245"], ["70051.50", "0.004"], ["70051.70", "0.297"], ["70052.40", "0.002"], ["70054.40", "0.094"], ["70054.60", "0.041"], ["70056.00", "1.006"], ["70056.10", "0.649"], ["70056.40", "0.094"], ["70056.60", "0.676"], ["70056.70", "0.291"], ["70056.80", "0.002"], ["70057.60", "0.000"], ["70057.80", "0.004"], ["70060.60", "0.000"], ["70064.60", "0.000"], ["70064.80", "1.192"], ["70065.60", "1.500"], ["70068.00", "0.097"], ["70068.10", "0.222"], ["70068.80", "0.049"], ["70070.10", "0.007"], ["70072.10", "0.514"], ["70072.20", "0.000"], ["70072.30", "0.012"], ["70072.40", "0.003"], ["70072.70", "0.024"], ["70073.30", "0.014"], ["70074.00", "0.596"], ["70075.00", "0.057"], ["70075.10", "0.002"], ["70075.20", "0.000"], ["70075.40", "0.000"], ["70075.60", "0.003"], ["70075.70", "0.000"], ["70075.90", "0.002"], ["70076.80", "0.000"], ["70076.90", "0.000"], ["70078.90", "0.095"], ["70079.60", "0.091"], ["70082.50", "0.000"], ["70082.90", "0.042"], ["70083.40", "0.291"], ["70084.50", "0.299"], ["70084.70", "0.002"], ["70084.90", "0.004"], ["70085.00", "0.385"], ["70086.70", "0.005"], ["70088.20", "0.587"], ["70089.10", "0.004"], ["70090.40", "0.004"], ["70091.40", "0.860"], ["70092.10", "0.005"], ["70092.80", "0.000"], ["70093.70", "0.006"], ["70094.20", "0.002"], ["70094.30", "0.002"], ["70094.70", "0.000"], ["70094.80", "0.053"], ["70095.30", "0.004"], ["70095.60", "0.080"], ["70096.30", "0.012"], ["70096.40", "0.002"], ["70096.50", "0.000"], ["70096.80", "0.000"], ["70097.40", "0.004"], ["70097.70", "0.861"], ["70097.80", "0.002"], ["70098.00", "0.004"], ["70098.40", "0.706"], ["70098.50", "0.001"], ["70098.60", "0.003"], ["70100.50", "0.111"], ["70101.40", "0.052"], ["70101.80", "0.011"], ["70104.60", "1.941"], ["70104.70", "0.000"], ["70104.90", "0.552"], ["70105.00", "0.308"], ["70105.30", "0.251"], ["70106.00", "0.003"], ["70106.10", "0.004"], ["70106.90", "0.259"], ["70107.30", "0.004"], ["70108.80", "0.089"], ["70109.50", "0.111"], ["70110.00", "0.577"], ["70110.10", "0.002"], ["70110.40", "0.020"], ["70111.20", "0.018"], ["70111.50", "0.004"], ["70111.60", "0.000"], ["70112.50", "0.000"], ["70112.60", "0.513"], ["70112.80", "0.000"], ["70113.00", "0.004"], ["70113.10", "0.007"], ["70113.50", "0.514"], ["70113.70", "0.235"], ["70114.10", "0.588"], ["70114.40", "0.000"], ["70114.60", "0.000"], ["70114.70", "0.013"], ["70114.80", "0.015"], ["70115.40", "0.007"], ["70115.50", "0.004"], ["70115.60", "0.300"], ["70115.90", "0.024"], ["70116.10", "0.008"], ["70116.20", "0.002"], ["70116.40", "0.000"], ["70116.50", "0.013"], ["70116.60", "0.077"], ["70116.80", "0.009"], ["70116.90", "0.007"], ["70117.20", "0.003"], ["70117.30", "0.096"], ["70117.50", "0.017"], ["70117.80", "0.079"], ["70118.00", "0.000"], ["70119.00", "0.596"], ["70119.10", "0.797"], ["70119.20", "0.002"], ["70119.30", "0.000"], ["70119.50", "0.000"], ["70119.60", "2.311"], ["70120.00", "0.006"], ["70120.20", "0.003"], ["70120.40", "0.287"], ["70121.00", "0.002"], ["70121.20", "0.023"], ["70121.30", "1.087"], ["70121.60", "0.009"], ["70122.00", "0.117"], ["70122.10", "0.002"], ["70122.20", "0.004"], ["70122.30", "0.000"], ["70122.40", "0.001"], ["70122.70", "0.093"], ["70122.90", "0.050"], ["70123.10", "0.514"], ["70123.20", "0.291"], ["70123.40", "0.004"], ["70123.50", "0.145"], ["70123.60", "0.007"], ["70123.70", "0.010"], ["70124.20", "0.006"], ["70124.40", "0.009"], ["70124.50", "0.002"], ["70124.80", "0.000"], ["70125.10", "0.003"], ["70125.20", "0.000"], ["70125.40", "0.006"], ["70125.60", "0.080"], ["70126.00", "0.011"], ["70126.10", "0.000"], ["70126.20", "0.000"], ["70126.70", "0.002"], ["70126.90", "0.007"], ["70127.20", "0.015"], ["70127.30", "0.000"], ["70127.40", "0.002"], ["70127.70", "0.003"], ["70127.80", "0.000"], ["70127.90", "1.000"], ["70128.00", "0.516"], ["70128.10", "0.078"], ["70128.20", "0.000"], ["70128.40", "0.004"], ["70128.50", "0.002"], ["70128.60", "0.002"], ["70128.70", "0.002"], ["70128.80", "0.016"], ["70129.00", "0.000"], ["70129.20", "0.647"], ["70129.30", "0.004"], ["70129.40", "0.007"], ["70129.60", "0.000"], ["70129.70", "0.345"], ["70129.80", "0.072"], ["70129.90", "0.027"], ["70130.00", "0.008"], ["70130.10", "0.050"], ["70130.20", "0.037"], ["70130.40", "0.005"], ["70130.60", "0.004"], ["70130.70", "0.004"], ["70130.80", "0.003"], ["70130.90", "0.004"], ["70131.00", "0.002"], ["70131.20", "0.001"], ["70131.50", "0.000"], ["70131.60", "0.002"], ["70131.70", "0.001"], ["70131.80", "0.007"], ["70131.90", "0.002"], ["70132.20", "0.002"], ["70132.30", "0.072"], ["70132.50", "0.037"], ["70132.60", "0.000"], ["70132.80", "0.002"], ["70132.90", "0.000"], ["70133.00", "0.138"], ["70133.10", "0.000"], ["70133.20", "0.003"], ["70133.40", "0.006"], ["70133.50", "0.002"], ["70133.60", "0.021"], ["70133.70", "0.008"], ["70133.90", "0.006"], ["70134.10", "0.004"], ["70134.30", "0.002"], ["70134.40", "0.641"], ["70134.70", "0.008"], ["70134.80", "0.004"], ["70134.90", "0.000"], ["70135.30", "0.002"], ["70135.60", "0.000"], ["70135.70", "0.028"], ["70135.80", "0.057"], ["70136.20", "0.000"], ["70136.40", "0.000"], ["70136.50", "0.131"], ["70136.60", "0.004"], ["70137.00", "0.000"], ["70137.10", "0.000"], ["70137.30", "0.002"], ["70138.20", "0.002"], ["70138.30", "0.060"], ["70138.40", "0.000"], ["70138.50", "0.000"], ["70138.60", "0.008"], ["70138.80", "0.003"], ["70139.00", "0.103"], ["70139.10", "0.000"], ["70139.20", "0.002"], ["70139.30", "0.002"], ["70139.40", "0.000"], ["70139.50", "0.000"], ["70139.60", "0.002"], ["70139.70", "0.000"], ["70140.00", "0.004"], ["70140.40", "0.004"], ["70140.70", "0.000"], ["70140.80", "0.000"], ["70141.00", "0.000"], ["70141.10", "0.000"], ["70141.20", "0.000"], ["70141.40", "0.000"], ["70141.60", "0.002"], ["70141.70", "0.000"], ["70141.80", "0.109"], ["70141.90", "0.000"], ["70142.00", "0.000"], ["70142.10", "0.000"], ["70142.40", "0.000"], ["70142.50", "0.000"], ["70142.60", "0.000"], ["70142.70", "0.000"], ["70142.80", "0.000"], ["70142.90", "0.000"], ["70143.10", "0.000"], ["70143.30", "0.000"], ["70143.60", "0.000"], ["70143.70", "0.000"], ["70143.90", "0.000"], ["70144.10", "0.000"], ["70144.40", "0.000"], ["70144.50", "0.000"], ["70144.60", "0.000"], ["70144.70", "0.000"], ["70144.80", "0.000"], ["70145.00", "0.000"], ["70145.20", "0.000"], ["70145.30", "0.000"], ["70145.40", "0.000"], ["70145.50", "0.000"], ["70145.60", "0.000"], ["70145.90", "0.000"], ["70146.50", "0.000"], ["70147.10", "0.000"], ["70147.50", "0.000"], ["70147.60", "0.000"]], "a": [["70141.90", "15.992"], ["70142.00", "0.147"], ["70142.10", "7.375"], ["70142.20", "0.001"], ["70142.50", "1.443"], ["70142.60", "0.264"], ["70142.70", "0.001"], ["70142.80", "0.676"], ["70142.90", "1.397"], ["70143.00", "0.001"], ["70143.10", "0.000"], ["70143.20", "0.000"], ["70143.30", "0.000"], ["70143.40", "0.000"], ["70143.50", "0.002"], ["70143.60", "0.000"], ["70143.70", "0.000"], ["70143.80", "0.001"], ["70144.00", "0.599"], ["70144.10", "0.000"], ["70144.20", "0.000"], ["70144.30", "0.001"], ["70144.40", "0.006"], ["70144.50", "0.000"], ["70144.60", "1.103"], ["70144.70", "1.213"], ["70144.80", "0.003"], ["70144.90", "0.517"], ["70145.00", "0.007"], ["70145.10", "0.000"], ["70145.30", "1.100"], ["70145.40", "1.389"], ["70145.50", "0.001"], ["70145.60", "0.000"], ["70145.70", "0.000"], ["70145.80", "0.002"], ["70145.90", "0.000"], ["70146.00", "0.380"], ["70146.10", "0.001"], ["70146.20", "0.000"], ["70146.30", "0.000"], ["70146.60", "0.000"], ["70146.90", "0.002"], ["70147.00", "0.004"], ["70147.10", "0.010"], ["70147.20", "0.003"], ["70147.40", "0.000"], ["70147.60", "0.639"], ["70147.70", "0.837"], ["70147.80", "0.001"], ["70147.90", "0.004"], ["70148.40", "0.000"], ["70149.00", "0.000"], ["70149.10", "0.001"], ["70149.20", "0.004"], ["70149.60", "0.004"], ["70149.70", "0.004"], ["70149.80", "0.002"], ["70149.90", "1.937"], ["70150.00", "0.011"], ["70150.20", "0.002"], ["70150.70", "0.002"], ["70150.80", "0.001"], ["70151.00", "0.007"], ["70151.10", "0.069"], ["70151.20", "0.097"], ["70151.40", "0.005"], ["70152.30", "0.005"], ["70152.50", "0.024"], ["70152.60", "0.050"], ["70153.20", "0.003"], ["70153.30", "0.021"], ["70153.50", "0.094"], ["70153.70", "0.048"], ["70153.90", "0.045"], ["70154.00", "0.047"], ["70154.10", "0.061"], ["70154.20", "0.068"], ["70154.30", "0.000"], ["70154.40", "0.047"], ["70154.50", "0.104"], ["70154.90", "0.205"], ["70155.00", "0.004"], ["70155.10", "0.083"], ["70155.20", "0.344"], ["70155.40", "0.000"], ["70155.50", "0.000"], ["70155.60", "0.039"], ["70155.70", "0.287"], ["70155.80", "1.011"], ["70155.90", "0.007"], ["70156.20", "0.000"], ["70156.30", "0.012"], ["70156.70", "0.002"], ["70156.80", "0.423"], ["70156.90", "0.006"], ["70157.00", "0.016"], ["70157.20", "0.000"], ["70157.30", "0.002"], ["70157.40", "0.000"], ["70157.50", "0.109"], ["70157.60", "0.020"], ["70157.90", "0.146"], ["70158.00", "0.034"], ["70158.10", "0.291"], ["70158.20", "0.000"], ["70158.30", "0.000"], ["70158.50", "0.000"], ["70158.60", "0.022"], ["70158.70", "0.153"], ["70158.80", "0.004"], ["70158.90", "0.002"], ["70159.00", "0.031"], ["70159.20", "0.001"], ["70159.30", "0.004"], ["70159.40", "0.004"], ["70159.50", "0.003"], ["70159.60", "0.000"], ["70159.70", "1.212"], ["70159.80", "0.005"], ["70159.90", "0.000"], ["70160.00", "0.011"], ["70160.10", "0.000"], ["70160.20", "0.096"], ["70160.30", "0.514"], ["70160.40", "0.000"], ["70160.50", "0.004"], ["70160.60", "0.001"], ["70160.70", "0.213"], ["70160.80", "0.000"], ["70160.90", "0.100"], ["70161.00", "0.499"], ["70161.10", "0.002"], ["70161.40", "0.007"], ["70161.50", "1.081"], ["70161.60", "0.010"], ["70161.70", "0.018"], ["70161.80", "0.002"], ["70161.90", "0.002"], ["70162.00", "0.124"], ["70162.10", "0.007"], ["70162.30", "0.002"], ["70162.50", "0.860"], ["70162.60", "0.000"], ["70162.70", "0.000"], ["70162.80", "0.513"], ["70162.90", "0.007"], ["70163.00", "0.004"], ["70163.10", "0.006"], ["70163.20", "0.006"], ["70163.30", "0.052"], ["70163.50", "0.002"], ["70163.60", "0.008"], ["70163.70", "0.002"], ["70163.90", "0.049"], ["70164.00", "0.002"], ["70164.10", "0.015"], ["70164.20", "0.061"], ["70164.30", "0.004"], ["70164.40", "0.005"], ["70164.50", "0.713"], ["70164.70", "0.000"], ["70164.80", "0.288"], ["70165.20", "0.030"], ["70165.30", "0.002"], ["70165.40", "1.508"], ["70165.50", "0.002"], ["70165.60", "0.042"], ["70165.70", "0.008"], ["70165.80", "0.004"], ["70165.90", "0.061"], ["70166.00", "0.001"], ["70166.10", "0.065"], ["70166.40", "0.084"], ["70166.50", "0.051"], ["70166.60", "0.000"], ["70166.90", "0.002"], ["70167.00", "0.299"], ["70167.30", "0.411"], ["70167.60", "0.000"], ["70168.00", "0.340"], ["70168.20", "0.007"], ["70168.40", "1.001"], ["70169.00", "0.008"], ["70169.20", "0.006"], ["70169.60", "0.142"], ["70169.70", "0.000"], ["70169.80", "0.007"], ["70169.90", "0.015"], ["70170.00", "0.004"], ["70170.10", "0.231"], ["70170.50", "0.075"], ["70170.90", "0.061"], ["70171.10", "0.047"], ["70171.20", "0.003"], ["70171.30", "0.006"], ["70171.40", "0.002"], ["70171.50", "2.180"], ["70171.60", "0.007"], ["70171.70", "0.072"], ["70172.30", "0.004"], ["70172.50", "0.643"], ["70173.00", "0.010"], ["70173.20", "0.011"], ["70173.30", "0.002"], ["70173.40", "10.264"], ["70173.50", "0.002"], ["70174.00", "1.621"], ["70174.30", "0.002"], ["70174.50", "0.377"], ["70174.90", "0.002"], ["70175.00", "0.223"], ["70175.10", "0.006"], ["70175.30", "0.178"], ["70175.50", "0.858"], ["70175.80", "0.024"], ["70176.00", "0.008"], ["70176.10", "0.438"], ["70176.30", "0.000"], ["70176.40", "0.292"], ["70176.70", "0.004"], ["70176.90", "0.028"], ["70177.10", "0.011"], ["70177.20", "0.017"], ["70177.40", "0.206"], ["70177.70", "0.000"], ["70177.80", "0.879"], ["70177.90", "0.004"], ["70178.50", "0.008"], ["70178.60", "0.002"], ["70178.90", "0.587"], ["70179.00", "0.924"], ["70179.20", "0.000"], ["70179.30", "0.000"], ["70179.80", "0.084"], ["70179.90", "0.007"], ["70180.00", "1.318"], ["70181.00", "0.002"], ["70181.50", "0.114"], ["70182.20", "0.000"], ["70182.50", "0.026"], ["70182.70", "0.869"], ["70182.90", "0.001"], ["70183.00", "0.004"], ["70183.30", "0.004"], ["70183.40", "0.010"], ["70183.50", "0.023"], ["70184.00", "0.287"], ["70184.10", "0.000"], ["70184.50", "0.050"], ["70185.00", "0.015"], ["70185.70", "0.064"], ["70186.20", "0.735"], ["70186.70", "0.000"], ["70188.10", "0.028"], ["70189.80", "0.386"], ["70192.00", "0.005"], ["70192.80", "0.053"], ["70193.20", "0.056"], ["70194.00", "0.002"], ["70194.40", "0.002"], ["70195.30", "0.004"], ["70195.90", "0.102"], ["70196.30", "0.133"], ["70196.80", "0.002"], ["70197.10", "1.691"], ["70197.20", "0.002"], ["70197.50", "0.199"], ["70197.70", "0.147"], ["70198.00", "0.377"], ["70198.10", "0.100"], ["70198.20", "0.078"], ["70198.30", "0.002"], ["70198.50", "0.006"], ["70198.70", "0.306"], ["70198.80", "0.000"], ["70199.00", "0.465"], ["70199.30", "0.085"], ["70199.40", "1.740"], ["70199.50", "0.161"], ["70199.70", "0.108"], ["70199.80", "1.698"], ["70200.10", "0.005"], ["70200.50", "0.324"], ["70201.10", "0.004"], ["70201.20", "0.100"], ["70201.50", "0.004"], ["70202.50", "0.039"], ["70202.80", "0.013"], ["70203.00", "0.004"], ["70203.80", "0.037"], ["70206.00", "0.117"], ["70206.60", "0.004"], ["70208.80", "0.428"], ["70209.70", "0.000"], ["70210.00", "0.594"], ["70212.10", "0.027"], ["70213.70", "0.064"], ["70218.00", "0.010"], ["70226.60", "0.016"], ["70227.70", "0.424"], ["70227.80", "2.820"], ["70228.40", "6.612"], ["70229.50", "0.000"], ["70232.80", "0.000"], ["70234.10", "1.945"], ["70234.90", "0.148"], ["70235.00", "0.000"], ["70235.50", "0.112"], ["70236.00", "0.448"], ["70237.20", "0.002"], ["70237.80", "0.016"], ["70238.00", "0.240"], ["70241.10", "2.058"], ["70241.80", "1.587"], ["70242.50", "0.408"], ["70243.00", "0.201"], ["70246.60", "0.112"], ["70247.10", "0.041"], ["70248.00", "0.011"], ["70248.10", "3.743"], ["70250.30", "0.000"], ["70252.90", "0.002"], ["70253.10", "0.609"], ["70257.40", "6.536"], ["70259.50", "0.108"], ["70259.90", "0.110"], ["70260.20", "0.160"], ["70264.70", "0.109"], ["70268.40", "0.002"], ["70275.90", "0.130"], ["70277.90", "0.299"], ["70281.80", "0.000"], ["70293.10", "0.095"], ["70293.70", "0.010"], ["70303.20", "0.000"], ["70324.90", "3.764"], ["70343.40", "0.000"], ["70376.80", "0.013"], ["70455.10", "1.174"], ["70455.20", "0.000"], ["70511.00", "0.000"], ["70514.50", "0.000"], ["70538.10", "0.015"], ["70544.60", "0.070"], ["70684.20", "0.014"], ["70844.30", "0.000"], ["70848.10", "0.000"], ["70849.20", "0.000"], ["71114.40", "0.000"], ["71114.60", "0.420"], ["71125.40", "0.000"], ["71141.90", "2.955"], ["71142.60", "0.010"], ["71142.90", "0.008"], ["71144.70", "0.017"], ["71144.90", "0.012"], ["71145.40", "0.014"], ["71145.70", "0.494"], ["71147.00", "1.681"], ["71147.10", "0.000"], ["71147.70", "0.000"], ["71147.90", "0.003"], ["71149.10", "1.344"], ["71529.60", "0.003"], ["73686.00", "0.131"], ["89523.20", "0.000"], ["100000.00", "15.238"]]}}
{"local_ts": 1773237582944, "server_ts": 1773237582751, "data": {"e": "depthUpdate", "E": 1773237582752, "T": 1773237582751, "s": "BTCUSDT", "U": 10088624331879, "u": 10088624337677, "pu": 10088624331849, "b": [["5000.00", "101.418"], ["19647.60", "0.240"], ["19741.80", "0.630"], ["19847.60", "0.120"], ["20041.80", "0.610"], ["33000.00", "10.804"], ["56113.00", "0.000"], ["66624.90", "0.002"], ["68634.10", "0.000"], ["68739.00", "0.013"], ["69106.00", "1.445"], ["69440.40", "0.000"], ["69602.20", "0.000"], ["69697.80", "39.582"], ["69875.00", "0.120"], ["69875.30", "0.052"], ["69938.20", "0.002"], ["69946.90", "1.115"], ["69959.50", "0.159"], ["69994.10", "0.807"], ["69997.70", "0.292"], ["70023.30", "0.093"], ["70025.50", "0.966"], ["70029.10", "1.082"], ["70051.50", "0.004"], ["70051.80", "3.049"], ["70056.40", "0.000"], ["70056.70", "0.009"], ["70057.60", "0.256"], ["70061.30", "0.000"], ["70072.30", "0.012"], ["70073.30", "0.014"], ["70075.90", "0.002"], ["70076.90", "0.000"], ["70081.80", "0.090"], ["70089.10", "0.004"], ["70089.40", "0.093"], ["70090.40", "0.192"], ["70090.50", "0.167"], ["70093.20", "0.000"], ["70103.20", "0.073"], ["70105.20", "0.521"], ["70105.30", "0.002"], ["70110.10", "0.251"], ["70111.70", "0.001"], ["70113.50", "0.514"], ["70121.70", "0.587"], ["70122.20", "0.098"], ["70123.00", "0.742"], ["70123.10", "0.516"], ["70123.30", "1.215"], ["70123.70", "0.007"], ["70125.10", "0.003"], ["70125.70", "0.012"], ["70126.80", "0.004"], ["70127.90", "0.002"], ["70128.00", "0.644"], ["70128.10", "0.214"], ["70129.10", "0.043"], ["70129.40", "0.032"], ["70129.50", "0.002"], ["70130.20", "1.002"], ["70130.80", "0.006"], ["70131.60", "0.006"], ["70131.70", "0.001"], ["70131.90", "0.002"], ["70133.00", "0.225"], ["70133.30", "0.036"], ["70133.60", "0.009"], ["70134.20", "0.000"], ["70135.10", "0.002"], ["70135.50", "0.514"], ["70135.80", "0.008"], ["70136.50", "0.200"], ["70136.60", "0.002"], ["70137.10", "0.021"], ["70138.20", "0.643"], ["70138.60", "0.057"], ["70139.50", "0.004"], ["70140.40", "0.154"], ["70141.30", "0.001"], ["70141.70", "0.001"], ["70141.80", "2.165"]], "a": [["70141.90", "4.690"], ["70143.30", "0.002"], ["70143.40", "0.036"], ["70143.50", "0.023"], ["70145.60", "0.049"], ["70146.80", "0.000"], ["70147.50", "0.002"], ["70148.90", "0.002"], ["70149.50", "0.007"], ["70149.80", "0.002"], ["70154.40", "0.004"], ["70155.70", "0.287"], ["70157.20", "0.005"], ["70162.90", "0.442"], ["70163.90", "0.047"], ["70165.80", "0.011"], ["70168.00", "0.477"], ["70169.10", "0.541"], ["70169.70", "0.007"], ["70171.40", "0.145"], ["70174.10", "0.000"], ["70174.50", "0.072"], ["70178.40", "0.070"], ["70179.60", "0.008"], ["70195.30", "0.000"], ["70195.80", "0.008"], ["70196.10", "0.002"], ["70196.30", "0.168"], ["70299.20", "0.016"], ["70299.50", "0.089"], ["70317.20", "2.030"], ["70334.00", "10.000"], ["70346.50", "1.795"], ["70348.10", "0.001"], ["70364.90", "10.000"], ["70442.50", "0.000"], ["70593.70", "38.538"], ["70681.40", "0.306"], ["70843.30", "0.000"], ["70855.60", "0.000"], ["71532.50", "0.013"], ["89523.20", "0.000"]]}}
{"local_ts": 1773237583963, "server_ts": 1773237583771, "data": {"e": "depthUpdate", "E": 1773237583772, "T": 1773237583771, "s": "BTCUSDT", "U": 10088624433059, "u": 10088624439341, "pu": 10088624432944, "b": [["1000.00", "26.642"], ["5000.00", "101.418"], ["19639.90", "0.480"], ["19641.80", "0.040"], ["19741.80", "0.230"], ["19939.90", "0.350"], ["20039.90", "1.180"], ["20041.80", "0.420"], ["66600.60", "0.002"], ["66638.00", "1.493"], ["66638.10", "0.002"], ["69142.40", "0.002"], ["69148.20", "0.000"], ["69201.10", "64.360"], ["69438.50", "0.000"], ["69938.20", "0.000"], ["69941.70", "0.002"], ["70016.80", "0.004"], ["70024.60", "0.004"], ["70048.00", "0.000"], ["70051.90", "0.007"], ["70056.70", "0.103"], ["70059.70", "0.002"], ["70066.50", "0.024"], ["70078.60", "0.005"], ["70087.00", "0.008"], ["70089.20", "0.199"], ["70090.80", "0.190"], ["70091.20", "0.004"], ["70091.50", "0.221"], ["70094.80", "0.010"], ["70097.10", "0.080"], ["70100.00", "1.793"], ["70104.10", "0.072"], ["70105.50", "0.000"], ["70107.90", "0.000"], ["70119.60", "0.518"], ["70121.10", "0.737"], ["70121.60", "0.352"], ["70122.10", "1.010"], ["70122.40", "0.074"], ["70123.20", "0.017"], ["70123.50", "0.003"], ["70124.40", "0.011"], ["70125.40", "0.245"], ["70125.70", "0.142"], ["70125.80", "0.038"], ["70126.00", "0.821"], ["70126.10", "0.000"], ["70126.50", "0.154"], ["70126.70", "0.002"], ["70126.80", "0.004"], ["70127.00", "0.014"], ["70127.10", "0.538"], ["70127.30", "0.021"], ["70127.40", "0.045"], ["70127.50", "0.067"], ["70127.70", "1.110"], ["70127.80", "0.029"], ["70128.10", "0.142"], ["70128.40", "0.059"], ["70128.50", "1.002"], ["70129.20", "0.002"], ["70130.00", "0.008"], ["70130.10", "0.007"], ["70130.20", "0.049"], ["70130.30", "0.007"], ["70131.30", "0.011"], ["70131.40", "0.514"], ["70131.70", "0.069"], ["70132.10", "0.035"], ["70133.00", "0.133"], ["70133.10", "0.270"], ["70133.60", "0.523"], ["70136.00", "0.134"], ["70136.10", "0.005"], ["70137.80", "0.641"], ["70139.70", "0.126"], ["70139.80", "0.001"], ["70139.90", "2.935"]], "a": [["70140.00", "4.124"], ["70141.90", "0.089"], ["70146.90", "0.005"], ["70147.80", "0.003"], ["70150.00", "0.035"], ["70150.80", "0.131"], ["70152.60", "0.000"], ["70152.80", "0.000"], ["70152.90", "0.002"], ["70153.30", "0.002"], ["70154.00", "0.106"], ["70154.30", "0.000"], ["70154.40", "0.061"], ["70154.60", "0.430"], ["70154.70", "0.005"], ["70155.30", "1.001"], ["70156.90", "0.006"], ["70157.60", "0.004"], ["70158.00", "1.018"], ["70159.30", "0.006"], ["70160.30", "0.005"], ["70161.30", "0.231"], ["70162.80", "0.633"], ["70164.50", "0.795"], ["70168.10", "0.243"], ["70169.80", "0.518"], ["70170.80", "0.000"], ["70170.90", "0.004"], ["70171.50", "2.189"], ["70171.60", "0.255"], ["70172.20", "0.089"], ["70172.30", "0.095"], ["70173.00", "0.012"], ["70178.40", "0.075"], ["70182.10", "0.022"], ["70193.90", "0.045"], ["70194.00", "0.002"], ["70196.80", "0.005"], ["70199.60", "0.091"], ["70200.00", "2.919"], ["70204.90", "0.300"], ["70231.90", "0.005"], ["70240.10", "0.096"], ["70267.10", "0.003"], ["70275.30", "0.001"], ["70368.50", "0.007"], ["70499.90", "0.007"], ["70841.40", "0.000"], ["70880.00", "61.198"], ["71092.60", "68.034"], ["71142.50", "0.021"], ["71148.30", "0.000"], ["71542.70", "0.003"], ["71552.80", "0.012"], ["89523.20", "0.000"]]}}
{"local_ts": 1773237584986, "server_ts": 1773237584788, "data": {"e": "depthUpdate", "E": 1773237584792, "T": 1773237584788, "s": "BTCUSDT", "U": 10088624517270, "u": 10088624522720, "pu": 10088624517197, "b": [["1000.00", "26.642"], ["5000.00", "101.418"], ["19639.90", "0.670"], ["19841.80", "0.200"], ["19941.80", "0.390"], ["20039.90", "0.190"], ["20041.80", "0.330"], ["66600.60", "0.000"], ["69145.80", "0.594"], ["69150.90", "0.433"], ["69440.40", "0.000"], ["69602.20", "0.000"], ["69994.10", "0.806"], ["70025.50", "0.966"], ["70058.70", "0.000"], ["70059.40", "0.019"], ["70072.30", "0.008"], ["70073.30", "0.014"], ["70090.50", "0.283"], ["70091.50", "0.033"], ["70120.20", "0.003"], ["70130.80", "0.003"], ["70132.00", "0.008"], ["70137.50", "0.004"], ["70139.90", "0.025"], ["70140.90", "0.002"], ["70141.30", "0.002"], ["70141.80", "11.444"]], "a": [["70141.90", "2.720"], ["70149.90", "1.940"], ["70156.80", "0.000"], ["70158.40", "1.002"], ["70161.20", "0.004"], ["70162.50", "0.004"], ["70167.20", "0.003"], ["70169.00", "0.008"], ["70169.20", "0.008"], ["70170.00", "0.423"], ["70171.00", "0.084"], ["70362.90", "0.309"], ["70681.40", "0.306"], ["70843.30", "0.000"], ["71191.70", "0.002"], ["71192.70", "0.000"], ["89523.20", "0.000"]]}}
{"local_ts": 1773237586009, "server_ts": 1773237585811, "data": {"e": "depthUpdate", "E": 1773237585812, "T": 1773237585811, "s": "BTCUSDT", "U": 10088624625379, "u": 10088624631579, "pu": 10088624625263, "b": [["5000.00", "101.418"], ["19731.80", "0.050"], ["19831.80", "0.150"], ["19841.80", "1.000"], ["19931.80", "0.100"], ["19939.90", "0.340"], ["19941.70", "0.000"], ["20041.80", "0.670"], ["66594.30", "0.000"], ["66625.00", "0.065"], ["68900.00", "11.646"], ["68974.70", "1.014"], ["68987.70", "0.000"], ["69150.00", "2.488"], ["69430.50", "0.000"], ["69904.40", "0.005"], ["70027.10", "0.642"], ["70030.20", "6.948"], ["70030.80", "1.506"], ["70044.70", "0.207"], ["70048.60", "0.014"], ["70061.60", "0.003"], ["70062.30", "0.010"], ["70065.50", "0.002"], ["70066.00", "0.020"], ["70072.90", "0.002"], ["70076.70", "0.002"], ["70080.20", "0.005"], ["70080.30", "0.027"], ["70083.70", "0.002"], ["70085.30", "0.009"], ["70086.00", "0.006"], ["70087.20", "0.004"], ["70089.90", "0.000"], ["70096.00", "0.009"], ["70104.90", "0.218"], ["70105.40", "0.009"], ["70111.80", "0.800"], ["70112.00", "0.044"], ["70112.10", "0.201"], ["70113.00", "0.717"], ["70113.20", "0.029"], ["70114.00", "0.002"], ["70114.80", "0.029"], ["70114.90", "0.312"], ["70116.70", "0.012"], ["70120.10", "0.012"], ["70120.70", "0.514"], ["70122.30", "0.644"], ["70122.60", "0.000"], ["70124.60", "0.027"], ["70125.00", "0.278"], ["70125.10", "0.000"], ["70125.30", "0.092"], ["70127.50", "0.004"], ["70128.70", "0.000"], ["70129.40", "0.005"], ["70130.10", "0.028"]], "a": [["70131.90", "6.543"], ["70132.00", "0.460"], ["70132.10", "0.001"], ["70132.20", "0.002"], ["70132.30", "0.049"], ["70132.40", "0.041"], ["70132.50", "0.002"], ["70133.60", "0.004"], ["70134.00", "0.000"], ["70137.20", "0.178"], ["70137.30", "0.002"], ["70139.20", "0.004"], ["70140.40", "0.049"], ["70141.70", "0.350"], ["70141.80", "0.200"], ["70141.90", "0.051"], ["70143.70", "0.004"], ["70143.90", "0.007"], ["70145.60", "0.002"], ["70145.90", "0.008"], ["70146.80", "0.000"], ["70148.70", "0.007"], ["70152.70", "0.111"], ["70153.30", "0.055"], ["70153.50", "0.193"], ["70153.80", "0.209"], ["70154.80", "0.007"], ["70161.40", "0.007"], ["70162.80", "0.030"], ["70163.00", "0.002"], ["70163.20", "0.004"], ["70165.90", "0.060"], ["70166.00", "0.003"], ["70173.60", "0.000"], ["70173.70", "0.004"], ["70183.70", "0.096"], ["70184.40", "0.000"], ["70185.10", "0.592"], ["70186.30", "0.859"], ["70187.30", "0.100"], ["70197.20", "0.045"], ["70198.50", "0.086"], ["70198.70", "0.349"], ["70201.70", "0.044"], ["70202.50", "1.058"], ["70207.40", "0.043"], ["70212.30", "0.043"], ["70219.50", "0.043"], ["70220.50", "0.714"], ["70226.40", "0.088"], ["70233.10", "0.208"], ["70234.90", "0.043"], ["70236.60", "0.345"], ["70239.40", "0.084"], ["70243.90", "0.045"], ["70249.40", "0.043"], ["70253.80", "0.000"], ["70255.70", "0.043"], ["70261.90", "0.043"], ["70274.20", "1.556"], ["70342.90", "0.807"], ["70430.70", "0.062"], ["70432.60", "0.000"], ["70435.40", "0.000"], ["70439.00", "0.000"], ["70833.20", "0.003"], ["71224.30", "0.260"], ["73568.40", "0.002"], ["73609.00", "0.100"], ["89523.20", "0.000"]]}}
{"local_ts": 1773237587027, "server_ts": 1773237586830, "data": {"e": "depthUpdate", "E": 1773237586832, "T": 1773237586830, "s": "BTCUSDT", "U": 10088624725037, "u": 10088624730016, "pu": 10088624725010, "b": [["1000.00", "26.642"], ["5000.00", "101.418"], ["19727.10", "1.150"], ["19827.10", "0.160"], ["19832.30", "0.100"], ["19927.10", "0.620"], ["19932.30", "0.040"], ["20032.30", "0.000"], ["63114.40", "0.006"], ["66608.70", "0.000"], ["66629.20", "0.002"], ["66971.30", "0.073"], ["68731.20", "0.000"], ["69021.20", "0.000"], ["69138.40", "0.361"], ["69201.10", "0.008"], ["69406.90", "0.000"], ["69423.70", "0.000"], ["69425.80", "0.000"], ["69566.90", "0.000"], ["69697.80", "0.006"], ["69698.10", "0.663"], ["69772.90", "0.000"], ["70016.80", "0.001"], ["70037.10", "0.005"], ["70051.90", "0.004"], ["70057.90", "0.207"], ["70058.90", "0.014"], ["70060.10", "0.063"], ["70064.00", "0.062"], ["70066.70", "0.943"], ["70067.10", "0.000"], ["70067.40", "0.209"], ["70084.00", "1.870"], ["70085.30", "0.006"], ["70090.50", "0.095"], ["70092.00", "0.004"], ["70095.60", "0.019"], ["70096.70", "0.255"], ["70098.10", "0.581"], ["70098.80", "0.005"], ["70099.20", "0.000"], ["70100.10", "0.004"], ["70103.10", "0.014"], ["70105.20", "0.000"], ["70106.40", "0.519"], ["70107.20", "0.011"], ["70107.30", "0.007"], ["70108.20", "0.071"], ["70108.30", "0.002"], ["70108.40", "0.006"], ["70109.00", "0.002"], ["70110.60", "0.004"], ["70111.10", "0.023"], ["70111.20", "0.021"], ["70111.60", "1.226"], ["70113.30", "0.030"], ["70113.70", "0.002"], ["70114.20", "0.035"], ["70114.40", "0.000"], ["70114.60", "0.003"], ["70115.00", "0.006"], ["70116.60", "0.006"], ["70116.90", "0.002"], ["70117.00", "1.002"], ["70118.70", "0.000"], ["70121.50", "0.004"], ["70122.40", "0.209"], ["70125.10", "0.000"], ["70127.10", "3.961"]], "a": [["70127.20", "3.196"], ["70132.20", "0.005"], ["70133.30", "0.197"], ["70135.40", "0.347"], ["70135.50", "1.029"], ["70136.10", "0.003"], ["70136.60", "0.121"], ["70137.40", "0.011"], ["70139.10", "0.216"], ["70139.20", "0.005"], ["70141.20", "0.192"], ["70141.50", "0.144"], ["70143.40", "1.147"], ["70144.70", "0.324"], ["70147.40", "0.615"], ["70152.60", "0.003"], ["70155.30", "0.721"], ["70155.80", "0.008"], ["70159.80", "0.002"], ["70163.70", "0.213"], ["70182.10", "0.005"], ["70196.80", "0.002"], ["70231.90", "0.002"], ["70252.40", "0.006"], ["70301.10", "0.191"], ["70355.50", "0.000"], ["70430.50", "0.002"], ["70476.60", "0.002"], ["70531.20", "0.007"], ["70593.70", "0.000"], ["70688.00", "0.165"], ["70716.20", "0.020"], ["70828.40", "0.469"], ["70828.50", "0.003"], ["70829.90", "0.000"], ["71092.60", "0.000"], ["71130.90", "0.491"], ["71287.40", "0.000"], ["71544.70", "0.293"], ["73634.50", "0.002"], ["77139.90", "0.002"], ["89523.20", "0.000"]]}}
{"local_ts": 1773237588046, "server_ts": 1773237587851, "data": {"e": "depthUpdate", "E": 1773237587852, "T": 1773237587851, "s": "BTCUSDT", "U": 10088624795785, "u": 10088624805551, "pu": 10088624795767, "b": [["5000.00", "101.398"], ["19620.80", "0.780"], ["19727.10", "0.750"], ["19820.80", "0.420"], ["19927.10", "0.120"], ["33000.00", "10.800"], ["63108.70", "0.002"], ["66603.50", "0.004"], ["66629.20", "0.000"], ["68156.70", "0.000"], ["68718.40", "0.005"], ["69419.20", "0.010"], ["69419.60", "1.418"], ["69423.80", "0.060"], ["69995.70", "0.005"], ["70012.50", "0.459"], ["70014.60", "0.155"], ["70030.80", "0.520"], ["70037.10", "0.002"], ["70039.30", "0.019"], ["70050.70", "0.855"], ["70052.50", "0.111"], ["70053.30", "0.022"], ["70054.20", "0.084"], ["70055.50", "0.492"], ["70056.40", "0.094"], ["70063.20", "0.000"], ["70065.90", "0.006"], ["70067.40", "0.207"], ["70075.60", "0.000"], ["70076.20", "0.005"], ["70076.80", "0.518"], ["70077.90", "0.947"], ["70088.80", "0.070"], ["70092.70", "0.217"], ["70095.60", "0.013"], ["70100.40", "0.071"], ["70101.00", "0.007"], ["70102.00", "0.002"], ["70102.60", "0.000"], ["70105.10", "0.005"], ["70105.40", "0.009"], ["70106.00", "0.044"], ["70109.80", "0.002"], ["70111.80", "0.126"], ["70113.30", "0.010"], ["70116.60", "0.010"], ["70120.80", "4.088"]], "a": [["70120.90", "4.131"], ["70121.10", "0.002"], ["70125.90", "0.003"], ["70128.40", "0.004"], ["70130.40", "1.402"], ["70130.50", "0.514"], ["70130.60", "0.003"], ["70133.20", "0.145"], ["70134.00", "0.000"], ["70134.70", "1.002"], ["70134.90", "0.106"], ["70135.80", "0.007"], ["70136.60", "0.489"], ["70136.70", "0.000"], ["70138.10", "0.000"], ["70140.00", "0.569"], ["70140.80", "0.007"], ["70141.50", "0.290"], ["70141.70", "0.352"], ["70141.90", "0.187"], ["70143.10", "0.000"], ["70143.80", "0.072"], ["70144.90", "0.000"], ["70146.90", "0.288"], ["70148.90", "0.104"], ["70149.90", "1.942"], ["70159.00", "0.000"], ["70170.00", "0.000"], ["70175.90", "0.003"], ["70178.40", "0.000"], ["70178.50", "0.006"], ["70182.10", "0.002"], ["70191.00", "0.086"], ["70194.50", "0.145"], ["70211.00", "0.003"], ["70212.50", "0.002"], ["70218.50", "0.336"], ["70226.40", "0.012"], ["70228.30", "0.000"], ["70230.70", "0.018"], ["70231.80", "2.054"], ["70241.00", "0.089"], ["70245.20", "0.610"], ["70246.20", "0.106"], ["70248.10", "0.670"], ["70252.40", "0.003"], ["70272.80", "0.018"], ["70273.10", "0.002"], ["70273.80", "0.310"], ["70330.90", "0.002"], ["70373.40", "0.047"], ["70422.20", "0.000"], ["70422.30", "0.000"], ["70426.80", "0.000"], ["70573.00", "0.025"], ["70822.10", "0.000"], ["70968.70", "1.125"], ["71523.30", "0.601"], ["72400.00", "81.800"], ["73600.30", "0.100"], ["73608.50", "0.000"], ["73658.60", "0.000"], ["76026.20", "0.002"], ["77133.00", "0.002"]]}}
{"local_ts": 1773237589067, "server_ts": 1773237588872, "data": {"e": "depthUpdate", "E": 1773237588874, "T": 1773237588872, "s": "BTCUSDT", "U": 10088624917180, "u": 10088624925917, "pu": 10088624916869, "b": [["1000.00", "26.642"], ["5000.00", "101.398"], ["19620.80", "1.020"], ["19624.90", "0.150"], ["19628.30", "0.000"], ["19629.80", "0.000"], ["19729.80", "0.370"], ["19820.80", "0.270"], ["20029.80", "0.590"], ["63116.80", "0.002"], ["66590.40", "0.010"], ["66629.20", "0.002"], ["68727.30", "0.439"], ["69139.90", "0.002"], ["69142.40", "0.000"], ["69145.30", "1.154"], ["69428.50", "0.134"], ["69823.50", "6.995"], ["69829.50", "0.000"], ["69858.50", "0.036"], ["69858.60", "0.036"], ["69859.40", "0.050"], ["69860.10", "0.027"], ["69995.70", "0.002"], ["70004.70", "0.290"], ["70028.20", "0.002"], ["70030.80", "0.000"], ["70039.80", "0.037"], ["70052.70", "0.151"], ["70055.60", "0.000"], ["70065.90", "0.003"], ["70074.90", "0.301"], ["70082.30", "0.012"], ["70083.80", "0.032"], ["70086.90", "0.383"], ["70091.00", "0.657"], ["70092.90", "1.977"], ["70093.00", "0.284"], ["70094.00", "0.088"], ["70097.80", "0.608"], ["70100.80", "0.052"], ["70101.00", "0.004"], ["70103.20", "0.002"], ["70104.90", "0.333"], ["70106.00", "0.003"], ["70106.90", "0.002"], ["70107.30", "0.005"], ["70107.80", "0.000"], ["70110.10", "0.009"], ["70111.60", "0.002"], ["70111.70", "0.039"], ["70112.00", "0.006"], ["70112.70", "0.038"], ["70114.10", "0.290"], ["70114.90", "0.629"], ["70115.80", "0.290"], ["70118.30", "0.009"], ["70118.50", "0.000"], ["70119.10", "0.114"], ["70119.90", "0.009"], ["70120.20", "0.028"], ["70120.50", "0.025"], ["70123.30", "0.144"], ["70125.20", "0.844"], ["70125.50", "0.005"], ["70129.10", "0.000"], ["70129.80", "10.868"]], "a": [["70132.20", "0.004"], ["70137.10", "0.172"], ["70137.30", "0.004"], ["70138.90", "0.018"], ["70139.10", "0.016"], ["70139.30", "0.016"], ["70139.40", "0.173"], ["70139.50", "0.969"], ["70139.60", "0.000"], ["70139.80", "0.000"], ["70139.90", "0.000"], ["70140.00", "0.273"], ["70141.20", "0.006"], ["70141.30", "0.345"], ["70141.60", "0.007"], ["70144.70", "0.005"], ["70145.20", "0.000"], ["70146.90", "0.002"], ["70147.50", "0.048"], ["70149.70", "0.007"], ["70150.50", "0.481"], ["70150.70", "0.007"], ["70150.80", "0.001"], ["70154.10", "1.065"], ["70155.90", "0.394"], ["70156.50", "0.051"], ["70156.80", "0.050"], ["70157.90", "0.686"], ["70175.90", "0.000"], ["70184.30", "0.004"], ["70184.80", "0.003"], ["70185.20", "0.297"], ["70191.70", "0.006"], ["70194.60", "0.002"], ["70205.70", "3.483"], ["70211.00", "0.000"], ["70216.10", "0.002"], ["70219.90", "9.818"], ["70246.20", "0.103"], ["70255.10", "0.003"], ["70284.20", "0.705"], ["70289.60", "0.006"], ["70402.60", "0.050"], ["70403.30", "0.045"], ["70404.10", "0.159"], ["70500.00", "12.043"], ["70831.20", "0.000"], ["70894.20", "0.915"], ["71117.20", "0.942"], ["71140.00", "0.133"], ["71142.50", "0.019"], ["71532.40", "0.006"], ["77142.90", "0.002"]]}}
{"local_ts": 1773237590087, "server_ts": 1773237589893, "data": {"e": "depthUpdate", "E": 1773237589894, "T": 1773237589893, "s": "BTCUSDT", "U": 10088624980382, "u": 10088624992773, "pu": 10088624980326, "b": [["1000.00", "26.642"], ["5000.00", "101.418"], ["19620.80", "0.000"], ["19633.80", "0.580"], ["19729.80", "0.060"], ["19933.80", "0.520"], ["20029.80", "0.660"], ["20033.80", "0.580"], ["33000.00", "10.804"], ["40000.00", "51.271"], ["60763.60", "0.000"], ["63120.40", "0.002"], ["66605.70", "0.000"], ["66629.20", "0.000"], ["68739.00", "0.013"], ["69347.80", "5.426"], ["69432.50", "0.000"], ["69572.70", "0.002"], ["69594.30", "0.002"], ["69599.10", "0.005"], ["69833.10", "0.000"], ["69862.30", "0.353"], ["69895.20", "0.005"], ["69945.70", "0.000"], ["70000.90", "1.521"], ["70015.00", "0.000"], ["70042.00", "0.415"], ["70051.90", "0.051"], ["70056.70", "0.004"], ["70056.80", "0.002"], ["70062.60", "0.008"], ["70064.20", "0.000"], ["70065.20", "0.020"], ["70071.90", "2.029"], ["70072.10", "4.205"], ["70072.70", "0.004"], ["70079.50", "1.239"], ["70081.30", "0.005"], ["70084.90", "0.004"], ["70090.40", "0.192"], ["70095.70", "2.142"], ["70095.90", "0.000"], ["70101.80", "0.000"], ["70111.50", "0.002"], ["70114.00", "0.005"], ["70114.40", "0.460"], ["70114.60", "0.485"], ["70115.80", "0.004"], ["70117.50", "0.513"], ["70119.70", "0.007"], ["70119.80", "0.292"], ["70119.90", "0.288"], ["70120.20", "0.121"], ["70121.50", "0.005"], ["70121.90", "0.049"], ["70122.00", "0.002"], ["70122.20", "0.000"], ["70122.30", "0.122"], ["70122.50", "0.043"], ["70122.60", "0.202"], ["70122.70", "0.045"], ["70122.80", "0.016"], ["70123.00", "0.029"], ["70123.20", "0.071"], ["70123.30", "0.246"], ["70123.40", "0.005"], ["70123.90", "0.025"], ["70124.20", "0.032"], ["70124.30", "0.091"], ["70124.90", "0.055"], ["70125.20", "1.217"], ["70125.40", "0.549"], ["70129.50", "0.002"], ["70129.80", "0.009"], ["70131.00", "0.003"], ["70131.50", "0.002"], ["70132.60", "0.015"], ["70133.80", "7.405"]], "a": [["70133.90", "0.188"], ["70134.00", "0.003"], ["70140.00", "0.009"], ["70140.40", "0.009"], ["70141.90", "0.007"], ["70142.30", "0.006"], ["70142.80", "0.002"], ["70142.90", "0.004"], ["70143.00", "0.046"], ["70143.20", "0.000"], ["70143.60", "0.348"], ["70145.70", "0.096"], ["70145.80", "0.971"], ["70146.20", "0.000"], ["70147.20", "0.003"], ["70147.30", "0.637"], ["70147.60", "0.006"], ["70148.30", "0.068"], ["70149.50", "0.009"], ["70149.70", "0.007"], ["70149.80", "0.006"], ["70149.90", "1.942"], ["70150.30", "0.004"], ["70150.40", "0.000"], ["70150.50", "0.037"], ["70150.60", "0.000"], ["70152.20", "0.002"], ["70152.40", "0.025"], ["70153.50", "0.004"], ["70154.00", "0.148"], ["70154.60", "0.145"], ["70154.80", "0.846"], ["70157.80", "1.082"], ["70159.90", "0.146"], ["70160.20", "0.111"], ["70160.50", "0.004"], ["70160.90", "0.090"], ["70161.10", "0.857"], ["70162.10", "0.000"], ["70162.60", "0.150"], ["70163.90", "0.295"], ["70164.10", "0.013"], ["70166.20", "0.011"], ["70168.20", "0.086"], ["70170.70", "0.221"], ["70171.30", "0.038"], ["70172.80", "0.081"], ["70179.90", "0.002"], ["70181.30", "1.906"], ["70199.30", "0.132"], ["70242.20", "0.184"], ["70242.50", "0.408"], ["70265.90", "0.004"], ["70266.70", "1.633"], ["70278.20", "0.002"], ["70313.60", "0.086"], ["70316.70", "0.086"], ["70323.40", "0.040"], ["70431.00", "0.289"], ["70431.10", "0.293"], ["70673.30", "0.002"], ["70835.20", "0.000"], ["71115.80", "0.494"], ["71426.40", "0.000"], ["73599.70", "0.100"], ["73608.20", "0.010"], ["77147.30", "0.002"]]}}
{"local_ts": 1773237591106, "server_ts": 1773237590913, "data": {"e": "depthUpdate", "E": 1773237590914, "T": 1773237590913, "s": "BTCUSDT", "U": 10088625087333, "u": 10088625091612, "pu": 10088625087311, "b": [["5000.00", "101.418"], ["19633.80", "0.570"], ["19831.80", "0.160"], ["19931.80", "0.170"], ["19937.50", "0.600"], ["20029.80", "0.080"], ["20031.80", "0.160"], ["59052.70", "0.700"], ["63118.60", "0.002"], ["66602.30", "0.002"], ["66630.00", "0.030"], ["66634.80", "0.002"], ["68729.20", "1.092"], ["69430.50", "0.000"], ["69899.00", "0.005"], ["70004.90", "0.294"], ["70008.30", "0.305"], ["70041.50", "2.684"], ["70042.80", "0.126"], ["70043.60", "0.002"], ["70045.80", "0.288"], ["70048.00", "0.102"], ["70054.70", "0.084"], ["70058.20", "0.291"], ["70062.00", "0.702"], ["70062.60", "0.287"], ["70065.70", "0.000"], ["70066.60", "0.910"], ["70073.50", "3.634"], ["70082.50", "0.004"], ["70083.20", "0.355"], ["70083.90", "0.007"], ["70084.60", "0.004"], ["70087.60", "0.030"], ["70090.40", "0.119"], ["70093.20", "0.159"], ["70096.70", "0.322"], ["70097.10", "1.930"], ["70100.30", "0.008"], ["70100.60", "0.115"], ["70103.50", "0.207"], ["70103.60", "0.026"], ["70104.20", "0.004"], ["70104.30", "0.006"], ["70104.90", "0.599"], ["70105.00", "0.195"], ["70106.50", "0.354"], ["70106.60", "0.520"], ["70107.20", "0.009"], ["70107.30", "0.006"], ["70108.10", "0.071"], ["70108.60", "0.520"], ["70109.40", "0.074"], ["70109.50", "0.000"], ["70109.90", "0.001"], ["70110.20", "0.045"], ["70111.40", "0.010"], ["70111.70", "0.001"], ["70113.00", "1.213"], ["70115.00", "0.018"], ["70115.70", "0.394"], ["70116.50", "0.050"], ["70120.80", "0.008"], ["70121.30", "0.058"], ["70122.10", "0.002"], ["70122.50", "0.008"], ["70125.30", "0.680"], ["70126.90", "0.045"], ["70128.10", "0.082"], ["70128.70", "0.000"], ["70129.00", "0.002"], ["70129.30", "0.036"], ["70131.60", "0.000"], ["70131.80", "4.232"]], "a": [["70131.90", "4.295"], ["70136.40", "0.004"], ["70137.80", "0.007"], ["70138.50", "0.004"], ["70139.90", "0.004"], ["70140.40", "0.009"], ["70140.60", "0.351"], ["70142.20", "0.002"], ["70142.30", "1.016"], ["70142.40", "0.000"], ["70142.60", "0.007"], ["70143.40", "1.073"], ["70143.50", "0.007"], ["70143.60", "0.605"], ["70143.90", "0.004"], ["70144.20", "0.139"], ["70144.40", "0.006"], ["70144.80", "0.005"], ["70145.10", "0.000"], ["70145.20", "0.514"], ["70145.30", "0.004"], ["70145.90", "0.008"], ["70146.00", "0.000"], ["70146.10", "0.002"], ["70146.50", "1.000"], ["70147.20", "0.003"], ["70148.40", "0.205"], ["70149.40", "0.003"], ["70150.50", "0.349"], ["70151.80", "0.012"], ["70153.20", "0.005"], ["70153.70", "0.285"], ["70153.90", "0.516"], ["70155.10", "0.244"], ["70156.40", "0.290"], ["70159.00", "0.002"], ["70159.90", "0.072"], ["70160.80", "0.862"], ["70161.10", "0.073"], ["70162.90", "0.254"], ["70163.30", "0.000"], ["70163.50", "0.000"], ["70164.80", "0.000"], ["70165.20", "0.009"], ["70165.30", "0.009"], ["70165.90", "0.002"], ["70166.00", "0.003"], ["70166.60", "0.000"], ["70166.70", "0.000"], ["70167.30", "0.002"], ["70167.40", "0.120"], ["70168.00", "0.538"], ["70168.10", "0.000"], ["70180.00", "1.320"], ["70180.30", "0.047"], ["70181.80", "0.046"], ["70182.50", "0.002"], ["70182.80", "0.006"], ["70183.40", "0.010"], ["70184.10", "0.000"], ["70184.40", "0.000"], ["70184.80", "0.003"], ["70188.00", "0.014"], ["70190.80", "0.192"], ["70198.50", "0.195"], ["70202.00", "0.009"], ["70219.60", "0.008"], ["70262.60", "0.000"], ["70280.10", "0.000"], ["70283.40", "0.820"], ["70289.50", "0.002"], ["70289.70", "0.124"], ["70290.20", "0.000"], ["70833.20", "0.003"], ["70839.00", "0.950"], ["71014.20", "0.146"], ["71075.30", "3.482"], ["71385.30", "1.109"], ["73607.80", "0.100"], ["73620.20", "0.005"], ["77145.10", "0.002"]]}}
{"local_ts": 1773237592128, "server_ts": 1773237591936, "data": {"e": "depthUpdate", "E": 1773237591938, "T": 1773237591936, "s": "BTCUSDT", "U": 10088625140071, "u": 10088625144114, "pu": 10088625140001, "b": [["1000.00", "26.792"], ["5000.00", "101.398"], ["19731.80", "0.160"], ["19831.80", "1.610"], ["19837.50", "0.000"], ["19931.80", "0.510"], ["19933.80", "0.000"], ["20031.80", "0.720"], ["20037.50", "0.000"], ["63118.60", "0.000"], ["66623.40", "0.017"], ["66634.80", "0.000"], ["69430.50", "0.719"], ["69592.30", "0.002"], ["69688.40", "40.889"], ["69724.20", "0.000"], ["69726.70", "0.033"], ["69976.60", "0.000"], ["70004.90", "0.292"], ["70007.30", "0.188"], ["70062.60", "0.005"], ["70063.40", "0.005"], ["70091.40", "0.371"], ["70121.70", "0.002"], ["70122.00", "0.082"], ["70122.50", "0.016"], ["70122.80", "0.096"], ["70123.40", "0.005"]], "a": [["70131.90", "3.769"], ["70137.00", "0.002"], ["70140.40", "0.009"], ["70141.40", "0.058"], ["70142.40", "0.000"], ["70142.60", "0.434"], ["70142.80", "0.002"], ["70143.50", "0.434"], ["70145.10", "0.425"], ["70145.90", "0.092"], ["70146.30", "0.115"], ["70146.40", "0.028"], ["70146.50", "0.000"], ["70147.70", "0.686"], ["70148.10", "1.002"], ["70149.70", "0.005"], ["70159.30", "0.040"], ["70159.40", "0.006"], ["70163.50", "0.241"], ["70170.50", "0.243"], ["70172.10", "0.037"], ["70172.30", "0.003"], ["70174.10", "0.059"], ["70175.00", "0.040"], ["70178.30", "0.032"], ["70188.30", "0.011"], ["70188.70", "0.021"], ["70200.30", "0.003"], ["70217.10", "0.012"], ["70256.50", "0.300"], ["70265.90", "0.018"], ["70275.20", "0.000"], ["70671.30", "0.002"], ["70833.20", "0.003"], ["73595.90", "0.100"], ["73607.80", "0.000"], ["77145.10", "0.000"]]}}
{"local_ts": 1773237593153, "server_ts": 1773237592959, "data": {"e": "depthUpdate", "E": 1773237592960, "T": 1773237592959, "s": "BTCUSDT", "U": 10088625186441, "u": 10088625191142, "pu": 10088625186354, "b": [["5000.00", "101.438"], ["19631.80", "0.010"], ["19731.80", "1.610"], ["19831.80", "0.510"], ["19931.80", "0.870"], ["56106.00", "0.000"], ["63118.60", "0.000"], ["66622.50", "0.002"], ["69430.50", "0.719"], ["69712.00", "0.000"], ["70006.90", "0.049"], ["70007.30", "0.186"], ["70063.40", "0.005"], ["70078.20", "0.051"], ["70091.40", "0.371"], ["70120.80", "0.052"], ["70123.70", "0.004"], ["70125.50", "1.058"]], "a": [["70132.40", "0.004"], ["70141.90", "0.104"], ["70142.40", "0.000"], ["70150.70", "0.026"], ["70163.50", "0.241"], ["70165.50", "0.000"], ["70170.50", "0.263"], ["70172.30", "0.003"], ["70187.40", "0.026"], ["70188.20", "0.102"], ["70200.30", "0.003"], ["70226.60", "0.018"], ["70256.50", "0.300"], ["70280.60", "0.517"], ["70280.80", "0.000"], ["70286.90", "0.129"], ["70393.10", "0.005"], ["70833.20", "0.003"], ["71100.00", "8.452"], ["72361.00", "0.592"], ["73658.10", "0.000"], ["77145.10", "0.000"]]}}
{"local_ts": 1773237594175, "server_ts": 1773237593980, "data": {"e": "depthUpdate", "E": 1773237593982, "T": 1773237593980, "s": "BTCUSDT", "U": 10088625249991, "u": 10088625253971, "pu": 10088625249820, "b": [["1000.00", "26.792"], ["5000.00", "101.418"], ["19631.80", "1.330"], ["19731.80", "0.670"], ["19831.80", "0.990"], ["19931.80", "0.010"], ["63118.60", "0.000"], ["69430.50", "0.719"], ["69497.30", "0.002"], ["69504.10", "0.016"], ["69671.00", "0.000"], ["69677.90", "0.008"], ["69845.20", "0.226"], ["69852.10", "0.004"], ["70005.60", "0.002"], ["70006.90", "0.047"], ["70019.80", "0.000"], ["70026.70", "0.355"], ["70062.60", "0.287"], ["70122.60", "0.244"], ["70122.70", "0.861"], ["70131.80", "4.039"]], "a": [["70143.60", "0.243"], ["70149.40", "0.003"], ["70163.50", "0.102"], ["70166.40", "0.095"], ["70167.60", "0.534"], ["70187.30", "0.042"], ["70187.40", "0.024"], ["70201.50", "0.032"], ["70205.00", "0.331"], ["70230.10", "0.002"], ["70237.00", "0.002"], ["70388.50", "1.234"], ["70392.30", "0.000"], ["70405.70", "0.006"], ["70412.60", "0.006"], ["70581.70", "0.000"], ["70588.60", "0.008"], ["70758.10", "0.000"], ["70765.10", "0.016"], ["70833.20", "0.003"], ["73287.80", "0.066"], ["73671.60", "0.002"], ["75888.00", "57.722"], ["77145.10", "0.000"]]}}
{"local_ts": 1773237595201, "server_ts": 1773237595005, "data": {"e": "depthUpdate", "E": 1773237595006, "T": 1773237595005, "s": "BTCUSDT", "U": 10088625330485, "u": 10088625336742, "pu": 10088625330430, "b": [["1000.00", "26.792"], ["5000.00", "101.418"], ["19631.80", "0.960"], ["19731.80", "0.840"], ["19831.80", "0.160"], ["20031.80", "1.040"], ["63118.60", "0.000"], ["66599.30", "0.002"], ["68637.30", "0.623"], ["69081.50", "1.453"], ["69430.50", "0.719"], ["69542.60", "0.276"], ["69826.80", "0.002"], ["69847.20", "0.036"], ["69849.20", "0.000"], ["69862.50", "0.039"], ["69863.50", "0.036"], ["69863.70", "0.094"], ["69865.20", "0.025"], ["69930.40", "13.681"], ["69986.90", "0.061"], ["69990.50", "0.000"], ["69998.60", "0.002"], ["70005.60", "0.000"], ["70018.30", "0.006"], ["70021.90", "0.000"], ["70041.40", "7.448"], ["70050.20", "0.008"], ["70051.10", "0.000"], ["70054.70", "0.000"], ["70063.40", "0.144"], ["70068.70", "0.855"], ["70072.30", "0.863"], ["70073.30", "0.287"], ["70078.20", "0.013"], ["70091.60", "0.305"], ["70096.70", "0.073"], ["70103.50", "0.224"], ["70103.70", "0.861"], ["70105.00", "0.444"], ["70109.10", "0.006"], ["70109.40", "0.003"], ["70112.30", "0.000"], ["70114.30", "0.008"], ["70114.60", "0.071"], ["70115.80", "0.002"], ["70116.80", "0.063"], ["70118.20", "0.012"], ["70118.60", "0.595"], ["70120.00", "0.080"], ["70120.10", "0.146"], ["70120.50", "0.000"], ["70121.30", "0.007"], ["70122.50", "0.022"], ["70122.90", "0.000"], ["70123.00", "0.110"], ["70123.80", "0.094"], ["70123.90", "0.518"], ["70124.80", "0.055"], ["70125.10", "0.002"], ["70125.50", "0.077"], ["70125.70", "0.000"], ["70125.90", "0.643"], ["70127.30", "0.035"], ["70129.40", "0.002"], ["70130.20", "0.002"], ["70131.80", "3.842"]], "a": [["70131.90", "2.792"], ["70137.40", "0.021"], ["70139.90", "0.004"], ["70141.10", "0.006"], ["70141.20", "0.113"], ["70143.10", "0.495"], ["70143.60", "0.147"], ["70145.90", "0.345"], ["70146.20", "0.090"], ["70147.10", "0.008"], ["70147.20", "0.196"], ["70147.50", "0.000"], ["70148.30", "0.000"], ["70148.70", "0.000"], ["70148.90", "0.144"], ["70149.50", "0.006"], ["70149.80", "2.595"], ["70149.90", "1.945"], ["70150.40", "0.022"], ["70151.10", "0.000"], ["70151.50", "0.008"], ["70152.90", "0.000"], ["70153.90", "0.589"], ["70154.30", "0.193"], ["70154.80", "0.534"], ["70155.50", "0.009"], ["70155.70", "0.285"], ["70156.70", "0.009"], ["70156.80", "0.009"], ["70157.80", "0.614"], ["70159.10", "0.000"], ["70161.30", "0.515"], ["70161.60", "0.052"], ["70162.40", "0.015"], ["70162.50", "0.013"], ["70163.10", "0.073"], ["70163.20", "0.004"], ["70163.50", "0.139"], ["70164.90", "0.004"], ["70166.80", "0.000"], ["70167.30", "0.071"], ["70167.70", "0.025"], ["70170.10", "0.604"], ["70170.20", "0.641"], ["70170.50", "0.297"], ["70170.70", "0.016"], ["70170.90", "0.144"], ["70175.30", "0.516"], ["70177.40", "0.208"], ["70186.20", "0.347"], ["70186.60", "0.020"], ["70193.70", "1.275"], ["70198.50", "0.009"], ["70204.70", "1.220"], ["70213.60", "0.000"], ["70376.70", "0.002"], ["70388.50", "1.232"], ["70833.20", "0.003"], ["70888.00", "203.714"], ["71344.10", "0.600"], ["77145.10", "0.000"]]}}
{"local_ts": 1773237596221, "server_ts": 1773237596024, "data": {"e": "depthUpdate", "E": 1773237596026, "T": 1773237596024, "s": "BTCUSDT", "U": 10088625387844, "u": 10088625392124, "pu": 10088625387683, "b": [["5000.00", "101.418"], ["19631.80", "0.690"], ["19731.80", "0.310"], ["19931.80", "0.740"], ["20031.80", "1.260"], ["63118.60", "0.000"], ["66599.50", "0.002"], ["66624.30", "0.002"], ["68037.60", "0.002"], ["68729.20", "1.107"], ["69367.40", "2.447"], ["69430.50", "0.719"], ["69550.00", "0.432"], ["69997.70", "0.287"], ["70000.00", "3.826"], ["70007.30", "0.186"], ["70029.10", "1.082"], ["70051.10", "0.205"], ["70063.40", "0.005"], ["70072.20", "0.000"], ["70075.90", "0.002"], ["70076.90", "0.000"], ["70079.50", "0.384"], ["70080.50", "0.116"], ["70084.00", "0.485"], ["70090.40", "0.192"], ["70091.00", "1.133"], ["70091.40", "0.371"], ["70091.60", "0.002"], ["70091.70", "0.230"], ["70098.00", "0.494"], ["70105.00", "0.920"], ["70120.80", "0.083"], ["70121.00", "0.075"], ["70121.30", "0.217"], ["70125.90", "0.255"], ["70126.10", "0.002"], ["70126.20", "0.000"], ["70131.80", "2.342"]], "a": [["70131.90", "3.908"], ["70137.40", "0.170"], ["70140.00", "1.020"], ["70141.20", "0.206"], ["70141.90", "0.367"], ["70142.00", "1.054"], ["70143.50", "0.299"], ["70144.30", "0.000"], ["70145.90", "0.509"], ["70146.30", "0.019"], ["70146.90", "0.023"], ["70147.20", "1.003"], ["70147.30", "0.882"], ["70148.60", "0.000"], ["70148.90", "0.002"], ["70149.40", "0.154"], ["70154.00", "0.519"], ["70160.40", "0.242"], ["70161.00", "1.216"], ["70162.10", "0.178"], ["70163.50", "0.200"], ["70168.00", "1.014"], ["70172.30", "0.003"], ["70175.00", "0.496"], ["70182.00", "0.825"], ["70198.50", "0.093"], ["70200.30", "0.003"], ["70204.70", "1.218"], ["70220.00", "0.289"], ["70222.00", "1.363"], ["70256.50", "0.300"], ["70368.70", "0.142"], ["70376.70", "0.000"], ["70385.20", "0.000"], ["70393.20", "0.038"], ["70833.20", "0.003"], ["77145.10", "0.000"], ["89523.20", "0.000"]]}}
{"local_ts": 1773237597245, "server_ts": 1773237597045, "data": {"e": "depthUpdate", "E": 1773237597046, "T": 1773237597045, "s": "BTCUSDT", "U": 10088625472570, "u": 10088625488770, "pu": 10088625472538, "b": [["1000.00", "26.792"], ["5000.00", "101.438"], ["19631.80", "0.460"], ["19831.80", "0.440"], ["19931.80", "1.560"], ["20031.80", "0.540"], ["33000.00", "10.800"], ["56105.00", "0.154"], ["66606.20", "0.000"], ["66618.10", "0.002"], ["68026.10", "0.000"], ["68027.90", "0.003"], ["69135.90", "0.576"], ["69285.90", "0.000"], ["69406.60", "57.317"], ["69430.50", "0.719"], ["69566.60", "44.348"], ["70007.60", "0.132"], ["70065.30", "0.265"], ["70075.80", "0.091"], ["70084.00", "0.485"], ["70091.00", "1.133"], ["70098.00", "0.494"], ["70103.80", "0.004"], ["70105.00", "0.920"], ["70110.00", "0.576"], ["70119.20", "0.006"], ["70120.60", "0.065"], ["70122.00", "0.044"], ["70126.30", "0.282"], ["70128.20", "0.203"], ["70128.30", "0.055"], ["70128.50", "0.345"], ["70128.70", "0.004"], ["70129.30", "0.416"], ["70131.80", "6.781"]], "a": [["70131.90", "0.153"], ["70140.70", "0.000"], ["70140.90", "0.000"], ["70141.00", "0.000"], ["70141.10", "0.063"], ["70141.70", "0.002"], ["70142.80", "0.002"], ["70142.90", "0.046"], ["70143.50", "0.195"], ["70145.90", "0.092"], ["70146.80", "0.096"], ["70146.90", "1.013"], ["70147.20", "0.003"], ["70153.50", "0.070"], ["70154.00", "0.519"], ["70161.00", "1.216"], ["70163.50", "0.421"], ["70168.00", "1.014"], ["70175.00", "1.137"], ["70182.00", "0.825"], ["70198.90", "3.564"], ["70199.30", "0.085"], ["70220.00", "0.287"], ["70230.90", "0.004"], ["70274.50", "2.229"], ["70274.80", "0.123"], ["70299.90", "13.169"], ["70393.20", "0.036"], ["70714.50", "48.608"], ["70833.20", "0.244"], ["70877.20", "58.308"], ["71534.50", "0.021"], ["72231.00", "0.413"], ["72234.00", "0.035"], ["80316.00", "3.524"], ["89523.20", "0.000"]]}}
{"local_ts": 1773237598258, "server_ts": 1773237598064, "data": {"e": "depthUpdate", "E": 1773237598066, "T": 1773237598064, "s": "BTCUSDT", "U": 10088625584319, "u": 10088625603963, "pu": 10088625583836, "b": [["5000.00", "101.418"], ["19737.00", "0.020"], ["19737.40", "0.240"], ["19837.00", "0.030"], ["19837.40", "0.840"], ["19931.80", "0.120"], ["19937.00", "0.030"], ["19937.40", "0.360"], ["20031.80", "0.610"], ["20035.70", "0.000"], ["56105.00", "0.150"], ["66614.30", "0.000"], ["68033.30", "0.032"], ["68734.30", "0.003"], ["68981.20", "0.000"], ["69050.30", "1.022"], ["69121.50", "12.974"], ["69435.60", "0.000"], ["69436.00", "0.000"], ["69597.80", "0.000"], ["69597.90", "0.011"], ["69800.00", "3.500"], ["69898.60", "0.005"], ["69943.70", "0.004"], ["69947.20", "0.008"], ["69968.50", "0.019"], ["70043.60", "0.002"], ["70044.50", "0.292"], ["70049.40", "0.355"], ["70052.80", "0.411"], ["70056.30", "1.276"], ["70059.80", "0.088"], ["70074.30", "0.012"], ["70078.90", "0.000"], ["70081.00", "0.322"], ["70084.00", "0.482"], ["70087.00", "0.005"], ["70088.20", "0.587"], ["70088.90", "0.004"], ["70091.00", "0.478"], ["70091.40", "0.349"], ["70095.30", "0.098"], ["70098.00", "1.149"], ["70100.40", "0.052"], ["70100.70", "0.005"], ["70103.40", "0.249"], ["70103.80", "0.004"], ["70104.40", "0.004"], ["70105.00", "0.668"], ["70105.10", "0.030"], ["70105.30", "0.009"], ["70107.10", "0.226"], ["70107.20", "0.002"], ["70108.90", "0.534"], ["70109.30", "0.001"], ["70113.50", "0.513"], ["70115.70", "0.416"], ["70116.10", "0.001"], ["70116.50", "1.262"], ["70116.60", "0.082"], ["70118.40", "0.008"], ["70118.60", "0.000"], ["70118.70", "0.002"], ["70118.80", "0.005"], ["70119.90", "0.006"], ["70120.00", "1.159"], ["70120.60", "0.010"], ["70120.70", "1.183"], ["70121.10", "0.225"], ["70122.20", "0.044"], ["70122.40", "0.350"], ["70122.90", "0.140"], ["70123.80", "0.000"], ["70124.70", "0.000"], ["70125.10", "0.000"], ["70125.70", "0.000"], ["70125.90", "0.233"], ["70126.20", "0.000"], ["70126.30", "0.616"], ["70126.70", "0.006"], ["70127.10", "0.000"], ["70127.20", "0.004"], ["70127.30", "0.002"], ["70127.40", "0.007"], ["70127.70", "0.002"], ["70128.20", "0.000"], ["70128.80", "0.047"], ["70129.90", "0.005"], ["70130.60", "0.002"], ["70131.80", "0.015"], ["70132.80", "0.031"], ["70133.50", "0.002"], ["70133.80", "0.006"], ["70133.90", "0.000"], ["70134.00", "0.000"], ["70134.40", "0.001"], ["70134.50", "0.001"], ["70135.60", "0.000"], ["70135.90", "0.103"], ["70136.00", "0.002"], ["70136.70", "0.000"], ["70136.90", "0.000"], ["70137.00", "0.725"], ["70137.10", "0.000"], ["70137.30", "0.000"], ["70137.40", "0.000"]], "a": [["70137.10", "11.972"], ["70137.20", "0.003"], ["70137.40", "0.002"], ["70137.50", "0.015"], ["70137.60", "0.018"], ["70138.00", "0.007"], ["70138.90", "0.006"], ["70140.60", "0.000"], ["70141.20", "0.002"], ["70141.30", "0.059"], ["70141.40", "0.006"], ["70141.60", "0.004"], ["70142.90", "0.006"], ["70143.30", "0.003"], ["70144.40", "0.082"], ["70144.50", "0.000"], ["70145.20", "0.000"], ["70146.90", "0.002"], ["70147.20", "0.000"], ["70147.40", "0.002"], ["70147.50", "0.042"], ["70147.60", "0.520"], ["70147.90", "0.208"], ["70148.00", "0.002"], ["70149.00", "0.006"], ["70149.70", "0.005"], ["70149.90", "1.944"], ["70150.50", "0.360"], ["70152.40", "0.009"], ["70153.30", "0.056"], ["70153.90", "0.287"], ["70154.00", "0.480"], ["70154.90", "0.205"], ["70156.00", "0.013"], ["70157.30", "0.002"], ["70159.50", "0.000"], ["70159.60", "0.007"], ["70159.90", "0.151"], ["70160.30", "0.000"], ["70160.40", "0.226"], ["70160.60", "0.378"], ["70161.00", "1.218"], ["70161.60", "0.102"], ["70162.00", "0.472"], ["70162.50", "0.004"], ["70162.90", "0.301"], ["70163.40", "1.143"], ["70163.50", "0.002"], ["70165.20", "0.321"], ["70165.30", "0.000"], ["70165.60", "0.515"], ["70166.60", "0.000"], ["70166.70", "0.000"], ["70167.30", "0.187"], ["70167.40", "0.569"], ["70167.60", "0.071"], ["70168.00", "1.014"], ["70170.40", "0.354"], ["70170.50", "0.000"], ["70171.20", "0.178"], ["70171.30", "1.079"], ["70171.50", "2.177"], ["70172.20", "0.301"], ["70172.30", "0.037"], ["70172.80", "0.005"], ["70172.90", "0.004"], ["70175.00", "0.496"], ["70179.20", "0.214"], ["70179.60", "0.290"], ["70182.00", "0.825"], ["70184.60", "0.078"], ["70185.40", "0.000"], ["70189.30", "0.005"], ["70189.40", "0.001"], ["70189.90", "0.855"], ["70192.30", "0.007"], ["70196.70", "0.529"], ["70198.50", "0.106"], ["70200.50", "0.320"], ["70200.60", "0.000"], ["70200.90", "0.000"], ["70201.10", "0.002"], ["70208.70", "0.200"], ["70216.20", "0.004"], ["70222.90", "0.004"], ["70230.90", "0.002"], ["70260.20", "0.178"], ["70261.20", "0.025"], ["70261.60", "0.000"], ["70272.60", "0.014"], ["70273.10", "0.002"], ["70300.70", "0.297"], ["70331.60", "0.325"], ["70332.70", "0.002"], ["70365.90", "0.017"], ["70396.00", "0.002"], ["70838.50", "0.000"], ["70838.80", "0.007"], ["70838.90", "0.000"], ["71084.40", "0.282"], ["71121.10", "0.002"], ["71122.20", "0.006"], ["71122.30", "0.000"], ["71122.50", "0.002"], ["71124.10", "0.002"], ["71126.20", "0.004"], ["71137.10", "0.489"], ["71137.50", "1.351"], ["72241.60", "0.008"], ["73665.50", "0.002"], ["89523.20", "0.000"]]}}
{"local_ts": 1773237599283, "server_ts": 1773237599088, "data": {"e": "depthUpdate", "E": 1773237599090, "T": 1773237599088, "s": "BTCUSDT", "U": 10088625690084, "u": 10088625696642, "pu": 10088625690065, "b": [["1000.00", "26.792"], ["5000.00", "101.418"], ["19634.70", "0.120"], ["19734.70", "1.070"], ["19737.40", "0.120"], ["19834.70", "0.240"], ["19837.00", "0.090"], ["19837.40", "0.000"], ["19937.40", "0.120"], ["33000.00", "10.804"], ["56105.00", "0.150"], ["56108.00", "0.005"], ["66618.20", "0.004"], ["68261.00", "0.013"], ["69277.50", "0.000"], ["69433.40", "0.000"], ["69863.90", "0.000"], ["69986.90", "0.061"], ["69990.50", "0.000"], ["69994.10", "0.515"], ["70018.30", "0.006"], ["70021.90", "0.000"], ["70025.50", "0.111"], ["70055.30", "0.365"], ["70065.10", "0.857"], ["70066.10", "0.304"], ["70068.70", "0.855"], ["70069.70", "0.377"], ["70072.30", "0.863"], ["70073.30", "0.286"], ["70075.90", "0.857"], ["70076.90", "0.286"], ["70083.70", "0.002"], ["70084.00", "0.006"], ["70091.00", "0.002"], ["70095.70", "0.235"], ["70098.00", "0.725"], ["70103.60", "0.205"], ["70103.80", "0.098"], ["70105.00", "0.192"], ["70117.50", "0.513"], ["70119.80", "0.002"], ["70122.10", "0.036"], ["70125.30", "0.025"], ["70126.60", "0.004"], ["70126.70", "0.022"], ["70126.80", "0.016"], ["70128.80", "0.523"], ["70128.90", "0.005"], ["70129.30", "0.360"], ["70129.40", "0.004"], ["70130.70", "0.002"], ["70131.10", "0.002"], ["70131.80", "1.166"], ["70131.90", "0.345"], ["70132.60", "0.001"], ["70133.70", "0.205"], ["70134.40", "0.000"], ["70134.70", "4.467"]], "a": [["70134.80", "1.910"], ["70134.90", "0.003"], ["70139.10", "0.002"], ["70141.60", "0.002"], ["70141.70", "0.054"], ["70144.40", "0.268"], ["70145.20", "0.213"], ["70145.30", "1.121"], ["70146.20", "0.016"], ["70146.80", "0.016"], ["70146.90", "0.877"], ["70147.40", "0.006"], ["70148.10", "0.000"], ["70149.80", "1.426"], ["70150.50", "0.177"], ["70152.80", "0.003"], ["70154.00", "0.004"], ["70154.20", "0.633"], ["70154.40", "0.105"], ["70154.70", "1.120"], ["70155.50", "0.004"], ["70156.20", "0.003"], ["70159.00", "0.002"], ["70161.00", "0.010"], ["70162.70", "0.096"], ["70168.00", "0.538"], ["70175.00", "0.020"], ["70175.70", "0.033"], ["70180.40", "0.025"], ["70181.20", "0.255"], ["70182.00", "0.349"], ["70183.20", "0.024"], ["70188.30", "0.011"], ["70188.80", "0.004"], ["70188.90", "0.002"], ["70194.40", "0.002"], ["70199.40", "1.792"], ["70222.90", "0.002"], ["70223.20", "0.310"], ["70264.10", "0.043"], ["70278.80", "0.002"], ["70287.70", "10.004"], ["70329.90", "0.019"], ["70331.30", "0.002"], ["70836.10", "0.000"], ["71254.10", "0.000"], ["78586.50", "0.003"], ["78587.60", "0.000"], ["78588.20", "0.000"], ["80316.00", "0.000"], ["89523.20", "0.000"]]}}
