{"local_ts": 1773378000691, "server_ts": 1773378000413, "data": {"e": "depthUpdate", "E": 1773378000415, "T": 1773378000413, "s": "BTCUSDT", "U": 10100833919544, "u": 10100833931816, "pu": 10100833919435, "b": [["1000.00", "26.142"], ["5000.00", "101.418"], ["20852.50", "0.117"], ["21052.50", "1.323"], ["21152.50", "0.477"], ["21252.50", "0.783"], ["33000.00", "9.339"], ["70210.90", "2.844"], ["70639.00", "1.047"], ["70971.60", "0.002"], ["71113.60", "0.011"], ["71192.90", "0.036"], ["71211.90", "0.061"], ["71213.40", "0.080"], ["71215.00", "0.085"], ["71217.80", "0.027"], ["71221.20", "0.105"], ["71222.30", "0.064"], ["71223.00", "0.000"], ["71254.70", "0.560"], ["71260.20", "0.045"], ["71265.10", "1.211"], ["71299.00", "0.088"], ["71304.00", "0.010"], ["71304.40", "0.009"], ["71306.20", "0.003"], ["71307.70", "0.177"], ["71309.60", "0.781"], ["71311.10", "0.001"], ["71314.20", "0.005"], ["71315.50", "0.004"], ["71322.10", "0.033"], ["71324.70", "0.104"], ["71324.90", "0.131"], ["71325.90", "0.102"], ["71326.50", "0.006"], ["71326.60", "0.029"], ["71327.50", "0.622"], ["71327.90", "0.008"], ["71328.10", "0.040"], ["71328.30", "0.000"], ["71328.60", "0.270"], ["71328.80", "0.010"], ["71329.20", "0.007"], ["71329.50", "0.043"], ["71329.60", "0.209"], ["71331.30", "0.035"], ["71332.00", "0.139"], ["71332.10", "0.001"], ["71332.20", "0.007"], ["71332.30", "0.000"], ["71332.70", "1.035"], ["71333.20", "0.210"], ["71333.60", "1.198"], ["71335.70", "0.067"], ["71336.30", "0.108"], ["71337.00", "0.030"], ["71337.50", "0.124"], ["71337.90", "0.148"], ["71338.00", "0.066"], ["71338.90", "0.291"], ["71339.60", "0.016"], ["71339.70", "0.000"], ["71339.90", "0.140"], ["71341.00", "0.724"], ["71341.80", "0.413"], ["71342.90", "0.018"], ["71343.90", "0.050"], ["71344.00", "0.050"], ["71344.20", "0.016"], ["71345.90", "0.000"], ["71348.30", "0.000"], ["71348.50", "0.003"], ["71349.00", "0.020"], ["71349.20", "0.000"], ["71350.30", "0.005"], ["71350.90", "0.212"], ["71351.60", "0.050"], ["71352.20", "0.008"], ["71352.50", "1.142"]], "a": [["71352.60", "6.052"], ["71353.40", "0.000"], ["71353.50", "0.002"], ["71353.60", "0.080"], ["71354.60", "0.000"], ["71355.60", "0.009"], ["71355.90", "0.000"], ["71356.40", "0.255"], ["71361.40", "0.295"], ["71362.40", "0.042"], ["71363.30", "0.048"], ["71363.80", "0.000"], ["71365.00", "1.422"], ["71366.30", "0.143"], ["71367.90", "0.079"], ["71394.50", "0.003"], ["71394.60", "0.623"], ["71394.70", "0.003"], ["71408.50", "0.761"], ["71493.40", "0.066"], ["71509.30", "0.062"], ["71595.80", "0.008"], ["71948.00", "0.055"], ["72066.00", "0.770"], ["72066.10", "2.218"], ["72092.40", "0.003"], ["72387.20", "1.932"], ["74923.10", "0.000"]]}}
{"local_ts": 1773378001721, "server_ts": 1773378001438, "data": {"e": "depthUpdate", "E": 1773378001439, "T": 1773378001438, "s": "BTCUSDT", "U": 10100834088173, "u": 10100834116603, "pu": 10100834088162, "b": [["1000.00", "26.142"], ["5000.00", "101.418"], ["20944.00", "0.198"], ["21052.50", "0.738"], ["21144.00", "0.099"], ["21252.50", "0.252"], ["67776.80", "0.004"], ["67778.30", "0.000"], ["68435.30", "0.625"], ["69925.50", "0.009"], ["70509.30", "0.571"], ["70630.60", "0.004"], ["70952.50", "0.028"], ["70972.20", "0.010"], ["71011.50", "0.352"], ["71013.10", "0.004"], ["71061.10", "4.081"], ["71064.00", "0.849"], ["71084.70", "0.221"], ["71085.50", "0.001"], ["71088.70", "8.985"], ["71089.00", "2.235"], ["71090.40", "0.001"], ["71093.90", "0.000"], ["71094.80", "0.083"], ["71096.00", "0.004"], ["71103.90", "5.151"], ["71106.30", "0.933"], ["71106.50", "0.004"], ["71111.50", "0.001"], ["71113.30", "0.000"], ["71114.70", "0.007"], ["71117.50", "0.231"], ["71117.60", "0.437"], ["71121.50", "0.018"], ["71125.30", "6.029"], ["71127.50", "0.520"], ["71128.50", "3.998"], ["71132.90", "0.029"], ["71136.70", "0.000"], ["71138.00", "2.326"], ["71139.40", "0.521"], ["71145.60", "0.040"], ["71146.00", "1.580"], ["71151.60", "0.000"], ["71157.60", "8.133"], ["71160.30", "0.003"], ["71160.60", "1.730"], ["71162.50", "0.036"], ["71165.60", "0.052"], ["71170.80", "0.047"], ["71171.00", "0.004"], ["71171.50", "0.009"], ["71171.70", "2.310"], ["71171.80", "0.671"], ["71173.90", "0.538"], ["71174.20", "0.061"], ["71176.50", "0.003"], ["71179.90", "0.045"], ["71180.00", "0.533"], ["71183.50", "0.505"], ["71185.00", "0.002"], ["71186.30", "0.000"], ["71187.00", "0.000"], ["71187.40", "0.061"], ["71189.70", "0.092"], ["71189.90", "0.278"], ["71191.20", "0.000"], ["71191.40", "0.123"], ["71193.00", "0.062"], ["71193.60", "0.005"], ["71195.90", "0.118"], ["71197.70", "0.090"], ["71198.60", "0.000"], ["71198.90", "0.020"], ["71201.20", "0.093"], ["71205.20", "0.996"], ["71207.70", "0.000"], ["71208.30", "0.042"], ["71210.60", "0.002"], ["71211.20", "2.971"], ["71211.30", "0.000"], ["71212.20", "2.042"], ["71214.90", "0.000"], ["71216.90", "0.001"], ["71221.80", "0.414"], ["71224.20", "0.000"], ["71225.10", "0.003"], ["71225.70", "0.096"], ["71229.20", "0.005"], ["71230.60", "0.075"], ["71230.90", "0.070"], ["71236.10", "0.212"], ["71236.40", "0.002"], ["71241.80", "0.000"], ["71242.00", "0.065"], ["71242.60", "0.343"], ["71243.00", "0.035"], ["71243.60", "0.516"], ["71245.50", "0.108"], ["71246.40", "0.000"], ["71246.50", "0.001"], ["71246.90", "0.003"], ["71247.00", "0.002"], ["71249.10", "0.000"], ["71249.20", "0.063"], ["71249.50", "1.305"], ["71250.50", "0.000"], ["71251.30", "0.535"], ["71251.40", "0.022"], ["71251.90", "0.062"], ["71252.60", "0.273"], ["71253.50", "0.082"], ["71253.60", "0.002"], ["71255.30", "0.000"], ["71255.50", "0.369"], ["71255.80", "0.539"], ["71256.60", "0.002"], ["71257.10", "0.061"], ["71257.50", "0.512"], ["71258.00", "0.007"], ["71258.60", "10.018"], ["71260.20", "0.043"], ["71260.70", "0.170"], ["71260.80", "0.087"], ["71261.10", "0.003"], ["71261.70", "2.561"], ["71262.40", "0.012"], ["71262.50", "0.042"], ["71263.30", "0.001"], ["71264.80", "0.072"], ["71265.10", "0.021"], ["71268.40", "0.000"], ["71269.60", "0.198"], ["71270.90", "0.006"], ["71271.50", "0.011"], ["71272.80", "0.502"], ["71273.30", "0.008"], ["71273.40", "0.100"], ["71275.80", "0.613"], ["71276.10", "0.083"], ["71276.20", "0.081"], ["71276.40", "0.000"], ["71276.60", "0.476"], ["71276.70", "0.036"], ["71276.90", "0.036"], ["71278.30", "0.002"], ["71278.60", "1.210"], ["71278.70", "0.226"], ["71279.30", "0.290"], ["71280.00", "0.543"], ["71280.10", "0.720"], ["71280.60", "0.002"], ["71281.80", "1.060"], ["71283.10", "0.038"], ["71283.70", "0.062"], ["71283.90", "0.043"], ["71284.30", "0.044"], ["71285.20", "0.002"], ["71285.40", "0.005"], ["71285.50", "0.000"], ["71286.30", "0.003"], ["71286.80", "0.284"], ["71286.90", "0.011"], ["71287.20", "0.461"], ["71287.50", "0.033"], ["71287.80", "0.002"], ["71287.90", "0.290"], ["71288.00", "1.610"], ["71288.40", "0.058"], ["71288.60", "0.040"], ["71289.10", "0.040"], ["71289.20", "0.070"], ["71289.30", "0.001"], ["71289.50", "0.002"], ["71289.70", "0.063"], ["71289.80", "0.872"], ["71290.00", "0.062"], ["71290.10", "0.554"], ["71290.20", "0.006"], ["71290.50", "2.119"], ["71290.80", "0.037"], ["71291.00", "0.002"], ["71291.10", "0.061"], ["71291.60", "0.506"], ["71291.80", "0.002"], ["71292.90", "0.006"], ["71293.00", "0.007"], ["71293.10", "0.063"], ["71293.30", "0.014"], ["71293.50", "0.003"], ["71293.90", "0.317"], ["71294.00", "0.281"], ["71294.30", "0.048"], ["71294.40", "0.790"], ["71294.60", "0.004"], ["71294.70", "0.001"], ["71295.30", "0.000"], ["71295.50", "0.000"], ["71295.80", "0.000"], ["71295.90", "1.035"], ["71296.00", "0.061"], ["71296.40", "0.003"], ["71296.80", "0.108"], ["71296.90", "0.255"], ["71297.00", "2.285"], ["71297.30", "0.273"], ["71297.90", "1.060"], ["71298.00", "0.008"], ["71298.10", "0.568"], ["71298.30", "0.373"], ["71298.50", "0.182"], ["71298.90", "0.677"], ["71299.10", "0.022"], ["71299.20", "0.000"], ["71299.60", "0.454"], ["71300.00", "0.287"], ["71300.10", "0.002"], ["71300.20", "0.045"], ["71300.30", "0.008"], ["71300.50", "0.004"], ["71300.70", "0.000"], ["71301.00", "0.003"], ["71301.10", "0.097"], ["71301.20", "0.026"], ["71301.30", "0.893"], ["71301.40", "0.676"], ["71301.70", "0.008"], ["71301.80", "0.114"], ["71302.30", "0.137"], ["71302.40", "0.003"], ["71302.70", "0.004"], ["71302.90", "0.185"], ["71303.00", "1.498"], ["71303.10", "0.005"], ["71303.20", "0.209"], ["71303.50", "0.070"], ["71303.60", "0.004"], ["71303.80", "0.000"], ["71304.20", "0.857"], ["71304.30", "0.014"], ["71304.60", "0.003"], ["71304.70", "0.007"], ["71305.30", "0.003"], ["71305.40", "0.455"], ["71305.50", "0.282"], ["71305.60", "0.674"], ["71305.70", "0.003"], ["71305.90", "0.340"], ["71306.00", "0.006"], ["71306.10", "0.000"], ["71306.60", "1.187"], ["71306.70", "0.007"], ["71306.80", "0.279"], ["71306.90", "0.002"], ["71307.10", "0.070"], ["71307.20", "0.095"], ["71307.60", "0.019"], ["71307.80", "0.895"], ["71307.90", "0.005"], ["71308.00", "0.001"], ["71308.20", "0.875"], ["71308.30", "0.259"], ["71308.40", "0.008"], ["71308.70", "0.000"], ["71308.80", "1.411"], ["71308.90", "0.680"], ["71309.00", "0.004"], ["71309.10", "0.315"], ["71309.20", "0.004"], ["71309.30", "0.000"], ["71309.50", "0.424"], ["71309.60", "0.090"], ["71310.00", "0.009"], ["71310.10", "0.131"], ["71310.40", "0.000"], ["71310.50", "0.005"], ["71310.90", "0.029"], ["71311.00", "0.000"], ["71311.10", "0.194"], ["71311.30", "0.870"], ["71311.40", "1.261"], ["71311.50", "0.387"], ["71311.80", "0.252"], ["71311.90", "1.003"], ["71312.10", "0.014"], ["71312.20", "0.251"], ["71312.30", "0.449"], ["71312.40", "0.766"], ["71312.50", "0.199"], ["71312.60", "0.076"], ["71312.70", "0.000"], ["71313.10", "0.001"], ["71313.20", "0.000"], ["71313.50", "0.002"], ["71313.70", "0.003"], ["71313.90", "0.000"], ["71314.30", "0.002"], ["71314.40", "0.002"], ["71314.50", "0.003"], ["71314.60", "0.000"], ["71314.70", "0.000"], ["71314.80", "1.448"], ["71315.10", "0.005"], ["71315.30", "0.947"], ["71315.40", "0.782"], ["71315.50", "2.067"], ["71315.60", "0.009"], ["71316.00", "0.077"], ["71316.10", "0.002"], ["71316.30", "0.000"], ["71316.40", "0.003"], ["71316.60", "0.000"], ["71316.80", "0.424"], ["71317.00", "0.009"], ["71317.20", "0.003"], ["71317.30", "0.029"], ["71317.50", "0.000"], ["71317.60", "0.212"], ["71317.70", "0.003"], ["71317.80", "0.004"], ["71318.00", "0.002"], ["71318.10", "0.080"], ["71318.20", "0.046"], ["71318.30", "0.086"], ["71318.40", "0.284"], ["71318.50", "0.098"], ["71318.60", "0.004"], ["71318.70", "0.000"], ["71318.90", "0.272"], ["71319.00", "0.527"], ["71319.10", "0.002"], ["71319.20", "0.329"], ["71319.30", "1.123"], ["71319.40", "0.029"], ["71319.50", "0.078"], ["71319.70", "0.003"], ["71319.80", "0.002"], ["71320.10", "0.006"], ["71320.20", "0.001"], ["71320.30", "0.000"], ["71320.40", "0.034"], ["71320.50", "0.125"], ["71320.60", "0.011"], ["71320.70", "1.192"], ["71320.80", "0.005"], ["71320.90", "0.007"], ["71321.20", "0.203"], ["71321.30", "0.003"], ["71321.50", "0.000"], ["71321.60", "1.404"], ["71321.70", "0.303"], ["71321.80", "1.005"], ["71322.00", "0.003"], ["71322.20", "0.002"], ["71322.30", "0.042"], ["71322.40", "0.003"], ["71322.50", "0.272"], ["71322.60", "0.632"], ["71322.70", "0.000"], ["71322.80", "0.004"], ["71322.90", "0.288"], ["71323.00", "0.192"], ["71323.10", "0.022"], ["71323.20", "1.069"], ["71323.30", "0.003"], ["71323.40", "0.025"], ["71323.80", "0.082"], ["71323.90", "0.021"], ["71324.10", "0.182"], ["71324.20", "0.013"], ["71324.30", "0.007"], ["71324.40", "0.159"], ["71324.50", "0.000"], ["71324.60", "0.046"], ["71324.70", "0.018"], ["71324.80", "0.045"], ["71324.90", "0.003"], ["71325.00", "0.004"], ["71325.10", "0.011"], ["71325.20", "0.047"], ["71325.30", "0.005"], ["71325.50", "0.021"], ["71325.60", "0.001"], ["71325.70", "0.004"], ["71325.80", "0.011"], ["71326.00", "0.209"], ["71326.10", "0.732"], ["71326.20", "0.320"], ["71326.30", "0.034"], ["71326.40", "0.128"], ["71326.50", "0.065"], ["71326.80", "0.386"], ["71326.90", "0.561"], ["71327.00", "0.029"], ["71327.10", "0.001"], ["71327.20", "0.000"], ["71327.30", "0.000"], ["71327.50", "0.002"], ["71327.60", "0.006"], ["71327.70", "0.019"], ["71327.80", "0.000"], ["71328.00", "0.004"], ["71328.10", "0.005"], ["71328.20", "0.002"], ["71328.30", "0.003"], ["71328.40", "0.344"], ["71328.50", "0.013"], ["71328.60", "0.484"], ["71328.70", "0.000"], ["71328.80", "0.010"], ["71328.90", "0.003"], ["71329.00", "0.344"], ["71329.10", "0.003"], ["71329.20", "0.004"], ["71329.30", "0.056"], ["71329.50", "0.001"], ["71329.60", "0.209"], ["71329.70", "0.004"], ["71329.80", "0.005"], ["71329.90", "0.060"], ["71330.00", "0.020"], ["71330.10", "0.029"], ["71330.20", "2.725"], ["71330.30", "0.843"], ["71330.40", "0.006"], ["71330.50", "0.000"], ["71330.60", "0.003"], ["71330.70", "0.004"], ["71330.80", "0.006"], ["71330.90", "0.032"], ["71331.00", "0.000"], ["71331.10", "0.228"], ["71331.20", "0.000"], ["71331.30", "0.285"], ["71331.40", "0.597"], ["71331.50", "0.316"], ["71331.60", "0.130"], ["71331.70", "0.058"], ["71331.80", "0.107"], ["71331.90", "0.453"], ["71332.00", "0.003"], ["71332.10", "0.001"], ["71332.20", "0.015"], ["71332.30", "0.000"], ["71332.40", "0.003"], ["71332.50", "0.007"], ["71332.60", "0.215"], ["71332.70", "0.002"], ["71332.80", "0.045"], ["71332.90", "0.000"], ["71333.00", "0.000"], ["71333.10", "0.004"], ["71333.20", "0.207"], ["71333.30", "0.316"], ["71333.40", "0.004"], ["71333.50", "0.020"], ["71333.70", "0.194"], ["71333.80", "0.005"], ["71333.90", "0.029"], ["71334.00", "0.005"], ["71334.10", "0.319"], ["71334.20", "0.650"], ["71334.40", "0.005"], ["71334.50", "0.116"], ["71334.60", "0.003"], ["71334.70", "0.683"], ["71334.80", "0.015"], ["71334.90", "0.029"], ["71335.00", "0.007"], ["71335.20", "0.004"], ["71335.30", "0.002"], ["71335.40", "0.001"], ["71335.50", "0.000"], ["71335.60", "0.000"], ["71335.70", "0.031"], ["71335.80", "0.054"], ["71335.90", "0.016"], ["71336.10", "0.015"], ["71336.30", "0.029"], ["71336.40", "0.000"], ["71336.50", "0.000"], ["71336.60", "0.008"], ["71336.70", "0.003"], ["71336.80", "0.210"], ["71336.90", "0.112"], ["71337.00", "0.015"], ["71337.10", "0.001"], ["71337.20", "0.003"], ["71337.30", "0.005"], ["71337.40", "0.009"], ["71337.50", "0.007"], ["71337.60", "0.251"], ["71337.70", "0.000"], ["71338.00", "0.008"], ["71338.10", "0.005"], ["71338.20", "0.112"], ["71338.30", "0.000"], ["71338.40", "0.000"], ["71338.80", "0.002"], ["71339.00", "0.000"], ["71339.10", "0.037"], ["71339.20", "0.008"], ["71339.30", "0.005"], ["71339.40", "0.004"], ["71339.60", "0.001"], ["71339.70", "0.029"], ["71339.80", "0.000"], ["71339.90", "0.050"], ["71340.00", "0.055"], ["71340.10", "0.005"], ["71340.30", "0.046"], ["71340.40", "0.210"], ["71340.50", "0.112"], ["71340.60", "0.120"], ["71340.80", "0.003"], ["71340.90", "0.002"], ["71341.00", "0.009"], ["71341.20", "0.004"], ["71341.50", "0.052"], ["71341.60", "0.001"], ["71341.70", "0.001"], ["71341.80", "0.000"], ["71342.00", "0.003"], ["71342.10", "0.004"], ["71342.30", "0.004"], ["71342.40", "0.008"], ["71342.50", "0.040"], ["71342.60", "0.049"], ["71342.70", "0.003"], ["71342.80", "0.000"], ["71342.90", "0.000"], ["71343.00", "0.002"], ["71343.10", "0.005"], ["71343.20", "0.000"], ["71343.30", "0.000"], ["71343.40", "0.003"], ["71343.60", "0.000"], ["71343.70", "0.000"], ["71343.80", "0.004"], ["71343.90", "0.009"], ["71344.00", "1.166"]], "a": [["71344.10", "3.578"], ["71344.20", "0.002"], ["71344.30", "0.000"], ["71344.40", "0.004"], ["71344.50", "0.090"], ["71344.60", "0.000"], ["71344.70", "0.000"], ["71344.90", "0.002"], ["71345.00", "0.018"], ["71345.10", "0.002"], ["71345.40", "0.000"], ["71345.50", "0.000"], ["71345.60", "0.266"], ["71345.70", "0.002"], ["71345.80", "0.003"], ["71345.90", "0.003"], ["71346.10", "0.000"], ["71346.30", "0.000"], ["71346.40", "0.030"], ["71346.60", "0.001"], ["71346.90", "0.212"], ["71347.00", "0.002"], ["71347.10", "0.015"], ["71347.40", "0.046"], ["71347.50", "0.003"], ["71347.70", "0.001"], ["71347.80", "0.000"], ["71347.90", "0.032"], ["71348.00", "0.011"], ["71348.10", "0.003"], ["71348.40", "0.001"], ["71348.50", "0.015"], ["71348.60", "0.003"], ["71348.70", "0.003"], ["71348.80", "0.283"], ["71349.00", "0.650"], ["71349.10", "0.183"], ["71349.30", "0.010"], ["71349.40", "0.000"], ["71349.50", "0.004"], ["71349.60", "0.057"], ["71349.80", "0.001"], ["71350.00", "0.007"], ["71350.10", "0.008"], ["71350.20", "0.032"], ["71350.30", "0.013"], ["71350.50", "0.001"], ["71350.60", "0.451"], ["71350.70", "0.005"], ["71350.80", "0.029"], ["71350.90", "0.002"], ["71351.00", "0.025"], ["71351.10", "0.268"], ["71351.20", "0.081"], ["71351.40", "0.003"], ["71351.60", "0.001"], ["71351.70", "0.031"], ["71351.90", "0.003"], ["71352.00", "0.001"], ["71352.10", "0.058"], ["71352.20", "0.000"], ["71352.30", "0.312"], ["71352.40", "0.525"], ["71352.60", "0.226"], ["71352.70", "0.002"], ["71353.00", "0.003"], ["71353.10", "0.029"], ["71353.20", "0.001"], ["71353.40", "0.003"], ["71353.70", "0.000"], ["71353.80", "0.675"], ["71353.90", "0.029"], ["71354.00", "0.008"], ["71354.10", "0.868"], ["71354.20", "0.009"], ["71354.40", "0.054"], ["71354.50", "0.014"], ["71354.60", "0.044"], ["71354.70", "0.011"], ["71354.80", "0.006"], ["71355.00", "0.002"], ["71355.10", "0.005"], ["71355.20", "0.045"], ["71355.30", "0.000"], ["71355.60", "0.283"], ["71355.70", "0.759"], ["71355.80", "0.002"], ["71355.90", "0.002"], ["71356.00", "0.007"], ["71356.20", "0.003"], ["71356.70", "0.003"], ["71356.80", "0.677"], ["71356.90", "0.000"], ["71357.00", "0.725"], ["71357.10", "0.021"], ["71357.20", "0.005"], ["71357.30", "0.000"], ["71357.40", "0.000"], ["71357.50", "0.002"], ["71357.60", "0.005"], ["71357.70", "0.202"], ["71357.80", "0.038"], ["71357.90", "0.002"], ["71358.00", "0.010"], ["71358.10", "0.070"], ["71358.20", "0.000"], ["71358.30", "0.001"], ["71358.40", "0.083"], ["71358.50", "0.011"], ["71358.60", "0.006"], ["71358.70", "0.106"], ["71358.80", "0.282"], ["71358.90", "1.407"], ["71359.00", "0.675"], ["71359.10", "0.140"], ["71359.20", "0.035"], ["71359.30", "0.924"], ["71359.40", "2.194"], ["71359.50", "0.048"], ["71359.60", "0.019"], ["71359.70", "0.058"], ["71359.80", "0.002"], ["71359.90", "0.110"], ["71360.00", "0.004"], ["71360.10", "0.000"], ["71360.30", "0.045"], ["71360.40", "0.063"], ["71360.50", "0.030"], ["71360.60", "0.272"], ["71360.70", "0.014"], ["71360.80", "0.000"], ["71360.90", "0.005"], ["71361.00", "0.002"], ["71361.10", "0.020"], ["71361.20", "0.039"], ["71361.30", "0.203"], ["71361.40", "0.152"], ["71361.50", "0.046"], ["71361.70", "0.049"], ["71361.80", "0.048"], ["71361.90", "0.000"], ["71362.00", "0.004"], ["71362.10", "0.003"], ["71362.20", "0.001"], ["71362.30", "0.103"], ["71362.40", "0.006"], ["71362.50", "0.000"], ["71362.60", "0.007"], ["71362.80", "0.429"], ["71362.90", "0.005"], ["71363.00", "0.029"], ["71363.60", "0.125"], ["71364.00", "0.003"], ["71364.20", "0.330"], ["71364.40", "0.000"], ["71364.60", "0.000"], ["71365.20", "0.093"], ["71365.30", "0.042"], ["71365.40", "0.000"], ["71365.50", "0.002"], ["71365.60", "0.003"], ["71365.70", "0.078"], ["71365.80", "0.085"], ["71365.90", "0.040"], ["71366.00", "0.285"], ["71366.10", "0.036"], ["71366.30", "0.003"], ["71366.40", "1.215"], ["71366.50", "1.403"], ["71366.60", "0.002"], ["71366.70", "0.209"], ["71367.50", "0.000"], ["71367.60", "0.006"], ["71367.70", "0.002"], ["71367.90", "0.002"], ["71368.00", "0.004"], ["71368.40", "0.007"], ["71368.80", "0.055"], ["71369.10", "0.111"], ["71369.30", "0.058"], ["71369.40", "0.661"], ["71369.50", "0.007"], ["71369.60", "0.003"], ["71369.70", "0.019"], ["71369.80", "0.003"], ["71369.90", "0.000"], ["71370.10", "0.166"], ["71370.20", "0.002"], ["71370.30", "0.245"], ["71371.10", "0.076"], ["71371.20", "0.009"], ["71371.40", "0.724"], ["71371.90", "0.507"], ["71372.20", "0.007"], ["71372.30", "0.002"], ["71372.40", "0.288"], ["71372.50", "1.662"], ["71372.60", "0.003"], ["71372.70", "0.292"], ["71372.80", "0.041"], ["71373.50", "0.001"], ["71373.90", "0.492"], ["71374.00", "0.149"], ["71374.10", "0.026"], ["71375.30", "0.297"], ["71375.50", "0.142"], ["71375.60", "0.095"], ["71375.70", "0.299"], ["71376.20", "0.015"], ["71376.60", "0.095"], ["71377.30", "0.858"], ["71377.60", "0.303"], ["71378.00", "0.025"], ["71378.20", "0.005"], ["71379.20", "0.029"], ["71379.70", "0.106"], ["71380.40", "0.002"], ["71380.50", "0.008"], ["71381.10", "0.000"], ["71381.20", "0.004"], ["71381.60", "0.030"], ["71381.70", "2.064"], ["71381.80", "7.708"], ["71381.90", "0.000"], ["71382.00", "0.079"], ["71382.10", "0.000"], ["71382.30", "0.001"], ["71382.40", "0.020"], ["71383.20", "0.000"], ["71383.80", "0.004"], ["71383.90", "0.000"], ["71384.00", "0.223"], ["71384.20", "0.075"], ["71384.40", "0.677"], ["71384.70", "0.477"], ["71385.20", "0.869"], ["71385.50", "0.007"], ["71386.30", "0.000"], ["71386.90", "0.001"], ["71387.00", "0.492"], ["71387.50", "0.092"], ["71387.90", "0.003"], ["71388.10", "1.712"], ["71388.20", "0.689"], ["71388.60", "0.020"], ["71388.80", "0.018"], ["71388.90", "0.279"], ["71389.50", "0.006"], ["71389.60", "0.006"], ["71389.80", "0.210"], ["71390.10", "0.010"], ["71390.20", "0.003"], ["71390.30", "0.061"], ["71390.80", "0.002"], ["71391.30", "0.014"], ["71391.50", "0.673"], ["71391.60", "0.337"], ["71391.70", "0.856"], ["71391.80", "0.000"], ["71392.30", "0.002"], ["71392.40", "0.003"], ["71392.70", "0.079"], ["71393.00", "0.278"], ["71393.20", "0.473"], ["71393.40", "0.068"], ["71394.00", "0.005"], ["71394.80", "0.018"], ["71396.40", "0.065"], ["71396.90", "0.061"], ["71397.30", "0.100"], ["71397.50", "0.038"], ["71397.60", "1.985"], ["71398.40", "0.315"], ["71398.60", "0.047"], ["71398.70", "0.771"], ["71398.90", "1.770"], ["71399.10", "0.080"], ["71400.20", "0.274"], ["71400.40", "0.939"], ["71400.50", "0.672"], ["71401.00", "0.353"], ["71401.10", "0.020"], ["71401.20", "0.005"], ["71402.20", "0.005"], ["71402.40", "1.077"], ["71402.60", "0.003"], ["71403.20", "0.839"], ["71403.50", "1.433"], ["71403.60", "0.007"], ["71403.90", "0.058"], ["71404.50", "0.002"], ["71405.50", "0.002"], ["71407.30", "0.000"], ["71408.30", "0.084"], ["71408.40", "0.000"], ["71409.00", "0.014"], ["71409.40", "0.519"], ["71410.90", "0.001"], ["71411.90", "0.004"], ["71412.30", "0.002"], ["71413.50", "0.675"], ["71413.60", "0.006"], ["71414.70", "0.060"], ["71414.90", "0.719"], ["71415.20", "0.000"], ["71415.30", "0.004"], ["71416.00", "0.020"], ["71416.50", "0.073"], ["71417.60", "0.016"], ["71420.40", "0.008"], ["71420.90", "0.004"], ["71422.20", "0.056"], ["71422.90", "0.010"], ["71423.70", "0.222"], ["71424.30", "0.124"], ["71424.40", "0.133"], ["71424.50", "0.002"], ["71425.50", "0.006"], ["71426.00", "0.204"], ["71426.80", "0.042"], ["71427.40", "0.111"], ["71427.60", "0.149"], ["71428.70", "6.531"], ["71429.40", "0.036"], ["71430.00", "0.479"], ["71430.30", "0.062"], ["71430.40", "0.048"], ["71432.10", "0.100"], ["71432.20", "0.039"], ["71432.70", "0.000"], ["71433.50", "0.181"], ["71433.80", "0.217"], ["71435.50", "0.000"], ["71436.60", "0.042"], ["71437.00", "0.066"], ["71438.80", "0.067"], ["71440.80", "0.010"], ["71440.90", "0.002"], ["71441.30", "0.000"], ["71441.60", "0.043"], ["71443.30", "0.061"], ["71444.10", "0.003"], ["71445.50", "1.642"], ["71445.60", "0.411"], ["71446.40", "0.000"], ["71446.90", "0.064"], ["71447.00", "0.042"], ["71448.10", "0.000"], ["71450.60", "0.003"], ["71452.20", "0.061"], ["71453.10", "1.157"], ["71454.20", "0.000"], ["71455.00", "0.218"], ["71460.00", "0.110"], ["71460.20", "1.307"], ["71461.30", "0.000"], ["71463.00", "0.020"], ["71467.30", "0.000"], ["71469.90", "0.003"], ["71474.70", "0.653"], ["71474.80", "0.449"], ["71476.90", "0.368"], ["71479.90", "0.623"], ["71481.10", "0.003"], ["71481.90", "0.063"], ["71483.60", "0.003"], ["71486.80", "0.009"], ["71489.00", "2.489"], ["71489.60", "0.018"], ["71492.00", "0.201"], ["71492.50", "0.439"], ["71492.80", "0.000"], ["71499.40", "0.070"], ["71500.60", "0.091"], ["71504.30", "0.001"], ["71510.80", "0.000"], ["71513.90", "0.156"], ["71514.20", "0.000"], ["71514.70", "0.008"], ["71515.40", "0.000"], ["71516.90", "0.000"], ["71518.60", "0.210"], ["71519.80", "0.000"], ["71523.20", "0.000"], ["71526.80", "0.055"], ["71527.80", "0.000"], ["71536.40", "2.558"], ["71541.40", "0.250"], ["71543.40", "0.282"], ["71547.30", "0.000"], ["71550.60", "0.000"], ["71551.90", "0.003"], ["71552.80", "0.000"], ["71553.70", "0.001"], ["71555.80", "0.000"], ["71558.90", "0.000"], ["71569.30", "0.000"], ["71577.30", "0.894"], ["71583.50", "3.583"], ["71585.70", "0.309"], ["71596.70", "0.000"], ["71598.60", "10.346"], ["71608.60", "0.261"], ["71615.10", "1.082"], ["71615.80", "0.203"], ["71625.70", "2.500"], ["71649.80", "0.278"], ["71653.60", "0.000"], ["71700.90", "0.002"], ["71712.80", "0.054"], ["71831.20", "0.000"], ["71873.80", "0.014"], ["72057.50", "0.221"], ["72065.10", "0.695"], ["72197.20", "0.000"], ["72313.10", "1.382"], ["72330.10", "1.655"], ["72344.10", "1.787"], ["72351.50", "0.675"], ["72365.80", "0.275"], ["72614.40", "0.688"], ["72779.80", "0.002"], ["72781.30", "0.002"], ["74917.70", "0.002"], ["89523.20", "0.006"], ["100000.00", "15.857"]]}}
{"local_ts": 1773378002746, "server_ts": 1773378002462, "data": {"e": "depthUpdate", "E": 1773378002463, "T": 1773378002462, "s": "BTCUSDT", "U": 10100834234162, "u": 10100834245592, "pu": 10100834233659, "b": [["5000.00", "101.418"], ["20851.90", "0.648"], ["20952.50", "0.018"], ["21051.90", "0.387"], ["21152.50", "0.000"], ["33000.00", "9.339"], ["69516.20", "0.000"], ["69559.60", "2.583"], ["69928.00", "0.007"], ["70245.90", "0.995"], ["70388.60", "0.283"], ["70583.90", "0.000"], ["70638.40", "0.000"], ["70645.50", "0.568"], ["70995.10", "0.000"], ["71036.10", "0.000"], ["71113.20", "0.007"], ["71159.00", "0.002"], ["71221.10", "0.077"], ["71229.20", "0.003"], ["71234.10", "0.136"], ["71265.60", "0.061"], ["71290.50", "2.119"], ["71303.60", "0.004"], ["71304.00", "0.012"], ["71310.00", "0.152"], ["71311.30", "0.556"], ["71314.30", "0.004"], ["71316.30", "0.000"], ["71319.40", "1.007"], ["71324.00", "0.264"], ["71326.20", "0.010"], ["71327.20", "0.070"], ["71328.60", "0.476"], ["71328.70", "0.073"], ["71329.70", "0.276"], ["71329.80", "0.047"], ["71331.20", "0.000"], ["71333.30", "0.285"], ["71334.90", "1.222"], ["71336.00", "0.002"], ["71336.10", "0.000"], ["71337.80", "0.073"], ["71339.40", "0.033"], ["71343.60", "0.512"], ["71343.80", "0.057"], ["71344.00", "2.448"], ["71344.10", "0.000"], ["71344.60", "0.024"], ["71344.90", "0.196"], ["71345.20", "0.001"], ["71345.40", "0.631"], ["71346.30", "0.065"], ["71346.50", "0.000"], ["71346.60", "0.115"], ["71347.20", "0.105"], ["71347.40", "0.000"], ["71351.70", "0.004"], ["71351.90", "7.430"]], "a": [["71352.00", "2.801"], ["71358.40", "0.703"], ["71362.70", "0.000"], ["71370.00", "0.013"], ["71370.10", "0.289"], ["71371.60", "0.054"], ["71372.30", "1.192"], ["71372.70", "0.004"], ["71374.30", "0.024"], ["71374.60", "0.075"], ["71375.00", "0.002"], ["71381.20", "0.796"], ["71381.40", "0.565"], ["71383.20", "0.245"], ["71398.20", "0.050"], ["71413.10", "0.000"], ["71419.50", "0.016"], ["71423.20", "0.009"], ["71494.00", "0.002"], ["71502.60", "0.003"], ["71502.70", "0.306"], ["71996.20", "6.240"], ["72065.50", "20.000"], ["72365.20", "0.275"], ["74923.50", "0.052"], ["74927.60", "0.000"], ["89523.20", "0.000"]]}}
{"local_ts": 1773378003763, "server_ts": 1773378003484, "data": {"e": "depthUpdate", "E": 1773378003487, "T": 1773378003484, "s": "BTCUSDT", "U": 10100834336898, "u": 10100834344476, "pu": 10100834336551, "b": [["1000.00", "26.142"], ["5000.00", "101.418"], ["20851.90", "0.891"], ["20856.50", "0.234"], ["20956.50", "0.387"], ["21051.90", "0.378"], ["21256.50", "0.531"], ["56445.30", "0.002"], ["67778.00", "0.065"], ["67787.90", "0.000"], ["69521.80", "0.029"], ["69928.00", "0.005"], ["70053.30", "0.504"], ["70144.10", "0.029"], ["70642.90", "0.000"], ["70906.50", "0.021"], ["70999.70", "0.000"], ["71052.10", "0.240"], ["71118.30", "0.009"], ["71195.90", "0.156"], ["71227.30", "0.003"], ["71236.40", "0.000"], ["71270.90", "0.006"], ["71293.90", "0.317"], ["71294.40", "0.790"], ["71295.80", "0.081"], ["71299.70", "1.242"], ["71310.10", "0.394"], ["71315.50", "1.002"], ["71316.70", "0.000"], ["71319.00", "0.555"], ["71320.90", "0.065"], ["71323.20", "1.235"], ["71325.50", "0.002"], ["71327.00", "0.001"], ["71327.90", "0.504"], ["71333.50", "0.010"], ["71333.70", "0.022"], ["71336.20", "0.001"], ["71339.10", "0.000"], ["71342.20", "0.002"], ["71345.70", "0.000"], ["71347.50", "0.640"], ["71348.90", "0.021"], ["71349.00", "0.003"], ["71349.40", "0.635"], ["71352.90", "0.010"], ["71353.90", "0.002"], ["71355.20", "0.000"], ["71355.30", "0.002"], ["71356.50", "2.828"]], "a": [["71356.60", "3.390"], ["71356.80", "0.044"], ["71356.90", "0.008"], ["71357.20", "0.003"], ["71359.40", "0.026"], ["71359.50", "0.260"], ["71359.60", "0.001"], ["71362.10", "0.005"], ["71362.30", "0.646"], ["71365.30", "0.004"], ["71369.90", "0.000"], ["71370.20", "0.002"], ["71370.50", "0.002"], ["71370.70", "0.009"], ["71381.70", "2.064"], ["71382.60", "0.248"], ["71382.70", "0.150"], ["71383.40", "0.635"], ["71383.80", "0.511"], ["71462.70", "0.222"], ["71468.40", "0.000"], ["71469.10", "0.002"], ["71470.10", "0.000"], ["71471.90", "0.002"], ["71481.10", "0.003"], ["71516.90", "0.027"], ["71582.80", "2.303"], ["71582.90", "0.000"], ["72070.20", "0.000"], ["72779.60", "0.006"], ["89523.20", "0.000"]]}}
{"local_ts": 1773378004782, "server_ts": 1773378004505, "data": {"e": "depthUpdate", "E": 1773378004507, "T": 1773378004505, "s": "BTCUSDT", "U": 10100834396734, "u": 10100834401508, "pu": 10100834396538, "b": [["5000.00", "101.438"], ["20851.90", "0.000"], ["20856.50", "0.252"], ["20956.50", "0.648"], ["21156.50", "0.261"], ["21256.50", "1.539"], ["33000.00", "9.343"], ["56445.30", "0.000"], ["67784.90", "0.005"], ["67785.00", "0.006"], ["67788.70", "0.002"], ["69932.50", "0.002"], ["70393.00", "0.291"], ["70642.90", "0.000"], ["70778.70", "0.000"], ["70847.30", "0.002"], ["71118.30", "0.002"], ["71192.40", "0.159"], ["71195.90", "0.057"], ["71349.40", "0.260"], ["71356.50", "2.715"]], "a": [["71356.60", "3.340"], ["71363.70", "1.013"], ["71373.60", "0.021"], ["71796.00", "0.020"], ["71884.80", "0.042"], ["72034.50", "1.110"], ["72070.20", "2.077"], ["72072.90", "2.078"], ["72358.30", "2.070"], ["72583.40", "0.000"], ["72584.10", "0.279"], ["72845.70", "0.000"], ["74952.90", "0.002"], ["89523.20", "0.000"]]}}
{"local_ts": 1773378005809, "server_ts": 1773378005529, "data": {"e": "depthUpdate", "E": 1773378005531, "T": 1773378005529, "s": "BTCUSDT", "U": 10100834474123, "u": 10100834485059, "pu": 10100834474090, "b": [["1000.00", "26.342"], ["5000.00", "101.418"], ["20856.50", "0.783"], ["21056.50", "0.126"], ["21156.50", "1.548"], ["21256.50", "0.243"], ["69899.20", "0.000"], ["69932.50", "0.000"], ["70642.90", "1.413"], ["70999.70", "0.141"], ["71255.70", "0.065"], ["71255.80", "0.607"], ["71262.90", "0.102"], ["71263.00", "0.070"], ["71270.00", "0.001"], ["71270.10", "0.112"], ["71316.30", "0.000"], ["71318.10", "0.275"], ["71319.10", "0.001"], ["71320.00", "0.005"], ["71321.90", "0.004"], ["71322.30", "0.000"], ["71323.00", "0.108"], ["71325.20", "0.053"], ["71326.20", "0.010"], ["71328.70", "0.248"], ["71344.20", "0.763"], ["71345.20", "0.043"], ["71346.20", "0.716"], ["71346.70", "0.201"], ["71347.40", "0.044"], ["71348.70", "1.439"], ["71348.80", "1.145"], ["71349.40", "0.262"], ["71356.50", "2.909"]], "a": [["71356.60", "3.582"], ["71359.50", "0.011"], ["71362.20", "0.003"], ["71363.70", "1.015"], ["71364.90", "0.018"], ["71371.30", "0.003"], ["71371.50", "0.008"], ["71373.40", "0.086"], ["71375.00", "0.305"], ["71376.40", "0.002"], ["71382.60", "0.003"], ["71383.40", "0.005"], ["71383.90", "0.252"], ["71384.40", "1.307"], ["71393.80", "0.126"], ["71394.00", "1.068"], ["71394.20", "0.002"], ["71394.40", "0.025"], ["71394.50", "0.014"], ["71395.10", "0.283"], ["71395.20", "0.000"], ["71434.20", "0.089"], ["71434.30", "0.070"], ["71441.30", "0.000"], ["71441.40", "0.108"], ["71448.50", "0.040"], ["71448.60", "0.070"], ["71700.00", "18.820"], ["72070.20", "2.077"], ["74926.50", "0.052"], ["74930.80", "0.000"], ["89523.20", "0.000"]]}}
{"local_ts": 1773378006829, "server_ts": 1773378006552, "data": {"e": "depthUpdate", "E": 1773378006553, "T": 1773378006552, "s": "BTCUSDT", "U": 10100834611296, "u": 10100834618989, "pu": 10100834611287, "b": [["1000.00", "26.542"], ["5000.00", "101.418"], ["20856.50", "0.009"], ["21060.30", "0.981"], ["21156.50", "0.270"], ["21260.30", "0.495"], ["67767.70", "0.000"], ["68337.70", "0.002"], ["69729.00", "0.000"], ["70646.70", "0.212"], ["71003.40", "0.000"], ["71210.40", "0.000"], ["71214.00", "0.000"], ["71221.00", "0.075"], ["71222.40", "0.000"], ["71244.20", "0.061"], ["71244.40", "0.000"], ["71277.80", "0.004"], ["71286.80", "0.284"], ["71292.70", "0.021"], ["71295.20", "0.003"], ["71301.90", "0.842"], ["71302.40", "0.019"], ["71313.00", "0.010"], ["71313.30", "0.003"], ["71313.50", "0.058"], ["71321.00", "0.063"], ["71321.10", "0.066"], ["71322.20", "0.891"], ["71333.10", "0.010"], ["71340.00", "0.011"], ["71340.60", "0.009"], ["71342.80", "0.000"], ["71344.90", "0.032"], ["71345.60", "0.169"], ["71347.70", "0.277"], ["71347.80", "0.001"], ["71349.20", "0.521"], ["71350.90", "0.021"], ["71351.50", "0.092"], ["71352.80", "0.069"], ["71352.90", "0.242"], ["71353.20", "0.254"], ["71353.30", "0.010"], ["71354.20", "0.114"], ["71356.50", "0.298"], ["71357.10", "0.015"], ["71360.30", "7.677"]], "a": [["71360.40", "0.464"], ["71361.70", "0.054"], ["71367.60", "0.006"], ["71376.40", "0.002"], ["71377.40", "0.487"], ["71377.90", "0.009"], ["71378.20", "0.302"], ["71385.80", "0.212"], ["71386.60", "0.014"], ["71387.00", "0.046"], ["71387.70", "0.281"], ["71388.00", "0.156"], ["71388.50", "0.000"], ["71388.80", "0.094"], ["71389.00", "0.328"], ["71389.50", "0.057"], ["71391.70", "0.861"], ["71392.20", "0.013"], ["71392.70", "0.008"], ["71393.20", "0.279"], ["71397.50", "0.306"], ["71419.20", "0.354"], ["71420.20", "0.006"], ["71420.50", "1.667"], ["71421.20", "0.004"], ["71421.50", "0.042"], ["71422.20", "0.007"], ["71428.00", "0.532"], ["71428.90", "0.043"], ["71429.90", "0.044"], ["71468.40", "0.000"], ["71469.10", "0.002"], ["71471.20", "0.216"], ["71472.20", "0.277"], ["71486.50", "0.093"], ["71588.00", "3.578"], ["71598.50", "0.000"], ["72074.00", "0.000"], ["72105.00", "0.020"], ["72297.50", "0.000"], ["89523.20", "0.000"]]}}
{"local_ts": 1773378007851, "server_ts": 1773378007572, "data": {"e": "depthUpdate", "E": 1773378007575, "T": 1773378007572, "s": "BTCUSDT", "U": 10100834687239, "u": 10100834693095, "pu": 10100834687042, "b": [["5000.00", "101.418"], ["20960.50", "1.125"], ["21056.50", "0.288"], ["21060.30", "0.243"], ["21160.50", "0.630"], ["21256.50", "0.144"], ["35680.20", "0.000"], ["67772.70", "0.002"], ["69928.00", "1.718"], ["70612.00", "1.178"], ["70646.90", "0.000"], ["70776.10", "0.000"], ["71003.60", "0.008"], ["71003.70", "0.000"], ["71092.60", "0.007"], ["71122.60", "0.418"], ["71286.90", "0.054"], ["71288.10", "0.085"], ["71288.70", "0.066"], ["71289.40", "0.063"], ["71290.30", "0.371"], ["71313.10", "0.003"], ["71313.40", "0.211"], ["71324.80", "0.006"], ["71351.80", "0.004"], ["71353.50", "0.000"], ["71353.80", "0.043"], ["71354.00", "0.302"], ["71354.20", "0.032"], ["71354.40", "0.037"], ["71355.00", "0.067"]], "a": [["71360.60", "1.116"], ["71367.80", "0.062"], ["71370.00", "0.012"], ["71371.00", "0.217"], ["71374.30", "0.086"], ["71374.90", "0.044"], ["71375.00", "0.062"], ["71375.30", "0.046"], ["71375.80", "0.040"], ["71376.10", "0.002"], ["71377.10", "0.011"], ["71377.20", "0.023"], ["71377.40", "0.571"], ["71378.40", "0.147"], ["71380.00", "0.105"], ["71380.90", "0.001"], ["71381.20", "0.105"], ["71381.40", "0.019"], ["71381.90", "0.015"], ["71382.00", "0.096"], ["71382.20", "0.005"], ["71382.50", "0.344"], ["71384.00", "0.249"], ["71384.50", "0.005"], ["71385.00", "0.002"], ["71385.50", "0.008"], ["71385.80", "0.212"], ["71388.10", "0.007"], ["71389.40", "0.002"], ["71397.50", "0.214"], ["71407.10", "0.142"], ["71407.80", "0.036"], ["71408.10", "0.066"], ["71409.30", "0.039"], ["71424.80", "0.085"], ["71431.30", "0.853"], ["71439.90", "0.087"], ["71440.60", "0.037"], ["71441.20", "0.185"], ["71442.70", "0.240"], ["71472.20", "0.277"], ["71475.80", "0.334"], ["71837.50", "0.000"], ["71942.20", "0.200"], ["72074.20", "0.000"], ["72108.80", "0.000"], ["72138.40", "0.703"], ["72288.20", "1.384"], ["72403.30", "0.690"], ["72431.00", "0.689"], ["72471.40", "0.003"], ["72502.40", "0.689"], ["73006.10", "0.616"], ["74949.20", "0.000"], ["89523.20", "0.000"]]}}
{"local_ts": 1773378008871, "server_ts": 1773378008593, "data": {"e": "depthUpdate", "E": 1773378008595, "T": 1773378008593, "s": "BTCUSDT", "U": 10100834775727, "u": 10100834783970, "pu": 10100834775532, "b": [["1000.00", "26.542"], ["5000.00", "101.418"], ["20860.50", "0.990"], ["20960.50", "0.675"], ["21060.50", "0.621"], ["21160.50", "0.153"], ["36291.40", "0.000"], ["68083.50", "0.106"], ["69219.60", "0.005"], ["70414.80", "67.750"], ["70626.70", "57.909"], ["70646.90", "0.000"], ["70789.50", "46.653"], ["71309.20", "0.159"], ["71313.40", "0.207"], ["71318.10", "0.279"], ["71323.40", "0.000"], ["71330.20", "2.084"], ["71330.80", "0.014"], ["71337.20", "1.412"], ["71338.10", "0.000"], ["71346.10", "0.008"], ["71350.50", "0.285"], ["71352.10", "0.008"], ["71353.50", "0.002"], ["71353.90", "0.078"], ["71356.80", "0.812"], ["71357.40", "0.005"], ["71360.40", "1.201"], ["71360.50", "7.944"]], "a": [["71360.60", "0.147"], ["71360.90", "0.000"], ["71361.80", "0.004"], ["71362.50", "0.020"], ["71363.20", "0.001"], ["71365.10", "0.007"], ["71366.70", "0.000"], ["71367.70", "0.001"], ["71367.80", "0.064"], ["71370.50", "0.000"], ["71370.90", "0.007"], ["71372.80", "0.001"], ["71373.60", "0.005"], ["71378.70", "0.046"], ["71382.20", "0.003"], ["71386.70", "0.000"], ["71387.00", "0.046"], ["71388.00", "0.151"], ["71388.10", "0.005"], ["71389.70", "0.009"], ["71390.20", "0.003"], ["71392.50", "0.034"], ["71394.20", "0.061"], ["71394.60", "0.495"], ["71394.70", "0.008"], ["71395.10", "0.005"], ["71396.30", "0.001"], ["71397.70", "1.191"], ["71398.40", "0.280"], ["71398.90", "2.005"], ["71400.70", "0.000"], ["71402.50", "0.855"], ["71402.70", "0.009"], ["71402.80", "0.128"], ["71404.10", "0.005"], ["71408.60", "2.335"], ["71408.70", "0.004"], ["71413.50", "0.673"], ["71413.80", "0.968"], ["71413.90", "0.534"], ["71470.90", "0.000"], ["71473.70", "0.004"], ["71475.50", "0.000"], ["71499.00", "0.165"], ["71502.80", "0.201"], ["71520.40", "0.014"], ["71945.90", "30.933"], ["72074.20", "0.000"], ["72111.40", "36.927"], ["72327.70", "45.600"], ["72680.80", "1.100"], ["74931.60", "0.000"]]}}
{"local_ts": 1773378009891, "server_ts": 1773378009614, "data": {"e": "depthUpdate", "E": 1773378009615, "T": 1773378009614, "s": "BTCUSDT", "U": 10100834886650, "u": 10100834893245, "pu": 10100834886376, "b": [["5000.00", "101.418"], ["20860.50", "1.080"], ["20960.50", "0.486"], ["21060.50", "0.414"], ["21260.50", "0.720"], ["61411.60", "0.022"], ["67784.70", "0.004"], ["70325.80", "0.994"], ["70643.00", "4.238"], ["70646.90", "0.000"], ["71003.60", "0.008"], ["71197.20", "0.021"], ["71198.20", "2.118"], ["71203.50", "0.000"], ["71220.30", "0.019"], ["71222.80", "0.042"], ["71226.60", "0.040"], ["71307.00", "0.851"], ["71310.50", "0.302"], ["71311.90", "1.035"], ["71312.00", "0.002"], ["71314.10", "0.099"], ["71319.50", "0.255"], ["71329.20", "0.002"], ["71338.00", "1.196"], ["71339.80", "0.002"], ["71343.60", "0.457"], ["71344.10", "0.012"], ["71344.40", "0.000"], ["71344.60", "0.160"], ["71345.10", "0.008"], ["71347.40", "0.002"], ["71347.90", "0.000"], ["71348.40", "0.000"], ["71348.90", "0.696"], ["71349.40", "0.061"], ["71360.50", "1.826"]], "a": [["71361.80", "0.014"], ["71375.60", "0.037"], ["71376.50", "0.159"], ["71378.50", "0.001"], ["71379.70", "0.000"], ["71382.70", "0.655"], ["71384.20", "0.715"], ["71385.20", "0.841"], ["71386.60", "0.688"], ["71386.90", "0.256"], ["71398.40", "0.406"], ["71398.60", "0.000"], ["71439.30", "0.077"], ["71439.90", "0.087"], ["72074.20", "0.000"], ["72395.30", "0.828"], ["72492.30", "0.000"], ["72666.80", "0.686"]]}}
{"local_ts": 1773378010912, "server_ts": 1773378010636, "data": {"e": "depthUpdate", "E": 1773378010637, "T": 1773378010636, "s": "BTCUSDT", "U": 10100834956278, "u": 10100834962798, "pu": 10100834956119, "b": [["1000.00", "26.142"], ["5000.00", "101.398"], ["20860.50", "0.351"], ["20960.50", "0.549"], ["21160.50", "0.450"], ["21260.50", "1.350"], ["57088.00", "0.015"], ["70290.10", "4.971"], ["70358.70", "2.128"], ["70646.90", "0.000"], ["71003.70", "0.000"], ["71122.60", "0.425"], ["71199.90", "0.060"], ["71305.80", "0.183"], ["71312.00", "0.002"], ["71312.20", "0.253"], ["71315.50", "0.674"], ["71315.90", "0.006"], ["71317.70", "0.102"], ["71319.50", "0.227"], ["71322.80", "0.001"], ["71329.50", "0.001"], ["71329.60", "0.278"], ["71333.00", "0.000"], ["71339.80", "0.002"], ["71341.10", "1.194"], ["71342.00", "0.007"], ["71343.30", "0.009"], ["71344.30", "0.042"], ["71344.60", "0.152"], ["71346.60", "0.144"], ["71347.00", "0.041"], ["71349.00", "0.135"], ["71350.40", "0.033"], ["71351.30", "0.636"], ["71351.60", "0.104"], ["71351.80", "0.004"], ["71352.30", "0.001"], ["71352.70", "0.045"], ["71353.40", "0.167"], ["71354.50", "0.012"], ["71354.70", "0.000"], ["71355.10", "0.109"], ["71355.20", "0.066"], ["71355.70", "0.042"], ["71356.40", "0.014"], ["71358.70", "0.015"], ["71358.90", "0.010"], ["71360.50", "1.989"]], "a": [["71360.60", "3.552"], ["71362.10", "0.003"], ["71362.80", "0.310"], ["71363.20", "0.003"], ["71363.40", "0.002"], ["71364.30", "0.008"], ["71364.40", "0.000"], ["71364.60", "0.009"], ["71365.10", "0.610"], ["71365.50", "0.211"], ["71365.60", "0.008"], ["71366.50", "0.000"], ["71367.40", "0.005"], ["71368.40", "0.000"], ["71370.00", "0.032"], ["71373.20", "0.114"], ["71373.30", "0.182"], ["71374.20", "0.110"], ["71374.50", "0.020"], ["71374.90", "0.031"], ["71375.20", "0.279"], ["71376.20", "0.044"], ["71398.90", "1.726"], ["71399.00", "0.128"], ["71399.10", "0.035"], ["72074.20", "0.000"], ["72395.30", "1.656"], ["74934.50", "0.050"], ["74939.40", "0.002"]]}}
{"local_ts": 1773378011932, "server_ts": 1773378011652, "data": {"e": "depthUpdate", "E": 1773378011657, "T": 1773378011652, "s": "BTCUSDT", "U": 10100835016067, "u": 10100835020833, "pu": 10100835016014, "b": [["1000.00", "26.142"], ["5000.00", "101.418"], ["20860.50", "0.684"], ["21060.50", "0.216"], ["21160.50", "1.548"], ["21260.50", "0.252"], ["21260.60", "0.000"], ["33000.00", "9.339"], ["67792.50", "0.020"], ["67792.60", "0.002"], ["70284.90", "0.426"], ["70311.30", "0.000"], ["70361.50", "0.002"], ["70646.90", "0.000"], ["71003.60", "0.008"], ["71122.80", "0.008"], ["71282.00", "0.454"], ["71296.30", "0.375"], ["71303.60", "0.001"], ["71312.00", "0.004"], ["71312.10", "0.018"], ["71315.90", "0.145"], ["71319.50", "0.319"], ["71324.10", "0.045"], ["71330.40", "0.250"], ["71332.00", "0.139"], ["71332.10", "0.001"], ["71335.00", "0.076"], ["71336.30", "0.070"], ["71351.60", "0.283"], ["71354.90", "0.029"], ["71356.30", "0.013"], ["71357.90", "0.006"], ["71358.30", "0.211"], ["71358.40", "0.098"], ["71358.90", "0.002"], ["71360.10", "0.000"], ["71360.50", "2.068"]], "a": [["71360.60", "3.634"], ["71360.80", "0.000"], ["71361.70", "0.000"], ["71361.90", "0.029"], ["71362.00", "0.004"], ["71363.30", "0.002"], ["71368.10", "0.269"], ["71368.30", "0.003"], ["71369.00", "0.002"], ["71369.20", "0.002"], ["71369.40", "0.018"], ["71369.80", "0.003"], ["71370.10", "0.010"], ["71371.00", "0.031"], ["71371.80", "0.010"], ["71372.30", "0.039"], ["71373.30", "0.008"], ["71374.70", "0.059"], ["71375.20", "0.517"], ["71375.30", "0.125"], ["71375.80", "0.006"], ["71376.80", "0.094"], ["71379.50", "0.033"], ["71380.30", "0.000"], ["71381.30", "0.674"], ["71382.30", "0.001"], ["71383.30", "0.505"], ["71384.30", "0.048"], ["71385.90", "0.044"], ["71388.00", "0.151"], ["71389.40", "0.275"], ["71390.40", "0.000"], ["71391.40", "1.467"], ["71392.30", "0.006"], ["71392.40", "0.042"], ["71393.30", "0.044"], ["71394.30", "0.045"], ["71395.30", "1.746"], ["71396.30", "0.043"], ["71397.20", "0.047"], ["71398.20", "0.003"], ["71399.20", "0.126"], ["71400.10", "0.017"], ["71401.10", "0.005"], ["71424.80", "0.003"], ["71439.10", "0.061"], ["71778.70", "0.000"], ["72074.20", "0.000"], ["74935.50", "0.050"], ["74961.40", "0.002"]]}}
{"local_ts": 1773378012963, "server_ts": 1773378012680, "data": {"e": "depthUpdate", "E": 1773378012683, "T": 1773378012680, "s": "BTCUSDT", "U": 10100835071761, "u": 10100835077826, "pu": 10100835071738, "b": [["5000.00", "101.418"], ["20960.50", "0.090"], ["21060.50", "1.548"], ["21160.50", "0.243"], ["21260.50", "0.819"], ["67772.70", "0.000"], ["69965.20", "0.000"], ["70397.10", "1.134"], ["70646.90", "0.000"], ["70682.60", "1.132"], ["71000.00", "25.854"], ["71003.70", "0.141"], ["71113.40", "0.055"], ["71167.60", "16.809"], ["71198.10", "3.226"], ["71199.90", "0.159"], ["71306.20", "0.009"], ["71308.00", "0.007"], ["71309.00", "0.096"], ["71311.70", "0.275"], ["71311.80", "0.007"], ["71312.40", "0.674"], ["71312.50", "0.107"], ["71315.90", "0.249"], ["71318.10", "0.275"], ["71319.30", "1.238"], ["71319.50", "0.571"], ["71325.50", "0.022"], ["71326.70", "0.003"], ["71326.80", "0.626"], ["71327.70", "0.053"], ["71328.00", "0.033"], ["71328.60", "0.282"], ["71329.30", "2.680"], ["71329.60", "0.251"], ["71330.50", "0.029"], ["71330.60", "0.090"], ["71331.50", "0.042"], ["71331.80", "0.092"], ["71332.50", "0.044"], ["71333.00", "0.029"], ["71334.30", "0.029"], ["71334.50", "0.003"], ["71334.60", "0.043"], ["71334.80", "0.691"], ["71335.50", "0.000"], ["71335.60", "0.042"], ["71335.90", "0.016"], ["71336.10", "0.095"], ["71336.60", "0.324"], ["71336.70", "0.002"], ["71337.20", "1.534"], ["71337.30", "0.586"], ["71338.00", "0.005"], ["71338.20", "0.005"], ["71338.60", "0.025"], ["71339.10", "0.031"], ["71339.50", "0.678"], ["71339.60", "0.009"], ["71339.80", "0.017"], ["71340.10", "0.010"], ["71340.40", "0.231"], ["71340.60", "0.009"], ["71340.70", "0.001"], ["71340.80", "0.629"], ["71341.00", "1.003"], ["71341.20", "0.011"], ["71341.70", "0.753"], ["71341.90", "0.000"], ["71342.00", "0.007"], ["71342.10", "0.001"], ["71342.20", "0.009"], ["71342.70", "0.004"], ["71343.00", "0.002"], ["71343.20", "0.014"], ["71344.50", "0.002"], ["71344.60", "0.160"], ["71344.70", "0.142"], ["71344.90", "0.004"], ["71345.10", "0.023"], ["71345.60", "0.051"], ["71345.70", "0.007"], ["71346.00", "0.008"], ["71346.10", "0.018"], ["71346.30", "0.062"], ["71346.40", "0.007"], ["71346.60", "0.111"], ["71346.80", "0.003"], ["71347.00", "0.049"], ["71347.30", "0.033"], ["71347.50", "0.007"], ["71348.10", "0.003"], ["71348.60", "0.010"], ["71349.10", "0.079"], ["71349.60", "0.065"], ["71350.60", "0.175"], ["71351.60", "0.000"], ["71351.70", "0.002"], ["71353.10", "0.002"], ["71353.40", "0.003"], ["71353.70", "0.001"], ["71353.90", "0.002"], ["71354.00", "0.004"], ["71354.20", "0.002"], ["71354.40", "0.001"], ["71354.50", "0.004"], ["71354.60", "0.000"], ["71355.00", "0.006"], ["71355.10", "0.094"], ["71355.20", "0.048"], ["71355.40", "0.000"], ["71355.60", "0.001"], ["71355.90", "0.010"], ["71356.10", "0.000"], ["71356.30", "0.013"], ["71356.40", "0.002"], ["71356.50", "0.017"], ["71356.60", "0.004"], ["71356.80", "0.008"], ["71356.90", "0.000"], ["71357.00", "0.058"], ["71357.10", "0.005"], ["71357.40", "0.001"], ["71357.50", "0.000"], ["71357.60", "0.000"], ["71357.90", "0.006"], ["71358.20", "0.001"], ["71358.40", "0.000"], ["71358.80", "0.000"], ["71358.90", "0.002"], ["71359.20", "0.002"], ["71359.30", "0.000"], ["71360.30", "0.012"], ["71360.50", "1.704"]], "a": [["71360.60", "3.870"], ["71360.70", "0.007"], ["71360.90", "0.000"], ["71361.40", "0.056"], ["71361.80", "0.035"], ["71362.30", "0.003"], ["71362.60", "0.004"], ["71363.00", "0.015"], ["71363.10", "0.030"], ["71363.90", "0.011"], ["71365.00", "0.014"], ["71366.70", "0.000"], ["71367.40", "0.005"], ["71367.90", "0.002"], ["71368.80", "0.031"], ["71370.10", "0.031"], ["71371.30", "0.047"], ["71371.40", "0.687"], ["71372.20", "0.049"], ["71372.40", "0.004"], ["71372.80", "0.058"], ["71372.90", "0.002"], ["71373.30", "0.092"], ["71373.40", "0.895"], ["71373.80", "0.002"], ["71374.10", "0.065"], ["71375.30", "0.127"], ["71375.50", "0.165"], ["71375.60", "0.039"], ["71376.20", "0.044"], ["71376.80", "0.123"], ["71377.00", "1.111"], ["71378.20", "0.302"], ["71379.00", "0.010"], ["71379.30", "0.250"], ["71380.60", "0.003"], ["71381.80", "0.007"], ["71382.70", "0.725"], ["71383.10", "0.000"], ["71384.30", "0.006"], ["71385.60", "0.004"], ["71386.50", "0.008"], ["71387.40", "0.635"], ["71389.00", "0.040"], ["71389.20", "0.754"], ["71389.50", "0.510"], ["71390.40", "0.000"], ["71390.60", "0.006"], ["71391.30", "0.014"], ["71392.30", "0.002"], ["71393.30", "0.002"], ["71398.90", "1.726"], ["71399.10", "0.126"], ["71402.80", "0.013"], ["71440.30", "0.015"], ["71441.20", "0.045"], ["72074.20", "0.000"]]}}
{"local_ts": 1773378013979, "server_ts": 1773378013701, "data": {"e": "depthUpdate", "E": 1773378013703, "T": 1773378013701, "s": "BTCUSDT", "U": 10100835128704, "u": 10100835134952, "pu": 10100835128546, "b": [["1000.00", "26.142"], ["5000.00", "101.418"], ["20960.50", "1.458"], ["21060.50", "0.342"], ["21160.50", "0.846"], ["21260.50", "0.054"], ["33000.00", "9.343"], ["67768.10", "0.023"], ["70303.20", "15.642"], ["70326.00", "0.006"], ["70620.10", "0.848"], ["70646.90", "0.000"], ["71198.10", "3.224"], ["71199.90", "0.159"], ["71200.20", "0.042"], ["71237.20", "5.717"], ["71240.70", "2.000"], ["71253.40", "0.045"], ["71253.80", "0.048"], ["71254.10", "0.000"], ["71254.90", "0.014"], ["71255.60", "0.006"], ["71255.90", "0.000"], ["71256.60", "0.002"], ["71256.70", "0.085"], ["71257.30", "0.004"], ["71257.40", "0.498"], ["71258.40", "0.000"], ["71262.20", "0.070"], ["71269.40", "0.271"], ["71276.20", "0.000"], ["71276.50", "0.079"], ["71278.40", "0.042"], ["71282.80", "0.042"], ["71282.90", "0.306"], ["71283.70", "0.098"], ["71286.90", "0.011"], ["71287.20", "0.972"], ["71287.50", "0.004"], ["71287.60", "0.044"], ["71288.10", "0.189"], ["71288.30", "0.045"], ["71288.70", "0.041"], ["71289.40", "0.002"], ["71289.90", "0.100"], ["71290.10", "0.596"], ["71290.30", "0.335"], ["71309.00", "0.004"], ["71310.90", "0.000"], ["71312.50", "0.201"], ["71312.60", "0.076"], ["71315.90", "0.249"], ["71320.90", "0.016"], ["71349.00", "0.005"], ["71349.10", "0.007"], ["71349.20", "0.582"], ["71349.30", "0.204"], ["71349.40", "0.000"], ["71349.60", "0.019"], ["71349.70", "0.029"], ["71349.80", "0.037"], ["71350.20", "0.001"], ["71350.50", "0.005"], ["71350.90", "0.050"], ["71351.20", "0.000"], ["71351.60", "0.000"], ["71353.40", "0.067"], ["71357.10", "0.034"], ["71357.90", "0.006"], ["71360.50", "1.799"]], "a": [["71361.20", "0.001"], ["71361.50", "0.214"], ["71363.90", "0.003"], ["71365.00", "0.014"], ["71365.30", "0.654"], ["71365.40", "0.452"], ["71366.40", "0.001"], ["71366.70", "0.002"], ["71366.80", "0.003"], ["71368.20", "0.004"], ["71368.70", "0.018"], ["71369.90", "0.000"], ["71370.20", "0.058"], ["71370.60", "0.000"], ["71371.00", "0.002"], ["71371.10", "0.004"], ["71371.20", "0.674"], ["71371.60", "0.006"], ["71372.10", "0.122"], ["71372.40", "0.004"], ["71372.60", "0.210"], ["71373.10", "0.009"], ["71373.30", "0.000"], ["71373.50", "0.003"], ["71373.60", "0.005"], ["71373.70", "0.616"], ["71373.90", "0.003"], ["71374.20", "0.038"], ["71374.30", "0.013"], ["71374.40", "0.198"], ["71374.50", "0.058"], ["71374.70", "0.001"], ["71374.80", "0.011"], ["71374.90", "0.111"], ["71375.00", "0.352"], ["71375.10", "0.000"], ["71375.20", "0.441"], ["71375.30", "0.080"], ["71375.50", "0.136"], ["71375.60", "0.003"], ["71375.70", "0.364"], ["71376.20", "0.031"], ["71376.50", "0.079"], ["71377.40", "0.971"], ["71378.10", "0.007"], ["71378.60", "0.305"], ["71381.20", "0.033"], ["71406.40", "0.000"], ["71406.60", "0.036"], ["71407.10", "0.018"], ["71407.80", "0.053"], ["71407.90", "0.099"], ["71408.10", "0.023"], ["71408.20", "0.003"], ["71408.30", "0.100"], ["71408.60", "2.297"], ["71409.30", "0.003"], ["71413.40", "0.004"], ["71414.10", "0.095"], ["71439.00", "0.005"], ["71439.10", "0.006"], ["71439.30", "0.022"], ["71439.90", "0.003"], ["71440.30", "0.013"], ["71440.60", "0.054"], ["71440.80", "0.080"], ["71440.90", "0.002"], ["71441.20", "0.002"], ["71441.30", "0.058"], ["71441.40", "0.040"], ["71441.70", "0.000"], ["71441.90", "0.002"], ["71442.10", "0.214"], ["71442.70", "0.204"], ["71447.90", "0.106"], ["71451.20", "0.001"], ["71453.10", "2.255"], ["71455.10", "0.236"], ["71933.30", "0.039"], ["72074.20", "0.000"], ["72633.90", "0.551"], ["73356.50", "0.024"]]}}
{"local_ts": 1773378014998, "server_ts": 1773378014720, "data": {"e": "depthUpdate", "E": 1773378014723, "T": 1773378014720, "s": "BTCUSDT", "U": 10100835190184, "u": 10100835194126, "pu": 10100835190131, "b": [["5000.00", "101.418"], ["20860.50", "1.188"], ["20960.50", "0.612"], ["21060.50", "0.711"], ["21160.50", "0.189"], ["56445.30", "0.002"], ["65454.90", "0.608"], ["65823.60", "0.606"], ["66192.40", "0.606"], ["66561.20", "0.606"], ["66930.00", "0.647"], ["67298.80", "0.606"], ["67667.60", "0.610"], ["67788.80", "0.000"], ["68036.40", "0.606"], ["68405.10", "0.620"], ["68773.90", "0.606"], ["69142.70", "0.606"], ["69511.50", "0.606"], ["69880.30", "0.615"], ["70196.20", "0.987"], ["70249.10", "1.050"], ["70254.40", "4.338"], ["70325.80", "5.822"], ["70617.90", "0.606"], ["70646.90", "0.000"], ["70986.70", "0.606"], ["71200.20", "0.040"], ["71202.80", "0.002"], ["71226.50", "0.340"], ["71227.90", "0.111"], ["71262.30", "0.073"], ["71269.50", "0.072"], ["71276.60", "0.124"], ["71296.30", "0.375"], ["71312.00", "0.004"], ["71312.10", "0.018"], ["71324.90", "0.000"], ["71343.50", "0.029"], ["71344.80", "0.116"], ["71346.00", "0.039"], ["71350.90", "0.021"], ["71352.20", "0.000"], ["71353.40", "0.053"], ["71355.40", "0.000"]], "a": [["71361.60", "0.000"], ["71361.70", "0.000"], ["71361.90", "0.002"], ["71362.00", "0.019"], ["71362.10", "0.003"], ["71367.30", "0.100"], ["71368.00", "0.007"], ["71370.20", "0.267"], ["71371.30", "0.649"], ["71378.30", "0.032"], ["71378.50", "1.001"], ["71378.70", "0.020"], ["71379.30", "0.250"], ["71379.70", "0.000"], ["71396.40", "0.102"], ["71424.80", "0.003"], ["71440.80", "0.123"], ["71441.90", "0.000"], ["71447.10", "0.002"], ["71447.90", "0.106"], ["71455.10", "0.236"], ["71724.20", "0.606"], ["72074.20", "0.000"], ["72093.00", "4.928"], ["72461.80", "0.608"], ["72830.60", "0.770"], ["73199.40", "0.606"], ["73568.20", "0.606"], ["73937.00", "0.610"], ["74952.40", "0.002"]]}}
{"local_ts": 1773378016019, "server_ts": 1773378015742, "data": {"e": "depthUpdate", "E": 1773378015743, "T": 1773378015742, "s": "BTCUSDT", "U": 10100835315284, "u": 10100835328993, "pu": 10100835315213, "b": [["556.80", "4.266"], ["1000.00", "26.142"], ["5000.00", "101.398"], ["20860.50", "0.810"], ["20953.10", "0.378"], ["21060.50", "0.324"], ["21253.10", "0.711"], ["56445.30", "0.000"], ["67765.40", "0.002"], ["67766.20", "0.000"], ["70211.50", "2.986"], ["70318.50", "2.984"], ["70639.60", "0.006"], ["71003.70", "0.141"], ["71026.20", "0.007"], ["71033.30", "0.009"], ["71033.70", "0.000"], ["71040.40", "0.007"], ["71040.80", "0.000"], ["71047.50", "0.007"], ["71047.90", "0.000"], ["71054.60", "0.015"], ["71055.00", "0.213"], ["71061.70", "0.007"], ["71062.10", "0.002"], ["71068.80", "0.007"], ["71069.20", "0.000"], ["71075.90", "0.011"], ["71076.30", "6.461"], ["71083.40", "0.000"], ["71193.50", "0.309"], ["71195.70", "0.002"], ["71199.70", "0.204"], ["71199.80", "0.101"], ["71202.80", "0.000"], ["71206.10", "0.047"], ["71211.20", "2.943"], ["71215.60", "0.041"], ["71218.40", "0.025"], ["71221.90", "0.143"], ["71222.30", "0.129"], ["71229.50", "0.294"], ["71260.20", "0.181"], ["71264.60", "0.927"], ["71269.80", "1.852"], ["71294.40", "4.412"], ["71295.20", "0.000"], ["71303.60", "0.049"], ["71305.70", "0.061"], ["71306.20", "0.009"], ["71309.60", "0.001"], ["71310.60", "0.004"], ["71311.60", "0.042"], ["71312.50", "0.107"], ["71313.50", "0.008"], ["71313.80", "0.045"], ["71314.50", "0.594"], ["71314.80", "1.525"], ["71315.40", "0.002"], ["71315.70", "0.042"], ["71316.40", "0.003"], ["71316.70", "0.042"], ["71317.70", "0.082"], ["71318.80", "0.045"], ["71320.30", "0.051"], ["71320.50", "0.165"], ["71321.10", "0.000"], ["71321.50", "0.323"], ["71321.60", "1.404"], ["71322.10", "0.004"], ["71322.20", "0.855"], ["71322.50", "0.276"], ["71322.60", "0.005"], ["71323.50", "0.042"], ["71323.70", "0.000"], ["71324.50", "0.498"], ["71325.70", "0.000"], ["71326.00", "0.209"], ["71326.10", "0.790"], ["71326.30", "0.014"], ["71326.80", "0.605"], ["71327.10", "0.001"], ["71327.20", "0.000"], ["71327.30", "0.008"], ["71327.60", "0.006"], ["71327.70", "0.002"], ["71327.80", "0.008"], ["71328.50", "0.004"], ["71328.60", "0.248"], ["71328.70", "0.000"], ["71329.00", "0.005"], ["71329.50", "0.001"], ["71329.90", "0.003"], ["71330.40", "0.012"], ["71331.00", "0.000"], ["71331.20", "0.011"], ["71331.40", "0.024"], ["71332.00", "1.305"], ["71332.20", "0.000"], ["71333.30", "1.287"], ["71333.50", "0.015"], ["71333.90", "0.026"], ["71334.30", "0.000"], ["71334.70", "0.307"], ["71335.40", "0.023"], ["71336.50", "0.000"], ["71337.70", "0.458"], ["71338.90", "0.001"], ["71339.00", "0.000"], ["71340.00", "0.008"], ["71340.20", "0.002"], ["71341.00", "0.001"], ["71341.90", "0.788"], ["71342.00", "0.007"], ["71342.20", "0.044"], ["71342.50", "0.138"], ["71342.70", "0.006"], ["71343.20", "0.003"], ["71343.50", "0.000"], ["71343.60", "0.002"], ["71344.00", "0.108"], ["71344.10", "0.004"], ["71344.50", "0.002"], ["71344.70", "0.151"], ["71344.80", "0.061"], ["71345.30", "0.012"], ["71345.40", "0.001"], ["71345.70", "0.000"], ["71346.80", "0.003"], ["71347.30", "0.001"], ["71347.40", "0.002"], ["71347.50", "0.007"], ["71348.50", "0.002"], ["71349.80", "0.001"], ["71350.70", "0.000"], ["71351.60", "0.049"], ["71351.70", "0.002"], ["71352.00", "0.008"], ["71352.10", "0.016"], ["71352.80", "0.000"], ["71352.90", "0.002"], ["71353.10", "0.221"]], "a": [["71353.20", "9.647"], ["71358.70", "0.083"], ["71359.40", "0.005"], ["71359.60", "0.449"], ["71364.10", "0.235"], ["71365.10", "0.013"], ["71368.60", "0.050"], ["71368.70", "0.140"], ["71369.20", "0.092"], ["71369.80", "0.049"], ["71370.00", "0.035"], ["71370.20", "0.046"], ["71370.30", "0.028"], ["71370.40", "0.034"], ["71370.80", "0.036"], ["71371.00", "1.303"], ["71371.40", "1.055"], ["71371.50", "0.064"], ["71371.90", "0.005"], ["71372.00", "0.034"], ["71372.10", "0.107"], ["71372.80", "0.035"], ["71373.90", "0.003"], ["71374.50", "0.679"], ["71374.90", "0.044"], ["71375.00", "0.304"], ["71375.30", "0.006"], ["71377.70", "0.630"], ["71378.10", "0.007"], ["71379.00", "0.098"], ["71380.90", "0.001"], ["71382.80", "0.002"], ["71385.80", "0.482"], ["71396.70", "0.020"], ["71396.90", "0.126"], ["71397.40", "0.071"], ["71402.30", "0.004"], ["71408.30", "0.000"], ["71413.90", "0.534"], ["71440.20", "0.030"], ["71444.00", "0.475"], ["71444.70", "0.002"], ["71447.10", "0.000"], ["72066.70", "0.004"], ["100000.00", "15.711"]]}}
{"local_ts": 1773378017040, "server_ts": 1773378016764, "data": {"e": "depthUpdate", "E": 1773378016765, "T": 1773378016764, "s": "BTCUSDT", "U": 10100835422278, "u": 10100835427941, "pu": 10100835422163, "b": [["1000.00", "26.142"], ["5000.00", "101.418"], ["20852.20", "0.243"], ["20953.10", "0.450"], ["21152.20", "0.432"], ["21253.10", "1.116"], ["56445.30", "0.002"], ["58456.00", "0.010"], ["67749.90", "0.002"], ["67759.70", "0.000"], ["70246.30", "2.969"], ["70332.30", "0.000"], ["70508.20", "0.000"], ["70638.70", "0.005"], ["70677.90", "0.630"], ["70740.50", "0.000"], ["71025.50", "0.007"], ["71026.20", "0.000"], ["71032.60", "0.012"], ["71033.30", "0.002"], ["71039.70", "0.007"], ["71040.40", "0.000"], ["71046.80", "0.007"], ["71047.50", "0.000"], ["71053.90", "0.007"], ["71054.60", "0.008"], ["71061.00", "0.007"], ["71061.70", "0.000"], ["71068.10", "0.019"], ["71068.80", "0.000"], ["71075.20", "0.007"], ["71075.90", "0.004"], ["71188.10", "0.159"], ["71192.60", "0.004"], ["71194.90", "0.014"], ["71195.70", "0.000"], ["71197.30", "0.064"], ["71200.40", "3.538"], ["71259.20", "0.198"], ["71272.80", "0.502"], ["71294.40", "0.881"], ["71297.90", "0.815"], ["71304.50", "0.284"], ["71316.60", "0.000"], ["71317.30", "0.000"], ["71325.70", "0.000"], ["71328.10", "0.011"], ["71328.60", "0.250"], ["71328.90", "0.342"], ["71329.10", "0.011"], ["71329.80", "0.047"], ["71331.60", "0.004"], ["71332.10", "0.008"], ["71332.60", "0.002"], ["71333.50", "0.023"], ["71344.30", "2.178"], ["71345.10", "0.028"]], "a": [["71375.80", "0.002"], ["71379.10", "0.675"], ["71382.40", "0.072"], ["71395.80", "0.009"], ["71395.90", "0.011"], ["71396.50", "0.806"], ["71396.60", "0.279"], ["71399.70", "0.372"], ["71406.80", "0.762"], ["71420.50", "0.921"], ["71422.60", "0.010"], ["71442.70", "0.206"], ["71444.70", "0.000"], ["71453.10", "1.151"], ["71456.20", "0.042"], ["71517.60", "9.290"], ["71518.30", "0.000"], ["71881.60", "0.003"], ["72065.80", "0.000"], ["72166.80", "0.013"], ["89523.20", "0.000"]]}}
{"local_ts": 1773378018064, "server_ts": 1773378017785, "data": {"e": "depthUpdate", "E": 1773378017787, "T": 1773378017785, "s": "BTCUSDT", "U": 10100835484217, "u": 10100835489675, "pu": 10100835484186, "b": [["5000.00", "101.418"], ["20852.20", "0.585"], ["21052.20", "0.378"], ["21152.20", "1.422"], ["21252.20", "0.315"], ["56445.30", "0.000"], ["57082.00", "0.000"], ["68211.30", "0.000"], ["70468.30", "1.132"], ["70626.70", "0.000"], ["70638.70", "0.005"], ["70789.50", "0.074"], ["70941.90", "0.104"], ["70943.50", "0.003"], ["70995.40", "0.003"], ["71019.80", "0.007"], ["71025.50", "0.000"], ["71026.90", "0.007"], ["71032.60", "0.005"], ["71034.00", "0.007"], ["71039.70", "0.000"], ["71041.10", "0.019"], ["71046.80", "0.000"], ["71048.20", "0.029"], ["71053.90", "0.000"], ["71055.30", "0.007"], ["71061.00", "0.000"], ["71062.40", "0.007"], ["71068.10", "0.012"], ["71069.50", "0.250"], ["71075.20", "0.000"], ["71268.70", "0.061"], ["71281.50", "0.016"], ["71289.10", "0.040"], ["71305.00", "0.009"], ["71305.10", "0.044"], ["71313.00", "0.172"], ["71326.60", "0.034"], ["71330.80", "0.151"], ["71344.10", "0.012"], ["71345.10", "0.000"], ["71345.20", "0.122"], ["71345.70", "0.000"], ["71346.10", "0.094"], ["71346.80", "0.003"], ["71347.30", "0.001"], ["71348.00", "0.002"], ["71348.40", "0.002"], ["71352.10", "0.777"], ["71352.20", "1.218"]], "a": [["71352.30", "8.798"], ["71360.60", "1.173"], ["71436.70", "0.019"], ["71450.60", "0.284"], ["71458.00", "0.012"], ["71628.40", "0.000"], ["71945.90", "0.000"], ["72065.80", "0.000"], ["72111.40", "0.000"], ["72366.40", "0.275"], ["73000.00", "142.619"], ["74936.00", "0.050"], ["89523.20", "0.000"]]}}
{"local_ts": 1773378019085, "server_ts": 1773378018805, "data": {"e": "depthUpdate", "E": 1773378018807, "T": 1773378018805, "s": "BTCUSDT", "U": 10100835566507, "u": 10100835575435, "pu": 10100835566501, "b": [["1000.00", "26.142"], ["5000.00", "101.418"], ["20949.20", "0.126"], ["21049.20", "0.117"], ["21052.20", "1.404"], ["21149.20", "0.126"], ["21152.20", "0.099"], ["21252.20", "0.720"], ["56445.30", "0.002"], ["67758.10", "0.000"], ["70253.60", "0.431"], ["70404.20", "54.867"], ["70616.10", "46.278"], ["70635.70", "0.018"], ["70855.10", "30.304"], ["70888.10", "18.840"], ["70917.40", "0.002"], ["70941.90", "0.102"], ["71013.10", "0.652"], ["71019.80", "0.000"], ["71026.90", "0.000"], ["71034.00", "0.000"], ["71041.10", "0.012"], ["71048.20", "0.022"], ["71055.30", "0.000"], ["71062.00", "0.545"], ["71062.40", "0.000"], ["71069.50", "0.243"], ["71085.30", "2.900"], ["71090.80", "0.001"], ["71091.30", "0.162"], ["71111.80", "0.199"], ["71198.90", "0.020"], ["71208.30", "0.042"], ["71208.50", "0.029"], ["71208.80", "0.182"], ["71212.80", "0.061"], ["71216.40", "0.000"], ["71253.30", "0.072"], ["71255.40", "0.002"], ["71260.50", "0.070"], ["71262.60", "0.047"], ["71267.60", "0.120"], ["71269.70", "0.013"], ["71270.70", "0.003"], ["71274.20", "0.003"], ["71274.50", "0.000"], ["71275.00", "0.247"], ["71275.40", "0.855"], ["71276.40", "0.000"], ["71277.40", "0.041"], ["71280.80", "0.019"], ["71283.00", "0.002"], ["71284.20", "0.201"], ["71285.00", "0.003"], ["71285.20", "0.027"], ["71286.10", "0.000"], ["71287.10", "0.000"], ["71288.10", "0.046"], ["71289.10", "0.040"], ["71291.50", "0.000"], ["71291.90", "0.045"], ["71293.00", "0.088"], ["71293.30", "0.015"], ["71293.70", "0.412"], ["71294.30", "0.129"], ["71294.50", "0.674"], ["71294.80", "0.044"], ["71295.10", "0.000"], ["71295.20", "0.000"], ["71296.20", "0.150"], ["71296.40", "0.103"], ["71297.30", "0.273"], ["71298.30", "0.467"], ["71298.40", "0.138"], ["71300.10", "0.002"], ["71300.40", "0.227"], ["71301.40", "0.721"], ["71301.60", "0.216"], ["71302.20", "0.010"], ["71302.40", "0.061"], ["71302.50", "0.003"], ["71304.60", "0.074"], ["71307.00", "0.002"], ["71307.20", "0.095"], ["71310.10", "0.123"], ["71314.50", "0.622"], ["71314.70", "0.023"], ["71315.50", "0.672"], ["71316.10", "0.001"], ["71316.50", "0.000"], ["71317.10", "0.011"], ["71318.70", "0.000"], ["71320.00", "0.009"], ["71320.10", "0.006"], ["71320.50", "0.123"], ["71320.60", "0.509"], ["71321.20", "0.203"], ["71321.70", "0.004"], ["71322.40", "0.017"], ["71322.60", "0.590"], ["71323.10", "0.096"], ["71324.10", "0.110"], ["71324.60", "0.299"], ["71325.20", "0.002"], ["71325.30", "0.013"], ["71325.40", "0.829"], ["71325.90", "0.015"], ["71326.00", "0.209"], ["71326.60", "0.000"], ["71327.50", "0.010"], ["71328.00", "0.004"], ["71328.20", "0.011"], ["71328.80", "0.064"], ["71328.90", "0.342"], ["71329.20", "0.003"], ["71329.80", "0.006"], ["71330.00", "0.297"], ["71330.40", "1.019"], ["71332.30", "0.449"], ["71332.70", "0.017"], ["71332.80", "0.013"], ["71332.90", "0.003"], ["71333.40", "0.000"], ["71333.50", "0.010"], ["71334.10", "0.039"], ["71335.90", "0.167"], ["71336.10", "0.000"], ["71337.50", "0.500"], ["71337.60", "0.255"], ["71337.70", "0.674"], ["71337.90", "0.202"], ["71338.00", "0.118"], ["71339.40", "0.008"], ["71340.80", "0.329"], ["71341.30", "0.004"], ["71343.10", "0.001"], ["71343.40", "0.002"], ["71344.30", "0.136"], ["71345.90", "0.025"], ["71346.60", "0.003"], ["71348.80", "0.005"], ["71349.10", "0.002"]], "a": [["71349.30", "7.415"], ["71349.50", "0.185"], ["71349.60", "0.200"], ["71349.80", "0.211"], ["71350.20", "0.010"], ["71350.30", "0.208"], ["71350.40", "0.082"], ["71350.80", "0.002"], ["71351.00", "0.049"], ["71351.20", "0.002"], ["71351.60", "0.002"], ["71352.00", "0.041"], ["71352.40", "0.007"], ["71352.90", "0.003"], ["71353.10", "0.003"], ["71355.20", "0.001"], ["71355.50", "0.000"], ["71355.70", "0.207"], ["71355.90", "0.210"], ["71356.10", "0.002"], ["71356.20", "0.646"], ["71356.50", "0.018"], ["71356.70", "0.033"], ["71357.00", "0.008"], ["71357.30", "0.004"], ["71357.80", "0.006"], ["71359.30", "0.002"], ["71359.40", "0.061"], ["71359.90", "0.338"], ["71360.00", "0.822"], ["71360.10", "0.002"], ["71360.50", "0.954"], ["71360.60", "1.447"], ["71363.30", "0.004"], ["71363.50", "0.009"], ["71363.80", "1.329"], ["71364.10", "0.297"], ["71364.30", "0.006"], ["71365.00", "1.014"], ["71365.70", "0.121"], ["71365.80", "0.051"], ["71366.50", "0.000"], ["71367.20", "0.056"], ["71371.90", "0.004"], ["71372.20", "0.006"], ["71373.00", "0.000"], ["71373.10", "0.007"], ["71373.50", "0.003"], ["71374.20", "0.051"], ["71374.30", "0.002"], ["71374.60", "0.023"], ["71375.10", "0.000"], ["71377.90", "0.294"], ["71379.10", "0.753"], ["71380.30", "0.013"], ["71380.40", "1.097"], ["71382.60", "0.003"], ["71383.20", "0.318"], ["71383.30", "0.507"], ["71383.90", "0.000"], ["71384.00", "0.002"], ["71384.30", "0.006"], ["71387.20", "0.000"], ["71387.70", "0.111"], ["71388.60", "0.035"], ["71389.00", "0.010"], ["71389.70", "0.000"], ["71391.60", "0.356"], ["71391.70", "0.862"], ["71392.20", "0.219"], ["71392.30", "0.008"], ["71392.40", "0.022"], ["71393.50", "0.002"], ["71395.60", "0.089"], ["71397.80", "0.028"], ["71398.30", "0.277"], ["71398.50", "0.002"], ["71398.90", "1.443"], ["71399.20", "0.056"], ["71399.60", "0.004"], ["71402.80", "0.146"], ["71406.40", "0.081"], ["71413.50", "1.297"], ["71416.30", "0.111"], ["71423.00", "0.952"], ["71423.80", "0.325"], ["71425.40", "0.410"], ["71427.00", "0.109"], ["71427.80", "0.023"], ["71431.30", "0.100"], ["71432.00", "0.070"], ["71434.30", "0.000"], ["71434.90", "0.654"], ["71436.50", "0.098"], ["71438.60", "0.200"], ["71439.10", "0.073"], ["71441.40", "0.040"], ["71446.20", "0.543"], ["71446.30", "0.136"], ["71448.60", "0.000"], ["71456.00", "0.171"], ["71460.00", "0.110"], ["71468.30", "0.000"], ["71513.10", "0.000"], ["71513.90", "0.063"], ["71524.50", "0.010"], ["71559.30", "0.234"], ["71561.10", "1.654"], ["71563.30", "10.017"], ["71589.80", "0.207"], ["71591.80", "0.002"], ["71593.20", "0.010"], ["71696.50", "0.650"], ["71728.90", "0.008"], ["71933.40", "48.368"], ["72062.80", "0.000"], ["72098.80", "58.994"], ["72315.10", "67.073"], ["73653.40", "1.220"], ["74366.30", "0.002"], ["74936.30", "0.002"], ["89523.20", "0.000"]]}}
{"local_ts": 1773378020108, "server_ts": 1773378019826, "data": {"e": "depthUpdate", "E": 1773378019827, "T": 1773378019826, "s": "BTCUSDT", "U": 10100835640417, "u": 10100835675555, "pu": 10100835640359, "b": [["5000.00", "101.418"], ["20846.20", "0.045"], ["20946.20", "0.081"], ["20948.10", "0.009"], ["20948.70", "0.009"], ["20949.20", "1.440"], ["20951.80", "0.000"], ["20952.00", "0.000"], ["20952.20", "0.000"], ["21046.20", "0.045"], ["21051.90", "0.000"], ["21052.20", "0.000"], ["21146.20", "0.027"], ["21149.20", "0.819"], ["21151.40", "0.000"], ["21151.90", "0.000"], ["21152.20", "0.000"], ["21252.20", "0.000"], ["56445.30", "0.000"], ["62373.80", "0.036"], ["69579.00", "0.002"], ["70326.10", "1.106"], ["70632.70", "0.006"], ["70634.60", "0.000"], ["70634.70", "0.011"], ["70635.60", "0.000"], ["70635.70", "0.390"], ["70915.50", "0.002"], ["70917.40", "0.000"], ["70971.10", "0.010"], ["71021.60", "0.213"], ["71068.70", "0.007"], ["71071.00", "1.717"], ["71071.10", "1.230"], ["71081.20", "0.017"], ["71086.20", "0.001"], ["71107.20", "0.007"], ["71123.00", "10.216"], ["71137.60", "0.004"], ["71138.80", "0.891"], ["71139.40", "0.521"], ["71157.40", "0.000"], ["71172.60", "0.041"], ["71178.50", "0.042"], ["71184.80", "0.263"], ["71185.70", "0.162"], ["71185.80", "0.060"], ["71187.50", "0.167"], ["71187.60", "1.470"], ["71187.70", "0.161"], ["71188.20", "0.159"], ["71188.40", "0.165"], ["71188.60", "0.159"], ["71198.10", "3.161"], ["71202.50", "0.138"], ["71204.10", "0.807"], ["71204.30", "0.061"], ["71207.60", "0.093"], ["71208.50", "0.027"], ["71210.40", "0.061"], ["71212.00", "0.004"], ["71212.50", "0.091"], ["71213.10", "0.089"], ["71214.40", "0.142"], ["71215.10", "0.385"], ["71228.30", "0.010"], ["71246.40", "0.145"], ["71250.80", "0.139"], ["71251.50", "0.451"], ["71252.70", "0.036"], ["71253.30", "0.002"], ["71254.10", "0.271"], ["71254.40", "0.362"], ["71256.70", "0.001"], ["71257.40", "1.351"], ["71258.00", "0.077"], ["71258.40", "0.000"], ["71259.50", "0.012"], ["71262.20", "0.063"], ["71264.40", "0.044"], ["71265.10", "0.234"], ["71265.20", "0.064"], ["71267.30", "0.040"], ["71272.50", "0.005"], ["71272.80", "0.572"], ["71272.90", "0.000"], ["71274.20", "0.143"], ["71275.70", "0.721"], ["71277.40", "0.002"], ["71278.30", "0.058"], ["71280.10", "0.004"], ["71282.10", "0.284"], ["71283.10", "0.035"], ["71284.70", "0.151"], ["71284.90", "0.081"], ["71287.10", "0.029"], ["71288.50", "0.111"], ["71289.40", "0.002"], ["71289.90", "0.100"], ["71292.00", "0.063"], ["71294.30", "0.988"], ["71295.60", "0.017"], ["71295.70", "0.119"], ["71296.10", "0.014"], ["71296.30", "0.276"], ["71296.70", "0.003"], ["71296.80", "0.108"], ["71298.10", "0.557"], ["71298.80", "0.203"], ["71299.10", "0.004"], ["71299.20", "0.000"], ["71299.30", "0.003"], ["71299.40", "0.016"], ["71300.00", "0.288"], ["71300.40", "0.096"], ["71300.60", "1.159"], ["71300.80", "0.003"], ["71301.40", "0.679"], ["71301.80", "0.118"], ["71301.90", "0.842"], ["71302.10", "0.120"], ["71302.30", "0.137"], ["71303.10", "0.026"], ["71305.50", "0.282"], ["71305.70", "0.153"], ["71306.00", "0.002"], ["71306.10", "0.000"], ["71307.00", "0.106"], ["71307.70", "0.207"], ["71309.80", "0.294"], ["71310.00", "0.009"], ["71310.10", "0.062"], ["71310.40", "0.051"], ["71310.60", "0.028"], ["71310.80", "0.050"], ["71311.00", "0.000"], ["71311.20", "0.291"], ["71312.30", "0.790"], ["71312.50", "0.392"], ["71312.80", "0.000"], ["71313.10", "0.001"], ["71313.30", "0.003"], ["71313.60", "0.000"], ["71313.80", "0.003"], ["71314.20", "0.005"], ["71314.30", "0.004"], ["71314.70", "0.004"], ["71314.80", "1.425"], ["71315.00", "0.863"], ["71315.10", "0.000"], ["71315.30", "0.947"], ["71315.80", "0.000"], ["71315.90", "0.114"], ["71316.10", "0.071"], ["71316.60", "0.000"], ["71316.70", "0.314"], ["71316.90", "0.605"], ["71317.00", "0.008"], ["71317.10", "0.011"], ["71317.20", "0.050"], ["71317.40", "0.014"], ["71317.50", "0.005"], ["71317.60", "0.981"], ["71317.80", "0.000"], ["71317.90", "0.016"], ["71318.00", "0.022"], ["71318.10", "0.275"], ["71318.20", "0.074"], ["71318.30", "0.080"], ["71318.40", "0.403"], ["71318.80", "0.017"], ["71319.00", "0.113"], ["71319.10", "0.001"], ["71319.30", "1.127"], ["71319.40", "0.890"], ["71319.60", "0.002"], ["71319.70", "0.001"], ["71319.80", "0.005"], ["71320.30", "0.000"], ["71320.60", "0.011"], ["71320.70", "0.032"], ["71320.80", "0.078"], ["71320.90", "0.004"], ["71321.00", "0.002"], ["71321.40", "0.004"], ["71321.50", "0.281"], ["71321.60", "1.404"], ["71321.80", "0.005"], ["71321.90", "0.002"], ["71322.00", "0.003"], ["71322.20", "0.002"], ["71322.30", "0.000"], ["71322.40", "0.072"], ["71322.50", "0.278"], ["71322.60", "0.005"], ["71322.80", "0.001"], ["71322.90", "0.003"], ["71323.00", "0.185"], ["71323.10", "0.029"], ["71323.30", "1.199"], ["71323.40", "0.056"], ["71323.50", "0.005"], ["71323.60", "0.003"], ["71323.70", "0.000"], ["71324.30", "0.016"], ["71324.50", "0.013"], ["71324.70", "0.015"], ["71324.80", "0.006"], ["71325.20", "0.003"], ["71325.30", "1.005"], ["71325.40", "0.011"], ["71325.50", "0.000"], ["71325.60", "0.014"], ["71325.90", "0.018"], ["71326.10", "0.449"], ["71326.20", "0.047"], ["71326.30", "0.006"], ["71326.40", "0.095"], ["71326.50", "0.006"], ["71326.60", "0.003"], ["71326.70", "0.162"], ["71326.90", "0.060"], ["71327.00", "0.675"], ["71327.10", "0.001"], ["71327.20", "0.504"], ["71327.80", "0.210"], ["71327.90", "0.143"], ["71328.30", "0.280"], ["71328.40", "0.016"], ["71328.70", "0.004"], ["71328.90", "0.006"], ["71329.00", "0.002"], ["71329.20", "0.014"], ["71329.30", "0.014"], ["71329.40", "0.054"], ["71329.50", "0.001"], ["71329.80", "0.006"], ["71329.90", "0.003"], ["71330.00", "0.017"], ["71330.10", "0.221"], ["71330.20", "1.421"], ["71330.30", "0.724"], ["71330.40", "0.008"], ["71330.50", "0.141"], ["71330.60", "0.003"], ["71330.70", "0.000"], ["71331.00", "0.000"], ["71331.30", "0.013"], ["71331.40", "0.154"], ["71331.60", "0.008"], ["71331.90", "0.231"], ["71332.00", "0.114"], ["71332.10", "0.001"], ["71332.20", "0.003"], ["71332.30", "0.006"], ["71332.40", "0.003"], ["71332.50", "0.000"], ["71332.70", "0.010"], ["71332.80", "0.005"], ["71332.90", "0.000"], ["71333.10", "0.007"], ["71333.20", "0.207"], ["71333.50", "0.007"], ["71333.70", "0.005"], ["71333.80", "0.724"], ["71333.90", "0.006"], ["71334.00", "0.634"], ["71334.10", "0.004"], ["71334.20", "0.000"], ["71334.60", "0.003"], ["71334.90", "0.006"], ["71335.30", "0.000"], ["71335.40", "0.001"], ["71335.70", "0.002"], ["71335.80", "0.001"], ["71335.90", "0.011"], ["71336.00", "0.004"], ["71336.40", "0.000"], ["71336.60", "0.261"], ["71336.80", "0.003"], ["71336.90", "0.019"], ["71337.00", "0.017"], ["71337.10", "0.005"], ["71337.20", "0.009"], ["71337.40", "0.001"], ["71337.50", "0.249"], ["71337.60", "0.225"], ["71337.70", "0.000"], ["71337.80", "0.018"], ["71337.90", "0.001"], ["71338.10", "0.110"], ["71338.40", "0.022"], ["71339.10", "0.000"], ["71339.20", "0.000"], ["71339.30", "0.000"], ["71339.60", "0.004"], ["71339.70", "0.000"], ["71339.80", "0.000"], ["71340.30", "0.053"], ["71340.40", "0.000"], ["71340.50", "0.106"], ["71340.60", "0.075"], ["71340.70", "0.283"], ["71340.80", "0.359"], ["71340.90", "0.063"], ["71341.10", "0.061"], ["71341.30", "0.038"], ["71341.50", "0.003"], ["71341.60", "0.004"], ["71342.00", "0.035"], ["71342.10", "0.001"], ["71342.70", "0.004"], ["71343.00", "0.004"], ["71343.60", "0.000"], ["71343.80", "0.002"], ["71344.00", "0.007"], ["71344.30", "0.000"], ["71344.60", "0.000"], ["71344.70", "0.000"], ["71344.90", "0.001"], ["71345.00", "0.000"], ["71345.30", "0.004"], ["71345.60", "0.004"], ["71346.00", "0.009"], ["71346.10", "0.003"], ["71346.20", "0.256"], ["71346.30", "0.000"], ["71346.40", "0.000"], ["71346.50", "0.000"], ["71346.60", "0.000"], ["71346.80", "0.000"], ["71347.00", "0.000"], ["71347.10", "0.000"], ["71347.20", "0.000"], ["71347.30", "0.000"], ["71347.40", "0.000"], ["71347.50", "0.000"], ["71347.70", "0.000"], ["71347.80", "0.000"], ["71348.00", "0.000"], ["71348.10", "0.000"], ["71348.20", "0.000"], ["71348.30", "0.000"], ["71348.40", "0.000"], ["71348.60", "0.000"], ["71348.70", "0.000"], ["71348.80", "0.000"], ["71348.90", "0.000"], ["71349.00", "0.000"], ["71349.10", "0.000"], ["71349.20", "0.000"]], "a": [["71346.30", "10.135"], ["71346.40", "0.125"], ["71346.50", "0.000"], ["71346.60", "0.000"], ["71346.70", "0.000"], ["71346.90", "0.002"], ["71347.10", "0.002"], ["71347.20", "0.080"], ["71347.30", "0.001"], ["71347.40", "0.000"], ["71347.50", "0.002"], ["71347.60", "0.200"], ["71347.70", "0.002"], ["71347.80", "0.002"], ["71347.90", "0.000"], ["71348.00", "0.113"], ["71348.10", "0.000"], ["71348.20", "0.688"], ["71348.30", "0.034"], ["71348.40", "0.001"], ["71348.50", "0.000"], ["71348.70", "0.002"], ["71348.80", "0.349"], ["71348.90", "0.001"], ["71349.00", "0.801"], ["71349.10", "0.004"], ["71349.20", "0.140"], ["71349.30", "0.050"], ["71349.40", "0.007"], ["71349.50", "0.003"], ["71349.60", "0.054"], ["71349.80", "0.001"], ["71349.90", "0.002"], ["71350.10", "0.005"], ["71350.20", "0.009"], ["71350.30", "0.003"], ["71350.40", "0.002"], ["71351.00", "0.051"], ["71351.50", "0.002"], ["71351.60", "0.001"], ["71351.80", "0.005"], ["71352.00", "0.086"], ["71352.10", "0.032"], ["71352.30", "0.033"], ["71352.40", "0.010"], ["71352.70", "0.002"], ["71352.80", "0.003"], ["71353.20", "0.050"], ["71353.30", "0.321"], ["71353.40", "0.003"], ["71353.50", "0.002"], ["71354.20", "0.006"], ["71354.70", "0.001"], ["71355.00", "0.006"], ["71355.10", "0.030"], ["71355.70", "0.204"], ["71355.80", "0.005"], ["71356.00", "0.006"], ["71356.10", "0.000"], ["71356.30", "0.003"], ["71356.50", "0.013"], ["71356.60", "0.037"], ["71357.00", "0.682"], ["71357.20", "0.002"], ["71357.30", "0.224"], ["71357.40", "0.002"], ["71357.90", "0.147"], ["71358.00", "0.148"], ["71358.20", "0.010"], ["71358.30", "0.165"], ["71358.50", "0.004"], ["71358.70", "0.147"], ["71358.80", "0.006"], ["71358.90", "0.070"], ["71359.20", "0.004"], ["71359.40", "0.005"], ["71359.50", "1.447"], ["71359.60", "0.449"], ["71359.70", "0.073"], ["71360.00", "1.350"], ["71360.10", "0.019"], ["71360.30", "0.025"], ["71360.40", "0.680"], ["71360.50", "2.286"], ["71360.60", "1.491"], ["71360.70", "0.835"], ["71360.90", "0.002"], ["71361.20", "0.005"], ["71361.30", "0.001"], ["71361.40", "0.095"], ["71361.60", "0.080"], ["71361.70", "0.054"], ["71361.90", "0.032"], ["71362.00", "0.004"], ["71362.20", "0.106"], ["71362.30", "0.113"], ["71362.40", "1.110"], ["71362.50", "0.070"], ["71362.70", "0.147"], ["71362.80", "0.176"], ["71363.30", "0.004"], ["71363.40", "0.084"], ["71363.70", "0.080"], ["71363.80", "0.677"], ["71363.90", "0.010"], ["71364.20", "0.476"], ["71364.40", "0.045"], ["71364.50", "0.002"], ["71364.60", "0.001"], ["71364.70", "0.042"], ["71364.90", "0.056"], ["71365.00", "0.025"], ["71365.10", "0.002"], ["71365.20", "0.023"], ["71365.30", "0.004"], ["71365.50", "0.211"], ["71365.60", "0.000"], ["71366.20", "0.070"], ["71366.40", "0.001"], ["71366.60", "0.001"], ["71366.70", "0.000"], ["71366.80", "0.003"], ["71366.90", "0.000"], ["71367.00", "0.006"], ["71367.10", "0.003"], ["71367.40", "0.005"], ["71367.50", "0.000"], ["71367.70", "0.056"], ["71368.00", "0.341"], ["71368.10", "0.003"], ["71368.20", "0.002"], ["71368.30", "0.680"], ["71368.50", "0.011"], ["71368.70", "0.020"], ["71369.00", "0.111"], ["71369.10", "0.067"], ["71369.50", "0.113"], ["71369.60", "0.005"], ["71369.70", "0.437"], ["71370.00", "0.032"], ["71370.10", "0.002"], ["71370.20", "0.004"], ["71370.30", "0.007"], ["71370.40", "0.008"], ["71370.60", "0.000"], ["71370.70", "0.020"], ["71370.80", "0.875"], ["71370.90", "0.557"], ["71371.20", "0.002"], ["71371.40", "0.934"], ["71371.50", "0.006"], ["71371.80", "0.007"], ["71372.00", "0.008"], ["71372.70", "0.003"], ["71373.30", "0.072"], ["71373.80", "0.059"], ["71374.10", "0.000"], ["71374.20", "0.000"], ["71374.40", "0.000"], ["71374.70", "0.021"], ["71374.80", "0.013"], ["71374.90", "0.289"], ["71376.20", "0.075"], ["71376.50", "0.058"], ["71376.70", "0.000"], ["71376.80", "0.074"], ["71377.40", "1.013"], ["71377.90", "0.001"], ["71378.00", "0.012"], ["71379.00", "0.096"], ["71379.10", "0.747"], ["71379.70", "0.002"], ["71379.80", "0.022"], ["71380.00", "0.004"], ["71380.20", "0.030"], ["71380.30", "0.006"], ["71380.40", "1.095"], ["71380.80", "0.005"], ["71380.90", "0.854"], ["71381.10", "0.000"], ["71381.20", "0.760"], ["71381.50", "0.499"], ["71381.60", "0.278"], ["71381.80", "0.004"], ["71381.90", "0.072"], ["71382.00", "0.007"], ["71382.40", "0.000"], ["71382.50", "0.340"], ["71382.60", "0.003"], ["71383.20", "0.288"], ["71383.50", "0.002"], ["71383.80", "0.002"], ["71384.00", "0.004"], ["71384.50", "0.891"], ["71384.90", "0.005"], ["71385.00", "0.076"], ["71385.40", "1.066"], ["71385.50", "0.001"], ["71385.70", "0.004"], ["71386.30", "0.000"], ["71386.60", "0.965"], ["71386.80", "0.074"], ["71387.00", "0.002"], ["71388.10", "1.147"], ["71388.20", "0.687"], ["71388.30", "0.000"], ["71388.40", "0.000"], ["71388.80", "0.045"], ["71388.90", "0.281"], ["71389.10", "0.817"], ["71389.20", "1.513"], ["71389.50", "0.010"], ["71389.60", "0.011"], ["71390.00", "0.039"], ["71390.10", "0.003"], ["71390.20", "0.007"], ["71390.30", "0.027"], ["71390.40", "0.000"], ["71390.90", "0.002"], ["71391.00", "0.003"], ["71391.20", "0.002"], ["71391.30", "0.085"], ["71391.60", "0.347"], ["71391.70", "0.853"], ["71392.00", "0.002"], ["71392.20", "0.009"], ["71392.30", "0.002"], ["71392.50", "0.999"], ["71392.60", "2.040"], ["71392.90", "0.679"], ["71393.10", "0.002"], ["71393.30", "0.002"], ["71393.60", "0.003"], ["71394.30", "0.115"], ["71394.50", "0.003"], ["71394.90", "0.008"], ["71395.00", "0.537"], ["71395.10", "0.005"], ["71395.40", "0.102"], ["71395.50", "0.015"], ["71396.00", "0.027"], ["71396.10", "0.013"], ["71396.30", "0.001"], ["71396.70", "0.002"], ["71397.40", "0.000"], ["71397.60", "1.960"], ["71397.80", "1.000"], ["71398.00", "0.115"], ["71398.50", "0.008"], ["71399.30", "0.000"], ["71399.40", "0.103"], ["71401.60", "0.719"], ["71401.80", "0.005"], ["71401.90", "0.498"], ["71402.00", "0.029"], ["71402.30", "0.096"], ["71402.80", "0.065"], ["71402.90", "0.003"], ["71403.40", "0.104"], ["71404.10", "0.002"], ["71404.70", "0.002"], ["71405.00", "0.004"], ["71405.30", "0.710"], ["71406.40", "0.000"], ["71406.90", "0.081"], ["71408.20", "0.043"], ["71408.40", "0.000"], ["71408.50", "2.878"], ["71408.60", "2.313"], ["71409.20", "0.748"], ["71410.70", "0.000"], ["71410.80", "0.002"], ["71412.90", "0.000"], ["71413.50", "1.296"], ["71414.00", "0.002"], ["71416.10", "0.014"], ["71416.30", "0.024"], ["71416.80", "0.034"], ["71419.20", "0.140"], ["71419.90", "0.677"], ["71421.60", "0.016"], ["71423.40", "2.457"], ["71427.60", "0.147"], ["71427.70", "0.000"], ["71429.30", "0.000"], ["71429.60", "0.072"], ["71430.90", "0.047"], ["71431.40", "0.103"], ["71431.70", "0.069"], ["71431.90", "0.171"], ["71433.60", "0.242"], ["71436.20", "0.275"], ["71436.70", "0.087"], ["71438.10", "0.061"], ["71439.80", "0.282"], ["71440.80", "0.043"], ["71441.00", "0.007"], ["71442.20", "0.000"], ["71442.60", "1.642"], ["71442.90", "0.459"], ["71443.90", "0.070"], ["71445.00", "0.062"], ["71446.80", "0.231"], ["71447.90", "0.000"], ["71452.20", "0.061"], ["71453.10", "2.225"], ["71458.00", "0.012"], ["71459.60", "0.000"], ["71460.30", "0.000"], ["71463.10", "0.063"], ["71466.20", "0.007"], ["71473.20", "0.000"], ["71475.70", "0.363"], ["71488.60", "0.000"], ["71507.30", "0.779"], ["71507.70", "0.250"], ["71512.10", "0.000"], ["71512.60", "1.541"], ["71513.00", "5.399"], ["71524.80", "4.404"], ["71525.50", "0.017"], ["71527.40", "0.002"], ["71528.10", "10.000"], ["71530.50", "0.121"], ["71538.90", "0.005"], ["71539.80", "0.000"], ["71540.00", "0.017"], ["71543.20", "0.283"], ["71551.50", "0.000"], ["71556.90", "0.017"], ["71558.20", "0.200"], ["71612.00", "0.000"], ["71651.20", "0.392"], ["72059.80", "0.006"], ["72061.60", "0.003"], ["72061.70", "0.000"], ["72062.30", "0.000"], ["72062.50", "0.020"], ["72062.70", "0.000"], ["72062.80", "0.000"], ["72344.10", "1.779"], ["72345.00", "0.470"], ["72348.20", "0.150"], ["72348.30", "0.004"], ["72348.80", "0.002"], ["72355.60", "12.005"], ["72355.90", "0.002"], ["72360.30", "0.008"], ["72360.40", "0.006"], ["72551.00", "0.294"], ["74938.40", "0.000"], ["76502.60", "0.081"], ["76680.10", "0.000"], ["89523.20", "0.000"]]}}
{"local_ts": 1773378021123, "server_ts": 1773378020846, "data": {"e": "depthUpdate", "E": 1773378020847, "T": 1773378020846, "s": "BTCUSDT", "U": 10100835789704, "u": 10100835794771, "pu": 10100835789701, "b": [["1000.00", "26.142"], ["5000.00", "101.418"], ["20839.60", "0.801"], ["20949.20", "0.126"], ["21039.60", "0.405"], ["21149.20", "0.063"], ["33000.00", "9.339"], ["56445.30", "0.002"], ["57082.00", "0.000"], ["64205.60", "0.002"], ["67762.80", "0.000"], ["67772.00", "0.029"], ["70626.20", "0.002"], ["70672.70", "1.217"], ["70898.30", "0.006"], ["70915.50", "0.000"], ["70982.90", "0.003"], ["71192.40", "0.546"], ["71203.50", "0.002"], ["71204.10", "0.061"], ["71212.00", "0.000"], ["71216.60", "0.067"], ["71283.90", "0.043"], ["71289.60", "0.005"], ["71290.30", "0.558"], ["71293.30", "0.017"], ["71293.40", "0.923"], ["71294.40", "1.994"], ["71305.70", "0.200"], ["71305.80", "0.110"], ["71307.50", "0.258"], ["71310.50", "0.075"], ["71311.00", "0.210"], ["71312.10", "0.018"], ["71312.60", "0.217"], ["71313.20", "0.000"], ["71314.80", "1.505"], ["71317.80", "0.070"], ["71319.40", "0.504"], ["71319.50", "0.151"], ["71320.10", "0.391"], ["71321.80", "0.222"], ["71322.20", "0.002"], ["71323.40", "0.036"], ["71323.50", "1.034"], ["71323.70", "0.000"], ["71325.30", "0.297"], ["71326.80", "0.670"], ["71326.90", "0.064"], ["71329.00", "0.042"], ["71329.20", "0.012"], ["71331.20", "0.000"], ["71332.20", "0.018"], ["71332.50", "0.028"], ["71334.20", "0.630"], ["71336.60", "0.168"], ["71338.10", "0.036"], ["71339.10", "0.003"], ["71339.60", "3.374"]], "a": [["71339.70", "5.442"], ["71339.80", "0.003"], ["71339.90", "0.002"], ["71340.00", "0.215"], ["71340.80", "0.082"], ["71341.20", "0.001"], ["71343.50", "0.213"], ["71343.80", "0.002"], ["71344.10", "0.000"], ["71344.30", "0.002"], ["71346.00", "0.016"], ["71346.10", "0.453"], ["71346.30", "0.838"], ["71347.50", "0.004"], ["71348.60", "0.176"], ["71349.20", "0.004"], ["71349.60", "0.015"], ["71350.40", "0.008"], ["71350.80", "0.002"], ["71351.10", "0.015"], ["71351.80", "0.651"], ["71352.00", "0.302"], ["71352.10", "0.037"], ["71352.40", "0.030"], ["71352.60", "0.002"], ["71352.70", "0.002"], ["71352.90", "0.012"], ["71353.00", "0.004"], ["71353.10", "0.011"], ["71353.30", "0.011"], ["71353.70", "0.027"], ["71353.80", "0.000"], ["71354.20", "0.006"], ["71354.30", "0.008"], ["71354.90", "0.027"], ["71355.00", "0.024"], ["71355.40", "0.004"], ["71355.90", "0.285"], ["71356.50", "0.286"], ["71359.70", "0.017"], ["71360.10", "0.032"], ["71360.60", "0.698"], ["71361.90", "0.000"], ["71362.00", "0.004"], ["71362.10", "0.003"], ["71362.30", "0.032"], ["71362.40", "0.032"], ["71362.70", "0.000"], ["71363.10", "0.016"], ["71363.20", "0.001"], ["71363.40", "0.000"], ["71363.80", "0.679"], ["71364.10", "0.003"], ["71364.50", "0.002"], ["71364.70", "0.000"], ["71364.80", "0.059"], ["71364.90", "0.047"], ["71365.30", "0.088"], ["71365.60", "0.000"], ["71365.70", "0.002"], ["71366.00", "0.052"], ["71366.10", "0.102"], ["71366.30", "0.018"], ["71366.60", "0.000"], ["71366.90", "0.006"], ["71367.20", "0.033"], ["71367.40", "0.005"], ["71367.70", "0.005"], ["71368.10", "0.054"], ["71368.20", "0.002"], ["71368.40", "0.002"], ["71368.50", "0.536"], ["71369.40", "0.032"], ["71370.10", "0.632"], ["71370.30", "0.000"], ["71370.60", "0.245"], ["71371.90", "0.103"], ["71372.40", "0.047"], ["71373.10", "0.508"], ["71373.20", "0.108"], ["71373.40", "1.526"], ["71374.40", "0.071"], ["71375.70", "0.245"], ["71376.90", "0.705"], ["71378.20", "0.326"], ["71379.40", "0.003"], ["71491.70", "0.525"], ["71501.50", "0.004"], ["72053.10", "2.823"], ["72376.80", "1.914"], ["72417.70", "17.908"], ["72428.40", "0.000"], ["72445.50", "0.957"], ["72484.80", "0.002"], ["72505.80", "0.002"], ["72607.20", "0.343"], ["78473.70", "0.002"], ["89523.20", "0.000"]]}}
{"local_ts": 1773378022148, "server_ts": 1773378021865, "data": {"e": "depthUpdate", "E": 1773378021867, "T": 1773378021865, "s": "BTCUSDT", "U": 10100835839725, "u": 10100835844064, "pu": 10100835839684, "b": [["1000.00", "26.142"], ["5000.00", "101.418"], ["20839.60", "0.702"], ["20939.60", "0.675"], ["21039.60", "0.225"], ["21239.60", "1.098"], ["56445.30", "0.000"], ["63887.00", "0.000"], ["64205.60", "0.010"], ["67755.70", "0.002"], ["68486.10", "0.005"], ["70019.90", "1.069"], ["70626.20", "1.422"], ["70888.50", "0.002"], ["70898.30", "0.004"], ["71192.40", "0.549"], ["71203.50", "0.000"], ["71207.00", "0.005"], ["71234.70", "0.094"], ["71261.10", "0.216"], ["71303.90", "0.204"], ["71305.70", "0.200"], ["71307.50", "0.000"], ["71308.00", "0.006"], ["71310.40", "0.080"], ["71311.10", "0.080"], ["71319.50", "0.151"], ["71323.50", "0.034"], ["71326.10", "0.749"], ["71329.10", "0.022"], ["71330.50", "0.080"], ["71332.50", "0.226"], ["71332.60", "0.676"], ["71337.70", "0.002"], ["71339.60", "3.107"]], "a": [["71339.70", "4.937"], ["71345.20", "0.003"], ["71346.00", "0.016"], ["71348.20", "0.034"], ["71348.70", "0.003"], ["71348.90", "0.010"], ["71349.20", "0.004"], ["71349.50", "0.009"], ["71349.60", "0.008"], ["71349.70", "0.035"], ["71349.90", "0.019"], ["71350.20", "0.009"], ["71350.40", "0.006"], ["71350.70", "0.010"], ["71351.10", "0.000"], ["71351.20", "0.013"], ["71351.30", "0.043"], ["71351.40", "0.000"], ["71351.60", "0.001"], ["71351.70", "0.197"], ["71351.80", "0.649"], ["71352.40", "0.007"], ["71353.50", "0.004"], ["71353.90", "0.003"], ["71354.20", "0.008"], ["71358.40", "0.001"], ["71358.70", "0.233"], ["71359.50", "1.405"], ["71360.20", "0.042"], ["71360.40", "0.677"], ["71361.30", "0.043"], ["71361.40", "0.031"], ["71361.90", "0.015"], ["71363.20", "0.016"], ["71367.30", "0.042"], ["71368.30", "1.010"], ["71369.20", "0.044"], ["71370.20", "0.044"], ["71371.30", "0.548"], ["71376.80", "0.166"], ["71488.50", "0.025"], ["71491.40", "0.595"], ["71577.90", "0.000"], ["72053.00", "0.000"], ["72053.10", "2.823"], ["72374.10", "4.790"], ["72417.70", "13.123"], ["72445.50", "4.785"], ["72489.10", "1.884"], ["74935.60", "0.002"], ["77035.10", "0.002"], ["78461.70", "0.012"], ["78473.70", "0.002"], ["89523.20", "0.000"]]}}
{"local_ts": 1773378023163, "server_ts": 1773378022886, "data": {"e": "depthUpdate", "E": 1773378022887, "T": 1773378022886, "s": "BTCUSDT", "U": 10100835882422, "u": 10100835885933, "pu": 10100835882404, "b": [["5000.00", "101.418"], ["20839.60", "0.540"], ["20939.60", "0.360"], ["21139.60", "0.828"], ["21239.60", "0.972"], ["33000.00", "9.343"], ["56445.30", "0.002"], ["57072.00", "0.008"], ["57076.00", "0.004"], ["57077.00", "0.004"], ["64205.60", "0.010"], ["67755.90", "0.002"], ["70626.20", "1.422"], ["70768.90", "0.847"], ["70982.90", "0.003"], ["71015.10", "1.188"], ["71186.20", "4.024"], ["71207.00", "0.003"], ["71207.10", "0.009"], ["71207.60", "0.095"], ["71254.00", "0.213"], ["71261.10", "0.003"], ["71302.80", "1.899"], ["71303.90", "0.204"], ["71305.70", "0.200"], ["71329.10", "0.022"], ["71330.70", "0.041"], ["71332.50", "0.000"], ["71339.60", "3.096"]], "a": [["71339.70", "3.362"], ["71341.10", "0.001"], ["71342.40", "0.010"], ["71343.90", "0.008"], ["71344.20", "0.091"], ["71344.80", "0.034"], ["71345.20", "0.003"], ["71345.40", "0.007"], ["71345.60", "0.017"], ["71347.80", "0.010"], ["71348.50", "0.029"], ["71348.60", "0.176"], ["71348.70", "0.003"], ["71350.50", "0.045"], ["71350.60", "0.017"], ["71351.80", "0.032"], ["71352.20", "0.002"], ["71352.40", "0.007"], ["71352.50", "0.017"], ["71353.30", "0.011"], ["71356.60", "0.125"], ["71357.10", "0.078"], ["71359.30", "0.042"], ["71363.20", "0.016"], ["71364.20", "0.518"], ["71364.40", "0.000"], ["71365.70", "0.002"], ["71369.90", "0.015"], ["71371.20", "0.002"], ["71372.40", "0.509"], ["71377.50", "1.526"], ["71378.50", "0.000"], ["71450.00", "1.252"], ["71577.70", "0.002"], ["71664.10", "0.005"], ["72053.00", "0.000"], ["72053.10", "2.823"], ["72228.60", "0.043"], ["74926.40", "0.000"], ["78473.70", "0.010"], ["89523.20", "0.000"]]}}
{"local_ts": 1773378024182, "server_ts": 1773378023906, "data": {"e": "depthUpdate", "E": 1773378023907, "T": 1773378023906, "s": "BTCUSDT", "U": 10100836248298, "u": 10100836264562, "pu": 10100836248181, "b": [["1000.00", "26.142"], ["5000.00", "101.418"], ["20839.60", "0.405"], ["20987.90", "0.342"], ["21139.60", "0.756"], ["21187.90", "0.189"], ["64159.10", "0.004"], ["67703.20", "0.004"], ["69862.20", "0.003"], ["70575.00", "0.164"], ["70853.00", "0.143"], ["70958.00", "0.002"], ["71036.90", "0.017"], ["71039.00", "0.141"], ["71052.20", "0.968"], ["71055.80", "0.002"], ["71066.00", "0.069"], ["71092.00", "0.006"], ["71115.40", "0.212"], ["71143.80", "0.091"], ["71149.50", "0.036"], ["71153.00", "1.228"], ["71168.20", "0.001"], ["71174.90", "0.016"], ["71178.20", "0.678"], ["71178.30", "0.548"], ["71179.50", "0.017"], ["71191.50", "0.040"], ["71195.40", "0.141"], ["71196.50", "0.000"], ["71197.20", "0.021"], ["71197.30", "0.080"], ["71197.60", "0.014"], ["71199.50", "0.003"], ["71207.60", "0.002"], ["71215.70", "0.004"], ["71220.10", "0.699"], ["71223.40", "0.002"], ["71226.50", "0.093"], ["71227.70", "1.282"], ["71231.60", "2.082"], ["71232.80", "0.000"], ["71235.60", "0.073"], ["71238.10", "0.329"], ["71241.50", "0.004"], ["71241.80", "0.000"], ["71243.20", "0.000"], ["71245.60", "0.000"], ["71249.90", "0.000"], ["71250.30", "0.273"], ["71251.60", "1.028"], ["71251.70", "0.026"], ["71252.30", "0.226"], ["71253.60", "0.276"], ["71254.70", "1.054"], ["71255.10", "0.000"], ["71255.90", "1.445"], ["71256.50", "0.060"], ["71257.60", "0.205"], ["71257.90", "1.017"], ["71258.60", "0.110"], ["71259.10", "0.012"], ["71259.50", "0.043"], ["71260.10", "0.008"], ["71260.50", "0.042"], ["71261.50", "0.820"], ["71262.40", "1.192"], ["71264.70", "0.045"], ["71265.40", "0.008"], ["71266.30", "0.002"], ["71266.60", "0.011"], ["71266.90", "0.011"], ["71267.30", "0.005"], ["71267.50", "0.009"], ["71267.60", "0.001"], ["71268.00", "0.084"], ["71268.60", "0.006"], ["71269.10", "0.004"], ["71269.30", "0.003"], ["71270.30", "0.046"], ["71270.40", "0.064"], ["71271.80", "0.045"], ["71272.30", "0.000"], ["71272.40", "0.005"], ["71272.90", "0.018"], ["71273.00", "0.045"], ["71273.30", "0.001"], ["71273.60", "0.083"], ["71274.10", "0.079"], ["71274.20", "0.215"], ["71276.80", "0.057"], ["71277.20", "0.323"], ["71277.30", "0.039"], ["71277.50", "0.425"], ["71277.60", "1.349"], ["71277.70", "0.113"], ["71277.80", "0.456"], ["71279.90", "0.009"], ["71280.00", "0.628"], ["71280.10", "0.003"], ["71280.80", "0.320"], ["71283.50", "0.008"], ["71284.90", "0.142"], ["71285.30", "0.005"], ["71286.10", "0.011"], ["71287.70", "0.002"], ["71287.80", "0.210"], ["71287.90", "1.226"]], "a": [["71288.00", "9.056"], ["71288.10", "0.002"], ["71288.40", "0.005"], ["71289.10", "0.001"], ["71289.40", "0.001"], ["71289.80", "0.006"], ["71289.90", "0.001"], ["71290.00", "1.003"], ["71290.10", "0.007"], ["71290.20", "0.002"], ["71290.50", "0.003"], ["71290.60", "0.077"], ["71290.70", "0.002"], ["71290.80", "0.005"], ["71290.90", "0.001"], ["71291.20", "0.005"], ["71291.30", "0.008"], ["71291.40", "0.176"], ["71291.50", "0.002"], ["71291.60", "0.066"], ["71291.90", "0.001"], ["71292.00", "0.001"], ["71292.30", "0.000"], ["71292.40", "0.111"], ["71292.50", "0.004"], ["71292.60", "0.244"], ["71292.80", "0.003"], ["71293.20", "0.009"], ["71293.30", "0.008"], ["71293.80", "0.012"], ["71294.30", "0.010"], ["71294.90", "0.146"], ["71295.00", "0.350"], ["71295.10", "0.004"], ["71295.70", "0.007"], ["71296.40", "0.002"], ["71297.90", "0.003"], ["71298.20", "0.148"], ["71298.30", "0.664"], ["71299.50", "0.137"], ["71301.70", "0.314"], ["71301.80", "0.103"], ["71302.00", "0.114"], ["71302.40", "0.039"], ["71303.30", "0.002"], ["71304.80", "0.004"], ["71305.00", "0.012"], ["71305.70", "0.052"], ["71305.80", "0.044"], ["71306.70", "1.087"], ["71306.80", "0.690"], ["71307.90", "0.000"], ["71309.80", "0.091"], ["71310.00", "0.275"], ["71310.70", "0.003"], ["71311.40", "0.075"], ["71312.10", "0.005"], ["71312.20", "0.000"], ["71312.30", "0.029"], ["71312.80", "0.003"], ["71313.00", "0.776"], ["71315.60", "0.504"], ["71315.70", "0.075"], ["71316.00", "0.048"], ["71316.50", "0.693"], ["71316.90", "0.001"], ["71317.40", "0.005"], ["71317.50", "0.004"], ["71317.60", "0.459"], ["71317.70", "0.085"], ["71317.80", "0.000"], ["71318.10", "0.984"], ["71318.30", "0.882"], ["71319.20", "0.094"], ["71319.40", "0.568"], ["71319.50", "1.410"], ["71322.40", "0.000"], ["71324.90", "0.002"], ["71325.50", "0.025"], ["71327.70", "0.064"], ["71328.40", "0.027"], ["71329.30", "0.010"], ["71329.60", "0.277"], ["71336.10", "0.203"], ["71337.60", "0.071"], ["71339.00", "0.003"], ["71339.70", "1.033"], ["71341.30", "0.853"], ["71341.70", "0.002"], ["71341.80", "0.168"], ["71342.00", "0.000"], ["71347.70", "0.271"], ["71348.60", "0.083"], ["71354.80", "0.272"], ["71356.10", "0.000"], ["71356.60", "0.133"], ["71358.00", "0.004"], ["71359.90", "0.337"], ["71365.90", "0.000"], ["71367.50", "0.824"], ["71370.00", "0.200"], ["71376.50", "0.000"], ["71389.50", "0.008"], ["71392.90", "0.924"], ["71393.70", "0.154"], ["71396.10", "0.000"], ["71396.40", "0.972"], ["71399.00", "0.008"], ["71404.60", "0.236"], ["71406.60", "0.000"], ["71407.60", "0.000"], ["71416.20", "0.000"], ["71420.00", "1.094"], ["71424.80", "0.000"], ["71428.40", "0.204"], ["71431.00", "0.089"], ["71453.10", "1.150"], ["71467.90", "0.603"], ["71480.90", "0.050"], ["71508.90", "0.002"], ["71528.50", "0.505"], ["71531.30", "0.253"], ["71556.00", "0.223"], ["71570.30", "0.348"], ["71579.90", "0.273"], ["71602.70", "0.000"], ["71647.40", "0.599"], ["71649.20", "2.086"], ["71728.20", "0.345"], ["71739.60", "0.904"], ["71792.00", "0.002"], ["71870.80", "0.413"], ["71966.20", "0.690"], ["71966.30", "1.376"], ["71986.60", "0.827"], ["72000.90", "0.045"], ["72030.70", "0.000"], ["72032.90", "5.702"], ["72037.70", "0.687"], ["72059.10", "0.004"], ["72065.00", "0.842"], ["72066.10", "4.285"], ["72137.60", "0.000"], ["72150.10", "0.000"], ["72182.40", "1.750"], ["72246.90", "4.262"], ["72250.40", "1.096"], ["72324.00", "0.275"], ["72325.00", "2.362"], ["72325.90", "2.737"], ["72377.00", "0.468"], ["72377.60", "0.000"], ["72386.90", "0.000"], ["72389.60", "9.170"], ["72397.20", "0.957"], ["72417.70", "9.159"], ["72428.60", "0.683"], ["72432.90", "0.957"], ["72461.00", "6.792"], ["72493.90", "1.862"], ["72503.30", "1.365"], ["72524.80", "2.114"], ["72539.80", "1.092"], ["72540.30", "1.092"], ["72596.20", "2.736"], ["72631.90", "15.260"], ["72891.60", "0.000"], ["73293.10", "1.226"], ["73381.90", "0.000"], ["78416.80", "0.002"]]}}
{"local_ts": 1773378025218, "server_ts": 1773378024927, "data": {"e": "depthUpdate", "E": 1773378024929, "T": 1773378024927, "s": "BTCUSDT", "U": 10100836451485, "u": 10100836462023, "pu": 10100836451406, "b": [["5000.00", "101.398"], ["20881.00", "0.288"], ["20981.00", "0.378"], ["20987.90", "0.864"], ["20990.00", "0.000"], ["20991.10", "0.000"], ["21081.00", "0.270"], ["21087.90", "0.000"], ["21090.00", "0.000"], ["21090.50", "0.000"], ["21187.90", "0.432"], ["21190.00", "0.000"], ["21190.50", "0.000"], ["21191.10", "0.000"], ["64152.90", "0.002"], ["67713.00", "0.000"], ["68419.60", "0.006"], ["68430.00", "0.642"], ["69855.40", "0.009"], ["70168.00", "0.186"], ["70500.00", "112.706"], ["70568.20", "0.003"], ["70768.10", "0.021"], ["70824.30", "0.000"], ["70996.30", "0.002"], ["71040.60", "0.002"], ["71044.20", "0.002"], ["71092.50", "3.771"], ["71109.10", "0.002"], ["71128.70", "0.000"], ["71152.50", "3.950"], ["71160.10", "0.063"], ["71162.00", "0.120"], ["71162.70", "0.000"], ["71164.40", "0.963"], ["71172.90", "0.413"], ["71173.00", "0.041"], ["71198.70", "0.456"], ["71208.00", "0.902"], ["71208.80", "0.049"], ["71209.50", "0.344"], ["71209.70", "0.241"], ["71210.50", "0.046"], ["71211.70", "0.026"], ["71212.00", "0.947"], ["71219.00", "0.050"], ["71220.60", "0.050"], ["71221.60", "1.407"], ["71222.50", "0.003"], ["71222.60", "0.152"], ["71222.70", "0.550"], ["71223.40", "0.002"], ["71226.20", "0.120"], ["71229.10", "0.000"], ["71232.50", "0.004"], ["71233.60", "1.126"], ["71235.90", "0.104"], ["71238.60", "0.077"], ["71242.80", "0.291"], ["71243.50", "0.003"], ["71244.20", "0.003"], ["71244.90", "0.049"], ["71246.30", "0.134"], ["71247.70", "0.045"], ["71251.60", "1.127"], ["71251.80", "0.083"], ["71252.00", "0.081"], ["71252.10", "0.002"], ["71252.30", "0.066"], ["71252.80", "0.039"], ["71255.80", "0.545"], ["71256.00", "0.002"], ["71256.10", "0.275"], ["71256.50", "0.010"], ["71258.90", "2.626"], ["71259.50", "0.152"], ["71265.20", "1.378"], ["71268.00", "0.012"], ["71270.20", "0.197"], ["71270.30", "0.260"], ["71273.20", "0.019"], ["71273.90", "0.001"], ["71277.30", "0.154"], ["71281.00", "0.738"]], "a": [["71281.10", "12.315"], ["71281.30", "0.000"], ["71282.00", "0.002"], ["71283.20", "1.053"], ["71283.30", "0.010"], ["71283.50", "0.220"], ["71288.00", "0.100"], ["71288.20", "0.000"], ["71290.40", "0.044"], ["71290.50", "0.140"], ["71290.60", "0.127"], ["71292.00", "0.003"], ["71293.40", "0.009"], ["71296.20", "0.011"], ["71301.10", "0.195"], ["71303.20", "0.000"], ["71304.70", "0.631"], ["71304.80", "0.074"], ["71308.40", "0.298"], ["71318.40", "1.074"], ["71320.70", "0.013"], ["71323.60", "0.037"], ["71324.00", "1.184"], ["71324.20", "0.018"], ["71326.90", "0.864"], ["71330.40", "0.005"], ["71331.10", "0.103"], ["71331.80", "0.003"], ["71332.50", "0.008"], ["71336.70", "0.004"], ["71338.10", "7.787"], ["71338.20", "0.126"], ["71339.70", "3.106"], ["71353.80", "0.028"], ["71353.90", "0.276"], ["71362.80", "0.092"], ["71402.40", "0.602"], ["71432.80", "0.000"], ["71460.20", "0.268"], ["71499.90", "0.164"], ["71502.70", "15.197"], ["71993.90", "0.000"], ["71997.50", "1.244"], ["71998.10", "0.240"], ["72097.10", "2.231"], ["72097.50", "0.000"], ["72112.40", "0.686"], ["72172.10", "0.412"], ["72180.40", "0.000"], ["72222.40", "2.088"], ["72257.00", "1.781"], ["72282.60", "4.661"], ["72314.70", "1.512"], ["72317.80", "11.632"], ["72374.10", "3.710"], ["72389.10", "4.785"], ["72389.60", "6.428"], ["72399.70", "1.668"], ["72417.60", "3.895"], ["72461.00", "2.012"], ["72928.80", "0.613"], ["72998.00", "0.109"], ["73285.20", "1.189"], ["73386.00", "0.097"], ["74877.20", "0.006"], ["78409.20", "0.002"]]}}
{"local_ts": 1773378026226, "server_ts": 1773378025950, "data": {"e": "depthUpdate", "E": 1773378025951, "T": 1773378025950, "s": "BTCUSDT", "U": 10100836569377, "u": 10100836585896, "pu": 10100836569360, "b": [["1000.00", "26.142"], ["5000.00", "101.418"], ["20781.00", "0.135"], ["20881.00", "1.557"], ["20981.00", "0.243"], ["21081.00", "0.765"], ["33000.00", "9.339"], ["56445.30", "0.000"], ["57025.00", "0.002"], ["61398.00", "0.000"], ["64152.90", "0.000"], ["69124.00", "0.692"], ["70261.40", "0.711"], ["70568.20", "0.003"], ["70614.50", "0.000"], ["70924.60", "0.000"], ["70991.60", "0.008"], ["71177.10", "0.000"], ["71198.70", "0.416"], ["71202.70", "0.054"], ["71206.40", "0.125"], ["71215.30", "0.005"], ["71224.90", "0.002"], ["71225.00", "0.107"], ["71226.70", "0.089"], ["71233.90", "0.058"], ["71235.30", "0.004"], ["71235.40", "0.257"], ["71235.50", "1.529"], ["71236.80", "0.011"], ["71236.90", "0.009"], ["71237.50", "0.004"], ["71237.60", "0.091"], ["71256.10", "0.275"], ["71256.50", "0.010"], ["71258.50", "0.008"], ["71259.40", "0.004"], ["71263.60", "0.002"], ["71265.70", "1.222"], ["71269.20", "0.748"], ["71269.40", "0.243"], ["71269.90", "0.051"], ["71273.80", "0.205"], ["71273.90", "0.150"], ["71274.40", "0.493"], ["71275.50", "0.003"], ["71275.70", "0.380"], ["71277.30", "0.240"]], "a": [["71281.10", "1.065"], ["71288.10", "0.007"], ["71288.20", "0.477"], ["71293.40", "0.006"], ["71298.40", "0.064"], ["71298.50", "0.002"], ["71299.70", "0.000"], ["71300.70", "0.006"], ["71300.80", "0.008"], ["71301.00", "0.007"], ["71301.50", "0.017"], ["71302.20", "1.192"], ["71302.40", "0.005"], ["71303.20", "0.000"], ["71304.20", "0.028"], ["71306.00", "0.658"], ["71306.40", "1.676"], ["71310.80", "0.077"], ["71313.20", "0.910"], ["71315.40", "0.002"], ["71316.60", "0.000"], ["71318.20", "1.347"], ["71318.60", "0.000"], ["71318.70", "0.001"], ["71319.20", "0.002"], ["71319.70", "0.853"], ["71320.00", "0.000"], ["71320.20", "0.000"], ["71322.90", "0.008"], ["71323.70", "1.009"], ["71323.80", "0.278"], ["71326.20", "0.108"], ["71326.70", "0.019"], ["71327.20", "0.010"], ["71327.70", "0.072"], ["71329.60", "0.289"], ["71330.80", "0.022"], ["71331.80", "0.003"], ["71332.80", "0.688"], ["71334.70", "0.020"], ["71335.70", "0.002"], ["71336.30", "0.200"], ["71336.70", "0.004"], ["71337.90", "1.541"], ["71339.20", "0.017"], ["71339.60", "0.122"], ["71339.70", "0.235"], ["71339.80", "0.003"], ["71340.20", "0.000"], ["71340.60", "0.487"], ["71341.60", "0.016"], ["71342.60", "0.001"], ["71343.50", "0.000"], ["71344.50", "0.016"], ["71344.70", "0.003"], ["71345.50", "0.000"], ["71346.40", "0.000"], ["71348.10", "0.061"], ["71349.10", "0.007"], ["71350.10", "0.271"], ["71351.10", "0.000"], ["71352.10", "0.892"], ["71353.10", "0.000"], ["71354.10", "0.004"], ["71355.00", "0.005"], ["71356.00", "0.180"], ["71357.00", "0.994"], ["71357.90", "0.321"], ["71358.80", "0.001"], ["71358.90", "0.000"], ["71359.90", "0.342"], ["71360.90", "0.161"], ["71361.80", "0.045"], ["71362.10", "0.088"], ["71362.80", "0.134"], ["71363.80", "0.716"], ["71364.70", "0.173"], ["71365.70", "0.044"], ["71366.70", "0.191"], ["71367.60", "1.485"], ["71386.70", "0.000"], ["71406.60", "0.000"], ["71449.40", "0.007"], ["71539.90", "0.002"], ["71548.20", "0.192"], ["71556.60", "0.000"], ["71993.90", "0.000"], ["72136.50", "6.176"], ["72214.60", "3.977"], ["72288.30", "1.447"], ["72599.80", "2.181"], ["72680.70", "0.002"], ["72920.60", "1.086"], ["72996.20", "0.000"], ["74851.10", "0.000"], ["78409.20", "0.002"]]}}
{"local_ts": 1773378027246, "server_ts": 1773378026970, "data": {"e": "depthUpdate", "E": 1773378026971, "T": 1773378026970, "s": "BTCUSDT", "U": 10100836794023, "u": 10100836801897, "pu": 10100836794003, "b": [["1000.00", "26.142"], ["5000.00", "101.418"], ["20777.10", "0.684"], ["20881.00", "0.243"], ["20977.10", "0.342"], ["21081.00", "0.000"], ["56445.30", "0.002"], ["64149.40", "0.000"], ["67691.60", "0.004"], ["67713.00", "0.000"], ["70290.70", "0.283"], ["70468.30", "0.000"], ["70564.30", "0.000"], ["70927.90", "32.821"], ["70930.80", "6.056"], ["70932.20", "1.736"], ["70991.00", "0.100"], ["70995.00", "0.000"], ["71084.10", "14.730"], ["71139.40", "0.003"], ["71141.40", "0.000"], ["71142.10", "0.090"], ["71170.60", "0.050"], ["71201.60", "5.490"], ["71203.00", "1.108"], ["71206.20", "0.002"], ["71218.70", "1.388"], ["71224.30", "0.032"], ["71226.40", "1.140"], ["71227.10", "0.003"], ["71227.80", "1.666"], ["71228.50", "0.112"], ["71230.50", "0.236"], ["71230.60", "0.005"], ["71231.70", "0.249"], ["71232.00", "2.183"], ["71232.10", "0.909"], ["71232.40", "0.206"], ["71234.40", "0.046"], ["71241.50", "0.074"], ["71243.00", "0.004"], ["71244.00", "1.011"], ["71245.10", "0.051"], ["71254.10", "0.329"], ["71254.20", "0.113"], ["71255.80", "0.064"], ["71259.40", "1.192"], ["71260.00", "0.412"], ["71261.70", "0.273"], ["71264.00", "0.678"], ["71264.80", "1.571"], ["71265.70", "0.523"], ["71267.60", "1.350"], ["71269.50", "0.002"], ["71269.90", "0.002"], ["71270.10", "0.010"], ["71271.00", "0.000"], ["71271.20", "1.406"], ["71271.30", "0.522"], ["71272.80", "0.000"], ["71274.80", "0.148"], ["71275.00", "0.010"], ["71277.10", "4.558"]], "a": [["71277.20", "1.231"], ["71277.90", "0.004"], ["71280.90", "0.000"], ["71281.60", "0.004"], ["71281.90", "0.000"], ["71284.00", "0.000"], ["71284.10", "0.378"], ["71284.20", "0.005"], ["71284.30", "0.419"], ["71284.60", "0.104"], ["71284.70", "0.034"], ["71285.20", "1.002"], ["71286.10", "0.006"], ["71286.30", "0.000"], ["71286.40", "0.003"], ["71287.50", "0.751"], ["71289.10", "0.055"], ["71289.40", "0.006"], ["71291.50", "0.382"], ["71292.00", "0.839"], ["71292.20", "0.925"], ["71292.60", "0.208"], ["71292.90", "0.005"], ["71293.90", "0.007"], ["71296.10", "0.105"], ["71296.30", "0.055"], ["71296.40", "0.045"], ["71296.60", "0.051"], ["71297.10", "1.731"], ["71298.60", "0.003"], ["71299.40", "0.075"], ["71300.10", "0.019"], ["71302.10", "0.409"], ["71302.80", "0.220"], ["71304.60", "0.042"], ["71306.10", "0.072"], ["71306.40", "0.002"], ["71306.60", "0.008"], ["71308.10", "0.008"], ["71308.40", "0.074"], ["71308.60", "0.277"], ["71310.90", "0.077"], ["71312.50", "0.861"], ["71312.70", "0.073"], ["71312.80", "0.654"], ["71323.10", "0.000"], ["71326.80", "0.000"], ["71329.50", "0.002"], ["71329.70", "0.295"], ["71330.40", "0.073"], ["71337.80", "0.441"], ["71343.80", "0.004"], ["71343.90", "0.128"], ["71392.50", "0.002"], ["71393.60", "0.118"], ["71395.00", "0.537"], ["71421.60", "0.032"], ["71422.70", "0.091"], ["71423.40", "0.064"], ["71455.10", "0.181"], ["71458.10", "6.426"], ["71528.50", "1.113"], ["71529.40", "2.563"], ["71529.50", "0.004"], ["71530.80", "0.000"], ["71535.50", "0.000"], ["71640.20", "5.467"], ["71640.80", "33.765"], ["71990.00", "1.532"], ["71993.90", "0.012"], ["72169.70", "0.692"], ["72356.60", "0.061"], ["74128.20", "0.004"], ["74843.90", "0.002"], ["78404.90", "0.010"]]}}
{"local_ts": 1773378028269, "server_ts": 1773378027992, "data": {"e": "depthUpdate", "E": 1773378027993, "T": 1773378027992, "s": "BTCUSDT", "U": 10100836857826, "u": 10100836862787, "pu": 10100836857750, "b": [["5000.00", "101.398"], ["20777.10", "0.513"], ["20877.10", "0.765"], ["20977.10", "0.135"], ["21177.10", "1.287"], ["33000.00", "9.339"], ["56445.30", "0.000"], ["64149.40", "0.000"], ["67692.10", "0.000"], ["70444.90", "0.000"], ["70564.30", "0.000"], ["70706.90", "0.000"], ["70920.70", "0.000"], ["71084.10", "0.000"], ["71148.10", "0.030"], ["71156.00", "0.055"], ["71160.90", "0.012"], ["71196.50", "0.003"], ["71200.60", "0.042"], ["71230.80", "0.081"], ["71232.10", "0.406"], ["71232.20", "0.027"], ["71246.00", "0.008"], ["71251.80", "1.883"], ["71253.20", "0.007"], ["71253.70", "0.138"], ["71254.20", "0.006"], ["71254.60", "0.015"], ["71255.70", "0.414"], ["71262.80", "0.409"], ["71267.90", "0.013"], ["71270.00", "0.302"], ["71272.90", "0.003"], ["71277.10", "2.712"]], "a": [["71277.20", "3.055"], ["71279.40", "0.033"], ["71280.80", "0.004"], ["71283.60", "0.394"], ["71284.20", "0.003"], ["71284.30", "0.313"], ["71284.70", "0.034"], ["71286.30", "0.000"], ["71286.40", "0.011"], ["71287.40", "0.000"], ["71290.60", "0.200"], ["71290.70", "0.001"], ["71293.00", "0.006"], ["71298.00", "1.355"], ["71302.50", "0.002"], ["71303.00", "0.004"], ["71303.30", "0.072"], ["71303.70", "0.007"], ["71307.40", "0.000"], ["71308.00", "0.457"], ["71342.10", "0.007"], ["71351.90", "0.740"], ["71353.00", "0.030"], ["71353.10", "0.000"], ["71371.90", "0.011"], ["71379.40", "0.003"], ["71415.10", "0.016"], ["71528.50", "0.660"], ["71529.30", "0.003"], ["71530.40", "0.010"], ["71594.10", "0.131"], ["71596.00", "0.577"], ["71599.60", "0.000"], ["71989.90", "0.006"], ["71990.00", "1.532"], ["72032.80", "0.000"], ["72346.40", "0.905"], ["72453.40", "0.000"], ["73662.60", "0.002"], ["74841.50", "0.052"], ["78404.90", "0.012"]]}}
{"local_ts": 1773378029289, "server_ts": 1773378029009, "data": {"e": "depthUpdate", "E": 1773378029013, "T": 1773378029009, "s": "BTCUSDT", "U": 10100836926574, "u": 10100836931748, "pu": 10100836926565, "b": [["1000.00", "26.142"], ["5000.00", "101.418"], ["20777.10", "0.630"], ["20877.10", "0.270"], ["21077.10", "1.017"], ["21177.10", "0.783"], ["56445.30", "0.002"], ["64149.40", "0.008"], ["69813.60", "0.003"], ["69862.20", "0.006"], ["69944.20", "0.285"], ["70541.50", "0.033"], ["70564.30", "0.000"], ["70980.70", "2.114"], ["71078.50", "0.000"], ["71110.90", "0.004"], ["71151.40", "0.000"], ["71197.60", "0.023"], ["71206.10", "0.040"], ["71207.00", "0.871"], ["71214.10", "0.043"], ["71228.00", "0.420"], ["71230.70", "0.013"], ["71230.90", "0.123"], ["71232.40", "0.128"], ["71239.40", "0.006"], ["71240.70", "0.005"], ["71251.40", "0.228"], ["71251.80", "0.748"], ["71252.20", "0.387"], ["71254.60", "0.029"], ["71259.50", "0.145"], ["71261.30", "0.004"], ["71263.50", "0.144"], ["71265.40", "0.000"], ["71265.90", "0.234"], ["71266.40", "0.219"], ["71266.70", "0.146"], ["71270.10", "0.010"], ["71270.90", "0.006"], ["71272.30", "0.006"]], "a": [["71277.20", "0.868"], ["71278.60", "0.089"], ["71280.00", "0.003"], ["71280.50", "0.002"], ["71280.70", "0.001"], ["71281.50", "0.002"], ["71283.60", "0.167"], ["71284.40", "0.004"], ["71284.70", "0.034"], ["71285.10", "0.004"], ["71285.20", "0.000"], ["71285.90", "0.000"], ["71286.80", "0.057"], ["71287.00", "0.436"], ["71287.30", "0.007"], ["71288.30", "0.445"], ["71289.90", "0.000"], ["71290.00", "1.005"], ["71291.30", "0.136"], ["71291.40", "0.815"], ["71294.50", "0.181"], ["71296.90", "0.738"], ["71297.90", "0.125"], ["71298.70", "0.052"], ["71300.40", "0.008"], ["71303.40", "0.015"], ["71303.90", "0.009"], ["71304.50", "0.001"], ["71304.90", "0.025"], ["71305.60", "0.003"], ["71306.10", "0.007"], ["71309.30", "0.198"], ["71311.00", "0.245"], ["71312.80", "0.731"], ["71313.40", "0.185"], ["71326.70", "0.011"], ["71342.80", "0.019"], ["71368.00", "0.073"], ["71369.90", "0.268"], ["71401.90", "0.449"], ["71446.90", "0.017"], ["71447.60", "0.000"], ["71502.70", "0.107"], ["71528.50", "0.869"], ["71529.90", "2.662"], ["71588.40", "0.000"], ["71592.10", "0.000"], ["71990.00", "1.532"], ["72377.10", "0.000"], ["72702.70", "0.006"], ["74852.70", "0.000"], ["78404.90", "0.024"], ["89523.20", "0.000"]]}}
{"local_ts": 1773378030314, "server_ts": 1773378030034, "data": {"e": "depthUpdate", "E": 1773378030035, "T": 1773378030034, "s": "BTCUSDT", "U": 10100837018233, "u": 10100837030292, "pu": 10100837018156, "b": [["5000.00", "101.418"], ["20777.10", "0.405"], ["20990.90", "0.666"], ["20994.30", "0.090"], ["21077.10", "0.936"], ["21086.40", "0.063"], ["21090.90", "0.000"], ["21190.90", "0.459"], ["21194.30", "0.036"], ["33000.00", "9.343"], ["40000.00", "49.408"], ["56445.30", "0.000"], ["64161.80", "0.000"], ["69855.40", "0.009"], ["70294.30", "0.073"], ["70578.00", "0.000"], ["70581.40", "0.002"], ["70734.60", "0.251"], ["70736.20", "0.286"], ["70889.90", "0.432"], ["70952.40", "0.220"], ["70976.00", "0.000"], ["70977.50", "0.160"], ["70982.10", "0.000"], ["71014.70", "1.149"], ["71016.40", "5.727"], ["71018.80", "1.577"], ["71021.50", "1.545"], ["71022.50", "0.000"], ["71051.70", "0.546"], ["71119.50", "0.002"], ["71137.50", "0.099"], ["71137.60", "0.094"], ["71141.00", "0.228"], ["71141.20", "0.090"], ["71144.80", "0.000"], ["71154.00", "0.004"], ["71158.80", "0.075"], ["71160.90", "0.009"], ["71169.80", "0.010"], ["71172.40", "0.002"], ["71180.40", "0.042"], ["71182.10", "0.004"], ["71186.60", "1.193"], ["71189.60", "0.188"], ["71191.40", "0.001"], ["71196.50", "0.000"], ["71200.80", "0.022"], ["71202.60", "0.214"], ["71203.00", "1.461"], ["71204.80", "0.001"], ["71205.80", "0.000"], ["71206.20", "0.000"], ["71207.00", "0.578"], ["71207.50", "0.025"], ["71211.10", "0.000"], ["71213.00", "0.063"], ["71214.10", "0.083"], ["71215.30", "0.005"], ["71216.60", "0.004"], ["71217.40", "0.004"], ["71217.90", "0.114"], ["71218.80", "0.059"], ["71220.10", "0.077"], ["71220.20", "0.049"], ["71221.70", "0.066"], ["71222.30", "0.000"], ["71223.00", "1.090"], ["71224.50", "0.047"], ["71225.20", "0.006"], ["71225.30", "0.019"], ["71227.40", "0.083"], ["71230.00", "1.004"], ["71231.30", "0.020"], ["71232.20", "0.002"], ["71233.50", "0.008"], ["71234.00", "0.100"], ["71234.30", "0.004"], ["71237.50", "1.150"], ["71237.80", "0.000"], ["71239.40", "0.004"], ["71240.80", "0.913"], ["71241.30", "0.006"], ["71241.40", "0.027"], ["71241.50", "0.076"], ["71242.40", "0.000"], ["71242.50", "0.676"], ["71245.80", "0.001"], ["71246.00", "0.686"], ["71247.30", "0.273"], ["71247.40", "0.084"], ["71248.00", "0.859"], ["71248.10", "0.000"], ["71248.70", "0.378"], ["71248.80", "0.006"], ["71249.40", "0.273"], ["71249.50", "1.206"], ["71250.40", "1.420"], ["71250.60", "0.207"], ["71251.50", "0.451"], ["71251.70", "2.169"], ["71251.80", "0.466"], ["71252.20", "0.205"], ["71253.00", "0.680"], ["71253.40", "0.077"], ["71253.70", "0.002"], ["71254.30", "0.055"], ["71255.00", "0.150"], ["71255.10", "1.085"], ["71255.30", "0.852"], ["71255.90", "0.002"], ["71256.40", "0.000"], ["71256.50", "0.010"], ["71256.60", "0.007"], ["71257.10", "0.000"], ["71257.20", "0.002"], ["71257.80", "0.089"], ["71257.90", "0.004"], ["71258.50", "0.055"], ["71258.60", "0.010"], ["71258.70", "0.009"], ["71258.80", "0.925"], ["71258.90", "0.012"], ["71259.20", "0.202"], ["71259.30", "0.016"], ["71260.00", "0.925"], ["71260.10", "0.001"], ["71260.20", "0.005"], ["71260.90", "0.003"], ["71261.00", "0.006"], ["71261.60", "0.515"], ["71261.90", "0.002"], ["71262.20", "0.014"], ["71262.30", "0.228"], ["71263.80", "0.018"], ["71264.20", "0.076"], ["71264.70", "0.060"], ["71265.70", "0.949"], ["71266.10", "0.284"], ["71266.20", "0.314"], ["71266.40", "0.003"], ["71267.00", "0.689"], ["71267.40", "0.009"], ["71267.50", "0.002"], ["71267.60", "0.003"], ["71267.80", "0.000"], ["71268.00", "0.009"], ["71268.50", "0.000"], ["71269.10", "1.008"], ["71270.40", "0.148"], ["71270.90", "0.023"], ["71271.20", "1.408"], ["71271.30", "0.114"], ["71271.70", "0.463"], ["71272.30", "0.000"], ["71272.50", "0.275"], ["71272.60", "1.229"], ["71272.90", "0.005"], ["71273.40", "0.074"], ["71273.50", "0.006"], ["71273.60", "0.232"], ["71273.70", "0.680"], ["71274.70", "0.345"], ["71274.80", "0.007"], ["71274.90", "0.047"], ["71275.50", "0.045"], ["71275.70", "0.544"], ["71275.90", "0.001"], ["71277.20", "1.403"], ["71277.30", "2.724"], ["71277.50", "0.451"], ["71277.80", "0.240"], ["71277.90", "0.004"], ["71278.40", "0.225"], ["71278.50", "0.002"], ["71278.60", "0.002"], ["71279.30", "0.000"], ["71279.50", "0.702"], ["71279.70", "0.275"], ["71280.00", "0.010"], ["71280.20", "0.162"], ["71280.30", "0.005"], ["71280.40", "0.003"], ["71280.50", "0.002"], ["71280.60", "0.000"], ["71280.80", "0.003"], ["71280.90", "1.070"], ["71281.00", "0.007"], ["71281.20", "0.003"], ["71281.40", "0.003"], ["71281.50", "0.004"], ["71282.00", "0.038"], ["71282.10", "0.005"], ["71282.60", "0.002"], ["71282.70", "0.370"], ["71282.80", "0.001"], ["71283.00", "0.002"], ["71283.30", "0.722"], ["71283.80", "0.002"], ["71283.90", "0.004"], ["71284.00", "0.007"], ["71284.90", "0.128"], ["71285.00", "0.008"], ["71285.30", "0.124"], ["71285.40", "1.104"], ["71285.50", "0.000"], ["71285.70", "0.003"], ["71285.80", "0.001"], ["71285.90", "0.002"], ["71286.00", "0.002"], ["71286.20", "0.808"], ["71286.30", "1.060"], ["71286.40", "2.219"], ["71286.50", "1.106"], ["71286.60", "1.544"], ["71286.70", "0.001"], ["71287.10", "0.005"], ["71287.20", "0.146"], ["71287.30", "0.083"], ["71287.40", "0.013"], ["71288.00", "0.002"], ["71288.30", "0.003"], ["71288.80", "0.003"], ["71288.90", "0.029"], ["71289.10", "0.005"], ["71290.00", "0.004"], ["71290.10", "0.001"], ["71290.30", "0.002"], ["71290.40", "0.639"], ["71290.50", "0.005"], ["71290.80", "0.001"], ["71290.90", "0.046"], ["71291.00", "0.002"], ["71291.20", "0.003"], ["71291.30", "0.070"], ["71291.50", "0.001"], ["71291.70", "0.002"], ["71291.80", "0.000"], ["71291.90", "0.003"], ["71292.00", "0.000"], ["71292.10", "0.000"], ["71292.20", "0.001"], ["71292.30", "0.000"], ["71292.40", "0.143"], ["71292.50", "0.000"], ["71292.60", "0.057"], ["71292.80", "0.004"], ["71292.90", "0.001"], ["71293.10", "0.000"], ["71293.70", "0.000"], ["71293.90", "0.002"], ["71294.00", "0.000"], ["71294.10", "0.000"], ["71294.20", "0.009"], ["71294.30", "6.631"]], "a": [["71291.00", "0.000"], ["71291.10", "0.000"], ["71291.30", "0.000"], ["71291.40", "0.000"], ["71291.80", "0.000"], ["71291.90", "0.000"], ["71292.00", "0.000"], ["71292.10", "0.000"], ["71292.20", "0.000"], ["71292.30", "0.000"], ["71292.40", "0.000"], ["71292.50", "0.000"], ["71292.60", "0.000"], ["71292.70", "0.000"], ["71292.90", "0.000"], ["71293.00", "0.000"], ["71293.10", "0.000"], ["71293.20", "0.000"], ["71293.30", "0.000"], ["71293.40", "0.000"], ["71293.50", "0.000"], ["71293.80", "0.000"], ["71294.00", "0.000"], ["71294.10", "0.000"], ["71294.30", "0.000"], ["71294.40", "2.542"], ["71294.50", "0.002"], ["71294.60", "0.002"], ["71294.70", "0.002"], ["71294.80", "0.008"], ["71294.90", "0.001"], ["71295.00", "0.007"], ["71295.10", "0.002"], ["71295.30", "0.001"], ["71295.40", "0.005"], ["71295.50", "0.059"], ["71295.90", "0.001"], ["71296.00", "0.004"], ["71296.20", "0.000"], ["71296.30", "0.000"], ["71296.40", "0.002"], ["71296.60", "0.001"], ["71296.70", "0.030"], ["71296.90", "0.062"], ["71297.00", "0.002"], ["71297.10", "0.001"], ["71297.60", "0.038"], ["71297.80", "0.043"], ["71297.90", "0.077"], ["71298.00", "0.431"], ["71298.10", "0.428"], ["71298.20", "0.007"], ["71298.50", "0.073"], ["71298.60", "0.003"], ["71298.90", "0.000"], ["71299.00", "0.000"], ["71299.50", "0.001"], ["71299.60", "0.047"], ["71299.70", "0.101"], ["71299.80", "1.003"], ["71300.20", "0.060"], ["71300.30", "0.132"], ["71300.50", "0.004"], ["71300.80", "0.008"], ["71301.20", "0.567"], ["71301.30", "0.002"], ["71301.90", "0.740"], ["71302.00", "0.009"], ["71302.10", "0.003"], ["71302.40", "0.056"], ["71302.90", "0.006"], ["71303.00", "0.176"], ["71303.20", "0.002"], ["71303.30", "0.000"], ["71303.70", "0.080"], ["71304.10", "0.149"], ["71304.20", "0.008"], ["71304.30", "0.004"], ["71304.40", "0.000"], ["71304.50", "0.237"], ["71305.00", "0.011"], ["71305.10", "0.058"], ["71305.20", "0.000"], ["71305.30", "0.038"], ["71305.40", "0.455"], ["71305.50", "0.074"], ["71305.60", "0.003"], ["71305.80", "0.147"], ["71306.00", "0.004"], ["71306.10", "0.276"], ["71306.20", "0.007"], ["71306.30", "0.245"], ["71306.40", "0.167"], ["71306.50", "0.006"], ["71306.70", "0.037"], ["71306.80", "0.131"], ["71307.00", "0.003"], ["71307.20", "0.004"], ["71307.30", "0.024"], ["71307.40", "0.674"], ["71307.50", "0.080"], ["71307.80", "0.121"], ["71307.90", "0.280"], ["71308.00", "0.456"], ["71308.30", "0.000"], ["71308.40", "0.009"], ["71308.50", "0.008"], ["71308.70", "0.000"], ["71308.80", "0.566"], ["71308.90", "0.013"], ["71309.00", "0.683"], ["71309.10", "0.000"], ["71309.20", "0.006"], ["71309.40", "0.009"], ["71309.50", "0.003"], ["71309.70", "1.198"], ["71309.80", "0.302"], ["71310.00", "0.004"], ["71310.10", "0.027"], ["71310.30", "0.000"], ["71310.40", "0.002"], ["71310.50", "0.008"], ["71310.80", "0.688"], ["71310.90", "0.011"], ["71311.30", "0.002"], ["71311.60", "0.004"], ["71311.80", "0.000"], ["71312.10", "0.111"], ["71312.20", "0.179"], ["71312.30", "0.212"], ["71312.40", "0.284"], ["71312.90", "0.021"], ["71313.10", "0.000"], ["71313.20", "0.001"], ["71313.30", "0.188"], ["71313.60", "0.684"], ["71314.70", "0.003"], ["71315.00", "0.002"], ["71315.20", "0.002"], ["71315.50", "0.019"], ["71315.60", "0.888"], ["71316.00", "0.687"], ["71316.10", "0.336"], ["71316.70", "0.000"], ["71318.30", "0.000"], ["71318.70", "0.029"], ["71319.40", "0.009"], ["71319.50", "2.001"], ["71319.60", "0.573"], ["71320.00", "0.074"], ["71320.50", "0.005"], ["71320.60", "0.000"], ["71320.80", "0.271"], ["71321.50", "0.000"], ["71321.60", "0.277"], ["71321.70", "0.271"], ["71322.10", "0.004"], ["71322.30", "0.548"], ["71322.40", "0.268"], ["71322.60", "0.207"], ["71322.90", "0.136"], ["71323.00", "0.973"], ["71323.10", "0.674"], ["71323.20", "0.004"], ["71323.60", "0.037"], ["71323.70", "0.861"], ["71323.80", "0.292"], ["71323.90", "0.070"], ["71324.10", "0.024"], ["71324.20", "0.018"], ["71324.40", "0.299"], ["71324.50", "0.002"], ["71324.70", "0.000"], ["71324.80", "0.070"], ["71325.00", "0.005"], ["71325.90", "0.000"], ["71326.60", "0.000"], ["71326.70", "0.062"], ["71326.80", "0.005"], ["71327.40", "0.000"], ["71327.90", "0.322"], ["71328.10", "1.761"], ["71328.20", "0.038"], ["71328.30", "0.035"], ["71329.00", "0.000"], ["71329.50", "0.002"], ["71330.00", "0.689"], ["71330.20", "0.784"], ["71330.30", "0.011"], ["71330.50", "1.587"], ["71331.90", "2.485"], ["71332.70", "0.074"], ["71332.80", "0.688"], ["71333.00", "0.285"], ["71333.30", "0.016"], ["71333.80", "0.000"], ["71334.00", "1.028"], ["71334.30", "0.007"], ["71335.00", "0.002"], ["71336.00", "0.002"], ["71336.20", "0.879"], ["71337.00", "0.682"], ["71337.20", "0.854"], ["71337.60", "0.071"], ["71339.90", "1.223"], ["71340.90", "0.003"], ["71341.30", "0.893"], ["71341.60", "0.018"], ["71341.90", "0.003"], ["71342.30", "0.679"], ["71342.60", "0.001"], ["71343.00", "0.004"], ["71346.50", "0.555"], ["71348.50", "0.995"], ["71348.90", "0.002"], ["71349.80", "0.272"], ["71349.90", "0.115"], ["71351.70", "0.807"], ["71352.80", "0.016"], ["71352.90", "0.048"], ["71354.50", "0.090"], ["71354.90", "0.064"], ["71355.60", "1.582"], ["71356.40", "0.064"], ["71358.00", "0.008"], ["71359.20", "0.087"], ["71359.50", "1.447"], ["71359.60", "0.493"], ["71360.30", "0.018"], ["71361.10", "0.275"], ["71361.20", "0.327"], ["71363.10", "0.534"], ["71363.70", "0.092"], ["71364.30", "0.104"], ["71365.10", "0.184"], ["71365.40", "0.449"], ["71365.50", "0.009"], ["71365.70", "1.002"], ["71367.50", "0.543"], ["71368.50", "0.093"], ["71368.70", "0.067"], ["71368.90", "0.147"], ["71369.30", "0.198"], ["71369.40", "0.201"], ["71369.80", "0.000"], ["71370.80", "10.017"], ["71372.40", "0.007"], ["71373.70", "2.994"], ["71375.00", "0.305"], ["71378.50", "0.112"], ["71379.40", "0.000"], ["71381.30", "0.689"], ["71384.90", "0.003"], ["71387.90", "0.032"], ["71397.70", "0.184"], ["71399.00", "0.000"], ["71400.20", "0.272"], ["71404.40", "0.007"], ["71408.10", "0.241"], ["71414.10", "0.095"], ["71415.10", "0.269"], ["71416.50", "0.000"], ["71419.20", "0.140"], ["71426.40", "9.325"], ["71428.20", "0.187"], ["71479.80", "0.040"], ["71500.90", "0.063"], ["71504.40", "0.005"], ["71520.40", "0.017"], ["71533.20", "0.235"], ["71534.40", "2.316"], ["71537.80", "0.236"], ["71541.40", "0.251"], ["71553.90", "4.257"], ["71554.20", "0.001"], ["71556.40", "19.810"], ["71594.10", "0.197"], ["71595.50", "0.547"], ["71605.50", "0.005"], ["71640.20", "4.042"], ["71640.60", "24.217"], ["71667.90", "0.017"], ["71671.40", "0.009"], ["71692.80", "0.002"], ["71753.60", "28.504"], ["71990.00", "1.565"], ["72003.90", "0.002"], ["72007.30", "0.000"], ["72720.20", "0.006"], ["74871.80", "0.002"], ["78420.10", "0.000"], ["78423.80", "0.002"], ["89523.20", "0.000"]]}}
{"local_ts": 1773378031338, "server_ts": 1773378031058, "data": {"e": "depthUpdate", "E": 1773378031059, "T": 1773378031058, "s": "BTCUSDT", "U": 10100837094745, "u": 10100837115111, "pu": 10100837094699, "b": [["1000.00", "26.142"], ["5000.00", "101.398"], ["20894.30", "0.486"], ["20994.30", "0.648"], ["21094.30", "0.360"], ["21194.30", "0.081"], ["50000.00", "162.125"], ["50001.00", "7.918"], ["50002.00", "0.137"], ["56445.30", "0.002"], ["67699.70", "0.002"], ["67722.00", "0.051"], ["69199.50", "0.081"], ["69757.70", "0.030"], ["70286.30", "2.134"], ["70581.40", "0.008"], ["70581.50", "0.717"], ["70936.10", "0.172"], ["70937.80", "5.317"], ["70985.70", "0.000"], ["70989.40", "0.000"], ["70992.00", "0.132"], ["71003.80", "0.000"], ["71024.30", "5.194"], ["71137.50", "0.000"], ["71154.70", "2.129"], ["71158.80", "0.036"], ["71160.70", "0.264"], ["71166.90", "0.000"], ["71170.60", "0.000"], ["71171.50", "0.009"], ["71173.30", "0.160"], ["71173.70", "0.004"], ["71178.20", "0.676"], ["71184.90", "0.255"], ["71189.20", "0.000"], ["71195.20", "0.678"], ["71202.00", "0.681"], ["71205.20", "0.333"], ["71208.40", "0.000"], ["71208.80", "0.704"], ["71222.70", "0.639"], ["71223.70", "0.031"], ["71231.30", "0.016"], ["71233.50", "0.005"], ["71239.10", "0.145"], ["71240.70", "0.000"], ["71243.00", "0.090"], ["71244.90", "0.280"], ["71245.30", "0.030"], ["71245.60", "0.028"], ["71245.80", "0.001"], ["71246.00", "0.010"], ["71249.10", "0.009"], ["71250.80", "0.013"], ["71250.90", "0.276"], ["71251.50", "0.394"], ["71251.60", "1.030"], ["71251.70", "2.010"], ["71252.20", "0.207"], ["71252.30", "0.002"], ["71252.80", "0.000"], ["71253.00", "0.002"], ["71253.20", "0.027"], ["71253.30", "0.002"], ["71255.00", "0.003"], ["71255.10", "0.812"], ["71255.30", "0.534"], ["71257.80", "0.000"], ["71258.70", "0.009"], ["71259.30", "0.034"], ["71259.90", "0.003"], ["71260.00", "0.247"], ["71260.60", "0.015"], ["71260.70", "0.009"], ["71262.00", "0.007"], ["71262.10", "0.055"], ["71262.20", "0.012"], ["71265.70", "0.661"], ["71265.80", "0.678"], ["71266.20", "0.602"], ["71267.00", "0.004"], ["71267.60", "0.092"], ["71270.30", "0.004"], ["71274.90", "0.016"], ["71275.60", "0.010"], ["71275.80", "0.333"], ["71279.50", "0.674"], ["71279.70", "0.423"], ["71280.10", "0.003"], ["71280.90", "0.136"], ["71281.40", "0.092"], ["71281.50", "0.000"], ["71282.40", "0.003"], ["71282.90", "0.003"], ["71283.60", "0.003"], ["71284.80", "0.006"], ["71285.10", "0.028"], ["71286.10", "0.134"], ["71286.20", "0.801"], ["71286.30", "0.976"], ["71286.80", "0.000"], ["71287.00", "0.003"], ["71287.10", "0.209"], ["71287.20", "0.345"], ["71287.30", "0.676"], ["71287.40", "0.016"], ["71288.30", "0.004"], ["71289.00", "0.004"], ["71291.30", "0.000"], ["71292.70", "0.008"], ["71294.20", "0.024"], ["71294.30", "1.917"], ["71294.40", "3.392"], ["71294.50", "1.682"], ["71294.60", "2.174"], ["71294.70", "2.889"], ["71294.80", "0.265"], ["71294.90", "2.433"], ["71295.00", "0.617"], ["71295.10", "0.175"], ["71295.20", "0.174"], ["71295.30", "0.591"], ["71295.40", "0.504"], ["71295.50", "0.975"], ["71295.60", "0.728"], ["71295.70", "0.415"], ["71295.80", "11.792"]], "a": [["71294.40", "0.000"], ["71294.50", "0.000"], ["71294.60", "0.000"], ["71294.70", "0.000"], ["71294.80", "0.000"], ["71294.90", "0.000"], ["71295.00", "0.000"], ["71295.10", "0.000"], ["71295.20", "0.000"], ["71295.30", "0.000"], ["71295.40", "0.000"], ["71295.50", "0.000"], ["71295.60", "0.000"], ["71295.70", "0.000"], ["71295.80", "0.000"], ["71295.90", "0.002"], ["71296.20", "0.000"], ["71296.70", "0.000"], ["71297.90", "0.005"], ["71298.00", "0.290"], ["71298.20", "0.000"], ["71298.40", "0.001"], ["71298.80", "0.000"], ["71299.40", "0.000"], ["71299.60", "0.009"], ["71299.70", "0.059"], ["71300.70", "0.003"], ["71301.20", "0.564"], ["71301.30", "0.002"], ["71301.90", "0.180"], ["71302.80", "0.000"], ["71303.00", "1.008"], ["71303.60", "0.053"], ["71303.70", "0.120"], ["71303.90", "0.001"], ["71304.50", "0.229"], ["71305.00", "0.060"], ["71305.10", "0.002"], ["71305.50", "0.066"], ["71306.00", "0.004"], ["71306.10", "0.176"], ["71306.60", "0.126"], ["71306.90", "0.005"], ["71307.20", "0.072"], ["71307.30", "0.197"], ["71307.40", "0.000"], ["71308.00", "0.007"], ["71308.20", "0.003"], ["71308.30", "0.000"], ["71308.90", "0.093"], ["71309.00", "0.007"], ["71310.10", "0.007"], ["71310.30", "0.000"], ["71310.80", "0.007"], ["71311.30", "0.002"], ["71311.50", "0.061"], ["71311.80", "0.000"], ["71311.90", "0.003"], ["71312.10", "0.014"], ["71312.50", "0.012"], ["71312.60", "0.007"], ["71312.80", "0.429"], ["71313.30", "0.004"], ["71313.40", "0.000"], ["71313.60", "0.010"], ["71313.80", "0.000"], ["71315.10", "0.687"], ["71315.50", "0.468"], ["71315.60", "0.345"], ["71315.80", "0.006"], ["71315.90", "0.001"], ["71316.00", "0.009"], ["71316.10", "0.336"], ["71316.40", "0.000"], ["71316.90", "0.151"], ["71317.20", "0.000"], ["71317.80", "0.020"], ["71318.30", "0.008"], ["71318.70", "0.703"], ["71318.80", "0.000"], ["71319.50", "0.598"], ["71319.70", "0.000"], ["71320.80", "0.000"], ["71323.00", "0.003"], ["71323.80", "0.283"], ["71324.20", "0.098"], ["71324.30", "0.249"], ["71324.80", "0.000"], ["71325.10", "0.022"], ["71325.20", "0.000"], ["71325.30", "0.210"], ["71325.80", "0.326"], ["71325.90", "0.000"], ["71326.00", "0.002"], ["71326.50", "0.013"], ["71326.60", "0.011"], ["71330.00", "0.150"], ["71333.20", "0.028"], ["71334.30", "0.072"], ["71337.00", "0.004"], ["71337.60", "0.071"], ["71341.20", "1.158"], ["71345.60", "0.558"], ["71348.40", "0.015"], ["71348.50", "0.914"], ["71348.80", "0.000"], ["71349.00", "0.011"], ["71349.20", "0.930"], ["71349.90", "0.112"], ["71350.90", "0.034"], ["71351.30", "0.000"], ["71351.90", "0.456"], ["71352.20", "0.091"], ["71352.30", "0.033"], ["71352.70", "0.046"], ["71352.90", "0.020"], ["71353.00", "0.128"], ["71367.40", "0.187"], ["71371.20", "0.000"], ["71372.50", "0.000"], ["71394.80", "0.454"], ["71403.80", "0.270"], ["71419.30", "0.002"], ["71450.00", "1.255"], ["71456.40", "0.505"], ["71461.80", "0.002"], ["71491.90", "0.001"], ["71602.10", "6.413"], ["71640.20", "3.226"], ["72007.30", "0.710"], ["72007.40", "0.002"], ["72285.40", "1.519"], ["74885.20", "0.000"], ["78423.80", "0.004"], ["89523.20", "0.000"]]}}
{"local_ts": 1773378032354, "server_ts": 1773378032076, "data": {"e": "depthUpdate", "E": 1773378032079, "T": 1773378032076, "s": "BTCUSDT", "U": 10100837194008, "u": 10100837211105, "pu": 10100837193980, "b": [["1000.00", "26.142"], ["5000.00", "101.418"], ["20800.90", "0.234"], ["20900.90", "1.026"], ["20990.90", "0.018"], ["21000.90", "0.234"], ["21100.90", "0.279"], ["40000.00", "49.105"], ["50000.00", "162.129"], ["50001.00", "7.922"], ["50002.00", "0.141"], ["56445.30", "0.000"], ["57041.00", "0.000"], ["67735.40", "0.000"], ["69161.90", "0.003"], ["69199.50", "0.078"], ["69300.00", "30.217"], ["69300.90", "0.031"], ["70257.60", "0.712"], ["70587.90", "0.000"], ["71185.50", "0.302"], ["71190.30", "0.000"], ["71194.00", "0.242"], ["71195.00", "0.015"], ["71206.60", "0.235"], ["71209.60", "0.051"], ["71218.10", "0.025"], ["71223.20", "0.674"], ["71224.20", "0.000"], ["71225.10", "1.057"], ["71227.30", "0.186"], ["71227.80", "1.615"], ["71230.00", "2.360"], ["71237.10", "0.007"], ["71241.50", "0.063"], ["71245.10", "0.060"], ["71248.80", "0.006"], ["71253.00", "0.002"], ["71254.60", "0.314"], ["71255.60", "0.025"], ["71259.90", "0.000"], ["71260.00", "0.245"], ["71260.60", "0.002"], ["71260.70", "0.002"], ["71262.50", "0.082"], ["71262.90", "0.002"], ["71263.90", "0.034"], ["71264.00", "0.004"], ["71265.10", "0.275"], ["71265.30", "0.385"], ["71266.00", "0.855"], ["71267.00", "0.004"], ["71268.20", "0.013"], ["71269.00", "0.722"], ["71269.10", "0.004"], ["71269.70", "0.019"], ["71270.00", "0.178"], ["71271.10", "0.005"], ["71271.20", "1.408"], ["71271.30", "0.003"], ["71271.80", "0.011"], ["71271.90", "0.619"], ["71272.30", "0.210"], ["71272.40", "0.056"], ["71272.50", "0.277"], ["71272.60", "0.003"], ["71273.40", "0.011"], ["71273.80", "0.004"], ["71274.00", "0.050"], ["71274.20", "0.006"], ["71274.70", "0.301"], ["71274.90", "0.014"], ["71275.80", "1.474"], ["71276.50", "1.201"], ["71276.90", "0.071"], ["71277.00", "0.002"], ["71277.20", "1.533"], ["71277.40", "0.247"], ["71277.80", "0.240"], ["71277.90", "0.146"], ["71278.00", "0.005"], ["71279.40", "0.005"], ["71279.50", "1.521"], ["71279.60", "0.281"], ["71280.90", "0.136"], ["71281.00", "1.199"], ["71281.30", "0.277"], ["71281.40", "0.092"], ["71281.70", "0.004"], ["71281.90", "0.007"], ["71282.60", "0.006"], ["71282.90", "0.003"], ["71283.00", "0.068"], ["71283.30", "0.795"], ["71283.40", "0.550"], ["71283.60", "0.045"], ["71284.10", "0.061"], ["71284.70", "0.001"], ["71284.90", "0.155"], ["71285.00", "0.148"], ["71285.30", "0.000"], ["71286.60", "0.292"], ["71286.80", "0.147"], ["71287.40", "0.150"], ["71287.50", "0.028"], ["71287.60", "0.016"], ["71288.10", "0.001"], ["71288.60", "0.000"], ["71289.20", "0.337"], ["71289.30", "0.125"], ["71289.70", "0.013"], ["71289.90", "0.504"], ["71290.10", "0.003"], ["71290.40", "0.108"], ["71290.60", "0.002"], ["71291.20", "0.126"], ["71291.30", "0.074"], ["71291.40", "0.195"], ["71291.60", "0.038"], ["71291.80", "0.050"], ["71292.20", "0.009"], ["71292.30", "0.003"], ["71292.60", "0.067"], ["71292.80", "0.259"], ["71293.20", "0.010"], ["71293.70", "0.218"], ["71294.00", "0.069"], ["71294.10", "0.005"], ["71294.30", "0.069"], ["71294.40", "1.171"], ["71294.50", "0.003"], ["71296.00", "0.802"], ["71296.10", "0.631"], ["71296.40", "0.805"], ["71297.00", "0.631"], ["71297.10", "0.532"], ["71297.40", "0.009"], ["71297.60", "0.604"], ["71297.70", "0.003"], ["71300.80", "0.011"], ["71300.90", "3.723"]], "a": [["71301.00", "0.831"], ["71301.10", "0.004"], ["71301.20", "0.002"], ["71301.30", "0.002"], ["71301.80", "0.000"], ["71302.00", "0.004"], ["71302.90", "0.005"], ["71304.00", "0.005"], ["71305.00", "0.100"], ["71305.30", "0.274"], ["71305.40", "0.034"], ["71305.70", "0.093"], ["71306.00", "0.005"], ["71306.20", "0.125"], ["71306.40", "0.078"], ["71306.80", "0.158"], ["71307.50", "0.000"], ["71308.00", "0.007"], ["71308.40", "0.002"], ["71308.60", "0.062"], ["71308.70", "0.000"], ["71308.80", "0.478"], ["71308.90", "0.013"], ["71309.30", "0.002"], ["71309.40", "0.007"], ["71309.80", "0.297"], ["71309.90", "0.001"], ["71310.50", "1.150"], ["71310.60", "0.152"], ["71311.90", "0.005"], ["71312.30", "0.212"], ["71312.40", "0.295"], ["71313.10", "0.548"], ["71313.20", "0.001"], ["71313.60", "0.011"], ["71313.90", "0.045"], ["71314.10", "0.021"], ["71314.40", "0.002"], ["71314.90", "0.244"], ["71315.10", "0.000"], ["71315.20", "0.138"], ["71315.30", "0.004"], ["71315.40", "0.003"], ["71315.60", "0.003"], ["71316.00", "0.009"], ["71316.10", "0.002"], ["71316.40", "0.000"], ["71316.90", "0.001"], ["71317.30", "0.001"], ["71317.40", "0.011"], ["71317.50", "0.006"], ["71317.60", "0.080"], ["71317.80", "0.695"], ["71317.90", "1.192"], ["71318.10", "0.000"], ["71318.20", "0.280"], ["71319.00", "0.007"], ["71319.20", "0.004"], ["71319.40", "0.002"], ["71319.50", "0.592"], ["71319.70", "0.196"], ["71319.80", "0.011"], ["71320.10", "0.118"], ["71320.20", "0.054"], ["71320.30", "0.003"], ["71320.60", "0.016"], ["71320.80", "0.000"], ["71320.90", "0.003"], ["71321.00", "0.005"], ["71321.10", "0.012"], ["71321.50", "0.000"], ["71321.80", "0.487"], ["71322.00", "0.007"], ["71322.20", "0.342"], ["71322.50", "0.000"], ["71322.80", "0.000"], ["71323.00", "0.012"], ["71323.50", "0.002"], ["71324.40", "0.026"], ["71324.70", "0.070"], ["71324.80", "0.000"], ["71325.00", "0.005"], ["71325.30", "0.000"], ["71325.40", "0.003"], ["71326.10", "0.010"], ["71326.80", "0.012"], ["71327.00", "0.011"], ["71327.50", "0.000"], ["71328.80", "0.267"], ["71329.50", "0.265"], ["71329.70", "0.346"], ["71330.00", "0.152"], ["71330.30", "0.000"], ["71330.60", "0.685"], ["71330.80", "0.001"], ["71331.40", "0.000"], ["71331.50", "0.067"], ["71331.80", "0.070"], ["71332.10", "0.009"], ["71332.20", "0.009"], ["71332.80", "0.690"], ["71332.90", "0.338"], ["71333.90", "0.075"], ["71334.10", "1.378"], ["71334.20", "0.023"], ["71335.10", "0.250"], ["71335.70", "0.630"], ["71336.40", "0.051"], ["71336.60", "0.068"], ["71337.00", "0.004"], ["71337.60", "0.184"], ["71338.00", "3.575"], ["71341.20", "0.588"], ["71341.30", "0.891"], ["71342.60", "0.001"], ["71343.10", "0.842"], ["71344.00", "1.409"], ["71345.30", "0.021"], ["71347.50", "0.010"], ["71351.50", "0.012"], ["71353.60", "0.006"], ["71354.70", "0.000"], ["71355.10", "0.050"], ["71356.10", "0.000"], ["71356.30", "0.045"], ["71356.50", "0.087"], ["71357.00", "0.994"], ["71357.40", "0.272"], ["71367.40", "0.187"], ["71377.50", "0.449"], ["71377.90", "0.064"], ["71390.00", "0.086"], ["71393.20", "0.279"], ["71395.20", "0.000"], ["71397.30", "0.198"], ["71401.10", "0.003"], ["71401.50", "0.282"], ["71406.70", "0.025"], ["71411.00", "0.750"], ["71424.30", "2.038"], ["71424.40", "0.000"], ["71452.20", "0.000"], ["71452.50", "0.000"], ["71464.00", "0.002"], ["71464.70", "0.016"], ["71475.90", "0.283"], ["71478.70", "0.144"], ["71496.30", "0.976"], ["71497.10", "0.000"], ["71543.10", "0.214"], ["71544.40", "0.002"], ["71549.80", "0.000"], ["71886.00", "0.087"], ["72014.00", "0.000"], ["72382.10", "0.414"], ["72655.90", "0.000"], ["72727.00", "1.807"], ["73479.80", "0.135"], ["74869.60", "0.002"], ["78431.10", "0.002"], ["89523.20", "0.000"]]}}
{"local_ts": 1773378033379, "server_ts": 1773378033102, "data": {"e": "depthUpdate", "E": 1773378033103, "T": 1773378033102, "s": "BTCUSDT", "U": 10100837311824, "u": 10100837325202, "pu": 10100837311775, "b": [["5000.00", "101.418"], ["20806.00", "0.396"], ["20808.70", "0.099"], ["20900.90", "0.009"], ["20908.70", "0.090"], ["21006.00", "0.162"], ["21006.60", "0.000"], ["21007.00", "0.000"], ["21208.70", "0.090"], ["50000.00", "162.125"], ["50001.00", "7.918"], ["50002.00", "0.137"], ["56445.30", "0.002"], ["57047.00", "0.004"], ["67719.60", "0.002"], ["69169.50", "0.003"], ["69580.20", "0.002"], ["69810.40", "0.002"], ["69882.60", "0.389"], ["70595.60", "0.000"], ["70781.10", "0.846"], ["70949.50", "0.710"], ["71003.50", "0.000"], ["71090.10", "0.002"], ["71141.10", "0.099"], ["71163.40", "0.014"], ["71196.90", "2.074"], ["71201.00", "0.527"], ["71203.80", "0.122"], ["71206.20", "0.000"], ["71206.80", "0.015"], ["71222.20", "0.943"], ["71230.00", "2.362"], ["71233.40", "0.698"], ["71235.50", "0.180"], ["71237.50", "0.005"], ["71246.90", "0.000"], ["71251.70", "1.846"], ["71252.00", "0.074"], ["71255.20", "0.916"], ["71257.20", "0.005"], ["71257.30", "0.000"], ["71258.00", "0.480"], ["71258.50", "0.002"], ["71259.80", "0.032"], ["71260.00", "0.243"], ["71266.20", "0.314"], ["71266.30", "0.002"], ["71266.90", "0.013"], ["71267.00", "0.006"], ["71267.80", "0.000"], ["71270.40", "0.063"], ["71271.20", "1.468"], ["71273.10", "0.069"], ["71274.00", "0.054"], ["71274.10", "0.054"], ["71274.60", "0.331"], ["71275.20", "0.012"], ["71275.40", "0.078"], ["71276.30", "0.000"], ["71277.40", "0.023"], ["71277.60", "0.251"], ["71278.80", "0.000"], ["71279.80", "0.000"], ["71280.10", "0.291"], ["71280.60", "0.070"], ["71281.00", "0.025"], ["71281.40", "0.092"], ["71281.60", "0.220"], ["71282.90", "0.000"], ["71283.40", "0.454"], ["71283.60", "0.003"], ["71286.30", "0.320"], ["71293.40", "0.004"], ["71294.40", "1.069"], ["71295.90", "0.003"], ["71297.00", "0.002"], ["71297.50", "0.633"], ["71297.60", "0.462"], ["71299.60", "0.000"], ["71301.30", "0.001"], ["71302.20", "0.003"], ["71303.80", "0.009"], ["71304.00", "0.036"], ["71304.90", "0.021"], ["71305.20", "0.019"], ["71305.90", "0.004"], ["71306.00", "0.917"], ["71306.50", "0.001"], ["71306.60", "0.833"], ["71307.00", "0.804"], ["71307.10", "0.519"], ["71307.30", "0.001"], ["71307.60", "0.000"], ["71307.70", "0.001"], ["71307.90", "0.000"], ["71308.30", "0.011"], ["71308.60", "0.004"], ["71308.70", "6.554"]], "a": [["71308.80", "4.153"], ["71308.90", "0.005"], ["71309.00", "0.004"], ["71309.10", "0.002"], ["71309.20", "0.070"], ["71309.50", "0.010"], ["71309.70", "0.002"], ["71311.50", "0.057"], ["71312.00", "0.002"], ["71312.10", "0.003"], ["71314.00", "0.002"], ["71314.10", "1.001"], ["71314.60", "0.002"], ["71314.80", "0.002"], ["71315.00", "0.005"], ["71315.20", "0.143"], ["71315.70", "0.000"], ["71316.30", "0.108"], ["71316.60", "0.076"], ["71316.80", "0.089"], ["71317.10", "0.008"], ["71317.20", "0.000"], ["71317.30", "0.076"], ["71317.40", "0.174"], ["71318.70", "0.001"], ["71319.30", "0.007"], ["71319.40", "0.056"], ["71319.90", "0.079"], ["71320.10", "0.004"], ["71320.50", "0.679"], ["71320.70", "0.063"], ["71320.80", "0.167"], ["71320.90", "0.020"], ["71321.10", "0.004"], ["71321.60", "0.003"], ["71321.70", "0.141"], ["71322.20", "0.196"], ["71322.30", "0.003"], ["71322.50", "0.000"], ["71323.10", "0.121"], ["71323.80", "0.013"], ["71324.80", "0.104"], ["71325.00", "1.197"], ["71325.70", "0.708"], ["71325.80", "0.001"], ["71325.90", "1.408"], ["71326.40", "0.001"], ["71326.50", "0.004"], ["71326.60", "0.005"], ["71326.90", "0.004"], ["71327.30", "0.015"], ["71327.40", "0.025"], ["71327.90", "0.008"], ["71328.00", "0.010"], ["71328.40", "0.008"], ["71328.50", "0.086"], ["71329.30", "0.380"], ["71329.40", "0.001"], ["71329.80", "0.377"], ["71330.00", "0.013"], ["71333.00", "0.079"], ["71334.20", "0.004"], ["71335.60", "0.002"], ["71337.00", "0.004"], ["71337.10", "0.071"], ["71337.30", "0.139"], ["71337.40", "0.498"], ["71337.70", "1.540"], ["71337.80", "0.071"], ["71338.00", "2.006"], ["71338.30", "0.246"], ["71338.40", "0.402"], ["71338.50", "0.002"], ["71338.70", "0.505"], ["71338.80", "0.279"], ["71339.20", "0.027"], ["71340.20", "0.000"], ["71341.60", "0.005"], ["71342.20", "0.000"], ["71342.80", "0.016"], ["71344.00", "1.413"], ["71344.40", "0.132"], ["71345.90", "0.045"], ["71351.00", "0.049"], ["71358.00", "0.010"], ["71358.30", "0.036"], ["71360.20", "0.092"], ["71360.90", "0.073"], ["71362.10", "0.000"], ["71362.30", "0.007"], ["71362.90", "0.855"], ["71363.00", "0.126"], ["71363.30", "0.002"], ["71379.40", "1.000"], ["71380.00", "0.024"], ["71381.10", "0.057"], ["71381.50", "0.023"], ["71390.40", "0.001"], ["71398.80", "0.002"], ["71401.00", "0.351"], ["71406.10", "0.030"], ["71413.20", "0.678"], ["71470.30", "0.042"], ["71521.40", "0.000"], ["71547.60", "0.089"], ["71568.70", "0.005"], ["71600.00", "32.467"], ["71607.60", "0.199"], ["71609.90", "0.273"], ["71780.00", "0.650"], ["72021.90", "0.000"], ["73448.00", "0.209"], ["74904.00", "0.050"], ["78439.70", "0.002"], ["89523.20", "0.000"]]}}
{"local_ts": 1773378034399, "server_ts": 1773378034122, "data": {"e": "depthUpdate", "E": 1773378034123, "T": 1773378034122, "s": "BTCUSDT", "U": 10100837453547, "u": 10100837461165, "pu": 10100837453535, "b": [["1000.00", "26.142"], ["5000.00", "101.418"], ["20800.90", "0.315"], ["20917.30", "0.252"], ["21000.90", "0.036"], ["21217.30", "0.513"], ["50000.00", "162.129"], ["50001.00", "7.922"], ["50002.00", "0.141"], ["56445.30", "0.000"], ["57054.00", "0.000"], ["64185.60", "0.008"], ["67733.80", "0.002"], ["67784.70", "0.004"], ["70082.20", "0.285"], ["70242.00", "0.008"], ["70243.50", "0.018"], ["70250.80", "0.000"], ["70257.90", "0.988"], ["70495.70", "1.132"], ["70604.10", "0.008"], ["71133.90", "0.000"], ["71153.60", "0.000"], ["71159.80", "0.000"], ["71175.00", "0.779"], ["71226.70", "0.205"], ["71234.90", "0.203"], ["71237.20", "0.916"], ["71265.60", "0.488"], ["71267.00", "0.004"], ["71268.10", "0.000"], ["71268.20", "0.076"], ["71269.50", "0.581"], ["71272.50", "2.466"], ["71274.00", "0.052"], ["71275.10", "0.036"], ["71277.40", "0.004"], ["71278.60", "0.002"], ["71281.00", "0.198"], ["71286.40", "2.184"], ["71288.00", "0.006"], ["71290.70", "0.681"], ["71290.80", "0.249"], ["71290.90", "0.038"], ["71292.70", "0.026"], ["71293.40", "0.004"], ["71294.00", "0.004"], ["71295.00", "0.014"], ["71300.40", "0.001"], ["71300.70", "0.000"], ["71300.80", "0.048"], ["71301.60", "0.038"], ["71301.90", "0.000"], ["71302.30", "0.003"], ["71302.70", "0.002"], ["71304.50", "0.002"], ["71306.00", "0.117"], ["71306.60", "0.198"], ["71310.40", "0.007"], ["71311.10", "0.678"], ["71311.20", "0.006"], ["71311.40", "0.002"], ["71311.50", "0.148"], ["71311.80", "0.002"], ["71312.90", "0.003"], ["71317.20", "0.015"], ["71317.30", "8.168"]], "a": [["71317.40", "0.826"], ["71317.70", "0.002"], ["71320.10", "0.001"], ["71328.10", "0.005"], ["71330.20", "0.003"], ["71331.70", "0.450"], ["71341.60", "0.026"], ["71342.50", "0.008"], ["71344.00", "0.012"], ["71345.60", "0.002"], ["71351.00", "0.219"], ["71358.00", "0.008"], ["71362.60", "0.012"], ["71365.00", "0.006"], ["71369.80", "2.209"], ["71402.60", "0.001"], ["71403.70", "0.004"], ["71410.40", "0.796"], ["71440.60", "0.202"], ["71454.50", "0.062"], ["71481.90", "0.006"], ["71510.60", "0.408"], ["71514.00", "4.280"], ["71516.60", "0.217"], ["71565.80", "0.024"], ["71639.50", "0.008"], ["72030.60", "0.006"], ["72743.70", "0.009"], ["78449.10", "0.006"], ["89523.20", "0.000"]]}}
{"local_ts": 1773378035423, "server_ts": 1773378035146, "data": {"e": "depthUpdate", "E": 1773378035147, "T": 1773378035146, "s": "BTCUSDT", "U": 10100837555113, "u": 10100837566336, "pu": 10100837554662, "b": [["5000.00", "101.418"], ["20823.00", "0.279"], ["20908.70", "0.162"], ["21123.00", "0.567"], ["21208.70", "0.288"], ["21217.30", "0.054"], ["57041.00", "0.000"], ["67721.60", "0.000"], ["70242.00", "0.008"], ["70257.90", "0.986"], ["70276.10", "0.002"], ["70609.80", "0.002"], ["71155.40", "0.159"], ["71180.40", "0.081"], ["71183.90", "0.041"], ["71187.50", "0.049"], ["71201.60", "0.000"], ["71219.00", "0.200"], ["71220.70", "0.015"], ["71220.80", "0.348"], ["71251.60", "1.242"], ["71254.70", "1.035"], ["71269.50", "0.649"], ["71274.00", "0.068"], ["71274.20", "0.149"], ["71277.20", "1.426"], ["71281.00", "0.198"], ["71286.40", "1.415"], ["71288.00", "0.282"], ["71294.40", "0.550"], ["71295.00", "0.012"], ["71295.10", "0.792"], ["71301.40", "0.274"], ["71301.50", "0.005"], ["71301.60", "0.334"], ["71302.00", "0.010"], ["71307.60", "0.008"], ["71309.30", "0.001"], ["71310.20", "0.000"], ["71310.70", "0.141"], ["71311.80", "0.006"], ["71312.40", "0.007"], ["71313.10", "0.003"], ["71314.10", "0.336"], ["71315.20", "0.040"], ["71315.40", "0.560"], ["71315.90", "0.097"], ["71317.00", "1.619"], ["71319.20", "0.005"], ["71319.50", "0.692"], ["71320.20", "0.005"], ["71322.50", "0.084"], ["71322.80", "2.203"], ["71322.90", "1.240"], ["71323.00", "8.502"]], "a": [["71323.10", "0.828"], ["71324.90", "0.213"], ["71325.80", "0.001"], ["71327.10", "0.000"], ["71329.70", "0.000"], ["71330.20", "0.033"], ["71330.80", "0.057"], ["71330.90", "0.002"], ["71331.10", "0.001"], ["71333.10", "0.003"], ["71333.70", "0.006"], ["71333.80", "0.002"], ["71334.10", "0.000"], ["71334.20", "0.009"], ["71334.30", "0.179"], ["71335.20", "0.000"], ["71335.30", "0.011"], ["71335.90", "0.055"], ["71336.10", "0.036"], ["71336.70", "0.196"], ["71336.90", "0.000"], ["71337.10", "0.058"], ["71337.50", "0.040"], ["71337.60", "0.086"], ["71337.90", "0.407"], ["71338.00", "0.262"], ["71338.20", "0.008"], ["71338.30", "0.003"], ["71338.40", "0.187"], ["71338.50", "0.086"], ["71338.60", "0.036"], ["71338.90", "0.039"], ["71339.00", "0.000"], ["71339.40", "0.002"], ["71340.00", "0.186"], ["71340.50", "0.046"], ["71340.60", "0.002"], ["71340.90", "0.007"], ["71341.00", "0.685"], ["71341.40", "0.009"], ["71341.50", "0.072"], ["71341.90", "0.004"], ["71342.00", "0.002"], ["71342.20", "0.080"], ["71342.50", "0.009"], ["71342.70", "0.000"], ["71343.20", "0.674"], ["71343.30", "0.212"], ["71343.70", "0.017"], ["71344.00", "0.013"], ["71344.50", "0.312"], ["71345.40", "0.676"], ["71346.20", "0.272"], ["71351.00", "0.009"], ["71357.80", "0.006"], ["71358.00", "0.017"], ["71365.00", "0.008"], ["71367.20", "0.004"], ["71370.00", "0.250"], ["71372.00", "0.004"], ["71373.20", "0.005"], ["71373.50", "0.126"], ["71380.70", "0.016"], ["71398.00", "0.311"], ["71400.00", "0.857"], ["71413.60", "0.008"], ["71425.40", "0.337"], ["71445.10", "0.355"], ["71446.80", "0.231"], ["71447.00", "0.156"], ["71447.50", "0.242"], ["71447.80", "0.033"], ["71448.80", "0.092"], ["71451.00", "0.417"], ["71454.50", "0.098"], ["71458.10", "6.462"], ["71469.30", "0.003"], ["71500.00", "46.242"], ["71548.10", "10.002"], ["71560.20", "0.013"], ["71894.90", "0.000"], ["72036.20", "0.006"], ["72036.30", "0.035"], ["72314.50", "0.935"], ["74896.20", "0.000"], ["89523.20", "0.000"]]}}
{"local_ts": 1773378036442, "server_ts": 1773378036166, "data": {"e": "depthUpdate", "E": 1773378036167, "T": 1773378036166, "s": "BTCUSDT", "U": 10100837668271, "u": 10100837672090, "pu": 10100837668154, "b": [["1000.00", "26.142"], ["5000.00", "101.418"], ["20819.40", "0.063"], ["21028.60", "0.855"], ["21119.40", "0.252"], ["21123.00", "0.342"], ["21228.60", "0.504"], ["50000.00", "162.129"], ["50001.00", "7.922"], ["50002.00", "0.141"], ["67739.80", "0.000"], ["67762.20", "0.004"], ["69874.90", "0.015"], ["69984.20", "2.307"], ["70185.50", "4.583"], ["70219.30", "0.713"], ["70223.00", "0.219"], ["70242.00", "0.006"], ["70256.80", "12.403"], ["70276.10", "0.000"], ["70295.50", "0.002"], ["70399.40", "1.406"], ["70437.00", "0.703"], ["70615.30", "0.009"], ["70821.30", "0.201"], ["70855.10", "30.304"], ["70888.10", "18.840"], ["70972.00", "0.000"], ["70976.70", "0.648"], ["71008.30", "0.002"], ["71014.20", "0.000"], ["71114.60", "0.006"], ["71187.60", "0.000"], ["71203.30", "0.111"], ["71279.00", "0.068"], ["71279.50", "0.690"], ["71283.80", "0.041"], ["71286.10", "0.043"], ["71300.00", "0.504"], ["71314.30", "0.088"], ["71321.00", "0.635"], ["71321.50", "0.002"], ["71328.60", "7.023"]], "a": [["71332.00", "0.024"], ["71335.80", "0.000"], ["71342.40", "0.179"], ["71343.00", "0.254"], ["71343.40", "0.102"], ["71343.90", "0.089"], ["71344.30", "0.084"], ["71344.80", "0.359"], ["71360.30", "0.081"], ["71360.60", "0.601"], ["71369.20", "0.009"], ["71394.50", "0.086"], ["71399.90", "0.061"], ["71440.60", "0.202"], ["71443.30", "0.058"], ["71445.50", "0.047"], ["71447.50", "0.276"], ["71451.00", "0.255"], ["71469.30", "0.003"], ["71477.70", "0.000"], ["71479.90", "0.633"], ["72042.00", "0.000"], ["72070.20", "2.077"], ["73468.50", "0.021"], ["74908.00", "0.052"], ["89523.20", "0.000"]]}}
{"local_ts": 1773378037464, "server_ts": 1773378037188, "data": {"e": "depthUpdate", "E": 1773378037189, "T": 1773378037188, "s": "BTCUSDT", "U": 10100837723437, "u": 10100837727725, "pu": 10100837723372, "b": [["1000.00", "26.142"], ["5000.00", "101.438"], ["20928.60", "0.684"], ["21028.60", "1.017"], ["21128.60", "0.468"], ["21228.60", "0.342"], ["33000.00", "9.339"], ["69874.90", "0.006"], ["70185.60", "0.000"], ["70223.00", "5.154"], ["70254.30", "2.123"], ["70256.80", "11.696"], ["70256.90", "0.000"], ["70274.20", "0.002"], ["70294.30", "8.097"], ["70295.50", "0.000"], ["70313.70", "0.002"], ["70343.90", "67.562"], ["70464.50", "0.000"], ["70500.30", "2.831"], ["70505.50", "0.705"], ["70551.10", "1.449"], ["70561.00", "57.527"], ["70615.30", "0.009"], ["70648.90", "0.729"], ["70686.60", "0.700"], ["70729.20", "47.559"], ["70856.80", "0.005"], ["70895.10", "0.361"], ["70897.50", "0.106"], ["71008.30", "0.000"], ["71016.10", "6.470"], ["71157.40", "0.249"], ["71161.00", "0.060"], ["71178.80", "0.041"], ["71182.40", "0.964"], ["71185.90", "0.002"], ["71188.30", "0.061"], ["71206.70", "0.018"], ["71278.80", "0.661"], ["71279.00", "1.270"], ["71281.00", "0.198"], ["71287.60", "0.869"], ["71288.00", "0.280"], ["71289.60", "0.000"], ["71294.10", "0.075"], ["71295.00", "0.010"], ["71297.60", "0.004"], ["71297.80", "1.037"], ["71297.90", "0.783"], ["71300.90", "0.083"], ["71301.20", "0.426"], ["71302.00", "0.292"], ["71302.50", "0.007"], ["71303.60", "0.300"], ["71309.00", "0.007"], ["71319.60", "0.145"], ["71327.90", "0.003"]], "a": [["71343.40", "0.104"], ["71344.30", "0.119"], ["71351.00", "0.013"], ["71353.30", "0.013"], ["71354.70", "0.012"], ["71358.00", "0.008"], ["71365.00", "0.008"], ["71370.40", "0.005"], ["71371.90", "0.035"], ["71372.00", "0.004"], ["71374.80", "2.224"], ["71379.00", "0.007"], ["71383.90", "0.003"], ["71387.60", "0.006"], ["71399.40", "10.309"], ["71405.30", "4.922"], ["71411.60", "0.000"], ["71419.30", "0.092"], ["71421.00", "0.674"], ["71451.60", "8.305"], ["71525.40", "15.486"], ["71540.80", "0.008"], ["71927.00", "33.200"], ["72042.00", "0.000"], ["72098.00", "41.054"], ["72155.80", "0.000"], ["72319.80", "46.809"], ["74910.50", "0.050"], ["74912.10", "0.173"]]}}
{"local_ts": 1773378038486, "server_ts": 1773378038208, "data": {"e": "depthUpdate", "E": 1773378038211, "T": 1773378038208, "s": "BTCUSDT", "U": 10100837838132, "u": 10100837844264, "pu": 10100837838076, "b": [["5000.00", "101.418"], ["20838.10", "0.414"], ["20928.60", "0.954"], ["20928.80", "0.000"], ["20938.10", "0.351"], ["21038.10", "0.333"], ["21128.60", "0.567"], ["21128.90", "0.000"], ["21130.50", "0.000"], ["67727.50", "0.000"], ["67728.70", "0.000"], ["70193.50", "0.000"], ["70232.40", "0.987"], ["70264.80", "3.380"], ["70274.20", "0.000"], ["70285.50", "1.139"], ["70303.70", "3.321"], ["70370.90", "2.814"], ["70417.80", "2.812"], ["70624.70", "0.007"], ["70981.40", "0.000"], ["71016.10", "0.002"], ["71035.80", "0.002"], ["71071.80", "0.000"], ["71093.90", "0.002"], ["71163.30", "0.026"], ["71181.90", "0.002"], ["71190.60", "0.634"], ["71230.20", "0.089"], ["71241.10", "0.036"], ["71242.20", "0.036"], ["71244.30", "0.025"], ["71263.90", "0.001"], ["71281.40", "0.042"], ["71284.40", "0.005"], ["71289.40", "0.068"], ["71289.50", "0.003"], ["71291.70", "0.014"], ["71291.80", "0.010"], ["71292.10", "0.006"], ["71299.00", "0.125"], ["71301.00", "0.755"], ["71306.20", "0.020"], ["71311.40", "0.074"], ["71314.20", "0.000"], ["71319.10", "0.000"], ["71321.90", "0.005"]], "a": [["71357.00", "0.275"], ["71358.30", "0.001"], ["71365.00", "0.010"], ["71378.80", "0.126"], ["71379.10", "0.674"], ["71384.70", "2.912"], ["71395.00", "0.670"], ["71395.20", "0.000"], ["71413.90", "1.403"], ["71415.10", "4.400"], ["71441.90", "0.058"], ["71447.00", "0.099"], ["71451.00", "0.255"], ["71469.30", "0.003"], ["71481.20", "0.446"], ["71488.50", "0.025"], ["71488.80", "0.719"], ["71499.50", "0.091"], ["71500.50", "0.100"], ["71522.00", "0.004"], ["71575.30", "0.760"], ["71582.30", "0.002"], ["72051.60", "3.200"], ["72329.80", "1.528"], ["74906.20", "0.006"]]}}
{"local_ts": 1773378039507, "server_ts": 1773378039230, "data": {"e": "depthUpdate", "E": 1773378039231, "T": 1773378039230, "s": "BTCUSDT", "U": 10100837892307, "u": 10100837898569, "pu": 10100837892300, "b": [["1000.00", "26.142"], ["5000.00", "101.418"], ["20838.10", "1.548"], ["20928.60", "0.054"], ["20938.10", "0.198"], ["21038.10", "0.702"], ["21238.10", "0.198"], ["33000.00", "9.343"], ["67729.60", "0.005"], ["67729.70", "0.002"], ["67746.40", "0.006"], ["70195.30", "1.222"], ["70446.20", "0.000"], ["70473.50", "0.002"], ["70482.00", "0.702"], ["70517.70", "1.404"], ["70624.70", "0.708"], ["70657.40", "0.010"], ["70663.20", "0.005"], ["70696.10", "5.600"], ["70710.30", "1.435"], ["70911.00", "0.577"], ["70946.80", "0.007"], ["71035.80", "0.000"], ["71042.10", "0.341"], ["71220.00", "0.133"], ["71228.90", "0.006"], ["71303.40", "0.000"], ["71307.00", "0.004"], ["71308.70", "0.057"], ["71311.00", "0.002"], ["71311.10", "0.676"], ["71311.40", "0.074"], ["71311.70", "0.000"], ["71311.80", "0.003"], ["71316.60", "0.004"], ["71321.80", "0.724"], ["71328.60", "21.936"], ["71328.70", "0.789"], ["71328.80", "0.032"], ["71334.40", "0.302"], ["71338.10", "10.194"]], "a": [["71338.20", "2.114"], ["71339.50", "0.002"], ["71355.10", "0.003"], ["71355.40", "0.048"], ["71362.60", "0.203"], ["71363.30", "0.005"], ["71364.60", "0.071"], ["71381.10", "0.035"], ["71382.70", "0.104"], ["71413.90", "1.379"], ["71506.10", "0.002"], ["71667.40", "0.000"], ["71881.30", "0.139"], ["72051.60", "3.200"], ["72100.00", "23.477"], ["72166.50", "1.123"], ["72764.90", "0.009"], ["74925.40", "0.000"], ["75792.60", "0.002"]]}}
{"local_ts": 1773378040526, "server_ts": 1773378040250, "data": {"e": "depthUpdate", "E": 1773378040251, "T": 1773378040250, "s": "BTCUSDT", "U": 10100837965484, "u": 10100837970806, "pu": 10100837965461, "b": [["5000.00", "101.398"], ["20838.10", "0.189"], ["20840.60", "0.063"], ["20940.60", "0.342"], ["21038.10", "0.000"], ["21140.60", "0.063"], ["21240.60", "0.801"], ["67764.80", "0.005"], ["70092.10", "1.168"], ["70455.00", "1.254"], ["70505.80", "0.575"], ["70627.20", "0.002"], ["70740.20", "0.000"], ["70954.10", "3.094"], ["71042.10", "0.339"], ["71044.10", "0.006"], ["71197.90", "0.157"], ["71263.90", "0.140"], ["71292.50", "0.692"], ["71292.60", "0.004"], ["71301.30", "0.680"], ["71307.30", "0.254"], ["71309.70", "0.006"], ["71313.00", "0.074"], ["71315.10", "0.003"], ["71321.90", "0.509"], ["71323.70", "0.000"], ["71323.80", "0.018"], ["71338.10", "1.777"]], "a": [["71340.70", "4.073"], ["71343.40", "0.012"], ["71369.40", "0.053"], ["71370.20", "0.511"], ["71375.90", "0.002"], ["71432.10", "0.068"], ["71490.10", "0.514"], ["71499.50", "0.091"], ["71514.10", "0.000"], ["72054.10", "0.000"], ["72353.70", "1.588"], ["75970.10", "0.002"]]}}
{"local_ts": 1773378041548, "server_ts": 1773378041270, "data": {"e": "depthUpdate", "E": 1773378041271, "T": 1773378041270, "s": "BTCUSDT", "U": 10100838027582, "u": 10100838032824, "pu": 10100838027576, "b": [["1000.00", "26.142"], ["5000.00", "101.418"], ["20840.60", "0.828"], ["20938.10", "0.072"], ["21140.60", "1.404"], ["21238.10", "0.324"], ["21240.60", "0.072"], ["69323.00", "0.100"], ["70196.80", "5.254"], ["70234.80", "1.412"], ["70268.10", "0.000"], ["70306.20", "0.986"], ["70448.80", "0.000"], ["70484.50", "0.702"], ["70627.20", "0.002"], ["70981.40", "0.000"], ["71158.70", "0.159"], ["71170.10", "0.070"], ["71176.70", "0.110"], ["71187.20", "0.041"], ["71188.60", "0.000"], ["71188.80", "0.180"], ["71244.20", "0.070"], ["71251.40", "0.074"], ["71258.50", "0.095"], ["71267.50", "0.197"], ["71271.20", "1.457"], ["71272.80", "0.651"], ["71276.40", "0.068"], ["71279.00", "0.088"], ["71290.00", "0.710"], ["71290.70", "0.652"], ["71291.10", "0.101"], ["71291.50", "0.036"], ["71292.50", "0.692"], ["71292.60", "0.004"], ["71301.20", "0.730"], ["71312.00", "0.500"], ["71312.10", "0.112"], ["71315.00", "0.573"], ["71316.80", "0.007"], ["71320.10", "0.150"], ["71325.90", "0.002"], ["71326.30", "0.106"], ["71328.50", "0.008"], ["71328.70", "0.677"], ["71330.10", "0.896"], ["71333.50", "0.145"]], "a": [["71340.70", "3.891"], ["71350.90", "0.062"], ["71351.40", "0.435"], ["71352.00", "0.584"], ["71355.00", "0.008"], ["71358.90", "0.007"], ["71362.10", "0.294"], ["71369.30", "0.288"], ["71370.70", "0.156"], ["71381.30", "0.677"], ["71381.70", "0.126"], ["71388.40", "2.192"], ["71390.30", "0.029"], ["71397.20", "0.003"], ["71397.30", "0.000"], ["71397.50", "0.088"], ["71397.80", "0.100"], ["71418.90", "4.272"], ["71422.70", "0.161"], ["71429.80", "0.201"], ["71437.00", "0.134"], ["71465.20", "7.886"], ["71538.20", "15.134"], ["71547.10", "0.000"], ["71697.30", "0.006"], ["72054.10", "0.000"], ["72767.50", "0.008"], ["74933.80", "0.000"]]}}
{"local_ts": 1773378042576, "server_ts": 1773378042292, "data": {"e": "depthUpdate", "E": 1773378042293, "T": 1773378042292, "s": "BTCUSDT", "U": 10100838120729, "u": 10100838125298, "pu": 10100838120655, "b": [["1000.00", "26.142"], ["5000.00", "101.418"], ["20840.60", "0.207"], ["21040.60", "1.143"], ["21140.60", "0.657"], ["21240.60", "0.693"], ["67739.50", "0.017"], ["70621.50", "2.313"], ["70627.20", "0.002"], ["70948.00", "0.068"], ["70983.80", "0.140"], ["71013.30", "0.007"], ["71014.30", "0.000"], ["71132.00", "0.003"], ["71158.50", "0.000"], ["71194.40", "0.002"], ["71226.90", "0.004"], ["71244.30", "0.070"], ["71251.50", "0.072"], ["71258.60", "0.171"], ["71265.30", "4.047"], ["71312.00", "0.002"], ["71326.30", "0.606"], ["71340.60", "25.600"]], "a": [["71340.70", "1.322"], ["71343.10", "0.003"], ["71351.40", "0.222"], ["71359.10", "0.178"], ["71361.10", "0.032"], ["71384.90", "0.037"], ["71397.50", "0.188"], ["71418.60", "4.174"], ["71423.40", "0.109"], ["71423.60", "0.207"], ["71430.50", "0.251"], ["71430.70", "0.043"], ["71437.70", "0.070"], ["71437.90", "0.508"], ["71474.20", "4.396"], ["71479.10", "0.009"], ["71505.70", "0.000"], ["72054.10", "0.000"], ["72644.30", "1.622"], ["73499.50", "0.582"], ["74907.70", "0.000"]]}}
{"local_ts": 1773378043588, "server_ts": 1773378043312, "data": {"e": "depthUpdate", "E": 1773378043313, "T": 1773378043312, "s": "BTCUSDT", "U": 10100838170732, "u": 10100838174147, "pu": 10100838170729, "b": [["5000.00", "101.418"], ["20940.60", "0.864"], ["21040.60", "0.936"], ["21140.60", "0.558"], ["21240.60", "0.342"], ["56445.30", "0.000"], ["67751.40", "0.009"], ["67751.50", "0.002"], ["67772.20", "0.005"], ["67773.00", "0.000"], ["69541.80", "0.000"], ["69930.90", "0.612"], ["70455.00", "0.121"], ["70627.20", "0.002"], ["70983.90", "0.144"], ["71013.30", "0.005"], ["71156.10", "0.054"], ["71156.90", "2.768"], ["71250.00", "90.709"], ["71292.20", "0.012"], ["71292.30", "0.004"], ["71305.40", "0.004"], ["71305.50", "0.002"], ["71306.10", "0.009"], ["71306.20", "0.022"], ["71307.00", "0.004"], ["71315.20", "0.002"], ["71315.30", "0.206"], ["71315.90", "0.009"], ["71316.00", "0.015"], ["71322.40", "0.008"], ["71322.50", "0.054"]], "a": [["71340.70", "3.472"], ["71341.90", "0.003"], ["71343.30", "0.008"], ["71367.50", "0.005"], ["71375.50", "0.005"], ["71375.60", "0.001"], ["71376.20", "0.061"], ["71376.30", "0.004"], ["71552.90", "0.000"], ["71858.70", "0.006"], ["72054.10", "0.002"], ["72302.10", "0.000"], ["74911.30", "0.161"]]}}
{"local_ts": 1773378044609, "server_ts": 1773378044332, "data": {"e": "depthUpdate", "E": 1773378044333, "T": 1773378044332, "s": "BTCUSDT", "U": 10100838209588, "u": 10100838212931, "pu": 10100838209534, "b": [["1000.00", "26.142"], ["5000.00", "101.418"], ["20840.60", "0.603"], ["20940.60", "1.197"], ["21040.60", "0.423"], ["21140.60", "0.477"], ["33000.00", "9.339"], ["56445.30", "0.002"], ["67773.00", "0.000"], ["70279.80", "0.000"], ["70627.20", "0.002"], ["71084.30", "0.002"]], "a": [["71347.60", "0.032"], ["71397.80", "0.021"], ["72054.10", "0.000"], ["72268.10", "2.487"], ["74941.80", "0.002"], ["89523.20", "0.000"]]}}
{"local_ts": 1773378045630, "server_ts": 1773378045353, "data": {"e": "depthUpdate", "E": 1773378045355, "T": 1773378045353, "s": "BTCUSDT", "U": 10100838248804, "u": 10100838252578, "pu": 10100838248799, "b": [["5000.00", "101.418"], ["20840.60", "1.467"], ["20940.60", "0.288"], ["21040.60", "0.612"], ["21240.60", "0.333"], ["67760.90", "0.000"], ["67773.00", "0.000"], ["69972.30", "0.358"], ["70261.30", "0.427"], ["70409.90", "0.017"], ["70627.20", "0.002"], ["71084.30", "0.000"], ["71088.50", "0.002"], ["71287.10", "0.274"], ["71292.20", "0.012"], ["71292.30", "0.004"], ["71293.90", "0.002"], ["71298.40", "0.946"], ["71300.90", "0.063"], ["71304.80", "1.874"], ["71304.90", "0.965"], ["71321.60", "0.000"], ["71324.70", "0.033"], ["71332.00", "0.002"], ["71340.60", "25.779"]], "a": [["71340.70", "1.574"], ["71340.80", "0.005"], ["71343.00", "0.006"], ["71349.00", "0.005"], ["71354.30", "1.111"], ["71355.50", "0.007"], ["71356.30", "0.003"], ["71357.10", "0.145"], ["71357.60", "0.003"], ["71362.60", "0.203"], ["71367.90", "0.271"], ["71383.10", "0.000"], ["71383.70", "0.187"], ["71455.00", "0.049"], ["72054.10", "0.000"], ["72375.10", "1.794"], ["74907.70", "0.000"], ["89523.20", "0.000"]]}}
{"local_ts": 1773378046653, "server_ts": 1773378046375, "data": {"e": "depthUpdate", "E": 1773378046377, "T": 1773378046375, "s": "BTCUSDT", "U": 10100838284454, "u": 10100838287756, "pu": 10100838284369, "b": [["1000.00", "26.142"], ["5000.00", "101.418"], ["20840.60", "0.243"], ["20940.60", "0.747"], ["21140.60", "0.153"], ["21240.60", "1.557"], ["33000.00", "9.343"], ["67754.30", "0.006"], ["67770.10", "0.015"], ["67773.60", "0.025"], ["70627.20", "0.002"], ["70983.90", "0.144"], ["71088.50", "0.000"], ["71111.60", "0.002"], ["71176.50", "0.159"], ["71284.70", "0.016"], ["71305.00", "0.335"], ["71340.60", "25.599"]], "a": [["71343.00", "0.006"], ["71348.70", "0.032"], ["71355.00", "0.298"], ["71362.90", "0.086"], ["71369.30", "0.002"], ["71370.10", "0.861"], ["71370.70", "0.145"], ["71372.60", "0.005"], ["71376.30", "0.032"], ["72054.10", "0.000"], ["72546.40", "0.274"], ["89523.20", "0.000"]]}}
{"local_ts": 1773378047672, "server_ts": 1773378047396, "data": {"e": "depthUpdate", "E": 1773378047397, "T": 1773378047396, "s": "BTCUSDT", "U": 10100838323462, "u": 10100838326410, "pu": 10100838323379, "b": [["1000.00", "26.142"], ["5000.00", "101.418"], ["20840.60", "0.882"], ["20940.60", "0.000"], ["21040.60", "0.018"], ["21140.60", "1.557"], ["21240.60", "0.243"], ["57072.50", "0.009"], ["67767.20", "0.000"], ["70627.20", "0.002"], ["71272.80", "0.570"], ["71340.60", "25.573"]], "a": [["71343.00", "0.006"], ["71350.10", "0.002"], ["71351.40", "0.313"], ["71358.50", "0.295"], ["71362.10", "0.299"], ["71372.90", "0.002"], ["71374.30", "0.506"], ["71397.80", "0.358"], ["72054.10", "0.000"], ["72407.80", "0.000"], ["72644.60", "0.000"], ["89523.20", "0.000"]]}}
{"local_ts": 1773378048696, "server_ts": 1773378048416, "data": {"e": "depthUpdate", "E": 1773378048417, "T": 1773378048416, "s": "BTCUSDT", "U": 10100838361315, "u": 10100838364607, "pu": 10100838361260, "b": [["5000.00", "101.418"], ["20840.60", "0.117"], ["21040.60", "1.323"], ["21140.60", "0.477"], ["21240.60", "0.783"], ["33000.00", "9.343"], ["67745.70", "0.000"], ["70324.30", "0.000"], ["70613.20", "10.794"], ["70627.20", "0.002"], ["70627.30", "0.744"], ["70983.90", "0.144"], ["71133.00", "2.225"], ["71233.00", "0.013"], ["71278.50", "0.008"], ["71297.60", "1.204"], ["71303.40", "0.000"], ["71323.30", "0.007"], ["71333.50", "0.141"], ["71340.60", "25.499"]], "a": [["71340.70", "2.414"], ["71341.50", "0.001"], ["71343.70", "0.005"], ["71347.80", "0.035"], ["71351.40", "0.511"], ["71357.00", "0.279"], ["71359.10", "0.290"], ["71397.50", "0.004"], ["72014.70", "0.000"], ["72054.10", "0.043"], ["72646.70", "0.687"], ["73480.90", "0.030"], ["74925.00", "0.066"], ["74938.60", "0.000"], ["89523.20", "0.000"]]}}
{"local_ts": 1773378049712, "server_ts": 1773378049436, "data": {"e": "depthUpdate", "E": 1773378049437, "T": 1773378049436, "s": "BTCUSDT", "U": 10100838401732, "u": 10100838407024, "pu": 10100838401628, "b": [["1000.00", "26.142"], ["5000.00", "101.418"], ["20940.60", "1.026"], ["21040.60", "0.774"], ["21140.60", "0.648"], ["21240.60", "0.252"], ["69917.20", "0.002"], ["70272.70", "2.983"], ["70627.20", "0.002"], ["71226.70", "0.243"], ["71327.60", "0.214"], ["71330.00", "0.086"]], "a": [["71340.70", "2.714"], ["71351.40", "0.511"], ["71584.00", "0.012"], ["72054.10", "0.043"], ["74909.10", "0.000"], ["74924.10", "0.002"], ["89523.20", "0.000"]]}}
{"local_ts": 1773378050733, "server_ts": 1773378050456, "data": {"e": "depthUpdate", "E": 1773378050459, "T": 1773378050456, "s": "BTCUSDT", "U": 10100838489889, "u": 10100838495331, "pu": 10100838489802, "b": [["5000.00", "101.418"], ["20840.60", "0.792"], ["20940.60", "1.008"], ["21040.60", "0.513"], ["21140.60", "0.387"], ["67742.10", "0.002"], ["69113.70", "0.000"], ["69916.30", "0.002"], ["70627.20", "0.002"], ["70628.90", "0.714"], ["71250.10", "0.352"], ["71294.30", "0.049"], ["71340.60", "25.516"]], "a": [["71343.00", "0.006"], ["71350.40", "0.385"], ["71369.40", "0.002"], ["71371.10", "1.307"], ["71400.00", "0.743"], ["72054.10", "0.043"], ["72065.80", "0.000"], ["73499.50", "1.164"], ["89523.20", "0.000"]]}}
{"local_ts": 1773378051759, "server_ts": 1773378051476, "data": {"e": "depthUpdate", "E": 1773378051479, "T": 1773378051476, "s": "BTCUSDT", "U": 10100838537825, "u": 10100838541773, "pu": 10100838537761, "b": [["1000.00", "26.142"], ["5000.00", "101.418"], ["20840.60", "1.278"], ["20940.60", "0.378"], ["21040.60", "0.522"], ["21240.60", "0.522"], ["57072.00", "0.000"], ["67766.70", "0.002"], ["69916.30", "0.000"], ["70627.20", "0.002"], ["70983.90", "0.144"], ["71176.50", "0.159"], ["71201.50", "0.041"], ["71265.00", "0.198"], ["71268.90", "0.944"], ["71300.00", "0.296"], ["71333.60", "0.009"], ["71339.50", "0.005"], ["71340.60", "24.445"]], "a": [["71340.70", "2.653"], ["71343.70", "0.005"], ["71347.70", "0.403"], ["71347.80", "0.224"], ["71347.90", "0.506"], ["71349.00", "0.005"], ["71349.60", "0.428"], ["71351.40", "0.420"], ["71352.60", "0.085"], ["71359.00", "0.025"], ["71359.20", "1.180"], ["71360.50", "0.152"], ["71360.70", "0.027"], ["71362.10", "0.026"], ["71369.30", "0.002"], ["71397.80", "0.102"], ["71455.00", "0.149"], ["71554.80", "0.006"], ["71696.40", "0.035"], ["72054.00", "0.036"], ["72054.10", "0.043"], ["72268.10", "3.359"], ["73168.60", "0.000"], ["74129.90", "0.002"], ["74932.00", "0.057"], ["89523.20", "0.000"]]}}
{"local_ts": 1773378052778, "server_ts": 1773378052500, "data": {"e": "depthUpdate", "E": 1773378052503, "T": 1773378052500, "s": "BTCUSDT", "U": 10100838618344, "u": 10100838624253, "pu": 10100838618278, "b": [["1000.00", "26.142"], ["5000.00", "101.418"], ["20840.60", "0.252"], ["20940.60", "0.648"], ["21140.60", "0.252"], ["21240.60", "1.548"], ["67769.50", "0.000"], ["69912.80", "0.002"], ["70627.20", "0.002"], ["71277.60", "1.203"], ["71292.20", "0.014"], ["71292.30", "0.002"], ["71319.20", "0.005"], ["71327.20", "0.057"], ["71331.10", "0.011"], ["71333.90", "0.380"]], "a": [["71340.70", "3.193"], ["71343.00", "0.006"], ["71346.10", "0.008"], ["71346.20", "0.217"], ["71346.90", "0.060"], ["71347.70", "0.189"], ["71347.80", "0.280"], ["71349.50", "0.004"], ["71349.60", "0.289"], ["71350.40", "0.151"], ["71351.40", "0.222"], ["71352.20", "0.132"], ["71352.50", "0.152"], ["71352.60", "0.005"], ["71353.10", "0.007"], ["71353.90", "0.007"], ["71354.60", "0.011"], ["71362.10", "0.328"], ["71373.50", "0.002"], ["71375.40", "0.004"], ["71379.50", "0.040"], ["71385.60", "0.071"], ["71394.20", "0.200"], ["71396.00", "0.589"], ["72054.10", "1.429"], ["72465.10", "0.591"], ["89523.20", "0.000"]]}}
{"local_ts": 1773378053799, "server_ts": 1773378053520, "data": {"e": "depthUpdate", "E": 1773378053525, "T": 1773378053520, "s": "BTCUSDT", "U": 10100838664091, "u": 10100838667519, "pu": 10100838663946, "b": [["5000.00", "101.418"], ["20840.60", "0.783"], ["21040.60", "0.117"], ["21140.60", "1.548"], ["21240.60", "0.252"], ["33000.00", "9.339"], ["67755.10", "0.006"], ["67756.30", "0.002"], ["69547.60", "2.684"], ["69912.80", "0.000"], ["70165.70", "1.976"], ["70275.80", "0.000"], ["70626.20", "1.422"], ["70627.20", "0.002"], ["70982.90", "0.003"], ["70983.90", "0.144"], ["71198.70", "0.067"], ["71264.60", "0.065"], ["71290.70", "0.815"]], "a": [["71342.90", "0.003"], ["71346.20", "0.217"], ["71347.70", "0.191"], ["71350.00", "0.040"], ["71353.40", "0.000"], ["71354.80", "0.455"], ["71357.80", "0.049"], ["71388.00", "0.164"], ["72054.10", "1.429"], ["72175.40", "0.554"], ["72295.10", "1.519"]]}}
{"local_ts": 1773378054823, "server_ts": 1773378054546, "data": {"e": "depthUpdate", "E": 1773378054547, "T": 1773378054546, "s": "BTCUSDT", "U": 10100838708754, "u": 10100838715704, "pu": 10100838708709, "b": [["1000.00", "26.142"], ["5000.00", "101.438"], ["20840.60", "0.018"], ["21040.60", "1.521"], ["21140.60", "0.279"], ["21240.60", "0.882"], ["69191.60", "3.466"], ["70627.20", "0.002"], ["71000.00", "25.862"], ["71089.90", "0.674"], ["71092.50", "3.771"], ["71149.60", "0.004"], ["71150.50", "17.486"], ["71150.60", "0.054"], ["71153.00", "3.848"], ["71251.40", "0.002"], ["71260.00", "0.241"], ["71323.20", "0.484"], ["71330.20", "0.012"], ["71333.50", "0.081"], ["71339.40", "0.002"]], "a": [["71340.70", "3.032"], ["71341.60", "0.007"], ["71347.80", "0.088"], ["71362.10", "0.643"], ["71375.40", "0.004"], ["71382.40", "0.002"], ["71408.90", "0.150"], ["71431.80", "0.002"], ["72054.10", "1.429"], ["74931.50", "0.050"]]}}
{"local_ts": 1773378055842, "server_ts": 1773378055565, "data": {"e": "depthUpdate", "E": 1773378055567, "T": 1773378055565, "s": "BTCUSDT", "U": 10100838755130, "u": 10100838761415, "pu": 10100838755014, "b": [["5000.00", "101.418"], ["20940.60", "1.251"], ["21040.60", "0.549"], ["21140.60", "0.747"], ["21240.60", "0.153"], ["33000.00", "9.339"], ["67746.30", "0.002"], ["67763.80", "0.000"], ["67773.00", "0.000"], ["67773.60", "0.025"], ["68759.30", "0.000"], ["69974.10", "11.302"], ["70323.70", "0.284"], ["70627.20", "0.002"], ["71172.90", "0.536"], ["71265.00", "0.198"], ["71282.80", "0.002"], ["71308.00", "0.415"], ["71313.50", "0.017"], ["71316.80", "0.072"], ["71335.90", "0.000"], ["71337.30", "0.056"], ["71340.60", "19.323"]], "a": [["71349.50", "0.004"], ["71349.60", "0.189"], ["71351.40", "0.222"], ["71351.60", "0.221"], ["71372.10", "0.017"], ["71374.80", "0.003"], ["71374.90", "0.000"], ["71375.40", "0.004"], ["71375.50", "0.007"], ["71375.60", "0.003"], ["71394.20", "0.200"], ["71396.00", "0.589"], ["71552.80", "0.006"], ["71589.10", "0.000"], ["71900.00", "33.618"], ["72053.80", "0.002"], ["72054.10", "1.429"], ["77835.30", "0.058"]]}}
{"local_ts": 1773378056863, "server_ts": 1773378056584, "data": {"e": "depthUpdate", "E": 1773378056587, "T": 1773378056584, "s": "BTCUSDT", "U": 10100838823812, "u": 10100838828938, "pu": 10100838823462, "b": [["1000.00", "26.142"], ["5000.00", "101.418"], ["20840.60", "0.981"], ["20940.60", "0.819"], ["21040.60", "0.612"], ["21140.60", "0.288"], ["67757.10", "0.076"], ["67773.00", "0.000"], ["70627.20", "0.709"], ["70628.80", "0.000"], ["70983.90", "0.214"], ["71172.90", "0.536"], ["71187.10", "0.007"], ["71246.90", "0.000"], ["71272.80", "0.570"], ["71282.70", "0.007"], ["71284.00", "0.859"], ["71304.20", "1.414"], ["71331.00", "0.002"], ["71331.60", "0.630"], ["71333.40", "0.211"], ["71339.50", "0.002"], ["71340.60", "18.675"]], "a": [["71340.70", "3.597"], ["71341.40", "0.002"], ["71341.50", "0.001"], ["71343.10", "0.003"], ["71345.90", "0.606"], ["71346.00", "0.430"], ["71346.10", "0.036"], ["71347.30", "0.602"], ["71347.70", "0.947"], ["71347.80", "0.596"], ["71349.20", "0.004"], ["71349.50", "0.805"], ["71349.60", "0.612"], ["71349.80", "0.003"], ["71351.40", "0.225"], ["71351.60", "0.405"], ["71351.90", "0.083"], ["71354.70", "1.872"], ["71354.80", "0.113"], ["71356.90", "0.678"], ["71357.40", "0.000"], ["71362.10", "0.130"], ["71362.60", "0.012"], ["71375.00", "0.575"], ["71394.20", "0.002"], ["71396.00", "0.450"], ["71396.60", "0.278"], ["71432.50", "0.065"], ["71492.70", "0.000"], ["72054.10", "1.429"], ["72320.60", "0.000"], ["74937.60", "0.000"]]}}
{"local_ts": 1773378057885, "server_ts": 1773378057607, "data": {"e": "depthUpdate", "E": 1773378057609, "T": 1773378057607, "s": "BTCUSDT", "U": 10100838877774, "u": 10100838882870, "pu": 10100838877672, "b": [["1000.00", "26.142"], ["5000.00", "101.398"], ["20840.60", "1.089"], ["20940.60", "0.477"], ["21040.60", "0.423"], ["21240.60", "0.711"], ["33000.00", "9.343"], ["67748.40", "0.000"], ["67773.00", "0.000"], ["67773.60", "0.027"], ["67773.70", "0.006"], ["68436.50", "0.027"], ["70349.00", "3.477"], ["70627.20", "0.709"]], "a": [["71340.70", "3.739"], ["71366.00", "0.006"], ["71367.90", "0.271"], ["71380.00", "0.022"], ["71450.00", "1.286"], ["71589.10", "0.000"], ["72054.10", "1.429"], ["74912.50", "0.052"]]}}
{"local_ts": 1773378058907, "server_ts": 1773378058628, "data": {"e": "depthUpdate", "E": 1773378058629, "T": 1773378058628, "s": "BTCUSDT", "U": 10100838927053, "u": 10100838933322, "pu": 10100838926943, "b": [["5000.00", "101.398"], ["20840.60", "0.342"], ["20940.60", "0.558"], ["21140.60", "0.450"], ["21240.60", "1.350"], ["67748.50", "0.000"], ["70234.80", "4.822"], ["70627.20", "0.709"], ["70983.90", "0.249"]], "a": [["71342.90", "0.003"], ["71367.50", "0.005"], ["71697.40", "0.201"], ["72054.10", "1.429"], ["72313.80", "1.513"], ["75945.60", "0.076"]]}}
{"local_ts": 1773378059932, "server_ts": 1773378059650, "data": {"e": "depthUpdate", "E": 1773378059651, "T": 1773378059650, "s": "BTCUSDT", "U": 10100838991527, "u": 10100838997238, "pu": 10100838991471, "b": [["1000.00", "26.142"], ["5000.00", "101.418"], ["20840.60", "0.693"], ["21040.60", "0.216"], ["21140.60", "1.548"], ["21240.60", "0.243"], ["67755.00", "0.306"], ["70106.10", "0.711"], ["70484.50", "2.260"], ["70627.20", "0.711"], ["70769.90", "0.357"], ["71172.90", "0.536"], ["71206.30", "0.137"], ["71206.80", "0.014"], ["71270.00", "0.064"], ["71273.90", "0.020"], ["71274.70", "0.069"], ["71279.70", "0.276"], ["71280.20", "3.356"], ["71281.90", "0.000"], ["71325.60", "0.004"], ["71329.80", "0.037"], ["71333.40", "0.211"], ["71333.80", "0.003"], ["71334.00", "0.010"], ["71338.30", "0.000"], ["71339.40", "0.002"], ["71340.40", "0.000"], ["71340.60", "14.636"]], "a": [["71340.70", "3.731"], ["71341.60", "0.008"], ["71343.20", "0.000"], ["71343.50", "0.001"], ["71347.70", "0.088"], ["71347.80", "0.342"], ["71347.90", "0.506"], ["71348.80", "0.432"], ["71349.40", "0.432"], ["71350.40", "0.020"], ["71350.80", "0.012"], ["71351.10", "0.186"], ["71351.40", "0.364"], ["71353.40", "0.277"], ["71361.80", "0.003"], ["71362.10", "0.465"], ["71371.00", "0.094"], ["71394.20", "0.002"], ["71395.00", "3.809"], ["71396.60", "0.275"], ["71455.00", "0.049"], ["72054.10", "1.429"], ["74917.60", "0.005"]]}}
{"local_ts": 1773378060951, "server_ts": 1773378060674, "data": {"e": "depthUpdate", "E": 1773378060675, "T": 1773378060674, "s": "BTCUSDT", "U": 10100839070254, "u": 10100839082013, "pu": 10100839070186, "b": [["5000.00", "101.418"], ["20940.60", "0.081"], ["21040.60", "1.548"], ["21140.60", "0.252"], ["21240.60", "0.819"], ["57072.00", "0.000"], ["68152.50", "0.000"], ["68487.00", "1.895"], ["70626.80", "14.987"], ["70627.20", "0.709"], ["71279.50", "0.674"], ["71286.30", "0.168"], ["71292.00", "0.004"], ["71292.10", "0.006"], ["71301.30", "0.679"], ["71305.00", "0.278"], ["71306.00", "0.002"], ["71306.90", "0.003"], ["71307.90", "0.028"], ["71308.90", "0.002"], ["71309.80", "0.147"], ["71313.30", "0.701"], ["71314.60", "0.007"], ["71317.40", "0.086"], ["71317.70", "0.001"], ["71318.90", "0.042"], ["71319.00", "0.029"], ["71320.10", "0.192"], ["71320.20", "0.006"], ["71321.40", "0.208"], ["71321.70", "0.042"], ["71322.80", "0.049"], ["71324.20", "0.016"], ["71325.00", "0.658"], ["71325.90", "0.017"], ["71326.10", "0.004"], ["71326.60", "0.315"], ["71327.10", "0.254"], ["71327.40", "0.052"], ["71328.70", "0.032"], ["71328.80", "0.032"], ["71328.90", "0.018"], ["71329.10", "0.001"], ["71329.30", "0.042"], ["71329.80", "0.037"], ["71331.00", "0.037"], ["71331.90", "0.005"], ["71332.50", "0.062"], ["71332.80", "0.006"], ["71333.50", "0.081"], ["71334.00", "0.010"], ["71334.30", "0.032"], ["71335.10", "0.008"], ["71336.10", "0.013"], ["71336.30", "0.029"], ["71337.20", "0.010"], ["71338.10", "0.111"], ["71338.30", "0.008"], ["71339.80", "0.033"], ["71340.10", "0.008"], ["71340.60", "15.142"]], "a": [["71340.70", "3.438"], ["71342.80", "0.024"], ["71343.90", "0.006"], ["71347.50", "0.225"], ["71347.80", "0.007"], ["71350.70", "0.084"], ["71351.10", "0.002"], ["71351.40", "0.225"], ["71352.60", "0.112"], ["71352.70", "0.166"], ["71352.80", "0.081"], ["71353.50", "0.004"], ["71362.10", "0.795"], ["71375.40", "0.004"], ["71375.80", "0.128"], ["71376.00", "0.004"], ["71588.90", "0.008"], ["71911.20", "0.000"], ["72054.00", "0.036"], ["72054.10", "1.429"], ["74922.20", "0.002"]]}}
{"local_ts": 1773378061971, "server_ts": 1773378061692, "data": {"e": "depthUpdate", "E": 1773378061695, "T": 1773378061692, "s": "BTCUSDT", "U": 10100839191721, "u": 10100839200228, "pu": 10100839191719, "b": [["1000.00", "26.142"], ["5000.00", "101.418"], ["20940.60", "1.440"], ["21040.60", "0.360"], ["21140.60", "0.846"], ["21240.60", "0.054"], ["67110.00", "0.088"], ["67756.30", "0.002"], ["70197.20", "0.000"], ["70291.90", "3.819"], ["70627.20", "0.709"], ["70983.90", "1.368"], ["71142.90", "0.002"], ["71158.70", "0.000"], ["71172.90", "0.536"], ["71188.30", "12.627"], ["71197.90", "0.157"], ["71216.50", "0.182"], ["71247.30", "6.278"], ["71247.50", "2.234"], ["71275.00", "0.106"], ["71282.80", "3.396"], ["71283.40", "0.950"], ["71285.10", "0.000"], ["71292.70", "0.088"], ["71304.20", "3.203"], ["71306.20", "1.200"], ["71315.90", "0.000"], ["71316.00", "0.018"], ["71316.60", "0.005"], ["71316.70", "0.002"], ["71319.00", "0.001"], ["71319.50", "0.964"], ["71320.20", "0.006"], ["71320.80", "0.001"], ["71321.00", "0.040"], ["71321.20", "0.002"], ["71321.50", "1.192"], ["71321.90", "0.287"], ["71322.70", "0.030"], ["71323.70", "0.000"], ["71327.00", "0.030"], ["71327.60", "0.450"], ["71329.20", "0.015"], ["71332.90", "0.006"], ["71333.50", "0.558"], ["71337.00", "0.004"], ["71337.10", "0.016"], ["71338.30", "0.000"], ["71339.70", "0.095"], ["71340.60", "15.199"]], "a": [["71340.70", "1.206"], ["71340.80", "0.026"], ["71343.00", "0.006"], ["71344.20", "0.000"], ["71346.90", "0.004"], ["71347.30", "0.068"], ["71348.00", "0.007"], ["71348.70", "0.034"], ["71349.30", "0.087"], ["71349.80", "0.001"], ["71350.70", "0.059"], ["71350.80", "0.023"], ["71351.40", "0.364"], ["71352.30", "0.148"], ["71352.40", "0.165"], ["71352.60", "0.032"], ["71353.70", "1.021"], ["71353.80", "0.451"], ["71354.30", "0.111"], ["71354.70", "0.007"], ["71355.40", "0.005"], ["71355.90", "0.247"], ["71356.00", "0.076"], ["71356.10", "0.241"], ["71356.20", "0.023"], ["71356.60", "0.004"], ["71356.80", "0.121"], ["71356.90", "0.678"], ["71357.70", "0.011"], ["71358.10", "1.191"], ["71358.20", "0.247"], ["71358.70", "0.027"], ["71359.30", "0.083"], ["71359.80", "0.334"], ["71362.10", "0.500"], ["71363.40", "0.000"], ["71367.90", "0.313"], ["71368.90", "0.045"], ["71369.90", "1.449"], ["71370.30", "0.066"], ["71370.80", "0.052"], ["71371.70", "0.000"], ["71372.00", "0.080"], ["71372.30", "0.000"], ["71372.40", "0.012"], ["71372.70", "0.005"], ["71373.60", "2.442"], ["71373.70", "0.888"], ["71374.00", "0.008"], ["71374.10", "0.003"], ["71374.20", "0.000"], ["71374.80", "0.012"], ["71374.90", "0.009"], ["71375.10", "0.029"], ["71375.60", "0.003"], ["71380.90", "0.983"], ["71391.60", "1.379"], ["71391.90", "0.003"], ["71394.20", "0.002"], ["71395.10", "3.326"], ["71397.80", "0.021"], ["71428.00", "2.375"], ["71430.40", "6.513"], ["71460.00", "0.210"], ["71488.80", "1.855"], ["71489.70", "12.696"], ["71490.10", "0.514"], ["72054.10", "1.429"], ["74921.70", "0.000"], ["89523.20", "0.000"]]}}
{"local_ts": 1773378062994, "server_ts": 1773378062716, "data": {"e": "depthUpdate", "E": 1773378062719, "T": 1773378062716, "s": "BTCUSDT", "U": 10100839291845, "u": 10100839298203, "pu": 10100839291733, "b": [["1000.00", "26.142"], ["5000.00", "101.418"], ["20840.60", "1.179"], ["20940.60", "0.621"], ["21040.60", "0.711"], ["21140.60", "0.189"], ["67768.60", "0.000"], ["69913.80", "0.015"], ["70234.80", "6.458"], ["70627.20", "0.709"], ["71172.90", "0.536"], ["71206.30", "0.151"], ["71206.80", "0.000"], ["71262.10", "0.091"], ["71276.40", "0.070"], ["71292.80", "0.196"], ["71292.90", "0.101"], ["71302.20", "1.299"], ["71307.80", "0.002"], ["71331.00", "0.037"], ["71332.20", "0.018"], ["71334.70", "0.001"], ["71334.80", "0.016"], ["71334.90", "0.000"], ["71335.10", "0.000"], ["71335.20", "0.042"], ["71335.50", "0.006"], ["71335.80", "0.055"], ["71335.90", "0.003"], ["71336.00", "0.004"], ["71336.30", "0.029"]], "a": [["71340.70", "1.990"], ["71343.00", "0.008"], ["71346.90", "0.070"], ["71347.80", "0.054"], ["71348.60", "0.002"], ["71349.10", "0.000"], ["71349.30", "0.095"], ["71349.40", "0.191"], ["71349.60", "0.006"], ["71350.50", "0.100"], ["71351.20", "0.209"], ["71351.40", "0.644"], ["71351.60", "0.229"], ["71352.00", "0.782"], ["71352.30", "0.156"], ["71352.50", "0.194"], ["71352.80", "0.089"], ["71353.30", "0.006"], ["71353.50", "0.044"], ["71353.80", "0.451"], ["71357.10", "0.005"], ["71358.60", "0.000"], ["71358.90", "0.146"], ["71360.60", "0.604"], ["71360.80", "0.044"], ["71361.80", "0.003"], ["71362.00", "0.006"], ["71362.20", "0.015"], ["71362.70", "0.734"], ["71362.80", "0.005"], ["71363.10", "1.656"], ["71363.40", "0.029"], ["71364.00", "0.012"], ["71364.20", "0.478"], ["71370.50", "0.006"], ["71371.30", "0.576"], ["71372.60", "0.029"], ["71373.80", "0.034"], ["71375.00", "0.575"], ["71404.90", "0.003"], ["71419.20", "0.183"], ["72054.10", "1.429"], ["74933.40", "0.002"], ["89523.20", "0.000"]]}}
{"local_ts": 1773378064019, "server_ts": 1773378063740, "data": {"e": "depthUpdate", "E": 1773378063741, "T": 1773378063740, "s": "BTCUSDT", "U": 10100839366834, "u": 10100839372297, "pu": 10100839366708, "b": [["5000.00", "101.418"], ["20840.60", "0.882"], ["20940.60", "0.576"], ["21040.60", "0.324"], ["21240.60", "0.918"], ["66612.10", "0.000"], ["67750.10", "2.213"], ["67773.50", "0.000"], ["70627.20", "2.123"], ["70769.90", "0.499"], ["70983.90", "1.368"], ["71036.50", "0.026"], ["71037.00", "0.300"], ["71043.60", "0.007"], ["71044.10", "0.000"], ["71050.70", "0.007"], ["71051.20", "0.000"], ["71057.80", "0.209"], ["71058.30", "0.000"], ["71064.90", "0.074"], ["71065.40", "0.002"], ["71072.00", "0.007"], ["71072.50", "0.000"], ["71079.10", "0.007"], ["71079.60", "0.003"], ["71086.20", "0.010"], ["71086.70", "0.000"], ["71093.10", "0.000"], ["71145.60", "0.001"], ["71214.70", "0.093"], ["71215.50", "0.001"], ["71226.90", "0.094"], ["71270.00", "0.164"], ["71292.70", "0.088"], ["71292.90", "0.101"], ["71321.70", "0.015"], ["71331.00", "0.012"], ["71332.70", "0.048"], ["71333.40", "0.425"], ["71333.60", "0.009"], ["71333.70", "0.046"], ["71333.80", "0.006"], ["71334.10", "0.035"], ["71334.70", "0.001"], ["71334.80", "0.001"], ["71335.10", "0.000"], ["71340.60", "14.760"]], "a": [["71343.60", "0.005"], ["71344.10", "0.006"], ["71344.60", "0.008"], ["71347.50", "0.013"], ["71347.80", "0.234"], ["71348.10", "0.044"], ["71349.10", "0.008"], ["71350.80", "0.027"], ["71351.40", "0.543"], ["71353.10", "0.072"], ["71353.60", "0.002"], ["71356.70", "0.033"], ["71356.90", "0.674"], ["71357.60", "0.000"], ["71358.00", "0.038"], ["71359.30", "0.104"], ["71359.70", "0.023"], ["71360.70", "0.027"], ["71361.00", "0.344"], ["71362.10", "0.321"], ["71372.60", "0.000"], ["71373.80", "0.005"], ["71375.00", "0.575"], ["71385.10", "1.403"], ["71385.50", "0.000"], ["71460.00", "0.210"], ["71460.10", "0.002"], ["71461.00", "0.000"], ["72054.10", "3.508"], ["72268.10", "5.017"], ["72292.60", "0.011"], ["72349.40", "0.000"], ["72351.30", "3.839"], ["72422.60", "4.033"], ["72508.20", "0.004"], ["72705.20", "0.000"], ["72723.80", "0.010"], ["89523.20", "0.000"]]}}
{"local_ts": 1773378065038, "server_ts": 1773378064760, "data": {"e": "depthUpdate", "E": 1773378064763, "T": 1773378064760, "s": "BTCUSDT", "U": 10100839489475, "u": 10100839496539, "pu": 10100839489380, "b": [["1000.00", "26.142"], ["5000.00", "101.418"], ["20840.60", "0.441"], ["20940.60", "0.459"], ["21140.60", "0.648"], ["21240.60", "1.152"], ["33000.00", "9.339"], ["64607.70", "0.058"], ["67767.10", "0.002"], ["70627.20", "2.830"], ["71035.50", "0.015"], ["71036.50", "0.019"], ["71042.60", "0.007"], ["71043.60", "0.000"], ["71049.70", "0.007"], ["71050.70", "0.000"], ["71056.80", "3.136"], ["71057.80", "0.202"], ["71063.90", "0.007"], ["71064.90", "0.067"], ["71071.00", "0.218"], ["71072.00", "0.000"], ["71078.10", "0.007"], ["71079.10", "0.000"], ["71085.20", "0.010"], ["71086.20", "0.003"], ["71213.80", "0.230"], ["71214.70", "0.091"], ["71292.10", "0.008"], ["71292.20", "0.012"], ["71310.20", "0.000"], ["71321.50", "0.030"], ["71322.80", "0.407"], ["71322.90", "0.030"], ["71323.40", "0.141"], ["71324.30", "0.043"], ["71324.90", "1.415"], ["71325.70", "0.006"]], "a": [["71346.10", "0.008"], ["71351.60", "0.452"], ["71352.10", "0.103"], ["71352.40", "0.794"], ["71353.60", "0.002"], ["71362.10", "0.262"], ["71378.30", "0.104"], ["71378.40", "0.134"], ["71458.30", "0.004"], ["71460.10", "0.000"], ["72054.10", "3.508"], ["72175.40", "1.107"], ["89523.20", "0.000"]]}}
{"local_ts": 1773378066061, "server_ts": 1773378065784, "data": {"e": "depthUpdate", "E": 1773378065785, "T": 1773378065784, "s": "BTCUSDT", "U": 10100839577476, "u": 10100839585563, "pu": 10100839577392, "b": [["5000.00", "101.418"], ["20840.60", "0.594"], ["21040.60", "0.378"], ["21140.60", "1.422"], ["21240.60", "0.306"], ["57073.00", "0.000"], ["67739.20", "0.000"], ["69913.80", "0.024"], ["69987.40", "0.031"], ["70627.20", "2.830"], ["71034.40", "0.683"], ["71035.50", "0.008"], ["71041.50", "0.007"], ["71042.60", "0.000"], ["71048.60", "0.007"], ["71049.70", "0.000"], ["71055.70", "0.007"], ["71056.80", "3.129"], ["71062.80", "0.007"], ["71063.90", "0.000"], ["71069.90", "0.021"], ["71071.00", "0.211"], ["71077.00", "1.170"], ["71078.10", "0.000"], ["71084.10", "0.009"], ["71085.20", "0.003"], ["71093.20", "0.019"], ["71172.90", "0.377"], ["71176.50", "0.159"], ["71203.20", "0.174"], ["71203.80", "0.000"], ["71212.50", "0.004"], ["71212.80", "0.000"], ["71213.80", "0.778"], ["71219.90", "0.002"], ["71220.90", "0.555"], ["71234.20", "2.094"], ["71235.20", "0.290"], ["71244.30", "0.070"], ["71248.20", "0.145"], ["71248.40", "0.022"], ["71251.50", "0.108"], ["71255.40", "0.142"], ["71255.60", "0.050"], ["71255.80", "0.079"], ["71258.60", "0.171"], ["71260.00", "0.341"], ["71262.50", "0.142"], ["71262.70", "0.036"], ["71270.00", "0.127"], ["71286.60", "0.044"], ["71287.60", "0.896"], ["71288.60", "0.319"], ["71289.00", "0.049"], ["71290.80", "0.042"], ["71293.90", "0.002"], ["71294.80", "0.927"], ["71295.00", "0.009"], ["71295.60", "0.139"], ["71296.60", "0.034"], ["71297.60", "0.004"], ["71297.90", "1.807"], ["71299.90", "0.042"], ["71301.60", "0.000"], ["71314.00", "0.002"], ["71318.10", "0.000"], ["71318.30", "0.021"], ["71319.10", "0.000"], ["71319.30", "0.017"], ["71321.70", "0.000"], ["71321.90", "0.147"], ["71322.00", "0.142"], ["71322.20", "0.005"], ["71322.30", "0.000"], ["71322.40", "0.008"], ["71322.50", "0.037"], ["71322.60", "0.000"], ["71322.70", "0.030"], ["71322.90", "0.001"], ["71324.50", "0.055"], ["71324.70", "0.026"], ["71325.50", "0.011"], ["71326.10", "0.033"], ["71326.50", "0.005"], ["71326.70", "0.004"], ["71327.00", "0.010"], ["71327.40", "0.008"], ["71328.00", "0.019"], ["71328.10", "0.005"], ["71328.70", "0.032"], ["71330.20", "0.092"], ["71332.30", "0.665"], ["71332.70", "0.006"], ["71333.20", "0.002"], ["71333.60", "0.009"], ["71340.60", "13.534"]], "a": [["71340.70", "3.803"], ["71341.90", "0.003"], ["71344.20", "0.000"], ["71346.20", "0.486"], ["71347.80", "0.058"], ["71349.60", "0.117"], ["71351.40", "0.602"], ["71362.10", "0.485"], ["71364.30", "0.068"], ["71376.30", "0.002"], ["71376.40", "0.132"], ["71381.90", "0.049"], ["71384.30", "0.408"], ["71397.80", "0.241"], ["71398.60", "0.276"], ["71400.00", "0.755"], ["71419.50", "0.180"], ["71419.80", "0.310"], ["71422.80", "0.226"], ["71426.60", "0.231"], ["71426.90", "0.133"], ["71429.90", "0.070"], ["71431.50", "0.216"], ["71432.50", "0.065"], ["71433.80", "0.357"], ["71434.10", "2.019"], ["71437.10", "0.072"], ["71438.60", "0.200"], ["71439.60", "0.000"], ["71450.00", "1.286"], ["71457.80", "0.002"], ["71458.30", "0.002"], ["71745.30", "0.552"], ["71746.30", "0.000"], ["72054.10", "3.508"], ["72362.80", "0.958"], ["72362.90", "9.591"], ["72469.90", "0.098"], ["72505.40", "0.111"], ["74942.40", "0.002"], ["89523.20", "0.000"]]}}
{"local_ts": 1773378067081, "server_ts": 1773378066804, "data": {"e": "depthUpdate", "E": 1773378066807, "T": 1773378066804, "s": "BTCUSDT", "U": 10100839639841, "u": 10100839644871, "pu": 10100839639769, "b": [["1000.00", "26.142"], ["5000.00", "101.418"], ["20940.60", "0.180"], ["21040.60", "1.548"], ["21140.60", "0.252"], ["21240.60", "0.720"], ["33000.00", "9.343"], ["67756.90", "0.002"], ["67766.80", "0.000"], ["70152.70", "0.002"], ["70234.80", "10.438"], ["70627.20", "2.830"], ["70983.90", "1.790"], ["71033.10", "0.007"], ["71034.40", "0.676"], ["71040.20", "0.007"], ["71041.50", "0.000"], ["71047.30", "0.025"], ["71048.60", "0.000"], ["71054.40", "0.007"], ["71055.70", "0.000"], ["71061.50", "0.007"], ["71062.80", "0.000"], ["71068.60", "0.206"], ["71069.90", "0.014"], ["71075.70", "0.007"], ["71077.00", "1.163"], ["71082.80", "0.026"], ["71084.10", "0.002"], ["71210.90", "0.028"], ["71212.50", "0.002"], ["71292.20", "0.012"], ["71292.50", "0.692"], ["71317.60", "0.025"], ["71331.10", "0.001"], ["71336.40", "0.031"]], "a": [["71343.00", "0.006"], ["71343.50", "0.001"], ["71347.40", "0.016"], ["71350.60", "0.006"], ["71350.70", "0.088"], ["71351.40", "0.404"], ["71386.60", "0.675"], ["71386.90", "0.000"], ["71457.40", "0.044"], ["71457.80", "0.000"], ["72054.10", "3.508"], ["89523.20", "0.000"]]}}
{"local_ts": 1773378068106, "server_ts": 1773378067829, "data": {"e": "depthUpdate", "E": 1773378067831, "T": 1773378067829, "s": "BTCUSDT", "U": 10100839703992, "u": 10100839709413, "pu": 10100839703890, "b": [["1000.00", "26.142"], ["5000.00", "101.398"], ["20840.60", "0.045"], ["20940.60", "1.557"], ["21040.60", "0.243"], ["21140.60", "0.855"], ["21240.60", "0.000"], ["64206.50", "0.018"], ["67773.00", "0.000"], ["69913.80", "0.012"], ["70197.30", "0.853"], ["70250.40", "0.000"], ["70627.20", "2.830"], ["70738.80", "0.000"], ["70743.80", "0.002"], ["71033.10", "0.000"], ["71035.00", "0.007"], ["71040.20", "0.000"], ["71042.10", "0.346"], ["71047.30", "0.018"], ["71049.20", "0.007"], ["71054.40", "0.000"], ["71056.30", "0.286"], ["71061.50", "0.000"], ["71063.40", "0.007"], ["71068.60", "0.199"], ["71070.50", "0.009"], ["71075.70", "0.000"], ["71077.60", "0.009"], ["71082.80", "0.019"], ["71084.70", "0.009"], ["71093.20", "0.429"], ["71210.90", "0.026"], ["71213.00", "0.052"], ["71270.00", "0.227"], ["71273.70", "0.674"], ["71331.10", "0.001"], ["71340.60", "14.206"]], "a": [["71346.30", "0.010"], ["71350.50", "0.085"], ["71351.00", "0.345"], ["71353.60", "0.002"], ["71354.10", "0.004"], ["71360.40", "0.020"], ["71361.10", "0.032"], ["71361.70", "0.242"], ["71362.90", "0.006"], ["71371.70", "0.029"], ["71372.90", "0.031"], ["71376.70", "0.006"], ["71377.40", "1.345"], ["71378.20", "0.146"], ["71455.00", "0.149"], ["71457.40", "0.042"], ["71459.80", "0.018"], ["71552.80", "0.000"], ["71665.80", "0.008"], ["72054.00", "0.036"], ["72054.10", "3.508"], ["72218.60", "1.383"], ["72531.70", "6.501"], ["72767.50", "0.005"], ["74930.40", "0.002"], ["78474.80", "0.018"], ["89523.20", "0.000"]]}}
