{"local_ts": 1773384761398, "server_ts": 1773384761182, "data": {"e": "depthUpdate", "E": 1773384761183, "T": 1773384761182, "s": "BTCUSDT", "U": 10101359059953, "u": 10101359074559, "pu": 10101359059918, "b": [["5000.00", "101.418"], ["20875.50", "0.756"], ["20975.50", "0.144"], ["21075.50", "1.278"], ["21175.50", "0.522"], ["33000.00", "9.339"], ["40000.00", "49.609"], ["67709.50", "0.000"], ["68424.50", "0.637"], ["69850.00", "0.910"], ["70562.70", "0.000"], ["70986.60", "0.000"], ["71017.20", "0.703"], ["71074.00", "2.867"], ["71074.60", "0.002"], ["71109.50", "0.279"], ["71177.50", "0.513"], ["71180.40", "1.250"], ["71181.00", "0.072"], ["71181.40", "0.080"], ["71181.50", "0.014"], ["71184.20", "0.002"], ["71188.60", "0.405"], ["71188.70", "0.002"], ["71191.30", "0.339"], ["71195.70", "0.072"], ["71195.80", "0.000"], ["71209.30", "0.322"], ["71211.40", "0.292"], ["71214.90", "0.022"], ["71215.00", "0.655"], ["71226.60", "0.023"], ["71227.00", "0.035"], ["71228.20", "0.220"], ["71231.90", "0.004"], ["71232.60", "0.069"], ["71234.60", "0.282"], ["71235.60", "0.010"], ["71238.90", "0.016"], ["71239.20", "0.000"], ["71240.20", "0.481"], ["71241.40", "0.024"], ["71242.00", "0.247"], ["71242.70", "0.000"], ["71243.50", "0.000"], ["71245.30", "0.072"], ["71246.90", "0.372"], ["71247.50", "0.003"], ["71248.30", "0.000"], ["71250.40", "0.009"], ["71250.70", "0.015"], ["71252.80", "0.000"], ["71253.10", "0.505"], ["71255.00", "0.017"], ["71255.30", "0.654"], ["71255.60", "0.070"], ["71256.30", "0.000"], ["71256.50", "0.343"], ["71256.60", "1.201"], ["71256.70", "0.815"], ["71256.80", "0.802"], ["71257.00", "0.810"], ["71257.30", "0.000"], ["71258.10", "0.005"], ["71258.30", "0.032"], ["71258.50", "0.003"], ["71258.60", "0.013"], ["71258.70", "0.006"], ["71258.80", "1.054"], ["71259.00", "0.051"], ["71259.10", "0.001"], ["71259.40", "0.003"], ["71259.70", "0.140"], ["71259.80", "0.032"], ["71260.30", "0.346"], ["71260.50", "0.005"], ["71260.80", "0.002"], ["71260.90", "0.028"], ["71261.10", "0.466"], ["71261.30", "0.015"], ["71261.70", "0.056"], ["71261.90", "0.007"], ["71262.10", "0.072"], ["71262.70", "0.110"], ["71263.40", "0.002"], ["71263.70", "0.000"], ["71263.80", "0.004"], ["71264.20", "0.007"], ["71264.30", "0.000"], ["71264.60", "0.007"], ["71264.70", "0.006"], ["71264.80", "1.051"], ["71264.90", "0.012"], ["71265.00", "0.029"], ["71265.30", "0.371"], ["71265.50", "0.007"], ["71266.20", "0.000"], ["71266.30", "0.084"], ["71266.80", "0.002"], ["71267.40", "0.005"], ["71267.50", "0.000"], ["71267.80", "0.005"], ["71268.00", "0.007"], ["71268.20", "0.002"], ["71268.30", "0.002"], ["71268.40", "0.050"], ["71268.70", "0.324"], ["71268.80", "0.005"], ["71269.20", "0.229"], ["71269.50", "0.010"], ["71269.90", "0.000"], ["71270.30", "0.002"], ["71270.60", "0.000"], ["71271.20", "0.001"], ["71271.90", "0.010"], ["71272.00", "0.000"], ["71272.20", "0.000"], ["71272.90", "0.000"], ["71273.00", "0.002"], ["71273.40", "0.003"], ["71274.50", "0.002"], ["71274.70", "0.002"], ["71275.00", "0.000"], ["71275.10", "0.000"], ["71275.40", "0.004"], ["71275.50", "0.596"]], "a": [["71275.60", "3.425"], ["71276.10", "0.460"], ["71278.10", "0.000"], ["71279.20", "0.206"], ["71279.80", "0.007"], ["71280.80", "0.005"], ["71281.10", "0.002"], ["71282.10", "0.071"], ["71282.30", "0.655"], ["71282.60", "0.185"], ["71282.70", "0.366"], ["71283.30", "0.007"], ["71283.40", "0.633"], ["71283.80", "0.003"], ["71284.40", "0.145"], ["71284.50", "0.580"], ["71285.20", "0.015"], ["71285.50", "0.612"], ["71285.60", "0.606"], ["71285.80", "0.386"], ["71285.90", "0.747"], ["71286.00", "0.034"], ["71286.10", "0.000"], ["71286.20", "0.008"], ["71286.30", "0.296"], ["71286.40", "0.689"], ["71286.50", "1.432"], ["71286.90", "0.023"], ["71287.50", "0.397"], ["71287.60", "0.102"], ["71287.90", "0.010"], ["71288.10", "0.126"], ["71288.20", "0.037"], ["71288.70", "0.154"], ["71288.80", "0.137"], ["71289.00", "0.283"], ["71289.10", "0.232"], ["71289.40", "0.141"], ["71289.60", "0.428"], ["71289.70", "0.071"], ["71289.90", "0.288"], ["71291.10", "0.650"], ["71291.30", "0.003"], ["71291.40", "1.052"], ["71292.20", "0.000"], ["71292.40", "0.090"], ["71292.50", "0.007"], ["71293.50", "0.120"], ["71293.70", "0.057"], ["71294.10", "0.000"], ["71294.30", "0.506"], ["71294.60", "0.004"], ["71294.90", "0.971"], ["71295.00", "0.029"], ["71295.70", "0.002"], ["71297.00", "0.493"], ["71297.30", "0.248"], ["71297.70", "0.509"], ["71298.90", "0.000"], ["71299.60", "0.000"], ["71300.40", "0.007"], ["71301.60", "0.074"], ["71301.80", "0.009"], ["71302.60", "0.005"], ["71302.80", "0.034"], ["71306.80", "0.093"], ["71307.50", "0.133"], ["71307.70", "0.298"], ["71308.30", "0.002"], ["71308.90", "0.002"], ["71311.20", "0.470"], ["71320.00", "0.764"], ["71324.10", "0.000"], ["71328.50", "0.140"], ["71338.70", "0.003"], ["71342.40", "0.006"], ["71345.90", "0.169"], ["71348.40", "0.084"], ["71349.20", "0.002"], ["71355.50", "0.285"], ["71356.30", "0.040"], ["71359.80", "0.171"], ["71359.90", "2.014"], ["71362.60", "0.007"], ["71363.40", "0.003"], ["71363.60", "0.038"], ["71369.70", "0.097"], ["71370.50", "0.005"], ["71371.80", "0.002"], ["71376.80", "0.007"], ["71377.60", "0.000"], ["71383.90", "0.106"], ["71384.70", "0.062"], ["71387.90", "0.042"], ["71391.00", "0.007"], ["71391.80", "0.250"], ["71398.10", "0.296"], ["71398.90", "0.000"], ["71502.50", "0.006"], ["71644.50", "0.000"], ["71795.90", "0.043"], ["71988.30", "0.111"], ["71988.40", "1.391"], ["72011.30", "0.010"], ["72226.60", "0.004"], ["72701.10", "0.033"], ["89523.20", "0.006"], ["100000.00", "15.554"]]}}
{"local_ts": 1773384762417, "server_ts": 1773384762202, "data": {"e": "depthUpdate", "E": 1773384762203, "T": 1773384762202, "s": "BTCUSDT", "U": 10101359138976, "u": 10101359145839, "pu": 10101359138901, "b": [["1000.00", "27.792"], ["5000.00", "101.418"], ["20775.50", "0.621"], ["20875.50", "0.279"], ["20975.50", "1.008"], ["21075.50", "0.792"], ["57020.00", "0.002"], ["70562.70", "0.708"], ["71140.50", "0.039"], ["71141.90", "0.021"], ["71213.10", "0.243"], ["71239.90", "0.054"]], "a": [["71311.20", "0.311"], ["71346.40", "0.007"], ["71348.40", "0.077"], ["71353.50", "0.268"], ["71355.50", "0.278"], ["71360.60", "0.012"], ["71362.60", "0.000"], ["71367.70", "0.007"], ["71369.70", "0.090"], ["71374.80", "0.007"], ["71376.80", "0.000"], ["71381.90", "0.098"], ["71383.90", "0.099"], ["71389.00", "0.007"], ["71391.00", "0.000"], ["71396.10", "0.007"], ["71398.10", "0.289"], ["71795.90", "0.043"], ["71988.40", "1.387"], ["72011.30", "0.010"], ["72208.70", "0.000"], ["72226.60", "0.004"], ["72442.00", "0.006"], ["72657.40", "0.004"], ["74845.80", "0.002"], ["74849.50", "0.050"], ["89523.20", "0.006"]]}}
{"local_ts": 1773384763453, "server_ts": 1773384763219, "data": {"e": "depthUpdate", "E": 1773384763225, "T": 1773384763219, "s": "BTCUSDT", "U": 10101359225380, "u": 10101359258459, "pu": 10101359225188, "b": [["5000.00", "101.398"], ["20775.50", "0.432"], ["20875.50", "0.684"], ["20975.50", "1.116"], ["21175.50", "0.468"], ["33000.00", "9.343"], ["35631.60", "0.000"], ["67709.70", "0.003"], ["70092.50", "1.163"], ["70257.50", "0.304"], ["70391.90", "0.010"], ["70562.70", "0.708"], ["70793.10", "0.006"], ["70795.60", "0.002"], ["70803.70", "0.000"], ["70808.00", "0.029"], ["70813.10", "0.000"], ["70819.10", "0.000"], ["70822.10", "0.000"], ["70825.20", "0.003"], ["70833.40", "0.000"], ["70835.70", "0.000"], ["70865.90", "0.012"], ["70868.40", "0.000"], ["70876.60", "0.005"], ["70882.90", "0.018"], ["70888.10", "3.419"], ["70894.10", "0.000"], ["70895.90", "0.000"], ["70904.60", "0.000"], ["70912.30", "0.002"], ["70915.10", "0.000"], ["70918.60", "0.061"], ["70919.10", "0.026"], ["70921.10", "0.078"], ["70927.10", "0.048"], ["70927.30", "0.002"], ["70941.00", "0.008"], ["70944.00", "0.008"], ["70947.50", "0.000"], ["70952.10", "0.000"], ["70955.00", "0.159"], ["70957.00", "0.000"], ["70962.90", "0.003"], ["70963.10", "0.004"], ["70966.50", "0.004"], ["70970.40", "0.000"], ["70973.70", "0.000"], ["70976.50", "0.000"], ["70980.20", "0.000"], ["70981.80", "0.003"], ["70988.00", "0.020"], ["70990.20", "0.000"], ["70999.10", "2.036"], ["71016.70", "0.004"], ["71020.10", "0.002"], ["71027.30", "0.000"], ["71030.60", "0.002"], ["71031.00", "0.012"], ["71038.40", "0.000"], ["71044.50", "0.001"], ["71050.10", "0.000"], ["71056.10", "0.454"], ["71060.10", "0.061"], ["71065.10", "0.011"], ["71070.10", "0.002"], ["71074.80", "0.000"], ["71077.80", "2.328"], ["71099.50", "0.008"], ["71103.30", "0.000"], ["71105.50", "0.040"], ["71107.00", "0.023"], ["71110.10", "0.282"], ["71114.30", "0.002"], ["71121.30", "0.013"], ["71124.60", "0.000"], ["71128.50", "0.009"], ["71131.40", "0.012"], ["71135.10", "0.003"], ["71142.70", "0.508"], ["71146.50", "0.000"], ["71150.30", "0.000"], ["71152.80", "0.000"], ["71155.40", "0.078"], ["71159.50", "0.320"], ["71161.10", "0.077"], ["71164.50", "0.284"], ["71168.40", "0.000"], ["71169.00", "0.081"], ["71171.50", "0.065"], ["71171.70", "0.039"], ["71172.10", "7.597"], ["71172.40", "0.036"], ["71172.80", "0.099"], ["71173.10", "0.025"], ["71173.40", "0.032"], ["71174.10", "0.000"], ["71174.80", "0.000"], ["71175.40", "0.104"], ["71178.80", "0.422"], ["71180.50", "0.427"], ["71182.80", "0.000"], ["71185.40", "0.077"], ["71185.90", "0.002"], ["71188.60", "0.045"], ["71192.90", "0.000"], ["71196.00", "0.004"], ["71196.20", "0.026"], ["71202.00", "0.575"], ["71202.10", "0.300"], ["71204.30", "0.009"], ["71207.70", "0.024"], ["71209.30", "0.320"], ["71209.40", "7.721"], ["71210.60", "0.960"], ["71211.40", "0.092"], ["71215.00", "0.025"], ["71215.10", "0.032"], ["71217.70", "0.716"], ["71218.50", "0.131"], ["71220.30", "0.003"], ["71220.70", "0.176"], ["71221.10", "0.005"], ["71222.00", "0.009"], ["71223.00", "0.000"], ["71225.20", "1.559"], ["71225.30", "0.001"], ["71225.60", "0.003"], ["71225.90", "0.003"], ["71229.40", "0.017"], ["71231.30", "0.000"], ["71232.10", "0.000"], ["71233.10", "0.000"], ["71233.40", "0.005"], ["71235.60", "0.010"], ["71236.00", "0.074"], ["71236.10", "0.002"], ["71238.10", "0.009"], ["71238.30", "0.000"], ["71239.00", "0.017"], ["71239.10", "0.102"], ["71239.90", "0.051"], ["71240.20", "0.016"], ["71241.40", "0.022"], ["71241.50", "0.209"], ["71241.70", "0.000"], ["71241.90", "0.020"], ["71242.80", "0.000"], ["71243.20", "0.000"], ["71243.30", "0.006"], ["71243.40", "0.060"], ["71243.90", "0.014"], ["71244.40", "0.005"], ["71245.10", "0.324"], ["71245.20", "0.019"], ["71246.30", "0.009"], ["71246.50", "0.003"], ["71246.60", "0.053"], ["71246.90", "0.004"], ["71249.10", "0.027"], ["71249.40", "0.021"], ["71249.90", "0.010"], ["71250.40", "0.002"], ["71250.80", "0.543"], ["71251.00", "0.006"], ["71252.00", "0.004"], ["71252.80", "0.000"], ["71252.90", "0.034"], ["71253.00", "0.010"], ["71253.40", "0.004"], ["71253.50", "0.002"], ["71253.70", "0.508"], ["71254.20", "0.003"], ["71254.30", "0.019"], ["71254.40", "0.004"], ["71254.70", "0.003"], ["71255.90", "0.377"], ["71256.40", "0.004"], ["71256.80", "0.800"], ["71257.20", "0.008"], ["71257.30", "0.280"], ["71258.00", "0.010"], ["71258.20", "0.002"], ["71258.30", "0.000"], ["71258.90", "0.292"], ["71259.20", "0.004"], ["71260.10", "0.002"], ["71260.20", "0.005"], ["71260.30", "0.066"], ["71260.90", "0.008"], ["71261.00", "0.016"], ["71262.00", "0.113"], ["71263.00", "0.171"], ["71263.20", "0.000"], ["71263.50", "0.515"], ["71263.70", "0.029"], ["71263.90", "0.004"], ["71264.50", "0.000"], ["71265.10", "0.017"], ["71265.30", "0.001"], ["71265.50", "0.007"], ["71265.60", "0.028"], ["71265.70", "0.512"], ["71266.10", "0.025"], ["71266.60", "0.609"], ["71266.80", "0.002"], ["71266.90", "0.006"], ["71267.50", "0.000"], ["71267.90", "0.014"], ["71268.10", "0.011"], ["71268.40", "0.363"], ["71268.60", "0.691"], ["71268.70", "0.000"], ["71268.80", "0.043"], ["71268.90", "0.021"], ["71269.20", "0.000"], ["71269.30", "0.004"], ["71269.40", "0.036"], ["71269.50", "0.007"], ["71270.00", "0.049"], ["71270.60", "0.003"], ["71271.20", "0.015"], ["71271.30", "0.338"], ["71271.90", "0.007"], ["71272.40", "0.063"], ["71272.60", "0.003"], ["71273.00", "0.036"], ["71273.10", "0.003"], ["71274.40", "0.004"], ["71275.00", "0.034"], ["71275.50", "2.330"], ["71275.60", "0.007"], ["71275.70", "0.502"], ["71275.90", "0.482"], ["71276.00", "2.669"], ["71276.10", "0.004"], ["71276.20", "0.008"], ["71276.40", "0.936"], ["71277.00", "0.936"], ["71277.50", "0.520"], ["71278.10", "0.530"], ["71279.10", "0.511"], ["71279.20", "1.256"]], "a": [["71275.60", "0.000"], ["71275.70", "0.000"], ["71275.80", "0.000"], ["71275.90", "0.000"], ["71276.00", "0.000"], ["71276.10", "0.000"], ["71276.20", "0.000"], ["71276.30", "0.000"], ["71276.40", "0.000"], ["71276.50", "0.000"], ["71276.60", "0.000"], ["71276.70", "0.000"], ["71276.80", "0.000"], ["71276.90", "0.000"], ["71277.00", "0.000"], ["71277.10", "0.000"], ["71277.20", "0.000"], ["71277.40", "0.000"], ["71277.50", "0.000"], ["71277.60", "0.000"], ["71277.70", "0.000"], ["71277.80", "0.000"], ["71277.90", "0.000"], ["71278.00", "0.000"], ["71278.20", "0.000"], ["71278.40", "0.000"], ["71278.50", "0.000"], ["71278.60", "0.000"], ["71278.70", "0.000"], ["71278.80", "0.000"], ["71278.90", "0.000"], ["71279.00", "0.000"], ["71279.10", "0.000"], ["71279.20", "0.000"], ["71279.60", "0.005"], ["71279.90", "0.003"], ["71280.30", "0.021"], ["71280.90", "0.000"], ["71281.00", "0.013"], ["71281.20", "0.006"], ["71281.90", "0.000"], ["71282.10", "0.008"], ["71282.20", "0.007"], ["71282.60", "0.005"], ["71282.70", "0.252"], ["71282.80", "0.004"], ["71282.90", "0.009"], ["71283.40", "0.001"], ["71283.70", "0.094"], ["71283.80", "0.028"], ["71284.00", "0.005"], ["71284.30", "0.003"], ["71284.50", "0.003"], ["71284.60", "0.087"], ["71285.00", "0.035"], ["71285.30", "0.002"], ["71285.40", "0.003"], ["71285.80", "0.002"], ["71286.00", "0.029"], ["71286.40", "0.007"], ["71286.80", "0.000"], ["71286.90", "0.002"], ["71287.00", "0.353"], ["71287.20", "0.000"], ["71287.30", "0.003"], ["71287.50", "0.065"], ["71287.70", "0.000"], ["71288.60", "0.005"], ["71288.90", "0.252"], ["71289.00", "0.001"], ["71290.30", "0.006"], ["71290.40", "0.007"], ["71290.50", "0.000"], ["71291.00", "0.164"], ["71291.10", "0.016"], ["71291.40", "0.008"], ["71291.60", "0.001"], ["71291.70", "0.004"], ["71291.90", "0.007"], ["71292.70", "0.001"], ["71293.00", "0.004"], ["71293.30", "0.003"], ["71293.40", "0.260"], ["71293.70", "0.055"], ["71293.80", "0.003"], ["71294.30", "0.000"], ["71294.60", "0.074"], ["71294.90", "0.336"], ["71295.80", "0.118"], ["71296.40", "0.058"], ["71296.50", "0.000"], ["71296.70", "0.000"], ["71297.00", "0.278"], ["71297.10", "0.003"], ["71297.20", "0.004"], ["71297.90", "0.001"], ["71299.70", "0.000"], ["71299.80", "0.007"], ["71300.00", "4.979"], ["71300.70", "0.000"], ["71301.60", "0.071"], ["71301.90", "0.087"], ["71302.50", "0.015"], ["71304.10", "0.005"], ["71304.20", "0.009"], ["71306.00", "0.290"], ["71306.10", "0.006"], ["71306.80", "0.022"], ["71307.60", "0.011"], ["71308.90", "0.002"], ["71309.00", "0.007"], ["71309.10", "0.003"], ["71309.20", "0.015"], ["71309.40", "0.980"], ["71310.40", "0.004"], ["71312.00", "0.076"], ["71312.20", "0.282"], ["71312.30", "0.003"], ["71312.90", "1.207"], ["71313.30", "0.006"], ["71314.50", "0.017"], ["71314.60", "0.085"], ["71315.50", "0.073"], ["71315.90", "0.388"], ["71316.00", "0.625"], ["71316.10", "0.002"], ["71316.60", "0.108"], ["71316.80", "0.102"], ["71316.90", "0.297"], ["71319.10", "0.002"], ["71319.40", "0.506"], ["71320.00", "0.024"], ["71320.70", "0.159"], ["71321.00", "0.725"], ["71321.10", "0.067"], ["71321.30", "0.004"], ["71322.70", "1.049"], ["71322.80", "0.096"], ["71323.50", "1.325"], ["71323.60", "6.382"], ["71325.80", "0.002"], ["71327.20", "0.018"], ["71327.80", "0.000"], ["71328.60", "0.063"], ["71328.80", "0.042"], ["71330.80", "0.003"], ["71332.00", "0.335"], ["71332.50", "0.000"], ["71336.00", "0.000"], ["71336.10", "0.019"], ["71336.30", "0.038"], ["71336.90", "0.033"], ["71338.20", "0.003"], ["71338.80", "0.002"], ["71340.80", "0.059"], ["71341.60", "0.003"], ["71344.50", "0.256"], ["71344.90", "0.002"], ["71348.90", "1.676"], ["71350.10", "0.030"], ["71352.10", "0.000"], ["71353.20", "0.005"], ["71353.40", "0.000"], ["71353.90", "0.205"], ["71354.30", "0.004"], ["71355.10", "0.004"], ["71356.70", "0.073"], ["71364.80", "0.000"], ["71366.50", "1.300"], ["71366.60", "0.005"], ["71372.30", "1.049"], ["71374.30", "0.002"], ["71379.30", "1.049"], ["71379.40", "0.003"], ["71381.80", "0.000"], ["71385.40", "0.000"], ["71386.50", "0.000"], ["71395.80", "0.000"], ["71397.80", "0.358"], ["71399.30", "1.555"], ["71399.60", "0.006"], ["71403.10", "0.002"], ["71403.80", "0.000"], ["71409.30", "1.054"], ["71409.60", "0.000"], ["71414.00", "0.005"], ["71417.80", "0.145"], ["71421.30", "0.004"], ["71438.70", "0.490"], ["71446.60", "0.000"], ["71446.70", "0.163"], ["71452.90", "0.062"], ["71454.20", "0.000"], ["71461.10", "0.095"], ["71463.80", "0.000"], ["71467.50", "1.120"], ["71477.90", "0.506"], ["71478.00", "0.000"], ["71478.10", "0.000"], ["71482.40", "0.000"], ["71494.30", "0.012"], ["71499.90", "0.009"], ["71502.60", "1.200"], ["71508.70", "0.306"], ["71511.70", "0.000"], ["71532.30", "0.000"], ["71536.80", "0.000"], ["71539.30", "0.103"], ["71544.50", "0.002"], ["71544.60", "4.103"], ["71546.70", "0.000"], ["71553.00", "0.002"], ["71554.90", "0.054"], ["71561.50", "0.000"], ["71568.80", "0.000"], ["71572.60", "0.000"], ["71577.10", "0.000"], ["71583.00", "0.000"], ["71604.10", "0.000"], ["71608.40", "0.224"], ["71614.40", "0.000"], ["71615.90", "0.000"], ["71619.90", "0.000"], ["71637.90", "0.000"], ["71643.90", "0.004"], ["71651.10", "0.049"], ["71654.90", "0.000"], ["71665.90", "0.007"], ["71673.50", "0.000"], ["71676.00", "0.096"], ["71679.60", "0.000"], ["71684.20", "0.463"], ["71694.60", "0.009"], ["71704.90", "0.006"], ["71709.90", "0.000"], ["71719.60", "0.000"], ["71731.90", "0.003"], ["71795.80", "0.304"], ["71988.30", "0.111"], ["71988.40", "2.776"], ["72011.10", "0.004"], ["72226.50", "1.179"], ["72438.20", "0.013"], ["72441.90", "0.004"], ["74863.70", "0.002"], ["89523.20", "0.006"]]}}
{"local_ts": 1773384764464, "server_ts": 1773384764244, "data": {"e": "depthUpdate", "E": 1773384764245, "T": 1773384764244, "s": "BTCUSDT", "U": 10101359597048, "u": 10101359607561, "pu": 10101359597024, "b": [["1000.00", "27.642"], ["5000.00", "101.398"], ["20763.50", "0.414"], ["20875.50", "0.333"], ["20875.90", "0.000"], ["21063.50", "0.306"], ["21175.50", "0.162"], ["64137.20", "0.000"], ["69850.00", "0.913"], ["70160.20", "2.236"], ["70226.60", "2.397"], ["70231.50", "3.984"], ["70550.90", "0.000"], ["70939.00", "0.002"], ["71101.00", "0.170"], ["71167.30", "0.004"], ["71167.40", "0.081"], ["71174.50", "0.001"], ["71174.60", "0.474"], ["71181.60", "0.000"], ["71181.70", "0.117"], ["71198.70", "1.200"], ["71207.30", "0.110"], ["71213.40", "0.510"], ["71213.50", "0.004"], ["71215.90", "0.086"], ["71220.00", "0.065"], ["71224.40", "0.045"], ["71232.50", "0.042"], ["71232.80", "0.072"], ["71235.40", "0.002"], ["71236.20", "0.210"], ["71239.50", "1.054"], ["71252.80", "0.200"], ["71256.50", "0.003"], ["71259.30", "0.210"], ["71262.20", "0.003"], ["71262.80", "0.030"], ["71262.90", "0.001"], ["71263.50", "2.845"]], "a": [["71263.60", "5.115"], ["71263.70", "0.064"], ["71263.90", "0.002"], ["71264.00", "0.069"], ["71266.00", "0.000"], ["71268.40", "0.013"], ["71269.10", "0.023"], ["71270.80", "0.001"], ["71271.20", "0.058"], ["71273.70", "0.003"], ["71273.80", "0.687"], ["71273.90", "0.203"], ["71275.30", "0.000"], ["71275.60", "0.004"], ["71276.00", "0.109"], ["71276.10", "0.013"], ["71277.80", "0.005"], ["71279.60", "0.000"], ["71284.00", "0.005"], ["71302.40", "0.324"], ["71310.00", "0.139"], ["71311.10", "0.017"], ["71311.40", "0.126"], ["71312.00", "0.078"], ["71315.60", "1.877"], ["71339.70", "3.523"], ["71345.70", "0.180"], ["71345.80", "0.104"], ["71378.10", "6.965"], ["71441.40", "12.928"], ["71445.20", "0.575"], ["71461.10", "0.095"], ["71976.20", "0.000"], ["72279.90", "0.959"], ["72281.80", "1.645"], ["72309.10", "6.769"], ["72380.40", "6.140"], ["72657.30", "0.014"], ["72688.80", "0.180"], ["74831.40", "0.014"], ["77981.40", "0.002"], ["78390.10", "0.020"], ["89523.20", "0.006"]]}}
{"local_ts": 1773384765484, "server_ts": 1773384765268, "data": {"e": "depthUpdate", "E": 1773384765269, "T": 1773384765268, "s": "BTCUSDT", "U": 10101359664155, "u": 10101359669500, "pu": 10101359664024, "b": [["1000.00", "27.642"], ["5000.00", "101.418"], ["20763.50", "1.548"], ["20863.50", "0.027"], ["20963.50", "0.225"], ["21063.50", "0.675"], ["21163.50", "0.225"], ["67668.60", "0.007"], ["70087.90", "0.004"], ["70550.90", "0.000"], ["70935.70", "0.002"], ["70935.90", "0.002"], ["70939.00", "0.000"], ["71036.70", "0.002"], ["71059.90", "0.002"], ["71189.10", "1.249"], ["71193.70", "0.002"], ["71196.60", "0.047"], ["71211.30", "0.191"], ["71227.90", "0.052"], ["71231.50", "0.554"], ["71252.90", "0.006"], ["71254.90", "0.004"], ["71256.40", "0.004"], ["71263.50", "1.398"]], "a": [["71263.60", "4.865"], ["71265.00", "0.000"], ["71265.70", "0.007"], ["71266.70", "0.654"], ["71268.60", "0.005"], ["71269.40", "0.003"], ["71270.30", "0.203"], ["71270.70", "0.003"], ["71273.70", "0.013"], ["71274.20", "0.065"], ["71295.60", "0.037"], ["71299.20", "0.800"], ["71307.40", "0.021"], ["71309.20", "0.015"], ["71312.30", "0.003"], ["71312.60", "0.014"], ["71424.80", "0.002"], ["71546.80", "12.305"], ["71592.40", "0.000"], ["71976.20", "0.000"], ["72701.10", "0.018"], ["74017.60", "0.002"], ["78336.70", "0.002"], ["89523.20", "0.006"]]}}
{"local_ts": 1773384766503, "server_ts": 1773384766288, "data": {"e": "depthUpdate", "E": 1773384766289, "T": 1773384766288, "s": "BTCUSDT", "U": 10101359714249, "u": 10101359718487, "pu": 10101359714175, "b": [["5000.00", "101.418"], ["20763.50", "0.153"], ["20863.50", "0.090"], ["20963.50", "0.810"], ["21063.50", "0.090"], ["21163.50", "1.557"], ["69903.40", "0.004"], ["70550.90", "0.000"], ["70935.70", "0.000"], ["70939.00", "0.002"], ["71167.40", "0.081"], ["71174.60", "0.474"], ["71181.70", "0.117"], ["71210.80", "0.184"], ["71211.30", "0.092"], ["71213.00", "0.303"], ["71213.20", "0.020"], ["71214.50", "0.105"], ["71214.60", "0.007"], ["71222.10", "1.901"], ["71257.40", "0.147"], ["71260.30", "0.002"]], "a": [["71273.70", "0.013"], ["71305.30", "2.172"], ["71338.30", "0.036"], ["71345.70", "0.180"], ["71389.00", "10.000"], ["71403.60", "0.078"], ["71403.70", "0.000"], ["71459.60", "0.159"], ["74827.20", "0.002"], ["89523.20", "0.006"]]}}
{"local_ts": 1773384767534, "server_ts": 1773384767309, "data": {"e": "depthUpdate", "E": 1773384767311, "T": 1773384767309, "s": "BTCUSDT", "U": 10101359768949, "u": 10101359780374, "pu": 10101359768919, "b": [["1000.00", "27.642"], ["5000.00", "101.418"], ["20863.50", "0.855"], ["20963.50", "0.045"], ["21063.50", "1.467"], ["21163.50", "0.333"], ["70586.50", "0.636"], ["70939.00", "0.000"], ["70940.60", "0.002"], ["71031.10", "0.200"], ["71212.30", "0.103"], ["71212.50", "0.221"], ["71214.70", "0.039"], ["71236.00", "0.094"], ["71238.00", "0.004"], ["71239.90", "0.000"], ["71241.40", "0.631"], ["71242.40", "0.011"], ["71242.70", "0.000"], ["71243.50", "0.003"]], "a": [["71263.70", "0.062"], ["71264.50", "0.007"], ["71265.70", "0.000"], ["71266.80", "1.105"], ["71269.60", "0.003"], ["71277.10", "0.914"], ["71277.40", "0.003"], ["71279.90", "0.000"], ["71282.60", "0.002"], ["71282.70", "0.025"], ["71293.90", "0.452"], ["71311.40", "0.107"], ["71311.70", "0.300"], ["71976.20", "0.000"], ["72347.70", "1.240"], ["74853.50", "0.052"], ["74854.40", "0.000"], ["89523.20", "0.006"]]}}
{"local_ts": 1773384768550, "server_ts": 1773384768334, "data": {"e": "depthUpdate", "E": 1773384768335, "T": 1773384768334, "s": "BTCUSDT", "U": 10101359855685, "u": 10101359861490, "pu": 10101359855578, "b": [["5000.00", "101.418"], ["20763.10", "0.459"], ["20863.50", "0.180"], ["20963.10", "0.927"], ["21063.50", "0.594"], ["33000.00", "9.339"], ["67697.90", "0.029"], ["67699.00", "0.010"], ["67699.80", "0.000"], ["70126.10", "0.659"], ["70907.20", "0.000"], ["70940.60", "0.000"], ["71163.70", "6.803"], ["71211.20", "0.184"], ["71213.00", "0.301"], ["71213.30", "0.445"], ["71216.80", "0.092"], ["71224.20", "0.017"], ["71224.30", "0.002"], ["71224.90", "0.005"], ["71225.00", "1.129"], ["71234.50", "0.360"], ["71236.50", "0.029"], ["71252.40", "0.000"], ["71256.00", "0.555"], ["71263.10", "0.724"]], "a": [["71266.60", "0.004"], ["71270.30", "0.031"], ["71276.00", "0.019"], ["71277.10", "0.205"], ["71279.40", "0.058"], ["71284.70", "0.544"], ["71287.30", "0.011"], ["71287.40", "0.012"], ["71288.00", "0.176"], ["71288.10", "0.063"], ["71295.60", "0.035"], ["71296.70", "0.032"], ["71298.90", "0.270"], ["71307.80", "0.322"], ["71311.00", "0.596"], ["71311.20", "0.136"], ["71937.30", "0.000"], ["71975.80", "0.000"], ["89523.20", "0.006"]]}}
{"local_ts": 1773384769573, "server_ts": 1773384769352, "data": {"e": "depthUpdate", "E": 1773384769355, "T": 1773384769352, "s": "BTCUSDT", "U": 10101359923104, "u": 10101359929834, "pu": 10101359922944, "b": [["1000.00", "27.642"], ["5000.00", "101.418"], ["20763.10", "0.315"], ["20863.10", "0.936"], ["20963.10", "0.864"], ["21163.10", "0.585"], ["69964.70", "0.576"], ["70550.50", "0.000"], ["71143.40", "0.322"], ["71148.60", "0.036"], ["71161.10", "1.955"], ["71211.20", "0.184"], ["71211.30", "0.276"], ["71212.30", "0.101"], ["71213.30", "0.443"], ["71213.40", "0.510"], ["71235.50", "0.002"], ["71238.10", "0.077"], ["71243.90", "0.077"], ["71244.70", "0.008"], ["71245.40", "0.286"], ["71252.40", "0.191"], ["71255.30", "0.023"], ["71263.10", "4.161"]], "a": [["71263.20", "7.271"], ["71263.70", "0.060"], ["71270.50", "0.273"], ["71277.60", "0.005"], ["71277.90", "0.052"], ["71282.20", "0.007"], ["71285.50", "0.310"], ["71293.60", "0.093"], ["71295.60", "0.033"], ["71298.10", "0.005"], ["71355.80", "0.000"], ["71975.80", "0.000"], ["72154.00", "0.230"], ["72688.40", "0.009"], ["74850.10", "0.002"], ["75260.10", "0.002"], ["89523.20", "0.006"]]}}
{"local_ts": 1773384770588, "server_ts": 1773384770373, "data": {"e": "depthUpdate", "E": 1773384770375, "T": 1773384770373, "s": "BTCUSDT", "U": 10101359973976, "u": 10101359977802, "pu": 10101359973877, "b": [["1000.00", "27.642"], ["5000.00", "101.418"], ["20763.10", "0.666"], ["20863.10", "1.134"], ["21063.10", "0.450"], ["21163.10", "0.450"], ["33000.00", "9.343"], ["57010.10", "0.000"], ["70051.60", "0.006"], ["70251.20", "0.566"], ["70286.80", "0.283"], ["70550.50", "0.000"], ["70550.60", "0.000"], ["71013.10", "0.008"], ["71109.50", "0.356"], ["71167.30", "0.214"], ["71172.00", "0.021"], ["71174.50", "0.211"], ["71180.00", "0.387"], ["71181.60", "1.193"], ["71209.70", "0.138"], ["71215.20", "1.051"], ["71215.30", "0.006"], ["71245.60", "0.009"], ["71246.40", "0.073"], ["71251.50", "0.185"], ["71252.40", "0.101"], ["71263.10", "3.754"]], "a": [["71270.20", "0.012"], ["71275.30", "0.015"], ["71284.80", "0.492"], ["71284.90", "0.437"], ["71291.30", "0.003"], ["71297.40", "0.002"], ["71298.10", "0.003"], ["71298.70", "0.088"], ["71307.60", "0.043"], ["71310.50", "0.034"], ["71310.60", "0.762"], ["71323.10", "0.000"], ["71345.60", "0.197"], ["71365.00", "0.606"], ["71440.20", "0.080"], ["71448.50", "0.000"], ["71782.00", "0.002"], ["71975.80", "0.000"], ["72040.00", "1.224"], ["72214.30", "1.174"], ["74851.40", "0.000"], ["75615.10", "0.002"], ["89523.20", "0.006"]]}}
{"local_ts": 1773384771613, "server_ts": 1773384771395, "data": {"e": "depthUpdate", "E": 1773384771397, "T": 1773384771395, "s": "BTCUSDT", "U": 10101360183108, "u": 10101360199883, "pu": 10101360183020, "b": [["5000.00", "101.418"], ["20763.10", "0.738"], ["20952.00", "0.315"], ["21063.10", "0.378"], ["21152.00", "0.396"], ["40000.00", "49.305"], ["67673.20", "0.000"], ["67689.00", "0.025"], ["69114.40", "0.005"], ["69479.00", "0.026"], ["69827.00", "0.012"], ["70151.20", "1.976"], ["70219.60", "1.634"], ["70539.50", "0.000"], ["71048.70", "0.002"], ["71065.00", "0.015"], ["71089.10", "0.863"], ["71111.90", "0.000"], ["71114.60", "0.544"], ["71128.40", "0.324"], ["71128.80", "0.040"], ["71129.50", "0.026"], ["71129.60", "0.007"], ["71130.40", "0.052"], ["71130.80", "0.020"], ["71131.20", "0.029"], ["71135.20", "0.040"], ["71153.40", "0.041"], ["71155.30", "0.079"], ["71156.80", "0.093"], ["71159.00", "0.174"], ["71160.90", "0.000"], ["71186.50", "0.031"], ["71191.30", "0.303"], ["71194.90", "0.342"], ["71199.40", "0.031"], ["71200.40", "0.000"], ["71203.30", "0.006"], ["71203.60", "0.003"], ["71204.80", "0.296"], ["71205.30", "0.280"], ["71209.70", "0.000"], ["71210.70", "0.156"], ["71210.80", "0.000"], ["71212.00", "0.062"], ["71213.20", "0.008"], ["71213.80", "0.005"], ["71214.20", "0.677"], ["71214.30", "0.186"], ["71216.90", "0.052"], ["71217.90", "0.006"], ["71219.30", "0.004"], ["71219.40", "0.599"], ["71219.60", "0.621"], ["71220.00", "0.062"], ["71220.10", "0.081"], ["71220.70", "0.003"], ["71220.80", "0.002"], ["71221.10", "0.002"], ["71221.40", "0.071"], ["71221.50", "0.009"], ["71223.90", "0.245"], ["71224.70", "0.000"], ["71225.50", "0.737"], ["71225.60", "0.148"], ["71225.70", "0.171"], ["71226.50", "0.000"], ["71226.70", "0.078"], ["71227.00", "0.000"], ["71227.10", "0.000"], ["71227.50", "0.512"], ["71229.00", "0.106"], ["71229.20", "0.000"], ["71229.30", "0.004"], ["71229.40", "0.300"], ["71229.60", "0.006"], ["71229.80", "0.276"], ["71230.00", "0.035"], ["71230.10", "0.003"], ["71230.90", "0.843"], ["71231.20", "0.505"], ["71231.70", "1.267"], ["71231.90", "0.000"], ["71232.60", "0.143"], ["71232.70", "0.001"], ["71232.80", "0.163"], ["71233.00", "0.061"], ["71233.70", "0.165"], ["71233.90", "0.026"], ["71234.80", "0.009"], ["71235.40", "0.142"], ["71235.50", "0.002"], ["71236.10", "0.062"], ["71237.00", "0.631"], ["71237.80", "0.003"], ["71238.00", "0.008"], ["71238.10", "0.294"], ["71238.20", "0.277"], ["71238.30", "0.028"], ["71238.40", "0.166"], ["71238.90", "0.058"], ["71239.30", "0.127"], ["71239.50", "0.003"], ["71239.80", "0.257"], ["71239.90", "0.107"], ["71240.20", "0.070"], ["71240.80", "0.200"], ["71240.90", "0.190"], ["71241.20", "0.037"], ["71241.30", "0.164"], ["71241.40", "0.134"], ["71241.60", "0.051"], ["71241.70", "0.074"], ["71241.80", "0.005"], ["71241.90", "0.066"], ["71242.10", "0.016"], ["71242.40", "0.038"], ["71242.80", "0.013"], ["71243.00", "0.052"], ["71243.80", "0.120"], ["71243.90", "0.008"], ["71244.00", "0.003"], ["71244.10", "0.665"], ["71244.40", "0.003"], ["71244.50", "0.014"], ["71244.90", "0.000"], ["71245.20", "0.007"], ["71246.40", "0.549"], ["71246.50", "0.203"], ["71247.00", "0.004"], ["71247.60", "0.005"], ["71249.90", "0.000"], ["71250.00", "0.087"], ["71250.20", "0.066"], ["71250.80", "0.023"], ["71252.00", "3.720"]], "a": [["71252.10", "2.070"], ["71252.20", "0.001"], ["71252.90", "0.000"], ["71253.10", "0.000"], ["71253.50", "0.001"], ["71253.60", "0.002"], ["71253.80", "0.002"], ["71254.20", "0.058"], ["71254.60", "0.000"], ["71255.20", "0.004"], ["71255.30", "0.005"], ["71255.40", "0.062"], ["71255.70", "0.007"], ["71256.00", "0.007"], ["71257.20", "0.068"], ["71257.30", "0.001"], ["71257.60", "0.000"], ["71259.20", "0.002"], ["71259.40", "0.000"], ["71260.00", "0.013"], ["71260.50", "0.005"], ["71260.70", "0.000"], ["71260.90", "0.001"], ["71261.70", "0.000"], ["71262.00", "0.438"], ["71262.10", "0.901"], ["71262.60", "0.105"], ["71262.70", "0.024"], ["71262.80", "0.040"], ["71262.90", "0.070"], ["71263.10", "0.005"], ["71263.20", "0.288"], ["71263.30", "0.190"], ["71263.50", "0.113"], ["71263.60", "0.401"], ["71263.80", "0.002"], ["71264.20", "0.002"], ["71264.40", "0.001"], ["71264.60", "0.127"], ["71264.90", "0.143"], ["71265.00", "0.053"], ["71265.10", "0.003"], ["71265.30", "0.000"], ["71265.60", "0.002"], ["71265.90", "0.140"], ["71266.00", "0.002"], ["71266.10", "0.006"], ["71266.20", "0.020"], ["71266.30", "0.041"], ["71266.40", "0.136"], ["71266.50", "0.010"], ["71266.60", "0.007"], ["71266.80", "0.215"], ["71266.90", "0.021"], ["71267.10", "0.000"], ["71267.30", "0.368"], ["71267.40", "0.004"], ["71267.80", "0.003"], ["71268.10", "0.010"], ["71268.50", "0.002"], ["71269.10", "0.082"], ["71269.20", "0.019"], ["71269.30", "0.014"], ["71269.60", "0.006"], ["71269.80", "0.003"], ["71269.90", "0.003"], ["71270.20", "0.000"], ["71270.70", "0.791"], ["71270.80", "0.087"], ["71271.00", "0.332"], ["71271.30", "0.004"], ["71271.40", "0.000"], ["71271.80", "0.005"], ["71271.90", "0.006"], ["71272.10", "0.002"], ["71272.40", "0.002"], ["71272.50", "0.009"], ["71272.60", "0.099"], ["71272.70", "0.000"], ["71272.80", "0.071"], ["71272.90", "0.089"], ["71273.00", "0.506"], ["71273.10", "0.000"], ["71273.50", "0.002"], ["71273.60", "0.069"], ["71273.90", "0.297"], ["71274.00", "0.036"], ["71274.10", "0.007"], ["71274.30", "0.008"], ["71274.40", "0.656"], ["71274.50", "0.003"], ["71274.60", "0.000"], ["71274.70", "0.073"], ["71274.80", "0.341"], ["71275.40", "0.077"], ["71276.20", "0.129"], ["71276.60", "0.570"], ["71276.80", "0.005"], ["71276.90", "0.002"], ["71277.00", "0.012"], ["71277.10", "0.051"], ["71277.30", "0.005"], ["71278.20", "0.000"], ["71278.30", "0.003"], ["71278.90", "0.153"], ["71279.00", "0.560"], ["71279.60", "0.000"], ["71279.70", "0.005"], ["71280.30", "0.005"], ["71280.40", "0.376"], ["71280.50", "0.507"], ["71280.70", "0.247"], ["71280.80", "0.212"], ["71281.30", "0.008"], ["71283.00", "0.006"], ["71284.20", "0.408"], ["71286.70", "0.029"], ["71287.70", "0.585"], ["71289.70", "0.006"], ["71290.60", "0.006"], ["71291.10", "1.084"], ["71292.00", "0.006"], ["71293.40", "0.005"], ["71294.80", "0.000"], ["71294.90", "0.551"], ["71297.00", "0.023"], ["71297.40", "0.070"], ["71298.40", "0.534"], ["71298.70", "0.311"], ["71298.90", "0.042"], ["71299.40", "0.006"], ["71299.80", "0.006"], ["71301.70", "0.086"], ["71307.90", "0.041"], ["71312.40", "0.816"], ["71312.60", "0.040"], ["71318.60", "0.314"], ["71319.50", "0.035"], ["71321.30", "0.082"], ["71328.80", "0.009"], ["71336.60", "0.002"], ["71337.30", "0.112"], ["71345.20", "0.058"], ["71356.90", "0.041"], ["71375.40", "0.102"], ["71409.60", "3.017"], ["71413.10", "10.000"], ["71419.50", "0.039"], ["71420.70", "2.454"], ["71422.50", "0.000"], ["71433.50", "0.000"], ["71438.70", "0.490"], ["71441.60", "0.012"], ["71448.00", "0.062"], ["71460.10", "4.356"], ["71460.20", "10.046"], ["71461.10", "0.041"], ["71472.80", "2.096"], ["71473.00", "0.100"], ["71488.80", "4.028"], ["71491.60", "10.000"], ["71498.90", "8.404"], ["71518.10", "0.000"], ["71522.90", "1.681"], ["71523.00", "10.000"], ["71523.40", "0.002"], ["71546.70", "1.484"], ["71546.80", "2.305"], ["71559.10", "0.246"], ["71559.60", "0.004"], ["71565.30", "0.000"], ["71569.90", "1.515"], ["71570.10", "10.017"], ["71964.60", "0.000"], ["74841.30", "0.002"], ["89523.20", "0.006"], ["100000.00", "15.858"]]}}
{"local_ts": 1773384772631, "server_ts": 1773384772416, "data": {"e": "depthUpdate", "E": 1773384772417, "T": 1773384772416, "s": "BTCUSDT", "U": 10101360247274, "u": 10101360251428, "pu": 10101360247164, "b": [["1000.00", "27.642"], ["5000.00", "101.418"], ["20752.00", "0.063"], ["20852.00", "0.189"], ["20952.00", "0.711"], ["21052.00", "0.189"], ["21152.00", "1.548"], ["57002.00", "0.004"], ["68402.00", "0.002"], ["70235.20", "0.006"], ["70539.50", "0.000"], ["71170.00", "0.408"], ["71184.30", "0.019"], ["71204.30", "0.031"], ["71204.60", "0.005"], ["71220.20", "2.135"], ["71225.70", "0.171"], ["71231.70", "0.217"], ["71232.60", "0.002"], ["71232.80", "0.022"], ["71241.30", "0.164"], ["71241.70", "0.074"], ["71243.50", "0.003"], ["71243.90", "0.012"]], "a": [["71252.10", "1.877"], ["71285.10", "0.007"], ["71289.70", "0.033"], ["71291.90", "0.011"], ["71300.20", "0.046"], ["71300.50", "0.009"], ["71301.90", "0.113"], ["71302.20", "0.023"], ["71307.70", "0.555"], ["71328.70", "1.067"], ["71355.00", "0.246"], ["71964.60", "0.000"], ["74827.20", "0.002"], ["89523.20", "0.006"]]}}
{"local_ts": 1773384773653, "server_ts": 1773384773436, "data": {"e": "depthUpdate", "E": 1773384773439, "T": 1773384773436, "s": "BTCUSDT", "U": 10101360313996, "u": 10101360318220, "pu": 10101360313881, "b": [["5000.00", "101.418"], ["20752.00", "0.054"], ["20852.00", "0.846"], ["20952.00", "0.054"], ["21052.00", "1.548"], ["21152.00", "0.198"], ["57002.00", "0.000"], ["67671.50", "0.000"], ["69827.00", "0.020"], ["70539.50", "0.000"], ["70895.70", "0.196"], ["70895.80", "2.396"], ["70979.40", "0.282"], ["71183.70", "1.485"], ["71193.70", "0.054"], ["71204.00", "0.044"], ["71204.40", "0.602"], ["71230.10", "0.010"], ["71231.10", "0.340"], ["71242.90", "0.249"], ["71243.90", "0.121"], ["71244.00", "0.007"], ["71244.20", "0.000"], ["71244.90", "0.032"], ["71252.00", "3.157"]], "a": [["71252.10", "2.818"], ["71253.60", "0.002"], ["71259.20", "0.040"], ["71262.00", "0.097"], ["71262.10", "0.549"], ["71273.10", "0.085"], ["71278.30", "0.010"], ["71280.70", "0.002"], ["71287.70", "0.486"], ["71299.90", "0.888"], ["71300.00", "4.987"], ["71338.70", "0.010"], ["71390.40", "0.000"], ["71479.10", "0.012"], ["71490.20", "0.202"], ["71964.50", "0.000"], ["71964.60", "0.014"], ["72677.10", "0.015"], ["74817.10", "0.002"]]}}
