{"local_ts": 1773384524264, "server_ts": 1773384524046, "data": {"e": "depthUpdate", "E": 1773384524047, "T": 1773384524046, "s": "BTCUSDT", "U": 10101339380881, "u": 10101339395694, "pu": 10101339380830, "b": [["1000.00", "27.492"], ["5000.00", "101.418"], ["20727.90", "0.009"], ["20728.40", "0.063"], ["20822.90", "1.422"], ["20827.80", "0.009"], ["20828.40", "0.072"], ["20922.90", "0.036"], ["21027.80", "0.009"], ["21028.40", "0.072"], ["21122.90", "0.693"], ["40000.00", "49.307"], ["67640.60", "0.004"], ["69935.60", "0.000"], ["70222.90", "5.185"], ["70223.00", "2.198"], ["70227.80", "0.008"], ["70227.90", "0.007"], ["70228.00", "0.021"], ["70228.40", "0.004"], ["70274.60", "0.000"], ["70332.60", "0.206"], ["70515.50", "0.000"], ["70515.60", "0.000"], ["70515.70", "0.028"], ["70516.10", "0.000"], ["70924.00", "0.010"], ["70927.10", "0.089"], ["70928.00", "0.902"], ["70935.10", "0.306"], ["70956.40", "0.310"], ["70963.50", "0.306"], ["70970.60", "0.300"], ["70983.30", "0.002"], ["70987.50", "1.001"], ["71028.90", "0.003"], ["71032.40", "0.003"], ["71038.00", "0.202"], ["71043.60", "0.002"], ["71050.10", "0.093"], ["71106.00", "0.272"], ["71107.00", "0.208"], ["71110.10", "3.337"], ["71121.50", "0.024"], ["71125.10", "0.082"], ["71128.70", "0.138"], ["71141.00", "0.129"], ["71142.40", "5.170"], ["71143.60", "0.292"], ["71151.10", "0.199"], ["71154.60", "0.002"], ["71157.40", "0.037"], ["71163.60", "0.000"], ["71164.50", "0.001"], ["71165.30", "0.940"], ["71165.90", "0.115"], ["71166.40", "0.000"], ["71167.80", "0.419"], ["71172.90", "0.000"], ["71173.60", "0.000"], ["71174.30", "0.506"], ["71175.00", "0.002"], ["71176.00", "0.807"], ["71177.10", "1.203"], ["71179.40", "0.022"], ["71180.60", "0.133"], ["71181.50", "0.002"], ["71181.60", "0.100"], ["71181.80", "0.026"], ["71182.30", "0.004"], ["71183.00", "0.805"], ["71184.80", "0.010"], ["71185.60", "0.087"], ["71187.80", "0.002"], ["71188.10", "0.000"], ["71189.30", "0.000"], ["71189.50", "0.000"], ["71189.90", "0.003"], ["71190.00", "0.823"], ["71190.50", "0.001"], ["71190.60", "0.252"], ["71190.70", "0.002"], ["71190.90", "0.055"], ["71191.30", "0.336"], ["71191.40", "0.005"], ["71193.00", "0.003"], ["71193.70", "0.508"], ["71194.10", "0.031"], ["71194.20", "0.037"], ["71194.80", "0.000"], ["71194.90", "0.321"], ["71195.50", "0.309"], ["71195.60", "0.009"], ["71196.00", "0.004"], ["71196.10", "0.005"], ["71196.20", "0.003"], ["71196.30", "0.002"], ["71196.50", "0.002"], ["71196.90", "0.027"], ["71197.00", "0.875"], ["71197.80", "0.030"], ["71199.90", "0.214"], ["71200.20", "0.452"], ["71200.30", "0.034"], ["71201.10", "0.032"], ["71201.60", "0.266"], ["71201.90", "0.093"], ["71202.30", "0.101"], ["71202.50", "0.140"], ["71202.60", "0.031"], ["71202.70", "0.000"], ["71203.00", "0.004"], ["71203.50", "1.543"], ["71203.70", "0.009"], ["71204.00", "0.844"], ["71204.20", "0.092"], ["71204.30", "0.012"], ["71204.90", "0.023"], ["71205.10", "0.003"], ["71205.60", "0.383"], ["71205.90", "0.072"], ["71206.30", "0.071"], ["71206.40", "0.003"], ["71206.50", "0.007"], ["71206.60", "0.004"], ["71206.70", "0.223"], ["71207.00", "0.015"], ["71208.00", "0.214"], ["71208.10", "0.001"], ["71209.30", "0.005"], ["71210.00", "0.178"], ["71210.60", "0.464"], ["71211.40", "0.147"], ["71211.60", "0.045"], ["71211.80", "0.356"], ["71211.90", "0.007"], ["71212.00", "0.511"], ["71212.10", "0.326"], ["71212.20", "0.004"], ["71212.30", "0.005"], ["71212.40", "0.001"], ["71212.60", "0.505"], ["71212.80", "0.632"], ["71212.90", "0.017"], ["71213.00", "0.307"], ["71213.20", "0.001"], ["71213.60", "1.235"], ["71214.10", "0.207"], ["71214.20", "0.603"], ["71214.30", "0.764"], ["71214.40", "0.072"], ["71214.50", "0.032"], ["71214.60", "0.041"], ["71214.70", "0.243"], ["71214.80", "0.032"], ["71214.90", "0.001"], ["71215.10", "0.059"], ["71215.20", "0.073"], ["71215.30", "0.366"], ["71215.40", "0.112"], ["71215.50", "0.004"], ["71215.60", "0.065"], ["71215.70", "1.103"], ["71215.80", "0.337"], ["71215.90", "0.005"], ["71216.00", "0.043"], ["71216.20", "0.009"], ["71216.30", "0.038"], ["71216.40", "0.522"], ["71216.50", "0.046"], ["71216.60", "0.307"], ["71216.70", "0.008"], ["71217.00", "0.093"], ["71217.10", "0.003"], ["71217.40", "0.030"], ["71217.60", "0.005"], ["71217.70", "0.016"], ["71217.90", "0.000"], ["71218.10", "0.140"], ["71218.50", "0.002"], ["71218.70", "0.005"], ["71218.80", "0.001"], ["71219.10", "0.037"], ["71219.40", "0.042"], ["71220.10", "0.007"], ["71220.80", "0.055"], ["71220.90", "0.007"], ["71221.60", "0.012"], ["71221.70", "0.003"], ["71221.80", "0.010"], ["71222.10", "0.216"], ["71222.50", "0.000"], ["71223.00", "0.371"], ["71223.10", "0.001"], ["71223.20", "0.005"], ["71223.30", "0.084"], ["71223.40", "0.002"], ["71223.60", "1.100"], ["71223.70", "0.509"], ["71223.80", "0.304"], ["71224.00", "0.006"], ["71224.20", "0.207"], ["71224.40", "0.001"], ["71224.70", "0.001"], ["71225.10", "0.001"], ["71225.30", "0.047"], ["71226.00", "0.032"], ["71226.10", "0.034"], ["71226.40", "0.002"], ["71226.50", "0.286"], ["71226.60", "0.003"], ["71226.70", "0.036"], ["71226.80", "0.000"], ["71226.90", "0.002"], ["71227.40", "0.000"], ["71227.50", "0.000"], ["71227.60", "0.000"], ["71227.70", "0.252"], ["71227.80", "0.082"], ["71227.90", "0.000"], ["71228.00", "0.000"], ["71228.10", "0.002"], ["71228.30", "0.002"], ["71228.40", "8.417"]], "a": [["71227.90", "0.000"], ["71228.00", "0.000"], ["71228.10", "0.000"], ["71228.20", "0.000"], ["71228.40", "0.000"], ["71228.50", "2.166"], ["71228.60", "0.001"], ["71228.70", "0.005"], ["71228.80", "0.212"], ["71228.90", "0.002"], ["71229.20", "0.049"], ["71229.60", "0.001"], ["71230.40", "0.000"], ["71230.50", "0.043"], ["71231.60", "0.002"], ["71232.00", "0.008"], ["71232.10", "0.008"], ["71232.20", "0.000"], ["71232.70", "0.001"], ["71232.90", "0.002"], ["71234.10", "0.000"], ["71235.20", "0.004"], ["71235.50", "0.006"], ["71235.80", "0.002"], ["71236.20", "0.001"], ["71236.30", "0.001"], ["71236.60", "0.003"], ["71236.70", "0.004"], ["71236.80", "0.002"], ["71236.90", "0.234"], ["71237.10", "0.000"], ["71237.30", "0.182"], ["71238.20", "0.002"], ["71238.30", "0.002"], ["71239.00", "0.014"], ["71239.10", "0.652"], ["71240.00", "0.004"], ["71240.30", "0.000"], ["71240.40", "0.199"], ["71241.20", "0.300"], ["71241.70", "0.001"], ["71242.40", "0.203"], ["71243.10", "0.024"], ["71243.50", "0.000"], ["71244.00", "0.005"], ["71244.20", "0.077"], ["71244.50", "0.330"], ["71244.80", "0.087"], ["71245.40", "0.022"], ["71245.50", "0.003"], ["71245.60", "0.345"], ["71245.70", "0.011"], ["71246.00", "0.813"], ["71246.10", "0.037"], ["71246.30", "0.035"], ["71247.20", "0.006"], ["71247.30", "0.071"], ["71247.40", "0.184"], ["71247.50", "0.144"], ["71247.60", "0.535"], ["71247.80", "0.005"], ["71248.00", "0.005"], ["71248.30", "0.004"], ["71248.60", "0.003"], ["71248.70", "0.023"], ["71248.80", "0.005"], ["71248.90", "0.425"], ["71249.20", "0.152"], ["71249.50", "0.009"], ["71249.60", "0.011"], ["71249.90", "0.030"], ["71250.10", "0.000"], ["71250.20", "0.005"], ["71250.30", "0.508"], ["71250.60", "0.635"], ["71251.30", "0.003"], ["71251.50", "0.383"], ["71252.50", "0.549"], ["71252.60", "0.376"], ["71253.00", "0.811"], ["71253.10", "0.002"], ["71253.20", "0.051"], ["71253.30", "0.072"], ["71253.40", "0.209"], ["71253.50", "0.273"], ["71253.70", "0.001"], ["71253.80", "0.002"], ["71253.90", "0.070"], ["71254.10", "0.001"], ["71254.30", "0.005"], ["71254.40", "0.040"], ["71254.50", "0.011"], ["71254.60", "0.002"], ["71254.70", "0.506"], ["71254.80", "0.110"], ["71255.00", "0.017"], ["71255.10", "0.526"], ["71255.20", "0.115"], ["71255.60", "0.004"], ["71255.70", "0.247"], ["71255.80", "0.719"], ["71255.90", "0.004"], ["71256.00", "0.009"], ["71256.50", "0.622"], ["71256.80", "0.002"], ["71257.00", "0.216"], ["71257.20", "0.078"], ["71257.40", "0.004"], ["71257.50", "0.002"], ["71258.30", "0.378"], ["71258.60", "0.004"], ["71259.60", "0.002"], ["71260.00", "0.812"], ["71260.80", "0.506"], ["71260.90", "0.003"], ["71261.60", "0.002"], ["71261.80", "0.009"], ["71262.10", "0.002"], ["71262.90", "0.040"], ["71263.80", "0.000"], ["71265.70", "0.027"], ["71266.00", "0.013"], ["71267.00", "0.805"], ["71268.10", "0.025"], ["71269.40", "0.009"], ["71270.10", "0.005"], ["71270.80", "0.003"], ["71271.40", "0.000"], ["71271.50", "0.029"], ["71272.50", "0.004"], ["71272.80", "0.638"], ["71273.30", "1.170"], ["71274.00", "0.880"], ["71277.00", "0.023"], ["71277.10", "0.328"], ["71277.30", "0.007"], ["71277.50", "0.004"], ["71278.20", "0.142"], ["71279.30", "0.000"], ["71280.00", "0.119"], ["71280.40", "0.049"], ["71282.50", "0.085"], ["71282.60", "0.121"], ["71283.50", "0.313"], ["71283.70", "0.062"], ["71284.90", "0.334"], ["71285.00", "0.668"], ["71285.50", "0.186"], ["71286.40", "0.000"], ["71287.00", "0.042"], ["71287.10", "0.231"], ["71287.20", "0.000"], ["71287.50", "0.366"], ["71289.00", "3.402"], ["71289.10", "0.224"], ["71289.20", "0.002"], ["71292.20", "0.000"], ["71297.50", "0.047"], ["71297.60", "0.339"], ["71299.90", "0.809"], ["71301.70", "0.344"], ["71302.00", "0.010"], ["71302.70", "0.406"], ["71302.80", "0.132"], ["71303.30", "0.081"], ["71304.50", "0.081"], ["71305.10", "0.000"], ["71306.90", "0.081"], ["71307.50", "0.004"], ["71321.80", "0.002"], ["71344.80", "0.025"], ["71368.20", "0.372"], ["71374.30", "0.018"], ["71390.40", "0.081"], ["71397.20", "0.012"], ["71397.50", "0.020"], ["71404.30", "0.007"], ["71404.60", "0.000"], ["71411.40", "0.008"], ["71411.70", "0.006"], ["71418.50", "0.007"], ["71418.80", "0.002"], ["71425.60", "0.011"], ["71425.90", "0.000"], ["71432.70", "0.294"], ["71433.00", "0.295"], ["71434.90", "0.343"], ["71438.40", "0.902"], ["71439.80", "0.007"], ["71440.10", "0.204"], ["71446.90", "0.203"], ["71464.80", "0.001"], ["71470.20", "0.000"], ["71480.60", "0.776"], ["71481.40", "0.000"], ["71485.80", "10.001"], ["71533.60", "6.420"], ["71850.50", "0.000"], ["71935.20", "0.718"], ["71940.20", "0.000"], ["71940.30", "0.000"], ["71940.40", "0.000"], ["71940.80", "0.014"], ["72281.90", "0.553"], ["77035.10", "0.000"], ["89523.20", "0.000"]]}}
{"local_ts": 1773384525283, "server_ts": 1773384525066, "data": {"e": "depthUpdate", "E": 1773384525067, "T": 1773384525066, "s": "BTCUSDT", "U": 10101339456535, "u": 10101339465619, "pu": 10101339456462, "b": [["1000.00", "27.492"], ["5000.00", "101.418"], ["20728.40", "1.413"], ["20822.90", "0.171"], ["20928.40", "0.072"], ["21028.40", "0.693"], ["21122.90", "0.000"], ["21128.40", "0.072"], ["33000.00", "9.339"], ["40000.00", "49.611"], ["70516.10", "0.000"], ["70688.70", "0.709"], ["71105.50", "0.072"], ["71106.20", "0.002"], ["71106.60", "0.137"], ["71148.60", "0.321"], ["71182.40", "0.378"], ["71182.80", "0.194"], ["71183.00", "0.002"], ["71184.80", "0.006"], ["71190.00", "0.020"], ["71197.00", "0.072"], ["71202.70", "0.000"], ["71203.70", "0.002"], ["71204.00", "0.041"], ["71207.40", "0.511"], ["71208.10", "1.194"], ["71209.80", "0.513"], ["71210.70", "0.021"], ["71211.00", "0.008"], ["71212.10", "0.326"], ["71212.70", "0.003"], ["71214.00", "0.046"], ["71215.00", "0.058"], ["71215.60", "0.029"], ["71216.30", "0.004"], ["71216.40", "0.508"], ["71216.70", "0.114"], ["71216.80", "0.074"], ["71217.10", "0.003"], ["71217.30", "0.009"], ["71217.40", "0.062"], ["71217.80", "0.134"], ["71217.90", "0.244"], ["71218.00", "0.019"], ["71218.30", "0.133"], ["71225.50", "0.001"], ["71226.50", "0.287"], ["71226.70", "0.038"], ["71227.70", "0.254"], ["71228.40", "4.504"]], "a": [["71228.50", "2.896"], ["71231.90", "0.000"], ["71241.20", "0.302"], ["71241.30", "0.081"], ["71242.30", "0.143"], ["71245.30", "0.083"], ["71245.40", "0.030"], ["71246.00", "0.010"], ["71246.30", "0.215"], ["71247.40", "0.020"], ["71247.50", "0.188"], ["71248.20", "0.006"], ["71248.30", "0.004"], ["71248.40", "0.023"], ["71249.50", "0.009"], ["71250.80", "0.070"], ["71250.90", "0.001"], ["71252.10", "0.006"], ["71253.00", "0.078"], ["71255.00", "0.051"], ["71257.60", "0.507"], ["71260.00", "0.009"], ["71262.30", "0.146"], ["71264.10", "0.173"], ["71265.80", "0.821"], ["71267.00", "0.002"], ["71274.00", "0.098"], ["71274.10", "0.000"], ["71275.90", "0.000"], ["71276.50", "0.011"], ["71276.90", "0.309"], ["71280.50", "0.149"], ["71284.20", "0.080"], ["71285.50", "0.171"], ["71287.30", "0.287"], ["71287.90", "1.641"], ["71300.50", "0.010"], ["71302.60", "0.796"], ["71341.90", "0.012"], ["71342.90", "0.009"], ["71343.40", "0.010"], ["71343.50", "0.300"], ["71395.90", "0.085"], ["71397.20", "0.005"], ["71403.00", "0.300"], ["71404.30", "0.000"], ["71410.10", "0.710"], ["71411.40", "0.001"], ["71417.20", "0.007"], ["71418.50", "0.000"], ["71424.30", "0.007"], ["71425.60", "0.004"], ["71431.40", "0.081"], ["71432.70", "0.287"], ["71438.50", "0.038"], ["71439.80", "0.000"], ["71445.60", "0.016"], ["71446.90", "0.196"], ["71940.80", "1.402"], ["72472.40", "0.000"], ["72653.00", "0.151"], ["74800.00", "32.087"], ["89523.20", "0.000"]]}}
{"local_ts": 1773384526307, "server_ts": 1773384526088, "data": {"e": "depthUpdate", "E": 1773384526089, "T": 1773384526088, "s": "BTCUSDT", "U": 10101339511747, "u": 10101339516040, "pu": 10101339511647, "b": [["5000.00", "101.398"], ["20722.90", "0.054"], ["20723.00", "0.000"], ["20723.50", "0.000"], ["20726.10", "0.000"], ["20726.40", "0.000"], ["20728.40", "0.306"], ["20928.40", "0.837"], ["21022.90", "0.063"], ["21023.50", "0.000"], ["21026.10", "0.000"], ["21027.80", "0.000"], ["21128.40", "1.440"], ["67644.10", "0.000"], ["67665.00", "0.077"], ["70516.10", "0.000"], ["70927.10", "0.048"], ["71067.10", "0.416"], ["71131.60", "0.087"], ["71138.70", "1.087"], ["71145.80", "0.117"], ["71183.00", "0.805"], ["71185.60", "0.136"], ["71190.00", "0.823"], ["71197.00", "0.875"], ["71204.00", "0.844"], ["71209.00", "0.508"], ["71209.50", "1.724"], ["71210.20", "0.002"], ["71210.70", "0.000"], ["71211.00", "0.811"], ["71211.10", "0.029"], ["71213.30", "0.049"], ["71215.60", "0.029"], ["71221.30", "0.001"]], "a": [["71235.60", "0.008"], ["71236.80", "0.012"], ["71243.90", "0.194"], ["71244.30", "0.713"], ["71246.00", "0.813"], ["71246.30", "0.209"], ["71247.50", "0.004"], ["71253.00", "0.811"], ["71259.70", "0.388"], ["71260.00", "0.896"], ["71267.00", "0.805"], ["71274.00", "0.901"], ["71291.20", "0.002"], ["71291.60", "0.000"], ["71299.70", "0.000"], ["71306.90", "0.000"], ["71309.80", "0.195"], ["71316.90", "0.080"], ["71395.50", "0.513"], ["71395.90", "0.078"], ["71402.60", "0.010"], ["71403.00", "0.293"], ["71409.70", "0.007"], ["71410.10", "0.703"], ["71413.70", "0.170"], ["71416.80", "0.304"], ["71417.20", "0.000"], ["71423.90", "0.010"], ["71424.30", "0.000"], ["71431.00", "0.085"], ["71431.40", "0.074"], ["71438.10", "0.007"], ["71438.50", "0.031"], ["71445.20", "0.297"], ["71445.60", "0.009"], ["71940.80", "1.402"], ["74110.40", "0.000"], ["89523.20", "0.000"]]}}
{"local_ts": 1773384527326, "server_ts": 1773384527108, "data": {"e": "depthUpdate", "E": 1773384527109, "T": 1773384527108, "s": "BTCUSDT", "U": 10101339559222, "u": 10101339564528, "pu": 10101339559077, "b": [["1000.00", "27.492"], ["5000.00", "101.398"], ["20828.40", "0.702"], ["20928.40", "0.198"], ["21028.40", "1.170"], ["21128.40", "0.630"], ["33000.00", "9.339"], ["67653.30", "0.002"], ["67666.00", "3.448"], ["67685.50", "0.006"], ["70117.20", "0.427"], ["70217.00", "1.281"], ["70516.10", "0.000"], ["70872.30", "0.063"], ["71071.10", "4.238"], ["71080.60", "0.853"], ["71131.70", "0.236"], ["71182.70", "0.291"], ["71182.80", "0.196"], ["71183.00", "0.002"], ["71187.30", "0.683"], ["71190.00", "0.020"], ["71193.40", "0.874"], ["71195.10", "0.076"], ["71197.00", "0.072"], ["71204.00", "0.041"], ["71211.00", "0.008"], ["71215.50", "0.065"], ["71215.60", "0.029"], ["71220.20", "0.000"], ["71225.60", "0.074"], ["71226.50", "0.287"], ["71228.30", "0.045"], ["71228.40", "4.888"]], "a": [["71228.50", "2.476"], ["71240.10", "0.039"], ["71243.00", "0.002"], ["71244.00", "0.132"], ["71244.10", "0.270"], ["71244.20", "0.261"], ["71246.00", "0.010"], ["71247.40", "0.020"], ["71247.70", "0.992"], ["71247.80", "0.028"], ["71253.00", "0.008"], ["71259.00", "0.019"], ["71260.00", "0.011"], ["71266.60", "1.064"], ["71267.00", "0.002"], ["71274.00", "0.077"], ["71282.00", "0.036"], ["71282.20", "0.063"], ["71285.50", "0.285"], ["71291.20", "0.000"], ["71291.50", "0.004"], ["71306.90", "0.000"], ["71310.00", "0.315"], ["71323.90", "0.039"], ["71352.80", "0.694"], ["71377.10", "1.127"], ["71395.50", "0.506"], ["71397.50", "0.027"], ["71402.60", "0.003"], ["71404.60", "0.007"], ["71409.70", "0.000"], ["71411.70", "0.013"], ["71413.70", "0.170"], ["71416.80", "0.297"], ["71418.80", "0.009"], ["71423.90", "0.003"], ["71425.90", "0.007"], ["71431.00", "0.078"], ["71433.00", "0.302"], ["71438.10", "0.000"], ["71440.10", "0.211"], ["71445.20", "0.290"], ["71447.20", "0.008"], ["71476.90", "0.873"], ["71940.80", "1.402"], ["72190.50", "0.692"], ["72332.50", "0.968"], ["89523.20", "0.000"]]}}
{"local_ts": 1773384528346, "server_ts": 1773384528128, "data": {"e": "depthUpdate", "E": 1773384528129, "T": 1773384528128, "s": "BTCUSDT", "U": 10101339616687, "u": 10101339623085, "pu": 10101339616637, "b": [["5000.00", "101.398"], ["20728.40", "0.567"], ["20828.40", "0.333"], ["20928.40", "0.900"], ["21028.40", "0.900"], ["67685.50", "0.002"], ["69798.60", "0.000"], ["70516.10", "0.000"], ["70978.90", "0.004"], ["71065.80", "0.204"], ["71146.80", "0.000"], ["71171.20", "1.372"], ["71183.00", "0.002"], ["71190.00", "0.020"], ["71197.00", "0.072"], ["71204.00", "0.041"], ["71205.70", "0.511"], ["71206.60", "0.004"], ["71207.60", "0.004"], ["71208.60", "0.003"], ["71210.60", "0.078"], ["71210.70", "0.000"], ["71211.00", "0.008"], ["71211.20", "0.205"], ["71215.60", "0.029"], ["71221.50", "0.558"], ["71223.30", "0.042"], ["71225.40", "0.002"], ["71225.60", "0.074"], ["71226.20", "0.044"], ["71228.30", "0.005"], ["71228.40", "4.479"]], "a": [["71244.00", "0.132"], ["71246.00", "0.010"], ["71246.30", "0.215"], ["71247.30", "0.198"], ["71247.60", "0.866"], ["71247.90", "0.174"], ["71253.00", "0.078"], ["71257.00", "0.216"], ["71260.00", "0.011"], ["71262.70", "0.573"], ["71266.60", "1.066"], ["71267.00", "0.002"], ["71274.00", "0.098"], ["71276.80", "0.005"], ["71276.90", "0.311"], ["71285.50", "0.171"], ["71285.70", "1.140"], ["71287.30", "0.287"], ["71291.50", "0.002"], ["71294.50", "3.567"], ["71299.10", "0.000"], ["71337.40", "0.000"], ["71397.50", "0.020"], ["71398.60", "0.301"], ["71404.60", "0.000"], ["71405.70", "0.214"], ["71411.70", "0.006"], ["71412.80", "0.009"], ["71413.70", "0.170"], ["71418.80", "0.002"], ["71419.90", "0.010"], ["71425.90", "0.000"], ["71427.00", "0.007"], ["71433.00", "0.295"], ["71434.10", "1.198"], ["71440.10", "0.204"], ["71441.20", "0.026"], ["71447.20", "0.001"], ["71448.30", "0.007"], ["71474.50", "0.337"], ["71476.70", "0.856"], ["71476.80", "0.008"], ["71940.80", "1.402"], ["72000.00", "159.585"], ["72307.90", "1.243"], ["74821.90", "0.000"], ["89523.20", "0.000"]]}}
{"local_ts": 1773384529374, "server_ts": 1773384529150, "data": {"e": "depthUpdate", "E": 1773384529151, "T": 1773384529150, "s": "BTCUSDT", "U": 10101339699852, "u": 10101339707915, "pu": 10101339699730, "b": [["1000.00", "27.492"], ["5000.00", "101.438"], ["20728.40", "0.468"], ["20832.60", "0.315"], ["20928.40", "1.170"], ["20928.60", "0.000"], ["20931.00", "0.000"], ["21132.60", "0.153"], ["33000.00", "9.343"], ["35614.20", "0.004"], ["67633.40", "0.005"], ["70520.30", "0.002"], ["70978.80", "0.000"], ["71010.10", "0.028"], ["71013.40", "0.004"], ["71017.00", "10.341"], ["71017.10", "2.066"], ["71031.30", "0.002"], ["71047.00", "0.303"], ["71048.30", "10.075"], ["71048.40", "2.534"], ["71050.40", "0.023"], ["71090.20", "0.104"], ["71154.70", "0.044"], ["71161.90", "0.007"], ["71176.50", "0.042"], ["71183.00", "0.002"], ["71186.30", "0.828"], ["71187.10", "1.135"], ["71190.00", "0.020"], ["71197.00", "0.070"], ["71199.50", "0.002"], ["71203.60", "0.273"], ["71204.00", "0.037"], ["71205.90", "0.000"], ["71211.00", "0.008"], ["71211.40", "0.328"], ["71213.00", "0.307"], ["71215.90", "0.510"], ["71217.40", "0.032"], ["71217.60", "0.636"], ["71218.80", "0.144"], ["71219.80", "0.055"], ["71220.20", "0.311"], ["71220.80", "0.010"], ["71221.60", "0.008"], ["71226.10", "0.005"], ["71228.40", "0.085"], ["71229.30", "0.046"], ["71231.50", "0.004"], ["71231.60", "0.046"], ["71231.70", "0.002"], ["71231.90", "0.004"], ["71232.60", "6.986"]], "a": [["71232.70", "1.276"], ["71234.00", "0.212"], ["71235.70", "0.029"], ["71236.10", "0.000"], ["71237.00", "0.015"], ["71238.10", "0.013"], ["71238.20", "0.002"], ["71238.60", "0.001"], ["71238.90", "0.101"], ["71239.00", "0.016"], ["71239.30", "0.000"], ["71239.40", "0.004"], ["71239.70", "0.003"], ["71239.80", "0.003"], ["71239.90", "0.003"], ["71240.00", "0.004"], ["71240.10", "0.005"], ["71240.40", "0.056"], ["71243.20", "0.006"], ["71244.10", "0.361"], ["71245.70", "0.011"], ["71245.80", "0.043"], ["71246.70", "0.077"], ["71246.80", "0.471"], ["71246.90", "0.415"], ["71247.30", "0.000"], ["71247.40", "0.127"], ["71252.00", "0.428"], ["71253.00", "0.014"], ["71253.70", "0.634"], ["71253.80", "0.007"], ["71254.40", "0.031"], ["71254.50", "0.002"], ["71257.30", "0.000"], ["71257.90", "0.002"], ["71258.00", "0.008"], ["71258.60", "0.018"], ["71258.70", "0.018"], ["71259.30", "0.007"], ["71259.40", "0.008"], ["71259.70", "0.517"], ["71260.00", "0.017"], ["71260.10", "0.002"], ["71263.40", "0.002"], ["71267.00", "0.002"], ["71268.30", "0.080"], ["71274.00", "0.009"], ["71280.90", "0.034"], ["71281.00", "0.002"], ["71281.10", "0.002"], ["71285.50", "0.012"], ["71286.10", "0.001"], ["71286.50", "1.202"], ["71287.80", "0.191"], ["71294.50", "3.565"], ["71296.30", "0.004"], ["71297.40", "0.053"], ["71304.40", "0.002"], ["71305.10", "0.002"], ["71313.40", "0.184"], ["71314.00", "0.435"], ["71337.40", "0.002"], ["71347.90", "0.293"], ["71356.00", "2.116"], ["71356.40", "10.309"], ["71945.00", "0.002"], ["72657.30", "0.013"], ["74827.70", "0.002"], ["89523.20", "0.000"]]}}
{"local_ts": 1773384530396, "server_ts": 1773384530172, "data": {"e": "depthUpdate", "E": 1773384530173, "T": 1773384530172, "s": "BTCUSDT", "U": 10101339772245, "u": 10101339781647, "pu": 10101339772182, "b": [["1000.00", "27.492"], ["5000.00", "101.418"], ["20732.60", "0.360"], ["20832.60", "1.125"], ["20928.40", "0.000"], ["21032.60", "0.306"], ["21132.60", "0.315"], ["67648.00", "0.005"], ["69058.90", "0.620"], ["70021.60", "0.427"], ["70520.30", "0.000"], ["71034.60", "0.002"], ["71171.50", "0.439"], ["71181.50", "1.202"], ["71183.00", "0.002"], ["71184.30", "0.002"], ["71189.90", "0.003"], ["71190.00", "0.020"], ["71195.40", "0.058"], ["71196.20", "0.003"], ["71196.30", "0.002"], ["71196.90", "0.027"], ["71197.00", "0.072"], ["71198.30", "0.004"], ["71203.60", "0.273"], ["71204.00", "0.037"], ["71205.90", "0.000"], ["71209.30", "0.010"], ["71210.90", "0.002"], ["71211.00", "0.008"], ["71212.30", "0.010"], ["71212.80", "0.015"], ["71214.10", "0.251"], ["71214.30", "0.002"], ["71215.60", "0.581"], ["71217.50", "0.009"], ["71218.60", "1.143"], ["71219.20", "0.219"], ["71220.20", "0.302"], ["71221.60", "0.012"], ["71222.10", "0.657"], ["71222.30", "0.067"], ["71223.00", "0.341"], ["71223.40", "0.003"], ["71225.50", "0.009"], ["71229.00", "0.201"], ["71229.30", "0.004"], ["71229.40", "0.189"], ["71229.60", "0.043"], ["71231.50", "0.001"], ["71231.90", "0.004"], ["71232.00", "0.029"], ["71232.40", "0.081"], ["71232.50", "0.057"], ["71232.60", "6.537"]], "a": [["71232.70", "1.790"], ["71232.80", "0.001"], ["71233.90", "0.213"], ["71234.20", "0.000"], ["71235.40", "0.003"], ["71236.20", "0.001"], ["71238.50", "0.004"], ["71239.80", "0.003"], ["71242.50", "0.022"], ["71243.30", "0.013"], ["71243.40", "0.086"], ["71243.80", "0.058"], ["71246.60", "0.002"], ["71246.70", "0.164"], ["71246.90", "0.659"], ["71251.40", "0.962"], ["71253.00", "0.014"], ["71253.20", "0.000"], ["71254.10", "0.177"], ["71255.80", "0.721"], ["71257.00", "0.076"], ["71259.90", "0.505"], ["71260.00", "0.024"], ["71260.10", "0.079"], ["71263.40", "0.002"], ["71263.80", "0.000"], ["71267.00", "0.002"], ["71272.80", "0.354"], ["71274.00", "0.030"], ["71274.90", "0.102"], ["71278.80", "0.136"], ["71279.20", "0.210"], ["71279.90", "0.053"], ["71281.00", "0.002"], ["71281.40", "0.003"], ["71281.50", "0.002"], ["71282.00", "0.073"], ["71286.10", "0.162"], ["71294.90", "1.558"], ["71296.30", "0.002"], ["71297.60", "0.341"], ["71304.40", "0.657"], ["71314.60", "0.797"], ["71318.20", "0.200"], ["71344.00", "0.365"], ["71344.60", "0.000"], ["71414.30", "0.101"], ["71417.90", "0.605"], ["71439.20", "0.003"], ["71442.70", "0.005"], ["71459.40", "2.788"], ["71584.50", "0.006"], ["71945.00", "0.002"], ["72312.00", "1.646"], ["74821.40", "0.000"], ["89523.20", "0.000"]]}}
{"local_ts": 1773384531412, "server_ts": 1773384531196, "data": {"e": "depthUpdate", "E": 1773384531197, "T": 1773384531196, "s": "BTCUSDT", "U": 10101339827599, "u": 10101339833704, "pu": 10101339827559, "b": [["5000.00", "101.418"], ["20732.60", "1.557"], ["20832.60", "0.036"], ["20932.60", "0.171"], ["21032.60", "0.729"], ["21132.60", "0.171"], ["56986.00", "0.007"], ["67648.00", "0.003"], ["67982.70", "0.021"], ["70520.30", "0.708"], ["71080.80", "0.311"], ["71081.20", "0.543"], ["71173.90", "3.608"], ["71175.30", "0.153"], ["71180.70", "0.051"], ["71183.00", "0.002"], ["71190.00", "0.020"], ["71191.90", "0.365"], ["71197.00", "0.120"], ["71204.00", "0.037"], ["71211.00", "0.008"], ["71214.10", "0.207"], ["71220.30", "0.002"], ["71221.60", "0.010"], ["71222.10", "0.657"], ["71232.20", "0.000"], ["71232.40", "0.084"], ["71232.60", "5.865"]], "a": [["71232.70", "0.306"], ["71232.80", "0.000"], ["71237.20", "0.002"], ["71238.50", "0.001"], ["71242.50", "0.012"], ["71243.20", "0.062"], ["71243.30", "0.180"], ["71243.40", "0.086"], ["71243.80", "0.002"], ["71245.20", "0.002"], ["71246.00", "0.037"], ["71246.10", "0.005"], ["71246.30", "0.035"], ["71246.40", "0.003"], ["71246.60", "0.002"], ["71249.20", "0.005"], ["71253.00", "0.034"], ["71253.40", "0.205"], ["71254.50", "0.004"], ["71256.30", "0.000"], ["71258.90", "0.073"], ["71260.00", "0.024"], ["71267.00", "0.002"], ["71267.10", "0.291"], ["71268.30", "0.048"], ["71271.90", "0.199"], ["71274.00", "0.026"], ["71280.90", "0.019"], ["71281.00", "0.002"], ["71282.00", "0.036"], ["71282.60", "0.121"], ["71286.10", "0.316"], ["71287.80", "0.318"], ["71296.70", "3.389"], ["71298.10", "0.330"], ["71303.00", "0.070"], ["71314.60", "0.971"], ["71320.00", "0.121"], ["71380.10", "0.648"], ["71417.90", "0.665"], ["71459.20", "4.736"], ["71945.00", "0.002"], ["72222.80", "0.967"], ["89523.20", "0.000"]]}}
{"local_ts": 1773384532435, "server_ts": 1773384532216, "data": {"e": "depthUpdate", "E": 1773384532217, "T": 1773384532216, "s": "BTCUSDT", "U": 10101339908343, "u": 10101339920599, "pu": 10101339908276, "b": [["1000.00", "27.492"], ["5000.00", "101.438"], ["20732.60", "0.207"], ["20833.80", "0.036"], ["20933.80", "0.684"], ["21032.60", "0.000"], ["21033.80", "0.036"], ["21133.80", "1.368"], ["67661.00", "0.010"], ["70206.40", "0.000"], ["70521.50", "0.029"], ["70877.60", "0.000"], ["70929.70", "0.002"], ["70998.90", "0.077"], ["71090.80", "0.103"], ["71187.60", "0.005"], ["71187.80", "0.306"], ["71191.70", "1.050"], ["71192.60", "0.002"], ["71201.30", "0.000"], ["71206.60", "0.044"], ["71207.70", "0.044"], ["71232.60", "0.030"], ["71233.70", "0.021"], ["71233.80", "2.786"]], "a": [["71235.40", "0.005"], ["71238.00", "0.009"], ["71242.60", "0.112"], ["71242.70", "0.000"], ["71242.80", "0.224"], ["71243.20", "0.190"], ["71244.60", "0.018"], ["71246.40", "0.128"], ["71249.00", "1.053"], ["71250.30", "0.634"], ["71252.80", "0.000"], ["71254.20", "0.119"], ["71254.60", "0.002"], ["71255.40", "0.005"], ["71256.40", "0.252"], ["71259.60", "0.089"], ["71269.50", "0.509"], ["71271.30", "0.270"], ["71282.20", "0.002"], ["71282.30", "0.012"], ["71287.30", "0.387"], ["71304.90", "0.007"], ["71481.00", "0.008"], ["71481.10", "0.839"], ["71941.40", "0.000"], ["71946.20", "0.003"]]}}
{"local_ts": 1773384533458, "server_ts": 1773384533242, "data": {"e": "depthUpdate", "E": 1773384533243, "T": 1773384533242, "s": "BTCUSDT", "U": 10101339977616, "u": 10101339984563, "pu": 10101339977533, "b": [["5000.00", "101.398"], ["20833.80", "0.801"], ["20932.60", "0.099"], ["21033.80", "1.368"], ["21132.60", "0.090"], ["21133.80", "0.342"], ["69809.20", "0.009"], ["70521.50", "0.029"], ["70521.60", "0.000"], ["70877.60", "0.035"], ["70993.40", "0.004"], ["71081.60", "0.000"], ["71081.80", "0.551"], ["71125.00", "0.362"], ["71201.50", "0.386"], ["71203.50", "1.500"], ["71207.40", "0.038"], ["71207.60", "0.078"], ["71209.20", "0.008"], ["71212.30", "0.508"], ["71213.70", "0.633"], ["71214.30", "0.002"], ["71215.10", "0.000"], ["71216.50", "0.036"], ["71226.70", "0.052"], ["71233.80", "3.170"]], "a": [["71241.00", "0.030"], ["71243.40", "0.005"], ["71245.40", "0.077"], ["71245.50", "0.026"], ["71245.60", "0.000"], ["71246.40", "0.483"], ["71249.40", "0.780"], ["71253.20", "0.000"], ["71256.50", "1.133"], ["71259.70", "0.310"], ["71275.10", "0.021"], ["71275.20", "0.001"], ["71276.60", "0.499"], ["71276.90", "0.016"], ["71281.80", "0.004"], ["71282.00", "0.036"], ["71304.30", "0.013"], ["71304.90", "0.005"], ["71307.00", "0.016"], ["71381.40", "0.555"], ["71480.60", "1.832"], ["71946.20", "0.003"], ["72195.60", "0.278"], ["74000.00", "231.694"], ["74083.20", "0.005"], ["74816.90", "0.002"], ["74819.60", "0.000"]]}}
{"local_ts": 1773384534486, "server_ts": 1773384534268, "data": {"e": "depthUpdate", "E": 1773384534269, "T": 1773384534268, "s": "BTCUSDT", "U": 10101340036037, "u": 10101340041581, "pu": 10101340035921, "b": [["1000.00", "27.492"], ["5000.00", "101.418"], ["20733.80", "0.675"], ["20833.80", "0.225"], ["20933.80", "1.098"], ["21033.80", "0.702"], ["33000.00", "9.339"], ["67672.00", "0.004"], ["69545.00", "0.021"], ["70108.10", "0.142"], ["70389.60", "0.003"], ["70521.50", "0.031"], ["70877.60", "0.035"], ["70974.50", "0.000"], ["71082.10", "0.105"], ["71082.20", "1.058"], ["71139.00", "0.090"], ["71140.30", "0.078"], ["71146.10", "0.070"], ["71153.20", "0.074"], ["71158.40", "10.074"], ["71161.20", "2.895"], ["71200.20", "0.002"], ["71200.40", "0.594"], ["71210.40", "0.044"], ["71211.40", "0.300"], ["71212.30", "0.045"], ["71213.00", "0.316"], ["71213.30", "0.046"], ["71214.20", "0.584"], ["71214.30", "0.044"], ["71216.40", "0.550"], ["71217.40", "0.072"], ["71218.40", "0.007"], ["71218.80", "0.004"], ["71219.80", "0.004"], ["71221.40", "0.007"], ["71222.60", "0.002"], ["71224.70", "0.001"], ["71225.20", "0.002"], ["71226.20", "0.002"], ["71226.70", "0.050"], ["71227.90", "0.005"], ["71229.10", "0.001"], ["71231.30", "0.062"], ["71233.80", "3.139"]], "a": [["71233.90", "3.185"], ["71235.30", "0.004"], ["71241.00", "0.028"], ["71243.10", "0.002"], ["71243.40", "0.561"], ["71243.90", "0.012"], ["71246.40", "0.367"], ["71248.40", "0.003"], ["71249.60", "0.144"], ["71269.50", "1.187"], ["71271.90", "0.000"], ["71275.80", "0.017"], ["71282.10", "0.002"], ["71282.20", "0.004"], ["71287.30", "0.592"], ["71304.30", "0.011"], ["71305.20", "0.004"], ["71307.00", "0.014"], ["71307.70", "0.508"], ["71310.60", "0.144"], ["71317.10", "0.070"], ["71324.20", "0.211"], ["71381.40", "0.554"], ["71481.10", "0.807"], ["71946.20", "0.005"], ["72144.80", "0.000"], ["72266.80", "0.829"], ["72655.70", "0.009"], ["72658.50", "0.011"], ["74804.70", "0.000"]]}}
{"local_ts": 1773384535513, "server_ts": 1773384535290, "data": {"e": "depthUpdate", "E": 1773384535291, "T": 1773384535290, "s": "BTCUSDT", "U": 10101340107581, "u": 10101340123863, "pu": 10101340107401, "b": [["1000.00", "27.492"], ["5000.00", "101.418"], ["20733.80", "0.360"], ["20833.80", "0.837"], ["20933.80", "0.963"], ["21133.80", "0.540"], ["40000.00", "49.611"], ["67653.40", "0.002"], ["67672.10", "0.010"], ["68384.40", "0.643"], ["70057.40", "0.000"], ["70305.90", "0.628"], ["70477.90", "0.707"], ["70521.50", "0.029"], ["70974.60", "0.000"], ["70977.20", "1.313"], ["70982.10", "10.000"], ["70984.80", "3.336"], ["71037.30", "0.000"], ["71038.40", "3.133"], ["71044.80", "10.000"], ["71115.80", "0.063"], ["71130.00", "16.124"], ["71182.40", "0.315"], ["71188.10", "0.002"], ["71189.00", "0.008"], ["71190.00", "0.020"], ["71191.00", "0.003"], ["71193.30", "0.018"], ["71194.80", "0.000"], ["71196.80", "0.068"], ["71197.00", "0.084"], ["71197.80", "0.001"], ["71200.90", "0.065"], ["71201.60", "0.021"], ["71201.90", "0.074"], ["71202.30", "0.123"], ["71204.00", "0.079"], ["71205.30", "0.087"], ["71205.90", "0.000"], ["71206.10", "0.070"], ["71206.60", "0.044"], ["71206.90", "0.118"], ["71207.60", "0.050"], ["71207.80", "0.003"], ["71208.50", "0.047"], ["71208.60", "0.010"], ["71208.90", "0.038"], ["71209.20", "0.078"], ["71209.50", "1.051"], ["71209.70", "1.150"], ["71210.00", "0.059"], ["71210.40", "0.002"], ["71210.50", "0.020"], ["71210.70", "0.000"], ["71211.00", "0.008"], ["71211.20", "0.000"], ["71211.40", "0.302"], ["71211.90", "0.042"], ["71212.30", "0.003"], ["71212.40", "0.015"], ["71212.50", "0.013"], ["71213.20", "0.116"], ["71213.60", "0.042"], ["71213.90", "0.007"], ["71214.00", "0.004"], ["71214.10", "0.207"], ["71214.20", "0.542"], ["71214.30", "0.002"], ["71214.90", "0.506"], ["71215.10", "0.631"], ["71216.30", "0.001"], ["71216.40", "0.508"], ["71216.70", "1.196"], ["71217.40", "0.030"], ["71218.00", "0.026"], ["71218.10", "0.070"], ["71218.30", "0.007"], ["71218.70", "0.005"], ["71219.20", "0.051"], ["71219.40", "0.002"], ["71219.70", "0.007"], ["71219.80", "0.302"], ["71219.90", "0.009"], ["71220.00", "0.014"], ["71220.20", "0.302"], ["71220.30", "0.142"], ["71220.50", "0.064"], ["71220.80", "0.008"], ["71221.30", "0.044"], ["71221.40", "0.007"], ["71221.50", "0.548"], ["71221.70", "1.052"], ["71221.80", "0.003"], ["71222.00", "0.148"], ["71222.10", "0.440"], ["71222.20", "0.038"], ["71222.30", "0.013"], ["71222.50", "0.006"], ["71222.70", "0.002"], ["71222.90", "0.096"], ["71223.10", "0.110"], ["71223.20", "0.159"], ["71223.30", "0.000"], ["71223.40", "0.003"], ["71223.60", "0.000"], ["71223.70", "0.512"], ["71223.80", "0.071"], ["71223.90", "0.057"], ["71224.30", "0.115"], ["71224.40", "0.001"], ["71224.70", "0.001"], ["71224.90", "0.027"], ["71225.60", "0.004"], ["71226.00", "0.007"], ["71226.10", "0.000"], ["71226.80", "0.507"], ["71226.90", "0.026"], ["71227.20", "0.008"], ["71227.70", "0.001"], ["71227.80", "0.003"], ["71229.40", "0.250"], ["71230.10", "0.000"], ["71230.20", "0.005"], ["71231.00", "0.257"], ["71231.40", "0.003"], ["71232.20", "0.000"], ["71232.60", "0.047"], ["71232.70", "0.059"], ["71233.70", "0.021"], ["71233.80", "1.838"]], "a": [["71233.90", "3.504"], ["71234.00", "0.003"], ["71234.90", "0.211"], ["71237.00", "0.005"], ["71238.90", "0.008"], ["71240.40", "0.007"], ["71241.10", "0.000"], ["71241.40", "0.028"], ["71241.60", "0.000"], ["71244.00", "0.015"], ["71244.40", "0.020"], ["71244.60", "0.369"], ["71246.10", "0.142"], ["71246.40", "0.365"], ["71246.70", "0.017"], ["71247.10", "0.119"], ["71247.20", "0.454"], ["71247.80", "0.062"], ["71248.30", "0.038"], ["71248.50", "0.238"], ["71248.80", "0.173"], ["71249.00", "0.004"], ["71249.20", "0.028"], ["71249.50", "0.060"], ["71249.60", "0.055"], ["71249.70", "0.015"], ["71249.90", "0.222"], ["71250.10", "0.014"], ["71250.20", "0.003"], ["71250.30", "0.033"], ["71250.40", "0.032"], ["71250.70", "0.120"], ["71250.80", "0.004"], ["71251.30", "1.054"], ["71251.40", "0.909"], ["71251.90", "0.067"], ["71252.20", "0.005"], ["71252.40", "0.001"], ["71252.60", "1.010"], ["71253.20", "0.007"], ["71253.90", "0.070"], ["71255.30", "0.170"], ["71255.70", "0.002"], ["71255.90", "0.012"], ["71256.10", "0.669"], ["71256.40", "0.051"], ["71256.70", "0.000"], ["71257.80", "0.073"], ["71258.20", "0.245"], ["71258.70", "0.005"], ["71260.50", "0.632"], ["71261.00", "0.000"], ["71262.60", "0.000"], ["71263.80", "0.000"], ["71267.70", "0.106"], ["71268.50", "0.074"], ["71268.80", "0.184"], ["71269.50", "1.073"], ["71271.30", "0.131"], ["71273.20", "0.830"], ["71273.30", "0.314"], ["71280.90", "0.000"], ["71281.60", "0.217"], ["71281.70", "0.692"], ["71287.30", "0.577"], ["71294.40", "0.659"], ["71296.70", "0.003"], ["71298.00", "1.121"], ["71305.20", "0.002"], ["71307.70", "0.506"], ["71308.40", "0.018"], ["71312.30", "0.083"], ["71315.70", "0.005"], ["71315.80", "0.212"], ["71320.00", "0.121"], ["71419.10", "0.159"], ["71946.20", "0.003"], ["71949.00", "3.192"], ["72658.50", "0.017"], ["73403.60", "0.583"], ["100000.00", "15.554"]]}}
{"local_ts": 1773384536529, "server_ts": 1773384536310, "data": {"e": "depthUpdate", "E": 1773384536311, "T": 1773384536310, "s": "BTCUSDT", "U": 10101340171907, "u": 10101340177203, "pu": 10101340171799, "b": [["5000.00", "101.418"], ["20733.80", "0.567"], ["20833.80", "1.233"], ["21033.80", "0.405"], ["21133.80", "0.495"], ["33000.00", "9.339"], ["67637.30", "0.002"], ["69825.20", "0.000"], ["69934.80", "0.000"], ["70500.00", "100.738"], ["70521.50", "1.445"], ["71138.90", "0.181"], ["71146.00", "0.080"], ["71153.10", "0.095"], ["71178.90", "1.551"], ["71187.70", "0.323"], ["71187.80", "0.306"], ["71213.60", "0.673"], ["71215.90", "0.001"], ["71221.10", "0.021"], ["71226.80", "0.509"]], "a": [["71233.90", "3.123"], ["71241.00", "0.176"], ["71241.10", "0.002"], ["71241.40", "0.384"], ["71242.50", "0.717"], ["71243.50", "0.127"], ["71244.00", "0.005"], ["71244.60", "0.160"], ["71245.70", "0.004"], ["71246.40", "0.226"], ["71281.90", "0.036"], ["71282.00", "0.095"], ["71290.90", "0.845"], ["71306.90", "0.002"], ["71308.40", "0.016"], ["71309.90", "0.509"], ["71315.70", "0.003"], ["71317.00", "0.072"], ["71324.10", "0.002"], ["71336.00", "0.823"], ["71399.00", "4.237"], ["71399.90", "0.000"], ["71419.10", "0.000"], ["71604.90", "4.079"], ["71673.50", "3.463"], ["71674.10", "0.002"], ["71946.20", "1.391"], ["72509.50", "0.000"], ["74812.30", "0.003"]]}}
{"local_ts": 1773384537549, "server_ts": 1773384537328, "data": {"e": "depthUpdate", "E": 1773384537333, "T": 1773384537328, "s": "BTCUSDT", "U": 10101340226150, "u": 10101340230706, "pu": 10101340226117, "b": [["1000.00", "27.492"], ["5000.00", "101.418"], ["20733.80", "1.503"], ["20833.80", "0.000"], ["20933.80", "0.270"], ["21033.80", "0.630"], ["21133.80", "0.297"], ["67643.60", "0.052"], ["70521.50", "1.445"], ["70521.60", "0.043"], ["70889.20", "0.279"], ["71174.90", "0.435"]], "a": [["71305.30", "0.007"], ["71306.90", "0.000"], ["71946.20", "1.434"], ["72279.00", "2.901"], ["72295.20", "1.461"], ["72421.50", "0.965"]]}}
{"local_ts": 1773384538575, "server_ts": 1773384538352, "data": {"e": "depthUpdate", "E": 1773384538353, "T": 1773384538352, "s": "BTCUSDT", "U": 10101340319151, "u": 10101340379011, "pu": 10101340319059, "b": [["5000.00", "101.418"], ["20733.80", "0.108"], ["20825.40", "0.045"], ["20828.00", "0.009"], ["20830.20", "0.009"], ["20836.00", "0.072"], ["20936.10", "0.054"], ["21025.40", "0.036"], ["21026.50", "0.009"], ["21029.30", "0.009"], ["21030.20", "0.009"], ["21036.00", "0.072"], ["21125.40", "0.045"], ["21127.00", "0.009"], ["21129.50", "0.009"], ["21132.60", "0.009"], ["21136.00", "0.216"], ["21136.10", "0.180"], ["33000.00", "9.343"], ["68304.00", "0.004"], ["69809.20", "0.006"], ["70033.70", "0.284"], ["70356.50", "0.000"], ["70513.10", "0.004"], ["70514.90", "0.000"], ["70516.20", "0.702"], ["70516.50", "0.000"], ["70522.40", "0.005"], ["70523.60", "0.000"], ["70868.80", "0.002"], ["70879.60", "0.002"], ["70923.80", "6.482"], ["70925.00", "0.362"], ["70927.10", "1.310"], ["70927.30", "0.298"], ["70940.10", "10.000"], ["70940.90", "1.687"], ["70963.40", "0.002"], ["70963.60", "0.005"], ["70970.60", "0.301"], ["70974.70", "0.311"], ["70975.10", "0.002"], ["70977.20", "1.313"], ["70977.30", "0.004"], ["70991.60", "0.155"], ["71002.70", "10.001"], ["71016.70", "0.046"], ["71025.40", "0.042"], ["71032.90", "0.003"], ["71034.20", "0.043"], ["71035.80", "0.154"], ["71036.20", "0.130"], ["71036.40", "0.379"], ["71037.00", "1.025"], ["71037.30", "0.040"], ["71037.80", "0.006"], ["71042.20", "0.040"], ["71043.30", "0.042"], ["71051.80", "0.040"], ["71056.80", "4.277"], ["71062.50", "0.014"], ["71064.20", "0.042"], ["71066.50", "0.504"], ["71068.00", "0.100"], ["71069.00", "0.010"], ["71069.90", "0.077"], ["71070.20", "0.112"], ["71070.60", "0.002"], ["71071.30", "0.011"], ["71071.50", "0.103"], ["71073.20", "0.110"], ["71073.30", "0.213"], ["71073.60", "0.103"], ["71074.10", "0.000"], ["71075.30", "0.102"], ["71075.40", "0.288"], ["71075.60", "0.000"], ["71076.20", "0.198"], ["71076.40", "0.018"], ["71078.80", "0.205"], ["71079.20", "0.000"], ["71079.60", "0.006"], ["71080.40", "0.104"], ["71081.70", "0.000"], ["71083.30", "0.105"], ["71083.80", "0.310"], ["71084.70", "0.000"], ["71085.00", "0.412"], ["71085.20", "0.080"], ["71085.50", "3.018"], ["71087.00", "0.081"], ["71088.60", "0.002"], ["71090.20", "0.182"], ["71092.30", "0.081"], ["71093.90", "0.078"], ["71097.40", "0.106"], ["71098.80", "0.000"], ["71099.90", "0.078"], ["71101.00", "0.269"], ["71102.00", "1.237"], ["71103.50", "0.000"], ["71104.30", "0.091"], ["71106.00", "0.204"], ["71106.50", "0.300"], ["71107.10", "0.066"], ["71108.10", "0.106"], ["71110.10", "3.343"], ["71110.20", "0.510"], ["71112.30", "0.174"], ["71112.70", "0.092"], ["71113.00", "0.125"], ["71120.60", "0.072"], ["71121.90", "0.004"], ["71125.20", "13.147"], ["71125.30", "0.002"], ["71126.20", "0.073"], ["71127.10", "0.115"], ["71129.70", "0.000"], ["71130.10", "0.106"], ["71132.00", "0.306"], ["71133.30", "6.772"], ["71133.40", "0.007"], ["71133.70", "0.335"], ["71133.80", "0.085"], ["71133.90", "0.135"], ["71134.20", "0.304"], ["71134.80", "0.548"], ["71135.20", "0.000"], ["71135.60", "0.022"], ["71135.80", "1.042"], ["71135.90", "0.002"], ["71136.10", "0.671"], ["71136.70", "0.176"], ["71136.80", "0.007"], ["71137.20", "0.000"], ["71137.30", "0.615"], ["71137.50", "0.002"], ["71137.70", "0.046"], ["71137.90", "0.002"], ["71138.40", "0.186"], ["71138.70", "1.370"], ["71138.80", "0.113"], ["71138.90", "0.111"], ["71139.70", "0.000"], ["71139.80", "0.001"], ["71140.30", "0.021"], ["71140.40", "0.791"], ["71140.60", "0.000"], ["71140.90", "0.299"], ["71141.00", "0.129"], ["71141.50", "0.000"], ["71141.60", "6.338"], ["71141.70", "0.005"], ["71142.00", "0.119"], ["71142.20", "0.175"], ["71142.60", "1.353"], ["71142.70", "0.002"], ["71142.90", "0.004"], ["71143.50", "0.000"], ["71143.90", "0.000"], ["71144.50", "0.401"], ["71144.70", "0.008"], ["71144.90", "0.000"], ["71145.10", "0.015"], ["71145.60", "0.352"], ["71145.80", "0.047"], ["71145.90", "0.010"], ["71146.00", "0.010"], ["71146.80", "0.000"], ["71146.90", "0.002"], ["71147.80", "0.005"], ["71148.50", "0.080"], ["71148.70", "0.036"], ["71149.90", "0.073"], ["71150.00", "1.534"], ["71151.20", "0.005"], ["71151.50", "0.000"], ["71152.40", "0.110"], ["71152.80", "0.074"], ["71153.00", "0.003"], ["71153.10", "0.025"], ["71153.90", "1.065"], ["71154.00", "0.005"], ["71154.20", "0.004"], ["71154.60", "0.010"], ["71155.40", "0.000"], ["71155.80", "0.000"], ["71156.20", "0.000"], ["71156.80", "0.321"], ["71157.20", "0.007"], ["71157.30", "1.158"], ["71157.40", "0.031"], ["71157.80", "0.202"], ["71158.10", "2.525"], ["71158.40", "10.077"], ["71158.50", "0.004"], ["71158.70", "0.057"], ["71158.80", "0.022"], ["71158.90", "0.812"], ["71159.10", "0.086"], ["71159.70", "0.020"], ["71160.00", "0.024"], ["71160.10", "0.001"], ["71160.20", "0.019"], ["71161.10", "0.044"], ["71161.60", "0.322"], ["71162.00", "1.756"], ["71162.10", "0.000"], ["71162.70", "0.103"], ["71163.00", "0.042"], ["71163.10", "0.839"], ["71163.20", "0.000"], ["71163.80", "0.002"], ["71163.90", "0.033"], ["71164.00", "0.003"], ["71164.30", "0.000"], ["71164.50", "0.001"], ["71164.90", "0.000"], ["71165.30", "0.942"], ["71165.70", "0.001"], ["71165.90", "0.115"], ["71166.70", "0.000"], ["71166.90", "0.000"], ["71167.10", "0.048"], ["71167.40", "0.011"], ["71167.60", "0.009"], ["71167.70", "0.002"], ["71168.00", "0.028"], ["71168.20", "0.000"], ["71168.40", "0.002"], ["71168.50", "0.000"], ["71168.90", "0.040"], ["71169.00", "0.002"], ["71169.20", "0.043"], ["71169.40", "0.627"], ["71170.10", "0.036"], ["71170.20", "0.000"], ["71170.30", "0.003"], ["71170.40", "0.000"], ["71171.00", "0.004"], ["71171.10", "0.062"], ["71171.20", "0.691"], ["71171.30", "0.000"], ["71171.40", "0.000"], ["71171.50", "0.399"], ["71171.70", "0.000"], ["71172.10", "0.004"], ["71172.30", "0.015"], ["71172.40", "0.174"], ["71172.70", "0.204"], ["71172.90", "0.001"], ["71174.20", "0.001"], ["71174.30", "0.508"], ["71174.40", "0.004"], ["71175.30", "0.003"], ["71175.40", "0.016"], ["71175.60", "0.109"], ["71175.70", "0.002"], ["71176.10", "0.040"], ["71176.20", "0.000"], ["71176.50", "0.042"], ["71177.10", "0.000"], ["71177.20", "0.397"], ["71177.30", "0.019"], ["71177.60", "0.051"], ["71177.70", "0.005"], ["71177.80", "0.034"], ["71177.90", "0.002"], ["71178.10", "1.577"], ["71178.20", "1.207"], ["71178.90", "0.889"], ["71179.70", "0.017"], ["71180.00", "0.031"], ["71180.10", "0.000"], ["71180.40", "0.661"], ["71180.70", "0.060"], ["71181.10", "0.003"], ["71182.00", "0.076"], ["71182.10", "0.000"], ["71182.20", "0.002"], ["71182.40", "0.355"], ["71182.70", "0.225"], ["71182.80", "0.194"], ["71183.10", "0.008"], ["71183.30", "0.047"], ["71183.40", "0.660"], ["71183.60", "0.002"], ["71183.80", "0.309"], ["71183.90", "0.000"], ["71184.20", "0.050"], ["71184.60", "0.002"], ["71184.90", "0.000"], ["71185.00", "0.508"], ["71185.10", "1.049"], ["71185.20", "0.003"], ["71185.30", "0.007"], ["71185.60", "0.002"], ["71185.70", "0.085"], ["71185.90", "0.005"], ["71186.00", "0.004"], ["71186.20", "0.051"], ["71186.30", "0.828"], ["71186.50", "0.008"], ["71186.60", "0.000"], ["71187.10", "1.093"], ["71187.20", "0.281"], ["71187.30", "0.636"], ["71187.40", "0.560"], ["71187.50", "0.008"], ["71187.80", "0.304"], ["71188.00", "0.074"], ["71188.10", "0.002"], ["71188.40", "0.024"], ["71188.90", "0.004"], ["71189.10", "0.338"], ["71189.20", "0.039"], ["71189.30", "0.002"], ["71189.40", "0.005"], ["71189.80", "0.017"], ["71189.90", "0.003"], ["71190.00", "0.020"], ["71190.10", "0.506"], ["71190.30", "0.000"], ["71190.50", "0.001"], ["71190.60", "0.252"], ["71190.70", "0.004"], ["71190.80", "0.026"], ["71190.90", "0.004"], ["71191.00", "0.003"], ["71191.20", "0.301"], ["71191.30", "0.338"], ["71191.40", "0.003"], ["71191.70", "1.050"], ["71191.90", "0.337"], ["71192.00", "0.322"], ["71192.10", "0.002"], ["71192.20", "0.080"], ["71192.30", "0.077"], ["71192.40", "0.000"], ["71192.50", "0.018"], ["71193.10", "0.000"], ["71193.30", "0.018"], ["71193.40", "0.640"], ["71193.50", "0.055"], ["71193.80", "0.004"], ["71194.10", "0.014"], ["71194.20", "7.731"], ["71194.30", "0.029"], ["71194.40", "0.003"], ["71194.80", "0.004"], ["71194.90", "0.323"], ["71195.00", "0.007"], ["71195.10", "0.038"], ["71195.30", "0.003"], ["71195.50", "0.302"], ["71195.60", "0.002"], ["71195.80", "0.332"], ["71195.90", "0.038"], ["71196.20", "0.003"], ["71196.30", "0.002"], ["71196.40", "0.085"], ["71196.60", "0.077"], ["71196.80", "0.070"], ["71196.90", "0.026"], ["71197.00", "0.139"], ["71197.30", "0.000"], ["71197.40", "0.004"], ["71197.50", "1.050"], ["71197.60", "0.003"], ["71197.70", "0.002"], ["71197.80", "0.071"], ["71198.30", "0.305"], ["71198.40", "0.009"], ["71198.60", "0.510"], ["71198.80", "0.033"], ["71199.00", "0.527"], ["71199.10", "0.000"], ["71199.40", "0.633"], ["71199.50", "0.002"], ["71199.60", "0.001"], ["71199.70", "0.002"], ["71199.80", "0.004"], ["71199.90", "0.136"], ["71200.00", "100.672"], ["71200.20", "0.564"], ["71200.30", "0.397"], ["71200.40", "0.314"], ["71200.50", "0.088"], ["71200.60", "0.086"], ["71200.70", "0.255"], ["71200.80", "0.006"], ["71200.90", "0.279"], ["71201.10", "0.004"], ["71201.20", "0.526"], ["71201.30", "0.039"], ["71201.40", "0.353"], ["71201.50", "0.012"], ["71201.70", "0.047"], ["71201.80", "0.040"], ["71201.90", "0.062"], ["71202.10", "0.516"], ["71202.20", "0.365"], ["71202.40", "0.454"], ["71202.50", "0.189"], ["71202.60", "0.024"], ["71202.70", "0.000"], ["71202.80", "0.052"], ["71202.90", "0.010"], ["71203.10", "0.000"], ["71203.20", "0.014"], ["71203.30", "0.338"], ["71203.40", "0.122"], ["71203.50", "1.142"], ["71203.60", "0.512"], ["71203.70", "0.085"], ["71203.90", "0.000"], ["71204.00", "0.043"], ["71204.10", "0.009"], ["71204.20", "0.003"], ["71204.40", "0.935"], ["71204.50", "0.000"], ["71204.60", "0.039"], ["71204.70", "0.142"], ["71204.90", "0.005"], ["71205.00", "0.006"], ["71205.30", "0.006"], ["71205.40", "0.049"], ["71205.50", "0.002"], ["71205.60", "0.002"], ["71205.70", "0.584"], ["71205.80", "0.506"], ["71205.90", "0.000"], ["71206.00", "0.035"], ["71206.10", "0.000"], ["71206.30", "0.001"], ["71206.40", "0.010"], ["71206.50", "0.001"], ["71206.70", "0.325"], ["71206.80", "0.163"], ["71207.00", "0.011"], ["71207.10", "0.004"], ["71207.30", "0.005"], ["71207.40", "0.038"], ["71207.50", "0.006"], ["71207.60", "0.089"], ["71207.90", "0.002"], ["71208.10", "0.007"], ["71208.80", "0.011"], ["71208.90", "0.039"], ["71209.20", "0.009"], ["71209.30", "0.134"], ["71209.40", "4.945"], ["71209.50", "1.049"], ["71209.60", "0.112"], ["71209.70", "0.828"], ["71209.80", "0.000"], ["71209.90", "0.341"], ["71210.00", "0.009"], ["71210.20", "0.002"], ["71210.30", "0.378"], ["71210.60", "0.007"], ["71210.90", "0.284"], ["71211.00", "0.006"], ["71211.10", "0.240"], ["71211.20", "0.526"], ["71211.30", "0.289"], ["71211.40", "0.111"], ["71211.50", "0.758"], ["71211.60", "0.119"], ["71211.90", "0.758"], ["71212.00", "0.005"], ["71212.10", "0.002"], ["71212.20", "0.015"], ["71212.30", "0.002"], ["71212.40", "0.005"], ["71212.50", "0.006"], ["71212.80", "0.001"], ["71212.90", "0.012"], ["71213.00", "0.833"], ["71213.10", "0.000"], ["71213.40", "0.006"], ["71213.50", "0.002"], ["71213.60", "0.003"], ["71213.70", "0.002"], ["71214.20", "0.019"], ["71214.40", "0.000"], ["71214.50", "0.005"], ["71214.60", "0.153"], ["71214.70", "1.246"], ["71214.80", "0.285"], ["71215.30", "0.000"], ["71215.60", "0.821"], ["71215.70", "0.000"], ["71215.80", "0.005"], ["71215.90", "0.001"], ["71216.30", "0.004"], ["71216.40", "0.002"], ["71216.50", "0.008"], ["71216.60", "0.002"], ["71216.70", "0.017"], ["71216.80", "0.007"], ["71216.90", "0.003"], ["71217.00", "0.002"], ["71217.10", "0.003"], ["71217.20", "0.007"], ["71217.40", "0.001"], ["71217.60", "0.003"], ["71217.80", "0.129"], ["71217.90", "0.101"], ["71218.00", "0.014"], ["71218.10", "0.000"], ["71218.20", "0.006"], ["71218.40", "0.007"], ["71218.50", "0.000"], ["71218.60", "0.002"], ["71218.70", "0.003"], ["71219.00", "0.002"], ["71219.10", "0.211"], ["71219.20", "0.002"], ["71219.30", "0.003"], ["71219.40", "0.000"], ["71219.50", "0.002"], ["71219.60", "0.002"], ["71220.00", "0.011"], ["71220.40", "0.006"], ["71220.50", "0.001"], ["71220.60", "0.007"], ["71220.70", "0.001"], ["71220.90", "0.002"], ["71221.00", "0.000"], ["71221.10", "0.003"], ["71221.20", "0.002"], ["71221.30", "0.001"], ["71221.40", "0.005"], ["71221.50", "0.008"], ["71221.60", "0.009"], ["71221.70", "0.003"], ["71221.80", "0.003"], ["71221.90", "0.002"], ["71222.00", "0.120"], ["71222.10", "0.002"], ["71222.20", "0.002"], ["71222.30", "0.000"], ["71222.40", "0.014"], ["71222.50", "0.003"], ["71222.80", "0.002"], ["71223.00", "0.000"], ["71223.10", "0.000"], ["71223.20", "0.003"], ["71223.40", "0.001"], ["71223.50", "0.001"], ["71223.70", "0.003"], ["71223.80", "0.000"], ["71223.90", "0.000"], ["71224.00", "0.006"], ["71224.20", "0.002"], ["71224.30", "0.064"], ["71224.50", "0.000"], ["71224.60", "0.002"], ["71224.80", "0.000"], ["71224.90", "0.002"], ["71225.00", "0.023"], ["71225.10", "0.003"], ["71225.20", "0.000"], ["71225.30", "0.003"], ["71225.40", "0.298"], ["71225.50", "0.000"], ["71225.60", "0.000"], ["71226.00", "0.000"], ["71226.20", "0.000"], ["71226.30", "0.000"], ["71226.50", "0.000"], ["71226.60", "0.000"], ["71226.70", "0.000"], ["71226.80", "0.000"], ["71226.90", "0.000"], ["71227.00", "0.000"], ["71227.10", "0.000"], ["71227.20", "0.000"], ["71227.30", "0.000"], ["71227.40", "0.000"], ["71227.60", "0.000"], ["71227.70", "0.000"], ["71227.90", "0.000"], ["71228.00", "0.000"], ["71228.10", "0.000"], ["71228.30", "0.000"], ["71228.40", "0.000"], ["71228.50", "0.000"], ["71228.60", "0.000"], ["71228.80", "0.000"], ["71228.90", "0.000"], ["71229.10", "0.000"], ["71229.20", "0.000"], ["71229.30", "0.000"], ["71229.40", "0.000"], ["71229.50", "0.000"], ["71229.60", "0.000"], ["71229.80", "0.000"], ["71230.00", "0.000"], ["71230.20", "0.000"], ["71230.30", "0.000"], ["71230.40", "0.000"], ["71230.70", "0.000"], ["71230.80", "0.000"], ["71230.90", "0.000"], ["71231.00", "0.000"], ["71231.10", "0.000"], ["71231.20", "0.000"], ["71231.30", "0.000"], ["71231.40", "0.000"], ["71231.70", "0.000"], ["71231.80", "0.000"], ["71231.90", "0.000"], ["71232.00", "0.000"], ["71232.10", "0.000"], ["71232.30", "0.000"], ["71232.50", "0.000"], ["71232.60", "0.000"], ["71232.70", "0.000"], ["71233.00", "0.000"], ["71233.10", "0.000"], ["71233.20", "0.000"], ["71233.30", "0.000"], ["71233.60", "0.000"], ["71233.70", "0.000"], ["71233.80", "0.000"], ["71233.90", "0.000"], ["71234.20", "0.000"], ["71234.30", "0.000"], ["71234.60", "0.000"], ["71235.00", "0.000"], ["71235.20", "0.000"], ["71235.40", "0.000"], ["71235.50", "0.000"], ["71236.00", "0.000"]], "a": [["71225.50", "7.145"], ["71225.60", "0.210"], ["71225.70", "0.000"], ["71225.80", "0.000"], ["71226.00", "0.002"], ["71226.10", "0.000"], ["71226.20", "0.002"], ["71226.30", "0.000"], ["71226.40", "0.000"], ["71226.50", "0.000"], ["71226.60", "0.003"], ["71226.70", "0.000"], ["71226.80", "0.000"], ["71226.90", "0.000"], ["71227.00", "1.290"], ["71227.10", "0.000"], ["71227.20", "0.004"], ["71227.30", "0.003"], ["71227.40", "0.000"], ["71227.50", "0.000"], ["71227.70", "0.000"], ["71227.80", "0.027"], ["71227.90", "0.005"], ["71228.00", "0.070"], ["71228.10", "0.000"], ["71228.40", "0.000"], ["71228.50", "0.002"], ["71228.60", "0.005"], ["71228.70", "0.000"], ["71228.90", "0.124"], ["71229.00", "0.000"], ["71229.20", "0.018"], ["71229.30", "0.017"], ["71229.40", "0.115"], ["71229.50", "0.000"], ["71229.60", "0.132"], ["71229.70", "0.006"], ["71229.90", "0.009"], ["71230.00", "0.002"], ["71230.10", "1.057"], ["71230.20", "1.103"], ["71230.30", "0.046"], ["71230.40", "0.019"], ["71230.50", "0.014"], ["71230.60", "0.023"], ["71230.70", "0.007"], ["71230.80", "0.016"], ["71230.90", "0.014"], ["71231.00", "0.018"], ["71231.10", "0.014"], ["71231.20", "0.016"], ["71231.30", "0.050"], ["71231.40", "0.000"], ["71231.50", "0.000"], ["71231.60", "0.002"], ["71231.70", "0.005"], ["71231.80", "0.008"], ["71231.90", "0.134"], ["71232.00", "0.004"], ["71232.10", "0.003"], ["71232.20", "0.001"], ["71232.30", "0.412"], ["71232.40", "0.004"], ["71232.50", "0.002"], ["71232.60", "0.002"], ["71232.70", "0.001"], ["71232.80", "0.000"], ["71232.90", "0.417"], ["71233.00", "0.000"], ["71233.10", "0.001"], ["71233.20", "0.000"], ["71233.30", "0.000"], ["71233.40", "0.002"], ["71233.50", "0.001"], ["71233.60", "0.000"], ["71233.70", "1.083"], ["71233.80", "0.010"], ["71233.90", "0.004"], ["71234.00", "0.000"], ["71234.20", "0.001"], ["71234.30", "0.000"], ["71234.40", "0.002"], ["71234.50", "0.003"], ["71234.60", "0.000"], ["71234.70", "0.002"], ["71234.80", "0.247"], ["71234.90", "0.001"], ["71235.00", "0.002"], ["71235.10", "0.000"], ["71235.20", "0.140"], ["71235.30", "0.002"], ["71235.40", "0.018"], ["71235.50", "0.131"], ["71235.60", "0.108"], ["71235.70", "0.039"], ["71235.80", "0.017"], ["71235.90", "0.441"], ["71236.00", "1.107"], ["71236.10", "2.225"], ["71236.20", "0.004"], ["71236.30", "0.037"], ["71236.40", "0.023"], ["71236.50", "0.000"], ["71236.60", "0.631"], ["71236.70", "0.052"], ["71236.80", "0.000"], ["71236.90", "0.000"], ["71237.00", "0.127"], ["71237.10", "0.000"], ["71237.20", "0.026"], ["71237.30", "0.309"], ["71237.40", "0.000"], ["71237.50", "0.056"], ["71237.60", "0.005"], ["71237.70", "0.096"], ["71237.80", "0.000"], ["71237.90", "0.004"], ["71238.10", "0.008"], ["71238.20", "0.041"], ["71238.30", "0.000"], ["71238.40", "0.000"], ["71238.60", "0.031"], ["71238.70", "0.000"], ["71238.80", "0.000"], ["71238.90", "0.002"], ["71239.00", "0.008"], ["71239.10", "0.003"], ["71239.20", "0.028"], ["71239.40", "0.053"], ["71239.50", "0.073"], ["71239.60", "0.007"], ["71239.70", "0.221"], ["71239.80", "0.000"], ["71240.00", "0.003"], ["71240.10", "0.000"], ["71240.20", "0.000"], ["71240.30", "0.164"], ["71240.40", "0.009"], ["71240.50", "0.000"], ["71240.60", "0.027"], ["71240.70", "0.001"], ["71240.80", "0.037"], ["71240.90", "0.003"], ["71241.00", "0.095"], ["71241.10", "0.268"], ["71241.30", "0.000"], ["71241.50", "0.005"], ["71241.80", "0.001"], ["71241.90", "0.002"], ["71242.00", "0.005"], ["71242.10", "0.004"], ["71242.20", "0.000"], ["71242.30", "0.000"], ["71242.40", "0.008"], ["71242.50", "0.080"], ["71242.90", "0.002"], ["71243.00", "0.002"], ["71243.10", "0.006"], ["71243.20", "0.002"], ["71243.30", "0.003"], ["71243.60", "0.000"], ["71243.70", "0.034"], ["71243.80", "0.000"], ["71244.00", "0.002"], ["71244.20", "0.361"], ["71244.40", "0.000"], ["71244.50", "0.000"], ["71244.60", "0.031"], ["71244.70", "0.000"], ["71244.90", "1.910"], ["71245.00", "1.072"], ["71245.10", "0.336"], ["71245.20", "0.245"], ["71245.30", "0.282"], ["71245.50", "0.517"], ["71245.60", "0.003"], ["71245.70", "0.253"], ["71245.80", "0.055"], ["71245.90", "0.005"], ["71246.00", "0.290"], ["71246.30", "0.069"], ["71246.50", "0.111"], ["71246.60", "0.059"], ["71246.70", "0.007"], ["71246.80", "0.505"], ["71246.90", "0.246"], ["71247.00", "0.011"], ["71247.10", "0.507"], ["71247.20", "0.453"], ["71247.40", "0.002"], ["71247.50", "0.057"], ["71247.60", "0.002"], ["71247.80", "0.732"], ["71247.90", "0.177"], ["71248.00", "0.005"], ["71248.10", "0.004"], ["71248.20", "0.008"], ["71248.40", "0.003"], ["71248.50", "0.006"], ["71248.60", "0.001"], ["71248.70", "0.002"], ["71248.80", "0.003"], ["71248.90", "0.425"], ["71249.10", "0.005"], ["71249.20", "0.005"], ["71249.30", "0.001"], ["71249.50", "0.009"], ["71249.60", "0.000"], ["71249.80", "0.286"], ["71249.90", "0.385"], ["71250.00", "1.009"], ["71250.20", "0.518"], ["71250.30", "0.000"], ["71250.70", "0.349"], ["71250.80", "1.055"], ["71250.90", "0.001"], ["71251.00", "0.017"], ["71251.10", "0.060"], ["71251.30", "0.204"], ["71251.60", "0.211"], ["71251.70", "0.035"], ["71251.90", "0.002"], ["71252.10", "0.245"], ["71252.30", "0.002"], ["71252.40", "0.001"], ["71252.50", "0.000"], ["71252.60", "0.002"], ["71252.70", "0.006"], ["71252.90", "0.012"], ["71253.00", "0.020"], ["71253.10", "0.002"], ["71253.30", "0.210"], ["71253.40", "0.204"], ["71253.70", "0.063"], ["71253.80", "0.011"], ["71253.90", "0.000"], ["71254.20", "0.050"], ["71254.30", "0.007"], ["71254.40", "0.083"], ["71254.50", "0.004"], ["71254.90", "0.000"], ["71255.00", "0.022"], ["71255.10", "0.213"], ["71255.20", "0.000"], ["71255.30", "0.603"], ["71255.40", "0.005"], ["71255.70", "0.002"], ["71255.80", "0.517"], ["71255.90", "0.012"], ["71256.00", "0.351"], ["71256.10", "1.174"], ["71256.20", "0.004"], ["71256.40", "0.001"], ["71256.50", "0.111"], ["71256.60", "0.003"], ["71256.70", "0.000"], ["71256.80", "1.051"], ["71257.00", "0.005"], ["71257.10", "0.002"], ["71257.20", "0.159"], ["71257.30", "0.000"], ["71257.50", "0.508"], ["71257.80", "0.007"], ["71257.90", "0.074"], ["71258.00", "0.007"], ["71258.20", "0.000"], ["71258.60", "0.003"], ["71258.70", "0.005"], ["71258.80", "0.034"], ["71259.00", "0.019"], ["71259.30", "0.007"], ["71259.40", "0.302"], ["71259.70", "0.510"], ["71259.80", "0.003"], ["71260.00", "0.309"], ["71260.10", "0.000"], ["71260.60", "0.086"], ["71260.80", "0.001"], ["71260.90", "0.308"], ["71261.10", "0.210"], ["71261.20", "0.000"], ["71261.40", "0.049"], ["71261.50", "0.020"], ["71262.00", "0.003"], ["71262.10", "0.008"], ["71262.20", "0.000"], ["71262.70", "0.003"], ["71262.80", "0.288"], ["71262.90", "0.003"], ["71263.20", "0.301"], ["71263.50", "0.008"], ["71263.60", "0.006"], ["71264.40", "0.002"], ["71264.70", "0.000"], ["71264.80", "0.041"], ["71265.00", "0.002"], ["71265.30", "1.272"], ["71265.40", "0.285"], ["71265.50", "0.484"], ["71266.10", "0.000"], ["71266.70", "0.006"], ["71266.80", "0.592"], ["71267.00", "0.072"], ["71267.60", "0.000"], ["71267.90", "0.338"], ["71268.10", "0.015"], ["71268.20", "0.342"], ["71268.30", "1.909"], ["71268.50", "0.074"], ["71268.60", "0.321"], ["71268.70", "0.002"], ["71268.90", "0.140"], ["71269.00", "0.032"], ["71270.00", "0.007"], ["71270.10", "0.009"], ["71270.20", "0.002"], ["71270.60", "0.000"], ["71270.70", "0.018"], ["71270.80", "0.003"], ["71271.00", "0.002"], ["71271.20", "0.008"], ["71271.40", "0.103"], ["71272.20", "0.003"], ["71272.30", "0.100"], ["71272.70", "0.000"], ["71273.00", "0.074"], ["71273.10", "0.000"], ["71273.20", "0.830"], ["71274.10", "0.000"], ["71274.20", "0.000"], ["71274.30", "0.003"], ["71274.50", "1.902"], ["71274.80", "0.003"], ["71274.90", "0.025"], ["71275.20", "0.001"], ["71275.30", "0.006"], ["71275.50", "0.001"], ["71276.10", "0.063"], ["71276.20", "0.000"], ["71276.40", "0.118"], ["71276.80", "0.003"], ["71277.10", "0.328"], ["71277.90", "0.000"], ["71278.80", "0.036"], ["71278.90", "0.023"], ["71279.20", "0.207"], ["71279.90", "0.050"], ["71280.20", "0.796"], ["71280.40", "0.102"], ["71280.60", "0.002"], ["71280.70", "0.585"], ["71281.10", "0.000"], ["71281.20", "0.048"], ["71281.30", "0.181"], ["71282.00", "0.093"], ["71282.40", "0.116"], ["71282.50", "0.115"], ["71282.60", "0.624"], ["71282.90", "0.009"], ["71283.00", "0.021"], ["71283.40", "0.003"], ["71283.50", "0.154"], ["71283.70", "0.067"], ["71284.10", "0.085"], ["71284.20", "0.009"], ["71284.70", "0.103"], ["71284.90", "0.008"], ["71285.10", "0.409"], ["71286.00", "0.150"], ["71286.30", "0.089"], ["71287.30", "0.318"], ["71287.40", "0.003"], ["71288.00", "0.159"], ["71289.00", "0.004"], ["71289.10", "0.242"], ["71290.60", "0.002"], ["71291.80", "0.100"], ["71292.10", "0.000"], ["71293.20", "0.085"], ["71294.20", "0.000"], ["71295.50", "0.000"], ["71296.00", "0.138"], ["71296.70", "0.005"], ["71297.70", "0.000"], ["71297.90", "0.003"], ["71298.00", "1.061"], ["71299.80", "0.002"], ["71299.90", "0.303"], ["71300.00", "3.349"], ["71300.20", "0.005"], ["71300.30", "0.000"], ["71301.50", "0.008"], ["71302.00", "0.010"], ["71302.80", "0.049"], ["71305.10", "0.006"], ["71305.30", "0.005"], ["71306.00", "0.002"], ["71306.10", "0.324"], ["71306.90", "0.000"], ["71307.30", "0.000"], ["71307.40", "0.099"], ["71307.50", "0.506"], ["71308.00", "0.159"], ["71308.60", "0.005"], ["71309.20", "0.016"], ["71312.50", "0.508"], ["71312.70", "0.101"], ["71313.20", "0.002"], ["71313.30", "0.004"], ["71313.40", "0.000"], ["71314.10", "0.000"], ["71314.30", "0.272"], ["71314.50", "0.437"], ["71314.60", "1.179"], ["71315.20", "0.013"], ["71316.20", "1.000"], ["71316.80", "1.647"], ["71317.00", "0.002"], ["71317.40", "0.007"], ["71318.10", "0.002"], ["71319.20", "0.006"], ["71319.60", "0.201"], ["71319.90", "0.352"], ["71320.30", "0.038"], ["71321.80", "0.000"], ["71322.60", "0.003"], ["71322.90", "0.009"], ["71323.00", "0.016"], ["71323.30", "0.100"], ["71323.70", "0.007"], ["71324.00", "0.000"], ["71324.10", "0.000"], ["71324.20", "0.223"], ["71324.80", "0.000"], ["71324.90", "0.206"], ["71329.60", "0.286"], ["71329.80", "4.047"], ["71329.90", "0.207"], ["71330.50", "0.000"], ["71330.80", "0.000"], ["71331.30", "0.248"], ["71332.30", "0.153"], ["71332.80", "0.132"], ["71333.00", "0.167"], ["71338.10", "10.077"], ["71338.30", "0.010"], ["71341.30", "1.320"], ["71343.70", "0.042"], ["71345.20", "0.020"], ["71345.40", "0.000"], ["71346.30", "0.103"], ["71348.40", "0.000"], ["71350.50", "0.112"], ["71352.60", "0.288"], ["71353.70", "0.055"], ["71353.80", "0.106"], ["71356.20", "0.314"], ["71361.90", "0.002"], ["71363.30", "0.093"], ["71368.00", "0.041"], ["71371.20", "0.018"], ["71371.60", "0.002"], ["71372.70", "0.007"], ["71372.90", "0.509"], ["71375.50", "0.040"], ["71376.60", "0.341"], ["71383.30", "0.000"], ["71385.80", "0.198"], ["71389.30", "0.159"], ["71390.60", "0.002"], ["71392.80", "0.009"], ["71392.90", "0.164"], ["71396.40", "0.062"], ["71396.50", "0.000"], ["71396.90", "0.000"], ["71397.80", "0.004"], ["71397.90", "0.002"], ["71398.90", "0.000"], ["71400.60", "0.000"], ["71400.90", "0.002"], ["71403.60", "0.203"], ["71407.20", "0.057"], ["71410.00", "1.013"], ["71410.70", "0.012"], ["71412.40", "3.509"], ["71412.80", "0.002"], ["71414.20", "0.000"], ["71416.50", "10.001"], ["71417.80", "0.030"], ["71432.00", "0.000"], ["71432.40", "0.000"], ["71432.60", "0.000"], ["71432.80", "0.000"], ["71434.90", "0.493"], ["71436.90", "0.000"], ["71438.40", "0.862"], ["71439.10", "0.000"], ["71439.60", "0.000"], ["71440.90", "0.000"], ["71447.90", "10.000"], ["71454.40", "0.000"], ["71469.70", "0.000"], ["71476.50", "0.085"], ["71481.00", "0.643"], ["71481.20", "0.000"], ["71485.80", "0.001"], ["71495.00", "0.000"], ["71497.50", "0.000"], ["71512.50", "0.002"], ["71513.10", "0.000"], ["71518.80", "0.609"], ["71532.10", "0.000"], ["71538.10", "0.000"], ["71591.60", "0.000"], ["71621.80", "0.000"], ["71625.20", "0.000"], ["71627.40", "0.000"], ["71646.00", "0.000"], ["71937.80", "0.011"], ["71938.60", "0.006"], ["71938.90", "0.000"], ["71939.40", "0.007"], ["71946.20", "1.434"], ["71948.00", "0.263"], ["72223.60", "1.782"], ["72225.40", "0.000"], ["72225.50", "0.908"], ["72227.30", "0.356"], ["72228.40", "1.589"], ["72228.90", "0.005"], ["72229.40", "0.006"], ["72229.60", "0.002"], ["72230.30", "0.008"], ["72237.50", "0.010"], ["72237.80", "0.286"], ["72340.40", "1.318"], ["73060.80", "0.003"], ["74813.10", "0.000"]]}}
{"local_ts": 1773384539601, "server_ts": 1773384539371, "data": {"e": "depthUpdate", "E": 1773384539373, "T": 1773384539371, "s": "BTCUSDT", "U": 10101340513972, "u": 10101340521605, "pu": 10101340513625, "b": [["1000.00", "27.492"], ["5000.00", "101.418"], ["20825.40", "0.810"], ["20933.80", "0.000"], ["21025.40", "1.458"], ["21133.80", "0.063"], ["67651.50", "0.002"], ["67668.00", "0.014"], ["70301.90", "0.000"], ["70513.10", "0.002"], ["70892.30", "0.002"], ["71113.60", "0.043"], ["71140.70", "0.126"], ["71148.70", "0.036"], ["71153.10", "0.125"], ["71158.70", "0.157"], ["71201.80", "0.842"], ["71202.40", "0.463"], ["71204.70", "0.440"], ["71204.80", "0.012"], ["71205.00", "0.013"], ["71205.60", "0.020"], ["71206.10", "0.002"], ["71206.30", "0.006"], ["71217.10", "0.032"], ["71222.90", "0.097"], ["71225.40", "4.810"]], "a": [["71241.50", "0.028"], ["71241.70", "0.000"], ["71241.80", "0.004"], ["71243.30", "0.385"], ["71245.60", "0.003"], ["71250.20", "0.085"], ["71250.60", "0.004"], ["71252.80", "0.248"], ["71258.90", "0.003"], ["71272.80", "0.625"], ["71276.90", "0.018"], ["71277.10", "0.328"], ["71282.50", "0.274"], ["71286.30", "0.004"], ["71314.50", "0.253"], ["71317.60", "0.062"], ["71318.40", "0.243"], ["71354.90", "2.410"], ["71361.00", "0.100"], ["71389.30", "0.041"], ["71414.20", "0.159"], ["71417.80", "0.030"], ["71937.80", "0.007"], ["72085.30", "0.000"], ["72549.80", "0.016"], ["72551.70", "1.032"]]}}
{"local_ts": 1773384540610, "server_ts": 1773384540392, "data": {"e": "depthUpdate", "E": 1773384540393, "T": 1773384540392, "s": "BTCUSDT", "U": 10101340655421, "u": 10101340667624, "pu": 10101340655358, "b": [["1000.00", "27.492"], ["5000.00", "101.418"], ["20722.90", "0.261"], ["20825.40", "0.135"], ["20922.90", "0.531"], ["21025.40", "0.513"], ["67638.30", "0.000"], ["67643.20", "0.002"], ["70119.00", "0.997"], ["70136.50", "0.000"], ["70190.30", "1.992"], ["70510.70", "2.832"], ["70545.30", "0.000"], ["70675.90", "0.000"], ["70917.40", "0.004"], ["70917.80", "0.315"], ["70941.30", "0.004"], ["70949.60", "0.002"], ["70971.10", "0.011"], ["70971.60", "0.288"], ["71001.10", "0.339"], ["71001.20", "0.002"], ["71024.90", "0.003"], ["71025.40", "0.306"], ["71053.80", "2.526"], ["71053.90", "0.000"], ["71071.40", "4.811"], ["71078.70", "0.511"], ["71079.10", "0.347"], ["71094.20", "0.000"], ["71106.50", "0.006"], ["71118.70", "0.031"], ["71127.00", "0.220"], ["71131.20", "3.550"], ["71132.40", "0.003"], ["71132.90", "0.222"], ["71159.10", "0.083"], ["71159.20", "0.017"], ["71178.60", "0.111"], ["71181.80", "0.053"], ["71182.20", "0.093"], ["71182.50", "0.001"], ["71183.10", "0.040"], ["71184.30", "0.031"], ["71186.30", "0.870"], ["71187.10", "1.093"], ["71187.80", "0.304"], ["71192.60", "0.022"], ["71193.40", "0.576"], ["71195.20", "0.430"], ["71195.50", "0.328"], ["71196.80", "0.066"], ["71198.00", "0.034"], ["71199.30", "0.003"], ["71200.00", "100.667"], ["71201.20", "0.515"], ["71201.50", "0.340"], ["71201.80", "0.037"], ["71202.90", "0.004"], ["71204.60", "0.038"], ["71205.60", "0.003"], ["71205.70", "0.304"], ["71206.20", "0.023"], ["71206.30", "0.001"], ["71206.70", "0.002"], ["71208.30", "0.019"], ["71208.50", "0.081"], ["71209.30", "0.103"], ["71210.70", "0.003"], ["71211.10", "0.255"], ["71211.80", "0.007"], ["71212.20", "0.289"], ["71212.80", "0.005"], ["71215.80", "0.788"], ["71220.60", "0.005"], ["71222.90", "0.694"]], "a": [["71225.30", "0.000"], ["71225.40", "1.106"], ["71226.50", "0.008"], ["71226.80", "0.102"], ["71227.00", "0.053"], ["71227.10", "0.080"], ["71227.20", "0.004"], ["71230.10", "0.067"], ["71231.80", "0.046"], ["71232.00", "0.008"], ["71232.20", "0.001"], ["71232.90", "0.572"], ["71234.10", "0.061"], ["71235.20", "0.050"], ["71235.70", "0.000"], ["71235.80", "0.024"], ["71237.10", "0.014"], ["71237.80", "0.066"], ["71238.10", "0.637"], ["71240.10", "0.617"], ["71240.50", "0.226"], ["71243.10", "0.003"], ["71244.50", "0.379"], ["71246.60", "0.007"], ["71255.00", "0.366"], ["71258.60", "0.053"], ["71260.40", "0.142"], ["71262.10", "0.046"], ["71272.80", "0.595"], ["71272.90", "0.005"], ["71293.80", "0.105"], ["71294.30", "0.242"], ["71317.20", "0.075"], ["71317.30", "0.007"], ["71332.20", "0.007"], ["71338.30", "0.000"], ["71340.70", "0.000"], ["71347.60", "0.005"], ["71348.10", "0.466"], ["71369.90", "0.509"], ["71401.40", "0.005"], ["71401.80", "0.292"], ["71422.60", "0.000"], ["71452.30", "0.000"], ["71455.10", "0.004"], ["71455.60", "10.313"], ["71475.20", "0.000"], ["71475.30", "0.000"], ["71510.50", "2.995"], ["71519.10", "0.000"], ["71527.00", "0.006"], ["71527.90", "0.015"], ["71817.90", "0.070"], ["71935.20", "0.695"], ["72077.40", "0.015"], ["72436.30", "0.490"], ["74097.20", "0.000"], ["74817.80", "0.002"]]}}
{"local_ts": 1773384541631, "server_ts": 1773384541412, "data": {"e": "depthUpdate", "E": 1773384541413, "T": 1773384541412, "s": "BTCUSDT", "U": 10101340792253, "u": 10101340809277, "pu": 10101340792006, "b": [["5000.00", "101.418"], ["20722.90", "0.270"], ["20822.00", "0.135"], ["20822.90", "0.882"], ["20922.90", "0.783"], ["21122.00", "0.063"], ["21122.90", "0.567"], ["66881.00", "4.000"], ["67633.20", "0.000"], ["67982.70", "0.019"], ["70445.80", "0.562"], ["70496.10", "0.000"], ["70508.80", "0.064"], ["70509.80", "2.127"], ["70510.70", "2.832"], ["70785.80", "0.028"], ["70881.70", "1.120"], ["70920.60", "0.305"], ["70961.40", "0.200"], ["70962.40", "0.001"], ["70983.50", "0.001"], ["70999.10", "1.219"], ["71070.10", "0.020"], ["71080.10", "0.000"], ["71087.30", "0.036"], ["71101.80", "0.259"], ["71105.30", "0.467"], ["71129.40", "2.006"], ["71142.40", "3.765"], ["71150.10", "0.511"], ["71150.70", "0.000"], ["71151.30", "0.003"], ["71151.80", "0.000"], ["71152.50", "0.463"], ["71153.90", "0.205"], ["71156.10", "0.000"], ["71157.10", "0.000"], ["71158.00", "0.018"], ["71159.00", "0.023"], ["71160.00", "0.024"], ["71160.90", "0.306"], ["71161.00", "2.846"], ["71161.80", "0.002"], ["71161.90", "0.005"], ["71162.80", "0.042"], ["71162.90", "0.000"], ["71163.80", "0.044"], ["71163.90", "0.033"], ["71164.80", "0.060"], ["71164.90", "0.000"], ["71165.00", "0.008"], ["71165.70", "0.043"], ["71165.80", "0.022"], ["71166.00", "0.237"], ["71166.30", "0.051"], ["71166.70", "0.000"], ["71168.30", "0.042"], ["71169.20", "0.043"], ["71170.00", "0.855"], ["71170.30", "0.051"], ["71170.60", "0.000"], ["71171.00", "0.046"], ["71171.70", "0.003"], ["71171.90", "0.005"], ["71172.20", "0.046"], ["71172.40", "0.177"], ["71174.30", "0.550"], ["71175.70", "0.044"], ["71176.80", "0.005"], ["71177.50", "0.006"], ["71177.70", "0.005"], ["71178.50", "0.003"], ["71179.20", "0.177"], ["71180.10", "0.010"], ["71180.40", "0.636"], ["71180.90", "0.050"], ["71182.20", "0.002"], ["71185.40", "0.025"], ["71185.60", "0.002"], ["71186.90", "0.003"], ["71187.90", "0.295"], ["71188.00", "0.032"], ["71188.30", "0.008"], ["71189.30", "1.945"], ["71189.40", "0.019"], ["71189.90", "0.003"], ["71190.20", "0.003"], ["71190.60", "0.256"], ["71190.90", "0.035"], ["71191.40", "0.004"], ["71191.50", "0.000"], ["71191.80", "0.003"], ["71192.10", "0.316"], ["71192.50", "0.019"], ["71192.60", "0.022"], ["71192.70", "0.223"], ["71193.10", "0.089"], ["71193.40", "0.576"], ["71193.50", "0.136"], ["71193.60", "0.004"], ["71193.70", "0.578"], ["71194.10", "0.005"], ["71194.40", "0.000"], ["71194.70", "0.032"], ["71194.90", "0.391"], ["71195.10", "0.036"], ["71195.40", "0.007"], ["71196.10", "0.005"], ["71196.20", "0.003"], ["71196.90", "0.028"], ["71197.00", "0.069"], ["71197.60", "0.003"], ["71198.60", "0.009"], ["71198.80", "0.033"], ["71199.10", "0.015"], ["71199.20", "0.006"], ["71199.50", "0.038"], ["71199.70", "1.217"], ["71199.90", "0.093"], ["71200.00", "100.667"], ["71200.20", "0.852"], ["71200.30", "0.397"], ["71200.40", "0.314"], ["71200.50", "0.090"], ["71200.60", "0.185"], ["71200.70", "0.262"], ["71200.80", "0.245"], ["71200.90", "0.210"], ["71201.00", "0.018"], ["71201.10", "0.004"], ["71201.40", "0.000"], ["71202.10", "0.534"], ["71202.30", "0.000"], ["71202.40", "0.279"], ["71203.40", "0.122"], ["71203.50", "1.290"], ["71204.20", "0.042"], ["71204.80", "0.002"], ["71204.90", "0.005"], ["71205.10", "0.010"], ["71205.20", "0.024"], ["71207.90", "0.042"], ["71208.10", "0.004"], ["71208.30", "0.002"], ["71208.50", "0.039"], ["71208.60", "0.001"], ["71210.40", "0.368"], ["71211.60", "0.003"], ["71211.90", "0.012"], ["71212.00", "0.005"], ["71212.80", "0.001"], ["71212.90", "0.012"], ["71214.10", "0.007"], ["71214.20", "0.019"], ["71214.80", "0.040"], ["71215.80", "0.005"], ["71216.00", "0.005"], ["71216.70", "0.000"], ["71217.60", "0.000"], ["71217.70", "0.009"], ["71217.90", "0.228"], ["71218.00", "0.014"], ["71218.10", "0.002"], ["71218.30", "0.210"], ["71218.70", "0.003"], ["71219.00", "0.005"], ["71219.50", "0.002"], ["71219.70", "0.002"], ["71220.80", "0.009"], ["71221.10", "0.000"], ["71221.60", "0.006"], ["71221.70", "0.002"], ["71221.90", "0.002"], ["71222.00", "0.461"], ["71222.10", "0.000"], ["71222.20", "0.000"], ["71222.40", "0.000"], ["71222.50", "0.000"], ["71222.60", "0.000"], ["71222.70", "0.000"], ["71222.90", "0.000"]], "a": [["71222.10", "8.131"], ["71222.20", "0.002"], ["71222.30", "0.000"], ["71222.40", "0.002"], ["71222.50", "0.283"], ["71222.60", "0.000"], ["71222.70", "0.000"], ["71222.80", "0.017"], ["71222.90", "1.100"], ["71223.00", "0.119"], ["71223.10", "0.210"], ["71223.90", "0.003"], ["71224.10", "0.000"], ["71224.20", "0.460"], ["71224.30", "1.100"], ["71224.40", "0.003"], ["71225.20", "0.004"], ["71225.30", "0.005"], ["71225.40", "1.106"], ["71226.20", "0.023"], ["71226.40", "0.004"], ["71226.50", "0.093"], ["71226.60", "0.200"], ["71226.80", "0.050"], ["71227.40", "0.001"], ["71229.50", "0.010"], ["71229.70", "0.006"], ["71230.10", "0.007"], ["71231.50", "0.278"], ["71231.60", "0.664"], ["71231.70", "0.003"], ["71231.80", "0.046"], ["71231.90", "0.001"], ["71232.20", "0.003"], ["71232.80", "0.017"], ["71233.70", "0.105"], ["71234.20", "0.326"], ["71234.30", "0.081"], ["71234.50", "0.347"], ["71234.60", "0.070"], ["71234.90", "0.061"], ["71235.20", "0.405"], ["71235.30", "0.032"], ["71235.40", "0.032"], ["71235.50", "0.060"], ["71235.60", "0.055"], ["71235.70", "0.032"], ["71235.80", "0.003"], ["71236.00", "0.009"], ["71236.20", "0.020"], ["71236.30", "0.003"], ["71236.40", "0.080"], ["71236.50", "0.000"], ["71236.60", "0.002"], ["71236.70", "0.084"], ["71236.80", "0.037"], ["71236.90", "0.000"], ["71237.10", "0.000"], ["71237.20", "0.022"], ["71237.30", "0.407"], ["71237.50", "0.664"], ["71237.60", "0.043"], ["71237.70", "0.046"], ["71237.90", "0.073"], ["71238.20", "0.004"], ["71238.50", "0.003"], ["71238.60", "0.005"], ["71238.90", "0.004"], ["71241.10", "0.394"], ["71241.90", "0.002"], ["71242.40", "0.004"], ["71243.50", "0.104"], ["71244.30", "0.000"], ["71244.40", "0.073"], ["71246.70", "0.011"], ["71246.80", "0.639"], ["71247.40", "0.002"], ["71247.50", "0.004"], ["71248.10", "0.007"], ["71250.10", "0.037"], ["71250.60", "0.214"], ["71251.20", "0.001"], ["71251.50", "0.175"], ["71252.30", "0.004"], ["71252.40", "0.003"], ["71253.00", "0.073"], ["71253.10", "0.037"], ["71257.70", "0.005"], ["71258.60", "0.333"], ["71259.30", "0.003"], ["71260.90", "0.308"], ["71261.80", "0.143"], ["71262.50", "0.756"], ["71263.80", "0.280"], ["71264.00", "0.144"], ["71266.10", "0.000"], ["71268.60", "0.044"], ["71272.20", "0.074"], ["71272.50", "0.002"], ["71273.00", "0.004"], ["71274.00", "0.325"], ["71274.40", "0.002"], ["71276.70", "0.003"], ["71276.90", "0.000"], ["71279.10", "0.041"], ["71284.20", "0.006"], ["71286.20", "0.184"], ["71286.30", "0.089"], ["71287.10", "0.396"], ["71289.80", "0.083"], ["71290.70", "0.000"], ["71293.30", "0.093"], ["71297.80", "0.007"], ["71301.00", "0.000"], ["71301.10", "0.004"], ["71302.20", "0.427"], ["71302.40", "0.301"], ["71302.90", "0.001"], ["71304.50", "0.000"], ["71306.90", "0.165"], ["71310.80", "0.000"], ["71314.70", "2.167"], ["71316.10", "1.772"], ["71319.00", "0.564"], ["71322.20", "0.043"], ["71336.00", "0.599"], ["71336.60", "0.002"], ["71370.00", "2.307"], ["71403.70", "0.159"], ["71407.30", "0.473"], ["71408.20", "0.005"], ["71411.40", "0.000"], ["71427.10", "0.000"], ["71428.60", "0.003"], ["71432.10", "0.003"], ["71464.80", "0.000"], ["71485.80", "0.000"], ["71491.40", "0.002"], ["71507.00", "0.620"], ["71507.60", "0.000"], ["71507.90", "0.000"], ["71934.30", "0.000"], ["71935.20", "0.695"], ["72212.00", "1.786"], ["72646.50", "0.003"], ["72861.10", "0.548"], ["73359.60", "0.000"], ["74083.20", "0.005"], ["74795.50", "0.052"], ["89523.20", "0.000"], ["100000.00", "15.554"]]}}
{"local_ts": 1773384542652, "server_ts": 1773384542431, "data": {"e": "depthUpdate", "E": 1773384542433, "T": 1773384542431, "s": "BTCUSDT", "U": 10101340978453, "u": 10101340985172, "pu": 10101340978222, "b": [["1000.00", "27.492"], ["5000.00", "101.418"], ["20709.40", "0.540"], ["20822.90", "0.135"], ["21009.40", "0.288"], ["21122.90", "0.072"], ["56980.00", "0.000"], ["67643.20", "0.000"], ["69794.50", "0.002"], ["70355.00", "1.292"], ["70497.30", "0.004"], ["70866.80", "0.041"], ["70882.70", "0.004"], ["70904.90", "0.000"], ["70943.60", "0.002"], ["70954.40", "0.005"], ["70970.90", "0.003"], ["71035.10", "0.002"], ["71059.00", "0.050"], ["71062.50", "0.012"], ["71062.60", "0.048"], ["71069.50", "0.633"], ["71070.80", "0.103"], ["71098.50", "0.006"], ["71099.00", "0.008"], ["71101.90", "0.001"], ["71104.10", "0.001"], ["71105.40", "0.500"], ["71107.70", "0.003"], ["71119.90", "0.040"], ["71121.80", "0.408"], ["71127.90", "0.107"], ["71129.90", "0.042"], ["71146.60", "1.227"], ["71151.30", "0.001"], ["71151.70", "1.337"], ["71151.80", "0.942"], ["71155.00", "0.004"], ["71156.80", "0.322"], ["71163.30", "0.003"], ["71163.60", "0.005"], ["71169.90", "0.109"], ["71173.40", "0.006"], ["71173.50", "0.053"], ["71173.60", "0.004"], ["71173.80", "0.030"], ["71173.90", "0.006"], ["71174.00", "0.005"], ["71175.80", "0.270"], ["71176.50", "0.000"], ["71188.80", "0.001"], ["71189.20", "0.037"], ["71190.90", "0.011"], ["71193.00", "0.004"], ["71194.10", "0.014"], ["71195.50", "0.000"], ["71196.50", "0.007"], ["71196.90", "0.028"], ["71197.10", "0.008"], ["71197.50", "0.008"], ["71198.30", "0.004"], ["71199.60", "0.057"], ["71199.70", "0.002"], ["71200.40", "0.087"], ["71200.50", "0.555"], ["71200.80", "0.003"], ["71201.00", "0.083"], ["71201.20", "0.077"], ["71202.30", "0.104"], ["71202.60", "0.019"], ["71204.40", "0.377"], ["71208.20", "0.005"], ["71208.80", "0.018"], ["71209.10", "0.062"], ["71209.30", "0.049"], ["71209.40", "7.567"]], "a": [["71209.50", "6.128"], ["71209.60", "0.001"], ["71210.90", "0.003"], ["71211.60", "0.001"], ["71212.30", "0.001"], ["71213.20", "0.004"], ["71213.30", "0.003"], ["71213.40", "0.002"], ["71213.50", "0.002"], ["71213.90", "1.101"], ["71214.00", "0.009"], ["71214.10", "0.001"], ["71214.20", "0.000"], ["71214.30", "0.000"], ["71214.40", "0.001"], ["71214.50", "0.003"], ["71214.60", "0.000"], ["71214.70", "0.003"], ["71214.80", "0.004"], ["71214.90", "0.005"], ["71215.00", "0.003"], ["71216.00", "0.006"], ["71216.70", "0.019"], ["71216.90", "0.000"], ["71218.00", "0.040"], ["71218.10", "0.088"], ["71218.30", "0.003"], ["71219.90", "0.092"], ["71220.20", "0.083"], ["71220.90", "0.036"], ["71221.00", "0.050"], ["71221.70", "0.134"], ["71222.00", "0.079"], ["71222.10", "0.233"], ["71222.80", "0.382"], ["71222.90", "0.647"], ["71223.30", "0.000"], ["71224.30", "0.140"], ["71226.90", "0.059"], ["71228.00", "0.083"], ["71233.30", "0.000"], ["71234.10", "0.000"], ["71234.40", "0.360"], ["71234.50", "0.003"], ["71234.60", "0.506"], ["71235.10", "0.036"], ["71235.20", "0.111"], ["71236.80", "0.002"], ["71238.60", "0.073"], ["71238.80", "0.000"], ["71239.90", "0.075"], ["71241.10", "0.270"], ["71242.50", "0.009"], ["71243.70", "0.022"], ["71245.10", "0.257"], ["71247.40", "0.945"], ["71250.80", "1.049"], ["71251.20", "0.303"], ["71252.20", "0.001"], ["71253.60", "0.002"], ["71255.00", "0.465"], ["71258.40", "0.792"], ["71261.60", "0.002"], ["71261.80", "0.017"], ["71268.70", "0.007"], ["71290.00", "0.010"], ["71305.50", "0.010"], ["71306.90", "0.100"], ["71307.00", "0.075"], ["71310.00", "0.217"], ["71314.30", "0.316"], ["71331.20", "0.000"], ["71332.20", "0.080"], ["71340.10", "0.003"], ["71340.20", "0.304"], ["71346.40", "0.000"], ["71352.50", "0.000"], ["71451.50", "0.000"], ["71921.60", "0.000"], ["72077.70", "0.970"], ["72135.20", "3.451"], ["72212.00", "0.826"], ["72250.90", "0.968"], ["73475.30", "0.000"], ["74804.40", "0.005"], ["89523.20", "0.000"]]}}
{"local_ts": 1773384543668, "server_ts": 1773384543450, "data": {"e": "depthUpdate", "E": 1773384543453, "T": 1773384543450, "s": "BTCUSDT", "U": 10101341050582, "u": 10101341056180, "pu": 10101341050433, "b": [["5000.00", "101.398"], ["20709.40", "1.323"], ["20909.40", "0.360"], ["21009.40", "0.540"], ["21109.40", "0.477"], ["33000.00", "9.339"], ["56968.00", "0.000"], ["69785.60", "0.004"], ["69800.90", "0.637"], ["70497.30", "0.004"], ["70639.70", "0.283"], ["70853.40", "0.029"], ["70943.60", "0.000"], ["70945.20", "0.002"], ["70960.10", "0.004"], ["71050.70", "0.020"], ["71055.00", "0.432"], ["71185.80", "0.008"], ["71189.40", "0.008"], ["71190.30", "0.005"], ["71193.80", "0.016"], ["71198.00", "0.030"], ["71198.90", "0.053"], ["71200.00", "0.637"], ["71200.30", "0.199"], ["71203.70", "0.161"]], "a": [["71209.50", "4.828"], ["71213.70", "0.014"], ["71214.60", "0.000"], ["71215.00", "0.003"], ["71215.40", "0.032"], ["71224.00", "0.045"], ["71224.50", "0.006"], ["71235.50", "0.007"], ["71250.10", "0.002"], ["71262.30", "0.007"], ["71262.40", "0.116"], ["71347.10", "0.018"], ["71350.40", "0.000"], ["71448.80", "0.000"], ["71514.70", "2.341"], ["71900.20", "2.890"], ["71906.70", "0.209"], ["71921.60", "0.138"], ["71939.00", "0.000"], ["71957.20", "1.858"], ["72002.20", "0.004"], ["72064.00", "3.458"], ["72116.20", "2.769"], ["72143.90", "0.686"], ["72180.30", "0.000"], ["72519.30", "0.483"], ["74790.70", "0.002"], ["76325.10", "0.002"], ["76915.60", "0.002"], ["89523.20", "0.000"]]}}
{"local_ts": 1773384544693, "server_ts": 1773384544476, "data": {"e": "depthUpdate", "E": 1773384544477, "T": 1773384544476, "s": "BTCUSDT", "U": 10101341142024, "u": 10101341148494, "pu": 10101341141898, "b": [["1000.00", "27.492"], ["5000.00", "101.418"], ["20709.40", "0.018"], ["20809.40", "0.234"], ["20909.40", "0.666"], ["21009.40", "0.234"], ["21109.40", "1.548"], ["56968.00", "0.000"], ["69785.60", "0.002"], ["70304.40", "3.408"], ["70433.20", "0.779"], ["70450.00", "8.197"], ["70497.30", "0.004"], ["70528.60", "0.002"], ["70853.40", "0.039"], ["70920.70", "0.002"], ["70924.40", "0.014"], ["70945.20", "0.000"], ["70959.50", "0.004"], ["71146.70", "0.000"], ["71163.20", "0.453"], ["71163.30", "0.001"], ["71163.40", "0.004"], ["71180.00", "0.042"], ["71182.80", "0.192"], ["71195.30", "0.004"], ["71196.30", "0.005"], ["71197.30", "0.042"], ["71198.60", "0.196"], ["71199.50", "0.056"], ["71199.70", "0.044"], ["71201.40", "0.003"]], "a": [["71212.90", "0.000"], ["71213.00", "1.100"], ["71213.30", "0.003"], ["71213.50", "0.138"], ["71236.90", "0.000"], ["71244.40", "0.000"], ["71708.60", "0.002"], ["71921.60", "0.138"], ["72242.00", "4.658"], ["72279.10", "1.934"], ["72313.20", "8.492"], ["72350.30", "0.966"], ["72565.10", "0.000"], ["73002.70", "2.467"], ["74782.10", "0.000"], ["89523.20", "0.000"]]}}
{"local_ts": 1773384545715, "server_ts": 1773384545497, "data": {"e": "depthUpdate", "E": 1773384545499, "T": 1773384545497, "s": "BTCUSDT", "U": 10101341235463, "u": 10101341240196, "pu": 10101341235412, "b": [["1000.00", "27.492"], ["5000.00", "101.438"], ["20709.40", "0.099"], ["20809.40", "0.801"], ["20909.40", "0.099"], ["21009.40", "1.548"], ["21109.40", "0.153"], ["33000.00", "9.343"], ["56968.00", "0.000"], ["67637.50", "0.005"], ["67648.90", "0.008"], ["69783.20", "0.002"], ["70497.30", "0.004"], ["70920.70", "0.000"], ["70921.70", "0.002"], ["71082.90", "0.077"], ["71084.80", "0.256"], ["71086.50", "0.079"], ["71119.20", "0.130"], ["71122.50", "2.116"], ["71126.30", "0.070"], ["71128.70", "0.199"], ["71129.80", "0.044"], ["71144.40", "0.105"], ["71159.80", "0.044"], ["71160.80", "0.050"], ["71167.60", "0.009"], ["71168.50", "0.000"], ["71173.30", "0.331"], ["71181.30", "0.056"], ["71181.50", "0.079"], ["71183.30", "0.000"], ["71189.40", "0.013"], ["71191.40", "0.004"], ["71193.90", "0.341"], ["71195.40", "0.371"], ["71197.20", "0.578"], ["71197.50", "0.013"], ["71199.50", "0.051"], ["71205.60", "0.012"], ["71207.50", "0.055"]], "a": [["71210.40", "0.002"], ["71211.20", "0.003"], ["71225.40", "0.090"], ["71244.50", "0.085"], ["71260.50", "0.127"], ["71260.90", "0.310"], ["71640.00", "0.405"], ["71779.20", "0.421"], ["71779.60", "0.052"], ["71921.60", "0.138"], ["72849.40", "1.226"], ["72922.20", "0.002"], ["73205.50", "1.192"], ["73283.30", "0.000"], ["89523.20", "0.000"]]}}
{"local_ts": 1773384546734, "server_ts": 1773384546517, "data": {"e": "depthUpdate", "E": 1773384546519, "T": 1773384546517, "s": "BTCUSDT", "U": 10101341298159, "u": 10101341302444, "pu": 10101341298101, "b": [["5000.00", "101.418"], ["20709.40", "0.864"], ["20809.40", "0.036"], ["20909.40", "1.476"], ["21009.40", "0.324"], ["56968.00", "0.000"], ["67640.60", "0.002"], ["68707.00", "0.003"], ["69783.20", "0.000"], ["70497.30", "1.427"], ["70921.70", "0.000"], ["70923.80", "6.484"], ["70926.50", "0.000"], ["70959.50", "0.004"], ["71128.20", "0.088"], ["71131.10", "0.085"], ["71145.30", "0.610"], ["71162.10", "0.000"], ["71163.30", "0.001"], ["71164.20", "0.002"], ["71164.50", "0.003"], ["71169.40", "0.624"], ["71170.40", "0.007"], ["71173.80", "0.042"], ["71185.50", "0.044"], ["71185.90", "0.149"], ["71187.90", "0.095"], ["71189.10", "0.347"], ["71190.30", "0.084"], ["71194.10", "0.012"], ["71197.60", "0.003"], ["71202.30", "0.043"], ["71204.90", "0.005"]], "a": [["71209.50", "5.203"], ["71210.30", "0.004"], ["71210.40", "0.058"], ["71210.60", "0.000"], ["71211.20", "0.001"], ["71211.30", "0.003"], ["71216.60", "0.039"], ["71224.10", "0.015"], ["71225.60", "0.007"], ["71226.40", "1.051"], ["71227.30", "0.005"], ["71236.90", "0.085"], ["71244.50", "0.000"], ["71245.10", "0.444"], ["71273.60", "0.086"], ["71287.90", "0.612"], ["71320.30", "0.000"], ["71320.40", "0.020"], ["71401.80", "0.451"], ["71436.70", "0.002"], ["71779.10", "0.007"], ["71921.60", "0.138"], ["72279.70", "2.554"], ["72405.80", "0.963"], ["72469.70", "0.688"], ["72549.00", "0.482"], ["72646.50", "0.000"], ["89523.20", "0.000"]]}}
{"local_ts": 1773384547758, "server_ts": 1773384547538, "data": {"e": "depthUpdate", "E": 1773384547539, "T": 1773384547538, "s": "BTCUSDT", "U": 10101341345479, "u": 10101341350314, "pu": 10101341345316, "b": [["1000.00", "27.492"], ["5000.00", "101.418"], ["20709.40", "0.171"], ["20809.40", "1.206"], ["20909.40", "0.594"], ["21109.40", "0.729"], ["56968.00", "0.000"], ["70010.70", "0.009"], ["70497.30", "1.427"], ["70639.70", "0.360"], ["70853.40", "0.029"], ["71069.50", "0.036"], ["71091.80", "0.212"], ["71092.10", "0.236"], ["71092.50", "0.036"], ["71092.80", "0.349"], ["71093.10", "0.025"], ["71093.50", "0.026"], ["71162.30", "0.274"], ["71166.00", "0.044"], ["71167.00", "0.049"], ["71168.00", "0.072"], ["71168.60", "0.052"], ["71168.90", "0.043"], ["71169.60", "0.054"], ["71169.90", "0.151"], ["71176.60", "0.105"], ["71177.90", "0.002"], ["71178.30", "0.272"], ["71179.20", "0.160"], ["71179.90", "0.000"], ["71180.90", "0.481"], ["71183.60", "0.072"], ["71184.60", "0.072"], ["71185.30", "0.003"], ["71186.40", "0.003"], ["71200.50", "0.633"], ["71200.60", "0.008"], ["71207.10", "0.004"], ["71209.40", "5.815"]], "a": [["71213.70", "0.004"], ["71259.70", "0.510"], ["71259.80", "0.097"], ["71434.00", "0.000"], ["71436.30", "0.293"], ["71921.50", "0.015"], ["71921.60", "0.138"], ["72549.00", "0.000"], ["74790.80", "0.000"], ["89523.20", "0.000"]]}}
{"local_ts": 1773384548781, "server_ts": 1773384548564, "data": {"e": "depthUpdate", "E": 1773384548565, "T": 1773384548564, "s": "BTCUSDT", "U": 10101341452053, "u": 10101341468072, "pu": 10101341451799, "b": [["5000.00", "101.418"], ["20709.40", "0.954"], ["20809.40", "0.846"], ["21009.40", "0.594"], ["21109.40", "0.306"], ["56968.00", "0.000"], ["67623.50", "0.004"], ["67628.60", "0.000"], ["70497.30", "1.434"], ["70853.50", "0.017"], ["70931.60", "0.000"], ["71015.90", "0.046"], ["71033.80", "0.044"], ["71035.70", "0.049"], ["71036.80", "0.055"], ["71080.20", "0.509"], ["71113.70", "0.144"], ["71114.80", "0.040"], ["71115.00", "1.145"], ["71129.60", "0.047"], ["71156.90", "0.000"], ["71157.60", "0.881"], ["71163.30", "0.187"], ["71163.40", "0.002"], ["71165.00", "0.008"], ["71165.30", "0.944"], ["71169.90", "0.105"], ["71175.20", "0.685"], ["71175.30", "0.003"], ["71175.90", "0.003"], ["71176.00", "0.006"], ["71176.40", "0.000"], ["71176.60", "0.107"], ["71176.70", "0.009"], ["71177.40", "0.026"], ["71177.50", "0.006"], ["71178.20", "1.249"], ["71178.30", "0.027"], ["71178.90", "2.519"], ["71179.30", "0.184"], ["71179.40", "0.040"], ["71179.50", "0.002"], ["71180.10", "0.004"], ["71180.20", "0.002"], ["71180.40", "0.601"], ["71180.80", "0.021"], ["71180.90", "0.411"], ["71181.50", "0.079"], ["71181.60", "0.000"], ["71181.90", "0.000"], ["71182.20", "0.004"], ["71182.30", "0.006"], ["71183.60", "0.000"], ["71184.30", "0.003"], ["71187.30", "0.636"], ["71187.90", "0.340"], ["71188.70", "0.105"], ["71188.90", "0.316"], ["71190.20", "0.003"], ["71190.70", "0.072"], ["71191.70", "1.070"], ["71193.60", "0.006"], ["71193.80", "0.007"], ["71195.20", "0.362"], ["71196.00", "0.004"], ["71197.20", "0.589"], ["71197.30", "0.072"], ["71197.50", "0.011"], ["71197.70", "0.002"], ["71199.50", "1.237"], ["71199.60", "0.049"], ["71199.70", "0.134"], ["71200.50", "1.045"], ["71200.60", "0.152"], ["71201.00", "0.649"], ["71201.10", "0.063"], ["71201.40", "0.088"], ["71202.00", "0.511"], ["71202.30", "0.109"], ["71202.40", "0.000"], ["71202.80", "0.002"], ["71203.60", "0.513"], ["71205.10", "0.037"], ["71205.50", "0.061"], ["71205.90", "0.018"], ["71206.10", "1.054"], ["71206.60", "0.002"], ["71206.90", "0.000"], ["71207.00", "0.006"], ["71207.20", "0.002"], ["71207.30", "0.018"], ["71207.50", "0.055"], ["71207.80", "0.127"], ["71208.00", "0.218"], ["71208.10", "0.001"], ["71208.20", "0.005"], ["71208.30", "1.125"], ["71209.40", "5.969"]], "a": [["71209.50", "0.261"], ["71212.90", "0.000"], ["71213.00", "0.004"], ["71213.30", "0.019"], ["71213.40", "0.030"], ["71213.60", "0.004"], ["71213.90", "0.005"], ["71214.40", "0.001"], ["71215.00", "0.003"], ["71216.00", "0.009"], ["71216.20", "0.000"], ["71216.60", "0.002"], ["71217.60", "0.067"], ["71218.40", "0.000"], ["71218.90", "0.004"], ["71219.50", "0.005"], ["71220.10", "0.178"], ["71220.90", "0.113"], ["71222.30", "0.004"], ["71224.10", "0.000"], ["71224.60", "0.000"], ["71224.80", "0.004"], ["71225.00", "0.010"], ["71225.60", "0.003"], ["71226.30", "0.194"], ["71226.40", "0.000"], ["71227.60", "0.677"], ["71227.90", "0.114"], ["71228.30", "0.000"], ["71228.40", "0.034"], ["71229.30", "0.014"], ["71230.10", "0.015"], ["71230.40", "0.154"], ["71230.90", "0.006"], ["71232.40", "0.009"], ["71232.70", "0.227"], ["71232.80", "0.003"], ["71233.60", "0.000"], ["71233.90", "0.028"], ["71234.40", "0.360"], ["71234.80", "0.000"], ["71234.90", "0.040"], ["71235.50", "0.007"], ["71235.60", "0.006"], ["71235.90", "0.348"], ["71236.10", "0.041"], ["71236.20", "0.182"], ["71236.30", "0.007"], ["71236.40", "0.004"], ["71236.50", "0.000"], ["71237.10", "0.004"], ["71237.90", "0.039"], ["71238.00", "0.729"], ["71238.60", "0.003"], ["71239.00", "1.157"], ["71239.10", "0.003"], ["71239.30", "0.633"], ["71239.70", "0.201"], ["71239.80", "0.106"], ["71240.40", "0.025"], ["71240.50", "0.228"], ["71240.80", "0.356"], ["71241.10", "0.270"], ["71241.20", "0.039"], ["71241.50", "0.424"], ["71241.80", "0.003"], ["71241.90", "0.004"], ["71242.70", "0.000"], ["71243.70", "0.092"], ["71244.00", "0.002"], ["71244.10", "0.000"], ["71245.10", "0.550"], ["71245.20", "0.751"], ["71245.70", "0.082"], ["71245.90", "0.002"], ["71247.00", "0.083"], ["71247.10", "0.000"], ["71248.50", "0.003"], ["71249.10", "0.004"], ["71250.00", "1.011"], ["71250.40", "0.508"], ["71255.80", "2.623"], ["71256.60", "0.056"], ["71256.80", "1.116"], ["71256.90", "0.000"], ["71257.20", "0.042"], ["71257.60", "0.001"], ["71258.10", "0.069"], ["71259.60", "0.383"], ["71259.70", "0.510"], ["71260.00", "0.308"], ["71260.50", "0.227"], ["71262.60", "1.049"], ["71267.60", "0.042"], ["71272.80", "0.504"], ["71275.50", "0.002"], ["71277.70", "0.104"], ["71280.70", "0.318"], ["71281.40", "0.081"], ["71282.50", "0.003"], ["71284.30", "0.005"], ["71287.10", "0.000"], ["71287.80", "0.002"], ["71290.00", "0.010"], ["71291.40", "0.001"], ["71295.00", "0.006"], ["71302.00", "0.012"], ["71304.20", "0.004"], ["71306.40", "0.005"], ["71334.30", "2.090"], ["71335.30", "0.002"], ["71356.30", "0.000"], ["71368.20", "0.390"], ["71401.80", "0.292"], ["71413.40", "0.506"], ["71415.90", "2.785"], ["71436.10", "0.009"], ["71921.50", "0.008"], ["71921.60", "0.209"], ["72220.70", "0.552"], ["73392.60", "0.000"], ["89523.20", "0.000"]]}}
{"local_ts": 1773384549803, "server_ts": 1773384549584, "data": {"e": "depthUpdate", "E": 1773384549587, "T": 1773384549584, "s": "BTCUSDT", "U": 10101341536499, "u": 10101341540774, "pu": 10101341536487, "b": [["1000.00", "27.492"], ["5000.00", "101.398"], ["20709.40", "0.828"], ["20713.20", "0.288"], ["20913.20", "0.459"], ["21009.40", "0.441"], ["21113.20", "0.684"], ["67621.30", "0.007"], ["67638.20", "0.000"], ["67649.00", "0.004"], ["68515.20", "0.004"], ["69484.00", "0.018"], ["69785.30", "0.014"], ["70501.10", "0.000"], ["70853.40", "0.029"], ["70964.00", "0.026"], ["71077.30", "0.048"], ["71105.00", "0.152"], ["71156.20", "0.843"], ["71172.50", "0.154"], ["71175.30", "0.003"], ["71177.60", "0.161"], ["71179.60", "0.191"], ["71198.70", "0.047"], ["71213.20", "6.540"]], "a": [["71213.30", "2.574"], ["71214.70", "0.006"], ["71226.10", "0.086"], ["71230.30", "0.142"], ["71231.50", "0.000"], ["71240.80", "0.457"], ["71248.90", "0.453"], ["71262.40", "0.114"], ["71263.10", "0.021"], ["71264.50", "0.507"], ["71264.60", "0.006"], ["71295.00", "0.106"], ["71316.10", "3.388"], ["71405.60", "0.159"], ["71925.40", "0.000"], ["72077.70", "0.831"]]}}
{"local_ts": 1773384550823, "server_ts": 1773384550606, "data": {"e": "depthUpdate", "E": 1773384550607, "T": 1773384550606, "s": "BTCUSDT", "U": 10101341640889, "u": 10101341646855, "pu": 10101341640836, "b": [["1000.00", "27.492"], ["5000.00", "101.418"], ["20813.20", "0.324"], ["20913.20", "0.576"], ["21013.20", "0.414"], ["21113.20", "1.386"], ["21113.30", "0.007"], ["56971.00", "0.000"], ["67649.00", "0.002"], ["69983.90", "3.426"], ["70501.10", "1.416"], ["70853.50", "0.013"], ["70900.00", "26.336"], ["70963.70", "0.000"], ["71143.50", "0.042"], ["71144.40", "0.147"], ["71145.40", "0.151"], ["71148.30", "0.118"], ["71151.00", "0.054"], ["71153.40", "0.001"], ["71155.30", "0.306"], ["71156.30", "0.004"], ["71157.20", "0.000"], ["71158.20", "0.003"], ["71159.20", "0.017"], ["71162.30", "0.189"], ["71177.00", "0.002"], ["71181.20", "0.304"], ["71181.30", "0.288"], ["71182.90", "0.312"], ["71184.90", "0.015"], ["71190.60", "0.254"], ["71192.00", "0.006"], ["71192.90", "0.049"], ["71195.30", "0.006"], ["71195.70", "0.301"], ["71196.10", "0.005"], ["71197.90", "0.045"], ["71199.10", "0.140"], ["71199.50", "0.320"], ["71199.80", "0.031"], ["71202.20", "0.205"], ["71206.10", "0.068"], ["71209.40", "4.843"], ["71209.50", "0.260"], ["71213.20", "1.693"]], "a": [["71216.60", "0.004"], ["71216.70", "0.000"], ["71219.80", "0.000"], ["71220.40", "0.028"], ["71221.10", "0.029"], ["71222.70", "0.140"], ["71223.40", "0.247"], ["71223.70", "0.365"], ["71224.90", "0.003"], ["71227.00", "0.034"], ["71227.50", "0.000"], ["71227.90", "0.114"], ["71228.60", "0.058"], ["71228.70", "0.014"], ["71229.00", "0.043"], ["71229.20", "0.001"], ["71230.90", "0.008"], ["71233.70", "0.832"], ["71234.70", "0.169"], ["71235.50", "0.009"], ["71235.60", "0.004"], ["71236.20", "0.182"], ["71236.30", "0.007"], ["71237.10", "0.163"], ["71238.30", "0.003"], ["71239.50", "0.003"], ["71239.70", "0.201"], ["71239.80", "0.104"], ["71240.40", "0.058"], ["71240.50", "0.228"], ["71240.70", "0.005"], ["71242.00", "0.948"], ["71247.00", "0.013"], ["71262.00", "0.003"], ["71262.20", "0.021"], ["71263.70", "0.002"], ["71263.90", "0.061"], ["71276.60", "0.954"], ["71289.40", "0.308"], ["71304.10", "0.001"], ["71328.90", "2.831"], ["71331.90", "1.797"], ["71440.50", "0.000"], ["71925.30", "0.000"], ["71925.40", "1.388"], ["72459.50", "1.102"], ["74792.50", "0.052"]]}}
{"local_ts": 1773384551847, "server_ts": 1773384551630, "data": {"e": "depthUpdate", "E": 1773384551631, "T": 1773384551630, "s": "BTCUSDT", "U": 10101341705700, "u": 10101341711055, "pu": 10101341705632, "b": [["1000.00", "27.642"], ["5000.00", "101.418"], ["20713.20", "0.198"], ["20813.20", "0.702"], ["20913.20", "0.198"], ["21013.20", "1.548"], ["21113.20", "0.054"], ["56971.00", "0.000"], ["67627.50", "0.002"], ["67634.60", "0.000"], ["69419.90", "2.588"], ["70501.10", "1.416"], ["71063.80", "0.002"], ["71127.90", "0.107"], ["71128.90", "0.141"], ["71129.90", "0.042"], ["71130.90", "0.145"], ["71135.40", "0.121"], ["71136.60", "0.042"], ["71137.60", "0.258"], ["71138.20", "0.071"], ["71138.60", "0.154"], ["71139.60", "0.044"], ["71140.10", "0.010"], ["71140.60", "0.042"], ["71143.00", "0.524"], ["71143.10", "0.000"], ["71143.90", "0.005"], ["71166.00", "0.002"], ["71166.10", "0.324"], ["71172.60", "0.017"], ["71182.00", "0.028"], ["71182.40", "0.332"], ["71183.30", "0.015"], ["71183.60", "0.177"], ["71183.80", "0.327"], ["71184.60", "0.021"], ["71184.80", "0.003"], ["71185.60", "0.002"], ["71186.10", "0.115"], ["71187.20", "0.114"], ["71187.30", "0.665"], ["71192.80", "0.029"], ["71193.40", "0.607"], ["71195.30", "0.006"], ["71196.20", "0.034"], ["71196.50", "0.007"], ["71196.60", "0.005"], ["71197.60", "0.034"], ["71198.00", "0.030"], ["71198.30", "0.293"], ["71198.80", "0.004"], ["71198.90", "0.085"], ["71199.30", "0.325"], ["71200.20", "0.007"], ["71200.70", "0.000"], ["71201.40", "0.003"], ["71202.40", "0.000"], ["71202.90", "0.036"], ["71204.80", "0.008"]], "a": [["71226.60", "0.204"], ["71228.20", "0.000"], ["71228.60", "0.058"], ["71229.00", "0.631"], ["71233.70", "0.834"], ["71234.30", "0.140"], ["71235.60", "0.249"], ["71235.70", "0.004"], ["71263.20", "0.303"], ["71263.50", "0.008"], ["71361.00", "0.100"], ["71402.00", "0.000"], ["71439.90", "0.007"], ["71440.30", "0.000"], ["71925.30", "0.000"], ["71925.40", "1.388"], ["72234.20", "0.000"], ["72559.20", "0.688"], ["72576.10", "0.005"]]}}
{"local_ts": 1773384552868, "server_ts": 1773384552650, "data": {"e": "depthUpdate", "E": 1773384552653, "T": 1773384552650, "s": "BTCUSDT", "U": 10101341766352, "u": 10101341771631, "pu": 10101341766211, "b": [["1000.00", "27.492"], ["5000.00", "101.418"], ["20713.20", "0.837"], ["20813.20", "0.063"], ["20913.20", "1.548"], ["21013.20", "0.189"], ["21113.20", "0.063"], ["33000.00", "9.339"], ["56971.00", "0.000"], ["67626.20", "0.000"], ["67640.90", "0.002"], ["69059.70", "3.470"], ["70020.20", "0.000"], ["70501.10", "1.416"], ["70501.20", "0.000"], ["70857.10", "0.085"], ["70963.40", "0.006"], ["70963.50", "0.306"], ["71051.80", "0.058"], ["71058.30", "0.004"], ["71166.60", "0.028"], ["71166.70", "0.067"], ["71171.10", "0.065"], ["71173.20", "0.051"], ["71179.60", "0.007"], ["71180.60", "0.360"], ["71183.60", "0.107"], ["71186.00", "0.144"], ["71193.30", "0.006"], ["71194.20", "0.005"], ["71195.10", "0.647"], ["71195.30", "1.199"], ["71196.20", "0.034"], ["71208.90", "0.274"]], "a": [["71214.30", "0.000"], ["71214.40", "0.001"], ["71223.60", "0.004"], ["71223.70", "0.365"], ["71224.50", "0.341"], ["71225.20", "0.004"], ["71225.50", "0.149"], ["71226.20", "0.042"], ["71226.30", "0.409"], ["71227.00", "0.005"], ["71228.30", "0.000"], ["71228.60", "0.007"], ["71229.30", "0.007"], ["71229.40", "0.005"], ["71229.60", "0.057"], ["71229.90", "0.506"], ["71230.30", "0.053"], ["71230.60", "0.631"], ["71235.60", "0.004"], ["71235.80", "0.034"], ["71236.60", "0.004"], ["71236.80", "0.009"], ["71237.00", "0.119"], ["71237.10", "0.408"], ["71238.30", "0.032"], ["71238.70", "0.006"], ["71239.50", "0.032"], ["71299.00", "0.149"], ["71348.20", "0.019"], ["71354.70", "0.012"], ["71925.40", "1.388"]]}}
{"local_ts": 1773384553895, "server_ts": 1773384553676, "data": {"e": "depthUpdate", "E": 1773384553679, "T": 1773384553676, "s": "BTCUSDT", "U": 10101341855920, "u": 10101341862975, "pu": 10101341855633, "b": [["5000.00", "101.418"], ["20713.20", "0.072"], ["20813.20", "1.422"], ["20913.20", "0.378"], ["21113.20", "0.828"], ["67617.10", "0.000"], ["69789.00", "0.090"], ["70501.10", "1.416"], ["71064.20", "0.697"], ["71075.30", "0.138"], ["71089.20", "0.825"], ["71093.30", "0.182"], ["71093.70", "0.119"], ["71094.40", "0.061"], ["71127.40", "0.000"], ["71128.40", "2.694"], ["71129.50", "0.042"], ["71130.50", "0.102"], ["71131.50", "0.089"], ["71132.50", "0.097"], ["71146.30", "0.143"], ["71151.50", "0.042"], ["71151.70", "1.339"], ["71153.20", "3.459"], ["71154.30", "0.060"], ["71155.50", "0.043"], ["71160.30", "0.046"], ["71167.10", "0.125"], ["71167.20", "0.005"], ["71172.60", "0.002"], ["71173.80", "0.000"], ["71175.10", "0.000"], ["71181.20", "0.403"], ["71187.20", "0.129"], ["71187.40", "0.506"], ["71188.50", "0.025"], ["71191.00", "0.523"], ["71191.20", "0.002"], ["71192.40", "0.337"], ["71193.70", "0.508"], ["71194.50", "0.014"], ["71195.80", "1.199"], ["71200.20", "0.000"], ["71202.40", "0.032"], ["71206.10", "0.055"], ["71206.40", "0.032"], ["71206.80", "0.003"], ["71207.70", "0.031"], ["71208.00", "0.044"], ["71208.90", "0.274"], ["71209.10", "0.020"], ["71209.40", "4.843"], ["71210.10", "0.005"], ["71210.50", "0.002"], ["71211.10", "0.032"], ["71211.20", "0.002"], ["71213.10", "0.001"], ["71213.20", "1.974"]], "a": [["71213.30", "3.743"], ["71213.70", "0.002"], ["71214.00", "0.008"], ["71214.30", "0.000"], ["71214.40", "0.001"], ["71216.00", "0.009"], ["71219.30", "0.005"], ["71219.40", "0.002"], ["71220.10", "0.003"], ["71220.40", "0.028"], ["71220.80", "0.005"], ["71222.10", "0.151"], ["71223.50", "0.000"], ["71224.40", "0.004"], ["71225.10", "0.030"], ["71225.20", "0.011"], ["71226.40", "0.029"], ["71227.50", "0.000"], ["71237.00", "0.007"], ["71238.20", "0.306"], ["71262.30", "0.009"], ["71262.40", "0.116"], ["71290.00", "0.110"], ["71361.00", "0.673"], ["71440.10", "0.211"], ["71925.30", "0.000"], ["71925.40", "1.388"], ["71999.30", "8.615"]]}}
{"local_ts": 1773384554919, "server_ts": 1773384554702, "data": {"e": "depthUpdate", "E": 1773384554703, "T": 1773384554702, "s": "BTCUSDT", "U": 10101341932756, "u": 10101341938747, "pu": 10101341932580, "b": [["1000.00", "27.492"], ["5000.00", "101.418"], ["20713.20", "1.152"], ["20813.20", "0.648"], ["21013.20", "0.702"], ["21113.20", "0.198"], ["33000.00", "9.343"], ["67632.80", "0.002"], ["70363.10", "0.000"], ["70501.10", "1.416"], ["70648.00", "0.039"], ["70857.10", "0.085"], ["70937.10", "0.000"], ["70979.50", "0.002"], ["71150.30", "30.744"], ["71162.40", "0.184"], ["71167.10", "0.077"], ["71167.70", "0.002"], ["71167.80", "0.007"], ["71175.90", "0.003"], ["71176.00", "0.006"], ["71176.60", "0.152"], ["71176.70", "0.009"], ["71178.50", "0.051"], ["71181.50", "0.079"], ["71181.60", "0.000"], ["71182.20", "0.004"], ["71182.30", "0.006"], ["71212.00", "0.002"]], "a": [["71227.50", "0.153"], ["71235.00", "0.003"], ["71238.20", "0.107"], ["71238.60", "0.573"], ["71241.80", "0.312"], ["71251.70", "0.781"], ["71260.40", "0.000"], ["71264.30", "0.015"], ["71265.60", "0.002"], ["71266.80", "0.080"], ["71268.10", "0.003"], ["71272.80", "0.004"], ["71274.30", "0.029"], ["71275.50", "0.029"], ["71276.80", "0.032"], ["71278.00", "0.029"], ["71284.50", "0.000"], ["71297.90", "0.000"], ["71331.40", "0.187"], ["71365.80", "0.000"], ["71373.80", "0.028"], ["71405.60", "0.159"], ["71440.30", "0.007"], ["71925.40", "1.388"], ["71989.50", "1.392"], ["72637.50", "0.017"], ["73006.90", "2.464"], ["74796.80", "0.000"]]}}
{"local_ts": 1773384555941, "server_ts": 1773384555722, "data": {"e": "depthUpdate", "E": 1773384555723, "T": 1773384555722, "s": "BTCUSDT", "U": 10101341998385, "u": 10101342003821, "pu": 10101341998354, "b": [["5000.00", "101.398"], ["20713.20", "0.918"], ["20913.20", "0.567"], ["21013.20", "0.333"], ["21113.20", "0.882"], ["67648.40", "0.002"], ["67652.00", "0.017"], ["70501.10", "1.416"], ["70979.50", "0.000"], ["70984.50", "0.006"], ["71065.70", "0.642"], ["71105.00", "0.152"], ["71162.40", "0.000"], ["71163.20", "0.184"], ["71167.60", "0.679"], ["71168.10", "1.058"], ["71184.10", "0.325"], ["71185.80", "0.002"], ["71186.40", "0.248"], ["71187.90", "0.095"], ["71192.90", "0.070"], ["71193.80", "0.007"], ["71196.90", "0.124"], ["71198.80", "0.509"], ["71199.80", "0.002"], ["71200.10", "0.642"], ["71200.70", "0.000"], ["71203.30", "0.000"], ["71203.40", "1.052"]], "a": [["71213.30", "0.647"], ["71214.80", "0.002"], ["71216.90", "0.042"], ["71222.90", "0.004"], ["71227.50", "0.153"], ["71230.10", "0.015"], ["71231.50", "0.140"], ["71235.80", "0.643"], ["71237.80", "0.015"], ["71240.10", "1.483"], ["71241.40", "0.002"], ["71241.90", "0.249"], ["71244.10", "0.000"], ["71254.80", "0.021"], ["71254.90", "0.004"], ["71255.90", "0.006"], ["71256.20", "0.104"], ["71256.30", "0.000"], ["71256.70", "0.000"], ["71257.10", "0.000"], ["71257.40", "7.725"], ["71257.70", "0.008"], ["71257.90", "0.000"], ["71258.10", "0.018"], ["71258.50", "0.033"], ["71259.60", "0.588"], ["71260.10", "0.000"], ["71260.60", "0.033"], ["71262.10", "0.046"], ["71262.20", "0.000"], ["71262.30", "0.007"], ["71263.40", "0.021"], ["71264.60", "0.004"], ["71275.50", "0.029"], ["71276.80", "0.032"], ["71295.00", "0.104"], ["71367.20", "0.590"], ["71419.80", "0.002"], ["71747.40", "1.396"], ["71925.40", "1.388"]]}}
{"local_ts": 1773384556962, "server_ts": 1773384556744, "data": {"e": "depthUpdate", "E": 1773384556747, "T": 1773384556744, "s": "BTCUSDT", "U": 10101342056229, "u": 10101342060577, "pu": 10101342056143, "b": [["1000.00", "27.492"], ["5000.00", "101.418"], ["20813.20", "0.432"], ["20913.20", "0.468"], ["21013.20", "0.621"], ["21113.20", "1.179"], ["70380.00", "0.658"], ["70501.10", "1.416"], ["70501.20", "0.000"], ["70963.40", "0.006"], ["70983.70", "0.009"], ["70984.50", "0.004"], ["71065.70", "0.103"], ["71163.20", "0.000"], ["71184.40", "0.000"], ["71198.40", "0.009"], ["71206.10", "0.010"], ["71210.40", "0.003"], ["71211.70", "0.004"], ["71212.00", "0.000"]], "a": [["71220.40", "0.002"], ["71222.50", "0.002"], ["71236.40", "0.139"], ["71242.20", "0.000"], ["71246.00", "0.293"], ["71246.40", "0.001"], ["71249.30", "0.000"], ["71249.80", "0.003"], ["71250.10", "0.031"], ["71254.30", "0.034"], ["71261.10", "0.209"], ["71261.30", "0.002"], ["71268.10", "0.003"], ["71367.10", "0.000"], ["71440.30", "0.007"], ["71925.40", "1.388"], ["74790.30", "0.000"]]}}
{"local_ts": 1773384557983, "server_ts": 1773384557765, "data": {"e": "depthUpdate", "E": 1773384557767, "T": 1773384557765, "s": "BTCUSDT", "U": 10101342112081, "u": 10101342117474, "pu": 10101342111887, "b": [["1000.00", "27.492"], ["5000.00", "101.418"], ["20713.20", "0.297"], ["20813.20", "0.603"], ["20913.20", "0.351"], ["21013.20", "1.449"], ["21113.20", "0.000"], ["67633.10", "0.061"], ["70109.00", "0.712"], ["70501.10", "2.832"], ["70857.10", "0.110"], ["70981.80", "0.005"], ["70983.70", "0.007"], ["71121.20", "0.020"], ["71128.70", "0.199"], ["71144.30", "1.302"], ["71205.50", "0.003"], ["71206.10", "0.075"], ["71209.70", "0.003"], ["71211.10", "0.005"], ["71213.20", "2.090"]], "a": [["71213.30", "3.427"], ["71216.00", "0.006"], ["71216.10", "0.005"], ["71220.40", "0.030"], ["71223.70", "0.024"], ["71224.90", "0.003"], ["71226.00", "0.736"], ["71227.10", "0.117"], ["71228.00", "0.085"], ["71228.80", "0.004"], ["71290.00", "0.110"], ["71925.40", "2.776"], ["74802.90", "0.002"]]}}
{"local_ts": 1773384559018, "server_ts": 1773384558788, "data": {"e": "depthUpdate", "E": 1773384558789, "T": 1773384558788, "s": "BTCUSDT", "U": 10101342187757, "u": 10101342196009, "pu": 10101342187643, "b": [["5000.00", "101.418"], ["20713.20", "0.738"], ["20813.20", "0.171"], ["20913.20", "1.548"], ["21013.20", "0.081"], ["21113.20", "0.162"], ["50500.00", "103.942"], ["67617.40", "0.002"], ["69420.00", "0.252"], ["70122.30", "0.142"], ["70501.10", "2.832"], ["70637.20", "0.000"], ["70820.30", "0.282"], ["70963.50", "0.306"], ["70963.80", "0.004"], ["70981.20", "6.471"], ["70981.80", "0.003"], ["71011.90", "0.000"], ["71015.40", "2.704"], ["71166.50", "0.027"], ["71166.60", "0.026"], ["71166.90", "0.008"], ["71168.50", "0.000"], ["71175.90", "0.005"], ["71176.00", "0.008"], ["71176.60", "0.150"], ["71176.70", "0.007"], ["71178.20", "1.222"], ["71180.10", "0.013"], ["71180.20", "0.056"], ["71180.80", "0.008"], ["71180.90", "0.068"], ["71181.50", "0.081"], ["71181.60", "0.002"], ["71182.20", "0.002"], ["71182.30", "0.004"], ["71192.80", "1.193"], ["71193.60", "0.006"], ["71193.90", "0.005"], ["71197.40", "1.733"], ["71197.60", "0.005"], ["71198.10", "0.000"], ["71198.40", "0.009"], ["71203.50", "0.766"], ["71204.50", "0.116"], ["71206.10", "0.010"], ["71207.90", "0.065"]], "a": [["71213.30", "5.150"], ["71213.40", "0.157"], ["71220.40", "0.002"], ["71223.90", "0.007"], ["71224.70", "0.737"], ["71224.80", "0.006"], ["71225.30", "0.051"], ["71225.70", "0.631"], ["71235.50", "0.011"], ["71235.60", "0.006"], ["71236.20", "0.180"], ["71236.30", "0.003"], ["71239.70", "0.210"], ["71239.80", "0.113"], ["71240.40", "0.049"], ["71240.50", "0.219"], ["71260.80", "0.076"], ["71260.90", "0.310"], ["71263.00", "0.140"], ["71281.10", "0.000"], ["71288.10", "0.499"], ["71313.00", "0.212"], ["71675.30", "0.004"], ["71889.00", "0.120"], ["71925.40", "2.776"], ["72434.90", "0.000"], ["72438.20", "0.289"]]}}
{"local_ts": 1773384560028, "server_ts": 1773384559810, "data": {"e": "depthUpdate", "E": 1773384559811, "T": 1773384559810, "s": "BTCUSDT", "U": 10101342278464, "u": 10101342284939, "pu": 10101342278454, "b": [["1000.00", "27.492"], ["5000.00", "101.418"], ["20710.40", "0.036"], ["20713.20", "0.000"], ["20810.40", "0.432"], ["20813.20", "1.089"], ["20913.20", "0.216"], ["21010.40", "0.027"], ["21110.40", "0.207"], ["21113.20", "0.657"], ["33000.00", "9.339"], ["70014.20", "0.288"], ["70249.20", "0.312"], ["70498.30", "0.000"], ["70857.10", "0.155"], ["71093.70", "0.126"], ["71094.10", "0.046"], ["71094.40", "0.061"], ["71094.80", "0.027"], ["71095.10", "0.531"], ["71095.40", "0.027"], ["71134.90", "1.061"], ["71149.10", "0.074"], ["71165.90", "0.007"], ["71166.00", "0.004"], ["71168.30", "0.001"], ["71171.30", "0.000"], ["71172.80", "0.033"], ["71174.20", "0.003"], ["71177.70", "1.904"], ["71177.80", "0.143"], ["71181.90", "0.004"], ["71185.30", "0.093"], ["71189.90", "0.003"], ["71192.30", "0.632"], ["71194.70", "0.341"], ["71195.00", "0.799"], ["71196.20", "0.003"], ["71197.60", "0.045"], ["71198.90", "0.052"], ["71201.10", "0.047"], ["71203.30", "0.000"], ["71203.40", "0.018"], ["71203.80", "0.005"], ["71204.00", "0.025"], ["71205.80", "0.039"], ["71210.40", "2.424"]], "a": [["71210.50", "9.479"], ["71213.30", "0.187"], ["71214.10", "0.003"], ["71214.20", "0.126"], ["71217.60", "0.018"], ["71222.00", "0.009"], ["71223.00", "0.004"], ["71225.90", "0.002"], ["71226.50", "1.061"], ["71227.60", "0.003"], ["71228.50", "0.951"], ["71230.80", "0.002"], ["71231.50", "0.000"], ["71231.60", "0.019"], ["71232.50", "1.126"], ["71232.90", "0.070"], ["71234.80", "0.002"], ["71234.90", "0.004"], ["71235.50", "0.009"], ["71235.60", "0.008"], ["71239.00", "1.106"], ["71239.10", "0.003"], ["71239.70", "0.210"], ["71239.80", "0.009"], ["71247.90", "0.174"], ["71256.80", "1.072"], ["71259.40", "0.359"], ["71259.50", "0.569"], ["71277.40", "0.000"], ["71291.70", "0.004"], ["71313.00", "0.000"], ["71313.80", "0.212"], ["71922.60", "0.778"], ["74792.70", "0.000"], ["74804.00", "0.052"], ["89523.20", "0.000"]]}}
{"local_ts": 1773384561054, "server_ts": 1773384560830, "data": {"e": "depthUpdate", "E": 1773384560831, "T": 1773384560830, "s": "BTCUSDT", "U": 10101342429235, "u": 10101342443278, "pu": 10101342429216, "b": [["5000.00", "101.418"], ["20701.60", "0.747"], ["20810.40", "0.450"], ["21001.60", "0.369"], ["21110.40", "0.108"], ["40000.00", "49.611"], ["56961.00", "0.000"], ["64081.40", "0.002"], ["67621.30", "0.007"], ["70294.00", "0.376"], ["70373.10", "0.379"], ["70452.30", "0.376"], ["70489.60", "0.000"], ["70531.50", "0.378"], ["71028.10", "0.000"], ["71056.00", "25.045"], ["71058.50", "0.595"], ["71088.00", "0.391"], ["71138.10", "0.513"], ["71139.00", "3.572"], ["71141.80", "0.000"], ["71142.80", "0.337"], ["71143.70", "0.000"], ["71144.70", "0.008"], ["71145.70", "0.122"], ["71146.70", "0.042"], ["71147.60", "0.506"], ["71147.70", "0.300"], ["71148.60", "0.494"], ["71149.60", "0.002"], ["71150.40", "0.226"], ["71150.50", "0.002"], ["71151.50", "0.000"], ["71151.60", "0.165"], ["71152.30", "2.057"], ["71152.50", "0.311"], ["71153.20", "0.002"], ["71153.50", "0.042"], ["71154.40", "0.005"], ["71155.00", "0.046"], ["71155.40", "0.002"], ["71155.50", "0.076"], ["71155.70", "0.002"], ["71155.90", "0.040"], ["71156.40", "0.004"], ["71157.30", "0.014"], ["71157.80", "0.308"], ["71158.30", "0.002"], ["71159.30", "0.406"], ["71159.50", "0.379"], ["71159.60", "0.023"], ["71159.70", "0.007"], ["71159.90", "0.380"], ["71160.20", "0.005"], ["71161.00", "2.790"], ["71161.10", "1.838"], ["71161.20", "1.159"], ["71161.80", "0.002"], ["71162.40", "0.575"], ["71162.70", "0.186"], ["71163.00", "0.042"], ["71164.70", "0.019"], ["71165.10", "0.591"], ["71165.90", "0.063"], ["71166.00", "0.042"], ["71166.20", "0.247"], ["71166.80", "0.000"], ["71167.00", "0.007"], ["71167.20", "0.018"], ["71167.80", "0.002"], ["71168.30", "0.001"], ["71168.50", "0.015"], ["71168.80", "0.003"], ["71169.60", "0.046"], ["71169.70", "0.398"], ["71170.30", "0.012"], ["71170.40", "0.018"], ["71171.00", "0.021"], ["71171.10", "0.065"], ["71171.20", "0.080"], ["71171.70", "0.005"], ["71171.80", "0.002"], ["71172.10", "0.004"], ["71172.20", "0.089"], ["71172.50", "0.174"], ["71173.50", "0.068"], ["71173.70", "0.033"], ["71173.90", "0.006"], ["71174.70", "0.024"], ["71174.80", "0.315"], ["71175.00", "0.053"], ["71175.70", "0.285"], ["71175.80", "0.028"], ["71176.00", "0.006"], ["71176.20", "0.031"], ["71176.40", "0.220"], ["71176.70", "0.026"], ["71176.80", "0.003"], ["71177.30", "0.019"], ["71177.40", "0.067"], ["71178.30", "0.607"], ["71178.50", "0.003"], ["71178.60", "0.011"], ["71178.70", "0.123"], ["71179.00", "0.000"], ["71179.10", "0.224"], ["71179.40", "0.070"], ["71179.50", "1.394"], ["71179.60", "0.014"], ["71179.70", "0.000"], ["71179.80", "0.333"], ["71179.90", "0.029"], ["71180.20", "0.138"], ["71180.50", "0.343"], ["71180.60", "0.115"], ["71180.80", "0.100"], ["71181.00", "0.010"], ["71181.30", "0.030"], ["71181.40", "0.006"], ["71181.50", "1.202"], ["71181.80", "0.004"], ["71182.90", "0.029"], ["71183.00", "0.027"], ["71183.10", "0.347"], ["71183.40", "0.005"], ["71183.80", "0.113"], ["71183.90", "0.006"], ["71184.20", "0.017"], ["71184.60", "0.002"], ["71184.70", "0.033"], ["71184.90", "0.001"], ["71185.20", "1.053"], ["71185.30", "0.509"], ["71185.40", "0.076"], ["71185.60", "0.002"], ["71185.70", "0.005"], ["71185.80", "0.002"], ["71186.10", "0.283"], ["71186.30", "0.674"], ["71186.40", "0.003"], ["71186.60", "0.000"], ["71186.80", "0.000"], ["71187.10", "0.002"], ["71187.20", "0.005"], ["71187.40", "0.270"], ["71187.60", "0.039"], ["71188.00", "0.006"], ["71188.10", "0.000"], ["71188.40", "0.036"], ["71188.60", "0.508"], ["71188.80", "0.001"], ["71189.30", "0.061"], ["71189.40", "0.101"], ["71190.00", "0.016"], ["71190.50", "0.004"], ["71190.60", "0.038"], ["71191.10", "0.012"], ["71191.30", "0.003"], ["71191.40", "0.004"], ["71191.60", "0.121"], ["71191.80", "0.003"], ["71192.30", "0.061"], ["71192.50", "0.030"], ["71192.60", "0.038"], ["71192.70", "0.208"], ["71192.80", "0.000"], ["71193.10", "0.002"], ["71193.20", "0.021"], ["71193.30", "0.071"], ["71193.40", "0.003"], ["71193.50", "0.004"], ["71193.70", "0.002"], ["71193.80", "0.001"], ["71193.90", "0.005"], ["71194.10", "0.749"], ["71194.50", "0.061"], ["71195.10", "0.014"], ["71195.50", "0.003"], ["71195.80", "0.003"], ["71196.30", "0.003"], ["71197.10", "0.003"], ["71198.30", "0.005"], ["71198.40", "0.009"], ["71198.80", "0.026"], ["71200.20", "0.003"], ["71200.70", "0.000"], ["71201.00", "0.002"], ["71201.10", "0.000"], ["71201.50", "0.000"], ["71201.60", "0.458"]], "a": [["71201.70", "4.790"], ["71204.60", "0.031"], ["71204.90", "0.007"], ["71207.00", "0.002"], ["71207.10", "0.029"], ["71209.70", "0.005"], ["71209.90", "0.031"], ["71211.50", "0.029"], ["71212.50", "0.201"], ["71213.10", "0.044"], ["71213.50", "0.006"], ["71215.20", "0.633"], ["71215.60", "0.265"], ["71215.70", "0.260"], ["71215.80", "0.002"], ["71215.90", "0.030"], ["71216.10", "0.387"], ["71218.30", "0.033"], ["71218.40", "0.110"], ["71218.50", "0.338"], ["71218.60", "0.029"], ["71219.20", "0.028"], ["71220.20", "0.004"], ["71220.60", "0.072"], ["71222.60", "0.001"], ["71222.80", "0.512"], ["71222.90", "0.000"], ["71223.00", "0.070"], ["71223.10", "0.478"], ["71223.50", "0.000"], ["71224.20", "0.086"], ["71224.30", "0.075"], ["71224.40", "0.247"], ["71224.50", "0.348"], ["71224.60", "0.043"], ["71224.80", "0.145"], ["71225.00", "0.073"], ["71225.10", "0.035"], ["71226.50", "1.060"], ["71227.90", "0.008"], ["71228.10", "0.036"], ["71229.90", "0.077"], ["71230.20", "0.360"], ["71234.20", "0.004"], ["71235.90", "0.338"], ["71237.10", "0.089"], ["71237.20", "0.655"], ["71237.30", "0.959"], ["71238.70", "0.002"], ["71240.90", "0.003"], ["71243.00", "0.508"], ["71243.70", "0.089"], ["71244.30", "0.847"], ["71244.80", "2.140"], ["71245.50", "0.000"], ["71248.60", "0.057"], ["71249.00", "0.004"], ["71252.30", "0.000"], ["71252.40", "0.001"], ["71252.60", "0.004"], ["71254.40", "0.102"], ["71274.40", "0.002"], ["71276.50", "0.124"], ["71278.20", "0.100"], ["71287.10", "2.082"], ["71296.10", "0.002"], ["71311.40", "0.004"], ["71313.80", "0.000"], ["71368.80", "10.000"], ["71383.20", "0.506"], ["71383.30", "0.000"], ["71390.40", "0.141"], ["71393.00", "0.017"], ["71404.60", "0.000"], ["71633.70", "0.063"], ["71635.70", "0.000"], ["71913.70", "0.000"], ["71956.30", "1.477"], ["72035.50", "0.788"], ["72114.70", "0.376"], ["72193.80", "0.376"], ["72273.00", "0.395"], ["72352.10", "0.382"], ["72431.30", "0.392"], ["72510.50", "0.376"], ["72589.60", "0.376"], ["72668.80", "1.756"], ["78321.90", "0.002"], ["89523.20", "0.000"]]}}
{"local_ts": 1773384562070, "server_ts": 1773384561852, "data": {"e": "depthUpdate", "E": 1773384561853, "T": 1773384561852, "s": "BTCUSDT", "U": 10101342514783, "u": 10101342519840, "pu": 10101342514756, "b": [["1000.00", "27.492"], ["5000.00", "101.438"], ["20701.60", "0.684"], ["20899.50", "0.378"], ["21001.60", "0.216"], ["21099.50", "0.756"], ["64079.50", "0.002"], ["67610.10", "0.002"], ["67636.50", "0.002"], ["70487.50", "0.000"], ["70562.30", "0.157"], ["70575.90", "0.000"], ["71052.00", "0.834"], ["71128.40", "1.181"], ["71142.70", "0.064"], ["71154.60", "0.002"], ["71154.80", "1.138"], ["71160.10", "0.049"], ["71162.70", "0.002"], ["71163.30", "0.185"], ["71163.50", "0.184"], ["71163.70", "0.000"], ["71165.00", "0.012"], ["71165.50", "0.210"], ["71168.40", "0.006"], ["71171.90", "0.039"], ["71174.20", "0.071"], ["71175.30", "0.094"], ["71180.60", "0.749"], ["71184.30", "0.045"], ["71186.00", "0.004"], ["71186.10", "0.045"], ["71186.20", "0.407"], ["71187.90", "0.000"], ["71189.70", "0.091"], ["71190.40", "0.022"], ["71190.60", "0.080"], ["71190.70", "0.002"], ["71190.80", "0.011"], ["71191.00", "0.003"], ["71191.20", "0.003"], ["71191.40", "0.004"], ["71191.60", "0.150"], ["71191.70", "0.001"], ["71191.80", "0.003"], ["71192.00", "0.008"], ["71192.10", "0.002"], ["71192.80", "0.000"], ["71195.10", "0.005"], ["71197.40", "0.002"], ["71198.30", "0.004"], ["71199.50", "2.941"]], "a": [["71199.60", "7.834"], ["71201.60", "1.106"], ["71201.70", "0.232"], ["71202.10", "0.000"], ["71202.80", "0.003"], ["71204.60", "0.055"], ["71204.80", "0.000"], ["71205.70", "0.000"], ["71206.40", "0.001"], ["71207.30", "0.005"], ["71207.40", "0.043"], ["71208.80", "0.505"], ["71210.10", "0.033"], ["71215.20", "0.000"], ["71215.90", "0.028"], ["71216.80", "0.029"], ["71243.30", "0.003"], ["71244.40", "0.638"], ["71248.90", "0.036"], ["71250.30", "0.004"], ["71250.50", "0.004"], ["71349.30", "0.430"], ["71566.60", "0.026"], ["71663.30", "0.008"], ["71677.00", "0.018"], ["71842.40", "0.016"], ["71856.20", "0.000"], ["71911.60", "0.000"], ["71946.00", "0.000"], ["72272.40", "0.000"], ["72447.70", "3.279"], ["72522.50", "0.000"], ["74789.90", "0.036"], ["78319.60", "0.002"], ["89523.20", "0.000"]]}}
{"local_ts": 1773384563092, "server_ts": 1773384562873, "data": {"e": "depthUpdate", "E": 1773384562875, "T": 1773384562873, "s": "BTCUSDT", "U": 10101342574899, "u": 10101342579552, "pu": 10101342574892, "b": [["1000.00", "27.492"], ["5000.00", "101.418"], ["20799.50", "0.531"], ["20899.50", "0.369"], ["20999.50", "0.810"], ["21099.50", "0.990"], ["64079.50", "0.002"], ["67606.10", "0.000"], ["70060.40", "0.003"], ["70273.90", "0.853"], ["70487.50", "0.000"], ["70843.50", "0.012"], ["71045.80", "13.116"], ["71046.00", "2.356"], ["71107.30", "6.972"], ["71144.10", "3.522"], ["71163.50", "0.000"], ["71164.00", "0.002"], ["71165.30", "0.944"], ["71165.50", "0.208"], ["71166.70", "1.913"], ["71170.20", "0.188"], ["71174.50", "0.004"], ["71174.90", "0.016"], ["71176.70", "0.004"], ["71193.40", "0.003"], ["71193.70", "0.002"], ["71194.30", "0.017"], ["71195.10", "0.047"], ["71195.60", "0.017"], ["71196.10", "0.005"], ["71196.20", "0.004"], ["71196.30", "0.003"], ["71196.40", "0.005"], ["71196.60", "0.000"], ["71196.70", "0.000"], ["71196.80", "0.023"], ["71197.10", "0.032"], ["71197.40", "0.002"], ["71197.60", "0.054"], ["71197.80", "0.003"], ["71197.90", "0.001"], ["71198.60", "0.042"], ["71199.50", "2.938"]], "a": [["71200.20", "0.001"], ["71200.30", "0.002"], ["71210.00", "0.004"], ["71211.00", "0.033"], ["71211.30", "0.002"], ["71212.50", "0.233"], ["71213.20", "0.003"], ["71213.80", "0.169"], ["71224.30", "0.003"], ["71224.40", "0.002"], ["71225.00", "0.010"], ["71225.10", "0.008"], ["71225.90", "0.002"], ["71226.30", "0.000"], ["71228.50", "0.267"], ["71228.60", "0.007"], ["71229.20", "0.010"], ["71229.30", "0.016"], ["71229.90", "0.000"], ["71230.00", "0.038"], ["71230.60", "0.002"], ["71230.70", "0.005"], ["71232.90", "0.004"], ["71235.10", "0.014"], ["71240.90", "0.003"], ["71242.10", "1.899"], ["71264.70", "4.263"], ["71301.70", "2.266"], ["71301.80", "6.895"], ["71302.20", "0.002"], ["71363.60", "12.960"], ["71379.20", "0.000"], ["71386.50", "0.054"], ["71399.00", "2.903"], ["71406.10", "4.512"], ["71426.00", "0.079"], ["71803.80", "0.000"], ["71911.60", "0.000"], ["71996.50", "2.080"], ["72088.70", "1.110"], ["72127.20", "4.812"], ["72139.00", "2.846"], ["72170.20", "0.830"], ["72232.00", "7.446"], ["72277.00", "4.661"], ["72281.40", "2.763"], ["74765.00", "0.052"], ["78319.60", "0.002"], ["89523.20", "0.000"]]}}
{"local_ts": 1773384564118, "server_ts": 1773384563892, "data": {"e": "depthUpdate", "E": 1773384563897, "T": 1773384563892, "s": "BTCUSDT", "U": 10101342624539, "u": 10101342627348, "pu": 10101342624516, "b": [["5000.00", "101.418"], ["20699.50", "0.396"], ["20799.50", "0.504"], ["20899.50", "0.540"], ["20999.50", "1.260"], ["33000.00", "9.343"], ["64079.50", "0.002"], ["67616.80", "0.002"], ["69908.30", "0.357"], ["70487.50", "0.708"], ["70487.60", "0.211"], ["70949.90", "0.004"], ["70950.30", "0.000"], ["71162.60", "0.269"], ["71165.30", "0.942"], ["71170.10", "0.443"], ["71170.20", "0.249"], ["71188.60", "0.563"], ["71199.50", "3.292"]], "a": [["71199.60", "3.136"], ["71200.10", "0.060"], ["71201.20", "0.003"], ["71211.80", "0.005"], ["71212.10", "0.004"], ["71214.50", "0.012"], ["71225.30", "0.003"], ["71226.40", "0.245"], ["71242.00", "0.985"], ["71249.70", "0.021"], ["71249.90", "0.339"], ["71252.40", "0.103"], ["71258.70", "0.071"], ["71264.80", "0.050"], ["71271.30", "0.023"], ["71272.90", "1.009"], ["71279.30", "0.018"], ["71280.00", "0.081"], ["71280.90", "0.005"], ["71287.30", "0.145"], ["71289.00", "0.005"], ["71295.40", "0.012"], ["71297.10", "0.038"], ["71303.50", "0.009"], ["71347.50", "6.725"], ["71708.60", "0.002"], ["71911.60", "0.000"], ["72160.80", "2.213"], ["72268.40", "0.824"], ["72993.30", "2.462"], ["73026.60", "2.461"], ["78319.60", "0.002"], ["89523.20", "0.000"]]}}
{"local_ts": 1773384565151, "server_ts": 1773384564916, "data": {"e": "depthUpdate", "E": 1773384564917, "T": 1773384564916, "s": "BTCUSDT", "U": 10101342753260, "u": 10101342766372, "pu": 10101342753048, "b": [["1000.00", "27.492"], ["5000.00", "101.418"], ["20699.50", "0.639"], ["20702.30", "0.000"], ["20703.40", "0.000"], ["20809.20", "0.270"], ["20899.50", "1.098"], ["20899.70", "0.000"], ["20909.20", "0.369"], ["20999.50", "0.000"], ["21109.20", "0.261"], ["64088.30", "0.002"], ["67606.90", "0.000"], ["67638.70", "0.002"], ["67648.00", "0.023"], ["69975.50", "0.000"], ["70497.10", "0.000"], ["70843.50", "0.002"], ["70853.20", "0.000"], ["71128.40", "1.079"], ["71129.20", "0.000"], ["71130.50", "0.000"], ["71157.00", "0.044"], ["71157.90", "0.046"], ["71158.90", "0.957"], ["71159.90", "0.380"], ["71160.80", "0.089"], ["71161.80", "0.044"], ["71162.50", "0.323"], ["71162.80", "0.043"], ["71163.80", "0.254"], ["71164.70", "0.019"], ["71169.80", "0.017"], ["71170.10", "0.441"], ["71170.80", "0.061"], ["71171.80", "0.002"], ["71172.70", "0.206"], ["71173.70", "0.004"], ["71174.60", "0.031"], ["71174.70", "0.017"], ["71175.30", "0.003"], ["71175.70", "0.217"], ["71175.90", "0.041"], ["71176.60", "0.092"], ["71177.10", "0.029"], ["71177.60", "0.092"], ["71177.70", "0.008"], ["71178.40", "0.031"], ["71178.60", "0.013"], ["71179.60", "0.036"], ["71180.60", "0.117"], ["71180.90", "0.039"], ["71181.40", "0.025"], ["71182.10", "0.030"], ["71183.30", "0.029"], ["71184.60", "0.002"], ["71185.20", "1.082"], ["71185.80", "0.006"], ["71186.20", "0.077"], ["71187.10", "0.009"], ["71187.50", "0.037"], ["71187.70", "0.314"], ["71188.30", "0.008"], ["71188.60", "0.683"], ["71189.40", "0.052"], ["71189.60", "0.000"], ["71190.80", "0.013"], ["71192.70", "0.210"], ["71192.90", "0.007"], ["71194.00", "0.002"], ["71194.30", "0.007"], ["71194.80", "0.083"], ["71195.20", "0.088"], ["71195.30", "0.144"], ["71195.60", "0.000"], ["71196.70", "0.099"], ["71196.90", "0.306"], ["71197.30", "0.542"], ["71197.90", "0.065"], ["71198.00", "0.058"], ["71198.30", "0.057"], ["71198.70", "0.025"], ["71199.00", "0.028"], ["71199.50", "0.088"], ["71199.80", "0.104"], ["71200.60", "0.004"], ["71200.80", "0.002"], ["71201.60", "0.010"], ["71202.90", "0.000"], ["71206.60", "0.108"], ["71209.10", "0.003"], ["71209.20", "5.235"]], "a": [["71209.30", "3.961"], ["71210.50", "0.005"], ["71225.00", "0.152"], ["71227.60", "0.003"], ["71257.90", "0.102"], ["71258.10", "0.018"], ["71261.10", "0.228"], ["71261.60", "0.012"], ["71262.60", "1.051"], ["71311.90", "0.036"], ["71331.20", "0.200"], ["71332.60", "0.219"], ["71333.10", "6.454"], ["71338.40", "0.301"], ["71350.40", "0.000"], ["71399.00", "2.744"], ["71458.50", "0.697"], ["71458.60", "0.006"], ["71779.60", "0.052"], ["71921.40", "0.016"], ["78330.20", "0.002"], ["89523.20", "0.000"]]}}
{"local_ts": 1773384566157, "server_ts": 1773384565940, "data": {"e": "depthUpdate", "E": 1773384565941, "T": 1773384565940, "s": "BTCUSDT", "U": 10101342862774, "u": 10101342869387, "pu": 10101342862699, "b": [["5000.00", "101.418"], ["20704.60", "0.135"], ["20804.60", "0.729"], ["20809.20", "0.792"], ["20899.50", "0.117"], ["21004.60", "0.126"], ["21109.20", "0.459"], ["56960.00", "0.002"], ["56964.00", "0.000"], ["64084.10", "0.000"], ["69409.90", "2.589"], ["70492.60", "0.000"], ["70528.30", "0.708"], ["71054.80", "0.292"], ["71067.40", "0.533"], ["71087.60", "0.030"], ["71089.70", "0.072"], ["71146.90", "0.002"], ["71148.30", "0.121"], ["71150.10", "0.510"], ["71151.10", "0.060"], ["71158.40", "0.018"], ["71158.50", "0.008"], ["71164.30", "0.081"], ["71164.40", "0.056"], ["71168.10", "1.056"], ["71169.80", "0.059"], ["71172.60", "0.048"], ["71173.90", "0.008"], ["71174.70", "0.017"], ["71176.90", "0.371"], ["71177.70", "0.006"], ["71180.00", "0.015"], ["71183.20", "0.010"], ["71197.50", "0.350"], ["71199.90", "0.003"], ["71200.30", "0.002"], ["71204.60", "0.897"]], "a": [["71204.70", "5.711"], ["71205.00", "0.009"], ["71205.20", "0.002"], ["71209.10", "0.000"], ["71211.80", "0.056"], ["71222.00", "0.136"], ["71233.40", "0.079"], ["71237.10", "0.342"], ["71243.90", "0.568"], ["71254.80", "0.027"], ["71254.90", "0.070"], ["71352.30", "0.100"], ["71372.00", "0.093"], ["71372.30", "0.000"], ["71431.30", "0.007"], ["71916.60", "0.087"], ["71916.70", "0.294"], ["72700.00", "14.167"], ["72900.00", "11.659"], ["74792.00", "0.050"], ["78325.20", "0.000"], ["89523.20", "0.000"]]}}
{"local_ts": 1773384567187, "server_ts": 1773384566964, "data": {"e": "depthUpdate", "E": 1773384566965, "T": 1773384566964, "s": "BTCUSDT", "U": 10101342928003, "u": 10101342931853, "pu": 10101342927886, "b": [["1000.00", "27.492"], ["5000.00", "101.418"], ["20704.60", "1.548"], ["20804.60", "0.252"], ["21004.60", "0.900"], ["21104.60", "0.000"], ["21104.70", "0.000"], ["64084.10", "0.000"], ["66000.00", "58.728"], ["67639.60", "0.006"], ["69802.00", "0.221"], ["70206.10", "0.004"], ["70492.60", "0.000"], ["70959.90", "0.004"], ["71158.30", "0.031"], ["71158.40", "0.018"], ["71192.00", "0.008"], ["71196.20", "0.058"], ["71197.50", "0.322"]], "a": [["71211.80", "0.006"], ["71223.00", "0.506"], ["71254.70", "0.075"], ["71254.80", "0.027"], ["71257.80", "0.411"], ["71431.30", "0.000"], ["71560.60", "0.048"], ["71565.30", "2.650"], ["71916.70", "0.294"], ["72647.10", "1.649"], ["72674.30", "0.000"], ["74088.10", "0.008"], ["74793.70", "0.002"], ["77035.10", "0.002"], ["78325.20", "0.000"]]}}
{"local_ts": 1773384568203, "server_ts": 1773384567984, "data": {"e": "depthUpdate", "E": 1773384567987, "T": 1773384567984, "s": "BTCUSDT", "U": 10101342999577, "u": 10101343004870, "pu": 10101342999524, "b": [["1000.00", "27.492"], ["5000.00", "101.418"], ["20704.60", "0.522"], ["20904.60", "0.765"], ["21004.60", "0.135"], ["21104.60", "1.278"], ["64084.10", "0.000"], ["67634.80", "0.000"], ["70215.70", "0.000"], ["70236.40", "0.000"], ["70492.60", "0.000"], ["70523.60", "3.019"], ["70848.60", "2.828"], ["70898.40", "0.002"], ["70955.30", "0.009"], ["71005.20", "0.002"], ["71008.70", "0.003"], ["71011.10", "0.021"], ["71060.50", "0.101"], ["71094.60", "0.318"], ["71126.30", "0.036"], ["71130.90", "0.043"], ["71140.50", "0.000"], ["71142.10", "0.068"], ["71145.10", "0.013"], ["71170.60", "0.030"], ["71174.20", "0.045"], ["71175.20", "0.431"], ["71178.50", "0.003"], ["71181.50", "0.006"], ["71182.90", "0.042"], ["71186.20", "0.016"], ["71187.60", "0.006"], ["71187.70", "0.319"], ["71204.60", "0.822"]], "a": [["71217.40", "0.015"], ["71220.40", "0.004"], ["71224.60", "0.022"], ["71239.00", "0.086"], ["71254.60", "0.064"], ["71254.90", "0.070"], ["71268.80", "0.000"], ["71273.10", "0.067"], ["71273.40", "0.006"], ["71283.00", "0.085"], ["71287.70", "0.109"], ["71330.10", "0.140"], ["71431.30", "0.007"], ["71916.60", "0.087"], ["71916.70", "0.294"], ["72266.80", "4.698"], ["72287.70", "0.000"], ["72409.30", "0.000"], ["74793.80", "0.017"], ["77390.10", "0.002"], ["78325.20", "0.000"]]}}
{"local_ts": 1773384569224, "server_ts": 1773384569008, "data": {"e": "depthUpdate", "E": 1773384569009, "T": 1773384569008, "s": "BTCUSDT", "U": 10101343054440, "u": 10101343058344, "pu": 10101343054382, "b": [["5000.00", "101.398"], ["20804.60", "0.630"], ["20904.60", "0.270"], ["21004.60", "1.017"], ["21104.60", "0.783"], ["33000.00", "9.339"], ["64084.10", "0.000"], ["67638.90", "0.000"], ["69063.40", "0.015"], ["69887.30", "1.071"], ["70207.70", "1.563"], ["70208.40", "0.000"], ["70492.60", "0.000"], ["71036.50", "0.006"], ["71036.70", "0.002"], ["71159.00", "0.025"], ["71159.20", "0.017"], ["71201.60", "0.213"]], "a": [["71254.10", "0.190"], ["71254.20", "0.085"], ["71431.40", "0.007"], ["71916.60", "0.087"], ["71916.70", "0.294"], ["72344.00", "2.366"], ["78325.20", "0.000"]]}}
{"local_ts": 1773384570249, "server_ts": 1773384570027, "data": {"e": "depthUpdate", "E": 1773384570029, "T": 1773384570027, "s": "BTCUSDT", "U": 10101343098843, "u": 10101343104381, "pu": 10101343098773, "b": [["1000.00", "27.492"], ["5000.00", "101.398"], ["20704.60", "0.495"], ["20804.60", "0.405"], ["20904.60", "0.738"], ["21004.60", "1.062"], ["56964.00", "0.000"], ["64084.10", "0.000"], ["70065.30", "2.997"], ["70085.80", "0.000"], ["70172.10", "8.751"], ["70192.60", "0.000"], ["70492.60", "0.000"], ["70848.60", "3.382"], ["71036.10", "0.004"], ["71036.50", "0.004"], ["71158.90", "0.915"], ["71159.10", "0.095"], ["71165.30", "0.942"], ["71166.30", "0.051"], ["71177.40", "0.038"], ["71178.30", "0.100"], ["71179.00", "0.000"], ["71179.20", "0.006"], ["71179.90", "0.042"], ["71181.40", "0.125"], ["71181.90", "0.005"], ["71183.30", "0.000"], ["71184.50", "0.000"], ["71185.20", "1.053"], ["71185.30", "0.515"], ["71185.60", "0.075"], ["71186.00", "0.004"], ["71186.30", "0.671"], ["71186.70", "0.505"], ["71187.40", "0.014"], ["71187.70", "0.319"], ["71188.30", "0.010"], ["71188.60", "1.140"], ["71188.80", "0.009"], ["71189.90", "0.015"], ["71191.60", "0.411"], ["71192.90", "0.015"], ["71194.10", "0.019"], ["71194.20", "0.392"], ["71194.30", "0.000"], ["71194.40", "0.004"], ["71195.40", "0.020"], ["71196.60", "0.015"], ["71197.20", "0.025"], ["71197.50", "0.070"], ["71197.90", "0.017"], ["71199.20", "0.017"], ["71200.40", "0.017"], ["71200.60", "0.007"], ["71201.20", "0.000"], ["71201.70", "0.018"], ["71202.70", "0.042"], ["71202.90", "0.003"], ["71204.20", "0.004"], ["71204.50", "0.043"], ["71204.60", "2.714"]], "a": [["71204.80", "0.009"], ["71205.20", "0.017"], ["71206.50", "1.121"], ["71207.70", "0.015"], ["71209.00", "0.015"], ["71210.20", "0.015"], ["71211.50", "0.015"], ["71212.70", "0.015"], ["71213.10", "0.067"], ["71214.00", "0.024"], ["71215.30", "0.021"], ["71220.00", "0.052"], ["71222.90", "0.506"], ["71223.00", "0.515"], ["71223.10", "0.177"], ["71224.10", "0.003"], ["71224.30", "0.972"], ["71225.50", "0.156"], ["71226.40", "0.099"], ["71229.70", "0.002"], ["71231.20", "0.247"], ["71235.60", "0.005"], ["71252.00", "0.015"], ["71916.70", "1.682"], ["72237.20", "9.542"], ["72344.00", "4.298"], ["72379.60", "0.975"], ["74786.10", "0.000"], ["78325.20", "0.000"]]}}
{"local_ts": 1773384571276, "server_ts": 1773384571050, "data": {"e": "depthUpdate", "E": 1773384571051, "T": 1773384571050, "s": "BTCUSDT", "U": 10101343162607, "u": 10101343170423, "pu": 10101343162488, "b": [["5000.00", "101.418"], ["20704.60", "0.540"], ["20804.60", "0.477"], ["20904.60", "1.323"], ["21104.60", "0.360"], ["33000.00", "9.343"], ["67619.10", "0.000"], ["67639.60", "0.002"], ["69890.30", "1.226"], ["70119.00", "0.000"], ["70190.30", "0.000"], ["70492.60", "0.000"], ["71035.70", "0.058"], ["71036.10", "0.002"], ["71122.30", "0.003"], ["71125.30", "1.076"], ["71126.30", "0.039"], ["71129.50", "0.042"], ["71140.50", "0.003"], ["71155.00", "0.885"], ["71158.40", "0.003"], ["71159.20", "0.017"], ["71159.40", "0.075"], ["71161.50", "0.021"], ["71162.00", "2.564"], ["71163.40", "0.679"], ["71169.00", "0.806"], ["71171.70", "0.003"], ["71172.90", "0.021"], ["71173.40", "0.251"], ["71174.90", "0.016"], ["71175.40", "0.061"], ["71176.00", "0.814"], ["71176.30", "0.244"], ["71177.30", "0.061"], ["71178.30", "0.142"], ["71179.30", "0.042"], ["71180.20", "0.112"], ["71181.20", "0.044"], ["71182.20", "0.307"], ["71183.00", "0.831"], ["71183.10", "0.354"], ["71183.30", "0.000"], ["71184.10", "0.309"], ["71184.90", "0.008"], ["71185.60", "0.075"], ["71186.70", "0.000"], ["71187.70", "0.321"], ["71188.70", "0.040"], ["71188.80", "0.003"], ["71189.70", "0.009"], ["71191.50", "1.052"], ["71191.60", "0.118"], ["71191.70", "0.001"], ["71191.80", "0.007"], ["71192.30", "0.000"], ["71192.50", "0.010"], ["71193.90", "0.009"], ["71194.10", "0.004"], ["71195.60", "0.000"], ["71196.20", "0.060"], ["71200.70", "0.000"], ["71201.60", "0.213"], ["71204.50", "0.000"], ["71204.60", "1.286"]], "a": [["71204.70", "4.487"], ["71209.00", "0.017"], ["71215.40", "0.006"], ["71220.10", "1.160"], ["71221.10", "0.000"], ["71222.50", "0.099"], ["71222.70", "0.000"], ["71223.60", "0.635"], ["71225.00", "0.816"], ["71226.60", "0.211"], ["71228.40", "0.030"], ["71232.00", "0.810"], ["71236.70", "0.665"], ["71239.00", "0.890"], ["71240.30", "0.170"], ["71243.90", "0.488"], ["71246.00", "0.816"], ["71251.80", "0.659"], ["71252.50", "0.021"], ["71253.00", "0.873"], ["71253.50", "0.049"], ["71253.70", "0.369"], ["71254.40", "0.096"], ["71256.20", "0.004"], ["71268.30", "1.066"], ["71268.80", "0.003"], ["71283.00", "0.007"], ["71297.60", "0.337"], ["71300.70", "0.072"], ["71310.60", "0.105"], ["71393.40", "0.100"], ["71397.00", "0.004"], ["71448.90", "0.000"], ["71450.20", "0.002"], ["71450.30", "0.007"], ["71457.30", "0.015"], ["71457.40", "0.007"], ["71464.40", "0.000"], ["71464.50", "0.062"], ["71470.90", "0.007"], ["71471.50", "0.019"], ["71471.60", "0.009"], ["71478.60", "0.002"], ["71478.70", "0.029"], ["71485.70", "1.303"], ["71485.80", "0.007"], ["71492.80", "0.000"], ["71492.90", "0.007"], ["71499.90", "0.009"], ["71500.00", "7.632"], ["71600.00", "19.762"], ["71916.60", "0.087"], ["71916.70", "2.376"]]}}
{"local_ts": 1773384572287, "server_ts": 1773384572070, "data": {"e": "depthUpdate", "E": 1773384572071, "T": 1773384572070, "s": "BTCUSDT", "U": 10101343257328, "u": 10101343271823, "pu": 10101343257251, "b": [["1000.00", "27.492"], ["5000.00", "101.418"], ["20698.90", "0.225"], ["20798.90", "0.657"], ["20804.60", "0.900"], ["20904.60", "0.018"], ["20998.90", "0.225"], ["21104.60", "0.459"], ["67620.20", "0.002"], ["69390.70", "0.087"], ["70117.40", "1.424"], ["70486.90", "1.066"], ["70522.50", "0.565"], ["71035.70", "0.056"], ["71040.20", "0.002"], ["71090.90", "6.789"], ["71111.50", "0.305"], ["71147.50", "0.312"], ["71148.20", "0.003"], ["71148.90", "0.005"], ["71149.60", "0.005"], ["71151.30", "0.001"], ["71151.60", "0.003"], ["71155.00", "0.888"], ["71158.10", "0.026"], ["71162.00", "2.564"], ["71162.90", "0.093"], ["71167.00", "0.049"], ["71168.20", "0.725"], ["71169.00", "0.815"], ["71170.40", "0.079"], ["71171.30", "0.000"], ["71172.70", "0.206"], ["71176.00", "0.812"], ["71178.30", "0.109"], ["71178.60", "0.011"], ["71179.40", "1.166"], ["71181.40", "0.010"], ["71183.00", "1.177"], ["71183.70", "0.003"], ["71185.60", "0.139"], ["71186.10", "0.114"], ["71186.30", "0.801"], ["71188.10", "0.216"], ["71188.40", "0.158"], ["71192.00", "0.004"], ["71192.10", "0.358"], ["71192.20", "1.050"], ["71195.20", "0.002"]], "a": [["71210.00", "0.004"], ["71210.10", "0.145"], ["71214.30", "0.086"], ["71215.40", "0.861"], ["71217.30", "0.003"], ["71217.50", "0.086"], ["71218.70", "0.752"], ["71218.90", "2.066"], ["71219.10", "0.001"], ["71219.80", "0.002"], ["71222.00", "0.046"], ["71222.20", "0.012"], ["71225.00", "0.812"], ["71232.00", "0.810"], ["71237.20", "0.937"], ["71239.00", "0.890"], ["71246.00", "0.816"], ["71251.50", "0.760"], ["71251.70", "0.266"], ["71253.00", "0.808"], ["71258.40", "0.766"], ["71265.50", "0.003"], ["71280.00", "0.081"], ["71287.60", "0.353"], ["71296.00", "0.113"], ["71316.10", "3.374"], ["71319.60", "2.701"], ["71330.10", "0.154"], ["71450.30", "0.000"], ["71454.40", "0.007"], ["71457.40", "0.000"], ["71461.50", "0.014"], ["71464.50", "0.055"], ["71468.60", "0.209"], ["71471.60", "0.002"], ["71475.70", "0.007"], ["71478.70", "0.022"], ["71482.80", "0.238"], ["71485.80", "0.000"], ["71489.90", "0.007"], ["71492.90", "0.000"], ["71497.00", "0.010"], ["71500.00", "7.625"], ["71504.10", "0.007"], ["71504.50", "0.311"], ["71911.00", "0.181"], ["74046.90", "0.002"]]}}
{"local_ts": 1773384573307, "server_ts": 1773384573090, "data": {"e": "depthUpdate", "E": 1773384573091, "T": 1773384573090, "s": "BTCUSDT", "U": 10101343334270, "u": 10101343340587, "pu": 10101343334264, "b": [["1000.00", "27.492"], ["5000.00", "101.398"], ["20698.90", "1.557"], ["20798.90", "0.153"], ["20898.90", "0.090"], ["20998.90", "0.810"], ["21098.90", "0.090"], ["33000.00", "9.343"], ["56959.00", "0.003"], ["67622.80", "0.002"], ["70116.80", "0.427"], ["70486.90", "1.066"], ["70842.90", "0.002"], ["71039.80", "0.002"], ["71040.20", "0.000"], ["71120.60", "1.043"], ["71131.30", "0.140"], ["71133.90", "1.338"], ["71134.80", "0.513"], ["71138.40", "0.244"], ["71151.60", "0.003"], ["71151.80", "0.003"], ["71156.00", "0.008"], ["71158.00", "0.078"], ["71158.30", "0.029"], ["71159.90", "0.338"], ["71162.10", "0.028"], ["71163.00", "0.004"], ["71163.20", "0.257"], ["71163.30", "0.001"], ["71163.90", "0.413"], ["71166.20", "0.090"], ["71168.20", "1.002"], ["71169.40", "0.868"], ["71176.30", "0.202"], ["71177.30", "0.357"], ["71178.30", "0.089"], ["71179.20", "0.002"], ["71181.40", "0.052"], ["71182.50", "0.071"], ["71183.90", "0.046"], ["71186.10", "0.114"], ["71187.40", "0.042"], ["71190.70", "0.044"], ["71191.80", "0.068"], ["71192.50", "0.730"], ["71192.80", "0.044"], ["71193.60", "0.292"], ["71195.10", "0.042"], ["71195.40", "0.001"], ["71196.50", "0.004"], ["71197.20", "0.046"], ["71197.30", "0.002"], ["71198.80", "0.045"], ["71198.90", "2.547"]], "a": [["71199.00", "1.693"], ["71200.20", "0.002"], ["71203.30", "0.002"], ["71204.20", "0.013"], ["71205.90", "0.753"], ["71206.10", "0.062"], ["71210.10", "0.005"], ["71211.70", "0.100"], ["71219.40", "0.656"], ["71219.80", "0.002"], ["71219.90", "0.004"], ["71220.00", "60.052"], ["71220.10", "1.185"], ["71227.80", "0.004"], ["71227.90", "0.010"], ["71228.50", "0.306"], ["71228.60", "0.018"], ["71237.10", "0.344"], ["71248.30", "0.004"], ["71248.50", "0.003"], ["71249.80", "0.000"], ["71250.00", "1.291"], ["71257.00", "0.000"], ["71263.10", "0.003"], ["71277.30", "1.006"], ["71325.60", "0.002"], ["71454.40", "0.000"], ["71455.70", "0.007"], ["71461.50", "0.007"], ["71462.80", "0.007"], ["71468.60", "0.202"], ["71469.90", "0.007"], ["71475.70", "0.000"], ["71477.00", "0.007"], ["71482.80", "0.231"], ["71484.10", "0.007"], ["71489.90", "0.000"], ["71491.20", "0.007"], ["71497.00", "0.003"], ["71498.30", "0.007"], ["71504.10", "0.000"], ["71505.40", "0.009"], ["71911.00", "0.181"], ["72622.90", "0.048"]]}}
{"local_ts": 1773384574329, "server_ts": 1773384574108, "data": {"e": "depthUpdate", "E": 1773384574111, "T": 1773384574108, "s": "BTCUSDT", "U": 10101343414655, "u": 10101343421890, "pu": 10101343414508, "b": [["5000.00", "101.418"], ["20698.90", "0.333"], ["20898.90", "0.855"], ["20998.90", "0.045"], ["21098.90", "1.467"], ["66806.50", "0.000"], ["67639.00", "0.016"], ["68388.60", "0.012"], ["69775.00", "0.259"], ["70042.60", "0.000"], ["70486.90", "1.066"], ["70487.00", "0.008"], ["70949.60", "0.002"], ["70996.00", "0.069"], ["71003.10", "0.004"], ["71039.70", "0.005"], ["71046.10", "0.000"], ["71090.00", "16.006"], ["71111.60", "0.000"], ["71129.40", "0.000"], ["71137.70", "0.288"], ["71151.90", "0.053"], ["71152.20", "0.004"], ["71155.00", "0.084"], ["71158.40", "0.003"], ["71162.00", "1.760"], ["71163.10", "0.060"], ["71163.40", "0.628"], ["71164.00", "1.345"], ["71166.50", "0.043"], ["71166.90", "0.380"], ["71169.00", "0.011"], ["71176.00", "0.008"], ["71183.00", "0.373"], ["71186.10", "0.114"], ["71187.90", "0.044"], ["71195.60", "0.021"], ["71196.30", "0.221"], ["71198.10", "0.042"], ["71198.20", "0.002"], ["71198.50", "0.002"], ["71198.60", "0.000"], ["71198.80", "0.003"], ["71198.90", "3.112"]], "a": [["71203.40", "0.002"], ["71205.10", "0.005"], ["71209.50", "0.015"], ["71219.30", "0.198"], ["71219.50", "9.351"], ["71225.00", "0.015"], ["71232.00", "0.006"], ["71234.50", "0.054"], ["71238.60", "0.573"], ["71239.00", "0.086"], ["71246.00", "0.012"], ["71253.00", "0.004"], ["71268.30", "1.066"], ["71455.70", "0.000"], ["71456.00", "0.058"], ["71462.80", "0.000"], ["71463.10", "0.021"], ["71469.90", "0.000"], ["71470.20", "0.007"], ["71477.00", "0.000"], ["71477.30", "0.007"], ["71484.10", "0.000"], ["71484.40", "0.007"], ["71491.20", "0.000"], ["71491.50", "0.007"], ["71498.30", "0.000"], ["71498.60", "0.007"], ["71505.40", "0.002"], ["71505.70", "0.007"], ["71748.00", "0.101"], ["71911.00", "0.181"], ["72237.50", "0.691"], ["74782.80", "0.000"]]}}
{"local_ts": 1773384575349, "server_ts": 1773384575132, "data": {"e": "depthUpdate", "E": 1773384575133, "T": 1773384575132, "s": "BTCUSDT", "U": 10101343471155, "u": 10101343478885, "pu": 10101343470945, "b": [["1000.00", "27.492"], ["5000.00", "101.418"], ["20798.90", "0.720"], ["20898.90", "0.180"], ["20998.90", "1.197"], ["21098.90", "0.603"], ["69775.00", "0.265"], ["70169.90", "0.005"], ["70486.90", "1.066"], ["70842.90", "0.002"], ["70949.60", "0.002"], ["70950.30", "0.002"], ["71051.50", "0.661"], ["71163.40", "0.628"], ["71168.90", "0.012"], ["71172.60", "0.002"], ["71174.00", "0.019"], ["71175.20", "0.387"], ["71186.00", "0.023"], ["71191.80", "0.139"], ["71195.40", "0.001"], ["71196.10", "0.043"], ["71196.50", "0.004"], ["71197.10", "0.045"], ["71197.20", "0.001"], ["71198.50", "0.044"], ["71198.60", "0.002"], ["71198.90", "3.087"]], "a": [["71199.00", "1.594"], ["71200.60", "0.000"], ["71200.70", "0.001"], ["71205.90", "0.753"], ["71208.50", "0.021"], ["71210.00", "0.007"], ["71210.70", "0.110"], ["71211.80", "0.006"], ["71220.00", "60.122"], ["71220.10", "1.059"], ["71220.20", "0.135"], ["71224.70", "0.054"], ["71234.50", "0.054"], ["71347.60", "0.488"], ["71421.70", "0.007"], ["71456.00", "0.051"], ["71456.40", "1.991"], ["71463.10", "0.014"], ["71463.50", "0.009"], ["71470.20", "0.000"], ["71470.60", "0.007"], ["71477.30", "0.000"], ["71477.70", "0.007"], ["71484.40", "0.000"], ["71484.80", "0.316"], ["71491.50", "0.000"], ["71491.90", "0.007"], ["71498.60", "0.000"], ["71499.00", "0.042"], ["71505.70", "0.000"], ["71506.10", "0.024"], ["71910.90", "0.000"], ["71911.00", "0.183"], ["72302.60", "0.969"], ["74785.70", "0.055"], ["74791.70", "0.002"], ["89523.20", "0.000"]]}}
{"local_ts": 1773384576372, "server_ts": 1773384576154, "data": {"e": "depthUpdate", "E": 1773384576155, "T": 1773384576154, "s": "BTCUSDT", "U": 10101343793339, "u": 10101343803148, "pu": 10101343793253, "b": [["5000.00", "101.418"], ["20730.60", "0.144"], ["20798.90", "0.315"], ["20930.60", "0.288"], ["20998.90", "0.792"], ["21009.20", "0.000"], ["21010.30", "0.000"], ["21011.60", "0.000"], ["21011.90", "0.000"], ["21012.00", "0.000"], ["21013.80", "0.000"], ["56984.00", "0.000"], ["67625.60", "0.000"], ["67653.80", "0.145"], ["70075.90", "0.641"], ["70354.90", "1.583"], ["70467.70", "0.073"], ["70518.30", "0.000"], ["70841.50", "3.582"], ["70872.50", "0.004"], ["70904.60", "0.099"], ["70908.80", "0.000"], ["70950.30", "0.000"], ["70962.40", "0.000"], ["70965.90", "2.002"], ["70968.70", "0.006"], ["70980.60", "0.004"], ["71006.60", "11.290"], ["71020.70", "0.000"], ["71085.00", "0.710"], ["71143.50", "0.002"], ["71152.20", "0.044"], ["71163.00", "0.002"], ["71164.50", "0.419"], ["71165.20", "0.002"], ["71166.50", "0.294"], ["71174.50", "0.569"], ["71175.20", "0.564"], ["71176.80", "0.000"], ["71178.10", "0.028"], ["71179.80", "0.000"], ["71180.60", "0.115"], ["71181.00", "0.942"], ["71181.30", "0.303"], ["71181.70", "0.055"], ["71182.70", "0.204"], ["71183.00", "0.354"], ["71184.10", "0.307"], ["71186.20", "0.007"], ["71186.30", "0.789"], ["71187.80", "0.004"], ["71188.70", "1.695"], ["71190.00", "0.010"], ["71190.70", "0.304"], ["71192.20", "0.000"], ["71193.60", "0.001"], ["71193.90", "0.072"], ["71195.70", "0.000"], ["71197.00", "0.002"], ["71197.50", "0.051"], ["71200.00", "0.006"], ["71202.90", "0.091"], ["71203.30", "0.001"], ["71203.90", "0.336"], ["71204.00", "0.148"], ["71204.30", "0.315"], ["71205.30", "0.000"], ["71205.70", "0.306"], ["71205.80", "0.132"], ["71206.10", "0.002"], ["71206.90", "0.000"], ["71207.20", "0.002"], ["71207.30", "0.001"], ["71207.60", "0.002"], ["71207.80", "0.000"], ["71208.10", "0.009"], ["71208.50", "0.054"], ["71208.60", "0.069"], ["71209.10", "0.035"], ["71209.40", "0.033"], ["71211.10", "0.056"], ["71211.50", "0.099"], ["71211.80", "0.041"], ["71213.70", "0.007"], ["71213.90", "0.511"], ["71214.00", "0.450"], ["71214.10", "0.033"], ["71215.60", "0.005"], ["71215.70", "0.071"], ["71216.30", "0.005"], ["71217.70", "0.508"], ["71217.80", "0.003"], ["71217.90", "0.634"], ["71218.00", "0.048"], ["71218.40", "0.007"], ["71219.00", "0.000"], ["71219.10", "0.013"], ["71220.10", "0.006"], ["71220.20", "0.000"], ["71220.40", "0.074"], ["71220.80", "0.000"], ["71221.30", "0.003"], ["71221.90", "0.042"], ["71222.10", "0.001"], ["71222.30", "1.107"], ["71223.00", "0.004"], ["71223.20", "0.067"], ["71223.40", "0.003"], ["71223.70", "0.033"], ["71223.90", "0.000"], ["71224.20", "0.043"], ["71224.40", "0.283"], ["71224.50", "0.040"], ["71224.80", "0.084"], ["71224.90", "0.001"], ["71225.10", "0.025"], ["71225.30", "0.160"], ["71225.40", "0.008"], ["71225.80", "0.001"], ["71226.10", "0.001"], ["71226.60", "0.000"], ["71226.80", "0.001"], ["71227.30", "0.007"], ["71227.60", "0.004"], ["71228.00", "0.002"], ["71228.30", "0.104"], ["71228.90", "0.003"], ["71229.00", "0.269"], ["71229.30", "0.002"], ["71229.40", "0.005"], ["71229.50", "0.003"], ["71229.90", "0.340"], ["71230.00", "0.813"], ["71230.50", "0.005"], ["71230.60", "6.254"]], "a": [["71230.70", "1.085"], ["71230.90", "0.001"], ["71232.30", "0.000"], ["71233.70", "0.006"], ["71235.10", "0.006"], ["71235.20", "0.000"], ["71238.40", "0.004"], ["71238.80", "0.002"], ["71239.20", "0.000"], ["71239.40", "0.069"], ["71239.50", "0.003"], ["71239.60", "0.004"], ["71239.70", "0.009"], ["71239.90", "0.207"], ["71240.30", "0.000"], ["71240.40", "0.329"], ["71240.60", "0.000"], ["71240.70", "0.005"], ["71241.00", "0.000"], ["71241.30", "0.002"], ["71243.20", "0.004"], ["71243.70", "0.008"], ["71244.80", "0.007"], ["71247.10", "0.004"], ["71247.70", "0.007"], ["71248.50", "0.087"], ["71249.10", "0.029"], ["71251.50", "0.464"], ["71252.00", "0.006"], ["71253.00", "0.028"], ["71253.80", "0.007"], ["71254.00", "0.002"], ["71254.30", "0.659"], ["71254.50", "0.002"], ["71254.70", "0.051"], ["71255.10", "0.215"], ["71255.60", "0.082"], ["71255.80", "0.718"], ["71256.70", "1.625"], ["71257.40", "0.008"], ["71258.60", "0.003"], ["71259.00", "0.019"], ["71259.10", "0.451"], ["71259.30", "0.004"], ["71259.40", "0.372"], ["71259.90", "0.245"], ["71260.00", "0.322"], ["71260.10", "0.009"], ["71261.60", "0.002"], ["71263.10", "0.000"], ["71265.30", "0.208"], ["71265.70", "0.001"], ["71266.30", "0.443"], ["71267.00", "0.002"], ["71269.60", "0.528"], ["71270.00", "0.350"], ["71270.20", "0.005"], ["71270.90", "0.003"], ["71271.60", "0.284"], ["71272.30", "0.003"], ["71274.00", "0.311"], ["71276.50", "0.032"], ["71280.50", "0.069"], ["71280.80", "0.004"], ["71281.00", "0.006"], ["71281.10", "0.017"], ["71284.80", "0.004"], ["71285.80", "0.317"], ["71286.20", "0.049"], ["71289.40", "0.362"], ["71290.70", "0.002"], ["71292.90", "0.035"], ["71294.80", "0.006"], ["71294.90", "1.147"], ["71297.80", "0.009"], ["71298.70", "0.068"], ["71307.90", "0.011"], ["71308.30", "0.003"], ["71308.80", "1.745"], ["71308.90", "0.007"], ["71309.00", "0.002"], ["71309.10", "0.006"], ["71309.60", "0.004"], ["71317.00", "0.000"], ["71317.10", "0.000"], ["71319.30", "0.000"], ["71319.50", "0.046"], ["71325.00", "0.043"], ["71326.80", "2.443"], ["71326.90", "6.582"], ["71327.00", "0.049"], ["71327.20", "0.340"], ["71327.40", "0.300"], ["71329.90", "0.012"], ["71332.10", "0.068"], ["71335.60", "0.284"], ["71345.20", "0.007"], ["71348.70", "1.933"], ["71353.60", "0.036"], ["71353.80", "0.090"], ["71358.60", "0.080"], ["71358.90", "0.081"], ["71359.20", "0.124"], ["71359.60", "0.068"], ["71363.60", "0.118"], ["71374.30", "0.018"], ["71389.40", "0.068"], ["71399.90", "0.040"], ["71407.10", "0.033"], ["71418.40", "0.000"], ["71419.20", "0.000"], ["71419.40", "0.007"], ["71419.50", "0.000"], ["71419.90", "0.000"], ["71429.20", "0.344"], ["71441.20", "0.061"], ["71442.50", "1.898"], ["71500.90", "0.004"], ["71834.30", "3.601"], ["71943.00", "0.012"], ["72682.70", "0.009"], ["74079.70", "0.004"], ["89523.20", "0.000"]]}}
{"local_ts": 1773384577393, "server_ts": 1773384577176, "data": {"e": "depthUpdate", "E": 1773384577177, "T": 1773384577176, "s": "BTCUSDT", "U": 10101343918737, "u": 10101343933087, "pu": 10101343918601, "b": [["1000.00", "27.492"], ["5000.00", "101.418"], ["20730.60", "0.009"], ["20833.00", "0.666"], ["20930.00", "0.081"], ["20930.60", "0.333"], ["20933.00", "0.153"], ["21133.00", "0.450"], ["40000.00", "49.307"], ["67639.00", "0.012"], ["67639.10", "0.004"], ["67644.30", "0.000"], ["67671.00", "0.120"], ["69935.20", "0.361"], ["70520.70", "0.015"], ["70845.60", "0.000"], ["70877.70", "0.123"], ["70957.80", "0.000"], ["71056.20", "0.758"], ["71113.60", "0.378"], ["71120.60", "6.459"], ["71131.80", "0.208"], ["71162.00", "1.756"], ["71167.30", "0.004"], ["71176.50", "0.002"], ["71184.70", "0.003"], ["71186.20", "0.055"], ["71188.70", "0.899"], ["71189.80", "0.544"], ["71193.10", "0.220"], ["71197.40", "0.116"], ["71199.40", "0.621"], ["71199.90", "0.086"], ["71204.10", "1.251"], ["71207.10", "0.288"], ["71208.40", "0.073"], ["71208.50", "0.070"], ["71210.20", "0.004"], ["71215.60", "0.005"], ["71215.80", "0.002"], ["71216.80", "0.307"], ["71217.50", "0.003"], ["71217.60", "0.295"], ["71217.70", "0.010"], ["71218.00", "0.050"], ["71218.10", "0.003"], ["71219.70", "0.800"], ["71220.00", "2.037"], ["71220.50", "0.002"], ["71220.70", "0.010"], ["71220.80", "0.697"], ["71220.90", "0.011"], ["71221.00", "0.001"], ["71221.50", "0.347"], ["71221.60", "1.751"], ["71221.90", "0.021"], ["71222.20", "0.002"], ["71222.30", "1.052"], ["71222.40", "0.283"], ["71222.50", "0.017"], ["71222.60", "0.004"], ["71223.00", "0.001"], ["71223.30", "0.143"], ["71223.70", "0.946"], ["71223.90", "0.232"], ["71224.30", "0.032"], ["71224.50", "0.067"], ["71224.60", "0.000"], ["71224.80", "0.039"], ["71224.90", "0.063"], ["71225.00", "0.066"], ["71225.10", "0.039"], ["71225.40", "0.280"], ["71225.50", "0.053"], ["71226.10", "0.372"], ["71226.50", "0.064"], ["71227.70", "0.009"], ["71229.30", "0.002"], ["71229.40", "0.208"], ["71229.50", "0.136"], ["71231.00", "0.002"], ["71231.90", "0.004"], ["71233.00", "8.494"]], "a": [["71235.50", "0.006"], ["71239.40", "0.002"], ["71242.20", "0.000"], ["71242.60", "0.006"], ["71242.70", "0.004"], ["71243.50", "0.062"], ["71243.70", "0.151"], ["71243.80", "0.272"], ["71244.00", "0.002"], ["71244.40", "0.505"], ["71244.50", "0.000"], ["71244.70", "0.113"], ["71245.30", "0.000"], ["71245.80", "0.000"], ["71246.00", "0.030"], ["71247.20", "0.000"], ["71247.30", "0.081"], ["71247.40", "0.000"], ["71248.80", "0.046"], ["71249.10", "0.029"], ["71249.70", "0.002"], ["71249.90", "0.001"], ["71250.90", "0.003"], ["71251.00", "0.027"], ["71252.20", "0.001"], ["71253.90", "0.140"], ["71257.20", "0.002"], ["71257.30", "0.000"], ["71257.50", "0.011"], ["71257.80", "0.000"], ["71257.90", "0.000"], ["71258.00", "0.017"], ["71258.10", "0.018"], ["71258.30", "0.070"], ["71258.60", "0.056"], ["71258.70", "0.007"], ["71259.40", "0.302"], ["71259.90", "0.077"], ["71260.50", "0.754"], ["71260.70", "0.004"], ["71260.80", "0.004"], ["71261.40", "0.004"], ["71261.50", "0.000"], ["71262.10", "0.014"], ["71262.20", "0.000"], ["71262.60", "1.049"], ["71262.80", "0.011"], ["71262.90", "0.021"], ["71263.00", "0.260"], ["71263.10", "0.000"], ["71263.50", "0.007"], ["71263.60", "0.084"], ["71264.20", "0.002"], ["71264.30", "0.039"], ["71264.70", "0.676"], ["71264.90", "0.000"], ["71266.10", "0.031"], ["71267.60", "0.505"], ["71268.70", "0.003"], ["71268.80", "0.005"], ["71268.90", "0.000"], ["71271.30", "0.004"], ["71272.30", "0.141"], ["71273.70", "0.018"], ["71273.90", "0.115"], ["71275.80", "0.006"], ["71287.70", "0.109"], ["71288.40", "0.002"], ["71290.90", "0.879"], ["71303.50", "0.009"], ["71307.60", "1.057"], ["71308.80", "1.090"], ["71320.90", "0.376"], ["71321.60", "0.124"], ["71324.30", "0.655"], ["71329.90", "0.010"], ["71343.00", "0.000"], ["71343.70", "0.119"], ["71349.20", "0.002"], ["71356.20", "0.316"], ["71393.40", "0.040"], ["71405.80", "6.433"], ["71414.70", "0.099"], ["71417.90", "0.506"], ["71418.30", "0.161"], ["71945.40", "0.002"], ["72657.70", "0.009"], ["74813.10", "0.002"], ["89523.20", "0.000"]]}}
{"local_ts": 1773384578415, "server_ts": 1773384578196, "data": {"e": "depthUpdate", "E": 1773384578199, "T": 1773384578196, "s": "BTCUSDT", "U": 10101344006142, "u": 10101344013823, "pu": 10101344005954, "b": [["1000.00", "27.492"], ["5000.00", "101.418"], ["20733.00", "0.396"], ["20833.00", "1.404"], ["21033.00", "0.324"], ["21133.00", "0.576"], ["33000.00", "9.339"], ["67647.40", "0.002"], ["69666.60", "0.259"], ["69775.00", "0.253"], ["70237.20", "1.002"], ["70301.00", "0.100"], ["70342.60", "1.408"], ["70514.60", "0.000"], ["70520.70", "1.415"], ["70550.20", "0.708"], ["70553.90", "0.702"], ["70591.90", "2.103"], ["70876.80", "0.077"], ["71118.10", "0.078"], ["71131.00", "0.051"], ["71137.10", "0.096"], ["71152.20", "0.061"], ["71152.80", "0.086"], ["71153.10", "0.578"], ["71153.30", "0.180"], ["71153.90", "0.240"], ["71154.30", "0.081"], ["71154.60", "0.005"], ["71154.70", "0.026"], ["71155.00", "0.104"], ["71166.50", "0.041"], ["71168.90", "0.105"], ["71174.00", "0.922"], ["71174.70", "0.000"], ["71176.00", "0.006"], ["71181.70", "0.053"], ["71184.10", "0.307"], ["71184.20", "0.510"], ["71196.60", "0.000"], ["71197.10", "0.320"], ["71197.40", "0.116"], ["71200.00", "0.008"], ["71201.10", "0.002"], ["71211.60", "0.582"], ["71212.50", "0.005"], ["71213.50", "0.000"], ["71213.60", "0.002"], ["71213.80", "0.004"], ["71214.80", "0.045"], ["71220.10", "0.076"], ["71220.50", "0.002"], ["71220.70", "0.574"], ["71222.00", "0.023"], ["71222.40", "0.283"], ["71223.70", "0.075"], ["71224.20", "0.311"], ["71225.10", "0.219"], ["71225.70", "0.061"], ["71226.00", "0.044"], ["71226.10", "0.433"], ["71226.40", "0.027"], ["71226.80", "0.026"], ["71228.80", "0.002"], ["71230.00", "0.806"], ["71233.00", "5.588"]], "a": [["71233.10", "2.658"], ["71239.70", "0.101"], ["71244.70", "0.002"], ["71247.30", "0.081"], ["71248.10", "0.081"], ["71248.50", "0.069"], ["71248.90", "0.124"], ["71249.30", "0.129"], ["71250.00", "1.659"], ["71254.50", "0.101"], ["71261.60", "0.380"], ["71265.20", "0.087"], ["71268.70", "0.168"], ["71272.30", "0.102"], ["71282.10", "0.023"], ["71284.00", "0.078"], ["71284.10", "0.018"], ["71284.20", "0.033"], ["71284.40", "0.065"], ["71284.80", "0.127"], ["71285.20", "0.045"], ["71285.90", "0.326"], ["71294.80", "0.000"], ["71297.20", "0.005"], ["71304.30", "1.094"], ["71306.60", "0.306"], ["71307.60", "1.055"], ["71309.10", "0.003"], ["71311.50", "0.011"], ["71319.90", "0.130"], ["71320.30", "0.063"], ["71320.70", "0.126"], ["71321.10", "0.510"], ["71321.70", "0.188"], ["71325.30", "0.004"], ["71337.70", "0.537"], ["71418.30", "0.002"], ["71459.60", "0.000"], ["71647.70", "0.004"], ["71945.30", "0.041"], ["71945.40", "0.417"], ["72237.40", "0.617"], ["72265.90", "0.829"], ["72266.00", "1.117"], ["89523.20", "0.000"]]}}
{"local_ts": 1773384579438, "server_ts": 1773384579218, "data": {"e": "depthUpdate", "E": 1773384579219, "T": 1773384579218, "s": "BTCUSDT", "U": 10101344138839, "u": 10101344150677, "pu": 10101344138461, "b": [["5000.00", "101.418"], ["20728.50", "0.603"], ["20733.00", "0.837"], ["20833.00", "0.063"], ["20926.40", "0.009"], ["20928.50", "0.180"], ["21033.00", "0.441"], ["21128.10", "0.009"], ["21128.50", "0.180"], ["67657.40", "0.124"], ["67671.10", "0.000"], ["67678.70", "0.023"], ["70514.10", "0.002"], ["70515.80", "0.000"], ["70516.20", "0.000"], ["70922.10", "6.475"], ["70979.00", "0.045"], ["71038.40", "3.133"], ["71078.20", "0.204"], ["71081.50", "0.114"], ["71085.10", "0.192"], ["71105.50", "0.000"], ["71106.50", "0.008"], ["71108.10", "0.148"], ["71113.60", "0.378"], ["71133.30", "2.144"], ["71140.40", "0.285"], ["71147.50", "1.879"], ["71149.30", "0.000"], ["71150.60", "0.354"], ["71150.70", "0.184"], ["71150.90", "1.200"], ["71156.10", "0.140"], ["71160.60", "0.002"], ["71162.00", "1.758"], ["71162.30", "0.739"], ["71162.40", "0.000"], ["71163.40", "0.044"], ["71164.40", "0.053"], ["71165.30", "1.015"], ["71166.30", "0.042"], ["71171.80", "1.365"], ["71171.90", "0.206"], ["71172.70", "0.214"], ["71173.00", "0.021"], ["71173.70", "0.004"], ["71174.70", "0.000"], ["71175.70", "0.005"], ["71176.20", "0.000"], ["71176.40", "0.002"], ["71176.60", "0.092"], ["71177.60", "0.092"], ["71178.60", "0.319"], ["71178.90", "0.890"], ["71180.50", "0.307"], ["71180.60", "0.115"], ["71180.70", "0.010"], ["71180.80", "0.008"], ["71181.00", "0.937"], ["71181.70", "0.053"], ["71182.40", "0.051"], ["71182.70", "0.204"], ["71182.80", "0.002"], ["71183.60", "0.004"], ["71183.90", "0.000"], ["71184.50", "0.000"], ["71184.60", "0.004"], ["71185.30", "0.051"], ["71185.60", "0.002"], ["71186.50", "0.511"], ["71187.40", "0.093"], ["71187.60", "0.008"], ["71188.80", "0.001"], ["71188.90", "0.018"], ["71189.90", "0.003"], ["71190.70", "0.304"], ["71190.90", "0.225"], ["71191.20", "0.506"], ["71191.40", "0.386"], ["71191.90", "0.005"], ["71192.00", "0.026"], ["71192.10", "0.002"], ["71192.70", "0.017"], ["71192.80", "0.313"], ["71192.90", "0.188"], ["71193.10", "0.220"], ["71193.30", "0.004"], ["71193.60", "0.001"], ["71194.10", "0.562"], ["71194.20", "0.005"], ["71194.30", "0.080"], ["71194.70", "0.034"], ["71194.80", "0.000"], ["71194.90", "0.307"], ["71195.00", "0.167"], ["71195.10", "0.008"], ["71195.40", "0.000"], ["71195.70", "0.000"], ["71196.00", "0.005"], ["71196.90", "0.011"], ["71197.00", "0.011"], ["71197.40", "0.188"], ["71197.50", "0.000"], ["71197.70", "0.012"], ["71197.80", "0.302"], ["71198.00", "0.002"], ["71198.30", "0.014"], ["71198.40", "0.308"], ["71198.70", "0.070"], ["71198.80", "0.004"], ["71198.90", "0.004"], ["71199.00", "0.021"], ["71199.10", "0.209"], ["71199.60", "0.008"], ["71199.70", "0.002"], ["71199.80", "0.010"], ["71200.20", "0.541"], ["71200.30", "0.024"], ["71200.40", "0.107"], ["71200.50", "0.002"], ["71200.70", "0.000"], ["71200.80", "0.003"], ["71202.40", "0.009"], ["71202.50", "0.002"], ["71202.70", "0.000"], ["71203.00", "0.002"], ["71203.90", "0.505"], ["71204.20", "0.656"], ["71204.30", "0.103"], ["71204.40", "0.007"], ["71204.80", "0.001"], ["71204.90", "0.073"], ["71205.00", "0.638"], ["71205.80", "1.228"], ["71205.90", "0.006"], ["71206.00", "0.008"], ["71206.20", "0.005"], ["71206.30", "0.001"], ["71206.40", "0.010"], ["71206.70", "0.010"], ["71206.80", "0.339"], ["71207.10", "0.078"], ["71207.50", "0.004"], ["71207.60", "0.002"], ["71207.70", "0.001"], ["71207.90", "0.038"], ["71208.00", "0.007"], ["71208.40", "0.143"], ["71208.60", "0.006"], ["71208.70", "0.044"], ["71208.90", "0.048"], ["71209.00", "0.000"], ["71209.20", "0.550"], ["71209.50", "0.318"], ["71209.60", "0.456"], ["71209.80", "0.072"], ["71209.90", "0.000"], ["71210.00", "0.096"], ["71210.10", "0.000"], ["71210.20", "0.004"], ["71210.50", "0.001"], ["71210.60", "0.000"], ["71210.70", "0.002"], ["71210.80", "0.000"], ["71211.00", "0.011"], ["71211.20", "0.021"], ["71211.50", "0.006"], ["71211.60", "0.512"], ["71211.70", "0.011"], ["71211.80", "0.012"], ["71212.30", "0.006"], ["71213.10", "0.305"], ["71213.30", "0.000"], ["71213.40", "0.360"], ["71214.00", "0.011"], ["71214.20", "0.000"], ["71214.50", "0.004"], ["71215.00", "1.073"], ["71215.60", "0.416"], ["71215.70", "0.272"], ["71216.00", "0.027"], ["71216.70", "0.002"], ["71216.90", "0.031"], ["71217.20", "0.509"], ["71217.30", "0.043"], ["71218.10", "0.036"], ["71219.40", "0.000"], ["71219.50", "0.007"], ["71219.90", "0.078"], ["71220.70", "0.010"], ["71220.80", "1.074"], ["71221.00", "0.037"], ["71221.40", "0.044"], ["71221.50", "0.006"], ["71221.60", "0.480"], ["71221.70", "0.003"], ["71221.80", "0.002"], ["71221.90", "0.003"], ["71222.10", "0.001"], ["71222.90", "0.024"], ["71223.10", "0.000"], ["71223.30", "0.003"], ["71223.40", "0.001"], ["71224.20", "0.100"], ["71224.40", "0.001"], ["71224.90", "0.001"], ["71225.00", "0.008"], ["71225.20", "0.002"], ["71225.30", "0.001"], ["71225.40", "0.339"], ["71225.50", "0.116"], ["71225.90", "0.002"], ["71226.40", "0.000"], ["71226.50", "0.000"], ["71226.70", "0.000"], ["71226.80", "0.000"], ["71227.20", "0.000"], ["71227.40", "0.000"], ["71227.60", "0.000"], ["71227.70", "0.000"], ["71227.80", "0.000"], ["71228.00", "0.000"], ["71228.10", "0.000"], ["71228.20", "0.000"], ["71228.30", "0.000"], ["71228.40", "0.000"], ["71228.50", "0.000"]], "a": [["71226.40", "17.164"], ["71226.50", "6.507"], ["71226.60", "0.000"], ["71226.80", "0.000"], ["71226.90", "0.000"], ["71227.20", "0.005"], ["71227.30", "0.378"], ["71227.50", "0.000"], ["71227.70", "0.002"], ["71227.80", "0.000"], ["71227.90", "0.414"], ["71228.00", "2.122"], ["71228.10", "2.766"], ["71228.20", "0.563"], ["71228.30", "0.002"], ["71228.40", "0.004"], ["71228.50", "1.336"], ["71228.60", "0.223"], ["71229.60", "0.002"], ["71230.50", "0.002"], ["71231.60", "0.004"], ["71231.70", "0.004"], ["71231.90", "0.004"], ["71232.00", "0.007"], ["71232.30", "0.003"], ["71232.50", "0.008"], ["71233.00", "0.284"], ["71233.50", "0.006"], ["71233.60", "0.222"], ["71233.70", "0.651"], ["71233.80", "0.288"], ["71233.90", "0.007"], ["71234.10", "0.007"], ["71235.70", "0.000"], ["71235.80", "0.004"], ["71237.40", "0.006"], ["71237.60", "0.140"], ["71238.70", "0.000"], ["71239.00", "0.011"], ["71239.80", "0.020"], ["71240.20", "0.000"], ["71240.30", "0.206"], ["71240.80", "0.006"], ["71240.90", "0.003"], ["71241.30", "0.002"], ["71241.60", "0.002"], ["71241.70", "0.191"], ["71241.80", "0.001"], ["71241.90", "0.007"], ["71242.00", "0.075"], ["71242.90", "0.631"], ["71243.00", "0.002"], ["71243.10", "0.161"], ["71243.20", "0.037"], ["71243.80", "0.002"], ["71244.00", "0.002"], ["71244.10", "0.353"], ["71244.40", "0.550"], ["71244.60", "0.201"], ["71245.00", "0.294"], ["71245.20", "0.280"], ["71245.90", "0.004"], ["71246.00", "0.016"], ["71246.30", "0.009"], ["71246.70", "0.285"], ["71247.80", "0.000"], ["71247.90", "0.150"], ["71248.40", "0.505"], ["71248.50", "0.006"], ["71248.90", "0.314"], ["71249.50", "0.044"], ["71249.60", "0.079"], ["71249.80", "0.003"], ["71250.00", "1.404"], ["71250.10", "0.004"], ["71251.00", "1.058"], ["71253.00", "0.004"], ["71253.50", "0.000"], ["71253.60", "0.005"], ["71254.40", "0.515"], ["71254.50", "0.004"], ["71254.70", "0.000"], ["71255.10", "0.215"], ["71255.20", "0.040"], ["71255.80", "0.725"], ["71255.90", "0.026"], ["71256.40", "0.073"], ["71256.90", "0.003"], ["71258.70", "0.014"], ["71259.00", "0.047"], ["71259.30", "0.011"], ["71259.40", "0.302"], ["71260.00", "0.311"], ["71260.10", "0.000"], ["71260.60", "0.118"], ["71260.70", "0.011"], ["71260.80", "0.006"], ["71261.40", "0.004"], ["71261.50", "0.086"], ["71263.40", "0.281"], ["71264.20", "0.070"], ["71265.60", "1.067"], ["71266.90", "0.293"], ["71267.60", "0.000"], ["71267.70", "0.174"], ["71267.80", "0.071"], ["71268.20", "0.790"], ["71269.00", "0.007"], ["71269.30", "1.179"], ["71270.10", "0.117"], ["71270.30", "0.087"], ["71271.40", "0.000"], ["71279.10", "0.041"], ["71279.20", "0.217"], ["71279.30", "0.018"], ["71279.40", "0.024"], ["71279.50", "0.534"], ["71279.70", "0.004"], ["71279.90", "6.405"], ["71282.30", "0.010"], ["71284.10", "0.018"], ["71285.20", "0.045"], ["71285.60", "0.000"], ["71288.70", "0.252"], ["71289.10", "0.204"], ["71291.00", "0.007"], ["71292.70", "0.509"], ["71294.90", "1.082"], ["71296.30", "0.002"], ["71297.80", "0.007"], ["71298.40", "0.031"], ["71306.60", "0.304"], ["71311.60", "0.070"], ["71315.20", "0.013"], ["71318.70", "0.002"], ["71346.20", "0.108"], ["71346.30", "0.103"], ["71383.80", "0.370"], ["71384.90", "0.000"], ["71385.20", "0.004"], ["71385.30", "0.002"], ["71397.40", "0.159"], ["71402.60", "0.209"], ["71402.70", "0.000"], ["71403.10", "0.000"], ["71405.20", "0.001"], ["71406.30", "0.000"], ["71406.70", "0.004"], ["71410.20", "0.043"], ["71413.80", "0.029"], ["71747.40", "0.700"], ["71940.40", "0.002"], ["71940.50", "0.000"], ["71940.90", "0.000"], ["72201.70", "0.004"], ["72204.70", "0.000"], ["72206.60", "0.004"], ["72206.70", "0.004"], ["72206.80", "0.035"], ["72211.60", "0.002"], ["72226.50", "0.008"], ["72228.10", "0.002"], ["72228.60", "0.030"], ["72230.70", "0.021"], ["72653.10", "0.017"], ["75001.20", "0.000"], ["89523.20", "0.006"], ["100000.00", "15.858"]]}}
{"local_ts": 1773384580457, "server_ts": 1773384580240, "data": {"e": "depthUpdate", "E": 1773384580241, "T": 1773384580240, "s": "BTCUSDT", "U": 10101344229053, "u": 10101344234603, "pu": 10101344228943, "b": [["1000.00", "27.492"], ["5000.00", "101.418"], ["20728.50", "0.126"], ["20824.20", "0.054"], ["20924.20", "0.603"], ["20928.50", "0.126"], ["21024.20", "0.054"], ["21028.50", "0.000"], ["21124.20", "1.260"], ["21128.50", "0.126"], ["67639.10", "0.000"], ["69775.00", "0.244"], ["70333.50", "0.710"], ["70872.40", "0.005"], ["71150.70", "0.000"], ["71177.00", "0.057"], ["71177.10", "0.005"], ["71205.60", "0.005"], ["71216.20", "0.143"], ["71216.60", "0.104"], ["71216.70", "0.006"], ["71217.10", "0.072"], ["71223.10", "0.004"]], "a": [["71227.70", "0.000"], ["71229.50", "0.007"], ["71231.40", "0.067"], ["71232.90", "0.647"], ["71237.80", "0.000"], ["71238.00", "0.007"], ["71258.50", "0.002"], ["71258.60", "0.131"], ["71267.00", "0.025"], ["71274.10", "0.016"], ["71274.40", "0.510"], ["71407.10", "3.615"], ["71528.30", "0.000"], ["71532.00", "0.000"], ["71673.10", "0.002"], ["71925.40", "1.388"], ["71936.50", "0.963"], ["72067.80", "0.000"], ["74786.30", "0.000"], ["74815.70", "0.002"]]}}
{"local_ts": 1773384581480, "server_ts": 1773384581262, "data": {"e": "depthUpdate", "E": 1773384581263, "T": 1773384581262, "s": "BTCUSDT", "U": 10101344315478, "u": 10101344319972, "pu": 10101344315345, "b": [["5000.00", "101.418"], ["20824.20", "0.819"], ["20924.20", "0.081"], ["21024.20", "1.395"], ["21124.20", "0.405"], ["67656.60", "0.002"], ["67662.00", "0.020"], ["69806.00", "0.048"], ["69882.00", "0.004"], ["70190.80", "1.423"], ["70512.00", "0.064"], ["71160.50", "0.000"], ["71164.00", "3.711"], ["71164.10", "1.736"], ["71164.40", "0.129"], ["71177.50", "0.837"], ["71177.60", "0.092"], ["71185.50", "1.116"], ["71187.30", "1.128"], ["71188.20", "0.002"], ["71200.00", "0.076"], ["71201.70", "0.006"], ["71202.00", "0.004"], ["71206.10", "0.516"], ["71206.90", "0.490"], ["71208.10", "0.002"], ["71209.60", "0.007"], ["71215.20", "0.141"], ["71215.30", "0.008"], ["71217.10", "0.070"], ["71221.50", "0.006"]], "a": [["71224.30", "4.319"], ["71226.30", "0.006"], ["71228.60", "0.034"], ["71231.40", "0.232"], ["71238.70", "0.000"], ["71243.60", "0.631"], ["71246.90", "0.006"], ["71248.70", "0.625"], ["71249.70", "0.262"], ["71253.60", "0.005"], ["71259.90", "0.099"], ["71281.50", "0.425"], ["71388.60", "1.721"], ["71451.20", "0.000"], ["71744.10", "0.004"], ["71928.40", "0.056"], ["71936.40", "0.153"], ["71936.50", "0.963"], ["72224.80", "0.007"]]}}
{"local_ts": 1773384582500, "server_ts": 1773384582284, "data": {"e": "depthUpdate", "E": 1773384582285, "T": 1773384582284, "s": "BTCUSDT", "U": 10101344388586, "u": 10101344392689, "pu": 10101344388460, "b": [["1000.00", "27.492"], ["5000.00", "101.418"], ["20724.20", "0.684"], ["20824.20", "0.216"], ["20924.20", "1.125"], ["21024.20", "0.675"], ["67634.80", "0.002"], ["67659.60", "0.002"], ["67662.00", "0.022"], ["67671.30", "0.000"], ["67671.40", "0.002"], ["70143.80", "0.853"], ["70234.20", "0.994"], ["70512.00", "0.064"], ["70974.20", "0.224"], ["71063.20", "8.226"], ["71097.10", "0.002"], ["71189.80", "0.785"], ["71192.60", "0.186"], ["71206.90", "0.370"], ["71217.60", "0.124"]], "a": [["71240.10", "0.006"], ["71241.10", "0.634"], ["71243.90", "0.006"], ["71244.80", "0.007"], ["71251.50", "0.500"], ["71261.60", "0.079"], ["71274.60", "0.012"], ["71275.00", "0.048"], ["71277.00", "7.834"], ["71277.10", "0.326"], ["71311.40", "0.006"], ["71313.60", "0.058"], ["71399.00", "4.270"], ["71423.00", "1.422"], ["71451.50", "0.006"], ["71936.40", "0.147"], ["71936.50", "2.351"], ["75970.10", "0.002"]]}}
