{"local_ts": 1773384634696, "server_ts": 1773384634476, "data": {"e": "depthUpdate", "E": 1773384634477, "T": 1773384634476, "s": "BTCUSDT", "U": 10101349055317, "u": 10101349064830, "pu": 10101349055021, "b": [["5000.00", "101.418"], ["20721.90", "0.018"], ["20819.00", "0.135"], ["20926.50", "0.666"], ["21019.00", "0.126"], ["21119.00", "0.126"], ["21126.50", "1.332"], ["56978.00", "0.000"], ["67637.00", "0.002"], ["69794.70", "0.006"], ["69801.40", "0.013"], ["70506.80", "0.000"], ["71000.10", "11.757"], ["71011.30", "0.005"], ["71041.00", "0.000"], ["71071.20", "0.000"], ["71077.30", "0.002"], ["71096.50", "0.001"], ["71118.10", "0.042"], ["71120.70", "6.473"], ["71121.10", "0.082"], ["71130.20", "0.042"], ["71140.70", "0.005"], ["71152.80", "0.002"], ["71154.90", "0.003"], ["71159.10", "3.685"], ["71169.90", "0.009"], ["71170.80", "0.010"], ["71171.10", "0.080"], ["71171.80", "0.830"], ["71172.20", "0.205"], ["71173.20", "0.009"], ["71173.40", "0.005"], ["71173.70", "0.040"], ["71178.40", "0.064"], ["71182.20", "0.763"], ["71182.90", "1.947"], ["71183.40", "1.055"], ["71183.50", "0.341"], ["71185.60", "0.051"], ["71186.30", "1.019"], ["71186.40", "0.279"], ["71188.40", "0.531"], ["71193.70", "0.016"], ["71197.20", "0.003"], ["71198.40", "0.632"], ["71198.80", "0.035"], ["71199.40", "0.649"], ["71200.40", "0.002"], ["71200.90", "0.001"], ["71205.70", "0.346"], ["71206.60", "0.008"], ["71207.30", "0.339"], ["71210.70", "0.710"], ["71211.00", "0.005"], ["71211.90", "0.704"], ["71212.30", "0.003"], ["71214.40", "0.233"], ["71214.50", "0.284"], ["71216.60", "0.049"], ["71217.30", "0.023"], ["71218.00", "0.013"], ["71218.60", "0.001"], ["71218.70", "0.002"], ["71218.80", "0.000"], ["71219.00", "1.481"]], "a": [["71219.10", "8.757"], ["71219.20", "0.001"], ["71220.20", "1.205"], ["71220.30", "0.044"], ["71220.40", "0.003"], ["71221.00", "0.000"], ["71221.90", "0.001"], ["71222.20", "0.007"], ["71224.00", "0.384"], ["71224.10", "0.650"], ["71224.30", "0.044"], ["71224.40", "0.000"], ["71225.00", "0.012"], ["71225.60", "0.002"], ["71226.20", "0.075"], ["71226.30", "0.004"], ["71228.50", "0.003"], ["71229.70", "0.009"], ["71230.00", "0.147"], ["71230.10", "0.088"], ["71231.90", "0.001"], ["71234.20", "0.000"], ["71235.70", "0.631"], ["71236.70", "0.001"], ["71238.70", "0.071"], ["71239.90", "0.004"], ["71241.60", "0.002"], ["71241.90", "0.003"], ["71243.40", "0.247"], ["71244.20", "0.005"], ["71244.60", "0.006"], ["71244.70", "0.002"], ["71245.30", "0.001"], ["71245.40", "0.002"], ["71248.80", "0.479"], ["71248.90", "0.010"], ["71249.50", "0.008"], ["71249.60", "0.000"], ["71250.20", "0.005"], ["71250.30", "0.006"], ["71250.90", "1.089"], ["71251.00", "0.004"], ["71254.70", "0.000"], ["71255.90", "0.057"], ["71257.00", "0.005"], ["71268.10", "0.007"], ["71269.10", "0.004"], ["71269.30", "0.717"], ["71277.50", "0.100"], ["71283.20", "0.003"], ["71290.00", "0.012"], ["71297.50", "0.082"], ["71346.50", "0.000"], ["71931.30", "0.000"], ["71938.90", "1.402"], ["76325.10", "0.002"], ["89523.20", "0.000"]]}}
{"local_ts": 1773384635714, "server_ts": 1773384635496, "data": {"e": "depthUpdate", "E": 1773384635497, "T": 1773384635496, "s": "BTCUSDT", "U": 10101349131071, "u": 10101349137569, "pu": 10101349131056, "b": [["1000.00", "27.492"], ["5000.00", "101.418"], ["20716.60", "0.072"], ["20719.00", "0.027"], ["20820.20", "0.000"], ["20821.20", "0.000"], ["20824.20", "0.000"], ["20916.60", "0.072"], ["20919.00", "0.027"], ["21016.60", "0.072"], ["21020.20", "0.009"], ["21021.20", "0.000"], ["21024.20", "0.000"], ["21120.20", "0.009"], ["21121.20", "0.000"], ["21124.20", "0.000"], ["56973.00", "0.000"], ["68566.90", "0.003"], ["68692.70", "0.000"], ["68744.60", "0.000"], ["68870.20", "0.000"], ["68922.20", "0.000"], ["69047.70", "0.000"], ["69790.80", "0.004"], ["69794.70", "0.015"], ["69815.70", "0.008"], ["69902.40", "1.179"], ["70504.40", "0.000"], ["70506.80", "1.416"], ["70923.40", "0.295"], ["70957.10", "0.017"], ["70978.10", "0.001"], ["71101.80", "0.268"], ["71105.50", "0.128"], ["71106.50", "1.055"], ["71107.70", "0.003"], ["71108.70", "0.003"], ["71114.20", "0.092"], ["71116.60", "0.125"], ["71122.10", "0.092"], ["71126.00", "0.743"], ["71127.40", "0.000"], ["71143.00", "0.328"], ["71145.50", "0.023"], ["71147.50", "0.309"], ["71152.30", "0.623"], ["71152.50", "0.002"], ["71155.10", "0.000"], ["71156.60", "1.202"], ["71159.00", "0.023"], ["71159.40", "0.073"], ["71167.80", "0.004"], ["71170.10", "0.020"], ["71170.20", "0.303"], ["71170.40", "0.006"], ["71170.50", "1.490"], ["71170.80", "0.013"], ["71172.20", "0.021"], ["71172.30", "0.018"], ["71172.40", "0.453"], ["71172.70", "0.206"], ["71174.80", "0.015"], ["71175.90", "0.054"], ["71176.20", "0.272"], ["71178.40", "0.013"], ["71178.90", "0.008"], ["71179.30", "0.002"], ["71182.90", "0.024"], ["71184.20", "0.002"], ["71184.60", "0.141"], ["71185.50", "0.002"], ["71185.70", "0.007"], ["71186.40", "0.034"], ["71187.30", "0.350"], ["71187.50", "0.008"], ["71187.80", "0.249"], ["71189.10", "0.000"], ["71189.50", "0.072"], ["71189.60", "0.022"], ["71190.30", "0.281"], ["71191.70", "0.000"], ["71192.30", "0.004"], ["71193.20", "0.083"], ["71193.70", "0.072"], ["71195.30", "0.001"], ["71195.60", "0.007"], ["71196.00", "1.053"], ["71196.20", "0.025"], ["71196.30", "0.136"], ["71196.50", "1.196"], ["71196.70", "0.007"], ["71196.80", "0.072"], ["71196.90", "1.343"], ["71197.10", "0.001"], ["71197.60", "0.003"], ["71198.00", "0.002"], ["71198.60", "0.343"], ["71198.90", "0.004"], ["71199.60", "0.636"], ["71199.70", "0.578"], ["71199.80", "0.146"], ["71200.40", "0.000"], ["71200.80", "0.033"], ["71201.70", "0.006"], ["71201.90", "0.053"], ["71202.30", "0.285"], ["71202.40", "0.077"], ["71202.80", "0.002"], ["71203.70", "0.007"], ["71204.10", "0.044"], ["71204.50", "0.004"], ["71205.00", "0.320"], ["71205.60", "0.007"], ["71205.70", "0.304"], ["71206.90", "0.002"], ["71207.50", "0.020"], ["71207.60", "0.289"], ["71209.00", "0.000"], ["71209.50", "0.569"], ["71209.60", "0.288"], ["71209.80", "0.311"], ["71210.60", "0.284"], ["71210.90", "0.008"], ["71211.00", "0.005"], ["71211.40", "0.035"], ["71211.50", "0.211"], ["71211.80", "0.003"], ["71211.90", "0.000"], ["71212.00", "1.128"], ["71212.30", "0.003"], ["71213.10", "0.020"], ["71214.00", "0.010"], ["71214.10", "0.006"], ["71214.80", "0.009"], ["71215.50", "0.002"], ["71215.90", "0.003"], ["71216.00", "0.002"], ["71216.10", "0.071"], ["71216.40", "0.004"], ["71216.50", "0.001"], ["71216.60", "3.098"], ["71216.70", "0.000"], ["71216.90", "0.000"], ["71217.00", "0.000"], ["71217.30", "0.000"], ["71217.40", "0.000"], ["71217.50", "0.000"], ["71217.60", "0.000"], ["71217.70", "0.000"], ["71217.80", "0.000"], ["71217.90", "0.000"], ["71218.00", "0.000"], ["71218.10", "0.000"], ["71218.20", "0.000"], ["71218.30", "0.000"], ["71218.40", "0.000"], ["71218.50", "0.000"], ["71218.60", "0.000"], ["71218.70", "0.000"], ["71218.80", "0.000"], ["71218.90", "0.000"], ["71219.00", "0.000"]], "a": [["71216.70", "5.768"], ["71216.80", "0.001"], ["71217.00", "0.000"], ["71217.30", "0.000"], ["71217.40", "0.000"], ["71217.80", "0.002"], ["71217.90", "0.000"], ["71218.00", "0.000"], ["71218.10", "0.001"], ["71218.20", "0.002"], ["71218.30", "0.000"], ["71218.40", "0.002"], ["71218.50", "0.003"], ["71218.60", "0.000"], ["71218.70", "0.000"], ["71218.80", "0.001"], ["71218.90", "0.002"], ["71219.00", "1.107"], ["71219.10", "0.116"], ["71219.20", "0.004"], ["71220.10", "0.000"], ["71220.20", "1.105"], ["71220.90", "0.004"], ["71221.10", "0.000"], ["71221.90", "0.000"], ["71222.00", "0.005"], ["71224.00", "0.145"], ["71224.10", "0.005"], ["71224.20", "0.005"], ["71224.50", "0.001"], ["71224.70", "0.015"], ["71225.20", "0.005"], ["71226.20", "0.077"], ["71227.30", "0.071"], ["71228.20", "0.004"], ["71230.10", "0.088"], ["71230.30", "0.005"], ["71230.60", "0.002"], ["71231.80", "0.083"], ["71231.90", "0.001"], ["71232.00", "0.008"], ["71232.30", "0.030"], ["71232.50", "0.004"], ["71232.60", "0.007"], ["71232.70", "0.002"], ["71233.00", "0.005"], ["71233.20", "0.003"], ["71233.50", "0.650"], ["71234.10", "0.006"], ["71234.40", "0.015"], ["71234.50", "0.006"], ["71234.70", "0.065"], ["71234.80", "0.002"], ["71234.90", "0.003"], ["71235.00", "0.058"], ["71235.10", "0.073"], ["71235.20", "0.506"], ["71235.30", "0.001"], ["71235.50", "0.056"], ["71235.90", "0.000"], ["71236.30", "0.004"], ["71236.40", "0.000"], ["71236.60", "0.646"], ["71236.70", "0.001"], ["71236.90", "0.001"], ["71238.10", "0.852"], ["71238.20", "0.005"], ["71238.40", "0.000"], ["71238.50", "0.000"], ["71238.70", "0.001"], ["71238.80", "0.006"], ["71240.10", "0.081"], ["71240.20", "0.008"], ["71240.30", "0.206"], ["71240.40", "1.006"], ["71240.50", "0.016"], ["71240.70", "0.070"], ["71241.20", "0.024"], ["71241.50", "0.077"], ["71241.60", "0.101"], ["71242.40", "0.006"], ["71243.20", "0.015"], ["71243.50", "1.056"], ["71246.90", "0.000"], ["71247.20", "0.296"], ["71247.70", "0.007"], ["71248.40", "0.115"], ["71248.70", "0.302"], ["71250.00", "3.289"], ["71250.20", "0.019"], ["71251.10", "0.107"], ["71252.60", "0.002"], ["71253.70", "0.281"], ["71254.00", "0.004"], ["71255.60", "0.755"], ["71255.80", "1.116"], ["71255.90", "0.057"], ["71256.10", "0.676"], ["71257.20", "0.282"], ["71257.50", "0.002"], ["71257.70", "0.004"], ["71258.20", "0.130"], ["71258.40", "1.046"], ["71259.50", "0.861"], ["71260.20", "0.002"], ["71260.80", "0.144"], ["71261.20", "0.999"], ["71261.90", "1.902"], ["71264.00", "0.064"], ["71265.70", "0.002"], ["71266.40", "0.151"], ["71267.10", "0.051"], ["71267.80", "0.004"], ["71267.90", "0.343"], ["71268.00", "0.006"], ["71270.00", "0.105"], ["71272.00", "0.298"], ["71273.90", "0.000"], ["71275.40", "0.305"], ["71277.50", "0.000"], ["71283.90", "0.000"], ["71287.70", "0.724"], ["71290.80", "0.002"], ["71306.40", "0.066"], ["71311.20", "0.002"], ["71315.20", "0.225"], ["71316.50", "0.000"], ["71337.90", "0.000"], ["71341.20", "0.506"], ["71341.30", "2.653"], ["71341.80", "0.000"], ["71342.40", "0.006"], ["71382.90", "0.055"], ["71384.10", "0.039"], ["71398.30", "0.159"], ["71400.70", "0.000"], ["71401.90", "0.159"], ["71424.90", "0.004"], ["71460.50", "0.002"], ["71522.40", "0.614"], ["71928.90", "0.010"], ["71931.30", "0.000"], ["72201.10", "0.004"], ["72219.10", "0.018"], ["72224.30", "0.006"], ["72225.10", "0.057"], ["74801.00", "0.054"], ["89523.20", "0.000"], ["100000.00", "15.858"]]}}
{"local_ts": 1773384636750, "server_ts": 1773384636524, "data": {"e": "depthUpdate", "E": 1773384636525, "T": 1773384636524, "s": "BTCUSDT", "U": 10101349185515, "u": 10101349231162, "pu": 10101349185319, "b": [["5000.00", "101.418"], ["20716.60", "0.810"], ["20718.90", "0.009"], ["20720.20", "0.009"], ["20819.00", "0.045"], ["20916.60", "1.395"], ["20916.80", "0.009"], ["20917.70", "0.009"], ["20919.30", "0.009"], ["20920.20", "0.009"], ["20921.40", "0.018"], ["21019.00", "0.099"], ["33000.00", "9.339"], ["35583.50", "0.000"], ["35610.10", "0.018"], ["56973.00", "0.000"], ["64097.60", "0.002"], ["64101.10", "0.000"], ["67645.20", "0.002"], ["68368.00", "0.112"], ["69790.80", "0.002"], ["70194.50", "0.000"], ["70205.60", "0.014"], ["70213.90", "0.002"], ["70214.10", "0.000"], ["70217.70", "0.004"], ["70217.90", "0.000"], ["70218.40", "0.855"], ["70218.90", "7.172"], ["70219.30", "0.004"], ["70219.80", "0.002"], ["70220.20", "0.010"], ["70222.00", "2.929"], ["70222.10", "0.004"], ["70504.40", "0.000"], ["70505.50", "0.158"], ["70507.60", "1.123"], ["70509.40", "3.020"], ["70860.50", "0.000"], ["71091.20", "0.152"], ["71097.10", "0.000"], ["71101.80", "0.266"], ["71102.70", "0.041"], ["71105.10", "0.077"], ["71105.40", "0.498"], ["71126.00", "0.741"], ["71128.20", "1.088"], ["71130.40", "0.018"], ["71132.60", "0.002"], ["71136.20", "0.004"], ["71145.40", "1.068"], ["71145.70", "0.107"], ["71154.30", "0.020"], ["71156.30", "0.078"], ["71159.50", "0.949"], ["71159.80", "0.004"], ["71161.00", "2.791"], ["71162.20", "0.000"], ["71165.00", "0.079"], ["71167.40", "0.059"], ["71169.30", "0.316"], ["71169.40", "0.861"], ["71170.00", "0.312"], ["71170.10", "0.020"], ["71170.30", "0.008"], ["71171.00", "0.050"], ["71171.50", "0.062"], ["71172.70", "0.204"], ["71172.90", "0.005"], ["71173.10", "0.501"], ["71173.20", "0.009"], ["71173.40", "0.005"], ["71173.80", "0.262"], ["71175.60", "0.185"], ["71176.20", "0.258"], ["71176.60", "0.106"], ["71176.70", "0.132"], ["71177.80", "0.029"], ["71180.70", "0.006"], ["71180.80", "0.011"], ["71180.90", "0.009"], ["71181.00", "0.007"], ["71181.10", "0.003"], ["71181.60", "0.001"], ["71183.40", "1.081"], ["71184.90", "0.083"], ["71186.40", "0.005"], ["71187.00", "0.005"], ["71188.70", "0.009"], ["71189.20", "0.001"], ["71189.30", "0.000"], ["71189.60", "0.020"], ["71189.90", "0.012"], ["71190.00", "0.037"], ["71190.40", "0.003"], ["71190.60", "0.030"], ["71190.70", "0.000"], ["71190.80", "0.064"], ["71191.30", "1.506"], ["71191.40", "0.004"], ["71191.80", "1.200"], ["71192.80", "0.020"], ["71193.20", "0.011"], ["71194.00", "0.005"], ["71194.40", "0.041"], ["71194.50", "0.004"], ["71194.80", "0.001"], ["71194.90", "0.302"], ["71195.80", "0.000"], ["71195.90", "0.903"], ["71196.20", "0.011"], ["71196.30", "0.000"], ["71196.40", "0.002"], ["71196.70", "0.005"], ["71197.50", "0.072"], ["71197.60", "0.001"], ["71197.80", "0.000"], ["71197.90", "0.003"], ["71198.40", "0.001"], ["71198.60", "0.251"], ["71198.80", "0.042"], ["71199.20", "0.004"], ["71199.40", "0.028"], ["71199.50", "0.116"], ["71199.80", "0.087"], ["71200.00", "0.008"], ["71200.10", "0.005"], ["71200.20", "0.002"], ["71200.30", "0.001"], ["71200.70", "0.002"], ["71200.80", "0.033"], ["71201.20", "0.033"], ["71201.60", "0.000"], ["71201.90", "0.051"], ["71202.00", "0.520"], ["71202.20", "0.073"], ["71202.30", "0.163"], ["71202.40", "0.082"], ["71202.50", "0.000"], ["71202.70", "0.000"], ["71202.80", "0.002"], ["71203.80", "0.006"], ["71204.10", "0.046"], ["71204.20", "0.846"], ["71204.30", "0.644"], ["71204.40", "0.142"], ["71204.50", "0.011"], ["71204.60", "0.000"], ["71204.80", "0.004"], ["71204.90", "0.000"], ["71205.20", "0.008"], ["71205.30", "0.001"], ["71205.40", "0.003"], ["71205.50", "0.009"], ["71205.60", "0.007"], ["71205.70", "0.306"], ["71205.80", "0.003"], ["71205.90", "0.004"], ["71206.20", "0.344"], ["71206.40", "0.034"], ["71206.50", "0.000"], ["71206.60", "0.005"], ["71206.80", "0.506"], ["71207.10", "0.045"], ["71207.20", "0.000"], ["71207.30", "0.012"], ["71207.40", "0.035"], ["71207.60", "0.361"], ["71207.70", "1.194"], ["71207.80", "0.000"], ["71207.90", "0.000"], ["71208.10", "0.028"], ["71208.30", "0.006"], ["71208.50", "0.000"], ["71208.60", "0.026"], ["71208.70", "0.049"], ["71208.90", "0.217"], ["71209.10", "0.070"], ["71209.20", "0.136"], ["71209.30", "0.305"], ["71209.50", "0.569"], ["71209.60", "0.006"], ["71209.80", "0.000"], ["71209.90", "0.062"], ["71210.00", "0.286"], ["71210.10", "0.634"], ["71210.30", "0.208"], ["71210.40", "0.049"], ["71210.50", "0.472"], ["71210.60", "0.002"], ["71210.70", "0.113"], ["71210.80", "0.007"], ["71211.30", "0.006"], ["71211.40", "0.056"], ["71211.50", "0.506"], ["71211.80", "0.042"], ["71211.90", "0.067"], ["71212.00", "0.846"], ["71212.10", "0.163"], ["71212.20", "0.018"], ["71212.30", "0.107"], ["71212.40", "0.039"], ["71212.50", "0.012"], ["71212.70", "0.035"], ["71212.80", "0.038"], ["71212.90", "0.017"], ["71213.50", "0.105"], ["71213.80", "0.030"], ["71214.00", "0.012"], ["71214.30", "0.004"], ["71214.40", "0.042"], ["71214.50", "0.002"], ["71214.60", "0.386"], ["71215.30", "0.002"], ["71216.10", "0.002"], ["71216.20", "0.004"], ["71216.30", "0.001"], ["71216.50", "0.007"], ["71216.60", "0.542"], ["71216.70", "1.525"], ["71216.80", "0.060"], ["71216.90", "0.002"], ["71217.00", "0.002"], ["71217.10", "0.103"], ["71217.20", "0.001"], ["71217.50", "0.002"], ["71217.60", "0.002"], ["71217.70", "2.143"], ["71217.80", "1.102"], ["71217.90", "0.003"], ["71218.00", "0.097"], ["71218.10", "0.137"], ["71218.20", "3.692"], ["71218.30", "0.000"], ["71218.40", "0.112"], ["71218.50", "0.000"], ["71218.70", "0.013"], ["71218.80", "0.003"], ["71218.90", "0.168"], ["71219.00", "0.002"], ["71219.10", "0.007"], ["71219.20", "0.002"], ["71219.30", "0.426"], ["71219.40", "0.186"], ["71219.50", "0.000"], ["71219.80", "0.221"], ["71219.90", "0.713"], ["71220.10", "0.000"], ["71220.20", "1.154"], ["71220.30", "1.291"], ["71220.40", "0.000"], ["71220.50", "8.021"], ["71220.60", "0.002"], ["71220.80", "0.372"], ["71221.00", "0.233"], ["71221.10", "1.923"], ["71221.20", "0.138"], ["71221.30", "0.138"], ["71221.40", "6.796"], ["71221.50", "2.014"], ["71221.60", "3.785"], ["71221.70", "0.021"], ["71221.90", "4.973"], ["71222.20", "1.699"], ["71222.30", "0.283"], ["71222.40", "0.510"], ["71222.60", "7.954"]], "a": [["71216.70", "0.000"], ["71217.80", "0.000"], ["71218.10", "0.000"], ["71218.20", "0.000"], ["71218.40", "0.000"], ["71218.50", "0.000"], ["71218.80", "0.000"], ["71219.00", "0.000"], ["71219.10", "0.000"], ["71219.20", "0.000"], ["71219.40", "0.000"], ["71219.90", "0.000"], ["71220.00", "0.000"], ["71220.20", "0.000"], ["71220.30", "0.000"], ["71220.40", "0.000"], ["71220.60", "0.000"], ["71220.90", "0.000"], ["71221.10", "0.000"], ["71221.20", "0.000"], ["71221.30", "0.000"], ["71221.40", "0.000"], ["71221.50", "0.000"], ["71221.70", "0.000"], ["71222.00", "0.000"], ["71222.30", "0.000"], ["71222.40", "0.000"], ["71222.50", "0.000"], ["71222.60", "0.000"], ["71222.70", "0.005"], ["71222.80", "0.010"], ["71222.90", "0.000"], ["71223.40", "0.001"], ["71223.60", "0.000"], ["71223.80", "0.001"], ["71224.00", "0.002"], ["71224.10", "0.003"], ["71224.20", "0.002"], ["71224.30", "0.008"], ["71224.50", "0.000"], ["71224.70", "0.000"], ["71224.80", "0.004"], ["71225.00", "0.006"], ["71225.20", "0.003"], ["71226.00", "0.007"], ["71226.20", "0.001"], ["71226.40", "0.021"], ["71226.50", "0.001"], ["71226.80", "0.005"], ["71227.10", "0.015"], ["71227.20", "0.058"], ["71227.30", "0.068"], ["71227.40", "0.000"], ["71227.80", "0.473"], ["71228.00", "0.012"], ["71228.20", "0.043"], ["71229.20", "0.004"], ["71229.30", "0.011"], ["71230.00", "0.007"], ["71230.10", "0.002"], ["71230.20", "0.001"], ["71230.30", "0.005"], ["71230.40", "0.072"], ["71230.50", "0.002"], ["71230.70", "0.084"], ["71230.90", "0.000"], ["71231.30", "0.003"], ["71231.40", "0.004"], ["71231.70", "0.003"], ["71231.80", "0.118"], ["71232.00", "0.008"], ["71232.10", "0.003"], ["71232.30", "0.027"], ["71232.40", "0.000"], ["71232.50", "0.134"], ["71232.90", "0.000"], ["71233.30", "0.000"], ["71233.40", "0.007"], ["71233.50", "0.003"], ["71233.60", "0.001"], ["71233.70", "0.017"], ["71233.80", "0.289"], ["71234.40", "0.010"], ["71234.60", "0.000"], ["71234.90", "0.153"], ["71235.10", "0.001"], ["71235.20", "0.000"], ["71235.40", "0.000"], ["71235.50", "0.159"], ["71236.60", "0.000"], ["71237.10", "0.000"], ["71237.20", "0.001"], ["71237.30", "0.010"], ["71237.40", "0.004"], ["71237.50", "0.004"], ["71237.80", "0.000"], ["71237.90", "0.001"], ["71238.10", "0.006"], ["71238.60", "0.038"], ["71238.90", "0.656"], ["71239.00", "0.010"], ["71239.10", "0.012"], ["71240.10", "0.002"], ["71240.20", "0.141"], ["71240.40", "0.009"], ["71240.50", "0.001"], ["71240.60", "0.281"], ["71240.70", "0.000"], ["71241.00", "0.002"], ["71241.10", "0.003"], ["71241.60", "0.002"], ["71241.90", "0.006"], ["71242.00", "0.002"], ["71242.10", "0.003"], ["71242.50", "0.134"], ["71242.60", "0.006"], ["71243.10", "0.030"], ["71243.30", "0.072"], ["71243.40", "0.002"], ["71243.50", "0.007"], ["71243.60", "0.565"], ["71243.70", "0.024"], ["71244.00", "0.002"], ["71244.10", "0.021"], ["71244.20", "0.005"], ["71244.30", "0.000"], ["71244.40", "0.517"], ["71244.60", "0.004"], ["71244.70", "0.000"], ["71245.00", "0.007"], ["71245.20", "0.145"], ["71245.30", "0.003"], ["71245.40", "0.004"], ["71245.70", "0.007"], ["71245.80", "0.002"], ["71245.90", "0.002"], ["71246.00", "0.009"], ["71246.50", "0.342"], ["71246.60", "0.012"], ["71246.90", "0.070"], ["71247.00", "0.257"], ["71247.10", "0.636"], ["71247.60", "0.101"], ["71247.90", "0.263"], ["71248.00", "0.148"], ["71248.10", "0.002"], ["71248.20", "0.017"], ["71248.40", "0.115"], ["71248.60", "0.339"], ["71248.70", "0.302"], ["71248.80", "0.348"], ["71248.90", "0.523"], ["71249.10", "0.004"], ["71249.50", "0.008"], ["71249.60", "0.000"], ["71249.90", "0.378"], ["71250.00", "3.291"], ["71250.10", "0.004"], ["71250.20", "0.019"], ["71250.30", "0.006"], ["71250.50", "0.005"], ["71250.80", "1.061"], ["71250.90", "0.035"], ["71251.10", "0.105"], ["71251.50", "0.592"], ["71252.20", "0.310"], ["71253.50", "0.506"], ["71253.70", "0.246"], ["71254.50", "0.130"], ["71255.20", "0.101"], ["71255.30", "0.048"], ["71255.50", "0.173"], ["71255.70", "0.618"], ["71255.80", "0.960"], ["71256.50", "0.509"], ["71257.20", "0.002"], ["71257.50", "0.004"], ["71257.90", "0.000"], ["71258.40", "0.766"], ["71259.10", "0.034"], ["71259.20", "0.552"], ["71259.50", "0.021"], ["71259.90", "0.067"], ["71260.10", "0.003"], ["71260.40", "0.000"], ["71260.50", "0.123"], ["71260.70", "1.074"], ["71260.80", "0.353"], ["71261.10", "0.209"], ["71261.50", "0.000"], ["71261.90", "0.009"], ["71262.00", "0.004"], ["71262.80", "0.004"], ["71263.20", "8.024"], ["71263.30", "0.301"], ["71264.00", "0.060"], ["71264.30", "0.038"], ["71264.40", "1.348"], ["71266.50", "0.002"], ["71266.60", "0.095"], ["71266.80", "0.019"], ["71266.90", "0.008"], ["71267.20", "0.018"], ["71267.70", "0.004"], ["71268.40", "0.019"], ["71271.20", "0.008"], ["71271.60", "0.052"], ["71271.80", "0.055"], ["71272.50", "0.004"], ["71273.20", "0.924"], ["71275.20", "0.004"], ["71275.70", "0.220"], ["71276.00", "0.000"], ["71276.90", "0.509"], ["71278.60", "1.349"], ["71279.20", "0.284"], ["71280.00", "0.230"], ["71280.80", "0.072"], ["71284.40", "0.172"], ["71284.80", "0.812"], ["71285.70", "0.319"], ["71287.70", "0.721"], ["71290.80", "0.005"], ["71293.90", "0.005"], ["71294.80", "0.472"], ["71295.50", "0.000"], ["71297.80", "0.013"], ["71300.40", "0.045"], ["71303.70", "0.324"], ["71304.50", "6.457"], ["71337.90", "0.002"], ["71340.00", "0.188"], ["71341.30", "1.028"], ["71343.60", "0.031"], ["71370.00", "3.118"], ["71372.90", "10.509"], ["71377.40", "0.022"], ["71381.40", "0.000"], ["71383.40", "0.082"], ["71401.30", "0.378"], ["71401.90", "0.060"], ["71402.50", "0.159"], ["71403.00", "0.452"], ["71403.90", "0.159"], ["71404.20", "17.000"], ["71406.20", "0.084"], ["71414.10", "0.911"], ["71414.80", "0.000"], ["71419.90", "10.000"], ["71426.40", "0.003"], ["71428.00", "0.004"], ["71429.90", "0.509"], ["71449.20", "1.966"], ["71451.30", "10.000"], ["71453.40", "0.000"], ["71456.40", "1.984"], ["71482.60", "1.676"], ["71482.70", "10.323"], ["71503.20", "0.482"], ["71503.50", "0.000"], ["71529.80", "10.000"], ["71572.80", "0.000"], ["71782.20", "0.002"], ["71928.90", "0.010"], ["71929.00", "0.074"], ["71930.00", "0.242"], ["71932.50", "0.004"], ["72134.20", "1.145"], ["72436.90", "0.715"], ["74788.30", "0.000"], ["89523.20", "0.000"]]}}
{"local_ts": 1773384637763, "server_ts": 1773384637544, "data": {"e": "depthUpdate", "E": 1773384637545, "T": 1773384637544, "s": "BTCUSDT", "U": 10101349383781, "u": 10101349398879, "pu": 10101349383723, "b": [["1000.00", "27.492"], ["5000.00", "101.418"], ["20716.60", "0.171"], ["20830.50", "0.207"], ["20833.30", "0.081"], ["20916.60", "0.585"], ["21130.50", "0.099"], ["21133.30", "0.045"], ["40000.00", "49.611"], ["56973.00", "0.000"], ["67666.10", "0.002"], ["69808.70", "0.075"], ["70221.60", "0.000"], ["70222.60", "0.078"], ["70225.90", "0.000"], ["70230.50", "0.018"], ["70518.20", "0.702"], ["70521.00", "0.006"], ["70584.50", "0.000"], ["70590.30", "0.016"], ["70761.00", "0.031"], ["70766.80", "0.010"], ["70867.50", "0.121"], ["70868.80", "0.000"], ["70900.10", "4.833"], ["70913.80", "0.061"], ["70920.00", "1.018"], ["70927.10", "0.308"], ["70937.90", "1.194"], ["70943.70", "0.308"], ["70969.40", "0.000"], ["71030.90", "2.307"], ["71032.90", "0.000"], ["71049.20", "0.006"], ["71056.20", "0.758"], ["71065.10", "0.011"], ["71071.00", "0.383"], ["71080.60", "0.315"], ["71085.70", "0.196"], ["71088.30", "0.100"], ["71090.10", "0.526"], ["71103.20", "0.041"], ["71103.40", "0.403"], ["71105.10", "2.077"], ["71112.30", "0.038"], ["71112.40", "0.510"], ["71115.20", "0.078"], ["71116.00", "0.016"], ["71116.80", "0.000"], ["71120.70", "6.459"], ["71121.10", "0.112"], ["71121.60", "0.254"], ["71131.00", "0.008"], ["71131.30", "0.000"], ["71132.70", "0.362"], ["71132.90", "6.630"], ["71133.20", "0.000"], ["71133.30", "0.053"], ["71133.60", "2.000"], ["71133.70", "0.050"], ["71135.00", "6.594"], ["71138.40", "0.003"], ["71138.70", "0.002"], ["71140.90", "0.100"], ["71142.10", "0.070"], ["71143.60", "0.290"], ["71145.30", "0.105"], ["71145.40", "0.690"], ["71145.50", "0.121"], ["71146.40", "0.303"], ["71147.80", "1.609"], ["71148.20", "0.016"], ["71149.20", "0.149"], ["71154.70", "0.079"], ["71159.00", "0.075"], ["71159.50", "0.001"], ["71159.90", "0.000"], ["71162.10", "1.107"], ["71162.20", "0.003"], ["71163.80", "0.061"], ["71166.30", "0.000"], ["71166.60", "0.026"], ["71166.80", "1.098"], ["71167.50", "0.003"], ["71168.20", "0.643"], ["71173.20", "0.040"], ["71173.40", "0.005"], ["71173.70", "0.183"], ["71173.80", "0.032"], ["71175.30", "0.513"], ["71176.10", "0.746"], ["71176.30", "0.207"], ["71176.80", "0.037"], ["71177.40", "1.998"], ["71178.10", "0.047"], ["71178.80", "0.424"], ["71180.10", "0.000"], ["71180.30", "0.026"], ["71180.40", "1.226"], ["71180.70", "0.008"], ["71180.80", "0.192"], ["71181.20", "0.002"], ["71181.30", "0.005"], ["71182.20", "0.810"], ["71182.90", "0.002"], ["71183.00", "0.508"], ["71183.10", "0.011"], ["71183.40", "1.178"], ["71185.20", "0.036"], ["71185.40", "0.004"], ["71185.50", "0.014"], ["71186.80", "0.020"], ["71189.20", "0.001"], ["71189.50", "0.002"], ["71189.60", "0.000"], ["71190.00", "0.024"], ["71190.30", "0.394"], ["71190.60", "0.053"], ["71191.00", "0.486"], ["71191.60", "0.187"], ["71192.00", "0.026"], ["71192.10", "0.000"], ["71192.30", "0.003"], ["71192.50", "0.002"], ["71192.70", "0.003"], ["71192.80", "0.002"], ["71192.90", "0.037"], ["71193.00", "0.004"], ["71193.60", "0.020"], ["71193.90", "0.034"], ["71194.40", "0.000"], ["71195.00", "0.000"], ["71195.20", "0.010"], ["71195.80", "0.000"], ["71196.20", "0.004"], ["71197.30", "0.002"], ["71197.60", "0.005"], ["71197.70", "0.342"], ["71198.00", "0.004"], ["71198.30", "0.211"], ["71198.40", "0.002"], ["71198.60", "0.057"], ["71199.80", "0.028"], ["71200.70", "0.002"], ["71201.20", "0.002"], ["71201.50", "0.031"], ["71201.90", "0.057"], ["71202.20", "0.002"], ["71202.40", "0.006"], ["71202.50", "0.000"], ["71202.80", "0.004"], ["71203.70", "0.005"], ["71204.00", "0.050"], ["71204.40", "0.245"], ["71205.30", "0.000"], ["71205.40", "0.003"], ["71205.50", "0.008"], ["71205.80", "0.000"], ["71206.90", "0.001"], ["71207.30", "0.003"], ["71207.40", "0.037"], ["71207.70", "0.000"], ["71208.10", "0.078"], ["71208.70", "0.002"], ["71208.80", "0.048"], ["71209.10", "0.000"], ["71209.20", "0.003"], ["71209.30", "0.375"], ["71210.20", "0.010"], ["71210.30", "0.280"], ["71210.40", "0.037"], ["71211.00", "0.004"], ["71211.30", "0.006"], ["71211.90", "0.002"], ["71212.10", "0.011"], ["71212.20", "0.009"], ["71212.30", "0.003"], ["71212.40", "0.004"], ["71212.70", "0.075"], ["71213.00", "0.303"], ["71213.70", "0.070"], ["71213.80", "1.195"], ["71214.40", "0.074"], ["71214.60", "0.004"], ["71215.00", "0.076"], ["71215.10", "0.008"], ["71215.30", "0.003"], ["71215.50", "0.013"], ["71216.10", "0.030"], ["71216.40", "0.008"], ["71216.80", "0.046"], ["71216.90", "0.131"], ["71217.40", "0.000"], ["71217.50", "0.002"], ["71217.80", "0.217"], ["71217.90", "0.001"], ["71218.40", "0.258"], ["71218.50", "0.031"], ["71218.70", "0.004"], ["71218.80", "0.009"], ["71218.90", "0.032"], ["71219.00", "0.002"], ["71219.10", "0.000"], ["71219.80", "0.005"], ["71219.90", "0.006"], ["71220.00", "0.006"], ["71220.10", "0.007"], ["71220.20", "0.839"], ["71220.30", "0.006"], ["71220.50", "0.018"], ["71220.70", "0.032"], ["71220.80", "0.013"], ["71221.00", "0.000"], ["71221.10", "0.005"], ["71221.30", "0.030"], ["71221.40", "0.078"], ["71221.50", "0.004"], ["71221.80", "0.001"], ["71222.00", "0.636"], ["71222.10", "0.000"], ["71222.20", "0.185"], ["71222.30", "0.003"], ["71222.50", "0.277"], ["71222.60", "0.044"], ["71222.70", "1.103"], ["71223.10", "0.000"], ["71223.40", "0.007"], ["71223.60", "0.003"], ["71223.80", "0.001"], ["71224.20", "0.003"], ["71224.30", "0.000"], ["71224.40", "0.007"], ["71225.20", "0.004"], ["71225.40", "0.007"], ["71225.50", "0.020"], ["71225.80", "0.002"], ["71225.90", "0.001"], ["71226.00", "0.515"], ["71226.40", "0.312"], ["71226.50", "0.000"], ["71226.90", "0.211"], ["71227.20", "0.004"], ["71227.40", "0.003"], ["71227.80", "0.003"], ["71228.50", "0.001"], ["71228.60", "0.000"], ["71228.70", "0.508"], ["71229.40", "0.004"], ["71229.50", "0.004"], ["71229.70", "0.065"], ["71229.80", "0.001"], ["71229.90", "0.021"], ["71230.00", "0.004"], ["71230.20", "0.003"], ["71230.40", "0.002"], ["71230.50", "0.152"], ["71230.60", "0.056"], ["71230.70", "0.000"], ["71230.80", "0.000"], ["71230.90", "0.004"], ["71231.10", "0.000"], ["71231.20", "0.001"], ["71231.50", "0.002"], ["71231.60", "0.006"], ["71231.70", "0.002"], ["71231.80", "0.002"], ["71231.90", "0.001"], ["71232.00", "0.002"], ["71232.10", "0.000"], ["71232.20", "0.000"], ["71232.30", "0.001"], ["71232.60", "0.002"], ["71233.00", "0.000"], ["71233.10", "0.000"], ["71233.20", "0.002"], ["71233.30", "9.135"]], "a": [["71230.60", "0.000"], ["71230.70", "0.000"], ["71230.80", "0.000"], ["71230.90", "0.000"], ["71231.20", "0.000"], ["71231.30", "0.000"], ["71231.40", "0.000"], ["71231.70", "0.000"], ["71231.80", "0.000"], ["71231.90", "0.000"], ["71232.00", "0.000"], ["71232.10", "0.000"], ["71232.20", "0.000"], ["71232.30", "0.000"], ["71232.50", "0.000"], ["71232.80", "0.000"], ["71233.00", "0.000"], ["71233.10", "0.000"], ["71233.20", "0.000"], ["71233.40", "1.122"], ["71233.50", "0.001"], ["71233.70", "0.002"], ["71233.80", "0.280"], ["71234.10", "0.001"], ["71234.30", "0.000"], ["71234.40", "0.004"], ["71234.90", "0.003"], ["71235.30", "0.001"], ["71235.60", "0.003"], ["71235.70", "0.000"], ["71235.80", "0.003"], ["71236.00", "0.004"], ["71236.40", "0.003"], ["71236.70", "0.001"], ["71236.80", "0.002"], ["71236.90", "0.010"], ["71237.40", "0.002"], ["71237.70", "0.002"], ["71238.10", "0.036"], ["71238.30", "0.056"], ["71238.60", "0.005"], ["71238.70", "0.002"], ["71238.90", "0.072"], ["71239.00", "0.007"], ["71239.10", "0.126"], ["71239.20", "0.001"], ["71239.30", "0.061"], ["71239.40", "0.002"], ["71240.30", "0.074"], ["71240.60", "0.004"], ["71240.70", "0.007"], ["71240.80", "0.002"], ["71241.20", "0.050"], ["71241.30", "0.017"], ["71242.50", "0.007"], ["71242.60", "0.006"], ["71243.20", "0.000"], ["71243.70", "0.006"], ["71243.90", "0.008"], ["71244.10", "0.006"], ["71244.30", "0.856"], ["71244.50", "0.010"], ["71244.60", "0.001"], ["71244.80", "0.005"], ["71245.20", "0.014"], ["71246.40", "0.000"], ["71246.50", "0.000"], ["71246.60", "0.062"], ["71247.00", "0.029"], ["71247.50", "0.003"], ["71247.60", "0.002"], ["71247.80", "0.292"], ["71248.00", "0.157"], ["71248.20", "0.143"], ["71248.30", "0.073"], ["71248.40", "0.149"], ["71248.60", "0.003"], ["71249.10", "0.021"], ["71249.20", "0.002"], ["71249.40", "0.007"], ["71249.70", "0.034"], ["71249.80", "0.004"], ["71249.90", "0.046"], ["71250.10", "0.007"], ["71250.40", "0.000"], ["71250.90", "0.038"], ["71251.00", "0.013"], ["71251.10", "0.131"], ["71251.80", "0.018"], ["71252.20", "0.001"], ["71252.30", "0.017"], ["71252.40", "0.001"], ["71252.50", "0.000"], ["71252.90", "0.000"], ["71253.00", "0.006"], ["71253.10", "0.030"], ["71253.50", "0.000"], ["71253.70", "0.002"], ["71253.80", "0.270"], ["71253.90", "0.002"], ["71254.00", "0.003"], ["71254.10", "0.003"], ["71254.20", "0.087"], ["71254.70", "0.003"], ["71254.90", "0.149"], ["71255.00", "0.317"], ["71255.70", "0.389"], ["71256.10", "0.679"], ["71256.50", "0.076"], ["71256.60", "0.567"], ["71257.00", "0.003"], ["71257.20", "0.011"], ["71257.30", "0.009"], ["71257.50", "0.014"], ["71257.60", "0.006"], ["71257.80", "0.631"], ["71257.90", "0.000"], ["71258.00", "0.008"], ["71258.50", "0.017"], ["71258.60", "0.008"], ["71258.70", "0.277"], ["71259.20", "0.028"], ["71259.30", "0.000"], ["71259.70", "0.009"], ["71259.80", "0.005"], ["71259.90", "0.067"], ["71260.40", "0.004"], ["71260.80", "0.459"], ["71260.90", "0.850"], ["71261.10", "0.209"], ["71261.40", "0.038"], ["71261.60", "0.038"], ["71261.90", "0.245"], ["71262.60", "1.053"], ["71263.10", "0.003"], ["71263.20", "8.360"], ["71263.50", "0.081"], ["71263.60", "0.510"], ["71263.90", "0.004"], ["71264.30", "0.040"], ["71265.20", "0.002"], ["71265.70", "0.003"], ["71266.10", "0.009"], ["71266.50", "0.034"], ["71267.00", "0.005"], ["71267.70", "0.945"], ["71268.80", "0.003"], ["71268.90", "0.280"], ["71269.80", "0.053"], ["71270.30", "0.003"], ["71270.50", "0.452"], ["71270.60", "0.000"], ["71271.10", "0.000"], ["71271.20", "0.077"], ["71272.30", "0.006"], ["71272.40", "0.021"], ["71272.60", "1.064"], ["71273.40", "0.108"], ["71273.60", "0.072"], ["71274.00", "0.582"], ["71275.10", "0.283"], ["71275.20", "0.004"], ["71276.10", "0.002"], ["71276.20", "0.847"], ["71276.50", "0.007"], ["71277.10", "0.005"], ["71277.70", "0.104"], ["71278.30", "0.022"], ["71278.40", "0.299"], ["71278.60", "1.361"], ["71279.20", "0.300"], ["71279.90", "6.308"], ["71280.20", "0.032"], ["71280.60", "0.009"], ["71280.70", "0.315"], ["71281.30", "0.109"], ["71282.00", "0.003"], ["71282.30", "0.013"], ["71283.30", "0.005"], ["71287.70", "0.724"], ["71287.80", "0.002"], ["71288.60", "0.654"], ["71289.10", "0.227"], ["71289.20", "0.002"], ["71290.40", "0.002"], ["71291.70", "0.034"], ["71294.80", "0.469"], ["71294.90", "1.052"], ["71298.00", "1.106"], ["71299.10", "0.513"], ["71300.50", "0.006"], ["71302.00", "0.010"], ["71302.10", "0.195"], ["71302.30", "0.450"], ["71303.10", "0.045"], ["71303.60", "0.509"], ["71304.50", "0.003"], ["71304.60", "1.002"], ["71306.10", "0.000"], ["71306.90", "0.000"], ["71309.60", "0.000"], ["71311.60", "0.004"], ["71312.30", "0.006"], ["71313.30", "0.072"], ["71315.30", "0.139"], ["71316.30", "0.003"], ["71316.70", "0.729"], ["71318.70", "0.002"], ["71318.80", "6.441"], ["71318.90", "1.500"], ["71319.00", "0.510"], ["71320.40", "0.003"], ["71322.50", "0.000"], ["71325.80", "0.509"], ["71326.10", "0.017"], ["71328.00", "0.009"], ["71328.70", "0.003"], ["71329.30", "2.324"], ["71333.10", "8.440"], ["71334.00", "0.002"], ["71334.60", "0.002"], ["71336.30", "0.079"], ["71336.90", "0.002"], ["71338.70", "0.171"], ["71340.90", "0.002"], ["71341.20", "0.510"], ["71344.80", "0.000"], ["71345.20", "0.016"], ["71348.40", "0.003"], ["71349.50", "0.001"], ["71355.70", "0.150"], ["71361.60", "2.000"], ["71374.30", "0.000"], ["71386.10", "0.018"], ["71407.90", "0.492"], ["71411.50", "0.040"], ["71412.20", "0.002"], ["71415.00", "0.159"], ["71416.60", "0.327"], ["71431.50", "6.126"], ["71439.90", "0.003"], ["71443.40", "0.000"], ["71443.80", "7.166"], ["71444.00", "0.029"], ["71473.40", "0.624"], ["71476.70", "8.835"], ["71507.00", "0.306"], ["71512.90", "0.009"], ["71533.70", "0.302"], ["71617.40", "0.117"], ["71621.80", "0.002"], ["71685.80", "0.000"], ["71691.70", "0.039"], ["71865.00", "0.156"], ["71870.90", "0.016"], ["71921.50", "0.008"], ["71942.90", "0.000"], ["71945.70", "0.012"], ["72658.00", "0.219"], ["73025.00", "2.492"], ["76857.60", "0.000"], ["89523.20", "0.000"]]}}
{"local_ts": 1773384638779, "server_ts": 1773384638564, "data": {"e": "depthUpdate", "E": 1773384638565, "T": 1773384638564, "s": "BTCUSDT", "U": 10101349475467, "u": 10101349480857, "pu": 10101349475343, "b": [["1000.00", "27.492"], ["5000.00", "101.418"], ["20733.30", "0.945"], ["20827.80", "0.585"], ["20833.30", "0.108"], ["21033.30", "0.594"], ["21127.80", "0.243"], ["33000.00", "9.343"], ["56335.30", "0.000"], ["56987.00", "0.043"], ["67645.20", "0.000"], ["67655.70", "0.000"], ["67655.80", "0.002"], ["67671.00", "0.100"], ["70515.50", "0.708"], ["70521.00", "0.000"], ["70870.20", "0.035"], ["70877.10", "0.002"], ["70877.60", "0.002"], ["70920.00", "1.016"], ["70923.50", "0.006"], ["71097.40", "0.052"], ["71110.30", "0.329"], ["71138.20", "0.071"], ["71145.30", "0.272"], ["71152.40", "0.072"], ["71191.60", "0.187"], ["71205.30", "0.006"], ["71216.80", "0.013"], ["71217.50", "0.004"], ["71217.90", "0.506"], ["71218.90", "0.034"], ["71226.20", "0.062"], ["71226.50", "1.415"], ["71230.00", "0.004"]], "a": [["71233.40", "0.959"], ["71240.50", "0.029"], ["71271.80", "0.033"], ["71280.20", "0.083"], ["71281.10", "0.006"], ["71281.30", "0.111"], ["71307.50", "0.630"], ["71316.40", "0.070"], ["71323.50", "2.011"], ["71324.90", "0.105"], ["71341.30", "0.002"], ["71945.70", "0.704"], ["72226.70", "0.000"], ["72370.20", "0.006"]]}}
{"local_ts": 1773384639804, "server_ts": 1773384639588, "data": {"e": "depthUpdate", "E": 1773384639589, "T": 1773384639588, "s": "BTCUSDT", "U": 10101349542263, "u": 10101349548508, "pu": 10101349542232, "b": [["5000.00", "101.418"], ["20733.30", "1.116"], ["20933.30", "0.468"], ["21033.30", "0.432"], ["21133.30", "0.684"], ["56335.30", "0.002"], ["69808.70", "0.081"], ["70521.00", "0.000"], ["70921.90", "0.002"], ["70923.50", "0.004"], ["71093.00", "0.073"], ["71138.20", "0.071"], ["71145.00", "1.130"], ["71145.30", "0.272"], ["71146.00", "0.136"], ["71146.30", "0.227"], ["71146.70", "0.025"], ["71152.40", "0.072"], ["71154.90", "0.003"], ["71169.20", "0.010"], ["71174.10", "0.957"], ["71182.20", "0.763"], ["71182.90", "0.004"], ["71183.10", "0.008"], ["71198.60", "0.004"], ["71204.10", "0.044"], ["71205.50", "0.008"], ["71214.70", "0.449"], ["71215.20", "0.014"], ["71215.80", "0.021"], ["71216.00", "0.005"], ["71216.70", "0.108"], ["71217.20", "0.002"], ["71217.80", "0.102"], ["71218.10", "0.033"], ["71218.30", "0.484"], ["71218.40", "0.285"], ["71219.30", "0.287"], ["71220.80", "0.037"], ["71221.30", "0.030"], ["71222.80", "0.025"], ["71223.30", "0.004"], ["71224.20", "0.000"], ["71226.00", "0.525"], ["71226.40", "0.027"], ["71227.20", "0.004"], ["71229.50", "0.004"], ["71230.00", "0.004"]], "a": [["71233.40", "3.507"], ["71240.10", "0.022"], ["71241.30", "0.007"], ["71242.10", "0.151"], ["71242.20", "0.001"], ["71243.20", "0.015"], ["71244.00", "0.703"], ["71244.60", "0.004"], ["71245.30", "0.076"], ["71245.60", "0.067"], ["71246.00", "0.064"], ["71247.10", "0.261"], ["71247.50", "0.003"], ["71248.40", "1.454"], ["71249.20", "0.062"], ["71249.40", "0.007"], ["71249.80", "0.062"], ["71250.00", "3.327"], ["71250.20", "0.672"], ["71250.50", "0.069"], ["71250.70", "0.041"], ["71250.80", "0.023"], ["71251.40", "0.009"], ["71251.50", "0.686"], ["71251.80", "0.011"], ["71252.70", "0.120"], ["71253.50", "0.000"], ["71254.60", "0.002"], ["71256.50", "0.255"], ["71257.50", "0.024"], ["71260.00", "0.352"], ["71260.10", "0.012"], ["71260.40", "0.004"], ["71260.70", "0.009"], ["71260.80", "0.003"], ["71261.90", "0.072"], ["71266.80", "0.023"], ["71271.20", "0.067"], ["71279.20", "0.217"], ["71280.40", "0.022"], ["71281.10", "0.081"], ["71281.30", "0.109"], ["71281.40", "0.102"], ["71281.50", "0.078"], ["71281.90", "0.055"], ["71283.00", "0.171"], ["71284.80", "0.002"], ["71297.50", "0.082"], ["71311.80", "0.003"], ["71316.30", "0.073"], ["71316.40", "0.000"], ["71323.40", "0.018"], ["71323.50", "1.057"], ["71325.00", "0.043"], ["71333.90", "0.009"], ["71335.30", "0.002"], ["71459.90", "3.080"], ["71910.00", "0.082"], ["71945.70", "0.704"], ["74801.90", "0.005"]]}}
{"local_ts": 1773384640826, "server_ts": 1773384640610, "data": {"e": "depthUpdate", "E": 1773384640611, "T": 1773384640610, "s": "BTCUSDT", "U": 10101349604434, "u": 10101349609829, "pu": 10101349604391, "b": [["1000.00", "27.492"], ["5000.00", "101.418"], ["20833.30", "0.333"], ["20933.30", "0.567"], ["21033.30", "0.414"], ["21133.30", "1.386"], ["56335.30", "0.000"], ["56987.00", "0.043"], ["69794.70", "0.003"], ["70482.80", "0.000"], ["70521.00", "1.404"], ["70552.70", "0.000"], ["70591.00", "0.701"], ["70920.70", "0.002"], ["70921.90", "0.000"], ["71039.30", "0.000"], ["71137.70", "0.214"], ["71137.80", "0.239"], ["71144.80", "0.268"], ["71144.90", "0.000"], ["71151.90", "0.070"], ["71152.00", "0.000"], ["71154.90", "0.000"], ["71169.20", "0.007"], ["71182.20", "0.763"], ["71182.30", "0.004"], ["71221.00", "0.000"], ["71233.30", "4.508"]], "a": [["71237.50", "0.006"], ["71240.10", "0.002"], ["71247.50", "0.023"], ["71297.50", "0.079"], ["71311.80", "0.000"], ["71316.30", "0.073"], ["71323.40", "0.018"], ["71945.70", "1.398"], ["72644.70", "0.000"], ["74811.50", "0.050"]]}}
{"local_ts": 1773384641848, "server_ts": 1773384641632, "data": {"e": "depthUpdate", "E": 1773384641633, "T": 1773384641632, "s": "BTCUSDT", "U": 10101349698229, "u": 10101349712485, "pu": 10101349698210, "b": [["5000.00", "101.418"], ["20733.30", "0.198"], ["20833.30", "0.702"], ["20933.30", "0.198"], ["21033.30", "1.548"], ["21133.30", "0.054"], ["56335.30", "0.002"], ["56987.00", "0.043"], ["67669.00", "0.000"], ["67669.10", "0.002"], ["70399.90", "0.567"], ["70521.00", "2.112"], ["70877.10", "0.002"], ["70920.70", "0.000"], ["71137.80", "0.239"], ["71137.90", "1.572"], ["71144.90", "0.000"], ["71145.00", "1.308"], ["71152.00", "0.000"], ["71152.10", "1.072"], ["71168.60", "0.002"], ["71174.80", "1.215"], ["71176.30", "0.346"], ["71182.70", "0.206"], ["71183.20", "0.026"], ["71191.40", "0.002"], ["71194.70", "0.959"], ["71211.10", "0.021"], ["71212.60", "0.020"], ["71214.10", "0.006"], ["71215.10", "0.001"], ["71216.70", "0.072"], ["71217.10", "0.102"], ["71217.80", "1.295"], ["71218.30", "0.753"], ["71219.00", "0.045"], ["71219.70", "1.897"], ["71220.50", "0.031"], ["71220.70", "0.000"], ["71220.80", "0.149"], ["71221.10", "0.077"], ["71221.40", "0.103"], ["71222.20", "0.544"], ["71224.80", "0.025"], ["71225.20", "0.029"], ["71225.50", "0.045"], ["71227.10", "0.086"], ["71229.70", "0.103"], ["71231.90", "0.051"]], "a": [["71233.40", "0.362"], ["71243.20", "0.000"], ["71245.90", "0.002"], ["71247.60", "0.129"], ["71249.40", "0.010"], ["71272.60", "1.701"], ["71279.20", "0.232"], ["71281.30", "0.109"], ["71281.70", "0.009"], ["71284.70", "0.102"], ["71316.20", "0.070"], ["71316.30", "0.003"], ["71323.30", "0.002"], ["71323.40", "0.016"], ["71600.00", "19.101"], ["71945.70", "1.405"], ["72066.80", "0.554"], ["74818.60", "0.000"]]}}
{"local_ts": 1773384642869, "server_ts": 1773384642652, "data": {"e": "depthUpdate", "E": 1773384642653, "T": 1773384642652, "s": "BTCUSDT", "U": 10101349841100, "u": 10101349846940, "pu": 10101349841036, "b": [["1000.00", "27.492"], ["5000.00", "101.418"], ["20736.80", "0.144"], ["20833.30", "0.000"], ["20836.80", "0.063"], ["20936.80", "0.414"], ["21033.30", "0.180"], ["21136.80", "0.063"], ["44452.50", "1.192"], ["56335.30", "0.000"], ["56989.00", "0.000"], ["67656.10", "0.002"], ["68692.70", "0.002"], ["69790.50", "0.003"], ["69915.50", "1.070"], ["70096.40", "10.386"], ["70132.60", "0.988"], ["70145.70", "0.002"], ["70167.10", "3.413"], ["70167.60", "12.418"], ["70200.90", "4.209"], ["70203.90", "1.712"], ["70238.80", "0.000"], ["70275.10", "0.704"], ["70310.10", "0.000"], ["70343.40", "0.704"], ["70479.00", "2.514"], ["70509.40", "2.246"], ["70524.40", "0.000"], ["70545.80", "0.772"], ["71141.20", "0.171"], ["71148.30", "0.070"], ["71155.40", "0.072"], ["71187.80", "0.002"], ["71199.70", "0.003"], ["71199.80", "0.011"], ["71200.40", "0.002"], ["71200.50", "0.341"], ["71205.30", "0.008"], ["71205.40", "0.005"], ["71206.00", "0.070"], ["71206.10", "0.000"], ["71208.90", "0.002"], ["71221.80", "0.040"], ["71233.70", "0.094"], ["71233.90", "1.102"], ["71236.80", "8.494"]], "a": [["71239.10", "0.073"], ["71255.00", "0.141"], ["71256.90", "0.003"], ["71258.30", "0.005"], ["71259.30", "0.510"], ["71259.40", "0.304"], ["71260.00", "0.341"], ["71260.10", "0.003"], ["71264.90", "0.002"], ["71265.00", "0.007"], ["71265.60", "0.414"], ["71265.70", "0.003"], ["71272.80", "0.075"], ["71284.60", "0.108"], ["71284.70", "0.102"], ["71319.50", "0.116"], ["71319.60", "0.203"], ["71326.60", "0.002"], ["71326.70", "0.000"], ["71472.40", "0.008"], ["71949.30", "0.688"], ["72269.70", "5.624"], ["72539.20", "0.590"], ["72551.70", "1.622"], ["72661.20", "0.000"], ["72697.20", "0.272"], ["74807.30", "0.000"]]}}
{"local_ts": 1773384643894, "server_ts": 1773384643674, "data": {"e": "depthUpdate", "E": 1773384643675, "T": 1773384643674, "s": "BTCUSDT", "U": 10101350091327, "u": 10101350102623, "pu": 10101350091278, "b": [["1000.00", "27.492"], ["5000.00", "101.418"], ["20733.30", "0.072"], ["20859.90", "0.396"], ["20860.90", "0.045"], ["20933.30", "0.126"], ["20933.70", "0.261"], ["21159.90", "0.198"], ["21160.90", "0.027"], ["33000.00", "9.339"], ["56335.30", "0.002"], ["67662.80", "0.002"], ["69834.80", "0.747"], ["70026.80", "0.998"], ["70081.80", "1.004"], ["70096.40", "4.452"], ["70098.00", "0.641"], ["70110.30", "0.003"], ["70151.20", "3.952"], ["70153.10", "1.976"], ["70167.60", "9.454"], ["70169.20", "2.704"], ["70181.50", "0.000"], ["70222.50", "8.125"], ["70224.40", "2.075"], ["70547.30", "0.006"], ["70548.30", "0.002"], ["70899.40", "0.013"], ["70903.90", "0.000"], ["70982.50", "0.298"], ["70983.70", "0.007"], ["71008.40", "0.009"], ["71030.20", "0.002"], ["71047.50", "4.631"], ["71073.60", "0.000"], ["71080.40", "0.102"], ["71106.50", "0.003"], ["71109.10", "0.255"], ["71110.10", "0.911"], ["71111.10", "0.084"], ["71117.30", "0.243"], ["71118.30", "0.000"], ["71120.10", "0.520"], ["71128.20", "0.086"], ["71131.50", "0.246"], ["71132.50", "0.000"], ["71133.30", "0.031"], ["71134.60", "2.500"], ["71136.60", "0.047"], ["71136.90", "0.082"], ["71142.10", "0.000"], ["71160.40", "0.000"], ["71161.10", "0.077"], ["71163.70", "1.390"], ["71166.30", "1.502"], ["71166.50", "0.209"], ["71167.00", "0.004"], ["71167.50", "0.010"], ["71167.90", "0.122"], ["71173.70", "0.074"], ["71177.70", "1.051"], ["71180.60", "0.506"], ["71180.80", "0.106"], ["71181.60", "0.000"], ["71183.50", "0.341"], ["71183.60", "0.187"], ["71187.60", "0.005"], ["71202.80", "0.000"], ["71205.80", "0.100"], ["71206.90", "0.269"], ["71207.30", "0.000"], ["71208.90", "0.002"], ["71209.00", "0.113"], ["71209.20", "0.005"], ["71211.10", "0.051"], ["71212.50", "0.100"], ["71216.20", "0.005"], ["71217.30", "0.011"], ["71219.50", "0.003"], ["71223.10", "0.000"], ["71223.60", "0.102"], ["71223.70", "0.363"], ["71224.30", "0.070"], ["71226.30", "0.002"], ["71226.80", "0.022"], ["71228.40", "0.047"], ["71228.90", "0.004"], ["71229.50", "0.006"], ["71232.00", "0.156"], ["71235.00", "0.011"], ["71236.80", "0.029"], ["71238.50", "0.000"], ["71238.90", "0.000"], ["71239.50", "0.004"], ["71241.30", "0.003"], ["71243.10", "0.006"], ["71244.80", "0.007"], ["71245.00", "0.011"], ["71246.40", "0.181"], ["71248.10", "0.001"], ["71248.90", "0.032"], ["71250.10", "0.002"], ["71250.30", "0.138"], ["71251.20", "0.000"], ["71251.30", "0.055"], ["71251.40", "0.004"], ["71251.50", "0.051"], ["71251.90", "0.028"], ["71252.10", "0.002"], ["71252.20", "0.014"], ["71253.00", "0.157"], ["71253.10", "1.050"], ["71253.20", "0.009"], ["71254.00", "0.037"], ["71254.10", "0.287"], ["71254.90", "0.045"], ["71255.00", "0.116"], ["71255.50", "0.007"], ["71255.60", "0.002"], ["71255.70", "0.022"], ["71255.90", "0.000"], ["71257.40", "0.002"], ["71258.50", "0.002"], ["71259.10", "0.004"], ["71259.40", "0.002"], ["71259.80", "0.004"], ["71259.90", "0.573"], ["71260.00", "0.002"], ["71260.10", "0.000"], ["71260.20", "0.506"], ["71260.30", "0.000"], ["71260.60", "0.000"], ["71260.70", "0.000"], ["71260.80", "0.002"], ["71260.90", "6.780"]], "a": [["71260.00", "0.000"], ["71260.10", "0.000"], ["71260.30", "0.000"], ["71260.40", "0.000"], ["71260.70", "0.000"], ["71260.80", "0.000"], ["71260.90", "0.000"], ["71261.00", "0.832"], ["71261.10", "0.002"], ["71261.40", "0.002"], ["71261.70", "0.000"], ["71262.90", "0.001"], ["71263.40", "0.000"], ["71264.20", "0.002"], ["71264.30", "0.041"], ["71265.40", "0.000"], ["71267.00", "0.007"], ["71268.40", "0.037"], ["71269.50", "0.048"], ["71269.90", "0.208"], ["71270.10", "0.006"], ["71271.20", "0.015"], ["71272.00", "0.002"], ["71272.10", "0.073"], ["71273.00", "0.003"], ["71278.70", "0.002"], ["71280.10", "0.023"], ["71280.70", "0.002"], ["71280.90", "0.029"], ["71281.40", "0.030"], ["71282.00", "0.008"], ["71282.40", "0.221"], ["71282.50", "0.005"], ["71283.00", "0.096"], ["71283.20", "0.104"], ["71283.40", "0.007"], ["71284.00", "0.638"], ["71284.30", "0.245"], ["71285.20", "0.029"], ["71286.20", "0.024"], ["71286.80", "0.001"], ["71287.50", "0.367"], ["71288.90", "0.506"], ["71289.30", "0.005"], ["71289.90", "0.072"], ["71290.20", "0.003"], ["71290.70", "0.015"], ["71290.80", "0.020"], ["71291.00", "0.247"], ["71291.10", "0.349"], ["71292.00", "0.093"], ["71292.90", "0.046"], ["71293.50", "0.504"], ["71294.30", "0.510"], ["71295.00", "0.006"], ["71295.60", "0.169"], ["71295.90", "0.019"], ["71296.40", "0.312"], ["71296.60", "0.002"], ["71297.80", "0.012"], ["71298.50", "0.290"], ["71299.80", "0.002"], ["71300.70", "1.111"], ["71302.00", "0.292"], ["71303.80", "0.109"], ["71305.80", "0.000"], ["71306.30", "0.404"], ["71307.00", "0.050"], ["71307.30", "0.202"], ["71308.40", "0.016"], ["71309.20", "0.032"], ["71311.50", "0.012"], ["71316.50", "0.016"], ["71318.00", "0.000"], ["71319.60", "0.205"], ["71320.10", "0.000"], ["71324.80", "0.000"], ["71326.40", "0.068"], ["71326.80", "0.016"], ["71328.20", "0.000"], ["71329.40", "0.028"], ["71330.50", "0.000"], ["71330.90", "0.096"], ["71332.20", "0.000"], ["71332.30", "0.040"], ["71333.20", "0.395"], ["71334.80", "0.000"], ["71335.40", "0.049"], ["71339.00", "0.022"], ["71339.40", "0.002"], ["71340.40", "0.202"], ["71341.20", "1.080"], ["71345.10", "0.070"], ["71345.20", "0.002"], ["71347.30", "0.000"], ["71347.70", "0.000"], ["71350.30", "4.048"], ["71351.60", "0.002"], ["71352.30", "0.101"], ["71354.40", "0.624"], ["71355.60", "0.002"], ["71360.50", "0.000"], ["71367.80", "0.036"], ["71369.90", "0.509"], ["71370.20", "0.099"], ["71376.30", "0.091"], ["71381.20", "0.009"], ["71389.80", "4.534"], ["71399.90", "0.040"], ["71401.90", "0.010"], ["71418.20", "0.018"], ["71427.60", "0.002"], ["71434.50", "0.101"], ["71464.10", "0.099"], ["71472.20", "0.202"], ["71473.00", "0.106"], ["71498.60", "0.002"], ["71645.60", "0.000"], ["71646.60", "0.200"], ["71666.90", "0.002"], ["71667.90", "0.374"], ["71972.60", "0.000"], ["71973.60", "0.004"], ["72507.90", "1.102"], ["74824.00", "0.188"]]}}
{"local_ts": 1773384644912, "server_ts": 1773384644696, "data": {"e": "depthUpdate", "E": 1773384644697, "T": 1773384644696, "s": "BTCUSDT", "U": 10101350175855, "u": 10101350182220, "pu": 10101350175757, "b": [["5000.00", "101.438"], ["20760.90", "1.143"], ["20841.00", "0.036"], ["20859.90", "0.090"], ["21060.90", "0.693"], ["21141.00", "0.018"], ["21144.90", "0.000"], ["56335.30", "0.000"], ["67663.80", "0.008"], ["67669.10", "0.000"], ["70111.40", "0.712"], ["70156.40", "3.954"], ["70172.10", "2.704"], ["70188.10", "1.410"], ["70200.00", "12.744"], ["70227.60", "6.627"], ["70363.80", "1.406"], ["70400.60", "0.707"], ["70548.30", "0.002"], ["70739.10", "0.020"], ["71000.20", "0.029"], ["71011.20", "0.057"], ["71059.50", "0.000"], ["71195.00", "0.000"], ["71203.90", "0.463"], ["71204.40", "0.592"], ["71204.50", "0.269"], ["71207.70", "0.024"], ["71209.60", "0.206"], ["71211.90", "0.000"], ["71218.80", "0.007"], ["71225.30", "0.002"], ["71238.60", "0.003"], ["71250.10", "0.004"], ["71250.20", "0.423"], ["71250.50", "0.275"], ["71253.80", "0.005"], ["71254.20", "0.000"], ["71255.30", "0.645"], ["71255.40", "0.005"], ["71256.40", "0.639"], ["71257.30", "0.000"], ["71257.70", "0.638"], ["71257.80", "0.506"], ["71257.90", "0.006"], ["71260.90", "3.236"]], "a": [["71261.00", "1.011"], ["71271.70", "0.083"], ["71273.10", "0.002"], ["71274.50", "0.009"], ["71275.30", "0.331"], ["71275.50", "0.008"], ["71278.30", "0.006"], ["71281.80", "0.012"], ["71284.60", "0.003"], ["71293.30", "0.104"], ["71296.60", "0.260"], ["71307.30", "0.103"], ["71323.00", "0.068"], ["71349.60", "0.003"], ["71353.20", "0.007"], ["71368.80", "0.017"], ["71380.00", "0.183"], ["71405.70", "0.209"], ["71410.90", "0.005"], ["71613.70", "0.215"], ["71973.60", "0.000"], ["72508.50", "0.689"]]}}
{"local_ts": 1773384645934, "server_ts": 1773384645715, "data": {"e": "depthUpdate", "E": 1773384645717, "T": 1773384645715, "s": "BTCUSDT", "U": 10101350236530, "u": 10101350247178, "pu": 10101350236485, "b": [["1000.00", "27.492"], ["5000.00", "101.418"], ["20760.90", "0.927"], ["20960.90", "0.558"], ["21060.90", "0.342"], ["21160.90", "0.873"], ["33000.00", "9.339"], ["40000.00", "49.307"], ["67670.50", "0.009"], ["70185.20", "0.000"], ["70227.60", "13.254"], ["70270.40", "0.923"], ["70548.30", "0.002"], ["70548.40", "0.000"], ["70904.60", "0.004"], ["70999.10", "0.004"], ["71004.50", "0.000"], ["71086.80", "0.000"], ["71091.00", "0.288"], ["71104.90", "0.002"], ["71109.10", "0.075"], ["71109.40", "0.004"], ["71109.70", "0.004"], ["71109.80", "0.002"], ["71110.10", "0.850"], ["71110.40", "0.075"], ["71110.80", "0.002"], ["71128.10", "0.040"], ["71130.30", "0.000"], ["71132.90", "0.002"], ["71134.00", "0.005"], ["71142.30", "0.001"], ["71145.00", "1.053"], ["71145.30", "0.202"], ["71145.60", "0.000"], ["71145.70", "0.106"], ["71146.00", "0.111"], ["71146.30", "0.202"], ["71146.70", "0.000"], ["71163.70", "1.387"], ["71169.60", "0.003"], ["71176.50", "0.472"], ["71176.80", "0.037"], ["71177.60", "0.130"], ["71199.30", "0.540"], ["71204.50", "0.085"], ["71204.60", "0.040"], ["71205.30", "0.080"], ["71205.80", "0.148"], ["71206.30", "0.598"], ["71209.60", "0.020"], ["71209.70", "0.005"], ["71210.00", "0.002"], ["71210.80", "1.200"], ["71210.90", "0.147"], ["71222.20", "0.000"], ["71235.00", "0.004"], ["71235.20", "0.001"], ["71237.20", "0.000"], ["71238.10", "0.333"], ["71239.90", "0.090"], ["71240.10", "0.004"], ["71240.20", "0.013"], ["71241.10", "0.000"], ["71242.50", "0.008"], ["71242.70", "0.000"], ["71242.90", "0.002"], ["71243.10", "0.076"], ["71243.50", "0.297"], ["71243.80", "0.007"], ["71244.10", "0.160"], ["71244.70", "0.011"], ["71244.90", "0.013"], ["71245.10", "0.055"], ["71246.10", "0.000"], ["71246.40", "0.280"], ["71246.70", "0.004"], ["71246.80", "0.002"], ["71247.10", "0.307"], ["71247.20", "0.006"], ["71247.40", "0.000"], ["71247.80", "0.002"], ["71248.30", "0.072"], ["71248.40", "0.005"], ["71248.50", "0.509"], ["71248.60", "0.038"], ["71249.10", "0.256"], ["71249.20", "0.150"], ["71249.30", "0.043"], ["71249.60", "0.967"], ["71250.10", "0.004"], ["71250.50", "0.275"], ["71250.60", "0.028"], ["71251.20", "0.042"], ["71252.80", "0.128"], ["71252.90", "0.619"], ["71253.00", "0.182"], ["71253.10", "1.050"], ["71253.20", "0.036"], ["71253.60", "0.141"], ["71253.70", "0.074"], ["71253.80", "0.172"], ["71253.90", "0.434"], ["71254.00", "0.141"], ["71254.10", "0.352"], ["71254.20", "0.049"], ["71254.30", "0.014"], ["71254.50", "0.040"], ["71254.80", "0.014"], ["71255.10", "0.080"], ["71255.20", "0.552"], ["71255.30", "0.007"], ["71255.70", "0.043"], ["71255.90", "0.003"], ["71256.40", "0.001"], ["71258.00", "0.002"], ["71258.50", "0.002"], ["71258.70", "0.696"], ["71260.00", "0.640"], ["71260.10", "0.510"], ["71260.60", "0.000"], ["71260.80", "0.092"], ["71260.90", "4.329"]], "a": [["71261.00", "0.137"], ["71264.60", "0.216"], ["71265.60", "0.085"], ["71266.30", "0.014"], ["71267.70", "0.002"], ["71268.40", "0.026"], ["71269.10", "0.016"], ["71269.80", "0.004"], ["71270.10", "0.003"], ["71271.20", "0.055"], ["71273.80", "0.000"], ["71274.20", "0.015"], ["71274.50", "0.074"], ["71274.60", "0.008"], ["71275.00", "0.140"], ["71275.20", "0.129"], ["71275.30", "0.087"], ["71275.50", "0.770"], ["71275.70", "0.092"], ["71275.80", "0.019"], ["71281.00", "0.013"], ["71281.30", "0.005"], ["71282.40", "0.124"], ["71283.40", "0.007"], ["71283.50", "0.124"], ["71283.90", "0.000"], ["71285.10", "0.031"], ["71285.30", "0.010"], ["71285.80", "0.731"], ["71286.10", "0.051"], ["71287.20", "0.077"], ["71288.30", "0.005"], ["71289.60", "0.579"], ["71290.20", "0.003"], ["71291.00", "0.002"], ["71291.60", "0.079"], ["71292.70", "0.000"], ["71293.30", "0.263"], ["71294.20", "0.539"], ["71296.60", "0.299"], ["71300.20", "0.143"], ["71302.80", "0.005"], ["71307.30", "0.064"], ["71310.40", "0.321"], ["71310.80", "0.102"], ["71311.10", "0.085"], ["71311.40", "0.120"], ["71311.80", "0.102"], ["71311.90", "0.051"], ["71316.70", "0.292"], ["71317.00", "0.001"], ["71317.40", "0.002"], ["71317.80", "0.000"], ["71318.20", "0.000"], ["71318.50", "0.020"], ["71318.90", "0.041"], ["71319.00", "0.510"], ["71321.50", "0.000"], ["71323.10", "0.050"], ["71331.00", "0.002"], ["71333.60", "0.000"], ["71338.30", "0.040"], ["71339.90", "0.111"], ["71343.20", "0.040"], ["71346.30", "0.170"], ["71347.00", "0.108"], ["71347.30", "0.129"], ["71352.60", "0.292"], ["71352.90", "0.000"], ["71353.30", "0.021"], ["71353.70", "0.043"], ["71354.00", "0.000"], ["71354.10", "0.102"], ["71354.40", "0.513"], ["71354.80", "0.004"], ["71354.90", "2.339"], ["71358.90", "0.011"], ["71372.90", "0.509"], ["71377.00", "0.595"], ["71382.20", "0.289"], ["71388.10", "0.003"], ["71460.50", "0.002"], ["71474.40", "0.000"], ["71488.30", "0.006"], ["71973.60", "0.000"], ["73398.80", "0.032"], ["74823.90", "0.003"], ["74858.70", "0.002"]]}}
{"local_ts": 1773384646954, "server_ts": 1773384646734, "data": {"e": "depthUpdate", "E": 1773384646737, "T": 1773384646734, "s": "BTCUSDT", "U": 10101350328470, "u": 10101350333219, "pu": 10101350328454, "b": [["5000.00", "101.418"], ["20862.30", "0.423"], ["20960.90", "0.477"], ["21062.30", "0.603"], ["21160.90", "0.873"], ["21162.30", "0.324"], ["70227.20", "1.991"], ["70549.70", "0.000"], ["70870.20", "0.000"], ["70906.00", "0.613"], ["70906.10", "0.000"], ["71012.20", "0.299"], ["71152.80", "0.019"], ["71200.00", "1.547"], ["71200.10", "1.230"], ["71204.50", "0.085"], ["71206.90", "0.284"], ["71207.50", "0.174"], ["71211.10", "0.002"], ["71222.00", "0.110"], ["71232.90", "0.004"], ["71238.80", "0.004"], ["71243.40", "0.009"], ["71245.20", "0.005"], ["71247.80", "0.383"], ["71248.00", "0.521"], ["71255.20", "0.575"], ["71259.50", "0.001"], ["71260.00", "0.215"], ["71260.90", "0.065"], ["71262.30", "2.788"]], "a": [["71262.40", "2.852"], ["71264.50", "0.212"], ["71266.90", "0.014"], ["71269.50", "0.036"], ["71272.60", "0.012"], ["71273.40", "0.644"], ["71279.20", "0.225"], ["71283.60", "0.532"], ["71287.20", "0.000"], ["71289.30", "0.007"], ["71291.10", "0.356"], ["71301.60", "2.129"], ["71310.50", "0.024"], ["71310.70", "0.871"], ["71341.20", "1.080"], ["71975.00", "0.599"], ["72114.40", "0.000"], ["72658.00", "0.216"], ["74836.30", "0.002"], ["74858.70", "0.000"], ["89523.20", "0.000"]]}}
{"local_ts": 1773384647974, "server_ts": 1773384647757, "data": {"e": "depthUpdate", "E": 1773384647759, "T": 1773384647757, "s": "BTCUSDT", "U": 10101350393280, "u": 10101350407032, "pu": 10101350392716, "b": [["1000.00", "27.492"], ["5000.00", "101.418"], ["20762.30", "0.288"], ["20862.30", "0.612"], ["20962.30", "0.342"], ["21062.30", "1.458"], ["21160.90", "0.000"], ["33000.00", "9.343"], ["67668.60", "0.007"], ["67688.50", "0.002"], ["69696.10", "0.614"], ["69809.10", "0.000"], ["69837.10", "0.012"], ["69975.10", "0.004"], ["70188.90", "0.000"], ["70193.40", "1.716"], ["70434.40", "0.000"], ["70442.10", "0.000"], ["70478.40", "1.411"], ["70485.50", "0.702"], ["70548.30", "0.016"], ["70549.70", "0.007"], ["70692.20", "0.000"], ["71089.20", "0.018"], ["71090.20", "0.103"], ["71166.40", "0.074"], ["71173.60", "0.085"], ["71180.70", "0.074"], ["71200.10", "0.030"], ["71204.50", "0.184"], ["71206.90", "0.100"], ["71207.20", "0.155"], ["71210.40", "0.034"], ["71210.50", "0.675"], ["71231.30", "0.030"], ["71232.90", "0.104"], ["71234.90", "0.072"], ["71253.20", "0.007"], ["71255.20", "0.575"], ["71255.40", "0.043"], ["71259.60", "0.002"], ["71262.30", "2.662"]], "a": [["71262.40", "3.031"], ["71264.60", "0.008"], ["71266.60", "0.002"], ["71269.50", "0.036"], ["71272.90", "0.007"], ["71274.20", "0.015"], ["71275.40", "0.688"], ["71276.40", "0.140"], ["71277.00", "0.003"], ["71279.10", "0.003"], ["71280.10", "0.663"], ["71280.90", "0.109"], ["71281.80", "0.009"], ["71283.80", "0.086"], ["71284.50", "0.072"], ["71286.60", "0.758"], ["71288.30", "0.005"], ["71291.50", "0.011"], ["71291.80", "0.003"], ["71315.00", "0.630"], ["71315.20", "0.063"], ["71344.70", "0.072"], ["71352.60", "0.290"], ["71369.30", "0.212"], ["71383.50", "2.893"], ["71386.70", "0.004"], ["71975.00", "0.668"], ["72538.90", "0.000"], ["72659.60", "0.000"], ["72661.60", "0.000"], ["72663.80", "0.003"], ["89523.20", "0.000"]]}}
{"local_ts": 1773384648995, "server_ts": 1773384648777, "data": {"e": "depthUpdate", "E": 1773384648781, "T": 1773384648777, "s": "BTCUSDT", "U": 10101350497639, "u": 10101350507426, "pu": 10101350497404, "b": [["1000.00", "27.492"], ["5000.00", "101.418"], ["20762.30", "0.747"], ["20862.30", "0.162"], ["20962.30", "1.548"], ["21062.30", "0.090"], ["21162.30", "0.153"], ["68034.60", "0.289"], ["69834.80", "0.729"], ["69837.10", "0.027"], ["69911.60", "0.000"], ["70256.10", "0.421"], ["70258.20", "0.570"], ["70259.60", "0.002"], ["70262.30", "0.014"], ["70358.60", "1.136"], ["70549.70", "0.007"], ["70906.00", "0.648"], ["71075.00", "0.076"], ["71136.10", "0.723"], ["71146.10", "0.091"], ["71195.00", "0.100"], ["71204.50", "0.269"], ["71207.20", "0.070"], ["71210.70", "0.230"], ["71210.90", "0.006"], ["71211.00", "0.256"], ["71240.20", "0.012"], ["71242.00", "7.251"], ["71243.50", "0.070"], ["71246.10", "0.000"], ["71250.30", "0.004"], ["71250.70", "0.002"], ["71251.60", "0.211"], ["71253.00", "0.074"], ["71255.20", "0.674"], ["71259.80", "0.004"], ["71261.20", "0.003"], ["71262.20", "0.005"], ["71262.30", "3.964"]], "a": [["71262.40", "0.127"], ["71269.50", "0.038"], ["71271.80", "0.002"], ["71272.60", "0.002"], ["71273.40", "0.694"], ["71275.00", "0.055"], ["71279.80", "0.002"], ["71283.40", "0.092"], ["71283.80", "0.185"], ["71284.10", "0.027"], ["71290.80", "0.009"], ["71290.90", "0.003"], ["71291.50", "0.011"], ["71291.60", "0.012"], ["71291.90", "0.542"], ["71292.60", "0.089"], ["71298.00", "0.475"], ["71302.50", "0.065"], ["71310.20", "0.053"], ["71310.40", "0.323"], ["71327.90", "0.128"], ["71380.00", "0.183"], ["71500.80", "0.003"], ["71522.00", "0.008"], ["71618.70", "0.212"], ["71974.90", "1.387"], ["71975.00", "0.668"], ["72447.50", "0.010"], ["72467.10", "0.000"], ["72685.10", "0.017"], ["72686.20", "0.355"], ["74850.00", "21.880"], ["89523.20", "0.000"]]}}
{"local_ts": 1773384650020, "server_ts": 1773384649802, "data": {"e": "depthUpdate", "E": 1773384649803, "T": 1773384649802, "s": "BTCUSDT", "U": 10101350615249, "u": 10101350621797, "pu": 10101350614992, "b": [["5000.00", "101.418"], ["20762.30", "0.000"], ["20767.80", "0.027"], ["20867.80", "0.558"], ["20962.30", "0.225"], ["21067.80", "0.027"], ["21167.80", "0.261"], ["68160.20", "0.202"], ["70193.40", "0.736"], ["70195.10", "0.000"], ["70234.40", "0.989"], ["70270.10", "0.427"], ["70277.20", "0.994"], ["70340.80", "0.070"], ["70394.80", "1.420"], ["70478.70", "1.124"], ["70482.40", "0.002"], ["70549.70", "0.021"], ["70554.80", "2.526"], ["70555.10", "0.037"], ["70906.00", "0.683"], ["70914.60", "0.000"], ["70919.90", "0.002"], ["71034.40", "0.000"], ["71098.80", "2.961"], ["71111.20", "0.000"], ["71141.10", "0.144"], ["71142.00", "0.028"], ["71200.70", "0.004"], ["71204.50", "0.184"], ["71207.00", "0.121"], ["71208.30", "0.946"], ["71232.90", "0.000"], ["71241.60", "0.111"], ["71248.30", "0.000"], ["71248.60", "0.072"], ["71252.00", "0.007"], ["71253.00", "0.042"], ["71260.00", "0.014"], ["71260.80", "0.079"], ["71262.30", "0.033"], ["71264.70", "0.003"], ["71265.20", "0.002"], ["71266.00", "0.064"], ["71267.80", "8.258"]], "a": [["71275.10", "0.061"], ["71276.20", "0.046"], ["71277.00", "0.001"], ["71278.40", "0.000"], ["71279.80", "0.000"], ["71281.30", "0.073"], ["71281.70", "0.057"], ["71282.00", "0.053"], ["71282.50", "0.234"], ["71283.10", "0.336"], ["71283.50", "0.055"], ["71296.00", "0.005"], ["71296.40", "0.417"], ["71296.70", "0.003"], ["71296.90", "0.007"], ["71297.80", "0.083"], ["71298.70", "0.042"], ["71300.00", "2.979"], ["71307.30", "0.000"], ["71308.00", "0.998"], ["71310.00", "0.206"], ["71310.80", "0.002"], ["71311.10", "0.017"], ["71311.40", "0.153"], ["71311.50", "0.010"], ["71312.60", "0.005"], ["71315.90", "0.002"], ["71316.10", "0.009"], ["71316.20", "0.001"], ["71318.90", "0.062"], ["71337.30", "0.002"], ["71381.40", "0.068"], ["71381.80", "0.057"], ["71382.10", "0.050"], ["71382.60", "0.638"], ["71383.20", "0.736"], ["71401.30", "0.272"], ["71408.70", "0.037"], ["71980.60", "0.000"], ["72194.40", "0.832"], ["72693.20", "5.866"], ["74828.50", "0.110"], ["74862.90", "0.002"], ["89523.20", "0.000"]]}}
{"local_ts": 1773384651041, "server_ts": 1773384650823, "data": {"e": "depthUpdate", "E": 1773384650825, "T": 1773384650823, "s": "BTCUSDT", "U": 10101350679414, "u": 10101350685197, "pu": 10101350679377, "b": [["1000.00", "27.492"], ["5000.00", "101.418"], ["20767.80", "1.332"], ["20862.30", "0.441"], ["20865.90", "0.009"], ["20867.80", "0.000"], ["21067.80", "0.792"], ["21162.30", "0.108"], ["57014.00", "0.000"], ["70193.40", "0.750"], ["70375.80", "0.703"], ["70412.60", "2.963"], ["70555.10", "0.037"], ["70919.90", "0.000"], ["70921.50", "0.036"], ["71018.10", "0.036"], ["71103.70", "4.808"], ["71174.00", "0.070"], ["71174.10", "0.002"], ["71180.90", "0.025"], ["71181.20", "0.111"], ["71181.30", "0.000"], ["71188.30", "0.072"], ["71188.40", "0.530"], ["71217.60", "0.006"], ["71217.80", "0.005"], ["71222.80", "0.048"], ["71232.20", "0.000"], ["71239.20", "0.288"], ["71242.90", "0.209"], ["71260.70", "0.007"], ["71264.20", "0.008"], ["71265.50", "0.096"], ["71266.10", "0.005"], ["71266.30", "0.000"], ["71267.80", "6.483"]], "a": [["71267.90", "1.091"], ["71268.00", "0.008"], ["71268.70", "0.002"], ["71268.80", "0.022"], ["71269.40", "0.007"], ["71269.90", "0.002"], ["71274.80", "0.001"], ["71276.20", "0.086"], ["71282.20", "0.083"], ["71284.20", "0.002"], ["71290.10", "0.070"], ["71293.90", "0.006"], ["71295.20", "0.048"], ["71296.40", "0.609"], ["71303.50", "0.072"], ["71307.10", "0.378"], ["71336.90", "1.051"], ["71352.40", "0.072"], ["71352.50", "0.012"], ["71980.60", "0.000"], ["72044.60", "1.380"], ["72180.00", "0.627"], ["73405.90", "0.000"], ["74835.90", "0.000"], ["74851.10", "0.002"], ["89523.20", "0.000"]]}}
{"local_ts": 1773384652061, "server_ts": 1773384651844, "data": {"e": "depthUpdate", "E": 1773384651845, "T": 1773384651844, "s": "BTCUSDT", "U": 10101350755011, "u": 10101350761039, "pu": 10101350754864, "b": [["5000.00", "101.418"], ["20767.80", "0.729"], ["20968.40", "0.522"], ["21067.80", "0.243"], ["21168.40", "0.936"], ["64141.60", "0.002"], ["67683.60", "0.000"], ["67685.00", "0.002"], ["67699.20", "0.003"], ["67699.30", "0.004"], ["69700.00", "21.636"], ["69948.70", "0.000"], ["70021.20", "1.131"], ["70157.10", "0.712"], ["70555.70", "0.011"], ["70591.50", "0.004"], ["70912.10", "0.000"], ["70921.50", "0.034"], ["70928.60", "2.036"], ["71018.40", "0.015"], ["71114.30", "0.002"], ["71118.20", "0.536"], ["71169.70", "0.040"], ["71174.00", "0.070"], ["71179.10", "0.036"], ["71181.20", "0.111"], ["71181.90", "0.036"], ["71182.40", "0.025"], ["71188.30", "0.072"], ["71211.40", "0.229"], ["71218.40", "0.256"], ["71218.50", "0.002"], ["71221.20", "0.007"], ["71253.60", "0.045"], ["71253.70", "0.734"], ["71253.90", "0.375"], ["71254.10", "0.012"], ["71254.20", "0.097"], ["71261.30", "0.074"], ["71265.60", "0.341"], ["71267.90", "0.709"], ["71268.30", "0.084"], ["71268.40", "5.693"]], "a": [["71268.50", "1.496"], ["71268.60", "0.001"], ["71271.30", "0.003"], ["71274.10", "0.001"], ["71274.90", "0.001"], ["71275.50", "0.265"], ["71276.70", "0.003"], ["71281.90", "0.241"], ["71282.40", "0.047"], ["71282.60", "0.061"], ["71282.70", "0.728"], ["71283.00", "0.127"], ["71283.10", "0.153"], ["71286.30", "0.349"], ["71297.00", "0.544"], ["71307.10", "0.219"], ["71316.20", "0.001"], ["71316.30", "0.005"], ["71318.30", "0.045"], ["71319.00", "0.575"], ["71320.10", "0.072"], ["71325.00", "0.054"], ["71339.70", "0.005"], ["71352.30", "0.171"], ["71354.20", "0.043"], ["71354.90", "2.404"], ["71357.50", "0.072"], ["71409.70", "0.053"], ["71415.80", "0.700"], ["71463.60", "0.345"], ["71504.70", "0.007"], ["71504.80", "0.004"], ["71981.10", "3.316"], ["71981.20", "0.060"], ["72348.40", "0.414"], ["78395.30", "0.002"], ["89523.20", "0.000"]]}}
{"local_ts": 1773384653082, "server_ts": 1773384652864, "data": {"e": "depthUpdate", "E": 1773384652867, "T": 1773384652864, "s": "BTCUSDT", "U": 10101350837585, "u": 10101350842871, "pu": 10101350837481, "b": [["1000.00", "27.492"], ["5000.00", "101.418"], ["20868.40", "0.522"], ["20968.40", "0.243"], ["21068.40", "0.801"], ["21168.40", "0.864"], ["33000.00", "9.339"], ["64141.60", "0.002"], ["67702.50", "0.002"], ["68949.90", "0.000"], ["70555.80", "0.004"], ["70928.40", "0.002"], ["70928.60", "2.034"], ["71017.80", "0.012"], ["71190.00", "0.040"], ["71200.00", "1.547"], ["71204.20", "0.518"], ["71218.50", "0.004"], ["71218.70", "0.002"], ["71267.10", "0.002"]], "a": [["71290.80", "0.029"], ["71290.90", "0.003"], ["71291.50", "0.004"], ["71291.60", "0.005"], ["71292.00", "0.006"], ["71297.00", "0.403"], ["71304.10", "0.102"], ["71315.70", "0.029"], ["71317.30", "0.024"], ["71332.70", "0.006"], ["71344.10", "0.093"], ["71346.90", "0.039"], ["71347.30", "0.000"], ["71981.20", "0.060"], ["74853.20", "0.002"], ["78395.30", "0.002"], ["89523.20", "0.000"]]}}
{"local_ts": 1773384654104, "server_ts": 1773384653888, "data": {"e": "depthUpdate", "E": 1773384653889, "T": 1773384653888, "s": "BTCUSDT", "U": 10101350922953, "u": 10101350930966, "pu": 10101350922758, "b": [["1000.00", "27.492"], ["5000.00", "101.418"], ["20768.40", "0.387"], ["20868.40", "0.513"], ["20968.40", "0.540"], ["21068.40", "1.260"], ["64141.60", "0.002"], ["69837.10", "0.000"], ["69843.00", "0.039"], ["70555.70", "1.426"], ["70926.50", "0.002"], ["70928.40", "0.000"], ["71057.80", "0.005"], ["71061.30", "0.024"], ["71118.50", "0.286"], ["71118.60", "0.536"], ["71209.60", "0.341"], ["71213.20", "0.271"], ["71218.10", "0.302"], ["71218.30", "0.301"], ["71220.40", "0.002"], ["71243.50", "0.547"], ["71257.70", "0.111"], ["71261.30", "0.587"], ["71261.40", "0.004"], ["71265.40", "0.004"], ["71265.90", "0.000"], ["71266.90", "0.034"], ["71268.40", "0.342"]], "a": [["71269.50", "0.010"], ["71272.30", "0.007"], ["71274.90", "0.001"], ["71275.00", "0.072"], ["71275.70", "0.006"], ["71278.70", "0.048"], ["71280.40", "0.063"], ["71284.90", "0.003"], ["71290.60", "0.011"], ["71314.00", "0.023"], ["71315.90", "0.002"], ["71415.80", "0.734"], ["71981.20", "0.060"], ["72230.60", "0.279"], ["72497.40", "0.284"], ["74837.50", "0.052"], ["74862.00", "0.050"], ["78395.30", "0.002"], ["89523.20", "0.000"]]}}
{"local_ts": 1773384655126, "server_ts": 1773384654910, "data": {"e": "depthUpdate", "E": 1773384654911, "T": 1773384654910, "s": "BTCUSDT", "U": 10101350976754, "u": 10101350979780, "pu": 10101350976717, "b": [["5000.00", "101.418"], ["20768.40", "0.648"], ["20868.40", "0.270"], ["20968.40", "1.530"], ["21068.40", "0.000"], ["21168.40", "0.252"], ["33000.00", "9.339"], ["64141.60", "0.002"], ["67690.80", "0.004"], ["67699.30", "0.000"], ["67704.00", "0.600"], ["67705.00", "0.005"], ["69843.00", "0.067"], ["70555.70", "1.426"], ["70926.50", "0.000"], ["71218.50", "0.002"], ["71218.70", "0.004"], ["71252.80", "0.003"], ["71254.70", "0.000"], ["71257.70", "0.247"], ["71265.70", "0.408"], ["71267.50", "0.002"], ["71268.40", "2.314"]], "a": [["71304.10", "0.042"], ["71354.80", "0.220"], ["71981.20", "0.190"], ["72480.10", "0.585"], ["72693.90", "0.014"], ["74119.20", "0.018"], ["74858.00", "0.058"], ["74862.40", "0.002"], ["78395.30", "0.002"], ["89523.20", "0.006"]]}}
{"local_ts": 1773384656146, "server_ts": 1773384655928, "data": {"e": "depthUpdate", "E": 1773384655931, "T": 1773384655928, "s": "BTCUSDT", "U": 10101351039918, "u": 10101351045698, "pu": 10101351039905, "b": [["1000.00", "27.492"], ["5000.00", "101.418"], ["20768.40", "0.126"], ["20868.40", "1.548"], ["20968.40", "0.126"], ["21068.40", "0.117"], ["21168.40", "0.783"], ["57015.00", "0.000"], ["64141.60", "0.002"], ["69843.00", "0.074"], ["69843.10", "0.024"], ["70555.70", "1.426"], ["71079.50", "0.000"], ["71095.50", "0.029"], ["71173.80", "0.029"], ["71181.00", "0.035"], ["71188.10", "0.005"], ["71194.60", "0.211"], ["71207.80", "0.099"], ["71209.60", "0.098"], ["71211.00", "0.002"], ["71213.20", "0.000"], ["71243.50", "0.651"], ["71255.90", "0.458"], ["71257.70", "0.136"], ["71265.40", "0.004"], ["71268.30", "0.088"], ["71268.40", "1.648"]], "a": [["71268.50", "2.789"], ["71273.60", "0.004"], ["71274.10", "0.001"], ["71274.20", "0.069"], ["71274.40", "0.008"], ["71274.80", "0.001"], ["71274.90", "0.003"], ["71275.00", "0.072"], ["71275.20", "0.352"], ["71286.30", "0.388"], ["71296.90", "0.007"], ["71297.00", "0.502"], ["71299.00", "0.446"], ["71306.40", "0.007"], ["71307.50", "1.626"], ["71317.60", "0.002"], ["71352.10", "0.000"], ["71371.80", "0.214"], ["71981.20", "0.190"], ["74837.80", "0.000"], ["78395.30", "0.002"]]}}
{"local_ts": 1773384657166, "server_ts": 1773384656950, "data": {"e": "depthUpdate", "E": 1773384656951, "T": 1773384656950, "s": "BTCUSDT", "U": 10101351113370, "u": 10101351120059, "pu": 10101351113318, "b": [["5000.00", "101.418"], ["20768.40", "1.530"], ["20868.40", "0.270"], ["21068.40", "0.882"], ["21168.40", "0.018"], ["33000.00", "9.343"], ["64141.60", "0.000"], ["70555.70", "1.426"], ["71167.20", "7.129"], ["71173.70", "0.074"], ["71178.80", "0.424"], ["71180.90", "0.095"], ["71188.00", "0.141"], ["71205.70", "4.428"], ["71213.20", "0.243"], ["71218.90", "0.034"], ["71219.10", "0.014"], ["71220.90", "0.105"], ["71229.60", "2.435"], ["71247.00", "0.011"], ["71255.90", "0.366"], ["71261.30", "0.565"], ["71268.40", "0.506"]], "a": [["71268.50", "2.801"], ["71269.40", "0.013"], ["71273.20", "0.011"], ["71274.90", "0.003"], ["71275.60", "1.642"], ["71315.90", "1.904"], ["71316.10", "0.021"], ["71316.50", "0.019"], ["71339.20", "1.321"], ["71339.80", "4.930"], ["71352.00", "0.472"], ["71375.00", "0.072"], ["71378.10", "6.932"], ["71428.90", "0.252"], ["71441.30", "12.952"], ["71457.40", "0.000"], ["71495.10", "0.006"], ["71981.20", "0.190"], ["72693.90", "0.042"], ["74833.40", "0.002"], ["78395.30", "0.000"]]}}
{"local_ts": 1773384658193, "server_ts": 1773384657972, "data": {"e": "depthUpdate", "E": 1773384657975, "T": 1773384657972, "s": "BTCUSDT", "U": 10101351201484, "u": 10101351205262, "pu": 10101351201439, "b": [["1000.00", "27.492"], ["5000.00", "101.418"], ["20768.40", "0.540"], ["20969.60", "0.603"], ["21068.40", "0.144"], ["21169.60", "1.107"], ["64142.60", "0.000"], ["70188.50", "0.854"], ["70305.60", "0.710"], ["70556.90", "0.016"], ["71061.50", "0.000"], ["71066.20", "0.004"], ["71106.80", "13.401"], ["71123.60", "0.293"], ["71127.80", "0.002"], ["71141.70", "0.105"], ["71145.90", "2.010"], ["71146.00", "0.994"], ["71146.20", "0.002"], ["71146.50", "0.000"], ["71146.60", "0.147"], ["71146.90", "0.608"], ["71147.20", "0.012"], ["71147.60", "0.000"], ["71167.10", "0.000"], ["71168.30", "1.684"], ["71169.30", "7.111"], ["71169.70", "0.004"], ["71173.70", "0.074"], ["71179.10", "0.000"], ["71180.90", "0.095"], ["71181.80", "0.012"], ["71181.90", "0.000"], ["71182.10", "0.377"], ["71182.40", "0.000"], ["71182.50", "0.340"], ["71182.80", "0.000"], ["71183.10", "0.041"], ["71183.40", "1.077"], ["71183.50", "0.157"], ["71188.00", "0.141"], ["71207.50", "3.670"], ["71208.30", "0.946"], ["71216.50", "0.019"], ["71220.90", "0.103"], ["71221.10", "0.004"], ["71253.60", "0.007"], ["71253.70", "0.419"], ["71253.90", "0.362"], ["71254.20", "0.000"], ["71254.30", "0.001"], ["71254.60", "0.004"], ["71254.90", "0.078"], ["71255.00", "0.082"], ["71255.20", "0.641"], ["71255.30", "0.163"], ["71262.40", "0.211"], ["71262.50", "0.040"], ["71269.10", "0.025"]], "a": [["71269.70", "1.964"], ["71274.10", "0.001"], ["71274.90", "0.002"], ["71275.30", "0.008"], ["71276.80", "0.036"], ["71281.10", "0.194"], ["71281.20", "0.007"], ["71281.60", "0.004"], ["71282.00", "0.003"], ["71282.30", "0.052"], ["71282.40", "0.001"], ["71282.50", "0.109"], ["71282.70", "0.009"], ["71282.90", "0.057"], ["71283.00", "0.073"], ["71283.10", "0.086"], ["71287.50", "0.186"], ["71289.10", "0.206"], ["71290.50", "0.127"], ["71291.80", "0.003"], ["71294.40", "0.000"], ["71296.10", "0.506"], ["71298.20", "0.271"], ["71307.50", "0.511"], ["71315.30", "0.186"], ["71317.00", "0.309"], ["71317.10", "0.278"], ["71317.50", "0.117"], ["71317.90", "0.003"], ["71318.20", "0.000"], ["71318.30", "0.002"], ["71318.40", "0.090"], ["71318.60", "0.002"], ["71318.80", "0.056"], ["71318.90", "0.041"], ["71319.00", "0.513"], ["71320.10", "0.000"], ["71325.00", "0.000"], ["71326.00", "0.078"], ["71326.10", "0.017"], ["71352.00", "0.472"], ["71353.00", "0.001"], ["71353.40", "0.763"], ["71353.80", "0.014"], ["71354.10", "0.102"], ["71354.20", "0.000"], ["71354.30", "0.043"], ["71354.50", "1.049"], ["71354.70", "0.068"], ["71354.80", "0.044"], ["71354.90", "2.509"], ["71357.50", "0.000"], ["71366.90", "0.004"], ["71369.60", "0.000"], ["71375.90", "7.148"], ["71433.60", "0.039"], ["71439.80", "13.493"], ["71982.40", "0.014"], ["74853.70", "0.002"], ["74865.20", "0.000"], ["78396.70", "0.000"]]}}
{"local_ts": 1773384659210, "server_ts": 1773384658992, "data": {"e": "depthUpdate", "E": 1773384658995, "T": 1773384658992, "s": "BTCUSDT", "U": 10101351244768, "u": 10101351247820, "pu": 10101351244630, "b": [["1000.00", "27.492"], ["5000.00", "101.418"], ["20869.60", "0.621"], ["20969.60", "0.126"], ["21069.60", "0.990"], ["21169.60", "0.657"], ["57016.00", "0.000"], ["64142.60", "0.000"], ["67694.00", "0.000"], ["67704.10", "0.005"], ["67706.10", "0.006"], ["69986.70", "0.018"], ["70129.20", "1.985"], ["70164.90", "4.940"], ["70307.50", "1.271"], ["70482.70", "0.008"], ["70485.30", "0.000"], ["70521.00", "1.417"], ["70521.30", "0.702"], ["70556.90", "0.718"], ["70592.20", "2.120"], ["70628.20", "1.402"], ["71066.10", "0.002"], ["71066.20", "0.002"], ["71173.70", "0.074"], ["71180.90", "0.095"], ["71188.00", "0.141"], ["71188.50", "0.000"], ["71208.20", "0.000"], ["71218.30", "0.299"], ["71268.40", "0.259"]], "a": [["71269.70", "3.362"], ["71274.10", "0.011"], ["71274.50", "0.009"], ["71274.90", "0.012"], ["71275.30", "0.006"], ["71275.40", "0.032"], ["71277.90", "0.022"], ["71294.60", "1.171"], ["71352.00", "0.472"], ["71764.30", "0.168"], ["71982.40", "0.014"], ["72049.00", "0.417"], ["78396.70", "0.000"]]}}
{"local_ts": 1773384660235, "server_ts": 1773384660016, "data": {"e": "depthUpdate", "E": 1773384660017, "T": 1773384660016, "s": "BTCUSDT", "U": 10101351305316, "u": 10101351311283, "pu": 10101351305264, "b": [["5000.00", "101.418"], ["20769.60", "0.486"], ["20869.60", "0.414"], ["20969.60", "0.720"], ["21069.60", "1.080"], ["57016.00", "0.108"], ["64142.60", "0.000"], ["67684.50", "0.004"], ["70556.90", "1.420"], ["70800.00", "31.775"], ["71063.90", "0.002"], ["71066.10", "0.000"], ["71168.50", "0.027"], ["71169.80", "0.125"], ["71172.50", "0.090"], ["71173.20", "0.072"], ["71173.60", "0.015"], ["71180.40", "1.478"], ["71180.80", "0.008"], ["71187.50", "0.078"], ["71187.90", "0.000"], ["71191.10", "0.005"], ["71196.30", "0.002"], ["71202.50", "0.042"], ["71203.50", "0.043"], ["71204.50", "0.059"], ["71205.50", "0.042"], ["71206.40", "0.046"], ["71207.40", "0.231"], ["71208.40", "0.132"], ["71209.30", "0.346"], ["71209.60", "0.409"], ["71210.30", "0.341"], ["71210.50", "0.721"], ["71210.80", "0.106"], ["71211.30", "0.044"], ["71212.00", "1.021"], ["71212.30", "0.084"], ["71212.50", "0.184"], ["71212.60", "0.241"], ["71212.90", "0.679"], ["71213.10", "0.316"], ["71213.20", "0.133"], ["71213.70", "0.071"], ["71214.20", "0.006"], ["71214.70", "0.042"], ["71214.90", "0.029"], ["71215.20", "0.035"], ["71216.10", "0.000"], ["71216.20", "0.064"], ["71217.10", "0.031"], ["71217.20", "0.067"], ["71217.40", "0.029"], ["71218.00", "0.815"], ["71218.10", "0.297"], ["71218.20", "0.000"], ["71218.70", "0.044"], ["71219.30", "0.029"], ["71219.80", "0.113"], ["71219.90", "0.002"], ["71220.10", "0.610"], ["71220.60", "0.043"], ["71221.00", "0.064"], ["71221.20", "0.038"], ["71222.40", "0.029"], ["71223.70", "0.371"], ["71224.90", "0.762"], ["71225.00", "0.822"], ["71225.20", "0.031"], ["71225.40", "0.003"], ["71226.20", "0.055"], ["71226.50", "0.000"], ["71226.60", "0.032"], ["71226.70", "0.005"], ["71227.40", "0.302"], ["71228.60", "0.002"], ["71229.50", "0.468"], ["71229.90", "0.021"], ["71232.00", "0.893"], ["71232.80", "0.000"], ["71233.00", "1.025"], ["71234.00", "0.064"], ["71234.70", "0.000"], ["71235.60", "0.073"], ["71236.70", "0.004"], ["71238.00", "0.276"], ["71238.40", "0.002"], ["71239.00", "0.872"], ["71242.90", "0.289"], ["71244.70", "0.136"], ["71246.00", "0.888"], ["71247.40", "0.391"], ["71248.20", "0.008"], ["71248.30", "0.022"], ["71248.60", "0.017"], ["71248.70", "0.191"], ["71248.90", "0.047"], ["71249.00", "0.297"], ["71249.10", "0.074"], ["71249.20", "0.020"], ["71249.50", "0.016"], ["71249.60", "0.022"], ["71249.70", "0.015"], ["71250.00", "0.041"], ["71250.20", "0.026"], ["71250.30", "0.552"], ["71250.40", "0.508"], ["71250.50", "1.707"], ["71250.60", "0.007"], ["71251.00", "1.182"], ["71251.20", "0.000"], ["71251.80", "0.003"], ["71251.90", "0.006"], ["71252.00", "0.022"], ["71252.30", "0.019"], ["71252.50", "0.295"], ["71252.90", "0.512"], ["71253.10", "1.050"], ["71253.40", "0.072"], ["71253.70", "0.099"], ["71254.50", "1.020"], ["71255.30", "0.343"], ["71258.50", "0.016"], ["71260.00", "0.018"], ["71262.20", "0.006"], ["71265.60", "0.115"], ["71266.60", "0.003"], ["71269.60", "1.680"]], "a": [["71269.70", "3.394"], ["71270.70", "0.045"], ["71271.00", "0.045"], ["71271.70", "0.042"], ["71272.20", "0.029"], ["71272.30", "0.020"], ["71273.50", "0.048"], ["71274.10", "0.011"], ["71274.70", "0.029"], ["71274.80", "0.016"], ["71274.90", "0.012"], ["71275.10", "0.015"], ["71276.00", "0.049"], ["71277.20", "0.031"], ["71277.30", "0.018"], ["71278.50", "0.066"], ["71280.00", "0.159"], ["71286.60", "0.074"], ["71286.70", "0.000"], ["71286.90", "0.635"], ["71288.00", "0.991"], ["71288.90", "0.266"], ["71289.80", "0.075"], ["71289.90", "0.130"], ["71290.10", "0.070"], ["71291.60", "0.005"], ["71291.80", "0.009"], ["71293.30", "0.302"], ["71294.40", "0.085"], ["71295.00", "0.825"], ["71295.10", "0.204"], ["71296.80", "0.001"], ["71300.50", "0.044"], ["71302.00", "0.819"], ["71302.30", "0.321"], ["71305.30", "0.035"], ["71306.80", "0.080"], ["71309.00", "0.807"], ["71311.30", "0.773"], ["71315.20", "0.039"], ["71316.00", "1.126"], ["71316.30", "0.026"], ["71316.60", "0.002"], ["71317.00", "0.311"], ["71352.00", "0.472"], ["71363.30", "0.058"], ["71417.80", "0.252"], ["71982.40", "0.014"], ["78396.70", "0.000"]]}}
{"local_ts": 1773384661257, "server_ts": 1773384661040, "data": {"e": "depthUpdate", "E": 1773384661041, "T": 1773384661040, "s": "BTCUSDT", "U": 10101351388821, "u": 10101351397593, "pu": 10101351388777, "b": [["1000.00", "27.492"], ["5000.00", "101.438"], ["20769.60", "0.549"], ["20869.60", "0.468"], ["20969.60", "1.332"], ["21169.60", "0.351"], ["64683.30", "0.000"], ["67673.10", "0.002"], ["69129.80", "0.000"], ["70193.50", "0.000"], ["70556.90", "1.420"], ["71063.50", "0.002"], ["71063.90", "0.000"], ["71171.30", "0.017"], ["71173.20", "0.002"], ["71173.50", "0.112"], ["71180.40", "1.408"], ["71180.70", "0.072"], ["71181.20", "0.045"], ["71187.50", "0.008"], ["71187.80", "0.117"], ["71210.80", "0.245"], ["71216.90", "0.042"], ["71217.90", "0.047"], ["71218.00", "0.815"], ["71218.80", "0.046"], ["71219.80", "0.111"], ["71220.80", "0.063"], ["71220.90", "0.105"], ["71224.70", "0.004"], ["71225.00", "0.864"], ["71225.60", "0.004"], ["71226.60", "0.003"], ["71228.90", "0.002"], ["71229.20", "0.051"], ["71229.50", "0.417"], ["71229.60", "0.539"], ["71229.80", "0.000"], ["71230.60", "0.000"], ["71230.80", "0.029"], ["71231.80", "0.002"], ["71232.00", "0.893"], ["71232.10", "0.033"], ["71232.90", "0.000"], ["71233.30", "0.325"], ["71234.40", "0.005"], ["71235.40", "0.636"], ["71236.60", "1.029"], ["71238.00", "0.276"], ["71238.30", "0.010"], ["71238.60", "0.003"], ["71239.00", "0.872"], ["71241.10", "0.029"], ["71241.30", "0.003"], ["71241.70", "0.222"], ["71243.20", "0.004"], ["71243.70", "0.522"], ["71244.30", "0.313"], ["71244.40", "0.002"], ["71244.70", "0.164"], ["71244.90", "0.021"], ["71245.50", "0.012"], ["71245.80", "0.004"], ["71246.00", "0.888"], ["71246.20", "0.019"], ["71246.30", "0.023"], ["71246.80", "0.002"], ["71248.00", "0.522"], ["71249.70", "0.000"], ["71250.10", "0.507"], ["71250.40", "0.508"], ["71250.60", "1.199"], ["71251.10", "0.009"], ["71251.20", "0.631"], ["71251.40", "0.004"], ["71251.90", "0.006"], ["71255.20", "0.671"], ["71255.40", "0.005"], ["71255.60", "0.342"], ["71256.60", "0.058"], ["71256.80", "0.007"], ["71258.20", "0.003"], ["71258.90", "0.005"], ["71259.50", "0.001"], ["71259.80", "0.002"], ["71260.10", "0.002"], ["71260.50", "0.002"], ["71262.50", "0.000"], ["71266.90", "0.002"], ["71268.40", "0.245"], ["71269.50", "0.004"], ["71269.60", "1.364"]], "a": [["71276.80", "0.008"], ["71282.50", "0.253"], ["71284.90", "0.088"], ["71286.50", "1.289"], ["71287.00", "0.662"], ["71287.30", "0.214"], ["71287.80", "1.071"], ["71288.00", "0.991"], ["71288.10", "0.001"], ["71291.70", "0.641"], ["71293.30", "0.302"], ["71294.40", "0.000"], ["71295.00", "0.847"], ["71302.00", "0.819"], ["71302.40", "0.435"], ["71302.70", "0.005"], ["71309.00", "0.807"], ["71315.90", "0.023"], ["71316.00", "1.126"], ["71316.20", "0.001"], ["71337.40", "3.780"], ["71338.80", "0.508"], ["71352.00", "0.472"], ["71422.90", "0.506"], ["71496.80", "2.211"], ["71907.50", "0.000"], ["71982.40", "0.014"]]}}
{"local_ts": 1773384662278, "server_ts": 1773384662061, "data": {"e": "depthUpdate", "E": 1773384662063, "T": 1773384662061, "s": "BTCUSDT", "U": 10101351470366, "u": 10101351479776, "pu": 10101351470110, "b": [["5000.00", "101.418"], ["20769.60", "0.225"], ["20869.60", "1.548"], ["20969.60", "0.027"], ["21069.60", "0.216"], ["21169.60", "0.684"], ["67675.10", "0.002"], ["67698.00", "0.000"], ["67706.00", "0.000"], ["69130.40", "0.009"], ["69131.60", "0.003"], ["70359.90", "0.000"], ["70556.90", "1.420"], ["70900.00", "26.038"], ["70913.30", "0.000"], ["71063.50", "0.000"], ["71063.60", "0.002"], ["71191.20", "0.000"], ["71205.40", "0.005"], ["71211.70", "0.046"], ["71212.70", "0.073"], ["71214.70", "0.042"], ["71220.50", "0.073"], ["71220.60", "0.016"], ["71221.00", "0.022"], ["71221.50", "0.386"], ["71222.60", "0.132"], ["71223.90", "0.001"], ["71224.40", "0.123"], ["71225.00", "0.017"], ["71228.30", "0.000"], ["71229.50", "0.704"], ["71230.80", "0.029"], ["71234.70", "0.000"], ["71235.50", "0.247"], ["71240.70", "0.320"], ["71241.90", "0.041"], ["71242.20", "0.000"], ["71242.60", "0.011"], ["71243.10", "0.004"], ["71243.80", "0.007"], ["71244.30", "0.284"], ["71244.70", "0.164"], ["71245.20", "0.002"], ["71245.70", "0.000"], ["71245.80", "0.004"], ["71247.60", "0.000"], ["71247.70", "0.022"], ["71247.90", "0.124"], ["71248.60", "0.633"], ["71249.10", "0.081"], ["71249.50", "0.016"], ["71249.60", "0.000"], ["71249.70", "1.192"], ["71254.50", "0.559"], ["71255.80", "0.002"], ["71256.10", "0.006"], ["71256.80", "0.003"], ["71258.90", "0.005"], ["71260.00", "0.018"], ["71266.90", "0.002"], ["71269.50", "0.019"]], "a": [["71277.20", "0.033"], ["71282.50", "0.249"], ["71283.70", "0.062"], ["71284.30", "0.740"], ["71284.90", "0.003"], ["71290.90", "0.248"], ["71291.40", "0.127"], ["71291.60", "0.005"], ["71291.80", "0.017"], ["71292.00", "0.508"], ["71301.10", "0.000"], ["71315.90", "0.004"], ["71316.00", "0.321"], ["71333.90", "0.000"], ["71348.10", "0.203"], ["71578.10", "0.003"], ["71982.40", "0.014"], ["72763.50", "0.004"], ["73406.50", "0.000"], ["73407.70", "0.005"]]}}
{"local_ts": 1773384663314, "server_ts": 1773384663082, "data": {"e": "depthUpdate", "E": 1773384663083, "T": 1773384663082, "s": "BTCUSDT", "U": 10101351572273, "u": 10101351593406, "pu": 10101351572266, "b": [["1000.00", "27.492"], ["5000.00", "101.418"], ["20769.60", "1.404"], ["20769.70", "0.144"], ["20869.60", "0.162"], ["20969.70", "0.081"], ["21069.60", "0.819"], ["21069.70", "0.000"], ["21169.70", "0.090"], ["57016.00", "0.020"], ["67685.30", "0.000"], ["69131.70", "0.005"], ["70164.20", "0.423"], ["70190.20", "2.134"], ["70557.00", "0.000"], ["70912.50", "0.236"], ["70979.40", "0.000"], ["71066.00", "0.411"], ["71184.20", "0.141"], ["71195.00", "0.000"], ["71209.80", "0.023"], ["71212.70", "0.326"], ["71217.00", "1.226"], ["71218.00", "0.010"], ["71221.10", "0.004"], ["71221.80", "0.100"], ["71225.00", "0.017"], ["71225.10", "0.525"], ["71232.00", "0.088"], ["71234.10", "0.184"], ["71234.40", "0.005"], ["71235.70", "0.056"], ["71236.00", "0.510"], ["71236.50", "0.000"], ["71239.00", "0.067"], ["71241.10", "0.210"], ["71241.80", "0.299"], ["71242.10", "0.165"], ["71243.40", "0.072"], ["71244.40", "0.247"], ["71246.00", "0.083"], ["71248.70", "0.176"], ["71250.70", "0.160"], ["71250.90", "0.006"], ["71251.20", "0.007"], ["71251.80", "1.204"], ["71252.20", "0.000"], ["71252.80", "0.010"], ["71254.80", "0.042"], ["71255.40", "0.112"], ["71255.50", "0.042"], ["71255.90", "0.167"], ["71256.20", "0.295"], ["71256.50", "0.032"], ["71256.70", "0.000"], ["71256.90", "0.002"], ["71257.00", "0.006"], ["71257.20", "0.386"], ["71257.30", "0.003"], ["71257.40", "0.006"], ["71257.80", "1.140"], ["71258.20", "1.323"], ["71258.30", "0.000"], ["71258.50", "0.025"], ["71258.70", "0.236"], ["71258.80", "0.002"], ["71259.00", "0.099"], ["71259.30", "0.255"], ["71259.40", "0.047"], ["71259.50", "0.000"], ["71259.70", "0.468"], ["71259.80", "0.042"], ["71259.90", "1.081"], ["71260.10", "0.043"], ["71260.20", "0.014"], ["71260.50", "0.034"], ["71260.60", "0.034"], ["71260.80", "0.121"], ["71261.00", "0.035"], ["71261.20", "0.007"], ["71261.30", "0.641"], ["71261.50", "0.047"], ["71261.60", "0.434"], ["71263.00", "0.012"], ["71263.20", "0.075"], ["71263.80", "0.509"], ["71264.70", "0.032"], ["71265.30", "0.046"], ["71265.80", "0.004"], ["71266.10", "0.218"], ["71266.30", "0.042"], ["71266.70", "0.000"], ["71267.00", "0.001"], ["71267.50", "0.015"], ["71267.60", "0.071"], ["71268.00", "0.002"], ["71268.70", "0.001"], ["71268.90", "0.000"], ["71269.10", "0.023"], ["71269.30", "0.000"], ["71269.40", "0.252"], ["71269.70", "8.147"]], "a": [["71269.80", "0.471"], ["71269.90", "0.000"], ["71270.50", "0.005"], ["71270.80", "0.000"], ["71271.20", "0.005"], ["71271.30", "0.003"], ["71271.50", "0.004"], ["71271.70", "0.000"], ["71272.00", "0.100"], ["71272.30", "0.007"], ["71273.00", "0.008"], ["71273.10", "0.000"], ["71273.40", "0.212"], ["71273.80", "0.000"], ["71273.90", "0.000"], ["71274.10", "0.001"], ["71274.20", "0.002"], ["71274.40", "0.006"], ["71274.50", "0.009"], ["71274.80", "0.001"], ["71275.00", "0.105"], ["71275.20", "0.001"], ["71275.50", "0.007"], ["71276.00", "0.005"], ["71276.30", "0.001"], ["71276.70", "0.000"], ["71276.80", "0.008"], ["71277.00", "0.001"], ["71277.50", "0.052"], ["71277.80", "0.008"], ["71278.00", "0.021"], ["71278.10", "0.000"], ["71278.20", "0.046"], ["71278.80", "0.000"], ["71278.90", "0.002"], ["71279.20", "0.208"], ["71279.30", "0.000"], ["71279.80", "0.000"], ["71280.00", "0.147"], ["71280.10", "0.005"], ["71280.40", "0.011"], ["71280.50", "0.002"], ["71280.70", "0.002"], ["71281.00", "0.078"], ["71281.20", "0.338"], ["71281.30", "0.278"], ["71281.40", "0.060"], ["71281.60", "0.004"], ["71281.80", "0.124"], ["71281.90", "0.002"], ["71282.60", "0.005"], ["71282.70", "0.009"], ["71282.90", "0.287"], ["71283.00", "0.138"], ["71283.10", "0.086"], ["71283.20", "0.002"], ["71283.80", "0.016"], ["71284.20", "0.000"], ["71284.30", "0.007"], ["71284.40", "0.061"], ["71284.90", "0.356"], ["71285.10", "0.173"], ["71285.30", "0.003"], ["71285.40", "0.002"], ["71285.60", "0.056"], ["71286.30", "0.184"], ["71286.70", "0.000"], ["71287.20", "0.019"], ["71287.30", "0.621"], ["71287.50", "0.589"], ["71287.60", "0.154"], ["71287.70", "0.008"], ["71287.90", "0.011"], ["71288.00", "0.186"], ["71288.20", "0.020"], ["71288.80", "1.066"], ["71289.20", "0.006"], ["71289.50", "0.004"], ["71289.70", "0.031"], ["71290.10", "0.015"], ["71290.40", "0.000"], ["71290.50", "0.057"], ["71290.60", "0.010"], ["71290.70", "0.023"], ["71290.90", "0.023"], ["71291.40", "0.016"], ["71291.50", "0.004"], ["71291.70", "0.511"], ["71291.90", "0.004"], ["71292.10", "0.123"], ["71292.40", "0.003"], ["71292.50", "0.006"], ["71292.60", "0.017"], ["71292.70", "0.001"], ["71292.80", "0.446"], ["71293.00", "0.000"], ["71293.10", "0.006"], ["71293.20", "0.005"], ["71293.30", "0.064"], ["71293.40", "0.412"], ["71293.70", "0.002"], ["71293.80", "0.055"], ["71293.90", "0.006"], ["71294.10", "0.631"], ["71294.40", "0.085"], ["71294.70", "0.508"], ["71295.00", "0.033"], ["71295.70", "0.009"], ["71296.00", "0.008"], ["71296.20", "0.253"], ["71297.20", "0.102"], ["71298.10", "0.161"], ["71298.30", "0.423"], ["71298.50", "0.012"], ["71299.10", "0.031"], ["71299.40", "0.120"], ["71299.80", "1.283"], ["71300.30", "0.029"], ["71300.40", "0.001"], ["71301.20", "0.001"], ["71301.30", "0.508"], ["71301.60", "1.151"], ["71302.00", "0.014"], ["71302.30", "0.321"], ["71302.80", "0.034"], ["71303.20", "0.293"], ["71303.90", "0.000"], ["71304.10", "0.030"], ["71304.90", "0.010"], ["71305.10", "0.000"], ["71305.30", "0.036"], ["71305.40", "0.284"], ["71305.90", "0.003"], ["71306.00", "0.004"], ["71306.60", "0.336"], ["71307.00", "0.017"], ["71309.00", "0.007"], ["71313.50", "0.008"], ["71316.00", "0.321"], ["71316.20", "0.022"], ["71316.30", "0.005"], ["71316.70", "0.296"], ["71318.10", "0.117"], ["71319.80", "0.534"], ["71320.60", "0.298"], ["71323.80", "0.317"], ["71327.70", "0.298"], ["71330.90", "0.099"], ["71334.80", "0.000"], ["71338.00", "0.007"], ["71341.90", "0.019"], ["71345.10", "0.007"], ["71349.00", "0.045"], ["71352.20", "0.555"], ["71356.10", "0.650"], ["71359.20", "0.082"], ["71359.30", "0.552"], ["71363.20", "0.040"], ["71366.40", "0.026"], ["71423.00", "0.894"], ["71426.50", "0.080"], ["71426.60", "0.042"], ["71492.70", "0.292"], ["71694.60", "0.058"], ["71694.90", "0.000"], ["71982.50", "0.002"], ["73407.80", "0.036"], ["74861.00", "0.052"]]}}
{"local_ts": 1773384664320, "server_ts": 1773384664100, "data": {"e": "depthUpdate", "E": 1773384664103, "T": 1773384664100, "s": "BTCUSDT", "U": 10101351691821, "u": 10101351700920, "pu": 10101351691789, "b": [["1000.00", "27.492"], ["5000.00", "101.418"], ["20769.60", "0.342"], ["20969.70", "0.846"], ["21069.60", "0.054"], ["21169.70", "1.458"], ["33000.00", "9.339"], ["67705.00", "0.005"], ["67705.10", "0.008"], ["70557.00", "0.000"], ["70699.40", "0.848"], ["70913.40", "0.000"], ["71019.90", "0.074"], ["71109.90", "0.003"], ["71113.10", "2.440"], ["71114.20", "0.737"], ["71122.00", "0.560"], ["71124.90", "0.035"], ["71129.10", "0.129"], ["71143.00", "0.219"], ["71147.20", "0.012"], ["71147.50", "0.350"], ["71147.80", "0.109"], ["71147.90", "0.000"], ["71148.20", "0.000"], ["71148.60", "0.000"], ["71148.90", "0.204"], ["71168.30", "1.648"], ["71171.00", "0.004"], ["71180.40", "1.372"], ["71183.10", "0.005"], ["71183.20", "0.008"], ["71183.40", "1.088"], ["71183.70", "0.000"], ["71183.80", "0.052"], ["71184.10", "0.300"], ["71184.50", "0.000"], ["71184.80", "0.006"], ["71193.70", "0.042"], ["71194.00", "0.013"], ["71213.30", "0.269"], ["71213.40", "0.186"], ["71220.90", "0.103"], ["71221.00", "0.024"], ["71221.10", "0.143"], ["71233.00", "0.045"], ["71251.70", "1.238"], ["71254.80", "0.000"], ["71254.90", "0.042"], ["71255.00", "0.082"], ["71255.20", "0.574"], ["71255.50", "0.017"], ["71255.60", "0.004"], ["71255.70", "0.054"], ["71255.90", "0.003"], ["71256.10", "0.006"], ["71256.30", "0.004"], ["71256.40", "0.008"], ["71256.60", "0.001"], ["71256.70", "0.042"], ["71256.90", "0.002"], ["71257.20", "0.681"], ["71259.00", "0.000"], ["71263.40", "0.002"], ["71264.00", "0.002"], ["71265.40", "0.075"], ["71266.20", "0.000"], ["71266.90", "0.002"], ["71267.00", "0.016"], ["71267.10", "0.042"], ["71267.70", "0.001"], ["71268.60", "0.073"], ["71269.00", "0.004"]], "a": [["71269.80", "0.902"], ["71270.70", "0.003"], ["71270.80", "0.000"], ["71271.00", "0.003"], ["71272.50", "0.002"], ["71273.40", "0.212"], ["71273.90", "0.000"], ["71274.80", "0.001"], ["71274.90", "0.017"], ["71276.40", "0.000"], ["71276.90", "0.060"], ["71277.10", "0.009"], ["71278.10", "0.000"], ["71278.30", "0.046"], ["71278.70", "0.004"], ["71279.80", "0.000"], ["71280.80", "0.007"], ["71281.00", "0.010"], ["71281.10", "0.004"], ["71281.40", "0.003"], ["71281.80", "0.009"], ["71282.20", "0.002"], ["71282.50", "0.000"], ["71282.60", "0.070"], ["71282.90", "0.003"], ["71283.00", "0.073"], ["71283.30", "0.007"], ["71283.50", "0.029"], ["71292.10", "0.174"], ["71292.30", "0.052"], ["71293.60", "0.319"], ["71293.80", "0.004"], ["71316.70", "0.289"], ["71316.90", "0.009"], ["71317.30", "0.005"], ["71317.70", "0.035"], ["71318.10", "0.002"], ["71318.40", "0.014"], ["71318.50", "0.085"], ["71318.80", "0.002"], ["71318.90", "0.041"], ["71319.90", "0.131"], ["71323.80", "0.310"], ["71324.00", "0.009"], ["71324.80", "0.000"], ["71326.00", "0.017"], ["71330.90", "0.092"], ["71331.10", "0.007"], ["71333.10", "0.002"], ["71338.00", "0.000"], ["71338.20", "1.523"], ["71345.10", "0.000"], ["71345.30", "0.007"], ["71352.20", "0.548"], ["71352.40", "0.009"], ["71352.90", "0.000"], ["71353.20", "0.007"], ["71353.60", "0.040"], ["71354.00", "1.500"], ["71354.30", "0.000"], ["71354.40", "0.611"], ["71354.70", "0.014"], ["71354.80", "0.044"], ["71357.30", "0.000"], ["71359.30", "0.545"], ["71359.50", "0.007"], ["71366.40", "0.019"], ["71366.60", "2.172"], ["71366.70", "6.954"], ["71369.40", "0.086"], ["71417.40", "0.630"], ["71424.70", "0.000"], ["71426.30", "2.695"], ["71982.50", "0.000"], ["72348.60", "2.788"], ["74868.50", "0.050"], ["89523.20", "0.000"]]}}
{"local_ts": 1773384665338, "server_ts": 1773384665121, "data": {"e": "depthUpdate", "E": 1773384665123, "T": 1773384665121, "s": "BTCUSDT", "U": 10101351777497, "u": 10101351789429, "pu": 10101351777411, "b": [["5000.00", "101.418"], ["20869.70", "0.711"], ["20969.70", "0.189"], ["21069.70", "1.188"], ["21169.70", "0.612"], ["67685.60", "0.000"], ["70107.00", "0.436"], ["70221.90", "1.280"], ["70236.30", "1.706"], ["70414.50", "0.426"], ["70557.00", "0.000"], ["70932.60", "0.002"], ["71148.20", "0.061"], ["71148.90", "0.243"], ["71172.80", "0.074"], ["71174.80", "0.047"], ["71175.50", "0.140"], ["71177.80", "0.767"], ["71180.00", "0.008"], ["71182.70", "0.344"], ["71187.10", "0.002"], ["71189.80", "0.145"], ["71210.10", "0.017"], ["71218.00", "0.010"], ["71221.10", "0.002"], ["71221.20", "0.009"], ["71221.30", "0.003"], ["71225.00", "0.017"], ["71225.20", "0.172"], ["71232.00", "0.086"], ["71234.10", "0.005"], ["71239.00", "0.067"], ["71246.00", "0.083"], ["71251.00", "0.160"], ["71251.70", "0.073"], ["71255.60", "0.238"], ["71256.30", "0.133"], ["71256.90", "0.002"], ["71257.10", "0.000"], ["71258.90", "0.636"], ["71259.50", "0.007"], ["71260.00", "0.467"], ["71260.10", "0.047"], ["71260.20", "0.014"], ["71262.60", "0.176"], ["71262.70", "0.070"], ["71269.70", "8.216"]], "a": [["71276.90", "0.028"], ["71278.30", "0.004"], ["71279.50", "0.044"], ["71282.60", "0.289"], ["71286.20", "0.011"], ["71287.50", "0.604"], ["71287.70", "0.008"], ["71288.00", "0.186"], ["71288.70", "0.033"], ["71289.00", "0.006"], ["71289.70", "0.011"], ["71290.00", "0.216"], ["71290.20", "0.005"], ["71291.20", "0.042"], ["71291.50", "0.002"], ["71291.90", "0.004"], ["71292.00", "0.004"], ["71292.20", "0.057"], ["71292.50", "0.021"], ["71292.70", "0.001"], ["71292.90", "0.106"], ["71293.60", "0.391"], ["71293.80", "0.019"], ["71294.00", "0.006"], ["71294.20", "0.000"], ["71294.70", "0.589"], ["71295.00", "0.682"], ["71295.10", "0.197"], ["71295.20", "0.097"], ["71295.50", "0.002"], ["71296.00", "0.008"], ["71296.30", "0.019"], ["71296.50", "0.002"], ["71296.90", "0.538"], ["71297.30", "0.023"], ["71297.80", "0.083"], ["71297.90", "0.085"], ["71298.50", "0.014"], ["71298.60", "0.342"], ["71298.70", "0.042"], ["71298.90", "1.372"], ["71299.00", "0.446"], ["71299.20", "0.002"], ["71299.30", "0.007"], ["71299.40", "0.149"], ["71300.00", "4.979"], ["71300.30", "0.000"], ["71300.60", "0.031"], ["71301.30", "0.004"], ["71301.50", "0.002"], ["71302.00", "0.014"], ["71302.50", "0.067"], ["71302.80", "0.005"], ["71303.80", "0.005"], ["71304.00", "0.005"], ["71305.00", "0.009"], ["71305.30", "0.007"], ["71305.40", "0.256"], ["71306.10", "0.030"], ["71306.30", "0.301"], ["71307.60", "1.060"], ["71308.30", "0.033"], ["71308.80", "0.344"], ["71309.00", "0.007"], ["71309.90", "0.018"], ["71310.20", "0.009"], ["71310.30", "0.526"], ["71310.40", "0.258"], ["71310.50", "0.022"], ["71310.70", "0.842"], ["71311.80", "0.000"], ["71312.40", "0.955"], ["71315.90", "0.023"], ["71316.00", "0.321"], ["71316.50", "0.019"], ["71316.70", "0.320"], ["71316.90", "0.002"], ["71318.30", "0.009"], ["71319.80", "0.305"], ["71320.00", "0.024"], ["71321.50", "0.042"], ["71321.80", "0.075"], ["71322.30", "0.042"], ["71322.80", "1.139"], ["71323.30", "0.042"], ["71323.80", "0.310"], ["71324.00", "0.002"], ["71324.20", "0.251"], ["71325.00", "0.000"], ["71325.40", "0.007"], ["71325.80", "0.508"], ["71326.20", "0.002"], ["71326.80", "0.016"], ["71327.40", "0.306"], ["71327.80", "1.197"], ["71331.10", "0.000"], ["71332.40", "0.250"], ["71332.50", "0.513"], ["71336.10", "0.966"], ["71338.20", "1.516"], ["71339.60", "0.007"], ["71344.20", "0.360"], ["71344.30", "0.000"], ["71345.30", "0.000"], ["71346.70", "0.019"], ["71347.70", "0.004"], ["71348.40", "0.217"], ["71348.60", "0.000"], ["71349.60", "0.000"], ["71351.30", "0.030"], ["71352.40", "0.002"], ["71353.20", "0.007"], ["71353.80", "0.021"], ["71354.20", "0.000"], ["71355.20", "0.018"], ["71355.50", "0.127"], ["71359.50", "0.000"], ["71360.90", "0.168"], ["71366.60", "2.165"], ["71368.00", "0.009"], ["71385.00", "0.000"], ["71496.60", "0.000"], ["71982.50", "0.000"], ["72491.10", "3.448"], ["72552.70", "0.482"], ["74844.20", "0.002"], ["89523.20", "0.000"]]}}
{"local_ts": 1773384666374, "server_ts": 1773384666144, "data": {"e": "depthUpdate", "E": 1773384666147, "T": 1773384666144, "s": "BTCUSDT", "U": 10101351870058, "u": 10101351876335, "pu": 10101351870049, "b": [["1000.00", "27.492"], ["5000.00", "101.398"], ["20769.70", "0.585"], ["20869.70", "0.315"], ["20969.70", "0.918"], ["21069.70", "0.882"], ["33000.00", "9.343"], ["57016.00", "0.000"], ["67684.50", "0.004"], ["67706.20", "0.014"], ["70557.00", "0.000"], ["70932.60", "0.000"], ["70934.40", "0.002"], ["71112.90", "0.075"], ["71120.00", "16.254"], ["71120.80", "0.128"], ["71121.20", "12.347"], ["71121.30", "5.612"], ["71152.20", "0.045"], ["71153.50", "0.094"], ["71180.30", "6.320"], ["71180.60", "2.656"], ["71184.20", "0.276"], ["71200.00", "3.445"], ["71212.70", "0.564"], ["71213.10", "0.274"], ["71215.90", "3.482"], ["71237.40", "1.790"], ["71239.60", "0.246"], ["71241.60", "0.035"], ["71243.00", "0.032"], ["71243.80", "0.007"], ["71253.10", "1.686"], ["71253.20", "1.201"], ["71253.80", "0.005"], ["71254.10", "0.080"], ["71256.90", "0.002"], ["71259.00", "0.000"], ["71260.00", "0.014"], ["71260.10", "0.009"], ["71262.60", "0.007"], ["71267.30", "0.002"], ["71269.70", "3.873"]], "a": [["71269.80", "2.590"], ["71269.90", "0.211"], ["71276.90", "0.000"], ["71282.60", "0.289"], ["71286.30", "0.169"], ["71287.30", "0.214"], ["71288.20", "0.020"], ["71288.60", "0.073"], ["71288.70", "0.018"], ["71289.00", "0.889"], ["71289.40", "0.122"], ["71289.50", "0.002"], ["71289.70", "0.011"], ["71290.40", "0.042"], ["71290.50", "0.064"], ["71290.60", "0.061"], ["71290.70", "0.023"], ["71291.40", "0.043"], ["71291.50", "0.002"], ["71292.40", "0.073"], ["71292.50", "0.006"], ["71299.60", "0.204"], ["71300.50", "0.044"], ["71301.00", "0.000"], ["71301.50", "0.002"], ["71302.30", "0.321"], ["71303.30", "0.002"], ["71304.20", "0.010"], ["71312.30", "1.760"], ["71314.70", "0.529"], ["71315.60", "0.004"], ["71315.80", "0.005"], ["71316.30", "0.003"], ["71318.30", "0.002"], ["71320.30", "0.009"], ["71325.40", "0.000"], ["71327.40", "0.313"], ["71332.50", "0.506"], ["71333.70", "3.278"], ["71334.50", "0.007"], ["71339.60", "0.000"], ["71341.60", "0.010"], ["71346.70", "0.012"], ["71348.70", "0.007"], ["71353.80", "0.014"], ["71355.80", "0.007"], ["71360.90", "0.161"], ["71362.90", "0.024"], ["71368.00", "0.002"], ["71368.90", "7.224"], ["71370.00", "0.556"], ["71427.90", "14.387"], ["71458.70", "2.347"], ["71484.70", "0.000"], ["71982.50", "1.387"], ["72303.20", "1.658"], ["89523.20", "0.000"]]}}
{"local_ts": 1773384667385, "server_ts": 1773384667168, "data": {"e": "depthUpdate", "E": 1773384667169, "T": 1773384667168, "s": "BTCUSDT", "U": 10101351926221, "u": 10101351931829, "pu": 10101351925970, "b": [["5000.00", "101.438"], ["20769.70", "0.450"], ["20869.70", "0.648"], ["20969.70", "1.152"], ["21169.70", "0.450"], ["67706.20", "0.016"], ["70065.20", "0.285"], ["70492.90", "0.988"], ["70557.00", "1.422"], ["70646.90", "0.000"], ["70913.40", "0.000"], ["70934.40", "0.000"], ["70934.70", "0.002"], ["71152.30", "0.000"], ["71184.20", "0.137"], ["71191.30", "1.205"], ["71205.20", "0.005"], ["71205.50", "0.003"], ["71210.90", "0.180"], ["71213.10", "0.090"], ["71238.60", "0.003"], ["71243.80", "0.191"], ["71247.00", "0.007"], ["71247.90", "0.126"], ["71258.90", "0.005"], ["71260.00", "0.018"], ["71263.20", "0.046"], ["71265.90", "0.042"], ["71267.50", "0.026"], ["71268.10", "0.005"], ["71269.70", "3.878"]], "a": [["71269.80", "2.613"], ["71270.80", "0.000"], ["71271.80", "0.002"], ["71275.10", "0.008"], ["71275.50", "0.694"], ["71276.10", "0.004"], ["71276.50", "0.049"], ["71277.00", "0.241"], ["71277.50", "0.094"], ["71278.00", "0.002"], ["71279.00", "0.002"], ["71294.70", "0.589"], ["71296.10", "0.247"], ["71298.30", "0.635"], ["71313.90", "0.018"], ["71315.50", "0.340"], ["71315.60", "0.006"], ["71316.00", "0.342"], ["71320.30", "0.002"], ["71320.60", "0.305"], ["71327.40", "0.306"], ["71327.70", "0.305"], ["71334.00", "0.007"], ["71334.50", "0.000"], ["71334.80", "0.007"], ["71341.60", "0.003"], ["71341.90", "0.026"], ["71348.20", "0.005"], ["71348.70", "0.000"], ["71349.00", "0.052"], ["71355.80", "0.000"], ["71356.10", "0.594"], ["71362.90", "0.017"], ["71363.20", "0.047"], ["71370.00", "0.549"], ["71370.30", "0.007"], ["71451.50", "0.000"], ["71496.60", "0.006"], ["71789.80", "0.000"], ["71797.60", "0.000"], ["71982.50", "1.394"], ["72602.50", "0.344"], ["74833.20", "0.009"], ["74859.50", "0.050"], ["89523.20", "0.000"]]}}
{"local_ts": 1773384668410, "server_ts": 1773384668190, "data": {"e": "depthUpdate", "E": 1773384668191, "T": 1773384668190, "s": "BTCUSDT", "U": 10101351996043, "u": 10101352042866, "pu": 10101351995765, "b": [["1000.00", "27.492"], ["5000.00", "101.418"], ["20759.80", "0.063"], ["20760.20", "0.018"], ["20760.30", "0.027"], ["20760.60", "0.009"], ["20769.70", "0.270"], ["20869.70", "1.413"], ["20969.70", "0.000"], ["21059.80", "0.036"], ["21060.30", "0.018"], ["21062.60", "0.009"], ["21069.70", "0.252"], ["21169.70", "0.585"], ["67272.70", "0.044"], ["67450.20", "0.000"], ["67627.70", "0.054"], ["67678.70", "0.023"], ["67805.20", "0.000"], ["67856.40", "0.000"], ["67982.70", "0.019"], ["68160.20", "0.200"], ["69834.70", "0.003"], ["70236.30", "2.701"], ["70460.00", "1.824"], ["70547.20", "0.004"], ["70547.60", "0.710"], ["70547.70", "0.000"], ["70556.90", "2.482"], ["70822.10", "0.315"], ["70928.10", "0.002"], ["70931.70", "0.002"], ["70934.70", "0.000"], ["70935.00", "0.018"], ["70950.10", "0.000"], ["70952.00", "6.485"], ["70952.10", "2.507"], ["70959.50", "0.291"], ["70960.30", "0.323"], ["70961.60", "0.296"], ["70963.60", "0.003"], ["70966.40", "6.767"], ["70967.40", "0.294"], ["70970.50", "0.003"], ["70972.30", "0.116"], ["70999.10", "2.034"], ["71020.10", "2.817"], ["71021.60", "0.001"], ["71034.60", "0.000"], ["71043.50", "0.162"], ["71052.60", "0.044"], ["71056.10", "4.906"], ["71056.60", "0.045"], ["71056.90", "0.077"], ["71060.40", "0.003"], ["71063.80", "0.041"], ["71068.20", "0.078"], ["71069.90", "0.000"], ["71070.00", "16.173"], ["71071.40", "0.062"], ["71073.90", "0.245"], ["71076.70", "0.328"], ["71099.10", "0.077"], ["71099.30", "2.004"], ["71101.30", "0.080"], ["71105.40", "0.624"], ["71105.50", "0.100"], ["71106.00", "0.299"], ["71110.10", "3.517"], ["71110.70", "0.141"], ["71111.60", "0.036"], ["71112.00", "0.072"], ["71112.50", "0.105"], ["71112.70", "0.100"], ["71112.90", "0.175"], ["71113.70", "0.104"], ["71114.20", "0.697"], ["71114.60", "0.547"], ["71115.10", "0.100"], ["71115.30", "0.089"], ["71116.10", "0.039"], ["71120.20", "0.000"], ["71121.30", "5.612"], ["71129.70", "0.506"], ["71135.40", "0.437"], ["71137.50", "0.508"], ["71139.60", "0.002"], ["71141.10", "0.355"], ["71142.00", "0.006"], ["71145.50", "0.119"], ["71145.60", "0.042"], ["71146.50", "0.000"], ["71147.50", "0.494"], ["71148.50", "0.000"], ["71149.00", "0.022"], ["71149.20", "0.198"], ["71149.40", "0.002"], ["71150.10", "3.323"], ["71150.40", "0.338"], ["71151.00", "0.294"], ["71151.10", "0.347"], ["71151.40", "0.000"], ["71152.30", "0.000"], ["71154.00", "0.005"], ["71155.30", "0.078"], ["71155.40", "0.078"], ["71156.10", "0.303"], ["71156.80", "0.183"], ["71157.50", "0.070"], ["71161.50", "0.078"], ["71162.00", "1.886"], ["71162.50", "0.075"], ["71163.00", "1.243"], ["71163.60", "0.078"], ["71164.70", "0.086"], ["71165.30", "0.295"], ["71165.70", "0.003"], ["71166.10", "0.297"], ["71166.70", "0.099"], ["71166.90", "0.523"], ["71167.60", "0.009"], ["71167.90", "0.099"], ["71168.00", "2.005"], ["71168.50", "0.000"], ["71168.60", "0.002"], ["71169.60", "0.000"], ["71169.70", "0.298"], ["71169.80", "0.003"], ["71170.00", "0.308"], ["71170.50", "1.070"], ["71170.90", "0.010"], ["71171.50", "1.309"], ["71171.80", "0.070"], ["71172.20", "0.021"], ["71172.50", "0.090"], ["71173.20", "0.000"], ["71173.30", "0.298"], ["71173.50", "0.000"], ["71173.60", "0.000"], ["71174.40", "0.016"], ["71174.80", "1.247"], ["71175.90", "0.075"], ["71176.10", "0.599"], ["71176.20", "0.000"], ["71176.60", "0.002"], ["71178.10", "0.004"], ["71179.70", "0.001"], ["71180.60", "2.017"], ["71180.80", "0.044"], ["71180.90", "0.025"], ["71181.00", "0.032"], ["71181.50", "0.000"], ["71182.40", "0.000"], ["71183.70", "0.263"], ["71183.90", "0.184"], ["71184.00", "0.190"], ["71184.20", "0.038"], ["71184.50", "0.061"], ["71185.00", "0.173"], ["71185.40", "0.004"], ["71185.70", "0.141"], ["71186.40", "0.080"], ["71187.40", "0.000"], ["71187.60", "0.005"], ["71187.90", "0.000"], ["71188.50", "0.000"], ["71188.60", "0.045"], ["71188.90", "0.358"], ["71189.40", "0.019"], ["71189.60", "0.000"], ["71190.60", "0.000"], ["71190.80", "0.011"], ["71191.10", "0.005"], ["71191.30", "1.202"], ["71191.50", "0.506"], ["71191.60", "0.551"], ["71191.90", "0.002"], ["71192.40", "0.040"], ["71192.50", "0.000"], ["71192.80", "0.000"], ["71193.10", "0.003"], ["71193.50", "0.000"], ["71193.80", "0.000"], ["71194.40", "0.000"], ["71194.50", "0.043"], ["71194.60", "0.211"], ["71194.80", "0.007"], ["71195.00", "0.000"], ["71195.40", "0.001"], ["71195.50", "0.000"], ["71195.70", "0.000"], ["71195.80", "0.000"], ["71196.00", "1.053"], ["71196.30", "0.002"], ["71196.40", "0.002"], ["71196.60", "0.040"], ["71196.70", "0.000"], ["71197.00", "0.895"], ["71197.20", "0.040"], ["71197.30", "0.057"], ["71197.60", "0.000"], ["71197.70", "0.002"], ["71198.00", "0.042"], ["71198.30", "0.258"], ["71198.90", "0.041"], ["71199.20", "0.101"], ["71199.40", "0.042"], ["71199.80", "0.023"], ["71200.00", "3.519"], ["71200.20", "0.027"], ["71200.30", "0.001"], ["71200.40", "0.000"], ["71200.50", "0.372"], ["71200.60", "0.093"], ["71200.70", "0.046"], ["71200.80", "0.002"], ["71201.20", "0.054"], ["71201.30", "0.005"], ["71201.60", "0.002"], ["71201.70", "0.002"], ["71201.90", "0.037"], ["71202.40", "0.329"], ["71203.00", "0.004"], ["71203.20", "0.086"], ["71203.50", "0.043"], ["71203.60", "0.002"], ["71203.90", "0.001"], ["71204.00", "0.004"], ["71204.20", "0.510"], ["71204.30", "0.000"], ["71204.40", "0.751"], ["71204.90", "0.000"], ["71205.00", "0.009"], ["71205.20", "0.005"], ["71205.30", "0.075"], ["71205.50", "0.000"], ["71205.70", "0.729"], ["71205.80", "0.000"], ["71206.50", "0.854"], ["71206.80", "0.606"], ["71206.90", "0.029"], ["71207.50", "0.006"], ["71207.60", "0.003"], ["71208.00", "0.002"], ["71208.40", "0.146"], ["71208.50", "0.594"], ["71208.70", "0.097"], ["71209.60", "0.088"], ["71210.00", "0.077"], ["71210.30", "0.208"], ["71210.40", "0.132"], ["71210.60", "0.679"], ["71210.70", "0.244"], ["71210.80", "0.002"], ["71210.90", "0.061"], ["71211.00", "0.049"], ["71211.10", "0.005"], ["71211.30", "0.004"], ["71211.70", "0.004"], ["71211.80", "0.021"], ["71211.90", "1.271"], ["71212.00", "0.846"], ["71212.10", "0.276"], ["71212.20", "0.280"], ["71212.30", "0.002"], ["71212.60", "0.142"], ["71212.70", "0.167"], ["71212.90", "0.637"], ["71213.50", "0.074"], ["71213.60", "0.007"], ["71213.90", "0.003"], ["71214.00", "0.268"], ["71214.10", "0.298"], ["71214.40", "0.020"], ["71214.60", "0.042"], ["71214.80", "0.000"], ["71215.00", "0.000"], ["71215.70", "0.012"], ["71215.80", "0.090"], ["71215.90", "0.024"], ["71216.20", "0.004"], ["71216.50", "0.019"], ["71216.70", "0.100"], ["71216.80", "0.003"], ["71217.00", "0.026"], ["71217.10", "0.073"], ["71217.20", "0.025"], ["71217.50", "0.005"], ["71217.70", "2.194"], ["71217.80", "0.465"], ["71218.00", "0.013"], ["71218.50", "0.002"], ["71218.70", "0.005"], ["71218.90", "0.032"], ["71219.20", "0.000"], ["71219.70", "0.029"], ["71219.80", "0.041"], ["71220.30", "0.010"], ["71220.40", "0.002"], ["71220.50", "0.075"], ["71220.80", "0.019"], ["71220.90", "0.105"], ["71221.20", "0.007"], ["71221.30", "0.001"], ["71221.40", "0.113"], ["71221.60", "0.382"], ["71221.90", "0.012"], ["71222.00", "0.081"], ["71222.40", "0.000"], ["71223.00", "0.011"], ["71223.50", "0.000"], ["71223.60", "0.233"], ["71223.90", "0.071"], ["71224.10", "1.049"], ["71224.30", "0.000"], ["71224.40", "0.123"], ["71224.80", "1.588"], ["71225.00", "0.021"], ["71225.20", "0.060"], ["71225.50", "0.013"], ["71226.10", "0.278"], ["71226.20", "0.002"], ["71226.40", "0.052"], ["71226.70", "0.017"], ["71226.80", "0.000"], ["71226.90", "0.003"], ["71227.30", "0.000"], ["71227.40", "0.300"], ["71227.70", "0.005"], ["71227.80", "2.021"], ["71228.10", "0.085"], ["71228.30", "0.003"], ["71228.70", "0.002"], ["71228.90", "0.002"], ["71229.60", "0.004"], ["71229.70", "0.098"], ["71229.90", "0.021"], ["71230.00", "0.013"], ["71230.30", "0.000"], ["71230.50", "0.086"], ["71230.60", "0.000"], ["71230.80", "0.029"], ["71230.90", "0.004"], ["71231.10", "0.000"], ["71231.20", "0.042"], ["71231.30", "0.030"], ["71231.60", "0.036"], ["71231.70", "0.507"], ["71231.90", "0.018"], ["71232.00", "0.099"], ["71232.20", "0.506"], ["71232.40", "0.000"], ["71232.60", "0.002"], ["71232.70", "0.000"], ["71233.20", "0.011"], ["71233.30", "0.300"], ["71233.40", "0.296"], ["71233.80", "0.507"], ["71233.90", "0.151"], ["71234.00", "0.009"], ["71234.10", "0.003"], ["71234.40", "0.009"], ["71234.70", "1.193"], ["71234.80", "0.000"], ["71235.10", "0.067"], ["71235.40", "0.636"], ["71235.50", "0.002"], ["71235.60", "0.000"], ["71235.70", "0.057"], ["71235.80", "1.051"], ["71235.90", "0.129"], ["71236.00", "0.011"], ["71236.10", "1.328"], ["71236.20", "0.009"], ["71236.60", "0.300"], ["71236.70", "0.006"], ["71236.80", "0.012"], ["71236.90", "0.004"], ["71237.00", "0.009"], ["71237.10", "0.000"], ["71237.30", "0.604"], ["71237.40", "0.000"], ["71237.50", "0.004"], ["71237.60", "0.001"], ["71237.70", "0.357"], ["71237.90", "1.992"], ["71238.00", "0.103"], ["71238.10", "0.142"], ["71238.20", "0.310"], ["71238.30", "0.017"], ["71238.40", "0.000"], ["71238.70", "0.000"], ["71238.80", "0.002"], ["71238.90", "0.000"], ["71239.00", "0.079"], ["71239.10", "0.298"], ["71239.20", "0.003"], ["71239.40", "0.000"], ["71239.50", "0.740"], ["71239.60", "0.001"], ["71239.70", "0.001"], ["71239.80", "0.285"], ["71239.90", "0.000"], ["71240.10", "0.513"], ["71240.30", "0.006"], ["71240.40", "0.005"], ["71240.50", "0.004"], ["71240.60", "0.048"], ["71240.70", "0.003"], ["71240.80", "0.287"], ["71240.90", "0.003"], ["71241.10", "0.000"], ["71241.40", "0.011"], ["71241.50", "1.391"], ["71241.60", "0.031"], ["71241.70", "0.000"], ["71241.80", "0.005"], ["71241.90", "0.014"], ["71242.10", "0.256"], ["71242.40", "0.012"], ["71242.50", "0.008"], ["71242.60", "0.019"], ["71242.80", "0.072"], ["71242.90", "0.002"], ["71243.00", "0.004"], ["71243.10", "0.510"], ["71243.30", "0.800"], ["71243.40", "0.005"], ["71243.50", "0.000"], ["71243.60", "0.000"], ["71243.70", "0.001"], ["71243.80", "0.102"], ["71244.10", "0.000"], ["71244.30", "0.284"], ["71244.40", "0.002"], ["71244.50", "0.071"], ["71244.60", "0.033"], ["71244.70", "0.001"], ["71244.80", "0.002"], ["71244.90", "0.006"], ["71245.10", "0.001"], ["71245.20", "0.002"], ["71245.30", "0.009"], ["71245.40", "0.004"], ["71245.50", "0.005"], ["71245.60", "0.509"], ["71245.80", "0.004"], ["71245.90", "0.002"], ["71246.00", "0.122"], ["71246.40", "0.005"], ["71246.60", "0.004"], ["71246.70", "0.002"], ["71247.20", "0.004"], ["71247.30", "0.113"], ["71247.40", "0.536"], ["71247.50", "0.007"], ["71247.80", "0.001"], ["71247.90", "0.126"], ["71248.00", "0.016"], ["71248.10", "0.003"], ["71248.20", "1.052"], ["71248.30", "0.506"], ["71248.40", "0.044"], ["71248.50", "0.122"], ["71248.60", "0.007"], ["71248.70", "0.096"], ["71248.90", "0.003"], ["71249.00", "0.000"], ["71249.10", "0.002"], ["71249.20", "0.005"], ["71249.40", "0.000"], ["71249.50", "0.009"], ["71249.80", "0.008"], ["71249.90", "0.033"], ["71250.00", "0.031"], ["71250.30", "0.006"], ["71250.40", "0.000"], ["71250.50", "0.267"], ["71250.80", "0.036"], ["71250.90", "0.003"], ["71251.00", "0.004"], ["71251.10", "0.009"], ["71251.20", "0.025"], ["71251.30", "0.003"], ["71251.40", "0.004"], ["71251.50", "0.002"], ["71251.80", "0.001"], ["71251.90", "0.005"], ["71252.00", "0.007"], ["71252.10", "0.004"], ["71252.20", "0.000"], ["71252.30", "0.022"], ["71252.40", "0.000"], ["71252.70", "0.214"], ["71252.90", "0.006"], ["71253.00", "0.011"], ["71253.10", "0.006"], ["71253.20", "0.013"], ["71253.40", "0.000"], ["71253.80", "0.002"], ["71253.90", "0.003"], ["71254.00", "0.387"], ["71254.10", "0.003"], ["71254.20", "0.000"], ["71254.40", "0.004"], ["71254.50", "0.120"], ["71254.90", "0.002"], ["71255.00", "0.010"], ["71255.20", "0.001"], ["71255.30", "0.010"], ["71255.40", "0.003"], ["71255.50", "0.000"], ["71255.60", "0.004"], ["71255.70", "0.012"], ["71255.90", "0.003"], ["71256.00", "0.004"], ["71256.10", "0.006"], ["71256.30", "0.004"], ["71256.60", "0.001"], ["71257.00", "0.000"], ["71257.20", "0.004"], ["71257.60", "1.683"], ["71257.70", "0.004"], ["71257.80", "0.021"], ["71258.00", "0.006"], ["71258.20", "0.005"], ["71258.30", "0.002"], ["71258.50", "0.006"], ["71258.60", "0.055"], ["71258.70", "0.002"], ["71258.90", "0.002"], ["71259.00", "0.000"], ["71259.10", "0.001"], ["71259.20", "0.001"], ["71259.30", "0.009"], ["71259.40", "0.004"], ["71259.50", "0.000"], ["71259.60", "0.006"], ["71259.70", "0.004"], ["71259.80", "2.048"], ["71259.90", "0.000"], ["71260.00", "0.000"], ["71260.10", "0.000"], ["71260.20", "0.000"], ["71260.30", "0.000"], ["71260.50", "0.000"], ["71260.60", "0.000"], ["71260.80", "0.000"], ["71260.90", "0.000"], ["71261.00", "0.000"], ["71261.20", "0.000"], ["71261.30", "0.000"], ["71261.40", "0.000"], ["71261.50", "0.000"], ["71261.60", "0.000"], ["71261.70", "0.000"], ["71261.80", "0.000"], ["71261.90", "0.000"], ["71262.00", "0.000"], ["71262.20", "0.000"], ["71262.30", "0.000"], ["71262.40", "0.000"], ["71262.60", "0.000"], ["71262.70", "0.000"], ["71262.80", "0.000"], ["71262.90", "0.000"], ["71263.10", "0.000"], ["71263.20", "0.000"], ["71263.40", "0.000"], ["71263.50", "0.000"], ["71263.70", "0.000"], ["71263.80", "0.000"], ["71263.90", "0.000"], ["71264.00", "0.000"], ["71264.10", "0.000"], ["71264.20", "0.000"], ["71264.30", "0.000"], ["71264.60", "0.000"], ["71264.70", "0.000"], ["71264.90", "0.000"], ["71265.00", "0.000"], ["71265.10", "0.000"], ["71265.30", "0.000"], ["71265.40", "0.000"], ["71265.60", "0.000"], ["71265.70", "0.000"], ["71265.80", "0.000"], ["71266.00", "0.000"], ["71266.10", "0.000"], ["71266.40", "0.000"], ["71266.60", "0.000"], ["71266.80", "0.000"], ["71266.90", "0.000"], ["71267.00", "0.000"], ["71267.20", "0.000"], ["71267.40", "0.000"], ["71267.50", "0.000"], ["71267.70", "0.000"], ["71267.80", "0.000"], ["71267.90", "0.000"], ["71268.10", "0.000"], ["71268.20", "0.000"], ["71268.30", "0.000"], ["71268.40", "0.000"], ["71268.60", "0.000"], ["71268.70", "0.000"], ["71269.00", "0.000"], ["71269.10", "0.000"], ["71269.20", "0.000"], ["71269.40", "0.000"], ["71269.50", "0.000"], ["71269.60", "0.000"], ["71269.70", "0.000"]], "a": [["71259.90", "6.829"], ["71260.00", "0.004"], ["71260.10", "0.002"], ["71260.20", "0.127"], ["71260.30", "1.102"], ["71260.40", "0.252"], ["71260.50", "0.000"], ["71260.60", "1.100"], ["71260.70", "0.002"], ["71260.80", "0.000"], ["71260.90", "0.043"], ["71261.00", "0.000"], ["71261.10", "0.000"], ["71261.30", "0.000"], ["71261.40", "0.044"], ["71261.50", "0.000"], ["71261.60", "0.003"], ["71261.70", "0.000"], ["71261.80", "0.004"], ["71261.90", "0.014"], ["71262.00", "0.014"], ["71262.10", "0.017"], ["71262.20", "0.000"], ["71262.30", "0.014"], ["71262.40", "0.046"], ["71262.50", "0.017"], ["71262.60", "0.000"], ["71262.70", "0.003"], ["71262.80", "0.000"], ["71262.90", "0.003"], ["71263.00", "0.014"], ["71263.20", "0.015"], ["71263.30", "0.000"], ["71263.50", "0.010"], ["71263.60", "0.000"], ["71263.70", "0.000"], ["71263.80", "0.007"], ["71263.90", "0.001"], ["71264.00", "0.004"], ["71264.10", "0.000"], ["71264.20", "0.021"], ["71264.30", "0.002"], ["71264.40", "0.000"], ["71264.50", "0.002"], ["71264.60", "0.003"], ["71264.70", "0.000"], ["71264.80", "0.000"], ["71264.90", "0.009"], ["71265.00", "0.005"], ["71265.10", "0.000"], ["71265.20", "0.000"], ["71265.30", "0.110"], ["71265.40", "0.237"], ["71265.50", "0.005"], ["71265.60", "0.217"], ["71265.70", "0.005"], ["71265.80", "0.000"], ["71265.90", "0.000"], ["71266.00", "0.065"], ["71266.10", "0.000"], ["71266.20", "0.000"], ["71266.30", "0.002"], ["71266.40", "0.007"], ["71266.50", "0.002"], ["71266.70", "0.004"], ["71266.80", "0.003"], ["71267.00", "0.010"], ["71267.10", "0.002"], ["71267.30", "0.000"], ["71267.40", "0.003"], ["71267.50", "0.001"], ["71267.60", "0.002"], ["71267.80", "0.000"], ["71267.90", "0.000"], ["71268.00", "0.291"], ["71268.20", "0.005"], ["71268.30", "0.066"], ["71268.40", "0.000"], ["71268.50", "0.000"], ["71268.60", "0.000"], ["71268.70", "0.000"], ["71268.80", "0.272"], ["71268.90", "0.001"], ["71269.00", "0.048"], ["71269.10", "0.006"], ["71269.20", "0.002"], ["71269.30", "0.003"], ["71269.40", "0.124"], ["71269.50", "0.540"], ["71269.60", "0.003"], ["71269.70", "1.793"], ["71269.80", "0.181"], ["71269.90", "0.004"], ["71270.00", "0.011"], ["71270.10", "0.109"], ["71270.30", "0.022"], ["71270.50", "0.005"], ["71270.70", "0.011"], ["71270.80", "0.002"], ["71270.90", "0.003"], ["71271.00", "0.004"], ["71271.10", "0.104"], ["71271.20", "0.007"], ["71271.40", "0.000"], ["71271.50", "0.002"], ["71271.60", "0.129"], ["71271.80", "0.002"], ["71271.90", "0.033"], ["71272.00", "0.090"], ["71272.10", "0.005"], ["71272.20", "0.376"], ["71272.30", "0.048"], ["71272.40", "0.016"], ["71272.50", "0.034"], ["71272.60", "0.060"], ["71272.70", "0.002"], ["71272.90", "0.073"], ["71273.10", "0.017"], ["71273.20", "0.006"], ["71273.30", "0.038"], ["71273.40", "0.217"], ["71273.50", "0.004"], ["71273.60", "0.004"], ["71273.70", "0.638"], ["71273.80", "0.026"], ["71273.90", "0.332"], ["71274.00", "0.007"], ["71274.20", "0.002"], ["71274.30", "0.372"], ["71274.50", "0.009"], ["71274.60", "0.005"], ["71274.70", "0.002"], ["71274.80", "0.001"], ["71274.90", "0.017"], ["71275.00", "0.103"], ["71275.20", "0.001"], ["71275.30", "0.007"], ["71275.40", "0.082"], ["71275.50", "0.003"], ["71275.60", "1.615"], ["71275.70", "0.004"], ["71275.90", "0.000"], ["71276.00", "0.005"], ["71276.10", "0.000"], ["71276.20", "0.004"], ["71276.30", "0.001"], ["71276.40", "0.000"], ["71276.50", "0.007"], ["71276.70", "0.509"], ["71276.80", "0.451"], ["71276.90", "1.069"], ["71277.00", "0.201"], ["71277.10", "0.024"], ["71277.20", "0.004"], ["71277.30", "0.003"], ["71277.50", "0.003"], ["71277.60", "0.004"], ["71277.70", "0.000"], ["71277.90", "0.002"], ["71278.00", "0.002"], ["71278.10", "0.120"], ["71278.30", "0.004"], ["71278.40", "0.000"], ["71278.50", "0.019"], ["71278.70", "0.004"], ["71278.80", "0.319"], ["71278.90", "0.532"], ["71279.00", "0.002"], ["71279.10", "0.353"], ["71279.20", "0.007"], ["71279.40", "0.007"], ["71279.50", "0.000"], ["71279.60", "0.046"], ["71279.70", "0.006"], ["71279.80", "0.002"], ["71279.90", "0.076"], ["71280.00", "0.067"], ["71280.20", "0.015"], ["71280.30", "0.008"], ["71280.40", "0.009"], ["71280.50", "0.004"], ["71280.60", "0.522"], ["71280.70", "0.203"], ["71280.80", "0.019"], ["71280.90", "0.023"], ["71281.00", "0.010"], ["71281.10", "0.565"], ["71281.20", "0.425"], ["71281.30", "0.007"], ["71281.50", "0.117"], ["71281.60", "0.004"], ["71281.70", "0.000"], ["71281.80", "0.009"], ["71281.90", "0.117"], ["71282.00", "0.012"], ["71282.30", "0.052"], ["71282.40", "0.056"], ["71282.50", "0.000"], ["71282.60", "0.289"], ["71282.70", "0.074"], ["71282.80", "0.207"], ["71282.90", "1.072"], ["71283.00", "0.036"], ["71283.70", "0.062"], ["71283.90", "0.004"], ["71284.10", "0.036"], ["71284.20", "0.009"], ["71284.30", "0.005"], ["71284.60", "0.129"], ["71284.70", "0.000"], ["71284.80", "0.459"], ["71284.90", "0.356"], ["71285.10", "0.018"], ["71285.30", "0.003"], ["71285.60", "0.004"], ["71285.80", "0.000"], ["71286.30", "0.017"], ["71286.40", "0.507"], ["71286.60", "0.010"], ["71286.80", "0.000"], ["71286.90", "0.002"], ["71287.10", "0.001"], ["71287.20", "0.019"], ["71287.50", "0.105"], ["71287.60", "0.058"], ["71287.90", "0.578"], ["71288.00", "0.886"], ["71288.10", "0.006"], ["71288.20", "0.020"], ["71288.40", "0.004"], ["71288.50", "0.003"], ["71288.60", "0.003"], ["71288.90", "0.266"], ["71289.30", "0.054"], ["71289.40", "0.010"], ["71289.50", "0.002"], ["71289.60", "0.012"], ["71289.70", "0.009"], ["71289.80", "0.011"], ["71290.10", "0.000"], ["71290.20", "0.005"], ["71290.30", "0.004"], ["71290.50", "0.002"], ["71290.70", "0.023"], ["71290.80", "0.009"], ["71290.90", "0.003"], ["71291.00", "0.002"], ["71291.10", "0.362"], ["71291.20", "0.025"], ["71291.40", "0.001"], ["71291.50", "0.011"], ["71291.60", "0.009"], ["71291.90", "0.004"], ["71292.10", "0.000"], ["71292.20", "0.028"], ["71292.30", "0.023"], ["71292.40", "0.003"], ["71292.60", "0.055"], ["71292.80", "0.320"], ["71293.20", "0.005"], ["71293.40", "0.308"], ["71293.60", "0.321"], ["71293.70", "0.004"], ["71293.80", "0.002"], ["71294.30", "0.004"], ["71294.40", "0.000"], ["71294.50", "0.000"], ["71294.70", "0.508"], ["71294.80", "0.031"], ["71295.00", "0.036"], ["71295.10", "0.197"], ["71295.60", "0.002"], ["71295.70", "0.000"], ["71295.80", "0.001"], ["71295.90", "0.019"], ["71296.00", "0.169"], ["71296.20", "0.253"], ["71296.40", "0.312"], ["71296.50", "0.031"], ["71297.00", "0.324"], ["71297.10", "0.033"], ["71297.20", "0.310"], ["71297.30", "0.127"], ["71297.80", "0.112"], ["71297.90", "0.000"], ["71298.00", "0.467"], ["71298.10", "0.057"], ["71298.20", "0.131"], ["71298.30", "0.225"], ["71298.40", "0.037"], ["71298.70", "0.051"], ["71298.80", "0.085"], ["71298.90", "1.372"], ["71299.10", "0.318"], ["71299.20", "0.002"], ["71299.30", "0.000"], ["71299.60", "0.065"], ["71299.70", "0.058"], ["71299.80", "1.066"], ["71299.90", "0.058"], ["71301.10", "0.280"], ["71301.70", "0.040"], ["71302.30", "0.315"], ["71302.50", "0.067"], ["71302.70", "0.027"], ["71303.10", "0.887"], ["71303.20", "0.567"], ["71303.70", "0.004"], ["71303.90", "0.000"], ["71304.10", "0.003"], ["71305.80", "0.000"], ["71305.90", "0.003"], ["71306.30", "0.299"], ["71306.60", "0.512"], ["71306.70", "0.122"], ["71306.90", "0.035"], ["71307.10", "0.219"], ["71307.20", "0.011"], ["71307.60", "1.057"], ["71307.70", "0.597"], ["71308.00", "0.002"], ["71308.10", "0.194"], ["71309.20", "0.015"], ["71309.30", "0.913"], ["71309.50", "0.002"], ["71309.60", "0.003"], ["71310.20", "0.030"], ["71310.40", "0.258"], ["71310.60", "0.004"], ["71310.70", "0.799"], ["71311.20", "0.115"], ["71311.30", "0.769"], ["71311.40", "0.140"], ["71312.40", "0.578"], ["71312.50", "0.534"], ["71313.70", "0.004"], ["71313.80", "0.001"], ["71313.90", "0.018"], ["71314.00", "0.004"], ["71315.00", "0.630"], ["71315.40", "1.051"], ["71315.70", "0.029"], ["71315.80", "0.003"], ["71316.50", "0.430"], ["71316.80", "0.002"], ["71316.90", "0.008"], ["71317.10", "0.327"], ["71317.30", "0.003"], ["71317.60", "0.005"], ["71319.60", "0.312"], ["71320.00", "0.021"], ["71320.30", "0.002"], ["71322.60", "0.000"], ["71322.70", "0.085"], ["71323.10", "0.030"], ["71324.70", "0.235"], ["71325.90", "0.000"], ["71326.20", "0.079"], ["71327.40", "0.300"], ["71327.60", "0.370"], ["71329.30", "2.324"], ["71329.40", "0.021"], ["71329.90", "0.003"], ["71330.00", "0.710"], ["71330.10", "0.062"], ["71331.70", "0.006"], ["71332.70", "0.080"], ["71333.40", "0.000"], ["71334.00", "0.004"], ["71334.60", "0.081"], ["71335.00", "0.181"], ["71335.80", "0.111"], ["71336.00", "0.047"], ["71336.90", "1.055"], ["71337.80", "0.002"], ["71338.30", "0.010"], ["71340.20", "0.290"], ["71340.50", "0.002"], ["71341.10", "0.016"], ["71341.40", "0.007"], ["71342.20", "0.000"], ["71342.30", "0.004"], ["71342.50", "0.229"], ["71343.10", "0.001"], ["71343.80", "0.111"], ["71343.90", "0.510"], ["71345.40", "0.007"], ["71345.80", "0.061"], ["71345.90", "0.259"], ["71347.20", "0.000"], ["71348.00", "8.107"], ["71348.20", "0.002"], ["71348.70", "0.077"], ["71348.80", "0.000"], ["71349.00", "0.257"], ["71350.40", "0.000"], ["71350.60", "0.293"], ["71351.90", "0.078"], ["71352.60", "0.290"], ["71353.80", "0.028"], ["71354.80", "0.042"], ["71354.90", "2.339"], ["71355.00", "0.134"], ["71356.30", "0.040"], ["71356.50", "0.102"], ["71356.90", "0.000"], ["71357.00", "0.181"], ["71360.60", "1.327"], ["71360.70", "1.392"], ["71361.30", "0.024"], ["71362.50", "0.031"], ["71362.80", "0.040"], ["71368.80", "0.023"], ["71373.60", "0.020"], ["71374.50", "10.004"], ["71375.70", "0.000"], ["71375.90", "0.003"], ["71376.60", "0.005"], ["71377.80", "0.000"], ["71379.90", "0.000"], ["71385.20", "0.004"], ["71386.20", "0.000"], ["71395.80", "1.757"], ["71396.00", "0.000"], ["71402.40", "0.042"], ["71402.80", "0.039"], ["71406.40", "0.000"], ["71410.00", "0.107"], ["71413.60", "0.080"], ["71416.60", "0.327"], ["71416.70", "0.321"], ["71416.80", "0.317"], ["71417.20", "0.000"], ["71417.80", "0.220"], ["71419.40", "0.007"], ["71422.90", "0.506"], ["71423.00", "0.855"], ["71427.40", "0.665"], ["71431.30", "1.613"], ["71431.40", "0.040"], ["71435.00", "0.089"], ["71442.10", "0.111"], ["71445.20", "0.449"], ["71448.00", "2.718"], ["71448.50", "0.000"], ["71448.60", "0.000"], ["71449.20", "0.018"], ["71465.40", "0.000"], ["71476.30", "0.000"], ["71476.60", "0.200"], ["71479.20", "0.010"], ["71479.50", "0.200"], ["71482.60", "0.504"], ["71484.80", "0.303"], ["71489.10", "0.001"], ["71496.40", "0.008"], ["71498.80", "0.301"], ["71504.70", "0.000"], ["71508.10", "0.002"], ["71529.10", "0.000"], ["71531.40", "10.000"], ["71545.40", "0.015"], ["71565.40", "0.000"], ["71569.00", "0.002"], ["71576.50", "0.000"], ["71576.60", "0.000"], ["71580.00", "2.551"], ["71583.00", "1.252"], ["71585.80", "0.000"], ["71612.60", "0.214"], ["71650.20", "0.125"], ["71653.60", "0.000"], ["71655.80", "0.011"], ["71674.40", "0.002"], ["71708.60", "0.002"], ["71972.50", "0.000"], ["71972.90", "0.000"], ["71973.00", "0.019"], ["71982.40", "0.014"], ["71982.50", "1.394"], ["72201.10", "0.002"], ["72201.80", "0.002"], ["72203.70", "0.040"], ["72221.30", "0.004"], ["72224.30", "0.002"], ["72231.90", "1.392"], ["72259.90", "0.004"], ["72260.30", "0.720"], ["74825.60", "0.002"], ["74833.60", "0.000"], ["74850.60", "0.000"], ["78328.30", "0.000"], ["78373.80", "0.000"], ["78386.40", "0.002"], ["78386.90", "0.004"], ["89523.20", "0.000"]]}}
{"local_ts": 1773384669430, "server_ts": 1773384669210, "data": {"e": "depthUpdate", "E": 1773384669211, "T": 1773384669210, "s": "BTCUSDT", "U": 10101352095854, "u": 10101352131250, "pu": 10101352095788, "b": [["1000.00", "27.492"], ["5000.00", "101.398"], ["20758.10", "0.027"], ["20759.80", "1.386"], ["20769.70", "0.090"], ["20869.70", "0.063"], ["20958.10", "0.018"], ["20958.60", "0.009"], ["20959.80", "0.153"], ["21069.70", "0.072"], ["21158.10", "0.018"], ["21158.60", "0.009"], ["21159.80", "0.153"], ["67696.80", "0.002"], ["68034.00", "0.009"], ["68211.70", "0.011"], ["69960.10", "0.000"], ["70262.20", "1.136"], ["70545.50", "0.028"], ["70546.00", "0.000"], ["70547.20", "0.000"], ["70903.50", "0.000"], ["70920.50", "0.002"], ["70931.70", "0.000"], ["70957.80", "0.294"], ["71053.40", "0.077"], ["71056.90", "0.074"], ["71072.90", "0.336"], ["71105.40", "0.624"], ["71133.30", "0.033"], ["71136.90", "0.084"], ["71140.80", "0.011"], ["71141.00", "0.027"], ["71145.50", "0.133"], ["71156.60", "0.293"], ["71158.50", "0.161"], ["71164.90", "0.148"], ["71165.90", "0.007"], ["71166.90", "0.523"], ["71167.80", "0.002"], ["71168.20", "0.003"], ["71168.70", "0.052"], ["71168.80", "0.003"], ["71169.80", "0.003"], ["71169.90", "1.205"], ["71170.80", "0.084"], ["71171.70", "0.141"], ["71172.70", "0.204"], ["71173.70", "0.004"], ["71174.60", "0.254"], ["71175.60", "0.017"], ["71176.60", "0.002"], ["71177.60", "0.002"], ["71178.10", "0.000"], ["71178.50", "0.091"], ["71179.10", "0.000"], ["71179.50", "0.000"], ["71180.10", "0.000"], ["71180.50", "0.724"], ["71181.00", "0.032"], ["71181.40", "0.004"], ["71181.50", "0.000"], ["71182.00", "0.045"], ["71182.40", "0.000"], ["71183.00", "0.550"], ["71183.40", "1.196"], ["71183.70", "0.459"], ["71183.80", "0.665"], ["71184.00", "0.006"], ["71184.30", "0.044"], ["71185.00", "0.173"], ["71185.30", "0.599"], ["71185.40", "0.009"], ["71186.40", "0.004"], ["71186.50", "0.042"], ["71186.60", "0.117"], ["71188.20", "0.380"], ["71189.80", "0.005"], ["71189.90", "0.003"], ["71190.60", "0.042"], ["71190.90", "0.004"], ["71191.60", "0.624"], ["71191.80", "0.000"], ["71192.10", "0.000"], ["71192.40", "0.000"], ["71192.80", "0.000"], ["71193.20", "0.084"], ["71193.80", "0.000"], ["71194.50", "0.043"], ["71194.70", "0.847"], ["71194.80", "0.046"], ["71195.60", "0.341"], ["71195.70", "0.003"], ["71195.80", "0.042"], ["71196.30", "0.100"], ["71196.40", "3.482"], ["71196.70", "0.000"], ["71196.90", "0.510"], ["71197.50", "0.073"], ["71197.70", "0.002"], ["71198.00", "0.042"], ["71198.40", "0.000"], ["71198.60", "0.002"], ["71199.20", "0.101"], ["71199.30", "0.508"], ["71199.40", "0.000"], ["71199.50", "0.067"], ["71199.60", "0.002"], ["71200.30", "0.000"], ["71200.50", "0.372"], ["71200.60", "0.032"], ["71200.70", "0.002"], ["71201.50", "0.000"], ["71201.70", "0.002"], ["71201.80", "0.000"], ["71202.40", "0.004"], ["71202.50", "0.941"], ["71203.00", "0.052"], ["71203.10", "0.000"], ["71203.40", "0.005"], ["71203.50", "0.001"], ["71203.60", "0.002"], ["71203.70", "7.727"], ["71203.80", "1.655"], ["71204.20", "0.510"], ["71204.30", "0.000"], ["71204.40", "1.162"], ["71204.50", "0.017"], ["71204.60", "0.040"], ["71204.70", "0.093"], ["71205.00", "0.009"], ["71205.40", "0.005"], ["71205.50", "0.000"], ["71206.40", "0.004"], ["71206.90", "0.000"], ["71207.40", "0.189"], ["71207.90", "0.947"], ["71208.20", "0.000"], ["71208.30", "0.005"], ["71208.90", "0.092"], ["71209.30", "0.304"], ["71209.60", "0.020"], ["71209.70", "0.000"], ["71210.00", "0.079"], ["71210.30", "0.208"], ["71210.60", "0.679"], ["71210.70", "0.103"], ["71211.20", "0.003"], ["71211.40", "0.188"], ["71211.50", "0.008"], ["71211.60", "0.002"], ["71212.20", "0.002"], ["71212.70", "0.000"], ["71213.20", "0.133"], ["71213.50", "0.004"], ["71214.20", "0.010"], ["71214.30", "0.004"], ["71215.10", "0.091"], ["71215.20", "0.035"], ["71215.40", "0.088"], ["71215.80", "0.100"], ["71216.10", "0.054"], ["71216.70", "0.100"], ["71217.00", "0.002"], ["71217.80", "0.465"], ["71217.90", "0.005"], ["71218.20", "0.000"], ["71218.50", "0.002"], ["71218.80", "0.004"], ["71218.90", "0.032"], ["71219.40", "0.000"], ["71219.80", "0.037"], ["71220.40", "0.002"], ["71220.70", "0.010"], ["71221.20", "0.026"], ["71223.10", "0.022"], ["71225.20", "0.336"], ["71226.70", "0.017"], ["71227.20", "0.004"], ["71227.50", "0.002"], ["71227.60", "0.002"], ["71227.90", "0.000"], ["71228.70", "0.000"], ["71228.80", "0.003"], ["71229.10", "0.010"], ["71229.20", "0.009"], ["71229.60", "0.292"], ["71229.80", "0.000"], ["71229.90", "0.021"], ["71230.10", "1.397"], ["71230.50", "0.008"], ["71230.60", "0.152"], ["71230.80", "0.051"], ["71231.20", "0.042"], ["71231.30", "0.030"], ["71231.70", "0.002"], ["71232.00", "0.090"], ["71232.30", "0.005"], ["71232.40", "0.028"], ["71234.00", "0.009"], ["71234.30", "0.002"], ["71234.50", "0.004"], ["71234.70", "1.200"], ["71235.50", "0.009"], ["71235.80", "1.051"], ["71236.00", "0.509"], ["71236.70", "0.004"], ["71237.00", "0.025"], ["71237.10", "0.631"], ["71237.30", "0.891"], ["71237.40", "0.000"], ["71237.60", "0.002"], ["71237.80", "0.002"], ["71238.30", "0.017"], ["71238.40", "0.002"], ["71238.50", "0.140"], ["71239.10", "0.000"], ["71239.60", "0.044"], ["71240.40", "0.005"], ["71240.60", "0.028"], ["71240.90", "0.007"], ["71241.00", "0.035"], ["71241.80", "0.005"], ["71241.90", "0.016"], ["71242.20", "0.006"], ["71242.60", "0.013"], ["71242.70", "1.970"], ["71242.80", "0.058"], ["71242.90", "0.150"], ["71243.20", "0.006"], ["71243.40", "0.005"], ["71243.50", "0.000"], ["71243.80", "0.430"], ["71243.90", "0.428"], ["71244.00", "0.002"], ["71244.10", "0.000"], ["71244.30", "0.680"], ["71244.50", "0.072"], ["71244.70", "0.001"], ["71245.30", "0.006"], ["71245.40", "0.182"], ["71245.50", "0.200"], ["71245.60", "0.114"], ["71245.70", "0.641"], ["71245.80", "0.046"], ["71246.00", "0.036"], ["71246.10", "0.147"], ["71246.80", "0.054"], ["71246.90", "0.003"], ["71247.30", "0.000"], ["71247.40", "0.413"], ["71247.50", "1.394"], ["71247.90", "0.126"], ["71248.00", "0.005"], ["71248.20", "0.003"], ["71248.30", "0.000"], ["71248.40", "0.257"], ["71248.80", "0.000"], ["71249.00", "0.000"], ["71249.10", "0.000"], ["71249.20", "0.005"], ["71249.40", "0.000"], ["71250.30", "0.024"], ["71250.40", "0.000"], ["71250.60", "0.000"], ["71251.50", "0.002"], ["71251.60", "0.001"], ["71251.80", "0.001"], ["71251.90", "0.000"], ["71253.00", "0.009"], ["71253.10", "0.000"], ["71253.20", "0.013"], ["71253.50", "0.003"], ["71253.60", "0.010"], ["71253.70", "0.213"], ["71253.90", "0.003"], ["71254.30", "0.000"], ["71254.40", "0.005"], ["71255.10", "0.002"], ["71255.20", "0.003"], ["71255.60", "0.003"], ["71256.30", "0.004"], ["71257.50", "0.000"], ["71257.80", "0.021"], ["71257.90", "0.006"], ["71258.10", "1.687"], ["71258.20", "0.000"], ["71258.30", "0.000"], ["71258.50", "0.000"], ["71258.60", "0.000"], ["71258.70", "0.000"], ["71259.10", "0.000"], ["71259.20", "0.000"], ["71259.30", "0.000"], ["71259.40", "0.000"], ["71259.60", "0.000"], ["71259.70", "0.000"], ["71259.80", "0.000"]], "a": [["71258.20", "12.439"], ["71258.30", "0.500"], ["71258.40", "0.000"], ["71258.50", "0.004"], ["71258.60", "1.100"], ["71258.70", "0.159"], ["71258.80", "0.003"], ["71259.00", "0.002"], ["71259.20", "0.000"], ["71259.30", "0.000"], ["71259.40", "0.000"], ["71259.50", "0.000"], ["71259.70", "0.042"], ["71259.80", "1.522"], ["71259.90", "0.018"], ["71260.00", "0.006"], ["71260.20", "0.006"], ["71260.30", "0.002"], ["71260.40", "0.001"], ["71260.50", "0.648"], ["71260.70", "0.045"], ["71260.90", "0.000"], ["71261.40", "0.003"], ["71261.90", "0.210"], ["71262.40", "0.004"], ["71263.30", "0.001"], ["71263.40", "0.125"], ["71263.50", "0.213"], ["71264.20", "0.030"], ["71264.40", "0.005"], ["71264.90", "0.007"], ["71265.10", "0.005"], ["71265.30", "0.110"], ["71265.40", "0.005"], ["71265.70", "0.001"], ["71266.00", "0.070"], ["71266.50", "0.003"], ["71266.60", "0.015"], ["71267.00", "0.010"], ["71267.80", "0.001"], ["71267.90", "0.003"], ["71268.20", "0.007"], ["71268.30", "0.052"], ["71268.50", "0.015"], ["71268.70", "0.017"], ["71268.80", "0.279"], ["71269.00", "0.049"], ["71269.20", "0.017"], ["71269.60", "0.001"], ["71269.70", "0.239"], ["71269.80", "0.124"], ["71269.90", "0.200"], ["71270.00", "0.118"], ["71270.10", "0.002"], ["71270.20", "0.023"], ["71270.30", "0.090"], ["71271.00", "0.127"], ["71271.10", "0.096"], ["71271.50", "0.036"], ["71271.60", "0.004"], ["71271.90", "0.001"], ["71272.10", "0.036"], ["71272.20", "0.421"], ["71272.30", "0.010"], ["71272.40", "0.045"], ["71272.50", "0.062"], ["71272.60", "0.002"], ["71273.00", "0.008"], ["71273.10", "0.646"], ["71273.20", "0.040"], ["71273.30", "0.011"], ["71273.40", "0.206"], ["71273.50", "0.071"], ["71273.80", "0.077"], ["71274.40", "0.010"], ["71275.30", "0.007"], ["71275.70", "0.004"], ["71276.60", "0.071"], ["71276.70", "0.641"], ["71277.40", "0.000"], ["71277.70", "0.000"], ["71278.10", "0.002"], ["71279.60", "0.048"], ["71279.70", "0.006"], ["71280.10", "0.021"], ["71280.30", "0.006"], ["71280.40", "0.089"], ["71280.50", "0.508"], ["71280.90", "0.023"], ["71281.00", "0.253"], ["71281.20", "0.254"], ["71281.30", "0.131"], ["71281.60", "0.004"], ["71282.90", "1.069"], ["71283.40", "0.058"], ["71283.90", "0.003"], ["71284.10", "0.036"], ["71284.50", "0.008"], ["71284.60", "0.005"], ["71284.70", "0.013"], ["71284.90", "0.355"], ["71285.00", "0.034"], ["71285.20", "0.000"], ["71285.30", "0.003"], ["71286.90", "0.212"], ["71288.00", "0.893"], ["71288.10", "0.013"], ["71288.50", "0.000"], ["71288.70", "1.443"], ["71288.80", "1.051"], ["71288.90", "0.353"], ["71289.30", "0.053"], ["71289.50", "0.004"], ["71290.00", "0.199"], ["71291.10", "0.386"], ["71291.90", "0.049"], ["71292.30", "0.015"], ["71293.60", "0.320"], ["71293.80", "0.002"], ["71294.30", "0.103"], ["71294.60", "1.053"], ["71295.00", "0.023"], ["71295.50", "0.047"], ["71295.60", "0.282"], ["71295.90", "0.017"], ["71296.80", "0.086"], ["71297.20", "0.017"], ["71297.90", "0.184"], ["71298.10", "0.108"], ["71298.20", "2.077"], ["71298.40", "0.003"], ["71298.80", "0.000"], ["71299.10", "0.194"], ["71299.50", "0.881"], ["71299.80", "0.002"], ["71300.40", "0.281"], ["71301.10", "0.840"], ["71301.30", "0.002"], ["71302.90", "0.292"], ["71303.10", "0.046"], ["71303.20", "0.272"], ["71306.80", "0.084"], ["71306.90", "0.069"], ["71307.00", "0.587"], ["71307.10", "0.212"], ["71307.20", "0.011"], ["71308.10", "0.296"], ["71315.70", "0.003"], ["71315.80", "0.049"], ["71317.10", "0.178"], ["71317.70", "0.003"], ["71318.90", "0.041"], ["71319.90", "0.057"], ["71322.80", "1.139"], ["71323.20", "0.286"], ["71324.70", "0.220"], ["71325.80", "0.508"], ["71326.40", "0.035"], ["71326.70", "0.000"], ["71327.60", "0.289"], ["71329.40", "0.021"], ["71330.20", "0.004"], ["71333.00", "0.208"], ["71333.80", "1.009"], ["71336.90", "1.051"], ["71341.50", "0.048"], ["71342.50", "0.180"], ["71343.10", "0.003"], ["71343.60", "0.040"], ["71347.10", "0.177"], ["71347.30", "0.212"], ["71347.80", "0.215"], ["71349.00", "0.045"], ["71359.70", "0.019"], ["71371.50", "0.019"], ["71373.80", "0.000"], ["71375.20", "0.216"], ["71385.20", "0.117"], ["71398.80", "0.000"], ["71411.40", "0.039"], ["71415.00", "0.039"], ["71415.50", "0.000"], ["71416.70", "0.282"], ["71420.20", "0.512"], ["71432.80", "0.162"], ["71436.30", "0.452"], ["71439.90", "0.159"], ["71440.00", "0.089"], ["71440.40", "0.002"], ["71443.60", "0.000"], ["71444.00", "0.029"], ["71445.20", "0.290"], ["71445.50", "0.075"], ["71447.50", "0.004"], ["71501.10", "0.000"], ["71522.10", "0.000"], ["71543.70", "0.000"], ["71544.90", "0.000"], ["71568.70", "0.000"], ["71970.80", "0.000"], ["71971.30", "0.000"], ["71972.50", "0.000"], ["72200.30", "0.000"], ["72201.80", "0.000"], ["72219.10", "0.008"], ["72220.30", "0.000"], ["72221.30", "0.000"], ["72224.30", "0.000"], ["72235.60", "0.276"], ["72258.20", "0.002"], ["72258.30", "0.010"], ["72258.70", "6.776"], ["72259.90", "0.012"], ["72348.20", "0.551"], ["72683.80", "0.005"], ["72695.10", "0.006"], ["74823.00", "0.052"], ["89523.20", "0.000"], ["100000.00", "15.554"]]}}
{"local_ts": 1773384670450, "server_ts": 1773384670232, "data": {"e": "depthUpdate", "E": 1773384670233, "T": 1773384670232, "s": "BTCUSDT", "U": 10101352227466, "u": 10101352232982, "pu": 10101352227275, "b": [["5000.00", "101.418"], ["20759.80", "0.108"], ["20854.00", "0.045"], ["20954.00", "0.621"], ["20959.80", "0.108"], ["21054.00", "0.045"], ["21059.80", "0.000"], ["21154.00", "1.296"], ["21159.80", "0.108"], ["67685.70", "0.012"], ["67693.70", "0.000"], ["70167.10", "0.711"], ["70541.50", "2.862"], ["70920.50", "0.000"], ["70923.50", "0.006"], ["71142.20", "0.016"], ["71143.50", "0.000"], ["71161.20", "12.343"], ["71181.90", "0.009"], ["71183.70", "0.003"], ["71183.80", "0.113"], ["71183.90", "0.269"], ["71184.50", "0.061"], ["71186.30", "0.204"], ["71199.60", "0.002"], ["71200.60", "0.032"], ["71201.90", "0.044"], ["71202.60", "0.045"], ["71204.10", "0.259"], ["71204.30", "0.003"], ["71204.40", "1.164"], ["71204.50", "0.203"], ["71204.60", "0.181"], ["71205.40", "0.005"], ["71206.40", "0.007"], ["71207.40", "0.039"], ["71208.40", "0.057"], ["71210.00", "0.000"], ["71211.10", "0.005"], ["71212.10", "0.045"], ["71213.30", "0.009"], ["71215.90", "0.024"], ["71216.70", "0.100"], ["71216.90", "0.042"], ["71220.30", "0.010"], ["71220.50", "0.003"], ["71221.30", "0.043"], ["71221.60", "0.382"], ["71221.70", "0.000"], ["71222.30", "0.045"], ["71223.00", "0.045"], ["71223.30", "0.044"], ["71223.50", "0.090"], ["71224.10", "1.049"], ["71224.20", "0.000"], ["71224.50", "0.418"], ["71224.80", "0.970"], ["71225.40", "0.363"], ["71225.50", "0.034"], ["71226.60", "0.003"], ["71227.00", "0.081"], ["71227.10", "0.000"], ["71227.20", "0.074"], ["71227.90", "0.003"], ["71228.00", "0.100"], ["71228.50", "0.002"], ["71229.10", "0.044"], ["71229.60", "0.004"], ["71229.80", "0.012"], ["71230.20", "0.003"], ["71231.10", "1.193"], ["71231.70", "0.019"], ["71231.80", "0.009"], ["71232.10", "0.000"], ["71232.30", "0.012"], ["71232.70", "0.024"], ["71232.80", "0.803"], ["71232.90", "0.042"], ["71233.40", "0.294"], ["71233.90", "0.155"], ["71234.00", "0.552"], ["71234.20", "0.048"], ["71234.50", "0.031"], ["71234.60", "0.140"], ["71235.30", "0.636"], ["71235.50", "0.002"], ["71235.60", "0.000"], ["71235.80", "1.052"], ["71236.30", "0.007"], ["71236.50", "0.000"], ["71236.60", "0.728"], ["71237.40", "0.000"], ["71238.50", "0.015"], ["71238.60", "0.099"], ["71238.70", "0.000"], ["71239.40", "0.383"], ["71240.00", "0.297"], ["71241.30", "0.019"], ["71242.00", "7.274"], ["71243.00", "0.017"], ["71243.30", "0.729"], ["71243.40", "0.271"], ["71243.60", "0.044"], ["71243.70", "0.122"], ["71244.60", "0.018"], ["71244.80", "0.007"], ["71244.90", "0.008"], ["71245.00", "0.010"], ["71245.10", "0.112"], ["71245.30", "0.032"], ["71245.90", "0.002"], ["71246.80", "0.027"], ["71247.50", "0.402"], ["71247.60", "0.002"], ["71247.90", "0.035"], ["71248.30", "0.000"], ["71249.20", "0.005"], ["71249.60", "0.029"], ["71250.00", "0.023"], ["71250.40", "0.000"], ["71251.00", "0.000"], ["71251.20", "0.000"], ["71252.20", "0.001"], ["71252.40", "0.271"], ["71252.50", "0.000"], ["71252.90", "0.000"], ["71253.50", "0.003"], ["71253.90", "0.003"], ["71254.00", "1.596"]], "a": [["71254.10", "4.659"], ["71254.40", "0.031"], ["71254.50", "0.000"], ["71254.90", "0.004"], ["71255.00", "0.006"], ["71256.30", "0.000"], ["71256.50", "0.026"], ["71257.20", "0.009"], ["71257.50", "0.004"], ["71257.90", "0.076"], ["71258.00", "1.109"], ["71258.10", "0.622"], ["71258.20", "0.004"], ["71258.60", "0.003"], ["71258.80", "0.038"], ["71260.00", "0.040"], ["71261.10", "0.000"], ["71261.90", "0.065"], ["71262.90", "0.020"], ["71263.40", "0.004"], ["71266.90", "0.029"], ["71269.90", "0.075"], ["71270.10", "0.002"], ["71270.80", "0.053"], ["71271.00", "0.707"], ["71272.10", "0.000"], ["71272.70", "0.070"], ["71273.20", "0.072"], ["71273.40", "0.206"], ["71274.10", "0.009"], ["71274.60", "0.008"], ["71275.50", "0.104"], ["71276.60", "0.001"], ["71276.80", "0.450"], ["71277.00", "0.207"], ["71278.40", "0.000"], ["71278.50", "0.145"], ["71278.60", "0.000"], ["71278.70", "0.506"], ["71278.80", "0.245"], ["71300.40", "0.151"], ["71300.50", "0.042"], ["71301.80", "0.009"], ["71301.90", "0.051"], ["71304.40", "0.002"], ["71305.60", "0.000"], ["71325.40", "1.002"], ["71376.20", "0.012"], ["71442.90", "0.159"], ["71528.80", "5.470"], ["71536.10", "0.006"], ["71789.90", "0.027"], ["71831.50", "0.000"], ["71832.20", "0.815"], ["71966.60", "0.027"], ["72134.20", "0.430"], ["72135.00", "0.715"], ["72436.90", "0.000"], ["72437.80", "0.722"], ["73418.70", "3.268"], ["89523.20", "0.000"]]}}
{"local_ts": 1773384671467, "server_ts": 1773384671251, "data": {"e": "depthUpdate", "E": 1773384671253, "T": 1773384671251, "s": "BTCUSDT", "U": 10101352314696, "u": 10101352325184, "pu": 10101352314541, "b": [["1000.00", "27.492"], ["5000.00", "101.418"], ["20852.30", "0.189"], ["20954.00", "0.090"], ["21052.30", "0.387"], ["21154.00", "0.423"], ["67657.30", "0.006"], ["67661.10", "0.151"], ["67691.00", "0.000"], ["70041.40", "0.002"], ["71154.50", "6.523"], ["71161.70", "0.580"], ["71168.80", "0.098"], ["71184.60", "0.002"], ["71203.20", "0.027"], ["71203.80", "1.655"], ["71204.20", "0.510"], ["71205.30", "0.022"], ["71205.80", "0.042"], ["71208.90", "0.112"], ["71211.30", "0.701"], ["71212.40", "0.040"], ["71213.60", "0.007"], ["71216.80", "0.003"], ["71217.90", "0.250"], ["71220.70", "0.555"], ["71224.30", "0.035"], ["71224.40", "0.193"], ["71225.40", "0.090"], ["71225.60", "0.003"], ["71227.20", "0.004"], ["71227.50", "1.200"], ["71228.80", "0.005"], ["71229.30", "0.004"], ["71229.50", "0.483"], ["71229.60", "0.004"], ["71230.30", "0.000"], ["71230.50", "0.010"], ["71231.30", "0.281"], ["71232.50", "0.142"], ["71233.10", "0.881"], ["71233.40", "0.000"], ["71233.90", "0.148"], ["71235.20", "0.566"], ["71236.80", "0.002"], ["71236.90", "0.027"], ["71237.10", "0.006"], ["71238.80", "0.001"], ["71243.40", "0.277"], ["71249.80", "0.009"], ["71250.30", "0.002"]], "a": [["71257.40", "0.004"], ["71257.50", "0.005"], ["71258.10", "0.482"], ["71258.80", "0.056"], ["71261.60", "0.143"], ["71262.50", "0.245"], ["71262.90", "0.032"], ["71263.40", "0.002"], ["71265.40", "0.007"], ["71271.40", "0.007"], ["71274.10", "0.002"], ["71278.50", "0.145"], ["71278.90", "0.508"], ["71279.10", "0.353"], ["71279.30", "0.000"], ["71288.00", "0.186"], ["71289.80", "0.009"], ["71293.30", "0.475"], ["71298.50", "0.014"], ["71298.60", "0.339"], ["71300.70", "0.034"], ["71301.40", "0.342"], ["71332.80", "0.072"], ["71339.90", "0.134"], ["71556.80", "0.000"], ["71964.90", "0.002"]]}}
{"local_ts": 1773384672490, "server_ts": 1773384672273, "data": {"e": "depthUpdate", "E": 1773384672275, "T": 1773384672273, "s": "BTCUSDT", "U": 10101352419966, "u": 10101352427259, "pu": 10101352419950, "b": [["5000.00", "101.418"], ["20752.30", "0.675"], ["20852.30", "0.225"], ["20854.00", "0.000"], ["20952.30", "1.116"], ["21052.30", "0.684"], ["21054.00", "0.000"], ["67657.40", "0.122"], ["67705.10", "0.002"], ["70539.80", "0.000"], ["70897.70", "0.002"], ["71153.60", "0.070"], ["71154.50", "6.453"], ["71160.80", "0.078"], ["71161.70", "0.510"], ["71164.70", "0.016"], ["71165.70", "0.001"], ["71166.60", "0.118"], ["71167.60", "0.009"], ["71167.90", "0.169"], ["71168.60", "0.002"], ["71168.80", "0.028"], ["71169.50", "0.790"], ["71170.50", "1.070"], ["71171.50", "1.309"], ["71174.70", "0.043"], ["71176.20", "0.000"], ["71178.40", "0.042"], ["71179.40", "0.042"], ["71180.50", "0.780"], ["71181.60", "0.042"], ["71182.60", "0.042"], ["71183.70", "0.272"], ["71183.90", "0.311"], ["71185.90", "0.143"], ["71187.00", "0.044"], ["71201.20", "0.054"], ["71202.50", "0.000"], ["71203.70", "7.729"], ["71205.00", "0.153"], ["71206.20", "0.364"], ["71206.50", "0.883"], ["71207.50", "0.006"], ["71207.70", "0.058"], ["71208.00", "0.098"], ["71209.50", "0.898"], ["71212.10", "0.025"], ["71215.30", "0.044"], ["71217.60", "0.033"], ["71218.90", "0.056"], ["71219.00", "0.000"], ["71219.50", "0.003"], ["71220.50", "0.003"], ["71221.10", "0.035"], ["71221.80", "0.121"], ["71222.30", "0.003"], ["71222.70", "0.002"], ["71223.60", "0.197"], ["71225.40", "0.075"], ["71225.70", "0.020"], ["71226.20", "0.022"], ["71226.80", "0.000"], ["71242.70", "1.248"], ["71243.70", "0.141"], ["71245.90", "0.000"], ["71246.00", "0.216"], ["71247.50", "0.000"], ["71248.20", "0.003"]], "a": [["71253.50", "0.343"], ["71254.10", "0.176"], ["71256.10", "0.000"], ["71257.50", "0.003"], ["71258.60", "0.005"], ["71260.70", "0.007"], ["71262.10", "0.020"], ["71262.70", "0.090"], ["71264.80", "0.058"], ["71265.20", "0.018"], ["71265.80", "0.003"], ["71266.50", "0.634"], ["71272.10", "0.000"], ["71273.50", "0.247"], ["71273.80", "0.025"], ["71274.10", "0.128"], ["71275.20", "0.506"], ["71276.00", "0.009"], ["71298.30", "0.225"], ["71298.40", "0.005"], ["71299.30", "0.021"], ["71299.40", "0.120"], ["71331.80", "1.567"], ["71332.80", "0.002"], ["71332.90", "0.098"], ["71333.70", "6.467"], ["71339.20", "0.248"], ["71339.90", "0.132"], ["71340.00", "0.243"], ["71340.50", "0.075"], ["71341.00", "0.270"], ["71347.80", "0.043"], ["71351.60", "0.120"], ["71362.60", "0.040"], ["71415.40", "0.072"], ["71416.30", "2.309"], ["71434.10", "0.199"], ["71437.70", "0.003"], ["71438.10", "0.000"], ["71440.60", "0.001"], ["71441.20", "0.019"], ["71461.60", "0.002"], ["71466.90", "0.000"], ["71479.40", "0.208"], ["71479.50", "0.200"], ["71561.50", "0.032"], ["71562.10", "0.000"], ["71562.20", "0.000"], ["71921.40", "0.016"], ["71964.90", "0.002"], ["72107.40", "0.149"], ["74102.40", "0.004"], ["74834.50", "0.052"]]}}
{"local_ts": 1773384673517, "server_ts": 1773384673297, "data": {"e": "depthUpdate", "E": 1773384673301, "T": 1773384673297, "s": "BTCUSDT", "U": 10101352491133, "u": 10101352497767, "pu": 10101352490775, "b": [["1000.00", "27.492"], ["5000.00", "101.418"], ["20752.30", "0.351"], ["20852.30", "0.846"], ["20952.30", "0.954"], ["21152.30", "0.549"], ["33000.00", "9.339"], ["70221.50", "0.062"], ["70539.80", "0.000"], ["71184.60", "0.141"], ["71203.90", "0.003"], ["71204.20", "0.753"], ["71209.50", "0.870"], ["71226.30", "0.002"], ["71227.50", "0.087"], ["71228.80", "0.104"], ["71229.90", "0.000"], ["71230.00", "0.042"], ["71234.20", "0.048"], ["71234.40", "0.063"], ["71237.00", "0.002"], ["71238.20", "0.179"], ["71238.80", "0.001"], ["71239.60", "0.300"], ["71240.60", "0.015"], ["71241.00", "0.035"], ["71242.10", "0.042"], ["71243.10", "0.058"], ["71243.40", "0.317"], ["71243.60", "0.044"], ["71244.40", "0.029"], ["71244.50", "0.001"], ["71244.90", "0.006"], ["71245.10", "0.001"], ["71245.20", "0.210"], ["71245.80", "0.033"], ["71247.80", "0.001"], ["71248.20", "0.213"], ["71248.60", "0.001"], ["71248.90", "0.003"], ["71249.10", "0.000"], ["71249.80", "0.010"], ["71249.90", "0.001"], ["71251.10", "0.008"], ["71251.60", "0.079"], ["71252.20", "0.018"]], "a": [["71252.40", "9.526"], ["71254.00", "1.131"], ["71254.40", "0.042"], ["71258.60", "0.003"], ["71259.50", "0.058"], ["71262.20", "0.051"], ["71288.00", "0.213"], ["71297.40", "0.117"], ["71297.50", "0.044"], ["71964.90", "0.002"], ["72188.00", "1.848"], ["72260.80", "0.006"], ["72283.00", "1.928"], ["72354.30", "2.874"], ["72392.40", "0.983"], ["72394.20", "0.972"], ["74837.70", "0.002"]]}}
{"local_ts": 1773384674538, "server_ts": 1773384674320, "data": {"e": "depthUpdate", "E": 1773384674321, "T": 1773384674320, "s": "BTCUSDT", "U": 10101352551393, "u": 10101352565439, "pu": 10101352551388, "b": [["1000.00", "27.492"], ["5000.00", "101.418"], ["20749.60", "0.162"], ["20852.30", "1.215"], ["21049.60", "0.081"], ["21152.30", "0.486"], ["69824.70", "0.003"], ["70119.70", "0.988"], ["70147.90", "0.997"], ["70226.60", "8.319"], ["70537.10", "0.002"], ["70539.80", "0.000"], ["70803.70", "0.082"], ["70896.00", "0.010"], ["70948.70", "0.882"], ["71046.70", "0.004"], ["71063.80", "0.005"], ["71064.70", "0.036"], ["71095.70", "0.000"], ["71127.00", "0.220"], ["71149.60", "1.753"], ["71152.30", "0.061"], ["71152.50", "8.625"], ["71156.80", "0.057"], ["71156.90", "0.844"], ["71162.20", "0.000"], ["71162.40", "0.063"], ["71162.70", "2.845"], ["71168.40", "0.681"], ["71170.90", "0.047"], ["71171.40", "4.283"], ["71175.40", "1.735"], ["71175.90", "0.367"], ["71177.80", "0.716"], ["71180.50", "0.735"], ["71181.30", "1.590"], ["71183.70", "0.475"], ["71183.90", "0.504"], ["71185.50", "0.136"], ["71185.70", "0.016"], ["71186.80", "0.074"], ["71187.70", "0.321"], ["71189.20", "0.000"], ["71190.20", "1.052"], ["71190.60", "0.048"], ["71191.20", "0.000"], ["71192.10", "0.000"], ["71192.70", "0.712"], ["71193.10", "0.003"], ["71194.10", "0.004"], ["71194.20", "1.333"], ["71194.60", "0.208"], ["71195.10", "0.043"], ["71195.40", "0.000"], ["71195.80", "0.000"], ["71196.00", "1.053"], ["71197.00", "1.260"], ["71197.10", "0.029"], ["71197.30", "0.057"], ["71198.00", "0.042"], ["71198.30", "0.212"], ["71198.90", "0.083"], ["71199.40", "0.020"], ["71199.50", "0.003"], ["71199.70", "0.003"], ["71199.80", "0.004"], ["71199.90", "0.004"], ["71200.40", "0.053"], ["71200.50", "0.387"], ["71200.80", "0.002"], ["71200.90", "0.000"], ["71201.00", "0.005"], ["71201.90", "0.041"], ["71202.50", "0.042"], ["71202.80", "0.011"], ["71202.90", "0.000"], ["71203.00", "0.007"], ["71203.80", "1.655"], ["71203.90", "0.043"], ["71204.00", "0.015"], ["71205.20", "0.005"], ["71205.30", "0.000"], ["71205.60", "0.049"], ["71206.20", "0.364"], ["71206.30", "0.646"], ["71206.80", "0.601"], ["71207.10", "0.042"], ["71207.30", "0.000"], ["71207.60", "0.000"], ["71207.70", "0.029"], ["71208.00", "0.078"], ["71208.10", "0.016"], ["71208.30", "0.005"], ["71208.50", "0.594"], ["71208.70", "0.077"], ["71208.80", "0.000"], ["71208.90", "0.092"], ["71210.30", "0.208"], ["71210.40", "0.181"], ["71210.50", "0.724"], ["71210.60", "0.679"], ["71211.00", "0.002"], ["71211.80", "0.063"], ["71212.00", "0.876"], ["71212.10", "0.019"], ["71212.20", "0.207"], ["71212.40", "0.188"], ["71212.90", "0.617"], ["71213.30", "0.023"], ["71213.90", "0.003"], ["71214.10", "0.543"], ["71214.20", "0.251"], ["71214.30", "0.004"], ["71214.70", "0.004"], ["71215.00", "0.004"], ["71215.10", "0.041"], ["71215.20", "0.006"], ["71215.30", "0.000"], ["71215.60", "0.040"], ["71215.80", "0.091"], ["71216.00", "0.002"], ["71216.60", "0.372"], ["71217.10", "0.050"], ["71217.30", "0.035"], ["71217.60", "0.008"], ["71217.80", "0.465"], ["71217.90", "0.005"], ["71218.30", "0.331"], ["71218.50", "0.002"], ["71218.90", "0.102"], ["71219.10", "0.041"], ["71219.80", "0.017"], ["71220.20", "0.903"], ["71220.40", "0.019"], ["71220.90", "0.009"], ["71221.00", "0.070"], ["71221.10", "0.477"], ["71221.30", "0.001"], ["71221.50", "0.494"], ["71221.60", "0.156"], ["71221.70", "0.000"], ["71222.00", "0.090"], ["71222.40", "0.000"], ["71222.80", "0.006"], ["71222.90", "0.525"], ["71223.00", "0.045"], ["71223.60", "0.193"], ["71223.70", "0.349"], ["71224.20", "0.015"], ["71224.30", "0.002"], ["71224.40", "0.126"], ["71224.70", "0.079"], ["71224.80", "0.890"], ["71225.00", "0.026"], ["71225.30", "0.002"], ["71225.40", "0.104"], ["71225.50", "0.028"], ["71225.70", "0.020"], ["71225.80", "0.060"], ["71225.90", "0.007"], ["71226.20", "0.000"], ["71226.40", "0.004"], ["71226.70", "0.019"], ["71226.80", "0.000"], ["71226.90", "0.000"], ["71227.10", "0.512"], ["71227.20", "1.197"], ["71227.30", "0.017"], ["71227.50", "0.080"], ["71227.60", "0.013"], ["71227.80", "0.007"], ["71227.90", "0.313"], ["71228.00", "0.059"], ["71228.10", "0.015"], ["71228.30", "0.632"], ["71228.40", "0.125"], ["71228.50", "0.002"], ["71228.80", "0.005"], ["71228.90", "0.005"], ["71229.00", "0.018"], ["71229.20", "0.070"], ["71229.30", "0.004"], ["71229.40", "0.620"], ["71229.50", "0.469"], ["71229.60", "0.006"], ["71229.70", "0.077"], ["71230.00", "0.023"], ["71230.10", "1.265"], ["71230.20", "0.036"], ["71230.30", "0.004"], ["71230.40", "0.001"], ["71230.50", "0.143"], ["71230.60", "0.000"], ["71230.70", "0.005"], ["71230.90", "0.006"], ["71231.10", "0.015"], ["71231.20", "0.000"], ["71231.30", "0.001"], ["71231.40", "0.007"], ["71231.50", "0.013"], ["71231.60", "0.039"], ["71231.80", "0.003"], ["71231.90", "0.004"], ["71232.10", "0.000"], ["71232.30", "0.005"], ["71232.60", "0.002"], ["71232.70", "0.016"], ["71232.90", "0.000"], ["71233.10", "0.438"], ["71233.20", "0.013"], ["71233.30", "0.000"], ["71233.50", "0.000"], ["71233.90", "0.148"], ["71234.00", "0.020"], ["71234.20", "0.000"], ["71234.30", "0.002"], ["71234.40", "0.063"], ["71234.60", "0.000"], ["71234.80", "0.000"], ["71234.90", "0.654"], ["71235.10", "0.006"], ["71235.50", "0.002"], ["71235.80", "1.050"], ["71236.00", "0.006"], ["71236.50", "0.045"], ["71236.70", "0.004"], ["71236.90", "0.009"], ["71237.10", "0.006"], ["71237.20", "0.014"], ["71237.50", "0.004"], ["71237.80", "0.002"], ["71238.10", "0.004"], ["71238.20", "0.110"], ["71238.60", "0.070"], ["71238.70", "0.029"], ["71239.00", "0.074"], ["71239.50", "0.002"], ["71239.60", "0.227"], ["71240.00", "0.010"], ["71240.10", "0.000"], ["71240.20", "0.192"], ["71240.30", "0.005"], ["71240.40", "0.011"], ["71240.70", "0.003"], ["71241.00", "0.035"], ["71241.50", "0.004"], ["71241.70", "1.051"], ["71241.80", "0.002"], ["71241.90", "0.024"], ["71242.00", "7.425"], ["71242.10", "0.548"], ["71242.40", "0.040"], ["71242.50", "0.165"], ["71242.70", "1.252"], ["71242.90", "0.150"], ["71243.00", "0.151"], ["71243.30", "0.004"], ["71243.40", "0.027"], ["71243.50", "0.002"], ["71243.70", "0.030"], ["71243.80", "0.005"], ["71244.10", "0.000"], ["71244.20", "0.008"], ["71244.30", "0.182"], ["71246.00", "0.008"], ["71246.60", "0.116"], ["71246.90", "0.002"], ["71247.00", "0.005"], ["71247.30", "0.021"], ["71248.10", "0.001"], ["71248.30", "0.000"], ["71248.80", "0.010"], ["71248.90", "0.002"], ["71249.30", "0.002"], ["71249.50", "0.011"], ["71249.60", "0.471"]], "a": [["71249.70", "7.958"], ["71249.80", "0.003"], ["71249.90", "0.002"], ["71250.00", "0.016"], ["71250.10", "0.212"], ["71250.20", "0.002"], ["71250.30", "0.000"], ["71250.40", "0.000"], ["71250.60", "0.000"], ["71250.70", "0.043"], ["71250.90", "0.239"], ["71251.00", "0.018"], ["71251.10", "0.001"], ["71251.20", "0.002"], ["71251.30", "0.000"], ["71251.40", "0.003"], ["71251.50", "0.003"], ["71251.60", "0.008"], ["71251.70", "0.047"], ["71251.80", "0.002"], ["71251.90", "0.000"], ["71252.10", "0.003"], ["71252.20", "0.649"], ["71252.30", "1.146"], ["71252.40", "0.404"], ["71252.60", "0.000"], ["71253.00", "0.021"], ["71253.20", "0.007"], ["71253.50", "0.018"], ["71253.70", "0.049"], ["71254.00", "1.105"], ["71254.10", "0.127"], ["71254.40", "0.009"], ["71254.80", "0.017"], ["71255.10", "0.004"], ["71255.30", "0.002"], ["71255.50", "0.000"], ["71255.70", "0.012"], ["71256.00", "0.015"], ["71256.50", "0.005"], ["71256.70", "0.000"], ["71257.10", "0.003"], ["71257.20", "0.000"], ["71257.30", "0.021"], ["71257.50", "0.004"], ["71257.70", "0.000"], ["71257.90", "0.002"], ["71258.00", "1.107"], ["71258.10", "0.547"], ["71258.30", "0.004"], ["71258.50", "0.019"], ["71258.80", "0.057"], ["71259.10", "0.003"], ["71259.50", "0.007"], ["71259.60", "0.032"], ["71259.70", "0.002"], ["71260.30", "0.008"], ["71260.80", "0.140"], ["71261.00", "0.008"], ["71262.20", "0.071"], ["71262.30", "0.070"], ["71262.40", "0.470"], ["71262.50", "0.017"], ["71262.60", "0.047"], ["71262.70", "0.072"], ["71263.10", "0.151"], ["71263.20", "0.004"], ["71263.30", "0.269"], ["71263.60", "0.053"], ["71263.70", "0.000"], ["71264.10", "0.392"], ["71264.30", "0.051"], ["71264.40", "0.056"], ["71264.80", "0.051"], ["71264.90", "0.677"], ["71265.00", "0.010"], ["71265.30", "0.080"], ["71265.50", "0.180"], ["71266.40", "0.041"], ["71266.50", "0.014"], ["71266.70", "0.303"], ["71267.10", "0.510"], ["71267.20", "0.003"], ["71268.10", "0.002"], ["71268.20", "0.217"], ["71268.50", "1.269"], ["71268.70", "0.072"], ["71269.10", "0.076"], ["71269.30", "0.004"], ["71269.80", "0.095"], ["71269.90", "0.009"], ["71270.20", "0.016"], ["71270.70", "0.126"], ["71271.00", "0.249"], ["71271.10", "1.056"], ["71271.30", "0.009"], ["71271.40", "0.000"], ["71271.50", "0.022"], ["71271.60", "0.510"], ["71271.80", "0.009"], ["71271.90", "0.000"], ["71272.20", "0.357"], ["71272.50", "0.004"], ["71272.60", "0.002"], ["71272.70", "0.020"], ["71272.80", "0.509"], ["71273.10", "0.015"], ["71273.20", "0.000"], ["71273.60", "0.587"], ["71274.00", "0.133"], ["71274.10", "0.009"], ["71274.20", "0.506"], ["71274.60", "0.012"], ["71274.80", "0.000"], ["71275.00", "0.103"], ["71276.20", "0.005"], ["71276.90", "1.051"], ["71278.00", "0.055"], ["71278.70", "0.001"], ["71279.20", "0.009"], ["71280.20", "1.373"], ["71280.40", "0.019"], ["71281.50", "0.099"], ["71282.20", "0.008"], ["71283.50", "0.000"], ["71284.20", "0.377"], ["71284.90", "0.355"], ["71285.30", "0.061"], ["71286.00", "0.012"], ["71286.30", "0.095"], ["71287.50", "0.104"], ["71287.70", "0.006"], ["71288.10", "0.001"], ["71289.10", "0.204"], ["71289.40", "0.010"], ["71289.90", "0.060"], ["71291.40", "0.072"], ["71291.70", "0.514"], ["71294.60", "1.567"], ["71295.20", "0.004"], ["71296.90", "1.123"], ["71297.00", "0.308"], ["71297.20", "0.060"], ["71297.80", "0.012"], ["71298.30", "0.223"], ["71298.40", "0.003"], ["71299.00", "0.191"], ["71299.50", "0.598"], ["71300.20", "0.002"], ["71301.40", "0.338"], ["71303.10", "0.098"], ["71304.00", "0.069"], ["71305.10", "0.278"], ["71306.40", "0.090"], ["71306.70", "0.099"], ["71309.80", "0.003"], ["71311.30", "0.768"], ["71313.80", "0.081"], ["71317.40", "0.038"], ["71318.40", "0.008"], ["71318.50", "0.076"], ["71319.30", "0.000"], ["71320.90", "0.084"], ["71322.70", "0.003"], ["71323.50", "1.831"], ["71327.90", "0.099"], ["71328.60", "0.525"], ["71328.70", "0.004"], ["71333.00", "0.229"], ["71333.90", "0.000"], ["71335.10", "0.168"], ["71336.70", "0.003"], ["71339.40", "0.000"], ["71340.40", "0.306"], ["71345.90", "0.480"], ["71346.70", "0.190"], ["71356.90", "0.122"], ["71379.00", "0.001"], ["71391.40", "0.506"], ["71391.50", "6.436"], ["71408.20", "0.048"], ["71410.00", "0.146"], ["71412.00", "10.000"], ["71412.70", "0.296"], ["71413.60", "0.119"], ["71417.10", "0.159"], ["71420.70", "1.667"], ["71427.80", "1.044"], ["71431.40", "0.199"], ["71434.10", "0.040"], ["71434.90", "0.101"], ["71436.00", "0.002"], ["71436.90", "0.000"], ["71454.60", "0.269"], ["71456.60", "0.036"], ["71459.40", "2.788"], ["71464.50", "0.056"], ["71479.00", "0.362"], ["71479.30", "0.287"], ["71492.50", "0.000"], ["71509.40", "0.007"], ["71513.50", "0.134"], ["71529.00", "0.283"], ["71536.30", "0.000"], ["71962.20", "0.071"], ["71964.90", "0.002"], ["72230.30", "0.559"], ["72249.70", "0.109"], ["72683.30", "0.000"], ["72683.80", "0.002"], ["74846.80", "0.002"], ["100000.00", "15.554"]]}}
{"local_ts": 1773384675559, "server_ts": 1773384675341, "data": {"e": "depthUpdate", "E": 1773384675343, "T": 1773384675341, "s": "BTCUSDT", "U": 10101352697905, "u": 10101352724462, "pu": 10101352697874, "b": [["5000.00", "101.418"], ["20746.90", "1.098"], ["20750.50", "0.009"], ["20750.70", "0.018"], ["20752.30", "0.108"], ["20852.30", "0.000"], ["20946.90", "0.216"], ["20949.50", "0.009"], ["20950.70", "0.054"], ["21052.30", "0.054"], ["21146.90", "0.216"], ["21149.50", "0.009"], ["21150.70", "0.090"], ["33000.00", "9.343"], ["40000.00", "49.305"], ["68397.10", "0.002"], ["70249.50", "0.030"], ["70250.60", "0.002"], ["70250.70", "0.729"], ["70265.90", "0.000"], ["70267.80", "0.033"], ["70269.30", "0.000"], ["70269.60", "0.002"], ["70534.40", "0.000"], ["70535.30", "0.056"], ["70537.00", "0.288"], ["70538.20", "0.000"], ["70609.20", "0.018"], ["70616.30", "0.000"], ["70883.00", "0.157"], ["70978.80", "0.295"], ["70987.30", "0.002"], ["71008.30", "0.302"], ["71024.80", "0.001"], ["71050.60", "0.296"], ["71060.10", "3.248"], ["71070.10", "3.000"], ["71078.00", "0.023"], ["71081.90", "0.001"], ["71082.00", "0.000"], ["71085.70", "0.018"], ["71090.40", "3.297"], ["71098.40", "1.002"], ["71099.30", "2.739"], ["71105.90", "0.003"], ["71107.40", "0.000"], ["71109.30", "0.025"], ["71111.80", "0.039"], ["71113.70", "0.002"], ["71114.20", "0.418"], ["71114.60", "0.508"], ["71115.00", "0.175"], ["71115.30", "0.050"], ["71116.10", "0.000"], ["71116.60", "0.105"], ["71117.80", "0.301"], ["71118.50", "0.385"], ["71120.00", "16.178"], ["71120.70", "6.556"], ["71122.30", "0.042"], ["71122.40", "0.635"], ["71124.50", "0.099"], ["71124.90", "0.035"], ["71127.00", "0.218"], ["71139.80", "0.000"], ["71158.90", "0.000"], ["71159.00", "0.021"], ["71160.20", "0.121"], ["71161.20", "12.343"], ["71170.50", "1.364"], ["71171.60", "0.025"], ["71175.90", "0.153"], ["71177.80", "0.716"], ["71183.00", "0.508"], ["71185.00", "0.074"], ["71186.60", "0.216"], ["71186.80", "0.022"], ["71189.00", "0.276"], ["71190.20", "1.115"], ["71191.20", "0.004"], ["71191.70", "0.309"], ["71191.80", "0.292"], ["71193.10", "0.005"], ["71194.80", "0.004"], ["71195.50", "0.000"], ["71195.60", "0.325"], ["71196.20", "0.004"], ["71196.30", "0.048"], ["71196.90", "0.510"], ["71198.40", "0.000"], ["71199.60", "0.002"], ["71199.80", "0.002"], ["71199.90", "0.004"], ["71200.10", "0.826"], ["71200.30", "0.003"], ["71200.40", "0.011"], ["71200.60", "0.032"], ["71200.70", "0.004"], ["71202.00", "0.510"], ["71203.50", "1.201"], ["71203.70", "7.725"], ["71204.10", "0.023"], ["71204.40", "1.263"], ["71205.00", "0.181"], ["71205.80", "0.097"], ["71206.10", "0.020"], ["71207.70", "0.114"], ["71207.80", "0.101"], ["71208.00", "0.078"], ["71211.50", "0.008"], ["71212.10", "0.223"], ["71212.20", "0.226"], ["71212.30", "0.002"], ["71212.60", "0.158"], ["71213.90", "0.162"], ["71214.80", "0.210"], ["71215.80", "0.120"], ["71215.90", "0.004"], ["71216.00", "0.002"], ["71216.40", "0.026"], ["71216.50", "0.003"], ["71216.60", "0.372"], ["71217.20", "0.004"], ["71217.30", "0.021"], ["71218.20", "0.000"], ["71218.50", "0.000"], ["71219.10", "0.041"], ["71219.60", "0.126"], ["71219.70", "0.019"], ["71220.00", "0.042"], ["71220.10", "0.612"], ["71220.20", "0.982"], ["71220.30", "0.014"], ["71220.70", "0.538"], ["71220.80", "0.028"], ["71221.00", "0.153"], ["71221.40", "0.080"], ["71221.50", "0.386"], ["71221.60", "0.137"], ["71221.70", "0.245"], ["71221.90", "0.001"], ["71222.00", "0.136"], ["71222.10", "0.000"], ["71222.20", "0.000"], ["71222.70", "0.025"], ["71222.80", "0.117"], ["71222.90", "0.510"], ["71223.00", "0.051"], ["71223.80", "0.437"], ["71224.20", "0.000"], ["71224.30", "0.000"], ["71225.00", "0.026"], ["71225.40", "0.145"], ["71225.50", "0.013"], ["71226.60", "0.189"], ["71226.80", "0.052"], ["71227.10", "0.000"], ["71227.50", "0.080"], ["71227.80", "0.007"], ["71228.30", "0.000"], ["71228.40", "0.014"], ["71228.50", "0.008"], ["71228.60", "0.009"], ["71229.10", "0.189"], ["71229.20", "0.070"], ["71229.30", "0.004"], ["71229.40", "0.360"], ["71229.50", "0.006"], ["71229.70", "0.005"], ["71230.20", "0.016"], ["71230.30", "0.019"], ["71230.40", "0.084"], ["71230.90", "0.020"], ["71231.10", "0.072"], ["71231.20", "0.003"], ["71231.40", "0.004"], ["71231.70", "0.176"], ["71231.80", "0.007"], ["71232.00", "0.010"], ["71232.60", "0.031"], ["71232.90", "0.000"], ["71233.20", "0.013"], ["71233.80", "2.342"], ["71233.90", "0.653"], ["71234.00", "0.012"], ["71234.20", "0.000"], ["71234.30", "0.002"], ["71234.60", "0.293"], ["71235.00", "0.214"], ["71235.30", "0.658"], ["71235.50", "0.002"], ["71235.90", "0.080"], ["71236.00", "0.004"], ["71236.10", "0.841"], ["71236.20", "1.556"], ["71236.70", "0.082"], ["71236.80", "0.009"], ["71236.90", "0.009"], ["71237.10", "0.003"], ["71237.40", "0.003"], ["71237.50", "0.284"], ["71238.20", "0.404"], ["71238.60", "0.033"], ["71238.80", "0.108"], ["71239.10", "0.161"], ["71239.40", "0.405"], ["71239.50", "0.002"], ["71239.70", "0.039"], ["71239.80", "0.136"], ["71239.90", "0.007"], ["71240.00", "0.047"], ["71240.10", "0.000"], ["71240.20", "0.429"], ["71240.30", "0.193"], ["71240.40", "0.020"], ["71240.50", "0.007"], ["71241.00", "0.080"], ["71241.60", "0.046"], ["71241.80", "0.002"], ["71242.10", "0.777"], ["71242.30", "0.000"], ["71242.40", "0.007"], ["71242.50", "0.019"], ["71242.80", "0.002"], ["71242.90", "0.002"], ["71243.00", "0.002"], ["71243.30", "0.252"], ["71243.50", "0.017"], ["71243.70", "0.005"], ["71243.90", "0.298"], ["71244.00", "0.005"], ["71244.10", "0.000"], ["71244.20", "0.009"], ["71244.70", "0.001"], ["71245.10", "0.000"], ["71245.20", "0.002"], ["71245.40", "0.002"], ["71245.50", "0.003"], ["71245.80", "0.004"], ["71245.90", "0.009"], ["71246.00", "0.006"], ["71246.40", "0.000"], ["71246.50", "0.001"], ["71246.70", "0.002"], ["71246.80", "0.091"], ["71246.90", "0.241"], ["71247.00", "1.102"], ["71247.10", "0.000"], ["71247.20", "0.001"], ["71247.30", "0.072"], ["71247.40", "0.315"], ["71247.70", "0.001"], ["71247.80", "0.597"], ["71247.90", "0.010"], ["71248.00", "0.005"], ["71248.10", "0.001"], ["71248.30", "0.003"], ["71248.40", "0.000"], ["71248.50", "0.044"], ["71248.60", "0.000"], ["71248.70", "0.000"], ["71248.90", "0.001"], ["71249.00", "0.005"], ["71249.20", "0.017"], ["71249.30", "0.000"], ["71249.40", "0.004"], ["71249.50", "0.271"], ["71249.60", "0.339"], ["71249.70", "0.000"], ["71249.80", "0.042"], ["71249.90", "0.002"], ["71250.00", "0.000"], ["71250.10", "0.002"], ["71250.20", "0.000"], ["71250.40", "0.002"], ["71250.50", "0.019"], ["71250.60", "0.832"], ["71250.70", "7.713"]], "a": [["71247.00", "0.000"], ["71247.30", "0.000"], ["71247.90", "0.000"], ["71248.00", "0.000"], ["71248.40", "0.000"], ["71248.50", "0.000"], ["71248.70", "0.000"], ["71248.80", "0.000"], ["71249.10", "0.000"], ["71249.40", "0.000"], ["71249.50", "0.000"], ["71249.60", "0.000"], ["71249.70", "0.000"], ["71249.80", "0.000"], ["71249.90", "0.000"], ["71250.00", "0.000"], ["71250.10", "0.000"], ["71250.20", "0.000"], ["71250.50", "0.000"], ["71250.60", "0.000"], ["71250.70", "0.000"], ["71250.80", "0.117"], ["71250.90", "0.000"], ["71251.00", "0.144"], ["71251.10", "0.000"], ["71251.50", "0.003"], ["71252.10", "0.000"], ["71252.20", "0.000"], ["71252.30", "0.009"], ["71252.40", "0.369"], ["71252.50", "0.005"], ["71252.80", "0.001"], ["71253.00", "0.000"], ["71253.10", "0.020"], ["71253.20", "0.004"], ["71253.40", "0.003"], ["71253.60", "0.002"], ["71253.70", "0.210"], ["71253.90", "0.006"], ["71254.00", "0.005"], ["71254.10", "0.072"], ["71254.20", "0.005"], ["71254.30", "0.212"], ["71254.40", "0.021"], ["71254.80", "0.002"], ["71254.90", "0.004"], ["71255.10", "0.000"], ["71255.30", "0.005"], ["71255.40", "0.000"], ["71255.80", "0.064"], ["71256.50", "0.005"], ["71256.60", "0.003"], ["71256.90", "0.006"], ["71257.00", "0.002"], ["71257.10", "0.000"], ["71257.30", "0.000"], ["71257.40", "0.004"], ["71257.50", "0.004"], ["71257.70", "0.001"], ["71257.80", "0.005"], ["71257.90", "0.002"], ["71258.00", "0.007"], ["71258.10", "0.006"], ["71258.20", "0.000"], ["71258.40", "0.004"], ["71258.50", "0.005"], ["71258.80", "0.004"], ["71259.10", "0.006"], ["71259.20", "0.000"], ["71259.50", "0.000"], ["71259.60", "0.006"], ["71259.90", "0.001"], ["71260.00", "0.011"], ["71260.40", "0.000"], ["71260.50", "0.003"], ["71260.60", "0.007"], ["71260.80", "0.003"], ["71261.00", "0.005"], ["71261.20", "0.000"], ["71261.30", "0.043"], ["71261.50", "0.000"], ["71261.60", "0.003"], ["71262.00", "0.059"], ["71262.10", "0.070"], ["71262.20", "0.115"], ["71262.30", "0.734"], ["71262.40", "0.206"], ["71262.70", "0.072"], ["71263.40", "0.222"], ["71263.50", "0.260"], ["71263.70", "0.000"], ["71263.80", "0.254"], ["71263.90", "0.011"], ["71264.10", "0.392"], ["71264.70", "0.003"], ["71264.80", "0.000"], ["71265.20", "0.003"], ["71265.50", "0.008"], ["71265.60", "0.483"], ["71265.80", "0.010"], ["71266.00", "0.318"], ["71266.10", "0.005"], ["71266.20", "0.003"], ["71266.60", "0.002"], ["71266.80", "0.003"], ["71266.90", "0.002"], ["71267.10", "0.004"], ["71267.20", "0.003"], ["71267.60", "0.002"], ["71267.80", "0.003"], ["71268.20", "0.242"], ["71268.50", "1.272"], ["71268.60", "0.003"], ["71269.00", "0.261"], ["71269.20", "0.002"], ["71269.30", "0.144"], ["71269.40", "0.124"], ["71269.90", "0.009"], ["71270.40", "0.000"], ["71270.60", "0.001"], ["71270.80", "0.002"], ["71271.00", "0.004"], ["71271.10", "1.082"], ["71271.40", "0.007"], ["71271.50", "0.002"], ["71271.60", "0.004"], ["71271.70", "0.001"], ["71271.90", "0.000"], ["71272.00", "0.089"], ["71272.30", "0.006"], ["71272.50", "0.635"], ["71272.60", "0.002"], ["71272.70", "0.004"], ["71272.80", "0.003"], ["71273.50", "0.053"], ["71273.70", "0.025"], ["71274.10", "0.009"], ["71274.30", "0.072"], ["71274.40", "0.010"], ["71274.70", "0.035"], ["71274.80", "0.000"], ["71274.90", "0.000"], ["71275.40", "0.002"], ["71275.50", "0.003"], ["71275.60", "1.615"], ["71275.70", "0.005"], ["71275.90", "0.000"], ["71276.10", "0.002"], ["71276.20", "0.005"], ["71276.40", "0.130"], ["71276.50", "0.155"], ["71276.70", "0.509"], ["71276.80", "0.450"], ["71277.70", "0.000"], ["71278.00", "0.002"], ["71278.20", "0.515"], ["71278.70", "0.105"], ["71278.80", "0.001"], ["71278.90", "0.512"], ["71279.00", "0.021"], ["71279.20", "0.005"], ["71279.30", "0.210"], ["71279.50", "0.014"], ["71279.60", "0.010"], ["71279.70", "0.053"], ["71280.00", "0.066"], ["71280.10", "0.248"], ["71280.20", "1.388"], ["71280.30", "1.042"], ["71280.40", "0.010"], ["71280.50", "0.004"], ["71281.00", "0.006"], ["71281.10", "0.508"], ["71281.20", "0.007"], ["71281.30", "0.006"], ["71281.40", "0.000"], ["71281.60", "0.019"], ["71281.70", "0.101"], ["71281.80", "0.011"], ["71282.00", "0.003"], ["71282.10", "0.007"], ["71282.30", "0.018"], ["71282.70", "0.008"], ["71282.80", "0.220"], ["71283.00", "0.004"], ["71283.20", "0.000"], ["71283.30", "0.011"], ["71283.40", "0.057"], ["71283.50", "0.000"], ["71284.10", "0.027"], ["71284.20", "0.377"], ["71284.30", "0.007"], ["71284.40", "0.086"], ["71284.60", "0.883"], ["71284.80", "0.006"], ["71285.40", "0.024"], ["71285.50", "0.012"], ["71285.60", "0.004"], ["71285.70", "0.004"], ["71285.80", "0.000"], ["71286.00", "0.012"], ["71286.40", "0.507"], ["71286.60", "0.047"], ["71286.70", "0.077"], ["71286.80", "0.000"], ["71286.90", "0.280"], ["71287.10", "0.001"], ["71287.80", "0.004"], ["71287.90", "0.590"], ["71288.00", "0.213"], ["71288.10", "0.000"], ["71288.30", "0.005"], ["71288.70", "1.404"], ["71289.00", "1.322"], ["71289.10", "0.219"], ["71289.20", "0.005"], ["71289.30", "0.016"], ["71289.60", "0.005"], ["71289.80", "0.009"], ["71290.30", "0.003"], ["71290.40", "0.326"], ["71290.50", "0.021"], ["71290.60", "0.007"], ["71290.80", "0.095"], ["71291.30", "0.286"], ["71291.80", "0.003"], ["71292.40", "0.840"], ["71292.80", "0.348"], ["71293.00", "0.003"], ["71294.00", "0.004"], ["71294.20", "0.003"], ["71294.40", "0.051"], ["71294.50", "0.000"], ["71294.90", "0.005"], ["71295.20", "0.062"], ["71295.40", "0.017"], ["71295.60", "0.002"], ["71296.50", "0.002"], ["71296.90", "1.125"], ["71297.00", "0.304"], ["71297.10", "0.093"], ["71297.20", "0.017"], ["71297.60", "0.020"], ["71297.70", "0.003"], ["71300.70", "0.000"], ["71302.90", "0.291"], ["71303.20", "0.283"], ["71303.60", "0.508"], ["71304.00", "0.118"], ["71305.30", "0.009"], ["71307.30", "0.001"], ["71307.90", "0.073"], ["71310.10", "0.003"], ["71312.50", "0.510"], ["71312.60", "3.560"], ["71318.40", "0.009"], ["71318.60", "0.004"], ["71320.90", "0.003"], ["71321.00", "0.286"], ["71322.00", "0.106"], ["71322.10", "0.128"], ["71322.20", "0.080"], ["71322.70", "0.088"], ["71325.60", "0.083"], ["71338.20", "0.976"], ["71338.50", "0.000"], ["71339.30", "0.000"], ["71339.50", "0.000"], ["71340.30", "1.716"], ["71340.50", "0.075"], ["71340.80", "0.000"], ["71341.20", "0.508"], ["71341.50", "0.047"], ["71341.60", "0.003"], ["71341.80", "0.040"], ["71342.30", "0.000"], ["71342.50", "0.180"], ["71342.70", "0.000"], ["71343.50", "0.300"], ["71345.80", "0.215"], ["71349.80", "0.071"], ["71350.10", "0.030"], ["71350.70", "0.000"], ["71351.10", "0.002"], ["71351.70", "0.203"], ["71352.10", "1.227"], ["71352.70", "0.000"], ["71353.00", "0.041"], ["71353.50", "0.252"], ["71353.70", "0.000"], ["71353.90", "0.120"], ["71354.00", "0.002"], ["71354.30", "0.000"], ["71354.50", "1.049"], ["71354.90", "2.339"], ["71355.30", "0.008"], ["71355.40", "0.217"], ["71355.50", "0.000"], ["71356.20", "0.316"], ["71356.40", "0.008"], ["71357.60", "0.000"], ["71358.60", "0.000"], ["71359.60", "0.000"], ["71363.10", "0.002"], ["71369.20", "0.000"], ["71374.40", "11.208"], ["71376.60", "10.003"], ["71382.10", "0.000"], ["71397.70", "0.444"], ["71402.60", "0.000"], ["71406.60", "1.037"], ["71409.60", "0.000"], ["71412.00", "0.000"], ["71423.60", "10.000"], ["71424.60", "0.005"], ["71440.30", "0.159"], ["71442.00", "0.262"], ["71443.00", "3.877"], ["71443.10", "0.159"], ["71443.20", "1.121"], ["71443.40", "0.000"], ["71446.70", "0.180"], ["71449.70", "0.516"], ["71480.70", "0.404"], ["71481.10", "10.003"], ["71531.40", "0.000"], ["71553.10", "0.000"], ["71559.40", "1.895"], ["71559.50", "10.000"], ["71559.90", "0.000"], ["71736.00", "0.018"], ["71959.50", "0.000"], ["71959.90", "0.000"], ["71960.40", "4.161"], ["71962.10", "0.000"], ["71962.30", "0.000"], ["71963.10", "0.000"], ["71963.20", "0.000"], ["71963.30", "0.000"], ["72679.10", "0.000"], ["74832.80", "0.008"], ["74848.80", "0.002"]]}}
{"local_ts": 1773384676579, "server_ts": 1773384676362, "data": {"e": "depthUpdate", "E": 1773384676363, "T": 1773384676362, "s": "BTCUSDT", "U": 10101352879910, "u": 10101352887108, "pu": 10101352879734, "b": [["1000.00", "27.492"], ["5000.00", "101.418"], ["20746.90", "0.099"], ["20858.80", "0.144"], ["20955.90", "0.099"], ["21058.80", "0.144"], ["21155.90", "0.288"], ["21158.80", "0.198"], ["67674.40", "0.049"], ["67693.00", "0.000"], ["69121.00", "0.008"], ["69277.50", "0.040"], ["70546.20", "0.000"], ["71000.10", "10.577"], ["71043.50", "0.162"], ["71105.50", "0.102"], ["71145.20", "0.095"], ["71167.30", "0.066"], ["71184.00", "0.105"], ["71200.20", "0.942"], ["71201.50", "1.074"], ["71204.90", "0.030"], ["71207.90", "0.997"], ["71208.40", "0.005"], ["71208.50", "0.622"], ["71212.60", "0.145"], ["71220.70", "0.003"], ["71220.80", "0.019"], ["71222.00", "0.010"], ["71222.90", "0.508"], ["71224.20", "0.002"], ["71224.30", "0.002"], ["71225.60", "0.003"], ["71225.70", "0.000"], ["71227.10", "0.000"], ["71227.30", "0.015"], ["71227.70", "0.012"], ["71227.80", "0.016"], ["71228.20", "0.031"], ["71228.40", "0.014"], ["71228.50", "0.002"], ["71228.60", "0.009"], ["71229.00", "0.073"], ["71229.10", "0.185"], ["71229.20", "0.274"], ["71230.10", "1.261"], ["71230.30", "0.004"], ["71230.80", "0.040"], ["71231.10", "0.317"], ["71233.20", "0.011"], ["71234.80", "0.000"], ["71235.00", "0.214"], ["71235.30", "0.021"], ["71236.20", "0.472"], ["71236.60", "0.390"], ["71236.70", "0.073"], ["71237.00", "0.009"], ["71237.10", "0.000"], ["71240.30", "0.034"], ["71240.70", "0.003"], ["71240.80", "0.001"], ["71240.90", "0.010"], ["71241.30", "0.052"], ["71241.50", "0.002"], ["71241.60", "0.002"], ["71241.90", "0.006"], ["71242.20", "0.013"], ["71242.30", "0.000"], ["71242.50", "0.510"], ["71242.60", "0.013"], ["71242.90", "2.040"], ["71243.20", "0.002"], ["71243.50", "0.638"], ["71243.70", "0.010"], ["71244.00", "0.025"], ["71244.10", "0.004"], ["71244.50", "0.323"], ["71244.80", "0.282"], ["71245.50", "0.006"], ["71245.60", "0.000"], ["71246.10", "0.053"], ["71246.20", "0.141"], ["71247.00", "0.004"], ["71247.30", "0.000"], ["71247.60", "0.610"], ["71247.80", "0.517"], ["71248.60", "0.000"], ["71250.10", "0.023"], ["71250.60", "0.035"], ["71251.80", "0.046"], ["71251.90", "1.147"], ["71252.00", "0.802"], ["71252.20", "1.005"], ["71254.30", "0.005"], ["71255.70", "0.049"], ["71256.00", "0.003"], ["71256.40", "0.006"], ["71256.50", "0.340"], ["71256.60", "0.066"], ["71256.70", "0.001"], ["71258.60", "0.002"], ["71258.70", "0.043"], ["71258.80", "5.480"]], "a": [["71258.90", "1.573"], ["71260.00", "0.004"], ["71260.30", "0.004"], ["71260.40", "0.000"], ["71261.10", "0.009"], ["71264.10", "0.000"], ["71265.20", "0.033"], ["71265.30", "0.000"], ["71267.30", "0.069"], ["71267.70", "0.059"], ["71267.80", "0.081"], ["71268.10", "0.002"], ["71268.40", "0.647"], ["71268.50", "1.310"], ["71268.80", "0.130"], ["71269.00", "0.178"], ["71269.10", "0.261"], ["71271.20", "0.070"], ["71271.90", "0.020"], ["71272.30", "0.062"], ["71272.80", "0.008"], ["71273.60", "0.587"], ["71274.10", "0.002"], ["71274.40", "0.010"], ["71274.50", "0.009"], ["71274.90", "0.007"], ["71275.00", "0.116"], ["71275.20", "0.141"], ["71275.40", "0.060"], ["71276.20", "0.073"], ["71277.90", "0.000"], ["71278.10", "0.002"], ["71278.20", "0.023"], ["71278.30", "0.001"], ["71279.00", "0.021"], ["71279.30", "0.007"], ["71279.80", "0.000"], ["71280.10", "0.054"], ["71280.20", "2.007"], ["71280.30", "1.049"], ["71280.40", "0.010"], ["71280.70", "0.002"], ["71280.90", "0.003"], ["71281.40", "0.007"], ["71281.50", "0.000"], ["71282.50", "0.000"], ["71283.00", "0.001"], ["71283.10", "0.074"], ["71283.20", "0.002"], ["71283.30", "0.077"], ["71283.50", "0.003"], ["71283.80", "0.000"], ["71283.90", "0.099"], ["71284.30", "0.007"], ["71284.80", "0.006"], ["71285.20", "0.000"], ["71285.30", "0.003"], ["71285.80", "0.000"], ["71285.90", "0.009"], ["71286.30", "0.008"], ["71286.50", "1.200"], ["71286.60", "0.043"], ["71286.70", "0.086"], ["71286.90", "0.000"], ["71287.40", "0.281"], ["71288.00", "0.219"], ["71288.10", "0.002"], ["71288.60", "0.003"], ["71288.70", "1.444"], ["71290.40", "0.000"], ["71292.60", "0.065"], ["71294.30", "0.004"], ["71294.50", "0.060"], ["71294.70", "0.511"], ["71296.90", "2.061"], ["71297.20", "1.015"], ["71298.30", "0.222"], ["71299.50", "0.619"], ["71301.80", "0.009"], ["71302.20", "0.007"], ["71304.70", "0.007"], ["71304.80", "0.111"], ["71305.90", "0.003"], ["71313.80", "0.002"], ["71314.70", "0.508"], ["71315.60", "0.019"], ["71315.70", "0.000"], ["71316.10", "0.049"], ["71316.80", "0.063"], ["71323.00", "0.021"], ["71323.80", "0.310"], ["71324.00", "0.033"], ["71324.80", "0.000"], ["71325.00", "0.013"], ["71325.70", "0.002"], ["71325.90", "0.000"], ["71327.80", "1.197"], ["71328.80", "1.058"], ["71329.80", "0.000"], ["71330.20", "0.003"], ["71331.20", "0.000"], ["71332.10", "0.009"], ["71332.40", "0.016"], ["71334.10", "0.203"], ["71334.80", "0.000"], ["71337.10", "0.349"], ["71337.80", "0.006"], ["71345.50", "0.066"], ["71366.30", "0.000"], ["71374.30", "3.840"], ["71374.60", "0.043"], ["71374.90", "4.062"], ["71375.00", "0.191"], ["71379.00", "0.001"], ["71386.20", "0.002"], ["71390.50", "1.773"], ["71396.40", "0.123"], ["71398.50", "0.110"], ["71398.60", "0.330"], ["71471.10", "0.000"], ["71471.30", "0.076"], ["71971.50", "0.000"], ["72684.00", "0.059"]]}}
{"local_ts": 1773384677605, "server_ts": 1773384677385, "data": {"e": "depthUpdate", "E": 1773384677387, "T": 1773384677385, "s": "BTCUSDT", "U": 10101352951917, "u": 10101352962140, "pu": 10101352951629, "b": [["5000.00", "101.438"], ["20758.80", "0.009"], ["20858.80", "0.891"], ["20946.90", "0.000"], ["20958.80", "0.018"], ["21058.80", "1.548"], ["21146.90", "0.000"], ["21152.30", "0.036"], ["70076.60", "0.641"], ["70546.20", "0.000"], ["70899.60", "0.035"], ["71034.60", "0.002"], ["71046.20", "0.000"], ["71047.30", "0.018"], ["71047.50", "4.556"], ["71048.30", "0.000"], ["71050.20", "0.000"], ["71053.40", "0.002"], ["71068.20", "0.155"], ["71071.40", "0.139"], ["71107.10", "0.026"], ["71107.30", "0.781"], ["71111.00", "0.558"], ["71120.00", "16.225"], ["71223.50", "0.125"], ["71229.00", "0.003"], ["71229.50", "0.251"], ["71231.10", "0.072"], ["71231.90", "0.070"], ["71233.70", "0.095"], ["71234.50", "0.004"], ["71236.00", "0.081"], ["71238.70", "0.000"], ["71240.50", "0.091"], ["71242.20", "0.511"], ["71242.90", "0.009"], ["71243.10", "0.635"], ["71243.70", "0.285"], ["71243.90", "0.043"], ["71244.90", "0.006"], ["71246.00", "0.178"], ["71247.50", "1.051"], ["71249.50", "0.040"], ["71250.10", "0.004"], ["71251.80", "0.044"], ["71253.30", "1.049"], ["71254.10", "0.008"], ["71254.30", "0.005"], ["71255.20", "0.106"], ["71258.80", "5.405"]], "a": [["71261.60", "0.005"], ["71271.60", "0.071"], ["71272.80", "0.006"], ["71278.90", "0.005"], ["71279.30", "0.077"], ["71284.20", "0.377"], ["71284.30", "0.133"], ["71309.30", "0.913"], ["71309.70", "0.012"], ["71310.30", "0.523"], ["71310.70", "0.799"], ["71310.90", "0.039"], ["71311.30", "0.768"], ["71311.70", "0.300"], ["71311.90", "0.000"], ["71312.90", "0.000"], ["71313.60", "0.042"], ["71314.50", "0.046"], ["71315.50", "0.380"], ["71406.10", "0.555"], ["71783.00", "0.278"], ["71832.20", "0.100"], ["71971.50", "0.000"], ["72067.90", "0.441"], ["74841.50", "0.052"], ["74843.10", "0.004"]]}}
{"local_ts": 1773384678628, "server_ts": 1773384678407, "data": {"e": "depthUpdate", "E": 1773384678409, "T": 1773384678407, "s": "BTCUSDT", "U": 10101353044347, "u": 10101353050231, "pu": 10101353044289, "b": [["1000.00", "27.492"], ["5000.00", "101.418"], ["20766.00", "0.711"], ["20858.80", "0.126"], ["20966.00", "1.251"], ["21058.80", "0.486"], ["33000.00", "9.339"], ["69266.00", "0.034"], ["70553.30", "0.000"], ["70688.70", "0.851"], ["70962.70", "0.011"], ["71016.40", "0.002"], ["71128.40", "0.335"], ["71210.80", "0.000"], ["71212.60", "0.215"], ["71216.50", "0.018"], ["71216.60", "0.374"], ["71220.00", "0.038"], ["71220.90", "0.005"], ["71221.90", "0.043"], ["71222.90", "0.550"], ["71228.10", "0.015"], ["71229.70", "0.005"], ["71230.10", "1.299"], ["71231.10", "0.000"], ["71233.40", "0.000"], ["71233.60", "0.064"], ["71235.30", "0.025"], ["71235.60", "0.047"], ["71236.60", "0.108"], ["71236.70", "0.072"], ["71236.80", "0.072"], ["71238.00", "0.037"], ["71238.70", "0.000"], ["71239.00", "0.070"], ["71240.30", "0.041"], ["71242.20", "0.013"], ["71242.30", "0.000"], ["71243.80", "0.012"], ["71244.00", "0.039"], ["71244.30", "0.004"], ["71245.40", "0.330"], ["71247.90", "0.084"], ["71250.10", "0.006"], ["71251.00", "0.007"], ["71251.80", "0.006"], ["71253.50", "0.076"], ["71254.30", "0.003"], ["71255.70", "0.007"], ["71255.80", "0.036"], ["71258.00", "0.009"], ["71258.90", "0.001"], ["71262.40", "0.000"], ["71262.50", "0.004"], ["71264.40", "0.004"], ["71266.00", "1.474"]], "a": [["71266.60", "0.002"], ["71268.40", "0.654"], ["71268.50", "1.270"], ["71271.60", "0.003"], ["71272.30", "0.017"], ["71273.10", "0.028"], ["71273.20", "0.000"], ["71274.20", "0.002"], ["71275.70", "0.004"], ["71276.90", "0.049"], ["71277.20", "0.017"], ["71279.30", "0.034"], ["71279.50", "0.020"], ["71279.80", "0.086"], ["71282.50", "0.000"], ["71283.20", "0.070"], ["71283.80", "0.000"], ["71284.60", "0.010"], ["71284.70", "0.203"], ["71286.40", "0.083"], ["71287.20", "0.000"], ["71288.20", "0.053"], ["71288.40", "0.009"], ["71288.50", "0.252"], ["71290.40", "0.000"], ["71316.40", "0.003"], ["71343.70", "0.000"], ["71345.10", "0.004"], ["71354.80", "0.155"], ["71611.60", "0.000"], ["71978.80", "0.025"], ["72477.50", "0.280"], ["74838.70", "0.000"]]}}
{"local_ts": 1773384679650, "server_ts": 1773384679434, "data": {"e": "depthUpdate", "E": 1773384679435, "T": 1773384679434, "s": "BTCUSDT", "U": 10101353106673, "u": 10101353110708, "pu": 10101353106585, "b": [["5000.00", "101.418"], ["20766.00", "0.189"], ["20861.50", "0.900"], ["20966.00", "0.585"], ["21161.50", "0.504"], ["57009.00", "0.000"], ["67667.40", "0.002"], ["70268.30", "1.632"], ["70548.90", "0.000"], ["70643.50", "0.160"], ["70909.70", "0.232"], ["71105.00", "12.586"], ["71107.30", "0.000"], ["71113.40", "0.639"], ["71165.60", "6.549"], ["71168.40", "2.064"], ["71202.20", "3.484"], ["71212.20", "0.005"], ["71212.40", "0.011"], ["71212.60", "0.142"], ["71224.70", "1.927"], ["71225.90", "0.037"], ["71230.30", "0.028"], ["71231.90", "0.000"], ["71234.00", "0.076"], ["71235.90", "0.218"], ["71237.00", "0.002"], ["71239.40", "0.007"], ["71239.90", "0.000"], ["71240.10", "0.006"], ["71240.20", "0.263"], ["71240.60", "0.000"], ["71241.10", "0.014"], ["71242.00", "7.746"], ["71242.20", "0.006"], ["71243.30", "0.221"], ["71244.60", "0.004"], ["71246.20", "0.141"], ["71252.50", "0.008"], ["71253.50", "0.287"], ["71260.20", "0.002"], ["71260.50", "0.000"]], "a": [["71261.60", "4.043"], ["71265.80", "0.073"], ["71266.70", "0.002"], ["71268.40", "0.651"], ["71271.70", "0.043"], ["71272.60", "0.044"], ["71272.80", "0.003"], ["71273.60", "0.045"], ["71273.80", "0.539"], ["71274.20", "0.000"], ["71274.30", "0.000"], ["71274.40", "0.078"], ["71274.80", "0.057"], ["71274.90", "0.140"], ["71279.40", "0.003"], ["71285.20", "0.213"], ["71286.40", "0.083"], ["71288.20", "0.057"], ["71288.70", "1.404"], ["71288.80", "1.053"], ["71289.40", "0.009"], ["71289.50", "0.011"], ["71290.40", "0.080"], ["71297.20", "0.149"], ["71302.30", "1.046"], ["71302.70", "0.027"], ["71304.80", "1.908"], ["71308.10", "0.192"], ["71308.40", "0.007"], ["71327.40", "3.840"], ["71329.30", "3.514"], ["71340.50", "0.126"], ["71345.10", "0.000"], ["71364.20", "1.640"], ["71364.30", "6.618"], ["71364.50", "0.003"], ["71406.10", "0.072"], ["71409.70", "0.591"], ["71425.50", "12.692"], ["71443.30", "0.071"], ["71454.00", "0.000"], ["71974.20", "0.000"], ["72269.70", "2.747"], ["72674.60", "0.000"], ["75970.10", "0.002"]]}}
{"local_ts": 1773384680671, "server_ts": 1773384680455, "data": {"e": "depthUpdate", "E": 1773384680457, "T": 1773384680455, "s": "BTCUSDT", "U": 10101353181826, "u": 10101353191768, "pu": 10101353181648, "b": [["1000.00", "27.492"], ["5000.00", "101.418"], ["20761.50", "0.783"], ["20861.50", "1.017"], ["21061.50", "0.513"], ["21161.50", "0.387"], ["33000.00", "9.339"], ["57009.00", "0.000"], ["69825.90", "0.000"], ["69835.70", "0.000"], ["70548.90", "0.000"], ["71146.30", "0.292"], ["71172.60", "0.231"], ["71206.10", "0.000"], ["71210.20", "0.036"], ["71211.80", "0.041"], ["71212.00", "0.848"], ["71213.00", "0.348"], ["71213.20", "0.184"], ["71213.40", "0.002"], ["71214.00", "0.045"], ["71214.80", "0.036"], ["71214.90", "0.036"], ["71215.40", "0.025"], ["71215.80", "0.116"], ["71216.20", "0.065"], ["71216.50", "0.043"], ["71217.30", "0.019"], ["71218.30", "0.302"], ["71219.30", "0.000"], ["71220.20", "0.839"], ["71224.80", "0.888"], ["71225.90", "0.000"], ["71226.10", "0.208"], ["71226.90", "0.007"], ["71227.70", "0.001"], ["71232.70", "0.073"], ["71233.90", "0.024"], ["71234.20", "0.070"], ["71236.00", "0.011"], ["71237.00", "0.044"], ["71238.00", "0.075"], ["71239.40", "0.000"], ["71239.70", "0.509"], ["71239.80", "0.010"], ["71240.20", "0.270"], ["71240.60", "0.045"], ["71241.10", "0.344"], ["71241.70", "1.682"], ["71242.00", "7.285"], ["71242.40", "0.285"], ["71243.50", "0.000"], ["71245.70", "0.003"], ["71246.40", "0.003"], ["71247.60", "0.425"], ["71249.40", "0.175"], ["71249.80", "0.073"], ["71250.20", "0.002"], ["71250.60", "0.035"], ["71250.80", "0.194"], ["71251.20", "0.635"], ["71251.30", "0.004"], ["71251.40", "0.008"], ["71251.70", "0.000"], ["71252.10", "0.032"], ["71252.20", "0.205"], ["71252.70", "0.015"], ["71252.80", "0.003"], ["71253.20", "0.005"], ["71254.00", "0.004"], ["71255.30", "0.020"], ["71258.20", "0.215"], ["71261.50", "0.886"]], "a": [["71262.90", "0.002"], ["71263.50", "0.004"], ["71266.70", "0.000"], ["71269.50", "0.068"], ["71269.90", "0.069"], ["71270.30", "0.051"], ["71270.50", "0.044"], ["71270.70", "0.046"], ["71270.90", "0.006"], ["71271.00", "0.119"], ["71271.30", "0.158"], ["71271.40", "0.067"], ["71272.10", "0.036"], ["71272.20", "0.011"], ["71272.30", "0.106"], ["71272.60", "0.142"], ["71273.00", "0.006"], ["71274.40", "0.076"], ["71275.90", "0.389"], ["71276.00", "0.005"], ["71276.10", "0.004"], ["71276.30", "0.258"], ["71277.40", "0.682"], ["71278.40", "0.001"], ["71278.50", "0.357"], ["71279.00", "0.103"], ["71279.50", "0.000"], ["71279.60", "0.001"], ["71279.90", "0.076"], ["71280.50", "0.008"], ["71280.60", "0.012"], ["71281.50", "0.070"], ["71282.60", "0.006"], ["71283.70", "0.072"], ["71284.30", "0.014"], ["71284.90", "0.520"], ["71285.20", "0.213"], ["71285.30", "0.005"], ["71285.90", "0.006"], ["71286.00", "0.010"], ["71288.80", "1.179"], ["71289.20", "0.005"], ["71293.70", "0.240"], ["71297.20", "0.017"], ["71299.00", "0.292"], ["71308.00", "0.004"], ["71308.10", "0.192"], ["71318.10", "0.003"], ["71342.40", "0.710"], ["71974.20", "0.000"], ["74841.00", "0.252"]]}}
{"local_ts": 1773384681696, "server_ts": 1773384681479, "data": {"e": "depthUpdate", "E": 1773384681481, "T": 1773384681479, "s": "BTCUSDT", "U": 10101353317343, "u": 10101353324506, "pu": 10101353317052, "b": [["1000.00", "27.492"], ["5000.00", "101.418"], ["20761.50", "1.152"], ["20764.40", "0.126"], ["20964.40", "0.378"], ["21061.50", "0.522"], ["21164.40", "0.522"], ["57009.00", "0.000"], ["57012.00", "0.204"], ["67702.00", "0.000"], ["69126.40", "0.000"], ["69842.40", "0.297"], ["70168.20", "0.000"], ["70551.80", "0.000"], ["70941.00", "0.008"], ["71016.90", "0.295"], ["71200.90", "0.000"], ["71211.00", "0.141"], ["71215.80", "0.154"], ["71215.90", "0.145"], ["71237.00", "0.274"], ["71239.50", "0.009"], ["71240.20", "0.263"], ["71243.10", "0.059"], ["71245.70", "0.003"], ["71245.80", "0.004"], ["71247.10", "1.207"], ["71247.50", "0.007"], ["71247.90", "0.010"], ["71248.10", "0.010"], ["71248.20", "1.136"], ["71248.80", "0.403"], ["71249.70", "0.359"], ["71250.10", "0.454"], ["71251.90", "0.130"], ["71257.30", "0.072"], ["71258.20", "0.007"], ["71261.10", "0.002"], ["71262.10", "0.000"], ["71262.80", "0.009"], ["71264.40", "5.535"]], "a": [["71264.50", "1.833"], ["71267.70", "0.000"], ["71268.40", "0.013"], ["71269.10", "0.016"], ["71271.60", "0.031"], ["71271.70", "0.019"], ["71275.20", "0.046"], ["71275.50", "0.263"], ["71275.70", "0.118"], ["71276.70", "0.208"], ["71276.80", "0.360"], ["71276.90", "0.001"], ["71278.00", "0.017"], ["71279.30", "0.015"], ["71279.90", "0.146"], ["71280.50", "0.019"], ["71281.70", "0.162"], ["71281.80", "0.234"], ["71282.60", "0.346"], ["71282.80", "0.208"], ["71283.00", "0.332"], ["71284.30", "0.022"], ["71284.80", "0.110"], ["71285.60", "0.019"], ["71285.80", "0.121"], ["71285.90", "0.254"], ["71286.10", "0.000"], ["71286.40", "1.050"], ["71286.50", "1.444"], ["71287.10", "0.043"], ["71287.30", "0.003"], ["71287.40", "0.094"], ["71288.10", "0.042"], ["71288.60", "0.511"], ["71288.90", "0.266"], ["71289.10", "0.246"], ["71289.20", "0.127"], ["71289.30", "0.003"], ["71289.40", "0.000"], ["71289.50", "0.031"], ["71289.90", "0.004"], ["71290.80", "0.096"], ["71291.10", "0.011"], ["71292.40", "0.504"], ["71293.10", "0.215"], ["71293.60", "0.319"], ["71293.70", "0.141"], ["71293.90", "0.084"], ["71298.50", "0.010"], ["71299.50", "0.092"], ["71299.60", "1.008"], ["71300.40", "0.004"], ["71300.50", "0.042"], ["71301.30", "0.002"], ["71301.40", "0.438"], ["71301.90", "0.022"], ["71302.10", "0.014"], ["71302.20", "0.007"], ["71303.20", "0.283"], ["71305.30", "0.586"], ["71310.70", "0.801"], ["71310.90", "0.039"], ["71321.70", "0.028"], ["71372.30", "0.922"], ["71387.40", "0.001"], ["71389.60", "0.024"], ["71446.90", "0.256"], ["71785.60", "0.000"], ["71977.10", "0.000"], ["74857.40", "0.002"], ["74862.70", "0.062"], ["89523.20", "0.000"]]}}
