{"local_ts": 1773384682725, "server_ts": 1773384682501, "data": {"e": "depthUpdate", "E": 1773384682503, "T": 1773384682501, "s": "BTCUSDT", "U": 10101353393110, "u": 10101353399599, "pu": 10101353392928, "b": [["5000.00", "101.418"], ["20761.50", "0.000"], ["20864.40", "0.252"], ["20964.40", "0.648"], ["21064.40", "0.252"], ["21164.40", "1.548"], ["33000.00", "9.343"], ["57009.00", "0.000"], ["57012.00", "0.200"], ["67684.50", "0.002"], ["67689.80", "0.000"], ["68566.90", "0.005"], ["69842.40", "0.295"], ["70551.80", "0.000"], ["70908.10", "0.000"], ["70941.60", "0.004"], ["71014.70", "0.017"], ["71144.20", "0.056"], ["71183.30", "0.037"], ["71184.40", "0.037"], ["71246.70", "0.008"], ["71249.40", "0.002"], ["71249.70", "0.287"], ["71258.40", "0.011"], ["71258.60", "0.002"], ["71264.20", "0.021"]], "a": [["71264.50", "0.722"], ["71271.30", "0.005"], ["71275.20", "0.044"], ["71276.30", "0.003"], ["71280.00", "0.066"], ["71281.20", "0.020"], ["71282.50", "0.000"], ["71282.90", "0.001"], ["71285.00", "0.049"], ["71286.80", "0.000"], ["71288.30", "0.007"], ["71288.80", "0.093"], ["71290.00", "0.142"], ["71290.10", "0.000"], ["71291.30", "0.021"], ["71291.50", "0.002"], ["71291.90", "0.106"], ["71292.40", "0.504"], ["71292.50", "0.008"], ["71292.60", "0.165"], ["71293.00", "0.527"], ["71293.80", "0.009"], ["71294.30", "0.370"], ["71295.20", "0.105"], ["71295.60", "0.162"], ["71296.90", "0.594"], ["71297.60", "0.002"], ["71298.10", "0.072"], ["71298.60", "0.003"], ["71299.40", "0.539"], ["71300.60", "0.033"], ["71301.90", "0.051"], ["71302.10", "0.014"], ["71303.00", "0.070"], ["71303.10", "0.046"], ["71303.90", "0.200"], ["71304.00", "1.126"], ["71304.40", "0.167"], ["71304.90", "0.007"], ["71305.00", "0.014"], ["71305.60", "0.029"], ["71306.80", "0.111"], ["71307.00", "0.586"], ["71310.80", "0.056"], ["71310.90", "0.041"], ["71322.00", "0.273"], ["71977.10", "0.000"], ["74827.90", "0.002"], ["89523.20", "0.000"]]}}
{"local_ts": 1773384683742, "server_ts": 1773384683524, "data": {"e": "depthUpdate", "E": 1773384683527, "T": 1773384683524, "s": "BTCUSDT", "U": 10101353458698, "u": 10101353466109, "pu": 10101353458535, "b": [["1000.00", "27.492"], ["5000.00", "101.418"], ["20764.40", "0.117"], ["20864.40", "0.783"], ["20964.40", "0.117"], ["21064.40", "1.557"], ["21164.40", "0.126"], ["57012.00", "0.200"], ["69458.80", "0.003"], ["69842.30", "0.002"], ["70054.60", "0.018"], ["70305.90", "1.560"], ["70551.80", "0.000"], ["70600.00", "73.416"], ["70908.10", "0.035"], ["71116.80", "0.666"]], "a": [["71264.50", "1.260"], ["71267.80", "0.003"], ["71277.70", "0.001"], ["71280.00", "0.066"], ["71281.20", "0.020"], ["71281.90", "0.000"], ["71282.50", "0.000"], ["71283.10", "0.011"], ["71283.70", "0.062"], ["71283.80", "0.000"], ["71284.40", "0.013"], ["71285.00", "0.034"], ["71285.20", "0.211"], ["71285.90", "0.254"], ["71286.30", "0.094"], ["71286.40", "1.050"], ["71287.10", "0.001"], ["71287.50", "0.119"], ["71287.70", "0.006"], ["71288.30", "0.500"], ["71288.60", "0.511"], ["71288.80", "0.093"], ["71288.90", "0.266"], ["71289.80", "0.010"], ["71290.00", "0.142"], ["71290.20", "0.005"], ["71291.10", "0.011"], ["71291.30", "0.021"], ["71291.40", "0.000"], ["71292.50", "0.052"], ["71292.70", "1.621"], ["71293.80", "0.017"], ["71294.00", "0.004"], ["71294.30", "0.551"], ["71295.00", "0.027"], ["71295.30", "0.026"], ["71295.90", "0.048"], ["71296.30", "0.510"], ["71297.10", "0.063"], ["71297.60", "0.002"], ["71301.90", "0.030"], ["71302.60", "0.005"], ["71302.70", "0.027"], ["71303.10", "0.046"], ["71303.50", "0.010"], ["71303.70", "0.004"], ["71304.40", "0.023"], ["71304.50", "0.940"], ["71304.70", "0.005"], ["71305.40", "0.389"], ["71306.30", "0.301"], ["71309.90", "0.060"], ["71310.80", "0.044"], ["71310.90", "0.041"], ["71311.00", "0.197"], ["71311.80", "0.096"], ["71412.70", "0.817"], ["71446.20", "0.161"], ["71600.00", "11.694"], ["71977.10", "0.000"], ["72070.50", "0.002"], ["72428.00", "0.455"], ["72643.30", "0.006"], ["74844.80", "0.002"], ["74850.40", "0.000"], ["89523.20", "0.000"]]}}
{"local_ts": 1773384684764, "server_ts": 1773384684548, "data": {"e": "depthUpdate", "E": 1773384684549, "T": 1773384684548, "s": "BTCUSDT", "U": 10101353525301, "u": 10101353528942, "pu": 10101353525217, "b": [["5000.00", "101.418"], ["20764.80", "0.387"], ["20864.40", "0.018"], ["20964.80", "0.774"], ["21064.40", "0.270"], ["57012.00", "0.204"], ["70552.20", "0.000"], ["70908.10", "0.035"], ["71210.50", "0.687"], ["71219.10", "0.061"], ["71228.10", "0.015"], ["71241.20", "0.008"], ["71242.20", "0.005"], ["71242.30", "0.000"], ["71243.60", "0.338"], ["71256.20", "0.000"], ["71257.10", "0.011"], ["71258.80", "0.143"], ["71263.20", "0.029"]], "a": [["71264.90", "2.784"], ["71265.70", "0.003"], ["71265.80", "0.034"], ["71266.60", "0.004"], ["71269.20", "0.002"], ["71270.80", "0.002"], ["71287.00", "0.005"], ["71294.30", "0.341"], ["71297.40", "0.080"], ["71297.50", "0.002"], ["71307.90", "0.068"], ["71346.90", "0.212"], ["71620.80", "0.000"], ["71977.50", "0.008"], ["72554.00", "5.233"], ["74827.90", "0.000"], ["89523.20", "0.000"]]}}
{"local_ts": 1773384685783, "server_ts": 1773384685568, "data": {"e": "depthUpdate", "E": 1773384685569, "T": 1773384685568, "s": "BTCUSDT", "U": 10101353628807, "u": 10101353636221, "pu": 10101353628644, "b": [["1000.00", "27.492"], ["5000.00", "101.398"], ["20764.40", "0.153"], ["20864.40", "0.828"], ["20964.40", "0.396"], ["20964.80", "0.144"], ["21164.40", "0.414"], ["57012.00", "0.200"], ["67672.80", "0.002"], ["69900.10", "0.000"], ["70152.70", "0.449"], ["70729.90", "0.706"], ["70975.40", "0.002"], ["71109.60", "0.036"], ["71110.40", "0.129"], ["71123.60", "0.329"], ["71127.20", "0.002"], ["71127.80", "0.110"], ["71127.90", "0.002"], ["71128.50", "0.492"], ["71128.90", "0.101"], ["71129.20", "0.025"], ["71129.50", "0.158"], ["71147.80", "0.156"], ["71189.50", "0.000"], ["71194.60", "0.216"], ["71207.30", "0.210"], ["71211.00", "0.002"], ["71214.10", "0.795"], ["71214.20", "0.006"], ["71221.60", "0.137"], ["71227.60", "0.004"], ["71228.50", "0.002"], ["71232.30", "0.005"], ["71232.60", "0.072"], ["71232.70", "0.071"], ["71234.70", "0.000"], ["71235.00", "0.221"], ["71238.30", "1.209"], ["71238.50", "0.505"], ["71239.70", "0.001"], ["71240.10", "0.013"], ["71241.30", "0.340"], ["71241.70", "1.331"], ["71241.80", "0.341"], ["71242.60", "0.013"], ["71243.30", "0.207"], ["71243.80", "0.059"], ["71244.50", "0.048"], ["71245.90", "0.007"], ["71246.30", "0.144"], ["71246.40", "0.039"], ["71246.60", "0.137"], ["71246.80", "0.120"], ["71246.90", "0.272"], ["71247.30", "0.061"], ["71247.70", "0.030"], ["71248.00", "0.038"], ["71249.80", "0.003"], ["71253.10", "0.004"]], "a": [["71264.50", "7.840"], ["71265.90", "0.044"], ["71270.40", "0.032"], ["71275.10", "0.126"], ["71275.20", "0.102"], ["71280.60", "0.152"], ["71286.60", "0.126"], ["71289.10", "0.226"], ["71290.10", "0.009"], ["71290.20", "0.014"], ["71290.80", "0.096"], ["71290.90", "0.005"], ["71293.30", "0.361"], ["71293.50", "0.053"], ["71296.60", "0.000"], ["71977.10", "0.000"], ["72430.70", "0.006"], ["72646.10", "0.004"], ["72829.70", "0.588"], ["72995.90", "0.000"], ["73055.90", "2.460"], ["89523.20", "0.000"]]}}
{"local_ts": 1773384686804, "server_ts": 1773384686588, "data": {"e": "depthUpdate", "E": 1773384686589, "T": 1773384686588, "s": "BTCUSDT", "U": 10101353691822, "u": 10101353697030, "pu": 10101353691765, "b": [["1000.00", "27.492"], ["5000.00", "101.418"], ["20764.40", "0.990"], ["20864.40", "0.810"], ["21064.40", "0.612"], ["21164.40", "0.288"], ["57012.00", "0.200"], ["67701.20", "0.004"], ["69051.00", "0.192"], ["69126.40", "0.005"], ["70551.80", "1.417"], ["70908.20", "0.010"], ["70940.10", "0.000"], ["71028.10", "0.000"], ["71194.70", "1.878"], ["71196.30", "0.000"], ["71211.20", "0.042"], ["71212.40", "0.051"], ["71216.00", "0.024"], ["71231.20", "0.038"], ["71231.30", "0.009"], ["71231.90", "0.000"], ["71232.00", "0.015"], ["71234.40", "0.104"], ["71235.10", "0.003"], ["71238.30", "0.016"], ["71240.20", "0.507"], ["71240.30", "1.196"], ["71241.10", "0.007"], ["71250.10", "0.321"], ["71259.70", "0.002"], ["71264.40", "0.192"]], "a": [["71264.50", "7.350"], ["71264.60", "1.114"], ["71275.10", "0.121"], ["71276.10", "0.011"], ["71279.90", "0.076"], ["71281.50", "0.070"], ["71281.70", "0.508"], ["71284.30", "0.007"], ["71284.50", "0.005"], ["71284.90", "0.524"], ["71290.10", "0.610"], ["71290.20", "0.014"], ["71290.80", "0.096"], ["71290.90", "0.005"], ["71292.60", "0.067"], ["71293.30", "0.235"], ["71293.40", "0.306"], ["71293.50", "0.179"], ["71309.40", "1.015"], ["71309.60", "0.058"], ["71491.50", "0.000"], ["71977.10", "0.000"], ["72255.00", "0.041"], ["72369.10", "0.977"], ["72538.40", "0.004"], ["72686.80", "0.000"], ["74846.70", "0.000"], ["74850.20", "0.002"], ["89523.20", "0.000"]]}}
{"local_ts": 1773384687829, "server_ts": 1773384687612, "data": {"e": "depthUpdate", "E": 1773384687613, "T": 1773384687612, "s": "BTCUSDT", "U": 10101353782568, "u": 10101353789574, "pu": 10101353782500, "b": [["5000.00", "101.418"], ["20764.40", "1.062"], ["20951.10", "0.189"], ["21064.40", "0.414"], ["21151.10", "0.360"], ["33000.00", "9.339"], ["67682.90", "0.002"], ["67688.50", "0.002"], ["70538.60", "0.002"], ["70908.10", "1.020"], ["70928.30", "0.002"], ["70941.80", "0.000"], ["71000.10", "10.739"], ["71021.10", "0.008"], ["71050.10", "2.785"], ["71074.30", "0.018"], ["71165.60", "1.516"], ["71181.80", "0.006"], ["71183.70", "0.275"], ["71186.10", "0.000"], ["71188.90", "3.724"], ["71189.00", "0.009"], ["71193.10", "0.952"], ["71200.00", "3.637"], ["71201.50", "0.133"], ["71203.90", "0.001"], ["71204.10", "1.022"], ["71204.20", "0.514"], ["71204.40", "1.162"], ["71208.10", "0.036"], ["71209.50", "0.548"], ["71210.00", "0.100"], ["71210.20", "0.003"], ["71210.90", "0.026"], ["71211.00", "0.807"], ["71211.30", "1.808"], ["71211.90", "0.098"], ["71213.30", "0.051"], ["71214.40", "0.016"], ["71215.20", "0.013"], ["71216.20", "0.024"], ["71218.00", "0.035"], ["71220.10", "0.610"], ["71222.70", "0.048"], ["71223.10", "0.026"], ["71223.90", "0.013"], ["71224.30", "0.183"], ["71225.10", "0.573"], ["71225.20", "0.316"], ["71226.80", "0.070"], ["71227.90", "0.000"], ["71229.60", "0.006"], ["71230.40", "0.004"], ["71232.10", "0.000"], ["71232.70", "0.009"], ["71233.80", "0.214"], ["71233.90", "0.024"], ["71234.00", "0.507"], ["71234.10", "0.634"], ["71234.70", "0.000"], ["71235.00", "0.221"], ["71235.40", "0.618"], ["71235.50", "0.530"], ["71236.00", "0.568"], ["71236.70", "0.142"], ["71236.80", "0.329"], ["71237.80", "0.007"], ["71239.40", "0.000"], ["71240.00", "0.017"], ["71242.00", "7.359"], ["71242.20", "0.287"], ["71243.00", "0.004"], ["71243.10", "0.286"], ["71244.90", "0.006"], ["71245.00", "0.528"], ["71245.90", "0.010"], ["71246.20", "0.037"], ["71247.00", "0.254"], ["71248.50", "0.007"], ["71249.20", "0.004"], ["71249.50", "0.014"], ["71251.00", "0.048"], ["71251.10", "5.864"]], "a": [["71251.20", "0.912"], ["71251.30", "0.000"], ["71251.80", "0.000"], ["71252.00", "0.002"], ["71253.50", "0.212"], ["71258.40", "0.426"], ["71258.50", "0.431"], ["71258.60", "0.010"], ["71258.70", "0.451"], ["71259.20", "0.003"], ["71262.30", "0.008"], ["71262.40", "0.014"], ["71263.50", "0.121"], ["71264.00", "0.484"], ["71264.10", "0.260"], ["71264.20", "0.345"], ["71264.30", "0.203"], ["71264.60", "0.011"], ["71265.50", "0.002"], ["71265.60", "0.008"], ["71266.60", "0.146"], ["71266.80", "0.020"], ["71268.80", "0.074"], ["71269.00", "0.046"], ["71269.70", "0.015"], ["71269.90", "0.098"], ["71271.50", "0.003"], ["71272.60", "0.004"], ["71273.20", "0.041"], ["71273.70", "0.003"], ["71273.80", "0.006"], ["71273.90", "0.138"], ["71275.20", "0.013"], ["71277.80", "0.007"], ["71278.40", "0.008"], ["71279.20", "0.008"], ["71279.90", "0.607"], ["71280.00", "0.066"], ["71281.00", "0.009"], ["71281.10", "0.040"], ["71281.70", "1.390"], ["71281.80", "0.221"], ["71281.90", "0.000"], ["71289.40", "0.000"], ["71289.60", "0.131"], ["71290.10", "0.002"], ["71291.50", "0.002"], ["71294.80", "0.022"], ["71295.80", "0.033"], ["71296.20", "0.281"], ["71296.60", "0.024"], ["71296.70", "0.000"], ["71296.80", "0.000"], ["71299.40", "0.510"], ["71299.80", "0.004"], ["71300.40", "0.004"], ["71300.70", "0.021"], ["71300.80", "0.007"], ["71301.30", "0.004"], ["71304.60", "0.131"], ["71304.70", "0.002"], ["71305.40", "0.328"], ["71306.80", "2.009"], ["71307.00", "0.611"], ["71329.60", "0.212"], ["71330.30", "0.004"], ["71332.60", "0.003"], ["71338.70", "0.233"], ["71533.40", "0.382"], ["71658.70", "0.675"], ["71658.80", "3.430"], ["71659.90", "0.000"], ["71799.00", "2.063"], ["71963.70", "0.004"], ["72989.00", "0.853"], ["89523.20", "0.000"]]}}
{"local_ts": 1773384688850, "server_ts": 1773384688634, "data": {"e": "depthUpdate", "E": 1773384688635, "T": 1773384688634, "s": "BTCUSDT", "U": 10101353847370, "u": 10101353852704, "pu": 10101353847362, "b": [["1000.00", "27.642"], ["5000.00", "101.418"], ["20854.50", "0.351"], ["20954.50", "0.189"], ["20958.80", "0.000"], ["21054.50", "0.450"], ["21154.50", "0.639"], ["21158.80", "0.000"], ["57012.00", "0.200"], ["70396.20", "0.426"], ["70464.00", "0.004"], ["70542.00", "0.078"], ["70928.30", "0.000"], ["70933.70", "0.005"], ["71110.10", "3.517"], ["71165.60", "1.516"], ["71171.50", "1.309"], ["71204.60", "0.242"], ["71206.00", "0.089"], ["71206.20", "0.366"], ["71219.20", "0.017"], ["71222.40", "0.000"], ["71223.10", "0.022"], ["71223.30", "0.002"], ["71225.70", "0.004"], ["71226.20", "0.004"], ["71226.50", "0.004"], ["71227.90", "0.070"], ["71232.70", "0.002"], ["71233.40", "0.000"], ["71234.90", "0.586"], ["71235.30", "0.516"], ["71235.70", "0.014"], ["71236.70", "0.005"], ["71238.30", "0.151"], ["71239.20", "0.000"], ["71241.00", "0.373"], ["71242.70", "1.745"], ["71243.00", "0.074"]], "a": [["71263.60", "0.007"], ["71263.70", "0.287"], ["71264.60", "0.008"], ["71267.70", "0.143"], ["71268.60", "0.009"], ["71270.70", "0.010"], ["71273.10", "0.007"], ["71275.20", "0.076"], ["71276.40", "0.070"], ["71278.10", "0.000"], ["71279.50", "0.099"], ["71280.10", "0.011"], ["71282.60", "0.343"], ["71296.60", "0.038"], ["71299.70", "0.026"], ["71300.40", "0.001"], ["71303.10", "0.018"], ["71303.20", "0.270"], ["71331.70", "0.133"], ["71332.40", "0.016"], ["71332.80", "0.006"], ["71333.60", "0.004"], ["71364.20", "0.358"], ["71425.40", "0.244"], ["71447.00", "0.161"], ["71624.80", "0.000"], ["71650.00", "3.347"], ["71967.10", "0.000"], ["74818.50", "0.050"], ["89523.20", "0.000"]]}}
{"local_ts": 1773384689874, "server_ts": 1773384689653, "data": {"e": "depthUpdate", "E": 1773384689655, "T": 1773384689653, "s": "BTCUSDT", "U": 10101353924750, "u": 10101353928766, "pu": 10101353924729, "b": [["5000.00", "101.418"], ["20752.00", "0.216"], ["20854.50", "0.207"], ["20952.00", "0.216"], ["21052.00", "1.170"], ["21054.50", "0.378"], ["21151.10", "0.036"], ["33000.00", "9.339"], ["67688.60", "0.002"], ["67701.20", "0.002"], ["67701.30", "0.002"], ["70539.50", "0.000"], ["70895.70", "0.055"], ["70928.60", "2.036"], ["70933.70", "0.003"], ["71161.20", "12.343"], ["71180.40", "1.224"], ["71218.50", "0.275"], ["71220.30", "0.010"], ["71224.40", "0.262"], ["71225.20", "0.388"], ["71226.10", "0.208"], ["71231.20", "0.505"], ["71232.30", "0.012"], ["71232.50", "0.636"], ["71233.00", "0.005"], ["71233.60", "0.002"], ["71236.80", "0.419"], ["71238.10", "0.046"], ["71243.00", "0.002"], ["71243.10", "0.032"], ["71243.40", "0.011"], ["71243.50", "0.000"], ["71249.20", "0.343"], ["71252.00", "1.983"]], "a": [["71261.30", "0.002"], ["71262.80", "0.100"], ["71263.30", "0.427"], ["71263.40", "0.507"], ["71264.30", "0.344"], ["71265.40", "0.008"], ["71266.70", "0.081"], ["71267.40", "0.002"], ["71268.90", "0.663"], ["71270.60", "0.000"], ["71274.80", "0.245"], ["71276.30", "0.001"], ["71277.70", "0.008"], ["71278.90", "0.004"], ["71279.00", "0.023"], ["71279.60", "0.001"], ["71279.70", "0.006"], ["71282.30", "0.058"], ["71283.30", "0.049"], ["71284.30", "0.053"], ["71285.20", "0.253"], ["71285.90", "0.002"], ["71286.20", "0.552"], ["71286.90", "0.002"], ["71287.70", "0.167"], ["71287.90", "0.006"], ["71288.80", "0.004"], ["71289.80", "0.010"], ["71290.50", "0.002"], ["71291.40", "0.000"], ["71292.40", "0.002"], ["71293.40", "0.306"], ["71294.30", "0.621"], ["71298.10", "0.226"], ["71298.30", "0.263"], ["71299.90", "0.060"], ["71300.20", "0.002"], ["71478.70", "0.022"], ["71964.60", "0.000"], ["72225.90", "0.000"], ["72242.50", "0.967"], ["72577.20", "1.031"]]}}
{"local_ts": 1773384690904, "server_ts": 1773384690676, "data": {"e": "depthUpdate", "E": 1773384690677, "T": 1773384690676, "s": "BTCUSDT", "U": 10101354001550, "u": 10101354013987, "pu": 10101354001354, "b": [["1000.00", "27.492"], ["5000.00", "101.418"], ["20752.00", "0.819"], ["20852.00", "0.081"], ["20952.00", "1.548"], ["21052.00", "0.171"], ["21152.00", "0.081"], ["57002.00", "0.000"], ["69839.20", "4.011"], ["70400.00", "10.829"], ["70539.50", "0.000"], ["70540.90", "0.006"], ["70900.00", "25.590"], ["70928.60", "2.034"], ["70931.00", "0.002"], ["71162.50", "0.077"], ["71168.10", "0.001"], ["71181.90", "0.009"], ["71192.80", "0.000"], ["71198.30", "1.409"], ["71203.90", "0.001"], ["71204.50", "0.017"], ["71205.10", "0.002"], ["71205.20", "0.054"], ["71205.40", "0.010"], ["71207.10", "0.243"], ["71207.50", "0.002"], ["71209.20", "0.146"], ["71211.00", "0.604"], ["71211.40", "0.301"], ["71216.40", "0.024"], ["71228.00", "0.030"], ["71231.60", "0.105"], ["71232.00", "0.010"], ["71232.10", "0.006"], ["71234.70", "0.014"], ["71235.80", "1.095"], ["71236.10", "0.894"], ["71237.30", "0.012"], ["71237.60", "0.002"], ["71237.70", "0.007"], ["71238.80", "0.143"], ["71241.10", "0.077"], ["71241.70", "0.017"], ["71241.80", "0.321"], ["71242.10", "1.082"], ["71242.20", "0.961"], ["71242.30", "0.051"], ["71242.60", "0.047"], ["71242.70", "1.322"], ["71242.80", "0.302"], ["71243.10", "0.506"], ["71243.40", "0.276"], ["71243.50", "0.085"], ["71243.90", "0.002"], ["71244.20", "0.046"], ["71244.50", "0.253"], ["71244.60", "0.000"], ["71244.90", "0.216"], ["71245.30", "0.003"], ["71246.80", "0.511"], ["71247.90", "1.057"], ["71248.50", "0.013"], ["71248.80", "0.003"], ["71249.20", "0.849"], ["71250.00", "0.008"], ["71250.10", "0.004"], ["71250.80", "0.013"], ["71250.90", "0.004"], ["71251.60", "0.002"], ["71252.00", "0.338"], ["71252.10", "3.435"], ["71252.20", "0.002"], ["71252.30", "0.000"], ["71252.90", "0.000"], ["71253.00", "0.002"], ["71253.10", "0.000"], ["71253.20", "0.004"], ["71253.30", "0.044"], ["71253.40", "8.919"]], "a": [["71252.10", "0.000"], ["71252.20", "0.000"], ["71252.40", "0.000"], ["71253.00", "0.000"], ["71253.10", "0.000"], ["71253.20", "0.000"], ["71253.40", "0.000"], ["71253.50", "0.239"], ["71253.90", "0.003"], ["71254.60", "0.062"], ["71255.80", "0.213"], ["71256.50", "0.014"], ["71257.70", "0.067"], ["71257.90", "0.005"], ["71258.10", "0.003"], ["71260.30", "0.000"], ["71260.50", "0.000"], ["71261.00", "0.002"], ["71261.40", "0.005"], ["71261.60", "0.023"], ["71262.10", "0.060"], ["71262.20", "0.420"], ["71262.30", "0.422"], ["71262.40", "0.431"], ["71262.50", "0.411"], ["71262.60", "0.005"], ["71265.50", "0.044"], ["71266.40", "0.118"], ["71266.60", "0.011"], ["71267.40", "0.002"], ["71268.00", "0.142"], ["71269.80", "0.077"], ["71270.70", "0.546"], ["71274.40", "0.007"], ["71274.80", "0.071"], ["71275.20", "0.012"], ["71280.50", "0.039"], ["71280.70", "0.003"], ["71281.70", "1.402"], ["71285.60", "0.143"], ["71285.90", "0.141"], ["71286.10", "0.000"], ["71287.70", "0.266"], ["71287.80", "0.004"], ["71288.50", "0.479"], ["71288.90", "0.392"], ["71294.60", "0.036"], ["71296.20", "0.281"], ["71299.10", "0.000"], ["71300.20", "0.002"], ["71300.50", "0.042"], ["71301.30", "0.004"], ["71314.80", "0.044"], ["71315.80", "0.000"], ["71316.50", "3.819"], ["71316.80", "0.002"], ["71317.70", "0.004"], ["71318.70", "0.000"], ["71320.00", "0.121"], ["71323.40", "0.201"], ["71324.60", "0.001"], ["71324.80", "0.081"], ["71325.60", "0.002"], ["71326.50", "0.003"], ["71326.90", "0.141"], ["71327.50", "0.000"], ["71328.50", "0.068"], ["71329.50", "0.002"], ["71333.10", "0.002"], ["71334.00", "0.004"], ["71334.10", "0.203"], ["71335.00", "0.081"], ["71335.90", "0.000"], ["71336.00", "0.000"], ["71336.90", "1.051"], ["71337.00", "0.002"], ["71337.30", "0.184"], ["71337.90", "0.002"], ["71338.20", "0.726"], ["71339.20", "0.222"], ["71340.20", "0.332"], ["71341.20", "0.550"], ["71360.00", "0.134"], ["71376.20", "0.012"], ["71442.30", "0.169"], ["71444.50", "0.159"], ["71445.90", "0.135"], ["71448.00", "2.718"], ["71815.10", "0.000"], ["71964.60", "0.000"], ["71966.00", "0.700"], ["74826.10", "0.004"], ["74841.00", "0.252"], ["76325.10", "0.000"]]}}
{"local_ts": 1773384691915, "server_ts": 1773384691700, "data": {"e": "depthUpdate", "E": 1773384691701, "T": 1773384691700, "s": "BTCUSDT", "U": 10101354070623, "u": 10101354074615, "pu": 10101354070540, "b": [["1000.00", "27.492"], ["5000.00", "101.418"], ["20752.00", "0.054"], ["20854.50", "1.368"], ["20952.00", "0.342"], ["21154.50", "0.765"], ["33000.00", "9.343"], ["67664.50", "0.000"], ["67677.90", "0.002"], ["70163.10", "0.000"], ["70397.00", "0.286"], ["70542.00", "0.078"], ["70682.00", "0.168"], ["70793.30", "0.012"], ["70803.10", "0.000"], ["70970.30", "0.221"], ["70980.10", "1.613"], ["71147.70", "0.009"], ["71157.60", "0.078"], ["71204.60", "0.270"], ["71204.80", "0.227"], ["71206.80", "0.508"], ["71207.00", "0.036"], ["71207.10", "0.467"], ["71211.10", "0.005"], ["71217.30", "2.060"], ["71234.00", "0.002"], ["71235.50", "0.011"], ["71238.40", "0.140"], ["71239.00", "0.405"], ["71239.10", "0.000"], ["71244.50", "0.005"], ["71247.40", "0.001"], ["71249.30", "0.000"]], "a": [["71254.60", "2.915"], ["71256.40", "0.005"], ["71259.90", "0.072"], ["71261.70", "0.010"], ["71263.20", "0.000"], ["71263.40", "0.480"], ["71263.50", "0.509"], ["71272.10", "0.024"], ["71280.40", "0.007"], ["71281.60", "0.507"], ["71302.10", "0.016"], ["71302.20", "0.330"], ["71361.40", "0.016"], ["71371.30", "0.000"], ["71539.80", "0.004"], ["71549.70", "0.000"], ["71718.70", "0.012"], ["71728.60", "3.582"], ["71824.50", "0.139"], ["71967.10", "0.000"], ["72031.30", "0.692"], ["72109.60", "4.436"], ["72517.50", "0.688"]]}}
{"local_ts": 1773384692939, "server_ts": 1773384692724, "data": {"e": "depthUpdate", "E": 1773384692725, "T": 1773384692724, "s": "BTCUSDT", "U": 10101354126563, "u": 10101354130921, "pu": 10101354126443, "b": [["5000.00", "101.418"], ["20754.50", "1.188"], ["20854.50", "0.522"], ["21054.50", "0.720"], ["21154.50", "0.099"], ["67658.80", "0.002"], ["70542.00", "0.078"], ["71193.10", "0.945"], ["71204.80", "0.043"], ["71243.80", "0.773"], ["71250.90", "0.069"]], "a": [["71257.80", "0.005"], ["71261.60", "0.006"], ["71261.70", "0.076"], ["71263.30", "0.420"], ["71263.40", "0.004"], ["71292.60", "0.065"], ["71302.00", "0.016"], ["71302.10", "0.014"], ["71967.10", "0.000"]]}}
{"local_ts": 1773384693961, "server_ts": 1773384693744, "data": {"e": "depthUpdate", "E": 1773384693745, "T": 1773384693744, "s": "BTCUSDT", "U": 10101354227973, "u": 10101354237381, "pu": 10101354227569, "b": [["1000.00", "27.492"], ["5000.00", "101.418"], ["20754.50", "0.882"], ["20954.50", "0.585"], ["21054.50", "0.315"], ["21154.50", "0.918"], ["67674.20", "0.000"], ["70542.00", "0.078"], ["71175.00", "0.002"], ["71183.20", "0.076"], ["71204.60", "0.185"], ["71207.00", "0.036"], ["71207.20", "0.072"], ["71244.50", "0.189"], ["71244.60", "0.103"]], "a": [["71258.10", "0.003"], ["71259.50", "0.002"], ["71263.20", "0.420"], ["71263.30", "0.000"], ["71263.40", "0.004"], ["71265.60", "0.008"], ["71265.70", "0.540"], ["71286.10", "0.000"], ["71302.00", "0.016"], ["71302.10", "0.014"], ["71967.10", "0.000"], ["74824.00", "0.188"]]}}
{"local_ts": 1773384694989, "server_ts": 1773384694768, "data": {"e": "depthUpdate", "E": 1773384694769, "T": 1773384694768, "s": "BTCUSDT", "U": 10101354296993, "u": 10101354301436, "pu": 10101354296891, "b": [["5000.00", "101.438"], ["20854.50", "0.450"], ["20954.50", "0.450"], ["21054.50", "0.657"], ["21154.50", "1.143"], ["69829.60", "0.004"], ["70221.30", "3.554"], ["70282.10", "1.845"], ["70477.80", "0.709"], ["70898.20", "0.000"], ["71015.90", "0.006"], ["71207.50", "0.004"], ["71207.70", "0.131"], ["71244.50", "0.185"], ["71244.80", "0.087"], ["71245.60", "0.610"], ["71247.40", "0.114"], ["71248.00", "0.012"]], "a": [["71261.70", "0.010"], ["71263.30", "0.420"], ["71263.50", "0.296"], ["71278.40", "0.003"], ["71301.70", "0.112"], ["71301.80", "0.009"], ["71478.80", "0.010"], ["71967.10", "0.000"], ["72266.40", "1.100"], ["72572.20", "0.008"], ["74832.40", "0.002"]]}}
{"local_ts": 1773384696008, "server_ts": 1773384695792, "data": {"e": "depthUpdate", "E": 1773384695793, "T": 1773384695792, "s": "BTCUSDT", "U": 10101354362470, "u": 10101354369913, "pu": 10101354362352, "b": [["1000.00", "27.492"], ["5000.00", "101.418"], ["20754.50", "0.315"], ["20854.50", "0.585"], ["20954.50", "0.387"], ["21054.50", "1.413"], ["21154.50", "0.000"], ["57004.00", "0.000"], ["67687.20", "0.002"], ["67691.00", "0.020"], ["67698.50", "0.002"], ["70920.00", "1.054"], ["71175.00", "0.002"], ["71207.70", "0.131"], ["71208.00", "0.174"], ["71208.20", "0.048"], ["71213.20", "0.000"], ["71215.60", "0.000"], ["71220.70", "0.056"], ["71224.60", "0.115"], ["71225.90", "0.288"], ["71227.10", "0.000"], ["71227.50", "0.325"], ["71229.50", "0.006"], ["71231.10", "0.003"], ["71231.20", "0.070"], ["71232.10", "0.000"], ["71233.80", "0.284"], ["71233.90", "0.032"], ["71234.50", "0.006"], ["71235.50", "0.164"], ["71237.40", "0.000"], ["71237.60", "0.009"], ["71238.40", "0.007"], ["71239.20", "0.000"], ["71239.90", "0.757"], ["71241.60", "0.631"], ["71242.80", "0.027"], ["71242.90", "0.186"], ["71243.80", "1.019"], ["71244.50", "0.068"], ["71245.70", "0.050"], ["71247.80", "0.133"], ["71248.00", "0.281"], ["71250.30", "0.002"], ["71251.00", "0.517"]], "a": [["71265.30", "0.005"], ["71270.60", "0.000"], ["71271.70", "0.143"], ["71274.40", "0.007"], ["71275.30", "0.006"], ["71275.90", "0.000"], ["71276.50", "0.594"], ["71277.00", "0.210"], ["71277.80", "0.586"], ["71278.40", "0.010"], ["71278.60", "0.841"], ["71279.90", "0.868"], ["71280.20", "0.120"], ["71280.50", "0.004"], ["71280.90", "0.371"], ["71281.40", "0.035"], ["71281.90", "0.000"], ["71282.20", "0.012"], ["71282.50", "0.000"], ["71282.70", "0.080"], ["71282.90", "0.246"], ["71283.00", "0.001"], ["71284.20", "1.123"], ["71286.00", "0.106"], ["71286.10", "0.085"], ["71287.40", "0.005"], ["71288.00", "0.161"], ["71289.70", "0.009"], ["71290.20", "0.104"], ["71290.50", "0.025"], ["71301.30", "0.004"], ["71301.60", "0.073"], ["71307.40", "0.033"], ["71967.10", "0.000"], ["73590.00", "0.339"], ["74104.80", "1.155"], ["74824.00", "0.186"]]}}
{"local_ts": 1773384697029, "server_ts": 1773384696811, "data": {"e": "depthUpdate", "E": 1773384696813, "T": 1773384696811, "s": "BTCUSDT", "U": 10101354450050, "u": 10101354460799, "pu": 10101354449837, "b": [["1000.00", "27.492"], ["5000.00", "101.418"], ["20759.80", "0.234"], ["20859.80", "0.171"], ["20860.70", "0.009"], ["20959.80", "0.819"], ["20960.70", "0.018"], ["21054.50", "0.063"], ["21159.80", "0.162"], ["21160.70", "0.018"], ["33000.00", "9.339"], ["40000.00", "49.588"], ["69829.50", "0.008"], ["70230.60", "0.000"], ["70253.40", "0.002"], ["70254.50", "0.000"], ["70255.90", "0.014"], ["70258.70", "0.016"], ["70259.80", "0.299"], ["70259.90", "0.002"], ["70547.20", "0.000"], ["70547.30", "0.006"], ["70548.10", "0.007"], ["70699.50", "0.071"], ["70904.30", "0.000"], ["71028.40", "0.001"], ["71047.70", "0.001"], ["71067.80", "0.081"], ["71110.20", "0.508"], ["71110.30", "0.288"], ["71117.30", "0.200"], ["71118.20", "0.064"], ["71121.70", "0.040"], ["71124.20", "0.062"], ["71132.90", "0.005"], ["71159.80", "0.004"], ["71168.50", "0.003"], ["71172.20", "0.019"], ["71177.00", "0.101"], ["71177.70", "1.051"], ["71183.70", "0.006"], ["71184.10", "0.404"], ["71185.40", "0.051"], ["71185.90", "0.101"], ["71186.00", "0.049"], ["71189.00", "0.007"], ["71191.40", "0.003"], ["71195.40", "0.000"], ["71199.30", "0.508"], ["71204.20", "0.617"], ["71204.30", "0.073"], ["71204.50", "0.286"], ["71204.60", "0.496"], ["71206.40", "0.019"], ["71206.50", "0.990"], ["71206.90", "0.187"], ["71207.00", "0.039"], ["71207.30", "0.437"], ["71210.80", "0.028"], ["71212.20", "0.002"], ["71212.30", "0.003"], ["71212.40", "0.009"], ["71212.50", "0.014"], ["71216.00", "0.002"], ["71217.00", "0.010"], ["71217.30", "2.110"], ["71217.90", "0.215"], ["71218.20", "0.000"], ["71219.70", "0.128"], ["71220.90", "0.005"], ["71221.50", "0.115"], ["71223.00", "0.011"], ["71223.40", "0.002"], ["71225.50", "0.064"], ["71227.10", "0.034"], ["71228.60", "0.010"], ["71229.30", "0.002"], ["71229.70", "0.005"], ["71231.10", "0.004"], ["71231.20", "0.000"], ["71231.80", "0.078"], ["71232.00", "0.006"], ["71232.10", "0.210"], ["71233.20", "0.252"], ["71234.10", "0.073"], ["71235.00", "0.216"], ["71236.40", "0.053"], ["71237.60", "0.000"], ["71238.00", "0.046"], ["71238.20", "0.928"], ["71238.40", "0.001"], ["71238.50", "0.000"], ["71238.60", "0.005"], ["71238.80", "0.002"], ["71239.20", "0.070"], ["71239.30", "0.010"], ["71240.50", "0.131"], ["71243.10", "0.004"], ["71243.50", "0.126"], ["71243.80", "0.063"], ["71244.10", "0.003"], ["71244.50", "0.001"], ["71245.00", "0.008"], ["71245.50", "0.008"], ["71245.60", "0.004"], ["71245.90", "0.045"], ["71246.10", "0.572"], ["71246.40", "0.117"], ["71246.50", "0.693"], ["71246.80", "0.583"], ["71247.00", "0.214"], ["71247.10", "0.003"], ["71247.30", "0.258"], ["71247.70", "0.198"], ["71248.10", "0.021"], ["71248.20", "0.079"], ["71248.30", "0.021"], ["71248.50", "0.013"], ["71248.60", "0.000"], ["71249.10", "0.000"], ["71249.30", "0.030"], ["71249.50", "0.008"], ["71249.60", "0.034"], ["71249.70", "0.002"], ["71250.20", "0.004"], ["71252.70", "0.001"], ["71252.90", "0.003"], ["71253.60", "0.508"], ["71253.90", "0.312"], ["71254.80", "0.003"], ["71255.10", "0.007"], ["71255.80", "0.009"], ["71256.00", "0.005"], ["71257.10", "0.011"], ["71257.20", "0.000"], ["71257.30", "0.130"], ["71259.00", "0.000"], ["71259.10", "0.000"], ["71259.40", "0.212"], ["71259.70", "0.004"], ["71259.80", "0.228"], ["71259.90", "0.035"], ["71260.00", "3.739"], ["71260.10", "0.000"], ["71260.20", "0.002"], ["71260.30", "0.000"], ["71260.40", "0.000"], ["71260.50", "0.002"], ["71260.60", "0.002"], ["71260.70", "8.087"]], "a": [["71259.90", "0.000"], ["71260.00", "0.000"], ["71260.10", "0.000"], ["71260.20", "0.000"], ["71260.40", "0.000"], ["71260.50", "0.000"], ["71260.80", "0.638"], ["71262.40", "0.009"], ["71263.80", "0.009"], ["71264.10", "0.004"], ["71264.40", "0.002"], ["71264.60", "0.006"], ["71264.80", "0.013"], ["71265.00", "0.216"], ["71265.20", "0.008"], ["71265.60", "0.008"], ["71265.80", "0.013"], ["71266.20", "0.006"], ["71266.90", "0.004"], ["71267.00", "0.251"], ["71268.10", "0.000"], ["71268.20", "0.003"], ["71268.70", "0.003"], ["71269.10", "0.012"], ["71272.40", "0.099"], ["71273.30", "0.668"], ["71273.40", "0.324"], ["71273.80", "0.460"], ["71274.20", "0.005"], ["71274.30", "0.000"], ["71274.60", "0.057"], ["71275.10", "0.297"], ["71275.50", "0.003"], ["71276.50", "0.592"], ["71277.70", "0.005"], ["71278.60", "0.291"], ["71279.60", "0.002"], ["71279.90", "0.801"], ["71280.40", "0.007"], ["71280.70", "0.006"], ["71281.00", "0.011"], ["71281.10", "0.007"], ["71281.40", "0.001"], ["71281.50", "0.007"], ["71281.70", "0.004"], ["71281.80", "0.226"], ["71282.20", "0.012"], ["71282.50", "0.070"], ["71282.60", "1.025"], ["71284.80", "0.006"], ["71285.20", "0.220"], ["71285.70", "0.161"], ["71285.90", "0.009"], ["71286.00", "0.106"], ["71286.90", "0.002"], ["71287.10", "0.071"], ["71288.20", "0.291"], ["71288.30", "0.007"], ["71288.50", "0.479"], ["71289.00", "0.256"], ["71289.40", "0.210"], ["71289.70", "0.049"], ["71290.30", "0.131"], ["71290.50", "0.506"], ["71291.40", "0.000"], ["71291.50", "0.002"], ["71291.70", "0.004"], ["71292.00", "0.106"], ["71292.10", "0.494"], ["71293.30", "0.009"], ["71295.50", "0.564"], ["71295.60", "0.307"], ["71296.00", "0.094"], ["71296.40", "0.167"], ["71297.10", "0.317"], ["71298.20", "1.881"], ["71298.70", "0.000"], ["71300.50", "0.045"], ["71305.20", "0.043"], ["71306.50", "1.931"], ["71306.60", "0.203"], ["71306.90", "0.009"], ["71307.10", "0.217"], ["71308.10", "0.196"], ["71308.30", "0.002"], ["71311.60", "0.000"], ["71312.20", "0.050"], ["71312.80", "0.001"], ["71315.60", "0.022"], ["71315.80", "0.007"], ["71323.40", "0.015"], ["71327.60", "0.289"], ["71327.90", "0.002"], ["71328.50", "0.000"], ["71328.80", "1.115"], ["71329.90", "0.114"], ["71336.00", "0.047"], ["71338.10", "0.000"], ["71339.10", "0.004"], ["71342.60", "0.004"], ["71351.30", "0.031"], ["71370.00", "0.409"], ["71378.30", "0.284"], ["71386.20", "0.002"], ["71387.00", "0.005"], ["71445.30", "0.159"], ["71446.10", "0.161"], ["71972.50", "0.694"], ["71972.60", "0.000"], ["71973.40", "0.005"], ["72557.40", "0.000"], ["72686.00", "0.186"], ["74819.50", "0.050"]]}}
{"local_ts": 1773384698048, "server_ts": 1773384697832, "data": {"e": "depthUpdate", "E": 1773384697833, "T": 1773384697832, "s": "BTCUSDT", "U": 10101354542597, "u": 10101354551921, "pu": 10101354542342, "b": [["5000.00", "101.418"], ["20754.50", "0.000"], ["20764.80", "0.045"], ["20864.80", "1.278"], ["20954.50", "0.198"], ["20955.90", "0.000"], ["20957.70", "0.000"], ["20959.80", "0.000"], ["21064.80", "0.045"], ["21164.80", "0.594"], ["64138.30", "0.002"], ["70552.20", "0.000"], ["70694.70", "0.062"], ["70906.00", "0.613"], ["70977.50", "0.006"], ["70986.60", "0.000"], ["71132.90", "0.002"], ["71137.90", "0.003"], ["71165.70", "1.649"], ["71165.80", "0.121"], ["71168.50", "0.000"], ["71173.50", "0.003"], ["71204.20", "0.614"], ["71209.20", "0.101"], ["71216.40", "0.024"], ["71216.80", "0.005"], ["71223.80", "0.298"], ["71225.40", "0.054"], ["71227.10", "0.000"], ["71227.70", "0.001"], ["71232.60", "0.002"], ["71232.70", "0.000"], ["71233.30", "0.013"], ["71233.40", "0.009"], ["71236.10", "0.562"], ["71239.80", "0.388"], ["71239.90", "0.265"], ["71241.00", "0.035"], ["71242.00", "7.245"], ["71247.10", "1.150"], ["71248.10", "0.003"], ["71248.60", "0.009"], ["71249.20", "0.850"], ["71253.50", "0.162"], ["71256.00", "0.009"], ["71257.50", "0.002"], ["71257.70", "0.074"], ["71259.80", "0.004"], ["71260.50", "0.000"], ["71264.80", "6.246"]], "a": [["71266.20", "0.004"], ["71270.10", "0.002"], ["71272.00", "0.185"], ["71272.50", "0.045"], ["71272.90", "0.000"], ["71273.40", "0.013"], ["71277.20", "0.002"], ["71277.50", "0.003"], ["71282.50", "0.191"], ["71282.70", "0.010"], ["71282.80", "0.836"], ["71284.90", "0.021"], ["71286.20", "0.075"], ["71286.90", "0.002"], ["71288.10", "0.070"], ["71290.50", "0.002"], ["71290.60", "0.043"], ["71292.60", "0.093"], ["71293.20", "0.242"], ["71293.40", "0.564"], ["71293.50", "0.455"], ["71293.60", "0.319"], ["71293.70", "0.002"], ["71293.90", "0.015"], ["71294.30", "0.343"], ["71294.40", "0.060"], ["71295.40", "0.019"], ["71296.00", "0.033"], ["71303.10", "0.079"], ["71311.30", "0.813"], ["71311.50", "0.010"], ["71363.30", "0.058"], ["71363.40", "0.014"], ["71899.60", "2.763"], ["71977.50", "0.008"], ["72369.40", "0.413"], ["72690.10", "0.010"], ["72699.30", "1.647"], ["74838.00", "0.056"], ["78391.40", "0.002"]]}}
{"local_ts": 1773384699066, "server_ts": 1773384698852, "data": {"e": "depthUpdate", "E": 1773384698853, "T": 1773384698852, "s": "BTCUSDT", "U": 10101354641322, "u": 10101354650512, "pu": 10101354641186, "b": [["1000.00", "27.492"], ["5000.00", "101.418"], ["20764.80", "1.377"], ["20859.80", "0.090"], ["20864.80", "0.315"], ["21064.80", "0.810"], ["21159.80", "0.090"], ["33000.00", "9.339"], ["57004.00", "0.000"], ["64138.30", "0.002"], ["70552.20", "0.000"], ["70908.40", "0.000"], ["70938.40", "0.013"], ["70938.50", "0.189"], ["71072.50", "0.078"], ["71220.20", "0.839"], ["71228.60", "0.003"], ["71229.20", "1.878"], ["71233.00", "0.003"], ["71236.40", "0.053"], ["71238.90", "0.429"], ["71240.90", "0.005"], ["71243.90", "0.112"], ["71247.40", "0.003"], ["71247.70", "0.199"], ["71248.40", "0.000"], ["71248.90", "0.003"], ["71249.60", "0.509"], ["71251.20", "0.631"], ["71255.40", "0.000"], ["71264.80", "6.095"]], "a": [["71264.90", "0.639"], ["71267.50", "0.071"], ["71268.00", "0.004"], ["71272.40", "0.080"], ["71272.90", "0.000"], ["71274.70", "0.080"], ["71277.50", "0.018"], ["71279.60", "0.002"], ["71280.90", "0.178"], ["71284.90", "0.041"], ["71285.30", "0.003"], ["71285.60", "0.003"], ["71286.20", "0.196"], ["71286.90", "0.633"], ["71288.00", "0.163"], ["71289.00", "0.256"], ["71291.10", "0.079"], ["71291.80", "0.003"], ["71293.10", "0.003"], ["71293.40", "0.368"], ["71294.20", "0.507"], ["71297.00", "0.467"], ["71300.50", "0.073"], ["71311.10", "0.043"], ["71311.20", "0.117"], ["71446.60", "0.142"], ["71977.50", "0.008"], ["72155.70", "0.131"], ["72262.50", "0.553"], ["72369.40", "1.738"], ["74844.30", "0.002"], ["78391.40", "0.002"]]}}
{"local_ts": 1773384700101, "server_ts": 1773384699872, "data": {"e": "depthUpdate", "E": 1773384699873, "T": 1773384699872, "s": "BTCUSDT", "U": 10101354736010, "u": 10101354743946, "pu": 10101354735777, "b": [["5000.00", "101.418"], ["20764.80", "0.684"], ["20964.80", "0.675"], ["21064.80", "0.225"], ["21164.80", "1.116"], ["64138.30", "0.002"], ["70389.10", "0.000"], ["70552.20", "0.000"], ["70904.40", "0.002"], ["70936.50", "0.045"], ["70938.40", "0.011"], ["70944.10", "0.002"], ["71015.40", "2.705"], ["71176.60", "0.002"], ["71185.00", "0.074"], ["71186.40", "0.004"], ["71190.30", "0.000"], ["71198.80", "0.048"], ["71200.00", "3.652"], ["71200.70", "0.002"], ["71216.20", "0.026"], ["71217.00", "0.012"], ["71217.30", "0.019"], ["71229.20", "1.814"], ["71232.60", "0.002"], ["71232.70", "0.000"], ["71233.30", "0.013"], ["71233.40", "0.009"], ["71235.60", "0.083"], ["71244.70", "0.008"], ["71245.80", "0.000"], ["71252.10", "0.029"], ["71256.40", "0.002"], ["71257.70", "0.011"], ["71264.60", "0.002"], ["71264.70", "0.027"], ["71264.80", "3.287"]], "a": [["71267.80", "0.003"], ["71269.40", "0.002"], ["71273.80", "0.124"], ["71277.80", "0.007"], ["71288.00", "0.161"], ["71288.10", "0.007"], ["71288.70", "0.898"], ["71288.80", "0.006"], ["71291.50", "0.002"], ["71291.60", "0.001"], ["71292.20", "0.045"], ["71292.30", "0.024"], ["71295.70", "0.109"], ["71295.80", "0.000"], ["71300.50", "0.045"], ["71310.10", "0.005"], ["71310.20", "0.009"], ["71329.10", "0.000"], ["71343.30", "0.000"], ["71370.00", "0.409"], ["71977.50", "0.008"], ["74856.60", "0.002"], ["78391.40", "0.002"], ["89523.20", "0.000"]]}}
{"local_ts": 1773384701110, "server_ts": 1773384700894, "data": {"e": "depthUpdate", "E": 1773384700895, "T": 1773384700894, "s": "BTCUSDT", "U": 10101354800787, "u": 10101354810440, "pu": 10101354800739, "b": [["1000.00", "27.492"], ["5000.00", "101.418"], ["20864.80", "0.540"], ["20964.80", "0.360"], ["21064.80", "0.846"], ["21164.80", "0.954"], ["57012.00", "0.212"], ["64138.30", "0.002"], ["67700.30", "0.002"], ["70151.60", "0.000"], ["70552.20", "0.000"], ["70908.40", "0.000"], ["70912.20", "0.000"], ["70912.30", "0.182"], ["70936.50", "0.045"], ["71172.20", "0.021"], ["71173.30", "0.294"], ["71177.50", "1.709"], ["71190.50", "0.000"], ["71204.30", "0.000"], ["71204.40", "1.166"], ["71212.30", "0.002"], ["71216.20", "0.028"], ["71216.50", "0.003"], ["71217.90", "0.005"], ["71224.00", "0.008"], ["71227.50", "0.325"], ["71228.40", "0.894"], ["71228.50", "0.004"], ["71229.10", "0.001"], ["71229.20", "1.812"], ["71229.30", "0.574"], ["71229.50", "0.026"], ["71231.20", "0.089"], ["71232.00", "0.006"], ["71232.60", "0.011"], ["71232.70", "0.009"], ["71233.30", "0.004"], ["71233.40", "0.000"], ["71233.80", "0.284"], ["71234.00", "0.004"], ["71234.10", "0.005"], ["71234.20", "0.070"], ["71234.40", "0.034"], ["71234.70", "0.000"], ["71234.80", "0.001"], ["71234.90", "0.072"], ["71235.60", "0.003"], ["71236.00", "0.510"], ["71236.60", "0.003"], ["71237.20", "0.064"], ["71239.00", "0.146"], ["71240.50", "0.514"], ["71240.60", "0.000"], ["71241.60", "0.631"], ["71242.20", "0.855"], ["71242.60", "0.029"], ["71242.70", "1.827"], ["71242.80", "0.143"], ["71243.00", "0.002"], ["71243.30", "0.209"], ["71243.40", "0.263"], ["71243.50", "1.251"], ["71243.60", "0.001"], ["71244.40", "0.508"], ["71244.50", "0.001"], ["71244.70", "0.004"], ["71244.80", "0.339"], ["71245.10", "0.007"], ["71245.40", "0.296"], ["71245.50", "0.008"], ["71246.30", "0.000"], ["71247.40", "0.283"], ["71247.50", "0.004"], ["71248.00", "0.084"], ["71248.10", "0.143"], ["71248.20", "0.118"], ["71248.40", "0.000"], ["71248.80", "0.153"], ["71249.00", "0.011"], ["71249.40", "0.007"], ["71249.60", "0.004"], ["71250.70", "0.003"], ["71250.80", "0.002"], ["71251.00", "0.519"], ["71251.10", "0.091"], ["71251.30", "0.049"], ["71251.60", "0.008"], ["71252.40", "0.002"], ["71253.10", "0.021"], ["71253.80", "0.040"], ["71253.90", "0.002"], ["71254.10", "0.073"], ["71255.10", "0.003"], ["71255.90", "0.065"], ["71256.30", "0.000"], ["71256.50", "0.002"], ["71256.70", "0.006"], ["71257.10", "0.004"], ["71258.10", "0.119"], ["71259.30", "0.221"], ["71259.60", "0.000"], ["71260.20", "0.001"], ["71260.60", "0.006"], ["71261.70", "0.044"], ["71262.40", "0.003"], ["71264.80", "1.227"]], "a": [["71264.90", "3.845"], ["71265.60", "0.017"], ["71266.30", "0.000"], ["71267.00", "0.002"], ["71267.10", "0.003"], ["71267.70", "0.007"], ["71268.20", "0.003"], ["71268.40", "0.000"], ["71269.90", "0.699"], ["71270.60", "0.080"], ["71271.30", "0.290"], ["71271.40", "0.002"], ["71271.60", "0.636"], ["71271.90", "0.633"], ["71272.00", "0.297"], ["71273.70", "0.636"], ["71274.80", "0.133"], ["71274.90", "0.647"], ["71276.50", "0.634"], ["71276.70", "0.509"], ["71276.80", "0.249"], ["71277.00", "0.240"], ["71277.10", "0.060"], ["71277.40", "0.881"], ["71277.60", "0.052"], ["71278.30", "0.001"], ["71278.50", "0.099"], ["71279.20", "0.475"], ["71279.50", "0.891"], ["71280.30", "0.405"], ["71280.60", "0.005"], ["71280.70", "0.029"], ["71280.90", "0.070"], ["71281.00", "0.081"], ["71281.70", "0.000"], ["71283.10", "0.002"], ["71283.40", "0.056"], ["71284.00", "0.250"], ["71284.20", "1.123"], ["71284.90", "0.021"], ["71286.20", "0.004"], ["71286.30", "0.740"], ["71286.50", "1.307"], ["71287.70", "0.008"], ["71290.20", "0.005"], ["71291.50", "0.011"], ["71291.60", "0.149"], ["71291.90", "0.006"], ["71292.00", "0.108"], ["71292.10", "0.864"], ["71292.20", "0.036"], ["71292.30", "0.015"], ["71292.90", "0.010"], ["71293.00", "0.003"], ["71293.50", "0.263"], ["71293.60", "0.319"], ["71293.70", "0.002"], ["71296.00", "0.080"], ["71301.20", "0.000"], ["71306.40", "0.008"], ["71310.10", "0.005"], ["71310.30", "0.523"], ["71311.20", "0.115"], ["71443.10", "0.159"], ["71446.60", "0.142"], ["71977.50", "0.008"], ["78391.40", "0.002"], ["89523.20", "0.000"]]}}
{"local_ts": 1773384702134, "server_ts": 1773384701916, "data": {"e": "depthUpdate", "E": 1773384701919, "T": 1773384701916, "s": "BTCUSDT", "U": 10101354863532, "u": 10101354869364, "pu": 10101354863386, "b": [["1000.00", "27.492"], ["5000.00", "101.418"], ["20764.80", "0.414"], ["20864.80", "0.486"], ["20964.80", "0.576"], ["21064.80", "1.224"], ["64138.30", "0.002"], ["67667.30", "0.000"], ["67691.80", "0.000"], ["67691.90", "0.008"], ["67701.00", "0.003"], ["70552.20", "0.000"], ["70934.70", "0.002"], ["70936.50", "0.043"], ["71183.70", "0.269"], ["71207.30", "3.533"], ["71216.10", "0.003"], ["71216.20", "0.028"], ["71217.20", "0.002"], ["71229.10", "0.005"], ["71229.50", "0.512"], ["71233.80", "0.214"], ["71236.60", "0.073"], ["71239.30", "0.004"], ["71240.50", "0.009"], ["71241.00", "0.037"], ["71242.80", "0.648"], ["71243.40", "0.900"], ["71243.60", "0.022"], ["71245.40", "0.300"], ["71246.90", "0.150"], ["71254.10", "0.518"], ["71256.20", "0.002"]], "a": [["71264.90", "2.925"], ["71268.50", "0.209"], ["71274.80", "0.048"], ["71275.10", "0.401"], ["71276.60", "0.046"], ["71278.70", "0.038"], ["71286.40", "1.050"], ["71287.40", "0.509"], ["71292.50", "0.134"], ["71292.70", "1.771"], ["71297.50", "0.002"], ["71298.40", "0.003"], ["71977.50", "0.008"], ["72492.10", "5.234"], ["74831.30", "0.002"], ["78391.40", "0.002"], ["89523.20", "0.000"]]}}
{"local_ts": 1773384703156, "server_ts": 1773384702940, "data": {"e": "depthUpdate", "E": 1773384702941, "T": 1773384702940, "s": "BTCUSDT", "U": 10101355010882, "u": 10101355021153, "pu": 10101355010502, "b": [["5000.00", "101.418"], ["20764.80", "0.621"], ["20869.70", "0.243"], ["20964.80", "1.323"], ["20969.70", "0.153"], ["21064.80", "0.000"], ["21169.70", "0.216"], ["57016.00", "0.000"], ["64142.70", "0.000"], ["67095.20", "0.002"], ["67669.70", "0.000"], ["67678.70", "0.025"], ["70557.00", "0.007"], ["70913.30", "0.000"], ["70934.70", "0.000"], ["70948.20", "0.010"], ["71050.10", "2.746"], ["71056.10", "5.068"], ["71212.70", "0.489"], ["71221.40", "0.877"], ["71221.50", "0.147"], ["71223.90", "0.001"], ["71225.10", "0.524"], ["71228.80", "0.023"], ["71230.20", "0.007"], ["71231.70", "0.004"], ["71234.10", "0.003"], ["71234.40", "0.014"], ["71236.40", "0.101"], ["71236.80", "0.011"], ["71236.90", "0.137"], ["71237.50", "0.074"], ["71237.60", "0.000"], ["71241.10", "0.210"], ["71242.30", "0.000"], ["71254.40", "0.075"], ["71254.80", "0.077"], ["71255.20", "0.345"], ["71255.70", "1.192"], ["71256.30", "0.000"], ["71256.80", "0.634"], ["71258.00", "0.004"], ["71258.50", "0.022"], ["71261.30", "0.360"], ["71262.00", "0.005"], ["71262.60", "0.064"], ["71265.90", "0.004"]], "a": [["71275.40", "0.002"], ["71276.80", "0.022"], ["71276.90", "0.031"], ["71279.50", "0.132"], ["71279.80", "0.057"], ["71280.20", "0.130"], ["71280.60", "0.075"], ["71280.90", "0.131"], ["71281.30", "0.170"], ["71282.70", "0.008"], ["71284.10", "1.006"], ["71288.20", "0.160"], ["71289.90", "0.002"], ["71295.50", "0.139"], ["71297.10", "0.004"], ["71297.20", "0.024"], ["71297.80", "0.301"], ["71297.90", "0.011"], ["71305.40", "0.392"], ["71310.60", "1.898"], ["71323.00", "0.023"], ["71332.70", "3.590"], ["71334.70", "0.031"], ["71344.60", "0.000"], ["71369.10", "6.609"], ["71370.50", "0.120"], ["71370.90", "0.072"], ["71371.20", "0.068"], ["71371.60", "0.115"], ["71388.30", "0.031"], ["71427.80", "2.723"], ["71429.60", "13.033"], ["71448.00", "2.856"], ["71453.80", "0.303"], ["71457.30", "0.015"], ["71457.40", "0.000"], ["71457.50", "0.000"], ["71458.00", "0.010"], ["71458.70", "1.640"], ["71478.20", "0.011"], ["71545.00", "0.006"], ["71982.50", "0.007"], ["72053.70", "0.069"], ["72697.20", "0.000"], ["74862.10", "0.002"], ["78396.80", "0.000"], ["89523.20", "0.000"]]}}
{"local_ts": 1773384704181, "server_ts": 1773384703960, "data": {"e": "depthUpdate", "E": 1773384703961, "T": 1773384703960, "s": "BTCUSDT", "U": 10101355082241, "u": 10101355086662, "pu": 10101355082090, "b": [["1000.00", "27.492"], ["5000.00", "101.418"], ["20769.70", "0.144"], ["20869.70", "1.494"], ["20964.80", "0.099"], ["21069.70", "0.144"], ["21169.70", "0.693"], ["57016.00", "0.000"], ["64142.70", "0.000"], ["66740.20", "0.002"], ["67323.50", "0.002"], ["67675.00", "0.010"], ["67706.20", "0.016"], ["70081.80", "0.015"], ["70151.20", "2.964"], ["70222.50", "4.308"], ["70557.00", "0.007"], ["70557.10", "0.711"], ["70962.70", "0.003"], ["71178.80", "0.422"], ["71188.80", "0.000"], ["71198.80", "0.148"], ["71220.80", "0.054"], ["71220.90", "0.005"], ["71230.80", "0.023"], ["71236.80", "0.002"], ["71236.90", "0.128"], ["71237.50", "0.083"], ["71237.60", "0.009"], ["71242.80", "0.143"], ["71243.50", "0.092"], ["71248.70", "0.005"], ["71251.50", "0.508"], ["71251.90", "0.515"], ["71252.60", "0.366"], ["71252.70", "0.001"], ["71253.30", "0.030"], ["71254.00", "0.326"], ["71254.10", "0.049"], ["71254.40", "0.003"], ["71254.50", "0.286"], ["71255.00", "0.035"], ["71255.40", "0.003"], ["71255.70", "0.000"], ["71256.30", "0.336"], ["71256.70", "0.044"], ["71256.80", "0.187"], ["71257.60", "0.236"], ["71258.10", "0.597"], ["71259.30", "0.508"], ["71261.90", "0.698"], ["71262.00", "0.511"], ["71262.60", "0.169"], ["71262.70", "0.634"], ["71263.80", "0.696"], ["71265.60", "0.182"], ["71266.80", "0.002"], ["71269.70", "2.395"]], "a": [["71269.80", "1.979"], ["71271.40", "0.000"], ["71275.10", "0.003"], ["71275.30", "0.007"], ["71276.30", "0.082"], ["71276.90", "0.196"], ["71278.70", "0.038"], ["71279.70", "0.004"], ["71280.30", "0.257"], ["71280.40", "0.014"], ["71280.70", "0.006"], ["71280.90", "0.203"], ["71281.60", "0.003"], ["71281.70", "0.000"], ["71281.80", "0.002"], ["71282.20", "0.009"], ["71282.30", "0.038"], ["71282.80", "0.205"], ["71282.90", "0.003"], ["71283.30", "0.001"], ["71283.60", "0.004"], ["71283.80", "0.007"], ["71283.90", "0.011"], ["71284.00", "0.145"], ["71284.20", "0.619"], ["71284.30", "0.027"], ["71285.10", "0.018"], ["71285.20", "0.211"], ["71286.30", "0.012"], ["71286.90", "0.003"], ["71287.40", "0.056"], ["71288.90", "0.268"], ["71289.10", "0.225"], ["71290.60", "0.079"], ["71291.90", "0.006"], ["71292.20", "0.041"], ["71293.30", "0.754"], ["71297.10", "0.002"], ["71297.20", "0.022"], ["71297.80", "0.303"], ["71297.90", "0.006"], ["71306.40", "0.093"], ["71307.90", "0.949"], ["71370.00", "0.409"], ["71448.00", "2.955"], ["71966.60", "0.027"], ["71982.50", "0.007"], ["72287.30", "0.967"], ["72358.50", "1.008"], ["74835.70", "0.002"], ["78396.80", "0.000"], ["89523.20", "0.000"], ["100000.00", "15.858"]]}}
{"local_ts": 1773384705197, "server_ts": 1773384704981, "data": {"e": "depthUpdate", "E": 1773384704983, "T": 1773384704981, "s": "BTCUSDT", "U": 10101355123382, "u": 10101355126610, "pu": 10101355123311, "b": [["5000.00", "101.418"], ["20769.70", "1.557"], ["20864.80", "0.000"], ["20865.50", "0.000"], ["20869.70", "0.234"], ["20969.70", "0.009"], ["21069.70", "0.891"], ["21164.80", "0.000"], ["21165.50", "0.000"], ["21169.70", "0.009"], ["64142.70", "0.000"], ["67694.80", "0.000"], ["67700.70", "0.014"], ["70236.30", "6.681"], ["70557.00", "0.007"], ["70712.60", "0.008"], ["70908.50", "0.000"], ["70913.30", "0.000"], ["71193.80", "0.100"], ["71221.90", "0.003"], ["71222.00", "0.010"], ["71225.10", "0.573"], ["71234.10", "0.034"], ["71243.40", "0.087"], ["71243.50", "0.191"], ["71249.50", "1.202"], ["71268.30", "0.005"]], "a": [["71305.40", "0.491"], ["71316.00", "0.302"], ["71316.30", "0.003"], ["71473.40", "0.002"], ["78396.80", "0.000"], ["89523.20", "0.000"]]}}
{"local_ts": 1773384706221, "server_ts": 1773384706006, "data": {"e": "depthUpdate", "E": 1773384706007, "T": 1773384706006, "s": "BTCUSDT", "U": 10101355168082, "u": 10101355172427, "pu": 10101355167941, "b": [["1000.00", "27.492"], ["5000.00", "101.418"], ["20769.70", "0.486"], ["20969.70", "0.774"], ["21069.70", "0.126"], ["21169.70", "1.314"], ["33000.00", "9.339"], ["64142.70", "0.000"], ["70557.00", "0.009"], ["71184.20", "1.610"], ["71185.00", "0.174"], ["71196.80", "0.286"], ["71197.10", "1.093"], ["71199.90", "0.000"], ["71201.90", "0.037"], ["71203.60", "0.000"], ["71212.10", "0.044"], ["71215.10", "0.004"], ["71225.10", "0.524"], ["71231.50", "0.006"], ["71234.10", "0.003"], ["71234.90", "0.079"], ["71239.50", "0.008"], ["71240.10", "0.000"], ["71243.40", "0.002"], ["71244.80", "0.400"], ["71249.70", "0.007"], ["71253.50", "0.005"], ["71255.40", "0.142"], ["71255.70", "0.004"], ["71258.00", "0.010"], ["71260.30", "0.004"], ["71261.70", "0.009"], ["71262.60", "0.030"], ["71264.80", "0.161"], ["71269.70", "1.186"]], "a": [["71269.80", "3.147"], ["71273.50", "0.000"], ["71275.60", "1.617"], ["71276.60", "0.001"], ["71276.90", "0.193"], ["71278.70", "0.036"], ["71284.00", "0.111"], ["71284.10", "0.458"], ["71284.20", "0.621"], ["71287.70", "0.010"], ["71288.80", "0.002"], ["71290.90", "0.007"], ["71291.90", "0.022"], ["71293.70", "0.004"], ["71305.40", "0.452"], ["71307.40", "0.002"], ["71307.70", "0.102"], ["71308.00", "0.119"], ["71308.30", "0.072"], ["71336.30", "0.078"], ["71375.00", "0.172"], ["71982.50", "0.007"], ["72587.80", "0.688"], ["73994.70", "0.000"], ["74846.00", "0.052"], ["78396.80", "0.000"], ["89523.20", "0.000"]]}}
{"local_ts": 1773384707246, "server_ts": 1773384707030, "data": {"e": "depthUpdate", "E": 1773384707031, "T": 1773384707030, "s": "BTCUSDT", "U": 10101355213053, "u": 10101355221534, "pu": 10101355212996, "b": [["1000.00", "27.492"], ["5000.00", "101.418"], ["20869.70", "0.648"], ["20969.70", "0.252"], ["21069.70", "1.044"], ["21169.70", "0.756"], ["64142.70", "0.000"], ["67686.20", "0.000"], ["67706.20", "0.024"], ["69839.60", "0.005"], ["70201.20", "0.283"], ["70557.00", "0.007"], ["70913.40", "0.000"], ["71067.40", "0.300"], ["71184.20", "1.511"], ["71184.40", "0.001"], ["71185.60", "0.062"], ["71186.00", "0.000"], ["71209.40", "1.049"], ["71211.10", "3.402"], ["71218.00", "0.838"], ["71225.00", "0.827"], ["71232.00", "0.812"], ["71239.00", "0.877"], ["71243.40", "0.186"], ["71246.00", "0.814"], ["71252.70", "0.001"], ["71253.40", "0.000"], ["71254.80", "0.217"], ["71255.40", "0.139"], ["71257.60", "0.294"], ["71262.60", "0.168"], ["71262.90", "0.289"], ["71268.10", "0.003"], ["71269.60", "0.001"], ["71269.70", "1.582"]], "a": [["71269.80", "2.815"], ["71273.60", "0.003"], ["71274.00", "0.007"], ["71274.30", "0.007"], ["71274.50", "0.010"], ["71275.10", "0.023"], ["71275.30", "0.007"], ["71276.10", "0.000"], ["71282.00", "0.041"], ["71283.60", "0.144"], ["71284.00", "0.026"], ["71286.90", "0.041"], ["71288.00", "0.967"], ["71290.60", "0.083"], ["71292.60", "0.089"], ["71293.10", "0.003"], ["71294.20", "0.010"], ["71295.00", "0.815"], ["71295.20", "0.000"], ["71296.30", "0.615"], ["71297.30", "0.149"], ["71302.00", "0.820"], ["71302.30", "0.319"], ["71302.70", "0.078"], ["71307.90", "0.949"], ["71308.80", "0.347"], ["71308.90", "0.003"], ["71309.00", "0.887"], ["71316.00", "1.106"], ["71317.10", "0.180"], ["71318.00", "0.176"], ["71330.30", "0.000"], ["71354.00", "0.115"], ["71982.50", "0.701"], ["72333.40", "0.551"], ["72347.70", "2.482"], ["74858.90", "0.004"], ["78396.80", "0.000"], ["89523.20", "0.000"]]}}
{"local_ts": 1773384708273, "server_ts": 1773384708052, "data": {"e": "depthUpdate", "E": 1773384708057, "T": 1773384708052, "s": "BTCUSDT", "U": 10101355297734, "u": 10101355301701, "pu": 10101355297667, "b": [["5000.00", "101.418"], ["20769.70", "0.513"], ["20869.70", "0.387"], ["20969.70", "0.783"], ["21069.70", "1.017"], ["33000.00", "9.343"], ["70557.00", "0.007"], ["70913.30", "0.000"], ["71066.80", "0.002"], ["71067.40", "0.298"], ["71171.70", "0.001"], ["71184.40", "0.270"], ["71207.70", "0.024"], ["71210.10", "3.527"], ["71211.10", "0.002"], ["71218.00", "0.838"], ["71225.00", "0.827"], ["71230.00", "0.057"], ["71232.00", "0.812"], ["71236.80", "0.002"], ["71236.90", "0.128"], ["71237.50", "0.083"], ["71237.60", "0.009"], ["71239.00", "0.877"], ["71243.20", "0.184"], ["71243.40", "0.002"], ["71243.50", "0.007"], ["71246.00", "0.814"], ["71256.90", "0.003"], ["71257.50", "0.103"], ["71262.60", "0.029"], ["71265.70", "0.028"], ["71266.70", "0.031"], ["71266.80", "0.004"], ["71267.10", "0.000"], ["71267.20", "0.002"], ["71269.70", "0.652"]], "a": [["71271.30", "0.022"], ["71271.40", "0.003"], ["71272.90", "0.007"], ["71273.50", "0.000"], ["71275.10", "0.005"], ["71276.90", "0.154"], ["71279.40", "0.075"], ["71281.10", "0.005"], ["71282.60", "0.007"], ["71285.80", "0.142"], ["71286.00", "0.132"], ["71288.00", "0.967"], ["71292.60", "0.004"], ["71295.00", "0.815"], ["71295.70", "0.085"], ["71295.80", "0.000"], ["71296.40", "0.052"], ["71296.50", "0.350"], ["71302.00", "0.820"], ["71309.00", "0.887"], ["71312.40", "0.928"], ["71315.50", "0.340"], ["71316.00", "1.106"], ["71330.30", "3.450"], ["71330.40", "0.091"], ["71331.40", "0.068"], ["71354.80", "0.046"], ["71982.50", "0.701"], ["72436.10", "0.011"], ["72651.50", "0.011"], ["72690.10", "0.010"], ["74838.50", "0.050"], ["74852.50", "0.052"], ["89523.20", "0.000"]]}}
{"local_ts": 1773384709296, "server_ts": 1773384709080, "data": {"e": "depthUpdate", "E": 1773384709081, "T": 1773384709080, "s": "BTCUSDT", "U": 10101355341947, "u": 10101355347107, "pu": 10101355341867, "b": [["1000.00", "27.492"], ["5000.00", "101.418"], ["20769.70", "0.513"], ["20869.70", "0.522"], ["20969.70", "1.278"], ["21169.70", "0.387"], ["40000.00", "49.558"], ["67689.00", "0.007"], ["67701.60", "0.004"], ["67701.70", "0.002"], ["67706.00", "0.000"], ["69126.90", "0.000"], ["70557.00", "0.007"], ["71066.80", "0.000"], ["71068.40", "0.077"], ["71179.30", "0.023"], ["71185.00", "0.074"], ["71197.90", "0.061"], ["71204.40", "2.366"], ["71213.00", "0.332"], ["71218.00", "0.032"], ["71221.90", "0.001"], ["71222.20", "0.344"], ["71225.00", "0.021"], ["71232.00", "0.006"], ["71233.20", "0.004"], ["71234.40", "0.127"], ["71238.60", "0.017"], ["71239.00", "0.071"], ["71243.20", "0.184"], ["71246.00", "0.008"], ["71248.40", "0.162"], ["71251.00", "0.699"], ["71251.10", "1.216"], ["71252.00", "0.111"], ["71253.90", "0.042"], ["71254.70", "0.633"], ["71255.30", "0.010"], ["71255.90", "0.068"], ["71256.40", "0.054"], ["71256.50", "0.069"], ["71256.90", "0.092"], ["71257.00", "0.012"], ["71257.40", "0.043"], ["71257.70", "0.162"], ["71258.10", "0.614"], ["71258.20", "0.259"], ["71259.00", "0.010"], ["71259.10", "0.022"], ["71262.20", "0.042"], ["71262.30", "0.000"], ["71262.50", "0.201"], ["71266.10", "0.002"], ["71266.60", "0.003"], ["71269.30", "0.074"], ["71269.70", "2.360"]], "a": [["71269.80", "2.107"], ["71273.70", "0.003"], ["71274.00", "0.014"], ["71274.40", "0.005"], ["71274.80", "0.000"], ["71276.50", "0.007"], ["71276.80", "0.007"], ["71278.70", "0.002"], ["71280.20", "0.071"], ["71282.60", "0.007"], ["71288.00", "0.161"], ["71291.20", "0.118"], ["71292.60", "0.089"], ["71294.80", "0.024"], ["71295.00", "0.009"], ["71295.20", "0.150"], ["71302.00", "0.014"], ["71307.00", "0.321"], ["71307.20", "0.148"], ["71309.00", "0.081"], ["71309.40", "0.977"], ["71315.90", "0.002"], ["71316.00", "0.302"], ["71326.80", "0.099"], ["71330.40", "0.091"], ["71340.90", "0.043"], ["71514.70", "0.642"], ["71517.00", "0.000"], ["71536.80", "2.963"], ["71538.60", "18.514"], ["71982.50", "0.701"], ["72347.80", "1.243"], ["72348.30", "0.828"], ["73402.80", "0.003"], ["89523.20", "0.000"]]}}
{"local_ts": 1773384710319, "server_ts": 1773384710101, "data": {"e": "depthUpdate", "E": 1773384710103, "T": 1773384710101, "s": "BTCUSDT", "U": 10101355382582, "u": 10101355389455, "pu": 10101355382546, "b": [["5000.00", "101.418"], ["20769.70", "0.252"], ["20869.70", "1.548"], ["20969.70", "0.000"], ["21069.70", "0.252"], ["21169.70", "0.648"], ["33000.00", "9.343"], ["57016.00", "0.000"], ["67677.70", "0.002"], ["67706.20", "0.018"], ["67706.30", "0.006"], ["69131.70", "0.008"], ["70557.00", "0.007"], ["70905.20", "0.003"], ["70913.40", "0.035"], ["71067.40", "0.300"], ["71068.40", "0.075"], ["71114.20", "0.012"], ["71218.00", "0.032"], ["71221.80", "0.018"], ["71221.90", "0.001"], ["71225.00", "0.021"], ["71232.00", "0.006"], ["71239.00", "0.071"], ["71246.00", "0.008"], ["71255.40", "0.003"], ["71256.90", "0.092"], ["71258.80", "0.006"], ["71266.80", "0.002"], ["71267.60", "0.001"], ["71269.00", "0.075"], ["71269.10", "0.004"], ["71269.70", "2.213"]], "a": [["71274.30", "0.000"], ["71274.60", "0.013"], ["71282.60", "0.007"], ["71288.00", "0.161"], ["71292.60", "0.089"], ["71295.00", "0.009"], ["71296.90", "0.131"], ["71297.20", "0.017"], ["71298.00", "0.163"], ["71302.00", "0.014"], ["71309.00", "0.081"], ["71316.00", "0.300"], ["71332.80", "0.009"], ["71335.90", "0.000"], ["71339.90", "0.149"], ["71343.00", "0.074"], ["71347.00", "0.049"], ["71350.10", "0.030"], ["71354.10", "0.109"], ["71357.20", "0.000"], ["71361.20", "0.180"], ["71364.30", "0.018"], ["71368.30", "0.007"], ["71371.40", "0.000"], ["71375.40", "0.109"], ["71378.50", "0.000"], ["71382.50", "0.007"], ["71385.60", "0.221"], ["71946.90", "3.052"], ["71982.50", "0.701"], ["72260.50", "6.249"], ["72347.70", "2.895"], ["72566.90", "0.482"], ["73402.80", "0.000"], ["73407.80", "0.033"], ["74852.50", "0.050"], ["89523.20", "0.000"]]}}
{"local_ts": 1773384711340, "server_ts": 1773384711120, "data": {"e": "depthUpdate", "E": 1773384711125, "T": 1773384711120, "s": "BTCUSDT", "U": 10101355422015, "u": 10101355432203, "pu": 10101355421882, "b": [["1000.00", "27.492"], ["5000.00", "101.438"], ["20769.70", "1.548"], ["20869.70", "0.135"], ["20969.70", "0.117"], ["21069.70", "0.783"], ["21169.70", "0.117"], ["57016.00", "0.004"], ["70165.00", "4.552"], ["70557.00", "0.007"], ["70557.10", "0.707"], ["70941.00", "0.012"], ["71020.20", "0.012"], ["71114.20", "1.786"], ["71114.30", "1.142"], ["71114.60", "0.508"], ["71118.00", "1.670"], ["71174.50", "0.001"], ["71175.40", "0.535"], ["71210.10", "0.101"], ["71210.40", "0.132"], ["71218.00", "0.032"], ["71225.00", "0.021"], ["71231.70", "0.004"], ["71232.00", "0.006"], ["71239.00", "0.071"], ["71246.00", "0.008"], ["71255.40", "0.318"], ["71255.80", "0.272"], ["71256.90", "0.092"], ["71262.60", "0.100"], ["71262.90", "0.025"], ["71269.70", "2.725"]], "a": [["71269.80", "1.799"], ["71276.90", "0.112"], ["71282.60", "0.007"], ["71288.00", "0.161"], ["71292.60", "0.004"], ["71295.00", "0.033"], ["71296.00", "0.107"], ["71302.00", "0.014"], ["71308.80", "0.347"], ["71309.00", "0.081"], ["71316.00", "0.300"], ["71316.50", "0.020"], ["71316.60", "0.006"], ["71327.30", "0.525"], ["71330.30", "0.003"], ["71332.80", "0.002"], ["71334.40", "0.007"], ["71337.00", "0.004"], ["71337.50", "0.379"], ["71339.90", "0.067"], ["71341.50", "0.054"], ["71347.00", "0.042"], ["71348.60", "0.007"], ["71354.10", "0.102"], ["71355.70", "0.009"], ["71361.20", "0.173"], ["71362.80", "0.047"], ["71364.20", "0.358"], ["71366.00", "0.000"], ["71368.30", "0.000"], ["71369.90", "0.515"], ["71375.40", "0.102"], ["71377.00", "0.604"], ["71382.50", "0.000"], ["71425.40", "0.616"], ["71425.70", "0.000"], ["71448.00", "2.955"], ["71455.10", "0.159"], ["71790.00", "0.132"], ["71982.50", "2.088"], ["72005.40", "0.000"], ["72220.80", "0.414"], ["72346.50", "0.827"], ["72436.10", "0.003"], ["72651.50", "0.003"], ["74849.90", "0.000"]]}}
{"local_ts": 1773384712367, "server_ts": 1773384712144, "data": {"e": "depthUpdate", "E": 1773384712147, "T": 1773384712144, "s": "BTCUSDT", "U": 10101355521429, "u": 10101355526869, "pu": 10101355521170, "b": [["1000.00", "27.492"], ["5000.00", "101.418"], ["20769.70", "0.279"], ["20969.70", "0.882"], ["21069.70", "0.018"], ["21169.70", "1.521"], ["67682.50", "0.002"], ["69424.80", "0.000"], ["69602.60", "0.000"], ["70557.00", "1.422"], ["70913.40", "0.070"], ["70995.50", "1.543"], ["71119.00", "12.214"], ["71177.30", "6.175"], ["71181.00", "0.032"], ["71184.20", "1.850"], ["71191.60", "0.002"], ["71195.60", "0.000"], ["71204.40", "1.169"], ["71218.00", "0.032"], ["71221.40", "0.081"], ["71221.50", "0.006"], ["71225.00", "0.021"], ["71230.80", "0.000"], ["71232.00", "0.006"], ["71239.00", "0.067"], ["71246.00", "0.008"], ["71256.90", "0.003"], ["71262.60", "0.053"], ["71263.10", "0.007"], ["71269.10", "0.030"], ["71269.20", "0.018"], ["71269.30", "0.004"]], "a": [["71269.80", "2.868"], ["71274.60", "0.006"], ["71275.40", "0.006"], ["71276.80", "0.010"], ["71276.90", "0.029"], ["71282.60", "0.007"], ["71284.10", "0.068"], ["71288.00", "0.163"], ["71289.40", "0.000"], ["71290.90", "0.077"], ["71294.90", "0.039"], ["71295.00", "0.009"], ["71296.40", "0.134"], ["71297.40", "0.343"], ["71302.00", "0.014"], ["71305.40", "0.691"], ["71307.00", "0.891"], ["71309.00", "0.007"], ["71316.00", "0.302"], ["71319.80", "0.303"], ["71327.30", "0.518"], ["71329.80", "0.007"], ["71333.90", "0.081"], ["71334.40", "0.000"], ["71336.90", "1.058"], ["71341.20", "0.508"], ["71341.50", "0.047"], ["71344.00", "0.546"], ["71348.60", "0.000"], ["71351.10", "0.009"], ["71355.70", "0.002"], ["71358.20", "0.012"], ["71362.80", "0.040"], ["71365.30", "0.009"], ["71369.90", "0.508"], ["71372.40", "2.796"], ["71377.00", "0.597"], ["71379.50", "0.007"], ["71403.00", "0.002"], ["71982.50", "2.088"], ["74048.00", "0.063"]]}}
{"local_ts": 1773384713386, "server_ts": 1773384713164, "data": {"e": "depthUpdate", "E": 1773384713167, "T": 1773384713164, "s": "BTCUSDT", "U": 10101355568485, "u": 10101355572924, "pu": 10101355568392, "b": [["5000.00", "101.418"], ["20869.70", "0.747"], ["20969.70", "0.153"], ["21069.70", "1.251"], ["21169.70", "0.549"], ["57016.00", "0.000"], ["67695.60", "0.003"], ["67703.60", "0.031"], ["67706.30", "0.004"], ["69629.40", "0.646"], ["70421.10", "0.004"], ["70557.00", "1.422"], ["71184.20", "1.989"], ["71195.10", "1.243"], ["71246.40", "0.010"], ["71247.50", "0.000"], ["71262.60", "0.031"], ["71268.70", "0.001"], ["71268.80", "0.000"], ["71269.70", "2.263"]], "a": [["71269.80", "3.232"], ["71275.40", "0.008"], ["71276.90", "0.130"], ["71283.60", "0.004"], ["71286.20", "0.074"], ["71289.20", "0.005"], ["71290.90", "0.147"], ["71294.80", "0.048"], ["71294.90", "0.015"], ["71306.90", "0.072"], ["71329.80", "0.000"], ["71332.40", "0.023"], ["71333.90", "0.081"], ["71336.90", "1.051"], ["71339.50", "0.418"], ["71344.00", "0.539"], ["71346.60", "0.047"], ["71351.10", "0.002"], ["71353.70", "0.007"], ["71358.20", "0.005"], ["71360.80", "0.012"], ["71365.30", "0.002"], ["71367.90", "0.007"], ["71372.40", "2.789"], ["71375.00", "0.179"], ["71379.50", "0.000"], ["71382.10", "0.007"], ["71982.50", "2.088"], ["72281.70", "0.695"], ["72346.60", "0.413"], ["72347.70", "2.482"]]}}
{"local_ts": 1773384714405, "server_ts": 1773384714188, "data": {"e": "depthUpdate", "E": 1773384714189, "T": 1773384714188, "s": "BTCUSDT", "U": 10101355617134, "u": 10101355622755, "pu": 10101355617078, "b": [["1000.00", "27.492"], ["5000.00", "101.418"], ["20769.70", "0.612"], ["20869.70", "0.288"], ["20969.70", "0.990"], ["21069.70", "0.810"], ["67679.70", "0.000"], ["67706.20", "0.012"], ["67706.30", "0.006"], ["70557.00", "1.422"], ["70945.00", "0.706"], ["70945.20", "0.002"], ["71166.00", "0.180"], ["71184.20", "1.511"], ["71195.10", "0.043"], ["71231.10", "0.000"], ["71238.40", "0.021"], ["71243.00", "0.360"], ["71244.80", "0.321"], ["71255.00", "0.350"], ["71257.00", "0.003"], ["71260.60", "1.647"], ["71261.80", "0.680"], ["71262.60", "0.213"], ["71269.70", "1.678"]], "a": [["71269.80", "2.898"], ["71274.30", "0.000"], ["71274.80", "0.007"], ["71275.40", "0.273"], ["71275.50", "0.007"], ["71276.90", "0.090"], ["71280.30", "0.313"], ["71281.90", "0.683"], ["71286.60", "0.090"], ["71290.90", "0.075"], ["71291.90", "0.164"], ["71292.10", "0.592"], ["71292.50", "0.511"], ["71292.70", "0.004"], ["71294.20", "0.248"], ["71294.30", "0.003"], ["71295.10", "0.197"], ["71295.50", "0.643"], ["71295.70", "0.211"], ["71295.90", "0.525"], ["71315.50", "0.347"], ["71315.90", "0.004"], ["71316.00", "0.300"], ["71332.40", "0.016"], ["71332.70", "0.086"], ["71339.50", "0.411"], ["71339.80", "0.320"], ["71346.60", "0.040"], ["71346.90", "0.147"], ["71353.70", "0.000"], ["71354.00", "0.226"], ["71360.80", "0.005"], ["71361.10", "0.026"], ["71367.90", "0.000"], ["71368.20", "0.300"], ["71375.00", "0.072"], ["71375.30", "0.007"], ["71382.10", "0.000"], ["71382.40", "0.007"], ["71454.30", "0.000"], ["71486.90", "0.693"], ["71494.10", "0.000"], ["71529.70", "0.813"], ["71537.50", "0.021"], ["71982.50", "2.088"], ["72464.10", "1.031"], ["74842.70", "0.002"]]}}
{"local_ts": 1773384715425, "server_ts": 1773384715208, "data": {"e": "depthUpdate", "E": 1773384715211, "T": 1773384715208, "s": "BTCUSDT", "U": 10101355683349, "u": 10101355690642, "pu": 10101355683271, "b": [["5000.00", "101.418"], ["20769.70", "0.423"], ["20869.70", "0.720"], ["20969.70", "1.080"], ["21169.70", "0.477"], ["33000.00", "9.339"], ["67706.00", "0.000"], ["70062.40", "0.000"], ["70557.00", "1.422"], ["70913.40", "0.070"], ["70940.50", "0.000"], ["70945.20", "0.000"], ["70945.70", "0.002"], ["71020.10", "2.821"], ["71221.10", "0.004"], ["71221.20", "0.007"], ["71254.80", "0.077"], ["71255.80", "0.297"], ["71262.20", "0.042"], ["71262.60", "0.892"], ["71262.70", "0.116"], ["71264.80", "0.141"], ["71265.60", "0.230"], ["71266.70", "0.000"], ["71267.10", "0.021"], ["71267.20", "0.004"]], "a": [["71273.70", "0.005"], ["71276.90", "0.092"], ["71291.90", "0.583"], ["71315.50", "0.345"], ["71315.60", "0.004"], ["72517.00", "3.306"], ["74837.30", "0.020"], ["74855.70", "0.002"]]}}
{"local_ts": 1773384716451, "server_ts": 1773384716232, "data": {"e": "depthUpdate", "E": 1773384716235, "T": 1773384716232, "s": "BTCUSDT", "U": 10101355724763, "u": 10101355731267, "pu": 10101355724507, "b": [["1000.00", "27.642"], ["5000.00", "101.418"], ["20769.70", "0.450"], ["20869.70", "1.350"], ["21069.70", "0.351"], ["21169.70", "0.549"], ["67697.90", "0.031"], ["67706.00", "0.020"], ["70238.20", "0.007"], ["70551.80", "0.000"], ["70557.00", "1.422"], ["70569.50", "0.057"], ["70945.70", "0.000"], ["70946.10", "0.002"], ["71220.80", "0.054"], ["71221.10", "0.002"]], "a": [["71272.50", "0.003"], ["71272.90", "0.007"], ["71273.70", "0.003"], ["71281.80", "0.002"], ["71282.20", "0.130"], ["71282.70", "0.148"], ["71291.90", "0.164"], ["71292.00", "0.452"], ["71300.30", "0.004"], ["71982.50", "2.088"], ["71999.30", "2.169"], ["74842.20", "0.000"]]}}
{"local_ts": 1773384717472, "server_ts": 1773384717252, "data": {"e": "depthUpdate", "E": 1773384717255, "T": 1773384717252, "s": "BTCUSDT", "U": 10101355772720, "u": 10101355775072, "pu": 10101355772662, "b": [["1000.00", "27.642"], ["5000.00", "101.418"], ["20769.70", "1.548"], ["20869.70", "0.036"], ["20969.70", "0.216"], ["21069.70", "0.684"], ["21169.70", "0.216"], ["33000.00", "9.343"], ["67674.80", "0.000"], ["67698.30", "0.002"], ["70307.90", "0.710"], ["70521.60", "0.000"], ["70557.00", "1.422"], ["70946.10", "0.002"], ["71175.00", "0.002"], ["71182.20", "0.000"], ["71189.30", "0.000"], ["71220.40", "0.004"], ["71220.60", "0.014"], ["71267.10", "0.051"]], "a": [["71333.90", "0.081"], ["71353.30", "0.021"], ["71370.00", "0.409"], ["71982.50", "2.088"]]}}
{"local_ts": 1773384718491, "server_ts": 1773384718274, "data": {"e": "depthUpdate", "E": 1773384718275, "T": 1773384718274, "s": "BTCUSDT", "U": 10101355834355, "u": 10101355838504, "pu": 10101355834198, "b": [["5000.00", "101.418"], ["20769.70", "0.171"], ["20870.50", "0.081"], ["20970.50", "0.594"], ["21070.50", "0.081"], ["21170.50", "1.323"], ["66881.00", "0.000"], ["67706.20", "0.014"], ["67706.30", "0.010"], ["68304.00", "0.004"], ["69778.90", "0.000"], ["70225.30", "0.000"], ["70514.50", "0.100"], ["70557.80", "0.000"], ["70571.40", "0.746"], ["70946.10", "0.000"], ["70950.20", "0.008"], ["71263.40", "0.259"], ["71270.50", "5.015"]], "a": [["71270.60", "1.612"], ["71270.70", "0.005"], ["71317.30", "0.005"], ["71317.40", "0.002"], ["71344.90", "0.977"], ["71347.90", "0.293"], ["71497.30", "0.008"], ["71618.90", "0.000"], ["71622.60", "0.000"], ["71983.30", "0.000"], ["72318.30", "0.552"], ["74850.10", "0.002"]]}}
{"local_ts": 1773384719512, "server_ts": 1773384719294, "data": {"e": "depthUpdate", "E": 1773384719297, "T": 1773384719294, "s": "BTCUSDT", "U": 10101355931604, "u": 10101355939007, "pu": 10101355931488, "b": [["1000.00", "27.642"], ["5000.00", "101.418"], ["20864.80", "0.270"], ["20969.70", "0.054"], ["21064.80", "0.540"], ["21169.70", "0.054"], ["21170.50", "0.306"], ["33000.00", "9.343"], ["67683.80", "0.002"], ["70146.70", "0.997"], ["70552.20", "1.416"], ["70633.00", "0.166"], ["71110.10", "4.397"], ["71116.30", "0.036"], ["71116.80", "0.075"], ["71132.60", "0.047"], ["71134.50", "0.313"], ["71134.90", "0.036"], ["71135.20", "0.025"], ["71135.60", "0.025"], ["71136.00", "0.019"], ["71136.30", "0.328"], ["71160.00", "0.022"], ["71160.10", "0.000"], ["71163.10", "0.071"], ["71170.30", "0.073"], ["71173.50", "1.200"], ["71174.90", "0.016"], ["71177.40", "0.072"], ["71180.20", "0.000"], ["71182.10", "0.047"], ["71189.20", "0.005"], ["71195.50", "0.083"], ["71204.40", "1.165"], ["71206.60", "0.988"], ["71213.40", "0.011"], ["71215.80", "0.096"], ["71215.90", "0.020"], ["71224.90", "0.801"], ["71233.20", "0.004"], ["71235.70", "0.006"], ["71237.60", "0.007"], ["71239.70", "0.029"], ["71240.50", "0.032"], ["71241.10", "0.010"], ["71243.10", "0.139"], ["71243.90", "0.409"], ["71245.50", "0.034"], ["71245.90", "0.196"], ["71248.30", "0.005"], ["71250.20", "0.046"], ["71250.30", "0.000"], ["71251.00", "0.007"], ["71251.10", "0.026"], ["71251.90", "0.112"], ["71252.60", "0.049"], ["71254.40", "0.109"], ["71254.70", "0.281"], ["71255.10", "0.402"], ["71255.50", "0.031"], ["71255.80", "0.010"], ["71256.10", "0.025"], ["71257.70", "0.031"], ["71260.90", "0.000"], ["71261.20", "0.008"], ["71261.30", "0.111"], ["71261.90", "0.007"]], "a": [["71264.90", "8.938"], ["71265.40", "0.007"], ["71267.60", "0.000"], ["71268.50", "0.004"], ["71268.70", "0.007"], ["71269.90", "0.004"], ["71272.00", "0.160"], ["71274.00", "0.347"], ["71274.30", "0.000"], ["71275.30", "0.087"], ["71276.30", "0.017"], ["71277.60", "0.007"], ["71283.00", "0.025"], ["71284.30", "0.005"], ["71289.30", "0.003"], ["71300.30", "0.000"], ["71309.20", "0.523"], ["71310.30", "0.002"], ["71311.30", "0.767"], ["71311.50", "0.012"], ["71320.70", "0.051"], ["71322.80", "1.148"], ["71342.40", "0.778"], ["71353.20", "0.007"], ["71365.70", "0.000"], ["71415.30", "0.175"], ["71491.60", "0.006"], ["71547.10", "0.144"], ["71570.10", "0.017"], ["71977.50", "0.702"], ["72303.50", "1.385"], ["74854.70", "0.000"]]}}
{"local_ts": 1773384720536, "server_ts": 1773384720316, "data": {"e": "depthUpdate", "E": 1773384720317, "T": 1773384720316, "s": "BTCUSDT", "U": 10101356012951, "u": 10101356018672, "pu": 10101356012781, "b": [["5000.00", "101.398"], ["20761.00", "0.432"], ["20864.80", "0.189"], ["20961.00", "0.873"], ["21064.80", "0.387"], ["70548.40", "0.000"], ["70818.40", "0.000"], ["70908.50", "0.000"], ["71035.00", "0.305"], ["71076.50", "0.000"], ["71111.40", "0.039"], ["71116.80", "0.075"], ["71140.60", "0.036"], ["71153.60", "0.014"], ["71154.50", "6.453"], ["71155.00", "1.128"], ["71157.30", "0.073"], ["71157.60", "0.103"], ["71184.30", "0.057"], ["71188.30", "0.002"], ["71188.40", "0.579"], ["71197.20", "1.240"], ["71213.50", "0.004"], ["71214.00", "0.008"], ["71231.60", "7.771"], ["71233.00", "0.337"], ["71235.90", "0.147"], ["71239.20", "0.003"], ["71240.20", "1.195"], ["71240.80", "0.000"], ["71240.90", "0.057"], ["71241.00", "0.035"], ["71241.10", "0.007"], ["71243.20", "0.263"], ["71243.30", "0.212"], ["71245.80", "0.593"], ["71245.90", "0.179"], ["71247.40", "0.008"], ["71248.40", "0.423"], ["71248.80", "0.061"], ["71251.00", "0.011"], ["71261.00", "2.857"]], "a": [["71261.10", "5.926"], ["71261.20", "0.002"], ["71263.20", "0.000"], ["71263.70", "0.006"], ["71263.80", "0.015"], ["71264.10", "0.000"], ["71264.50", "1.100"], ["71264.60", "0.002"], ["71264.80", "0.003"], ["71265.00", "0.101"], ["71265.10", "0.017"], ["71265.70", "0.001"], ["71265.90", "0.001"], ["71266.00", "0.044"], ["71266.30", "0.016"], ["71266.60", "0.003"], ["71266.70", "0.002"], ["71267.00", "0.048"], ["71267.20", "0.000"], ["71267.30", "0.001"], ["71267.60", "0.015"], ["71267.90", "0.043"], ["71268.00", "0.025"], ["71268.30", "0.008"], ["71268.40", "0.008"], ["71268.60", "0.000"], ["71268.80", "0.018"], ["71268.90", "0.059"], ["71269.20", "0.000"], ["71269.30", "0.000"], ["71269.60", "0.019"], ["71269.70", "0.074"], ["71269.80", "0.201"], ["71270.10", "0.018"], ["71270.20", "0.069"], ["71270.50", "0.005"], ["71270.80", "0.002"], ["71270.90", "0.000"], ["71271.20", "0.009"], ["71271.30", "0.018"], ["71271.50", "0.007"], ["71271.70", "0.005"], ["71271.80", "0.004"], ["71272.20", "0.008"], ["71272.60", "0.017"], ["71272.70", "0.001"], ["71273.00", "0.008"], ["71273.40", "0.007"], ["71273.70", "0.004"], ["71274.30", "0.000"], ["71274.70", "0.072"], ["71274.80", "0.003"], ["71275.50", "0.064"], ["71276.00", "0.082"], ["71277.00", "0.068"], ["71278.10", "0.000"], ["71278.20", "0.032"], ["71279.50", "0.040"], ["71281.30", "0.066"], ["71283.00", "0.297"], ["71283.20", "0.029"], ["71284.70", "0.324"], ["71285.70", "0.351"], ["71286.00", "0.468"], ["71286.10", "0.210"], ["71287.30", "0.509"], ["71288.20", "0.068"], ["71289.50", "0.033"], ["71290.80", "0.411"], ["71290.90", "0.540"], ["71291.70", "0.004"], ["71292.10", "0.037"], ["71293.60", "0.011"], ["71296.70", "0.238"], ["71299.00", "0.275"], ["71302.20", "0.330"], ["71303.40", "0.003"], ["71305.00", "0.012"], ["71307.10", "0.217"], ["71308.10", "0.192"], ["71308.40", "0.010"], ["71309.20", "0.521"], ["71310.40", "0.371"], ["71312.70", "0.104"], ["71314.10", "0.008"], ["71315.40", "0.002"], ["71316.80", "0.120"], ["71318.10", "0.084"], ["71319.40", "0.000"], ["71321.40", "0.100"], ["71322.90", "0.001"], ["71324.30", "0.000"], ["71325.80", "0.508"], ["71327.30", "0.515"], ["71374.00", "2.061"], ["71374.30", "3.980"], ["71389.90", "0.036"], ["71390.00", "0.382"], ["71391.00", "0.061"], ["71438.80", "1.004"], ["71973.70", "0.049"], ["72033.00", "3.002"], ["72107.10", "0.009"], ["74837.30", "0.020"]]}}
{"local_ts": 1773384721560, "server_ts": 1773384721338, "data": {"e": "depthUpdate", "E": 1773384721339, "T": 1773384721338, "s": "BTCUSDT", "U": 10101356111321, "u": 10101356125684, "pu": 10101356111067, "b": [["1000.00", "27.642"], ["5000.00", "101.418"], ["20761.00", "0.234"], ["20860.60", "0.081"], ["20860.80", "0.828"], ["20961.00", "0.459"], ["21160.60", "0.045"], ["21160.80", "0.531"], ["66881.00", "4.000"], ["67592.50", "3.002"], ["67663.40", "0.002"], ["67706.30", "0.006"], ["69835.40", "0.005"], ["70132.60", "2.586"], ["70548.00", "0.026"], ["70548.20", "0.002"], ["71107.40", "0.039"], ["71111.00", "0.597"], ["71160.80", "0.008"], ["71161.00", "2.860"], ["71168.00", "0.005"], ["71168.20", "0.070"], ["71173.80", "1.200"], ["71175.10", "0.000"], ["71175.30", "0.651"], ["71178.40", "0.085"], ["71178.70", "0.142"], ["71178.90", "0.005"], ["71195.60", "0.042"], ["71196.60", "0.082"], ["71196.90", "0.539"], ["71197.60", "0.042"], ["71198.10", "0.029"], ["71198.50", "0.346"], ["71199.40", "0.029"], ["71199.50", "0.042"], ["71200.20", "0.000"], ["71200.50", "0.414"], ["71200.60", "0.029"], ["71201.40", "0.085"], ["71201.80", "0.029"], ["71202.20", "3.603"], ["71202.40", "0.045"], ["71202.70", "0.000"], ["71203.10", "0.029"], ["71203.70", "0.042"], ["71204.30", "0.029"], ["71205.10", "0.044"], ["71205.60", "0.031"], ["71209.40", "1.100"], ["71212.20", "0.007"], ["71212.70", "0.236"], ["71213.00", "0.301"], ["71213.30", "0.284"], ["71215.90", "0.020"], ["71216.40", "0.083"], ["71216.90", "0.000"], ["71217.60", "0.004"], ["71217.90", "0.020"], ["71218.20", "0.000"], ["71218.80", "0.006"], ["71218.90", "0.072"], ["71219.80", "0.019"], ["71220.10", "0.684"], ["71220.80", "0.052"], ["71221.30", "0.000"], ["71222.30", "0.003"], ["71222.60", "0.084"], ["71222.90", "0.508"], ["71223.20", "0.082"], ["71223.30", "0.000"], ["71223.80", "0.318"], ["71224.10", "1.049"], ["71224.20", "0.245"], ["71224.30", "0.000"], ["71225.10", "2.396"], ["71225.20", "0.031"], ["71225.40", "0.003"], ["71225.90", "0.000"], ["71226.20", "0.002"], ["71226.60", "0.003"], ["71226.70", "0.016"], ["71227.00", "0.041"], ["71227.10", "0.002"], ["71227.20", "0.002"], ["71227.70", "0.001"], ["71227.80", "0.003"], ["71228.10", "0.015"], ["71228.30", "0.298"], ["71228.60", "0.003"], ["71228.70", "0.003"], ["71228.80", "0.003"], ["71228.90", "0.827"], ["71229.10", "0.005"], ["71229.20", "0.000"], ["71229.40", "0.340"], ["71229.50", "0.512"], ["71229.60", "0.006"], ["71229.70", "0.005"], ["71230.10", "1.272"], ["71230.30", "1.147"], ["71230.50", "0.107"], ["71230.60", "0.102"], ["71231.00", "0.299"], ["71231.10", "0.070"], ["71231.20", "0.009"], ["71231.30", "0.000"], ["71231.40", "0.075"], ["71231.60", "7.771"], ["71231.80", "0.002"], ["71231.90", "0.072"], ["71232.00", "0.504"], ["71232.40", "0.009"], ["71232.50", "0.005"], ["71232.60", "0.019"], ["71232.70", "0.002"], ["71232.80", "0.008"], ["71232.90", "0.020"], ["71233.10", "1.701"], ["71233.20", "0.024"], ["71233.30", "0.029"], ["71233.40", "0.002"], ["71233.70", "0.080"], ["71233.80", "0.214"], ["71233.90", "0.040"], ["71234.00", "0.009"], ["71234.20", "0.084"], ["71234.50", "0.002"], ["71234.70", "0.000"], ["71235.10", "0.020"], ["71235.30", "0.039"], ["71235.50", "0.024"], ["71235.80", "1.053"], ["71236.40", "0.063"], ["71236.60", "0.003"], ["71236.70", "0.510"], ["71236.80", "0.002"], ["71236.90", "0.128"], ["71237.00", "0.002"], ["71237.40", "0.000"], ["71237.50", "0.034"], ["71237.60", "0.631"], ["71237.70", "0.015"], ["71238.00", "0.004"], ["71238.40", "0.008"], ["71238.50", "0.000"], ["71238.70", "0.343"], ["71238.80", "1.195"], ["71239.10", "0.002"], ["71239.40", "0.513"], ["71239.50", "0.016"], ["71239.60", "0.216"], ["71239.80", "0.004"], ["71239.90", "0.265"], ["71240.00", "0.012"], ["71240.10", "0.873"], ["71240.50", "0.012"], ["71240.60", "0.000"], ["71241.70", "0.002"], ["71241.80", "0.296"], ["71242.10", "1.053"], ["71242.70", "1.912"], ["71242.80", "0.142"], ["71242.90", "0.012"], ["71243.00", "0.360"], ["71243.20", "0.000"], ["71243.30", "0.208"], ["71243.70", "0.013"], ["71245.00", "0.004"], ["71245.10", "0.004"], ["71245.30", "0.004"], ["71245.40", "0.005"], ["71245.60", "0.166"], ["71246.40", "0.045"], ["71246.60", "0.054"], ["71247.00", "0.349"], ["71247.80", "0.011"], ["71247.90", "0.004"], ["71248.30", "0.075"], ["71248.50", "0.525"], ["71248.60", "1.088"], ["71249.20", "0.340"], ["71249.60", "0.004"], ["71249.70", "0.034"], ["71249.90", "0.003"], ["71250.50", "0.118"], ["71250.60", "0.002"], ["71250.80", "0.000"], ["71250.90", "0.003"], ["71251.00", "0.007"], ["71251.10", "0.940"], ["71251.40", "0.019"], ["71251.50", "0.000"], ["71251.80", "0.015"], ["71252.00", "0.037"], ["71252.10", "0.005"], ["71252.30", "0.000"], ["71253.70", "0.238"], ["71253.80", "0.004"], ["71254.60", "0.094"], ["71255.00", "0.009"], ["71255.10", "0.001"], ["71256.00", "0.005"], ["71256.10", "0.000"], ["71256.90", "0.000"], ["71257.10", "0.010"], ["71257.50", "0.116"], ["71257.70", "0.004"], ["71257.80", "0.004"], ["71258.20", "0.004"], ["71258.60", "0.003"], ["71258.70", "0.001"], ["71259.30", "0.002"], ["71260.60", "0.327"], ["71260.70", "0.000"], ["71260.80", "0.000"]], "a": [["71260.70", "7.797"], ["71260.80", "1.152"], ["71260.90", "0.447"], ["71261.00", "0.005"], ["71262.30", "0.000"], ["71262.50", "0.003"], ["71262.80", "0.017"], ["71263.50", "0.011"], ["71263.90", "0.003"], ["71264.20", "0.000"], ["71264.50", "1.298"], ["71264.90", "0.003"], ["71265.10", "0.020"], ["71265.40", "0.007"], ["71265.90", "0.003"], ["71266.00", "0.002"], ["71268.20", "0.006"], ["71268.30", "0.074"], ["71269.90", "0.004"], ["71271.50", "0.007"], ["71271.60", "0.002"], ["71271.70", "0.048"], ["71272.00", "0.105"], ["71272.20", "0.008"], ["71272.40", "0.077"], ["71272.50", "0.008"], ["71272.60", "0.020"], ["71273.00", "0.047"], ["71273.20", "0.237"], ["71273.30", "0.008"], ["71273.50", "0.682"], ["71273.60", "0.668"], ["71273.70", "0.006"], ["71274.00", "0.347"], ["71274.20", "0.316"], ["71274.30", "0.102"], ["71274.60", "0.049"], ["71274.90", "0.291"], ["71275.00", "0.103"], ["71275.20", "0.336"], ["71275.30", "0.245"], ["71275.40", "0.090"], ["71275.50", "0.128"], ["71275.60", "1.680"], ["71275.70", "0.004"], ["71276.10", "0.000"], ["71276.30", "0.055"], ["71276.40", "0.013"], ["71276.70", "0.069"], ["71277.30", "0.003"], ["71277.40", "0.000"], ["71277.90", "0.001"], ["71278.20", "0.102"], ["71278.90", "0.077"], ["71279.80", "0.245"], ["71279.90", "0.750"], ["71280.20", "0.392"], ["71280.60", "0.003"], ["71281.10", "0.003"], ["71281.50", "0.001"], ["71282.10", "0.029"], ["71282.30", "0.018"], ["71282.90", "0.002"], ["71285.80", "0.506"], ["71285.90", "1.071"], ["71286.00", "0.351"], ["71286.60", "0.006"], ["71286.70", "0.000"], ["71287.30", "0.003"], ["71287.40", "0.607"], ["71289.30", "0.474"], ["71289.40", "0.010"], ["71289.50", "0.013"], ["71289.70", "0.010"], ["71290.10", "0.003"], ["71290.20", "0.005"], ["71290.80", "0.411"], ["71290.90", "0.511"], ["71291.50", "0.004"], ["71291.60", "0.109"], ["71292.20", "0.035"], ["71292.30", "0.015"], ["71292.70", "0.028"], ["71292.80", "0.317"], ["71296.00", "0.128"], ["71296.20", "0.255"], ["71296.30", "0.208"], ["71296.60", "0.000"], ["71299.80", "0.087"], ["71299.90", "0.943"], ["71306.70", "0.003"], ["71308.00", "0.006"], ["71308.10", "0.192"], ["71309.70", "0.010"], ["71317.70", "0.116"], ["71321.30", "0.423"], ["71321.50", "0.000"], ["71321.70", "0.001"], ["71324.80", "0.081"], ["71325.00", "0.002"], ["71326.00", "3.593"], ["71326.60", "0.000"], ["71328.60", "0.521"], ["71339.40", "0.072"], ["71342.50", "0.291"], ["71342.90", "0.318"], ["71347.80", "0.439"], ["71385.20", "0.004"], ["71435.30", "0.159"], ["71438.90", "0.099"], ["71442.40", "0.665"], ["71442.60", "0.075"], ["71545.70", "0.146"], ["71545.90", "0.000"], ["71899.60", "1.387"], ["71973.30", "0.552"], ["71973.50", "0.000"], ["72091.70", "0.000"], ["72212.80", "0.000"], ["72260.90", "0.022"], ["72263.90", "0.004"], ["72264.60", "0.012"], ["72264.80", "0.000"], ["72446.30", "0.000"], ["72517.50", "0.689"], ["72695.10", "0.000"], ["74830.00", "0.050"], ["89523.20", "0.000"], ["100000.00", "15.554"]]}}
{"local_ts": 1773384722578, "server_ts": 1773384722356, "data": {"e": "depthUpdate", "E": 1773384722359, "T": 1773384722356, "s": "BTCUSDT", "U": 10101356220604, "u": 10101356225976, "pu": 10101356220591, "b": [["1000.00", "27.642"], ["5000.00", "101.418"], ["20760.60", "0.639"], ["20860.80", "0.189"], ["21060.60", "0.441"], ["21160.80", "0.090"], ["67681.70", "0.002"], ["69122.70", "0.005"], ["70548.00", "0.022"], ["70904.30", "0.000"], ["71152.20", "0.069"], ["71153.60", "0.000"], ["71178.20", "0.444"], ["71178.70", "0.003"], ["71179.20", "1.324"], ["71186.00", "0.000"], ["71230.40", "0.128"], ["71231.40", "0.060"], ["71232.40", "0.051"], ["71237.00", "0.013"], ["71237.10", "0.000"], ["71238.30", "1.231"], ["71239.20", "0.003"], ["71239.50", "0.051"], ["71240.40", "0.005"], ["71240.60", "0.631"], ["71241.10", "0.000"], ["71241.40", "0.005"], ["71242.20", "0.846"], ["71242.60", "0.027"], ["71242.80", "0.414"], ["71243.20", "0.188"], ["71243.50", "0.225"], ["71243.70", "0.013"], ["71243.80", "0.301"], ["71244.20", "0.357"], ["71245.60", "0.208"], ["71249.90", "0.003"], ["71250.10", "0.006"], ["71253.20", "0.000"], ["71253.30", "0.017"], ["71253.60", "0.037"], ["71254.00", "0.216"], ["71255.10", "0.016"], ["71257.20", "0.002"], ["71258.60", "0.003"], ["71258.70", "0.003"], ["71259.90", "0.000"], ["71260.00", "0.004"], ["71260.20", "0.030"], ["71260.50", "0.001"], ["71260.60", "1.464"]], "a": [["71260.70", "7.299"], ["71261.60", "0.002"], ["71261.80", "0.000"], ["71262.00", "0.001"], ["71262.10", "0.021"], ["71262.70", "0.045"], ["71262.80", "0.014"], ["71262.90", "0.258"], ["71264.30", "0.006"], ["71264.60", "0.061"], ["71265.60", "0.001"], ["71265.70", "0.001"], ["71267.10", "0.018"], ["71268.30", "0.074"], ["71269.40", "0.035"], ["71269.60", "0.034"], ["71270.90", "0.029"], ["71276.20", "0.092"], ["71276.50", "0.005"], ["71277.00", "0.632"], ["71277.40", "0.000"], ["71277.70", "0.411"], ["71278.60", "0.070"], ["71279.10", "0.030"], ["71281.00", "0.018"], ["71283.20", "0.005"], ["71286.00", "0.347"], ["71286.70", "0.002"], ["71307.90", "0.011"], ["71308.00", "0.004"], ["71331.80", "0.010"], ["71372.30", "1.971"], ["71487.70", "0.000"], ["71973.20", "0.000"], ["71973.30", "0.550"], ["72189.40", "0.830"], ["72205.70", "0.000"], ["72349.10", "1.919"], ["89523.20", "0.000"]]}}
{"local_ts": 1773384723596, "server_ts": 1773384723377, "data": {"e": "depthUpdate", "E": 1773384723379, "T": 1773384723377, "s": "BTCUSDT", "U": 10101356307696, "u": 10101356315893, "pu": 10101356307688, "b": [["5000.00", "101.418"], ["20755.00", "0.171"], ["20760.60", "0.909"], ["20860.60", "0.000"], ["20955.00", "0.234"], ["21060.60", "0.459"], ["21155.00", "0.297"], ["67669.90", "0.000"], ["70412.60", "2.541"], ["70542.40", "0.000"], ["71078.70", "0.566"], ["71156.60", "0.002"], ["71166.30", "0.184"], ["71179.20", "1.324"], ["71184.10", "0.300"], ["71208.00", "0.006"], ["71208.20", "0.090"], ["71208.60", "0.005"], ["71213.70", "0.051"], ["71215.20", "0.002"], ["71219.40", "0.000"], ["71221.20", "0.266"], ["71222.30", "0.003"], ["71231.00", "0.328"], ["71232.20", "0.535"], ["71233.60", "0.004"], ["71235.20", "0.631"], ["71236.20", "0.356"], ["71239.70", "0.030"], ["71240.40", "0.005"], ["71240.90", "0.001"], ["71241.30", "0.007"], ["71241.60", "0.000"], ["71241.70", "0.211"], ["71241.80", "0.627"], ["71242.00", "7.247"], ["71242.40", "0.005"], ["71243.00", "0.358"], ["71243.40", "0.161"], ["71243.80", "0.257"], ["71244.00", "0.005"], ["71244.30", "0.128"], ["71244.40", "0.006"], ["71244.80", "0.005"], ["71244.90", "0.006"], ["71245.10", "0.187"], ["71245.20", "0.064"], ["71245.50", "0.005"], ["71245.60", "0.166"], ["71245.90", "0.202"], ["71246.00", "0.009"], ["71246.40", "0.171"], ["71247.10", "0.312"], ["71247.30", "0.205"], ["71247.90", "0.032"], ["71248.10", "0.003"], ["71248.50", "0.007"], ["71251.70", "0.042"], ["71253.60", "0.015"], ["71253.70", "0.002"], ["71253.90", "0.000"], ["71254.10", "0.033"], ["71254.30", "0.000"], ["71254.50", "0.071"], ["71254.80", "0.003"], ["71255.00", "1.778"]], "a": [["71255.10", "6.826"], ["71255.30", "0.000"], ["71255.70", "0.042"], ["71255.80", "0.017"], ["71256.60", "0.006"], ["71256.70", "0.071"], ["71257.00", "0.015"], ["71257.40", "0.000"], ["71257.60", "1.145"], ["71257.70", "0.090"], ["71257.90", "0.000"], ["71258.30", "0.019"], ["71258.60", "0.043"], ["71258.80", "0.000"], ["71258.90", "0.003"], ["71259.50", "0.047"], ["71259.60", "0.054"], ["71259.80", "0.001"], ["71259.90", "0.000"], ["71260.00", "0.008"], ["71260.40", "0.016"], ["71260.80", "0.019"], ["71261.30", "0.000"], ["71261.80", "0.000"], ["71262.10", "0.021"], ["71262.20", "0.066"], ["71262.50", "0.005"], ["71262.80", "0.039"], ["71263.30", "0.015"], ["71263.80", "0.000"], ["71264.60", "0.021"], ["71265.10", "0.005"], ["71266.30", "0.055"], ["71267.60", "0.140"], ["71269.20", "0.065"], ["71269.70", "0.174"], ["71269.90", "0.006"], ["71270.30", "0.111"], ["71270.70", "0.010"], ["71270.90", "0.051"], ["71271.10", "0.631"], ["71271.30", "0.001"], ["71272.00", "0.103"], ["71272.90", "0.106"], ["71273.00", "0.009"], ["71277.50", "0.249"], ["71279.70", "0.002"], ["71281.20", "0.002"], ["71286.70", "0.002"], ["71289.30", "0.083"], ["71290.70", "0.011"], ["71292.60", "0.002"], ["71293.40", "0.306"], ["71294.00", "0.530"], ["71294.80", "0.022"], ["71295.50", "0.085"], ["71296.10", "0.006"], ["71296.20", "0.253"], ["71296.90", "0.125"], ["71297.70", "0.005"], ["71299.90", "0.858"], ["71304.10", "0.010"], ["71304.20", "0.005"], ["71325.00", "0.007"], ["71332.10", "0.000"], ["71900.00", "31.204"], ["71967.70", "0.000"], ["72680.20", "0.625"], ["89523.20", "0.000"]]}}
{"local_ts": 1773384724615, "server_ts": 1773384724398, "data": {"e": "depthUpdate", "E": 1773384724399, "T": 1773384724398, "s": "BTCUSDT", "U": 10101356384409, "u": 10101356391399, "pu": 10101356384394, "b": [["1000.00", "27.642"], ["5000.00", "101.418"], ["20755.00", "0.072"], ["20855.00", "0.171"], ["20955.00", "0.729"], ["21055.00", "0.171"], ["21155.00", "1.557"], ["33000.00", "9.339"], ["69912.50", "0.388"], ["70218.80", "0.003"], ["70542.40", "0.002"], ["71219.10", "0.022"], ["71225.30", "0.004"], ["71226.00", "0.006"], ["71237.20", "0.030"], ["71249.90", "0.003"]], "a": [["71303.70", "0.004"], ["71304.00", "0.024"], ["73392.70", "0.005"], ["74837.60", "0.002"], ["89523.20", "0.000"]]}}
{"local_ts": 1773384725639, "server_ts": 1773384725420, "data": {"e": "depthUpdate", "E": 1773384725421, "T": 1773384725420, "s": "BTCUSDT", "U": 10101356547163, "u": 10101356551867, "pu": 10101356547095, "b": [["1000.00", "27.842"], ["5000.00", "101.418"], ["20747.00", "0.036"], ["20847.00", "0.297"], ["20855.00", "0.468"], ["20947.00", "0.045"], ["20955.00", "0.000"], ["21047.00", "0.630"], ["21055.00", "0.720"], ["21155.00", "0.207"], ["57004.00", "0.004"], ["70432.40", "0.000"], ["70534.50", "0.217"], ["70898.70", "6.123"], ["71060.80", "0.022"], ["71113.60", "0.000"], ["71113.70", "0.100"], ["71125.80", "0.076"], ["71126.50", "0.000"], ["71201.70", "0.002"], ["71202.20", "0.050"], ["71202.50", "0.000"], ["71211.40", "0.193"], ["71213.60", "0.005"], ["71214.20", "0.668"], ["71214.60", "0.019"], ["71215.10", "0.009"], ["71215.20", "0.004"], ["71215.80", "0.094"], ["71215.90", "0.008"], ["71217.00", "0.002"], ["71217.80", "0.208"], ["71222.40", "0.000"], ["71225.30", "0.004"], ["71227.50", "0.022"], ["71228.50", "0.005"], ["71228.60", "0.003"], ["71228.70", "1.209"], ["71229.10", "0.527"], ["71230.40", "0.916"], ["71231.60", "0.338"], ["71233.80", "0.550"], ["71235.30", "0.037"], ["71236.70", "0.665"], ["71238.10", "0.046"], ["71239.50", "0.054"], ["71239.90", "0.022"], ["71240.20", "1.053"], ["71240.30", "0.793"], ["71241.50", "0.004"], ["71242.40", "0.009"], ["71244.50", "0.507"], ["71245.30", "0.103"], ["71247.00", "3.417"]], "a": [["71247.10", "4.766"], ["71250.30", "0.171"], ["71252.30", "0.007"], ["71254.20", "0.000"], ["71254.40", "0.009"], ["71255.10", "0.022"], ["71255.90", "0.067"], ["71257.00", "0.000"], ["71259.80", "0.081"], ["71263.20", "0.174"], ["71263.50", "0.115"], ["71263.60", "0.236"], ["71268.90", "0.000"], ["71269.90", "0.216"], ["71270.00", "0.009"], ["71270.30", "0.431"], ["71272.10", "0.002"], ["71274.00", "0.388"], ["71274.10", "1.099"], ["71274.50", "0.010"], ["71274.70", "0.002"], ["71274.80", "0.003"], ["71275.60", "2.041"], ["71276.90", "0.044"], ["71281.00", "0.016"], ["71281.10", "0.030"], ["71281.20", "0.126"], ["71282.70", "0.402"], ["71283.00", "0.623"], ["71284.00", "0.047"], ["71284.70", "0.022"], ["71285.00", "0.269"], ["71285.70", "0.087"], ["71286.00", "0.389"], ["71286.30", "1.073"], ["71286.70", "0.000"], ["71287.60", "0.406"], ["71287.70", "0.008"], ["71289.10", "0.206"], ["71290.60", "0.007"], ["71292.00", "0.008"], ["71296.20", "0.255"], ["71297.10", "0.008"], ["71300.80", "0.004"], ["71353.90", "0.181"], ["71959.60", "0.000"], ["72351.40", "0.936"], ["72672.00", "0.064"], ["74836.10", "0.002"]]}}
{"local_ts": 1773384726656, "server_ts": 1773384726440, "data": {"e": "depthUpdate", "E": 1773384726441, "T": 1773384726440, "s": "BTCUSDT", "U": 10101356597656, "u": 10101356602519, "pu": 10101356597524, "b": [["1000.00", "28.042"], ["5000.00", "101.418"], ["20747.00", "0.801"], ["20847.00", "0.099"], ["20947.00", "1.368"], ["21047.00", "0.432"], ["33000.00", "9.343"], ["57004.00", "0.000"], ["67683.20", "0.002"], ["67687.20", "0.000"], ["69821.50", "0.002"], ["69835.40", "0.011"], ["70534.50", "1.639"], ["70534.60", "0.005"], ["70997.50", "0.004"], ["71146.90", "1.077"], ["71148.00", "0.067"], ["71202.70", "0.004"], ["71202.90", "0.005"], ["71211.30", "0.005"], ["71213.20", "0.033"], ["71234.70", "0.473"], ["71238.30", "0.219"], ["71243.40", "0.101"]], "a": [["71259.60", "0.012"], ["71262.80", "0.381"], ["71265.40", "0.049"], ["71266.40", "0.550"], ["71267.40", "0.049"], ["71268.30", "0.076"], ["71268.40", "0.006"], ["71268.50", "0.003"], ["71269.30", "0.051"], ["71269.50", "0.000"], ["71270.40", "0.000"], ["71271.40", "0.000"], ["71272.40", "0.028"], ["71275.60", "1.829"], ["71276.40", "0.002"], ["71294.00", "0.025"], ["71294.20", "0.003"], ["71295.70", "0.593"], ["71295.80", "0.074"], ["71610.90", "0.561"], ["71959.60", "0.000"], ["73062.30", "0.000"], ["89523.20", "0.000"]]}}
{"local_ts": 1773384727680, "server_ts": 1773384727464, "data": {"e": "depthUpdate", "E": 1773384727465, "T": 1773384727464, "s": "BTCUSDT", "U": 10101356683376, "u": 10101356688245, "pu": 10101356683306, "b": [["1000.00", "28.042"], ["5000.00", "101.418"], ["20747.00", "0.225"], ["20847.00", "1.098"], ["20947.00", "0.702"], ["21147.00", "0.675"], ["56998.00", "0.000"], ["67667.30", "0.000"], ["67676.60", "0.002"], ["67684.60", "0.004"], ["68397.20", "0.004"], ["69821.30", "0.002"], ["70534.50", "1.639"], ["70890.80", "0.006"], ["70890.90", "0.004"], ["70997.00", "0.055"], ["71175.60", "0.021"], ["71202.50", "0.004"], ["71202.60", "0.043"], ["71233.20", "0.004"], ["71242.50", "0.011"]], "a": [["71248.00", "0.000"], ["71254.90", "0.005"], ["71255.80", "0.176"], ["71257.40", "0.105"], ["71258.10", "0.060"], ["71261.30", "0.001"], ["71262.10", "0.357"], ["71264.90", "0.091"], ["71274.20", "0.203"], ["71276.20", "0.005"], ["71276.40", "0.000"], ["71278.30", "0.002"], ["71314.50", "0.004"], ["71443.00", "4.036"], ["71610.60", "0.008"], ["71959.60", "0.000"], ["72080.50", "0.002"], ["72570.00", "0.726"], ["89523.20", "0.000"]]}}
{"local_ts": 1773384728706, "server_ts": 1773384728488, "data": {"e": "depthUpdate", "E": 1773384728489, "T": 1773384728488, "s": "BTCUSDT", "U": 10101356758501, "u": 10101356762429, "pu": 10101356758438, "b": [["5000.00", "101.398"], ["20747.00", "0.837"], ["20847.00", "0.963"], ["21047.00", "0.540"], ["21147.00", "0.360"], ["33000.00", "9.343"], ["56998.00", "0.000"], ["67684.60", "0.008"], ["69821.30", "0.000"], ["70534.50", "1.639"], ["70534.60", "0.005"], ["70700.80", "0.706"], ["70924.20", "0.004"], ["70996.90", "0.291"], ["71178.00", "0.008"], ["71217.60", "0.074"], ["71219.30", "0.000"], ["71222.60", "0.074"], ["71223.90", "0.003"], ["71226.20", "1.195"], ["71226.40", "0.010"], ["71226.80", "0.014"], ["71227.20", "0.647"], ["71227.50", "0.002"], ["71228.00", "0.002"], ["71228.20", "0.004"], ["71228.50", "0.012"], ["71228.90", "0.003"], ["71229.40", "0.005"], ["71232.40", "0.039"], ["71233.60", "0.338"], ["71238.90", "0.006"], ["71239.30", "0.004"], ["71239.50", "0.059"], ["71240.30", "0.366"], ["71242.30", "0.067"], ["71242.60", "0.006"], ["71243.40", "0.005"], ["71245.70", "0.000"], ["71246.00", "0.007"], ["71247.00", "0.585"]], "a": [["71249.90", "0.003"], ["71250.00", "0.009"], ["71250.20", "0.000"], ["71250.80", "0.000"], ["71255.20", "0.644"], ["71255.30", "0.382"], ["71256.90", "0.650"], ["71257.00", "0.687"], ["71258.40", "0.367"], ["71259.80", "0.771"], ["71260.80", "0.009"], ["71261.20", "0.001"], ["71261.30", "0.181"], ["71261.60", "0.000"], ["71264.10", "0.028"], ["71264.40", "0.018"], ["71265.80", "0.000"], ["71268.00", "0.051"], ["71271.10", "0.007"], ["71272.00", "0.246"], ["71273.50", "0.085"], ["71275.30", "0.010"], ["71276.20", "0.003"], ["71277.70", "0.003"], ["71278.30", "0.000"], ["71279.50", "0.043"], ["71289.50", "0.289"], ["71289.60", "0.005"], ["71295.90", "0.027"], ["71296.10", "0.024"], ["71296.20", "0.255"], ["71296.60", "0.081"], ["71474.40", "0.401"], ["71537.00", "0.215"], ["71610.50", "0.000"], ["71959.60", "0.000"], ["73384.50", "0.005"], ["73991.20", "0.000"], ["74829.00", "0.052"], ["75878.20", "0.031"], ["89523.20", "0.000"]]}}
{"local_ts": 1773384729727, "server_ts": 1773384729508, "data": {"e": "depthUpdate", "E": 1773384729511, "T": 1773384729508, "s": "BTCUSDT", "U": 10101356828916, "u": 10101356837623, "pu": 10101356828801, "b": [["1000.00", "28.042"], ["5000.00", "101.418"], ["20747.00", "1.233"], ["20947.00", "0.405"], ["21047.00", "0.495"], ["21147.00", "0.567"], ["56998.00", "0.000"], ["67649.40", "0.000"], ["67679.40", "0.002"], ["69818.70", "0.002"], ["70534.50", "2.347"], ["70534.60", "0.005"], ["70962.80", "0.289"], ["70970.80", "0.000"], ["71064.80", "0.079"], ["71114.80", "0.040"], ["71137.00", "0.048"], ["71140.20", "2.546"], ["71141.40", "0.114"], ["71141.60", "0.180"], ["71148.20", "0.000"], ["71165.00", "1.358"], ["71165.10", "0.099"], ["71171.60", "0.456"], ["71171.90", "0.002"], ["71172.00", "0.023"], ["71186.90", "0.000"], ["71189.40", "1.036"], ["71199.70", "0.000"], ["71216.70", "0.070"], ["71217.80", "0.095"], ["71222.80", "0.002"], ["71236.70", "0.108"], ["71237.30", "0.013"], ["71239.90", "0.033"], ["71240.10", "0.003"], ["71240.40", "0.005"], ["71243.80", "0.005"], ["71243.90", "0.143"], ["71245.60", "0.008"], ["71247.00", "0.578"]], "a": [["71247.10", "3.259"], ["71248.00", "0.000"], ["71248.40", "0.002"], ["71248.50", "0.010"], ["71248.70", "0.000"], ["71250.20", "0.000"], ["71250.70", "0.007"], ["71250.80", "0.000"], ["71250.90", "0.006"], ["71251.80", "0.018"], ["71251.90", "0.074"], ["71252.00", "0.005"], ["71252.20", "0.007"], ["71252.30", "0.008"], ["71253.90", "0.004"], ["71254.20", "0.070"], ["71254.50", "0.004"], ["71255.10", "0.160"], ["71257.70", "0.019"], ["71258.40", "0.379"], ["71260.70", "0.654"], ["71260.80", "0.675"], ["71261.20", "0.694"], ["71261.30", "0.181"], ["71261.40", "0.234"], ["71265.70", "0.215"], ["71265.80", "0.033"], ["71266.80", "0.256"], ["71267.40", "0.024"], ["71275.30", "0.010"], ["71277.20", "0.004"], ["71277.70", "0.001"], ["71281.00", "0.011"], ["71282.70", "0.420"], ["71287.80", "0.002"], ["71290.20", "0.007"], ["71293.60", "0.005"], ["71295.40", "0.019"], ["71295.60", "0.003"], ["71321.90", "0.099"], ["71335.80", "0.041"], ["71336.10", "0.522"], ["71342.60", "0.020"], ["71353.90", "0.158"], ["71361.90", "0.019"], ["71363.30", "0.056"], ["71373.50", "0.022"], ["71435.90", "0.159"], ["71439.50", "0.159"], ["71443.00", "3.877"], ["71474.40", "0.395"], ["71532.30", "1.417"], ["71540.30", "0.000"], ["71959.60", "0.000"], ["74096.80", "0.000"]]}}
{"local_ts": 1773384730750, "server_ts": 1773384730533, "data": {"e": "depthUpdate", "E": 1773384730535, "T": 1773384730533, "s": "BTCUSDT", "U": 10101356935044, "u": 10101356942068, "pu": 10101356934915, "b": [["1000.00", "27.642"], ["5000.00", "101.398"], ["20747.00", "0.000"], ["20842.00", "0.180"], ["20947.00", "0.594"], ["21042.00", "0.216"], ["21142.00", "0.153"], ["21147.00", "1.179"], ["56994.00", "0.000"], ["67654.80", "0.002"], ["67672.00", "0.004"], ["70209.10", "1.493"], ["70209.60", "0.711"], ["70266.10", "0.283"], ["70352.00", "0.711"], ["70529.60", "0.009"], ["70565.20", "0.710"], ["70890.80", "0.006"], ["70964.20", "1.616"], ["70980.10", "0.000"], ["70997.00", "0.055"], ["71093.10", "0.151"], ["71094.70", "0.002"], ["71113.70", "0.147"], ["71115.50", "0.072"], ["71130.30", "0.128"], ["71135.00", "6.526"], ["71140.20", "2.664"], ["71140.40", "0.042"], ["71143.80", "0.203"], ["71151.30", "0.001"], ["71152.00", "0.043"], ["71160.20", "0.003"], ["71164.80", "0.018"], ["71170.70", "0.476"], ["71171.60", "0.269"], ["71174.80", "0.002"], ["71177.90", "0.001"], ["71189.40", "0.978"], ["71190.80", "0.010"], ["71192.60", "0.007"], ["71193.40", "0.004"], ["71194.20", "0.002"], ["71194.50", "0.003"], ["71195.10", "0.016"], ["71197.80", "0.284"], ["71198.80", "0.008"], ["71203.10", "0.243"], ["71206.40", "0.001"], ["71206.70", "0.231"], ["71207.00", "0.036"], ["71207.40", "0.038"], ["71207.50", "0.034"], ["71208.10", "0.016"], ["71208.20", "0.044"], ["71210.20", "0.070"], ["71210.50", "0.327"], ["71210.60", "2.662"], ["71211.60", "0.011"], ["71211.70", "0.014"], ["71212.30", "0.044"], ["71212.40", "0.009"], ["71213.00", "0.338"], ["71213.10", "0.132"], ["71213.60", "0.321"], ["71213.70", "0.007"], ["71213.80", "0.002"], ["71214.20", "0.434"], ["71214.70", "0.540"], ["71215.00", "0.039"], ["71215.10", "0.007"], ["71215.30", "0.000"], ["71215.60", "0.080"], ["71216.20", "0.032"], ["71216.30", "0.007"], ["71216.40", "0.042"], ["71216.50", "0.577"], ["71217.40", "0.003"], ["71217.50", "0.016"], ["71217.80", "0.095"], ["71218.70", "0.008"], ["71219.20", "0.641"], ["71219.60", "0.643"], ["71220.50", "0.008"], ["71221.30", "0.112"], ["71221.40", "0.688"], ["71222.30", "0.003"], ["71223.40", "0.008"], ["71223.50", "0.336"], ["71226.80", "0.004"], ["71226.90", "0.094"], ["71227.30", "0.315"], ["71228.00", "0.003"], ["71229.00", "0.011"], ["71229.40", "0.002"], ["71230.30", "0.047"], ["71230.90", "0.003"], ["71231.10", "0.004"], ["71231.90", "0.072"], ["71232.30", "0.041"], ["71232.70", "0.001"], ["71233.10", "0.515"], ["71233.40", "0.000"], ["71233.50", "0.000"], ["71234.00", "0.002"], ["71234.10", "0.003"], ["71234.50", "0.019"], ["71234.80", "0.001"], ["71236.10", "0.062"], ["71236.60", "0.003"], ["71236.90", "0.001"], ["71237.20", "0.001"], ["71237.30", "0.006"], ["71237.60", "0.051"], ["71238.00", "0.002"], ["71238.20", "0.003"], ["71238.30", "0.012"], ["71239.10", "0.025"], ["71241.60", "0.002"]], "a": [["71242.10", "11.974"], ["71242.30", "0.000"], ["71242.40", "0.002"], ["71242.90", "0.000"], ["71243.00", "0.002"], ["71243.20", "0.005"], ["71243.70", "0.002"], ["71243.90", "0.018"], ["71244.60", "0.032"], ["71244.70", "0.012"], ["71244.90", "0.002"], ["71245.90", "0.654"], ["71246.10", "0.006"], ["71247.10", "0.076"], ["71248.00", "0.002"], ["71249.10", "0.000"], ["71249.50", "0.023"], ["71249.90", "0.003"], ["71251.90", "0.147"], ["71253.00", "0.016"], ["71253.90", "0.014"], ["71254.70", "0.053"], ["71255.80", "0.119"], ["71256.10", "0.116"], ["71256.30", "0.033"], ["71256.60", "0.047"], ["71256.90", "0.249"], ["71257.80", "0.041"], ["71258.50", "0.036"], ["71260.80", "0.122"], ["71261.00", "0.402"], ["71261.40", "0.002"], ["71261.70", "0.000"], ["71262.50", "0.005"], ["71262.80", "0.005"], ["71263.30", "0.000"], ["71263.50", "0.189"], ["71265.20", "0.000"], ["71266.00", "0.009"], ["71266.90", "0.032"], ["71270.50", "0.012"], ["71270.60", "0.114"], ["71270.70", "0.010"], ["71271.20", "0.011"], ["71271.30", "0.306"], ["71271.90", "0.006"], ["71272.00", "0.280"], ["71272.60", "0.002"], ["71272.70", "0.054"], ["71273.10", "0.002"], ["71274.10", "1.083"], ["71274.40", "0.003"], ["71275.20", "0.004"], ["71275.30", "0.006"], ["71277.00", "0.017"], ["71277.10", "0.135"], ["71277.30", "0.087"], ["71277.40", "0.085"], ["71277.70", "0.046"], ["71278.20", "0.023"], ["71281.20", "0.040"], ["71284.80", "0.052"], ["71288.50", "0.527"], ["71290.20", "0.004"], ["71290.70", "0.084"], ["71290.80", "0.095"], ["71290.90", "0.506"], ["71291.30", "0.042"], ["71291.80", "0.000"], ["71292.50", "0.004"], ["71295.50", "0.033"], ["71296.10", "0.003"], ["71298.40", "0.000"], ["71307.20", "0.057"], ["71307.60", "0.154"], ["71310.80", "0.030"], ["71315.20", "0.012"], ["71346.00", "0.000"], ["71354.00", "0.040"], ["71366.80", "0.191"], ["71380.40", "0.000"], ["71399.30", "0.532"], ["71415.30", "1.616"], ["71424.10", "0.000"], ["71430.90", "0.701"], ["71431.30", "0.000"], ["71488.90", "0.503"], ["71514.70", "2.093"], ["71527.10", "0.316"], ["71559.40", "0.194"], ["71954.50", "0.002"]]}}
{"local_ts": 1773384731773, "server_ts": 1773384731556, "data": {"e": "depthUpdate", "E": 1773384731557, "T": 1773384731556, "s": "BTCUSDT", "U": 10101357007546, "u": 10101357012743, "pu": 10101357007499, "b": [["1000.00", "27.642"], ["5000.00", "101.418"], ["20742.00", "0.144"], ["20842.00", "0.756"], ["20843.80", "0.000"], ["20844.50", "0.000"], ["20846.00", "0.000"], ["20942.00", "0.144"], ["21042.00", "1.548"], ["21043.80", "0.000"], ["21046.00", "0.000"], ["21142.00", "0.108"], ["21142.10", "0.000"], ["21143.80", "0.000"], ["21146.00", "0.000"], ["56994.00", "0.004"], ["69817.20", "0.018"], ["70184.10", "0.713"], ["70529.60", "1.425"], ["71087.40", "0.212"], ["71091.10", "0.814"], ["71099.60", "0.000"], ["71171.70", "0.185"], ["71172.50", "0.616"], ["71185.00", "0.356"], ["71186.30", "0.233"], ["71187.50", "0.456"], ["71188.80", "0.971"], ["71190.00", "0.236"], ["71191.20", "0.000"], ["71191.30", "0.637"], ["71192.10", "0.283"], ["71192.50", "0.029"], ["71193.10", "0.045"], ["71193.80", "0.078"], ["71194.10", "0.051"], ["71195.00", "0.053"], ["71195.10", "0.045"], ["71196.00", "1.110"], ["71196.20", "0.557"], ["71196.40", "0.033"], ["71197.00", "0.092"], ["71197.50", "0.036"], ["71197.70", "0.035"], ["71198.00", "0.046"], ["71198.70", "0.000"], ["71198.90", "0.001"], ["71199.00", "0.042"], ["71199.90", "0.053"], ["71200.00", "3.163"], ["71200.10", "0.860"], ["71200.90", "0.000"], ["71201.20", "0.045"], ["71201.80", "0.000"], ["71202.50", "0.044"], ["71204.90", "0.031"], ["71206.20", "0.343"], ["71207.40", "0.038"], ["71208.40", "1.908"], ["71208.70", "0.002"], ["71209.30", "0.384"], ["71210.00", "0.010"], ["71210.30", "0.212"], ["71211.30", "0.005"], ["71212.00", "0.867"], ["71212.30", "0.002"], ["71212.80", "0.000"], ["71213.20", "0.038"], ["71213.30", "0.288"], ["71214.00", "0.082"], ["71214.40", "0.003"], ["71215.40", "0.047"], ["71215.50", "0.262"], ["71216.00", "0.004"], ["71216.60", "0.372"], ["71216.80", "0.017"], ["71218.00", "0.012"], ["71218.10", "0.018"], ["71218.20", "0.002"], ["71219.30", "0.015"], ["71219.70", "1.699"], ["71220.60", "0.029"], ["71221.30", "0.743"], ["71224.40", "0.020"], ["71225.70", "0.015"], ["71226.00", "0.008"], ["71226.60", "0.188"], ["71227.00", "0.035"], ["71227.10", "0.019"], ["71227.20", "0.003"], ["71228.50", "0.005"], ["71230.00", "0.007"], ["71231.00", "0.004"], ["71231.40", "0.106"], ["71231.60", "0.026"], ["71231.80", "0.847"], ["71232.70", "0.001"], ["71234.80", "0.001"], ["71234.90", "0.000"], ["71242.00", "7.342"]], "a": [["71242.10", "12.792"], ["71247.90", "0.005"], ["71249.10", "0.118"], ["71249.20", "0.003"], ["71253.00", "0.008"], ["71253.90", "0.004"], ["71255.90", "0.082"], ["71256.30", "0.033"], ["71257.00", "0.853"], ["71260.00", "0.012"], ["71260.80", "0.052"], ["71261.70", "0.070"], ["71262.20", "0.002"], ["71262.70", "0.070"], ["71263.90", "0.252"], ["71264.40", "0.601"], ["71264.50", "0.209"], ["71265.30", "0.505"], ["71265.60", "0.010"], ["71266.20", "0.528"], ["71271.20", "0.141"], ["71294.70", "0.002"], ["71295.50", "0.031"], ["71389.10", "0.391"], ["71395.80", "1.775"], ["71954.50", "0.002"], ["74830.80", "0.002"], ["74836.10", "0.002"]]}}
{"local_ts": 1773384732795, "server_ts": 1773384732578, "data": {"e": "depthUpdate", "E": 1773384732579, "T": 1773384732578, "s": "BTCUSDT", "U": 10101357144827, "u": 10101357150544, "pu": 10101357144811, "b": [["1000.00", "27.642"], ["5000.00", "101.398"], ["20735.90", "0.315"], ["20742.00", "0.576"], ["20835.90", "0.009"], ["20842.00", "0.000"], ["20935.90", "0.621"], ["20942.00", "0.918"], ["21042.00", "0.243"], ["21135.90", "0.009"], ["56994.00", "0.000"], ["67663.50", "0.000"], ["67664.80", "0.042"], ["69493.80", "0.618"], ["70452.30", "0.070"], ["70523.50", "0.000"], ["70890.80", "0.006"], ["70900.00", "25.590"], ["71086.50", "0.038"], ["71098.50", "0.093"], ["71105.00", "0.177"], ["71113.60", "0.061"], ["71171.60", "0.000"], ["71172.20", "0.021"], ["71184.10", "0.300"], ["71187.50", "0.427"], ["71187.60", "0.007"], ["71190.50", "0.020"], ["71194.70", "0.844"], ["71198.00", "0.002"], ["71200.30", "0.100"], ["71201.00", "0.055"], ["71201.10", "0.053"], ["71204.20", "0.506"], ["71204.90", "0.029"], ["71206.60", "0.067"], ["71207.00", "0.466"], ["71208.60", "0.005"], ["71210.60", "1.793"], ["71211.00", "0.527"], ["71211.20", "0.070"], ["71213.00", "0.311"], ["71213.30", "0.284"], ["71213.80", "0.008"], ["71214.60", "0.003"], ["71215.50", "0.000"], ["71217.60", "0.016"], ["71219.90", "0.236"], ["71221.30", "1.987"], ["71221.40", "1.278"], ["71221.70", "0.551"], ["71222.40", "0.186"], ["71222.80", "0.123"], ["71222.90", "0.005"], ["71223.00", "0.576"], ["71223.10", "0.061"], ["71224.10", "0.091"], ["71224.60", "0.046"], ["71225.40", "0.202"], ["71225.70", "0.004"], ["71225.80", "0.043"], ["71226.00", "0.007"], ["71226.20", "0.000"], ["71227.00", "0.371"], ["71227.40", "0.509"], ["71227.80", "0.004"], ["71230.10", "0.511"], ["71231.20", "0.796"], ["71231.30", "1.049"], ["71232.30", "0.011"], ["71232.70", "0.399"]], "a": [["71236.10", "0.052"], ["71240.40", "0.002"], ["71241.70", "0.000"], ["71242.40", "0.002"], ["71244.00", "0.004"], ["71245.30", "0.071"], ["71245.90", "0.774"], ["71250.30", "0.014"], ["71250.80", "0.046"], ["71251.80", "0.004"], ["71253.10", "0.015"], ["71254.40", "0.027"], ["71254.80", "0.452"], ["71255.40", "0.381"], ["71255.60", "0.015"], ["71255.70", "0.002"], ["71256.10", "0.023"], ["71256.40", "0.400"], ["71256.50", "0.042"], ["71256.90", "0.335"], ["71258.10", "0.017"], ["71258.20", "0.000"], ["71259.00", "0.070"], ["71259.40", "0.018"], ["71260.60", "0.016"], ["71260.70", "0.077"], ["71261.90", "0.024"], ["71262.70", "0.000"], ["71264.30", "0.003"], ["71265.80", "0.070"], ["71266.00", "0.009"], ["71266.70", "1.050"], ["71267.10", "0.004"], ["71267.60", "0.000"], ["71267.70", "0.000"], ["71268.00", "0.040"], ["71268.10", "0.003"], ["71268.20", "0.371"], ["71268.30", "0.048"], ["71268.50", "0.002"], ["71269.20", "0.449"], ["71269.60", "0.061"], ["71269.80", "0.198"], ["71270.10", "0.000"], ["71270.30", "0.000"], ["71270.50", "0.045"], ["71270.80", "0.000"], ["71271.50", "0.047"], ["71271.60", "0.876"], ["71272.10", "0.004"], ["71272.50", "0.894"], ["71273.50", "0.070"], ["71275.60", "1.614"], ["71276.80", "0.038"], ["71277.00", "0.043"], ["71278.30", "0.029"], ["71279.50", "0.029"], ["71280.80", "0.762"], ["71282.00", "0.203"], ["71285.10", "0.002"], ["71285.30", "0.004"], ["71288.40", "0.002"], ["71289.70", "0.002"], ["71295.90", "0.002"], ["71317.90", "0.834"], ["71318.40", "0.007"], ["71326.20", "0.734"], ["71328.40", "0.002"], ["71354.00", "0.040"], ["71488.80", "0.116"], ["71948.40", "0.007"], ["72250.20", "0.000"], ["72539.20", "0.000"], ["72663.70", "0.589"], ["74195.10", "0.002"], ["75000.00", "261.100"]]}}
{"local_ts": 1773384733817, "server_ts": 1773384733600, "data": {"e": "depthUpdate", "E": 1773384733601, "T": 1773384733600, "s": "BTCUSDT", "U": 10101357198463, "u": 10101357202205, "pu": 10101357198284, "b": [["1000.00", "27.792"], ["5000.00", "101.418"], ["20735.90", "0.126"], ["20835.90", "1.305"], ["20935.90", "0.495"], ["21135.90", "0.774"], ["33000.00", "9.339"], ["56994.00", "0.000"], ["67641.20", "0.000"], ["67661.00", "0.010"], ["70523.50", "0.000"], ["71061.20", "0.018"], ["71184.30", "0.155"], ["71200.30", "0.108"], ["71228.90", "0.006"]], "a": [["71236.00", "2.215"], ["71240.70", "0.003"], ["71241.10", "0.007"], ["71243.20", "0.003"], ["71246.50", "0.012"], ["71249.00", "0.000"], ["71250.60", "0.002"], ["71254.80", "0.581"], ["71260.30", "0.032"], ["71261.50", "0.035"], ["71261.90", "0.044"], ["71262.00", "0.455"], ["71262.20", "0.247"], ["71262.80", "0.044"], ["71263.00", "0.000"], ["71263.70", "0.002"], ["71263.80", "0.549"], ["71264.00", "0.526"], ["71264.80", "0.073"], ["71265.00", "0.070"], ["71265.70", "0.253"], ["71265.90", "0.000"], ["71266.90", "0.032"], ["71267.60", "0.000"], ["71267.80", "0.128"], ["71271.60", "0.899"], ["71272.80", "0.092"], ["71285.20", "0.102"], ["71285.70", "0.020"], ["71428.30", "0.000"], ["71462.40", "0.006"], ["71462.60", "0.002"], ["71627.70", "0.054"], ["71651.30", "0.000"], ["71651.60", "0.000"], ["71948.30", "0.000"], ["71948.40", "0.007"], ["72289.40", "0.681"]]}}
{"local_ts": 1773384734837, "server_ts": 1773384734620, "data": {"e": "depthUpdate", "E": 1773384734623, "T": 1773384734620, "s": "BTCUSDT", "U": 10101357242891, "u": 10101357247483, "pu": 10101357242819, "b": [["1000.00", "27.642"], ["5000.00", "101.418"], ["20735.90", "1.035"], ["20835.90", "0.765"], ["21035.90", "0.639"], ["21135.90", "0.261"], ["56989.00", "0.000"], ["67643.00", "0.000"], ["67647.80", "0.007"], ["67674.00", "0.002"], ["70523.50", "0.000"], ["71157.50", "0.000"], ["71167.00", "0.004"], ["71168.00", "1.235"], ["71168.10", "0.637"], ["71171.80", "0.284"], ["71173.00", "0.036"], ["71178.90", "0.004"], ["71183.60", "0.013"], ["71190.00", "0.209"], ["71190.10", "0.067"], ["71191.60", "0.002"], ["71200.30", "0.102"], ["71221.70", "1.036"], ["71221.80", "0.185"], ["71222.90", "0.003"], ["71224.40", "0.043"], ["71228.80", "0.039"], ["71232.30", "0.110"], ["71235.90", "3.700"]], "a": [["71236.00", "2.244"], ["71240.60", "0.001"], ["71241.00", "0.003"], ["71241.10", "0.007"], ["71241.90", "0.006"], ["71242.20", "0.005"], ["71243.10", "0.001"], ["71243.70", "0.022"], ["71244.40", "0.015"], ["71244.90", "0.009"], ["71246.00", "1.120"], ["71246.40", "0.000"], ["71247.70", "0.000"], ["71248.50", "0.005"], ["71248.70", "0.000"], ["71249.00", "0.000"], ["71249.70", "0.611"], ["71250.00", "0.012"], ["71250.30", "0.014"], ["71250.60", "0.002"], ["71251.20", "0.000"], ["71251.50", "0.415"], ["71251.60", "0.002"], ["71251.70", "0.046"], ["71252.60", "0.002"], ["71253.50", "0.007"], ["71254.50", "0.000"], ["71255.50", "0.235"], ["71258.10", "0.031"], ["71259.40", "0.032"], ["71259.60", "0.002"], ["71260.60", "0.030"], ["71261.90", "0.031"], ["71262.20", "0.002"], ["71262.80", "0.044"], ["71263.70", "0.289"], ["71264.70", "0.048"], ["71265.70", "0.253"], ["71266.60", "0.045"], ["71267.50", "0.000"], ["71268.50", "0.002"], ["71269.40", "0.007"], ["71270.40", "0.000"], ["71271.40", "0.000"], ["71271.60", "1.105"], ["71284.80", "0.051"], ["71285.30", "0.002"], ["71300.10", "0.317"], ["71304.20", "3.644"], ["71305.90", "0.067"], ["71314.40", "0.146"], ["71424.80", "0.062"], ["71495.60", "0.003"], ["71948.30", "0.006"], ["71948.40", "0.007"]]}}
{"local_ts": 1773384735857, "server_ts": 1773384735642, "data": {"e": "depthUpdate", "E": 1773384735643, "T": 1773384735642, "s": "BTCUSDT", "U": 10101357325598, "u": 10101357332497, "pu": 10101357325539, "b": [["5000.00", "101.418"], ["20735.90", "1.035"], ["20935.90", "0.504"], ["21035.90", "0.396"], ["21135.90", "0.765"], ["33000.00", "9.343"], ["67648.30", "0.002"], ["70093.70", "1.003"], ["70131.70", "4.427"], ["70203.00", "5.696"], ["70236.30", "6.681"], ["70255.10", "0.710"], ["70523.50", "0.000"], ["70879.70", "0.000"], ["70912.70", "0.000"], ["70914.00", "0.020"], ["71190.10", "0.067"], ["71190.20", "1.052"], ["71200.30", "0.123"], ["71230.20", "0.060"], ["71230.30", "0.004"], ["71232.50", "0.005"]], "a": [["71240.30", "0.002"], ["71256.60", "0.004"], ["71258.30", "0.083"], ["71259.70", "0.000"], ["71265.70", "0.220"], ["71266.40", "0.853"], ["71267.10", "0.033"], ["71267.50", "0.000"], ["71267.90", "0.506"], ["71268.30", "0.008"], ["71268.80", "0.003"], ["71271.20", "0.170"], ["71271.60", "0.998"], ["71271.80", "0.049"], ["71272.70", "0.042"], ["71273.70", "0.047"], ["71274.70", "0.080"], ["71275.60", "1.656"], ["71284.10", "0.062"], ["71284.30", "0.106"], ["71289.90", "0.002"], ["71462.90", "5.365"], ["71463.20", "0.017"], ["71948.40", "0.007"], ["72268.90", "6.769"], ["74822.20", "0.005"]]}}
{"local_ts": 1773384736878, "server_ts": 1773384736664, "data": {"e": "depthUpdate", "E": 1773384736665, "T": 1773384736664, "s": "BTCUSDT", "U": 10101357390425, "u": 10101357394765, "pu": 10101357390287, "b": [["1000.00", "27.642"], ["5000.00", "101.418"], ["20837.70", "0.369"], ["20935.90", "0.531"], ["21037.70", "0.504"], ["21135.90", "0.999"], ["21137.70", "0.297"], ["67651.70", "0.002"], ["68388.20", "0.004"], ["69902.80", "0.005"], ["70525.30", "0.003"], ["70914.00", "0.018"], ["70918.20", "0.007"], ["71137.20", "0.156"], ["71176.90", "1.294"], ["71191.60", "0.002"], ["71191.70", "0.287"], ["71209.20", "0.213"], ["71223.40", "0.143"], ["71230.60", "0.136"], ["71230.70", "0.005"], ["71231.30", "1.070"]], "a": [["71237.80", "1.058"], ["71238.30", "0.070"], ["71240.40", "0.002"], ["71241.40", "0.002"], ["71242.40", "0.002"], ["71243.30", "0.003"], ["71244.30", "0.042"], ["71245.00", "0.036"], ["71245.30", "0.113"], ["71245.50", "0.004"], ["71245.60", "0.000"], ["71246.30", "0.044"], ["71246.60", "0.009"], ["71247.20", "0.043"], ["71247.60", "0.045"], ["71248.20", "0.046"], ["71248.50", "0.086"], ["71249.50", "0.653"], ["71254.60", "0.162"], ["71255.40", "0.478"], ["71257.60", "0.634"], ["71259.40", "0.003"], ["71287.30", "0.006"], ["71287.90", "0.028"], ["71950.20", "0.000"], ["72270.70", "0.829"], ["74818.60", "0.002"]]}}
{"local_ts": 1773384737906, "server_ts": 1773384737682, "data": {"e": "depthUpdate", "E": 1773384737685, "T": 1773384737682, "s": "BTCUSDT", "U": 10101357458619, "u": 10101357462775, "pu": 10101357458548, "b": [["5000.00", "101.418"], ["20746.10", "0.239"], ["20846.10", "0.063"], ["20946.10", "0.234"], ["21046.10", "0.594"], ["21135.90", "0.009"], ["33000.00", "9.343"], ["67660.70", "0.002"], ["67679.00", "0.029"], ["69921.30", "1.239"], ["70533.60", "0.004"], ["70881.50", "0.044"], ["70918.20", "0.005"], ["70925.70", "0.002"], ["71183.70", "0.285"], ["71209.30", "0.304"], ["71209.40", "8.769"], ["71228.00", "0.088"], ["71229.60", "0.006"], ["71234.50", "0.006"], ["71236.00", "0.346"], ["71238.90", "0.004"], ["71246.10", "2.657"]], "a": [["71253.20", "0.071"], ["71255.20", "0.374"], ["71255.40", "0.045"], ["71271.70", "0.106"], ["71271.80", "0.133"], ["71282.90", "0.128"], ["71283.20", "0.007"], ["71292.20", "0.021"], ["71292.40", "0.000"], ["71427.70", "0.000"], ["71923.00", "0.615"], ["71958.70", "0.699"], ["72236.50", "1.520"]]}}
{"local_ts": 1773384738922, "server_ts": 1773384738706, "data": {"e": "depthUpdate", "E": 1773384738707, "T": 1773384738706, "s": "BTCUSDT", "U": 10101357513326, "u": 10101357518961, "pu": 10101357513300, "b": [["1000.00", "27.642"], ["5000.00", "101.418"], ["20746.10", "0.806"], ["20846.10", "0.108"], ["20946.10", "1.548"], ["21037.70", "0.144"], ["21146.10", "0.099"], ["67649.50", "0.004"], ["67663.60", "0.000"], ["67674.10", "0.002"], ["67674.20", "0.006"], ["69097.50", "3.477"], ["69825.00", "0.877"], ["70533.60", "0.004"], ["70923.70", "0.002"], ["70925.70", "0.000"], ["70996.40", "0.000"], ["71117.90", "4.346"], ["71134.60", "2.586"], ["71167.70", "0.028"], ["71182.00", "0.152"], ["71183.80", "0.117"], ["71210.50", "0.002"], ["71226.50", "0.141"], ["71226.70", "0.010"], ["71231.20", "0.113"], ["71239.00", "0.063"]], "a": [["71246.20", "5.845"], ["71247.20", "0.045"], ["71248.50", "0.007"], ["71248.90", "0.000"], ["71251.40", "0.080"], ["71253.30", "0.036"], ["71260.80", "0.357"], ["71264.80", "0.242"], ["71272.40", "0.222"], ["71273.30", "0.000"], ["71273.40", "0.311"], ["71281.80", "0.042"], ["71283.70", "0.066"], ["71284.50", "0.019"], ["71291.80", "0.335"], ["71291.90", "1.072"], ["71310.30", "0.005"], ["71324.60", "0.004"], ["71923.00", "1.239"], ["71958.70", "1.393"], ["73037.70", "2.460"], ["89523.20", "0.000"]]}}
{"local_ts": 1773384739948, "server_ts": 1773384739732, "data": {"e": "depthUpdate", "E": 1773384739733, "T": 1773384739732, "s": "BTCUSDT", "U": 10101357573075, "u": 10101357580281, "pu": 10101357572961, "b": [["1000.00", "27.642"], ["5000.00", "101.418"], ["20746.10", "0.032"], ["20846.10", "1.503"], ["20946.10", "0.297"], ["21146.10", "0.873"], ["65000.00", "58.215"], ["67000.00", "36.326"], ["67501.10", "0.002"], ["67674.60", "0.000"], ["69811.20", "0.000"], ["70452.30", "0.000"], ["70533.60", "0.004"], ["70923.70", "0.000"], ["70924.90", "0.014"], ["71036.20", "0.090"], ["71059.70", "0.004"], ["71097.00", "0.088"], ["71138.50", "0.142"], ["71155.00", "0.115"], ["71161.20", "0.002"], ["71169.70", "0.290"], ["71189.10", "0.101"], ["71198.10", "0.003"], ["71198.90", "0.003"], ["71224.60", "0.506"], ["71226.00", "0.661"], ["71226.20", "0.161"], ["71227.20", "0.052"], ["71228.60", "0.167"], ["71228.70", "0.003"], ["71229.10", "0.008"], ["71229.80", "0.042"], ["71231.20", "0.253"], ["71231.90", "0.346"], ["71232.70", "0.574"], ["71236.10", "0.244"], ["71236.70", "0.004"], ["71237.70", "0.111"], ["71237.80", "1.057"], ["71238.40", "0.028"], ["71239.10", "0.000"], ["71239.20", "0.332"], ["71244.40", "0.006"], ["71246.10", "2.567"]], "a": [["71249.90", "0.000"], ["71250.50", "0.009"], ["71251.20", "0.007"], ["71258.40", "0.316"], ["71258.60", "0.003"], ["71259.60", "0.144"], ["71261.70", "0.048"], ["71262.80", "0.633"], ["71264.40", "0.531"], ["71264.90", "0.008"], ["71265.30", "0.000"], ["71268.30", "0.008"], ["71269.10", "0.007"], ["71269.20", "0.681"], ["71269.80", "0.207"], ["71269.90", "0.015"], ["71271.10", "0.230"], ["71272.70", "0.296"], ["71273.20", "0.042"], ["71274.20", "0.198"], ["71274.30", "0.002"], ["71274.40", "0.131"], ["71284.10", "1.004"], ["71290.90", "0.021"], ["71291.10", "0.012"], ["71293.20", "0.002"], ["71293.50", "0.330"], ["71293.80", "0.004"], ["71303.90", "0.000"], ["71306.00", "0.002"], ["71313.00", "0.017"], ["71321.00", "0.579"], ["71366.60", "2.092"], ["71435.00", "0.248"], ["71445.70", "0.207"], ["71834.90", "0.042"], ["71958.70", "1.393"], ["74096.00", "0.074"], ["74827.10", "0.005"], ["89523.20", "0.000"]]}}
{"local_ts": 1773384740969, "server_ts": 1773384740752, "data": {"e": "depthUpdate", "E": 1773384740755, "T": 1773384740752, "s": "BTCUSDT", "U": 10101357623420, "u": 10101357626851, "pu": 10101357623354, "b": [["5000.00", "101.418"], ["20746.10", "1.238"], ["20846.10", "0.567"], ["21046.10", "0.738"], ["21146.10", "0.162"], ["67674.20", "0.004"], ["67681.20", "0.000"], ["70533.60", "0.004"], ["70615.50", "0.002"], ["70889.90", "0.037"], ["70936.10", "0.174"], ["70962.00", "0.000"], ["70996.30", "0.004"], ["71119.00", "0.002"], ["71156.80", "0.057"], ["71158.00", "0.395"], ["71180.80", "0.192"], ["71198.80", "0.010"], ["71199.20", "0.001"], ["71213.70", "0.042"], ["71213.80", "0.002"], ["71215.10", "0.003"], ["71216.00", "0.004"], ["71216.30", "0.000"], ["71217.00", "0.042"], ["71217.80", "0.089"], ["71219.10", "0.012"], ["71220.30", "0.005"], ["71220.40", "0.212"], ["71221.60", "0.168"], ["71222.90", "0.032"], ["71224.10", "0.151"], ["71225.10", "0.006"], ["71226.30", "0.081"], ["71227.10", "0.018"], ["71228.10", "0.036"], ["71228.60", "0.167"], ["71229.00", "0.002"], ["71229.10", "0.006"], ["71229.60", "0.064"], ["71229.90", "0.028"], ["71230.00", "0.381"], ["71230.20", "0.506"], ["71231.20", "0.000"], ["71231.50", "0.031"], ["71232.90", "0.535"], ["71233.00", "0.006"], ["71233.80", "0.198"], ["71234.70", "0.032"], ["71234.90", "0.000"], ["71235.50", "0.075"], ["71236.90", "0.001"], ["71237.10", "0.038"], ["71238.30", "0.016"], ["71238.50", "0.002"], ["71238.60", "0.000"], ["71238.70", "0.001"], ["71239.00", "0.116"], ["71239.70", "0.032"], ["71240.00", "0.016"], ["71241.10", "0.036"], ["71246.10", "2.498"]], "a": [["71250.20", "0.002"], ["71253.30", "0.036"], ["71260.80", "0.054"], ["71270.90", "0.085"], ["71275.60", "1.616"], ["71291.90", "1.072"], ["71292.00", "0.005"], ["71293.80", "0.004"], ["71293.90", "0.003"], ["71431.40", "0.100"], ["71513.40", "0.002"], ["71834.00", "0.013"], ["71958.70", "1.809"], ["74834.30", "0.002"], ["89523.20", "0.000"]]}}
{"local_ts": 1773384741993, "server_ts": 1773384741773, "data": {"e": "depthUpdate", "E": 1773384741775, "T": 1773384741773, "s": "BTCUSDT", "U": 10101357667231, "u": 10101357672261, "pu": 10101357667183, "b": [["1000.00", "27.642"], ["5000.00", "101.418"], ["20746.10", "0.842"], ["20946.10", "0.603"], ["21046.10", "0.297"], ["21146.10", "0.963"], ["67683.00", "0.096"], ["67683.80", "0.004"], ["68396.30", "0.010"], ["69822.10", "0.379"], ["69843.10", "0.000"], ["69901.20", "0.376"], ["69918.60", "0.000"], ["69922.30", "0.714"], ["69980.40", "0.376"], ["70001.50", "0.000"], ["70059.60", "0.380"], ["70080.70", "0.000"], ["70138.70", "0.376"], ["70159.90", "0.014"], ["70217.90", "0.376"], ["70239.10", "0.000"], ["70297.00", "1.229"], ["70318.30", "0.000"], ["70376.20", "0.943"], ["70397.40", "0.962"], ["70455.40", "0.376"], ["70476.60", "0.000"], ["70533.60", "0.004"], ["70534.50", "2.723"], ["70555.80", "0.000"], ["71118.10", "0.002"], ["71156.80", "0.097"], ["71198.00", "0.004"], ["71198.10", "0.003"], ["71209.90", "0.111"], ["71228.80", "0.005"], ["71233.50", "0.000"], ["71238.80", "0.003"], ["71244.80", "0.004"], ["71245.40", "0.002"], ["71245.50", "0.000"]], "a": [["71248.50", "0.042"], ["71249.40", "0.046"], ["71250.10", "0.001"], ["71250.40", "0.043"], ["71251.10", "0.000"], ["71251.40", "0.050"], ["71252.10", "0.058"], ["71252.30", "0.046"], ["71253.00", "0.004"], ["71254.00", "0.039"], ["71258.40", "0.254"], ["71260.80", "0.143"], ["71260.90", "0.638"], ["71261.60", "0.002"], ["71262.80", "0.002"], ["71271.10", "0.275"], ["71272.40", "0.166"], ["71272.60", "0.132"], ["71272.70", "0.298"], ["71272.80", "0.141"], ["71291.90", "1.072"], ["71292.20", "0.000"], ["71293.10", "0.003"], ["71293.20", "0.004"], ["71431.40", "0.199"], ["71473.50", "0.002"], ["71958.60", "0.016"], ["71958.70", "1.809"], ["71981.20", "0.060"], ["72060.40", "0.000"], ["72139.60", "0.000"], ["72218.70", "0.000"], ["72297.90", "0.405"], ["72377.10", "0.000"], ["72386.10", "0.689"], ["72456.30", "0.013"], ["72535.50", "0.004"], ["72614.70", "0.000"], ["72693.90", "0.049"], ["74096.00", "0.078"], ["74816.00", "0.054"], ["89523.20", "0.000"]]}}
{"local_ts": 1773384743012, "server_ts": 1773384742795, "data": {"e": "depthUpdate", "E": 1773384742797, "T": 1773384742795, "s": "BTCUSDT", "U": 10101357710321, "u": 10101357715494, "pu": 10101357710224, "b": [["5000.00", "101.418"], ["20846.10", "0.468"], ["20946.10", "0.432"], ["21046.10", "0.693"], ["21146.10", "1.107"], ["33000.00", "9.339"], ["69455.60", "2.608"], ["70021.60", "0.000"], ["70533.60", "0.004"], ["70889.90", "0.037"], ["71167.70", "0.028"], ["71182.00", "0.053"], ["71204.40", "0.048"], ["71210.50", "0.198"], ["71220.70", "0.032"], ["71221.90", "0.135"], ["71222.80", "0.044"], ["71223.20", "0.031"], ["71223.70", "0.383"], ["71224.70", "0.255"], ["71225.70", "0.673"], ["71230.90", "0.045"], ["71231.00", "0.285"], ["71231.40", "0.059"], ["71231.50", "0.002"], ["71231.90", "0.111"], ["71232.90", "0.506"], ["71234.30", "0.001"], ["71234.40", "0.003"], ["71235.40", "0.006"], ["71235.60", "0.131"], ["71235.80", "0.041"], ["71236.90", "0.001"], ["71240.60", "0.015"], ["71243.20", "0.000"], ["71243.60", "0.015"], ["71244.60", "0.000"], ["71244.70", "0.001"], ["71245.20", "0.002"], ["71245.30", "0.002"], ["71246.10", "2.423"]], "a": [["71246.50", "0.000"], ["71247.80", "0.000"], ["71248.80", "0.002"], ["71249.10", "0.001"], ["71250.10", "0.043"], ["71250.30", "0.015"], ["71251.40", "0.015"], ["71251.50", "0.652"], ["71251.60", "0.251"], ["71251.90", "0.000"], ["71252.80", "0.124"], ["71254.10", "0.027"], ["71255.00", "0.058"], ["71255.10", "0.007"], ["71255.30", "0.048"], ["71256.30", "0.001"], ["71256.60", "0.019"], ["71257.40", "0.037"], ["71257.50", "0.006"], ["71257.80", "0.314"], ["71258.80", "0.002"], ["71259.10", "0.016"], ["71260.00", "0.008"], ["71261.30", "0.030"], ["71262.50", "0.035"], ["71263.80", "0.002"], ["71264.20", "0.034"], ["71264.30", "0.039"], ["71265.20", "0.004"], ["71265.30", "0.000"], ["71281.80", "0.070"], ["71290.90", "0.021"], ["71291.10", "0.019"], ["71310.30", "0.005"], ["71324.60", "0.004"], ["71435.00", "0.188"], ["71958.70", "1.809"], ["72542.90", "0.551"], ["72671.10", "0.012"], ["72988.80", "0.611"], ["74834.30", "0.000"], ["89523.20", "0.000"]]}}
{"local_ts": 1773384744034, "server_ts": 1773384743820, "data": {"e": "depthUpdate", "E": 1773384743821, "T": 1773384743820, "s": "BTCUSDT", "U": 10101357750764, "u": 10101357754462, "pu": 10101357750707, "b": [["1000.00", "27.642"], ["5000.00", "101.438"], ["20746.10", "0.347"], ["20846.10", "0.558"], ["20946.10", "0.432"], ["21046.10", "1.368"], ["56997.00", "0.000"], ["70533.60", "1.420"], ["70533.70", "0.000"], ["70837.20", "0.000"], ["70996.50", "0.288"], ["70996.70", "0.004"], ["71091.70", "12.897"], ["71151.80", "6.657"], ["71178.90", "0.186"], ["71187.80", "3.820"], ["71198.00", "0.002"], ["71198.10", "0.005"], ["71209.50", "2.569"], ["71232.80", "0.102"], ["71239.00", "0.064"], ["71240.30", "0.031"], ["71240.90", "0.003"], ["71241.30", "0.000"], ["71242.40", "0.000"], ["71243.50", "0.000"], ["71243.80", "0.002"], ["71243.90", "0.000"], ["71244.00", "0.001"], ["71244.10", "0.000"], ["71244.40", "0.006"], ["71244.50", "0.002"], ["71244.60", "0.000"], ["71245.10", "0.001"]], "a": [["71246.20", "4.755"], ["71247.70", "0.047"], ["71249.00", "0.016"], ["71249.10", "0.001"], ["71250.20", "0.017"], ["71250.40", "0.001"], ["71251.50", "0.020"], ["71251.70", "0.147"], ["71252.70", "0.015"], ["71252.90", "0.038"], ["71253.30", "0.038"], ["71254.00", "0.039"], ["71254.20", "0.000"], ["71255.30", "0.019"], ["71255.40", "0.009"], ["71256.50", "0.081"], ["71256.70", "0.037"], ["71258.00", "0.007"], ["71259.20", "0.033"], ["71263.80", "0.002"], ["71265.90", "0.521"], ["71287.40", "1.808"], ["71290.90", "0.000"], ["71291.20", "0.026"], ["71309.10", "3.405"], ["71320.40", "2.240"], ["71320.70", "0.044"], ["71341.60", "1.507"], ["71344.80", "6.261"], ["71403.90", "11.854"], ["71442.10", "0.270"], ["71445.70", "0.207"], ["71692.40", "0.000"], ["71906.20", "0.004"], ["71958.70", "3.197"], ["74833.70", "0.002"], ["89523.20", "0.000"]]}}
{"local_ts": 1773384745058, "server_ts": 1773384744842, "data": {"e": "depthUpdate", "E": 1773384744843, "T": 1773384744842, "s": "BTCUSDT", "U": 10101357798579, "u": 10101357809477, "pu": 10101357798445, "b": [["1000.00", "27.642"], ["5000.00", "101.418"], ["20746.10", "0.698"], ["20846.10", "0.207"], ["20946.10", "1.548"], ["21046.10", "0.045"], ["21146.10", "0.207"], ["33000.00", "9.343"], ["64121.50", "0.002"], ["67680.30", "0.002"], ["67683.80", "0.008"], ["69892.40", "0.572"], ["70533.60", "1.420"], ["70634.20", "0.005"], ["70640.00", "0.201"], ["70925.50", "0.002"], ["71137.80", "0.275"], ["71140.90", "0.280"], ["71141.30", "0.042"], ["71141.50", "0.025"], ["71141.60", "0.216"], ["71142.00", "0.064"], ["71142.30", "0.025"], ["71142.60", "6.651"], ["71181.80", "0.004"], ["71182.80", "0.901"], ["71183.70", "0.285"], ["71184.70", "0.000"], ["71185.70", "0.005"], ["71186.60", "0.117"], ["71187.60", "0.007"], ["71188.30", "0.004"], ["71188.60", "0.045"], ["71189.50", "0.651"], ["71190.50", "0.006"], ["71191.50", "0.507"], ["71191.60", "0.004"], ["71191.80", "0.044"], ["71192.50", "0.000"], ["71193.00", "0.048"], ["71193.40", "0.004"], ["71194.00", "0.057"], ["71194.40", "0.073"], ["71195.10", "0.056"], ["71195.40", "0.000"], ["71195.50", "0.000"], ["71195.80", "0.022"], ["71196.30", "0.000"], ["71196.60", "0.042"], ["71196.90", "0.510"], ["71197.00", "0.004"], ["71197.30", "0.015"], ["71197.80", "0.328"], ["71197.90", "0.002"], ["71198.20", "0.000"], ["71198.30", "0.209"], ["71199.50", "0.044"], ["71199.80", "0.568"], ["71199.90", "0.044"], ["71200.70", "0.031"], ["71202.00", "1.168"], ["71202.20", "0.005"], ["71203.90", "0.062"], ["71204.50", "0.180"], ["71204.90", "0.046"], ["71205.70", "0.324"], ["71206.40", "0.030"], ["71207.00", "0.036"], ["71207.70", "0.585"], ["71208.20", "0.020"], ["71208.40", "0.031"], ["71209.50", "2.456"], ["71210.00", "0.035"], ["71210.70", "0.144"], ["71210.80", "0.000"], ["71211.30", "0.005"], ["71211.60", "0.037"], ["71212.80", "0.014"], ["71213.70", "0.031"], ["71216.80", "0.031"], ["71217.00", "0.000"], ["71217.40", "0.073"], ["71218.10", "0.003"], ["71218.30", "0.001"], ["71219.50", "0.003"], ["71220.80", "0.028"], ["71222.00", "1.308"], ["71223.10", "0.507"], ["71223.90", "0.001"], ["71227.10", "0.003"], ["71228.10", "0.031"], ["71228.30", "0.169"], ["71228.40", "0.000"], ["71228.60", "0.007"], ["71228.90", "0.006"], ["71229.10", "0.006"], ["71229.20", "0.029"], ["71229.40", "0.017"], ["71229.60", "0.006"], ["71230.10", "0.626"], ["71230.30", "0.036"], ["71230.70", "0.020"], ["71230.80", "0.000"], ["71230.90", "0.003"], ["71231.20", "0.000"], ["71231.40", "0.001"], ["71231.60", "0.230"], ["71231.80", "0.005"], ["71232.00", "0.288"], ["71232.10", "0.000"], ["71232.50", "0.017"], ["71233.70", "0.040"], ["71234.10", "0.018"], ["71235.20", "0.223"], ["71235.80", "0.011"], ["71237.80", "0.008"], ["71238.00", "0.005"], ["71238.20", "1.053"], ["71238.90", "0.007"], ["71239.40", "0.001"], ["71239.80", "0.115"], ["71240.40", "0.002"], ["71242.00", "0.002"], ["71242.30", "0.005"], ["71243.10", "0.076"]], "a": [["71253.90", "0.009"], ["71255.40", "0.002"], ["71256.00", "0.420"], ["71258.40", "0.487"], ["71260.40", "1.054"], ["71260.50", "0.883"], ["71262.20", "0.074"], ["71262.30", "0.016"], ["71263.80", "0.546"], ["71263.90", "0.088"], ["71264.20", "0.004"], ["71265.90", "0.762"], ["71266.10", "0.003"], ["71267.70", "0.507"], ["71269.10", "0.007"], ["71269.70", "0.000"], ["71271.10", "0.215"], ["71272.50", "0.978"], ["71272.80", "0.141"], ["71273.00", "1.565"], ["71283.50", "0.058"], ["71283.80", "0.509"], ["71292.90", "0.005"], ["71293.00", "0.511"], ["71442.10", "0.111"], ["71673.60", "19.046"], ["71958.70", "3.197"], ["73037.80", "2.460"], ["78370.80", "0.002"], ["89523.20", "0.000"]]}}
{"local_ts": 1773384746080, "server_ts": 1773384745862, "data": {"e": "depthUpdate", "E": 1773384745863, "T": 1773384745862, "s": "BTCUSDT", "U": 10101357885684, "u": 10101357890074, "pu": 10101357885643, "b": [["5000.00", "101.418"], ["20745.10", "0.072"], ["20746.10", "0.005"], ["20845.10", "1.377"], ["20846.10", "0.171"], ["20946.10", "0.180"], ["21045.10", "0.072"], ["21145.10", "0.657"], ["21146.10", "0.171"], ["64120.60", "0.002"], ["67666.00", "3.450"], ["67674.20", "0.000"], ["70105.20", "0.000"], ["70141.30", "1.216"], ["70467.40", "0.000"], ["70532.60", "0.000"], ["70625.10", "0.007"], ["70818.60", "0.005"], ["70888.90", "0.000"], ["70930.20", "0.026"], ["71008.50", "4.744"], ["71197.50", "0.036"], ["71197.70", "0.006"], ["71213.00", "0.313"], ["71213.10", "0.005"], ["71213.70", "0.000"], ["71213.80", "0.002"], ["71216.30", "0.070"], ["71217.40", "0.003"], ["71221.10", "0.338"], ["71230.70", "0.005"], ["71231.10", "0.002"], ["71231.50", "0.017"], ["71231.60", "0.566"], ["71232.80", "0.016"], ["71233.00", "0.006"], ["71234.10", "0.007"]], "a": [["71283.20", "0.002"], ["71472.10", "0.000"], ["71472.60", "0.034"], ["71887.30", "0.002"], ["71957.60", "3.014"], ["71957.70", "1.103"], ["74828.80", "0.000"], ["78369.70", "0.002"], ["89523.20", "0.000"]]}}
{"local_ts": 1773384747101, "server_ts": 1773384746885, "data": {"e": "depthUpdate", "E": 1773384746887, "T": 1773384746885, "s": "BTCUSDT", "U": 10101357938063, "u": 10101357941551, "pu": 10101357937988, "b": [["1000.00", "27.642"], ["5000.00", "101.398"], ["20745.10", "1.431"], ["20845.10", "0.369"], ["21045.10", "0.837"], ["21145.10", "0.063"], ["33000.00", "9.343"], ["64120.60", "0.002"], ["67664.20", "0.000"], ["67681.50", "0.003"], ["68146.20", "0.000"], ["70105.00", "0.000"], ["70532.60", "0.000"], ["70995.40", "0.007"], ["71094.10", "0.493"], ["71172.20", "0.024"], ["71197.80", "0.284"], ["71198.00", "0.004"], ["71204.30", "0.030"], ["71204.60", "0.116"], ["71210.40", "0.037"], ["71210.50", "0.142"], ["71211.10", "0.461"], ["71221.90", "0.217"], ["71223.50", "0.365"], ["71234.30", "0.003"], ["71238.40", "0.024"], ["71239.80", "0.004"], ["71243.70", "0.047"], ["71245.00", "0.072"]], "a": [["71245.20", "2.623"], ["71247.20", "0.003"], ["71248.20", "0.000"], ["71249.10", "0.002"], ["71250.10", "0.018"], ["71251.10", "0.007"], ["71252.00", "0.002"], ["71253.00", "0.004"], ["71254.40", "0.005"], ["71255.60", "0.005"], ["71258.30", "0.047"], ["71259.30", "0.043"], ["71260.30", "0.048"], ["71261.20", "0.043"], ["71262.20", "0.044"], ["71263.80", "0.508"], ["71263.90", "0.007"], ["71264.40", "0.546"], ["71264.50", "0.204"], ["71265.20", "0.000"], ["71265.70", "0.227"], ["71266.10", "0.005"], ["71266.80", "0.002"], ["71267.50", "0.001"], ["71268.90", "0.000"], ["71272.40", "0.113"], ["71277.50", "0.688"], ["71278.70", "0.029"], ["71279.90", "0.035"], ["71284.20", "0.071"], ["71285.80", "1.889"], ["71290.70", "0.015"], ["71291.40", "0.021"], ["71292.00", "0.005"], ["71292.10", "0.004"], ["71307.60", "3.668"], ["71320.00", "0.314"], ["71359.90", "0.002"], ["71957.70", "1.103"], ["72456.40", "0.276"], ["72528.60", "0.893"], ["78369.70", "0.002"], ["89523.20", "0.000"]]}}
{"local_ts": 1773384748135, "server_ts": 1773384747910, "data": {"e": "depthUpdate", "E": 1773384747911, "T": 1773384747910, "s": "BTCUSDT", "U": 10101357980863, "u": 10101358028064, "pu": 10101357980805, "b": [["5000.00", "101.418"], ["20745.10", "0.630"], ["20945.10", "0.657"], ["20946.10", "0.045"], ["21045.10", "0.198"], ["21145.10", "1.062"], ["21146.10", "0.090"], ["21147.50", "0.009"], ["21147.60", "0.009"], ["40000.00", "49.305"], ["64120.60", "0.002"], ["68361.00", "0.000"], ["69821.20", "0.037"], ["70197.80", "1.138"], ["70247.50", "0.012"], ["70247.60", "0.002"], ["70259.90", "0.000"], ["70265.00", "0.067"], ["70265.50", "0.004"], ["70411.50", "0.572"], ["70532.60", "0.000"], ["70533.60", "1.420"], ["70535.00", "0.000"], ["70535.10", "0.004"], ["70677.50", "2.231"], ["70883.00", "0.157"], ["70888.90", "0.035"], ["70930.90", "0.002"], ["70936.50", "0.043"], ["70988.20", "0.000"], ["70995.40", "0.007"], ["71008.80", "0.000"], ["71017.00", "0.045"], ["71036.20", "0.090"], ["71039.70", "0.003"], ["71127.80", "0.002"], ["71134.60", "2.500"], ["71134.80", "0.586"], ["71136.30", "0.002"], ["71139.50", "0.002"], ["71140.80", "0.011"], ["71142.00", "0.064"], ["71143.30", "0.039"], ["71144.50", "0.005"], ["71145.80", "0.212"], ["71147.00", "0.009"], ["71148.20", "0.000"], ["71148.80", "0.016"], ["71149.90", "0.305"], ["71151.70", "0.398"], ["71153.90", "0.242"], ["71156.80", "0.095"], ["71158.40", "0.025"], ["71159.00", "0.023"], ["71160.00", "0.008"], ["71160.30", "0.012"], ["71162.70", "1.531"], ["71164.00", "0.029"], ["71166.60", "0.147"], ["71168.20", "0.047"], ["71168.50", "0.000"], ["71170.20", "0.025"], ["71170.40", "0.065"], ["71171.60", "0.016"], ["71171.80", "0.177"], ["71173.70", "0.029"], ["71174.80", "0.000"], ["71175.00", "0.005"], ["71175.10", "0.000"], ["71175.30", "0.512"], ["71175.70", "0.002"], ["71176.50", "0.128"], ["71179.60", "0.002"], ["71179.80", "0.072"], ["71182.00", "0.078"], ["71182.10", "0.068"], ["71182.90", "0.078"], ["71187.70", "0.305"], ["71188.10", "0.000"], ["71189.10", "0.007"], ["71190.30", "0.269"], ["71195.20", "1.207"], ["71196.50", "0.002"], ["71197.20", "0.029"], ["71197.90", "0.000"], ["71198.00", "0.002"], ["71198.10", "0.003"], ["71198.30", "0.211"], ["71199.40", "0.000"], ["71201.00", "0.016"], ["71201.30", "0.005"], ["71202.60", "0.588"], ["71204.40", "0.593"], ["71205.80", "0.001"], ["71207.10", "0.003"], ["71207.60", "0.000"], ["71207.70", "0.584"], ["71208.50", "0.003"], ["71208.80", "0.080"], ["71209.50", "2.569"], ["71210.00", "0.002"], ["71210.60", "1.793"], ["71210.70", "0.148"], ["71211.10", "0.008"], ["71211.30", "0.299"], ["71211.40", "0.032"], ["71211.60", "0.002"], ["71211.70", "0.005"], ["71212.00", "0.850"], ["71212.30", "0.339"], ["71212.40", "0.025"], ["71212.50", "0.115"], ["71213.00", "0.311"], ["71213.10", "0.003"], ["71213.70", "0.002"], ["71213.80", "0.004"], ["71213.90", "0.005"], ["71214.00", "0.435"], ["71214.30", "0.225"], ["71214.80", "0.141"], ["71216.10", "0.060"], ["71216.40", "0.027"], ["71216.60", "0.317"], ["71217.00", "0.000"], ["71217.60", "0.004"], ["71217.80", "0.017"], ["71218.80", "0.115"], ["71218.90", "0.063"], ["71219.00", "0.000"], ["71219.10", "0.019"], ["71219.20", "0.004"], ["71219.30", "0.000"], ["71219.40", "0.004"], ["71219.70", "0.000"], ["71220.00", "0.054"], ["71220.10", "0.070"], ["71220.40", "0.212"], ["71220.80", "0.093"], ["71221.30", "0.012"], ["71221.40", "0.038"], ["71221.50", "0.469"], ["71221.90", "0.112"], ["71222.00", "1.363"], ["71223.10", "0.247"], ["71223.80", "0.291"], ["71224.10", "0.000"], ["71224.20", "0.000"], ["71224.50", "0.000"], ["71224.70", "0.211"], ["71224.80", "0.000"], ["71225.00", "0.027"], ["71225.40", "0.073"], ["71226.10", "0.227"], ["71226.20", "0.006"], ["71226.30", "0.031"], ["71226.40", "0.010"], ["71226.50", "0.000"], ["71226.80", "0.000"], ["71227.30", "0.002"], ["71227.70", "0.002"], ["71228.30", "0.000"], ["71228.40", "0.000"], ["71228.70", "0.005"], ["71228.80", "0.005"], ["71229.00", "0.002"], ["71229.10", "0.396"], ["71229.20", "0.099"], ["71229.50", "0.025"], ["71229.70", "0.165"], ["71230.20", "0.005"], ["71230.30", "0.101"], ["71230.40", "0.001"], ["71230.80", "0.000"], ["71230.90", "0.003"], ["71231.00", "0.281"], ["71231.20", "0.000"], ["71231.70", "1.195"], ["71231.80", "0.005"], ["71232.20", "0.507"], ["71232.40", "0.007"], ["71232.60", "0.009"], ["71232.70", "0.803"], ["71233.00", "0.218"], ["71233.30", "0.002"], ["71233.50", "0.000"], ["71233.90", "0.027"], ["71234.20", "0.000"], ["71234.60", "0.285"], ["71234.90", "0.052"], ["71235.20", "0.219"], ["71235.30", "0.669"], ["71235.50", "0.103"], ["71235.60", "0.134"], ["71235.80", "0.009"], ["71236.10", "0.347"], ["71236.20", "0.113"], ["71236.40", "0.000"], ["71236.60", "0.044"], ["71236.70", "0.004"], ["71236.80", "0.021"], ["71236.90", "0.001"], ["71237.00", "0.042"], ["71237.30", "0.002"], ["71237.40", "0.055"], ["71237.50", "0.002"], ["71237.60", "0.004"], ["71237.70", "0.072"], ["71237.80", "0.235"], ["71238.00", "0.005"], ["71238.10", "0.534"], ["71238.40", "0.067"], ["71238.50", "0.012"], ["71238.60", "0.000"], ["71238.70", "0.039"], ["71238.80", "0.065"], ["71238.90", "0.058"], ["71239.00", "0.039"], ["71239.10", "0.003"], ["71239.30", "0.072"], ["71239.40", "0.050"], ["71239.50", "0.051"], ["71239.70", "0.728"], ["71239.80", "0.004"], ["71239.90", "0.027"], ["71240.00", "0.080"], ["71240.20", "0.010"], ["71240.30", "0.508"], ["71240.40", "0.048"], ["71240.50", "0.014"], ["71240.60", "0.042"], ["71241.00", "0.004"], ["71241.40", "0.000"], ["71241.50", "0.216"], ["71241.70", "0.338"], ["71241.90", "0.016"], ["71242.10", "0.002"], ["71242.30", "0.005"], ["71242.40", "0.002"], ["71242.50", "0.058"], ["71243.10", "0.131"], ["71243.50", "0.000"], ["71243.70", "0.050"], ["71243.90", "0.004"], ["71244.30", "0.006"], ["71244.40", "0.006"], ["71244.80", "0.004"], ["71244.90", "0.105"], ["71245.00", "0.048"], ["71245.10", "0.049"], ["71245.20", "0.017"], ["71245.30", "0.000"], ["71245.60", "0.210"], ["71245.80", "0.001"], ["71245.90", "0.001"], ["71246.00", "0.075"], ["71246.10", "0.272"], ["71246.20", "3.311"], ["71246.30", "1.049"], ["71246.50", "0.000"], ["71246.60", "0.000"], ["71246.90", "0.000"], ["71247.00", "0.002"], ["71247.10", "0.000"], ["71247.20", "0.815"], ["71247.30", "0.000"], ["71247.40", "0.000"], ["71247.50", "1.016"], ["71247.60", "14.723"], ["71247.70", "0.011"], ["71247.80", "2.874"], ["71247.90", "0.913"], ["71248.00", "12.485"]], "a": [["71245.20", "0.000"], ["71245.30", "0.000"], ["71246.00", "0.000"], ["71246.10", "0.000"], ["71246.20", "0.000"], ["71246.30", "0.000"], ["71246.60", "0.000"], ["71246.70", "0.000"], ["71247.00", "0.000"], ["71247.20", "0.000"], ["71247.30", "0.000"], ["71247.40", "0.000"], ["71247.60", "0.000"], ["71247.70", "0.000"], ["71247.80", "0.000"], ["71247.90", "0.000"], ["71248.00", "0.000"], ["71248.10", "0.002"], ["71249.20", "0.002"], ["71249.50", "0.008"], ["71249.60", "0.007"], ["71249.80", "0.002"], ["71250.10", "0.001"], ["71250.30", "0.000"], ["71251.00", "0.000"], ["71251.30", "0.000"], ["71251.40", "0.005"], ["71251.60", "0.002"], ["71251.70", "0.004"], ["71251.80", "0.009"], ["71252.20", "0.003"], ["71252.30", "0.005"], ["71252.40", "0.002"], ["71252.70", "0.210"], ["71252.80", "0.061"], ["71253.00", "0.013"], ["71253.20", "0.004"], ["71253.30", "0.003"], ["71253.60", "0.142"], ["71253.70", "0.027"], ["71253.80", "0.004"], ["71254.00", "0.004"], ["71254.10", "0.006"], ["71254.20", "0.056"], ["71254.30", "0.008"], ["71254.40", "0.054"], ["71254.60", "0.000"], ["71254.70", "0.009"], ["71254.80", "0.007"], ["71255.00", "0.002"], ["71255.10", "0.067"], ["71255.50", "0.288"], ["71255.60", "0.005"], ["71255.70", "0.002"], ["71256.20", "0.107"], ["71256.30", "0.001"], ["71256.40", "0.000"], ["71256.60", "0.046"], ["71256.80", "0.041"], ["71256.90", "0.354"], ["71257.10", "0.009"], ["71257.20", "0.015"], ["71257.40", "0.071"], ["71257.50", "0.003"], ["71257.70", "0.006"], ["71257.80", "0.299"], ["71258.00", "0.004"], ["71258.10", "0.002"], ["71258.20", "0.000"], ["71258.40", "0.000"], ["71258.60", "0.003"], ["71258.70", "0.007"], ["71258.80", "0.005"], ["71258.90", "0.005"], ["71259.10", "0.001"], ["71259.50", "0.003"], ["71259.60", "0.024"], ["71259.70", "0.001"], ["71259.80", "0.004"], ["71260.10", "0.007"], ["71260.20", "0.002"], ["71260.30", "0.003"], ["71260.50", "0.006"], ["71260.70", "0.009"], ["71260.90", "0.003"], ["71261.00", "0.002"], ["71261.30", "0.001"], ["71261.60", "0.000"], ["71261.70", "0.002"], ["71261.90", "0.647"], ["71262.00", "0.322"], ["71262.20", "0.008"], ["71262.30", "0.002"], ["71262.40", "0.002"], ["71263.00", "0.000"], ["71263.10", "0.002"], ["71263.20", "0.019"], ["71263.30", "0.000"], ["71263.50", "0.008"], ["71263.60", "0.002"], ["71263.80", "0.002"], ["71263.90", "0.147"], ["71264.00", "0.005"], ["71264.20", "0.004"], ["71264.30", "0.011"], ["71264.40", "0.005"], ["71264.50", "0.210"], ["71264.60", "0.008"], ["71264.90", "0.003"], ["71265.20", "0.020"], ["71265.30", "0.020"], ["71265.40", "0.007"], ["71265.60", "0.003"], ["71265.70", "0.215"], ["71265.80", "0.111"], ["71266.00", "0.011"], ["71266.10", "0.010"], ["71266.20", "0.010"], ["71266.30", "0.001"], ["71266.40", "0.004"], ["71266.60", "0.005"], ["71266.70", "0.001"], ["71266.90", "0.003"], ["71267.00", "0.009"], ["71267.10", "0.002"], ["71267.40", "0.005"], ["71267.60", "0.003"], ["71267.70", "0.002"], ["71267.80", "0.342"], ["71267.90", "0.001"], ["71268.10", "0.006"], ["71268.20", "0.004"], ["71268.30", "0.008"], ["71268.40", "0.003"], ["71268.70", "0.000"], ["71269.00", "0.083"], ["71269.10", "0.592"], ["71269.20", "0.566"], ["71269.60", "0.022"], ["71269.70", "0.051"], ["71269.80", "0.198"], ["71270.10", "0.000"], ["71270.20", "0.002"], ["71270.30", "0.002"], ["71270.40", "0.000"], ["71270.50", "0.062"], ["71270.60", "0.006"], ["71270.80", "0.000"], ["71271.00", "0.075"], ["71271.10", "0.000"], ["71271.20", "0.020"], ["71271.30", "0.012"], ["71271.60", "0.263"], ["71271.70", "0.106"], ["71271.90", "0.004"], ["71272.00", "0.104"], ["71272.10", "0.002"], ["71272.40", "0.659"], ["71272.50", "0.852"], ["71272.60", "0.006"], ["71272.70", "0.298"], ["71272.90", "0.004"], ["71273.00", "1.565"], ["71273.10", "0.002"], ["71273.30", "0.000"], ["71273.40", "0.146"], ["71273.50", "0.368"], ["71273.70", "0.005"], ["71273.90", "0.007"], ["71274.00", "0.006"], ["71274.10", "0.002"], ["71274.20", "0.200"], ["71274.40", "0.005"], ["71274.50", "0.010"], ["71274.70", "0.000"], ["71274.80", "0.000"], ["71275.00", "0.173"], ["71275.10", "0.003"], ["71275.20", "0.244"], ["71275.30", "0.764"], ["71275.40", "0.268"], ["71275.60", "1.616"], ["71276.00", "7.719"], ["71276.20", "0.975"], ["71276.70", "0.000"], ["71276.90", "0.004"], ["71277.10", "0.138"], ["71277.40", "0.000"], ["71277.50", "0.659"], ["71278.70", "0.000"], ["71278.80", "0.505"], ["71278.90", "0.026"], ["71279.70", "0.773"], ["71279.80", "1.893"], ["71280.80", "0.444"], ["71282.40", "0.102"], ["71282.70", "0.005"], ["71283.70", "0.066"], ["71284.60", "0.022"], ["71284.90", "0.001"], ["71286.10", "0.033"], ["71287.10", "0.003"], ["71287.20", "0.058"], ["71287.40", "0.041"], ["71288.20", "1.153"], ["71288.60", "0.005"], ["71288.80", "0.053"], ["71289.00", "0.004"], ["71289.10", "0.271"], ["71289.90", "0.007"], ["71290.10", "0.003"], ["71290.30", "0.005"], ["71290.50", "0.015"], ["71291.10", "0.019"], ["71291.40", "0.000"], ["71291.80", "0.335"], ["71292.00", "0.026"], ["71292.10", "0.002"], ["71292.80", "0.056"], ["71292.90", "0.005"], ["71293.40", "0.002"], ["71293.60", "0.065"], ["71293.90", "0.003"], ["71294.40", "0.000"], ["71294.70", "0.000"], ["71294.90", "0.000"], ["71295.10", "0.197"], ["71295.40", "0.014"], ["71295.70", "0.036"], ["71295.90", "0.002"], ["71296.40", "0.578"], ["71296.50", "0.521"], ["71296.60", "0.997"], ["71296.70", "0.032"], ["71296.80", "0.000"], ["71296.90", "0.031"], ["71297.20", "0.002"], ["71297.60", "0.292"], ["71297.70", "0.000"], ["71298.10", "0.000"], ["71298.30", "0.050"], ["71298.40", "0.003"], ["71298.50", "0.010"], ["71298.60", "0.003"], ["71298.80", "0.000"], ["71298.90", "0.005"], ["71299.00", "0.149"], ["71299.20", "0.002"], ["71299.30", "0.000"], ["71299.50", "0.207"], ["71299.60", "0.000"], ["71299.70", "0.000"], ["71300.00", "4.987"], ["71300.20", "0.002"], ["71300.50", "0.042"], ["71300.70", "0.015"], ["71300.90", "0.000"], ["71301.10", "0.000"], ["71302.20", "0.330"], ["71302.30", "0.009"], ["71302.50", "0.015"], ["71302.70", "0.066"], ["71303.40", "0.000"], ["71303.50", "0.010"], ["71304.60", "0.000"], ["71305.10", "0.416"], ["71305.90", "0.067"], ["71306.00", "0.578"], ["71307.00", "0.611"], ["71307.10", "0.142"], ["71307.30", "0.076"], ["71308.00", "0.000"], ["71308.30", "0.006"], ["71308.40", "0.000"], ["71308.90", "0.000"], ["71309.30", "0.145"], ["71309.60", "0.029"], ["71309.90", "0.079"], ["71310.20", "0.009"], ["71310.30", "0.002"], ["71310.90", "0.032"], ["71311.20", "0.810"], ["71311.30", "0.002"], ["71311.90", "0.000"], ["71312.10", "0.029"], ["71312.20", "0.003"], ["71312.70", "0.004"], ["71312.80", "0.001"], ["71313.20", "0.005"], ["71313.40", "0.029"], ["71313.70", "0.044"], ["71313.80", "0.442"], ["71314.20", "0.004"], ["71314.60", "0.606"], ["71314.70", "0.044"], ["71315.20", "0.012"], ["71315.50", "0.369"], ["71315.60", "0.020"], ["71315.70", "0.256"], ["71315.90", "0.093"], ["71316.50", "0.020"], ["71316.60", "0.044"], ["71317.10", "0.029"], ["71318.10", "0.143"], ["71318.30", "0.084"], ["71320.00", "0.371"], ["71320.30", "0.087"], ["71321.00", "0.846"], ["71324.90", "0.000"], ["71325.20", "0.000"], ["71325.90", "0.004"], ["71326.50", "0.007"], ["71329.60", "0.209"], ["71339.40", "0.009"], ["71339.70", "0.025"], ["71342.50", "0.180"], ["71345.00", "0.000"], ["71347.50", "6.723"], ["71348.10", "0.203"], ["71350.00", "2.956"], ["71352.00", "0.133"], ["71353.50", "0.261"], ["71355.50", "0.278"], ["71356.40", "0.010"], ["71356.60", "0.000"], ["71357.70", "0.000"], ["71357.80", "0.000"], ["71358.70", "0.018"], ["71360.40", "0.356"], ["71366.60", "0.791"], ["71367.40", "0.514"], ["71371.80", "0.152"], ["71375.70", "0.279"], ["71399.60", "10.006"], ["71414.00", "1.271"], ["71414.50", "0.002"], ["71423.90", "0.150"], ["71425.50", "0.281"], ["71435.00", "0.248"], ["71436.40", "0.159"], ["71436.60", "0.000"], ["71445.90", "0.000"], ["71446.70", "10.004"], ["71457.70", "0.000"], ["71459.90", "0.321"], ["71462.00", "0.280"], ["71473.90", "0.000"], ["71478.10", "10.000"], ["71486.70", "0.002"], ["71490.40", "0.284"], ["71497.50", "0.561"], ["71524.80", "0.873"], ["71597.90", "0.212"], ["71598.90", "0.212"], ["71957.70", "1.103"], ["71958.70", "3.197"], ["71960.10", "0.035"], ["72077.60", "0.554"], ["72670.10", "0.017"], ["72671.10", "0.006"], ["74815.70", "0.002"], ["78369.70", "0.002"], ["89523.20", "0.000"]]}}
{"local_ts": 1773384749151, "server_ts": 1773384748928, "data": {"e": "depthUpdate", "E": 1773384748931, "T": 1773384748928, "s": "BTCUSDT", "U": 10101358141295, "u": 10101358148745, "pu": 10101358141266, "b": [["1000.00", "27.642"], ["5000.00", "101.398"], ["20849.90", "0.567"], ["20945.10", "0.333"], ["21049.90", "0.900"], ["21145.10", "0.729"], ["21149.90", "0.108"], ["57000.00", "37.772"], ["64124.90", "0.006"], ["67671.70", "0.007"], ["69226.40", "0.011"], ["69460.50", "0.000"], ["70234.40", "5.791"], ["70537.40", "0.000"], ["70930.90", "0.000"], ["70941.00", "0.010"], ["70995.50", "0.000"], ["71000.00", "66.550"], ["71171.50", "2.630"], ["71180.80", "0.008"], ["71185.80", "0.008"], ["71190.30", "1.200"], ["71202.10", "1.357"], ["71202.20", "0.005"], ["71211.10", "0.144"], ["71211.60", "0.002"], ["71211.70", "0.005"], ["71212.30", "0.228"], ["71212.40", "0.018"], ["71216.40", "0.008"], ["71217.20", "0.001"], ["71217.30", "0.011"], ["71217.90", "0.008"], ["71218.00", "0.012"], ["71222.00", "1.290"], ["71234.50", "0.020"], ["71239.90", "0.030"], ["71247.50", "0.076"], ["71248.10", "0.121"], ["71249.70", "0.000"]], "a": [["71250.00", "2.025"], ["71252.10", "0.002"], ["71260.90", "0.045"], ["71270.00", "0.012"], ["71272.40", "0.028"], ["71274.20", "0.200"], ["71274.70", "0.040"], ["71274.80", "0.013"], ["71275.40", "0.280"], ["71275.50", "0.014"], ["71276.10", "0.105"], ["71276.20", "0.975"], ["71276.80", "0.007"], ["71276.90", "0.006"], ["71277.00", "0.014"], ["71278.00", "0.031"], ["71278.80", "0.086"], ["71282.90", "0.008"], ["71283.00", "0.413"], ["71288.60", "0.005"], ["71289.50", "0.004"], ["71290.50", "0.015"], ["71291.50", "0.835"], ["71292.30", "0.003"], ["71292.40", "0.000"], ["71292.50", "0.021"], ["71294.50", "0.110"], ["71295.50", "0.102"], ["71296.50", "0.563"], ["71297.00", "0.043"], ["71297.10", "0.005"], ["71297.20", "0.031"], ["71297.40", "0.488"], ["71298.10", "0.000"], ["71298.40", "0.074"], ["71299.10", "0.000"], ["71300.10", "0.236"], ["71301.00", "0.000"], ["71304.70", "0.002"], ["71305.70", "0.000"], ["71306.70", "0.018"], ["71307.60", "0.157"], ["71308.60", "0.003"], ["71314.10", "0.003"], ["71328.40", "0.005"], ["71597.90", "0.000"], ["71598.90", "0.000"], ["71606.20", "0.212"], ["71962.50", "0.144"], ["72684.30", "1.648"], ["78375.00", "0.018"]]}}
{"local_ts": 1773384750171, "server_ts": 1773384749950, "data": {"e": "depthUpdate", "E": 1773384749951, "T": 1773384749950, "s": "BTCUSDT", "U": 10101358260331, "u": 10101358302559, "pu": 10101358260305, "b": [["1000.00", "27.642"], ["5000.00", "101.418"], ["20760.10", "0.009"], ["20760.20", "0.009"], ["20760.40", "0.009"], ["20761.30", "0.054"], ["20849.90", "0.468"], ["20958.50", "0.009"], ["20959.50", "0.009"], ["20960.20", "0.018"], ["20960.30", "0.018"], ["20960.40", "0.009"], ["20961.30", "0.117"], ["21049.90", "1.170"], ["64130.80", "0.000"], ["67685.00", "0.002"], ["69246.10", "0.000"], ["69820.20", "0.012"], ["69821.20", "0.031"], ["69836.10", "0.003"], ["70212.30", "0.713"], ["70252.90", "0.002"], ["70253.00", "1.545"], ["70253.70", "0.004"], ["70258.60", "5.708"], ["70259.50", "0.002"], ["70260.20", "0.006"], ["70260.40", "0.014"], ["70261.30", "0.004"], ["70288.00", "0.473"], ["70546.00", "0.000"], ["70547.50", "0.000"], ["70547.60", "0.710"], ["70547.70", "0.000"], ["70548.70", "0.000"], ["70551.70", "1.638"], ["70705.20", "0.706"], ["70879.90", "0.000"], ["70882.00", "0.047"], ["70887.10", "0.000"], ["70890.60", "0.000"], ["70913.70", "0.000"], ["70915.10", "0.256"], ["70939.50", "0.213"], ["70941.00", "0.008"], ["70953.70", "0.285"], ["70957.30", "0.645"], ["70970.40", "10.223"], ["70973.70", "1.657"], ["70974.50", "0.000"], ["70976.50", "0.362"], ["70985.50", "1.514"], ["70990.00", "0.030"], ["70998.20", "0.000"], ["71000.90", "0.298"], ["71001.30", "0.000"], ["71012.00", "4.934"], ["71013.90", "10.004"], ["71016.70", "1.965"], ["71029.60", "0.000"], ["71030.60", "3.400"], ["71037.20", "0.004"], ["71038.40", "0.701"], ["71052.70", "0.904"], ["71053.40", "0.273"], ["71053.60", "0.044"], ["71054.90", "0.008"], ["71056.10", "5.185"], ["71057.10", "0.004"], ["71057.70", "0.006"], ["71074.90", "2.532"], ["71081.10", "0.003"], ["71086.00", "0.089"], ["71086.10", "0.006"], ["71092.10", "5.293"], ["71093.30", "0.002"], ["71094.10", "0.292"], ["71095.20", "0.007"], ["71096.20", "0.298"], ["71096.70", "0.000"], ["71101.10", "0.000"], ["71102.50", "11.429"], ["71104.50", "0.042"], ["71106.20", "0.002"], ["71114.20", "0.038"], ["71115.40", "0.042"], ["71115.90", "0.040"], ["71117.90", "2.310"], ["71119.30", "0.004"], ["71126.20", "0.005"], ["71129.50", "0.001"], ["71132.10", "0.506"], ["71133.00", "4.268"], ["71135.40", "0.435"], ["71135.90", "0.284"], ["71136.20", "0.003"], ["71136.60", "0.039"], ["71137.00", "0.000"], ["71137.40", "0.280"], ["71140.20", "0.047"], ["71142.00", "0.064"], ["71142.80", "0.335"], ["71146.40", "0.303"], ["71148.70", "0.734"], ["71148.80", "0.002"], ["71149.60", "0.103"], ["71150.30", "1.830"], ["71151.40", "0.076"], ["71152.00", "0.156"], ["71152.80", "0.452"], ["71153.00", "0.004"], ["71154.00", "0.081"], ["71154.40", "2.644"], ["71154.60", "0.008"], ["71154.80", "0.003"], ["71154.90", "0.075"], ["71156.50", "0.043"], ["71157.50", "0.222"], ["71158.40", "0.000"], ["71159.10", "6.961"], ["71159.30", "0.000"], ["71159.50", "0.043"], ["71160.20", "0.002"], ["71160.40", "0.118"], ["71160.60", "0.002"], ["71161.50", "2.078"], ["71161.80", "0.005"], ["71163.30", "0.051"], ["71163.50", "0.151"], ["71164.30", "0.090"], ["71164.40", "0.008"], ["71165.60", "0.014"], ["71166.10", "0.081"], ["71166.80", "0.212"], ["71167.90", "0.269"], ["71168.60", "0.044"], ["71169.90", "0.038"], ["71170.00", "0.306"], ["71170.20", "0.025"], ["71170.70", "0.000"], ["71172.20", "0.259"], ["71172.90", "0.151"], ["71173.80", "0.000"], ["71174.60", "0.404"], ["71174.90", "0.016"], ["71175.30", "0.509"], ["71175.80", "1.578"], ["71176.40", "0.041"], ["71177.00", "0.101"], ["71177.60", "0.100"], ["71178.40", "0.167"], ["71178.60", "0.077"], ["71178.80", "2.029"], ["71179.10", "0.009"], ["71179.30", "0.187"], ["71180.50", "0.737"], ["71181.80", "0.155"], ["71182.20", "0.003"], ["71183.50", "0.160"], ["71183.60", "0.088"], ["71184.20", "0.002"], ["71185.40", "0.081"], ["71185.50", "0.047"], ["71185.70", "0.054"], ["71186.40", "0.004"], ["71186.80", "0.000"], ["71187.10", "0.002"], ["71187.20", "0.094"], ["71187.30", "0.000"], ["71187.50", "0.008"], ["71187.60", "0.017"], ["71187.70", "0.301"], ["71187.80", "0.291"], ["71188.50", "0.075"], ["71188.60", "0.335"], ["71189.00", "0.286"], ["71189.10", "0.005"], ["71189.50", "0.000"], ["71189.70", "0.002"], ["71190.00", "1.040"], ["71190.50", "0.000"], ["71190.60", "0.000"], ["71191.30", "0.605"], ["71191.40", "0.013"], ["71191.50", "1.793"], ["71191.60", "0.002"], ["71192.00", "0.414"], ["71192.20", "0.003"], ["71192.60", "0.002"], ["71192.70", "0.003"], ["71192.90", "1.072"], ["71194.10", "0.014"], ["71194.80", "0.029"], ["71195.40", "0.280"], ["71195.80", "0.002"], ["71196.20", "0.935"], ["71196.90", "0.530"], ["71197.20", "0.029"], ["71197.40", "0.064"], ["71197.50", "0.000"], ["71198.00", "0.000"], ["71198.70", "0.100"], ["71199.30", "0.742"], ["71200.00", "2.598"], ["71200.50", "0.341"], ["71200.70", "0.005"], ["71201.10", "0.572"], ["71201.30", "0.105"], ["71201.60", "0.696"], ["71202.00", "1.075"], ["71202.30", "0.134"], ["71202.60", "0.017"], ["71202.90", "0.000"], ["71203.40", "0.005"], ["71203.60", "0.000"], ["71203.80", "0.000"], ["71203.90", "0.210"], ["71204.10", "0.004"], ["71204.30", "1.706"], ["71204.40", "0.590"], ["71205.10", "0.000"], ["71205.40", "0.005"], ["71205.50", "0.000"], ["71205.70", "0.303"], ["71206.20", "0.340"], ["71206.40", "0.419"], ["71206.80", "0.506"], ["71207.10", "0.000"], ["71207.60", "0.143"], ["71207.70", "1.798"], ["71207.80", "0.001"], ["71208.00", "0.002"], ["71208.40", "0.004"], ["71209.20", "0.048"], ["71209.50", "0.890"], ["71209.60", "0.021"], ["71209.80", "0.419"], ["71210.00", "0.103"], ["71210.40", "0.063"], ["71210.50", "0.002"], ["71210.60", "1.826"], ["71210.70", "0.196"], ["71210.80", "0.453"], ["71210.90", "0.003"], ["71211.00", "0.081"], ["71211.20", "0.000"], ["71211.30", "0.005"], ["71211.40", "0.193"], ["71211.50", "0.035"], ["71211.80", "0.021"], ["71211.90", "0.142"], ["71212.10", "0.085"], ["71212.20", "0.176"], ["71212.30", "0.000"], ["71212.40", "0.009"], ["71212.50", "0.346"], ["71212.60", "0.004"], ["71213.20", "0.007"], ["71213.60", "0.005"], ["71214.00", "0.006"], ["71214.20", "0.536"], ["71214.50", "0.105"], ["71215.00", "0.025"], ["71216.30", "0.000"], ["71216.60", "0.315"], ["71217.00", "0.015"], ["71217.30", "0.015"], ["71217.40", "0.003"], ["71217.50", "0.208"], ["71217.70", "2.103"], ["71218.30", "0.000"], ["71218.40", "0.097"], ["71218.50", "0.526"], ["71219.30", "0.000"], ["71219.40", "0.557"], ["71219.70", "0.015"], ["71220.00", "0.044"], ["71220.10", "0.002"], ["71220.60", "0.007"], ["71220.70", "0.003"], ["71220.80", "0.000"], ["71220.90", "0.590"], ["71221.40", "0.040"], ["71221.60", "0.139"], ["71221.90", "0.111"], ["71222.10", "0.000"], ["71222.20", "0.000"], ["71222.40", "0.000"], ["71222.60", "0.008"], ["71222.70", "0.000"], ["71222.80", "0.002"], ["71223.50", "0.365"], ["71223.60", "0.002"], ["71223.90", "0.008"], ["71224.20", "0.000"], ["71224.30", "0.002"], ["71224.60", "0.358"], ["71224.90", "0.002"], ["71225.00", "1.140"], ["71225.60", "0.003"], ["71225.70", "0.070"], ["71226.00", "0.006"], ["71226.30", "0.002"], ["71226.40", "0.003"], ["71226.50", "0.000"], ["71227.00", "0.000"], ["71227.10", "0.000"], ["71227.60", "0.035"], ["71227.70", "0.002"], ["71227.80", "0.005"], ["71228.20", "0.077"], ["71228.40", "0.009"], ["71228.50", "0.012"], ["71228.60", "0.003"], ["71229.00", "0.004"], ["71229.10", "0.011"], ["71229.20", "0.029"], ["71229.40", "0.344"], ["71229.50", "0.022"], ["71229.80", "0.278"], ["71229.90", "0.003"], ["71230.20", "0.005"], ["71230.50", "0.003"], ["71230.60", "0.051"], ["71230.80", "0.002"], ["71230.90", "0.842"], ["71231.40", "0.029"], ["71231.80", "0.062"], ["71232.00", "0.006"], ["71232.10", "0.049"], ["71232.30", "0.208"], ["71232.50", "0.002"], ["71233.10", "0.629"], ["71233.30", "0.005"], ["71233.40", "0.039"], ["71233.80", "0.009"], ["71234.80", "0.001"], ["71234.90", "0.072"], ["71235.00", "0.004"], ["71235.10", "0.506"], ["71235.20", "0.673"], ["71235.30", "0.143"], ["71235.40", "0.002"], ["71235.50", "0.025"], ["71235.60", "0.205"], ["71235.70", "0.007"], ["71235.90", "0.761"], ["71236.00", "0.412"], ["71236.20", "0.036"], ["71236.30", "0.062"], ["71236.40", "0.000"], ["71236.50", "0.006"], ["71236.60", "0.042"], ["71236.70", "0.004"], ["71236.80", "0.004"], ["71237.00", "0.001"], ["71237.10", "0.000"], ["71237.20", "0.019"], ["71237.30", "0.289"], ["71237.50", "0.002"], ["71237.60", "0.002"], ["71237.70", "0.076"], ["71237.80", "0.010"], ["71238.00", "0.017"], ["71238.10", "0.515"], ["71238.30", "0.280"], ["71238.60", "0.000"], ["71238.70", "0.032"], ["71238.80", "0.003"], ["71238.90", "0.007"], ["71239.00", "0.011"], ["71239.20", "0.159"], ["71239.30", "0.004"], ["71239.50", "0.007"], ["71239.60", "0.000"], ["71239.80", "0.109"], ["71239.90", "0.023"], ["71240.00", "0.013"], ["71240.40", "0.033"], ["71240.50", "0.005"], ["71240.80", "0.008"], ["71240.90", "0.006"], ["71241.30", "0.003"], ["71242.00", "0.002"], ["71242.10", "0.002"], ["71242.30", "0.007"], ["71242.50", "0.002"], ["71242.70", "0.017"], ["71243.00", "0.005"], ["71243.10", "0.000"], ["71243.20", "0.210"], ["71243.30", "0.253"], ["71243.50", "0.073"], ["71243.70", "0.023"], ["71243.90", "0.320"], ["71244.20", "0.160"], ["71244.40", "0.012"], ["71244.70", "0.001"], ["71245.20", "0.023"], ["71245.60", "0.003"], ["71245.70", "0.101"], ["71245.90", "0.000"], ["71246.00", "0.038"], ["71246.50", "0.006"], ["71246.70", "0.296"], ["71246.80", "0.167"], ["71247.00", "0.005"], ["71247.10", "0.039"], ["71247.50", "0.068"], ["71247.80", "0.036"], ["71248.00", "0.214"], ["71248.10", "0.003"], ["71248.20", "0.068"], ["71248.50", "0.001"], ["71248.60", "0.025"], ["71248.70", "0.510"], ["71248.80", "0.142"], ["71248.90", "1.221"], ["71249.10", "0.329"], ["71249.20", "0.027"], ["71249.40", "0.301"], ["71249.50", "0.044"], ["71249.60", "0.018"], ["71249.70", "0.002"], ["71249.90", "0.063"], ["71250.00", "0.008"], ["71250.20", "0.002"], ["71250.40", "0.000"], ["71250.50", "0.028"], ["71250.60", "0.507"], ["71250.70", "0.003"], ["71250.80", "0.569"], ["71251.00", "0.218"], ["71251.10", "0.071"], ["71251.20", "0.004"], ["71251.30", "0.045"], ["71251.40", "0.009"], ["71251.50", "0.000"], ["71251.60", "0.637"], ["71251.70", "0.001"], ["71251.80", "0.004"], ["71252.00", "1.052"], ["71252.10", "0.001"], ["71252.30", "0.004"], ["71252.60", "0.233"], ["71252.70", "0.042"], ["71252.80", "0.003"], ["71252.90", "0.091"], ["71253.00", "0.077"], ["71253.10", "0.002"], ["71253.20", "0.074"], ["71253.30", "0.002"], ["71253.40", "0.003"], ["71253.60", "0.060"], ["71253.70", "0.155"], ["71253.80", "0.036"], ["71254.00", "0.037"], ["71254.10", "0.074"], ["71254.20", "0.017"], ["71254.30", "0.537"], ["71254.60", "0.287"], ["71254.70", "0.003"], ["71254.80", "0.045"], ["71254.90", "0.030"], ["71255.00", "0.019"], ["71255.20", "0.092"], ["71255.30", "0.020"], ["71255.40", "0.072"], ["71255.50", "0.000"], ["71255.60", "0.000"], ["71255.70", "0.800"], ["71255.90", "0.002"], ["71256.00", "0.542"], ["71256.10", "0.000"], ["71256.20", "0.005"], ["71256.40", "0.045"], ["71256.50", "0.003"], ["71256.60", "0.100"], ["71256.70", "0.000"], ["71256.80", "0.000"], ["71256.90", "0.310"], ["71257.10", "1.105"], ["71257.20", "0.000"], ["71257.30", "0.000"], ["71257.40", "0.000"], ["71257.50", "0.005"], ["71257.60", "0.000"], ["71257.70", "0.042"], ["71257.80", "0.032"], ["71257.90", "0.017"], ["71258.00", "0.005"], ["71258.20", "0.506"], ["71258.30", "0.000"], ["71258.40", "0.000"], ["71258.50", "0.002"], ["71258.60", "0.010"], ["71258.70", "1.102"], ["71258.80", "0.000"], ["71258.90", "0.000"], ["71259.00", "0.042"], ["71259.10", "0.002"], ["71259.20", "0.000"], ["71259.30", "0.338"], ["71259.40", "0.000"], ["71259.50", "0.000"], ["71259.60", "0.005"], ["71259.70", "0.000"], ["71259.80", "0.004"], ["71259.90", "0.059"], ["71260.00", "0.056"], ["71260.10", "0.247"], ["71260.20", "0.081"], ["71260.30", "0.064"], ["71260.40", "0.697"], ["71260.50", "0.000"], ["71260.60", "0.000"], ["71260.70", "0.000"], ["71260.80", "0.000"], ["71260.90", "0.000"], ["71261.00", "0.004"], ["71261.10", "0.000"], ["71261.20", "0.044"], ["71261.30", "8.174"]], "a": [["71260.30", "0.000"], ["71260.40", "0.000"], ["71260.50", "0.000"], ["71260.60", "0.000"], ["71260.70", "0.000"], ["71260.80", "0.000"], ["71260.90", "0.000"], ["71261.00", "0.000"], ["71261.10", "0.000"], ["71261.20", "0.000"], ["71261.30", "0.000"], ["71261.40", "0.059"], ["71261.80", "0.001"], ["71262.40", "0.000"], ["71262.50", "0.003"], ["71262.80", "0.000"], ["71262.90", "0.000"], ["71263.00", "0.000"], ["71264.00", "0.005"], ["71264.10", "0.000"], ["71264.20", "0.004"], ["71264.30", "0.004"], ["71264.50", "0.000"], ["71264.60", "0.006"], ["71264.70", "0.008"], ["71264.80", "0.003"], ["71265.00", "0.057"], ["71265.10", "0.019"], ["71265.40", "0.008"], ["71265.60", "0.002"], ["71266.00", "0.004"], ["71266.30", "0.001"], ["71266.50", "0.002"], ["71266.70", "0.001"], ["71266.80", "0.000"], ["71267.00", "0.004"], ["71267.40", "0.035"], ["71267.70", "0.000"], ["71267.80", "0.000"], ["71268.20", "0.002"], ["71269.00", "0.001"], ["71269.10", "0.061"], ["71269.20", "0.212"], ["71269.70", "0.000"], ["71269.90", "0.006"], ["71270.10", "0.001"], ["71270.40", "0.040"], ["71270.80", "0.000"], ["71270.90", "0.082"], ["71271.00", "0.003"], ["71271.10", "0.000"], ["71271.20", "0.009"], ["71271.30", "0.003"], ["71271.40", "0.003"], ["71271.50", "0.007"], ["71271.60", "0.000"], ["71271.70", "0.000"], ["71271.80", "0.017"], ["71272.00", "0.089"], ["71272.10", "0.083"], ["71272.20", "0.078"], ["71272.30", "0.006"], ["71272.40", "0.014"], ["71272.60", "0.067"], ["71272.70", "0.298"], ["71272.80", "0.004"], ["71273.00", "0.056"], ["71273.10", "0.004"], ["71273.30", "0.103"], ["71273.60", "0.039"], ["71273.70", "0.070"], ["71273.80", "0.041"], ["71274.00", "0.139"], ["71274.10", "0.004"], ["71274.30", "0.038"], ["71274.40", "0.192"], ["71274.60", "0.006"], ["71274.70", "0.000"], ["71274.80", "0.000"], ["71274.90", "0.322"], ["71275.20", "0.006"], ["71275.40", "0.217"], ["71275.60", "1.616"], ["71275.70", "0.003"], ["71275.80", "0.005"], ["71275.90", "0.000"], ["71276.00", "0.005"], ["71276.10", "0.002"], ["71276.30", "0.002"], ["71276.50", "0.005"], ["71276.60", "0.000"], ["71276.70", "0.000"], ["71276.80", "0.014"], ["71277.40", "0.111"], ["71277.50", "0.333"], ["71278.00", "0.073"], ["71278.10", "0.004"], ["71278.40", "0.002"], ["71278.90", "0.002"], ["71279.00", "0.034"], ["71279.10", "0.001"], ["71279.20", "0.008"], ["71279.30", "0.002"], ["71279.50", "0.140"], ["71279.60", "0.001"], ["71279.70", "0.004"], ["71279.90", "1.044"], ["71280.00", "0.111"], ["71280.10", "0.008"], ["71280.30", "0.225"], ["71280.40", "0.000"], ["71280.60", "0.005"], ["71280.70", "0.230"], ["71280.80", "0.073"], ["71281.20", "0.005"], ["71281.30", "0.002"], ["71281.70", "0.000"], ["71281.80", "0.212"], ["71282.00", "0.011"], ["71282.10", "0.005"], ["71282.20", "0.014"], ["71282.30", "0.024"], ["71282.40", "0.100"], ["71282.50", "0.000"], ["71282.60", "0.005"], ["71282.80", "0.189"], ["71283.10", "0.009"], ["71283.20", "0.000"], ["71283.40", "0.000"], ["71283.60", "0.287"], ["71283.70", "0.086"], ["71283.80", "0.003"], ["71283.90", "0.661"], ["71284.00", "0.096"], ["71284.10", "0.009"], ["71284.20", "0.002"], ["71284.30", "0.010"], ["71284.40", "0.038"], ["71284.50", "0.019"], ["71284.60", "0.029"], ["71284.80", "0.010"], ["71284.90", "0.001"], ["71285.10", "0.085"], ["71285.20", "0.109"], ["71285.30", "0.209"], ["71285.40", "0.138"], ["71285.60", "0.812"], ["71285.70", "0.415"], ["71285.80", "0.026"], ["71285.90", "0.003"], ["71286.00", "0.009"], ["71286.10", "0.012"], ["71286.20", "0.007"], ["71286.30", "0.034"], ["71286.50", "1.200"], ["71286.60", "0.111"], ["71286.70", "0.000"], ["71286.90", "0.054"], ["71287.20", "0.000"], ["71287.30", "0.730"], ["71287.40", "0.041"], ["71287.60", "0.126"], ["71287.70", "0.092"], ["71288.00", "0.234"], ["71288.10", "0.009"], ["71288.30", "0.267"], ["71288.40", "0.002"], ["71288.70", "0.015"], ["71288.80", "0.009"], ["71288.90", "0.007"], ["71289.10", "0.271"], ["71289.40", "0.770"], ["71289.50", "0.004"], ["71289.70", "0.050"], ["71289.80", "0.030"], ["71289.90", "0.080"], ["71290.00", "0.127"], ["71290.40", "0.003"], ["71290.70", "0.011"], ["71291.20", "0.002"], ["71292.50", "0.000"], ["71292.70", "0.023"], ["71292.80", "0.056"], ["71293.40", "0.002"], ["71293.70", "0.073"], ["71294.00", "0.004"], ["71294.40", "0.003"], ["71294.80", "0.031"], ["71295.00", "0.068"], ["71295.20", "0.105"], ["71295.60", "0.653"], ["71296.00", "0.106"], ["71296.10", "0.347"], ["71296.30", "0.004"], ["71296.60", "0.350"], ["71296.90", "0.003"], ["71297.00", "0.071"], ["71297.30", "0.003"], ["71297.40", "0.340"], ["71297.50", "0.118"], ["71297.60", "0.298"], ["71297.90", "1.388"], ["71298.30", "0.334"], ["71298.60", "0.003"], ["71299.30", "0.000"], ["71300.00", "3.016"], ["71300.10", "0.211"], ["71300.40", "1.064"], ["71300.80", "0.006"], ["71301.20", "0.017"], ["71301.30", "0.005"], ["71301.80", "0.289"], ["71301.90", "0.001"], ["71302.00", "0.015"], ["71302.10", "0.542"], ["71302.20", "0.496"], ["71302.40", "0.301"], ["71302.70", "0.069"], ["71302.80", "0.002"], ["71303.10", "0.283"], ["71303.20", "0.000"], ["71303.40", "0.003"], ["71303.60", "0.053"], ["71303.80", "0.005"], ["71303.90", "0.210"], ["71304.10", "0.508"], ["71304.20", "0.872"], ["71304.80", "0.000"], ["71305.10", "0.005"], ["71305.30", "0.027"], ["71305.40", "0.009"], ["71305.80", "0.117"], ["71306.00", "0.677"], ["71306.20", "0.000"], ["71306.40", "0.004"], ["71306.50", "0.002"], ["71306.70", "0.003"], ["71307.20", "0.057"], ["71307.50", "0.000"], ["71307.80", "0.293"], ["71308.40", "0.024"], ["71308.50", "0.090"], ["71308.80", "0.011"], ["71309.80", "0.000"], ["71310.70", "0.832"], ["71311.20", "0.115"], ["71311.30", "0.004"], ["71311.70", "0.300"], ["71312.50", "0.061"], ["71312.70", "0.019"], ["71312.80", "0.006"], ["71312.90", "0.004"], ["71313.40", "0.015"], ["71313.60", "0.000"], ["71313.70", "0.051"], ["71314.40", "0.042"], ["71315.00", "0.675"], ["71315.40", "0.044"], ["71315.50", "0.371"], ["71315.60", "0.024"], ["71315.70", "0.214"], ["71315.80", "0.033"], ["71315.90", "0.282"], ["71316.10", "1.049"], ["71316.30", "0.045"], ["71316.60", "0.063"], ["71316.90", "0.541"], ["71317.00", "0.664"], ["71317.30", "0.045"], ["71317.40", "0.019"], ["71317.90", "0.000"], ["71318.30", "0.097"], ["71318.40", "0.011"], ["71318.70", "0.103"], ["71318.90", "0.041"], ["71319.00", "0.069"], ["71319.10", "0.040"], ["71319.80", "0.480"], ["71320.20", "0.000"], ["71320.30", "0.087"], ["71320.60", "0.298"], ["71320.80", "0.000"], ["71321.50", "0.000"], ["71321.60", "0.000"], ["71321.70", "0.066"], ["71322.00", "0.224"], ["71322.20", "10.035"], ["71322.30", "0.000"], ["71322.50", "0.000"], ["71322.70", "0.000"], ["71323.20", "0.235"], ["71323.50", "1.828"], ["71324.20", "0.360"], ["71324.50", "0.011"], ["71325.00", "0.000"], ["71325.50", "0.033"], ["71325.70", "0.002"], ["71325.90", "0.000"], ["71326.30", "0.002"], ["71326.50", "0.003"], ["71326.60", "0.000"], ["71327.30", "0.004"], ["71327.40", "0.711"], ["71327.70", "0.298"], ["71327.90", "0.002"], ["71328.20", "0.020"], ["71328.90", "2.790"], ["71329.20", "0.064"], ["71329.70", "0.000"], ["71329.80", "0.000"], ["71330.00", "0.720"], ["71330.10", "0.060"], ["71330.80", "0.174"], ["71330.90", "0.112"], ["71331.00", "0.002"], ["71331.70", "0.000"], ["71331.80", "0.010"], ["71331.90", "0.294"], ["71332.00", "0.587"], ["71332.50", "0.573"], ["71332.70", "1.081"], ["71332.80", "0.094"], ["71333.00", "0.160"], ["71333.70", "0.030"], ["71333.80", "1.420"], ["71334.00", "0.004"], ["71334.30", "0.017"], ["71334.70", "0.000"], ["71334.80", "0.000"], ["71335.00", "0.181"], ["71335.30", "0.078"], ["71335.40", "0.004"], ["71335.50", "0.132"], ["71335.60", "0.002"], ["71335.80", "0.088"], ["71336.60", "0.002"], ["71337.60", "0.040"], ["71338.20", "0.682"], ["71338.30", "0.279"], ["71338.50", "0.292"], ["71338.70", "0.007"], ["71339.70", "1.644"], ["71339.90", "0.083"], ["71340.00", "0.190"], ["71340.30", "0.004"], ["71342.50", "0.180"], ["71342.90", "0.033"], ["71343.50", "0.300"], ["71343.80", "0.151"], ["71344.30", "0.442"], ["71344.50", "1.308"], ["71344.90", "1.644"], ["71345.40", "0.000"], ["71345.90", "0.091"], ["71346.00", "0.002"], ["71346.20", "0.002"], ["71346.40", "0.000"], ["71346.90", "1.668"], ["71347.10", "0.076"], ["71347.20", "0.070"], ["71348.90", "1.676"], ["71349.00", "0.045"], ["71349.40", "0.063"], ["71349.80", "0.124"], ["71349.90", "0.351"], ["71350.10", "1.105"], ["71350.40", "0.002"], ["71350.50", "0.133"], ["71350.60", "0.142"], ["71350.80", "0.074"], ["71350.90", "0.000"], ["71351.20", "0.320"], ["71352.50", "0.012"], ["71352.60", "0.292"], ["71352.80", "0.040"], ["71353.00", "0.041"], ["71353.70", "0.016"], ["71354.20", "0.000"], ["71354.80", "0.044"], ["71355.90", "0.003"], ["71356.90", "0.000"], ["71357.00", "6.967"], ["71357.10", "0.049"], ["71357.90", "0.003"], ["71358.80", "0.041"], ["71359.90", "2.181"], ["71360.60", "0.005"], ["71361.20", "2.070"], ["71362.20", "0.000"], ["71363.60", "0.115"], ["71364.40", "0.118"], ["71364.50", "0.039"], ["71365.60", "0.280"], ["71367.40", "0.514"], ["71369.30", "0.002"], ["71369.50", "0.054"], ["71370.10", "0.244"], ["71371.70", "0.002"], ["71371.80", "0.002"], ["71373.30", "0.000"], ["71373.50", "0.000"], ["71373.60", "0.020"], ["71373.90", "0.000"], ["71374.20", "0.006"], ["71374.30", "3.842"], ["71374.40", "11.208"], ["71374.90", "0.134"], ["71378.20", "0.002"], ["71380.20", "0.016"], ["71382.60", "0.398"], ["71383.70", "0.827"], ["71385.00", "0.214"], ["71387.80", "0.534"], ["71387.90", "0.064"], ["71389.10", "0.111"], ["71389.70", "2.000"], ["71391.50", "6.662"], ["71399.20", "0.039"], ["71399.90", "2.834"], ["71400.60", "0.150"], ["71401.70", "0.075"], ["71407.30", "0.260"], ["71408.30", "0.092"], ["71408.40", "0.000"], ["71417.80", "0.220"], ["71428.80", "1.508"], ["71441.60", "0.012"], ["71449.10", "6.722"], ["71451.80", "0.002"], ["71454.60", "0.397"], ["71456.80", "0.431"], ["71467.80", "0.003"], ["71468.60", "0.202"], ["71471.30", "0.357"], ["71476.30", "0.268"], ["71476.80", "0.008"], ["71477.70", "0.281"], ["71481.30", "0.014"], ["71484.80", "0.282"], ["71488.80", "1.301"], ["71502.80", "0.280"], ["71539.30", "0.173"], ["71541.40", "0.282"], ["71544.20", "0.207"], ["71555.80", "0.278"], ["71559.60", "0.284"], ["71559.70", "0.280"], ["71562.90", "0.279"], ["71606.20", "0.000"], ["71609.30", "0.007"], ["71613.10", "0.212"], ["71614.10", "0.212"], ["71673.90", "0.002"], ["71962.40", "0.006"], ["71970.50", "0.000"], ["71970.90", "0.000"], ["71971.20", "0.012"], ["71972.90", "0.000"], ["71973.00", "0.019"], ["71973.10", "0.005"], ["71974.00", "0.004"], ["72045.20", "2.771"], ["72205.90", "0.000"], ["72330.10", "2.760"], ["74111.80", "0.002"], ["74835.40", "0.000"], ["78382.30", "0.000"]]}}
{"local_ts": 1773384751207, "server_ts": 1773384750969, "data": {"e": "depthUpdate", "E": 1773384750971, "T": 1773384750969, "s": "BTCUSDT", "U": 10101358524655, "u": 10101358532457, "pu": 10101358524578, "b": [["5000.00", "101.418"], ["20771.90", "0.045"], ["20875.50", "0.279"], ["20971.90", "0.360"], ["20975.50", "0.108"], ["21049.90", "0.000"], ["21175.50", "0.216"], ["64147.90", "0.000"], ["67663.80", "0.006"], ["69507.50", "0.619"], ["69817.50", "0.000"], ["69850.00", "0.901"], ["70156.30", "0.000"], ["70562.70", "0.000"], ["70715.20", "0.002"], ["70850.40", "0.000"], ["70939.50", "0.211"], ["70959.20", "0.019"], ["71126.20", "0.002"], ["71144.90", "0.043"], ["71146.10", "0.108"], ["71146.60", "0.147"], ["71153.60", "0.036"], ["71161.80", "0.002"], ["71167.60", "0.143"], ["71180.50", "0.427"], ["71197.40", "0.000"], ["71210.50", "0.002"], ["71211.40", "0.193"], ["71212.30", "0.101"], ["71212.40", "0.013"], ["71216.20", "0.005"], ["71216.30", "0.000"], ["71225.00", "1.136"], ["71225.20", "1.555"], ["71226.80", "1.200"], ["71232.60", "0.004"], ["71232.70", "0.213"], ["71237.50", "0.004"], ["71237.60", "0.003"], ["71238.10", "0.566"], ["71239.90", "0.156"], ["71241.10", "0.084"], ["71241.40", "0.022"], ["71244.00", "0.031"], ["71245.80", "0.006"], ["71247.30", "0.000"], ["71248.60", "0.077"], ["71250.50", "0.001"], ["71251.20", "0.103"], ["71256.90", "1.018"], ["71257.90", "0.110"], ["71258.40", "0.030"], ["71259.40", "0.003"], ["71261.60", "0.398"], ["71261.90", "0.032"], ["71262.00", "0.827"], ["71262.80", "0.018"], ["71263.10", "0.004"], ["71266.90", "0.003"], ["71268.40", "0.107"], ["71271.90", "0.310"], ["71272.00", "0.091"], ["71272.90", "0.847"], ["71275.20", "0.002"], ["71275.40", "0.001"], ["71275.50", "5.300"]], "a": [["71275.60", "1.342"], ["71276.70", "0.001"], ["71277.00", "0.005"], ["71277.80", "0.003"], ["71279.90", "0.006"], ["71282.00", "0.053"], ["71282.20", "0.007"], ["71283.60", "0.007"], ["71286.20", "0.064"], ["71286.30", "0.296"], ["71287.00", "0.004"], ["71292.00", "0.017"], ["71295.20", "0.000"], ["71296.90", "0.054"], ["71297.00", "0.181"], ["71300.90", "0.002"], ["71301.80", "0.079"], ["71302.00", "0.031"], ["71307.70", "0.159"], ["71308.80", "0.007"], ["71309.80", "0.019"], ["71313.00", "0.144"], ["71314.80", "0.529"], ["71316.90", "0.508"], ["71318.40", "0.011"], ["71322.00", "0.027"], ["71322.20", "0.005"], ["71327.70", "0.301"], ["71330.80", "0.040"], ["71344.50", "1.305"], ["71347.30", "0.106"], ["71347.50", "0.334"], ["71356.70", "0.306"], ["71380.20", "0.011"], ["71455.10", "0.000"], ["71488.70", "0.000"], ["71988.40", "0.002"], ["72252.00", "0.280"], ["78403.20", "0.000"]]}}
{"local_ts": 1773384752209, "server_ts": 1773384751992, "data": {"e": "depthUpdate", "E": 1773384751993, "T": 1773384751992, "s": "BTCUSDT", "U": 10101358607644, "u": 10101358612828, "pu": 10101358607527, "b": [["1000.00", "27.792"], ["5000.00", "101.418"], ["20775.50", "0.171"], ["20875.50", "1.467"], ["20955.40", "0.045"], ["20956.40", "0.000"], ["20958.50", "0.000"], ["20960.20", "0.000"], ["20960.30", "0.000"], ["20960.40", "0.000"], ["20961.30", "0.000"], ["21075.50", "0.171"], ["21175.50", "0.648"], ["33000.00", "9.339"], ["57020.00", "0.002"], ["64147.90", "0.000"], ["65852.70", "0.002"], ["67677.10", "0.000"], ["67677.70", "0.002"], ["70057.90", "0.290"], ["70204.80", "0.681"], ["70242.00", "7.337"], ["70334.90", "0.852"], ["70560.10", "0.004"], ["70562.70", "0.000"], ["70598.40", "1.419"], ["70644.30", "0.002"], ["70959.20", "0.019"], ["71044.90", "0.000"], ["71102.00", "1.124"], ["71118.40", "0.000"], ["71128.10", "0.502"], ["71154.40", "0.918"], ["71154.60", "0.000"], ["71182.90", "0.228"], ["71212.60", "0.006"], ["71216.00", "0.000"], ["71239.90", "0.086"], ["71248.00", "0.207"], ["71252.00", "1.053"], ["71255.50", "0.010"], ["71258.20", "0.566"], ["71262.10", "0.101"], ["71262.30", "0.023"], ["71268.40", "0.165"], ["71273.80", "0.005"], ["71275.50", "4.568"]], "a": [["71277.00", "0.002"], ["71282.70", "0.186"], ["71287.50", "0.346"], ["71288.80", "0.038"], ["71295.60", "0.010"], ["71311.20", "0.334"], ["71313.60", "0.017"], ["71343.30", "0.011"], ["71343.60", "0.049"], ["71377.40", "0.141"], ["71394.10", "0.074"], ["71397.20", "0.005"], ["71397.40", "0.000"], ["71397.90", "0.143"], ["71426.90", "0.909"], ["71500.00", "7.646"], ["71517.60", "0.008"], ["71988.30", "0.111"], ["71988.40", "1.387"], ["75480.90", "1.323"], ["78403.20", "0.000"]]}}
{"local_ts": 1773384753229, "server_ts": 1773384753014, "data": {"e": "depthUpdate", "E": 1773384753015, "T": 1773384753014, "s": "BTCUSDT", "U": 10101358657256, "u": 10101358663712, "pu": 10101358657074, "b": [["5000.00", "101.418"], ["20775.50", "1.548"], ["20874.90", "0.000"], ["20875.50", "0.216"], ["20975.50", "0.036"], ["21075.50", "0.864"], ["21174.90", "0.000"], ["21175.50", "0.036"], ["57020.00", "0.002"], ["64147.90", "0.000"], ["65675.20", "0.002"], ["67046.20", "1.489"], ["67678.10", "0.000"], ["67685.90", "0.002"], ["67711.00", "2.520"], ["69825.00", "0.879"], ["69954.00", "0.008"], ["70028.20", "4.034"], ["70221.40", "0.000"], ["70705.30", "0.002"], ["70919.10", "0.000"], ["71099.40", "0.000"], ["71099.50", "1.714"], ["71159.10", "0.453"], ["71161.10", "0.875"], ["71197.10", "0.004"], ["71211.30", "0.010"], ["71216.80", "0.000"], ["71217.80", "0.008"], ["71220.50", "1.200"], ["71220.60", "0.191"], ["71226.00", "0.002"], ["71226.40", "0.005"], ["71226.60", "0.003"], ["71229.40", "0.331"], ["71234.10", "0.003"], ["71236.10", "0.440"], ["71247.70", "0.247"], ["71249.20", "0.002"], ["71268.40", "0.167"], ["71271.90", "0.236"], ["71275.50", "4.605"]], "a": [["71282.70", "0.188"], ["71304.90", "0.016"], ["71306.00", "1.302"], ["71320.00", "0.681"], ["71320.10", "0.000"], ["71322.90", "0.003"], ["71323.00", "0.021"], ["71339.80", "0.316"], ["71347.20", "0.076"], ["71354.00", "0.005"], ["71364.10", "0.491"], ["71366.30", "0.000"], ["71424.90", "0.299"], ["71427.30", "0.002"], ["71532.00", "0.007"], ["71600.00", "12.259"], ["71988.40", "1.387"], ["72217.30", "0.066"], ["78403.20", "0.000"]]}}
{"local_ts": 1773384754248, "server_ts": 1773384754033, "data": {"e": "depthUpdate", "E": 1773384754035, "T": 1773384754033, "s": "BTCUSDT", "U": 10101358721802, "u": 10101358726903, "pu": 10101358721652, "b": [["1000.00", "27.642"], ["5000.00", "101.418"], ["20775.50", "0.450"], ["20975.50", "0.801"], ["21075.50", "0.099"], ["21175.50", "1.350"], ["33000.00", "9.343"], ["64147.90", "0.000"], ["67389.00", "4.013"], ["67685.70", "0.012"], ["70234.40", "4.945"], ["70562.70", "0.000"], ["71025.70", "0.000"], ["71058.50", "0.002"], ["71197.10", "0.004"], ["71208.00", "0.296"], ["71210.80", "0.000"], ["71211.30", "0.010"], ["71218.60", "0.184"], ["71220.60", "0.007"], ["71250.10", "0.002"], ["71254.90", "0.810"], ["71255.00", "0.017"], ["71262.70", "0.106"], ["71274.60", "0.053"], ["71275.50", "2.730"]], "a": [["71275.60", "1.349"], ["71282.40", "0.001"], ["71282.90", "0.014"], ["71288.50", "0.007"], ["71307.30", "0.001"], ["71307.60", "0.140"], ["71311.20", "0.334"], ["71314.80", "0.545"], ["71339.80", "0.316"], ["71341.20", "1.080"], ["71354.00", "0.005"], ["71631.90", "0.026"], ["71988.40", "1.387"], ["72380.40", "1.932"], ["72500.00", "157.942"], ["74859.80", "0.002"], ["78403.20", "0.000"]]}}
{"local_ts": 1773384755270, "server_ts": 1773384755053, "data": {"e": "depthUpdate", "E": 1773384755055, "T": 1773384755053, "s": "BTCUSDT", "U": 10101358772568, "u": 10101358778250, "pu": 10101358772432, "b": [["1000.00", "27.642"], ["5000.00", "101.418"], ["20875.50", "0.666"], ["20975.50", "0.234"], ["21075.50", "1.080"], ["21175.50", "0.720"], ["57020.00", "0.002"], ["67689.40", "0.002"], ["67691.90", "0.000"], ["70177.40", "0.000"], ["70420.20", "0.845"], ["70562.70", "0.000"], ["71128.00", "0.491"], ["71150.60", "0.000"], ["71166.60", "0.176"], ["71187.30", "0.183"], ["71189.70", "0.002"], ["71194.50", "0.141"], ["71196.90", "0.514"], ["71201.60", "0.836"], ["71204.00", "0.004"], ["71213.20", "0.005"], ["71213.30", "0.366"], ["71218.60", "0.000"], ["71220.30", "0.326"], ["71220.70", "0.176"], ["71227.30", "0.002"], ["71227.40", "0.792"], ["71229.30", "0.001"], ["71237.90", "0.255"], ["71246.40", "0.459"], ["71261.60", "0.003"], ["71262.70", "0.102"], ["71266.70", "0.005"], ["71271.90", "0.252"], ["71275.20", "0.004"], ["71275.50", "2.709"]], "a": [["71288.40", "0.004"], ["71299.90", "0.095"], ["71302.60", "0.005"], ["71309.20", "0.521"], ["71309.80", "0.126"], ["71310.00", "0.192"], ["71314.70", "0.006"], ["71314.80", "0.386"], ["71319.60", "0.255"], ["71358.60", "0.140"], ["71361.00", "0.002"], ["71365.70", "0.127"], ["71368.10", "0.001"], ["71391.30", "0.166"], ["71425.10", "0.686"], ["71425.20", "0.296"], ["71988.40", "1.387"]]}}
{"local_ts": 1773384756292, "server_ts": 1773384756076, "data": {"e": "depthUpdate", "E": 1773384756077, "T": 1773384756076, "s": "BTCUSDT", "U": 10101358824519, "u": 10101358830757, "pu": 10101358824418, "b": [["5000.00", "101.418"], ["20775.50", "0.531"], ["20875.50", "0.369"], ["20975.50", "0.819"], ["21075.50", "0.981"], ["33000.00", "9.343"], ["57020.00", "0.006"], ["67696.60", "0.002"], ["69850.00", "0.910"], ["70248.10", "0.779"], ["70562.70", "0.000"], ["71126.20", "0.101"], ["71131.80", "0.490"], ["71136.40", "0.173"], ["71138.30", "0.106"], ["71142.30", "0.099"], ["71190.00", "1.037"], ["71196.90", "0.510"], ["71198.40", "0.113"], ["71212.80", "0.000"], ["71218.50", "1.403"], ["71220.30", "0.003"], ["71224.70", "0.002"], ["71225.00", "1.134"], ["71225.70", "0.184"], ["71227.80", "0.005"], ["71228.00", "0.167"], ["71232.00", "0.006"], ["71239.00", "0.294"], ["71239.90", "0.103"], ["71246.00", "0.090"], ["71253.00", "0.010"], ["71262.70", "0.102"], ["71268.90", "0.014"], ["71270.20", "0.142"], ["71275.50", "2.641"]], "a": [["71288.40", "0.004"], ["71293.40", "0.278"], ["71295.00", "0.029"], ["71301.90", "0.627"], ["71302.00", "0.276"], ["71302.10", "0.003"], ["71307.70", "0.298"], ["71309.00", "0.829"], ["71310.20", "0.012"], ["71310.30", "0.128"], ["71311.20", "0.498"], ["71316.00", "0.883"], ["71322.40", "0.008"], ["71322.50", "0.002"], ["71323.00", "0.021"], ["71335.90", "0.559"], ["71371.80", "0.214"], ["71502.30", "0.006"], ["71988.30", "0.111"], ["71988.40", "1.387"], ["72226.60", "0.000"], ["72442.00", "0.002"], ["72657.40", "0.000"], ["73888.00", "45.304"]]}}
{"local_ts": 1773384757318, "server_ts": 1773384757102, "data": {"e": "depthUpdate", "E": 1773384757103, "T": 1773384757102, "s": "BTCUSDT", "U": 10101358875577, "u": 10101358883105, "pu": 10101358875530, "b": [["1000.00", "27.642"], ["5000.00", "101.418"], ["20775.50", "0.504"], ["20875.50", "0.558"], ["20975.50", "1.242"], ["21175.50", "0.396"], ["67704.80", "0.000"], ["68424.50", "0.006"], ["70385.10", "0.721"], ["70562.70", "0.000"], ["71075.90", "0.280"], ["71113.40", "12.770"], ["71114.30", "2.516"], ["71127.60", "0.191"], ["71170.90", "1.820"], ["71171.50", "2.518"], ["71171.90", "4.292"], ["71176.30", "6.921"], ["71204.40", "0.598"], ["71214.90", "3.668"], ["71215.00", "0.209"], ["71216.00", "0.000"], ["71225.00", "1.134"], ["71225.70", "0.000"], ["71227.70", "0.003"], ["71227.80", "0.007"], ["71232.00", "0.006"], ["71238.90", "1.893"], ["71239.00", "0.294"], ["71246.00", "0.090"], ["71247.70", "0.072"], ["71249.10", "0.306"], ["71250.60", "0.071"], ["71251.90", "0.004"], ["71253.00", "0.010"], ["71257.10", "1.851"], ["71257.70", "0.635"], ["71258.30", "0.032"], ["71258.70", "0.006"], ["71262.70", "0.102"], ["71264.70", "0.258"], ["71265.60", "0.133"], ["71265.70", "0.012"], ["71272.80", "0.002"], ["71274.40", "0.002"], ["71274.50", "0.002"], ["71274.60", "0.051"], ["71274.70", "0.000"], ["71274.90", "0.000"], ["71275.00", "0.100"], ["71275.10", "0.002"], ["71275.20", "0.002"], ["71275.30", "0.000"], ["71275.50", "2.228"]], "a": [["71275.60", "2.907"], ["71288.40", "0.004"], ["71292.00", "0.016"], ["71295.00", "0.029"], ["71295.20", "0.002"], ["71295.70", "0.072"], ["71296.80", "0.000"], ["71298.20", "0.069"], ["71302.00", "0.276"], ["71302.40", "0.885"], ["71309.00", "0.829"], ["71310.50", "0.154"], ["71310.90", "0.006"], ["71311.10", "0.019"], ["71311.20", "0.470"], ["71315.30", "0.494"], ["71316.00", "0.883"], ["71319.00", "1.938"], ["71322.80", "1.145"], ["71322.90", "0.003"], ["71323.00", "0.021"], ["71328.10", "0.642"], ["71336.20", "0.002"], ["71341.60", "1.025"], ["71343.20", "3.635"], ["71343.90", "0.509"], ["71364.90", "0.046"], ["71381.80", "1.326"], ["71381.90", "6.911"], ["71442.50", "4.158"], ["71445.30", "13.185"], ["71460.90", "0.000"], ["71502.30", "0.006"], ["71655.30", "0.000"], ["71988.40", "1.387"], ["72202.20", "1.840"], ["72237.80", "2.972"]]}}
{"local_ts": 1773384758336, "server_ts": 1773384758120, "data": {"e": "depthUpdate", "E": 1773384758123, "T": 1773384758120, "s": "BTCUSDT", "U": 10101358924842, "u": 10101358930056, "pu": 10101358924733, "b": [["5000.00", "101.418"], ["20775.50", "0.288"], ["20875.50", "1.512"], ["20975.50", "0.000"], ["21075.50", "0.261"], ["21175.50", "0.639"], ["21175.60", "0.000"], ["57020.00", "0.002"], ["70048.10", "4.277"], ["70201.00", "1.396"], ["70562.70", "0.000"], ["70919.10", "0.026"], ["71026.10", "0.004"], ["71075.30", "0.002"], ["71075.90", "0.278"], ["71195.30", "0.108"], ["71215.00", "1.199"], ["71217.80", "0.192"], ["71227.50", "0.015"], ["71227.70", "0.005"], ["71239.60", "0.000"], ["71239.70", "0.005"], ["71240.30", "0.510"], ["71240.40", "0.024"], ["71262.70", "0.160"], ["71275.50", "2.601"]], "a": [["71276.10", "0.457"], ["71279.40", "0.005"], ["71286.30", "0.395"], ["71288.40", "0.004"], ["71289.50", "0.124"], ["71294.80", "0.198"], ["71297.80", "0.024"], ["71300.50", "0.123"], ["71307.70", "0.298"], ["71322.10", "0.004"], ["71322.20", "0.002"], ["71323.20", "0.040"], ["71347.70", "0.135"], ["71349.80", "0.007"], ["71354.80", "0.044"], ["71356.90", "0.009"], ["71361.90", "0.020"], ["71364.00", "0.007"], ["71369.00", "0.018"], ["71371.10", "0.068"], ["71376.10", "0.000"], ["71378.20", "0.009"], ["71383.20", "0.506"], ["71385.30", "0.009"], ["71390.30", "0.001"], ["71392.40", "0.013"], ["71397.40", "0.000"], ["71399.50", "0.113"], ["71655.10", "0.006"], ["71845.80", "0.139"], ["71988.30", "0.111"], ["71988.40", "1.387"], ["72226.50", "1.179"], ["72441.90", "0.004"], ["72657.30", "0.014"], ["74864.00", "0.052"], ["89523.20", "0.006"]]}}
{"local_ts": 1773384759357, "server_ts": 1773384759140, "data": {"e": "depthUpdate", "E": 1773384759143, "T": 1773384759140, "s": "BTCUSDT", "U": 10101358968740, "u": 10101358973417, "pu": 10101358968576, "b": [["1000.00", "27.642"], ["5000.00", "101.418"], ["20775.50", "1.548"], ["20875.50", "0.117"], ["20975.50", "0.126"], ["21075.50", "0.774"], ["21175.50", "0.135"], ["57020.00", "0.002"], ["67701.00", "0.005"], ["69400.00", "23.473"], ["69850.00", "0.901"], ["70249.30", "0.000"], ["70441.60", "1.134"], ["70562.70", "0.000"], ["71071.70", "0.080"], ["71075.30", "0.000"], ["71075.50", "0.002"], ["71201.90", "0.011"], ["71214.10", "0.497"], ["71214.20", "0.108"], ["71217.80", "0.008"], ["71220.40", "0.186"], ["71225.00", "1.134"], ["71227.80", "0.005"], ["71228.00", "0.026"], ["71232.00", "0.006"], ["71239.00", "0.294"], ["71246.00", "0.090"], ["71253.00", "0.010"], ["71262.70", "0.110"], ["71275.40", "0.009"], ["71275.50", "2.752"]], "a": [["71275.60", "2.549"], ["71286.30", "0.296"], ["71288.40", "0.004"], ["71290.40", "0.000"], ["71295.00", "0.029"], ["71297.00", "0.210"], ["71301.00", "0.080"], ["71302.00", "0.276"], ["71307.70", "0.298"], ["71309.00", "0.829"], ["71310.90", "0.006"], ["71311.00", "0.718"], ["71311.20", "0.311"], ["71313.70", "0.005"], ["71314.80", "0.261"], ["71316.00", "1.207"], ["71323.00", "0.021"], ["71341.10", "0.020"], ["71346.80", "0.716"], ["71349.80", "0.000"], ["71350.80", "0.013"], ["71356.90", "0.038"], ["71357.90", "0.010"], ["71364.00", "0.000"], ["71364.60", "0.293"], ["71365.00", "0.513"], ["71371.10", "0.061"], ["71372.10", "0.007"], ["71378.20", "0.002"], ["71379.20", "0.139"], ["71385.30", "0.002"], ["71386.30", "0.007"], ["71392.40", "0.006"], ["71393.40", "0.008"], ["71399.50", "0.106"], ["71400.50", "0.013"], ["71450.20", "0.002"], ["71988.40", "1.387"], ["72322.00", "0.000"], ["72380.40", "2.276"], ["72701.10", "0.030"], ["89523.20", "0.006"]]}}
{"local_ts": 1773384760378, "server_ts": 1773384760162, "data": {"e": "depthUpdate", "E": 1773384760163, "T": 1773384760162, "s": "BTCUSDT", "U": 10101359011103, "u": 10101359016247, "pu": 10101359011071, "b": [["1000.00", "27.642"], ["5000.00", "101.418"], ["20775.50", "0.252"], ["20975.50", "0.891"], ["21075.50", "0.009"], ["21175.50", "1.548"], ["70562.70", "0.002"], ["71074.60", "0.004"], ["71075.50", "0.000"], ["71124.70", "0.389"], ["71142.20", "0.004"], ["71168.10", "0.001"], ["71168.40", "2.232"], ["71209.90", "1.446"], ["71275.50", "2.386"]], "a": [["71275.60", "2.520"], ["71297.00", "0.210"], ["71310.90", "0.006"], ["71311.00", "0.592"], ["71311.10", "0.145"], ["71311.20", "0.410"], ["71321.70", "0.006"], ["71321.80", "0.140"], ["71349.20", "0.009"], ["71350.80", "0.006"], ["71356.30", "0.047"], ["71357.90", "0.003"], ["71363.40", "0.010"], ["71365.00", "0.506"], ["71370.50", "0.012"], ["71372.10", "0.000"], ["71377.60", "0.007"], ["71379.20", "0.132"], ["71384.70", "0.051"], ["71386.30", "0.000"], ["71391.80", "0.257"], ["71393.40", "0.001"], ["71398.90", "0.007"], ["71400.50", "0.006"], ["71988.40", "1.387"], ["72657.30", "0.014"], ["72955.30", "0.000"], ["74861.10", "0.007"], ["89523.20", "0.006"]]}}
