{"local_ts": 1773384583524, "server_ts": 1773384583304, "data": {"e": "depthUpdate", "E": 1773384583305, "T": 1773384583304, "s": "BTCUSDT", "U": 10101344456384, "u": 10101344493505, "pu": 10101344456258, "b": [["1000.00", "27.492"], ["5000.00", "101.418"], ["20724.20", "0.351"], ["20818.00", "0.045"], ["20818.20", "0.009"], ["20818.40", "0.009"], ["20818.60", "0.009"], ["20819.30", "0.009"], ["20819.80", "0.009"], ["20821.50", "0.009"], ["20822.00", "0.018"], ["20824.20", "0.738"], ["20924.20", "0.945"], ["21118.00", "0.027"], ["21118.50", "0.009"], ["21119.60", "0.009"], ["21121.50", "0.009"], ["21122.00", "0.009"], ["21124.20", "0.486"], ["33000.00", "9.339"], ["40000.00", "49.611"], ["67663.00", "0.013"], ["67856.40", "0.000"], ["68034.00", "0.009"], ["68211.70", "0.011"], ["68389.30", "0.013"], ["68566.90", "0.003"], ["68870.20", "0.000"], ["69047.70", "0.000"], ["69225.20", "0.000"], ["69402.70", "0.856"], ["70171.20", "1.351"], ["70221.50", "0.628"], ["70505.80", "0.009"], ["70506.00", "0.009"], ["70506.30", "0.000"], ["70506.40", "0.015"], ["70507.10", "0.019"], ["70507.30", "0.000"], ["70507.40", "0.000"], ["70507.60", "1.123"], ["70507.80", "0.035"], ["70509.30", "0.004"], ["70509.80", "0.003"], ["70512.00", "1.480"], ["70868.10", "0.007"], ["70916.00", "0.309"], ["70916.20", "0.302"], ["70918.20", "0.312"], ["70919.60", "0.309"], ["70919.80", "0.236"], ["70962.40", "0.001"], ["70983.50", "0.001"], ["70991.60", "0.154"], ["70998.10", "0.000"], ["71017.70", "0.047"], ["71027.90", "0.016"], ["71032.70", "0.000"], ["71040.50", "0.000"], ["71064.30", "0.327"], ["71068.60", "0.000"], ["71070.10", "0.020"], ["71071.00", "0.099"], ["71076.60", "0.733"], ["71077.70", "6.462"], ["71078.00", "0.023"], ["71080.10", "0.000"], ["71081.90", "0.154"], ["71082.70", "0.001"], ["71082.90", "0.002"], ["71086.70", "0.367"], ["71087.70", "2.357"], ["71089.80", "2.000"], ["71090.20", "0.181"], ["71096.80", "0.126"], ["71097.90", "0.078"], ["71101.80", "0.268"], ["71102.00", "1.200"], ["71103.90", "0.002"], ["71104.80", "0.000"], ["71105.40", "0.498"], ["71112.20", "0.014"], ["71112.90", "0.000"], ["71117.50", "2.830"], ["71118.30", "2.240"], ["71119.30", "0.002"], ["71120.30", "0.019"], ["71121.30", "4.106"], ["71122.20", "0.134"], ["71122.30", "0.340"], ["71122.70", "0.080"], ["71122.80", "0.002"], ["71123.00", "0.369"], ["71123.10", "0.000"], ["71123.20", "6.630"], ["71123.70", "0.944"], ["71123.80", "0.000"], ["71124.10", "0.158"], ["71124.20", "0.062"], ["71124.30", "0.002"], ["71124.70", "0.047"], ["71124.80", "0.000"], ["71124.90", "0.037"], ["71125.00", "0.262"], ["71125.10", "0.000"], ["71125.20", "0.078"], ["71125.30", "1.121"], ["71125.60", "0.292"], ["71125.70", "0.000"], ["71125.80", "0.040"], ["71126.00", "0.741"], ["71126.50", "0.351"], ["71126.70", "0.013"], ["71126.90", "0.005"], ["71127.00", "0.283"], ["71127.70", "0.562"], ["71127.80", "0.049"], ["71127.90", "0.002"], ["71128.20", "0.088"], ["71128.60", "0.014"], ["71128.90", "1.689"], ["71129.20", "0.000"], ["71129.70", "0.506"], ["71129.90", "0.042"], ["71130.10", "0.643"], ["71130.20", "0.000"], ["71130.30", "0.000"], ["71130.40", "0.124"], ["71130.70", "0.017"], ["71130.80", "0.121"], ["71131.10", "0.082"], ["71131.30", "0.000"], ["71131.70", "0.104"], ["71131.80", "0.208"], ["71132.30", "0.265"], ["71132.40", "0.070"], ["71132.50", "1.797"], ["71132.60", "0.022"], ["71132.70", "0.301"], ["71132.90", "0.002"], ["71133.10", "1.052"], ["71133.30", "0.033"], ["71133.40", "0.000"], ["71133.60", "0.000"], ["71133.70", "0.341"], ["71133.80", "0.000"], ["71134.00", "0.002"], ["71134.30", "0.005"], ["71134.40", "0.045"], ["71134.60", "0.000"], ["71134.80", "0.508"], ["71134.90", "1.200"], ["71135.10", "2.866"], ["71135.30", "0.000"], ["71135.40", "0.002"], ["71135.60", "0.022"], ["71135.80", "1.043"], ["71136.00", "0.018"], ["71136.20", "0.003"], ["71136.30", "0.303"], ["71136.40", "0.338"], ["71136.60", "0.004"], ["71136.90", "0.002"], ["71137.20", "0.000"], ["71137.30", "0.452"], ["71137.50", "0.002"], ["71137.60", "0.222"], ["71137.70", "0.004"], ["71138.20", "0.001"], ["71138.30", "0.007"], ["71139.00", "0.126"], ["71139.20", "0.012"], ["71139.50", "0.072"], ["71139.90", "0.004"], ["71140.00", "16.536"], ["71140.60", "0.000"], ["71140.90", "0.308"], ["71141.00", "0.025"], ["71141.50", "0.010"], ["71141.60", "0.002"], ["71141.90", "0.021"], ["71142.00", "0.177"], ["71142.30", "0.001"], ["71142.90", "0.049"], ["71143.00", "0.018"], ["71143.10", "0.000"], ["71143.30", "0.000"], ["71143.50", "0.051"], ["71143.70", "0.004"], ["71143.80", "0.075"], ["71144.00", "0.012"], ["71144.70", "0.008"], ["71144.80", "0.050"], ["71145.10", "0.018"], ["71145.30", "0.000"], ["71145.40", "0.213"], ["71145.70", "0.079"], ["71145.80", "0.144"], ["71146.40", "0.205"], ["71146.50", "0.140"], ["71146.60", "0.538"], ["71146.70", "0.033"], ["71146.80", "1.004"], ["71147.00", "0.009"], ["71147.30", "0.002"], ["71147.50", "0.309"], ["71147.70", "0.007"], ["71148.50", "0.003"], ["71148.60", "0.319"], ["71148.70", "0.000"], ["71148.90", "0.002"], ["71149.00", "0.008"], ["71149.10", "0.074"], ["71149.60", "0.002"], ["71150.00", "201.637"], ["71150.10", "0.510"], ["71150.30", "31.030"], ["71150.50", "0.041"], ["71150.60", "0.036"], ["71150.90", "0.000"], ["71151.00", "0.465"], ["71151.10", "0.196"], ["71151.50", "0.002"], ["71151.70", "0.306"], ["71151.80", "0.000"], ["71152.20", "0.002"], ["71152.30", "0.626"], ["71152.50", "0.002"], ["71152.80", "0.008"], ["71152.90", "0.083"], ["71153.00", "0.169"], ["71153.40", "0.001"], ["71153.50", "0.000"], ["71154.00", "0.080"], ["71154.40", "0.078"], ["71154.90", "0.000"], ["71155.40", "1.378"], ["71156.30", "1.678"], ["71156.40", "0.744"], ["71156.50", "0.002"], ["71157.30", "0.044"], ["71157.40", "0.042"], ["71157.60", "0.318"], ["71158.30", "0.029"], ["71158.60", "0.042"], ["71159.00", "0.023"], ["71159.20", "0.037"], ["71159.30", "0.550"], ["71159.60", "0.042"], ["71160.10", "0.001"], ["71160.30", "0.004"], ["71160.70", "0.000"], ["71161.00", "2.790"], ["71161.10", "0.007"], ["71161.20", "1.119"], ["71161.50", "0.120"], ["71161.80", "0.002"], ["71161.90", "0.011"], ["71162.10", "0.000"], ["71162.20", "0.000"], ["71162.40", "0.000"], ["71162.70", "0.044"], ["71163.20", "0.942"], ["71163.70", "0.122"], ["71164.00", "3.713"], ["71164.10", "1.736"], ["71164.40", "0.126"], ["71164.50", "0.419"], ["71164.70", "0.176"], ["71165.00", "0.032"], ["71165.40", "1.898"], ["71165.50", "0.348"], ["71165.60", "0.018"], ["71165.80", "0.126"], ["71165.90", "0.106"], ["71166.20", "0.592"], ["71166.50", "0.000"], ["71166.60", "0.070"], ["71166.90", "0.006"], ["71167.00", "0.007"], ["71167.20", "0.002"], ["71167.40", "0.081"], ["71167.50", "0.057"], ["71167.80", "0.002"], ["71167.90", "0.018"], ["71168.10", "0.004"], ["71168.50", "0.000"], ["71169.30", "0.318"], ["71169.40", "0.623"], ["71169.50", "0.506"], ["71170.30", "0.003"], ["71170.40", "0.006"], ["71171.10", "0.064"], ["71171.40", "0.000"], ["71171.50", "0.063"], ["71171.60", "0.342"], ["71171.70", "1.345"], ["71171.80", "0.646"], ["71171.90", "0.002"], ["71172.30", "0.509"], ["71172.40", "0.167"], ["71172.50", "0.012"], ["71172.60", "0.002"], ["71172.70", "0.214"], ["71172.90", "0.001"], ["71173.00", "0.074"], ["71173.30", "0.323"], ["71173.60", "0.000"], ["71174.20", "0.001"], ["71174.50", "0.506"], ["71174.60", "0.002"], ["71174.80", "0.000"], ["71175.00", "0.002"], ["71175.10", "0.002"], ["71175.20", "0.564"], ["71175.30", "0.387"], ["71175.40", "0.016"], ["71175.70", "0.056"], ["71175.80", "0.001"], ["71176.00", "0.004"], ["71176.40", "0.000"], ["71176.50", "0.000"], ["71176.60", "0.092"], ["71176.70", "0.177"], ["71177.00", "0.007"], ["71177.30", "0.357"], ["71177.40", "0.014"], ["71177.70", "0.008"], ["71178.10", "0.001"], ["71178.30", "0.335"], ["71178.40", "0.003"], ["71179.20", "0.010"], ["71179.70", "0.000"], ["71179.90", "0.000"], ["71180.70", "0.008"], ["71181.50", "0.002"], ["71182.50", "0.000"], ["71182.90", "0.060"], ["71183.10", "0.016"], ["71183.50", "0.019"], ["71183.60", "0.002"], ["71183.70", "0.073"], ["71183.90", "0.048"], ["71184.20", "0.753"], ["71185.00", "0.006"], ["71185.80", "0.005"], ["71185.90", "0.612"], ["71186.40", "0.005"], ["71186.50", "0.512"], ["71186.60", "0.020"], ["71186.80", "0.000"], ["71187.10", "0.006"], ["71187.20", "0.003"], ["71187.30", "1.128"], ["71187.80", "0.037"], ["71187.90", "0.023"], ["71188.00", "0.026"], ["71188.10", "0.311"], ["71188.20", "0.002"], ["71188.50", "1.987"], ["71188.60", "0.002"], ["71188.80", "0.002"], ["71188.90", "0.007"], ["71189.20", "0.001"], ["71189.30", "0.308"], ["71189.60", "0.002"], ["71189.70", "0.036"], ["71189.90", "0.074"], ["71190.20", "0.003"], ["71190.30", "0.281"], ["71190.60", "7.732"], ["71190.70", "0.311"], ["71190.80", "0.016"], ["71191.10", "0.077"], ["71191.20", "0.506"], ["71191.30", "1.354"], ["71191.40", "0.217"], ["71192.00", "0.006"], ["71192.10", "0.229"], ["71192.60", "0.284"], ["71192.70", "0.000"], ["71192.80", "0.311"], ["71193.00", "0.088"], ["71193.10", "0.105"], ["71193.20", "0.007"], ["71193.40", "0.324"], ["71193.50", "0.511"], ["71193.60", "0.001"], ["71193.70", "0.075"], ["71193.80", "0.000"], ["71193.90", "0.368"], ["71194.10", "0.562"], ["71194.20", "0.077"], ["71194.30", "0.000"], ["71194.50", "0.000"], ["71194.80", "0.000"], ["71194.90", "0.309"], ["71195.00", "0.187"], ["71195.10", "0.068"], ["71195.20", "0.016"], ["71195.30", "0.213"], ["71195.50", "0.003"], ["71195.60", "0.000"], ["71195.70", "0.138"], ["71195.80", "1.213"], ["71195.90", "0.791"], ["71196.20", "0.031"], ["71196.30", "0.507"], ["71196.40", "0.006"], ["71196.50", "0.004"], ["71196.60", "0.139"], ["71196.90", "0.002"], ["71197.00", "0.006"], ["71197.10", "0.410"], ["71197.20", "0.636"], ["71197.40", "0.122"], ["71197.50", "0.092"], ["71197.80", "0.280"], ["71197.90", "0.011"], ["71198.30", "0.000"], ["71198.40", "0.000"], ["71198.60", "0.006"], ["71198.70", "0.007"], ["71199.10", "0.209"], ["71199.20", "0.141"], ["71199.30", "0.000"], ["71199.40", "0.508"], ["71199.50", "0.001"], ["71199.70", "0.013"], ["71199.90", "0.002"], ["71200.20", "0.515"], ["71200.30", "0.074"], ["71200.40", "0.029"], ["71200.50", "0.002"], ["71200.60", "0.004"], ["71200.70", "0.001"], ["71201.00", "0.345"], ["71201.10", "0.002"], ["71201.30", "0.036"], ["71201.50", "0.000"], ["71201.60", "0.025"], ["71201.70", "0.006"], ["71201.90", "0.001"], ["71202.00", "0.006"], ["71202.10", "0.001"], ["71202.30", "0.023"], ["71202.40", "0.002"], ["71202.50", "0.300"], ["71202.60", "0.007"], ["71202.70", "0.000"], ["71202.80", "0.002"], ["71202.90", "0.003"], ["71203.00", "0.005"], ["71203.10", "0.334"], ["71203.50", "0.007"], ["71203.70", "0.108"], ["71203.90", "0.000"], ["71204.00", "0.008"], ["71204.10", "0.001"], ["71204.20", "0.506"], ["71204.30", "0.595"], ["71204.50", "0.117"], ["71204.60", "0.038"], ["71204.70", "0.000"], ["71204.80", "0.005"], ["71205.20", "0.003"], ["71205.30", "0.111"], ["71205.50", "0.004"], ["71205.70", "0.001"], ["71205.90", "0.069"], ["71206.10", "0.002"], ["71206.20", "0.003"], ["71206.40", "0.509"], ["71206.50", "0.004"], ["71207.00", "0.217"], ["71207.10", "0.179"], ["71207.50", "0.005"], ["71207.60", "0.007"], ["71208.00", "0.025"], ["71208.20", "0.002"], ["71208.40", "0.003"], ["71208.50", "0.000"], ["71208.70", "0.119"], ["71208.90", "0.018"], ["71209.00", "0.039"], ["71209.10", "0.035"], ["71209.20", "0.042"], ["71209.30", "0.008"], ["71209.40", "1.055"], ["71209.50", "0.004"], ["71209.60", "0.007"], ["71209.80", "0.336"], ["71209.90", "0.018"], ["71210.00", "0.009"], ["71210.30", "0.003"], ["71210.40", "0.166"], ["71210.50", "0.138"], ["71210.60", "0.000"], ["71210.80", "0.002"], ["71210.90", "0.001"], ["71211.00", "0.008"], ["71211.20", "0.253"], ["71211.30", "0.002"], ["71211.70", "0.002"], ["71212.00", "0.005"], ["71212.20", "0.007"], ["71212.30", "0.004"], ["71212.40", "0.003"], ["71212.60", "0.000"], ["71212.80", "0.042"], ["71212.90", "0.011"], ["71213.00", "0.221"], ["71213.10", "0.045"], ["71213.20", "0.002"], ["71213.40", "0.804"], ["71213.50", "0.000"], ["71213.60", "0.025"], ["71213.70", "0.038"], ["71213.80", "0.004"], ["71214.00", "0.063"], ["71214.10", "0.105"], ["71214.20", "0.000"], ["71214.40", "0.030"], ["71214.50", "0.002"], ["71214.60", "0.000"], ["71214.70", "0.025"], ["71214.80", "0.004"], ["71215.10", "0.250"], ["71215.20", "0.000"], ["71215.30", "0.006"], ["71215.40", "0.000"], ["71215.50", "0.000"], ["71215.60", "0.005"], ["71215.90", "0.012"], ["71216.00", "0.007"], ["71216.10", "0.002"], ["71216.20", "0.000"], ["71216.30", "0.000"], ["71216.50", "0.000"], ["71216.60", "0.003"], ["71216.90", "0.000"], ["71217.00", "0.003"], ["71217.10", "0.000"], ["71217.20", "0.000"], ["71217.30", "0.001"], ["71217.40", "0.000"], ["71217.60", "0.004"], ["71217.70", "0.000"], ["71217.80", "0.002"], ["71217.90", "0.000"], ["71218.00", "0.412"], ["71218.10", "0.000"], ["71218.20", "0.000"], ["71218.30", "0.000"], ["71218.40", "0.000"], ["71218.50", "0.000"], ["71218.60", "0.000"], ["71218.70", "0.000"], ["71218.80", "0.000"], ["71218.90", "0.000"], ["71219.10", "0.000"], ["71219.20", "0.000"], ["71219.30", "0.000"], ["71219.50", "0.000"], ["71219.60", "0.000"], ["71219.80", "0.000"], ["71219.90", "0.000"], ["71220.00", "0.000"], ["71220.10", "0.000"], ["71220.30", "0.000"], ["71220.40", "0.000"], ["71220.50", "0.000"], ["71220.60", "0.000"], ["71220.70", "0.000"], ["71220.80", "0.000"], ["71221.00", "0.000"], ["71221.20", "0.000"], ["71221.30", "0.000"], ["71221.40", "0.000"], ["71221.50", "0.000"], ["71221.60", "0.000"], ["71221.70", "0.000"], ["71221.90", "0.000"], ["71222.00", "0.000"], ["71222.40", "0.000"], ["71222.60", "0.000"], ["71222.70", "0.000"], ["71222.90", "0.000"], ["71223.00", "0.000"], ["71223.10", "0.000"], ["71223.40", "0.000"], ["71223.50", "0.000"], ["71223.70", "0.000"], ["71223.80", "0.000"], ["71224.00", "0.000"], ["71224.10", "0.000"], ["71224.20", "0.000"]], "a": [["71218.10", "8.257"], ["71218.20", "0.004"], ["71218.30", "1.219"], ["71218.40", "0.002"], ["71218.50", "0.426"], ["71218.60", "0.000"], ["71218.70", "0.000"], ["71218.80", "0.000"], ["71218.90", "0.002"], ["71219.00", "0.000"], ["71219.20", "0.000"], ["71219.30", "0.000"], ["71219.40", "0.210"], ["71219.50", "0.000"], ["71219.60", "0.000"], ["71219.70", "0.000"], ["71219.80", "0.000"], ["71219.90", "0.000"], ["71220.00", "0.005"], ["71220.10", "0.002"], ["71220.20", "0.000"], ["71220.30", "0.000"], ["71220.40", "0.000"], ["71220.50", "0.000"], ["71220.60", "0.002"], ["71220.70", "0.000"], ["71220.80", "0.003"], ["71221.10", "0.000"], ["71221.30", "0.003"], ["71221.40", "0.002"], ["71221.50", "0.116"], ["71221.60", "0.218"], ["71221.70", "0.153"], ["71221.80", "0.000"], ["71221.90", "0.003"], ["71222.00", "0.000"], ["71222.10", "0.005"], ["71222.20", "0.005"], ["71222.50", "0.003"], ["71222.60", "0.001"], ["71222.70", "0.000"], ["71222.80", "0.002"], ["71223.00", "0.001"], ["71223.10", "0.001"], ["71223.20", "0.002"], ["71223.30", "0.003"], ["71223.50", "0.001"], ["71223.60", "0.103"], ["71223.70", "0.001"], ["71223.80", "0.002"], ["71223.90", "0.001"], ["71224.00", "0.001"], ["71224.10", "0.005"], ["71224.20", "0.651"], ["71224.30", "0.364"], ["71224.40", "0.006"], ["71224.80", "0.007"], ["71224.90", "0.001"], ["71225.00", "0.055"], ["71225.20", "0.062"], ["71225.30", "0.009"], ["71225.50", "0.002"], ["71226.10", "0.002"], ["71226.30", "0.003"], ["71226.40", "0.003"], ["71226.70", "0.003"], ["71226.90", "0.005"], ["71227.00", "0.076"], ["71227.10", "0.074"], ["71228.00", "0.007"], ["71228.50", "0.003"], ["71228.60", "0.036"], ["71228.70", "0.120"], ["71229.50", "0.009"], ["71229.60", "0.081"], ["71229.70", "0.004"], ["71230.20", "0.283"], ["71230.30", "0.075"], ["71230.40", "0.017"], ["71230.50", "0.006"], ["71231.00", "0.004"], ["71231.20", "0.019"], ["71231.30", "0.000"], ["71231.40", "0.002"], ["71231.50", "0.207"], ["71231.60", "0.050"], ["71231.70", "0.018"], ["71232.00", "0.011"], ["71232.10", "0.047"], ["71232.20", "0.004"], ["71232.30", "0.038"], ["71232.50", "0.238"], ["71232.60", "0.002"], ["71232.70", "0.051"], ["71232.80", "0.023"], ["71232.90", "0.003"], ["71233.00", "0.059"], ["71233.30", "0.012"], ["71233.40", "0.015"], ["71233.50", "0.234"], ["71233.60", "0.154"], ["71233.70", "0.028"], ["71233.90", "0.002"], ["71234.10", "0.042"], ["71234.30", "0.009"], ["71234.40", "0.006"], ["71234.70", "0.117"], ["71234.90", "0.136"], ["71235.00", "0.024"], ["71235.20", "0.003"], ["71235.30", "0.000"], ["71235.40", "0.632"], ["71235.50", "0.009"], ["71235.60", "0.044"], ["71235.70", "0.026"], ["71236.00", "0.073"], ["71236.10", "0.078"], ["71236.40", "0.005"], ["71236.50", "0.003"], ["71236.60", "0.000"], ["71237.00", "0.009"], ["71237.10", "0.000"], ["71237.20", "0.019"], ["71237.30", "0.591"], ["71237.40", "0.294"], ["71237.50", "0.003"], ["71237.70", "0.114"], ["71237.80", "0.000"], ["71237.90", "0.212"], ["71238.10", "0.086"], ["71238.30", "0.341"], ["71238.50", "0.066"], ["71238.60", "0.128"], ["71238.70", "0.060"], ["71238.90", "0.069"], ["71239.00", "1.059"], ["71239.10", "0.083"], ["71239.30", "0.051"], ["71239.50", "0.007"], ["71239.70", "0.070"], ["71239.80", "0.020"], ["71239.90", "0.075"], ["71240.00", "0.298"], ["71240.10", "0.002"], ["71240.20", "0.000"], ["71240.50", "0.344"], ["71240.60", "0.000"], ["71240.70", "0.001"], ["71240.80", "0.003"], ["71241.00", "0.506"], ["71241.10", "0.003"], ["71241.30", "0.022"], ["71241.40", "0.009"], ["71241.50", "0.007"], ["71241.70", "0.070"], ["71241.90", "0.004"], ["71242.00", "0.058"], ["71242.10", "0.004"], ["71242.40", "0.005"], ["71242.50", "0.007"], ["71242.60", "0.006"], ["71243.00", "0.002"], ["71243.10", "0.061"], ["71243.20", "0.017"], ["71243.40", "0.247"], ["71243.50", "0.512"], ["71243.80", "0.013"], ["71244.00", "0.845"], ["71244.20", "0.088"], ["71244.30", "0.488"], ["71244.40", "0.503"], ["71244.50", "0.698"], ["71244.60", "0.004"], ["71244.80", "0.035"], ["71244.90", "0.006"], ["71245.00", "0.255"], ["71245.20", "0.002"], ["71245.30", "0.001"], ["71245.50", "0.007"], ["71245.60", "0.005"], ["71245.70", "0.000"], ["71245.90", "0.002"], ["71246.00", "0.013"], ["71246.10", "0.002"], ["71246.60", "0.002"], ["71246.70", "0.260"], ["71246.80", "0.422"], ["71246.90", "0.002"], ["71247.10", "0.006"], ["71247.40", "0.000"], ["71247.50", "0.004"], ["71247.90", "0.146"], ["71248.10", "0.005"], ["71248.20", "0.304"], ["71248.30", "0.002"], ["71248.50", "0.047"], ["71248.70", "0.927"], ["71248.80", "0.509"], ["71248.90", "0.001"], ["71249.10", "0.027"], ["71249.30", "0.000"], ["71249.40", "0.007"], ["71249.50", "0.006"], ["71249.60", "0.000"], ["71249.90", "0.315"], ["71250.00", "1.270"], ["71250.20", "0.015"], ["71250.30", "0.013"], ["71250.40", "0.035"], ["71250.50", "0.338"], ["71250.80", "0.070"], ["71250.90", "1.052"], ["71251.00", "0.002"], ["71251.60", "0.216"], ["71251.70", "0.002"], ["71252.00", "0.085"], ["71252.20", "0.310"], ["71252.30", "0.017"], ["71252.40", "0.001"], ["71252.50", "0.000"], ["71252.60", "0.002"], ["71252.70", "0.126"], ["71252.80", "0.056"], ["71253.00", "0.004"], ["71253.10", "0.005"], ["71253.30", "0.061"], ["71253.60", "0.005"], ["71253.70", "0.003"], ["71253.80", "0.002"], ["71254.00", "0.003"], ["71254.20", "0.002"], ["71254.40", "0.005"], ["71254.50", "0.002"], ["71254.60", "0.002"], ["71254.80", "0.003"], ["71255.00", "0.301"], ["71255.10", "0.215"], ["71255.20", "0.320"], ["71255.80", "0.715"], ["71255.90", "0.026"], ["71256.00", "0.002"], ["71256.10", "0.606"], ["71256.30", "0.000"], ["71256.40", "0.004"], ["71256.50", "0.004"], ["71256.60", "1.054"], ["71256.80", "0.006"], ["71256.90", "0.005"], ["71257.10", "0.087"], ["71257.30", "1.655"], ["71257.50", "0.123"], ["71258.00", "0.004"], ["71258.40", "0.767"], ["71258.50", "0.067"], ["71258.60", "0.005"], ["71258.70", "0.285"], ["71258.90", "0.003"], ["71259.00", "0.047"], ["71259.90", "0.000"], ["71260.00", "0.591"], ["71260.20", "0.002"], ["71260.30", "0.946"], ["71260.40", "0.024"], ["71260.60", "0.065"], ["71260.80", "0.027"], ["71261.10", "1.050"], ["71261.20", "0.000"], ["71261.30", "0.000"], ["71261.70", "0.353"], ["71262.50", "0.642"], ["71262.80", "0.002"], ["71263.40", "0.001"], ["71263.80", "0.000"], ["71263.90", "0.107"], ["71264.20", "0.142"], ["71264.70", "0.606"], ["71264.90", "0.004"], ["71265.20", "0.002"], ["71265.70", "0.002"], ["71266.00", "0.010"], ["71266.30", "0.053"], ["71266.60", "0.044"], ["71266.80", "0.376"], ["71267.00", "0.058"], ["71267.10", "0.000"], ["71267.70", "0.004"], ["71267.80", "0.100"], ["71267.90", "0.338"], ["71268.00", "0.010"], ["71268.10", "0.005"], ["71268.20", "0.508"], ["71269.00", "0.002"], ["71269.30", "0.003"], ["71269.50", "0.007"], ["71269.60", "0.000"], ["71269.80", "0.057"], ["71270.00", "0.007"], ["71270.20", "0.004"], ["71270.80", "0.000"], ["71270.90", "0.000"], ["71271.50", "0.783"], ["71271.60", "0.007"], ["71271.70", "0.020"], ["71271.90", "0.103"], ["71272.20", "0.140"], ["71272.30", "0.000"], ["71272.40", "0.013"], ["71272.70", "0.085"], ["71272.80", "0.750"], ["71272.90", "0.002"], ["71273.10", "0.085"], ["71273.20", "0.830"], ["71273.30", "0.312"], ["71273.50", "0.220"], ["71273.60", "0.002"], ["71273.70", "0.000"], ["71273.80", "1.897"], ["71273.90", "0.432"], ["71274.10", "0.002"], ["71274.20", "0.070"], ["71274.30", "0.000"], ["71274.50", "1.396"], ["71275.00", "0.048"], ["71275.10", "0.050"], ["71275.20", "0.003"], ["71275.30", "0.006"], ["71275.40", "0.347"], ["71275.50", "0.411"], ["71275.80", "0.004"], ["71276.20", "0.036"], ["71276.90", "0.506"], ["71277.50", "0.048"], ["71277.60", "0.104"], ["71278.60", "0.191"], ["71279.20", "0.217"], ["71279.80", "0.441"], ["71279.90", "6.405"], ["71280.50", "0.002"], ["71280.60", "0.002"], ["71281.10", "0.000"], ["71282.20", "0.113"], ["71282.60", "0.613"], ["71283.00", "0.000"], ["71283.80", "0.002"], ["71284.70", "0.202"], ["71285.10", "0.108"], ["71285.40", "0.000"], ["71285.80", "0.199"], ["71286.20", "0.004"], ["71287.10", "0.002"], ["71287.20", "0.045"], ["71288.50", "0.013"], ["71288.80", "0.379"], ["71289.30", "1.007"], ["71289.40", "0.306"], ["71289.50", "0.002"], ["71290.10", "0.000"], ["71290.70", "0.000"], ["71290.90", "0.407"], ["71291.70", "0.034"], ["71291.90", "0.297"], ["71292.40", "0.000"], ["71292.70", "0.506"], ["71292.90", "0.005"], ["71294.10", "0.079"], ["71294.20", "0.067"], ["71294.80", "0.003"], ["71294.90", "1.052"], ["71295.50", "0.000"], ["71296.10", "0.060"], ["71296.60", "0.000"], ["71297.40", "0.053"], ["71297.80", "0.084"], ["71297.90", "0.000"], ["71298.60", "0.004"], ["71299.10", "0.506"], ["71300.60", "0.002"], ["71301.50", "0.000"], ["71301.70", "1.359"], ["71303.40", "0.070"], ["71303.60", "2.006"], ["71303.70", "6.764"], ["71304.00", "0.004"], ["71304.30", "0.011"], ["71304.90", "0.003"], ["71305.40", "0.168"], ["71306.40", "0.003"], ["71307.00", "0.014"], ["71308.60", "0.001"], ["71309.20", "0.113"], ["71310.50", "0.026"], ["71310.80", "0.041"], ["71311.40", "0.004"], ["71312.30", "0.004"], ["71312.50", "0.720"], ["71313.20", "0.002"], ["71313.30", "0.002"], ["71313.60", "0.000"], ["71314.20", "0.103"], ["71314.40", "0.139"], ["71314.50", "0.000"], ["71314.70", "0.554"], ["71314.80", "0.619"], ["71315.50", "0.549"], ["71315.70", "0.241"], ["71316.20", "0.002"], ["71316.90", "0.004"], ["71317.30", "0.157"], ["71317.40", "0.000"], ["71317.70", "0.218"], ["71317.80", "2.000"], ["71318.00", "0.353"], ["71318.60", "0.002"], ["71318.80", "6.441"], ["71323.20", "0.002"], ["71323.70", "0.014"], ["71326.80", "2.449"], ["71331.20", "2.096"], ["71331.90", "0.411"], ["71332.50", "0.581"], ["71332.80", "0.122"], ["71333.00", "0.161"], ["71337.30", "0.002"], ["71340.00", "0.186"], ["71342.10", "0.200"], ["71343.10", "0.001"], ["71345.20", "0.003"], ["71346.30", "2.103"], ["71346.70", "0.003"], ["71346.90", "0.002"], ["71353.90", "0.256"], ["71354.00", "0.042"], ["71355.10", "0.100"], ["71359.60", "0.018"], ["71361.30", "0.024"], ["71362.80", "0.000"], ["71363.90", "0.005"], ["71365.40", "0.004"], ["71367.80", "0.099"], ["71371.60", "0.002"], ["71371.80", "0.563"], ["71372.40", "2.788"], ["71372.80", "2.307"], ["71374.70", "0.000"], ["71375.40", "0.012"], ["71378.30", "0.284"], ["71381.90", "0.040"], ["71383.10", "0.015"], ["71383.20", "0.506"], ["71384.60", "0.088"], ["71385.50", "0.545"], ["71386.80", "0.080"], ["71389.90", "0.000"], ["71390.50", "0.008"], ["71390.60", "0.866"], ["71391.80", "1.963"], ["71398.00", "0.016"], ["71399.70", "1.816"], ["71400.20", "0.000"], ["71403.60", "0.004"], ["71403.70", "0.000"], ["71405.20", "0.001"], ["71405.90", "0.000"], ["71409.50", "0.000"], ["71410.20", "0.003"], ["71418.00", "2.541"], ["71418.30", "10.002"], ["71419.30", "0.000"], ["71423.50", "0.284"], ["71428.00", "0.009"], ["71429.10", "0.311"], ["71431.40", "0.282"], ["71434.90", "0.002"], ["71445.80", "1.299"], ["71447.20", "0.000"], ["71458.50", "0.002"], ["71480.90", "0.200"], ["71483.80", "0.394"], ["71523.10", "0.000"], ["71532.30", "0.380"], ["71533.10", "0.000"], ["71645.50", "0.000"], ["71850.40", "0.000"], ["71930.30", "0.081"], ["71930.50", "0.000"], ["71930.80", "0.000"], ["71931.50", "0.000"], ["71931.60", "0.000"], ["71932.10", "0.000"], ["71933.80", "0.010"], ["71934.30", "0.000"], ["71936.50", "2.351"], ["72206.60", "0.000"], ["72206.70", "0.000"], ["72206.80", "0.033"], ["72209.50", "0.003"], ["72211.60", "0.000"], ["72218.10", "0.004"], ["72218.50", "0.073"], ["72219.40", "0.002"], ["72219.60", "0.569"], ["72221.60", "0.012"], ["72222.10", "0.052"], ["72223.90", "0.002"], ["72226.50", "0.000"], ["72228.60", "0.002"], ["72230.70", "0.015"], ["72281.30", "0.008"], ["72642.40", "0.003"], ["74816.50", "0.050"], ["100000.00", "15.554"]]}}
{"local_ts": 1773384584546, "server_ts": 1773384584328, "data": {"e": "depthUpdate", "E": 1773384584331, "T": 1773384584328, "s": "BTCUSDT", "U": 10101344561127, "u": 10101344565354, "pu": 10101344561091, "b": [["5000.00", "101.418"], ["20715.80", "0.594"], ["20824.20", "0.144"], ["21015.80", "0.423"], ["21124.20", "0.063"], ["70361.20", "1.134"], ["70503.60", "0.000"], ["70915.20", "0.063"], ["70916.30", "0.162"], ["71098.10", "0.508"], ["71101.40", "0.042"], ["71101.50", "0.135"], ["71101.80", "0.293"], ["71102.50", "11.289"], ["71166.20", "0.453"], ["71166.40", "0.186"], ["71169.10", "0.215"], ["71169.20", "0.007"], ["71173.00", "0.125"], ["71175.70", "0.005"], ["71188.00", "0.096"], ["71189.90", "0.006"], ["71192.60", "0.002"], ["71194.80", "0.007"], ["71195.20", "0.649"], ["71195.60", "0.338"], ["71195.90", "0.509"], ["71196.70", "0.006"], ["71197.20", "0.005"], ["71198.30", "0.002"], ["71198.60", "0.007"], ["71199.00", "0.005"], ["71202.40", "0.338"], ["71204.30", "0.031"], ["71208.80", "0.000"], ["71210.80", "0.283"], ["71212.90", "0.011"], ["71214.80", "0.006"], ["71215.80", "3.069"]], "a": [["71215.90", "7.979"], ["71221.40", "0.069"], ["71221.50", "0.072"], ["71223.10", "0.008"], ["71223.70", "0.002"], ["71230.90", "0.004"], ["71232.20", "0.655"], ["71235.10", "0.000"], ["71237.30", "0.404"], ["71238.20", "0.004"], ["71240.40", "0.252"], ["71243.10", "0.148"], ["71259.10", "0.507"], ["71259.70", "0.002"], ["71260.50", "0.123"], ["71266.80", "0.454"], ["71272.70", "0.006"], ["71287.10", "0.083"], ["71290.70", "0.040"], ["71302.80", "0.004"], ["71312.30", "0.002"], ["71315.60", "0.537"], ["71324.50", "0.078"], ["71324.80", "0.000"], ["71336.30", "0.040"], ["71344.90", "4.544"], ["71396.00", "0.426"], ["71526.00", "0.074"], ["71921.40", "0.016"], ["71928.10", "0.000"], ["72887.90", "0.054"], ["74780.00", "0.171"]]}}
{"local_ts": 1773384585567, "server_ts": 1773384585350, "data": {"e": "depthUpdate", "E": 1773384585351, "T": 1773384585350, "s": "BTCUSDT", "U": 10101344661190, "u": 10101344666831, "pu": 10101344661147, "b": [["1000.00", "27.492"], ["5000.00", "101.418"], ["20715.80", "1.476"], ["20815.80", "0.000"], ["20915.80", "0.288"], ["21015.80", "0.612"], ["21115.80", "0.324"], ["33000.00", "9.343"], ["67627.90", "0.002"], ["70126.80", "0.002"], ["70503.60", "0.000"], ["70859.70", "0.000"], ["71128.20", "1.309"], ["71128.40", "0.511"], ["71139.70", "0.018"], ["71150.50", "0.310"], ["71153.90", "0.215"], ["71164.10", "0.000"], ["71166.20", "0.000"], ["71166.30", "0.000"], ["71166.40", "0.044"], ["71169.50", "0.506"], ["71169.70", "0.325"], ["71170.00", "0.314"], ["71195.50", "0.005"], ["71195.80", "0.289"], ["71197.40", "0.124"], ["71198.40", "0.106"], ["71204.30", "0.031"], ["71209.70", "1.790"], ["71210.80", "0.481"], ["71211.00", "0.514"], ["71211.10", "0.000"], ["71212.70", "0.008"], ["71212.90", "0.011"]], "a": [["71216.60", "0.002"], ["71217.30", "0.001"], ["71221.50", "0.074"], ["71234.40", "0.008"], ["71251.50", "0.742"], ["71265.20", "0.004"], ["71265.30", "0.205"], ["71269.30", "0.162"], ["71272.90", "0.807"], ["71282.20", "0.032"], ["71290.70", "0.121"], ["71294.20", "0.148"], ["71296.50", "0.284"], ["71299.70", "0.202"], ["71302.80", "0.002"], ["71320.90", "0.303"], ["71324.50", "0.076"], ["71331.20", "3.206"], ["71334.30", "0.505"], ["71337.30", "0.004"], ["71340.50", "0.002"], ["71381.80", "0.552"], ["71382.50", "0.000"], ["71399.00", "2.744"], ["71399.80", "0.000"], ["71399.90", "0.094"], ["71406.00", "1.545"], ["71408.20", "0.164"], ["71411.70", "0.162"], ["72274.40", "0.000"], ["72294.30", "0.828"]]}}
{"local_ts": 1773384586591, "server_ts": 1773384586374, "data": {"e": "depthUpdate", "E": 1773384586375, "T": 1773384586374, "s": "BTCUSDT", "U": 10101344724374, "u": 10101344732449, "pu": 10101344724288, "b": [["5000.00", "101.418"], ["20715.80", "0.090"], ["20815.80", "0.153"], ["20915.80", "0.747"], ["21015.80", "0.153"], ["21115.80", "1.557"], ["67632.60", "0.000"], ["70503.60", "0.000"], ["70914.60", "0.306"], ["71113.70", "2.517"], ["71136.00", "0.518"], ["71139.60", "1.202"], ["71142.70", "0.849"], ["71144.10", "0.000"], ["71144.20", "0.073"], ["71150.50", "0.041"], ["71150.60", "0.000"], ["71151.90", "0.184"], ["71163.30", "1.098"], ["71169.80", "0.019"], ["71169.90", "0.005"], ["71195.60", "0.001"], ["71200.70", "0.071"], ["71201.90", "0.003"], ["71202.40", "0.002"], ["71205.10", "0.026"], ["71205.50", "0.002"], ["71205.90", "0.002"], ["71208.70", "0.047"], ["71211.00", "0.516"], ["71211.10", "0.004"], ["71212.90", "0.015"], ["71215.80", "0.224"]], "a": [["71215.90", "8.928"], ["71216.60", "0.000"], ["71216.70", "0.002"], ["71217.30", "0.003"], ["71222.10", "0.005"], ["71223.00", "0.089"], ["71230.60", "0.006"], ["71241.90", "0.002"], ["71247.90", "0.243"], ["71258.80", "0.745"], ["71259.10", "0.003"], ["71268.50", "0.002"], ["71268.90", "0.277"], ["71287.10", "0.002"], ["71298.80", "0.002"], ["71299.70", "0.200"], ["71319.80", "2.076"], ["71370.00", "2.300"], ["71395.40", "0.243"], ["71460.10", "0.702"], ["71928.10", "0.000"], ["72392.00", "0.005"], ["74803.50", "0.134"]]}}
{"local_ts": 1773384587621, "server_ts": 1773384587396, "data": {"e": "depthUpdate", "E": 1773384587399, "T": 1773384587396, "s": "BTCUSDT", "U": 10101344802345, "u": 10101344811827, "pu": 10101344802168, "b": [["1000.00", "27.492"], ["5000.00", "101.418"], ["20715.80", "0.018"], ["20815.80", "0.882"], ["20915.80", "0.027"], ["21015.80", "1.548"], ["21115.80", "0.225"], ["67627.60", "0.000"], ["67639.70", "0.002"], ["69215.80", "0.008"], ["70503.60", "0.000"], ["71119.70", "0.070"], ["71120.00", "16.168"], ["71126.80", "0.113"], ["71127.10", "0.115"], ["71133.90", "0.308"], ["71134.20", "0.317"], ["71151.80", "0.269"], ["71151.90", "0.000"], ["71153.10", "1.102"], ["71165.90", "0.205"], ["71168.20", "0.751"], ["71169.70", "0.325"], ["71169.80", "0.017"], ["71180.20", "0.123"], ["71181.00", "0.311"], ["71191.60", "0.023"], ["71194.00", "0.002"], ["71194.40", "0.341"], ["71198.00", "0.146"], ["71201.00", "0.689"], ["71205.30", "0.111"], ["71209.90", "0.004"], ["71211.10", "0.002"], ["71212.30", "0.108"], ["71212.50", "0.001"]], "a": [["71215.90", "8.011"], ["71216.60", "0.002"], ["71216.70", "0.058"], ["71217.30", "0.001"], ["71233.50", "0.330"], ["71234.80", "0.506"], ["71235.20", "0.005"], ["71236.10", "0.085"], ["71236.90", "0.140"], ["71237.60", "0.017"], ["71238.20", "0.004"], ["71240.20", "0.505"], ["71251.50", "0.811"], ["71265.20", "0.002"], ["71265.50", "0.022"], ["71287.10", "0.083"], ["71298.10", "0.478"], ["71298.80", "0.000"], ["71300.10", "0.210"], ["71305.20", "0.004"], ["71385.40", "5.385"], ["71442.30", "0.058"], ["71928.10", "0.139"], ["72295.30", "0.413"]]}}
{"local_ts": 1773384588640, "server_ts": 1773384588421, "data": {"e": "depthUpdate", "E": 1773384588423, "T": 1773384588421, "s": "BTCUSDT", "U": 10101344862472, "u": 10101344867026, "pu": 10101344862277, "b": [["1000.00", "27.492"], ["5000.00", "101.418"], ["20715.80", "0.792"], ["20815.80", "0.108"], ["20915.80", "1.332"], ["21015.80", "0.468"], ["56973.00", "0.000"], ["67630.90", "0.000"], ["69794.40", "0.613"], ["70859.70", "0.000"], ["71077.90", "0.072"], ["71119.90", "0.110"], ["71122.60", "0.176"], ["71123.60", "0.303"], ["71127.00", "0.353"], ["71129.70", "0.646"], ["71130.70", "0.017"], ["71134.10", "0.143"], ["71136.80", "0.281"], ["71137.80", "0.239"], ["71151.80", "0.000"], ["71209.90", "0.004"]], "a": [["71230.60", "0.035"], ["71262.70", "0.014"], ["71262.90", "0.024"], ["71266.10", "0.003"], ["71293.90", "0.145"], ["71295.80", "0.001"], ["71298.10", "0.478"], ["71301.00", "0.128"], ["71302.90", "0.001"], ["71305.20", "0.004"], ["71379.60", "0.541"], ["71401.10", "0.001"], ["71928.10", "0.139"], ["72141.70", "0.839"], ["72642.40", "0.003"], ["74786.00", "0.111"]]}}
{"local_ts": 1773384589659, "server_ts": 1773384589440, "data": {"e": "depthUpdate", "E": 1773384589443, "T": 1773384589440, "s": "BTCUSDT", "U": 10101344921436, "u": 10101344927314, "pu": 10101344921301, "b": [["5000.00", "101.418"], ["20715.80", "0.243"], ["20815.80", "1.062"], ["20915.80", "0.738"], ["21115.80", "0.657"], ["56973.00", "0.000"], ["67643.50", "0.002"], ["69423.90", "2.590"], ["69474.20", "0.616"], ["69794.60", "0.004"], ["70503.60", "0.000"], ["71067.30", "0.000"], ["71170.20", "0.303"], ["71170.30", "0.188"], ["71208.00", "0.006"], ["71212.60", "0.000"], ["71213.50", "0.210"], ["71215.70", "0.004"], ["71215.80", "1.453"]], "a": [["71215.90", "5.126"], ["71221.70", "0.005"], ["71253.60", "0.007"], ["71262.90", "0.024"], ["71263.00", "0.253"], ["71265.30", "0.207"], ["71265.40", "0.002"], ["71321.60", "0.165"], ["71364.00", "0.074"], ["71404.60", "0.000"], ["71407.70", "0.043"], ["71928.10", "0.139"], ["72255.70", "9.067"], ["72307.90", "0.002"]]}}
{"local_ts": 1773384590683, "server_ts": 1773384590462, "data": {"e": "depthUpdate", "E": 1773384590465, "T": 1773384590462, "s": "BTCUSDT", "U": 10101344988939, "u": 10101345003830, "pu": 10101344988886, "b": [["1000.00", "27.492"], ["5000.00", "101.418"], ["20715.80", "0.792"], ["20815.80", "1.008"], ["21015.80", "0.522"], ["21115.80", "0.378"], ["56973.00", "0.000"], ["67620.40", "0.000"], ["69794.60", "0.002"], ["70503.70", "0.000"], ["70859.70", "0.035"], ["70964.30", "0.011"], ["70966.40", "6.477"], ["71101.20", "0.291"], ["71122.30", "0.123"], ["71131.70", "0.140"], ["71134.30", "0.149"], ["71135.00", "6.549"], ["71135.70", "0.019"], ["71146.40", "1.405"], ["71153.60", "1.189"], ["71170.10", "0.019"], ["71170.20", "0.303"], ["71180.20", "0.095"], ["71197.40", "0.315"], ["71198.20", "0.000"], ["71206.10", "0.184"], ["71206.40", "0.064"], ["71206.70", "0.028"], ["71207.90", "0.040"], ["71208.70", "0.075"], ["71212.60", "0.000"], ["71213.40", "0.006"], ["71215.80", "1.105"]], "a": [["71223.00", "0.149"], ["71223.50", "0.000"], ["71229.40", "0.187"], ["71229.60", "0.185"], ["71230.00", "0.412"], ["71241.00", "1.013"], ["71244.00", "0.380"], ["71245.10", "1.052"], ["71251.50", "0.795"], ["71265.20", "0.047"], ["71265.90", "0.266"], ["71267.00", "0.137"], ["71271.90", "0.200"], ["71301.10", "0.173"], ["71301.70", "1.625"], ["71304.40", "0.081"], ["71313.80", "0.097"], ["71442.50", "0.320"], ["71442.60", "0.269"], ["71928.00", "0.069"], ["71928.10", "0.139"], ["72225.50", "0.000"], ["72383.90", "0.000"], ["89523.20", "0.000"]]}}
{"local_ts": 1773384591708, "server_ts": 1773384591484, "data": {"e": "depthUpdate", "E": 1773384591485, "T": 1773384591484, "s": "BTCUSDT", "U": 10101345075209, "u": 10101345081946, "pu": 10101345075000, "b": [["5000.00", "101.418"], ["20715.80", "1.269"], ["20915.80", "0.387"], ["21015.80", "0.513"], ["21115.80", "0.531"], ["56973.00", "0.004"], ["67635.70", "0.000"], ["67646.90", "0.002"], ["69084.90", "0.002"], ["69791.30", "0.024"], ["70286.30", "0.000"], ["70503.60", "1.487"], ["70964.30", "0.011"], ["71052.10", "4.820"], ["71205.80", "0.154"], ["71208.00", "0.006"], ["71208.70", "0.075"], ["71213.40", "0.006"], ["71215.80", "1.020"]], "a": [["71223.00", "0.149"], ["71247.90", "0.303"], ["71258.80", "0.684"], ["71290.90", "1.806"], ["71317.70", "0.003"], ["71928.10", "1.527"], ["72312.10", "0.000"], ["72374.40", "0.977"], ["72997.60", "0.397"], ["89523.20", "0.000"]]}}
{"local_ts": 1773384592724, "server_ts": 1773384592505, "data": {"e": "depthUpdate", "E": 1773384592507, "T": 1773384592505, "s": "BTCUSDT", "U": 10101345131024, "u": 10101345135755, "pu": 10101345130949, "b": [["1000.00", "27.492"], ["5000.00", "101.418"], ["20715.80", "0.000"], ["20815.80", "0.252"], ["20915.80", "0.648"], ["21015.80", "0.261"], ["21115.80", "1.539"], ["33000.00", "9.339"], ["56973.00", "0.000"], ["67634.40", "0.002"], ["67636.50", "0.002"], ["67655.00", "0.058"], ["69791.30", "0.022"], ["70503.60", "1.487"], ["70964.30", "0.009"], ["70964.60", "0.002"], ["71067.50", "0.000"], ["71067.60", "0.604"], ["71119.90", "0.110"], ["71127.00", "0.353"], ["71134.10", "0.143"], ["71180.20", "0.095"], ["71201.60", "0.064"], ["71208.70", "0.075"], ["71213.40", "0.006"]], "a": [["71216.10", "0.216"], ["71223.00", "0.150"], ["71251.50", "0.795"], ["71262.90", "0.024"], ["71264.60", "0.011"], ["71269.60", "0.565"], ["71298.00", "1.174"], ["71305.10", "0.004"], ["71363.40", "0.538"], ["71566.60", "0.000"], ["71928.10", "1.527"], ["72462.60", "0.692"], ["89523.20", "0.000"]]}}
{"local_ts": 1773384593747, "server_ts": 1773384593528, "data": {"e": "depthUpdate", "E": 1773384593531, "T": 1773384593528, "s": "BTCUSDT", "U": 10101345186173, "u": 10101345191840, "pu": 10101345186122, "b": [["1000.00", "27.492"], ["5000.00", "101.418"], ["20715.80", "0.117"], ["20815.80", "0.783"], ["20915.80", "0.126"], ["21015.80", "1.548"], ["21115.80", "0.126"], ["21115.90", "0.007"], ["67633.70", "0.002"], ["69794.90", "0.006"], ["70503.60", "1.487"], ["70859.70", "0.061"], ["70859.80", "0.035"], ["70963.50", "0.308"], ["70964.60", "0.000"], ["71119.90", "0.112"], ["71122.90", "0.000"], ["71123.00", "0.509"], ["71127.00", "0.353"], ["71130.00", "16.027"], ["71130.10", "0.783"], ["71134.10", "0.143"], ["71136.00", "0.543"], ["71137.10", "0.096"], ["71137.20", "0.140"], ["71137.50", "0.005"], ["71151.70", "0.309"], ["71197.20", "0.007"], ["71198.00", "0.007"], ["71205.30", "0.111"], ["71209.90", "0.000"], ["71210.80", "0.243"], ["71211.00", "0.008"], ["71212.50", "0.001"], ["71212.60", "0.338"], ["71215.80", "0.689"]], "a": [["71215.90", "4.184"], ["71216.00", "0.007"], ["71226.60", "0.186"], ["71263.00", "0.253"], ["71264.60", "0.032"], ["71280.00", "0.172"], ["71294.00", "0.184"], ["71294.30", "0.004"], ["71298.00", "1.174"], ["71301.10", "0.173"], ["71305.10", "0.004"], ["71928.10", "1.527"], ["72227.20", "1.660"], ["72341.00", "0.005"], ["72413.60", "0.000"], ["89523.20", "0.000"]]}}
{"local_ts": 1773384594769, "server_ts": 1773384594550, "data": {"e": "depthUpdate", "E": 1773384594551, "T": 1773384594550, "s": "BTCUSDT", "U": 10101345235450, "u": 10101345239800, "pu": 10101345235422, "b": [["5000.00", "101.398"], ["20715.80", "0.882"], ["20815.80", "0.018"], ["20915.80", "1.530"], ["21015.80", "0.270"], ["33000.00", "9.343"], ["56973.00", "0.000"], ["67620.80", "0.000"], ["69791.50", "0.015"], ["70347.50", "0.002"], ["70503.60", "1.487"], ["70962.80", "0.002"], ["70963.50", "0.306"], ["71169.80", "0.017"], ["71169.90", "0.005"], ["71194.80", "0.184"], ["71213.40", "0.006"]], "a": [["71215.90", "4.177"], ["71216.70", "0.005"], ["71223.70", "0.002"], ["71246.80", "0.424"], ["71254.40", "0.950"], ["71262.70", "0.033"], ["71264.40", "0.571"], ["71290.70", "0.040"], ["71442.60", "0.269"], ["71928.00", "0.076"], ["71928.10", "1.527"], ["72141.70", "1.670"], ["72500.00", "158.122"], ["73320.70", "0.158"], ["74803.40", "0.068"], ["89523.20", "0.000"]]}}
{"local_ts": 1773384595788, "server_ts": 1773384595569, "data": {"e": "depthUpdate", "E": 1773384595571, "T": 1773384595569, "s": "BTCUSDT", "U": 10101345292741, "u": 10101345312309, "pu": 10101345292554, "b": [["1000.00", "27.492"], ["5000.00", "101.458"], ["20715.80", "0.153"], ["20815.80", "1.260"], ["20915.80", "0.540"], ["21115.80", "0.747"], ["56973.00", "0.000"], ["67621.30", "0.005"], ["69791.50", "0.018"], ["70503.60", "1.487"], ["70859.70", "0.061"], ["70962.80", "0.000"], ["71123.80", "0.002"], ["71159.80", "0.004"], ["71160.80", "0.013"], ["71163.40", "0.455"], ["71165.90", "0.106"], ["71166.40", "0.002"], ["71167.40", "0.081"], ["71169.10", "0.213"], ["71169.70", "0.325"], ["71169.80", "0.015"], ["71170.30", "0.003"], ["71170.40", "0.006"], ["71176.00", "0.006"], ["71179.20", "0.010"], ["71186.70", "0.024"], ["71186.80", "0.070"], ["71186.90", "0.083"], ["71187.30", "1.198"], ["71187.90", "0.007"], ["71188.00", "0.096"], ["71189.50", "0.000"], ["71189.70", "0.116"], ["71190.00", "0.036"], ["71192.50", "0.000"], ["71192.60", "0.009"], ["71194.00", "0.002"], ["71194.20", "1.775"], ["71194.40", "0.478"], ["71194.70", "0.041"], ["71195.00", "0.184"], ["71195.40", "0.000"], ["71195.50", "0.637"], ["71195.60", "0.003"], ["71196.00", "0.005"], ["71196.30", "0.142"], ["71196.50", "0.284"], ["71197.00", "0.004"], ["71197.30", "1.049"], ["71197.40", "0.265"], ["71197.60", "0.002"], ["71197.80", "0.000"], ["71198.00", "0.146"], ["71198.60", "0.007"], ["71200.90", "0.029"], ["71201.00", "0.987"], ["71201.50", "0.002"], ["71201.80", "0.000"], ["71201.90", "0.509"], ["71202.10", "0.001"], ["71203.60", "0.048"], ["71203.70", "1.059"], ["71204.20", "0.003"], ["71204.30", "0.551"], ["71204.60", "0.037"], ["71206.60", "0.096"], ["71206.70", "0.534"], ["71206.80", "0.037"], ["71206.90", "0.343"], ["71207.20", "0.151"], ["71208.80", "0.000"], ["71208.90", "0.003"], ["71209.10", "0.003"], ["71209.20", "0.006"], ["71209.60", "0.056"], ["71210.80", "0.111"], ["71211.00", "0.029"], ["71211.60", "0.009"], ["71211.80", "0.003"], ["71212.30", "0.002"], ["71212.70", "0.008"], ["71212.80", "0.074"], ["71213.50", "0.000"], ["71213.80", "0.004"], ["71214.20", "0.000"], ["71215.10", "0.003"], ["71215.70", "0.000"], ["71215.80", "0.179"]], "a": [["71215.90", "4.564"], ["71216.60", "0.070"], ["71217.30", "0.010"], ["71219.40", "0.002"], ["71220.10", "0.003"], ["71220.50", "0.010"], ["71221.40", "0.005"], ["71222.90", "0.647"], ["71223.00", "0.450"], ["71223.70", "0.683"], ["71224.10", "0.085"], ["71226.00", "0.062"], ["71226.30", "0.003"], ["71226.50", "0.018"], ["71226.90", "0.725"], ["71227.70", "0.015"], ["71227.80", "0.000"], ["71228.50", "0.068"], ["71229.00", "0.049"], ["71229.10", "0.000"], ["71229.80", "0.069"], ["71230.00", "0.732"], ["71230.10", "0.036"], ["71230.30", "0.106"], ["71230.60", "0.041"], ["71230.70", "0.012"], ["71230.90", "0.049"], ["71231.10", "0.102"], ["71231.70", "0.046"], ["71232.20", "0.163"], ["71232.60", "0.340"], ["71232.70", "0.000"], ["71233.00", "0.099"], ["71233.10", "0.051"], ["71233.20", "0.014"], ["71234.10", "0.000"], ["71234.70", "0.120"], ["71235.10", "0.000"], ["71235.50", "0.029"], ["71236.30", "0.075"], ["71237.30", "0.404"], ["71238.90", "0.262"], ["71241.90", "0.002"], ["71243.10", "0.092"], ["71244.40", "0.561"], ["71245.10", "1.051"], ["71247.90", "0.575"], ["71251.50", "0.802"], ["71264.10", "0.005"], ["71264.30", "0.135"], ["71269.30", "0.261"], ["71272.70", "0.210"], ["71272.90", "1.179"], ["71273.90", "0.417"], ["71275.10", "0.002"], ["71278.70", "0.424"], ["71282.20", "0.002"], ["71284.20", "0.000"], ["71284.80", "0.004"], ["71385.50", "2.085"], ["71389.00", "1.614"], ["71399.70", "0.078"], ["71403.30", "0.000"], ["71928.10", "1.527"], ["72640.20", "0.003"], ["89523.20", "0.000"], ["100000.00", "15.554"]]}}
{"local_ts": 1773384596811, "server_ts": 1773384596588, "data": {"e": "depthUpdate", "E": 1773384596591, "T": 1773384596588, "s": "BTCUSDT", "U": 10101345420954, "u": 10101345425551, "pu": 10101345420893, "b": [["5000.00", "101.418"], ["20710.50", "0.729"], ["20815.80", "0.324"], ["21010.50", "0.360"], ["21115.80", "0.171"], ["56973.00", "0.000"], ["67619.40", "0.002"], ["70046.30", "4.278"], ["70106.80", "0.997"], ["70199.60", "0.272"], ["70498.40", "0.000"], ["71083.70", "0.109"], ["71091.20", "0.077"], ["71115.40", "0.118"], ["71119.30", "0.005"], ["71126.80", "0.040"], ["71130.10", "0.927"], ["71130.40", "0.149"], ["71130.50", "0.036"], ["71130.80", "0.157"], ["71131.50", "0.071"], ["71132.20", "0.003"], ["71146.40", "0.208"], ["71150.60", "0.269"], ["71154.90", "0.003"], ["71162.40", "0.015"], ["71183.20", "0.078"], ["71184.50", "0.000"], ["71190.50", "0.003"], ["71201.90", "0.687"], ["71202.20", "0.142"], ["71202.60", "0.038"], ["71203.20", "0.025"]], "a": [["71210.60", "8.322"], ["71211.70", "0.002"], ["71215.20", "0.878"], ["71215.60", "0.006"], ["71222.40", "0.357"], ["71224.00", "0.114"], ["71224.70", "0.157"], ["71225.10", "0.271"], ["71225.30", "0.049"], ["71225.40", "0.407"], ["71230.30", "0.071"], ["71233.50", "0.231"], ["71235.60", "0.003"], ["71236.40", "0.002"], ["71236.90", "0.705"], ["71250.50", "0.338"], ["71259.20", "0.510"], ["71259.30", "0.033"], ["71259.80", "0.063"], ["71260.20", "0.057"], ["71260.30", "0.023"], ["71260.60", "0.113"], ["71260.90", "0.381"], ["71261.00", "0.052"], ["71261.30", "0.266"], ["71266.20", "0.013"], ["71268.50", "0.070"], ["71272.60", "0.140"], ["71273.70", "0.000"], ["71274.70", "0.243"], ["71285.40", "0.000"], ["71289.00", "0.003"], ["71295.70", "0.063"], ["71296.40", "0.087"], ["71296.80", "0.125"], ["71297.20", "0.268"], ["71301.90", "0.005"], ["71309.40", "0.987"], ["71311.90", "0.070"], ["71313.70", "0.036"], ["71317.40", "0.212"], ["71324.90", "0.029"], ["71337.60", "0.003"], ["71345.10", "0.080"], ["71518.40", "1.360"], ["71785.60", "0.209"], ["71922.60", "0.785"], ["71922.70", "0.005"], ["72070.50", "0.417"], ["72295.90", "1.241"], ["74780.50", "0.050"], ["89523.20", "0.000"]]}}
{"local_ts": 1773384597826, "server_ts": 1773384597610, "data": {"e": "depthUpdate", "E": 1773384597611, "T": 1773384597610, "s": "BTCUSDT", "U": 10101345467104, "u": 10101345484728, "pu": 10101345467059, "b": [["1000.00", "27.492"], ["5000.00", "101.418"], ["20710.50", "1.080"], ["20910.50", "0.477"], ["21010.50", "0.423"], ["21110.50", "0.720"], ["40000.00", "49.307"], ["67626.80", "0.002"], ["70498.40", "0.000"], ["70912.80", "0.302"], ["71119.40", "0.114"], ["71121.60", "0.001"], ["71149.00", "0.007"], ["71149.90", "0.075"], ["71158.10", "1.351"], ["71160.70", "0.000"], ["71162.60", "0.000"], ["71167.50", "0.007"], ["71171.80", "1.008"], ["71179.00", "1.165"], ["71179.10", "0.799"], ["71180.00", "0.168"], ["71183.40", "0.320"], ["71184.50", "0.000"], ["71187.00", "0.004"], ["71188.50", "0.000"], ["71188.90", "0.077"], ["71189.40", "0.003"], ["71189.80", "0.787"], ["71190.20", "0.073"], ["71191.40", "0.072"], ["71191.50", "0.001"], ["71192.10", "0.158"], ["71192.20", "0.001"], ["71192.40", "0.029"], ["71192.50", "0.001"], ["71192.70", "0.243"], ["71192.80", "0.000"], ["71193.00", "0.009"], ["71193.30", "0.004"], ["71193.60", "0.001"], ["71194.50", "0.218"], ["71194.80", "0.009"], ["71194.90", "0.316"], ["71195.00", "0.799"], ["71195.40", "1.353"], ["71195.90", "1.011"], ["71196.30", "0.002"], ["71197.00", "0.006"], ["71197.10", "0.496"], ["71197.30", "1.049"], ["71197.50", "0.007"], ["71197.60", "0.005"], ["71198.00", "0.009"], ["71198.70", "0.142"], ["71199.00", "0.283"], ["71200.20", "0.382"], ["71200.30", "0.044"], ["71200.90", "0.071"], ["71201.10", "0.027"], ["71201.50", "0.002"], ["71201.60", "0.060"], ["71201.90", "0.805"], ["71202.00", "0.008"], ["71202.30", "0.003"], ["71202.40", "0.002"], ["71203.10", "0.000"], ["71203.30", "0.202"], ["71203.40", "0.069"], ["71203.70", "0.156"], ["71203.80", "1.163"], ["71204.00", "0.067"], ["71204.20", "0.003"], ["71204.40", "0.761"], ["71204.50", "0.457"], ["71204.60", "0.044"], ["71204.80", "0.096"], ["71204.90", "0.134"], ["71205.20", "0.036"], ["71205.30", "0.133"], ["71205.50", "0.030"], ["71205.60", "0.717"], ["71206.00", "0.049"], ["71206.20", "0.028"], ["71206.30", "0.047"], ["71206.80", "0.721"], ["71206.90", "0.301"], ["71207.10", "0.175"], ["71207.40", "0.009"], ["71207.60", "0.002"], ["71207.80", "0.017"], ["71208.00", "0.776"], ["71209.30", "0.715"], ["71209.60", "0.053"], ["71210.50", "4.281"]], "a": [["71210.60", "0.545"], ["71210.70", "0.002"], ["71211.10", "0.058"], ["71211.20", "0.002"], ["71211.80", "0.000"], ["71212.50", "0.002"], ["71213.60", "0.210"], ["71213.80", "0.002"], ["71214.00", "0.005"], ["71214.20", "0.174"], ["71215.00", "0.005"], ["71215.20", "0.000"], ["71215.30", "0.011"], ["71216.10", "0.007"], ["71216.50", "0.000"], ["71217.50", "0.002"], ["71218.20", "0.005"], ["71218.70", "0.000"], ["71219.20", "0.005"], ["71219.40", "0.002"], ["71219.50", "0.007"], ["71220.10", "0.003"], ["71220.80", "0.003"], ["71221.30", "0.006"], ["71222.10", "0.061"], ["71222.20", "0.649"], ["71222.30", "0.005"], ["71222.50", "0.047"], ["71222.60", "0.004"], ["71222.90", "0.007"], ["71223.00", "0.003"], ["71223.40", "0.002"], ["71223.50", "0.030"], ["71223.70", "0.004"], ["71223.90", "0.000"], ["71224.00", "0.068"], ["71224.60", "0.000"], ["71224.70", "0.120"], ["71225.00", "0.009"], ["71225.20", "0.006"], ["71225.30", "0.028"], ["71225.60", "0.000"], ["71225.90", "0.005"], ["71226.00", "0.006"], ["71226.10", "0.002"], ["71226.30", "0.003"], ["71226.40", "0.003"], ["71226.60", "0.227"], ["71226.70", "0.006"], ["71226.80", "0.005"], ["71226.90", "0.003"], ["71227.20", "0.002"], ["71227.60", "0.002"], ["71227.70", "0.000"], ["71228.10", "0.006"], ["71228.20", "0.003"], ["71228.50", "0.005"], ["71229.20", "0.142"], ["71229.30", "0.000"], ["71229.70", "0.561"], ["71229.80", "0.003"], ["71229.90", "0.000"], ["71230.20", "0.009"], ["71231.30", "0.000"], ["71232.00", "0.013"], ["71232.50", "0.006"], ["71232.60", "0.053"], ["71232.70", "0.638"], ["71232.90", "0.000"], ["71233.00", "0.068"], ["71233.80", "0.288"], ["71234.00", "0.002"], ["71234.60", "0.080"], ["71234.70", "0.070"], ["71234.80", "0.000"], ["71234.90", "0.006"], ["71235.40", "0.010"], ["71236.90", "0.768"], ["71237.00", "0.347"], ["71237.10", "0.000"], ["71237.20", "0.023"], ["71237.30", "0.402"], ["71238.20", "1.060"], ["71238.30", "0.006"], ["71238.80", "0.002"], ["71238.90", "0.255"], ["71239.00", "0.007"], ["71240.20", "0.505"], ["71241.00", "0.002"], ["71243.40", "0.508"], ["71243.50", "0.005"], ["71243.90", "1.302"], ["71244.00", "0.042"], ["71244.20", "0.343"], ["71245.00", "0.001"], ["71245.10", "0.002"], ["71246.20", "0.002"], ["71246.40", "0.507"], ["71246.50", "0.311"], ["71247.40", "0.055"], ["71248.10", "0.002"], ["71248.60", "0.001"], ["71248.80", "0.003"], ["71249.70", "0.521"], ["71249.80", "0.003"], ["71249.90", "0.646"], ["71250.20", "0.013"], ["71250.80", "1.049"], ["71250.90", "0.003"], ["71251.10", "0.060"], ["71254.10", "0.511"], ["71254.20", "0.875"], ["71254.30", "0.028"], ["71255.70", "0.353"], ["71256.50", "0.510"], ["71256.70", "0.000"], ["71259.10", "0.003"], ["71259.20", "0.510"], ["71261.70", "0.355"], ["71263.50", "0.024"], ["71266.10", "0.003"], ["71267.00", "0.025"], ["71267.50", "0.015"], ["71267.60", "0.099"], ["71272.20", "0.000"], ["71272.70", "0.155"], ["71274.70", "0.162"], ["71279.60", "0.140"], ["71285.40", "0.081"], ["71288.90", "1.272"], ["71317.40", "0.212"], ["71332.30", "0.153"], ["71364.60", "10.891"], ["71393.60", "0.000"], ["71399.30", "0.506"], ["71402.90", "0.453"], ["71411.70", "10.003"], ["71418.30", "0.002"], ["71442.10", "0.000"], ["71443.10", "10.000"], ["71474.50", "10.240"], ["71922.70", "0.005"], ["72483.80", "0.004"], ["72634.80", "0.015"], ["89523.20", "0.000"], ["100000.00", "15.858"]]}}
{"local_ts": 1773384598851, "server_ts": 1773384598630, "data": {"e": "depthUpdate", "E": 1773384598631, "T": 1773384598630, "s": "BTCUSDT", "U": 10101345582376, "u": 10101345594065, "pu": 10101345582284, "b": [["1000.00", "27.492"], ["5000.00", "101.418"], ["20821.30", "0.342"], ["20921.30", "0.000"], ["21021.30", "0.450"], ["21117.90", "0.063"], ["21118.00", "0.000"], ["21121.30", "0.486"], ["56977.00", "0.125"], ["67632.90", "0.002"], ["67634.50", "0.000"], ["68744.60", "0.002"], ["69986.00", "0.285"], ["70509.10", "1.123"], ["70854.40", "0.141"], ["70865.10", "0.000"], ["71083.70", "0.106"], ["71094.50", "0.003"], ["71105.50", "0.002"], ["71114.00", "0.436"], ["71119.30", "0.002"], ["71130.10", "0.823"], ["71141.00", "0.027"], ["71151.50", "0.000"], ["71153.20", "0.278"], ["71153.30", "0.164"], ["71154.90", "0.000"], ["71156.80", "0.321"], ["71165.70", "0.419"], ["71170.20", "0.303"], ["71173.00", "0.059"], ["71173.60", "0.004"], ["71178.70", "0.023"], ["71178.90", "0.903"], ["71179.20", "0.000"], ["71179.60", "0.003"], ["71187.30", "1.148"], ["71190.50", "0.070"], ["71191.30", "1.384"], ["71191.80", "0.070"], ["71192.40", "0.175"], ["71192.80", "0.232"], ["71193.20", "0.002"], ["71195.10", "0.056"], ["71195.80", "0.006"], ["71197.50", "0.070"], ["71197.80", "0.509"], ["71198.50", "0.645"], ["71198.90", "0.000"], ["71199.20", "0.002"], ["71199.30", "0.637"], ["71200.20", "0.833"], ["71200.50", "0.002"], ["71200.70", "0.001"], ["71201.00", "0.363"], ["71202.00", "0.078"], ["71203.70", "0.053"], ["71203.80", "0.000"], ["71203.90", "0.309"], ["71204.30", "0.752"], ["71204.60", "0.037"], ["71205.40", "0.003"], ["71206.00", "0.090"], ["71206.30", "0.003"], ["71207.40", "0.444"], ["71210.20", "0.002"], ["71210.30", "0.000"], ["71210.40", "1.055"], ["71210.50", "0.591"], ["71210.70", "0.510"], ["71211.60", "0.392"], ["71211.70", "0.115"], ["71213.80", "0.002"], ["71214.50", "0.051"], ["71214.90", "0.123"], ["71215.90", "0.037"], ["71216.30", "0.003"], ["71216.60", "0.009"], ["71217.30", "0.002"], ["71217.70", "0.006"], ["71217.80", "0.002"], ["71218.90", "0.008"], ["71219.00", "0.000"]], "a": [["71221.40", "4.280"], ["71221.50", "0.056"], ["71222.20", "0.011"], ["71223.10", "0.001"], ["71225.00", "0.009"], ["71233.70", "0.580"], ["71236.20", "0.020"], ["71236.40", "0.005"], ["71237.30", "0.344"], ["71238.60", "0.075"], ["71241.00", "0.019"], ["71241.40", "0.005"], ["71241.90", "0.026"], ["71242.50", "0.009"], ["71242.60", "0.029"], ["71243.20", "0.015"], ["71243.30", "0.080"], ["71243.70", "0.006"], ["71246.70", "0.220"], ["71246.80", "0.431"], ["71247.40", "0.002"], ["71247.50", "0.003"], ["71248.10", "0.140"], ["71248.20", "0.303"], ["71248.80", "0.003"], ["71248.90", "0.001"], ["71251.40", "0.053"], ["71255.00", "0.354"], ["71261.20", "1.811"], ["71262.70", "0.012"], ["71266.20", "0.010"], ["71266.30", "0.050"], ["71268.00", "0.012"], ["71268.50", "0.070"], ["71274.20", "0.070"], ["71274.30", "0.000"], ["71277.10", "0.329"], ["71301.90", "0.002"], ["71312.80", "0.003"], ["71337.60", "0.000"], ["71348.50", "0.003"], ["71933.60", "0.005"], ["72178.60", "0.277"], ["89523.20", "0.000"]]}}
{"local_ts": 1773384599870, "server_ts": 1773384599654, "data": {"e": "depthUpdate", "E": 1773384599655, "T": 1773384599654, "s": "BTCUSDT", "U": 10101345648398, "u": 10101345662322, "pu": 10101345648358, "b": [["5000.00", "101.418"], ["20720.30", "0.036"], ["20721.30", "0.180"], ["20821.30", "0.684"], ["20920.30", "0.036"], ["20921.30", "0.180"], ["21020.30", "0.027"], ["21021.00", "0.009"], ["21021.30", "1.512"], ["21110.50", "0.036"], ["56977.00", "0.125"], ["68389.30", "0.015"], ["69791.50", "0.009"], ["69795.90", "0.009"], ["69796.90", "0.017"], ["69920.40", "1.326"], ["70508.10", "0.014"], ["70508.60", "0.000"], ["70508.80", "0.064"], ["70509.00", "0.000"], ["70509.10", "1.123"], ["70754.90", "0.000"], ["70760.40", "0.011"], ["70918.10", "0.302"], ["70931.80", "0.023"], ["70937.30", "0.004"], ["71070.00", "16.173"], ["71109.10", "0.000"], ["71114.60", "0.510"], ["71128.20", "1.309"], ["71148.30", "1.273"], ["71148.50", "0.009"], ["71149.80", "0.278"], ["71150.10", "0.510"], ["71156.70", "1.064"], ["71164.30", "0.099"], ["71166.20", "0.269"], ["71167.80", "0.002"], ["71172.40", "0.004"], ["71172.50", "0.027"], ["71172.60", "0.002"], ["71172.90", "0.001"], ["71173.00", "0.060"], ["71173.70", "0.011"], ["71176.40", "0.051"], ["71179.10", "0.003"], ["71179.70", "0.000"], ["71179.90", "0.181"], ["71186.00", "0.251"], ["71187.20", "0.003"], ["71187.60", "0.046"], ["71188.80", "0.080"], ["71189.20", "0.005"], ["71190.30", "0.361"], ["71190.60", "8.045"], ["71191.20", "0.508"], ["71192.60", "0.004"], ["71192.70", "0.295"], ["71193.60", "0.008"], ["71194.90", "0.307"], ["71195.20", "0.010"], ["71195.30", "0.206"], ["71196.00", "0.309"], ["71196.10", "0.000"], ["71196.30", "0.002"], ["71197.00", "0.012"], ["71197.10", "0.510"], ["71198.00", "0.079"], ["71198.10", "0.635"], ["71198.50", "0.307"], ["71198.60", "0.014"], ["71198.70", "0.002"], ["71199.20", "0.001"], ["71199.90", "0.115"], ["71200.00", "0.077"], ["71200.10", "0.018"], ["71200.20", "0.510"], ["71200.50", "0.004"], ["71201.10", "0.027"], ["71201.50", "0.002"], ["71201.90", "0.507"], ["71202.00", "0.080"], ["71202.20", "1.240"], ["71203.50", "0.013"], ["71203.80", "0.000"], ["71204.00", "0.011"], ["71204.50", "0.005"], ["71205.10", "0.006"], ["71205.20", "0.142"], ["71205.30", "0.304"], ["71205.50", "0.000"], ["71206.10", "0.004"], ["71206.60", "0.003"], ["71207.40", "0.577"], ["71207.50", "0.076"], ["71207.70", "0.015"], ["71209.30", "0.006"], ["71210.80", "0.002"], ["71211.00", "0.008"], ["71211.70", "0.113"], ["71211.80", "0.003"], ["71212.50", "0.700"], ["71212.80", "0.001"], ["71213.70", "0.007"], ["71213.80", "0.000"], ["71214.20", "0.000"], ["71214.50", "0.053"], ["71214.60", "0.000"], ["71215.00", "0.005"], ["71215.10", "0.222"], ["71216.10", "0.005"], ["71216.20", "0.004"], ["71216.80", "0.005"], ["71217.10", "0.092"], ["71217.20", "0.000"], ["71217.30", "0.002"], ["71217.90", "0.000"], ["71218.00", "0.007"], ["71218.20", "0.000"], ["71218.40", "0.002"], ["71218.60", "0.212"], ["71218.70", "0.064"], ["71218.90", "0.001"], ["71219.60", "0.003"], ["71220.00", "0.001"], ["71220.30", "0.178"], ["71220.80", "0.000"], ["71221.00", "0.000"], ["71221.10", "0.000"], ["71221.20", "0.000"], ["71221.30", "0.000"]], "a": [["71220.40", "10.237"], ["71220.60", "0.002"], ["71220.80", "0.105"], ["71220.90", "0.172"], ["71221.00", "1.207"], ["71221.10", "0.000"], ["71221.20", "1.102"], ["71221.30", "1.750"], ["71221.40", "0.179"], ["71221.50", "0.084"], ["71222.00", "0.002"], ["71222.10", "0.218"], ["71222.20", "0.011"], ["71222.40", "0.003"], ["71222.50", "0.002"], ["71222.90", "0.003"], ["71223.40", "0.001"], ["71223.80", "0.002"], ["71225.00", "0.011"], ["71225.10", "0.003"], ["71225.20", "0.006"], ["71226.70", "0.001"], ["71227.50", "0.153"], ["71227.60", "0.200"], ["71228.50", "0.007"], ["71229.50", "0.009"], ["71229.60", "0.273"], ["71229.70", "0.371"], ["71230.50", "0.049"], ["71230.90", "0.009"], ["71231.00", "0.004"], ["71231.40", "0.002"], ["71231.60", "0.004"], ["71231.80", "0.018"], ["71232.10", "0.045"], ["71232.50", "0.008"], ["71232.60", "0.002"], ["71235.40", "0.003"], ["71235.50", "0.134"], ["71235.60", "0.634"], ["71236.20", "0.140"], ["71236.60", "0.002"], ["71236.70", "0.206"], ["71237.10", "0.004"], ["71237.30", "0.340"], ["71237.40", "0.364"], ["71238.60", "0.012"], ["71239.00", "0.012"], ["71239.50", "0.075"], ["71240.20", "0.001"], ["71240.60", "0.000"], ["71241.00", "0.020"], ["71241.30", "0.003"], ["71241.40", "0.005"], ["71241.80", "0.005"], ["71242.30", "0.002"], ["71242.40", "0.012"], ["71242.50", "0.011"], ["71242.60", "0.027"], ["71242.70", "0.247"], ["71242.80", "0.003"], ["71242.90", "1.051"], ["71243.00", "0.002"], ["71243.10", "0.508"], ["71243.40", "0.002"], ["71245.80", "0.002"], ["71246.00", "0.011"], ["71246.20", "0.002"], ["71246.30", "0.519"], ["71246.50", "0.311"], ["71247.20", "0.002"], ["71247.60", "0.000"], ["71247.80", "0.106"], ["71247.90", "0.142"], ["71248.10", "0.004"], ["71248.50", "0.512"], ["71253.40", "0.118"], ["71255.10", "0.214"], ["71255.60", "0.156"], ["71257.00", "0.000"], ["71259.30", "0.089"], ["71260.60", "0.113"], ["71261.70", "0.635"], ["71262.40", "0.146"], ["71266.70", "0.255"], ["71267.30", "0.085"], ["71268.10", "0.004"], ["71268.20", "0.508"], ["71268.30", "1.066"], ["71268.50", "0.070"], ["71268.60", "0.067"], ["71269.10", "0.060"], ["71271.00", "0.370"], ["71271.50", "0.684"], ["71272.70", "0.091"], ["71272.80", "0.693"], ["71273.80", "0.509"], ["71274.80", "0.000"], ["71277.00", "7.876"], ["71278.10", "0.022"], ["71281.60", "0.100"], ["71283.20", "3.628"], ["71283.40", "0.001"], ["71285.20", "0.000"], ["71289.10", "0.204"], ["71291.30", "10.114"], ["71292.20", "0.003"], ["71294.80", "0.000"], ["71308.60", "0.001"], ["71317.50", "0.002"], ["71322.60", "0.000"], ["71324.40", "0.212"], ["71324.70", "0.000"], ["71328.10", "0.002"], ["71341.50", "0.212"], ["71346.20", "0.106"], ["71373.50", "0.039"], ["71377.10", "0.508"], ["71398.50", "0.159"], ["71402.70", "0.000"], ["71406.60", "0.000"], ["71409.80", "0.012"], ["71413.60", "0.006"], ["71413.70", "0.000"], ["71417.30", "0.009"], ["71468.20", "0.002"], ["71500.90", "0.004"], ["71506.00", "0.000"], ["71506.20", "0.000"], ["71506.30", "0.000"], ["71506.40", "0.007"], ["71600.00", "19.090"], ["71679.70", "2.000"], ["71685.20", "0.030"], ["71858.90", "0.000"], ["71864.40", "0.016"], ["71932.60", "0.000"], ["71933.10", "0.000"], ["71933.30", "1.090"], ["71933.50", "0.000"], ["71933.60", "0.005"], ["72112.00", "0.754"], ["72127.30", "8.508"], ["72206.80", "0.031"], ["72211.10", "0.055"], ["72214.20", "0.020"], ["72215.90", "0.000"], ["72217.70", "0.121"], ["72218.50", "0.546"], ["72220.40", "0.004"], ["72220.90", "0.002"], ["72221.10", "0.022"], ["72254.00", "2.974"], ["72644.80", "0.003"], ["74782.80", "0.002"]]}}
{"local_ts": 1773384600891, "server_ts": 1773384600672, "data": {"e": "depthUpdate", "E": 1773384600675, "T": 1773384600672, "s": "BTCUSDT", "U": 10101345779613, "u": 10101345788220, "pu": 10101345779347, "b": [["1000.00", "27.492"], ["5000.00", "101.418"], ["20723.30", "0.063"], ["20823.30", "0.081"], ["20923.30", "0.288"], ["21021.30", "0.099"], ["21123.30", "0.081"], ["33000.00", "9.343"], ["56977.00", "0.125"], ["67660.00", "0.029"], ["70511.10", "0.010"], ["71105.40", "0.500"], ["71105.90", "0.104"], ["71139.30", "0.004"], ["71150.10", "0.512"], ["71152.30", "0.628"], ["71156.20", "0.000"], ["71156.70", "0.004"], ["71158.80", "0.022"], ["71160.90", "0.308"], ["71172.50", "0.031"], ["71183.60", "0.002"], ["71185.40", "0.008"], ["71187.80", "0.002"], ["71187.90", "0.002"], ["71188.50", "0.003"], ["71188.60", "0.004"], ["71189.30", "0.308"], ["71191.30", "1.386"], ["71191.50", "0.010"], ["71192.00", "0.024"], ["71192.10", "0.022"], ["71192.60", "0.010"], ["71192.70", "0.304"], ["71192.80", "0.814"], ["71193.40", "0.003"], ["71193.50", "0.511"], ["71194.10", "0.258"], ["71194.20", "0.252"], ["71201.70", "0.114"], ["71204.10", "0.540"], ["71205.00", "0.050"], ["71206.60", "0.036"], ["71207.80", "0.128"], ["71208.10", "0.004"], ["71208.30", "1.212"], ["71209.70", "0.002"], ["71210.10", "0.123"], ["71210.40", "0.010"], ["71210.70", "0.516"], ["71210.80", "1.098"], ["71212.30", "0.014"], ["71212.60", "0.108"], ["71213.00", "0.268"], ["71213.20", "0.056"], ["71214.10", "0.101"], ["71215.60", "0.017"], ["71216.40", "0.016"], ["71216.70", "0.206"], ["71216.90", "0.007"], ["71218.30", "0.000"], ["71218.70", "0.013"], ["71221.00", "0.129"], ["71223.20", "0.052"], ["71223.30", "6.866"]], "a": [["71223.40", "1.897"], ["71225.50", "0.002"], ["71226.80", "0.003"], ["71227.40", "0.013"], ["71228.20", "0.013"], ["71228.80", "0.143"], ["71230.00", "0.009"], ["71230.10", "0.023"], ["71230.50", "0.032"], ["71231.30", "0.015"], ["71231.50", "0.000"], ["71232.60", "0.015"], ["71232.80", "0.003"], ["71233.00", "0.004"], ["71233.80", "0.305"], ["71234.00", "0.003"], ["71235.00", "0.038"], ["71235.10", "0.140"], ["71235.30", "0.001"], ["71235.40", "0.274"], ["71235.70", "0.111"], ["71235.80", "0.427"], ["71235.90", "0.006"], ["71236.30", "0.019"], ["71236.60", "0.002"], ["71237.40", "0.292"], ["71237.60", "0.029"], ["71237.80", "0.002"], ["71238.90", "0.029"], ["71239.10", "0.003"], ["71239.80", "0.015"], ["71240.30", "0.206"], ["71244.10", "0.015"], ["71245.20", "0.000"], ["71246.40", "0.006"], ["71246.70", "0.209"], ["71246.80", "0.422"], ["71246.90", "0.126"], ["71247.40", "0.002"], ["71247.50", "0.012"], ["71248.40", "0.087"], ["71248.70", "0.926"], ["71250.60", "0.004"], ["71250.90", "0.003"], ["71251.00", "0.009"], ["71251.20", "0.509"], ["71251.40", "0.256"], ["71251.60", "0.223"], ["71251.70", "0.015"], ["71252.30", "0.028"], ["71252.40", "0.002"], ["71252.50", "0.300"], ["71253.00", "0.006"], ["71253.10", "0.007"], ["71253.30", "0.057"], ["71254.70", "0.000"], ["71255.00", "0.301"], ["71255.80", "0.717"], ["71256.10", "0.604"], ["71256.50", "0.006"], ["71257.40", "0.027"], ["71257.70", "0.004"], ["71258.40", "0.766"], ["71258.60", "0.003"], ["71258.70", "0.005"], ["71259.00", "0.019"], ["71259.10", "0.005"], ["71259.20", "1.514"], ["71259.70", "0.002"], ["71260.10", "0.941"], ["71260.20", "0.355"], ["71260.70", "0.004"], ["71260.90", "0.308"], ["71261.00", "0.004"], ["71261.30", "0.198"], ["71262.40", "0.006"], ["71262.50", "0.639"], ["71263.10", "1.897"], ["71263.60", "0.000"], ["71266.10", "0.003"], ["71268.00", "0.008"], ["71268.50", "0.002"], ["71269.40", "0.004"], ["71269.70", "1.106"], ["71270.20", "0.002"], ["71270.30", "0.039"], ["71271.00", "0.271"], ["71271.30", "0.033"], ["71271.60", "0.003"], ["71272.60", "0.050"], ["71272.80", "0.793"], ["71273.00", "0.202"], ["71273.80", "0.109"], ["71281.90", "0.000"], ["71285.00", "0.888"], ["71285.40", "3.475"], ["71292.70", "0.508"], ["71332.00", "0.547"], ["71332.10", "0.043"], ["71332.40", "0.045"], ["71333.10", "6.764"], ["71336.80", "0.043"], ["71337.20", "0.084"], ["71340.20", "0.297"], ["71351.10", "0.063"], ["71366.60", "0.003"], ["71576.40", "0.048"], ["71691.80", "0.010"], ["71692.70", "0.000"], ["71935.60", "0.000"], ["72304.80", "0.000"], ["72327.40", "0.966"], ["74801.50", "0.050"]]}}
{"local_ts": 1773384601917, "server_ts": 1773384601696, "data": {"e": "depthUpdate", "E": 1773384601697, "T": 1773384601696, "s": "BTCUSDT", "U": 10101345926694, "u": 10101345937578, "pu": 10101345926531, "b": [["5000.00", "101.418"], ["20720.30", "0.054"], ["20818.80", "0.648"], ["20920.30", "0.360"], ["21118.80", "0.333"], ["33000.00", "9.343"], ["66881.00", "4.000"], ["68515.20", "0.004"], ["69082.20", "0.005"], ["69842.70", "0.613"], ["70506.60", "0.002"], ["70762.50", "1.222"], ["70864.20", "0.000"], ["70995.90", "2.671"], ["70999.10", "1.219"], ["71020.10", "0.002"], ["71020.30", "10.000"], ["71020.40", "4.516"], ["71095.30", "0.267"], ["71172.50", "0.033"], ["71173.60", "0.002"], ["71183.10", "0.129"], ["71183.60", "0.004"], ["71183.70", "0.005"], ["71184.00", "0.010"], ["71184.30", "0.002"], ["71184.40", "0.001"], ["71184.90", "0.001"], ["71185.90", "0.610"], ["71186.40", "0.249"], ["71186.90", "0.003"], ["71187.80", "0.011"], ["71188.20", "0.002"], ["71188.80", "0.000"], ["71189.80", "0.544"], ["71190.80", "0.345"], ["71191.70", "0.285"], ["71191.80", "0.004"], ["71192.70", "0.295"], ["71193.70", "0.002"], ["71196.90", "0.003"], ["71197.90", "0.000"], ["71198.00", "0.046"], ["71198.70", "0.002"], ["71199.00", "0.005"], ["71199.20", "0.001"], ["71200.20", "0.359"], ["71200.40", "0.009"], ["71200.80", "0.047"], ["71202.00", "0.078"], ["71202.80", "0.031"], ["71203.30", "0.622"], ["71204.50", "0.005"], ["71205.50", "0.042"], ["71205.60", "0.161"], ["71208.00", "0.010"], ["71208.10", "0.046"], ["71208.90", "0.002"], ["71209.10", "0.023"], ["71209.40", "0.510"], ["71210.10", "0.208"], ["71210.60", "0.004"], ["71211.20", "0.015"], ["71211.70", "0.844"], ["71211.80", "0.007"], ["71212.30", "0.051"], ["71212.90", "0.015"], ["71213.40", "0.044"], ["71214.60", "0.003"], ["71214.90", "0.015"], ["71215.20", "0.002"], ["71215.30", "0.000"], ["71215.40", "0.092"], ["71215.50", "0.046"], ["71216.00", "0.064"], ["71216.20", "0.002"], ["71216.30", "0.003"], ["71216.40", "0.004"], ["71216.70", "0.018"], ["71216.90", "0.000"], ["71217.00", "0.029"], ["71217.30", "0.053"], ["71217.40", "0.002"], ["71217.60", "0.002"], ["71217.70", "0.004"], ["71218.10", "0.001"], ["71218.20", "0.002"], ["71218.50", "0.000"], ["71218.60", "0.002"], ["71218.70", "0.076"], ["71218.80", "2.768"]], "a": [["71218.90", "7.306"], ["71219.30", "0.000"], ["71219.80", "0.000"], ["71219.90", "0.004"], ["71220.00", "0.512"], ["71220.20", "0.001"], ["71220.40", "0.007"], ["71221.10", "0.045"], ["71221.30", "0.000"], ["71221.40", "0.003"], ["71221.50", "0.017"], ["71221.70", "0.001"], ["71222.10", "0.008"], ["71222.40", "0.000"], ["71222.70", "0.015"], ["71222.80", "0.002"], ["71223.00", "0.001"], ["71223.10", "0.001"], ["71223.50", "0.041"], ["71223.60", "0.002"], ["71224.00", "0.017"], ["71224.60", "0.000"], ["71224.90", "0.004"], ["71225.20", "0.019"], ["71225.70", "0.002"], ["71225.90", "0.000"], ["71226.00", "0.013"], ["71226.10", "0.002"], ["71226.50", "0.019"], ["71227.10", "0.006"], ["71227.40", "0.003"], ["71227.70", "0.015"], ["71228.10", "0.006"], ["71228.40", "0.016"], ["71228.70", "0.000"], ["71229.00", "0.168"], ["71229.20", "0.002"], ["71229.60", "0.002"], ["71229.80", "0.003"], ["71229.90", "0.017"], ["71230.30", "0.016"], ["71230.50", "0.004"], ["71230.70", "0.026"], ["71231.00", "0.004"], ["71231.10", "0.000"], ["71231.20", "0.015"], ["71231.40", "0.002"], ["71231.80", "0.018"], ["71232.10", "0.665"], ["71232.40", "0.001"], ["71232.60", "0.000"], ["71233.40", "0.007"], ["71233.50", "0.007"], ["71233.60", "0.577"], ["71233.80", "0.290"], ["71233.90", "0.082"], ["71234.10", "0.000"], ["71234.70", "0.123"], ["71235.00", "0.043"], ["71235.20", "0.000"], ["71235.90", "0.003"], ["71237.40", "0.004"], ["71237.60", "0.011"], ["71237.80", "0.005"], ["71237.90", "0.212"], ["71238.20", "0.004"], ["71238.30", "0.976"], ["71238.70", "0.084"], ["71238.80", "0.002"], ["71239.50", "0.005"], ["71239.60", "0.252"], ["71240.10", "0.013"], ["71240.80", "0.010"], ["71241.00", "0.003"], ["71241.10", "0.025"], ["71241.30", "0.071"], ["71241.70", "0.514"], ["71242.00", "0.002"], ["71242.20", "0.007"], ["71242.40", "0.004"], ["71242.50", "0.011"], ["71242.60", "0.006"], ["71243.10", "0.032"], ["71243.20", "0.015"], ["71243.30", "0.000"], ["71244.60", "0.513"], ["71244.90", "0.021"], ["71245.20", "0.029"], ["71246.40", "0.003"], ["71246.60", "0.002"], ["71247.90", "0.195"], ["71249.10", "0.005"], ["71250.30", "0.075"], ["71250.40", "0.000"], ["71251.60", "0.214"], ["71251.70", "0.035"], ["71252.80", "0.056"], ["71253.00", "0.033"], ["71254.10", "0.511"], ["71255.30", "0.077"], ["71256.60", "1.084"], ["71257.80", "0.029"], ["71259.10", "0.005"], ["71260.30", "0.002"], ["71261.60", "0.009"], ["71262.50", "0.455"], ["71262.80", "0.002"], ["71264.10", "0.001"], ["71264.90", "0.000"], ["71267.20", "0.005"], ["71268.10", "0.002"], ["71272.30", "0.251"], ["71382.70", "0.039"], ["71407.60", "0.212"], ["71409.70", "2.361"], ["71409.80", "10.012"], ["71409.90", "0.000"], ["71411.20", "0.000"], ["71414.80", "0.000"], ["71442.00", "1.921"], ["71443.10", "0.000"], ["71443.50", "0.068"], ["71931.00", "0.054"], ["71931.10", "0.002"], ["74799.30", "0.004"], ["74815.40", "0.002"]]}}
{"local_ts": 1773384602937, "server_ts": 1773384602716, "data": {"e": "depthUpdate", "E": 1773384602717, "T": 1773384602716, "s": "BTCUSDT", "U": 10101346071300, "u": 10101346087929, "pu": 10101346071273, "b": [["1000.00", "27.492"], ["5000.00", "101.418"], ["20715.10", "1.035"], ["20818.80", "0.513"], ["21015.10", "0.567"], ["21118.80", "0.189"], ["67637.30", "0.002"], ["68366.60", "0.632"], ["70502.90", "1.127"], ["70645.40", "0.087"], ["70859.00", "0.502"], ["71065.30", "0.000"], ["71067.00", "1.068"], ["71067.10", "1.540"], ["71094.20", "0.000"], ["71101.30", "0.003"], ["71104.30", "0.169"], ["71115.40", "0.082"], ["71118.10", "0.042"], ["71126.00", "0.743"], ["71126.40", "0.064"], ["71126.90", "0.003"], ["71127.40", "0.000"], ["71128.20", "1.309"], ["71130.10", "0.639"], ["71130.40", "0.124"], ["71130.50", "0.000"], ["71130.70", "0.017"], ["71130.80", "0.121"], ["71131.20", "0.116"], ["71131.50", "0.046"], ["71131.80", "0.231"], ["71133.90", "0.274"], ["71136.70", "0.036"], ["71137.80", "0.275"], ["71138.10", "0.913"], ["71147.90", "0.000"], ["71168.60", "0.002"], ["71169.00", "0.004"], ["71169.30", "0.320"], ["71169.60", "0.000"], ["71169.80", "0.015"], ["71170.00", "0.363"], ["71170.70", "0.018"], ["71171.10", "0.062"], ["71175.60", "0.110"], ["71176.70", "0.000"], ["71177.10", "0.000"], ["71177.40", "0.034"], ["71177.80", "0.029"], ["71178.10", "0.000"], ["71178.40", "0.003"], ["71182.00", "0.552"], ["71182.90", "0.020"], ["71183.00", "0.345"], ["71183.50", "0.071"], ["71183.60", "0.002"], ["71183.70", "0.005"], ["71184.10", "0.342"], ["71191.30", "0.357"], ["71192.40", "0.030"], ["71194.30", "0.007"], ["71194.40", "0.018"], ["71194.70", "0.108"], ["71195.30", "0.213"], ["71195.60", "0.142"], ["71200.80", "0.003"], ["71201.20", "0.001"], ["71201.30", "0.383"], ["71201.40", "0.080"], ["71204.90", "0.007"], ["71205.50", "0.000"], ["71206.00", "0.073"], ["71206.70", "0.341"], ["71207.00", "1.062"], ["71207.90", "0.118"], ["71208.00", "0.038"], ["71208.50", "0.036"], ["71208.70", "0.046"], ["71209.50", "0.040"], ["71210.80", "0.004"], ["71211.60", "0.243"], ["71211.70", "0.004"], ["71214.40", "0.000"]], "a": [["71215.20", "4.186"], ["71222.30", "0.068"], ["71222.50", "0.070"], ["71224.70", "0.004"], ["71226.50", "0.342"], ["71226.80", "0.003"], ["71226.90", "0.457"], ["71229.30", "1.049"], ["71230.40", "0.177"], ["71232.40", "0.071"], ["71233.10", "0.099"], ["71233.50", "0.571"], ["71233.60", "0.575"], ["71233.90", "0.007"], ["71234.30", "0.044"], ["71234.70", "0.000"], ["71235.10", "0.001"], ["71235.40", "0.000"], ["71235.80", "0.055"], ["71236.20", "0.126"], ["71236.50", "0.506"], ["71236.90", "0.000"], ["71237.20", "0.313"], ["71237.60", "0.011"], ["71238.90", "0.011"], ["71240.40", "0.010"], ["71249.20", "0.002"], ["71262.40", "0.106"], ["71263.20", "0.317"], ["71263.70", "0.005"], ["71268.30", "1.134"], ["71269.40", "0.062"], ["71269.90", "0.221"], ["71270.50", "0.083"], ["71295.30", "0.000"], ["71295.70", "0.041"], ["71296.10", "0.002"], ["71296.40", "0.008"], ["71296.60", "0.000"], ["71296.80", "0.001"], ["71297.20", "0.078"], ["71299.90", "0.304"], ["71304.20", "0.070"], ["71305.30", "0.063"], ["71307.90", "0.088"], ["71309.20", "0.012"], ["71311.90", "0.000"], ["71331.20", "2.096"], ["71331.60", "0.077"], ["71332.00", "0.547"], ["71332.30", "0.153"], ["71332.40", "0.000"], ["71332.70", "0.002"], ["71333.10", "6.440"], ["71337.20", "0.005"], ["71351.10", "0.002"], ["71355.30", "0.000"], ["71394.80", "0.000"], ["71403.90", "0.159"], ["71927.40", "0.003"], ["74782.40", "0.000"], ["75855.20", "0.000"], ["76325.10", "0.002"]]}}
{"local_ts": 1773384603953, "server_ts": 1773384603736, "data": {"e": "depthUpdate", "E": 1773384603737, "T": 1773384603736, "s": "BTCUSDT", "U": 10101346170455, "u": 10101346176878, "pu": 10101346170191, "b": [["1000.00", "27.492"], ["5000.00", "101.418"], ["20715.10", "0.756"], ["20912.40", "0.468"], ["21015.10", "0.324"], ["21112.40", "0.792"], ["49855.00", "0.004"], ["69076.00", "0.165"], ["70500.30", "0.000"], ["70859.00", "0.502"], ["71065.00", "0.013"], ["71066.00", "0.409"], ["71067.00", "1.018"], ["71121.40", "0.043"], ["71126.20", "0.017"], ["71127.20", "0.002"], ["71141.30", "0.055"], ["71151.60", "1.001"], ["71159.80", "1.204"], ["71160.10", "0.001"], ["71164.70", "0.176"], ["71166.90", "0.006"], ["71167.00", "0.148"], ["71187.80", "0.253"], ["71189.40", "0.002"], ["71189.50", "0.070"], ["71191.20", "0.508"], ["71198.60", "1.297"], ["71199.20", "0.388"], ["71199.40", "0.002"], ["71200.40", "0.631"], ["71200.60", "0.675"], ["71201.40", "0.019"], ["71204.20", "0.036"], ["71206.90", "0.005"], ["71211.10", "0.005"], ["71212.40", "3.911"]], "a": [["71212.50", "1.483"], ["71212.60", "0.003"], ["71241.00", "0.243"], ["71261.70", "0.340"], ["71262.00", "0.015"], ["71273.00", "0.301"], ["71275.00", "0.206"], ["71907.50", "0.209"], ["71924.60", "0.000"], ["74781.20", "0.002"], ["74801.00", "0.050"], ["76680.10", "0.002"]]}}
{"local_ts": 1773384604975, "server_ts": 1773384604758, "data": {"e": "depthUpdate", "E": 1773384604759, "T": 1773384604758, "s": "BTCUSDT", "U": 10101346238173, "u": 10101346244972, "pu": 10101346237939, "b": [["5000.00", "101.418"], ["20812.40", "0.441"], ["20912.40", "0.459"], ["21012.40", "0.639"], ["21112.40", "1.161"], ["70500.30", "0.000"], ["70785.90", "0.000"], ["70892.70", "0.023"], ["70900.90", "0.002"], ["70929.70", "0.002"], ["71112.40", "0.524"], ["71126.20", "0.003"], ["71172.50", "0.027"], ["71176.20", "0.002"], ["71181.10", "0.027"], ["71181.20", "1.635"], ["71184.40", "0.007"], ["71185.00", "0.011"], ["71190.70", "0.013"], ["71191.30", "0.335"], ["71191.50", "0.283"], ["71192.90", "0.285"], ["71193.60", "0.283"], ["71195.70", "0.000"], ["71197.80", "0.018"], ["71198.30", "0.044"], ["71199.80", "0.007"], ["71200.90", "0.351"], ["71201.60", "0.184"], ["71205.30", "0.028"], ["71206.80", "1.052"], ["71208.10", "0.000"], ["71208.90", "0.004"], ["71209.40", "0.000"], ["71210.70", "0.000"], ["71210.90", "0.011"], ["71212.00", "0.005"], ["71212.40", "3.209"]], "a": [["71212.50", "2.847"], ["71212.60", "0.005"], ["71219.60", "0.049"], ["71226.50", "0.347"], ["71227.10", "0.008"], ["71232.40", "0.003"], ["71240.80", "0.080"], ["71241.80", "0.003"], ["71244.30", "0.263"], ["71244.60", "0.006"], ["71247.20", "0.013"], ["71252.60", "0.004"], ["71253.90", "0.022"], ["71255.10", "0.216"], ["71258.90", "0.000"], ["71260.20", "0.005"], ["71262.00", "0.015"], ["71262.10", "0.055"], ["71262.20", "0.021"], ["71262.40", "0.004"], ["71263.50", "0.022"], ["71263.80", "0.000"], ["71264.50", "0.002"], ["71290.80", "0.000"], ["71304.80", "0.014"], ["71305.50", "0.000"], ["71640.50", "0.008"], ["71854.10", "0.000"], ["71886.00", "6.301"], ["71924.60", "0.000"], ["72134.30", "0.003"], ["72242.00", "8.234"], ["72313.20", "8.622"], ["72644.80", "0.003"], ["72763.50", "0.375"], ["74789.80", "0.000"]]}}
{"local_ts": 1773384605994, "server_ts": 1773384605776, "data": {"e": "depthUpdate", "E": 1773384605779, "T": 1773384605776, "s": "BTCUSDT", "U": 10101346319988, "u": 10101346325681, "pu": 10101346319923, "b": [["1000.00", "27.892"], ["5000.00", "101.418"], ["20712.40", "0.306"], ["20812.40", "0.594"], ["20912.40", "0.369"], ["21012.40", "1.431"], ["21112.40", "0.000"], ["67639.60", "0.002"], ["70500.30", "0.000"], ["70900.90", "0.000"], ["70901.00", "0.005"], ["70976.70", "0.000"], ["71102.60", "6.241"], ["71102.70", "0.008"], ["71141.30", "0.055"], ["71153.00", "0.083"], ["71162.30", "0.564"], ["71162.60", "0.099"], ["71165.00", "0.072"], ["71176.40", "0.002"], ["71176.80", "0.042"], ["71180.00", "0.053"], ["71183.00", "0.345"], ["71205.30", "0.000"]], "a": [["71219.60", "0.002"], ["71230.30", "0.181"], ["71231.60", "0.006"], ["71248.10", "0.189"], ["71250.40", "0.002"], ["71268.70", "0.002"], ["71404.80", "0.000"], ["71924.60", "0.694"], ["72245.10", "3.027"], ["72351.40", "0.591"], ["74804.70", "0.000"]]}}
{"local_ts": 1773384607024, "server_ts": 1773384606796, "data": {"e": "depthUpdate", "E": 1773384606801, "T": 1773384606796, "s": "BTCUSDT", "U": 10101346387688, "u": 10101346395789, "pu": 10101346387629, "b": [["5000.00", "101.418"], ["20712.40", "0.729"], ["20812.40", "0.171"], ["20912.40", "1.557"], ["21012.40", "0.072"], ["21112.40", "0.171"], ["33000.00", "9.339"], ["67641.30", "0.002"], ["67659.40", "0.002"], ["70357.80", "0.142"], ["70500.30", "0.708"], ["70501.70", "0.003"], ["70523.60", "0.702"], ["70856.30", "0.004"], ["70901.00", "0.003"], ["70902.90", "0.002"], ["71167.00", "0.007"], ["71167.20", "0.004"], ["71170.20", "0.303"], ["71176.80", "0.000"], ["71190.70", "0.083"], ["71191.90", "0.037"], ["71196.80", "0.505"], ["71197.60", "0.004"], ["71198.60", "0.083"], ["71199.00", "0.003"], ["71200.90", "0.489"], ["71201.50", "0.003"], ["71205.40", "0.507"], ["71206.90", "0.005"], ["71210.00", "0.006"], ["71212.40", "2.544"]], "a": [["71212.50", "1.748"], ["71212.60", "0.005"], ["71218.30", "0.002"], ["71219.70", "0.006"], ["71220.20", "0.008"], ["71229.00", "0.140"], ["71230.30", "0.082"], ["71233.90", "0.090"], ["71248.10", "0.161"], ["71317.70", "0.005"], ["71439.30", "0.000"], ["71924.50", "0.007"], ["71924.60", "0.694"], ["72421.30", "0.000"], ["72470.10", "0.689"], ["74791.00", "0.060"]]}}
{"local_ts": 1773384608036, "server_ts": 1773384607820, "data": {"e": "depthUpdate", "E": 1773384607821, "T": 1773384607820, "s": "BTCUSDT", "U": 10101346465789, "u": 10101346472345, "pu": 10101346465568, "b": [["1000.00", "27.892"], ["5000.00", "101.418"], ["20712.40", "0.045"], ["20812.40", "1.548"], ["20912.40", "0.207"], ["21012.40", "0.036"], ["21112.40", "0.864"], ["66100.00", "8.274"], ["67638.80", "0.010"], ["69076.00", "0.165"], ["70108.60", "0.997"], ["70179.80", "1.067"], ["70500.30", "0.708"], ["70901.00", "0.005"], ["70902.90", "0.000"], ["71110.00", "16.369"], ["71118.00", "1.711"], ["71128.20", "1.311"], ["71142.90", "0.186"], ["71144.70", "0.047"], ["71156.70", "0.657"], ["71157.20", "0.302"], ["71162.10", "0.000"], ["71167.20", "0.004"], ["71167.30", "0.007"], ["71185.30", "0.000"], ["71192.80", "0.659"], ["71198.30", "0.633"], ["71199.00", "0.005"], ["71205.40", "0.507"], ["71212.40", "2.856"]], "a": [["71212.50", "3.303"], ["71214.20", "0.001"], ["71218.00", "0.151"], ["71219.70", "0.004"], ["71225.80", "0.006"], ["71230.60", "0.233"], ["71232.00", "0.018"], ["71233.60", "0.384"], ["71233.90", "0.009"], ["71234.10", "0.020"], ["71236.40", "0.002"], ["71238.60", "0.005"], ["71242.70", "0.094"], ["71248.10", "0.062"], ["71261.20", "0.002"], ["71261.40", "0.027"], ["71273.00", "0.202"], ["71290.80", "0.081"], ["71303.60", "2.008"], ["71314.50", "0.443"], ["71326.40", "0.224"], ["71333.00", "0.161"], ["71370.00", "2.404"], ["71411.90", "0.159"], ["71924.60", "0.694"], ["72200.60", "0.000"], ["72245.10", "4.823"], ["74800.10", "0.000"], ["89523.20", "0.000"]]}}
{"local_ts": 1773384609067, "server_ts": 1773384608841, "data": {"e": "depthUpdate", "E": 1773384608843, "T": 1773384608841, "s": "BTCUSDT", "U": 10101346556150, "u": 10101346564061, "pu": 10101346556143, "b": [["1000.00", "27.892"], ["5000.00", "101.418"], ["20712.40", "1.368"], ["20812.40", "0.432"], ["21012.40", "0.801"], ["21112.40", "0.099"], ["33000.00", "9.343"], ["56970.00", "0.000"], ["64091.20", "0.002"], ["67651.00", "0.003"], ["70179.80", "2.063"], ["70222.50", "2.203"], ["70500.30", "1.416"], ["70609.90", "0.120"], ["70856.30", "0.004"], ["70901.00", "0.003"], ["70901.40", "0.002"], ["71121.30", "6.510"], ["71133.40", "0.144"], ["71134.00", "0.027"], ["71134.40", "0.106"], ["71134.70", "0.025"], ["71135.00", "0.097"], ["71138.60", "1.204"], ["71142.90", "0.186"], ["71143.00", "0.103"], ["71143.20", "0.263"], ["71148.30", "0.115"], ["71166.60", "0.033"], ["71167.30", "0.007"], ["71171.00", "0.026"], ["71171.50", "0.060"], ["71172.00", "7.745"], ["71172.10", "0.227"], ["71173.00", "0.057"], ["71173.90", "0.003"], ["71175.80", "0.006"], ["71176.00", "0.119"], ["71176.20", "0.000"], ["71179.50", "0.033"], ["71180.00", "0.055"], ["71182.10", "0.678"], ["71183.40", "0.248"], ["71184.70", "0.045"], ["71185.80", "0.115"], ["71191.10", "0.056"], ["71192.10", "0.376"], ["71192.40", "0.033"], ["71193.30", "0.006"], ["71193.80", "0.001"], ["71194.00", "0.007"], ["71194.60", "0.480"], ["71195.90", "0.639"], ["71197.30", "0.007"], ["71198.00", "0.004"], ["71198.40", "0.313"], ["71201.10", "0.061"], ["71201.50", "0.003"], ["71203.30", "0.202"], ["71203.40", "0.045"], ["71203.60", "0.007"], ["71203.70", "0.053"], ["71204.80", "0.025"], ["71205.10", "0.174"], ["71205.40", "0.507"], ["71205.60", "0.303"], ["71205.70", "0.092"], ["71206.10", "0.027"], ["71206.30", "0.006"], ["71206.50", "0.025"], ["71206.80", "1.075"], ["71212.30", "0.007"], ["71212.40", "1.576"]], "a": [["71212.50", "3.776"], ["71219.70", "0.008"], ["71220.30", "1.102"], ["71220.50", "0.003"], ["71225.30", "0.018"], ["71225.90", "0.077"], ["71226.30", "0.287"], ["71226.70", "0.124"], ["71227.10", "0.085"], ["71227.20", "0.047"], ["71227.80", "0.291"], ["71227.90", "0.077"], ["71228.40", "0.096"], ["71229.40", "0.004"], ["71230.00", "0.009"], ["71230.10", "0.012"], ["71230.60", "0.235"], ["71231.10", "0.000"], ["71231.80", "0.018"], ["71232.70", "0.638"], ["71233.90", "0.009"], ["71235.90", "0.000"], ["71236.40", "0.087"], ["71236.60", "1.053"], ["71236.80", "0.443"], ["71238.20", "0.249"], ["71239.40", "0.006"], ["71241.80", "0.001"], ["71243.30", "0.000"], ["71256.00", "0.004"], ["71261.80", "0.581"], ["71262.20", "0.063"], ["71262.60", "1.172"], ["71263.00", "0.124"], ["71263.70", "0.196"], ["71269.50", "0.163"], ["71269.70", "1.008"], ["71311.60", "0.061"], ["71462.20", "0.000"], ["71924.60", "1.388"], ["72158.60", "0.046"], ["72245.10", "5.790"], ["74780.50", "0.050"], ["78333.70", "0.059"], ["89523.20", "0.000"]]}}
{"local_ts": 1773384610082, "server_ts": 1773384609864, "data": {"e": "depthUpdate", "E": 1773384609865, "T": 1773384609864, "s": "BTCUSDT", "U": 10101346651151, "u": 10101346661893, "pu": 10101346651016, "b": [["5000.00", "101.398"], ["20712.40", "0.702"], ["20912.40", "0.675"], ["21012.40", "0.225"], ["21112.40", "1.098"], ["56335.30", "0.000"], ["64091.20", "0.002"], ["67638.30", "0.000"], ["67651.80", "0.012"], ["69921.40", "0.005"], ["70165.60", "1.444"], ["70500.30", "1.416"], ["71064.90", "0.724"], ["71065.00", "0.013"], ["71134.10", "0.039"], ["71148.30", "0.076"], ["71172.10", "0.043"], ["71172.40", "0.186"], ["71179.10", "0.371"], ["71180.40", "0.108"], ["71192.90", "0.852"], ["71201.70", "0.003"], ["71205.30", "0.000"], ["71205.70", "0.096"], ["71206.90", "0.001"], ["71207.00", "0.013"]], "a": [["71212.50", "1.791"], ["71212.60", "0.005"], ["71219.60", "0.000"], ["71220.40", "0.076"], ["71233.90", "0.090"], ["71248.50", "1.518"], ["71248.70", "0.304"], ["71260.90", "0.310"], ["71261.00", "0.004"], ["71276.60", "3.031"], ["71290.90", "1.807"], ["71362.30", "6.999"], ["71362.80", "0.000"], ["71924.60", "1.388"], ["74808.50", "0.062"], ["78333.70", "0.059"], ["89523.20", "0.000"]]}}
{"local_ts": 1773384611100, "server_ts": 1773384610884, "data": {"e": "depthUpdate", "E": 1773384610885, "T": 1773384610884, "s": "BTCUSDT", "U": 10101346726384, "u": 10101346732042, "pu": 10101346726319, "b": [["1000.00", "27.492"], ["5000.00", "101.418"], ["20812.40", "0.540"], ["20912.40", "0.360"], ["21012.40", "0.828"], ["21112.40", "0.972"], ["56335.30", "0.002"], ["56970.00", "0.008"], ["64091.20", "0.002"], ["70215.40", "3.128"], ["70500.30", "1.416"], ["71168.50", "0.040"], ["71172.40", "0.002"], ["71175.20", "1.610"], ["71177.40", "0.034"], ["71179.10", "0.300"], ["71196.60", "0.631"], ["71197.80", "0.426"], ["71198.10", "0.004"], ["71203.60", "0.007"], ["71204.10", "0.034"], ["71204.60", "0.035"], ["71205.70", "0.055"], ["71206.20", "0.050"], ["71206.40", "0.010"], ["71206.50", "0.025"], ["71206.90", "0.339"], ["71210.00", "0.006"], ["71212.40", "1.800"]], "a": [["71220.00", "0.024"], ["71220.10", "0.219"], ["71220.20", "0.653"], ["71221.40", "0.003"], ["71224.70", "0.005"], ["71226.10", "0.002"], ["71226.20", "0.036"], ["71226.30", "0.555"], ["71226.40", "0.006"], ["71236.90", "0.523"], ["71248.10", "0.454"], ["71269.40", "0.088"], ["71461.80", "0.813"], ["71924.60", "1.388"], ["74781.70", "0.000"], ["74788.30", "0.002"], ["78333.70", "0.059"], ["89523.20", "0.000"]]}}
{"local_ts": 1773384612122, "server_ts": 1773384611904, "data": {"e": "depthUpdate", "E": 1773384611907, "T": 1773384611904, "s": "BTCUSDT", "U": 10101346786479, "u": 10101346792398, "pu": 10101346786373, "b": [["5000.00", "101.418"], ["20712.40", "0.405"], ["20812.40", "0.495"], ["20912.40", "0.558"], ["21012.40", "1.242"], ["56335.30", "0.000"], ["64091.20", "0.010"], ["67619.80", "0.144"], ["70500.30", "1.416"], ["70856.30", "0.004"], ["71036.00", "0.160"], ["71036.90", "0.054"], ["71041.00", "0.000"], ["71052.60", "0.004"], ["71052.90", "0.004"], ["71060.80", "0.100"], ["71061.60", "0.072"], ["71062.60", "0.073"], ["71063.00", "0.675"], ["71063.30", "0.822"], ["71064.90", "0.697"], ["71166.90", "0.008"], ["71167.00", "0.007"], ["71171.80", "0.893"], ["71176.80", "0.068"], ["71179.10", "0.116"], ["71179.20", "0.000"], ["71180.80", "0.011"], ["71191.40", "1.051"], ["71192.60", "0.062"], ["71192.70", "0.768"], ["71193.60", "0.185"], ["71194.00", "0.014"], ["71195.20", "0.154"], ["71195.30", "0.235"], ["71195.70", "0.000"], ["71196.00", "0.004"], ["71196.10", "0.003"], ["71196.20", "0.130"], ["71196.30", "0.003"], ["71196.60", "0.025"], ["71196.80", "0.000"], ["71196.90", "0.030"], ["71197.30", "0.007"], ["71197.70", "0.008"], ["71198.20", "0.039"], ["71198.30", "0.002"], ["71198.40", "0.351"], ["71198.70", "0.002"], ["71199.00", "0.003"], ["71199.60", "0.008"], ["71200.10", "0.018"], ["71200.20", "0.004"], ["71200.30", "0.015"], ["71200.40", "0.002"], ["71200.50", "0.004"], ["71200.60", "0.443"], ["71200.70", "0.001"], ["71200.80", "0.003"], ["71200.90", "0.349"], ["71201.00", "0.076"], ["71201.10", "0.565"], ["71201.20", "0.001"], ["71201.40", "0.019"], ["71201.50", "0.003"], ["71201.70", "0.003"], ["71201.80", "0.000"], ["71202.00", "0.008"], ["71202.10", "0.001"], ["71202.20", "0.009"], ["71202.30", "0.000"], ["71202.50", "0.005"], ["71202.60", "0.002"], ["71202.70", "0.000"], ["71202.90", "0.070"], ["71203.00", "0.002"], ["71203.20", "0.022"], ["71203.40", "1.090"], ["71203.50", "0.015"], ["71203.70", "0.053"], ["71203.80", "0.000"], ["71204.00", "0.009"], ["71204.10", "0.005"], ["71204.20", "0.003"], ["71204.40", "0.002"], ["71204.80", "0.025"]], "a": [["71230.20", "0.241"], ["71230.60", "0.235"], ["71231.10", "0.000"], ["71231.50", "0.051"], ["71231.90", "0.631"], ["71232.90", "0.000"], ["71234.30", "0.072"], ["71235.20", "0.005"], ["71236.80", "0.002"], ["71238.20", "0.249"], ["71248.10", "0.289"], ["71260.70", "0.004"], ["71260.80", "0.050"], ["71261.50", "0.000"], ["71303.60", "2.006"], ["71361.90", "0.558"], ["71362.00", "0.000"], ["71450.40", "0.002"], ["71924.50", "0.007"], ["71924.60", "1.388"], ["74060.90", "0.020"], ["74775.30", "0.000"], ["78333.70", "0.067"], ["89523.20", "0.000"]]}}
{"local_ts": 1773384613149, "server_ts": 1773384612927, "data": {"e": "depthUpdate", "E": 1773384612929, "T": 1773384612927, "s": "BTCUSDT", "U": 10101346867867, "u": 10101346874799, "pu": 10101346867836, "b": [["1000.00", "27.492"], ["5000.00", "101.418"], ["20712.40", "0.630"], ["20812.40", "0.288"], ["20912.40", "1.512"], ["21012.40", "0.000"], ["21112.40", "0.270"], ["56335.30", "0.002"], ["64091.20", "0.010"], ["67643.50", "0.000"], ["70500.30", "1.416"], ["70512.00", "0.064"], ["71052.90", "0.002"], ["71054.60", "0.340"], ["71080.40", "0.178"], ["71091.30", "0.116"], ["71144.70", "0.107"], ["71150.70", "1.200"], ["71153.00", "0.005"], ["71156.70", "1.234"], ["71166.40", "0.002"], ["71167.20", "0.004"], ["71167.50", "0.003"], ["71170.80", "0.011"], ["71172.50", "0.075"], ["71172.70", "0.277"], ["71175.50", "0.051"], ["71177.00", "0.010"], ["71178.30", "0.321"], ["71179.20", "0.085"], ["71179.50", "0.215"], ["71180.20", "0.035"], ["71180.40", "0.351"], ["71181.10", "0.039"], ["71181.40", "0.041"], ["71182.20", "0.247"], ["71184.30", "0.011"], ["71185.10", "0.005"], ["71186.60", "0.029"], ["71187.10", "0.076"], ["71188.80", "0.000"], ["71189.00", "0.012"], ["71190.20", "0.073"], ["71190.30", "0.281"], ["71190.40", "0.010"], ["71190.70", "0.013"], ["71191.30", "0.335"], ["71191.40", "1.119"], ["71192.00", "0.004"], ["71192.20", "0.043"], ["71192.70", "0.770"], ["71192.80", "0.532"], ["71193.20", "0.049"], ["71193.70", "0.004"], ["71194.00", "0.027"], ["71194.20", "0.047"], ["71194.60", "0.341"], ["71194.70", "0.007"], ["71195.20", "0.268"], ["71195.30", "0.221"], ["71195.70", "0.000"], ["71196.00", "0.011"], ["71196.10", "0.683"], ["71196.30", "1.737"], ["71196.50", "0.019"], ["71197.10", "0.551"], ["71197.40", "0.512"], ["71198.10", "0.284"], ["71198.20", "0.039"], ["71198.50", "0.348"], ["71198.60", "0.083"], ["71198.70", "0.030"], ["71198.80", "0.073"], ["71198.90", "0.000"], ["71199.00", "0.003"], ["71199.50", "0.141"], ["71199.70", "0.002"], ["71200.00", "0.077"], ["71200.50", "0.048"], ["71200.60", "0.682"], ["71200.70", "0.043"], ["71201.20", "0.030"], ["71201.30", "0.258"], ["71201.40", "0.019"], ["71201.60", "0.021"], ["71201.90", "0.043"], ["71202.40", "0.002"], ["71202.50", "0.072"], ["71202.60", "0.002"], ["71202.70", "0.000"], ["71203.30", "0.724"], ["71203.50", "0.015"], ["71203.70", "0.067"], ["71203.80", "0.032"], ["71203.90", "0.015"], ["71204.00", "0.009"], ["71204.40", "0.002"], ["71204.80", "0.007"], ["71205.60", "0.327"], ["71206.30", "0.003"], ["71207.50", "0.004"], ["71207.90", "0.264"], ["71208.80", "0.050"], ["71208.90", "0.009"], ["71210.00", "0.006"], ["71210.10", "0.000"], ["71210.40", "0.107"], ["71210.60", "0.004"], ["71211.10", "0.005"], ["71211.30", "0.004"], ["71211.70", "0.000"], ["71211.80", "0.225"], ["71212.30", "0.036"], ["71212.40", "2.251"]], "a": [["71212.50", "3.559"], ["71213.00", "0.002"], ["71213.10", "0.015"], ["71213.40", "0.002"], ["71213.50", "0.001"], ["71214.30", "0.018"], ["71214.50", "0.214"], ["71214.70", "0.000"], ["71215.10", "0.002"], ["71215.60", "0.018"], ["71216.00", "0.001"], ["71216.90", "0.075"], ["71217.20", "0.000"], ["71218.10", "0.017"], ["71218.40", "0.006"], ["71218.50", "0.106"], ["71219.40", "0.017"], ["71219.70", "0.006"], ["71220.20", "0.653"], ["71220.60", "0.020"], ["71220.70", "0.007"], ["71221.00", "0.005"], ["71221.90", "0.015"], ["71222.30", "0.000"], ["71222.40", "0.002"], ["71223.50", "0.041"], ["71224.80", "0.006"], ["71226.20", "0.036"], ["71227.30", "0.002"], ["71227.40", "0.261"], ["71227.50", "0.240"], ["71227.60", "0.000"], ["71229.50", "0.017"], ["71230.20", "0.137"], ["71230.30", "0.001"], ["71231.60", "0.006"], ["71231.70", "0.634"], ["71233.20", "0.002"], ["71233.90", "0.226"], ["71234.10", "0.069"], ["71234.40", "0.008"], ["71234.80", "0.000"], ["71235.00", "0.007"], ["71235.70", "0.000"], ["71235.80", "0.021"], ["71236.20", "0.007"], ["71236.30", "0.075"], ["71236.50", "0.576"], ["71236.60", "1.053"], ["71236.70", "0.226"], ["71237.30", "0.002"], ["71237.40", "0.085"], ["71237.60", "0.011"], ["71237.70", "0.030"], ["71237.80", "0.002"], ["71237.90", "0.211"], ["71238.20", "0.004"], ["71238.70", "0.084"], ["71238.90", "0.009"], ["71239.40", "0.249"], ["71239.60", "0.004"], ["71239.70", "0.033"], ["71239.90", "0.004"], ["71240.00", "0.011"], ["71240.60", "0.505"], ["71241.10", "0.032"], ["71241.20", "0.002"], ["71241.30", "0.001"], ["71241.80", "0.001"], ["71242.50", "0.106"], ["71243.70", "0.134"], ["71243.90", "0.001"], ["71245.00", "0.030"], ["71245.70", "0.000"], ["71246.20", "0.031"], ["71247.10", "0.006"], ["71247.40", "0.000"], ["71247.50", "0.032"], ["71248.10", "0.715"], ["71249.60", "0.029"], ["71250.10", "0.004"], ["71251.10", "0.200"], ["71251.40", "1.069"], ["71252.30", "0.024"], ["71252.40", "0.100"], ["71252.80", "0.336"], ["71253.70", "0.001"], ["71254.90", "1.164"], ["71255.30", "0.892"], ["71256.70", "0.000"], ["71258.10", "0.018"], ["71258.20", "0.003"], ["71259.50", "0.050"], ["71260.60", "0.036"], ["71260.70", "0.004"], ["71260.80", "0.032"], ["71262.40", "0.025"], ["71263.50", "0.122"], ["71266.00", "0.005"], ["71268.50", "0.002"], ["71269.70", "1.008"], ["71269.90", "0.385"], ["71273.40", "0.106"], ["71274.60", "0.019"], ["71306.40", "0.003"], ["71344.20", "0.358"], ["71439.20", "0.000"], ["71568.60", "0.035"], ["71580.30", "0.060"], ["71924.60", "1.388"], ["72257.30", "0.829"], ["72861.40", "0.002"], ["74779.60", "0.002"], ["78333.70", "0.067"], ["89523.20", "0.000"]]}}
{"local_ts": 1773384614166, "server_ts": 1773384613949, "data": {"e": "depthUpdate", "E": 1773384613951, "T": 1773384613949, "s": "BTCUSDT", "U": 10101346946057, "u": 10101346950736, "pu": 10101346946049, "b": [["1000.00", "27.492"], ["5000.00", "101.438"], ["20712.40", "0.135"], ["20812.40", "1.557"], ["20912.40", "0.108"], ["21012.40", "0.135"], ["21112.40", "0.765"], ["56335.30", "0.000"], ["56970.00", "0.000"], ["64091.20", "0.008"], ["69894.60", "1.457"], ["70500.30", "1.416"], ["70856.30", "0.004"], ["71054.40", "0.002"], ["71054.60", "0.338"], ["71167.30", "0.007"], ["71167.40", "0.083"], ["71177.40", "1.820"], ["71179.10", "0.484"], ["71179.20", "0.184"], ["71179.50", "0.031"], ["71179.70", "0.085"], ["71181.10", "0.019"], ["71190.70", "0.019"], ["71204.40", "0.006"], ["71211.90", "0.769"], ["71212.40", "3.334"]], "a": [["71214.50", "0.229"], ["71216.10", "0.017"], ["71248.10", "0.584"], ["71256.60", "1.053"], ["71258.00", "0.008"], ["71258.10", "0.018"], ["71258.40", "0.766"], ["71259.70", "0.002"], ["71260.80", "0.034"], ["71260.90", "0.308"], ["71261.10", "0.236"], ["71278.90", "0.002"], ["71280.60", "0.002"], ["71924.60", "1.388"], ["74783.60", "0.002"], ["78333.70", "0.065"], ["89523.20", "0.000"]]}}
{"local_ts": 1773384615196, "server_ts": 1773384614972, "data": {"e": "depthUpdate", "E": 1773384614973, "T": 1773384614972, "s": "BTCUSDT", "U": 10101347094348, "u": 10101347128878, "pu": 10101347094318, "b": [["5000.00", "101.398"], ["20724.20", "0.054"], ["20727.00", "0.144"], ["20812.40", "0.243"], ["21027.00", "0.072"], ["21112.40", "0.000"], ["40000.00", "49.307"], ["56335.30", "0.002"], ["64100.90", "0.000"], ["64104.30", "0.004"], ["67651.80", "0.006"], ["67651.90", "0.012"], ["68389.30", "0.015"], ["70217.90", "0.000"], ["70219.90", "2.847"], ["70224.20", "0.004"], ["70227.00", "0.016"], ["70512.00", "0.064"], ["70514.70", "0.002"], ["70922.60", "0.000"], ["70962.40", "0.000"], ["70982.50", "0.300"], ["70999.30", "0.000"], ["71014.90", "0.004"], ["71020.30", "0.000"], ["71020.40", "0.201"], ["71028.90", "0.003"], ["71031.10", "0.200"], ["71033.10", "0.000"], ["71035.00", "10.400"], ["71035.10", "2.294"], ["71035.40", "0.000"], ["71035.90", "0.000"], ["71041.40", "0.002"], ["71047.50", "0.075"], ["71054.40", "0.000"], ["71056.10", "3.200"], ["71065.60", "0.002"], ["71070.00", "16.175"], ["71075.30", "0.102"], ["71079.40", "0.010"], ["71081.50", "0.000"], ["71081.60", "0.000"], ["71096.80", "0.004"], ["71097.50", "0.000"], ["71097.60", "0.227"], ["71097.80", "0.003"], ["71097.90", "0.078"], ["71098.10", "0.507"], ["71098.20", "0.202"], ["71098.50", "0.004"], ["71098.60", "0.001"], ["71098.80", "0.077"], ["71099.20", "0.028"], ["71102.00", "1.198"], ["71105.40", "0.500"], ["71106.00", "0.199"], ["71113.40", "0.077"], ["71114.00", "0.476"], ["71114.80", "0.120"], ["71115.30", "1.140"], ["71115.70", "0.001"], ["71116.60", "2.106"], ["71117.00", "0.045"], ["71118.70", "0.070"], ["71120.10", "0.512"], ["71121.30", "6.474"], ["71122.00", "0.005"], ["71122.40", "0.546"], ["71122.80", "0.038"], ["71123.70", "0.938"], ["71127.90", "0.002"], ["71128.10", "4.306"], ["71128.70", "0.228"], ["71130.50", "0.122"], ["71130.70", "0.017"], ["71130.80", "0.121"], ["71133.40", "0.000"], ["71133.70", "0.036"], ["71134.00", "0.002"], ["71134.10", "0.000"], ["71134.40", "0.045"], ["71134.70", "0.000"], ["71135.00", "0.072"], ["71135.10", "2.038"], ["71135.20", "0.140"], ["71136.00", "0.018"], ["71137.00", "0.000"], ["71137.50", "0.544"], ["71137.80", "0.300"], ["71139.70", "0.047"], ["71139.90", "0.004"], ["71142.30", "0.071"], ["71143.80", "0.075"], ["71146.70", "0.000"], ["71148.50", "0.000"], ["71151.70", "0.306"], ["71152.70", "0.523"], ["71153.80", "0.105"], ["71154.40", "0.153"], ["71155.00", "0.079"], ["71155.50", "0.079"], ["71156.40", "0.082"], ["71156.80", "0.324"], ["71157.00", "0.077"], ["71166.90", "0.003"], ["71169.30", "0.316"], ["71170.10", "0.959"], ["71170.20", "0.873"], ["71173.00", "0.025"], ["71173.30", "0.332"], ["71175.00", "0.145"], ["71175.10", "0.002"], ["71175.80", "0.003"], ["71175.90", "0.003"], ["71176.30", "0.205"], ["71176.80", "0.000"], ["71177.00", "0.003"], ["71177.10", "0.005"], ["71177.40", "1.800"], ["71177.50", "0.835"], ["71177.60", "0.398"], ["71177.90", "0.000"], ["71178.40", "0.017"], ["71178.60", "0.319"], ["71179.00", "1.052"], ["71179.50", "0.186"], ["71179.60", "1.302"], ["71179.90", "0.110"], ["71180.30", "0.003"], ["71180.40", "0.048"], ["71181.60", "0.000"], ["71182.00", "0.508"], ["71182.50", "0.049"], ["71182.80", "0.017"], ["71183.50", "0.000"], ["71184.20", "0.518"], ["71184.30", "0.004"], ["71184.80", "0.005"], ["71185.20", "0.704"], ["71185.80", "0.002"], ["71186.60", "0.000"], ["71187.10", "0.006"], ["71187.20", "0.043"], ["71187.30", "2.016"], ["71187.80", "0.002"], ["71187.90", "0.087"], ["71188.00", "0.024"], ["71188.10", "0.311"], ["71188.50", "0.001"], ["71188.60", "0.316"], ["71188.80", "0.000"], ["71188.90", "0.007"], ["71189.20", "0.001"], ["71189.30", "0.308"], ["71189.90", "0.006"], ["71190.00", "0.016"], ["71191.30", "0.335"], ["71191.40", "1.124"], ["71192.00", "0.004"], ["71192.10", "0.002"], ["71192.60", "0.312"], ["71192.70", "0.339"], ["71192.80", "0.000"], ["71193.10", "0.010"], ["71193.40", "0.003"], ["71193.50", "0.531"], ["71194.10", "0.265"], ["71194.20", "0.127"], ["71194.30", "0.055"], ["71194.40", "0.053"], ["71194.70", "0.007"], ["71194.80", "0.000"], ["71194.90", "0.388"], ["71195.20", "0.049"], ["71195.40", "0.000"], ["71195.50", "0.007"], ["71195.60", "0.003"], ["71196.40", "0.907"], ["71196.80", "0.000"], ["71197.80", "0.000"], ["71198.60", "0.004"], ["71199.00", "0.023"], ["71199.20", "0.001"], ["71199.30", "0.005"], ["71200.00", "0.079"], ["71200.50", "0.038"], ["71200.60", "0.119"], ["71201.20", "0.275"], ["71201.50", "0.031"], ["71201.70", "0.002"], ["71202.40", "0.028"], ["71202.50", "0.020"], ["71202.60", "0.001"], ["71202.80", "0.000"], ["71202.90", "0.004"], ["71203.00", "0.004"], ["71203.40", "1.089"], ["71204.20", "0.003"], ["71204.50", "0.004"], ["71204.60", "0.042"], ["71204.80", "0.012"], ["71204.90", "0.002"], ["71205.30", "0.062"], ["71205.40", "0.087"], ["71205.60", "0.007"], ["71205.80", "0.004"], ["71205.90", "0.002"], ["71206.40", "0.167"], ["71206.50", "0.000"], ["71207.40", "0.016"], ["71207.90", "0.264"], ["71208.00", "0.008"], ["71208.20", "0.026"], ["71208.60", "0.039"], ["71208.90", "0.002"], ["71209.20", "0.041"], ["71209.30", "0.300"], ["71209.50", "0.008"], ["71209.60", "0.130"], ["71209.90", "0.003"], ["71210.00", "0.303"], ["71210.20", "0.002"], ["71210.30", "0.015"], ["71210.40", "0.008"], ["71210.60", "0.319"], ["71210.80", "0.101"], ["71210.90", "0.002"], ["71212.00", "0.014"], ["71212.20", "0.001"], ["71212.30", "0.045"], ["71212.60", "0.510"], ["71212.70", "1.267"], ["71212.80", "0.000"], ["71212.90", "0.301"], ["71213.00", "0.000"], ["71213.40", "0.736"], ["71213.50", "0.000"], ["71213.60", "0.008"], ["71213.70", "0.635"], ["71213.90", "0.000"], ["71214.00", "0.010"], ["71214.10", "0.000"], ["71214.20", "0.005"], ["71214.30", "0.032"], ["71214.50", "0.076"], ["71214.90", "0.104"], ["71215.00", "0.006"], ["71215.10", "0.004"], ["71215.20", "0.061"], ["71215.30", "0.003"], ["71215.40", "0.001"], ["71215.60", "0.252"], ["71215.70", "0.002"], ["71215.80", "0.020"], ["71215.90", "0.000"], ["71216.00", "0.004"], ["71216.10", "0.509"], ["71216.20", "0.004"], ["71216.30", "0.045"], ["71216.40", "0.038"], ["71216.50", "0.002"], ["71216.60", "0.073"], ["71216.80", "0.003"], ["71217.10", "0.021"], ["71217.20", "0.246"], ["71217.30", "0.249"], ["71217.50", "0.023"], ["71217.70", "0.000"], ["71217.80", "0.078"], ["71218.00", "0.056"], ["71218.10", "0.048"], ["71218.30", "0.000"], ["71218.40", "0.598"], ["71218.50", "0.435"], ["71218.60", "0.060"], ["71218.70", "0.078"], ["71218.80", "0.025"], ["71219.00", "1.090"], ["71219.30", "0.021"], ["71219.80", "0.412"], ["71219.90", "0.044"], ["71220.10", "0.324"], ["71220.20", "0.713"], ["71220.50", "0.000"], ["71220.60", "0.509"], ["71220.90", "0.002"], ["71221.00", "0.004"], ["71221.10", "0.011"], ["71221.30", "0.000"], ["71221.80", "0.000"], ["71222.00", "0.046"], ["71222.30", "0.004"], ["71222.70", "0.003"], ["71222.90", "0.032"], ["71223.00", "0.000"], ["71223.20", "0.085"], ["71223.30", "0.006"], ["71223.40", "0.204"], ["71223.50", "0.001"], ["71223.60", "0.034"], ["71223.70", "0.099"], ["71223.90", "0.003"], ["71224.00", "0.000"], ["71224.10", "0.002"], ["71224.20", "0.075"], ["71224.30", "1.100"], ["71224.40", "0.000"], ["71224.60", "0.004"], ["71224.80", "0.002"], ["71224.90", "0.001"], ["71225.00", "0.068"], ["71225.10", "0.000"], ["71225.20", "0.042"], ["71225.30", "0.010"], ["71225.40", "0.000"], ["71225.50", "0.002"], ["71225.60", "0.001"], ["71225.70", "0.000"], ["71225.80", "0.002"], ["71225.90", "0.002"], ["71226.00", "0.001"], ["71226.10", "0.000"], ["71226.20", "0.210"], ["71226.30", "0.042"], ["71226.40", "0.002"], ["71226.50", "0.000"], ["71226.60", "0.000"], ["71226.70", "0.000"], ["71226.90", "0.002"], ["71227.00", "9.358"]], "a": [["71224.30", "0.000"], ["71224.40", "0.000"], ["71224.50", "0.000"], ["71224.70", "0.000"], ["71224.90", "0.000"], ["71225.00", "0.000"], ["71225.20", "0.000"], ["71225.30", "0.000"], ["71225.40", "0.000"], ["71225.50", "0.000"], ["71225.70", "0.000"], ["71225.80", "0.000"], ["71226.00", "0.000"], ["71226.10", "0.000"], ["71226.20", "0.000"], ["71226.30", "0.000"], ["71226.40", "0.000"], ["71226.50", "0.000"], ["71226.60", "0.000"], ["71226.70", "0.000"], ["71226.80", "0.000"], ["71227.00", "0.000"], ["71227.10", "0.069"], ["71227.40", "0.002"], ["71227.70", "0.000"], ["71228.10", "0.003"], ["71228.40", "0.004"], ["71228.50", "0.005"], ["71228.60", "0.034"], ["71229.00", "0.003"], ["71229.30", "0.000"], ["71229.40", "0.002"], ["71229.50", "0.005"], ["71229.70", "0.002"], ["71229.90", "0.150"], ["71230.10", "0.009"], ["71230.40", "0.003"], ["71230.50", "0.004"], ["71230.70", "0.009"], ["71231.60", "0.002"], ["71231.80", "0.013"], ["71232.00", "0.010"], ["71232.10", "0.002"], ["71232.30", "0.027"], ["71232.40", "0.003"], ["71232.70", "0.028"], ["71232.80", "0.003"], ["71232.90", "0.000"], ["71233.10", "0.049"], ["71233.20", "0.038"], ["71233.30", "0.210"], ["71233.40", "0.038"], ["71233.50", "0.007"], ["71233.70", "0.006"], ["71233.80", "0.288"], ["71234.00", "0.003"], ["71234.10", "0.072"], ["71234.20", "0.000"], ["71234.70", "0.000"], ["71235.10", "0.002"], ["71235.40", "0.101"], ["71235.50", "0.206"], ["71235.60", "0.003"], ["71235.90", "0.069"], ["71236.00", "0.007"], ["71236.10", "0.003"], ["71236.20", "0.007"], ["71236.40", "0.000"], ["71236.50", "0.003"], ["71236.60", "0.004"], ["71236.70", "0.002"], ["71236.80", "0.004"], ["71236.90", "0.018"], ["71237.00", "0.009"], ["71237.10", "0.058"], ["71237.20", "0.300"], ["71237.40", "0.004"], ["71237.50", "0.004"], ["71237.60", "0.000"], ["71238.00", "0.008"], ["71238.10", "0.008"], ["71238.30", "0.003"], ["71238.40", "0.001"], ["71238.70", "0.084"], ["71238.80", "0.002"], ["71239.50", "0.131"], ["71239.60", "0.006"], ["71239.80", "0.000"], ["71239.90", "0.004"], ["71240.00", "0.007"], ["71240.60", "0.001"], ["71240.70", "0.000"], ["71241.00", "0.161"], ["71241.30", "0.001"], ["71241.70", "0.001"], ["71241.80", "0.001"], ["71241.90", "0.026"], ["71242.10", "0.007"], ["71242.50", "0.029"], ["71242.80", "0.003"], ["71242.90", "0.019"], ["71243.00", "0.002"], ["71243.10", "0.003"], ["71243.70", "0.755"], ["71243.80", "0.006"], ["71243.90", "0.001"], ["71244.10", "0.015"], ["71244.20", "0.244"], ["71244.30", "0.015"], ["71244.40", "0.501"], ["71244.50", "0.005"], ["71244.70", "0.000"], ["71244.90", "0.021"], ["71245.10", "0.006"], ["71245.50", "0.000"], ["71245.60", "0.003"], ["71245.70", "0.003"], ["71245.80", "0.002"], ["71246.10", "0.000"], ["71246.30", "0.009"], ["71246.40", "0.006"], ["71246.50", "0.002"], ["71246.60", "0.142"], ["71246.70", "0.315"], ["71246.80", "0.425"], ["71247.00", "0.015"], ["71247.30", "0.001"], ["71247.40", "0.000"], ["71247.50", "0.003"], ["71247.60", "0.000"], ["71247.80", "0.086"], ["71247.90", "0.142"], ["71248.10", "0.347"], ["71248.20", "0.301"], ["71248.40", "0.341"], ["71248.50", "1.133"], ["71248.70", "0.304"], ["71248.80", "0.005"], ["71248.90", "0.003"], ["71249.20", "0.013"], ["71249.40", "0.007"], ["71249.50", "0.008"], ["71249.60", "0.000"], ["71249.70", "0.027"], ["71250.10", "0.024"], ["71250.20", "0.046"], ["71250.30", "0.022"], ["71250.40", "0.000"], ["71250.60", "0.040"], ["71250.70", "0.109"], ["71250.80", "0.000"], ["71250.90", "1.052"], ["71251.00", "0.004"], ["71251.10", "0.219"], ["71251.20", "0.001"], ["71251.40", "0.055"], ["71251.50", "0.650"], ["71251.60", "0.845"], ["71251.70", "0.006"], ["71251.80", "0.007"], ["71252.00", "0.370"], ["71252.30", "0.015"], ["71252.40", "0.000"], ["71252.70", "0.000"], ["71252.90", "0.000"], ["71253.00", "0.020"], ["71253.10", "0.014"], ["71253.40", "0.114"], ["71253.60", "0.511"], ["71253.70", "0.001"], ["71253.80", "0.002"], ["71254.10", "0.705"], ["71254.20", "0.013"], ["71254.40", "0.946"], ["71254.50", "0.004"], ["71254.70", "0.035"], ["71254.80", "0.043"], ["71254.90", "0.001"], ["71255.00", "0.305"], ["71255.10", "0.216"], ["71255.60", "0.000"], ["71255.90", "0.044"], ["71256.00", "0.508"], ["71256.40", "0.004"], ["71256.50", "0.076"], ["71257.20", "0.247"], ["71257.30", "0.000"], ["71257.50", "0.005"], ["71258.30", "0.002"], ["71258.60", "0.007"], ["71258.70", "0.005"], ["71258.90", "0.070"], ["71259.10", "0.459"], ["71259.40", "0.302"], ["71259.90", "0.000"], ["71260.80", "0.011"], ["71261.10", "0.214"], ["71261.20", "0.100"], ["71261.60", "0.509"], ["71261.80", "0.506"], ["71262.00", "0.014"], ["71262.20", "0.000"], ["71262.40", "0.011"], ["71262.60", "1.049"], ["71262.70", "0.040"], ["71262.90", "0.012"], ["71263.00", "0.000"], ["71263.20", "0.301"], ["71263.30", "0.065"], ["71263.60", "0.029"], ["71263.70", "0.002"], ["71263.80", "0.003"], ["71263.90", "0.307"], ["71264.50", "0.002"], ["71264.80", "0.002"], ["71265.10", "0.059"], ["71265.30", "0.205"], ["71265.70", "0.999"], ["71266.00", "1.072"], ["71266.50", "0.002"], ["71266.60", "0.072"], ["71267.10", "0.003"], ["71267.30", "0.283"], ["71267.70", "0.022"], ["71268.10", "0.179"], ["71268.40", "0.022"], ["71268.80", "0.280"], ["71269.10", "0.030"], ["71269.70", "1.106"], ["71269.80", "0.199"], ["71269.90", "1.061"], ["71270.80", "0.000"], ["71270.90", "0.003"], ["71271.40", "0.124"], ["71271.50", "0.694"], ["71271.60", "0.003"], ["71271.80", "0.106"], ["71271.90", "0.036"], ["71272.10", "0.000"], ["71272.40", "0.013"], ["71272.50", "0.004"], ["71273.30", "0.310"], ["71273.40", "0.205"], ["71273.70", "0.015"], ["71273.90", "0.002"], ["71274.40", "0.512"], ["71275.10", "0.004"], ["71275.20", "0.160"], ["71275.50", "0.001"], ["71275.90", "0.000"], ["71276.60", "2.922"], ["71276.90", "0.514"], ["71277.00", "7.846"], ["71277.20", "0.108"], ["71277.50", "0.000"], ["71277.60", "0.004"], ["71277.70", "0.104"], ["71277.90", "0.004"], ["71278.30", "0.247"], ["71278.50", "0.016"], ["71278.70", "0.140"], ["71278.90", "0.070"], ["71279.00", "0.002"], ["71279.30", "0.018"], ["71279.40", "0.003"], ["71279.80", "0.348"], ["71280.10", "0.003"], ["71280.20", "0.000"], ["71280.40", "0.043"], ["71280.90", "0.051"], ["71281.60", "0.103"], ["71281.70", "0.060"], ["71281.80", "0.002"], ["71281.90", "0.099"], ["71282.00", "0.000"], ["71282.40", "0.107"], ["71282.80", "0.205"], ["71285.00", "0.526"], ["71286.20", "0.004"], ["71287.30", "0.195"], ["71288.80", "0.340"], ["71290.20", "0.000"], ["71292.30", "0.102"], ["71292.40", "0.000"], ["71292.80", "0.312"], ["71293.30", "0.005"], ["71293.40", "0.308"], ["71294.10", "0.000"], ["71294.20", "0.016"], ["71294.70", "0.000"], ["71295.50", "0.000"], ["71296.20", "0.251"], ["71296.30", "0.002"], ["71296.90", "0.020"], ["71297.70", "0.000"], ["71297.80", "0.007"], ["71297.90", "0.073"], ["71298.00", "1.106"], ["71298.10", "0.079"], ["71298.40", "0.440"], ["71298.50", "0.004"], ["71298.90", "0.000"], ["71299.20", "0.002"], ["71299.50", "0.025"], ["71299.60", "0.063"], ["71299.70", "0.041"], ["71299.80", "0.414"], ["71299.90", "0.307"], ["71301.50", "0.055"], ["71301.60", "1.096"], ["71301.70", "0.611"], ["71301.80", "0.284"], ["71302.20", "0.006"], ["71303.70", "0.327"], ["71303.80", "0.000"], ["71304.60", "0.000"], ["71305.50", "0.070"], ["71306.10", "0.000"], ["71307.30", "0.146"], ["71307.60", "1.123"], ["71308.40", "1.703"], ["71311.60", "0.000"], ["71312.60", "0.003"], ["71313.50", "0.455"], ["71313.60", "0.000"], ["71314.30", "0.001"], ["71316.60", "0.442"], ["71317.40", "0.002"], ["71319.60", "2.703"], ["71320.50", "0.000"], ["71320.70", "0.003"], ["71322.30", "0.068"], ["71332.00", "0.558"], ["71332.60", "0.071"], ["71333.00", "0.161"], ["71333.60", "0.000"], ["71333.80", "0.093"], ["71334.00", "0.056"], ["71334.30", "0.505"], ["71334.40", "0.000"], ["71334.70", "0.000"], ["71334.80", "0.000"], ["71335.10", "0.042"], ["71335.40", "0.077"], ["71335.50", "0.000"], ["71342.00", "0.284"], ["71342.30", "0.011"], ["71343.90", "0.549"], ["71344.20", "0.572"], ["71347.40", "0.511"], ["71348.90", "0.002"], ["71352.50", "0.019"], ["71353.50", "0.353"], ["71373.70", "4.981"], ["71381.70", "0.000"], ["71381.80", "0.000"], ["71382.40", "0.040"], ["71394.70", "10.000"], ["71395.20", "1.963"], ["71395.30", "1.553"], ["71395.40", "0.000"], ["71399.90", "0.000"], ["71401.60", "0.140"], ["71405.00", "0.077"], ["71405.20", "0.100"], ["71406.20", "0.081"], ["71407.70", "0.002"], ["71424.50", "0.040"], ["71429.20", "0.344"], ["71438.30", "0.003"], ["71441.80", "0.008"], ["71465.70", "0.006"], ["71486.70", "0.003"], ["71528.30", "0.602"], ["71528.60", "0.302"], ["71532.30", "1.289"], ["71533.10", "6.420"], ["71602.20", "0.000"], ["71645.50", "0.002"], ["71924.60", "1.424"], ["71936.50", "0.963"], ["71939.40", "0.007"], ["73006.90", "0.002"], ["73007.50", "0.274"], ["74804.20", "0.002"], ["75437.60", "0.000"], ["75615.10", "0.000"], ["78345.60", "0.000"], ["89523.20", "0.000"]]}}
{"local_ts": 1773384616214, "server_ts": 1773384615994, "data": {"e": "depthUpdate", "E": 1773384615995, "T": 1773384615994, "s": "BTCUSDT", "U": 10101347190981, "u": 10101347196295, "pu": 10101347190971, "b": [["1000.00", "27.492"], ["5000.00", "101.418"], ["20712.40", "0.315"], ["20718.80", "0.099"], ["20927.00", "0.765"], ["21012.40", "0.135"], ["21127.00", "1.296"], ["21127.10", "0.000"], ["33000.00", "9.339"], ["56335.30", "0.000"], ["64104.30", "0.012"], ["67639.60", "0.002"], ["68870.30", "0.000"], ["69791.40", "0.617"], ["70421.10", "0.022"], ["70514.70", "0.000"], ["70977.40", "6.415"], ["71065.60", "0.000"], ["71065.80", "0.304"], ["71075.70", "0.000"], ["71169.40", "0.625"], ["71186.20", "0.046"], ["71187.10", "0.048"], ["71188.10", "0.353"], ["71189.10", "0.042"], ["71190.10", "0.043"], ["71191.00", "0.583"], ["71192.00", "0.046"], ["71193.00", "0.049"], ["71193.90", "0.008"], ["71194.90", "0.317"], ["71195.90", "0.003"], ["71196.90", "0.005"], ["71197.60", "0.022"], ["71197.80", "0.000"], ["71198.80", "0.002"], ["71199.80", "0.007"], ["71201.40", "0.019"], ["71202.40", "0.020"], ["71203.50", "0.072"], ["71205.60", "0.026"], ["71206.60", "0.076"], ["71207.70", "0.002"], ["71208.20", "0.014"], ["71210.00", "0.639"], ["71211.20", "0.000"], ["71213.70", "0.473"], ["71213.80", "0.004"], ["71216.50", "0.002"], ["71218.80", "0.024"], ["71219.90", "0.038"], ["71227.00", "4.408"]], "a": [["71227.10", "3.727"], ["71228.50", "0.005"], ["71234.20", "0.000"], ["71237.20", "0.355"], ["71239.00", "0.068"], ["71239.50", "0.134"], ["71241.30", "0.082"], ["71243.10", "0.282"], ["71243.20", "0.100"], ["71246.50", "0.009"], ["71247.80", "0.001"], ["71268.10", "0.004"], ["71268.30", "1.117"], ["71269.50", "0.057"], ["71269.80", "0.358"], ["71273.70", "0.000"], ["71275.80", "0.006"], ["71276.10", "0.063"], ["71276.80", "0.026"], ["71277.00", "7.886"], ["71280.90", "0.000"], ["71281.70", "0.007"], ["71374.60", "0.000"], ["71939.40", "0.007"], ["72113.30", "4.743"], ["74813.70", "0.000"], ["78349.80", "0.000"], ["78414.30", "0.000"], ["89523.20", "0.000"]]}}
{"local_ts": 1773384617237, "server_ts": 1773384617016, "data": {"e": "depthUpdate", "E": 1773384617019, "T": 1773384617016, "s": "BTCUSDT", "U": 10101347291672, "u": 10101347300575, "pu": 10101347291648, "b": [["5000.00", "101.418"], ["20826.20", "0.450"], ["20927.00", "0.261"], ["21026.20", "0.837"], ["21127.00", "0.711"], ["40000.00", "49.560"], ["56335.30", "0.002"], ["64103.60", "0.000"], ["67641.20", "0.002"], ["70167.60", "14.394"], ["70229.10", "0.288"], ["70513.90", "0.000"], ["70870.90", "0.000"], ["71096.20", "0.016"], ["71127.10", "0.169"], ["71132.60", "0.020"], ["71164.20", "1.202"], ["71168.40", "0.080"], ["71169.50", "0.506"], ["71173.60", "0.004"], ["71175.60", "0.110"], ["71185.60", "0.027"], ["71194.30", "0.004"], ["71194.50", "0.252"], ["71197.10", "0.516"], ["71202.20", "0.012"], ["71202.90", "0.004"], ["71205.30", "0.002"], ["71206.70", "0.073"], ["71206.90", "0.339"], ["71207.00", "0.013"], ["71207.10", "0.001"], ["71207.50", "0.006"], ["71208.00", "1.208"], ["71208.60", "0.405"], ["71208.70", "0.001"], ["71209.50", "0.008"], ["71209.60", "0.032"], ["71210.20", "0.054"], ["71210.40", "0.012"], ["71210.80", "0.438"], ["71210.90", "0.192"], ["71212.00", "0.145"], ["71213.10", "0.086"], ["71213.30", "0.988"], ["71213.50", "0.093"], ["71213.60", "0.132"], ["71214.00", "0.101"], ["71214.70", "0.046"], ["71218.80", "0.731"], ["71219.90", "0.713"], ["71220.20", "0.257"], ["71220.60", "0.003"], ["71223.40", "0.213"], ["71226.20", "1.608"]], "a": [["71226.30", "7.366"], ["71226.90", "0.000"], ["71227.00", "0.002"], ["71231.30", "0.061"], ["71232.30", "0.034"], ["71233.20", "0.002"], ["71234.00", "0.005"], ["71236.30", "0.014"], ["71236.40", "0.181"], ["71236.70", "0.002"], ["71237.20", "0.718"], ["71237.80", "0.001"], ["71238.70", "0.082"], ["71240.00", "0.004"], ["71240.90", "0.150"], ["71241.20", "0.004"], ["71241.40", "0.002"], ["71242.10", "0.010"], ["71242.30", "0.083"], ["71242.40", "0.008"], ["71242.60", "0.004"], ["71242.90", "0.003"], ["71243.20", "0.100"], ["71243.30", "0.000"], ["71243.40", "0.003"], ["71243.50", "0.090"], ["71243.60", "0.000"], ["71244.20", "1.005"], ["71244.60", "0.056"], ["71244.70", "0.012"], ["71246.00", "0.013"], ["71249.40", "0.007"], ["71249.70", "0.015"], ["71251.10", "0.305"], ["71251.20", "0.514"], ["71253.00", "0.004"], ["71253.10", "0.018"], ["71253.70", "0.010"], ["71253.80", "0.011"], ["71254.40", "0.944"], ["71254.50", "0.002"], ["71255.10", "0.216"], ["71255.20", "0.002"], ["71265.50", "0.205"], ["71274.30", "0.071"], ["71274.60", "0.021"], ["71279.10", "0.136"], ["71296.00", "0.704"], ["71297.10", "0.035"], ["71321.00", "0.322"], ["71938.60", "0.006"], ["78348.90", "0.000"], ["100000.00", "15.858"]]}}
{"local_ts": 1773384618276, "server_ts": 1773384618038, "data": {"e": "depthUpdate", "E": 1773384618039, "T": 1773384618038, "s": "BTCUSDT", "U": 10101347412684, "u": 10101347428292, "pu": 10101347412462, "b": [["1000.00", "27.492"], ["5000.00", "101.418"], ["20720.60", "0.495"], ["20826.20", "0.252"], ["20920.60", "0.756"], ["21026.20", "0.486"], ["33000.00", "9.343"], ["56335.30", "0.000"], ["67501.10", "0.000"], ["70000.20", "0.003"], ["70187.90", "0.996"], ["70508.40", "0.004"], ["70963.60", "0.003"], ["70977.60", "0.714"], ["70999.10", "0.002"], ["71069.90", "0.000"], ["71081.50", "0.338"], ["71101.60", "0.115"], ["71103.00", "0.000"], ["71106.50", "1.055"], ["71119.80", "0.202"], ["71120.70", "0.002"], ["71121.30", "6.614"], ["71128.40", "0.288"], ["71132.00", "3.650"], ["71134.00", "0.286"], ["71135.00", "0.069"], ["71135.50", "0.023"], ["71142.60", "1.360"], ["71148.40", "0.000"], ["71150.00", "1.595"], ["71150.10", "0.007"], ["71152.70", "0.017"], ["71156.30", "0.078"], ["71156.40", "0.079"], ["71156.60", "0.002"], ["71159.40", "0.077"], ["71162.30", "0.060"], ["71165.10", "0.000"], ["71165.40", "0.005"], ["71165.80", "0.072"], ["71166.10", "0.322"], ["71166.50", "0.002"], ["71167.00", "0.007"], ["71168.20", "0.751"], ["71168.50", "0.275"], ["71169.00", "0.848"], ["71169.50", "0.050"], ["71170.20", "0.457"], ["71171.60", "0.004"], ["71171.70", "0.050"], ["71171.90", "0.004"], ["71172.30", "0.003"], ["71172.70", "0.277"], ["71172.80", "0.042"], ["71174.50", "0.001"], ["71174.80", "0.003"], ["71175.50", "0.003"], ["71176.00", "0.836"], ["71177.20", "0.000"], ["71177.30", "0.021"], ["71177.90", "0.002"], ["71178.10", "0.040"], ["71179.00", "0.003"], ["71179.40", "0.025"], ["71181.40", "0.140"], ["71181.80", "0.055"], ["71182.00", "0.002"], ["71182.90", "0.004"], ["71183.00", "0.812"], ["71184.20", "0.012"], ["71185.00", "0.032"], ["71185.50", "0.016"], ["71185.70", "0.004"], ["71186.30", "1.039"], ["71186.50", "0.004"], ["71186.60", "0.000"], ["71186.70", "0.029"], ["71187.30", "0.189"], ["71187.90", "0.007"], ["71188.70", "0.055"], ["71188.80", "0.265"], ["71189.60", "0.000"], ["71189.70", "0.036"], ["71190.00", "0.832"], ["71190.40", "0.003"], ["71191.20", "0.002"], ["71191.30", "0.032"], ["71191.40", "0.011"], ["71193.50", "0.007"], ["71194.10", "0.244"], ["71194.60", "0.001"], ["71194.90", "0.003"], ["71195.10", "0.010"], ["71196.40", "0.006"], ["71196.70", "0.000"], ["71197.00", "0.811"], ["71197.10", "0.474"], ["71197.40", "0.007"], ["71197.50", "0.003"], ["71197.60", "0.002"], ["71197.70", "0.008"], ["71198.00", "0.014"], ["71198.50", "0.011"], ["71199.20", "0.003"], ["71200.40", "0.000"], ["71200.80", "1.024"], ["71200.90", "0.011"], ["71201.00", "0.004"], ["71201.10", "0.002"], ["71201.30", "0.003"], ["71201.50", "0.000"], ["71202.10", "0.003"], ["71202.50", "0.003"], ["71202.60", "0.003"], ["71203.00", "0.002"], ["71203.20", "0.022"], ["71203.30", "0.005"], ["71203.40", "0.009"], ["71203.50", "0.000"], ["71203.80", "0.000"], ["71204.30", "0.002"], ["71204.60", "0.003"], ["71204.70", "0.002"], ["71205.30", "0.000"], ["71205.50", "0.000"], ["71205.60", "0.007"], ["71205.80", "0.004"], ["71206.00", "0.005"], ["71206.10", "0.046"], ["71206.20", "0.014"], ["71206.40", "0.046"], ["71206.50", "0.072"], ["71206.60", "0.000"], ["71206.70", "0.000"], ["71206.80", "0.000"], ["71206.90", "0.000"], ["71207.00", "0.000"], ["71207.10", "0.000"], ["71207.20", "0.000"], ["71207.40", "0.000"], ["71207.50", "0.000"], ["71207.60", "0.000"], ["71207.70", "0.000"], ["71207.80", "0.000"], ["71207.90", "0.000"], ["71208.00", "0.000"], ["71208.20", "0.000"], ["71208.30", "0.000"], ["71208.40", "0.000"], ["71208.60", "0.000"], ["71208.70", "0.000"], ["71208.80", "0.000"], ["71208.90", "0.000"], ["71209.00", "0.000"], ["71209.10", "0.000"], ["71209.20", "0.000"], ["71209.40", "0.000"], ["71209.50", "0.000"], ["71209.60", "0.000"], ["71209.80", "0.000"], ["71209.90", "0.000"], ["71210.00", "0.000"], ["71210.10", "0.000"], ["71210.20", "0.000"], ["71210.40", "0.000"], ["71210.50", "0.000"], ["71210.60", "0.000"], ["71210.80", "0.000"], ["71210.90", "0.000"], ["71211.00", "0.000"], ["71211.10", "0.000"], ["71211.20", "0.000"], ["71211.30", "0.000"], ["71211.40", "0.000"], ["71211.50", "0.000"], ["71211.60", "0.000"], ["71211.80", "0.000"], ["71211.90", "0.000"], ["71212.00", "0.000"], ["71212.20", "0.000"], ["71212.30", "0.000"], ["71212.40", "0.000"], ["71212.50", "0.000"], ["71212.60", "0.000"], ["71212.70", "0.000"], ["71213.10", "0.000"], ["71213.20", "0.000"], ["71213.30", "0.000"], ["71213.40", "0.000"], ["71213.50", "0.000"], ["71213.60", "0.000"], ["71213.70", "0.000"], ["71213.80", "0.000"], ["71214.00", "0.000"], ["71214.10", "0.000"], ["71214.20", "0.000"], ["71214.30", "0.000"], ["71214.40", "0.000"], ["71214.50", "0.000"], ["71214.60", "0.000"], ["71214.70", "0.000"], ["71214.80", "0.000"], ["71215.00", "0.000"], ["71215.10", "0.000"], ["71215.20", "0.000"], ["71215.50", "0.000"], ["71215.70", "0.000"], ["71215.80", "0.000"], ["71216.00", "0.000"], ["71216.10", "0.000"], ["71216.30", "0.000"], ["71216.40", "0.000"], ["71216.60", "0.000"], ["71216.70", "0.000"], ["71216.80", "0.000"], ["71217.00", "0.000"], ["71217.10", "0.000"], ["71217.50", "0.000"], ["71217.60", "0.000"], ["71217.80", "0.000"], ["71217.90", "0.000"], ["71218.00", "0.000"], ["71218.10", "0.000"], ["71218.20", "0.000"], ["71218.30", "0.000"], ["71218.40", "0.000"], ["71218.50", "0.000"], ["71218.60", "0.000"], ["71218.70", "0.000"], ["71218.80", "0.000"], ["71219.00", "0.000"], ["71219.20", "0.000"], ["71219.40", "0.000"], ["71219.50", "0.000"], ["71219.60", "0.000"], ["71219.70", "0.000"], ["71219.80", "0.000"], ["71220.00", "0.000"], ["71220.10", "0.000"], ["71220.20", "0.000"], ["71220.30", "0.000"], ["71220.40", "0.000"], ["71220.50", "0.000"], ["71220.60", "0.000"]], "a": [["71208.50", "4.233"], ["71208.90", "0.000"], ["71209.10", "0.120"], ["71212.10", "0.386"], ["71212.50", "0.158"], ["71213.20", "1.221"], ["71213.30", "1.121"], ["71213.40", "1.169"], ["71213.50", "0.675"], ["71213.90", "0.017"], ["71214.10", "0.017"], ["71214.40", "0.239"], ["71214.60", "0.377"], ["71214.80", "0.182"], ["71214.90", "0.017"], ["71215.90", "0.034"], ["71216.10", "0.099"], ["71216.40", "0.052"], ["71216.60", "0.000"], ["71216.80", "0.289"], ["71216.90", "0.289"], ["71217.10", "1.032"], ["71217.20", "1.882"], ["71217.60", "0.774"], ["71217.70", "0.213"], ["71217.90", "0.231"], ["71218.00", "0.258"], ["71218.10", "4.124"], ["71218.20", "0.462"], ["71218.30", "1.671"], ["71218.40", "0.037"], ["71218.50", "2.753"], ["71218.60", "0.696"], ["71218.70", "0.682"], ["71218.80", "0.450"], ["71218.90", "0.432"], ["71219.10", "0.850"], ["71219.20", "0.099"], ["71219.30", "2.116"], ["71219.50", "0.028"], ["71219.60", "0.014"], ["71219.70", "0.852"], ["71219.80", "1.381"], ["71219.90", "1.465"], ["71220.00", "0.107"], ["71220.10", "1.348"], ["71220.20", "3.169"], ["71220.30", "1.105"], ["71220.40", "2.043"], ["71220.50", "1.385"], ["71220.60", "6.595"], ["71220.70", "1.267"], ["71220.80", "0.004"], ["71220.90", "0.002"], ["71221.00", "0.034"], ["71222.40", "0.001"], ["71223.10", "0.829"], ["71223.40", "0.709"], ["71223.60", "1.100"], ["71224.00", "0.016"], ["71224.30", "0.008"], ["71224.40", "0.000"], ["71225.00", "0.062"], ["71225.20", "0.004"], ["71227.80", "0.019"], ["71228.90", "0.004"], ["71229.10", "0.014"], ["71229.40", "0.002"], ["71229.90", "0.080"], ["71230.40", "0.341"], ["71230.60", "0.022"], ["71230.80", "0.022"], ["71230.90", "0.051"], ["71231.20", "0.000"], ["71231.90", "0.000"], ["71232.00", "0.008"], ["71232.10", "0.002"], ["71232.20", "0.236"], ["71232.30", "0.027"], ["71232.40", "0.024"], ["71232.60", "0.002"], ["71232.80", "0.018"], ["71233.10", "0.013"], ["71233.20", "0.002"], ["71233.30", "0.063"], ["71233.40", "0.053"], ["71233.50", "0.513"], ["71233.60", "0.523"], ["71233.70", "0.016"], ["71233.80", "0.293"], ["71234.00", "0.003"], ["71234.20", "0.000"], ["71234.30", "0.366"], ["71234.40", "0.065"], ["71234.50", "0.047"], ["71234.60", "0.038"], ["71234.70", "0.000"], ["71234.80", "0.028"], ["71234.90", "0.025"], ["71235.50", "0.011"], ["71235.60", "0.041"], ["71235.70", "0.074"], ["71235.80", "0.004"], ["71235.90", "0.004"], ["71236.00", "0.007"], ["71236.20", "0.000"], ["71236.60", "0.508"], ["71237.10", "0.132"], ["71237.30", "0.128"], ["71237.70", "0.029"], ["71237.90", "0.211"], ["71238.00", "0.006"], ["71238.70", "0.082"], ["71239.80", "0.631"], ["71242.10", "0.116"], ["71243.50", "0.090"], ["71244.70", "0.002"], ["71244.90", "0.343"], ["71246.00", "0.816"], ["71249.30", "0.000"], ["71252.20", "0.401"], ["71253.00", "0.809"], ["71256.30", "0.069"], ["71258.60", "0.007"], ["71260.00", "1.146"], ["71261.70", "0.340"], ["71262.50", "0.484"], ["71263.90", "0.023"], ["71265.70", "0.056"], ["71267.00", "0.830"], ["71269.00", "0.002"], ["71269.20", "0.005"], ["71273.60", "0.002"], ["71274.00", "1.116"], ["71281.50", "0.425"], ["71292.70", "0.555"], ["71294.10", "0.655"], ["71298.40", "0.104"], ["71300.00", "3.326"], ["71301.00", "0.036"], ["71301.50", "0.002"], ["71308.00", "0.000"], ["71313.70", "0.000"], ["71353.80", "0.594"], ["71355.60", "0.000"], ["71389.30", "0.000"], ["71394.10", "0.017"], ["71402.30", "0.667"], ["71932.90", "1.184"], ["74802.30", "0.002"], ["78346.00", "0.002"], ["78347.90", "0.000"], ["78348.00", "0.004"], ["78428.00", "0.060"], ["78436.00", "0.100"], ["100000.00", "15.554"]]}}
{"local_ts": 1773384619279, "server_ts": 1773384619056, "data": {"e": "depthUpdate", "E": 1773384619059, "T": 1773384619056, "s": "BTCUSDT", "U": 10101347602717, "u": 10101347611083, "pu": 10101347602708, "b": [["1000.00", "27.492"], ["5000.00", "101.418"], ["20720.60", "0.126"], ["20806.50", "0.486"], ["20920.60", "0.270"], ["21106.50", "0.369"], ["65151.80", "0.000"], ["67631.80", "0.002"], ["68358.30", "0.004"], ["70494.40", "0.000"], ["70850.50", "0.034"], ["70953.80", "0.027"], ["70954.50", "0.014"], ["71011.60", "0.017"], ["71014.20", "0.022"], ["71048.40", "0.000"], ["71056.30", "0.000"], ["71058.90", "0.000"], ["71096.70", "0.000"], ["71102.30", "6.813"], ["71128.20", "1.679"], ["71132.50", "1.600"], ["71137.10", "1.296"], ["71142.00", "0.152"], ["71142.40", "3.576"], ["71149.50", "0.989"], ["71155.00", "0.886"], ["71156.50", "0.002"], ["71157.00", "0.726"], ["71159.60", "0.004"], ["71159.90", "0.874"], ["71162.00", "2.563"], ["71169.00", "0.812"], ["71171.30", "0.002"], ["71172.20", "0.004"], ["71174.50", "0.020"], ["71176.00", "0.811"], ["71181.00", "0.353"], ["71181.70", "0.027"], ["71182.50", "0.112"], ["71183.00", "1.322"], ["71185.10", "0.190"], ["71188.30", "0.007"], ["71188.40", "0.532"], ["71188.90", "0.038"], ["71190.60", "0.003"], ["71192.30", "0.046"], ["71193.30", "0.512"], ["71193.70", "0.035"], ["71196.00", "0.046"], ["71196.10", "0.527"], ["71196.20", "0.006"], ["71197.30", "0.193"], ["71197.40", "0.004"], ["71198.10", "0.004"], ["71203.10", "0.000"], ["71204.20", "0.003"]], "a": [["71206.60", "3.642"], ["71212.40", "0.019"], ["71216.60", "0.009"], ["71217.30", "0.145"], ["71218.00", "0.006"], ["71219.10", "0.709"], ["71219.30", "0.085"], ["71219.50", "0.017"], ["71219.90", "0.000"], ["71220.30", "0.144"], ["71220.40", "0.001"], ["71222.80", "0.511"], ["71224.40", "0.012"], ["71225.60", "0.598"], ["71231.50", "0.000"], ["71232.00", "0.811"], ["71232.70", "0.000"], ["71232.80", "0.017"], ["71233.40", "0.002"], ["71233.50", "0.012"], ["71236.00", "0.054"], ["71236.40", "0.000"], ["71238.60", "0.624"], ["71239.00", "1.156"], ["71240.80", "0.008"], ["71244.40", "0.783"], ["71246.00", "0.816"], ["71247.40", "0.018"], ["71253.00", "0.809"], ["71254.60", "0.024"], ["71261.80", "0.538"], ["71262.00", "0.002"], ["71266.00", "0.005"], ["71270.70", "0.162"], ["71272.80", "0.123"], ["71274.20", "0.429"], ["71279.90", "6.366"], ["71281.40", "0.047"], ["71284.90", "1.018"], ["71301.00", "0.000"], ["71336.80", "0.007"], ["71377.50", "0.039"], ["71381.10", "0.000"], ["71398.90", "0.159"], ["71433.50", "0.016"], ["71918.50", "0.000"], ["71918.70", "0.000"], ["72802.00", "0.000"]]}}
{"local_ts": 1773384620295, "server_ts": 1773384620078, "data": {"e": "depthUpdate", "E": 1773384620079, "T": 1773384620078, "s": "BTCUSDT", "U": 10101347663443, "u": 10101347671521, "pu": 10101347663407, "b": [["5000.00", "101.418"], ["20706.50", "0.234"], ["20806.50", "1.548"], ["20906.50", "0.018"], ["21006.50", "0.234"], ["21106.50", "0.666"], ["56965.00", "0.000"], ["65151.90", "0.005"], ["69888.60", "2.204"], ["70494.40", "0.000"], ["70503.60", "0.071"], ["70900.00", "26.065"], ["70954.50", "0.012"], ["70954.80", "0.002"], ["71035.60", "0.080"], ["71041.80", "0.478"], ["71045.10", "0.058"], ["71047.60", "0.005"], ["71048.50", "3.544"], ["71048.60", "1.048"], ["71056.80", "4.277"], ["71057.40", "0.770"], ["71138.80", "0.010"], ["71146.00", "0.109"], ["71159.90", "0.874"], ["71160.00", "0.010"], ["71164.40", "0.137"], ["71175.40", "0.131"], ["71178.80", "0.457"], ["71180.00", "0.013"], ["71180.50", "1.300"], ["71181.00", "0.311"], ["71181.30", "0.306"], ["71182.50", "0.070"], ["71183.80", "0.030"], ["71185.00", "0.033"], ["71185.10", "0.091"], ["71185.40", "0.008"], ["71185.50", "0.019"], ["71186.20", "0.882"], ["71186.50", "1.209"], ["71187.40", "0.007"], ["71187.50", "0.039"], ["71188.40", "0.532"], ["71188.50", "0.001"], ["71188.70", "0.043"], ["71189.40", "0.113"], ["71189.70", "0.053"], ["71190.30", "0.281"], ["71190.90", "0.228"], ["71191.10", "0.964"], ["71191.30", "0.044"], ["71192.20", "0.058"], ["71192.90", "0.000"], ["71193.10", "0.713"], ["71193.40", "0.003"], ["71193.50", "0.358"], ["71193.60", "0.030"], ["71193.70", "0.035"], ["71194.70", "0.060"], ["71194.90", "0.030"], ["71195.30", "0.206"], ["71195.70", "0.042"], ["71195.90", "0.001"], ["71196.00", "0.019"], ["71196.40", "0.033"], ["71196.70", "0.000"], ["71196.90", "0.003"], ["71197.00", "0.050"], ["71197.10", "0.461"], ["71197.20", "0.302"], ["71198.30", "0.002"], ["71198.40", "0.548"], ["71198.50", "0.007"], ["71198.60", "0.003"], ["71198.70", "0.001"], ["71198.80", "0.007"], ["71198.90", "0.015"], ["71199.00", "0.003"], ["71199.10", "0.007"], ["71199.30", "0.005"], ["71199.40", "0.099"], ["71199.70", "0.000"], ["71199.80", "0.187"], ["71200.30", "0.030"], ["71200.50", "0.065"], ["71200.90", "0.068"], ["71201.00", "0.289"], ["71201.10", "0.004"], ["71201.30", "0.003"], ["71201.80", "0.000"], ["71202.30", "0.000"], ["71202.40", "0.000"], ["71202.50", "0.003"], ["71202.60", "0.001"], ["71202.70", "0.000"], ["71202.80", "0.015"], ["71202.90", "0.004"], ["71203.20", "0.000"], ["71204.00", "0.009"], ["71204.30", "0.002"], ["71204.60", "0.052"], ["71205.30", "0.028"], ["71205.50", "0.000"], ["71205.80", "0.018"], ["71206.20", "0.055"], ["71206.50", "0.693"]], "a": [["71206.60", "4.241"], ["71207.50", "0.004"], ["71207.60", "0.003"], ["71207.90", "0.044"], ["71208.20", "0.000"], ["71208.60", "0.017"], ["71209.10", "0.029"], ["71209.20", "0.015"], ["71210.30", "0.005"], ["71210.40", "0.048"], ["71211.30", "0.003"], ["71211.60", "0.032"], ["71211.70", "0.088"], ["71211.90", "0.009"], ["71212.30", "0.067"], ["71212.90", "0.017"], ["71213.70", "0.055"], ["71214.10", "0.003"], ["71214.20", "0.019"], ["71215.40", "0.015"], ["71215.60", "0.253"], ["71217.60", "0.057"], ["71217.70", "0.706"], ["71218.70", "0.142"], ["71218.80", "0.229"], ["71218.90", "0.722"], ["71219.00", "0.004"], ["71219.10", "0.123"], ["71219.20", "0.022"], ["71219.40", "0.004"], ["71220.60", "1.843"], ["71222.60", "0.104"], ["71222.70", "0.321"], ["71223.00", "0.038"], ["71227.70", "0.252"], ["71230.20", "0.506"], ["71233.60", "0.146"], ["71234.40", "0.006"], ["71239.60", "0.004"], ["71242.30", "0.007"], ["71243.70", "0.089"], ["71256.00", "0.508"], ["71256.50", "0.008"], ["71268.90", "0.002"], ["71270.70", "0.042"], ["71271.20", "0.138"], ["71281.40", "0.047"], ["71283.70", "0.363"], ["71297.60", "0.337"], ["71299.10", "0.506"], ["71337.00", "0.002"], ["71340.30", "0.018"], ["71354.00", "0.535"], ["71355.70", "0.009"], ["71356.10", "0.667"], ["71362.80", "0.007"], ["71362.90", "2.114"], ["71363.20", "0.771"], ["71369.90", "0.516"], ["71370.30", "0.042"], ["71377.00", "0.602"], ["71377.40", "0.022"], ["71381.10", "0.000"], ["71384.10", "0.007"], ["71384.50", "0.001"], ["71391.20", "0.007"], ["71391.60", "0.009"], ["71398.30", "0.007"], ["71398.70", "0.291"], ["71405.40", "0.011"], ["71405.80", "6.433"], ["71471.00", "3.989"], ["71567.00", "0.101"], ["71918.70", "0.000"], ["71922.60", "0.000"], ["71993.80", "0.002"], ["73370.70", "3.266"], ["74787.80", "0.002"], ["74800.80", "0.002"]]}}
{"local_ts": 1773384621316, "server_ts": 1773384621096, "data": {"e": "depthUpdate", "E": 1773384621099, "T": 1773384621096, "s": "BTCUSDT", "U": 10101347788449, "u": 10101347801388, "pu": 10101347788422, "b": [["1000.00", "27.492"], ["5000.00", "101.418"], ["20701.60", "1.269"], ["20706.50", "0.207"], ["20806.50", "0.153"], ["20901.60", "0.099"], ["21006.50", "0.180"], ["21101.60", "0.099"], ["56961.00", "0.004"], ["67635.80", "0.003"], ["70098.00", "0.997"], ["70154.90", "1.283"], ["70169.20", "1.992"], ["70489.60", "0.000"], ["70954.80", "0.000"], ["70966.30", "0.031"], ["70999.10", "1.176"], ["71028.80", "12.708"], ["71066.10", "7.227"], ["71066.80", "0.000"], ["71067.50", "0.000"], ["71070.50", "0.100"], ["71079.40", "0.010"], ["71083.50", "0.001"], ["71092.00", "13.848"], ["71097.40", "0.002"], ["71101.60", "0.043"], ["71101.70", "0.150"], ["71101.90", "0.001"], ["71102.00", "3.200"], ["71102.30", "0.002"], ["71102.70", "0.002"], ["71103.00", "0.000"], ["71103.30", "0.000"], ["71106.40", "1.765"], ["71115.30", "1.139"], ["71118.00", "1.785"], ["71118.80", "0.045"], ["71119.00", "0.116"], ["71122.80", "0.002"], ["71125.40", "0.043"], ["71130.20", "3.570"], ["71134.80", "0.808"], ["71136.70", "0.284"], ["71137.50", "0.508"], ["71137.60", "0.222"], ["71137.80", "0.306"], ["71138.10", "0.930"], ["71138.50", "1.342"], ["71138.60", "0.006"], ["71138.90", "0.214"], ["71139.20", "0.012"], ["71142.30", "0.001"], ["71142.90", "0.002"], ["71143.10", "0.184"], ["71143.40", "0.006"], ["71150.50", "1.319"], ["71154.00", "2.545"], ["71155.00", "0.886"], ["71155.80", "0.027"], ["71156.00", "0.005"], ["71160.90", "0.310"], ["71161.00", "2.793"], ["71162.00", "2.565"], ["71169.00", "0.807"], ["71169.10", "0.221"], ["71176.00", "0.811"], ["71177.10", "0.000"], ["71177.20", "0.019"], ["71177.50", "1.343"], ["71178.90", "0.096"], ["71181.20", "0.004"], ["71181.30", "1.197"], ["71181.90", "0.000"], ["71182.70", "0.207"], ["71182.80", "0.008"], ["71183.00", "1.320"], ["71183.50", "0.141"], ["71183.80", "0.563"], ["71184.80", "0.008"], ["71185.10", "0.049"], ["71185.30", "0.005"], ["71185.80", "0.045"], ["71188.00", "0.067"], ["71188.80", "0.000"], ["71188.90", "0.083"], ["71189.70", "0.044"], ["71189.80", "0.378"], ["71189.90", "0.006"], ["71190.00", "0.054"], ["71190.30", "0.281"], ["71190.40", "0.005"], ["71190.50", "0.005"], ["71190.70", "0.000"], ["71190.80", "0.048"], ["71191.00", "0.296"], ["71191.10", "0.509"], ["71191.20", "0.184"], ["71191.40", "0.130"], ["71191.70", "0.285"], ["71192.80", "0.000"], ["71193.20", "0.002"], ["71193.40", "0.037"], ["71194.10", "0.004"], ["71194.20", "0.047"], ["71194.40", "0.000"], ["71194.50", "0.239"], ["71195.80", "0.006"], ["71195.90", "0.001"], ["71196.00", "0.046"], ["71196.10", "0.029"], ["71196.30", "0.003"], ["71196.70", "0.001"], ["71196.80", "0.000"], ["71197.00", "0.053"], ["71197.10", "0.166"], ["71197.20", "0.068"], ["71197.60", "0.043"], ["71197.80", "0.000"], ["71197.90", "0.032"], ["71198.10", "0.004"], ["71198.20", "0.000"], ["71198.30", "0.021"], ["71198.40", "0.000"], ["71198.50", "0.005"], ["71198.70", "0.001"], ["71198.90", "0.000"], ["71199.00", "0.018"], ["71199.20", "0.211"], ["71199.40", "0.042"], ["71199.50", "0.000"], ["71199.70", "0.002"], ["71199.80", "0.036"], ["71199.90", "0.002"], ["71200.20", "0.006"], ["71200.30", "0.030"], ["71200.40", "0.002"], ["71200.50", "0.011"], ["71200.60", "0.005"], ["71200.80", "0.003"], ["71201.00", "0.007"], ["71201.20", "0.100"], ["71201.30", "0.002"], ["71201.40", "0.002"], ["71201.50", "0.000"], ["71201.60", "1.425"]], "a": [["71201.70", "3.421"], ["71202.50", "0.000"], ["71202.70", "0.002"], ["71202.80", "0.004"], ["71202.90", "0.029"], ["71203.00", "0.002"], ["71203.10", "0.002"], ["71203.30", "0.044"], ["71203.70", "0.210"], ["71203.80", "0.004"], ["71204.00", "0.052"], ["71204.10", "0.029"], ["71204.30", "0.060"], ["71204.40", "0.001"], ["71204.60", "0.000"], ["71204.70", "0.025"], ["71205.00", "0.002"], ["71205.10", "0.002"], ["71205.30", "0.043"], ["71205.40", "0.000"], ["71205.50", "0.050"], ["71205.60", "0.000"], ["71205.90", "0.003"], ["71206.20", "0.002"], ["71206.30", "0.004"], ["71206.60", "0.008"], ["71206.80", "0.027"], ["71206.90", "0.104"], ["71207.60", "0.006"], ["71207.90", "0.000"], ["71208.00", "0.019"], ["71208.10", "0.000"], ["71208.70", "0.068"], ["71208.80", "0.153"], ["71208.90", "0.209"], ["71209.20", "0.000"], ["71209.30", "0.015"], ["71209.40", "0.002"], ["71209.70", "0.000"], ["71210.10", "0.003"], ["71210.50", "0.017"], ["71210.70", "0.002"], ["71210.90", "0.000"], ["71211.30", "0.003"], ["71211.40", "0.002"], ["71211.80", "0.020"], ["71211.90", "0.002"], ["71212.10", "0.058"], ["71212.40", "0.010"], ["71212.60", "0.006"], ["71212.80", "0.000"], ["71213.00", "0.011"], ["71213.10", "0.072"], ["71213.20", "0.005"], ["71213.40", "0.000"], ["71213.60", "0.078"], ["71214.00", "0.005"], ["71214.30", "0.123"], ["71214.50", "0.047"], ["71214.70", "0.315"], ["71214.80", "0.097"], ["71215.30", "0.054"], ["71215.50", "0.003"], ["71218.60", "0.029"], ["71222.30", "0.000"], ["71222.80", "0.669"], ["71225.00", "0.815"], ["71226.10", "0.000"], ["71227.10", "0.315"], ["71228.70", "0.004"], ["71230.80", "0.022"], ["71232.00", "0.813"], ["71232.80", "0.017"], ["71239.00", "1.114"], ["71240.90", "1.240"], ["71244.20", "2.438"], ["71246.00", "0.816"], ["71249.50", "0.082"], ["71250.50", "0.062"], ["71250.60", "0.076"], ["71251.50", "0.706"], ["71251.70", "0.083"], ["71268.10", "3.581"], ["71272.40", "0.013"], ["71272.80", "0.004"], ["71273.10", "0.000"], ["71274.20", "0.002"], ["71277.10", "0.002"], ["71277.70", "0.144"], ["71278.10", "0.089"], ["71278.50", "0.020"], ["71278.80", "0.000"], ["71278.90", "0.002"], ["71279.10", "0.075"], ["71279.60", "0.136"], ["71280.00", "0.082"], ["71289.40", "6.748"], ["71306.40", "7.009"], ["71306.60", "0.217"], ["71307.30", "0.022"], ["71307.60", "1.055"], ["71308.30", "0.003"], ["71308.90", "0.003"], ["71309.00", "0.002"], ["71311.60", "0.000"], ["71313.60", "0.000"], ["71313.90", "0.013"], ["71314.30", "0.001"], ["71314.70", "0.508"], ["71315.40", "1.049"], ["71322.30", "0.000"], ["71327.50", "0.000"], ["71342.50", "0.103"], ["71343.20", "0.012"], ["71343.50", "0.300"], ["71355.70", "0.002"], ["71362.80", "0.000"], ["71369.30", "0.007"], ["71369.90", "0.509"], ["71376.40", "0.009"], ["71377.00", "0.595"], ["71383.30", "0.000"], ["71383.50", "0.007"], ["71384.10", "0.000"], ["71390.60", "0.873"], ["71391.20", "0.000"], ["71397.70", "0.208"], ["71398.30", "0.000"], ["71404.80", "0.007"], ["71405.40", "0.004"], ["71411.90", "0.007"], ["71419.00", "0.217"], ["71486.40", "0.000"], ["71510.20", "0.000"], ["71913.70", "0.000"], ["74776.50", "0.052"], ["78321.80", "0.007"]]}}
{"local_ts": 1773384622335, "server_ts": 1773384622117, "data": {"e": "depthUpdate", "E": 1773384622119, "T": 1773384622117, "s": "BTCUSDT", "U": 10101347849351, "u": 10101347857016, "pu": 10101347849345, "b": [["5000.00", "101.418"], ["20701.60", "0.324"], ["20901.60", "0.864"], ["21001.60", "0.036"], ["21101.60", "1.476"], ["69764.30", "0.002"], ["70489.60", "1.417"], ["70845.60", "0.000"], ["70966.30", "0.029"], ["70968.40", "0.002"], ["71105.60", "0.116"], ["71112.70", "0.070"], ["71119.80", "0.272"], ["71141.10", "0.039"], ["71142.20", "1.204"], ["71142.90", "0.106"], ["71144.00", "0.703"], ["71155.00", "0.081"], ["71156.70", "0.056"], ["71162.00", "1.760"], ["71169.00", "0.002"], ["71176.00", "0.006"], ["71179.80", "0.005"], ["71182.50", "0.000"], ["71183.00", "0.515"], ["71183.80", "0.464"], ["71184.30", "0.005"], ["71185.20", "0.144"], ["71185.90", "0.006"], ["71187.60", "0.016"], ["71187.90", "0.050"], ["71188.30", "0.038"], ["71188.80", "0.000"], ["71189.70", "0.188"], ["71192.70", "0.141"], ["71193.10", "0.592"], ["71193.20", "0.002"], ["71194.50", "0.239"], ["71195.60", "0.507"], ["71195.70", "0.006"], ["71195.80", "0.006"], ["71197.10", "0.401"], ["71197.70", "0.007"], ["71198.30", "0.023"], ["71198.40", "0.029"], ["71199.70", "0.031"], ["71200.50", "0.011"], ["71200.80", "0.001"], ["71201.30", "0.017"], ["71201.40", "0.113"], ["71201.60", "1.580"]], "a": [["71201.70", "3.229"], ["71202.10", "0.003"], ["71202.40", "0.000"], ["71202.80", "0.004"], ["71203.60", "0.002"], ["71204.00", "0.050"], ["71204.30", "0.003"], ["71204.80", "0.002"], ["71205.00", "0.002"], ["71205.50", "0.060"], ["71206.10", "0.025"], ["71206.60", "0.008"], ["71207.20", "0.000"], ["71207.30", "0.015"], ["71207.50", "0.003"], ["71207.90", "0.000"], ["71208.40", "0.012"], ["71208.60", "0.031"], ["71208.70", "0.068"], ["71209.10", "0.003"], ["71209.90", "0.017"], ["71210.20", "0.011"], ["71210.60", "0.000"], ["71210.70", "0.002"], ["71210.90", "0.029"], ["71211.10", "0.018"], ["71212.40", "0.025"], ["71212.80", "0.075"], ["71212.90", "0.005"], ["71213.20", "0.097"], ["71213.60", "0.148"], ["71213.90", "0.791"], ["71214.10", "0.107"], ["71214.50", "0.018"], ["71214.90", "0.015"], ["71215.30", "0.054"], ["71215.40", "0.002"], ["71216.30", "0.005"], ["71216.60", "0.009"], ["71217.30", "0.042"], ["71217.40", "0.005"], ["71217.90", "0.050"], ["71218.20", "0.062"], ["71218.60", "0.029"], ["71219.10", "0.016"], ["71219.20", "0.054"], ["71220.40", "0.121"], ["71221.60", "0.003"], ["71222.90", "0.024"], ["71225.00", "0.010"], ["71227.80", "0.508"], ["71229.00", "0.000"], ["71230.10", "0.640"], ["71232.00", "0.008"], ["71236.60", "0.508"], ["71237.30", "0.246"], ["71237.50", "0.006"], ["71238.30", "0.005"], ["71238.50", "1.100"], ["71239.00", "0.309"], ["71239.30", "0.002"], ["71240.20", "0.003"], ["71240.90", "1.295"], ["71246.00", "0.011"], ["71250.30", "0.004"], ["71251.00", "0.004"], ["71253.00", "0.004"], ["71259.90", "0.049"], ["71261.00", "0.004"], ["71283.70", "0.248"], ["71290.80", "0.002"], ["71369.30", "0.000"], ["71372.60", "0.009"], ["71376.10", "0.000"], ["71376.40", "0.002"], ["71379.70", "0.049"], ["71383.50", "0.000"], ["71386.80", "0.007"], ["71390.60", "0.866"], ["71393.90", "0.007"], ["71397.70", "0.201"], ["71401.00", "0.007"], ["71404.80", "0.000"], ["71408.10", "0.030"], ["71411.90", "0.000"], ["71415.20", "0.056"], ["71419.00", "0.210"], ["71422.30", "0.060"], ["71913.70", "0.000"], ["74765.80", "0.002"], ["74776.50", "0.050"]]}}
{"local_ts": 1773384623354, "server_ts": 1773384623138, "data": {"e": "depthUpdate", "E": 1773384623139, "T": 1773384623138, "s": "BTCUSDT", "U": 10101347904504, "u": 10101347910660, "pu": 10101347904456, "b": [["1000.00", "27.492"], ["5000.00", "101.418"], ["20801.60", "0.729"], ["20901.60", "0.171"], ["21001.60", "1.206"], ["21101.60", "0.594"], ["56961.00", "0.000"], ["67637.00", "0.002"], ["67651.90", "0.004"], ["69998.40", "1.525"], ["70010.40", "0.000"], ["70489.60", "1.417"], ["70968.10", "0.315"], ["70968.40", "0.000"], ["71142.90", "0.106"], ["71155.00", "0.081"], ["71155.80", "0.025"], ["71156.00", "0.007"], ["71162.00", "1.760"], ["71169.00", "0.002"], ["71176.00", "0.006"], ["71183.00", "0.515"], ["71188.80", "0.000"], ["71192.70", "0.141"], ["71199.70", "0.031"], ["71201.00", "0.007"], ["71201.50", "0.044"]], "a": [["71201.70", "3.697"], ["71203.00", "0.004"], ["71203.10", "0.031"], ["71204.30", "0.032"], ["71205.00", "0.044"], ["71205.40", "0.015"], ["71206.00", "0.045"], ["71206.90", "0.003"], ["71207.00", "0.042"], ["71207.90", "0.000"], ["71208.90", "0.209"], ["71214.50", "0.018"], ["71224.00", "0.002"], ["71225.00", "0.010"], ["71225.30", "0.004"], ["71232.00", "0.008"], ["71234.80", "0.004"], ["71239.00", "0.309"], ["71239.90", "0.006"], ["71240.90", "1.447"], ["71245.10", "0.945"], ["71246.00", "0.011"], ["71251.10", "0.062"], ["71251.30", "0.204"], ["71253.00", "0.004"], ["71278.60", "1.297"], ["71326.30", "0.289"], ["71372.00", "0.061"], ["71372.60", "0.002"], ["71379.10", "0.009"], ["71379.70", "0.042"], ["71386.20", "0.084"], ["71386.80", "0.000"], ["71393.30", "0.009"], ["71393.90", "0.000"], ["71397.50", "0.080"], ["71400.40", "0.007"], ["71401.00", "0.000"], ["71407.50", "0.007"], ["71408.10", "0.023"], ["71414.60", "0.007"], ["71415.20", "0.049"], ["71421.70", "0.007"], ["71422.30", "0.053"], ["89523.20", "0.000"]]}}
{"local_ts": 1773384624378, "server_ts": 1773384624160, "data": {"e": "depthUpdate", "E": 1773384624163, "T": 1773384624160, "s": "BTCUSDT", "U": 10101347960137, "u": 10101347965732, "pu": 10101347960051, "b": [["1000.00", "27.492"], ["5000.00", "101.418"], ["20701.60", "0.594"], ["20801.60", "0.306"], ["20901.60", "0.945"], ["21001.60", "0.855"], ["56961.00", "0.000"], ["67641.00", "0.020"], ["69715.00", "0.000"], ["70425.50", "1.274"], ["70489.60", "1.417"], ["70845.60", "0.000"], ["70968.10", "0.313"], ["71113.80", "0.042"], ["71143.10", "0.368"], ["71143.30", "0.085"], ["71147.40", "0.316"], ["71166.00", "0.336"], ["71166.30", "0.003"], ["71167.30", "0.004"], ["71168.30", "0.316"], ["71169.50", "0.002"], ["71175.00", "0.009"], ["71175.30", "0.857"], ["71175.90", "0.003"], ["71176.30", "0.238"], ["71178.40", "0.044"], ["71178.60", "0.319"], ["71179.40", "0.072"], ["71183.50", "0.141"], ["71183.80", "0.358"], ["71185.90", "0.035"], ["71187.40", "0.433"], ["71188.80", "0.000"], ["71189.10", "0.003"], ["71189.60", "0.018"], ["71190.50", "0.005"], ["71190.90", "0.214"], ["71191.00", "0.296"], ["71191.50", "0.121"], ["71192.20", "0.016"], ["71192.50", "0.002"], ["71193.30", "0.513"], ["71193.70", "0.002"], ["71195.10", "0.005"], ["71195.60", "0.507"], ["71199.70", "0.002"], ["71201.60", "0.654"]], "a": [["71212.40", "0.109"], ["71212.70", "0.142"], ["71214.70", "0.463"], ["71218.10", "0.649"], ["71218.80", "0.005"], ["71220.20", "0.211"], ["71223.40", "1.177"], ["71223.70", "0.070"], ["71237.30", "0.108"], ["71240.80", "0.689"], ["71240.90", "1.009"], ["71371.10", "0.007"], ["71372.00", "0.054"], ["71378.20", "0.193"], ["71379.10", "0.002"], ["71385.30", "0.009"], ["71386.20", "0.077"], ["71392.40", "0.013"], ["71393.30", "0.002"], ["71399.50", "0.013"], ["71400.40", "0.000"], ["71406.60", "0.007"], ["71407.50", "0.000"], ["71413.70", "0.007"], ["71414.60", "0.000"], ["71420.80", "0.007"], ["71421.70", "0.000"], ["71474.40", "0.098"], ["71475.80", "0.202"], ["71489.70", "0.000"], ["71496.90", "0.307"], ["71913.70", "1.388"], ["71977.80", "0.975"], ["72270.80", "0.000"], ["74781.80", "0.002"], ["89523.20", "0.000"]]}}
{"local_ts": 1773384625401, "server_ts": 1773384625182, "data": {"e": "depthUpdate", "E": 1773384625183, "T": 1773384625182, "s": "BTCUSDT", "U": 10101348071741, "u": 10101348083218, "pu": 10101348071650, "b": [["5000.00", "101.418"], ["20701.60", "0.441"], ["20794.60", "0.522"], ["20901.60", "0.972"], ["21094.60", "0.306"], ["33000.00", "9.339"], ["67620.90", "0.000"], ["67651.90", "0.000"], ["70183.60", "0.387"], ["70482.70", "0.712"], ["70500.30", "2.834"], ["70945.20", "0.002"], ["71016.50", "0.036"], ["71029.80", "0.281"], ["71038.60", "0.018"], ["71041.00", "0.043"], ["71041.80", "0.478"], ["71043.30", "0.096"], ["71046.20", "0.075"], ["71046.60", "0.101"], ["71046.90", "2.475"], ["71087.60", "0.004"], ["71089.10", "0.002"], ["71098.80", "0.075"], ["71103.90", "0.072"], ["71105.60", "0.046"], ["71109.40", "0.004"], ["71111.00", "0.620"], ["71112.70", "0.000"], ["71117.20", "1.202"], ["71118.10", "0.112"], ["71119.80", "0.202"], ["71121.80", "0.448"], ["71128.40", "0.319"], ["71132.00", "3.678"], ["71135.50", "0.071"], ["71142.50", "0.750"], ["71142.90", "0.370"], ["71143.10", "0.269"], ["71143.20", "0.165"], ["71143.30", "0.000"], ["71148.00", "0.010"], ["71149.40", "0.004"], ["71149.50", "0.011"], ["71155.00", "0.081"], ["71160.70", "0.005"], ["71161.60", "0.304"], ["71162.00", "1.760"], ["71162.60", "0.362"], ["71163.60", "0.941"], ["71165.30", "0.315"], ["71166.50", "0.042"], ["71167.60", "0.015"], ["71167.80", "0.002"], ["71168.40", "0.103"], ["71169.00", "0.368"], ["71169.30", "0.418"], ["71169.70", "0.334"], ["71169.90", "0.027"], ["71172.90", "0.001"], ["71174.00", "0.029"], ["71174.10", "0.062"], ["71175.90", "0.677"], ["71176.00", "0.006"], ["71176.10", "0.353"], ["71176.90", "0.353"], ["71177.40", "0.018"], ["71177.80", "0.031"], ["71179.10", "1.015"], ["71179.90", "0.047"], ["71180.30", "0.003"], ["71180.50", "0.748"], ["71181.60", "0.218"], ["71181.70", "0.069"], ["71182.00", "0.002"], ["71182.30", "0.032"], ["71182.70", "0.706"], ["71182.80", "0.086"], ["71183.40", "1.055"], ["71183.90", "0.000"], ["71184.40", "0.004"], ["71184.80", "0.006"], ["71185.30", "0.113"], ["71185.60", "0.031"], ["71185.70", "0.094"], ["71186.00", "0.038"], ["71186.20", "0.512"], ["71188.50", "0.004"], ["71188.60", "0.030"], ["71188.90", "0.003"], ["71190.00", "0.020"], ["71191.50", "0.010"], ["71192.20", "0.093"], ["71194.50", "0.211"], ["71194.60", "1.810"]], "a": [["71194.70", "6.464"], ["71195.10", "0.000"], ["71195.30", "0.029"], ["71197.20", "1.103"], ["71197.30", "0.017"], ["71200.30", "0.006"], ["71200.40", "0.074"], ["71200.50", "1.109"], ["71204.00", "0.005"], ["71210.30", "0.006"], ["71211.10", "0.021"], ["71223.30", "0.129"], ["71223.60", "0.003"], ["71223.80", "0.001"], ["71225.00", "0.008"], ["71232.00", "0.006"], ["71233.20", "0.945"], ["71239.00", "0.309"], ["71241.80", "0.057"], ["71243.50", "0.090"], ["71244.90", "0.289"], ["71245.00", "0.005"], ["71246.00", "0.011"], ["71262.10", "0.007"], ["71269.80", "0.053"], ["71275.80", "0.699"], ["71282.30", "0.080"], ["71283.70", "0.173"], ["71289.40", "6.750"], ["71290.80", "0.000"], ["71333.80", "0.116"], ["71337.00", "0.002"], ["71354.10", "22.993"], ["71365.60", "0.039"], ["71371.00", "0.040"], ["71371.70", "0.002"], ["71385.40", "0.621"], ["71386.50", "0.000"], ["71386.60", "0.014"], ["71394.00", "0.159"], ["71396.70", "0.057"], ["71396.80", "19.838"], ["71427.60", "0.632"], ["71429.30", "0.000"], ["71906.60", "0.002"], ["72200.00", "437.981"], ["72260.20", "1.519"], ["72996.70", "2.466"], ["73192.70", "1.192"], ["73265.50", "0.000"], ["76325.10", "0.002"], ["89523.20", "0.000"]]}}
{"local_ts": 1773384626418, "server_ts": 1773384626201, "data": {"e": "depthUpdate", "E": 1773384626203, "T": 1773384626201, "s": "BTCUSDT", "U": 10101348146851, "u": 10101348153899, "pu": 10101348146736, "b": [["1000.00", "27.492"], ["5000.00", "101.418"], ["20694.60", "0.405"], ["20794.60", "1.395"], ["20994.60", "0.324"], ["21094.60", "0.576"], ["67618.30", "0.003"], ["67636.80", "0.000"], ["70482.70", "0.710"], ["70930.80", "1.481"], ["71016.10", "0.997"], ["71057.90", "0.190"], ["71106.20", "0.002"], ["71130.80", "0.020"], ["71137.30", "0.353"], ["71137.60", "1.063"], ["71138.40", "0.003"], ["71140.40", "0.413"], ["71142.90", "0.370"], ["71144.40", "0.108"], ["71148.00", "0.010"], ["71148.30", "0.039"], ["71152.60", "1.204"], ["71155.00", "0.081"], ["71157.00", "0.602"], ["71162.00", "1.762"], ["71166.90", "0.264"], ["71167.00", "0.010"], ["71168.50", "0.162"], ["71169.00", "0.409"], ["71176.00", "0.006"], ["71178.60", "0.162"], ["71179.90", "0.011"], ["71184.50", "0.000"], ["71193.60", "0.003"], ["71194.20", "0.004"], ["71194.60", "3.660"]], "a": [["71196.40", "0.001"], ["71199.40", "0.001"], ["71220.80", "0.007"], ["71220.90", "0.007"], ["71221.50", "0.007"], ["71221.60", "0.003"], ["71223.10", "0.006"], ["71223.20", "0.584"], ["71223.40", "1.049"], ["71223.60", "0.129"], ["71225.00", "0.017"], ["71230.10", "0.899"], ["71232.00", "0.006"], ["71239.00", "0.309"], ["71240.00", "0.002"], ["71241.00", "0.100"], ["71242.40", "0.006"], ["71243.60", "0.170"], ["71244.30", "1.107"], ["71245.10", "0.004"], ["71245.40", "0.004"], ["71246.00", "0.011"], ["71246.10", "0.301"], ["71247.60", "0.002"], ["71248.10", "0.002"], ["71249.00", "0.000"], ["71249.20", "0.002"], ["71250.50", "0.256"], ["71251.00", "0.002"], ["71251.70", "0.079"], ["71251.80", "0.000"], ["71252.50", "0.328"], ["71252.90", "0.000"], ["71261.60", "0.052"], ["71262.10", "1.092"], ["71262.90", "0.032"], ["71263.80", "0.000"], ["71264.80", "0.000"], ["71265.80", "0.000"], ["71266.40", "0.008"], ["71267.40", "0.002"], ["71268.30", "1.066"], ["71268.40", "0.059"], ["71269.30", "0.042"], ["71270.30", "0.045"], ["71270.50", "0.060"], ["71284.40", "0.002"], ["71298.00", "2.555"], ["71310.80", "0.141"], ["71312.50", "0.761"], ["71316.80", "0.102"], ["71328.80", "1.253"], ["71352.00", "4.354"], ["71382.50", "0.273"], ["71389.70", "0.000"], ["71395.90", "10.004"], ["71422.10", "0.007"], ["71424.10", "0.904"], ["71425.10", "0.000"], ["71453.40", "2.126"], ["71474.40", "0.157"], ["71503.20", "1.819"], ["71557.60", "0.000"], ["71700.00", "20.543"], ["71906.60", "0.002"], ["72618.50", "0.006"], ["74766.40", "0.002"], ["76680.10", "0.002"], ["89523.20", "0.000"]]}}
{"local_ts": 1773384627440, "server_ts": 1773384627222, "data": {"e": "depthUpdate", "E": 1773384627223, "T": 1773384627222, "s": "BTCUSDT", "U": 10101348211080, "u": 10101348216604, "pu": 10101348211024, "b": [["5000.00", "101.418"], ["20694.60", "1.557"], ["20794.60", "0.054"], ["20894.60", "0.189"], ["20994.60", "0.711"], ["21094.60", "0.189"], ["33000.00", "9.343"], ["56956.00", "0.087"], ["61006.20", "0.000"], ["62425.00", "0.061"], ["67632.60", "0.002"], ["67641.70", "0.000"], ["69399.80", "2.594"], ["69996.90", "0.613"], ["70482.70", "0.710"], ["70838.60", "0.004"], ["70927.20", "3.709"], ["71057.00", "0.302"], ["71058.20", "0.321"], ["71059.90", "0.000"], ["71064.00", "0.106"], ["71077.90", "0.029"], ["71082.10", "0.115"], ["71082.20", "0.510"], ["71082.40", "0.000"], ["71082.70", "0.000"], ["71082.80", "1.068"], ["71083.10", "0.003"], ["71083.50", "0.040"], ["71083.80", "0.310"], ["71103.30", "0.000"], ["71105.90", "0.105"], ["71113.50", "0.072"], ["71114.60", "0.533"], ["71114.90", "0.087"], ["71115.20", "0.103"], ["71115.30", "1.100"], ["71118.00", "1.713"], ["71118.30", "0.000"], ["71118.60", "0.002"], ["71118.70", "0.070"], ["71119.00", "0.080"], ["71119.30", "0.502"], ["71119.70", "0.000"], ["71137.40", "0.000"], ["71138.90", "0.113"], ["71142.90", "0.271"], ["71144.80", "0.227"], ["71145.30", "0.377"], ["71159.10", "0.129"], ["71165.60", "0.264"], ["71166.90", "0.019"], ["71177.80", "0.536"], ["71178.80", "0.466"], ["71185.30", "0.077"], ["71185.40", "0.023"], ["71185.60", "0.048"], ["71185.70", "0.025"], ["71185.90", "0.006"], ["71186.00", "0.002"], ["71186.30", "0.665"], ["71186.40", "0.033"], ["71186.60", "0.215"], ["71186.70", "0.012"], ["71187.00", "0.040"], ["71187.50", "0.008"], ["71191.60", "0.007"], ["71192.50", "0.002"], ["71194.10", "0.006"]], "a": [["71194.70", "1.736"], ["71201.80", "0.007"], ["71208.70", "0.119"], ["71211.00", "0.081"], ["71211.30", "0.068"], ["71211.70", "0.116"], ["71212.80", "0.135"], ["71213.20", "0.005"], ["71213.60", "0.023"], ["71213.90", "0.065"], ["71214.00", "0.005"], ["71214.30", "0.000"], ["71214.70", "0.117"], ["71214.80", "0.006"], ["71214.90", "0.631"], ["71217.10", "0.154"], ["71220.60", "0.009"], ["71222.20", "0.004"], ["71227.50", "0.071"], ["71230.20", "0.534"], ["71230.30", "1.254"], ["71231.40", "0.280"], ["71236.30", "0.059"], ["71237.00", "0.819"], ["71237.30", "0.004"], ["71238.30", "0.003"], ["71244.40", "0.512"], ["71246.80", "0.215"], ["71246.90", "0.000"], ["71247.20", "0.063"], ["71247.60", "0.099"], ["71247.90", "0.188"], ["71248.60", "0.551"], ["71248.70", "0.428"], ["71248.80", "0.000"], ["71249.10", "0.002"], ["71249.40", "0.007"], ["71249.50", "0.006"], ["71249.60", "0.042"], ["71249.80", "0.340"], ["71249.90", "0.308"], ["71250.20", "0.003"], ["71250.50", "0.000"], ["71250.60", "0.004"], ["71251.70", "0.000"], ["71256.60", "1.053"], ["71257.70", "0.004"], ["71267.50", "0.038"], ["71270.50", "0.058"], ["71282.70", "1.552"], ["71283.10", "0.065"], ["71283.50", "0.124"], ["71283.70", "0.385"], ["71284.50", "0.000"], ["71284.60", "0.232"], ["71284.90", "1.015"], ["71285.30", "0.123"], ["71285.70", "0.316"], ["71285.80", "0.376"], ["71286.00", "0.121"], ["71286.40", "0.607"], ["71286.50", "1.216"], ["71289.00", "0.000"], ["71298.50", "0.004"], ["71301.10", "0.075"], ["71316.10", "2.868"], ["71362.80", "4.543"], ["71394.00", "0.060"], ["71395.20", "6.127"], ["71421.70", "0.000"], ["71427.60", "1.479"], ["71467.50", "0.925"], ["71785.50", "0.002"], ["71906.60", "0.002"], ["72618.50", "0.012"], ["74771.10", "0.000"], ["77035.10", "0.002"], ["89523.20", "0.000"]]}}
{"local_ts": 1773384628461, "server_ts": 1773384628245, "data": {"e": "depthUpdate", "E": 1773384628247, "T": 1773384628245, "s": "BTCUSDT", "U": 10101348266291, "u": 10101348271204, "pu": 10101348266189, "b": [["1000.00", "27.492"], ["5000.00", "101.438"], ["20694.60", "0.189"], ["20794.60", "0.054"], ["20894.60", "0.846"], ["20994.60", "0.063"], ["21094.60", "1.548"], ["56335.30", "0.002"], ["67634.00", "0.017"], ["68080.20", "0.170"], ["70304.70", "0.134"], ["70482.70", "0.710"], ["71148.00", "1.210"], ["71154.00", "0.808"], ["71155.00", "0.081"], ["71162.00", "1.762"], ["71169.00", "0.339"], ["71176.00", "0.006"], ["71192.60", "0.004"]], "a": [["71194.70", "1.416"], ["71215.30", "0.005"], ["71218.00", "0.006"], ["71218.10", "0.020"], ["71220.60", "0.011"], ["71223.50", "0.625"], ["71223.60", "0.129"], ["71225.00", "0.017"], ["71230.30", "1.155"], ["71232.00", "0.006"], ["71233.40", "0.736"], ["71233.70", "0.000"], ["71239.00", "0.309"], ["71244.40", "0.512"], ["71244.90", "0.289"], ["71245.00", "0.005"], ["71262.80", "0.002"], ["71263.70", "0.002"], ["71264.00", "0.058"], ["71264.70", "0.606"], ["71265.00", "0.002"], ["71265.90", "0.081"], ["71267.10", "0.186"], ["71267.50", "0.036"], ["71268.10", "0.005"], ["71269.00", "0.042"], ["71273.90", "0.042"], ["71274.90", "0.044"], ["71275.70", "0.120"], ["71275.90", "0.044"], ["71276.60", "0.082"], ["71277.60", "0.004"], ["71286.50", "1.218"], ["71287.30", "0.259"], ["71352.30", "0.002"], ["71427.50", "0.294"], ["71906.50", "0.007"], ["71906.60", "0.009"], ["72254.00", "1.178"], ["74783.40", "0.002"], ["74788.10", "0.002"], ["77345.60", "0.150"], ["89523.20", "0.000"]]}}
{"local_ts": 1773384629482, "server_ts": 1773384629266, "data": {"e": "depthUpdate", "E": 1773384629267, "T": 1773384629266, "s": "BTCUSDT", "U": 10101348380699, "u": 10101348405340, "pu": 10101348380610, "b": [["1000.00", "27.492"], ["5000.00", "101.438"], ["20801.90", "0.277"], ["20894.60", "0.081"], ["21001.90", "0.558"], ["21094.60", "0.396"], ["56335.30", "0.000"], ["60988.50", "0.249"], ["67421.30", "0.037"], ["68744.60", "0.002"], ["69777.90", "0.008"], ["70185.80", "0.000"], ["70342.50", "0.012"], ["70489.90", "0.007"], ["70838.60", "0.039"], ["70842.30", "0.000"], ["70894.20", "0.000"], ["70952.30", "0.022"], ["71056.80", "4.268"], ["71070.00", "16.175"], ["71078.70", "0.533"], ["71101.90", "0.044"], ["71103.60", "0.072"], ["71105.40", "0.500"], ["71107.60", "0.043"], ["71110.70", "0.070"], ["71117.80", "0.473"], ["71143.10", "0.000"], ["71145.30", "0.523"], ["71154.70", "0.004"], ["71155.20", "0.116"], ["71155.50", "0.076"], ["71158.50", "0.006"], ["71164.20", "0.511"], ["71166.10", "1.522"], ["71166.70", "0.023"], ["71167.50", "0.003"], ["71167.60", "0.013"], ["71168.00", "0.002"], ["71168.20", "0.443"], ["71168.30", "0.029"], ["71168.80", "0.054"], ["71168.90", "0.003"], ["71169.00", "0.381"], ["71171.00", "0.004"], ["71171.10", "0.077"], ["71171.70", "0.001"], ["71171.80", "0.566"], ["71172.30", "0.018"], ["71172.40", "0.193"], ["71172.50", "0.051"], ["71173.10", "0.008"], ["71173.20", "0.009"], ["71173.40", "0.018"], ["71173.80", "0.037"], ["71173.90", "0.025"], ["71175.40", "0.333"], ["71177.00", "0.005"], ["71179.80", "0.005"], ["71180.20", "0.023"], ["71180.30", "0.063"], ["71180.80", "0.011"], ["71182.80", "0.096"], ["71185.20", "0.024"], ["71185.30", "0.149"], ["71186.00", "0.007"], ["71186.30", "1.001"], ["71186.80", "0.000"], ["71186.90", "0.007"], ["71188.70", "0.636"], ["71188.80", "1.193"], ["71189.20", "0.051"], ["71189.90", "0.048"], ["71191.70", "0.121"], ["71191.80", "0.152"], ["71192.00", "0.040"], ["71192.30", "0.029"], ["71193.00", "0.005"], ["71193.10", "0.592"], ["71194.50", "0.287"], ["71195.70", "0.003"], ["71197.10", "0.004"], ["71198.80", "0.002"], ["71199.20", "0.002"], ["71199.30", "0.538"], ["71201.10", "0.002"], ["71201.30", "0.002"], ["71201.60", "0.009"], ["71201.90", "8.590"]], "a": [["71202.00", "0.248"], ["71204.30", "0.004"], ["71205.70", "0.070"], ["71206.10", "0.051"], ["71207.10", "0.001"], ["71208.30", "0.001"], ["71208.80", "0.003"], ["71209.90", "0.002"], ["71210.50", "0.058"], ["71211.50", "0.000"], ["71211.60", "0.004"], ["71211.70", "0.140"], ["71211.80", "0.007"], ["71211.90", "0.002"], ["71212.10", "0.088"], ["71212.70", "0.649"], ["71213.10", "0.001"], ["71213.60", "0.010"], ["71213.80", "0.004"], ["71214.00", "0.008"], ["71214.10", "0.000"], ["71214.20", "0.031"], ["71215.30", "0.003"], ["71215.40", "0.000"], ["71216.30", "0.005"], ["71217.30", "0.020"], ["71218.10", "0.020"], ["71218.20", "0.000"], ["71218.50", "0.059"], ["71219.20", "0.071"], ["71219.30", "0.011"], ["71219.60", "0.007"], ["71220.30", "0.000"], ["71221.80", "0.140"], ["71222.70", "0.008"], ["71223.00", "0.000"], ["71223.30", "0.253"], ["71223.40", "0.002"], ["71224.00", "0.029"], ["71224.40", "0.026"], ["71225.80", "0.631"], ["71225.90", "0.055"], ["71226.40", "0.004"], ["71226.50", "0.007"], ["71227.10", "0.006"], ["71227.20", "0.002"], ["71227.80", "0.510"], ["71227.90", "1.412"], ["71228.40", "0.003"], ["71228.60", "0.034"], ["71228.80", "0.000"], ["71229.10", "0.007"], ["71229.20", "0.017"], ["71229.60", "0.225"], ["71230.10", "0.002"], ["71230.30", "1.054"], ["71230.60", "0.031"], ["71230.70", "0.217"], ["71231.30", "0.003"], ["71231.40", "0.000"], ["71231.90", "0.010"], ["71232.00", "0.260"], ["71232.10", "0.516"], ["71232.70", "0.302"], ["71232.80", "0.046"], ["71233.40", "0.002"], ["71233.50", "0.310"], ["71235.50", "0.079"], ["71237.60", "0.638"], ["71238.70", "0.370"], ["71239.40", "0.022"], ["71241.10", "0.003"], ["71241.20", "0.161"], ["71241.60", "0.172"], ["71242.70", "0.000"], ["71243.40", "0.008"], ["71243.60", "0.155"], ["71243.80", "0.601"], ["71243.90", "0.005"], ["71254.50", "0.040"], ["71255.20", "0.015"], ["71259.20", "0.554"], ["71265.00", "0.000"], ["71273.50", "0.203"], ["71276.70", "0.040"], ["71281.70", "0.117"], ["71288.80", "0.342"], ["71293.20", "0.002"], ["71295.40", "0.012"], ["71297.00", "0.303"], ["71394.20", "0.062"], ["71394.60", "0.002"], ["71409.10", "0.003"], ["71412.60", "0.004"], ["71421.20", "0.025"], ["71424.00", "0.044"], ["71488.70", "0.302"], ["71502.90", "3.086"], ["71914.00", "0.002"], ["72254.10", "0.967"], ["72305.60", "1.343"], ["72349.00", "0.000"], ["72625.70", "0.106"], ["72626.00", "0.035"], ["74758.40", "0.000"], ["79596.50", "0.000"], ["89523.20", "0.000"]]}}
{"local_ts": 1773384630539, "server_ts": 1773384630286, "data": {"e": "depthUpdate", "E": 1773384630287, "T": 1773384630286, "s": "BTCUSDT", "U": 10101348575649, "u": 10101348592914, "pu": 10101348575628, "b": [["5000.00", "101.418"], ["20710.40", "0.162"], ["20794.60", "0.216"], ["20910.40", "0.315"], ["20911.40", "0.018"], ["20994.60", "0.378"], ["21001.90", "0.162"], ["51060.20", "1.257"], ["56335.30", "0.002"], ["67610.60", "0.002"], ["70201.00", "0.116"], ["70201.10", "0.146"], ["70201.90", "0.000"], ["70205.60", "0.016"], ["70206.00", "0.000"], ["70206.70", "0.002"], ["70207.00", "0.088"], ["70210.40", "0.008"], ["70211.40", "0.008"], ["70222.30", "0.000"], ["70490.00", "0.007"], ["70498.30", "0.000"], ["70525.50", "0.709"], ["70900.60", "0.000"], ["70906.20", "0.004"], ["70917.40", "0.000"], ["70917.80", "0.007"], ["70947.00", "0.209"], ["70952.40", "0.005"], ["70958.00", "0.011"], ["70970.80", "0.000"], ["70994.80", "0.009"], ["70994.90", "0.884"], ["71015.90", "2.573"], ["71016.00", "0.002"], ["71030.90", "5.199"], ["71039.20", "0.077"], ["71048.90", "0.009"], ["71049.00", "0.817"], ["71063.30", "0.797"], ["71066.20", "0.020"], ["71069.70", "0.000"], ["71069.80", "0.100"], ["71077.30", "0.000"], ["71090.30", "0.043"], ["71094.90", "0.604"], ["71101.50", "0.135"], ["71103.00", "0.762"], ["71108.90", "0.101"], ["71109.30", "0.129"], ["71114.20", "0.334"], ["71121.90", "0.044"], ["71123.60", "0.433"], ["71123.70", "0.029"], ["71124.50", "0.514"], ["71124.60", "0.395"], ["71125.10", "0.000"], ["71135.50", "0.047"], ["71142.80", "0.897"], ["71142.90", "0.002"], ["71143.10", "0.000"], ["71143.40", "0.006"], ["71146.10", "0.000"], ["71146.30", "0.089"], ["71147.00", "0.009"], ["71153.40", "0.943"], ["71155.50", "0.872"], ["71156.00", "0.009"], ["71156.10", "0.303"], ["71156.90", "0.874"], ["71157.00", "0.609"], ["71157.10", "0.691"], ["71157.20", "0.002"], ["71157.90", "0.000"], ["71158.60", "0.000"], ["71163.30", "0.001"], ["71163.50", "0.021"], ["71163.60", "0.956"], ["71165.20", "0.000"], ["71165.30", "0.326"], ["71167.60", "0.012"], ["71169.20", "0.007"], ["71169.30", "0.318"], ["71172.20", "0.315"], ["71172.30", "0.202"], ["71173.40", "0.005"], ["71174.00", "1.208"], ["71174.80", "0.018"], ["71177.40", "0.002"], ["71177.50", "0.511"], ["71178.60", "0.011"], ["71178.70", "0.003"], ["71179.20", "0.030"], ["71179.80", "0.907"], ["71180.70", "0.011"], ["71181.50", "0.000"], ["71183.50", "0.245"], ["71184.00", "0.011"], ["71186.40", "0.033"], ["71186.70", "0.300"], ["71187.30", "0.025"], ["71188.10", "0.034"], ["71188.30", "0.011"], ["71188.80", "0.000"], ["71189.00", "0.051"], ["71189.10", "0.000"], ["71189.20", "0.094"], ["71189.80", "0.005"], ["71190.00", "0.022"], ["71190.20", "1.153"], ["71190.40", "0.104"], ["71191.70", "0.036"], ["71191.90", "0.006"], ["71192.30", "0.164"], ["71192.50", "0.038"], ["71192.70", "0.002"], ["71193.10", "0.570"], ["71193.40", "0.005"], ["71193.50", "0.004"], ["71193.60", "0.004"], ["71194.30", "0.000"], ["71195.50", "0.004"], ["71196.40", "0.002"], ["71196.80", "0.099"], ["71196.90", "1.190"], ["71197.30", "0.332"], ["71197.70", "0.003"], ["71198.70", "0.003"], ["71199.20", "0.046"], ["71199.30", "0.648"], ["71199.40", "0.004"], ["71199.70", "0.103"], ["71200.00", "0.029"], ["71200.40", "0.027"], ["71200.50", "0.341"], ["71200.60", "0.476"], ["71201.00", "0.066"], ["71201.10", "0.129"], ["71201.30", "0.004"], ["71201.60", "0.034"], ["71201.90", "0.207"], ["71202.10", "1.063"], ["71202.30", "0.054"], ["71202.40", "0.039"], ["71202.50", "0.057"], ["71202.70", "0.033"], ["71203.20", "0.035"], ["71203.40", "0.637"], ["71203.50", "0.683"], ["71203.60", "0.000"], ["71203.80", "0.031"], ["71203.90", "0.639"], ["71204.20", "1.184"], ["71204.30", "0.871"], ["71204.80", "0.004"], ["71205.10", "0.000"], ["71205.30", "0.001"], ["71205.50", "0.003"], ["71205.90", "0.104"], ["71206.00", "0.166"], ["71206.20", "0.381"], ["71206.70", "0.061"], ["71206.80", "0.515"], ["71206.90", "0.109"], ["71207.30", "0.050"], ["71207.40", "0.035"], ["71207.50", "0.018"], ["71208.00", "0.004"], ["71208.20", "0.002"], ["71208.30", "0.006"], ["71208.70", "0.001"], ["71208.80", "0.000"], ["71209.30", "0.003"], ["71209.40", "0.001"], ["71209.80", "0.000"], ["71210.30", "0.004"], ["71210.40", "0.372"], ["71210.50", "1.513"], ["71210.60", "0.269"], ["71210.70", "0.000"], ["71210.80", "0.002"], ["71210.90", "0.000"], ["71211.10", "0.138"], ["71211.20", "0.000"], ["71211.30", "0.042"], ["71211.40", "7.075"], ["71211.50", "4.433"], ["71211.60", "14.663"]], "a": [["71210.50", "0.000"], ["71210.60", "0.000"], ["71210.80", "0.000"], ["71210.90", "0.000"], ["71211.00", "0.000"], ["71211.20", "0.000"], ["71211.30", "0.000"], ["71211.40", "0.000"], ["71211.50", "0.000"], ["71211.60", "0.000"], ["71211.90", "0.001"], ["71212.10", "0.006"], ["71212.60", "0.002"], ["71212.70", "0.002"], ["71212.90", "0.010"], ["71213.00", "0.006"], ["71213.40", "0.000"], ["71213.60", "0.000"], ["71215.60", "0.210"], ["71215.70", "0.006"], ["71215.90", "0.000"], ["71217.70", "0.004"], ["71218.50", "0.002"], ["71218.60", "0.028"], ["71218.70", "0.001"], ["71219.10", "0.000"], ["71219.20", "0.000"], ["71219.90", "0.000"], ["71221.00", "0.000"], ["71222.00", "0.066"], ["71222.30", "0.150"], ["71222.50", "0.003"], ["71223.30", "0.072"], ["71223.40", "0.078"], ["71223.50", "0.341"], ["71223.60", "0.705"], ["71223.90", "0.003"], ["71224.00", "0.002"], ["71224.20", "0.002"], ["71224.70", "0.000"], ["71224.80", "0.119"], ["71224.90", "0.004"], ["71225.00", "0.008"], ["71225.10", "0.072"], ["71225.20", "0.227"], ["71226.00", "0.517"], ["71226.10", "0.000"], ["71226.20", "0.647"], ["71226.30", "0.004"], ["71226.50", "0.006"], ["71226.80", "0.023"], ["71227.20", "0.002"], ["71227.70", "0.267"], ["71228.10", "0.036"], ["71228.30", "0.004"], ["71228.80", "0.006"], ["71229.30", "0.001"], ["71230.50", "0.004"], ["71230.60", "0.450"], ["71230.70", "0.218"], ["71231.00", "0.025"], ["71231.10", "0.000"], ["71231.40", "0.001"], ["71231.60", "0.002"], ["71232.60", "0.682"], ["71233.80", "0.659"], ["71234.10", "0.003"], ["71234.20", "0.000"], ["71234.40", "0.006"], ["71234.50", "0.006"], ["71234.80", "0.002"], ["71234.90", "0.005"], ["71236.50", "0.015"], ["71236.70", "0.341"], ["71236.90", "0.000"], ["71237.00", "0.033"], ["71237.10", "0.007"], ["71237.30", "0.016"], ["71237.70", "0.029"], ["71237.90", "0.000"], ["71238.00", "0.005"], ["71239.00", "0.309"], ["71239.10", "0.009"], ["71239.20", "0.126"], ["71239.80", "0.072"], ["71240.60", "0.771"], ["71241.60", "0.106"], ["71242.50", "0.240"], ["71242.60", "0.004"], ["71242.70", "0.000"], ["71243.10", "0.061"], ["71243.50", "0.211"], ["71243.70", "0.004"], ["71243.80", "0.641"], ["71244.80", "0.061"], ["71246.10", "0.332"], ["71246.80", "0.140"], ["71247.00", "0.015"], ["71247.60", "0.074"], ["71247.70", "0.032"], ["71247.90", "0.140"], ["71248.60", "0.847"], ["71248.70", "0.490"], ["71249.00", "1.899"], ["71249.60", "0.040"], ["71251.50", "0.650"], ["71252.10", "0.005"], ["71252.80", "0.130"], ["71253.20", "0.045"], ["71253.60", "0.005"], ["71254.10", "0.024"], ["71254.20", "0.002"], ["71254.30", "0.005"], ["71255.10", "0.214"], ["71256.00", "0.544"], ["71256.10", "0.676"], ["71257.00", "0.000"], ["71258.00", "0.005"], ["71258.60", "0.055"], ["71258.70", "0.273"], ["71259.70", "0.004"], ["71262.90", "0.003"], ["71263.30", "0.003"], ["71263.90", "0.002"], ["71264.40", "0.508"], ["71264.90", "0.000"], ["71266.40", "0.078"], ["71267.10", "0.051"], ["71268.10", "0.005"], ["71268.60", "0.069"], ["71269.00", "0.042"], ["71272.90", "0.578"], ["71273.50", "0.201"], ["71273.80", "0.655"], ["71274.40", "0.508"], ["71276.40", "0.031"], ["71276.50", "0.004"], ["71277.40", "0.000"], ["71278.40", "0.299"], ["71279.70", "0.134"], ["71281.40", "0.003"], ["71282.70", "1.554"], ["71285.30", "0.206"], ["71286.30", "0.085"], ["71287.90", "3.181"], ["71289.40", "0.306"], ["71294.40", "0.104"], ["71295.90", "0.286"], ["71297.40", "0.056"], ["71297.50", "0.000"], ["71299.20", "1.572"], ["71299.30", "0.063"], ["71302.00", "0.010"], ["71305.80", "1.191"], ["71307.30", "6.581"], ["71307.40", "0.049"], ["71318.60", "0.077"], ["71319.00", "0.573"], ["71319.30", "0.760"], ["71320.10", "0.048"], ["71320.40", "0.257"], ["71321.40", "0.078"], ["71325.70", "1.957"], ["71326.60", "0.000"], ["71337.20", "0.005"], ["71337.70", "0.356"], ["71339.10", "0.000"], ["71342.60", "0.070"], ["71348.90", "0.038"], ["71351.30", "0.036"], ["71351.40", "0.438"], ["71362.90", "2.150"], ["71370.00", "1.667"], ["71373.30", "0.007"], ["71373.40", "0.983"], ["71377.80", "0.039"], ["71381.40", "0.039"], ["71382.40", "0.039"], ["71382.50", "1.736"], ["71392.90", "0.005"], ["71393.00", "0.017"], ["71403.80", "0.099"], ["71410.90", "0.003"], ["71421.10", "0.024"], ["71421.20", "0.018"], ["71427.40", "0.510"], ["71427.50", "1.044"], ["71446.80", "0.007"], ["71470.00", "0.669"], ["71478.40", "0.562"], ["71481.50", "0.812"], ["71500.60", "0.000"], ["71518.80", "6.429"], ["71535.60", "0.874"], ["71550.40", "0.000"], ["71566.50", "0.075"], ["71914.00", "0.000"], ["72242.80", "0.857"], ["74802.60", "0.002"], ["74803.60", "0.002"], ["79594.20", "0.005"], ["89523.20", "0.000"]]}}
{"local_ts": 1773384631630, "server_ts": 1773384631409, "data": {"e": "depthUpdate", "E": 1773384631411, "T": 1773384631409, "s": "BTCUSDT", "U": 10101348732686, "u": 10101348739172, "pu": 10101348732604, "b": [["5000.00", "101.418"], ["20701.90", "0.270"], ["20821.90", "0.774"], ["20901.90", "0.495"], ["20915.80", "0.000"], ["20916.50", "0.000"], ["21121.90", "0.387"], ["40000.00", "49.453"], ["56977.50", "0.000"], ["67630.10", "0.021"], ["67660.00", "0.029"], ["70080.90", "0.000"], ["70116.40", "0.000"], ["70187.60", "0.000"], ["70194.50", "0.854"], ["70854.50", "0.004"], ["70865.80", "5.700"], ["70958.00", "0.007"], ["71124.60", "0.395"], ["71148.80", "0.004"], ["71156.30", "0.178"], ["71158.00", "0.074"], ["71173.10", "0.002"], ["71173.30", "0.337"], ["71181.50", "0.000"], ["71186.30", "0.638"], ["71188.50", "0.121"], ["71191.60", "0.288"], ["71193.60", "0.093"], ["71202.40", "0.051"], ["71205.00", "0.640"], ["71205.60", "0.035"], ["71206.20", "0.386"], ["71207.70", "0.541"], ["71208.00", "0.119"], ["71208.20", "0.110"], ["71208.30", "0.006"], ["71208.90", "0.074"], ["71209.30", "0.403"], ["71209.40", "1.101"], ["71209.50", "0.396"], ["71209.80", "0.038"], ["71210.20", "0.034"], ["71210.50", "0.045"], ["71210.80", "0.030"], ["71214.00", "0.860"], ["71221.70", "0.002"], ["71221.80", "0.137"]], "a": [["71222.00", "0.967"], ["71222.10", "0.002"], ["71227.70", "0.001"], ["71229.20", "0.002"], ["71230.20", "0.007"], ["71230.50", "0.006"], ["71231.50", "0.000"], ["71231.70", "0.045"], ["71232.10", "0.003"], ["71232.40", "0.422"], ["71232.50", "0.482"], ["71233.40", "0.000"], ["71233.70", "0.004"], ["71234.30", "0.281"], ["71234.60", "0.000"], ["71234.70", "0.063"], ["71234.90", "0.003"], ["71235.00", "0.003"], ["71235.10", "0.146"], ["71235.40", "0.056"], ["71235.60", "0.048"], ["71235.80", "0.208"], ["71236.00", "0.008"], ["71236.10", "0.075"], ["71236.20", "0.534"], ["71236.30", "0.078"], ["71236.40", "0.000"], ["71236.60", "0.143"], ["71237.00", "0.005"], ["71237.30", "0.010"], ["71238.30", "0.057"], ["71238.40", "0.087"], ["71238.60", "0.010"], ["71238.80", "0.008"], ["71239.40", "0.004"], ["71240.10", "0.009"], ["71240.40", "0.542"], ["71240.70", "0.682"], ["71241.70", "0.000"], ["71242.70", "0.007"], ["71243.40", "0.141"], ["71244.10", "0.921"], ["71244.80", "0.015"], ["71246.50", "0.000"], ["71246.90", "0.000"], ["71247.40", "0.245"], ["71247.50", "0.302"], ["71248.40", "0.142"], ["71248.50", "1.012"], ["71248.60", "0.845"], ["71248.70", "0.428"], ["71251.30", "0.203"], ["71256.10", "0.697"], ["71256.40", "0.006"], ["71257.60", "0.003"], ["71260.20", "0.002"], ["71261.10", "1.272"], ["71264.00", "0.058"], ["71267.80", "0.054"], ["71282.20", "0.005"], ["71290.00", "0.112"], ["71331.90", "0.371"], ["71354.50", "0.075"], ["71354.80", "0.071"], ["71355.20", "0.145"], ["71355.60", "0.124"], ["71356.30", "0.198"], ["71356.40", "0.080"], ["71361.90", "0.088"], ["71380.40", "0.100"], ["71383.40", "10.118"], ["71386.10", "0.000"], ["71434.70", "6.443"], ["71517.10", "0.000"], ["71934.20", "0.009"], ["72256.00", "2.502"], ["72442.60", "0.000"], ["72711.20", "0.104"], ["74070.80", "0.002"], ["89523.20", "0.000"], ["100000.00", "15.858"]]}}
{"local_ts": 1773384632650, "server_ts": 1773384632432, "data": {"e": "depthUpdate", "E": 1773384632433, "T": 1773384632432, "s": "BTCUSDT", "U": 10101348828397, "u": 10101348856778, "pu": 10101348828344, "b": [["1000.00", "27.492"], ["5000.00", "101.418"], ["20721.90", "0.693"], ["20722.10", "0.009"], ["20724.20", "0.036"], ["20726.50", "0.009"], ["20821.90", "0.810"], ["21021.90", "0.468"], ["21022.80", "0.009"], ["21024.20", "0.009"], ["21026.50", "0.009"], ["21121.90", "0.162"], ["56977.50", "0.000"], ["56978.00", "0.000"], ["67634.90", "0.000"], ["67635.00", "0.004"], ["69397.60", "0.000"], ["69800.80", "0.043"], ["70200.00", "12.033"], ["70201.10", "0.144"], ["70211.40", "0.002"], ["70213.20", "0.000"], ["70213.90", "0.004"], ["70215.80", "0.000"], ["70216.50", "0.000"], ["70222.00", "2.935"], ["70222.10", "0.010"], ["70222.50", "2.205"], ["70224.20", "0.018"], ["70246.20", "0.283"], ["70506.70", "0.000"], ["70509.70", "0.020"], ["70652.10", "0.076"], ["70922.20", "0.000"], ["70939.20", "0.000"], ["70951.70", "1.509"], ["70962.20", "0.000"], ["70972.00", "0.000"], ["71050.20", "0.075"], ["71058.10", "0.099"], ["71080.30", "0.000"], ["71087.70", "4.356"], ["71091.20", "0.191"], ["71092.80", "0.363"], ["71094.50", "0.000"], ["71095.40", "0.306"], ["71098.10", "0.507"], ["71102.00", "1.198"], ["71103.10", "0.000"], ["71103.90", "0.000"], ["71105.40", "0.539"], ["71106.00", "0.199"], ["71108.80", "0.010"], ["71115.90", "0.040"], ["71116.90", "0.540"], ["71117.10", "0.112"], ["71126.80", "0.124"], ["71127.90", "0.002"], ["71133.70", "0.036"], ["71134.10", "0.004"], ["71134.80", "0.676"], ["71137.00", "0.000"], ["71138.50", "0.103"], ["71139.60", "0.002"], ["71139.70", "0.018"], ["71141.00", "0.028"], ["71141.60", "0.103"], ["71142.80", "0.335"], ["71142.90", "0.002"], ["71144.10", "0.000"], ["71145.90", "0.245"], ["71146.20", "0.002"], ["71146.30", "0.101"], ["71147.00", "0.009"], ["71148.10", "0.301"], ["71148.20", "0.049"], ["71148.50", "0.284"], ["71149.50", "0.008"], ["71150.40", "0.341"], ["71151.80", "0.048"], ["71152.80", "0.000"], ["71152.90", "0.005"], ["71153.80", "0.029"], ["71154.40", "0.662"], ["71155.00", "1.342"], ["71155.10", "0.008"], ["71158.20", "0.003"], ["71158.80", "0.325"], ["71159.00", "0.023"], ["71162.30", "0.102"], ["71163.70", "1.508"], ["71164.40", "0.019"], ["71165.30", "0.356"], ["71166.20", "0.003"], ["71166.90", "0.509"], ["71167.50", "0.005"], ["71168.00", "0.000"], ["71170.00", "0.312"], ["71170.80", "0.058"], ["71171.90", "0.023"], ["71172.20", "0.974"], ["71173.00", "1.906"], ["71173.10", "0.950"], ["71173.40", "0.005"], ["71173.80", "0.271"], ["71174.30", "0.140"], ["71174.50", "0.004"], ["71174.60", "0.294"], ["71174.90", "0.026"], ["71175.00", "0.093"], ["71175.10", "0.002"], ["71175.40", "0.016"], ["71175.60", "0.185"], ["71175.90", "0.003"], ["71176.00", "0.006"], ["71176.10", "0.616"], ["71176.20", "0.162"], ["71176.40", "0.002"], ["71176.90", "0.351"], ["71177.80", "0.170"], ["71177.90", "0.000"], ["71178.00", "0.027"], ["71180.40", "1.202"], ["71180.50", "0.675"], ["71180.60", "1.184"], ["71182.70", "0.205"], ["71182.90", "0.024"], ["71183.50", "0.157"], ["71183.70", "0.003"], ["71183.80", "0.000"], ["71184.50", "0.000"], ["71185.90", "0.009"], ["71186.10", "0.002"], ["71186.20", "0.509"], ["71186.30", "1.187"], ["71186.40", "0.004"], ["71186.80", "0.004"], ["71187.80", "0.000"], ["71187.90", "0.007"], ["71188.10", "0.000"], ["71188.50", "0.252"], ["71188.60", "0.003"], ["71190.00", "0.024"], ["71190.60", "0.081"], ["71190.90", "0.116"], ["71191.30", "2.707"], ["71192.70", "0.112"], ["71193.20", "0.006"], ["71193.40", "0.007"], ["71193.50", "0.032"], ["71193.60", "0.020"], ["71193.70", "0.004"], ["71194.50", "0.008"], ["71194.90", "0.300"], ["71195.50", "0.000"], ["71195.60", "0.000"], ["71195.90", "0.599"], ["71196.40", "0.002"], ["71196.50", "0.006"], ["71196.70", "0.070"], ["71197.00", "0.249"], ["71198.10", "0.000"], ["71198.20", "0.004"], ["71198.40", "0.000"], ["71198.50", "0.302"], ["71198.90", "0.004"], ["71199.20", "0.001"], ["71199.80", "0.030"], ["71200.00", "0.065"], ["71200.10", "0.005"], ["71200.30", "0.001"], ["71200.50", "0.341"], ["71200.60", "0.546"], ["71200.70", "0.002"], ["71200.90", "0.080"], ["71201.10", "0.002"], ["71201.20", "0.003"], ["71201.40", "0.338"], ["71201.60", "0.017"], ["71201.70", "0.346"], ["71201.90", "0.054"], ["71202.00", "1.611"], ["71202.10", "1.360"], ["71202.30", "0.003"], ["71202.40", "0.009"], ["71202.50", "0.000"], ["71202.70", "0.001"], ["71202.80", "0.003"], ["71202.90", "0.015"], ["71203.10", "0.004"], ["71203.30", "0.012"], ["71203.40", "0.659"], ["71203.60", "0.000"], ["71203.70", "0.005"], ["71204.10", "0.002"], ["71204.30", "1.431"], ["71204.40", "0.429"], ["71204.60", "0.730"], ["71205.00", "0.018"], ["71205.10", "0.002"], ["71205.20", "0.643"], ["71205.30", "0.044"], ["71205.40", "0.002"], ["71205.60", "0.019"], ["71205.80", "0.042"], ["71205.90", "0.004"], ["71206.00", "0.067"], ["71206.30", "0.073"], ["71206.50", "0.003"], ["71206.60", "0.005"], ["71206.90", "0.002"], ["71207.70", "0.008"], ["71207.80", "0.007"], ["71208.10", "0.074"], ["71208.20", "0.003"], ["71208.60", "0.025"], ["71208.70", "0.009"], ["71208.90", "0.007"], ["71209.00", "0.523"], ["71209.20", "0.020"], ["71209.40", "1.063"], ["71209.50", "0.031"], ["71209.80", "0.000"], ["71209.90", "0.283"], ["71210.00", "0.006"], ["71210.10", "0.003"], ["71210.20", "0.549"], ["71210.40", "0.033"], ["71210.50", "0.628"], ["71210.60", "0.009"], ["71210.70", "0.078"], ["71211.20", "0.000"], ["71211.30", "0.007"], ["71211.40", "0.041"], ["71211.90", "0.000"], ["71212.10", "0.173"], ["71212.20", "0.109"], ["71212.30", "0.010"], ["71212.40", "0.001"], ["71212.90", "0.366"], ["71213.00", "1.195"], ["71213.30", "0.110"], ["71213.40", "0.005"], ["71213.60", "0.084"], ["71213.90", "0.000"], ["71214.00", "0.857"], ["71214.10", "0.080"], ["71214.20", "0.113"], ["71214.40", "0.329"], ["71214.70", "0.840"], ["71214.90", "0.000"], ["71215.10", "0.001"], ["71215.30", "0.140"], ["71215.80", "0.047"], ["71216.00", "0.006"], ["71216.10", "0.008"], ["71216.30", "0.000"], ["71216.60", "0.004"], ["71217.00", "0.000"], ["71217.10", "0.000"], ["71217.30", "0.001"], ["71217.40", "0.010"], ["71217.70", "0.000"], ["71218.00", "0.006"], ["71218.10", "0.007"], ["71218.40", "0.511"], ["71218.60", "0.002"], ["71218.70", "0.001"], ["71218.80", "0.005"], ["71218.90", "0.003"], ["71219.10", "0.003"], ["71219.30", "0.000"], ["71219.40", "0.024"], ["71219.60", "0.010"], ["71219.90", "0.003"], ["71220.00", "0.018"], ["71220.20", "0.342"], ["71220.30", "0.000"], ["71220.40", "0.002"], ["71220.50", "0.060"], ["71220.90", "0.003"], ["71221.10", "0.003"], ["71221.30", "0.007"], ["71221.50", "0.002"], ["71221.80", "0.130"], ["71221.90", "0.026"], ["71222.00", "0.582"], ["71222.10", "0.007"], ["71222.20", "0.142"], ["71222.30", "0.002"], ["71222.50", "0.005"], ["71222.60", "0.000"], ["71222.70", "0.002"], ["71222.80", "0.002"], ["71222.90", "0.002"], ["71223.00", "0.042"], ["71223.10", "0.000"], ["71223.30", "0.000"], ["71223.40", "0.000"], ["71223.50", "0.000"], ["71223.60", "0.000"], ["71223.70", "0.007"], ["71223.80", "0.000"], ["71223.90", "0.000"], ["71224.00", "0.000"], ["71224.10", "0.093"], ["71224.20", "0.165"], ["71224.30", "0.002"], ["71224.40", "1.484"], ["71224.50", "0.506"], ["71224.70", "0.000"], ["71224.80", "0.000"], ["71224.90", "0.000"], ["71225.00", "0.008"], ["71225.20", "0.000"], ["71225.40", "0.000"], ["71225.50", "0.000"], ["71225.60", "0.000"], ["71225.70", "0.042"], ["71225.80", "0.002"], ["71225.90", "0.000"], ["71226.20", "0.000"], ["71226.30", "0.000"], ["71226.40", "0.004"], ["71226.50", "9.148"]], "a": [["71222.00", "0.000"], ["71222.10", "0.000"], ["71222.20", "0.000"], ["71222.40", "0.000"], ["71222.60", "0.000"], ["71222.70", "0.000"], ["71222.80", "0.000"], ["71222.90", "0.000"], ["71223.10", "0.000"], ["71223.40", "0.000"], ["71223.50", "0.000"], ["71223.60", "0.000"], ["71223.80", "0.000"], ["71223.90", "0.000"], ["71224.00", "0.000"], ["71224.30", "0.000"], ["71224.40", "0.000"], ["71224.50", "0.000"], ["71224.60", "0.000"], ["71224.90", "0.000"], ["71225.00", "0.000"], ["71225.30", "0.000"], ["71225.50", "0.000"], ["71225.60", "0.000"], ["71225.70", "0.000"], ["71225.90", "0.000"], ["71226.00", "0.000"], ["71226.30", "0.000"], ["71226.40", "0.000"], ["71226.60", "1.408"], ["71226.70", "0.003"], ["71226.90", "0.000"], ["71227.20", "0.000"], ["71227.30", "0.002"], ["71227.60", "0.000"], ["71227.80", "0.002"], ["71227.90", "0.215"], ["71228.00", "0.011"], ["71228.10", "0.000"], ["71229.20", "0.002"], ["71229.40", "0.000"], ["71229.50", "0.005"], ["71230.30", "0.005"], ["71230.50", "0.046"], ["71231.30", "0.065"], ["71231.40", "0.001"], ["71231.70", "0.003"], ["71231.80", "0.086"], ["71231.90", "0.210"], ["71232.20", "0.004"], ["71232.30", "0.027"], ["71232.40", "0.006"], ["71232.50", "0.006"], ["71232.60", "0.000"], ["71232.70", "0.053"], ["71232.90", "0.004"], ["71233.20", "0.003"], ["71233.30", "0.005"], ["71233.50", "0.003"], ["71233.70", "0.004"], ["71233.90", "0.004"], ["71235.10", "0.128"], ["71235.30", "0.003"], ["71235.50", "0.090"], ["71236.00", "0.006"], ["71236.10", "0.859"], ["71236.20", "0.354"], ["71236.30", "0.076"], ["71236.40", "0.003"], ["71236.90", "0.001"], ["71237.00", "0.008"], ["71237.10", "0.000"], ["71237.60", "0.004"], ["71237.80", "0.002"], ["71238.40", "0.000"], ["71238.50", "0.007"], ["71238.60", "0.008"], ["71238.70", "0.000"], ["71238.80", "0.007"], ["71239.20", "0.001"], ["71239.40", "0.002"], ["71239.50", "0.004"], ["71239.60", "0.003"], ["71239.80", "0.051"], ["71240.10", "0.009"], ["71240.20", "0.057"], ["71240.40", "0.395"], ["71240.50", "0.016"], ["71240.80", "0.013"], ["71241.10", "0.003"], ["71241.70", "0.059"], ["71241.80", "0.001"], ["71241.90", "0.003"], ["71242.10", "0.005"], ["71242.60", "0.427"], ["71242.80", "0.140"], ["71242.90", "0.026"], ["71243.20", "0.001"], ["71243.40", "0.141"], ["71243.50", "0.007"], ["71243.70", "0.004"], ["71243.80", "0.041"], ["71244.10", "0.850"], ["71244.20", "0.005"], ["71244.30", "0.004"], ["71244.50", "0.013"], ["71244.90", "0.017"], ["71245.00", "0.007"], ["71245.10", "0.007"], ["71245.90", "0.142"], ["71246.10", "0.001"], ["71246.60", "0.059"], ["71246.90", "0.000"], ["71247.00", "0.012"], ["71247.10", "0.002"], ["71247.30", "0.017"], ["71247.40", "0.020"], ["71247.50", "0.302"], ["71247.90", "0.142"], ["71248.00", "0.402"], ["71248.10", "0.002"], ["71248.20", "0.037"], ["71248.30", "0.153"], ["71248.40", "0.115"], ["71248.80", "0.005"], ["71248.90", "0.080"], ["71249.00", "0.958"], ["71249.40", "0.007"], ["71249.70", "0.000"], ["71250.00", "3.291"], ["71250.10", "0.005"], ["71250.40", "0.659"], ["71251.30", "0.201"], ["71251.50", "0.648"], ["71251.60", "0.211"], ["71251.70", "0.000"], ["71251.80", "0.000"], ["71252.00", "0.009"], ["71252.10", "0.012"], ["71252.30", "0.015"], ["71252.40", "0.000"], ["71252.50", "0.299"], ["71252.70", "0.000"], ["71253.00", "0.013"], ["71253.10", "0.014"], ["71253.20", "0.566"], ["71253.40", "0.184"], ["71253.60", "0.009"], ["71253.70", "0.059"], ["71253.80", "0.289"], ["71254.10", "0.003"], ["71254.20", "0.008"], ["71254.40", "0.006"], ["71254.50", "0.004"], ["71254.90", "0.246"], ["71255.00", "0.303"], ["71255.10", "0.249"], ["71255.30", "0.048"], ["71255.50", "0.144"], ["71255.60", "0.531"], ["71255.70", "0.338"], ["71255.90", "0.058"], ["71256.00", "0.508"], ["71256.50", "0.130"], ["71256.70", "0.070"], ["71257.70", "0.509"], ["71257.80", "0.000"], ["71258.30", "0.013"], ["71258.50", "0.001"], ["71258.60", "0.008"], ["71258.70", "0.273"], ["71259.00", "0.019"], ["71259.10", "0.869"], ["71259.40", "0.302"], ["71259.80", "0.015"], ["71259.90", "0.067"], ["71260.00", "0.374"], ["71260.40", "0.106"], ["71260.80", "0.008"], ["71261.10", "0.207"], ["71261.20", "1.014"], ["71261.50", "0.000"], ["71261.90", "0.000"], ["71262.20", "0.000"], ["71262.50", "0.013"], ["71262.90", "0.003"], ["71263.10", "0.031"], ["71263.60", "0.285"], ["71263.70", "0.002"], ["71264.00", "0.060"], ["71264.30", "0.038"], ["71264.80", "0.000"], ["71265.30", "0.207"], ["71265.50", "0.000"], ["71265.60", "0.634"], ["71265.70", "1.070"], ["71266.00", "0.037"], ["71266.60", "0.095"], ["71266.70", "0.358"], ["71267.10", "0.338"], ["71268.20", "0.513"], ["71268.30", "1.346"], ["71268.80", "0.000"], ["71268.90", "0.003"], ["71269.30", "0.069"], ["71269.40", "0.844"], ["71269.50", "0.004"], ["71269.70", "0.947"], ["71269.80", "0.053"], ["71269.90", "0.254"], ["71270.60", "0.100"], ["71271.50", "0.684"], ["71271.90", "0.002"], ["71273.90", "0.004"], ["71274.30", "0.017"], ["71274.90", "0.618"], ["71275.30", "0.079"], ["71275.90", "0.000"], ["71278.60", "1.308"], ["71279.80", "0.311"], ["71280.00", "0.109"], ["71280.30", "0.007"], ["71281.50", "0.015"], ["71281.80", "0.536"], ["71281.90", "0.000"], ["71282.10", "0.002"], ["71283.00", "0.045"], ["71283.20", "0.048"], ["71285.00", "0.002"], ["71286.30", "0.030"], ["71288.00", "0.229"], ["71288.40", "0.026"], ["71288.60", "0.649"], ["71289.70", "0.041"], ["71289.80", "0.002"], ["71290.70", "0.042"], ["71290.80", "0.085"], ["71294.80", "0.472"], ["71295.00", "0.046"], ["71296.00", "0.078"], ["71296.30", "0.770"], ["71296.40", "0.312"], ["71297.90", "0.008"], ["71298.00", "1.527"], ["71299.10", "0.506"], ["71300.20", "0.004"], ["71301.20", "0.000"], ["71301.70", "0.611"], ["71302.60", "0.004"], ["71303.00", "0.070"], ["71304.20", "0.004"], ["71305.10", "0.000"], ["71305.50", "0.085"], ["71305.90", "4.442"], ["71306.10", "0.000"], ["71306.90", "0.000"], ["71307.80", "0.289"], ["71307.90", "0.009"], ["71308.70", "0.000"], ["71308.80", "0.817"], ["71309.70", "0.010"], ["71309.90", "0.001"], ["71310.10", "0.002"], ["71310.20", "0.009"], ["71310.90", "0.003"], ["71311.10", "0.000"], ["71311.30", "0.082"], ["71311.50", "0.008"], ["71311.80", "0.000"], ["71312.00", "0.072"], ["71312.90", "0.108"], ["71315.20", "0.015"], ["71316.50", "0.002"], ["71316.70", "0.729"], ["71317.40", "0.002"], ["71318.70", "0.002"], ["71321.20", "0.000"], ["71322.00", "0.139"], ["71322.10", "0.004"], ["71322.60", "0.000"], ["71323.00", "0.016"], ["71323.10", "0.000"], ["71323.50", "1.057"], ["71324.00", "0.000"], ["71324.50", "0.076"], ["71324.70", "0.000"], ["71325.70", "1.957"], ["71327.30", "0.006"], ["71328.20", "0.000"], ["71329.20", "0.002"], ["71332.30", "0.153"], ["71332.80", "0.122"], ["71333.40", "0.000"], ["71333.80", "0.093"], ["71334.30", "0.505"], ["71336.40", "0.141"], ["71338.00", "0.000"], ["71341.30", "2.441"], ["71342.10", "0.202"], ["71343.60", "10.028"], ["71343.70", "0.042"], ["71344.20", "0.357"], ["71344.70", "0.004"], ["71352.80", "0.000"], ["71354.10", "0.102"], ["71356.00", "0.337"], ["71357.00", "0.008"], ["71357.90", "0.003"], ["71377.80", "0.052"], ["71381.40", "1.860"], ["71381.50", "0.000"], ["71386.20", "22.957"], ["71388.60", "2.477"], ["71389.80", "0.000"], ["71393.10", "0.536"], ["71396.80", "0.000"], ["71399.90", "0.000"], ["71400.20", "0.099"], ["71400.30", "0.099"], ["71401.10", "0.160"], ["71401.40", "0.164"], ["71402.40", "0.162"], ["71403.60", "0.004"], ["71403.70", "0.099"], ["71403.80", "0.000"], ["71404.10", "3.662"], ["71404.70", "0.099"], ["71408.70", "3.511"], ["71419.20", "0.000"], ["71421.20", "0.018"], ["71429.00", "17.457"], ["71429.90", "0.509"], ["71433.40", "0.003"], ["71442.50", "0.582"], ["71448.90", "0.000"], ["71526.00", "0.104"], ["71526.10", "0.331"], ["71527.00", "0.300"], ["71527.60", "0.296"], ["71532.30", "1.420"], ["71534.20", "6.419"], ["71577.90", "0.027"], ["71578.00", "0.068"], ["71578.20", "0.212"], ["71645.50", "0.002"], ["71791.80", "0.070"], ["71934.20", "0.016"], ["72589.30", "0.000"], ["74815.20", "0.002"], ["89523.20", "0.000"]]}}
{"local_ts": 1773384633669, "server_ts": 1773384633451, "data": {"e": "depthUpdate", "E": 1773384633453, "T": 1773384633451, "s": "BTCUSDT", "U": 10101348951962, "u": 10101348959279, "pu": 10101348951810, "b": [["1000.00", "27.492"], ["5000.00", "101.418"], ["20726.50", "0.585"], ["20926.50", "0.360"], ["21026.50", "0.054"], ["21126.50", "0.477"], ["56978.00", "0.000"], ["64103.80", "0.008"], ["69404.90", "0.000"], ["69770.80", "0.000"], ["69801.40", "0.015"], ["70116.80", "0.000"], ["70367.20", "0.142"], ["70514.20", "0.002"], ["70865.90", "1.298"], ["70870.40", "0.002"], ["71055.40", "0.021"], ["71059.60", "0.000"], ["71073.50", "0.000"], ["71077.60", "0.002"], ["71077.70", "6.461"], ["71078.00", "0.023"], ["71078.30", "0.000"], ["71078.40", "0.000"], ["71078.70", "0.508"], ["71079.00", "0.024"], ["71079.40", "0.011"], ["71098.80", "0.075"], ["71101.50", "0.099"], ["71110.90", "6.831"], ["71113.50", "0.029"], ["71113.60", "0.421"], ["71113.90", "1.500"], ["71114.20", "0.092"], ["71114.60", "0.508"], ["71114.90", "0.062"], ["71115.20", "0.080"], ["71173.10", "0.911"], ["71173.40", "0.189"], ["71176.70", "0.132"], ["71176.80", "0.003"], ["71190.90", "0.116"], ["71201.90", "0.051"], ["71204.90", "0.631"], ["71211.80", "0.547"], ["71213.30", "0.000"], ["71213.40", "0.005"], ["71213.70", "0.003"], ["71214.00", "0.856"], ["71214.40", "0.446"], ["71214.70", "0.209"], ["71215.00", "0.004"], ["71220.60", "0.005"], ["71221.20", "0.118"], ["71221.80", "0.004"], ["71224.20", "0.076"], ["71225.60", "0.070"], ["71225.70", "0.000"], ["71226.30", "0.009"], ["71226.40", "0.078"], ["71226.50", "1.094"]], "a": [["71226.60", "3.905"], ["71227.60", "0.002"], ["71227.70", "0.001"], ["71233.60", "0.269"], ["71233.70", "0.682"], ["71235.10", "0.001"], ["71235.40", "0.041"], ["71235.80", "0.047"], ["71236.10", "0.076"], ["71236.20", "0.001"], ["71237.00", "0.010"], ["71237.80", "0.000"], ["71238.60", "0.005"], ["71239.00", "0.010"], ["71239.40", "0.030"], ["71239.60", "0.088"], ["71239.70", "0.036"], ["71239.80", "0.043"], ["71240.10", "0.642"], ["71240.50", "0.052"], ["71246.20", "0.002"], ["71248.40", "0.535"], ["71248.50", "1.014"], ["71248.70", "0.312"], ["71262.20", "0.002"], ["71263.10", "0.093"], ["71273.20", "0.851"], ["71273.30", "0.354"], ["71273.40", "0.106"], ["71275.40", "0.305"], ["71282.70", "1.479"], ["71283.10", "0.002"], ["71283.50", "0.069"], ["71283.80", "0.000"], ["71283.90", "0.049"], ["71284.20", "0.002"], ["71284.50", "0.000"], ["71284.60", "0.106"], ["71287.20", "0.000"], ["71296.60", "0.000"], ["71299.20", "1.504"], ["71318.60", "0.012"], ["71319.00", "0.510"], ["71319.30", "0.633"], ["71319.70", "0.000"], ["71319.80", "0.781"], ["71320.00", "0.021"], ["71320.10", "0.000"], ["71320.40", "0.001"], ["71320.50", "0.000"], ["71324.60", "0.000"], ["71338.50", "0.000"], ["71342.70", "0.043"], ["71404.70", "0.159"], ["71486.90", "0.222"], ["71629.40", "0.222"], ["71938.90", "0.007"], ["72618.50", "0.000"], ["74802.00", "0.052"], ["75500.00", "23.028"], ["89523.20", "0.000"]]}}
