{"local_ts": 1773384470907, "server_ts": 1773384470688, "data": {"e": "depthUpdate", "E": 1773384470689, "T": 1773384470688, "s": "BTCUSDT", "U": 10101335225802, "u": 10101335232385, "pu": 10101335225705, "b": [["1000.00", "27.342"], ["5000.00", "101.418"], ["20774.50", "0.981"], ["20873.30", "0.450"], ["20875.50", "0.090"], ["21074.50", "0.549"], ["21173.30", "0.207"], ["57020.00", "0.002"], ["67694.70", "0.002"], ["67709.30", "0.004"], ["67709.40", "0.004"], ["69810.30", "0.028"], ["69849.10", "0.006"], ["70561.80", "0.000"], ["70918.10", "0.003"], ["71163.20", "0.077"], ["71178.30", "0.022"], ["71185.30", "0.064"], ["71226.90", "0.002"], ["71227.20", "0.014"], ["71230.30", "0.554"], ["71238.90", "0.079"], ["71243.20", "0.000"], ["71246.30", "0.342"], ["71250.50", "0.003"], ["71251.50", "0.007"], ["71254.70", "0.631"], ["71255.90", "0.005"], ["71256.80", "0.336"], ["71262.20", "0.417"], ["71266.20", "0.254"], ["71267.40", "0.009"], ["71271.20", "0.000"], ["71271.70", "0.177"], ["71273.30", "0.162"]], "a": [["71274.60", "6.397"], ["71275.50", "1.100"], ["71280.30", "0.180"], ["71281.70", "0.000"], ["71285.60", "0.002"], ["71294.90", "1.687"], ["71297.90", "0.248"], ["71304.60", "0.034"], ["71310.20", "0.167"], ["71310.40", "0.276"], ["71320.10", "0.032"], ["71321.70", "0.003"], ["71321.90", "0.002"], ["71322.10", "0.020"], ["71329.30", "2.363"], ["71332.60", "0.055"], ["71362.40", "0.569"], ["71384.50", "0.077"], ["71987.30", "0.000"], ["72148.50", "0.000"], ["72521.80", "1.104"], ["89523.20", "0.000"]]}}
{"local_ts": 1773384471936, "server_ts": 1773384471712, "data": {"e": "depthUpdate", "E": 1773384471713, "T": 1773384471712, "s": "BTCUSDT", "U": 10101335295105, "u": 10101335329618, "pu": 10101335294870, "b": [["5000.00", "101.418"], ["20774.50", "0.936"], ["20966.90", "0.009"], ["20967.00", "0.009"], ["20967.40", "0.009"], ["20967.50", "0.009"], ["20974.50", "0.522"], ["21074.50", "0.342"], ["21167.00", "0.027"], ["21167.40", "0.018"], ["21167.50", "0.009"], ["21170.60", "0.009"], ["21171.80", "0.009"], ["21174.50", "0.792"], ["33000.00", "9.339"], ["67694.70", "0.000"], ["67709.30", "0.002"], ["67709.40", "0.006"], ["67856.40", "0.000"], ["68034.00", "0.009"], ["70237.70", "1.251"], ["70553.90", "0.006"], ["70554.20", "0.006"], ["70554.30", "0.000"], ["70554.70", "0.000"], ["70554.80", "0.000"], ["70555.00", "2.738"], ["70559.10", "0.005"], ["70560.20", "0.007"], ["70561.80", "0.007"], ["70784.00", "0.010"], ["70879.90", "0.002"], ["70887.10", "0.002"], ["70890.60", "0.002"], ["70896.20", "0.002"], ["70897.20", "0.005"], ["70915.20", "0.002"], ["70965.90", "2.329"], ["70966.10", "0.330"], ["70992.50", "1.508"], ["70998.10", "1.543"], ["71002.50", "0.002"], ["71008.20", "0.272"], ["71011.70", "0.007"], ["71032.70", "0.001"], ["71064.70", "0.040"], ["71068.40", "0.003"], ["71069.90", "0.000"], ["71071.90", "0.006"], ["71081.70", "0.040"], ["71082.30", "0.042"], ["71082.70", "0.000"], ["71083.00", "0.166"], ["71083.20", "0.000"], ["71083.30", "0.028"], ["71084.30", "0.040"], ["71084.70", "0.040"], ["71085.70", "0.058"], ["71090.70", "0.044"], ["71096.30", "0.000"], ["71100.80", "0.000"], ["71104.60", "0.168"], ["71105.40", "0.538"], ["71108.70", "0.081"], ["71109.60", "0.002"], ["71112.70", "0.078"], ["71115.00", "0.114"], ["71117.70", "0.078"], ["71117.90", "2.349"], ["71120.40", "0.078"], ["71121.70", "0.040"], ["71129.20", "0.204"], ["71129.30", "0.400"], ["71130.00", "16.007"], ["71132.10", "0.506"], ["71133.90", "0.184"], ["71139.60", "0.002"], ["71140.30", "0.078"], ["71141.00", "0.027"], ["71141.70", "0.003"], ["71143.80", "0.178"], ["71145.60", "0.396"], ["71148.70", "0.078"], ["71149.10", "0.074"], ["71149.20", "0.001"], ["71153.10", "0.002"], ["71153.60", "0.393"], ["71155.90", "0.034"], ["71156.10", "0.000"], ["71156.60", "0.080"], ["71157.00", "0.002"], ["71158.30", "0.048"], ["71162.70", "0.103"], ["71164.20", "0.440"], ["71166.20", "0.000"], ["71167.30", "0.004"], ["71167.70", "0.042"], ["71167.80", "0.124"], ["71168.40", "0.122"], ["71169.90", "0.005"], ["71171.30", "0.074"], ["71172.60", "0.002"], ["71173.00", "0.022"], ["71173.20", "0.007"], ["71174.20", "0.088"], ["71174.50", "0.197"], ["71174.70", "1.240"], ["71174.80", "0.321"], ["71176.90", "0.343"], ["71177.30", "0.019"], ["71178.80", "1.380"], ["71179.30", "0.000"], ["71179.60", "6.473"], ["71179.70", "0.017"], ["71179.80", "0.000"], ["71180.00", "0.009"], ["71180.10", "2.000"], ["71180.20", "0.074"], ["71180.30", "0.229"], ["71180.50", "0.325"], ["71181.00", "0.008"], ["71181.40", "0.000"], ["71182.10", "2.448"], ["71182.80", "0.235"], ["71184.10", "0.323"], ["71184.80", "0.003"], ["71186.00", "0.215"], ["71191.50", "0.046"], ["71193.00", "0.049"], ["71193.90", "0.046"], ["71194.50", "0.046"], ["71196.80", "0.132"], ["71197.10", "0.046"], ["71197.60", "0.003"], ["71200.80", "0.005"], ["71201.20", "0.552"], ["71201.80", "0.386"], ["71203.60", "0.118"], ["71204.90", "0.000"], ["71206.30", "0.056"], ["71206.40", "0.775"], ["71206.50", "0.104"], ["71206.60", "0.002"], ["71206.70", "0.002"], ["71206.90", "0.000"], ["71207.10", "0.001"], ["71207.20", "0.525"], ["71209.00", "0.000"], ["71209.10", "0.023"], ["71211.00", "0.002"], ["71211.10", "0.179"], ["71211.30", "0.002"], ["71212.70", "0.001"], ["71213.30", "0.051"], ["71214.50", "0.000"], ["71215.40", "0.421"], ["71215.50", "0.000"], ["71216.60", "0.327"], ["71216.80", "0.015"], ["71217.10", "0.001"], ["71217.80", "0.130"], ["71218.10", "0.004"], ["71218.20", "2.948"], ["71218.40", "0.210"], ["71219.20", "0.087"], ["71219.80", "0.002"], ["71219.90", "0.006"], ["71220.30", "0.100"], ["71220.40", "0.029"], ["71220.80", "0.003"], ["71221.00", "0.001"], ["71222.10", "0.187"], ["71222.40", "0.030"], ["71223.50", "0.840"], ["71223.80", "0.323"], ["71223.90", "0.067"], ["71224.30", "0.052"], ["71224.70", "0.000"], ["71224.90", "0.804"], ["71225.00", "0.816"], ["71225.40", "1.108"], ["71225.60", "0.574"], ["71225.70", "0.000"], ["71225.80", "0.058"], ["71226.50", "0.002"], ["71226.60", "0.004"], ["71226.70", "0.151"], ["71226.80", "0.076"], ["71227.00", "0.304"], ["71227.10", "0.000"], ["71227.50", "0.000"], ["71227.60", "0.002"], ["71228.20", "0.015"], ["71228.70", "0.000"], ["71229.70", "0.000"], ["71229.80", "0.006"], ["71230.00", "0.006"], ["71230.50", "0.615"], ["71231.10", "0.123"], ["71231.40", "0.248"], ["71231.70", "0.063"], ["71231.90", "0.006"], ["71232.50", "0.000"], ["71232.80", "0.182"], ["71233.00", "0.042"], ["71233.60", "0.002"], ["71234.00", "0.004"], ["71234.20", "0.002"], ["71234.30", "0.020"], ["71234.70", "0.000"], ["71234.90", "0.302"], ["71235.00", "0.336"], ["71235.30", "0.000"], ["71235.40", "0.012"], ["71235.50", "0.369"], ["71235.70", "0.339"], ["71236.10", "0.000"], ["71236.20", "0.508"], ["71236.30", "0.148"], ["71236.50", "0.003"], ["71236.60", "0.089"], ["71236.80", "0.024"], ["71236.90", "0.124"], ["71237.00", "1.194"], ["71237.30", "0.006"], ["71237.40", "0.007"], ["71237.50", "0.002"], ["71237.60", "0.003"], ["71237.70", "0.017"], ["71237.80", "0.004"], ["71238.00", "0.002"], ["71238.20", "0.338"], ["71238.30", "0.144"], ["71238.40", "0.000"], ["71238.90", "0.011"], ["71239.00", "0.091"], ["71239.60", "0.013"], ["71239.70", "0.027"], ["71240.10", "0.509"], ["71240.20", "0.055"], ["71240.30", "0.004"], ["71240.40", "0.009"], ["71240.70", "0.003"], ["71240.80", "0.336"], ["71241.00", "0.012"], ["71241.10", "0.008"], ["71241.20", "0.111"], ["71241.30", "0.356"], ["71241.70", "0.000"], ["71241.80", "0.328"], ["71241.90", "0.167"], ["71242.40", "0.063"], ["71242.50", "0.004"], ["71242.60", "0.081"], ["71242.70", "0.007"], ["71242.80", "0.006"], ["71243.00", "0.002"], ["71243.10", "0.053"], ["71243.20", "0.505"], ["71243.40", "0.007"], ["71243.50", "0.710"], ["71243.60", "2.323"], ["71243.80", "0.002"], ["71243.90", "0.007"], ["71244.10", "0.005"], ["71244.20", "0.004"], ["71244.40", "0.000"], ["71244.50", "0.072"], ["71244.60", "0.047"], ["71244.70", "0.007"], ["71244.80", "0.009"], ["71244.90", "0.033"], ["71245.00", "0.639"], ["71245.10", "0.003"], ["71245.20", "0.529"], ["71245.30", "0.040"], ["71245.50", "0.072"], ["71245.60", "0.008"], ["71245.80", "0.506"], ["71245.90", "0.002"], ["71246.00", "0.008"], ["71246.10", "0.003"], ["71246.20", "0.000"], ["71246.50", "0.070"], ["71246.60", "0.004"], ["71246.90", "0.000"], ["71247.00", "0.006"], ["71247.10", "1.330"], ["71247.20", "0.033"], ["71247.40", "0.145"], ["71247.90", "0.035"], ["71248.00", "0.510"], ["71248.10", "0.007"], ["71248.30", "0.000"], ["71248.60", "0.035"], ["71248.70", "0.002"], ["71248.80", "0.006"], ["71249.00", "0.000"], ["71249.20", "0.006"], ["71249.30", "0.000"], ["71249.40", "0.001"], ["71249.50", "0.011"], ["71249.60", "0.003"], ["71249.70", "0.002"], ["71249.90", "0.000"], ["71250.00", "0.007"], ["71250.10", "0.040"], ["71250.20", "0.003"], ["71250.30", "0.006"], ["71250.50", "0.863"], ["71250.70", "0.306"], ["71250.90", "0.152"], ["71251.10", "0.001"], ["71251.40", "0.002"], ["71251.50", "0.008"], ["71251.60", "0.795"], ["71251.80", "0.000"], ["71251.90", "0.002"], ["71252.10", "0.006"], ["71252.20", "0.002"], ["71252.30", "0.002"], ["71252.40", "0.000"], ["71252.50", "0.007"], ["71252.60", "0.066"], ["71252.70", "0.048"], ["71252.80", "0.001"], ["71253.00", "0.009"], ["71253.10", "0.032"], ["71253.20", "1.588"], ["71253.30", "0.881"], ["71253.40", "0.344"], ["71253.70", "0.002"], ["71253.80", "0.153"], ["71254.10", "0.000"], ["71254.20", "0.000"], ["71254.30", "0.007"], ["71254.40", "0.321"], ["71254.90", "0.216"], ["71255.00", "1.280"], ["71255.20", "0.108"], ["71255.30", "0.005"], ["71255.50", "0.206"], ["71255.60", "0.010"], ["71255.70", "0.007"], ["71255.80", "0.005"], ["71255.90", "0.005"], ["71256.00", "0.002"], ["71256.40", "0.030"], ["71256.50", "0.005"], ["71256.60", "0.005"], ["71257.20", "0.002"], ["71257.30", "0.012"], ["71257.60", "0.005"], ["71257.90", "0.004"], ["71258.00", "0.009"], ["71258.10", "0.019"], ["71258.20", "0.003"], ["71258.30", "0.429"], ["71258.40", "0.000"], ["71258.50", "0.003"], ["71258.60", "0.428"], ["71258.70", "0.214"], ["71258.80", "0.332"], ["71258.90", "0.002"], ["71259.00", "0.002"], ["71259.10", "0.032"], ["71259.20", "0.008"], ["71259.50", "0.005"], ["71259.60", "0.004"], ["71259.70", "0.003"], ["71260.00", "0.013"], ["71260.10", "0.000"], ["71260.20", "0.002"], ["71260.40", "0.006"], ["71260.50", "0.068"], ["71260.70", "0.000"], ["71261.00", "0.007"], ["71261.30", "0.002"], ["71261.40", "0.002"], ["71261.50", "0.003"], ["71261.60", "0.005"], ["71261.80", "0.004"], ["71262.00", "0.159"], ["71262.20", "0.061"], ["71262.30", "0.150"], ["71262.40", "0.007"], ["71262.50", "0.003"], ["71262.70", "0.004"], ["71262.80", "0.001"], ["71262.90", "0.000"], ["71263.00", "0.050"], ["71263.50", "0.004"], ["71263.80", "0.002"], ["71263.90", "0.005"], ["71264.20", "0.001"], ["71264.30", "0.000"], ["71264.40", "0.000"], ["71264.50", "0.005"], ["71264.60", "0.005"], ["71264.70", "0.000"], ["71265.00", "0.005"], ["71265.20", "0.000"], ["71265.40", "0.027"], ["71265.50", "0.038"], ["71265.60", "0.002"], ["71265.70", "0.000"], ["71265.80", "0.038"], ["71265.90", "0.028"], ["71266.20", "0.031"], ["71266.40", "0.000"], ["71266.60", "0.000"], ["71266.70", "0.000"], ["71266.80", "0.000"], ["71266.90", "0.000"], ["71267.00", "0.000"], ["71267.10", "0.000"], ["71267.20", "0.000"], ["71267.30", "0.000"], ["71267.40", "0.000"], ["71267.50", "0.000"], ["71267.70", "0.000"], ["71267.80", "0.000"], ["71267.90", "0.000"], ["71268.00", "0.000"], ["71268.20", "0.000"], ["71268.40", "0.000"], ["71268.50", "0.000"], ["71268.90", "0.000"], ["71269.00", "0.000"], ["71269.10", "0.000"], ["71269.30", "0.000"], ["71269.50", "0.000"], ["71269.60", "0.000"], ["71269.70", "0.000"], ["71269.90", "0.000"], ["71270.00", "0.000"], ["71270.10", "0.000"], ["71270.20", "0.000"], ["71270.30", "0.000"], ["71270.40", "0.000"], ["71270.50", "0.000"], ["71270.60", "0.000"], ["71270.70", "0.000"], ["71270.80", "0.000"], ["71271.10", "0.000"], ["71271.40", "0.000"], ["71271.50", "0.000"], ["71271.60", "0.000"], ["71271.70", "0.000"], ["71271.80", "0.000"], ["71272.00", "0.000"], ["71272.10", "0.000"], ["71272.20", "0.000"], ["71272.40", "0.000"], ["71272.50", "0.000"], ["71272.70", "0.000"], ["71272.90", "0.000"], ["71273.00", "0.000"], ["71273.20", "0.000"], ["71273.30", "0.000"], ["71273.40", "0.000"], ["71273.50", "0.000"], ["71273.80", "0.000"], ["71274.00", "0.000"], ["71274.10", "0.000"], ["71274.40", "0.000"], ["71274.50", "0.000"]], "a": [["71266.60", "10.555"], ["71266.70", "8.023"], ["71266.80", "0.438"], ["71266.90", "2.926"], ["71267.00", "3.050"], ["71267.10", "0.124"], ["71267.20", "0.110"], ["71267.30", "0.014"], ["71267.40", "1.100"], ["71267.50", "0.000"], ["71267.60", "0.238"], ["71267.70", "0.006"], ["71267.80", "0.046"], ["71267.90", "0.000"], ["71268.00", "0.019"], ["71268.10", "0.016"], ["71268.30", "0.014"], ["71268.50", "0.014"], ["71268.60", "0.014"], ["71268.90", "0.007"], ["71269.00", "0.290"], ["71269.10", "0.018"], ["71269.20", "0.016"], ["71269.40", "0.014"], ["71269.50", "0.647"], ["71269.60", "0.014"], ["71269.70", "0.014"], ["71269.80", "0.014"], ["71270.00", "0.016"], ["71270.10", "0.376"], ["71270.20", "0.016"], ["71270.30", "0.014"], ["71270.40", "0.014"], ["71270.50", "0.002"], ["71270.60", "4.396"], ["71270.70", "0.032"], ["71270.80", "0.000"], ["71270.90", "0.014"], ["71271.10", "0.004"], ["71271.20", "0.020"], ["71271.40", "0.006"], ["71271.50", "0.344"], ["71271.60", "0.001"], ["71271.70", "0.000"], ["71271.80", "0.009"], ["71271.90", "0.000"], ["71272.00", "0.003"], ["71272.10", "0.000"], ["71272.20", "0.000"], ["71272.50", "0.003"], ["71272.60", "0.054"], ["71272.80", "0.002"], ["71272.90", "1.867"], ["71273.00", "0.101"], ["71273.10", "0.005"], ["71273.20", "0.003"], ["71273.30", "0.003"], ["71273.40", "0.006"], ["71273.50", "0.000"], ["71273.60", "0.001"], ["71273.70", "0.201"], ["71273.90", "0.004"], ["71274.00", "0.006"], ["71274.10", "0.080"], ["71274.20", "0.000"], ["71274.30", "0.001"], ["71274.40", "0.000"], ["71274.50", "0.003"], ["71274.60", "0.037"], ["71275.00", "0.002"], ["71275.20", "0.002"], ["71275.30", "0.000"], ["71275.40", "0.003"], ["71275.50", "0.000"], ["71275.60", "1.623"], ["71275.70", "0.002"], ["71275.80", "0.019"], ["71275.90", "0.000"], ["71276.40", "0.145"], ["71276.50", "0.046"], ["71276.60", "0.031"], ["71276.80", "0.004"], ["71277.20", "0.007"], ["71277.30", "0.003"], ["71277.50", "0.045"], ["71277.60", "0.234"], ["71277.70", "0.228"], ["71277.80", "0.002"], ["71277.90", "0.004"], ["71278.00", "0.027"], ["71278.30", "0.071"], ["71278.40", "0.071"], ["71278.50", "0.053"], ["71278.70", "0.053"], ["71278.90", "0.033"], ["71279.00", "0.000"], ["71279.10", "0.221"], ["71279.20", "0.258"], ["71279.30", "0.021"], ["71279.70", "0.086"], ["71279.90", "0.035"], ["71280.00", "0.072"], ["71280.10", "0.003"], ["71280.30", "0.079"], ["71280.50", "0.040"], ["71280.60", "0.011"], ["71280.70", "0.151"], ["71280.80", "0.011"], ["71280.90", "0.713"], ["71281.00", "0.009"], ["71281.20", "0.015"], ["71281.30", "0.002"], ["71281.40", "0.002"], ["71281.60", "0.000"], ["71281.70", "0.017"], ["71281.80", "0.152"], ["71281.90", "0.000"], ["71282.00", "0.022"], ["71282.10", "0.002"], ["71282.20", "0.122"], ["71282.70", "0.006"], ["71282.80", "0.544"], ["71282.90", "0.098"], ["71283.00", "0.003"], ["71283.10", "0.002"], ["71283.20", "0.001"], ["71283.30", "0.006"], ["71283.40", "0.001"], ["71283.50", "0.053"], ["71283.70", "0.004"], ["71283.90", "0.022"], ["71284.00", "0.003"], ["71284.10", "0.000"], ["71284.20", "0.000"], ["71284.30", "0.278"], ["71284.40", "0.005"], ["71284.50", "0.004"], ["71284.70", "0.002"], ["71284.80", "0.002"], ["71285.00", "0.126"], ["71285.10", "0.000"], ["71285.20", "0.001"], ["71285.30", "0.011"], ["71285.40", "0.079"], ["71285.50", "0.011"], ["71285.70", "0.008"], ["71285.90", "0.005"], ["71286.10", "0.002"], ["71286.20", "0.008"], ["71286.30", "0.004"], ["71286.50", "0.005"], ["71286.60", "0.085"], ["71286.70", "0.001"], ["71286.80", "0.015"], ["71286.90", "0.215"], ["71287.20", "0.249"], ["71287.30", "0.010"], ["71287.40", "0.021"], ["71287.80", "0.508"], ["71287.90", "0.372"], ["71288.00", "0.113"], ["71288.10", "0.523"], ["71288.30", "0.056"], ["71288.40", "0.005"], ["71288.50", "0.003"], ["71288.60", "0.061"], ["71288.70", "0.120"], ["71288.80", "0.508"], ["71288.90", "0.374"], ["71289.00", "1.125"], ["71289.10", "0.262"], ["71289.20", "0.128"], ["71289.30", "0.062"], ["71289.40", "0.157"], ["71289.60", "0.036"], ["71289.70", "0.377"], ["71289.90", "0.002"], ["71290.30", "0.008"], ["71290.40", "0.040"], ["71290.50", "0.005"], ["71291.00", "0.006"], ["71291.40", "0.270"], ["71291.50", "0.005"], ["71291.70", "0.004"], ["71291.80", "0.003"], ["71292.00", "0.011"], ["71292.10", "0.003"], ["71292.50", "0.002"], ["71292.60", "0.007"], ["71292.70", "0.055"], ["71292.90", "0.005"], ["71293.20", "0.010"], ["71293.30", "0.002"], ["71293.40", "0.004"], ["71293.60", "0.008"], ["71293.70", "0.000"], ["71293.80", "0.002"], ["71294.10", "0.017"], ["71294.30", "0.037"], ["71294.40", "0.003"], ["71294.50", "0.007"], ["71294.60", "0.002"], ["71294.70", "0.893"], ["71294.80", "0.002"], ["71294.90", "1.610"], ["71295.00", "0.464"], ["71295.10", "0.002"], ["71295.20", "0.086"], ["71295.30", "0.017"], ["71295.60", "0.005"], ["71295.70", "0.004"], ["71295.80", "0.001"], ["71295.90", "0.002"], ["71296.00", "0.002"], ["71296.40", "0.008"], ["71297.10", "0.000"], ["71297.20", "0.002"], ["71297.60", "0.339"], ["71297.80", "0.009"], ["71297.90", "0.003"], ["71298.00", "0.008"], ["71298.10", "0.330"], ["71298.20", "0.006"], ["71298.50", "0.015"], ["71298.60", "0.013"], ["71298.70", "0.020"], ["71298.80", "0.001"], ["71299.10", "0.077"], ["71299.20", "0.596"], ["71299.30", "0.000"], ["71299.50", "0.012"], ["71299.60", "1.080"], ["71299.80", "0.009"], ["71299.90", "0.506"], ["71300.00", "3.263"], ["71300.20", "0.006"], ["71300.60", "0.004"], ["71300.70", "0.003"], ["71300.90", "0.003"], ["71301.10", "0.002"], ["71301.20", "0.002"], ["71301.30", "0.004"], ["71301.40", "0.369"], ["71302.00", "0.394"], ["71302.10", "0.364"], ["71302.70", "0.021"], ["71302.80", "0.002"], ["71302.90", "0.001"], ["71303.20", "0.002"], ["71303.30", "0.041"], ["71303.40", "0.018"], ["71303.50", "0.093"], ["71303.70", "0.317"], ["71304.10", "0.001"], ["71304.20", "0.018"], ["71304.40", "0.282"], ["71305.10", "0.000"], ["71305.20", "0.001"], ["71305.40", "0.000"], ["71305.50", "0.005"], ["71305.70", "0.070"], ["71305.90", "0.007"], ["71306.20", "0.917"], ["71306.30", "0.296"], ["71306.70", "1.075"], ["71306.80", "0.018"], ["71307.40", "0.023"], ["71307.50", "0.002"], ["71307.60", "1.057"], ["71307.70", "0.508"], ["71307.90", "0.289"], ["71308.10", "0.201"], ["71308.20", "0.004"], ["71308.70", "0.000"], ["71309.30", "0.339"], ["71309.40", "0.977"], ["71309.70", "0.023"], ["71310.00", "0.226"], ["71310.20", "0.102"], ["71310.30", "0.846"], ["71310.80", "0.004"], ["71311.10", "0.145"], ["71311.20", "0.002"], ["71311.50", "0.020"], ["71311.70", "0.300"], ["71312.40", "0.001"], ["71312.80", "1.749"], ["71312.90", "0.060"], ["71313.00", "0.004"], ["71313.50", "0.003"], ["71313.60", "0.034"], ["71313.80", "0.001"], ["71314.20", "0.144"], ["71315.30", "0.004"], ["71315.50", "1.387"], ["71316.00", "0.210"], ["71317.00", "0.132"], ["71317.30", "0.305"], ["71317.40", "0.116"], ["71317.60", "0.181"], ["71318.10", "0.007"], ["71318.40", "0.030"], ["71318.60", "0.002"], ["71318.80", "0.075"], ["71319.30", "0.110"], ["71319.70", "0.021"], ["71319.80", "0.299"], ["71320.40", "0.021"], ["71320.60", "0.298"], ["71320.70", "0.003"], ["71320.90", "0.003"], ["71321.00", "0.293"], ["71321.10", "0.427"], ["71321.20", "0.002"], ["71321.30", "1.998"], ["71321.40", "7.725"], ["71321.60", "0.005"], ["71321.80", "0.002"], ["71322.00", "0.077"], ["71322.10", "0.018"], ["71323.80", "0.364"], ["71324.30", "0.005"], ["71324.40", "0.002"], ["71325.20", "0.000"], ["71326.00", "0.002"], ["71326.40", "0.000"], ["71326.90", "0.105"], ["71327.00", "0.003"], ["71327.10", "0.002"], ["71327.70", "0.576"], ["71328.80", "0.012"], ["71329.40", "0.004"], ["71329.90", "0.003"], ["71330.00", "0.712"], ["71330.30", "0.050"], ["71330.90", "0.278"], ["71332.60", "0.005"], ["71333.30", "0.336"], ["71334.20", "3.281"], ["71334.60", "0.000"], ["71334.90", "0.081"], ["71335.00", "0.081"], ["71335.20", "0.002"], ["71337.10", "0.349"], ["71337.20", "0.007"], ["71338.00", "0.078"], ["71338.40", "0.219"], ["71338.70", "0.004"], ["71338.80", "0.242"], ["71338.90", "0.136"], ["71339.00", "0.000"], ["71339.60", "0.047"], ["71339.80", "0.310"], ["71340.10", "0.268"], ["71340.50", "0.177"], ["71340.60", "0.519"], ["71341.00", "0.000"], ["71341.10", "0.019"], ["71341.20", "0.613"], ["71341.80", "0.005"], ["71342.50", "0.049"], ["71342.60", "0.002"], ["71342.80", "0.065"], ["71343.40", "0.049"], ["71343.90", "0.508"], ["71345.90", "0.120"], ["71347.50", "6.723"], ["71348.10", "0.207"], ["71349.90", "0.116"], ["71351.20", "0.000"], ["71352.50", "0.168"], ["71353.40", "1.241"], ["71353.90", "0.000"], ["71354.00", "0.082"], ["71354.10", "1.051"], ["71354.80", "0.001"], ["71356.80", "0.558"], ["71357.00", "0.008"], ["71359.20", "1.664"], ["71360.10", "0.276"], ["71361.10", "0.007"], ["71361.40", "0.000"], ["71362.30", "6.445"], ["71365.50", "1.621"], ["71366.50", "0.208"], ["71366.90", "0.174"], ["71367.30", "0.217"], ["71367.40", "0.592"], ["71367.50", "0.014"], ["71369.00", "0.346"], ["71369.10", "0.355"], ["71369.90", "0.778"], ["71370.30", "0.040"], ["71379.90", "0.043"], ["71381.30", "10.017"], ["71382.00", "0.043"], ["71384.10", "0.000"], ["71384.70", "0.044"], ["71386.90", "0.000"], ["71393.20", "0.344"], ["71394.90", "0.029"], ["71395.00", "0.287"], ["71396.20", "0.004"], ["71402.10", "0.000"], ["71402.40", "1.616"], ["71406.10", "0.000"], ["71409.20", "0.000"], ["71409.60", "8.564"], ["71413.60", "0.006"], ["71417.30", "0.009"], ["71421.20", "0.018"], ["71422.40", "0.000"], ["71423.70", "0.000"], ["71427.00", "0.099"], ["71427.40", "0.705"], ["71427.50", "0.453"], ["71427.80", "0.075"], ["71427.90", "12.140"], ["71428.80", "0.040"], ["71429.20", "0.290"], ["71431.50", "0.002"], ["71435.10", "0.040"], ["71435.20", "0.040"], ["71435.60", "0.002"], ["71435.80", "1.508"], ["71438.00", "1.981"], ["71442.30", "0.010"], ["71442.80", "2.064"], ["71445.70", "0.205"], ["71445.90", "0.000"], ["71446.00", "0.600"], ["71446.40", "2.982"], ["71446.50", "0.000"], ["71447.20", "0.001"], ["71447.80", "0.000"], ["71448.90", "0.000"], ["71456.10", "0.000"], ["71457.30", "0.015"], ["71461.50", "0.007"], ["71463.10", "0.014"], ["71487.10", "0.000"], ["71501.50", "0.000"], ["71510.00", "0.000"], ["71513.70", "0.000"], ["71536.00", "0.138"], ["71552.70", "0.000"], ["71552.80", "0.000"], ["71556.80", "0.000"], ["71559.70", "0.002"], ["71576.30", "0.000"], ["71577.20", "0.002"], ["71627.20", "0.003"], ["71688.10", "0.000"], ["71979.80", "0.000"], ["71980.20", "0.000"], ["71980.30", "0.004"], ["71983.40", "0.000"], ["71984.60", "0.000"], ["71987.30", "0.000"], ["72032.20", "0.762"], ["72215.10", "0.017"], ["72267.10", "0.695"], ["72267.50", "1.532"], ["72267.60", "1.249"], ["72267.80", "0.014"], ["72273.10", "0.692"], ["72275.60", "0.842"], ["72278.50", "0.002"], ["72279.20", "0.006"], ["72280.60", "0.002"], ["72280.80", "0.000"], ["72281.00", "0.092"], ["72282.60", "0.003"], ["72698.80", "0.008"], ["75970.10", "0.000"], ["89523.20", "0.000"], ["100000.00", "15.554"]]}}
{"local_ts": 1773384472950, "server_ts": 1773384472732, "data": {"e": "depthUpdate", "E": 1773384472733, "T": 1773384472732, "s": "BTCUSDT", "U": 10101335433655, "u": 10101335444553, "pu": 10101335433452, "b": [["1000.00", "27.492"], ["5000.00", "101.418"], ["20866.20", "0.423"], ["20974.50", "0.099"], ["21066.20", "0.594"], ["21174.50", "0.198"], ["67674.60", "0.000"], ["67687.10", "0.002"], ["69840.90", "0.022"], ["70254.20", "0.283"], ["70553.50", "0.000"], ["70909.90", "0.000"], ["71068.40", "0.000"], ["71149.80", "0.227"], ["71195.10", "0.002"], ["71216.10", "0.208"], ["71218.40", "0.005"], ["71218.60", "0.000"], ["71218.80", "0.205"], ["71219.00", "0.002"], ["71220.80", "0.006"], ["71225.70", "0.000"], ["71229.50", "0.004"], ["71230.60", "0.184"], ["71234.80", "0.012"], ["71235.50", "0.705"], ["71246.30", "0.513"], ["71256.60", "0.003"], ["71259.40", "0.006"], ["71259.60", "0.320"], ["71263.00", "0.003"], ["71266.20", "0.241"]], "a": [["71266.30", "6.481"], ["71271.20", "0.074"], ["71271.50", "0.214"], ["71273.20", "0.001"], ["71294.40", "0.185"], ["71295.50", "0.046"], ["71301.90", "0.070"], ["71306.10", "0.000"], ["71307.00", "0.606"], ["71307.20", "0.009"], ["71314.10", "0.004"], ["71314.30", "0.003"], ["71321.00", "0.295"], ["71386.20", "0.045"], ["71416.90", "0.016"], ["71493.30", "0.324"], ["71978.90", "0.000"], ["71979.00", "1.224"], ["72594.60", "0.688"], ["75970.10", "0.002"], ["89523.20", "0.000"]]}}
{"local_ts": 1773384473974, "server_ts": 1773384473755, "data": {"e": "depthUpdate", "E": 1773384473757, "T": 1773384473755, "s": "BTCUSDT", "U": 10101335527968, "u": 10101335535073, "pu": 10101335527754, "b": [["5000.00", "101.418"], ["20766.20", "0.288"], ["20866.20", "0.612"], ["20966.20", "0.333"], ["21066.20", "1.467"], ["21166.20", "0.000"], ["33000.00", "9.343"], ["70232.80", "0.853"], ["70553.50", "0.708"], ["71097.90", "0.001"], ["71101.60", "0.071"], ["71104.90", "0.004"], ["71112.00", "0.047"], ["71142.00", "0.103"], ["71143.10", "0.180"], ["71149.10", "0.077"], ["71216.30", "0.028"], ["71216.60", "0.323"], ["71218.80", "0.203"], ["71219.10", "0.003"], ["71226.00", "0.059"], ["71231.90", "0.006"], ["71239.90", "0.080"], ["71248.30", "0.101"], ["71248.80", "0.403"], ["71251.90", "0.361"], ["71252.40", "0.697"], ["71254.80", "0.000"], ["71255.50", "0.004"], ["71256.40", "0.030"], ["71256.70", "0.003"], ["71257.30", "0.511"], ["71259.40", "0.028"], ["71259.60", "0.004"], ["71264.70", "0.000"], ["71266.20", "2.222"]], "a": [["71266.30", "2.744"], ["71266.40", "0.001"], ["71266.50", "0.002"], ["71266.60", "0.002"], ["71266.70", "0.004"], ["71272.60", "0.000"], ["71275.00", "0.005"], ["71275.10", "0.004"], ["71276.70", "0.054"], ["71285.90", "0.116"], ["71287.00", "0.003"], ["71292.00", "0.009"], ["71294.20", "0.184"], ["71294.40", "0.003"], ["71294.80", "0.598"], ["71295.50", "0.003"], ["71296.00", "0.042"], ["71298.40", "0.900"], ["71304.20", "0.020"], ["71307.00", "0.585"], ["71307.20", "0.030"], ["71314.00", "0.007"], ["71314.50", "0.017"], ["71979.00", "1.224"], ["74835.10", "0.000"], ["89523.20", "0.000"]]}}
{"local_ts": 1773384474995, "server_ts": 1773384474772, "data": {"e": "depthUpdate", "E": 1773384474777, "T": 1773384474772, "s": "BTCUSDT", "U": 10101335602603, "u": 10101335609668, "pu": 10101335602221, "b": [["1000.00", "27.342"], ["5000.00", "101.418"], ["20766.20", "0.747"], ["20866.20", "0.153"], ["20966.20", "1.557"], ["21066.20", "0.090"], ["21166.20", "0.153"], ["70235.80", "0.000"], ["70240.20", "0.000"], ["70553.50", "1.558"], ["70962.40", "0.043"], ["71104.90", "0.002"], ["71106.20", "0.004"], ["71112.00", "0.045"], ["71113.90", "0.002"], ["71127.10", "0.190"], ["71145.70", "0.077"], ["71215.00", "0.000"], ["71215.10", "0.000"], ["71219.60", "0.115"], ["71219.70", "1.009"], ["71250.80", "1.356"], ["71251.20", "0.104"], ["71251.50", "0.009"], ["71251.90", "0.106"], ["71252.30", "0.000"], ["71258.00", "0.079"], ["71258.40", "0.061"], ["71259.10", "0.089"], ["71259.90", "0.004"], ["71262.60", "0.012"], ["71264.90", "0.002"]], "a": [["71271.20", "0.002"], ["71274.80", "0.000"], ["71275.20", "0.061"], ["71279.40", "0.045"], ["71282.00", "0.006"], ["71286.70", "0.004"], ["71287.70", "0.530"], ["71287.90", "0.638"], ["71288.70", "0.256"], ["71292.90", "0.005"], ["71293.00", "0.000"], ["71293.60", "0.017"], ["71293.70", "0.254"], ["71294.80", "0.577"], ["71295.50", "0.045"], ["71301.40", "0.369"], ["71307.00", "0.606"], ["71307.20", "0.009"], ["71417.80", "0.105"], ["71979.00", "1.918"], ["74839.50", "0.052"], ["74847.70", "0.000"], ["89523.20", "0.000"]]}}
{"local_ts": 1773384476022, "server_ts": 1773384475799, "data": {"e": "depthUpdate", "E": 1773384475801, "T": 1773384475799, "s": "BTCUSDT", "U": 10101335664325, "u": 10101335668743, "pu": 10101335664176, "b": [["1000.00", "27.342"], ["5000.00", "101.418"], ["20766.20", "0.027"], ["20866.20", "1.548"], ["20966.20", "0.225"], ["21066.20", "0.018"], ["21166.20", "0.882"], ["69840.90", "0.048"], ["70553.50", "1.558"], ["70589.20", "1.003"], ["70909.90", "0.000"], ["71100.80", "0.000"], ["71105.20", "0.002"], ["71106.20", "0.002"], ["71112.40", "0.551"], ["71113.90", "0.000"], ["71163.30", "0.000"], ["71169.50", "0.002"], ["71218.40", "0.189"], ["71223.70", "0.004"], ["71225.70", "0.021"], ["71235.20", "0.022"], ["71249.00", "0.849"], ["71255.70", "0.004"], ["71265.50", "0.004"]], "a": [["71295.50", "0.088"], ["71312.80", "0.003"], ["71314.00", "0.011"], ["71314.10", "0.002"], ["71332.90", "0.031"], ["71334.10", "0.690"], ["71334.20", "0.005"], ["71367.00", "0.144"], ["71369.40", "0.002"], ["71427.90", "0.000"], ["71493.10", "0.008"], ["71978.90", "0.000"], ["71979.00", "1.918"], ["74117.00", "0.645"], ["74838.20", "0.002"], ["89523.20", "0.000"]]}}
{"local_ts": 1773384477086, "server_ts": 1773384476615, "data": {"e": "depthUpdate", "E": 1773384476617, "T": 1773384476615, "s": "BTCUSDT", "U": 10101335710456, "u": 10101335715807, "pu": 10101335710302, "b": [["1000.00", "27.342"], ["5000.00", "101.418"], ["20766.20", "1.026"], ["20866.20", "0.774"], ["21066.20", "0.630"], ["21166.20", "0.270"], ["33000.00", "9.343"], ["57013.00", "0.000"], ["67678.50", "0.003"], ["68415.60", "0.006"], ["70275.60", "1.562"], ["70553.50", "1.558"], ["70909.90", "0.000"], ["70988.80", "0.002"], ["70989.00", "0.388"], ["71218.50", "0.125"], ["71225.70", "0.000"], ["71239.50", "0.007"], ["71242.70", "0.070"], ["71255.10", "0.542"], ["71255.70", "0.000"], ["71255.80", "0.009"], ["71265.60", "0.002"]], "a": [["71266.30", "2.046"], ["71266.40", "0.005"], ["71291.70", "0.004"], ["71293.10", "0.504"], ["71298.40", "0.765"], ["71305.50", "0.175"], ["71979.00", "1.918"], ["74849.70", "0.002"], ["89523.20", "0.000"]]}}
{"local_ts": 1773384478164, "server_ts": 1773384477945, "data": {"e": "depthUpdate", "E": 1773384477947, "T": 1773384477945, "s": "BTCUSDT", "U": 10101335777403, "u": 10101335781578, "pu": 10101335777265, "b": [["5000.00", "101.418"], ["20766.20", "0.576"], ["20966.20", "0.729"], ["21066.20", "0.171"], ["21166.20", "1.224"], ["64139.60", "0.003"], ["67691.40", "0.000"], ["70232.80", "4.692"], ["70553.50", "1.558"], ["70589.20", "1.709"], ["70990.50", "0.301"], ["70991.10", "0.019"], ["71225.70", "0.000"], ["71226.00", "0.243"], ["71234.30", "1.899"], ["71252.80", "0.141"], ["71253.60", "0.133"], ["71266.20", "3.660"]], "a": [["71266.30", "2.278"], ["71281.50", "0.140"], ["71283.30", "0.012"], ["71298.40", "0.765"], ["71307.50", "0.021"], ["71313.30", "0.004"], ["71313.50", "0.005"], ["71316.50", "0.254"], ["71493.10", "0.002"], ["71978.90", "0.006"], ["71979.00", "1.918"], ["72299.70", "8.578"], ["72362.40", "0.000"], ["72370.90", "4.852"], ["72406.60", "1.931"], ["78392.90", "0.000"]]}}
{"local_ts": 1773384479187, "server_ts": 1773384478969, "data": {"e": "depthUpdate", "E": 1773384478971, "T": 1773384478969, "s": "BTCUSDT", "U": 10101335827991, "u": 10101335833274, "pu": 10101335827986, "b": [["1000.00", "27.342"], ["5000.00", "101.418"], ["20866.20", "0.603"], ["20966.20", "0.297"], ["21066.20", "0.954"], ["21166.20", "0.846"], ["57013.00", "0.000"], ["64139.60", "0.003"], ["67670.30", "0.002"], ["67683.80", "0.000"], ["70137.10", "0.000"], ["70232.80", "7.677"], ["70244.00", "20.948"], ["70553.50", "1.558"], ["70991.10", "0.017"], ["70991.30", "0.002"], ["71218.40", "0.210"], ["71259.10", "0.096"], ["71265.00", "0.002"], ["71265.60", "0.002"], ["71266.20", "3.783"]], "a": [["71295.90", "0.006"], ["71303.90", "0.002"], ["71307.00", "0.606"], ["71307.20", "0.009"], ["71307.70", "0.508"], ["71979.00", "1.918"], ["72370.90", "6.784"], ["72585.10", "0.688"], ["72691.60", "0.021"], ["78392.90", "0.000"]]}}
{"local_ts": 1773384480207, "server_ts": 1773384479990, "data": {"e": "depthUpdate", "E": 1773384479991, "T": 1773384479990, "s": "BTCUSDT", "U": 10101335914896, "u": 10101335920005, "pu": 10101335914876, "b": [["1000.00", "27.342"], ["5000.00", "101.438"], ["20766.20", "0.468"], ["20866.20", "0.432"], ["20966.20", "0.684"], ["21066.20", "1.116"], ["64139.60", "0.003"], ["67669.30", "0.000"], ["67689.00", "0.007"], ["68415.60", "0.012"], ["69840.90", "0.045"], ["70022.20", "0.023"], ["70553.50", "1.558"], ["70589.20", "2.416"], ["70909.90", "0.000"], ["70991.00", "0.002"], ["70991.30", "0.000"], ["71173.30", "6.984"], ["71185.20", "0.515"], ["71192.40", "0.000"], ["71218.40", "0.189"], ["71233.60", "1.906"], ["71237.00", "1.132"], ["71239.90", "0.000"], ["71247.30", "1.055"], ["71248.70", "0.374"], ["71250.80", "0.639"], ["71251.60", "0.000"], ["71258.30", "0.599"], ["71266.20", "3.976"]], "a": [["71266.30", "2.636"], ["71269.00", "0.003"], ["71277.10", "0.004"], ["71286.90", "0.285"], ["71294.80", "0.819"], ["71304.40", "1.222"], ["71309.40", "2.800"], ["71310.60", "0.004"], ["71357.00", "0.008"], ["71979.00", "1.920"], ["75898.60", "0.031"], ["78392.90", "0.000"], ["89523.20", "0.000"]]}}
{"local_ts": 1773384481229, "server_ts": 1773384481010, "data": {"e": "depthUpdate", "E": 1773384481011, "T": 1773384481010, "s": "BTCUSDT", "U": 10101336124131, "u": 10101336137307, "pu": 10101336123994, "b": [["5000.00", "101.418"], ["20766.20", "0.387"], ["20855.00", "0.414"], ["20966.20", "0.774"], ["21155.00", "0.333"], ["64129.50", "0.000"], ["67702.90", "0.004"], ["67703.00", "0.016"], ["69117.30", "0.005"], ["70123.60", "0.000"], ["70221.90", "0.853"], ["70542.40", "0.000"], ["70617.20", "0.040"], ["70628.40", "1.409"], ["70743.10", "0.000"], ["71005.00", "0.004"], ["71095.70", "12.658"], ["71102.80", "0.006"], ["71114.30", "0.074"], ["71114.90", "0.087"], ["71115.00", "0.114"], ["71115.40", "0.002"], ["71156.90", "0.002"], ["71157.20", "6.824"], ["71157.30", "1.438"], ["71159.60", "0.002"], ["71172.80", "0.001"], ["71173.70", "0.046"], ["71174.30", "0.506"], ["71174.70", "0.042"], ["71175.30", "0.267"], ["71175.60", "0.129"], ["71177.80", "0.212"], ["71179.40", "0.022"], ["71181.90", "0.082"], ["71182.90", "0.000"], ["71183.40", "0.781"], ["71183.90", "0.000"], ["71184.00", "0.004"], ["71184.90", "0.000"], ["71185.70", "0.005"], ["71186.80", "0.036"], ["71187.90", "0.099"], ["71188.10", "0.000"], ["71189.30", "0.029"], ["71190.60", "0.324"], ["71191.80", "0.029"], ["71193.10", "0.029"], ["71194.30", "0.104"], ["71196.80", "0.073"], ["71198.10", "0.029"], ["71198.30", "0.001"], ["71198.70", "0.942"], ["71199.40", "0.029"], ["71199.50", "0.002"], ["71200.00", "0.125"], ["71201.20", "0.552"], ["71201.50", "0.000"], ["71202.10", "0.516"], ["71202.40", "0.115"], ["71202.60", "0.119"], ["71203.20", "0.038"], ["71203.90", "0.153"], ["71204.10", "0.000"], ["71204.70", "0.002"], ["71205.50", "0.002"], ["71205.70", "0.522"], ["71206.80", "0.003"], ["71207.30", "0.020"], ["71207.70", "0.002"], ["71207.80", "0.057"], ["71208.70", "0.004"], ["71210.20", "0.051"], ["71210.70", "0.150"], ["71211.90", "0.627"], ["71214.00", "0.334"], ["71217.30", "0.014"], ["71217.40", "0.034"], ["71220.00", "0.013"], ["71220.10", "0.002"], ["71220.70", "0.000"], ["71220.80", "0.006"], ["71224.60", "0.008"], ["71225.60", "0.540"], ["71225.70", "0.002"], ["71226.00", "0.383"], ["71226.30", "0.153"], ["71226.40", "0.030"], ["71226.80", "0.000"], ["71226.90", "0.002"], ["71227.00", "0.207"], ["71229.20", "0.112"], ["71231.40", "0.075"], ["71233.20", "1.222"], ["71234.20", "0.011"], ["71237.20", "0.324"], ["71238.80", "0.006"], ["71244.90", "0.002"], ["71247.90", "0.002"], ["71250.30", "0.063"], ["71250.80", "0.003"], ["71252.50", "0.005"], ["71254.60", "0.004"]], "a": [["71262.20", "0.066"], ["71264.00", "0.015"], ["71267.40", "0.056"], ["71268.60", "0.653"], ["71269.40", "0.007"], ["71269.90", "0.222"], ["71270.10", "0.049"], ["71270.30", "0.083"], ["71271.60", "0.002"], ["71272.30", "0.000"], ["71272.50", "0.007"], ["71272.60", "0.000"], ["71272.80", "0.004"], ["71273.10", "0.126"], ["71273.40", "0.125"], ["71273.70", "0.000"], ["71274.40", "0.002"], ["71275.90", "0.002"], ["71277.30", "0.194"], ["71278.90", "0.004"], ["71279.00", "0.004"], ["71279.60", "0.575"], ["71279.70", "0.006"], ["71279.80", "0.001"], ["71280.50", "0.002"], ["71283.10", "0.349"], ["71283.20", "0.012"], ["71283.80", "0.003"], ["71283.90", "0.000"], ["71284.50", "0.004"], ["71284.60", "0.004"], ["71285.20", "0.036"], ["71285.30", "0.005"], ["71298.10", "0.540"], ["71303.00", "0.002"], ["71303.10", "0.004"], ["71307.40", "0.002"], ["71314.00", "0.007"], ["71317.00", "0.004"], ["71326.50", "0.064"], ["71336.40", "0.141"], ["71352.30", "0.100"], ["71352.40", "0.046"], ["71353.40", "2.037"], ["71353.80", "6.374"], ["71376.10", "0.085"], ["71397.60", "0.008"], ["71414.10", "3.316"], ["71414.20", "12.154"], ["71414.80", "0.000"], ["71423.30", "0.001"], ["71426.90", "0.296"], ["71427.20", "0.000"], ["71433.20", "0.000"], ["71561.60", "0.035"], ["71567.20", "0.000"], ["71967.70", "0.000"], ["72197.40", "1.509"], ["72314.40", "0.000"], ["72514.10", "1.720"], ["74827.50", "0.057"], ["78380.60", "0.000"], ["89523.20", "0.000"]]}}
{"local_ts": 1773384482249, "server_ts": 1773384482030, "data": {"e": "depthUpdate", "E": 1773384482031, "T": 1773384482030, "s": "BTCUSDT", "U": 10101336224404, "u": 10101336250959, "pu": 10101336224356, "b": [["1000.00", "27.342"], ["5000.00", "101.418"], ["20751.50", "0.198"], ["20851.50", "0.792"], ["20855.00", "0.720"], ["20955.00", "0.054"], ["21051.50", "0.198"], ["21155.00", "0.387"], ["40000.00", "49.307"], ["64126.30", "0.000"], ["69113.90", "0.000"], ["69136.30", "0.017"], ["69826.50", "0.003"], ["70350.90", "2.546"], ["70539.00", "0.014"], ["70882.00", "0.049"], ["70898.80", "0.000"], ["71140.20", "0.080"], ["71159.00", "0.021"], ["71161.20", "13.234"], ["71162.30", "0.063"], ["71162.50", "0.000"], ["71175.20", "0.005"], ["71177.40", "0.000"], ["71196.50", "0.002"], ["71198.90", "1.202"], ["71200.20", "0.000"], ["71204.00", "0.824"], ["71204.40", "0.995"], ["71206.70", "0.002"], ["71208.40", "0.055"], ["71208.60", "0.003"], ["71211.00", "0.805"], ["71211.70", "0.002"], ["71215.40", "0.341"], ["71216.50", "0.008"], ["71216.60", "0.325"], ["71217.00", "1.729"], ["71217.10", "0.019"], ["71217.20", "0.166"], ["71217.30", "0.016"], ["71217.70", "0.051"], ["71218.00", "1.738"], ["71218.40", "0.005"], ["71219.90", "0.020"], ["71220.00", "0.046"], ["71220.30", "0.002"], ["71220.70", "0.000"], ["71220.80", "0.006"], ["71221.40", "0.012"], ["71221.50", "0.013"], ["71221.70", "0.001"], ["71222.10", "0.005"], ["71222.20", "0.006"], ["71222.30", "0.000"], ["71222.80", "0.004"], ["71222.90", "0.085"], ["71223.50", "0.674"], ["71224.50", "0.001"], ["71225.00", "1.622"], ["71225.30", "1.124"], ["71225.70", "0.198"], ["71226.40", "0.074"], ["71228.10", "0.145"], ["71228.70", "0.070"], ["71230.10", "0.056"], ["71230.90", "0.040"], ["71231.10", "0.080"], ["71231.20", "0.002"], ["71232.00", "0.816"], ["71232.50", "0.019"], ["71232.80", "0.002"], ["71233.00", "0.161"], ["71233.20", "0.029"], ["71234.60", "0.353"], ["71234.80", "0.004"], ["71235.60", "0.028"], ["71236.20", "0.059"], ["71236.80", "0.050"], ["71237.00", "0.143"], ["71237.10", "3.341"], ["71237.20", "0.216"], ["71237.50", "0.002"], ["71237.60", "0.043"], ["71237.70", "0.017"], ["71238.00", "0.005"], ["71238.20", "0.366"], ["71238.80", "0.029"], ["71239.10", "0.003"], ["71240.00", "0.707"], ["71240.80", "0.073"], ["71240.90", "0.087"], ["71241.20", "0.089"], ["71241.30", "0.321"], ["71241.40", "0.256"], ["71241.70", "0.036"], ["71241.80", "0.090"], ["71242.10", "0.041"], ["71242.20", "0.011"], ["71242.40", "0.081"], ["71242.70", "0.038"], ["71242.90", "0.072"], ["71243.00", "0.113"], ["71243.10", "0.017"], ["71243.40", "0.049"], ["71243.70", "0.111"], ["71244.00", "0.036"], ["71244.10", "0.002"], ["71244.30", "0.043"], ["71244.40", "0.044"], ["71244.60", "0.323"], ["71244.70", "0.067"], ["71245.50", "0.790"], ["71245.60", "0.533"], ["71245.90", "0.003"], ["71246.70", "0.790"], ["71247.00", "0.006"], ["71247.30", "0.447"], ["71247.90", "0.805"], ["71248.00", "0.005"], ["71248.30", "0.012"], ["71248.80", "0.003"], ["71249.00", "0.000"], ["71249.20", "0.002"], ["71249.30", "0.015"], ["71250.00", "0.148"], ["71250.10", "0.005"], ["71251.20", "0.002"], ["71251.40", "0.213"], ["71251.50", "4.176"]], "a": [["71251.60", "1.881"], ["71251.70", "0.069"], ["71251.90", "0.000"], ["71252.10", "0.002"], ["71252.20", "0.058"], ["71252.70", "0.000"], ["71252.80", "0.000"], ["71253.00", "0.002"], ["71253.20", "0.002"], ["71255.10", "0.247"], ["71255.20", "0.212"], ["71255.30", "0.000"], ["71255.70", "0.029"], ["71257.20", "0.000"], ["71257.30", "0.000"], ["71258.20", "0.000"], ["71258.30", "0.000"], ["71258.40", "0.772"], ["71259.60", "0.004"], ["71259.70", "0.007"], ["71259.90", "0.073"], ["71260.10", "0.006"], ["71260.80", "0.001"], ["71260.90", "0.003"], ["71261.90", "0.003"], ["71262.10", "0.000"], ["71262.20", "0.000"], ["71263.20", "0.001"], ["71263.30", "0.005"], ["71263.40", "0.057"], ["71263.60", "0.002"], ["71263.70", "0.002"], ["71264.00", "0.015"], ["71264.60", "0.121"], ["71264.90", "0.001"], ["71265.00", "0.308"], ["71265.20", "0.647"], ["71265.80", "0.000"], ["71265.90", "0.002"], ["71266.10", "0.000"], ["71266.20", "0.112"], ["71266.50", "0.023"], ["71266.70", "0.004"], ["71267.00", "0.013"], ["71267.10", "0.001"], ["71268.10", "0.007"], ["71268.20", "0.348"], ["71268.30", "0.000"], ["71268.40", "0.000"], ["71268.80", "0.003"], ["71268.90", "0.000"], ["71269.00", "0.143"], ["71269.10", "0.026"], ["71269.20", "0.004"], ["71269.30", "0.270"], ["71269.50", "0.137"], ["71269.60", "0.000"], ["71269.70", "0.003"], ["71270.20", "0.018"], ["71270.40", "0.004"], ["71270.70", "0.000"], ["71270.90", "0.001"], ["71271.00", "0.000"], ["71271.20", "0.004"], ["71271.30", "0.034"], ["71271.60", "0.016"], ["71271.90", "0.043"], ["71272.10", "0.001"], ["71272.20", "0.005"], ["71272.30", "0.003"], ["71272.50", "0.005"], ["71272.70", "0.002"], ["71272.90", "0.016"], ["71273.00", "0.114"], ["71273.10", "0.000"], ["71273.40", "0.006"], ["71273.50", "0.203"], ["71273.60", "0.003"], ["71273.80", "0.000"], ["71274.00", "0.811"], ["71274.10", "0.015"], ["71274.60", "0.078"], ["71274.70", "0.510"], ["71274.80", "1.438"], ["71275.10", "0.070"], ["71275.20", "0.090"], ["71275.40", "0.056"], ["71275.50", "0.000"], ["71275.70", "0.634"], ["71275.80", "0.135"], ["71275.90", "0.000"], ["71276.00", "0.002"], ["71276.10", "0.080"], ["71276.20", "0.004"], ["71276.30", "0.001"], ["71276.50", "0.000"], ["71276.70", "0.015"], ["71276.80", "0.005"], ["71277.00", "0.037"], ["71277.20", "0.005"], ["71277.60", "0.004"], ["71277.70", "0.008"], ["71277.90", "0.017"], ["71278.10", "0.003"], ["71278.30", "0.003"], ["71278.90", "0.002"], ["71279.10", "0.070"], ["71279.20", "0.222"], ["71279.30", "0.001"], ["71279.40", "0.052"], ["71279.50", "0.000"], ["71279.60", "0.575"], ["71279.70", "0.006"], ["71279.80", "0.001"], ["71280.10", "0.034"], ["71280.30", "0.019"], ["71280.40", "0.320"], ["71280.50", "0.002"], ["71280.60", "0.002"], ["71280.80", "0.002"], ["71281.00", "0.808"], ["71281.10", "0.003"], ["71281.20", "0.017"], ["71281.40", "0.020"], ["71281.70", "0.002"], ["71281.80", "0.007"], ["71282.00", "0.004"], ["71282.10", "0.751"], ["71282.50", "0.000"], ["71282.60", "0.005"], ["71283.30", "0.003"], ["71283.80", "0.003"], ["71283.90", "0.000"], ["71284.10", "0.006"], ["71284.40", "0.005"], ["71284.50", "0.002"], ["71285.00", "0.056"], ["71286.30", "0.006"], ["71286.50", "0.023"], ["71286.80", "0.066"], ["71287.20", "0.440"], ["71287.30", "0.080"], ["71287.50", "0.056"], ["71287.70", "0.007"], ["71288.00", "1.205"], ["71288.80", "0.508"], ["71289.20", "0.336"], ["71289.30", "0.003"], ["71289.70", "0.006"], ["71290.00", "0.684"], ["71290.10", "0.000"], ["71290.50", "0.003"], ["71291.00", "1.196"], ["71291.30", "0.000"], ["71291.80", "0.002"], ["71292.40", "0.606"], ["71292.50", "0.000"], ["71292.80", "0.023"], ["71292.90", "0.005"], ["71293.50", "0.000"], ["71293.70", "0.000"], ["71293.80", "0.282"], ["71294.10", "0.019"], ["71294.30", "0.975"], ["71294.40", "0.250"], ["71294.50", "0.000"], ["71294.80", "0.002"], ["71295.00", "0.948"], ["71295.10", "0.002"], ["71295.20", "0.000"], ["71295.50", "0.001"], ["71295.70", "0.014"], ["71296.10", "0.002"], ["71296.20", "0.251"], ["71296.30", "0.010"], ["71296.50", "0.000"], ["71297.10", "0.508"], ["71297.30", "0.122"], ["71297.50", "0.000"], ["71297.60", "0.339"], ["71298.00", "0.006"], ["71298.70", "0.000"], ["71298.90", "0.033"], ["71299.00", "0.047"], ["71299.40", "0.020"], ["71300.00", "3.255"], ["71300.10", "0.210"], ["71300.20", "0.063"], ["71300.30", "0.029"], ["71300.70", "0.001"], ["71301.20", "0.004"], ["71301.30", "0.019"], ["71301.50", "0.008"], ["71301.70", "0.041"], ["71302.00", "1.226"], ["71302.40", "0.015"], ["71302.50", "0.002"], ["71302.60", "0.002"], ["71303.20", "0.029"], ["71303.70", "0.317"], ["71304.60", "0.031"], ["71305.00", "0.531"], ["71306.20", "0.617"], ["71306.40", "0.034"], ["71307.40", "0.002"], ["71307.50", "0.015"], ["71307.60", "1.084"], ["71308.70", "0.000"], ["71308.90", "0.029"], ["71309.00", "0.002"], ["71309.10", "0.018"], ["71309.90", "0.507"], ["71310.10", "0.107"], ["71310.20", "0.099"], ["71311.20", "0.000"], ["71312.20", "0.159"], ["71312.40", "0.051"], ["71313.00", "0.002"], ["71313.70", "0.002"], ["71314.50", "0.000"], ["71314.80", "0.047"], ["71315.10", "0.002"], ["71316.40", "0.074"], ["71317.90", "0.000"], ["71319.10", "0.002"], ["71319.30", "0.308"], ["71319.80", "0.299"], ["71319.90", "0.366"], ["71321.00", "0.286"], ["71323.20", "0.002"], ["71325.60", "0.002"], ["71326.90", "0.005"], ["71328.10", "0.006"], ["71329.40", "0.004"], ["71330.00", "0.791"], ["71330.60", "0.791"], ["71331.90", "0.334"], ["71333.10", "0.002"], ["71334.40", "0.000"], ["71335.00", "0.221"], ["71341.30", "2.900"], ["71341.60", "0.013"], ["71351.90", "0.155"], ["71367.90", "0.948"], ["71368.00", "0.003"], ["71373.80", "10.002"], ["71399.90", "3.507"], ["71402.00", "0.000"], ["71420.70", "2.172"], ["71420.80", "0.000"], ["71420.90", "10.000"], ["71446.50", "0.000"], ["71449.10", "6.442"], ["71474.80", "0.235"], ["71477.80", "0.000"], ["71478.00", "1.906"], ["71480.50", "10.000"], ["71510.50", "2.243"], ["71511.90", "10.000"], ["71524.80", "0.000"], ["71524.90", "0.002"], ["71558.10", "1.664"], ["71559.00", "10.327"], ["71964.10", "0.000"], ["72537.90", "0.613"], ["74841.50", "0.050"], ["74849.20", "0.002"], ["78376.80", "0.002"], ["89523.20", "0.000"]]}}
{"local_ts": 1773384483271, "server_ts": 1773384483053, "data": {"e": "depthUpdate", "E": 1773384483055, "T": 1773384483053, "s": "BTCUSDT", "U": 10101336336377, "u": 10101336341808, "pu": 10101336336339, "b": [["5000.00", "101.418"], ["20751.50", "1.557"], ["20851.50", "0.180"], ["20951.50", "0.063"], ["21051.50", "0.837"], ["21151.50", "0.063"], ["33000.00", "9.339"], ["67656.20", "0.002"], ["67684.70", "0.007"], ["69114.00", "0.005"], ["69128.30", "0.000"], ["70539.00", "0.014"], ["70978.50", "0.169"], ["71013.50", "0.000"], ["71042.00", "0.306"], ["71210.80", "0.226"], ["71212.30", "0.003"], ["71232.40", "0.038"], ["71236.20", "0.017"], ["71238.70", "0.151"], ["71248.30", "0.002"], ["71248.40", "0.011"], ["71250.40", "0.042"], ["71250.50", "0.005"], ["71250.60", "0.000"], ["71250.70", "0.002"], ["71250.80", "0.002"]], "a": [["71253.00", "0.004"], ["71255.50", "0.003"], ["71255.70", "0.001"], ["71258.20", "0.004"], ["71268.20", "0.346"], ["71269.40", "0.125"], ["71275.50", "0.000"], ["71277.50", "0.250"], ["71277.70", "0.001"], ["71285.10", "0.143"], ["71285.20", "0.220"], ["71285.50", "0.014"], ["71288.00", "0.091"], ["71301.20", "0.006"], ["71301.30", "0.004"], ["71379.50", "0.207"], ["71380.10", "0.000"], ["71386.60", "0.021"], ["71387.20", "0.000"], ["71393.70", "0.620"], ["71394.30", "0.000"], ["71400.80", "0.007"], ["71401.40", "0.002"], ["71407.90", "0.300"], ["71408.50", "0.000"], ["71415.00", "0.007"], ["71415.60", "0.000"], ["71422.10", "0.007"], ["71422.70", "0.000"], ["71429.20", "0.297"], ["71429.80", "0.002"], ["71964.10", "0.000"], ["72228.50", "0.828"], ["73404.20", "0.020"], ["89523.20", "0.000"]]}}
{"local_ts": 1773384484297, "server_ts": 1773384484080, "data": {"e": "depthUpdate", "E": 1773384484081, "T": 1773384484080, "s": "BTCUSDT", "U": 10101336401436, "u": 10101336408740, "pu": 10101336401070, "b": [["1000.00", "27.342"], ["5000.00", "101.418"], ["20751.50", "0.378"], ["20951.50", "0.828"], ["21051.50", "0.072"], ["21151.50", "1.422"], ["67655.30", "0.000"], ["67688.00", "0.250"], ["67703.00", "0.014"], ["69114.00", "0.008"], ["70539.00", "0.014"], ["71204.40", "1.524"], ["71220.30", "0.247"], ["71221.40", "0.016"], ["71234.20", "0.640"], ["71235.40", "0.004"], ["71237.20", "0.067"], ["71238.70", "0.151"], ["71248.90", "0.010"], ["71250.30", "0.008"], ["71251.50", "3.658"]], "a": [["71255.40", "0.031"], ["71269.40", "0.121"], ["71269.90", "0.859"], ["71270.60", "0.005"], ["71272.10", "0.001"], ["71274.60", "0.078"], ["71274.80", "1.626"], ["71281.40", "0.016"], ["71285.10", "0.014"], ["71285.20", "0.163"], ["71287.20", "0.558"], ["71289.30", "0.007"], ["71299.50", "0.608"], ["71379.50", "0.200"], ["71380.10", "0.007"], ["71386.60", "0.014"], ["71387.20", "0.007"], ["71393.70", "0.613"], ["71394.30", "0.007"], ["71400.80", "0.000"], ["71401.40", "0.009"], ["71407.90", "0.293"], ["71408.50", "0.007"], ["71415.00", "0.000"], ["71415.60", "0.007"], ["71422.10", "0.000"], ["71422.70", "0.007"], ["71429.20", "0.290"], ["71429.80", "0.009"], ["71478.20", "0.057"], ["71643.20", "0.066"], ["71964.10", "0.000"], ["73080.40", "0.000"], ["73389.10", "0.003"], ["73404.20", "0.017"], ["89523.20", "0.000"]]}}
{"local_ts": 1773384485319, "server_ts": 1773384485102, "data": {"e": "depthUpdate", "E": 1773384485103, "T": 1773384485102, "s": "BTCUSDT", "U": 10101336463138, "u": 10101336473139, "pu": 10101336463110, "b": [["1000.00", "27.342"], ["5000.00", "101.418"], ["20851.50", "0.702"], ["20951.50", "0.198"], ["21051.50", "1.152"], ["21151.50", "0.648"], ["33000.00", "9.343"], ["57001.00", "0.441"], ["67702.90", "0.000"], ["67703.00", "0.016"], ["70205.80", "0.568"], ["70284.50", "0.004"], ["70477.90", "4.007"], ["70539.00", "1.430"], ["70895.20", "0.002"], ["71062.50", "0.014"], ["71095.70", "0.000"], ["71098.50", "0.396"], ["71144.10", "0.101"], ["71151.80", "0.014"], ["71157.20", "0.000"], ["71157.30", "0.445"], ["71170.10", "0.019"], ["71170.20", "0.570"], ["71176.70", "1.200"], ["71183.20", "0.008"], ["71194.20", "0.007"], ["71197.10", "0.518"], ["71204.00", "0.824"], ["71204.70", "0.038"], ["71205.50", "0.002"], ["71205.70", "0.527"], ["71208.00", "0.248"], ["71211.00", "0.820"], ["71216.10", "0.003"], ["71216.90", "0.010"], ["71218.00", "1.738"], ["71218.10", "0.245"], ["71220.30", "0.022"], ["71224.80", "0.017"], ["71225.00", "1.622"], ["71229.60", "0.804"], ["71232.00", "0.816"], ["71233.10", "0.721"], ["71238.60", "0.001"], ["71240.50", "0.097"], ["71240.80", "0.052"], ["71244.00", "0.040"], ["71244.10", "0.002"], ["71244.50", "0.002"], ["71245.70", "0.042"], ["71246.40", "0.211"], ["71247.40", "0.003"], ["71249.20", "0.002"], ["71249.30", "0.000"], ["71251.50", "1.455"]], "a": [["71263.50", "0.090"], ["71266.40", "0.011"], ["71267.00", "0.145"], ["71267.20", "0.019"], ["71268.00", "0.007"], ["71269.30", "0.227"], ["71270.60", "0.003"], ["71272.40", "0.128"], ["71274.00", "0.811"], ["71281.00", "0.808"], ["71285.20", "0.036"], ["71285.30", "0.189"], ["71288.00", "0.894"], ["71295.00", "0.948"], ["71297.90", "0.142"], ["71299.20", "0.002"], ["71302.00", "1.197"], ["71315.70", "0.220"], ["71319.30", "0.149"], ["71322.00", "0.276"], ["71330.00", "0.794"], ["71353.40", "1.241"], ["71353.80", "0.052"], ["71372.30", "0.002"], ["71378.30", "0.291"], ["71380.10", "0.000"], ["71385.40", "0.708"], ["71387.20", "0.000"], ["71392.50", "0.209"], ["71394.30", "0.000"], ["71399.60", "0.161"], ["71401.40", "0.002"], ["71406.70", "0.011"], ["71408.50", "0.000"], ["71413.80", "0.036"], ["71414.10", "1.373"], ["71414.20", "0.000"], ["71415.60", "0.000"], ["71420.90", "10.007"], ["71422.70", "0.000"], ["71428.00", "0.011"], ["71429.80", "0.002"], ["71479.00", "0.077"], ["71964.10", "0.002"], ["72263.30", "1.658"], ["73389.10", "0.011"], ["74817.60", "0.002"], ["89523.20", "0.000"]]}}
{"local_ts": 1773384486350, "server_ts": 1773384486124, "data": {"e": "depthUpdate", "E": 1773384486125, "T": 1773384486124, "s": "BTCUSDT", "U": 10101336529799, "u": 10101336576073, "pu": 10101336529711, "b": [["5000.00", "101.418"], ["20745.30", "0.018"], ["20747.80", "0.009"], ["20747.90", "0.009"], ["20751.50", "0.531"], ["20851.50", "0.333"], ["20945.30", "0.027"], ["20945.40", "0.009"], ["20947.90", "0.018"], ["20948.70", "0.009"], ["20951.50", "0.819"], ["21051.50", "0.918"], ["57001.00", "0.445"], ["67661.00", "0.008"], ["67688.90", "0.011"], ["69829.90", "0.010"], ["69832.80", "0.005"], ["69834.20", "0.000"], ["70069.90", "0.989"], ["70109.20", "0.999"], ["70143.90", "0.988"], ["70180.50", "5.949"], ["70532.80", "0.004"], ["70533.90", "0.000"], ["70536.20", "0.000"], ["70537.00", "0.288"], ["70538.20", "0.000"], ["70539.00", "1.430"], ["70572.00", "0.701"], ["70608.20", "2.879"], ["70817.90", "0.349"], ["70857.70", "0.000"], ["70937.50", "6.658"], ["70944.30", "0.321"], ["70944.80", "0.324"], ["70947.30", "0.314"], ["70948.50", "0.087"], ["70976.20", "1.580"], ["70978.70", "1.543"], ["70982.10", "0.000"], ["70988.30", "0.193"], ["70991.20", "0.000"], ["70991.60", "0.154"], ["70998.10", "0.292"], ["71009.30", "0.001"], ["71013.40", "0.004"], ["71017.00", "0.482"], ["71017.10", "0.002"], ["71020.60", "0.000"], ["71020.70", "0.000"], ["71020.80", "0.868"], ["71030.90", "2.322"], ["71042.10", "0.000"], ["71043.50", "23.300"], ["71044.40", "0.042"], ["71046.80", "0.874"], ["71051.90", "0.000"], ["71052.00", "0.012"], ["71056.20", "0.758"], ["71070.60", "0.002"], ["71076.00", "0.546"], ["71089.60", "0.101"], ["71090.60", "0.004"], ["71094.90", "3.854"], ["71095.30", "0.267"], ["71095.60", "6.577"], ["71096.60", "0.204"], ["71097.60", "0.401"], ["71097.80", "0.078"], ["71099.40", "0.101"], ["71099.80", "0.000"], ["71100.90", "0.000"], ["71102.00", "1.239"], ["71103.00", "0.000"], ["71103.80", "0.856"], ["71104.50", "0.176"], ["71106.60", "0.137"], ["71110.20", "0.508"], ["71112.60", "0.489"], ["71114.20", "1.787"], ["71119.40", "0.100"], ["71120.10", "4.684"], ["71121.40", "4.144"], ["71122.80", "0.002"], ["71124.50", "0.000"], ["71124.90", "0.037"], ["71127.00", "0.220"], ["71127.80", "0.005"], ["71129.00", "0.107"], ["71134.80", "0.506"], ["71135.20", "0.256"], ["71135.80", "2.721"], ["71137.30", "0.204"], ["71140.20", "0.002"], ["71141.00", "0.029"], ["71142.50", "0.600"], ["71145.70", "0.208"], ["71147.10", "0.109"], ["71150.70", "0.002"], ["71151.30", "0.001"], ["71151.90", "0.014"], ["71152.40", "0.000"], ["71152.50", "0.002"], ["71152.90", "0.066"], ["71153.10", "6.625"], ["71154.10", "0.000"], ["71156.90", "0.000"], ["71157.30", "0.507"], ["71157.70", "0.000"], ["71158.10", "0.001"], ["71158.90", "0.824"], ["71159.70", "0.007"], ["71159.80", "0.004"], ["71160.10", "0.001"], ["71160.20", "0.062"], ["71160.30", "0.159"], ["71160.60", "0.002"], ["71161.10", "0.102"], ["71161.30", "0.045"], ["71161.60", "0.322"], ["71162.30", "0.042"], ["71162.50", "0.318"], ["71162.80", "0.000"], ["71163.20", "0.042"], ["71163.50", "0.140"], ["71164.70", "0.019"], ["71165.00", "0.006"], ["71165.40", "0.021"], ["71165.50", "0.204"], ["71165.80", "0.038"], ["71166.00", "0.002"], ["71167.10", "0.000"], ["71167.20", "0.003"], ["71168.10", "1.051"], ["71169.10", "0.463"], ["71170.10", "0.019"], ["71170.50", "0.021"], ["71170.70", "0.215"], ["71171.10", "0.382"], ["71171.40", "0.210"], ["71171.60", "1.202"], ["71172.00", "0.093"], ["71172.60", "0.002"], ["71173.00", "0.020"], ["71173.20", "0.000"], ["71173.40", "0.053"], ["71173.60", "0.000"], ["71173.90", "0.006"], ["71174.00", "0.040"], ["71174.60", "0.042"], ["71175.00", "6.305"], ["71175.10", "2.431"], ["71175.20", "0.023"], ["71175.50", "0.074"], ["71175.60", "0.019"], ["71175.70", "0.145"], ["71175.90", "0.003"], ["71176.70", "0.000"], ["71176.90", "0.320"], ["71177.60", "0.000"], ["71177.80", "0.170"], ["71177.90", "0.000"], ["71178.30", "0.025"], ["71178.40", "0.074"], ["71178.50", "0.001"], ["71178.60", "0.054"], ["71178.80", "1.382"], ["71178.90", "0.873"], ["71179.40", "0.022"], ["71179.90", "0.000"], ["71180.30", "0.079"], ["71180.40", "0.607"], ["71180.50", "0.323"], ["71180.90", "1.050"], ["71181.00", "0.013"], ["71181.30", "0.000"], ["71181.40", "0.000"], ["71182.00", "0.046"], ["71184.40", "0.003"], ["71185.20", "0.513"], ["71185.50", "0.074"], ["71185.70", "0.053"], ["71186.10", "0.049"], ["71186.60", "0.043"], ["71187.50", "0.008"], ["71187.90", "0.113"], ["71188.30", "0.005"], ["71188.80", "0.000"], ["71189.00", "0.009"], ["71189.10", "1.037"], ["71189.40", "0.067"], ["71189.90", "0.003"], ["71190.60", "0.252"], ["71190.90", "0.004"], ["71191.50", "0.052"], ["71191.70", "1.050"], ["71192.50", "0.001"], ["71193.00", "0.000"], ["71193.70", "0.508"], ["71193.80", "3.536"], ["71193.90", "0.002"], ["71194.10", "0.002"], ["71194.50", "0.272"], ["71195.10", "0.057"], ["71195.50", "0.019"], ["71195.60", "0.028"], ["71196.60", "0.000"], ["71196.90", "0.027"], ["71197.10", "1.124"], ["71197.30", "0.000"], ["71197.50", "1.049"], ["71198.10", "0.000"], ["71198.70", "0.000"], ["71198.80", "0.041"], ["71199.00", "0.606"], ["71199.10", "0.002"], ["71199.30", "0.006"], ["71199.60", "0.001"], ["71199.90", "0.000"], ["71200.00", "0.125"], ["71200.20", "0.000"], ["71200.30", "0.005"], ["71200.60", "0.031"], ["71200.70", "1.870"], ["71201.00", "0.813"], ["71201.20", "0.513"], ["71201.40", "0.317"], ["71201.50", "0.051"], ["71201.80", "0.102"], ["71201.90", "0.024"], ["71202.00", "0.004"], ["71202.20", "0.537"], ["71202.50", "0.010"], ["71202.60", "0.119"], ["71202.90", "0.337"], ["71203.10", "0.000"], ["71203.50", "1.049"], ["71203.70", "0.002"], ["71203.90", "0.000"], ["71204.00", "0.021"], ["71204.20", "0.003"], ["71204.60", "0.003"], ["71204.80", "0.133"], ["71204.90", "0.003"], ["71205.40", "0.003"], ["71206.10", "0.000"], ["71206.20", "0.020"], ["71206.80", "0.003"], ["71206.90", "0.000"], ["71207.40", "0.013"], ["71207.80", "0.011"], ["71207.90", "0.000"], ["71208.10", "0.008"], ["71208.30", "0.000"], ["71208.40", "0.005"], ["71208.50", "0.077"], ["71208.60", "0.003"], ["71208.70", "0.000"], ["71208.90", "0.019"], ["71209.60", "0.353"], ["71209.70", "1.675"], ["71209.80", "0.004"], ["71209.90", "0.333"], ["71210.00", "0.009"], ["71210.30", "0.030"], ["71210.50", "0.070"], ["71210.70", "0.000"], ["71210.80", "0.121"], ["71210.90", "0.001"], ["71211.00", "0.002"], ["71211.10", "0.320"], ["71211.20", "0.000"], ["71211.50", "0.040"], ["71211.60", "0.003"], ["71211.80", "0.252"], ["71211.90", "0.506"], ["71212.10", "0.031"], ["71212.20", "0.006"], ["71212.50", "0.000"], ["71212.80", "0.000"], ["71213.00", "0.648"], ["71213.10", "0.005"], ["71213.20", "0.074"], ["71213.50", "0.109"], ["71213.70", "0.182"], ["71214.00", "0.336"], ["71214.20", "0.019"], ["71214.40", "0.002"], ["71214.50", "0.004"], ["71214.60", "0.009"], ["71214.70", "0.103"], ["71215.00", "0.049"], ["71215.10", "0.004"], ["71215.70", "0.000"], ["71215.80", "0.510"], ["71215.90", "0.004"], ["71216.00", "7.731"], ["71216.40", "0.002"], ["71216.50", "0.008"], ["71216.60", "0.325"], ["71216.80", "0.109"], ["71216.90", "0.010"], ["71217.10", "1.892"], ["71217.20", "0.003"], ["71217.30", "0.014"], ["71217.60", "0.064"], ["71217.90", "0.009"], ["71218.00", "0.944"], ["71218.10", "0.288"], ["71218.40", "0.005"], ["71218.50", "0.245"], ["71218.60", "0.179"], ["71218.70", "0.003"], ["71218.80", "0.302"], ["71219.20", "0.107"], ["71219.30", "0.031"], ["71219.40", "0.173"], ["71219.50", "0.002"], ["71219.80", "0.002"], ["71220.00", "0.013"], ["71220.10", "0.002"], ["71220.20", "0.477"], ["71220.30", "0.070"], ["71220.40", "0.177"], ["71220.50", "0.000"], ["71220.70", "0.000"], ["71220.80", "0.006"], ["71221.00", "0.073"], ["71221.20", "0.000"], ["71221.40", "0.341"], ["71221.50", "0.006"], ["71221.60", "0.004"], ["71221.90", "0.004"], ["71222.00", "0.025"], ["71222.10", "0.003"], ["71222.20", "0.002"], ["71222.30", "0.000"], ["71222.50", "0.083"], ["71222.60", "0.000"], ["71222.70", "0.102"], ["71222.80", "0.009"], ["71222.90", "0.004"], ["71223.10", "0.328"], ["71223.40", "0.006"], ["71223.50", "0.652"], ["71223.60", "0.000"], ["71223.90", "1.608"], ["71224.00", "0.527"], ["71224.50", "0.001"], ["71224.90", "0.004"], ["71225.00", "0.023"], ["71225.10", "0.004"], ["71225.20", "0.004"], ["71225.30", "0.079"], ["71225.40", "1.187"], ["71225.50", "0.010"], ["71225.60", "0.004"], ["71225.70", "1.181"], ["71225.80", "0.000"], ["71225.90", "0.209"], ["71226.00", "0.038"], ["71226.10", "0.012"], ["71226.30", "0.002"], ["71226.40", "0.033"], ["71226.50", "0.510"], ["71226.60", "0.004"], ["71226.70", "0.004"], ["71226.80", "0.000"], ["71227.00", "0.000"], ["71227.20", "0.005"], ["71227.40", "0.388"], ["71227.70", "0.003"], ["71227.80", "0.007"], ["71227.90", "0.159"], ["71228.10", "0.005"], ["71228.20", "0.013"], ["71228.60", "0.010"], ["71228.70", "0.000"], ["71228.80", "0.421"], ["71228.90", "0.510"], ["71229.10", "0.006"], ["71229.40", "0.006"], ["71229.50", "0.002"], ["71229.70", "0.338"], ["71229.90", "0.003"], ["71230.00", "0.009"], ["71230.10", "0.108"], ["71230.20", "0.006"], ["71230.30", "0.001"], ["71230.40", "0.000"], ["71230.50", "0.470"], ["71230.60", "0.115"], ["71230.70", "0.010"], ["71230.80", "0.000"], ["71230.90", "0.000"], ["71231.00", "0.005"], ["71231.10", "0.277"], ["71231.20", "0.000"], ["71231.30", "0.000"], ["71231.40", "0.581"], ["71231.50", "0.006"], ["71231.60", "0.009"], ["71231.90", "0.006"], ["71232.00", "0.013"], ["71232.40", "0.038"], ["71232.60", "0.038"], ["71233.00", "0.006"], ["71233.20", "0.002"], ["71233.30", "0.039"], ["71233.40", "0.032"], ["71233.50", "0.004"], ["71233.60", "0.509"], ["71233.70", "0.000"], ["71233.80", "0.014"], ["71233.90", "0.001"], ["71234.10", "0.387"], ["71234.30", "0.147"], ["71234.40", "0.000"], ["71234.50", "0.226"], ["71234.60", "1.071"], ["71234.90", "0.000"], ["71235.00", "0.008"], ["71235.10", "0.018"], ["71235.20", "0.307"], ["71235.30", "0.008"], ["71235.40", "0.006"], ["71235.50", "0.128"], ["71235.80", "0.006"], ["71235.90", "0.005"], ["71236.00", "0.071"], ["71236.20", "0.002"], ["71236.30", "0.002"], ["71236.40", "0.005"], ["71236.60", "0.007"], ["71236.90", "0.036"], ["71237.00", "0.004"], ["71237.10", "0.003"], ["71237.20", "0.003"], ["71237.30", "0.002"], ["71237.40", "0.002"], ["71237.50", "0.002"], ["71237.60", "0.003"], ["71237.90", "0.342"], ["71238.00", "0.002"], ["71238.10", "0.012"], ["71238.20", "0.014"], ["71238.40", "0.055"], ["71238.50", "0.000"], ["71238.70", "0.151"], ["71238.80", "0.000"], ["71238.90", "0.011"], ["71239.00", "0.097"], ["71239.20", "0.001"], ["71239.60", "0.000"], ["71239.70", "0.019"], ["71239.80", "0.224"], ["71239.90", "0.001"], ["71240.00", "0.074"], ["71240.20", "0.055"], ["71240.30", "0.003"], ["71240.50", "0.003"], ["71240.70", "0.004"], ["71240.90", "0.002"], ["71241.00", "0.000"], ["71241.20", "0.000"], ["71241.30", "0.004"], ["71241.40", "0.003"], ["71241.50", "0.004"], ["71241.60", "0.000"], ["71241.80", "0.006"], ["71242.40", "0.006"], ["71242.50", "0.004"], ["71242.60", "0.000"], ["71242.80", "0.003"], ["71242.90", "0.219"], ["71243.00", "0.002"], ["71243.30", "0.004"], ["71243.40", "0.004"], ["71243.50", "0.062"], ["71243.70", "0.001"], ["71243.80", "0.000"], ["71243.90", "0.523"], ["71244.00", "0.000"], ["71244.10", "0.000"], ["71244.30", "0.000"], ["71244.40", "0.000"], ["71244.50", "0.000"], ["71244.60", "0.000"], ["71244.70", "0.000"], ["71244.80", "0.000"], ["71244.90", "0.000"], ["71245.00", "0.000"], ["71245.10", "0.000"], ["71245.20", "0.000"], ["71245.30", "0.000"], ["71245.40", "0.000"], ["71245.50", "0.000"], ["71245.60", "0.000"], ["71245.70", "0.000"], ["71245.90", "0.000"], ["71246.00", "0.000"], ["71246.10", "0.000"], ["71246.20", "0.000"], ["71246.30", "0.000"], ["71246.40", "0.000"], ["71246.50", "0.000"], ["71246.60", "0.000"], ["71246.70", "0.000"], ["71246.80", "0.000"], ["71246.90", "0.000"], ["71247.00", "0.000"], ["71247.10", "0.000"], ["71247.20", "0.000"], ["71247.30", "0.000"], ["71247.40", "0.000"], ["71247.60", "0.000"], ["71247.70", "0.000"], ["71247.80", "0.000"], ["71247.90", "0.000"], ["71248.00", "0.000"], ["71248.20", "0.000"], ["71248.30", "0.000"], ["71248.40", "0.000"], ["71248.50", "0.000"], ["71248.70", "0.000"], ["71248.80", "0.000"], ["71248.90", "0.000"], ["71249.10", "0.000"], ["71249.40", "0.000"], ["71249.50", "0.000"], ["71249.60", "0.000"], ["71249.80", "0.000"], ["71250.00", "0.000"], ["71250.10", "0.000"], ["71250.20", "0.000"], ["71250.30", "0.000"], ["71250.50", "0.000"], ["71250.70", "0.000"], ["71250.80", "0.000"], ["71251.10", "0.000"], ["71251.40", "0.000"], ["71251.50", "0.000"]], "a": [["71244.00", "12.951"], ["71244.10", "2.950"], ["71244.20", "0.559"], ["71244.40", "2.590"], ["71244.60", "0.559"], ["71244.70", "3.057"], ["71244.80", "0.559"], ["71244.90", "0.596"], ["71245.00", "0.666"], ["71245.10", "1.676"], ["71245.20", "3.579"], ["71245.30", "3.351"], ["71245.40", "6.154"], ["71245.50", "0.234"], ["71245.60", "0.014"], ["71245.70", "0.014"], ["71245.90", "0.005"], ["71246.00", "0.007"], ["71246.10", "0.002"], ["71246.30", "0.000"], ["71246.40", "0.000"], ["71246.50", "0.000"], ["71246.60", "0.002"], ["71246.80", "0.000"], ["71246.90", "0.002"], ["71247.00", "0.002"], ["71247.10", "0.000"], ["71247.20", "0.110"], ["71247.30", "0.124"], ["71247.40", "0.126"], ["71247.50", "0.126"], ["71247.60", "0.007"], ["71247.70", "0.014"], ["71247.80", "3.262"], ["71247.90", "0.561"], ["71248.00", "0.171"], ["71248.10", "0.006"], ["71248.20", "0.006"], ["71248.30", "0.018"], ["71248.40", "0.014"], ["71248.50", "0.014"], ["71248.60", "0.014"], ["71248.70", "0.000"], ["71248.80", "0.017"], ["71248.90", "0.000"], ["71249.00", "0.375"], ["71249.20", "0.044"], ["71249.40", "0.003"], ["71249.50", "0.004"], ["71249.60", "0.256"], ["71249.70", "0.000"], ["71249.80", "0.004"], ["71249.90", "0.001"], ["71250.00", "0.002"], ["71250.10", "0.000"], ["71250.20", "0.001"], ["71250.30", "0.000"], ["71250.40", "0.071"], ["71250.50", "0.001"], ["71250.60", "0.002"], ["71250.70", "0.000"], ["71250.80", "0.117"], ["71250.90", "0.001"], ["71251.00", "0.002"], ["71251.10", "0.000"], ["71251.20", "0.001"], ["71251.40", "0.274"], ["71251.50", "1.747"], ["71251.60", "0.186"], ["71251.70", "0.005"], ["71252.00", "0.002"], ["71252.10", "0.000"], ["71252.30", "0.003"], ["71252.40", "0.002"], ["71252.60", "0.002"], ["71252.70", "0.003"], ["71252.80", "0.000"], ["71252.90", "0.002"], ["71253.00", "0.038"], ["71253.10", "0.004"], ["71253.40", "0.006"], ["71253.50", "0.000"], ["71253.70", "0.000"], ["71253.80", "0.000"], ["71254.00", "0.039"], ["71254.20", "0.003"], ["71254.40", "0.002"], ["71254.70", "0.015"], ["71255.00", "0.004"], ["71255.10", "0.003"], ["71255.20", "0.208"], ["71255.30", "0.004"], ["71255.50", "0.003"], ["71255.60", "0.073"], ["71256.50", "0.080"], ["71256.90", "0.003"], ["71257.20", "0.004"], ["71257.40", "0.005"], ["71257.60", "0.002"], ["71258.10", "0.021"], ["71258.20", "0.000"], ["71258.30", "0.002"], ["71258.60", "0.004"], ["71258.70", "0.000"], ["71258.80", "0.035"], ["71259.10", "0.142"], ["71259.60", "0.004"], ["71259.70", "0.002"], ["71259.90", "0.001"], ["71260.10", "0.004"], ["71260.20", "0.176"], ["71260.30", "0.017"], ["71260.60", "0.000"], ["71260.70", "0.020"], ["71261.00", "0.030"], ["71261.10", "0.210"], ["71261.30", "0.000"], ["71261.40", "0.032"], ["71261.50", "0.007"], ["71261.60", "0.854"], ["71262.10", "0.036"], ["71262.20", "0.340"], ["71262.30", "0.114"], ["71262.40", "0.004"], ["71262.50", "0.031"], ["71262.70", "0.000"], ["71263.00", "0.274"], ["71263.20", "0.001"], ["71263.30", "0.005"], ["71263.40", "0.069"], ["71263.50", "0.005"], ["71263.60", "0.006"], ["71263.70", "0.002"], ["71263.90", "0.082"], ["71264.00", "0.134"], ["71264.30", "0.000"], ["71264.40", "0.002"], ["71264.60", "0.286"], ["71264.80", "0.000"], ["71264.90", "0.232"], ["71265.00", "0.002"], ["71265.10", "0.005"], ["71265.20", "0.020"], ["71265.30", "0.786"], ["71265.40", "0.039"], ["71265.50", "0.000"], ["71265.60", "0.020"], ["71265.70", "0.001"], ["71265.90", "0.031"], ["71266.00", "0.010"], ["71266.10", "0.414"], ["71266.20", "0.118"], ["71266.30", "0.134"], ["71266.60", "0.000"], ["71266.70", "0.004"], ["71266.80", "0.022"], ["71266.90", "0.002"], ["71267.00", "0.008"], ["71267.10", "0.003"], ["71267.20", "0.271"], ["71267.30", "0.002"], ["71267.40", "0.005"], ["71267.50", "0.001"], ["71267.90", "0.002"], ["71268.20", "0.344"], ["71268.30", "0.000"], ["71268.80", "1.259"], ["71269.10", "0.028"], ["71269.20", "0.004"], ["71269.30", "0.232"], ["71269.40", "0.007"], ["71269.50", "0.007"], ["71269.80", "0.059"], ["71269.90", "0.241"], ["71270.20", "0.003"], ["71270.30", "0.000"], ["71270.40", "0.000"], ["71270.50", "0.002"], ["71270.80", "0.003"], ["71271.00", "0.000"], ["71271.20", "0.006"], ["71271.30", "0.006"], ["71271.70", "0.007"], ["71272.10", "0.000"], ["71272.20", "0.005"], ["71272.40", "0.000"], ["71272.50", "0.510"], ["71272.70", "0.002"], ["71272.80", "0.002"], ["71272.90", "0.008"], ["71273.00", "0.031"], ["71273.20", "0.145"], ["71273.30", "0.817"], ["71273.40", "0.008"], ["71273.80", "0.028"], ["71274.00", "0.006"], ["71274.30", "0.003"], ["71274.50", "0.003"], ["71274.60", "0.007"], ["71274.70", "0.510"], ["71274.80", "1.387"], ["71275.00", "0.056"], ["71275.20", "0.092"], ["71275.30", "0.044"], ["71275.40", "0.005"], ["71275.50", "0.000"], ["71275.70", "0.005"], ["71275.90", "0.000"], ["71276.00", "0.323"], ["71276.10", "0.078"], ["71276.20", "0.000"], ["71276.60", "0.001"], ["71277.00", "0.041"], ["71277.10", "0.706"], ["71277.50", "0.014"], ["71277.60", "0.013"], ["71278.40", "0.000"], ["71278.90", "0.004"], ["71279.00", "0.004"], ["71279.40", "0.317"], ["71279.60", "0.575"], ["71279.70", "0.005"], ["71280.00", "0.061"], ["71280.20", "0.434"], ["71280.30", "0.010"], ["71280.40", "0.366"], ["71281.00", "0.005"], ["71281.10", "0.003"], ["71281.40", "0.050"], ["71281.60", "0.050"], ["71281.70", "0.000"], ["71281.80", "0.005"], ["71282.80", "0.485"], ["71284.00", "0.005"], ["71284.90", "1.070"], ["71285.00", "0.003"], ["71285.20", "0.001"], ["71285.30", "0.005"], ["71285.40", "0.004"], ["71285.60", "0.342"], ["71285.80", "0.792"], ["71286.10", "0.001"], ["71286.30", "0.286"], ["71286.50", "1.203"], ["71286.60", "0.002"], ["71286.80", "0.015"], ["71286.90", "0.002"], ["71287.00", "0.003"], ["71287.20", "0.089"], ["71287.30", "0.007"], ["71287.70", "0.285"], ["71287.80", "0.075"], ["71288.00", "0.091"], ["71288.10", "0.082"], ["71288.30", "0.005"], ["71288.70", "0.322"], ["71288.80", "1.348"], ["71289.00", "0.008"], ["71289.10", "0.214"], ["71289.60", "7.714"], ["71290.50", "0.003"], ["71291.10", "0.002"], ["71291.20", "0.007"], ["71291.60", "0.000"], ["71291.70", "0.196"], ["71292.10", "0.007"], ["71292.20", "0.000"], ["71292.30", "0.022"], ["71292.40", "0.326"], ["71293.10", "0.075"], ["71293.60", "0.333"], ["71293.80", "0.002"], ["71294.00", "0.005"], ["71294.10", "0.004"], ["71294.30", "0.004"], ["71294.40", "0.047"], ["71294.70", "0.930"], ["71294.90", "1.561"], ["71295.00", "0.145"], ["71295.30", "0.085"], ["71295.70", "0.000"], ["71295.80", "0.001"], ["71296.30", "0.005"], ["71297.30", "0.002"], ["71297.90", "0.003"], ["71298.30", "0.004"], ["71298.50", "0.128"], ["71298.60", "0.677"], ["71298.80", "0.081"], ["71298.90", "0.004"], ["71299.20", "0.074"], ["71299.30", "0.068"], ["71299.50", "0.085"], ["71299.60", "1.072"], ["71299.70", "0.055"], ["71300.90", "0.000"], ["71301.40", "0.362"], ["71301.50", "0.003"], ["71301.80", "0.002"], ["71302.00", "0.397"], ["71302.10", "0.105"], ["71302.40", "0.081"], ["71302.50", "0.000"], ["71303.00", "0.000"], ["71304.80", "0.000"], ["71306.00", "0.138"], ["71306.90", "0.284"], ["71307.40", "0.000"], ["71307.60", "1.104"], ["71308.60", "0.003"], ["71309.50", "0.005"], ["71309.70", "0.010"], ["71310.10", "0.004"], ["71311.10", "1.058"], ["71312.20", "0.000"], ["71312.30", "0.002"], ["71312.70", "0.004"], ["71313.70", "0.002"], ["71314.90", "0.741"], ["71315.40", "0.002"], ["71315.70", "0.008"], ["71316.80", "0.463"], ["71316.90", "0.002"], ["71317.50", "0.724"], ["71317.60", "0.002"], ["71318.80", "0.102"], ["71319.20", "0.002"], ["71319.30", "0.112"], ["71319.40", "0.000"], ["71321.20", "0.020"], ["71321.40", "0.005"], ["71322.00", "0.045"], ["71322.80", "0.000"], ["71322.90", "0.000"], ["71323.60", "0.049"], ["71323.70", "0.000"], ["71326.10", "0.016"], ["71326.40", "0.012"], ["71326.50", "0.003"], ["71327.10", "0.311"], ["71327.30", "0.626"], ["71330.60", "1.729"], ["71330.70", "0.079"], ["71331.00", "0.000"], ["71331.80", "0.449"], ["71333.10", "6.440"], ["71333.60", "0.000"], ["71333.70", "0.002"], ["71334.20", "0.173"], ["71334.50", "0.000"], ["71335.00", "0.293"], ["71337.20", "0.005"], ["71338.80", "0.014"], ["71339.30", "0.009"], ["71339.40", "0.000"], ["71339.90", "0.302"], ["71340.00", "0.508"], ["71340.20", "0.429"], ["71340.50", "0.177"], ["71340.60", "0.415"], ["71341.30", "2.898"], ["71342.50", "0.012"], ["71343.40", "0.002"], ["71343.50", "0.291"], ["71345.10", "0.105"], ["71346.70", "0.003"], ["71347.10", "0.000"], ["71348.30", "0.290"], ["71349.80", "0.002"], ["71351.80", "0.058"], ["71352.80", "2.215"], ["71354.90", "2.238"], ["71355.00", "0.273"], ["71355.50", "0.000"], ["71359.10", "0.055"], ["71361.00", "0.116"], ["71363.10", "0.000"], ["71364.90", "0.083"], ["71365.20", "0.002"], ["71368.10", "0.077"], ["71369.70", "0.155"], ["71370.10", "0.309"], ["71371.20", "0.000"], ["71372.20", "0.000"], ["71373.20", "0.002"], ["71375.50", "0.083"], ["71375.90", "1.081"], ["71378.00", "0.015"], ["71378.30", "0.284"], ["71382.00", "0.043"], ["71383.50", "0.100"], ["71384.60", "0.009"], ["71385.10", "0.041"], ["71385.40", "0.701"], ["71385.90", "0.295"], ["71388.00", "0.071"], ["71389.80", "0.009"], ["71392.20", "0.007"], ["71392.50", "0.202"], ["71399.30", "0.891"], ["71399.60", "0.154"], ["71401.20", "0.000"], ["71405.70", "0.246"], ["71406.40", "0.007"], ["71406.70", "0.004"], ["71408.20", "1.701"], ["71409.30", "0.044"], ["71412.80", "0.002"], ["71413.50", "0.007"], ["71413.80", "0.029"], ["71415.20", "0.052"], ["71415.30", "0.002"], ["71416.20", "0.000"], ["71419.00", "23.080"], ["71420.00", "0.466"], ["71420.60", "0.007"], ["71420.90", "10.000"], ["71421.30", "1.580"], ["71427.70", "0.007"], ["71428.00", "0.004"], ["71429.70", "0.002"], ["71431.30", "0.002"], ["71432.40", "0.040"], ["71434.90", "0.581"], ["71436.40", "0.000"], ["71446.20", "0.082"], ["71446.40", "2.942"], ["71452.10", "0.000"], ["71453.00", "0.000"], ["71456.30", "0.430"], ["71461.60", "0.002"], ["71467.30", "2.303"], ["71491.40", "0.004"], ["71499.10", "0.681"], ["71511.90", "0.000"], ["71513.00", "0.000"], ["71513.30", "0.194"], ["71513.50", "0.000"], ["71530.60", "0.000"], ["71531.60", "0.000"], ["71536.60", "0.000"], ["71546.60", "2.325"], ["71548.00", "5.612"], ["71551.40", "0.000"], ["71554.90", "0.282"], ["71561.00", "0.038"], ["71561.80", "0.002"], ["71575.60", "0.000"], ["71578.70", "0.000"], ["71636.00", "0.005"], ["71637.70", "0.002"], ["71641.60", "0.074"], ["71655.40", "0.002"], ["71660.20", "0.000"], ["71736.00", "0.016"], ["71957.90", "7.441"], ["71958.00", "0.124"], ["71961.30", "0.000"], ["71962.10", "0.000"], ["71963.30", "0.000"], ["71964.10", "0.000"], ["72245.40", "0.018"], ["72247.80", "1.098"], ["72248.00", "0.058"], ["72251.60", "1.378"], ["72252.10", "0.006"], ["72253.10", "0.000"], ["72254.10", "0.000"], ["72254.70", "0.002"], ["72255.00", "0.035"], ["72257.50", "0.000"], ["72267.80", "0.000"], ["72279.20", "0.000"], ["72284.70", "2.555"], ["72691.60", "0.000"], ["75569.10", "0.082"], ["75604.80", "0.000"], ["78336.60", "0.002"], ["89523.20", "0.000"], ["100000.00", "15.751"]]}}
{"local_ts": 1773384487365, "server_ts": 1773384487146, "data": {"e": "depthUpdate", "E": 1773384487147, "T": 1773384487146, "s": "BTCUSDT", "U": 10101336661515, "u": 10101336668622, "pu": 10101336661453, "b": [["1000.00", "27.892"], ["5000.00", "101.418"], ["20751.50", "0.099"], ["20843.90", "0.621"], ["20951.50", "0.198"], ["21143.90", "0.432"], ["67677.70", "0.002"], ["70502.40", "3.510"], ["70531.50", "0.002"], ["70887.70", "0.082"], ["71136.70", "0.098"], ["71147.20", "0.015"], ["71181.00", "0.194"], ["71181.50", "0.042"], ["71197.00", "0.002"], ["71197.80", "0.001"], ["71198.10", "0.005"], ["71204.00", "0.023"], ["71211.00", "0.002"], ["71217.30", "0.084"], ["71218.00", "0.935"], ["71221.60", "0.510"], ["71225.00", "0.024"], ["71226.10", "0.005"], ["71227.40", "0.390"], ["71231.10", "0.043"], ["71233.20", "0.002"], ["71236.50", "0.409"], ["71236.70", "0.038"], ["71236.80", "0.056"], ["71237.30", "0.002"], ["71238.00", "0.008"], ["71239.20", "0.003"], ["71241.30", "0.004"]], "a": [["71244.00", "5.302"], ["71246.00", "0.002"], ["71247.40", "0.011"], ["71247.80", "0.006"], ["71249.20", "0.005"], ["71249.40", "0.004"], ["71251.00", "0.143"], ["71251.10", "0.718"], ["71251.20", "0.469"], ["71256.40", "0.005"], ["71267.00", "0.008"], ["71273.20", "0.058"], ["71274.00", "0.006"], ["71281.00", "0.005"], ["71283.90", "0.000"], ["71288.00", "0.091"], ["71288.20", "0.140"], ["71292.80", "0.025"], ["71293.20", "0.010"], ["71340.60", "0.203"], ["71956.40", "0.000"], ["72277.00", "2.978"], ["72319.10", "0.000"], ["74808.60", "0.000"], ["74814.10", "0.002"]]}}
{"local_ts": 1773384488387, "server_ts": 1773384488168, "data": {"e": "depthUpdate", "E": 1773384488169, "T": 1773384488168, "s": "BTCUSDT", "U": 10101336749280, "u": 10101336757092, "pu": 10101336749174, "b": [["5000.00", "101.418"], ["20743.90", "0.351"], ["20843.90", "1.449"], ["20943.90", "0.000"], ["21043.90", "0.297"], ["21143.90", "0.603"], ["56995.00", "0.000"], ["70244.00", "18.269"], ["70531.50", "0.002"], ["71096.30", "0.002"], ["71137.50", "0.020"], ["71181.00", "0.031"], ["71184.50", "0.796"], ["71187.80", "0.184"], ["71192.10", "0.590"], ["71198.20", "0.004"], ["71198.30", "0.051"], ["71202.40", "0.115"], ["71203.40", "0.508"], ["71205.40", "0.043"], ["71206.30", "0.042"], ["71231.20", "0.042"], ["71231.30", "0.000"], ["71233.90", "0.001"], ["71234.20", "0.009"], ["71234.30", "0.004"], ["71234.70", "0.042"], ["71236.70", "0.036"], ["71236.80", "0.028"], ["71241.10", "0.024"], ["71242.00", "0.003"], ["71243.90", "0.825"]], "a": [["71244.00", "5.465"], ["71244.10", "0.071"], ["71251.00", "0.012"], ["71251.10", "0.651"], ["71262.20", "0.354"], ["71272.30", "0.144"], ["71277.20", "0.631"], ["71283.20", "0.942"], ["71284.00", "0.019"], ["71294.50", "0.655"], ["71302.10", "0.105"], ["71956.40", "0.000"], ["72134.60", "4.862"], ["72170.20", "5.488"], ["72176.40", "0.000"], ["72212.00", "8.228"], ["72512.30", "0.000"], ["74837.60", "0.002"]]}}
{"local_ts": 1773384489408, "server_ts": 1773384489190, "data": {"e": "depthUpdate", "E": 1773384489191, "T": 1773384489190, "s": "BTCUSDT", "U": 10101336816774, "u": 10101336823010, "pu": 10101336816729, "b": [["1000.00", "27.742"], ["5000.00", "101.418"], ["20743.90", "1.548"], ["20843.90", "0.081"], ["20943.90", "0.162"], ["21043.90", "0.738"], ["21143.90", "0.171"], ["67688.90", "0.000"], ["67689.00", "0.011"], ["70191.30", "0.000"], ["70531.50", "0.002"], ["70566.40", "0.011"], ["71083.90", "13.460"], ["71146.40", "7.250"], ["71148.40", "0.070"], ["71155.50", "0.071"], ["71162.60", "0.070"], ["71184.00", "3.504"], ["71187.80", "0.000"], ["71207.30", "1.914"], ["71208.30", "0.001"], ["71236.80", "0.056"], ["71239.20", "0.003"], ["71241.30", "0.004"]], "a": [["71247.90", "0.018"], ["71251.10", "0.070"], ["71260.70", "0.020"], ["71262.20", "0.354"], ["71272.80", "0.572"], ["71277.20", "0.546"], ["71279.60", "0.655"], ["71284.00", "0.015"], ["71285.40", "0.006"], ["71285.60", "2.213"], ["71292.60", "0.015"], ["71292.80", "0.023"], ["71308.90", "3.634"], ["71315.40", "0.004"], ["71326.60", "0.070"], ["71333.70", "0.004"], ["71346.70", "6.668"], ["71352.80", "1.187"], ["71362.20", "0.080"], ["71408.90", "12.466"], ["71436.40", "0.159"], ["71956.40", "0.000"], ["74830.40", "0.000"]]}}
{"local_ts": 1773384490432, "server_ts": 1773384490212, "data": {"e": "depthUpdate", "E": 1773384490213, "T": 1773384490212, "s": "BTCUSDT", "U": 10101336878594, "u": 10101336886377, "pu": 10101336878489, "b": [["1000.00", "27.492"], ["5000.00", "101.418"], ["20743.90", "0.216"], ["20843.90", "0.036"], ["20943.90", "0.864"], ["21043.90", "0.036"], ["21143.90", "1.548"], ["33000.00", "9.339"], ["67681.00", "0.000"], ["69911.60", "0.357"], ["70211.00", "2.139"], ["70306.40", "0.710"], ["70531.50", "0.002"], ["70887.70", "0.082"], ["71171.00", "1.204"], ["71176.80", "0.000"], ["71198.60", "0.103"], ["71198.80", "0.046"], ["71210.00", "0.254"], ["71212.10", "0.031"], ["71217.50", "0.110"], ["71218.70", "0.075"], ["71223.90", "0.084"], ["71225.00", "1.217"], ["71227.70", "0.003"], ["71228.20", "0.175"], ["71229.10", "0.000"], ["71230.90", "0.000"], ["71232.50", "0.162"], ["71232.70", "0.004"], ["71233.20", "0.002"], ["71233.60", "0.548"], ["71233.80", "0.078"], ["71236.70", "0.036"], ["71237.30", "0.508"], ["71241.10", "0.032"], ["71242.20", "0.000"], ["71243.10", "0.032"], ["71243.80", "0.056"], ["71243.90", "1.144"]], "a": [["71244.00", "5.859"], ["71244.30", "0.000"], ["71245.00", "0.005"], ["71245.10", "0.017"], ["71245.20", "0.000"], ["71245.30", "0.031"], ["71246.40", "0.018"], ["71247.30", "0.000"], ["71247.60", "0.015"], ["71248.50", "0.003"], ["71248.90", "0.016"], ["71249.80", "0.004"], ["71250.10", "0.015"], ["71251.00", "0.012"], ["71251.10", "0.066"], ["71251.40", "0.666"], ["71252.30", "0.003"], ["71252.60", "0.017"], ["71253.20", "0.002"], ["71253.30", "0.126"], ["71253.60", "0.004"], ["71253.90", "0.015"], ["71254.00", "0.042"], ["71254.90", "0.019"], ["71267.60", "0.008"], ["71268.40", "0.000"], ["71269.70", "0.003"], ["71277.80", "0.598"], ["71285.40", "0.004"], ["71286.10", "0.003"], ["71290.10", "0.002"], ["71291.20", "0.009"], ["71292.00", "0.006"], ["71292.30", "0.122"], ["71956.40", "0.000"], ["72077.60", "0.554"], ["72191.60", "0.028"], ["74828.10", "0.002"]]}}
{"local_ts": 1773384491455, "server_ts": 1773384491236, "data": {"e": "depthUpdate", "E": 1773384491237, "T": 1773384491236, "s": "BTCUSDT", "U": 10101336957466, "u": 10101336969560, "pu": 10101336957331, "b": [["5000.00", "101.418"], ["20843.90", "0.801"], ["20943.90", "0.099"], ["21043.90", "1.359"], ["21143.90", "0.441"], ["67651.70", "0.002"], ["68394.20", "0.002"], ["69819.10", "0.009"], ["69997.10", "1.141"], ["70531.50", "0.002"], ["71176.20", "0.139"], ["71197.00", "0.006"], ["71198.80", "0.044"], ["71199.00", "0.608"], ["71201.50", "0.051"], ["71203.10", "0.000"], ["71204.00", "0.023"], ["71206.30", "0.000"], ["71207.20", "0.000"], ["71208.20", "0.016"], ["71208.30", "0.029"], ["71209.20", "0.006"], ["71209.90", "0.333"], ["71210.00", "0.009"], ["71211.00", "0.002"], ["71211.10", "0.248"], ["71212.10", "0.031"], ["71212.40", "0.110"], ["71212.80", "0.002"], ["71213.60", "0.002"], ["71214.70", "0.103"], ["71214.90", "0.001"], ["71215.60", "0.070"], ["71216.10", "0.032"], ["71216.50", "0.008"], ["71216.60", "0.367"], ["71217.30", "0.043"], ["71217.60", "0.106"], ["71218.00", "0.935"], ["71218.60", "0.250"], ["71219.80", "0.002"], ["71220.00", "0.053"], ["71220.10", "0.029"], ["71221.10", "0.045"], ["71221.80", "0.032"], ["71222.30", "0.000"], ["71222.40", "0.017"], ["71222.50", "0.118"], ["71222.80", "0.044"], ["71223.10", "0.032"], ["71223.50", "0.341"], ["71223.60", "0.000"], ["71223.70", "0.056"], ["71223.90", "1.277"], ["71224.00", "0.016"], ["71224.20", "0.000"], ["71224.40", "0.004"], ["71224.80", "0.017"], ["71225.00", "0.039"], ["71225.10", "0.000"], ["71225.50", "0.654"], ["71225.80", "0.758"], ["71226.10", "0.012"], ["71226.30", "0.017"], ["71226.80", "0.001"], ["71227.30", "0.034"], ["71227.40", "0.394"], ["71227.50", "0.087"], ["71227.80", "0.403"], ["71228.70", "0.029"], ["71228.80", "0.018"], ["71228.90", "0.510"], ["71229.20", "0.480"], ["71229.40", "0.328"], ["71230.00", "0.024"], ["71230.10", "0.132"], ["71230.40", "0.000"], ["71232.50", "0.147"], ["71232.90", "0.015"], ["71233.40", "0.093"], ["71233.80", "0.063"], ["71233.90", "0.001"], ["71234.20", "0.009"], ["71234.60", "0.024"], ["71234.70", "0.000"], ["71235.00", "0.034"], ["71235.10", "0.018"], ["71235.30", "0.042"], ["71235.80", "0.010"], ["71236.30", "0.074"], ["71236.60", "0.061"], ["71236.70", "0.078"], ["71236.80", "0.035"], ["71237.10", "0.003"], ["71237.30", "0.508"], ["71237.60", "0.005"], ["71238.10", "0.065"], ["71239.00", "0.097"], ["71239.50", "0.001"], ["71240.00", "0.010"], ["71240.60", "0.001"], ["71241.10", "0.001"], ["71241.30", "0.004"], ["71242.10", "0.067"], ["71242.80", "0.000"], ["71243.80", "0.056"], ["71243.90", "0.676"]], "a": [["71244.00", "5.918"], ["71244.10", "0.071"], ["71244.40", "0.000"], ["71244.50", "0.000"], ["71244.80", "0.004"], ["71245.00", "0.003"], ["71245.20", "0.015"], ["71245.30", "0.002"], ["71245.50", "0.212"], ["71246.60", "0.002"], ["71251.00", "0.012"], ["71254.10", "0.016"], ["71254.20", "0.032"], ["71254.30", "0.128"], ["71254.50", "0.020"], ["71255.40", "0.050"], ["71256.60", "0.017"], ["71258.20", "0.180"], ["71258.70", "0.051"], ["71259.90", "0.107"], ["71260.80", "0.001"], ["71261.20", "0.635"], ["71261.30", "0.000"], ["71263.80", "0.000"], ["71264.80", "0.070"], ["71265.80", "0.000"], ["71266.00", "0.010"], ["71266.90", "0.247"], ["71267.00", "0.008"], ["71268.00", "0.007"], ["71272.50", "1.221"], ["71274.00", "0.008"], ["71277.70", "0.001"], ["71279.60", "0.880"], ["71281.00", "0.075"], ["71285.90", "0.007"], ["71286.10", "0.001"], ["71288.00", "0.091"], ["71290.60", "0.004"], ["71291.20", "0.007"], ["71291.80", "0.104"], ["71291.90", "0.007"], ["71295.00", "0.145"], ["71325.90", "0.348"], ["71366.80", "0.195"], ["71371.20", "0.000"], ["71470.80", "0.512"], ["71470.90", "0.000"], ["71635.70", "0.008"], ["71956.40", "0.000"], ["72490.80", "2.827"], ["72668.80", "1.401"], ["72676.60", "0.002"]]}}
{"local_ts": 1773384492478, "server_ts": 1773384492260, "data": {"e": "depthUpdate", "E": 1773384492261, "T": 1773384492260, "s": "BTCUSDT", "U": 10101337078781, "u": 10101337087723, "pu": 10101337078592, "b": [["1000.00", "27.492"], ["5000.00", "101.418"], ["20743.90", "0.666"], ["20843.90", "0.234"], ["20943.90", "1.098"], ["21043.90", "0.702"], ["33000.00", "9.343"], ["67647.90", "0.002"], ["67671.30", "0.000"], ["70531.50", "1.418"], ["70887.70", "0.082"], ["71136.50", "0.043"], ["71143.10", "0.043"], ["71188.70", "0.061"], ["71197.00", "0.070"], ["71198.20", "0.004"], ["71198.40", "0.054"], ["71199.60", "0.001"], ["71201.10", "0.106"], ["71201.80", "0.102"], ["71201.90", "0.024"], ["71202.10", "0.516"], ["71203.30", "0.001"], ["71203.60", "0.106"], ["71203.90", "0.051"], ["71204.60", "0.051"], ["71204.70", "0.018"], ["71205.60", "0.002"], ["71206.20", "0.020"], ["71206.80", "0.003"], ["71207.60", "0.000"], ["71207.90", "0.000"], ["71209.00", "0.024"], ["71210.00", "0.009"], ["71211.90", "0.780"], ["71212.90", "0.330"], ["71213.40", "0.047"], ["71214.40", "0.029"], ["71215.40", "0.420"], ["71216.70", "0.054"], ["71217.20", "0.048"], ["71217.30", "0.014"], ["71218.70", "0.145"], ["71218.90", "0.005"], ["71220.00", "0.011"], ["71221.20", "0.042"], ["71222.50", "0.118"], ["71222.70", "0.008"], ["71222.90", "0.046"], ["71223.50", "0.024"], ["71223.60", "1.193"], ["71224.20", "0.042"], ["71224.60", "0.032"], ["71224.70", "0.001"], ["71224.90", "0.000"], ["71225.90", "0.843"], ["71226.00", "0.069"], ["71228.00", "0.033"], ["71229.60", "0.811"], ["71230.00", "0.038"], ["71230.50", "0.397"], ["71231.80", "0.046"], ["71232.10", "0.000"], ["71232.20", "0.006"], ["71233.00", "0.033"], ["71233.10", "0.794"], ["71233.20", "0.141"], ["71233.80", "0.063"], ["71233.90", "0.001"], ["71234.50", "0.234"], ["71235.10", "0.018"], ["71235.40", "0.023"], ["71235.90", "0.030"], ["71236.10", "0.043"], ["71236.70", "0.061"], ["71236.80", "0.056"], ["71237.00", "0.007"], ["71237.70", "0.032"], ["71238.30", "0.033"], ["71238.60", "0.001"], ["71238.70", "0.003"], ["71239.50", "0.016"], ["71241.00", "0.018"], ["71241.10", "0.001"], ["71241.70", "0.000"], ["71242.00", "0.045"], ["71242.60", "0.042"], ["71243.90", "0.747"]], "a": [["71244.00", "5.316"], ["71244.10", "0.071"], ["71251.00", "0.012"], ["71251.10", "0.065"], ["71258.90", "0.003"], ["71260.30", "0.469"], ["71260.50", "0.072"], ["71261.50", "0.036"], ["71262.20", "0.985"], ["71264.70", "0.372"], ["71265.00", "0.007"], ["71266.60", "0.070"], ["71266.90", "0.002"], ["71267.50", "0.001"], ["71268.10", "0.262"], ["71269.30", "0.926"], ["71272.50", "1.357"], ["71277.00", "0.117"], ["71283.00", "1.579"], ["71283.20", "0.942"], ["71285.10", "0.016"], ["71285.90", "0.005"], ["71290.10", "0.004"], ["71290.60", "0.002"], ["71325.90", "0.212"], ["71343.70", "2.042"], ["71956.40", "0.000"]]}}
{"local_ts": 1773384493501, "server_ts": 1773384493284, "data": {"e": "depthUpdate", "E": 1773384493285, "T": 1773384493284, "s": "BTCUSDT", "U": 10101337141293, "u": 10101337145877, "pu": 10101337141190, "b": [["5000.00", "101.418"], ["20743.90", "0.360"], ["20843.90", "0.828"], ["20943.90", "0.972"], ["21143.90", "0.540"], ["67651.00", "0.005"], ["67670.00", "0.005"], ["67689.00", "0.007"], ["69819.10", "0.018"], ["70241.00", "0.000"], ["70531.50", "1.418"], ["71133.20", "0.000"], ["71155.30", "0.054"], ["71186.80", "0.709"], ["71213.10", "0.250"], ["71214.20", "0.019"], ["71217.20", "0.118"], ["71217.60", "0.064"], ["71219.40", "0.000"], ["71220.10", "0.140"], ["71220.60", "0.025"], ["71221.80", "0.010"], ["71222.50", "0.116"], ["71225.60", "0.509"], ["71226.00", "0.069"], ["71227.00", "0.000"], ["71227.10", "0.000"], ["71227.90", "0.442"], ["71228.10", "0.175"], ["71233.20", "0.141"], ["71236.70", "0.061"], ["71241.40", "0.003"], ["71243.90", "3.753"]], "a": [["71244.00", "4.616"], ["71249.80", "0.004"], ["71249.90", "0.001"], ["71250.00", "0.006"], ["71250.60", "0.004"], ["71250.80", "0.126"], ["71251.00", "0.012"], ["71254.20", "0.003"], ["71255.40", "0.006"], ["71256.60", "0.142"], ["71256.70", "0.000"], ["71257.10", "0.000"], ["71260.20", "0.013"], ["71261.50", "0.000"], ["71264.20", "0.036"], ["71264.50", "0.070"], ["71264.70", "0.033"], ["71265.50", "0.015"], ["71265.90", "0.031"], ["71266.70", "0.019"], ["71267.20", "0.322"], ["71268.80", "0.509"], ["71269.70", "0.003"], ["71270.30", "0.512"], ["71271.80", "0.009"], ["71273.20", "0.054"], ["71277.00", "0.032"], ["71277.20", "0.511"], ["71290.10", "0.002"], ["71291.40", "0.264"], ["71294.20", "0.022"], ["71342.10", "0.202"], ["71364.20", "0.100"], ["71431.70", "3.791"], ["71431.80", "16.832"], ["71434.50", "0.019"], ["71460.10", "3.833"], ["71463.00", "0.017"], ["71956.40", "1.388"], ["73033.70", "2.461"]]}}
{"local_ts": 1773384494527, "server_ts": 1773384494308, "data": {"e": "depthUpdate", "E": 1773384494309, "T": 1773384494308, "s": "BTCUSDT", "U": 10101337188660, "u": 10101337193419, "pu": 10101337188580, "b": [["1000.00", "27.492"], ["5000.00", "101.418"], ["20743.90", "0.567"], ["20843.90", "1.233"], ["21043.90", "0.405"], ["21143.90", "0.495"], ["67671.10", "0.002"], ["70021.50", "0.000"], ["70139.30", "2.562"], ["70531.50", "1.418"], ["70916.60", "0.061"], ["71175.20", "0.002"], ["71185.80", "0.002"], ["71186.20", "3.583"], ["71197.70", "0.004"], ["71198.10", "0.003"], ["71216.20", "0.009"], ["71217.10", "0.089"], ["71226.30", "0.009"], ["71226.50", "0.507"], ["71227.90", "0.582"], ["71228.10", "0.035"], ["71228.20", "0.021"], ["71229.60", "0.813"], ["71230.50", "0.397"], ["71236.70", "0.061"], ["71237.70", "0.074"], ["71238.00", "0.004"], ["71239.00", "0.112"], ["71239.30", "0.005"], ["71239.50", "0.001"], ["71240.90", "0.028"], ["71242.30", "0.020"], ["71242.60", "0.000"], ["71243.80", "0.015"], ["71243.90", "2.856"]], "a": [["71244.00", "4.652"], ["71245.30", "0.019"], ["71246.10", "0.003"], ["71246.30", "0.000"], ["71246.60", "0.017"], ["71247.60", "0.000"], ["71247.80", "0.054"], ["71249.10", "0.015"], ["71250.10", "0.000"], ["71250.30", "0.015"], ["71251.00", "0.014"], ["71251.30", "0.022"], ["71251.60", "0.176"], ["71251.80", "0.000"], ["71252.00", "0.133"], ["71252.40", "0.031"], ["71252.60", "0.002"], ["71252.80", "0.016"], ["71253.80", "0.004"], ["71255.10", "0.003"], ["71256.10", "0.678"], ["71256.40", "0.005"], ["71256.60", "0.002"], ["71256.90", "0.145"], ["71257.60", "0.165"], ["71258.80", "0.064"], ["71258.90", "0.003"], ["71259.20", "0.379"], ["71260.70", "0.049"], ["71261.70", "0.003"], ["71262.10", "0.067"], ["71266.30", "0.141"], ["71267.10", "0.002"], ["71270.20", "0.003"], ["71270.60", "0.508"], ["71271.10", "0.000"], ["71272.50", "1.432"], ["71273.90", "0.044"], ["71277.00", "0.118"], ["71277.80", "0.600"], ["71282.60", "0.005"], ["71282.80", "0.226"], ["71291.40", "0.260"], ["71307.00", "0.513"], ["71308.90", "0.000"], ["71310.50", "3.672"], ["71332.80", "0.012"], ["71956.40", "1.388"], ["72066.20", "0.003"], ["72236.10", "0.002"]]}}
{"local_ts": 1773384495546, "server_ts": 1773384495327, "data": {"e": "depthUpdate", "E": 1773384495329, "T": 1773384495327, "s": "BTCUSDT", "U": 10101337246326, "u": 10101337252561, "pu": 10101337246142, "b": [["1000.00", "27.492"], ["5000.00", "101.418"], ["20743.90", "1.512"], ["20843.90", "0.000"], ["20943.90", "0.270"], ["21043.90", "0.630"], ["21143.90", "0.288"], ["69950.20", "1.000"], ["70068.40", "0.643"], ["70531.50", "1.418"], ["70545.70", "0.919"], ["70887.70", "0.117"], ["71148.30", "6.199"], ["71155.40", "0.000"], ["71162.50", "0.318"], ["71224.00", "0.002"], ["71224.90", "0.007"], ["71225.30", "0.084"], ["71226.10", "0.510"], ["71236.70", "0.061"], ["71236.80", "0.056"], ["71237.40", "0.073"], ["71243.90", "3.562"]], "a": [["71250.70", "0.000"], ["71251.00", "0.014"], ["71251.10", "0.066"], ["71251.50", "1.228"], ["71251.70", "0.075"], ["71251.90", "0.000"], ["71256.10", "0.649"], ["71256.60", "0.002"], ["71257.10", "0.000"], ["71257.60", "0.165"], ["71258.00", "0.052"], ["71258.40", "0.902"], ["71258.70", "0.000"], ["71260.20", "0.006"], ["71260.30", "0.338"], ["71260.50", "0.101"], ["71260.60", "0.043"], ["71260.70", "0.035"], ["71262.00", "0.019"], ["71262.80", "1.057"], ["71263.40", "0.632"], ["71264.30", "0.070"], ["71265.20", "0.526"], ["71266.30", "0.134"], ["71266.70", "0.011"], ["71277.00", "0.032"], ["71291.80", "0.104"], ["71291.90", "0.007"], ["71326.50", "0.003"], ["71333.60", "0.000"], ["71470.50", "0.008"], ["71956.20", "0.000"], ["71956.40", "1.388"], ["72206.20", "1.383"], ["74093.70", "0.002"], ["74840.90", "0.002"]]}}
{"local_ts": 1773384496569, "server_ts": 1773384496349, "data": {"e": "depthUpdate", "E": 1773384496351, "T": 1773384496349, "s": "BTCUSDT", "U": 10101337309096, "u": 10101337315173, "pu": 10101337309062, "b": [["5000.00", "101.458"], ["20743.90", "0.108"], ["20843.90", "0.135"], ["20943.90", "0.765"], ["21043.90", "0.135"], ["21143.90", "1.557"], ["69243.90", "0.003"], ["70531.50", "1.418"], ["70531.60", "0.000"], ["70969.20", "0.004"], ["70994.30", "0.000"], ["71168.60", "0.000"], ["71197.10", "0.592"], ["71197.70", "0.004"], ["71216.10", "0.083"], ["71217.10", "0.019"], ["71217.20", "0.006"], ["71218.10", "0.358"], ["71218.50", "0.453"], ["71219.00", "0.517"], ["71220.50", "0.077"], ["71221.20", "0.000"], ["71223.90", "0.126"], ["71224.60", "0.003"], ["71225.40", "0.203"], ["71225.50", "1.216"], ["71226.30", "0.514"], ["71227.00", "0.015"], ["71227.90", "0.162"], ["71228.10", "0.666"], ["71228.80", "0.003"], ["71229.30", "0.145"], ["71229.40", "0.286"], ["71230.90", "0.002"], ["71232.60", "0.042"], ["71233.30", "0.034"], ["71233.80", "0.101"], ["71233.90", "0.001"], ["71236.80", "0.028"], ["71237.40", "0.031"], ["71238.00", "0.017"], ["71242.40", "0.003"], ["71242.70", "0.015"], ["71243.00", "0.004"], ["71243.80", "0.090"], ["71243.90", "4.171"]], "a": [["71244.00", "4.304"], ["71245.00", "0.003"], ["71245.30", "0.004"], ["71246.20", "0.000"], ["71246.70", "0.002"], ["71247.50", "0.002"], ["71247.80", "0.067"], ["71248.30", "0.007"], ["71248.70", "0.000"], ["71249.60", "0.009"], ["71250.00", "0.006"], ["71250.90", "0.001"], ["71251.10", "0.000"], ["71251.20", "0.469"], ["71251.40", "0.130"], ["71252.10", "0.000"], ["71252.50", "0.000"], ["71253.70", "0.000"], ["71253.80", "0.004"], ["71254.70", "0.017"], ["71254.90", "0.002"], ["71255.00", "0.004"], ["71256.00", "0.029"], ["71256.10", "0.649"], ["71256.30", "0.080"], ["71257.00", "0.043"], ["71257.20", "0.076"], ["71257.50", "0.002"], ["71257.80", "0.003"], ["71257.90", "0.141"], ["71258.50", "0.020"], ["71259.20", "0.283"], ["71259.40", "0.004"], ["71259.70", "0.017"], ["71260.60", "0.036"], ["71260.90", "0.003"], ["71261.00", "0.015"], ["71261.50", "0.007"], ["71261.80", "0.002"], ["71262.10", "0.038"], ["71262.20", "0.391"], ["71262.30", "0.022"], ["71262.70", "0.511"], ["71263.40", "0.001"], ["71263.50", "0.022"], ["71264.00", "0.639"], ["71264.30", "0.000"], ["71264.50", "0.000"], ["71264.70", "0.000"], ["71264.80", "0.015"], ["71265.30", "0.640"], ["71266.00", "0.025"], ["71266.60", "0.000"], ["71266.70", "0.004"], ["71267.00", "0.006"], ["71267.10", "0.031"], ["71267.20", "0.252"], ["71267.30", "0.009"], ["71268.30", "0.070"], ["71268.50", "0.034"], ["71269.70", "0.032"], ["71269.80", "0.053"], ["71270.40", "0.245"], ["71271.00", "0.029"], ["71271.10", "0.505"], ["71272.20", "0.345"], ["71272.50", "0.952"], ["71272.80", "0.002"], ["71273.50", "0.232"], ["71274.30", "0.403"], ["71274.70", "0.538"], ["71276.00", "0.352"], ["71277.20", "0.540"], ["71281.80", "0.005"], ["71282.50", "0.028"], ["71282.60", "0.005"], ["71291.40", "0.260"], ["71291.50", "0.004"], ["71322.40", "0.087"], ["71325.90", "0.646"], ["71343.90", "0.548"], ["71956.40", "1.388"], ["71957.10", "0.009"], ["72388.10", "0.414"], ["72455.10", "3.411"], ["72668.80", "1.386"], ["74821.40", "0.002"]]}}
{"local_ts": 1773384497593, "server_ts": 1773384497372, "data": {"e": "depthUpdate", "E": 1773384497373, "T": 1773384497372, "s": "BTCUSDT", "U": 10101337439446, "u": 10101337448209, "pu": 10101337439387, "b": [["1000.00", "27.492"], ["5000.00", "101.418"], ["20837.70", "0.126"], ["20943.90", "0.000"], ["21037.70", "0.252"], ["21143.90", "0.243"], ["67658.60", "0.002"], ["67669.00", "0.000"], ["69813.00", "0.009"], ["69968.00", "0.002"], ["70271.00", "0.015"], ["70525.30", "0.003"], ["70667.80", "0.060"], ["70882.80", "2.428"], ["70887.70", "0.143"], ["70950.60", "0.002"], ["70968.00", "0.002"], ["71036.80", "0.017"], ["71040.30", "0.003"], ["71056.10", "0.054"], ["71060.10", "0.136"], ["71071.50", "0.000"], ["71077.50", "0.056"], ["71086.40", "0.320"], ["71092.10", "0.172"], ["71092.50", "0.025"], ["71093.20", "0.350"], ["71093.50", "0.001"], ["71112.10", "0.003"], ["71118.40", "0.000"], ["71140.20", "0.225"], ["71146.40", "0.375"], ["71147.70", "0.261"], ["71153.00", "0.003"], ["71154.00", "0.002"], ["71159.20", "0.269"], ["71159.40", "0.073"], ["71175.40", "0.016"], ["71178.10", "1.557"], ["71180.40", "0.607"], ["71181.30", "0.029"], ["71183.30", "0.045"], ["71189.60", "0.786"], ["71190.40", "0.043"], ["71190.60", "0.254"], ["71190.80", "0.026"], ["71197.70", "0.051"], ["71198.50", "0.521"], ["71201.50", "0.042"], ["71202.60", "0.119"], ["71204.30", "0.002"], ["71204.50", "0.013"], ["71206.70", "0.082"], ["71207.70", "0.186"], ["71207.80", "0.015"], ["71208.60", "0.007"], ["71209.10", "0.018"], ["71209.90", "0.333"], ["71212.30", "0.003"], ["71214.60", "0.003"], ["71215.00", "0.054"], ["71215.20", "0.006"], ["71216.20", "0.376"], ["71216.50", "0.041"], ["71217.10", "1.220"], ["71219.00", "0.342"], ["71219.30", "0.008"], ["71219.40", "0.010"], ["71219.70", "0.008"], ["71219.90", "0.144"], ["71220.50", "0.146"], ["71220.80", "0.286"], ["71222.40", "0.299"], ["71223.60", "0.000"], ["71224.00", "0.222"], ["71224.60", "0.045"], ["71225.90", "0.203"], ["71226.50", "0.114"], ["71226.80", "0.101"], ["71227.00", "0.141"], ["71227.50", "0.061"], ["71228.50", "0.006"], ["71230.00", "0.010"], ["71237.70", "0.194"]], "a": [["71237.80", "9.103"], ["71237.90", "0.072"], ["71239.10", "0.458"], ["71241.50", "0.130"], ["71241.70", "0.003"], ["71242.40", "0.021"], ["71243.30", "0.011"], ["71244.10", "0.006"], ["71247.40", "0.051"], ["71249.20", "0.085"], ["71249.40", "0.146"], ["71250.10", "0.002"], ["71250.40", "0.006"], ["71250.70", "0.003"], ["71251.20", "0.589"], ["71251.50", "1.100"], ["71252.80", "0.008"], ["71254.40", "0.068"], ["71255.10", "0.178"], ["71255.50", "0.210"], ["71257.00", "1.162"], ["71257.50", "0.129"], ["71259.90", "0.000"], ["71260.00", "0.083"], ["71260.10", "0.509"], ["71260.30", "0.235"], ["71260.60", "0.000"], ["71261.00", "0.000"], ["71261.40", "0.013"], ["71262.00", "0.054"], ["71262.40", "0.004"], ["71265.30", "0.568"], ["71265.40", "0.021"], ["71265.80", "0.000"], ["71270.30", "0.000"], ["71270.70", "0.045"], ["71272.00", "0.014"], ["71272.30", "0.091"], ["71273.40", "0.244"], ["71276.60", "0.022"], ["71282.50", "0.000"], ["71282.70", "0.005"], ["71285.60", "1.857"], ["71287.10", "0.011"], ["71289.10", "0.209"], ["71289.80", "0.002"], ["71294.10", "0.004"], ["71294.70", "0.877"], ["71300.00", "3.452"], ["71301.10", "0.000"], ["71316.00", "0.211"], ["71316.70", "0.293"], ["71317.30", "0.319"], ["71318.00", "0.000"], ["71323.30", "0.456"], ["71330.40", "0.077"], ["71332.10", "0.213"], ["71336.80", "0.006"], ["71362.30", "6.469"], ["71366.10", "0.003"], ["71372.50", "0.053"], ["71375.90", "0.004"], ["71379.70", "0.042"], ["71407.00", "0.046"], ["71422.20", "0.002"], ["71451.20", "0.000"], ["71463.40", "0.896"], ["71950.20", "0.693"], ["72343.30", "1.635"], ["72379.30", "0.000"], ["72510.90", "1.094"], ["72675.90", "1.648"], ["74812.10", "0.000"], ["74817.50", "0.052"], ["89523.20", "0.000"]]}}
{"local_ts": 1773384498612, "server_ts": 1773384498393, "data": {"e": "depthUpdate", "E": 1773384498395, "T": 1773384498393, "s": "BTCUSDT", "U": 10101337528977, "u": 10101337536026, "pu": 10101337528968, "b": [["5000.00", "101.418"], ["20736.50", "0.099"], ["20839.00", "0.009"], ["20936.50", "0.216"], ["21039.00", "0.009"], ["56990.20", "0.002"], ["69918.50", "0.713"], ["69999.00", "3.228"], ["70203.90", "2.699"], ["70239.50", "0.006"], ["70524.10", "0.002"], ["70714.70", "0.021"], ["70755.40", "0.000"], ["70913.70", "0.061"], ["70945.70", "0.000"], ["70950.10", "0.002"], ["70950.60", "0.000"], ["70958.70", "1.614"], ["70981.70", "6.469"], ["70994.40", "0.022"], ["71044.70", "0.111"], ["71074.90", "0.006"], ["71090.10", "0.526"], ["71094.30", "0.000"], ["71125.30", "0.008"], ["71130.10", "0.104"], ["71135.80", "2.692"], ["71136.40", "0.000"], ["71138.20", "0.714"], ["71153.90", "0.869"], ["71154.60", "1.202"], ["71158.10", "0.004"], ["71172.40", "0.177"], ["71173.00", "0.017"], ["71173.70", "0.038"], ["71174.00", "0.040"], ["71174.90", "0.016"], ["71175.30", "0.724"], ["71176.20", "0.000"], ["71176.90", "0.320"], ["71180.90", "0.050"], ["71182.50", "0.464"], ["71183.80", "0.309"], ["71185.40", "0.019"], ["71190.00", "0.019"], ["71190.20", "0.003"], ["71190.40", "0.004"], ["71190.70", "0.003"], ["71190.80", "0.028"], ["71192.70", "0.216"], ["71195.70", "0.002"], ["71197.10", "0.117"], ["71197.50", "1.069"], ["71197.90", "0.035"], ["71199.90", "0.042"], ["71202.10", "0.544"], ["71203.00", "0.389"], ["71203.50", "1.049"], ["71204.40", "0.997"], ["71204.70", "0.018"], ["71206.50", "0.004"], ["71207.40", "0.322"], ["71207.80", "0.011"], ["71208.10", "0.071"], ["71208.20", "0.025"], ["71208.60", "0.003"], ["71208.80", "0.008"], ["71208.90", "0.019"], ["71209.00", "0.045"], ["71209.30", "0.011"], ["71209.40", "5.246"], ["71209.80", "0.074"], ["71210.00", "0.432"], ["71211.10", "0.073"], ["71213.60", "0.044"], ["71214.00", "0.358"], ["71215.50", "0.005"], ["71215.90", "0.005"], ["71216.30", "0.001"], ["71216.40", "0.009"], ["71217.00", "0.002"], ["71217.10", "0.009"], ["71217.40", "0.010"], ["71217.50", "0.637"], ["71218.20", "0.364"], ["71218.30", "1.193"], ["71218.40", "0.007"], ["71218.90", "0.002"], ["71219.00", "0.678"], ["71219.40", "0.003"], ["71219.50", "0.004"], ["71219.70", "0.002"], ["71220.20", "0.403"], ["71220.50", "0.006"], ["71220.60", "0.012"], ["71221.60", "0.871"], ["71222.00", "0.287"], ["71222.30", "0.334"], ["71222.70", "0.312"], ["71222.80", "0.004"], ["71222.90", "0.068"], ["71223.60", "0.042"], ["71224.10", "0.002"], ["71224.40", "0.002"], ["71225.50", "0.003"], ["71225.80", "0.551"], ["71226.00", "0.013"], ["71226.10", "0.553"], ["71226.20", "0.008"], ["71226.60", "0.149"], ["71226.70", "0.117"], ["71226.90", "0.101"], ["71228.50", "0.035"], ["71229.80", "0.005"], ["71230.70", "0.009"], ["71231.10", "0.000"], ["71231.40", "0.010"], ["71231.80", "0.009"], ["71233.20", "0.002"], ["71234.80", "0.053"], ["71235.20", "0.064"], ["71235.90", "0.000"], ["71236.40", "0.003"], ["71236.50", "2.363"]], "a": [["71236.60", "5.701"], ["71236.70", "0.172"], ["71236.80", "0.002"], ["71236.90", "0.210"], ["71237.70", "1.100"], ["71237.80", "0.483"], ["71237.90", "0.004"], ["71238.40", "0.006"], ["71238.80", "0.058"], ["71239.00", "1.105"], ["71239.10", "0.004"], ["71239.80", "0.001"], ["71240.40", "0.092"], ["71241.80", "0.152"], ["71242.00", "0.003"], ["71243.70", "0.001"], ["71243.80", "0.073"], ["71245.30", "0.005"], ["71245.90", "0.003"], ["71247.70", "0.647"], ["71247.80", "0.006"], ["71248.00", "0.002"], ["71249.50", "0.022"], ["71250.20", "0.005"], ["71250.40", "0.008"], ["71251.00", "0.146"], ["71251.20", "0.646"], ["71252.30", "0.002"], ["71252.60", "0.002"], ["71252.80", "0.001"], ["71253.30", "0.001"], ["71253.40", "0.010"], ["71253.50", "0.321"], ["71253.70", "0.001"], ["71253.90", "0.631"], ["71254.10", "0.008"], ["71254.50", "0.560"], ["71255.70", "0.008"], ["71256.90", "0.082"], ["71257.70", "0.073"], ["71259.10", "0.002"], ["71259.90", "0.040"], ["71260.10", "0.003"], ["71260.30", "0.264"], ["71261.10", "0.210"], ["71261.40", "0.012"], ["71261.70", "0.008"], ["71261.90", "0.003"], ["71262.40", "0.011"], ["71263.40", "0.000"], ["71264.10", "0.002"], ["71264.60", "0.013"], ["71266.10", "0.440"], ["71267.60", "0.000"], ["71268.40", "0.006"], ["71268.50", "0.005"], ["71268.60", "0.000"], ["71269.10", "0.004"], ["71269.20", "0.006"], ["71270.70", "0.063"], ["71272.20", "0.179"], ["71272.40", "0.311"], ["71273.40", "0.075"], ["71275.40", "0.060"], ["71280.20", "0.462"], ["71284.90", "0.021"], ["71285.50", "0.407"], ["71285.60", "0.014"], ["71285.70", "1.153"], ["71286.50", "1.225"], ["71287.00", "0.004"], ["71287.70", "0.002"], ["71289.40", "0.006"], ["71289.50", "0.079"], ["71289.60", "7.732"], ["71293.50", "0.232"], ["71293.60", "0.330"], ["71299.30", "0.010"], ["71299.80", "0.008"], ["71300.70", "0.047"], ["71301.30", "0.017"], ["71302.70", "0.443"], ["71303.30", "0.019"], ["71304.00", "0.002"], ["71306.90", "0.047"], ["71308.70", "0.006"], ["71308.80", "1.038"], ["71308.90", "0.023"], ["71311.40", "0.087"], ["71314.10", "0.000"], ["71315.00", "0.714"], ["71315.50", "1.519"], ["71322.10", "0.418"], ["71338.40", "0.121"], ["71348.30", "0.290"], ["71354.80", "0.003"], ["71379.00", "0.439"], ["71379.40", "0.003"], ["71409.80", "0.836"], ["71410.20", "0.003"], ["71425.40", "0.159"], ["71428.90", "0.411"], ["71432.50", "0.356"], ["71447.00", "0.002"], ["71447.70", "0.002"], ["71565.40", "0.061"], ["71597.70", "0.000"], ["71617.00", "0.125"], ["71650.90", "0.002"], ["71949.00", "3.192"], ["72165.20", "0.693"], ["72202.80", "0.000"], ["72209.20", "0.000"], ["74840.90", "0.000"], ["77922.60", "0.002"], ["89523.20", "0.000"]]}}
{"local_ts": 1773384499633, "server_ts": 1773384499416, "data": {"e": "depthUpdate", "E": 1773384499417, "T": 1773384499416, "s": "BTCUSDT", "U": 10101337581995, "u": 10101337586662, "pu": 10101337581875, "b": [["1000.00", "27.492"], ["5000.00", "101.418"], ["20737.70", "0.018"], ["20836.50", "1.026"], ["20937.70", "0.045"], ["21136.50", "0.639"], ["33000.00", "9.339"], ["56989.20", "0.000"], ["70274.80", "0.283"], ["70524.10", "0.000"], ["70916.90", "0.019"], ["70950.10", "0.000"], ["70952.70", "0.005"], ["71084.40", "0.646"], ["71096.00", "0.117"], ["71173.60", "3.551"], ["71173.70", "0.035"], ["71191.30", "0.327"], ["71191.40", "0.006"], ["71220.30", "0.002"], ["71220.70", "0.003"], ["71225.10", "0.042"], ["71226.80", "0.040"], ["71227.10", "0.029"], ["71227.50", "0.042"], ["71228.80", "0.001"], ["71236.50", "2.979"]], "a": [["71238.00", "0.002"], ["71240.80", "0.001"], ["71240.90", "0.129"], ["71261.90", "0.010"], ["71263.50", "0.005"], ["71272.00", "0.141"], ["71272.40", "0.000"], ["71286.50", "1.222"], ["71384.20", "0.406"], ["71394.10", "0.000"], ["71421.80", "0.000"], ["71949.00", "3.192"], ["72212.50", "2.866"], ["72310.30", "0.000"], ["72491.10", "3.448"], ["74804.50", "0.052"], ["89523.20", "0.000"]]}}
{"local_ts": 1773384500660, "server_ts": 1773384500441, "data": {"e": "depthUpdate", "E": 1773384500443, "T": 1773384500441, "s": "BTCUSDT", "U": 10101337640491, "u": 10101337644926, "pu": 10101337640190, "b": [["1000.00", "27.492"], ["5000.00", "101.418"], ["20736.50", "0.765"], ["20836.50", "1.035"], ["21036.50", "0.504"], ["21136.50", "0.396"], ["56989.20", "0.000"], ["69808.20", "0.000"], ["69918.60", "0.500"], ["70524.10", "0.354"], ["70952.70", "0.005"], ["71176.10", "0.080"], ["71178.70", "0.003"], ["71179.50", "0.012"], ["71180.00", "0.018"], ["71181.30", "0.942"], ["71182.60", "0.581"], ["71205.40", "0.005"], ["71205.70", "0.511"], ["71213.40", "0.086"], ["71215.50", "0.005"], ["71217.70", "0.508"], ["71219.10", "0.704"], ["71219.20", "0.087"], ["71219.90", "0.257"], ["71221.50", "0.154"], ["71221.80", "0.119"], ["71222.00", "0.005"], ["71222.30", "0.000"], ["71223.70", "0.066"], ["71224.90", "0.158"], ["71226.30", "0.031"], ["71227.80", "0.030"], ["71229.10", "0.029"], ["71230.00", "0.010"], ["71231.20", "0.000"], ["71231.40", "0.047"], ["71233.30", "0.083"], ["71234.00", "0.004"], ["71235.20", "0.037"], ["71236.50", "3.682"]], "a": [["71236.60", "3.622"], ["71239.40", "0.004"], ["71240.20", "0.000"], ["71240.60", "0.100"], ["71241.50", "0.004"], ["71241.80", "0.082"], ["71242.10", "0.000"], ["71244.30", "0.086"], ["71244.70", "0.000"], ["71246.20", "0.000"], ["71246.40", "0.003"], ["71247.60", "0.459"], ["71249.00", "0.003"], ["71250.10", "0.005"], ["71250.20", "0.061"], ["71250.80", "0.174"], ["71251.00", "0.146"], ["71251.10", "1.049"], ["71251.20", "0.646"], ["71251.30", "0.010"], ["71251.50", "0.171"], ["71252.60", "0.002"], ["71253.80", "0.002"], ["71254.40", "0.295"], ["71254.90", "0.631"], ["71255.10", "0.251"], ["71255.70", "0.010"], ["71256.40", "0.066"], ["71256.50", "0.009"], ["71257.00", "1.050"], ["71257.60", "0.017"], ["71258.30", "0.002"], ["71258.90", "0.018"], ["71259.40", "0.071"], ["71259.50", "0.005"], ["71260.10", "0.018"], ["71260.80", "0.001"], ["71261.40", "0.024"], ["71262.00", "0.003"], ["71262.60", "0.522"], ["71262.80", "1.060"], ["71263.00", "0.176"], ["71263.30", "0.003"], ["71263.90", "0.025"], ["71264.50", "0.000"], ["71272.30", "0.074"], ["71285.50", "0.407"], ["71285.70", "1.153"], ["71287.20", "0.058"], ["71327.60", "0.282"], ["71421.80", "0.000"], ["71463.50", "0.000"], ["71948.90", "0.000"], ["71949.00", "3.192"], ["74826.90", "0.000"], ["74834.00", "0.187"], ["89523.20", "0.000"]]}}
{"local_ts": 1773384501681, "server_ts": 1773384501464, "data": {"e": "depthUpdate", "E": 1773384501465, "T": 1773384501464, "s": "BTCUSDT", "U": 10101337686170, "u": 10101337693993, "pu": 10101337686043, "b": [["5000.00", "101.418"], ["20736.50", "1.296"], ["20936.50", "0.369"], ["21036.50", "0.531"], ["21136.50", "0.504"], ["33000.00", "9.343"], ["56989.00", "0.004"], ["56989.20", "0.000"], ["69810.10", "0.015"], ["70388.40", "0.000"], ["70524.10", "0.354"], ["70880.30", "0.035"], ["70952.70", "0.003"], ["71142.00", "0.103"], ["71143.60", "0.292"], ["71143.80", "0.270"], ["71169.90", "0.105"], ["71172.50", "0.110"], ["71174.20", "0.181"], ["71175.90", "0.015"], ["71183.40", "0.696"], ["71186.40", "0.015"], ["71187.70", "0.401"], ["71188.40", "0.101"], ["71190.80", "0.026"], ["71191.40", "0.008"], ["71193.80", "0.036"], ["71195.00", "0.032"], ["71196.30", "0.031"], ["71196.40", "0.044"], ["71197.30", "0.317"], ["71197.50", "1.098"], ["71198.30", "0.043"], ["71198.80", "0.034"], ["71199.30", "0.047"], ["71200.20", "0.047"], ["71201.20", "0.557"], ["71202.20", "0.428"], ["71202.50", "0.000"], ["71203.20", "0.051"], ["71203.80", "0.005"], ["71204.10", "0.005"], ["71205.00", "0.004"], ["71205.10", "0.044"], ["71206.10", "0.042"], ["71206.20", "0.021"], ["71206.50", "0.004"], ["71207.00", "0.120"], ["71207.80", "0.011"], ["71208.00", "0.249"], ["71208.70", "0.066"], ["71209.70", "1.675"], ["71210.70", "0.042"], ["71211.50", "0.071"], ["71211.70", "0.044"], ["71212.70", "0.045"], ["71213.40", "0.009"], ["71213.60", "0.002"], ["71215.00", "0.024"], ["71215.50", "0.012"], ["71216.00", "0.008"], ["71216.30", "0.001"], ["71216.80", "0.037"], ["71216.90", "0.002"], ["71217.60", "0.182"], ["71217.90", "0.000"], ["71218.50", "0.179"], ["71218.90", "0.015"], ["71219.80", "0.002"], ["71219.90", "0.145"], ["71220.10", "0.015"], ["71220.50", "0.003"], ["71220.80", "0.006"], ["71220.90", "0.005"], ["71221.40", "0.367"], ["71221.80", "0.075"], ["71222.60", "0.225"], ["71223.30", "0.008"], ["71223.90", "0.664"], ["71225.10", "0.015"], ["71226.80", "0.069"], ["71227.00", "0.006"], ["71227.50", "0.000"], ["71227.70", "0.003"], ["71228.90", "0.004"], ["71229.50", "0.002"], ["71229.70", "0.023"], ["71229.80", "0.005"], ["71230.20", "0.007"], ["71231.40", "0.003"], ["71231.60", "0.006"], ["71232.50", "0.000"], ["71232.70", "0.003"], ["71233.70", "0.000"], ["71233.80", "0.003"], ["71233.90", "0.001"], ["71235.20", "0.022"], ["71235.30", "0.000"], ["71236.50", "0.117"]], "a": [["71236.60", "5.094"], ["71237.30", "0.003"], ["71237.40", "0.015"], ["71240.70", "0.003"], ["71242.70", "0.020"], ["71242.80", "0.126"], ["71244.20", "0.003"], ["71244.30", "0.180"], ["71244.40", "0.001"], ["71245.00", "0.009"], ["71246.00", "0.022"], ["71247.30", "0.174"], ["71247.40", "0.311"], ["71247.50", "0.793"], ["71247.60", "0.461"], ["71247.90", "0.023"], ["71249.00", "0.158"], ["71249.60", "0.058"], ["71250.10", "0.002"], ["71250.90", "0.037"], ["71251.00", "0.035"], ["71251.10", "1.281"], ["71251.40", "0.027"], ["71252.10", "0.053"], ["71252.20", "0.181"], ["71252.70", "0.018"], ["71253.30", "0.118"], ["71253.70", "0.032"], ["71254.20", "0.043"], ["71254.30", "0.013"], ["71254.40", "0.121"], ["71254.50", "0.576"], ["71254.80", "0.056"], ["71254.90", "0.035"], ["71255.20", "0.348"], ["71255.70", "0.010"], ["71257.30", "0.137"], ["71257.70", "0.003"], ["71260.20", "0.008"], ["71268.50", "0.005"], ["71268.60", "0.000"], ["71268.70", "0.394"], ["71284.30", "0.007"], ["71284.80", "0.657"], ["71286.50", "1.260"], ["71312.30", "0.004"], ["71315.00", "0.813"], ["71389.80", "0.011"], ["71397.00", "0.004"], ["71421.80", "0.000"], ["71949.00", "3.192"], ["72552.60", "0.000"], ["74822.00", "0.052"], ["89523.20", "0.000"], ["100000.00", "15.554"]]}}
{"local_ts": 1773384502713, "server_ts": 1773384502484, "data": {"e": "depthUpdate", "E": 1773384502487, "T": 1773384502484, "s": "BTCUSDT", "U": 10101337752719, "u": 10101337757239, "pu": 10101337752706, "b": [["1000.00", "27.492"], ["5000.00", "101.418"], ["20736.50", "0.009"], ["20836.50", "0.234"], ["20936.50", "0.666"], ["21036.50", "0.243"], ["21136.50", "1.548"], ["56989.20", "0.000"], ["69810.10", "0.013"], ["69965.40", "1.428"], ["70011.20", "0.285"], ["70524.10", "0.354"], ["70666.60", "0.437"], ["70880.30", "0.035"], ["71085.20", "0.003"], ["71227.00", "0.006"], ["71233.90", "0.001"]], "a": [["71263.80", "0.035"], ["71384.10", "0.000"], ["71463.20", "0.017"], ["71600.00", "19.090"], ["71948.90", "0.006"], ["71949.00", "3.192"], ["71987.30", "0.694"], ["72373.40", "0.591"], ["74803.20", "0.000"], ["74820.00", "0.226"], ["89523.20", "0.000"]]}}
{"local_ts": 1773384503722, "server_ts": 1773384503505, "data": {"e": "depthUpdate", "E": 1773384503507, "T": 1773384503505, "s": "BTCUSDT", "U": 10101337807954, "u": 10101337812886, "pu": 10101337807731, "b": [["5000.00", "101.418"], ["20736.50", "0.099"], ["20836.50", "0.801"], ["20936.50", "0.108"], ["21036.50", "1.548"], ["21136.50", "0.144"], ["56989.20", "0.000"], ["67651.20", "0.019"], ["67674.00", "0.002"], ["69421.70", "0.000"], ["69808.30", "0.375"], ["70274.40", "2.546"], ["70524.10", "1.770"], ["71085.50", "0.665"], ["71175.40", "0.016"], ["71178.20", "1.204"], ["71195.80", "0.332"], ["71196.80", "0.050"], ["71197.70", "0.031"], ["71215.10", "0.000"], ["71217.20", "0.129"], ["71220.80", "0.146"], ["71221.30", "0.133"], ["71227.40", "0.098"], ["71228.10", "0.005"], ["71229.30", "0.034"], ["71234.00", "0.004"]], "a": [["71237.80", "0.249"], ["71242.10", "0.126"], ["71242.50", "0.006"], ["71242.80", "0.000"], ["71242.90", "0.005"], ["71244.10", "0.035"], ["71245.40", "0.031"], ["71249.90", "0.141"], ["71250.70", "0.003"], ["71251.00", "0.037"], ["71251.30", "0.008"], ["71252.30", "0.064"], ["71252.90", "0.017"], ["71254.20", "0.056"], ["71255.40", "0.204"], ["71256.80", "0.108"], ["71258.00", "0.014"], ["71268.70", "0.297"], ["71272.10", "0.313"], ["71272.30", "0.076"], ["71276.00", "0.325"], ["71294.80", "0.000"], ["71295.10", "0.197"], ["71315.50", "1.523"], ["71316.70", "0.289"], ["71384.10", "0.000"], ["71421.80", "0.000"], ["71949.00", "3.192"], ["73452.10", "0.933"], ["89523.20", "0.000"]]}}
{"local_ts": 1773384504748, "server_ts": 1773384504528, "data": {"e": "depthUpdate", "E": 1773384504531, "T": 1773384504528, "s": "BTCUSDT", "U": 10101337856797, "u": 10101337861219, "pu": 10101337856774, "b": [["1000.00", "27.492"], ["5000.00", "101.418"], ["20736.50", "0.873"], ["20836.50", "0.027"], ["20936.50", "1.494"], ["21036.50", "0.306"], ["56989.20", "0.000"], ["67645.80", "0.000"], ["69808.30", "0.373"], ["69938.60", "0.571"], ["70524.10", "1.770"], ["71085.70", "0.018"], ["71085.90", "0.765"], ["71220.70", "0.003"], ["71221.80", "0.370"], ["71231.30", "0.033"], ["71231.60", "0.006"], ["71233.90", "0.001"], ["71235.90", "0.000"], ["71236.50", "1.168"]], "a": [["71236.60", "4.508"], ["71242.20", "0.017"], ["71242.60", "0.003"], ["71252.70", "0.033"], ["71272.20", "0.483"], ["71345.80", "0.006"], ["71346.40", "0.001"], ["71381.20", "0.004"], ["71383.00", "0.338"], ["71384.10", "0.509"], ["71394.90", "2.142"], ["71425.40", "0.159"], ["71463.40", "0.896"], ["71806.50", "0.904"], ["71948.80", "0.090"], ["71949.00", "3.192"], ["89523.20", "0.000"]]}}
{"local_ts": 1773384505772, "server_ts": 1773384505554, "data": {"e": "depthUpdate", "E": 1773384505555, "T": 1773384505554, "s": "BTCUSDT", "U": 10101337963126, "u": 10101337973452, "pu": 10101337963100, "b": [["1000.00", "27.492"], ["5000.00", "101.418"], ["20736.50", "0.162"], ["20840.50", "0.279"], ["20936.50", "0.567"], ["21140.50", "0.135"], ["56989.00", "0.000"], ["56992.40", "0.000"], ["69935.20", "0.361"], ["70183.30", "1.353"], ["70528.10", "0.000"], ["70644.20", "0.000"], ["70884.20", "0.005"], ["71060.50", "0.000"], ["71137.40", "1.750"], ["71149.70", "0.042"], ["71155.00", "0.306"], ["71158.60", "0.240"], ["71168.60", "0.000"], ["71169.30", "0.323"], ["71172.70", "1.206"], ["71174.10", "0.667"], ["71174.50", "0.040"], ["71178.50", "0.000"], ["71183.50", "0.191"], ["71184.10", "1.119"], ["71185.40", "0.005"], ["71189.10", "1.596"], ["71189.70", "0.002"], ["71190.70", "0.000"], ["71191.40", "0.003"], ["71193.20", "0.003"], ["71193.30", "0.038"], ["71193.60", "0.006"], ["71195.80", "0.332"], ["71196.00", "0.021"], ["71197.70", "0.116"], ["71204.90", "0.083"], ["71205.90", "0.000"], ["71206.50", "0.000"], ["71206.80", "0.001"], ["71207.40", "0.318"], ["71208.70", "0.086"], ["71209.30", "0.003"], ["71209.50", "1.185"], ["71209.60", "0.353"], ["71210.20", "0.188"], ["71210.30", "0.011"], ["71210.60", "0.010"], ["71211.40", "0.023"], ["71212.10", "0.276"], ["71213.40", "0.045"], ["71214.20", "0.019"], ["71214.50", "0.120"], ["71215.20", "0.006"], ["71215.70", "0.000"], ["71216.10", "0.010"], ["71216.70", "0.004"], ["71217.90", "0.000"], ["71218.40", "0.668"], ["71218.90", "0.070"], ["71219.30", "0.008"], ["71219.40", "0.077"], ["71220.00", "0.017"], ["71220.10", "0.000"], ["71220.20", "0.447"], ["71220.70", "0.000"], ["71221.10", "0.005"], ["71221.40", "0.352"], ["71222.20", "0.002"], ["71223.70", "0.045"], ["71224.60", "0.508"], ["71224.70", "0.001"], ["71225.90", "0.207"], ["71226.10", "1.137"], ["71226.40", "0.134"], ["71226.50", "0.147"], ["71226.70", "0.004"], ["71226.90", "0.011"], ["71227.30", "0.005"], ["71227.90", "0.010"], ["71228.30", "0.004"], ["71228.40", "0.715"], ["71228.70", "0.003"], ["71229.30", "0.005"], ["71229.40", "0.048"], ["71229.70", "0.004"], ["71229.80", "0.012"], ["71229.90", "0.023"], ["71230.20", "0.072"], ["71230.70", "0.241"], ["71230.80", "0.072"], ["71230.90", "0.140"], ["71231.40", "1.332"], ["71231.50", "0.021"], ["71232.30", "0.001"], ["71232.90", "0.244"], ["71233.00", "0.003"], ["71233.30", "0.054"], ["71233.80", "0.008"], ["71233.90", "0.007"], ["71234.10", "0.014"], ["71234.50", "0.034"], ["71235.20", "0.021"], ["71235.40", "0.001"], ["71235.50", "0.036"], ["71235.60", "0.015"], ["71235.70", "0.001"], ["71235.80", "0.006"], ["71235.90", "0.000"], ["71236.50", "0.126"], ["71236.60", "0.850"], ["71236.90", "0.003"], ["71237.10", "0.004"], ["71237.40", "0.000"], ["71237.50", "0.006"], ["71237.90", "0.058"], ["71238.00", "0.091"], ["71238.10", "0.204"], ["71238.20", "0.003"], ["71238.30", "0.001"], ["71238.70", "0.002"], ["71239.50", "0.002"], ["71240.00", "0.073"], ["71240.10", "0.251"], ["71240.30", "0.001"], ["71240.40", "0.174"], ["71240.50", "11.323"]], "a": [["71240.60", "1.767"], ["71240.80", "0.000"], ["71241.50", "0.003"], ["71241.80", "0.289"], ["71244.30", "0.003"], ["71245.80", "0.005"], ["71245.90", "0.127"], ["71247.00", "0.007"], ["71248.40", "0.000"], ["71249.50", "0.008"], ["71250.00", "0.103"], ["71250.70", "0.021"], ["71251.10", "0.647"], ["71252.20", "0.029"], ["71253.30", "0.058"], ["71254.10", "0.116"], ["71254.70", "0.017"], ["71254.80", "0.328"], ["71255.20", "0.227"], ["71255.80", "0.059"], ["71256.20", "0.202"], ["71256.80", "0.038"], ["71258.40", "0.785"], ["71258.50", "0.005"], ["71259.10", "0.003"], ["71259.70", "0.005"], ["71260.00", "0.033"], ["71260.20", "0.002"], ["71260.30", "0.239"], ["71260.40", "0.003"], ["71260.90", "0.089"], ["71261.00", "0.143"], ["71261.20", "0.005"], ["71261.30", "0.015"], ["71261.40", "0.375"], ["71261.60", "0.226"], ["71261.70", "0.001"], ["71261.80", "0.078"], ["71261.90", "0.003"], ["71262.00", "0.073"], ["71263.00", "0.778"], ["71263.50", "0.008"], ["71264.10", "0.015"], ["71264.30", "0.051"], ["71264.40", "0.009"], ["71264.50", "0.006"], ["71264.60", "0.088"], ["71264.80", "0.000"], ["71265.20", "0.007"], ["71265.40", "0.020"], ["71265.50", "0.000"], ["71265.70", "0.000"], ["71266.10", "0.616"], ["71266.60", "0.070"], ["71266.70", "0.019"], ["71267.10", "0.033"], ["71267.30", "0.304"], ["71267.50", "0.000"], ["71267.90", "0.017"], ["71268.00", "0.043"], ["71268.40", "0.004"], ["71268.80", "0.512"], ["71269.00", "0.011"], ["71269.10", "0.283"], ["71269.20", "0.030"], ["71269.40", "0.007"], ["71269.50", "0.004"], ["71269.60", "0.607"], ["71269.80", "0.055"], ["71270.40", "0.044"], ["71270.80", "0.010"], ["71270.90", "0.506"], ["71271.00", "0.000"], ["71271.20", "0.008"], ["71271.40", "0.000"], ["71271.70", "0.044"], ["71271.90", "0.000"], ["71272.30", "0.002"], ["71272.40", "0.000"], ["71272.60", "0.108"], ["71272.70", "0.258"], ["71272.90", "0.016"], ["71273.20", "0.001"], ["71273.50", "0.232"], ["71273.90", "0.044"], ["71274.20", "0.000"], ["71274.50", "0.012"], ["71275.20", "0.090"], ["71275.50", "0.071"], ["71276.20", "0.000"], ["71276.30", "0.001"], ["71276.40", "0.003"], ["71276.50", "0.009"], ["71277.50", "0.005"], ["71277.70", "0.000"], ["71278.30", "0.032"], ["71278.70", "0.000"], ["71278.90", "0.002"], ["71279.40", "1.381"], ["71280.00", "0.061"], ["71280.20", "0.788"], ["71281.10", "0.003"], ["71281.20", "0.015"], ["71281.50", "0.033"], ["71282.50", "0.000"], ["71283.80", "0.032"], ["71284.40", "0.002"], ["71284.80", "0.002"], ["71285.00", "0.000"], ["71286.40", "0.010"], ["71286.50", "1.200"], ["71286.60", "0.004"], ["71286.70", "0.075"], ["71287.10", "0.014"], ["71287.30", "0.218"], ["71287.40", "0.003"], ["71287.80", "0.012"], ["71287.90", "1.645"], ["71288.10", "0.075"], ["71288.50", "0.037"], ["71288.60", "0.386"], ["71288.70", "0.322"], ["71288.80", "0.578"], ["71288.90", "1.389"], ["71289.00", "0.009"], ["71289.20", "0.086"], ["71289.40", "0.000"], ["71290.30", "0.156"], ["71290.90", "0.313"], ["71291.00", "0.512"], ["71291.20", "0.042"], ["71292.00", "0.028"], ["71292.20", "0.000"], ["71292.60", "0.000"], ["71293.30", "0.660"], ["71293.50", "0.232"], ["71294.00", "0.017"], ["71294.80", "0.000"], ["71295.80", "0.001"], ["71296.20", "0.259"], ["71297.70", "0.000"], ["71298.20", "0.004"], ["71299.50", "0.023"], ["71299.80", "0.004"], ["71300.00", "3.261"], ["71300.20", "0.041"], ["71300.80", "0.039"], ["71302.00", "0.392"], ["71302.40", "0.000"], ["71303.30", "0.017"], ["71303.70", "0.317"], ["71304.80", "0.000"], ["71314.00", "0.031"], ["71318.00", "0.000"], ["71319.50", "0.007"], ["71335.30", "0.002"], ["71369.90", "0.778"], ["71397.70", "0.201"], ["71425.40", "0.000"], ["71463.40", "0.896"], ["71478.90", "0.001"], ["71499.90", "0.010"], ["71787.50", "0.000"], ["71949.00", "3.886"], ["71953.00", "0.044"], ["72072.40", "0.000"], ["74811.60", "0.010"], ["74829.70", "0.000"], ["89523.20", "0.000"]]}}
{"local_ts": 1773384506791, "server_ts": 1773384506573, "data": {"e": "depthUpdate", "E": 1773384506575, "T": 1773384506573, "s": "BTCUSDT", "U": 10101338025235, "u": 10101338039280, "pu": 10101338025043, "b": [["5000.00", "101.418"], ["20740.50", "0.963"], ["20836.50", "0.639"], ["20840.50", "0.189"], ["21040.50", "0.603"], ["21136.50", "0.297"], ["40000.00", "49.307"], ["56992.00", "0.000"], ["56992.40", "0.000"], ["67668.20", "0.000"], ["67672.40", "0.002"], ["70193.30", "1.279"], ["70528.10", "0.000"], ["70884.20", "0.005"], ["71119.90", "0.094"], ["71186.70", "0.044"], ["71194.00", "0.013"], ["71194.10", "0.004"], ["71195.10", "0.045"], ["71198.60", "0.095"], ["71213.10", "0.005"], ["71214.20", "0.019"], ["71214.50", "0.002"], ["71215.50", "0.024"], ["71216.70", "0.249"], ["71217.00", "0.020"], ["71217.10", "0.016"], ["71217.20", "0.005"], ["71217.50", "0.012"], ["71218.60", "0.070"], ["71219.40", "0.070"], ["71219.60", "0.117"], ["71220.20", "0.403"], ["71220.70", "0.014"], ["71221.10", "0.005"], ["71221.50", "0.023"], ["71221.80", "0.088"], ["71221.90", "0.690"], ["71222.20", "0.002"], ["71222.60", "0.210"], ["71222.80", "0.004"], ["71223.90", "0.588"], ["71225.10", "0.007"], ["71225.80", "0.398"], ["71226.60", "0.177"], ["71227.00", "0.002"], ["71227.20", "0.044"], ["71227.80", "0.506"], ["71228.10", "0.005"], ["71228.70", "0.003"], ["71228.90", "0.635"], ["71229.00", "0.009"], ["71229.10", "0.036"], ["71229.40", "0.050"], ["71229.50", "0.004"], ["71229.60", "0.756"], ["71229.70", "0.004"], ["71229.80", "0.005"], ["71230.00", "0.010"], ["71230.60", "0.916"], ["71230.80", "0.377"], ["71230.90", "0.057"], ["71231.20", "0.092"], ["71231.40", "1.052"], ["71231.60", "0.076"], ["71231.70", "0.161"], ["71231.80", "0.038"], ["71232.10", "0.105"], ["71232.20", "0.020"], ["71232.30", "0.015"], ["71232.60", "0.054"], ["71232.80", "0.047"], ["71233.20", "0.303"], ["71233.40", "0.030"], ["71236.20", "0.002"], ["71237.60", "0.011"], ["71238.10", "0.206"], ["71240.50", "10.373"]], "a": [["71240.60", "0.213"], ["71244.30", "0.005"], ["71244.80", "0.032"], ["71247.00", "0.005"], ["71247.70", "0.002"], ["71251.00", "0.062"], ["71252.20", "0.002"], ["71253.40", "0.007"], ["71253.70", "0.054"], ["71254.30", "0.000"], ["71254.70", "0.664"], ["71255.00", "0.004"], ["71257.50", "0.002"], ["71258.70", "0.003"], ["71258.90", "0.004"], ["71259.20", "0.005"], ["71259.30", "0.008"], ["71259.90", "0.140"], ["71260.00", "0.018"], ["71260.40", "0.259"], ["71262.60", "0.008"], ["71262.90", "0.012"], ["71263.90", "0.010"], ["71264.40", "0.002"], ["71264.70", "0.000"], ["71264.80", "0.631"], ["71265.20", "0.000"], ["71265.50", "0.000"], ["71265.80", "0.007"], ["71266.20", "0.008"], ["71266.50", "0.002"], ["71266.90", "0.053"], ["71267.10", "0.004"], ["71267.30", "0.098"], ["71267.50", "0.015"], ["71268.10", "0.085"], ["71268.80", "0.527"], ["71269.00", "0.004"], ["71269.50", "0.004"], ["71269.60", "0.614"], ["71269.90", "0.218"], ["71270.00", "0.024"], ["71270.70", "0.063"], ["71271.40", "0.070"], ["71271.80", "0.005"], ["71271.90", "0.000"], ["71272.00", "0.325"], ["71272.10", "0.247"], ["71273.90", "0.114"], ["71274.20", "0.507"], ["71275.50", "0.005"], ["71279.30", "0.000"], ["71279.80", "0.000"], ["71280.20", "0.788"], ["71281.70", "0.355"], ["71281.90", "0.035"], ["71282.10", "0.002"], ["71282.30", "0.010"], ["71282.70", "0.005"], ["71283.90", "0.000"], ["71284.10", "0.002"], ["71284.20", "0.007"], ["71285.00", "0.000"], ["71285.20", "0.004"], ["71285.40", "0.003"], ["71285.80", "0.000"], ["71286.10", "0.001"], ["71286.60", "0.004"], ["71286.90", "0.000"], ["71287.80", "0.009"], ["71288.00", "0.091"], ["71288.20", "0.119"], ["71288.30", "0.014"], ["71288.50", "0.000"], ["71288.70", "0.324"], ["71289.70", "0.005"], ["71290.50", "0.036"], ["71290.90", "0.313"], ["71291.00", "0.512"], ["71291.10", "0.023"], ["71291.20", "0.042"], ["71292.10", "0.053"], ["71292.20", "0.000"], ["71293.40", "0.031"], ["71293.50", "0.232"], ["71295.90", "0.031"], ["71297.20", "0.350"], ["71298.40", "0.058"], ["71299.70", "0.029"], ["71300.90", "0.029"], ["71302.20", "0.537"], ["71303.40", "0.029"], ["71309.60", "0.000"], ["71335.00", "0.155"], ["71370.90", "2.500"], ["71953.00", "0.044"], ["72287.20", "2.877"], ["72358.40", "3.832"]]}}
{"local_ts": 1773384507814, "server_ts": 1773384507595, "data": {"e": "depthUpdate", "E": 1773384507597, "T": 1773384507595, "s": "BTCUSDT", "U": 10101338100285, "u": 10101338107029, "pu": 10101338100147, "b": [["1000.00", "27.492"], ["5000.00", "101.418"], ["20740.50", "0.801"], ["20745.90", "0.306"], ["20945.90", "0.468"], ["21040.50", "0.432"], ["21145.90", "0.693"], ["40000.00", "49.307"], ["56996.70", "0.000"], ["67659.40", "0.000"], ["67671.30", "0.000"], ["67683.60", "0.002"], ["69277.50", "0.040"], ["69805.90", "1.718"], ["70065.00", "1.005"], ["70141.60", "0.999"], ["70193.30", "3.910"], ["70212.80", "1.493"], ["70221.40", "11.005"], ["70533.40", "0.000"], ["70889.70", "0.000"], ["70996.60", "0.013"], ["71081.30", "0.594"], ["71085.30", "2.456"], ["71094.20", "23.617"], ["71103.40", "0.288"], ["71105.10", "0.000"], ["71123.00", "0.308"], ["71126.50", "0.020"], ["71142.50", "0.600"], ["71171.30", "0.074"], ["71181.20", "0.014"], ["71185.30", "0.000"], ["71189.10", "0.341"], ["71197.80", "0.047"], ["71200.00", "100.199"], ["71201.40", "0.357"], ["71205.30", "0.100"], ["71205.40", "0.005"], ["71206.00", "0.002"], ["71206.10", "0.000"], ["71209.50", "1.185"], ["71209.60", "0.353"], ["71210.20", "0.148"], ["71210.30", "0.806"], ["71212.00", "0.257"], ["71213.80", "0.463"], ["71214.30", "0.023"], ["71214.60", "0.143"], ["71215.60", "0.104"], ["71216.40", "0.079"], ["71216.70", "0.000"], ["71217.20", "0.003"], ["71217.30", "0.014"], ["71217.70", "0.003"], ["71218.60", "0.000"], ["71218.90", "0.000"], ["71219.90", "0.075"], ["71221.40", "0.352"], ["71221.90", "0.528"], ["71225.40", "0.508"], ["71226.40", "0.098"], ["71226.60", "0.153"], ["71226.70", "0.004"], ["71227.20", "0.002"], ["71228.00", "0.012"], ["71228.10", "0.033"], ["71228.80", "0.045"], ["71229.60", "0.758"], ["71229.70", "0.046"], ["71230.40", "0.004"], ["71231.40", "1.056"], ["71231.70", "0.076"], ["71232.20", "0.113"], ["71232.60", "0.133"], ["71232.80", "0.111"], ["71232.90", "0.220"], ["71233.10", "0.628"], ["71233.20", "0.106"], ["71233.30", "0.116"], ["71233.70", "0.038"], ["71233.80", "0.063"], ["71234.10", "0.046"], ["71234.20", "0.021"], ["71234.40", "0.045"], ["71234.60", "0.356"], ["71236.70", "0.006"], ["71240.40", "0.008"], ["71242.30", "0.413"], ["71243.80", "0.341"], ["71243.90", "0.284"], ["71244.00", "0.227"], ["71244.70", "0.004"], ["71245.80", "0.006"], ["71245.90", "7.076"]], "a": [["71246.00", "3.376"], ["71249.90", "0.001"], ["71251.00", "0.004"], ["71251.20", "0.003"], ["71253.30", "0.090"], ["71254.10", "0.077"], ["71255.20", "0.004"], ["71255.70", "0.001"], ["71256.20", "0.188"], ["71256.80", "0.040"], ["71256.90", "0.082"], ["71257.10", "0.034"], ["71257.50", "0.002"], ["71258.20", "0.006"], ["71258.90", "0.020"], ["71259.20", "0.004"], ["71259.60", "0.002"], ["71259.80", "0.003"], ["71260.10", "0.003"], ["71260.50", "0.123"], ["71260.70", "0.005"], ["71260.90", "0.018"], ["71261.20", "0.003"], ["71261.40", "0.009"], ["71261.80", "0.003"], ["71262.00", "0.003"], ["71262.10", "0.004"], ["71262.30", "0.007"], ["71262.90", "0.224"], ["71263.10", "0.036"], ["71263.20", "0.001"], ["71263.30", "0.003"], ["71263.40", "0.028"], ["71263.50", "0.015"], ["71264.10", "0.012"], ["71264.50", "0.077"], ["71264.70", "0.338"], ["71264.80", "0.002"], ["71265.40", "0.005"], ["71265.80", "0.000"], ["71265.90", "0.000"], ["71266.70", "0.011"], ["71267.10", "0.762"], ["71267.20", "0.000"], ["71267.30", "0.003"], ["71267.90", "0.002"], ["71268.10", "0.107"], ["71268.40", "0.000"], ["71268.60", "0.188"], ["71268.70", "0.158"], ["71268.80", "0.006"], ["71268.90", "1.049"], ["71269.50", "0.516"], ["71269.70", "0.947"], ["71269.90", "0.209"], ["71270.40", "0.252"], ["71270.50", "0.344"], ["71270.60", "0.508"], ["71270.90", "0.001"], ["71271.20", "0.006"], ["71271.30", "0.030"], ["71271.40", "0.000"], ["71271.70", "0.047"], ["71271.90", "0.000"], ["71272.00", "0.043"], ["71272.10", "0.002"], ["71272.20", "0.245"], ["71273.40", "0.006"], ["71274.60", "0.348"], ["71275.90", "0.029"], ["71276.00", "0.343"], ["71277.10", "0.357"], ["71277.80", "0.002"], ["71278.40", "0.029"], ["71279.60", "0.601"], ["71279.70", "0.095"], ["71280.90", "0.046"], ["71281.60", "0.530"], ["71282.10", "0.311"], ["71282.90", "0.133"], ["71283.40", "0.069"], ["71284.30", "0.007"], ["71285.20", "0.145"], ["71288.70", "0.324"], ["71291.10", "0.005"], ["71291.70", "0.025"], ["71306.70", "3.419"], ["71307.30", "0.000"], ["71320.80", "0.255"], ["71393.50", "0.756"], ["71402.40", "5.487"], ["71431.20", "0.199"], ["71626.60", "0.728"], ["71627.80", "3.420"], ["71953.00", "0.044"], ["71958.50", "0.003"], ["72279.10", "1.934"], ["72297.10", "2.879"], ["72348.60", "2.788"], ["72350.30", "1.932"], ["72421.50", "1.930"], ["100000.00", "15.858"]]}}
{"local_ts": 1773384508836, "server_ts": 1773384508616, "data": {"e": "depthUpdate", "E": 1773384508617, "T": 1773384508616, "s": "BTCUSDT", "U": 10101338162438, "u": 10101338175961, "pu": 10101338162289, "b": [["5000.00", "101.418"], ["20845.90", "0.333"], ["20945.90", "0.567"], ["21045.90", "0.423"], ["21145.90", "1.377"], ["33000.00", "9.339"], ["40000.00", "49.453"], ["56992.00", "0.000"], ["56992.40", "0.000"], ["67667.10", "0.000"], ["67681.90", "0.002"], ["70161.60", "2.415"], ["70232.80", "8.672"], ["70270.40", "0.000"], ["70278.80", "0.639"], ["70533.40", "0.000"], ["70900.00", "25.393"], ["70992.50", "0.002"], ["71158.90", "0.815"], ["71163.30", "0.042"], ["71164.40", "0.052"], ["71165.80", "0.080"], ["71166.00", "0.002"], ["71166.80", "0.042"], ["71167.00", "0.005"], ["71167.80", "0.501"], ["71167.90", "0.000"], ["71168.90", "0.001"], ["71169.70", "0.403"], ["71169.90", "0.105"], ["71170.80", "0.008"], ["71170.90", "0.116"], ["71171.20", "0.000"], ["71171.80", "0.084"], ["71171.90", "2.322"], ["71172.80", "0.004"], ["71173.80", "0.000"], ["71175.40", "0.064"], ["71177.70", "0.002"], ["71177.90", "0.042"], ["71178.10", "1.632"], ["71178.80", "1.445"], ["71179.10", "0.000"], ["71180.70", "0.004"], ["71180.90", "0.050"], ["71181.20", "0.014"], ["71181.70", "0.002"], ["71182.60", "0.581"], ["71183.60", "0.000"], ["71184.60", "0.002"], ["71186.90", "0.004"], ["71188.00", "0.317"], ["71188.30", "0.983"], ["71190.90", "3.500"], ["71191.20", "0.000"], ["71191.30", "0.322"], ["71193.60", "0.006"], ["71193.80", "0.007"], ["71196.20", "0.003"], ["71196.90", "0.029"], ["71197.00", "7.788"], ["71197.20", "1.824"], ["71197.30", "0.000"], ["71197.90", "0.035"], ["71198.00", "0.002"], ["71198.10", "0.003"], ["71198.20", "0.006"], ["71198.70", "0.000"], ["71198.80", "0.003"], ["71199.50", "0.002"], ["71199.80", "0.104"], ["71200.10", "0.209"], ["71200.70", "0.000"], ["71200.80", "0.005"], ["71201.80", "0.001"], ["71202.70", "0.001"], ["71203.20", "0.021"], ["71204.30", "0.051"], ["71205.90", "0.000"], ["71206.00", "0.004"], ["71206.90", "0.198"], ["71207.60", "0.000"], ["71207.90", "0.000"], ["71208.90", "0.019"], ["71209.90", "0.333"], ["71210.10", "0.002"], ["71210.80", "0.000"], ["71211.40", "0.000"], ["71211.80", "0.252"], ["71212.60", "0.274"], ["71212.80", "0.020"], ["71213.40", "0.045"], ["71213.70", "0.001"], ["71213.90", "0.034"], ["71214.20", "0.019"], ["71214.30", "0.002"], ["71215.10", "0.029"], ["71215.50", "0.004"], ["71216.00", "0.081"], ["71216.30", "0.001"], ["71216.40", "0.038"], ["71216.80", "0.030"], ["71217.10", "0.016"], ["71217.60", "0.035"], ["71217.80", "0.129"], ["71217.90", "0.000"], ["71218.60", "0.070"], ["71218.70", "0.009"], ["71218.80", "0.232"], ["71219.60", "0.146"], ["71219.80", "0.012"], ["71219.90", "0.005"], ["71220.10", "0.000"], ["71220.70", "0.000"], ["71220.80", "0.042"], ["71221.20", "1.049"], ["71221.30", "0.133"], ["71221.40", "0.352"], ["71221.50", "0.016"], ["71221.70", "0.001"], ["71222.30", "0.029"], ["71222.60", "0.210"], ["71222.70", "0.141"], ["71223.20", "0.003"], ["71223.60", "0.000"], ["71223.80", "0.310"], ["71224.00", "0.018"], ["71224.20", "0.007"], ["71224.70", "0.001"], ["71225.00", "0.053"], ["71225.10", "0.000"], ["71225.40", "0.508"], ["71225.70", "0.000"], ["71225.80", "0.398"], ["71226.10", "0.000"], ["71226.20", "0.510"], ["71226.30", "0.000"], ["71226.40", "0.729"], ["71226.50", "0.073"], ["71226.90", "0.004"], ["71227.00", "0.007"], ["71227.10", "0.338"], ["71227.40", "0.381"], ["71227.50", "0.000"], ["71227.70", "0.151"], ["71227.80", "0.001"], ["71227.90", "1.058"], ["71228.00", "0.145"], ["71228.40", "0.489"], ["71228.50", "0.543"], ["71228.90", "0.004"], ["71229.10", "0.000"], ["71229.30", "0.005"], ["71229.50", "0.004"], ["71229.70", "0.004"], ["71229.90", "0.034"], ["71230.30", "0.002"], ["71230.50", "0.507"], ["71230.60", "0.038"], ["71230.70", "0.515"], ["71230.90", "0.036"], ["71231.00", "0.006"], ["71231.20", "0.025"], ["71231.30", "0.338"], ["71231.40", "0.007"], ["71231.50", "0.078"], ["71231.70", "0.022"], ["71231.80", "0.002"], ["71232.00", "0.012"], ["71232.10", "0.004"], ["71232.40", "0.000"], ["71232.60", "0.008"], ["71232.70", "0.003"], ["71232.80", "0.002"], ["71232.90", "0.199"], ["71233.00", "0.001"], ["71233.10", "0.628"], ["71233.20", "0.930"], ["71233.30", "0.054"], ["71233.50", "0.001"], ["71233.60", "1.052"], ["71233.70", "0.000"], ["71233.80", "0.027"], ["71234.10", "0.012"], ["71234.20", "0.000"], ["71234.40", "0.000"], ["71234.50", "0.002"], ["71234.60", "0.047"], ["71234.70", "0.004"], ["71234.80", "0.004"], ["71235.50", "0.293"], ["71235.60", "0.000"], ["71236.10", "0.010"], ["71236.40", "0.003"], ["71236.60", "0.006"], ["71236.90", "0.000"], ["71237.50", "0.008"], ["71237.70", "0.063"], ["71237.90", "0.000"], ["71238.00", "0.007"], ["71238.80", "0.076"], ["71239.10", "0.000"], ["71239.30", "0.006"], ["71239.40", "0.000"], ["71239.50", "0.003"], ["71239.70", "0.000"], ["71240.20", "0.115"], ["71240.50", "0.067"], ["71240.90", "0.003"], ["71241.10", "0.039"], ["71242.30", "0.005"], ["71242.50", "0.221"], ["71243.00", "0.003"], ["71243.40", "0.000"], ["71243.50", "0.007"], ["71243.80", "0.001"], ["71243.90", "0.003"], ["71244.20", "0.001"], ["71244.70", "0.004"], ["71244.80", "0.002"], ["71245.10", "0.000"], ["71245.80", "0.004"], ["71245.90", "0.591"]], "a": [["71246.00", "3.953"], ["71246.60", "0.033"], ["71249.50", "0.065"], ["71249.90", "0.004"], ["71250.10", "0.010"], ["71253.10", "0.030"], ["71253.20", "0.002"], ["71254.00", "0.015"], ["71255.20", "0.007"], ["71256.40", "0.002"], ["71256.60", "0.145"], ["71256.70", "0.039"], ["71256.80", "0.238"], ["71257.10", "0.027"], ["71258.00", "0.009"], ["71259.70", "0.002"], ["71259.90", "0.036"], ["71260.20", "0.257"], ["71260.40", "0.167"], ["71261.50", "0.625"], ["71261.60", "0.005"], ["71262.50", "0.334"], ["71262.80", "0.642"], ["71263.20", "0.071"], ["71263.50", "0.008"], ["71263.80", "0.010"], ["71264.00", "0.154"], ["71264.20", "0.002"], ["71264.40", "0.002"], ["71264.50", "0.007"], ["71264.60", "0.514"], ["71264.80", "0.007"], ["71264.90", "0.002"], ["71265.00", "0.009"], ["71265.20", "0.000"], ["71265.60", "0.019"], ["71265.70", "0.000"], ["71266.30", "0.174"], ["71266.50", "0.072"], ["71266.60", "0.004"], ["71266.70", "0.004"], ["71266.90", "0.002"], ["71267.40", "0.757"], ["71268.50", "0.032"], ["71268.60", "0.011"], ["71268.70", "0.112"], ["71268.80", "0.251"], ["71269.00", "0.004"], ["71269.60", "1.118"], ["71270.20", "0.032"], ["71270.40", "0.000"], ["71271.30", "0.030"], ["71271.40", "0.000"], ["71271.50", "0.073"], ["71274.00", "0.038"], ["71274.60", "0.319"], ["71276.40", "0.005"], ["71280.30", "0.039"], ["71281.60", "0.649"], ["71282.80", "0.234"], ["71282.90", "0.006"], ["71284.60", "0.002"], ["71285.20", "0.205"], ["71285.80", "0.000"], ["71287.10", "0.294"], ["71288.30", "0.017"], ["71289.60", "7.835"], ["71290.80", "0.000"], ["71292.10", "0.058"], ["71293.30", "0.009"], ["71306.70", "0.011"], ["71307.80", "3.914"], ["71320.80", "0.127"], ["71321.10", "0.024"], ["71322.40", "0.003"], ["71322.50", "0.129"], ["71325.90", "0.119"], ["71493.30", "1.213"], ["71958.50", "0.005"], ["72279.10", "7.736"], ["72299.70", "4.572"], ["72370.90", "1.954"], ["72421.60", "1.930"], ["72670.90", "0.006"]]}}
{"local_ts": 1773384509854, "server_ts": 1773384509636, "data": {"e": "depthUpdate", "E": 1773384509637, "T": 1773384509636, "s": "BTCUSDT", "U": 10101338272790, "u": 10101338279438, "pu": 10101338272687, "b": [["1000.00", "27.492"], ["5000.00", "101.418"], ["20747.80", "0.198"], ["20847.80", "0.054"], ["20947.80", "0.207"], ["21047.80", "0.504"], ["21145.90", "0.045"], ["56992.00", "0.000"], ["56998.20", "0.002"], ["67675.80", "0.002"], ["70090.30", "1.309"], ["70212.80", "4.480"], ["70232.80", "3.697"], ["70535.30", "0.056"], ["70535.40", "0.000"], ["70599.10", "2.121"], ["70985.70", "0.004"], ["70992.50", "0.000"], ["70994.90", "0.004"], ["71094.50", "0.000"], ["71155.20", "0.070"], ["71200.40", "0.005"], ["71200.60", "0.018"], ["71217.40", "0.114"], ["71220.70", "0.070"], ["71222.80", "0.004"], ["71224.20", "0.000"], ["71224.90", "0.007"], ["71226.70", "0.004"], ["71228.40", "0.209"], ["71228.50", "0.550"], ["71230.30", "0.009"], ["71230.40", "0.011"], ["71232.60", "0.006"], ["71232.70", "0.010"], ["71233.20", "0.881"], ["71234.40", "0.280"], ["71239.50", "0.003"], ["71240.70", "0.137"], ["71241.00", "0.004"], ["71244.60", "0.344"], ["71244.90", "0.001"], ["71245.10", "0.002"], ["71245.40", "0.006"], ["71247.00", "0.004"], ["71247.60", "0.000"]], "a": [["71247.90", "2.966"], ["71255.00", "0.030"], ["71259.60", "0.046"], ["71262.60", "0.401"], ["71264.60", "0.008"], ["71275.10", "0.505"], ["71279.10", "0.000"], ["71283.50", "0.212"], ["71295.90", "0.044"], ["71296.10", "0.004"], ["71318.40", "0.007"], ["71320.80", "0.081"], ["71377.30", "0.073"], ["71393.50", "0.074"], ["71960.40", "0.694"], ["72418.30", "0.005"]]}}
{"local_ts": 1773384510877, "server_ts": 1773384510656, "data": {"e": "depthUpdate", "E": 1773384510659, "T": 1773384510656, "s": "BTCUSDT", "U": 10101338343489, "u": 10101338347585, "pu": 10101338343423, "b": [["1000.00", "27.492"], ["5000.00", "101.418"], ["20747.80", "0.837"], ["20845.90", "0.000"], ["20847.80", "0.072"], ["20947.80", "1.548"], ["21045.90", "0.180"], ["21147.80", "0.063"], ["33000.00", "9.343"], ["56998.00", "0.000"], ["56998.20", "0.002"], ["67681.90", "0.000"], ["67685.00", "0.000"], ["68397.80", "0.023"], ["70143.50", "1.012"], ["70214.70", "0.996"], ["70421.20", "0.640"], ["70448.00", "0.005"], ["70535.30", "0.056"], ["70992.40", "0.004"], ["70994.90", "0.002"], ["71099.80", "0.000"], ["71107.30", "0.036"], ["71121.20", "0.040"], ["71125.40", "0.180"], ["71125.70", "0.061"], ["71126.40", "0.062"], ["71170.90", "0.074"], ["71171.90", "2.280"], ["71180.10", "0.003"], ["71188.30", "0.989"], ["71192.20", "0.122"], ["71199.50", "0.002"], ["71199.60", "0.003"], ["71204.20", "0.003"], ["71205.80", "0.366"], ["71212.20", "0.075"], ["71221.50", "0.010"], ["71222.20", "0.009"], ["71223.10", "0.003"], ["71227.20", "0.004"], ["71233.20", "0.879"], ["71244.80", "0.002"]], "a": [["71249.10", "0.002"], ["71254.60", "0.040"], ["71263.00", "0.155"], ["71266.70", "0.016"], ["71268.10", "0.037"], ["71269.50", "0.509"], ["71279.80", "0.002"], ["71283.50", "0.240"], ["71299.50", "0.023"], ["71299.80", "0.057"], ["71317.50", "0.714"], ["71340.50", "0.000"], ["71341.90", "10.087"], ["71398.30", "0.074"], ["71960.40", "0.694"], ["72352.20", "1.020"], ["74840.60", "0.002"]]}}
{"local_ts": 1773384511919, "server_ts": 1773384511677, "data": {"e": "depthUpdate", "E": 1773384511679, "T": 1773384511677, "s": "BTCUSDT", "U": 10101338389822, "u": 10101338395170, "pu": 10101338389502, "b": [["5000.00", "101.418"], ["20747.80", "0.072"], ["20847.80", "1.422"], ["20947.80", "0.378"], ["21147.80", "0.828"], ["68000.00", "109.239"], ["69815.70", "4.299"], ["69822.90", "0.019"], ["70408.30", "0.000"], ["70535.30", "0.056"], ["70992.40", "0.002"], ["70993.20", "0.016"], ["71041.00", "2.060"], ["71042.80", "0.003"], ["71089.00", "0.705"], ["71089.10", "2.958"], ["71098.00", "0.668"], ["71174.00", "0.040"], ["71174.20", "0.040"], ["71175.00", "0.002"], ["71176.00", "0.004"], ["71176.90", "0.320"], ["71177.90", "0.042"], ["71178.90", "0.917"], ["71180.90", "0.092"], ["71181.80", "0.027"], ["71181.90", "0.086"], ["71182.80", "0.192"], ["71182.90", "0.089"], ["71183.90", "0.042"], ["71184.60", "0.002"], ["71185.00", "0.548"], ["71186.00", "0.044"], ["71186.20", "0.048"], ["71187.30", "0.640"], ["71188.30", "0.947"], ["71191.20", "0.000"], ["71192.20", "0.080"], ["71194.00", "0.013"], ["71199.20", "0.005"], ["71199.30", "0.003"], ["71210.40", "0.139"], ["71225.50", "0.011"], ["71226.30", "0.000"], ["71240.50", "0.008"], ["71240.60", "0.005"], ["71247.80", "1.727"]], "a": [["71247.90", "3.317"], ["71250.00", "0.136"], ["71254.90", "0.002"], ["71265.30", "0.566"], ["71266.30", "0.215"], ["71271.50", "0.032"], ["71282.70", "0.007"], ["71287.00", "0.002"], ["71295.10", "0.270"], ["71295.50", "0.001"], ["71395.40", "0.696"], ["71404.30", "15.872"], ["71429.60", "0.099"], ["71452.40", "1.245"], ["71455.30", "0.000"], ["71960.40", "0.694"], ["72281.00", "2.026"], ["72452.00", "0.275"], ["72665.40", "0.151"], ["74820.60", "0.002"]]}}
{"local_ts": 1773384513019, "server_ts": 1773384512801, "data": {"e": "depthUpdate", "E": 1773384512803, "T": 1773384512801, "s": "BTCUSDT", "U": 10101338454876, "u": 10101338459616, "pu": 10101338454741, "b": [["5000.00", "101.438"], ["20747.80", "1.305"], ["20847.80", "0.495"], ["21047.80", "0.774"], ["21147.80", "0.126"], ["33000.00", "9.343"], ["67672.80", "0.002"], ["70535.30", "0.056"], ["70927.20", "3.324"], ["71089.10", "2.455"], ["71089.20", "0.823"], ["71111.00", "0.550"], ["71111.10", "0.011"], ["71129.30", "0.400"], ["71129.40", "0.508"], ["71195.20", "0.344"], ["71198.90", "0.002"], ["71199.00", "0.508"], ["71212.20", "0.073"], ["71226.50", "0.010"], ["71228.40", "0.211"], ["71239.20", "0.002"], ["71239.30", "1.052"], ["71239.50", "0.143"], ["71240.30", "0.002"], ["71244.70", "0.005"], ["71247.80", "0.429"]], "a": [["71247.90", "3.744"], ["71253.00", "0.008"], ["71258.90", "0.012"], ["71266.50", "0.006"], ["71268.60", "0.033"], ["71283.50", "0.141"], ["71463.00", "0.017"], ["71675.30", "0.006"], ["71788.00", "0.883"], ["71881.50", "2.084"], ["71960.30", "21.109"], ["71960.40", "0.698"], ["74839.40", "0.003"], ["89523.20", "0.000"]]}}
{"local_ts": 1773384514042, "server_ts": 1773384513824, "data": {"e": "depthUpdate", "E": 1773384513825, "T": 1773384513824, "s": "BTCUSDT", "U": 10101338509123, "u": 10101338513840, "pu": 10101338508967, "b": [["1000.00", "27.492"], ["5000.00", "101.418"], ["20747.80", "0.756"], ["20947.80", "0.639"], ["21047.80", "0.261"], ["21147.80", "1.044"], ["67650.90", "0.003"], ["67653.70", "0.002"], ["67683.70", "0.000"], ["70535.30", "0.056"], ["71095.70", "0.685"], ["71111.10", "0.011"], ["71129.40", "0.508"], ["71150.30", "3.532"], ["71157.30", "1.971"], ["71157.40", "0.070"], ["71164.50", "0.148"], ["71193.40", "0.910"], ["71223.00", "0.001"], ["71223.80", "0.815"], ["71224.90", "0.000"], ["71245.00", "0.053"]], "a": [["71247.90", "3.739"], ["71269.80", "0.055"], ["71270.40", "0.007"], ["71302.00", "0.869"], ["71328.40", "0.059"], ["71328.50", "0.070"], ["71335.50", "0.000"], ["71335.60", "0.002"], ["71395.40", "0.682"], ["71399.90", "3.851"], ["71500.80", "0.009"], ["71500.90", "0.004"], ["71960.20", "0.027"], ["71960.40", "4.855"], ["72024.50", "1.597"], ["72068.40", "4.433"], ["89523.20", "0.000"]]}}
{"local_ts": 1773384515066, "server_ts": 1773384514847, "data": {"e": "depthUpdate", "E": 1773384514849, "T": 1773384514847, "s": "BTCUSDT", "U": 10101338563228, "u": 10101338567510, "pu": 10101338563160, "b": [["1000.00", "27.492"], ["5000.00", "101.398"], ["20847.80", "0.504"], ["20947.80", "0.396"], ["21047.80", "0.774"], ["21147.80", "1.026"], ["64123.00", "0.051"], ["67684.50", "0.004"], ["69705.30", "0.000"], ["69822.90", "0.016"], ["70000.00", "68.510"], ["70001.00", "1.912"], ["70535.30", "0.056"], ["71111.10", "0.009"], ["71112.00", "0.047"], ["71129.40", "0.506"], ["71130.80", "0.123"], ["71150.30", "3.532"], ["71157.40", "0.070"], ["71164.50", "0.148"], ["71198.60", "0.047"], ["71198.70", "0.044"], ["71199.80", "0.146"]], "a": [["71252.10", "0.004"], ["71294.40", "0.006"], ["71294.50", "0.070"], ["71320.50", "1.930"], ["71328.50", "0.070"], ["71335.60", "0.002"], ["71960.40", "4.855"], ["74845.60", "0.000"], ["78372.70", "0.013"], ["89523.20", "0.000"]]}}
{"local_ts": 1773384516102, "server_ts": 1773384515868, "data": {"e": "depthUpdate", "E": 1773384515869, "T": 1773384515868, "s": "BTCUSDT", "U": 10101338640501, "u": 10101338690792, "pu": 10101338640471, "b": [["5000.00", "101.418"], ["20729.60", "0.009"], ["20732.90", "0.009"], ["20733.70", "0.009"], ["20737.90", "0.009"], ["20740.40", "0.036"], ["20847.80", "0.531"], ["20931.00", "0.009"], ["20932.90", "0.018"], ["20933.70", "0.009"], ["20934.10", "0.009"], ["20935.50", "0.009"], ["20940.40", "0.072"], ["20941.50", "0.036"], ["21047.80", "1.314"], ["56992.00", "0.000"], ["64111.30", "0.002"], ["67680.60", "0.000"], ["68389.30", "0.013"], ["68566.90", "0.003"], ["69047.70", "0.000"], ["69225.20", "0.000"], ["69247.80", "0.000"], ["69402.70", "0.856"], ["69580.20", "0.000"], ["69757.70", "0.030"], ["69815.60", "0.010"], ["69816.70", "0.619"], ["69987.20", "0.438"], ["70216.40", "0.003"], ["70314.10", "1.418"], ["70314.80", "2.819"], ["70358.00", "0.031"], ["70359.80", "0.004"], ["70378.30", "0.718"], ["70379.00", "0.703"], ["70414.70", "0.703"], ["70415.00", "3.862"], ["70457.60", "0.706"], ["70508.40", "1.551"], ["70517.30", "0.052"], ["70520.60", "0.004"], ["70521.40", "0.000"], ["70525.50", "0.002"], ["70527.60", "0.000"], ["70528.00", "0.002"], ["70529.10", "0.000"], ["70555.50", "0.750"], ["70556.30", "0.727"], ["70557.10", "0.702"], ["70557.60", "0.000"], ["70591.50", "0.701"], ["70593.10", "0.000"], ["70608.20", "0.706"], ["70627.60", "0.000"], ["70868.80", "0.002"], ["70879.60", "0.004"], ["70922.30", "6.475"], ["70929.70", "0.312"], ["70931.90", "0.303"], ["70932.00", "0.312"], ["70939.00", "0.310"], ["70956.70", "36.579"], ["70968.60", "0.208"], ["70974.50", "0.310"], ["70976.20", "0.002"], ["70978.70", "0.000"], ["70982.10", "0.000"], ["70994.60", "0.006"], ["71013.40", "10.004"], ["71023.10", "0.248"], ["71033.20", "0.040"], ["71035.70", "0.012"], ["71038.10", "0.040"], ["71039.70", "0.003"], ["71040.80", "0.077"], ["71043.20", "0.004"], ["71044.80", "10.000"], ["71049.70", "0.012"], ["71051.70", "0.042"], ["71052.30", "0.546"], ["71065.30", "0.000"], ["71080.10", "0.018"], ["71082.80", "0.059"], ["71083.50", "0.000"], ["71088.20", "0.020"], ["71089.30", "0.105"], ["71090.50", "0.027"], ["71090.70", "0.310"], ["71090.90", "0.053"], ["71091.20", "0.027"], ["71092.40", "0.516"], ["71097.20", "0.701"], ["71098.70", "0.208"], ["71101.60", "0.000"], ["71102.80", "0.112"], ["71103.20", "8.605"], ["71103.30", "0.000"], ["71108.10", "0.106"], ["71110.20", "0.510"], ["71111.60", "0.002"], ["71112.00", "0.045"], ["71112.30", "0.174"], ["71113.60", "0.040"], ["71114.40", "0.102"], ["71116.50", "0.073"], ["71118.60", "0.080"], ["71122.80", "0.041"], ["71126.50", "0.018"], ["71127.80", "0.002"], ["71128.70", "0.099"], ["71130.10", "0.112"], ["71130.30", "0.000"], ["71130.80", "0.121"], ["71134.00", "0.086"], ["71134.20", "0.346"], ["71135.60", "0.029"], ["71135.80", "1.107"], ["71136.20", "0.010"], ["71138.30", "0.049"], ["71139.10", "0.002"], ["71139.60", "0.002"], ["71140.20", "0.272"], ["71141.50", "0.040"], ["71142.10", "0.000"], ["71143.60", "0.290"], ["71144.50", "0.408"], ["71145.70", "0.077"], ["71145.80", "0.045"], ["71147.70", "0.300"], ["71148.00", "0.008"], ["71148.10", "0.308"], ["71148.60", "0.321"], ["71149.30", "0.042"], ["71149.70", "0.000"], ["71149.80", "0.227"], ["71149.90", "0.073"], ["71150.10", "0.508"], ["71150.80", "0.011"], ["71150.90", "0.338"], ["71151.30", "1.501"], ["71151.60", "0.001"], ["71151.70", "0.306"], ["71151.80", "0.000"], ["71151.90", "0.000"], ["71152.50", "0.002"], ["71152.60", "0.008"], ["71152.70", "0.002"], ["71153.70", "0.000"], ["71154.10", "0.000"], ["71154.30", "0.018"], ["71154.50", "6.809"], ["71154.60", "0.002"], ["71154.70", "0.047"], ["71155.00", "0.002"], ["71155.60", "0.000"], ["71156.00", "0.000"], ["71156.60", "0.002"], ["71157.00", "0.002"], ["71157.90", "0.051"], ["71158.10", "1.050"], ["71158.80", "0.022"], ["71158.90", "0.812"], ["71159.10", "0.086"], ["71159.30", "1.364"], ["71159.40", "0.076"], ["71159.70", "0.023"], ["71159.80", "0.046"], ["71159.90", "0.336"], ["71160.30", "0.004"], ["71160.80", "0.008"], ["71160.90", "0.306"], ["71161.70", "0.004"], ["71161.80", "0.002"], ["71161.90", "0.066"], ["71162.80", "0.000"], ["71163.60", "0.100"], ["71164.10", "0.000"], ["71164.20", "0.440"], ["71164.50", "0.001"], ["71164.80", "0.018"], ["71165.00", "0.006"], ["71165.40", "0.005"], ["71165.60", "0.015"], ["71166.20", "0.000"], ["71166.40", "0.000"], ["71167.30", "0.004"], ["71167.40", "0.011"], ["71167.50", "0.790"], ["71167.60", "0.009"], ["71167.70", "0.002"], ["71167.90", "0.000"], ["71168.20", "0.651"], ["71168.30", "0.000"], ["71168.40", "0.000"], ["71168.50", "0.000"], ["71169.00", "0.002"], ["71169.30", "0.323"], ["71169.40", "0.622"], ["71169.90", "0.107"], ["71170.20", "0.570"], ["71170.30", "0.003"], ["71170.60", "0.000"], ["71170.70", "0.000"], ["71171.10", "0.071"], ["71171.30", "0.074"], ["71171.80", "0.084"], ["71172.10", "1.265"], ["71172.20", "0.004"], ["71172.50", "0.185"], ["71172.70", "1.206"], ["71172.80", "0.001"], ["71173.20", "0.000"], ["71173.40", "0.006"], ["71173.50", "0.000"], ["71173.80", "0.000"], ["71174.20", "0.040"], ["71174.30", "0.553"], ["71174.40", "0.014"], ["71174.60", "0.042"], ["71174.90", "0.016"], ["71175.10", "0.000"], ["71175.40", "0.016"], ["71175.70", "0.042"], ["71175.80", "0.001"], ["71176.10", "0.080"], ["71176.50", "0.040"], ["71177.10", "0.000"], ["71177.50", "0.003"], ["71177.70", "0.005"], ["71177.80", "0.030"], ["71178.10", "1.632"], ["71178.20", "1.204"], ["71178.40", "0.076"], ["71178.50", "0.002"], ["71178.60", "0.054"], ["71178.70", "0.003"], ["71178.80", "1.382"], ["71179.00", "0.000"], ["71179.30", "0.000"], ["71179.60", "0.004"], ["71179.70", "0.017"], ["71180.30", "0.235"], ["71180.40", "0.607"], ["71180.70", "0.054"], ["71180.80", "0.056"], ["71180.90", "0.050"], ["71181.30", "0.000"], ["71181.40", "0.048"], ["71181.90", "0.040"], ["71182.10", "0.017"], ["71182.20", "0.002"], ["71182.40", "0.315"], ["71182.80", "0.192"], ["71182.90", "0.000"], ["71183.10", "0.008"], ["71183.40", "0.660"], ["71183.70", "0.000"], ["71184.20", "0.002"], ["71185.50", "0.000"], ["71185.70", "0.005"], ["71185.80", "0.049"], ["71186.60", "0.176"], ["71186.80", "0.000"], ["71186.90", "0.004"], ["71187.00", "0.003"], ["71187.20", "0.003"], ["71187.30", "0.636"], ["71187.90", "0.104"], ["71188.30", "0.005"], ["71188.40", "0.100"], ["71188.50", "0.003"], ["71188.90", "0.079"], ["71189.10", "0.338"], ["71189.20", "0.006"], ["71189.40", "0.004"], ["71189.50", "0.000"], ["71190.00", "0.067"], ["71191.00", "0.003"], ["71192.20", "0.075"], ["71192.50", "0.051"], ["71192.70", "0.218"], ["71192.80", "0.000"], ["71193.10", "0.000"], ["71193.40", "0.910"], ["71193.50", "0.055"], ["71193.90", "0.002"], ["71194.00", "0.108"], ["71194.10", "0.002"], ["71195.00", "0.007"], ["71195.60", "0.013"], ["71195.90", "0.666"], ["71196.40", "0.005"], ["71196.80", "0.003"], ["71197.00", "7.810"], ["71197.10", "0.120"], ["71197.60", "0.801"], ["71197.70", "0.247"], ["71197.80", "0.080"], ["71198.20", "0.084"], ["71198.30", "0.004"], ["71198.40", "0.009"], ["71198.50", "0.523"], ["71198.60", "0.004"], ["71199.10", "0.000"], ["71199.60", "0.001"], ["71199.80", "0.005"], ["71200.00", "100.207"], ["71200.10", "15.442"], ["71200.20", "0.205"], ["71200.30", "0.029"], ["71200.50", "0.073"], ["71200.60", "0.086"], ["71200.70", "0.180"], ["71201.10", "0.007"], ["71201.20", "0.550"], ["71201.50", "0.000"], ["71201.60", "0.159"], ["71201.80", "0.025"], ["71201.90", "0.023"], ["71202.00", "0.008"], ["71202.40", "1.042"], ["71202.50", "0.000"], ["71202.60", "0.019"], ["71203.00", "0.004"], ["71203.10", "0.000"], ["71203.20", "0.013"], ["71203.30", "0.015"], ["71203.50", "1.337"], ["71203.60", "0.006"], ["71203.90", "0.000"], ["71204.00", "0.064"], ["71204.20", "0.092"], ["71204.50", "0.053"], ["71204.60", "0.003"], ["71204.70", "0.018"], ["71204.90", "0.068"], ["71205.00", "0.004"], ["71205.20", "0.024"], ["71205.30", "0.127"], ["71205.40", "0.012"], ["71205.60", "0.072"], ["71205.90", "0.000"], ["71206.00", "0.002"], ["71206.10", "0.000"], ["71206.30", "0.007"], ["71206.70", "0.018"], ["71206.80", "0.010"], ["71207.10", "0.004"], ["71207.40", "0.318"], ["71207.50", "0.020"], ["71207.60", "0.000"], ["71208.10", "1.201"], ["71208.20", "0.127"], ["71208.80", "0.008"], ["71208.90", "0.019"], ["71209.10", "0.022"], ["71209.20", "0.013"], ["71209.30", "0.003"], ["71209.50", "1.142"], ["71209.60", "0.360"], ["71209.70", "1.865"], ["71209.80", "0.248"], ["71209.90", "0.003"], ["71210.20", "0.032"], ["71210.30", "0.607"], ["71210.50", "0.044"], ["71210.60", "0.289"], ["71210.70", "0.000"], ["71210.80", "0.000"], ["71210.90", "0.078"], ["71211.00", "0.008"], ["71211.10", "0.003"], ["71211.20", "0.505"], ["71211.60", "0.003"], ["71211.70", "0.633"], ["71211.90", "0.000"], ["71212.00", "0.005"], ["71212.10", "0.283"], ["71212.20", "0.004"], ["71212.30", "0.003"], ["71212.40", "0.096"], ["71212.50", "0.004"], ["71212.60", "0.000"], ["71212.70", "0.003"], ["71212.80", "0.000"], ["71212.90", "0.014"], ["71213.00", "0.007"], ["71213.10", "0.077"], ["71213.20", "0.009"], ["71213.30", "0.009"], ["71213.50", "0.029"], ["71213.80", "0.313"], ["71214.00", "0.004"], ["71214.20", "0.019"], ["71214.30", "0.038"], ["71214.40", "0.000"], ["71214.50", "0.006"], ["71214.60", "0.012"], ["71214.70", "0.000"], ["71214.80", "0.023"], ["71215.00", "0.014"], ["71215.10", "0.100"], ["71215.30", "0.028"], ["71215.40", "0.341"], ["71215.50", "0.011"], ["71215.60", "0.000"], ["71215.70", "0.000"], ["71215.80", "0.004"], ["71215.90", "0.076"], ["71216.20", "0.009"], ["71216.50", "0.329"], ["71216.60", "0.002"], ["71216.80", "0.002"], ["71216.90", "0.002"], ["71217.00", "0.002"], ["71217.10", "0.003"], ["71217.30", "0.014"], ["71217.40", "0.003"], ["71217.60", "0.004"], ["71217.90", "0.002"], ["71218.00", "0.016"], ["71218.10", "0.000"], ["71218.20", "0.019"], ["71218.30", "0.000"], ["71218.40", "0.666"], ["71218.50", "0.000"], ["71218.60", "0.002"], ["71218.70", "0.044"], ["71218.80", "0.203"], ["71218.90", "0.000"], ["71219.00", "0.037"], ["71219.10", "0.001"], ["71219.20", "0.003"], ["71219.30", "0.008"], ["71219.40", "0.000"], ["71219.50", "0.003"], ["71219.60", "0.117"], ["71219.70", "0.002"], ["71220.00", "0.032"], ["71220.10", "0.000"], ["71220.20", "0.000"], ["71220.30", "0.000"], ["71220.40", "0.000"], ["71220.60", "0.005"], ["71220.70", "0.000"], ["71220.80", "0.003"], ["71220.90", "0.002"], ["71221.10", "0.003"], ["71221.20", "0.000"], ["71221.30", "0.001"], ["71221.40", "0.016"], ["71221.50", "0.019"], ["71221.60", "0.225"], ["71221.70", "0.001"], ["71221.90", "0.738"], ["71222.00", "0.270"], ["71222.10", "0.004"], ["71222.20", "0.002"], ["71222.30", "0.004"], ["71222.40", "0.166"], ["71222.50", "0.070"], ["71222.60", "0.210"], ["71222.70", "0.001"], ["71222.80", "0.013"], ["71222.90", "0.002"], ["71223.20", "0.005"], ["71223.50", "0.012"], ["71223.60", "0.000"], ["71223.70", "0.001"], ["71223.90", "0.055"], ["71224.00", "0.091"], ["71224.20", "0.002"], ["71224.40", "0.003"], ["71224.60", "0.012"], ["71224.70", "0.001"], ["71224.80", "0.000"], ["71225.00", "0.024"], ["71225.10", "0.000"], ["71225.20", "0.004"], ["71225.40", "0.022"], ["71225.50", "0.003"], ["71225.80", "0.000"], ["71225.90", "0.000"], ["71226.00", "0.243"], ["71226.10", "0.000"], ["71226.20", "0.001"], ["71226.30", "0.000"], ["71226.40", "0.026"], ["71226.50", "0.003"], ["71226.60", "0.006"], ["71226.80", "0.001"], ["71227.00", "0.000"], ["71227.10", "0.000"], ["71227.40", "0.094"], ["71227.50", "0.000"], ["71227.60", "0.000"], ["71227.70", "0.001"], ["71227.90", "0.042"], ["71228.00", "0.002"], ["71228.10", "0.005"], ["71228.20", "0.003"], ["71228.30", "0.027"], ["71228.40", "0.319"], ["71228.50", "0.000"], ["71228.60", "0.000"], ["71228.70", "0.000"], ["71228.80", "0.000"], ["71228.90", "0.000"], ["71229.00", "0.000"], ["71229.10", "0.000"], ["71229.20", "0.000"], ["71229.30", "0.000"], ["71229.40", "0.000"], ["71229.50", "0.000"], ["71229.60", "0.000"], ["71229.70", "0.000"], ["71229.80", "0.000"], ["71229.90", "0.000"], ["71230.00", "0.000"], ["71230.10", "0.000"], ["71230.20", "0.000"], ["71230.30", "0.000"], ["71230.40", "0.000"], ["71230.50", "0.000"], ["71230.60", "0.000"], ["71230.70", "0.000"], ["71230.80", "0.000"], ["71230.90", "0.000"], ["71231.00", "0.000"], ["71231.40", "0.000"], ["71231.50", "0.000"], ["71231.60", "0.000"], ["71231.70", "0.000"], ["71231.80", "0.000"], ["71231.90", "0.000"], ["71232.00", "0.000"], ["71232.10", "0.000"], ["71232.20", "0.000"], ["71232.30", "0.000"], ["71232.40", "0.000"], ["71232.50", "0.000"], ["71232.60", "0.000"], ["71232.70", "0.000"], ["71232.80", "0.000"], ["71232.90", "0.000"], ["71233.00", "0.000"], ["71233.10", "0.000"], ["71233.20", "0.000"], ["71233.30", "0.000"], ["71233.40", "0.000"], ["71233.50", "0.000"], ["71233.60", "0.000"], ["71233.70", "0.000"], ["71233.80", "0.000"], ["71234.00", "0.000"], ["71234.10", "0.000"], ["71234.30", "0.000"], ["71234.40", "0.000"], ["71234.50", "0.000"], ["71234.60", "0.000"], ["71234.80", "0.000"], ["71235.00", "0.000"], ["71235.10", "0.000"], ["71235.20", "0.000"], ["71235.30", "0.000"], ["71235.40", "0.000"], ["71235.50", "0.000"], ["71235.70", "0.000"], ["71235.80", "0.000"], ["71236.00", "0.000"], ["71236.10", "0.000"], ["71236.20", "0.000"], ["71236.30", "0.000"], ["71236.40", "0.000"], ["71236.50", "0.000"], ["71236.60", "0.000"], ["71236.70", "0.000"], ["71236.80", "0.000"], ["71237.00", "0.000"], ["71237.10", "0.000"], ["71237.40", "0.000"], ["71237.50", "0.000"], ["71237.60", "0.000"], ["71237.70", "0.000"], ["71237.80", "0.000"], ["71237.90", "0.000"], ["71238.00", "0.000"], ["71238.10", "0.000"], ["71238.20", "0.000"], ["71238.30", "0.000"], ["71238.60", "0.000"], ["71238.70", "0.000"], ["71238.80", "0.000"], ["71239.00", "0.000"], ["71239.20", "0.000"], ["71239.30", "0.000"], ["71239.50", "0.000"], ["71239.80", "0.000"], ["71239.90", "0.000"], ["71240.00", "0.000"], ["71240.10", "0.000"], ["71240.40", "0.000"], ["71240.50", "0.000"], ["71240.60", "0.000"], ["71240.70", "0.000"], ["71240.80", "0.000"], ["71240.90", "0.000"], ["71241.10", "0.000"], ["71241.20", "0.000"], ["71241.30", "0.000"], ["71241.40", "0.000"], ["71241.50", "0.000"]], "a": [["71228.50", "16.956"], ["71228.60", "1.629"], ["71228.70", "0.014"], ["71228.80", "0.014"], ["71228.90", "0.124"], ["71229.00", "0.124"], ["71229.10", "0.124"], ["71229.30", "0.684"], ["71229.40", "0.124"], ["71229.50", "1.460"], ["71229.60", "2.369"], ["71229.70", "3.030"], ["71229.80", "0.210"], ["71230.00", "0.004"], ["71230.10", "0.000"], ["71230.20", "1.182"], ["71230.30", "0.124"], ["71230.40", "0.124"], ["71230.50", "0.126"], ["71230.60", "0.500"], ["71230.70", "1.852"], ["71230.80", "2.470"], ["71230.90", "0.014"], ["71231.00", "1.478"], ["71231.10", "0.164"], ["71231.20", "0.000"], ["71231.30", "0.184"], ["71231.50", "0.005"], ["71231.60", "0.126"], ["71231.70", "0.141"], ["71231.80", "2.788"], ["71231.90", "0.212"], ["71232.00", "0.498"], ["71232.10", "1.185"], ["71232.20", "0.014"], ["71232.30", "0.124"], ["71232.40", "0.550"], ["71232.50", "0.000"], ["71232.60", "2.212"], ["71232.70", "0.086"], ["71232.80", "0.000"], ["71232.90", "1.231"], ["71233.00", "0.090"], ["71233.10", "0.000"], ["71233.20", "0.000"], ["71233.30", "0.000"], ["71233.40", "0.000"], ["71233.50", "0.110"], ["71233.60", "0.000"], ["71233.70", "4.966"], ["71233.80", "0.654"], ["71233.90", "0.582"], ["71234.10", "1.119"], ["71234.20", "0.016"], ["71234.40", "0.002"], ["71234.50", "0.430"], ["71234.60", "0.014"], ["71234.70", "0.014"], ["71234.80", "0.003"], ["71234.90", "0.254"], ["71235.00", "0.036"], ["71235.10", "0.000"], ["71235.20", "0.759"], ["71235.30", "0.761"], ["71235.40", "0.017"], ["71235.50", "0.018"], ["71235.60", "0.050"], ["71235.80", "0.000"], ["71235.90", "0.014"], ["71236.00", "0.002"], ["71236.10", "0.016"], ["71236.20", "0.000"], ["71236.30", "0.014"], ["71236.40", "0.014"], ["71236.50", "0.023"], ["71236.60", "0.003"], ["71236.70", "0.000"], ["71236.80", "0.000"], ["71236.90", "0.002"], ["71237.00", "0.000"], ["71237.10", "0.000"], ["71237.20", "0.000"], ["71237.40", "0.002"], ["71237.50", "0.153"], ["71237.60", "0.002"], ["71237.70", "0.052"], ["71237.80", "0.054"], ["71237.90", "4.985"], ["71238.00", "0.008"], ["71238.10", "0.005"], ["71238.20", "0.002"], ["71238.30", "0.016"], ["71238.40", "0.003"], ["71238.60", "0.046"], ["71238.70", "0.000"], ["71238.80", "0.000"], ["71238.90", "0.000"], ["71239.00", "0.011"], ["71239.10", "0.000"], ["71239.30", "0.000"], ["71239.40", "0.000"], ["71239.60", "0.000"], ["71239.70", "0.039"], ["71239.80", "0.000"], ["71239.90", "0.128"], ["71240.00", "0.036"], ["71240.10", "0.134"], ["71240.20", "0.021"], ["71240.30", "0.033"], ["71240.40", "2.658"], ["71240.50", "0.109"], ["71240.60", "0.051"], ["71240.70", "0.000"], ["71240.80", "0.002"], ["71240.90", "0.000"], ["71241.00", "0.032"], ["71241.10", "0.000"], ["71241.20", "0.000"], ["71241.30", "0.000"], ["71241.40", "0.208"], ["71241.50", "0.045"], ["71241.60", "0.000"], ["71241.70", "0.000"], ["71241.80", "0.000"], ["71241.90", "0.002"], ["71242.00", "0.087"], ["71242.10", "0.034"], ["71242.20", "0.007"], ["71242.30", "0.003"], ["71242.40", "0.006"], ["71242.50", "0.006"], ["71242.60", "0.002"], ["71242.70", "0.007"], ["71242.80", "0.043"], ["71242.90", "0.018"], ["71243.00", "0.004"], ["71243.10", "0.027"], ["71243.20", "0.069"], ["71243.40", "0.003"], ["71243.50", "0.051"], ["71243.60", "0.000"], ["71243.70", "0.009"], ["71243.80", "0.001"], ["71243.90", "0.000"], ["71244.00", "0.003"], ["71244.10", "0.000"], ["71244.20", "0.001"], ["71244.30", "0.004"], ["71244.50", "0.000"], ["71244.60", "0.021"], ["71244.70", "0.018"], ["71244.90", "0.110"], ["71245.00", "0.002"], ["71245.10", "0.000"], ["71245.40", "0.002"], ["71245.60", "0.002"], ["71245.70", "0.001"], ["71245.80", "0.000"], ["71246.00", "0.012"], ["71246.10", "0.134"], ["71246.20", "0.006"], ["71246.30", "0.000"], ["71246.60", "0.002"], ["71246.70", "0.003"], ["71246.80", "0.000"], ["71246.90", "0.001"], ["71247.00", "0.149"], ["71247.10", "0.175"], ["71247.20", "0.004"], ["71247.30", "0.000"], ["71247.40", "0.000"], ["71247.50", "0.003"], ["71247.60", "0.199"], ["71247.70", "0.990"], ["71247.90", "0.037"], ["71248.00", "0.009"], ["71248.10", "0.006"], ["71248.20", "0.059"], ["71248.30", "0.000"], ["71248.40", "0.631"], ["71248.50", "0.002"], ["71248.60", "0.010"], ["71248.70", "0.002"], ["71248.80", "0.009"], ["71249.20", "0.002"], ["71249.40", "0.009"], ["71249.50", "0.040"], ["71249.70", "0.015"], ["71249.80", "0.004"], ["71249.90", "0.000"], ["71250.10", "0.051"], ["71250.30", "0.000"], ["71250.50", "0.004"], ["71250.60", "0.004"], ["71250.90", "0.001"], ["71251.10", "0.062"], ["71251.20", "0.090"], ["71251.50", "0.415"], ["71251.60", "0.211"], ["71251.70", "0.034"], ["71252.10", "0.006"], ["71252.20", "0.004"], ["71252.30", "0.002"], ["71252.50", "0.005"], ["71252.60", "0.340"], ["71252.80", "0.001"], ["71252.90", "0.009"], ["71253.20", "0.001"], ["71253.30", "0.056"], ["71253.40", "0.009"], ["71253.60", "0.002"], ["71253.80", "0.006"], ["71253.90", "0.023"], ["71254.00", "0.010"], ["71254.40", "0.003"], ["71254.50", "0.084"], ["71254.60", "0.038"], ["71254.70", "0.070"], ["71254.80", "0.058"], ["71254.90", "0.000"], ["71255.20", "0.008"], ["71255.30", "0.016"], ["71255.40", "0.145"], ["71255.60", "0.000"], ["71255.70", "0.754"], ["71255.80", "0.513"], ["71255.90", "0.004"], ["71256.10", "0.002"], ["71256.20", "0.076"], ["71256.30", "0.000"], ["71256.50", "0.027"], ["71256.80", "0.038"], ["71256.90", "0.003"], ["71257.00", "0.156"], ["71257.10", "1.049"], ["71257.20", "0.005"], ["71257.50", "0.002"], ["71257.80", "0.026"], ["71257.90", "0.001"], ["71258.00", "0.381"], ["71258.10", "0.021"], ["71258.20", "0.006"], ["71258.40", "0.781"], ["71258.50", "0.007"], ["71258.60", "0.004"], ["71258.70", "0.004"], ["71258.80", "0.035"], ["71258.90", "0.004"], ["71259.10", "0.009"], ["71259.20", "0.008"], ["71259.30", "0.009"], ["71259.40", "0.015"], ["71259.80", "0.509"], ["71260.00", "0.013"], ["71260.30", "0.018"], ["71260.50", "0.123"], ["71260.70", "0.020"], ["71260.80", "0.003"], ["71261.00", "0.007"], ["71261.10", "0.210"], ["71261.30", "0.310"], ["71261.40", "0.007"], ["71261.50", "0.001"], ["71261.70", "0.001"], ["71261.90", "0.003"], ["71262.00", "0.548"], ["71262.10", "0.002"], ["71262.30", "0.094"], ["71262.50", "0.010"], ["71262.70", "0.073"], ["71262.90", "0.224"], ["71263.00", "0.150"], ["71263.10", "0.000"], ["71263.20", "0.574"], ["71263.40", "0.000"], ["71263.50", "0.003"], ["71263.60", "0.045"], ["71263.70", "0.617"], ["71264.20", "0.004"], ["71264.30", "0.000"], ["71264.50", "0.007"], ["71264.60", "0.913"], ["71264.90", "0.000"], ["71265.00", "0.014"], ["71265.40", "0.016"], ["71265.60", "0.023"], ["71265.70", "0.000"], ["71266.00", "0.013"], ["71266.10", "0.397"], ["71266.20", "0.008"], ["71266.30", "0.153"], ["71266.40", "0.012"], ["71266.50", "0.002"], ["71266.60", "0.000"], ["71266.70", "0.004"], ["71266.80", "0.020"], ["71267.00", "0.002"], ["71267.10", "0.254"], ["71267.60", "0.040"], ["71267.70", "0.007"], ["71267.80", "0.002"], ["71267.90", "0.003"], ["71268.30", "0.000"], ["71268.40", "0.000"], ["71268.50", "0.001"], ["71268.60", "0.007"], ["71268.80", "0.003"], ["71269.00", "0.049"], ["71269.10", "0.008"], ["71269.20", "0.006"], ["71269.60", "0.506"], ["71269.80", "0.053"], ["71269.90", "0.207"], ["71270.00", "0.007"], ["71270.10", "0.285"], ["71270.40", "0.000"], ["71270.50", "0.340"], ["71270.60", "0.003"], ["71271.10", "0.000"], ["71271.20", "0.008"], ["71271.30", "1.090"], ["71271.40", "0.000"], ["71271.50", "0.017"], ["71271.90", "0.000"], ["71272.00", "0.005"], ["71272.20", "0.005"], ["71272.40", "0.516"], ["71272.60", "0.005"], ["71272.70", "0.280"], ["71272.80", "0.572"], ["71273.40", "0.006"], ["71273.70", "0.280"], ["71273.90", "0.004"], ["71274.10", "0.000"], ["71274.20", "0.000"], ["71274.60", "0.319"], ["71274.80", "2.229"], ["71274.90", "0.004"], ["71275.10", "0.000"], ["71275.20", "0.001"], ["71275.40", "0.004"], ["71275.50", "0.057"], ["71275.60", "1.615"], ["71275.70", "0.005"], ["71276.00", "0.807"], ["71276.10", "0.078"], ["71276.20", "0.000"], ["71276.70", "0.000"], ["71277.00", "0.026"], ["71277.10", "0.328"], ["71277.20", "0.005"], ["71277.30", "0.002"], ["71278.00", "0.006"], ["71278.10", "0.022"], ["71278.40", "0.004"], ["71278.90", "0.002"], ["71279.20", "0.209"], ["71279.30", "0.000"], ["71279.40", "0.317"], ["71279.70", "0.095"], ["71279.80", "0.000"], ["71280.00", "0.071"], ["71280.60", "0.002"], ["71280.80", "0.069"], ["71281.00", "0.019"], ["71281.10", "0.001"], ["71281.20", "0.058"], ["71281.30", "0.097"], ["71281.40", "0.001"], ["71281.50", "0.002"], ["71282.20", "0.335"], ["71282.30", "0.036"], ["71282.40", "0.004"], ["71282.70", "0.189"], ["71282.90", "1.925"], ["71283.30", "0.010"], ["71283.40", "0.001"], ["71284.00", "0.005"], ["71284.40", "0.006"], ["71284.50", "0.007"], ["71284.60", "0.002"], ["71285.10", "0.000"], ["71285.40", "0.002"], ["71285.60", "0.000"], ["71286.70", "0.018"], ["71286.90", "0.000"], ["71287.20", "0.000"], ["71287.30", "0.248"], ["71287.70", "0.004"], ["71288.10", "0.075"], ["71288.30", "0.014"], ["71288.60", "0.369"], ["71288.80", "0.508"], ["71288.90", "1.389"], ["71289.80", "0.002"], ["71289.90", "0.002"], ["71290.00", "0.684"], ["71290.10", "0.002"], ["71290.90", "0.311"], ["71291.00", "0.535"], ["71292.50", "0.060"], ["71293.10", "0.075"], ["71293.30", "0.055"], ["71293.40", "0.002"], ["71293.60", "0.442"], ["71293.80", "0.058"], ["71294.20", "0.022"], ["71294.30", "0.001"], ["71294.40", "0.001"], ["71294.50", "0.000"], ["71295.00", "0.004"], ["71295.10", "0.265"], ["71295.90", "0.044"], ["71297.90", "0.000"], ["71299.00", "0.149"], ["71301.50", "0.006"], ["71301.80", "0.000"], ["71302.00", "0.867"], ["71302.70", "0.443"], ["71302.80", "0.374"], ["71303.50", "0.009"], ["71304.60", "3.588"], ["71306.50", "0.347"], ["71306.90", "0.045"], ["71307.00", "0.114"], ["71307.50", "0.003"], ["71308.20", "0.011"], ["71309.30", "0.059"], ["71310.40", "0.256"], ["71311.00", "0.070"], ["71311.90", "0.090"], ["71312.00", "0.072"], ["71312.80", "0.056"], ["71314.50", "0.266"], ["71315.00", "0.634"], ["71315.10", "0.005"], ["71316.10", "0.526"], ["71317.40", "0.009"], ["71318.80", "6.441"], ["71318.90", "0.212"], ["71319.30", "0.002"], ["71319.40", "0.000"], ["71319.50", "0.003"], ["71319.60", "0.201"], ["71320.00", "0.021"], ["71320.30", "0.201"], ["71320.40", "0.233"], ["71321.00", "0.290"], ["71321.10", "0.026"], ["71321.20", "0.000"], ["71321.80", "0.000"], ["71322.50", "0.009"], ["71323.10", "0.007"], ["71323.40", "0.184"], ["71324.00", "0.000"], ["71324.30", "0.002"], ["71324.40", "0.005"], ["71325.00", "0.000"], ["71326.20", "0.000"], ["71326.30", "0.003"], ["71327.50", "0.000"], ["71327.60", "0.282"], ["71328.40", "0.057"], ["71329.00", "0.011"], ["71329.10", "0.095"], ["71329.50", "1.607"], ["71330.40", "0.074"], ["71331.40", "0.000"], ["71332.40", "0.009"], ["71333.30", "0.336"], ["71335.10", "0.050"], ["71337.40", "0.012"], ["71338.40", "0.077"], ["71339.40", "0.000"], ["71339.90", "0.163"], ["71340.00", "0.188"], ["71340.20", "0.290"], ["71340.60", "0.383"], ["71347.40", "0.557"], ["71348.40", "0.000"], ["71349.90", "0.346"], ["71350.50", "0.112"], ["71351.60", "0.000"], ["71352.60", "0.288"], ["71353.10", "0.016"], ["71354.70", "0.014"], ["71355.10", "0.100"], ["71356.20", "0.314"], ["71356.80", "0.546"], ["71357.10", "0.075"], ["71359.30", "0.581"], ["71362.50", "0.245"], ["71365.20", "0.000"], ["71371.00", "0.040"], ["71372.80", "2.386"], ["71373.40", "0.295"], ["71374.30", "0.018"], ["71378.10", "0.002"], ["71383.00", "0.356"], ["71384.10", "0.000"], ["71389.30", "0.000"], ["71389.70", "0.067"], ["71397.60", "0.008"], ["71398.30", "0.074"], ["71399.80", "1.577"], ["71399.90", "3.833"], ["71400.80", "12.334"], ["71401.90", "0.099"], ["71404.20", "3.144"], ["71404.40", "0.000"], ["71405.50", "0.677"], ["71408.50", "10.000"], ["71411.10", "0.000"], ["71412.70", "0.296"], ["71414.60", "0.000"], ["71415.40", "0.000"], ["71417.30", "0.016"], ["71417.70", "0.204"], ["71418.60", "0.000"], ["71421.30", "0.002"], ["71422.20", "0.002"], ["71425.70", "0.000"], ["71426.30", "0.077"], ["71426.80", "0.002"], ["71432.20", "0.003"], ["71441.90", "0.000"], ["71442.60", "0.080"], ["71443.00", "0.000"], ["71443.90", "0.040"], ["71446.90", "0.199"], ["71452.40", "1.242"], ["71454.40", "0.000"], ["71467.20", "0.546"], ["71468.80", "0.005"], ["71484.60", "0.000"], ["71495.00", "10.935"], ["71495.80", "0.000"], ["71498.60", "0.000"], ["71505.60", "0.000"], ["71526.60", "0.000"], ["71533.80", "0.312"], ["71544.20", "0.000"], ["71546.40", "3.413"], ["71546.70", "0.000"], ["71591.60", "0.000"], ["71598.10", "0.000"], ["71621.80", "0.000"], ["71625.20", "0.000"], ["71627.40", "0.000"], ["71645.10", "7.021"], ["71646.00", "0.000"], ["71659.70", "0.000"], ["71686.90", "0.000"], ["71924.80", "1.110"], ["71942.00", "0.012"], ["71943.10", "1.653"], ["71945.30", "0.035"], ["71946.10", "0.016"], ["71946.50", "0.002"], ["71952.50", "0.000"], ["71952.90", "0.000"], ["71954.00", "0.028"], ["72231.10", "0.004"], ["72232.00", "1.696"], ["72233.00", "0.797"], ["72233.80", "0.024"], ["72234.20", "0.554"], ["72235.60", "2.772"], ["72238.00", "0.102"], ["72240.50", "0.022"], ["72241.80", "0.002"], ["72241.90", "2.742"], ["72242.40", "0.000"], ["72242.70", "0.000"], ["72242.80", "0.028"], ["72246.10", "0.000"], ["74824.20", "0.002"], ["75970.10", "0.000"], ["78358.40", "0.002"], ["100000.00", "15.554"]]}}
{"local_ts": 1773384517112, "server_ts": 1773384516888, "data": {"e": "depthUpdate", "E": 1773384516889, "T": 1773384516888, "s": "BTCUSDT", "U": 10101338854580, "u": 10101338867953, "pu": 10101338854176, "b": [["1000.00", "27.492"], ["5000.00", "101.418"], ["20747.80", "0.009"], ["20822.90", "0.243"], ["20922.90", "1.161"], ["20947.80", "0.018"], ["21047.80", "0.009"], ["21122.90", "0.243"], ["64100.60", "0.002"], ["69400.00", "23.716"], ["70225.90", "1.136"], ["70510.70", "0.000"], ["70867.40", "0.000"], ["71057.70", "0.006"], ["71071.50", "0.206"], ["71101.60", "0.110"], ["71111.60", "0.000"], ["71114.80", "0.002"], ["71117.30", "0.391"], ["71120.70", "0.002"], ["71123.60", "0.389"], ["71127.90", "0.106"], ["71128.30", "0.386"], ["71130.10", "0.104"], ["71131.80", "0.070"], ["71135.40", "0.082"], ["71138.90", "0.181"], ["71142.50", "0.750"], ["71146.00", "0.080"], ["71146.30", "0.103"], ["71153.10", "0.002"], ["71158.70", "0.004"], ["71167.00", "0.157"], ["71171.50", "0.450"], ["71172.20", "0.011"], ["71172.90", "0.003"], ["71173.60", "0.003"], ["71182.20", "0.002"], ["71182.50", "0.359"], ["71186.00", "0.004"], ["71189.90", "0.003"], ["71190.00", "0.026"], ["71190.60", "0.254"], ["71190.70", "0.002"], ["71192.70", "0.208"], ["71192.80", "0.000"], ["71194.80", "0.009"], ["71194.90", "0.330"], ["71196.80", "0.068"], ["71203.80", "0.005"], ["71204.40", "0.925"], ["71205.70", "0.581"], ["71206.00", "0.008"], ["71207.00", "0.013"], ["71208.70", "0.010"], ["71209.90", "0.194"], ["71210.00", "0.118"], ["71210.50", "0.083"], ["71210.70", "0.007"], ["71211.70", "0.002"], ["71211.90", "0.141"], ["71212.40", "0.005"], ["71213.10", "0.143"], ["71213.30", "0.004"], ["71213.50", "0.097"], ["71213.60", "0.013"], ["71214.70", "0.155"], ["71214.80", "0.081"], ["71215.70", "0.025"], ["71216.10", "0.376"], ["71217.20", "0.084"], ["71217.60", "0.029"], ["71218.30", "0.036"], ["71218.80", "0.018"], ["71221.00", "0.002"], ["71221.90", "0.038"], ["71222.00", "0.120"], ["71222.80", "0.296"]], "a": [["71223.00", "0.445"], ["71230.50", "0.000"], ["71234.10", "0.000"], ["71234.20", "0.003"], ["71234.90", "0.001"], ["71235.50", "0.024"], ["71236.10", "0.004"], ["71236.40", "0.118"], ["71236.70", "0.001"], ["71237.40", "0.210"], ["71237.80", "0.000"], ["71239.90", "0.003"], ["71240.50", "0.030"], ["71240.70", "0.140"], ["71242.00", "0.005"], ["71244.40", "0.498"], ["71245.70", "0.006"], ["71248.20", "0.006"], ["71248.50", "0.023"], ["71248.80", "0.075"], ["71248.90", "0.011"], ["71249.50", "0.007"], ["71249.60", "0.009"], ["71252.50", "0.506"], ["71253.40", "0.275"], ["71253.70", "0.010"], ["71253.80", "0.011"], ["71255.10", "0.662"], ["71255.40", "0.005"], ["71256.40", "0.505"], ["71258.50", "0.005"], ["71260.10", "0.000"], ["71260.70", "0.016"], ["71265.80", "0.509"], ["71265.90", "0.031"], ["71268.70", "0.010"], ["71269.70", "1.021"], ["71269.90", "0.224"], ["71271.00", "0.000"], ["71272.90", "0.001"], ["71274.90", "0.213"], ["71280.00", "0.232"], ["71282.10", "0.002"], ["71282.90", "0.007"], ["71287.10", "0.345"], ["71287.70", "0.002"], ["71295.10", "0.348"], ["71304.90", "0.086"], ["71306.90", "0.000"], ["71310.20", "0.171"], ["71314.00", "0.435"], ["71317.30", "0.251"], ["71327.80", "0.076"], ["71348.20", "0.252"], ["71375.70", "0.002"], ["71399.90", "2.285"], ["71400.80", "0.000"], ["71407.50", "0.000"], ["71422.40", "0.060"], ["71899.60", "1.927"], ["71935.20", "0.000"], ["71954.70", "2.889"], ["72255.70", "4.252"], ["72297.10", "1.920"], ["72327.00", "2.958"], ["72364.80", "1.385"], ["74824.20", "0.000"], ["78345.30", "0.002"]]}}
{"local_ts": 1773384518130, "server_ts": 1773384517912, "data": {"e": "depthUpdate", "E": 1773384517913, "T": 1773384517912, "s": "BTCUSDT", "U": 10101338933276, "u": 10101338944156, "pu": 10101338933252, "b": [["5000.00", "101.418"], ["20722.90", "0.108"], ["20822.90", "1.557"], ["20922.90", "0.135"], ["21022.90", "0.108"], ["21122.90", "0.792"], ["33000.00", "9.339"], ["40000.00", "49.307"], ["56978.00", "0.000"], ["64100.60", "0.002"], ["67674.80", "0.000"], ["70510.70", "1.416"], ["70900.00", "26.336"], ["71096.70", "0.082"], ["71101.60", "0.074"], ["71108.80", "0.002"], ["71113.60", "0.043"], ["71131.80", "0.070"], ["71134.80", "0.542"], ["71138.90", "0.181"], ["71146.00", "0.080"], ["71163.80", "0.002"], ["71165.70", "0.045"], ["71171.20", "0.995"], ["71174.80", "1.690"], ["71178.20", "1.206"], ["71178.30", "0.031"], ["71184.40", "0.000"], ["71189.50", "0.051"], ["71189.90", "0.003"], ["71190.00", "0.026"], ["71190.60", "0.254"], ["71190.70", "0.002"], ["71195.50", "0.000"], ["71195.60", "0.000"], ["71196.00", "0.024"], ["71196.20", "0.005"], ["71196.30", "0.004"], ["71197.20", "0.571"], ["71199.10", "0.245"], ["71200.00", "100.223"], ["71200.30", "0.880"], ["71200.70", "0.245"], ["71201.30", "0.174"], ["71202.90", "0.010"], ["71204.50", "0.160"], ["71205.10", "0.039"], ["71205.90", "1.301"], ["71206.40", "0.003"], ["71207.00", "0.013"], ["71207.60", "0.039"], ["71208.20", "0.045"], ["71208.60", "0.003"], ["71209.20", "0.008"], ["71209.70", "1.197"], ["71211.50", "0.003"], ["71211.60", "0.676"], ["71212.00", "0.743"], ["71212.30", "0.096"], ["71212.50", "0.073"], ["71212.80", "0.081"], ["71212.90", "0.021"], ["71213.00", "0.060"], ["71213.10", "0.084"], ["71213.20", "0.149"], ["71213.40", "0.133"], ["71213.50", "0.034"], ["71213.60", "0.132"], ["71214.10", "0.361"], ["71214.20", "0.588"], ["71214.40", "0.113"], ["71214.90", "0.015"], ["71215.10", "0.000"], ["71215.80", "0.056"], ["71216.40", "0.508"], ["71219.30", "0.211"], ["71222.80", "0.085"], ["71222.90", "4.832"]], "a": [["71223.00", "0.534"], ["71224.50", "0.002"], ["71225.00", "0.004"], ["71226.40", "0.004"], ["71230.80", "0.006"], ["71236.50", "0.009"], ["71236.70", "0.072"], ["71237.20", "0.179"], ["71238.10", "0.051"], ["71238.90", "0.000"], ["71240.30", "0.000"], ["71240.40", "0.436"], ["71240.80", "0.200"], ["71243.10", "0.024"], ["71244.20", "0.135"], ["71244.40", "0.348"], ["71245.20", "0.506"], ["71245.30", "0.001"], ["71246.70", "0.003"], ["71247.10", "0.051"], ["71247.30", "0.631"], ["71248.50", "0.093"], ["71249.10", "0.039"], ["71249.30", "0.000"], ["71251.20", "0.164"], ["71251.30", "0.003"], ["71252.50", "0.506"], ["71253.10", "0.002"], ["71253.20", "0.000"], ["71254.30", "0.003"], ["71254.60", "0.247"], ["71255.20", "0.510"], ["71256.80", "0.042"], ["71259.60", "0.002"], ["71264.20", "0.000"], ["71267.30", "0.609"], ["71274.80", "1.390"], ["71287.10", "0.518"], ["71294.20", "0.002"], ["71310.00", "0.285"], ["71310.20", "0.101"], ["71313.00", "0.002"], ["71317.10", "0.002"], ["71317.30", "0.249"], ["71471.50", "4.777"], ["71935.20", "0.695"], ["71939.10", "0.149"], ["72148.90", "2.746"], ["72190.20", "1.372"], ["72255.70", "10.973"], ["72298.50", "0.959"], ["72327.00", "8.706"], ["72369.80", "0.000"], ["72647.40", "0.014"], ["74791.10", "0.002"], ["78345.30", "0.002"]]}}
{"local_ts": 1773384519150, "server_ts": 1773384518932, "data": {"e": "depthUpdate", "E": 1773384518933, "T": 1773384518932, "s": "BTCUSDT", "U": 10101339040771, "u": 10101339047787, "pu": 10101339040749, "b": [["1000.00", "27.492"], ["5000.00", "101.418"], ["20722.90", "1.503"], ["20822.90", "0.297"], ["21022.90", "0.873"], ["21122.90", "0.027"], ["70086.30", "0.611"], ["70446.60", "0.710"], ["70510.70", "1.416"], ["70866.90", "0.004"], ["70973.50", "0.008"], ["71101.90", "0.041"], ["71105.50", "0.036"], ["71105.80", "0.077"], ["71106.70", "0.000"], ["71107.40", "0.177"], ["71171.20", "0.727"], ["71177.90", "0.004"], ["71178.00", "0.008"], ["71178.40", "0.112"], ["71179.40", "0.119"], ["71179.80", "0.025"], ["71180.00", "0.054"], ["71180.10", "0.146"], ["71187.20", "0.003"], ["71195.30", "0.328"], ["71203.30", "0.001"], ["71203.70", "1.198"], ["71205.10", "0.039"], ["71206.40", "0.003"], ["71207.50", "0.148"], ["71208.50", "0.006"], ["71209.10", "0.298"], ["71209.90", "0.187"], ["71210.00", "0.557"], ["71213.30", "0.007"], ["71214.10", "0.318"], ["71215.80", "0.052"], ["71216.70", "0.001"], ["71218.40", "0.436"], ["71218.50", "0.002"], ["71218.80", "0.001"], ["71220.90", "0.004"], ["71222.90", "3.444"]], "a": [["71223.00", "1.173"], ["71223.10", "0.210"], ["71225.00", "0.004"], ["71227.10", "0.000"], ["71230.80", "0.006"], ["71231.80", "0.004"], ["71232.70", "0.001"], ["71233.40", "0.388"], ["71234.30", "0.000"], ["71235.40", "0.006"], ["71235.50", "0.006"], ["71235.60", "0.015"], ["71235.70", "0.709"], ["71235.80", "0.012"], ["71236.60", "0.270"], ["71236.70", "0.707"], ["71236.80", "0.649"], ["71237.80", "0.140"], ["71238.60", "0.039"], ["71239.30", "0.413"], ["71240.80", "0.119"], ["71244.40", "0.348"], ["71247.20", "0.187"], ["71260.40", "0.320"], ["71265.60", "1.882"], ["71274.60", "0.423"], ["71274.70", "0.556"], ["71280.00", "0.317"], ["71283.50", "0.275"], ["71285.30", "0.106"], ["71287.10", "0.345"], ["71289.00", "3.439"], ["71304.90", "0.145"], ["71326.60", "6.625"], ["71388.40", "12.736"], ["71471.40", "0.332"], ["71935.10", "0.006"], ["71935.20", "0.695"], ["72220.10", "1.438"], ["74789.90", "0.036"], ["76857.60", "0.002"]]}}
{"local_ts": 1773384520175, "server_ts": 1773384519958, "data": {"e": "depthUpdate", "E": 1773384519959, "T": 1773384519958, "s": "BTCUSDT", "U": 10101339105554, "u": 10101339109850, "pu": 10101339105550, "b": [["1000.00", "27.492"], ["5000.00", "101.418"], ["20722.90", "0.558"], ["20922.90", "0.738"], ["21022.90", "0.162"], ["21122.90", "1.242"], ["33000.00", "9.343"], ["64100.60", "0.000"], ["67646.50", "0.000"], ["67685.40", "2.216"], ["67685.50", "0.012"], ["70510.70", "1.416"], ["70581.90", "0.042"], ["70886.10", "0.006"], ["70909.30", "0.000"], ["70988.00", "0.022"], ["71131.60", "0.020"], ["71138.70", "0.981"], ["71145.80", "0.047"], ["71186.10", "0.067"], ["71188.40", "0.026"], ["71193.80", "0.252"], ["71196.00", "0.024"], ["71205.00", "0.343"], ["71206.30", "0.506"], ["71207.70", "0.002"], ["71207.80", "0.635"], ["71209.00", "0.003"], ["71210.50", "0.022"], ["71218.00", "0.016"], ["71218.10", "0.018"], ["71222.90", "3.073"]], "a": [["71245.00", "0.007"], ["71247.50", "0.003"], ["71262.40", "1.039"], ["71262.60", "0.004"], ["71274.70", "0.556"], ["71274.80", "1.390"], ["71280.00", "0.257"], ["71280.50", "0.150"], ["71309.80", "0.000"], ["71316.90", "0.078"], ["71935.20", "0.695"], ["72150.10", "0.242"], ["72195.50", "0.692"], ["72338.80", "0.345"], ["74071.90", "0.580"], ["74809.80", "0.011"], ["78345.30", "0.000"]]}}
{"local_ts": 1773384521198, "server_ts": 1773384520976, "data": {"e": "depthUpdate", "E": 1773384520981, "T": 1773384520976, "s": "BTCUSDT", "U": 10101339176117, "u": 10101339180723, "pu": 10101339176056, "b": [["5000.00", "101.418"], ["20822.90", "0.603"], ["20922.90", "0.297"], ["21022.90", "0.972"], ["21122.90", "0.828"], ["56978.00", "0.000"], ["64100.60", "0.000"], ["67634.70", "0.002"], ["69803.80", "0.000"], ["69976.50", "4.084"], ["70510.70", "1.416"], ["70510.80", "0.002"], ["70973.40", "0.004"], ["70985.80", "0.002"], ["70988.00", "0.020"], ["71105.50", "0.072"], ["71105.80", "0.113"], ["71106.10", "0.531"], ["71106.20", "0.038"], ["71106.70", "0.025"], ["71107.00", "0.231"], ["71107.40", "0.202"], ["71160.40", "1.200"], ["71167.90", "0.866"], ["71171.70", "0.000"], ["71178.00", "0.010"], ["71178.20", "1.204"], ["71190.50", "0.001"], ["71200.20", "0.228"], ["71203.60", "0.267"], ["71204.70", "0.634"], ["71209.90", "0.024"], ["71213.20", "0.184"], ["71213.50", "0.036"], ["71213.80", "0.203"], ["71213.90", "0.041"], ["71214.20", "0.639"], ["71214.50", "0.033"], ["71214.90", "0.026"], ["71222.90", "1.729"]], "a": [["71223.00", "3.517"], ["71223.70", "0.004"], ["71233.20", "0.328"], ["71235.50", "0.006"], ["71236.40", "0.706"], ["71239.00", "0.265"], ["71242.30", "0.005"], ["71256.60", "0.004"], ["71273.40", "0.008"], ["71273.60", "0.002"], ["71287.10", "0.489"], ["71379.00", "0.676"], ["71386.80", "0.000"], ["71935.20", "0.695"], ["74794.50", "0.050"], ["78345.30", "0.000"]]}}
{"local_ts": 1773384522222, "server_ts": 1773384522003, "data": {"e": "depthUpdate", "E": 1773384522005, "T": 1773384522003, "s": "BTCUSDT", "U": 10101339229562, "u": 10101339235763, "pu": 10101339229522, "b": [["1000.00", "27.492"], ["5000.00", "101.418"], ["20722.90", "0.477"], ["20822.90", "0.423"], ["20922.90", "0.702"], ["21022.90", "1.098"], ["64100.60", "0.000"], ["67642.00", "0.009"], ["69979.30", "2.284"], ["70510.70", "1.416"], ["70866.80", "0.006"], ["70900.00", "27.008"], ["70985.80", "0.000"], ["70986.20", "0.002"], ["71066.00", "4.039"], ["71074.90", "0.796"], ["71125.80", "0.110"], ["71132.90", "0.072"], ["71140.00", "16.606"], ["71163.10", "1.373"], ["71165.40", "0.737"], ["71170.20", "0.002"], ["71173.60", "0.005"], ["71192.40", "0.245"], ["71193.80", "0.007"], ["71198.60", "0.074"], ["71200.00", "100.203"], ["71200.20", "0.186"], ["71203.60", "1.276"], ["71205.20", "0.004"], ["71207.30", "0.157"], ["71209.90", "0.024"], ["71210.20", "0.004"], ["71210.60", "0.441"], ["71211.30", "0.041"], ["71212.20", "0.304"], ["71212.80", "0.005"], ["71215.80", "0.052"], ["71216.50", "0.046"], ["71218.50", "0.002"], ["71219.30", "0.018"], ["71220.90", "0.001"], ["71222.90", "1.673"]], "a": [["71223.00", "3.713"], ["71225.20", "0.007"], ["71228.20", "0.002"], ["71232.40", "0.003"], ["71235.30", "0.029"], ["71236.40", "0.846"], ["71238.50", "0.001"], ["71238.60", "0.090"], ["71239.00", "0.404"], ["71240.10", "0.005"], ["71240.80", "0.341"], ["71242.30", "0.132"], ["71245.10", "0.009"], ["71254.60", "0.073"], ["71258.00", "0.008"], ["71274.40", "0.004"], ["71274.60", "0.319"], ["71283.50", "0.215"], ["71285.30", "0.106"], ["71287.10", "0.443"], ["71304.00", "0.072"], ["71311.10", "0.049"], ["71370.40", "0.568"], ["71379.30", "2.318"], ["71379.40", "0.003"], ["71388.20", "2.868"], ["71449.70", "0.522"], ["71579.00", "0.050"], ["71935.20", "0.695"], ["74815.90", "0.000"], ["78345.30", "0.000"]]}}
{"local_ts": 1773384523263, "server_ts": 1773384523024, "data": {"e": "depthUpdate", "E": 1773384523027, "T": 1773384523024, "s": "BTCUSDT", "U": 10101339303163, "u": 10101339308345, "pu": 10101339302930, "b": [["5000.00", "101.398"], ["20722.90", "0.558"], ["20822.90", "0.441"], ["20922.90", "1.359"], ["21122.90", "0.342"], ["56978.00", "0.000"], ["64100.60", "0.000"], ["67632.50", "0.002"], ["68374.00", "0.013"], ["69086.20", "0.034"], ["70143.80", "2.132"], ["70175.90", "1.351"], ["70510.70", "1.416"], ["70956.30", "0.000"], ["70983.30", "0.004"], ["70986.20", "0.000"], ["71074.90", "0.006"], ["71075.00", "0.980"], ["71144.50", "0.411"], ["71150.00", "1.537"], ["71152.80", "0.000"], ["71153.90", "2.049"], ["71158.80", "0.025"], ["71171.90", "0.005"], ["71208.60", "0.003"], ["71209.60", "0.346"], ["71209.90", "0.024"], ["71215.80", "0.024"], ["71216.10", "0.325"], ["71220.50", "0.006"], ["71220.90", "0.001"], ["71222.20", "0.002"], ["71222.40", "0.493"], ["71222.50", "0.168"], ["71222.60", "0.004"], ["71222.80", "0.077"], ["71222.90", "2.148"]], "a": [["71223.00", "2.548"], ["71223.60", "0.059"], ["71223.70", "0.002"], ["71223.80", "0.004"], ["71225.40", "0.005"], ["71229.60", "0.006"], ["71233.70", "0.000"], ["71240.80", "0.121"], ["71241.10", "0.000"], ["71242.20", "0.631"], ["71244.40", "0.418"], ["71245.10", "0.009"], ["71245.20", "0.529"], ["71246.10", "0.122"], ["71247.20", "0.132"], ["71247.60", "0.471"], ["71249.30", "0.505"], ["71255.70", "0.002"], ["71257.60", "0.594"], ["71269.20", "0.072"], ["71271.30", "0.027"], ["71280.00", "0.271"], ["71287.10", "0.504"], ["71292.40", "0.056"], ["71301.40", "0.380"], ["71319.70", "0.000"], ["71370.40", "0.573"], ["71935.20", "0.695"], ["72327.30", "0.690"], ["72647.40", "0.011"], ["74801.50", "0.052"], ["78345.30", "0.000"]]}}
